#######################################################################
# +-----------------------------------------------------------------+ #
# |                            BO3 object                           | #
# +-----------------------------------------------------------------+ #
#######################################################################

# The descriptions in this file are true only for TerrainControl. They are not true for the Minecraft Worlds mod!
# Minecraft Worlds completely reimplemented BO3s, check the MCW documentation on the mc/mctcp forums for how to use BO3s with MCW
# or watch the video's on my YT channel at https://www.youtube.com/user/PeeGee85. You can check out the "Editing and importing schematics & BO3s" 
# series of video's, in part 2 I explain BO3s. 

# This is the config file of a custom object.
# If you add this object correctly to your BiomeConfigs, it will spawn in the world.

# This is the creator of this BO3 object
Author: Unknown

# A short description of this BO3 object
Description: This BO3 was converted from a schematic using the MineCraft Worlds Editor. Unfortunately the author and description information for the schematic could not be found. If you know who the author of the schematic is then please tell the author of this BO3!

# The BO3 version, don't change this! It can be used by external applications to do a version check.
Version: 3

# The settings mode, WriteAll, WriteWithoutComments or WriteDisable. See WorldConfig.
SettingsMode: WriteDisable

#######################################################################
# +-----------------------------------------------------------------+ #
# |                          Main settings                          | #
# +-----------------------------------------------------------------+ #
#######################################################################

# This needs to be set to true to spawn the object in the Tree and Sapling resources.
Tree: false

# The frequency of the BO3 from 1 to 200. Tries this many times to spawn this BO3 when using the CustomObject(...) resource.
# Ignored by Tree(..), Sapling(..) and CustomStructure(..)
Frequency: 40

# The rarity of the BO3 from 0 to 100. Each spawn attempt has rarity% chance to succeed when using the CustomObject(...) resource.
# Ignored by Tree(..), Sapling(..) and CustomStructure(..)
Rarity: 100.0

# If you set this to true, the BO3 will be placed with a random rotation.
RotateRandomly: false

# The spawn height of the BO3 - randomY, highestBlock or highestSolidBlock.
SpawnHeight: highestBlock

# The height limits for the BO3.
MinHeight: 0

MaxHeight: 256

# Objects can have other objects attached to it: branches. Branches can also
# have branches attached to it, which can also have branches, etc. This is the
# maximum branch depth for this objects.
MaxBranchDepth: 10

# When spawned with the UseWorld keyword, this BO3 should NOT spawn in the following biomes.
# If you writer.write the BO3 name directly in the BiomeConfigs, this will be ignored.
ExcludedBiomes: All

#######################################################################
# +-----------------------------------------------------------------+ #
# |                      Source block settings                      | #
# +-----------------------------------------------------------------+ #
#######################################################################

# The block(s) the BO3 should spawn in.
SourceBlocks: AIR

# The maximum percentage of the BO3 that can be outside the SourceBlock.
# The BO3 won't be placed on a location with more blocks outside the SourceBlock than this percentage.
MaxPercentageOutsideSourceBlock: 100

# What to do when a block is about to be placed outside the SourceBlock? (dontPlace, placeAnyway)
OutsideSourceBlock: placeAnyway

#######################################################################
# +-----------------------------------------------------------------+ #
# |                              Blocks                             | #
# +-----------------------------------------------------------------+ #
#######################################################################

# All the blocks used in the BO3 are listed here. Possible blocks:
# Block(x,y,z,id[.data][,nbtfile.nbt)
# RandomBlock(x,y,z,id[:data][,nbtfile.nbt],chance[,id[:data][,nbtfile.nbt],chance[,...]])
# So RandomBlock(0,0,0,CHEST,chest.nbt,50,CHEST,anotherchest.nbt,100) will spawn a chest at
# the BO3 origin, and give it a 50% chance to have the contents of chest.nbt, or, if that
# fails, a 100% percent chance to have the contents of anotherchest.nbt.

Block(-8,31,-4,1)
Block(-8,31,5,1)
Block(-8,31,6,1)
Block(-8,31,7,1)
Block(-8,31,8,1)
Block(-8,32,-7,1)
Block(-8,32,-6,1)
Block(-8,32,-5,1)
Block(-8,32,-4,1)
Block(-8,32,-3,1)
Block(-8,32,-2,1)
Block(-8,32,-1,1)
Block(-8,32,0,1)
Block(-8,32,4,1)
Block(-8,32,5,1)
Block(-8,32,6,1)
Block(-8,32,7,1)
Block(-8,32,8,1)
Block(-8,33,-7,1)
Block(-8,33,-6,1)
Block(-8,33,-5,1)
Block(-8,33,-4,1)
Block(-8,33,-3,1)
Block(-8,33,-2,1)
Block(-8,33,-1,1)
Block(-8,33,0,1)
Block(-8,33,1,1)
Block(-8,33,2,1)
Block(-8,33,3,1)
Block(-8,33,4,1)
Block(-8,33,5,1)
Block(-8,33,6,1)
Block(-8,33,7,1)
Block(-8,33,8,1)
Block(-8,34,-7,1)
Block(-8,34,-6,1)
Block(-8,34,-5,1)
Block(-8,34,-4,1)
Block(-8,34,-3,1)
Block(-8,34,-2,1)
Block(-8,34,-1,1)
Block(-8,34,0,1)
Block(-8,34,1,1)
Block(-8,34,2,1)
Block(-8,34,3,1)
Block(-8,34,4,1)
Block(-8,34,5,1)
Block(-8,34,6,1)
Block(-8,34,7,1)
Block(-8,34,8,1)
Block(-8,35,-7,1)
Block(-8,35,-6,1)
Block(-8,35,-5,1)
Block(-8,35,-4,1)
Block(-8,35,-3,1)
Block(-8,35,-2,1)
Block(-8,35,-1,1)
Block(-8,35,0,1)
Block(-8,35,1,1)
Block(-8,35,2,1)
Block(-8,35,3,1)
Block(-8,35,4,1)
Block(-8,35,5,1)
Block(-8,35,6,1)
Block(-8,35,7,1)
Block(-8,35,8,1)
Block(-8,36,-7,1)
Block(-8,36,-6,1)
Block(-8,36,-5,1)
Block(-8,36,-4,1)
Block(-8,36,-3,1)
Block(-8,36,-2,1)
Block(-8,36,-1,1)
Block(-8,36,0,1)
Block(-8,36,1,1)
Block(-8,36,2,1)
Block(-8,36,3,1)
Block(-8,36,4,1)
Block(-8,36,5,1)
Block(-8,36,6,1)
Block(-8,36,7,1)
Block(-8,36,8,1)
Block(-8,37,-7,1)
Block(-8,37,-6,1)
Block(-8,37,-5,1)
Block(-8,37,-4,1)
Block(-8,37,-3,1)
Block(-8,37,-2,1)
Block(-8,37,-1,1)
Block(-8,37,0,1)
Block(-8,37,1,1)
Block(-8,37,2,1)
Block(-8,37,3,1)
Block(-8,37,4,1)
Block(-8,37,5,1)
Block(-8,37,6,1)
Block(-8,37,7,1)
Block(-8,37,8,1)
Block(-8,38,-7,1)
Block(-8,38,-6,1)
Block(-8,38,-5,1)
Block(-8,38,-4,1)
Block(-8,38,-3,1)
Block(-8,38,-2,1)
Block(-8,38,-1,1)
Block(-8,38,0,1)
Block(-8,38,1,1)
Block(-8,38,2,1)
Block(-8,38,3,1)
Block(-8,38,4,1)
Block(-8,38,5,1)
Block(-8,38,6,1)
Block(-8,38,7,1)
Block(-8,38,8,1)
Block(-8,39,-7,1)
Block(-8,39,-6,1)
Block(-8,39,-5,1)
Block(-8,39,-4,1)
Block(-8,39,-3,1)
Block(-8,39,-2,1)
Block(-8,39,-1,1)
Block(-8,39,0,1)
Block(-8,39,1,1)
Block(-8,39,2,1)
Block(-8,39,3,1)
Block(-8,39,4,1)
Block(-8,39,5,1)
Block(-8,39,6,1)
Block(-8,39,7,3)
Block(-8,39,8,3)
Block(-8,40,-7,3)
Block(-8,40,-6,3)
Block(-8,40,-5,3)
Block(-8,40,-4,3)
Block(-8,40,-3,3)
Block(-8,40,-2,3)
Block(-8,40,-1,3)
Block(-8,40,0,3)
Block(-8,40,1,3)
Block(-8,40,2,3)
Block(-8,40,3,3)
Block(-8,40,4,3)
Block(-8,40,5,3)
Block(-8,40,6,3)
Block(-8,40,7,3)
Block(-8,40,8,3)
Block(-8,41,-7,3)
Block(-8,41,-6,3)
Block(-8,41,-5,3)
Block(-8,41,-4,3)
Block(-8,41,-3,3)
Block(-8,41,-2,3)
Block(-8,41,-1,3)
Block(-8,41,0,3)
Block(-8,41,1,3)
Block(-8,41,2,3)
Block(-8,41,3,3)
Block(-8,41,4,3)
Block(-8,41,5,3)
Block(-8,41,6,3)
Block(-8,41,7,3)
Block(-8,41,8,3)
Block(-8,42,-7,3)
Block(-8,42,-6,3)
Block(-8,42,-5,3)
Block(-8,42,-4,3)
Block(-8,42,-3,3)
Block(-8,42,-2,3)
Block(-8,42,-1,3)
Block(-8,42,0,3)
Block(-8,42,1,3)
Block(-8,42,2,3)
Block(-8,42,3,3)
Block(-8,42,4,3)
Block(-8,42,5,3)
Block(-8,42,6,3)
Block(-8,42,7,2)
Block(-8,42,8,2)
Block(-8,43,-7,2)
Block(-8,43,-6,2)
Block(-8,43,-5,2)
Block(-8,43,-4,2)
Block(-8,43,-3,2)
Block(-8,43,-2,2)
Block(-8,43,-1,2)
Block(-8,43,0,2)
Block(-8,43,1,2)
Block(-8,43,2,2)
Block(-8,43,3,2)
Block(-8,43,4,2)
Block(-8,43,5,2)
Block(-8,43,6,2)
Block(-7,29,-7,1)
Block(-7,30,-7,1)
Block(-7,30,5,1)
Block(-7,30,6,1)
Block(-7,31,-7,1)
Block(-7,31,-6,1)
Block(-7,31,5,1)
Block(-7,31,6,1)
Block(-7,31,7,1)
Block(-7,31,8,1)
Block(-7,32,-7,1)
Block(-7,32,-6,1)
Block(-7,32,-5,1)
Block(-7,32,-4,1)
Block(-7,32,-3,1)
Block(-7,32,-2,1)
Block(-7,32,-1,1)
Block(-7,32,5,1)
Block(-7,32,6,1)
Block(-7,32,7,1)
Block(-7,32,8,1)
Block(-7,33,-7,1)
Block(-7,33,-6,1)
Block(-7,33,-5,1)
Block(-7,33,-4,1)
Block(-7,33,-3,1)
Block(-7,33,-2,1)
Block(-7,33,-1,1)
Block(-7,33,0,1)
Block(-7,33,1,1)
Block(-7,33,2,1)
Block(-7,33,3,1)
Block(-7,33,4,1)
Block(-7,33,5,1)
Block(-7,33,6,1)
Block(-7,33,7,1)
Block(-7,33,8,1)
Block(-7,34,-7,1)
Block(-7,34,-6,1)
Block(-7,34,-5,1)
Block(-7,34,-4,1)
Block(-7,34,-3,1)
Block(-7,34,-2,1)
Block(-7,34,-1,1)
Block(-7,34,0,1)
Block(-7,34,1,1)
Block(-7,34,2,1)
Block(-7,34,3,1)
Block(-7,34,4,1)
Block(-7,34,5,1)
Block(-7,34,6,1)
Block(-7,34,7,1)
Block(-7,34,8,1)
Block(-7,35,-7,1)
Block(-7,35,-6,1)
Block(-7,35,-5,1)
Block(-7,35,-4,1)
Block(-7,35,-3,1)
Block(-7,35,-2,1)
Block(-7,35,-1,1)
Block(-7,35,0,1)
Block(-7,35,1,1)
Block(-7,35,2,1)
Block(-7,35,3,1)
Block(-7,35,4,1)
Block(-7,35,5,1)
Block(-7,35,6,1)
Block(-7,35,7,1)
Block(-7,35,8,1)
Block(-7,36,-7,1)
Block(-7,36,-6,1)
Block(-7,36,-5,1)
Block(-7,36,-4,1)
Block(-7,36,-3,1)
Block(-7,36,-2,1)
Block(-7,36,-1,1)
Block(-7,36,0,1)
Block(-7,36,1,1)
Block(-7,36,2,1)
Block(-7,36,3,1)
Block(-7,36,4,1)
Block(-7,36,5,1)
Block(-7,36,6,1)
Block(-7,36,7,1)
Block(-7,36,8,1)
Block(-7,37,-7,1)
Block(-7,37,-6,1)
Block(-7,37,-5,1)
Block(-7,37,-4,1)
Block(-7,37,-3,1)
Block(-7,37,-2,1)
Block(-7,37,-1,1)
Block(-7,37,0,1)
Block(-7,37,1,1)
Block(-7,37,2,1)
Block(-7,37,3,1)
Block(-7,37,4,1)
Block(-7,37,5,1)
Block(-7,37,6,1)
Block(-7,37,7,1)
Block(-7,37,8,1)
Block(-7,38,-7,1)
Block(-7,38,-6,1)
Block(-7,38,-5,1)
Block(-7,38,-4,1)
Block(-7,38,-3,1)
Block(-7,38,-2,1)
Block(-7,38,-1,1)
Block(-7,38,0,1)
Block(-7,38,1,1)
Block(-7,38,2,1)
Block(-7,38,3,1)
Block(-7,38,4,1)
Block(-7,38,5,1)
Block(-7,38,6,1)
Block(-7,38,7,1)
Block(-7,38,8,1)
Block(-7,39,-7,1)
Block(-7,39,-6,1)
Block(-7,39,-5,1)
Block(-7,39,-4,1)
Block(-7,39,-3,1)
Block(-7,39,-2,1)
Block(-7,39,-1,1)
Block(-7,39,0,1)
Block(-7,39,1,1)
Block(-7,39,2,1)
Block(-7,39,3,3)
Block(-7,39,4,3)
Block(-7,39,5,3)
Block(-7,39,6,3)
Block(-7,39,7,3)
Block(-7,39,8,3)
Block(-7,40,-7,3)
Block(-7,40,-6,3)
Block(-7,40,-5,3)
Block(-7,40,-4,3)
Block(-7,40,-3,3)
Block(-7,40,-2,3)
Block(-7,40,-1,3)
Block(-7,40,0,3)
Block(-7,40,1,3)
Block(-7,40,2,3)
Block(-7,40,3,3)
Block(-7,40,4,3)
Block(-7,40,5,3)
Block(-7,40,6,3)
Block(-7,40,7,3)
Block(-7,40,8,3)
Block(-7,41,-7,3)
Block(-7,41,-6,3)
Block(-7,41,-5,3)
Block(-7,41,-4,3)
Block(-7,41,-3,3)
Block(-7,41,-2,3)
Block(-7,41,-1,3)
Block(-7,41,0,3)
Block(-7,41,1,3)
Block(-7,41,2,3)
Block(-7,41,3,3)
Block(-7,41,4,3)
Block(-7,41,5,3)
Block(-7,41,6,3)
Block(-7,41,7,3)
Block(-7,41,8,3)
Block(-7,42,-7,3)
Block(-7,42,-6,3)
Block(-7,42,-5,3)
Block(-7,42,-4,3)
Block(-7,42,-3,3)
Block(-7,42,-2,3)
Block(-7,42,-1,3)
Block(-7,42,0,3)
Block(-7,42,1,3)
Block(-7,42,2,3)
Block(-7,42,3,2)
Block(-7,42,4,2)
Block(-7,42,5,2)
Block(-7,42,6,2)
Block(-7,42,7,2)
Block(-7,42,8,2)
Block(-7,43,-7,2)
Block(-7,43,-6,2)
Block(-7,43,-5,2)
Block(-7,43,-4,2)
Block(-7,43,-3,2)
Block(-7,43,-2,2)
Block(-7,43,-1,2)
Block(-7,43,0,2)
Block(-7,43,1,2)
Block(-7,43,2,2)
Block(-6,28,-7,1)
Block(-6,29,-7,1)
Block(-6,29,-6,1)
Block(-6,30,-7,1)
Block(-6,30,-6,1)
Block(-6,30,4,1)
Block(-6,30,7,1)
Block(-6,30,8,1)
Block(-6,31,-7,1)
Block(-6,31,-6,1)
Block(-6,31,4,1)
Block(-6,31,5,1)
Block(-6,31,6,1)
Block(-6,31,7,1)
Block(-6,31,8,1)
Block(-6,32,-7,1)
Block(-6,32,-6,1)
Block(-6,32,-5,1)
Block(-6,32,-4,1)
Block(-6,32,-3,1)
Block(-6,32,-2,1)
Block(-6,32,4,1)
Block(-6,32,5,1)
Block(-6,32,6,1)
Block(-6,32,7,1)
Block(-6,32,8,1)
Block(-6,33,-7,1)
Block(-6,33,-6,1)
Block(-6,33,-5,1)
Block(-6,33,-4,1)
Block(-6,33,-3,1)
Block(-6,33,-2,1)
Block(-6,33,-1,1)
Block(-6,33,0,1)
Block(-6,33,1,1)
Block(-6,33,3,1)
Block(-6,33,4,1)
Block(-6,33,5,1)
Block(-6,33,6,1)
Block(-6,33,7,1)
Block(-6,33,8,1)
Block(-6,34,-7,1)
Block(-6,34,-6,1)
Block(-6,34,-5,1)
Block(-6,34,-4,1)
Block(-6,34,-3,1)
Block(-6,34,-2,1)
Block(-6,34,-1,1)
Block(-6,34,0,1)
Block(-6,34,1,1)
Block(-6,34,2,1)
Block(-6,34,3,1)
Block(-6,34,4,1)
Block(-6,34,5,1)
Block(-6,34,6,1)
Block(-6,34,7,1)
Block(-6,34,8,1)
Block(-6,35,-7,1)
Block(-6,35,-6,1)
Block(-6,35,-5,1)
Block(-6,35,-4,1)
Block(-6,35,-3,1)
Block(-6,35,-2,1)
Block(-6,35,-1,1)
Block(-6,35,0,1)
Block(-6,35,1,1)
Block(-6,35,2,1)
Block(-6,35,3,1)
Block(-6,35,4,1)
Block(-6,35,5,1)
Block(-6,35,6,1)
Block(-6,35,7,1)
Block(-6,35,8,1)
Block(-6,36,-7,1)
Block(-6,36,-6,1)
Block(-6,36,-5,1)
Block(-6,36,-4,1)
Block(-6,36,-3,1)
Block(-6,36,-2,1)
Block(-6,36,-1,1)
Block(-6,36,0,1)
Block(-6,36,1,1)
Block(-6,36,2,1)
Block(-6,36,3,1)
Block(-6,36,4,1)
Block(-6,36,5,1)
Block(-6,36,6,1)
Block(-6,36,7,1)
Block(-6,36,8,1)
Block(-6,37,-7,1)
Block(-6,37,-6,1)
Block(-6,37,-5,1)
Block(-6,37,-4,1)
Block(-6,37,-3,1)
Block(-6,37,-2,1)
Block(-6,37,-1,1)
Block(-6,37,0,1)
Block(-6,37,1,1)
Block(-6,37,2,1)
Block(-6,37,3,1)
Block(-6,37,4,1)
Block(-6,37,5,1)
Block(-6,37,6,1)
Block(-6,37,7,1)
Block(-6,37,8,1)
Block(-6,38,-7,1)
Block(-6,38,-6,1)
Block(-6,38,-5,1)
Block(-6,38,-4,1)
Block(-6,38,-3,1)
Block(-6,38,-2,1)
Block(-6,38,-1,1)
Block(-6,38,0,1)
Block(-6,38,1,1)
Block(-6,38,2,1)
Block(-6,38,3,1)
Block(-6,38,4,3)
Block(-6,38,5,3)
Block(-6,38,6,3)
Block(-6,38,7,3)
Block(-6,38,8,3)
Block(-6,39,-7,1)
Block(-6,39,-6,1)
Block(-6,39,-5,1)
Block(-6,39,-4,1)
Block(-6,39,-3,1)
Block(-6,39,-2,1)
Block(-6,39,-1,1)
Block(-6,39,0,1)
Block(-6,39,1,1)
Block(-6,39,2,3)
Block(-6,39,3,3)
Block(-6,39,4,3)
Block(-6,39,5,3)
Block(-6,39,6,3)
Block(-6,39,7,3)
Block(-6,39,8,3)
Block(-6,40,-7,3)
Block(-6,40,-6,3)
Block(-6,40,-5,3)
Block(-6,40,-4,3)
Block(-6,40,-3,3)
Block(-6,40,-2,3)
Block(-6,40,-1,3)
Block(-6,40,0,3)
Block(-6,40,1,3)
Block(-6,40,2,3)
Block(-6,40,3,3)
Block(-6,40,4,3)
Block(-6,40,5,3)
Block(-6,40,6,3)
Block(-6,40,7,3)
Block(-6,40,8,3)
Block(-6,41,-7,3)
Block(-6,41,-6,3)
Block(-6,41,-5,3)
Block(-6,41,-4,3)
Block(-6,41,-3,3)
Block(-6,41,-2,3)
Block(-6,41,-1,3)
Block(-6,41,0,3)
Block(-6,41,1,3)
Block(-6,41,2,3)
Block(-6,41,3,3)
Block(-6,41,4,2)
Block(-6,41,5,2)
Block(-6,41,6,2)
Block(-6,41,7,2)
Block(-6,41,8,2)
Block(-6,42,-7,3)
Block(-6,42,-6,3)
Block(-6,42,-5,3)
Block(-6,42,-4,3)
Block(-6,42,-3,3)
Block(-6,42,-2,3)
Block(-6,42,-1,3)
Block(-6,42,0,3)
Block(-6,42,1,3)
Block(-6,42,2,2)
Block(-6,42,3,2)
Block(-6,43,-7,2)
Block(-6,43,-6,2)
Block(-6,43,-5,2)
Block(-6,43,-4,2)
Block(-6,43,-3,2)
Block(-6,43,-2,2)
Block(-6,43,-1,2)
Block(-6,43,0,2)
Block(-6,43,1,2)
Block(-5,28,-7,1)
Block(-5,28,8,1)
Block(-5,29,-7,1)
Block(-5,29,7,1)
Block(-5,29,8,1)
Block(-5,30,-7,1)
Block(-5,30,6,1)
Block(-5,30,7,1)
Block(-5,30,8,1)
Block(-5,31,-7,1)
Block(-5,31,4,1)
Block(-5,31,5,1)
Block(-5,31,6,1)
Block(-5,31,7,1)
Block(-5,31,8,1)
Block(-5,32,-7,1)
Block(-5,32,-5,1)
Block(-5,32,-4,1)
Block(-5,32,-3,1)
Block(-5,32,4,1)
Block(-5,32,5,1)
Block(-5,32,6,1)
Block(-5,32,7,1)
Block(-5,32,8,1)
Block(-5,33,-7,1)
Block(-5,33,-6,1)
Block(-5,33,-5,1)
Block(-5,33,-4,1)
Block(-5,33,-3,1)
Block(-5,33,-1,1)
Block(-5,33,0,1)
Block(-5,33,3,1)
Block(-5,33,4,1)
Block(-5,33,5,1)
Block(-5,33,6,1)
Block(-5,33,7,1)
Block(-5,33,8,1)
Block(-5,34,-7,1)
Block(-5,34,-6,1)
Block(-5,34,-5,1)
Block(-5,34,-4,1)
Block(-5,34,-3,1)
Block(-5,34,-2,1)
Block(-5,34,-1,1)
Block(-5,34,0,1)
Block(-5,34,1,1)
Block(-5,34,2,1)
Block(-5,34,3,1)
Block(-5,34,4,1)
Block(-5,34,5,1)
Block(-5,34,6,1)
Block(-5,34,7,1)
Block(-5,34,8,1)
Block(-5,35,-7,1)
Block(-5,35,-6,1)
Block(-5,35,-5,1)
Block(-5,35,-4,1)
Block(-5,35,-3,1)
Block(-5,35,-2,1)
Block(-5,35,-1,1)
Block(-5,35,0,1)
Block(-5,35,1,1)
Block(-5,35,2,1)
Block(-5,35,3,1)
Block(-5,35,4,1)
Block(-5,35,5,1)
Block(-5,35,6,1)
Block(-5,35,7,1)
Block(-5,35,8,1)
Block(-5,36,-7,1)
Block(-5,36,-6,1)
Block(-5,36,-5,1)
Block(-5,36,-4,1)
Block(-5,36,-3,1)
Block(-5,36,-2,1)
Block(-5,36,-1,1)
Block(-5,36,0,1)
Block(-5,36,1,1)
Block(-5,36,2,1)
Block(-5,36,3,1)
Block(-5,36,4,1)
Block(-5,36,5,1)
Block(-5,36,6,1)
Block(-5,36,7,1)
Block(-5,36,8,1)
Block(-5,37,-7,1)
Block(-5,37,-6,1)
Block(-5,37,-5,1)
Block(-5,37,-4,1)
Block(-5,37,-3,1)
Block(-5,37,-2,1)
Block(-5,37,-1,1)
Block(-5,37,0,1)
Block(-5,37,1,1)
Block(-5,37,2,1)
Block(-5,37,3,1)
Block(-5,37,4,1)
Block(-5,37,5,3)
Block(-5,37,6,3)
Block(-5,37,7,1)
Block(-5,37,8,1)
Block(-5,38,-7,1)
Block(-5,38,-6,1)
Block(-5,38,-5,1)
Block(-5,38,-4,1)
Block(-5,38,-3,1)
Block(-5,38,-2,1)
Block(-5,38,-1,1)
Block(-5,38,0,1)
Block(-5,38,1,1)
Block(-5,38,2,1)
Block(-5,38,3,3)
Block(-5,38,4,3)
Block(-5,38,5,3)
Block(-5,38,6,3)
Block(-5,38,7,3)
Block(-5,38,8,3)
Block(-5,39,-7,1)
Block(-5,39,-6,1)
Block(-5,39,-5,1)
Block(-5,39,-4,1)
Block(-5,39,-3,1)
Block(-5,39,-2,1)
Block(-5,39,-1,1)
Block(-5,39,0,1)
Block(-5,39,1,3)
Block(-5,39,2,3)
Block(-5,39,3,3)
Block(-5,39,4,3)
Block(-5,39,5,3)
Block(-5,39,6,3)
Block(-5,39,7,3)
Block(-5,39,8,3)
Block(-5,40,-7,3)
Block(-5,40,-6,3)
Block(-5,40,-5,3)
Block(-5,40,-4,3)
Block(-5,40,-3,3)
Block(-5,40,-2,3)
Block(-5,40,-1,3)
Block(-5,40,0,3)
Block(-5,40,1,3)
Block(-5,40,2,3)
Block(-5,40,3,3)
Block(-5,40,4,3)
Block(-5,40,5,2)
Block(-5,40,6,2)
Block(-5,40,7,3)
Block(-5,40,8,3)
Block(-5,41,-7,3)
Block(-5,41,-6,3)
Block(-5,41,-5,3)
Block(-5,41,-4,3)
Block(-5,41,-3,3)
Block(-5,41,-2,3)
Block(-5,41,-1,3)
Block(-5,41,0,3)
Block(-5,41,1,3)
Block(-5,41,2,3)
Block(-5,41,3,2)
Block(-5,41,4,2)
Block(-5,41,7,2)
Block(-5,41,8,2)
Block(-5,42,-7,3)
Block(-5,42,-6,3)
Block(-5,42,-5,3)
Block(-5,42,-4,3)
Block(-5,42,-3,3)
Block(-5,42,-2,3)
Block(-5,42,-1,3)
Block(-5,42,0,3)
Block(-5,42,1,2)
Block(-5,42,2,2)
Block(-5,43,-7,2)
Block(-5,43,-6,2)
Block(-5,43,-5,2)
Block(-5,43,-4,2)
Block(-5,43,-3,2)
Block(-5,43,-2,2)
Block(-5,43,-1,2)
Block(-5,43,0,2)
Block(-4,25,8,1)
Block(-4,26,8,1)
Block(-4,27,8,1)
Block(-4,28,7,1)
Block(-4,28,8,1)
Block(-4,29,6,1)
Block(-4,29,7,1)
Block(-4,29,8,1)
Block(-4,30,5,1)
Block(-4,30,6,1)
Block(-4,30,7,1)
Block(-4,30,8,1)
Block(-4,31,4,1)
Block(-4,31,5,1)
Block(-4,31,6,1)
Block(-4,31,7,1)
Block(-4,31,8,1)
Block(-4,32,4,1)
Block(-4,32,5,1)
Block(-4,32,6,1)
Block(-4,32,7,1)
Block(-4,32,8,1)
Block(-4,33,-7,1)
Block(-4,33,-6,1)
Block(-4,33,-5,1)
Block(-4,33,-4,1)
Block(-4,33,-3,1)
Block(-4,33,-1,1)
Block(-4,33,0,1)
Block(-4,33,1,1)
Block(-4,33,2,1)
Block(-4,33,3,1)
Block(-4,33,4,1)
Block(-4,33,5,1)
Block(-4,33,6,1)
Block(-4,33,7,1)
Block(-4,33,8,1)
Block(-4,34,-7,1)
Block(-4,34,-6,1)
Block(-4,34,-5,1)
Block(-4,34,-4,1)
Block(-4,34,-3,1)
Block(-4,34,-2,1)
Block(-4,34,-1,1)
Block(-4,34,0,1)
Block(-4,34,1,1)
Block(-4,34,2,1)
Block(-4,34,3,1)
Block(-4,34,4,1)
Block(-4,34,5,1)
Block(-4,34,6,1)
Block(-4,34,7,1)
Block(-4,34,8,1)
Block(-4,35,-7,1)
Block(-4,35,-6,1)
Block(-4,35,-5,1)
Block(-4,35,-4,1)
Block(-4,35,-3,1)
Block(-4,35,-2,1)
Block(-4,35,-1,1)
Block(-4,35,0,1)
Block(-4,35,1,1)
Block(-4,35,2,1)
Block(-4,35,3,1)
Block(-4,35,4,1)
Block(-4,35,5,1)
Block(-4,35,6,1)
Block(-4,35,7,1)
Block(-4,35,8,1)
Block(-4,36,-7,1)
Block(-4,36,-6,1)
Block(-4,36,-5,1)
Block(-4,36,-4,1)
Block(-4,36,-3,1)
Block(-4,36,-2,1)
Block(-4,36,-1,1)
Block(-4,36,0,1)
Block(-4,36,1,1)
Block(-4,36,2,1)
Block(-4,36,3,1)
Block(-4,36,4,1)
Block(-4,36,5,1)
Block(-4,36,6,1)
Block(-4,36,7,1)
Block(-4,36,8,1)
Block(-4,37,-7,1)
Block(-4,37,-6,1)
Block(-4,37,-5,1)
Block(-4,37,-4,1)
Block(-4,37,-3,1)
Block(-4,37,-2,1)
Block(-4,37,-1,1)
Block(-4,37,0,1)
Block(-4,37,1,1)
Block(-4,37,2,1)
Block(-4,37,3,1)
Block(-4,37,4,3)
Block(-4,37,5,3)
Block(-4,37,6,3)
Block(-4,37,7,3)
Block(-4,37,8,1)
Block(-4,38,-7,1)
Block(-4,38,-6,1)
Block(-4,38,-5,1)
Block(-4,38,-4,1)
Block(-4,38,-3,1)
Block(-4,38,-2,1)
Block(-4,38,-1,1)
Block(-4,38,0,1)
Block(-4,38,1,1)
Block(-4,38,2,3)
Block(-4,38,3,3)
Block(-4,38,4,3)
Block(-4,38,5,3)
Block(-4,38,6,3)
Block(-4,38,7,3)
Block(-4,38,8,3)
Block(-4,39,-7,1)
Block(-4,39,-6,1)
Block(-4,39,-5,1)
Block(-4,39,-4,1)
Block(-4,39,-3,1)
Block(-4,39,-2,1)
Block(-4,39,-1,3)
Block(-4,39,0,3)
Block(-4,39,1,3)
Block(-4,39,2,3)
Block(-4,39,3,3)
Block(-4,39,4,3)
Block(-4,39,5,3)
Block(-4,39,6,3)
Block(-4,39,7,3)
Block(-4,39,8,3)
Block(-4,40,-7,3)
Block(-4,40,-6,3)
Block(-4,40,-5,3)
Block(-4,40,-4,3)
Block(-4,40,-3,3)
Block(-4,40,-2,3)
Block(-4,40,-1,3)
Block(-4,40,0,3)
Block(-4,40,1,3)
Block(-4,40,2,3)
Block(-4,40,3,3)
Block(-4,40,4,2)
Block(-4,40,5,2)
Block(-4,40,6,2)
Block(-4,40,7,2)
Block(-4,40,8,3)
Block(-4,41,-7,3)
Block(-4,41,-6,3)
Block(-4,41,-5,3)
Block(-4,41,-4,3)
Block(-4,41,-3,3)
Block(-4,41,-2,3)
Block(-4,41,-1,3)
Block(-4,41,0,3)
Block(-4,41,1,3)
Block(-4,41,2,2)
Block(-4,41,3,2)
Block(-4,41,8,2)
Block(-4,42,-7,3)
Block(-4,42,-6,3)
Block(-4,42,-5,3)
Block(-4,42,-4,3)
Block(-4,42,-3,3)
Block(-4,42,-2,3)
Block(-4,42,-1,2)
Block(-4,42,0,2)
Block(-4,42,1,2)
Block(-4,43,-7,2)
Block(-4,43,-6,2)
Block(-4,43,-5,2)
Block(-4,43,-4,2)
Block(-4,43,-3,2)
Block(-4,43,-2,2)
Block(-3,25,8,1)
Block(-3,26,7,1)
Block(-3,26,8,1)
Block(-3,27,7,1)
Block(-3,27,8,1)
Block(-3,28,6,1)
Block(-3,28,7,1)
Block(-3,28,8,1)
Block(-3,29,4,1)
Block(-3,29,5,1)
Block(-3,29,6,1)
Block(-3,29,7,1)
Block(-3,29,8,1)
Block(-3,30,4,1)
Block(-3,30,5,1)
Block(-3,30,6,1)
Block(-3,30,7,1)
Block(-3,30,8,1)
Block(-3,31,3,1)
Block(-3,31,4,1)
Block(-3,31,5,1)
Block(-3,31,6,1)
Block(-3,31,7,1)
Block(-3,31,8,1)
Block(-3,32,3,1)
Block(-3,32,4,1)
Block(-3,32,5,1)
Block(-3,32,6,1)
Block(-3,32,7,1)
Block(-3,32,8,1)
Block(-3,33,-7,1)
Block(-3,33,-6,1)
Block(-3,33,-5,1)
Block(-3,33,-4,1)
Block(-3,33,-3,1)
Block(-3,33,-2,1)
Block(-3,33,-1,1)
Block(-3,33,0,1)
Block(-3,33,1,1)
Block(-3,33,2,1)
Block(-3,33,3,1)
Block(-3,33,4,1)
Block(-3,33,5,1)
Block(-3,33,6,1)
Block(-3,33,7,1)
Block(-3,33,8,1)
Block(-3,34,-7,1)
Block(-3,34,-6,1)
Block(-3,34,-5,1)
Block(-3,34,-4,1)
Block(-3,34,-3,1)
Block(-3,34,-2,1)
Block(-3,34,-1,1)
Block(-3,34,0,1)
Block(-3,34,1,1)
Block(-3,34,2,1)
Block(-3,34,3,1)
Block(-3,34,4,1)
Block(-3,34,5,1)
Block(-3,34,6,1)
Block(-3,34,7,1)
Block(-3,34,8,1)
Block(-3,35,-7,1)
Block(-3,35,-6,1)
Block(-3,35,-5,1)
Block(-3,35,-4,1)
Block(-3,35,-3,1)
Block(-3,35,-2,1)
Block(-3,35,-1,1)
Block(-3,35,0,1)
Block(-3,35,1,1)
Block(-3,35,2,1)
Block(-3,35,3,1)
Block(-3,35,4,1)
Block(-3,35,5,1)
Block(-3,35,6,1)
Block(-3,35,7,1)
Block(-3,35,8,1)
Block(-3,36,-7,1)
Block(-3,36,-6,1)
Block(-3,36,-5,1)
Block(-3,36,-4,1)
Block(-3,36,-3,1)
Block(-3,36,-2,1)
Block(-3,36,-1,1)
Block(-3,36,0,1)
Block(-3,36,1,1)
Block(-3,36,2,1)
Block(-3,36,3,1)
Block(-3,36,4,1)
Block(-3,36,5,1)
Block(-3,36,6,1)
Block(-3,36,7,1)
Block(-3,36,8,1)
Block(-3,37,-7,1)
Block(-3,37,-6,1)
Block(-3,37,-5,1)
Block(-3,37,-4,1)
Block(-3,37,-3,1)
Block(-3,37,-2,1)
Block(-3,37,-1,1)
Block(-3,37,0,1)
Block(-3,37,1,1)
Block(-3,37,2,1)
Block(-3,37,3,3)
Block(-3,37,4,3)
Block(-3,37,5,3)
Block(-3,37,6,3)
Block(-3,37,7,3)
Block(-3,37,8,3)
Block(-3,38,-7,1)
Block(-3,38,-6,1)
Block(-3,38,-5,1)
Block(-3,38,-4,1)
Block(-3,38,-3,1)
Block(-3,38,-2,1)
Block(-3,38,-1,1)
Block(-3,38,0,1)
Block(-3,38,1,3)
Block(-3,38,2,3)
Block(-3,38,3,3)
Block(-3,38,4,3)
Block(-3,38,5,3)
Block(-3,38,6,3)
Block(-3,38,7,3)
Block(-3,38,8,3)
Block(-3,39,-7,1)
Block(-3,39,-6,1)
Block(-3,39,-5,1)
Block(-3,39,-4,1)
Block(-3,39,-3,1)
Block(-3,39,-2,1)
Block(-3,39,-1,3)
Block(-3,39,0,3)
Block(-3,39,1,3)
Block(-3,39,2,3)
Block(-3,39,3,3)
Block(-3,39,4,3)
Block(-3,39,5,3)
Block(-3,39,6,3)
Block(-3,39,7,3)
Block(-3,39,8,3)
Block(-3,40,-7,3)
Block(-3,40,-6,3)
Block(-3,40,-5,3)
Block(-3,40,-4,3)
Block(-3,40,-3,3)
Block(-3,40,-2,3)
Block(-3,40,-1,3)
Block(-3,40,0,3)
Block(-3,40,1,3)
Block(-3,40,2,3)
Block(-3,40,3,2)
Block(-3,40,4,2)
Block(-3,40,5,2)
Block(-3,40,6,2)
Block(-3,40,7,2)
Block(-3,40,8,2)
Block(-3,41,-7,3)
Block(-3,41,-6,3)
Block(-3,41,-5,3)
Block(-3,41,-4,3)
Block(-3,41,-3,3)
Block(-3,41,-2,3)
Block(-3,41,-1,3)
Block(-3,41,0,3)
Block(-3,41,1,2)
Block(-3,41,2,2)
Block(-3,42,-7,3)
Block(-3,42,-6,3)
Block(-3,42,-5,3)
Block(-3,42,-4,3)
Block(-3,42,-3,3)
Block(-3,42,-2,3)
Block(-3,42,-1,2)
Block(-3,42,0,2)
Block(-3,43,-7,2)
Block(-3,43,-6,2)
Block(-3,43,-5,2)
Block(-3,43,-4,2)
Block(-3,43,-3,2)
Block(-3,43,-2,2)
Block(-2,24,8,1)
Block(-2,25,7,1)
Block(-2,25,8,1)
Block(-2,26,6,1)
Block(-2,26,7,1)
Block(-2,26,8,1)
Block(-2,27,6,1)
Block(-2,27,7,1)
Block(-2,27,8,1)
Block(-2,28,5,1)
Block(-2,28,6,1)
Block(-2,28,7,1)
Block(-2,28,8,1)
Block(-2,29,5,1)
Block(-2,29,6,1)
Block(-2,29,7,1)
Block(-2,29,8,1)
Block(-2,30,3,1)
Block(-2,30,4,1)
Block(-2,30,5,1)
Block(-2,30,6,1)
Block(-2,30,7,1)
Block(-2,30,8,1)
Block(-2,31,2,1)
Block(-2,31,3,1)
Block(-2,31,4,1)
Block(-2,31,5,1)
Block(-2,31,6,1)
Block(-2,31,7,1)
Block(-2,31,8,1)
Block(-2,32,-5,1)
Block(-2,32,-4,1)
Block(-2,32,-3,1)
Block(-2,32,-2,1)
Block(-2,32,-1,1)
Block(-2,32,2,1)
Block(-2,32,3,1)
Block(-2,32,4,1)
Block(-2,32,5,1)
Block(-2,32,6,1)
Block(-2,32,7,1)
Block(-2,32,8,1)
Block(-2,33,-7,1)
Block(-2,33,-6,1)
Block(-2,33,-5,1)
Block(-2,33,-4,1)
Block(-2,33,-3,1)
Block(-2,33,-2,1)
Block(-2,33,-1,1)
Block(-2,33,0,1)
Block(-2,33,1,1)
Block(-2,33,2,1)
Block(-2,33,3,1)
Block(-2,33,4,1)
Block(-2,33,5,1)
Block(-2,33,6,1)
Block(-2,33,7,1)
Block(-2,33,8,1)
Block(-2,34,-7,1)
Block(-2,34,-6,1)
Block(-2,34,-5,1)
Block(-2,34,-4,1)
Block(-2,34,-3,1)
Block(-2,34,-2,1)
Block(-2,34,-1,1)
Block(-2,34,0,1)
Block(-2,34,1,1)
Block(-2,34,2,1)
Block(-2,34,3,1)
Block(-2,34,4,1)
Block(-2,34,5,1)
Block(-2,34,6,1)
Block(-2,34,7,1)
Block(-2,34,8,1)
Block(-2,35,-7,1)
Block(-2,35,-6,1)
Block(-2,35,-5,1)
Block(-2,35,-4,1)
Block(-2,35,-3,1)
Block(-2,35,-2,1)
Block(-2,35,-1,1)
Block(-2,35,0,1)
Block(-2,35,1,1)
Block(-2,35,2,1)
Block(-2,35,3,1)
Block(-2,35,4,1)
Block(-2,35,5,1)
Block(-2,35,6,1)
Block(-2,35,7,1)
Block(-2,35,8,1)
Block(-2,36,-7,1)
Block(-2,36,-6,1)
Block(-2,36,-5,1)
Block(-2,36,-4,1)
Block(-2,36,-3,1)
Block(-2,36,-2,1)
Block(-2,36,-1,1)
Block(-2,36,0,1)
Block(-2,36,1,1)
Block(-2,36,2,1)
Block(-2,36,3,1)
Block(-2,36,4,1)
Block(-2,36,5,1)
Block(-2,36,6,1)
Block(-2,36,7,1)
Block(-2,36,8,1)
Block(-2,37,-7,1)
Block(-2,37,-6,1)
Block(-2,37,-5,1)
Block(-2,37,-4,1)
Block(-2,37,-3,1)
Block(-2,37,-2,1)
Block(-2,37,-1,1)
Block(-2,37,0,1)
Block(-2,37,1,1)
Block(-2,37,2,3)
Block(-2,37,3,3)
Block(-2,37,4,3)
Block(-2,37,5,3)
Block(-2,37,6,3)
Block(-2,37,7,3)
Block(-2,37,8,3)
Block(-2,38,-7,1)
Block(-2,38,-6,1)
Block(-2,38,-5,1)
Block(-2,38,-4,1)
Block(-2,38,-3,1)
Block(-2,38,-2,1)
Block(-2,38,-1,1)
Block(-2,38,0,3)
Block(-2,38,1,3)
Block(-2,38,2,3)
Block(-2,38,3,3)
Block(-2,38,4,3)
Block(-2,38,5,3)
Block(-2,38,6,3)
Block(-2,38,7,3)
Block(-2,38,8,3)
Block(-2,39,-7,1)
Block(-2,39,-6,1)
Block(-2,39,-5,1)
Block(-2,39,-4,1)
Block(-2,39,-3,1)
Block(-2,39,-2,1)
Block(-2,39,-1,3)
Block(-2,39,0,3)
Block(-2,39,1,3)
Block(-2,39,2,3)
Block(-2,39,3,3)
Block(-2,39,4,3)
Block(-2,39,5,3)
Block(-2,39,6,3)
Block(-2,39,7,3)
Block(-2,39,8,3)
Block(-2,40,-7,3)
Block(-2,40,-6,3)
Block(-2,40,-5,3)
Block(-2,40,-4,3)
Block(-2,40,-3,3)
Block(-2,40,-2,3)
Block(-2,40,-1,3)
Block(-2,40,0,3)
Block(-2,40,1,3)
Block(-2,40,2,2)
Block(-2,40,3,2)
Block(-2,40,4,2)
Block(-2,40,5,2)
Block(-2,40,6,2)
Block(-2,40,7,2)
Block(-2,40,8,2)
Block(-2,41,-7,3)
Block(-2,41,-6,3)
Block(-2,41,-5,3)
Block(-2,41,-4,3)
Block(-2,41,-3,3)
Block(-2,41,-2,3)
Block(-2,41,-1,3)
Block(-2,41,0,2)
Block(-2,41,1,2)
Block(-2,42,-7,3)
Block(-2,42,-6,3)
Block(-2,42,-5,3)
Block(-2,42,-4,3)
Block(-2,42,-3,3)
Block(-2,42,-2,3)
Block(-2,42,-1,2)
Block(-2,43,-7,2)
Block(-2,43,-6,2)
Block(-2,43,-5,2)
Block(-2,43,-4,2)
Block(-2,43,-3,2)
Block(-2,43,-2,2)
Block(-1,24,8,1)
Block(-1,25,7,1)
Block(-1,25,8,1)
Block(-1,26,6,1)
Block(-1,26,7,1)
Block(-1,26,8,1)
Block(-1,27,5,1)
Block(-1,27,6,1)
Block(-1,27,7,1)
Block(-1,27,8,1)
Block(-1,28,5,1)
Block(-1,28,6,1)
Block(-1,28,7,1)
Block(-1,28,8,1)
Block(-1,29,4,1)
Block(-1,29,5,1)
Block(-1,29,6,1)
Block(-1,29,7,1)
Block(-1,29,8,1)
Block(-1,30,4,1)
Block(-1,30,5,1)
Block(-1,30,6,1)
Block(-1,30,7,1)
Block(-1,30,8,1)
Block(-1,31,2,1)
Block(-1,31,3,1)
Block(-1,31,4,1)
Block(-1,31,5,1)
Block(-1,31,6,1)
Block(-1,31,7,1)
Block(-1,31,8,1)
Block(-1,32,-5,1)
Block(-1,32,-4,1)
Block(-1,32,-3,1)
Block(-1,32,-2,1)
Block(-1,32,-1,1)
Block(-1,32,0,1)
Block(-1,32,1,1)
Block(-1,32,2,1)
Block(-1,32,3,1)
Block(-1,32,4,1)
Block(-1,32,5,1)
Block(-1,32,6,1)
Block(-1,32,7,1)
Block(-1,32,8,1)
Block(-1,33,-7,1)
Block(-1,33,-6,1)
Block(-1,33,-5,1)
Block(-1,33,-4,1)
Block(-1,33,-3,1)
Block(-1,33,-2,1)
Block(-1,33,-1,1)
Block(-1,33,0,1)
Block(-1,33,1,1)
Block(-1,33,2,1)
Block(-1,33,3,1)
Block(-1,33,4,1)
Block(-1,33,5,1)
Block(-1,33,6,1)
Block(-1,33,7,1)
Block(-1,33,8,1)
Block(-1,34,-7,1)
Block(-1,34,-6,1)
Block(-1,34,-5,1)
Block(-1,34,-4,1)
Block(-1,34,-3,1)
Block(-1,34,-2,1)
Block(-1,34,-1,1)
Block(-1,34,0,1)
Block(-1,34,1,1)
Block(-1,34,2,1)
Block(-1,34,3,1)
Block(-1,34,4,1)
Block(-1,34,5,1)
Block(-1,34,6,1)
Block(-1,34,7,1)
Block(-1,34,8,1)
Block(-1,35,-7,1)
Block(-1,35,-6,1)
Block(-1,35,-5,1)
Block(-1,35,-4,1)
Block(-1,35,-3,1)
Block(-1,35,-2,1)
Block(-1,35,-1,1)
Block(-1,35,0,1)
Block(-1,35,1,1)
Block(-1,35,2,1)
Block(-1,35,3,1)
Block(-1,35,4,1)
Block(-1,35,5,1)
Block(-1,35,6,1)
Block(-1,35,7,1)
Block(-1,35,8,1)
Block(-1,36,-7,1)
Block(-1,36,-6,1)
Block(-1,36,-5,1)
Block(-1,36,-4,1)
Block(-1,36,-3,1)
Block(-1,36,-2,1)
Block(-1,36,-1,1)
Block(-1,36,0,1)
Block(-1,36,1,1)
Block(-1,36,2,1)
Block(-1,36,3,1)
Block(-1,36,4,1)
Block(-1,36,5,1)
Block(-1,36,6,1)
Block(-1,36,7,1)
Block(-1,36,8,1)
Block(-1,37,-7,1)
Block(-1,37,-6,1)
Block(-1,37,-5,1)
Block(-1,37,-4,1)
Block(-1,37,-3,1)
Block(-1,37,-2,1)
Block(-1,37,-1,1)
Block(-1,37,0,1)
Block(-1,37,1,1)
Block(-1,37,2,3)
Block(-1,37,3,3)
Block(-1,37,4,3)
Block(-1,37,5,3)
Block(-1,37,6,3)
Block(-1,37,7,3)
Block(-1,37,8,3)
Block(-1,38,-7,1)
Block(-1,38,-6,1)
Block(-1,38,-5,1)
Block(-1,38,-4,1)
Block(-1,38,-3,1)
Block(-1,38,-2,1)
Block(-1,38,-1,1)
Block(-1,38,0,3)
Block(-1,38,1,3)
Block(-1,38,2,3)
Block(-1,38,3,3)
Block(-1,38,4,3)
Block(-1,38,5,3)
Block(-1,38,6,3)
Block(-1,38,7,3)
Block(-1,38,8,3)
Block(-1,39,-7,1)
Block(-1,39,-6,1)
Block(-1,39,-5,1)
Block(-1,39,-4,1)
Block(-1,39,-3,1)
Block(-1,39,-2,1)
Block(-1,39,-1,3)
Block(-1,39,0,3)
Block(-1,39,1,3)
Block(-1,39,2,3)
Block(-1,39,3,3)
Block(-1,39,4,3)
Block(-1,39,5,3)
Block(-1,39,6,3)
Block(-1,39,7,3)
Block(-1,39,8,3)
Block(-1,40,-7,3)
Block(-1,40,-6,3)
Block(-1,40,-5,3)
Block(-1,40,-4,3)
Block(-1,40,-3,3)
Block(-1,40,-2,3)
Block(-1,40,-1,3)
Block(-1,40,0,3)
Block(-1,40,1,3)
Block(-1,40,2,2)
Block(-1,40,3,2)
Block(-1,40,4,2)
Block(-1,40,5,2)
Block(-1,40,6,2)
Block(-1,40,7,2)
Block(-1,40,8,2)
Block(-1,41,-7,3)
Block(-1,41,-6,3)
Block(-1,41,-5,3)
Block(-1,41,-4,3)
Block(-1,41,-3,3)
Block(-1,41,-2,3)
Block(-1,41,-1,3)
Block(-1,41,0,2)
Block(-1,41,1,2)
Block(-1,42,-7,3)
Block(-1,42,-6,3)
Block(-1,42,-5,3)
Block(-1,42,-4,3)
Block(-1,42,-3,3)
Block(-1,42,-2,3)
Block(-1,42,-1,2)
Block(-1,43,-7,2)
Block(-1,43,-6,2)
Block(-1,43,-5,2)
Block(-1,43,-4,2)
Block(-1,43,-3,2)
Block(-1,43,-2,2)
Block(0,24,8,1)
Block(0,25,7,1)
Block(0,25,8,1)
Block(0,26,6,1)
Block(0,26,7,1)
Block(0,26,8,1)
Block(0,27,5,1)
Block(0,27,6,1)
Block(0,27,7,1)
Block(0,27,8,1)
Block(0,28,4,1)
Block(0,28,5,1)
Block(0,28,6,1)
Block(0,28,7,1)
Block(0,28,8,1)
Block(0,29,4,1)
Block(0,29,5,1)
Block(0,29,6,1)
Block(0,29,7,1)
Block(0,29,8,1)
Block(0,30,-7,1)
Block(0,30,3,1)
Block(0,30,4,1)
Block(0,30,5,1)
Block(0,30,6,1)
Block(0,30,7,1)
Block(0,30,8,1)
Block(0,31,-7,1)
Block(0,31,-6,1)
Block(0,31,1,1)
Block(0,31,2,1)
Block(0,31,3,1)
Block(0,31,4,1)
Block(0,31,5,1)
Block(0,31,6,1)
Block(0,31,7,1)
Block(0,31,8,1)
Block(0,32,-7,1)
Block(0,32,-6,1)
Block(0,32,-5,1)
Block(0,32,-4,1)
Block(0,32,-3,1)
Block(0,32,-2,1)
Block(0,32,-1,1)
Block(0,32,0,1)
Block(0,32,1,1)
Block(0,32,2,1)
Block(0,32,3,1)
Block(0,32,4,1)
Block(0,32,5,1)
Block(0,32,6,1)
Block(0,32,7,1)
Block(0,32,8,1)
Block(0,33,-7,1)
Block(0,33,-6,1)
Block(0,33,-5,1)
Block(0,33,-4,1)
Block(0,33,-3,1)
Block(0,33,-2,1)
Block(0,33,-1,1)
Block(0,33,0,1)
Block(0,33,1,1)
Block(0,33,2,1)
Block(0,33,3,1)
Block(0,33,4,1)
Block(0,33,5,1)
Block(0,33,6,1)
Block(0,33,7,1)
Block(0,33,8,1)
Block(0,34,-7,1)
Block(0,34,-6,1)
Block(0,34,-5,1)
Block(0,34,-4,1)
Block(0,34,-3,1)
Block(0,34,-2,1)
Block(0,34,-1,1)
Block(0,34,0,1)
Block(0,34,1,1)
Block(0,34,2,1)
Block(0,34,3,1)
Block(0,34,4,1)
Block(0,34,5,1)
Block(0,34,6,1)
Block(0,34,7,1)
Block(0,34,8,1)
Block(0,35,-7,1)
Block(0,35,-6,1)
Block(0,35,-5,1)
Block(0,35,-4,1)
Block(0,35,-3,1)
Block(0,35,-2,1)
Block(0,35,-1,1)
Block(0,35,0,1)
Block(0,35,1,1)
Block(0,35,2,1)
Block(0,35,3,1)
Block(0,35,4,1)
Block(0,35,5,1)
Block(0,35,6,1)
Block(0,35,7,1)
Block(0,35,8,1)
Block(0,36,-7,1)
Block(0,36,-6,1)
Block(0,36,-5,1)
Block(0,36,-4,1)
Block(0,36,-3,1)
Block(0,36,-2,1)
Block(0,36,-1,1)
Block(0,36,0,1)
Block(0,36,1,1)
Block(0,36,2,1)
Block(0,36,3,1)
Block(0,36,4,1)
Block(0,36,5,1)
Block(0,36,6,1)
Block(0,36,7,1)
Block(0,36,8,1)
Block(0,37,-7,1)
Block(0,37,-6,1)
Block(0,37,-5,1)
Block(0,37,-4,1)
Block(0,37,-3,1)
Block(0,37,-2,1)
Block(0,37,-1,1)
Block(0,37,0,1)
Block(0,37,1,1)
Block(0,37,2,3)
Block(0,37,3,3)
Block(0,37,4,3)
Block(0,37,5,3)
Block(0,37,6,3)
Block(0,37,7,3)
Block(0,37,8,3)
Block(0,38,-7,1)
Block(0,38,-6,1)
Block(0,38,-5,1)
Block(0,38,-4,1)
Block(0,38,-3,1)
Block(0,38,-2,1)
Block(0,38,-1,1)
Block(0,38,0,1)
Block(0,38,1,3)
Block(0,38,2,3)
Block(0,38,3,3)
Block(0,38,4,3)
Block(0,38,5,3)
Block(0,38,6,3)
Block(0,38,7,3)
Block(0,38,8,3)
Block(0,39,-7,1)
Block(0,39,-6,1)
Block(0,39,-5,1)
Block(0,39,-4,1)
Block(0,39,-3,1)
Block(0,39,-2,1)
Block(0,39,-1,3)
Block(0,39,0,3)
Block(0,39,1,3)
Block(0,39,2,3)
Block(0,39,3,3)
Block(0,39,4,3)
Block(0,39,5,3)
Block(0,39,6,3)
Block(0,39,7,3)
Block(0,39,8,3)
Block(0,40,-7,3)
Block(0,40,-6,3)
Block(0,40,-5,3)
Block(0,40,-4,3)
Block(0,40,-3,3)
Block(0,40,-2,3)
Block(0,40,-1,3)
Block(0,40,0,3)
Block(0,40,1,3)
Block(0,40,2,2)
Block(0,40,3,2)
Block(0,40,4,2)
Block(0,40,5,2)
Block(0,40,6,2)
Block(0,40,7,2)
Block(0,40,8,2)
Block(0,41,-7,3)
Block(0,41,-6,3)
Block(0,41,-5,3)
Block(0,41,-4,3)
Block(0,41,-3,3)
Block(0,41,-2,3)
Block(0,41,-1,3)
Block(0,41,0,3)
Block(0,41,1,2)
Block(0,42,-7,3)
Block(0,42,-6,3)
Block(0,42,-5,3)
Block(0,42,-4,3)
Block(0,42,-3,3)
Block(0,42,-2,3)
Block(0,42,-1,2)
Block(0,42,0,2)
Block(0,43,-7,2)
Block(0,43,-6,2)
Block(0,43,-5,2)
Block(0,43,-4,2)
Block(0,43,-3,2)
Block(0,43,-2,2)
Block(1,12,8,1)
Block(1,24,8,1)
Block(1,25,7,1)
Block(1,25,8,1)
Block(1,26,6,1)
Block(1,26,7,1)
Block(1,26,8,1)
Block(1,27,5,1)
Block(1,27,6,1)
Block(1,27,7,1)
Block(1,27,8,1)
Block(1,28,4,1)
Block(1,28,5,1)
Block(1,28,6,1)
Block(1,28,7,1)
Block(1,28,8,1)
Block(1,29,-7,1)
Block(1,29,-6,1)
Block(1,29,-5,1)
Block(1,29,-4,14)
Block(1,29,4,1)
Block(1,29,5,1)
Block(1,29,6,1)
Block(1,29,7,1)
Block(1,29,8,1)
Block(1,30,-7,1)
Block(1,30,-6,1)
Block(1,30,-5,1)
Block(1,30,-4,14)
Block(1,30,4,1)
Block(1,30,5,1)
Block(1,30,6,1)
Block(1,30,7,1)
Block(1,30,8,1)
Block(1,31,-7,1)
Block(1,31,-6,1)
Block(1,31,-5,1)
Block(1,31,-4,1)
Block(1,31,-3,1)
Block(1,31,-2,1)
Block(1,31,-1,1)
Block(1,31,1,1)
Block(1,31,2,1)
Block(1,31,3,1)
Block(1,31,4,1)
Block(1,31,5,1)
Block(1,31,6,1)
Block(1,31,7,1)
Block(1,31,8,1)
Block(1,32,-7,1)
Block(1,32,-6,1)
Block(1,32,-5,1)
Block(1,32,-4,1)
Block(1,32,-3,1)
Block(1,32,-2,1)
Block(1,32,-1,1)
Block(1,32,0,1)
Block(1,32,1,1)
Block(1,32,2,1)
Block(1,32,3,1)
Block(1,32,4,1)
Block(1,32,5,1)
Block(1,32,6,1)
Block(1,32,7,1)
Block(1,32,8,1)
Block(1,33,-7,1)
Block(1,33,-6,1)
Block(1,33,-5,1)
Block(1,33,-4,1)
Block(1,33,-3,1)
Block(1,33,-2,1)
Block(1,33,-1,1)
Block(1,33,0,1)
Block(1,33,1,1)
Block(1,33,2,1)
Block(1,33,3,1)
Block(1,33,4,1)
Block(1,33,5,1)
Block(1,33,6,1)
Block(1,33,7,1)
Block(1,33,8,1)
Block(1,34,-7,1)
Block(1,34,-6,1)
Block(1,34,-5,1)
Block(1,34,-4,1)
Block(1,34,-3,1)
Block(1,34,-2,1)
Block(1,34,-1,1)
Block(1,34,0,1)
Block(1,34,1,1)
Block(1,34,2,1)
Block(1,34,3,1)
Block(1,34,4,1)
Block(1,34,5,1)
Block(1,34,6,1)
Block(1,34,7,1)
Block(1,34,8,1)
Block(1,35,-7,1)
Block(1,35,-6,1)
Block(1,35,-5,1)
Block(1,35,-4,1)
Block(1,35,-3,1)
Block(1,35,-2,1)
Block(1,35,-1,1)
Block(1,35,0,1)
Block(1,35,1,1)
Block(1,35,2,1)
Block(1,35,3,1)
Block(1,35,4,1)
Block(1,35,5,1)
Block(1,35,6,1)
Block(1,35,7,1)
Block(1,35,8,1)
Block(1,36,-7,1)
Block(1,36,-6,1)
Block(1,36,-5,1)
Block(1,36,-4,1)
Block(1,36,-3,1)
Block(1,36,-2,1)
Block(1,36,-1,1)
Block(1,36,0,1)
Block(1,36,1,1)
Block(1,36,2,1)
Block(1,36,3,1)
Block(1,36,4,1)
Block(1,36,5,1)
Block(1,36,6,1)
Block(1,36,7,1)
Block(1,36,8,1)
Block(1,37,-7,1)
Block(1,37,-6,1)
Block(1,37,-5,1)
Block(1,37,-4,1)
Block(1,37,-3,1)
Block(1,37,-2,1)
Block(1,37,-1,1)
Block(1,37,0,1)
Block(1,37,1,1)
Block(1,37,2,1)
Block(1,37,3,3)
Block(1,37,4,3)
Block(1,37,5,3)
Block(1,37,6,3)
Block(1,37,7,3)
Block(1,37,8,3)
Block(1,38,-7,1)
Block(1,38,-6,1)
Block(1,38,-5,1)
Block(1,38,-4,1)
Block(1,38,-3,1)
Block(1,38,-2,1)
Block(1,38,-1,1)
Block(1,38,0,1)
Block(1,38,1,3)
Block(1,38,2,3)
Block(1,38,3,3)
Block(1,38,4,3)
Block(1,38,5,3)
Block(1,38,6,3)
Block(1,38,7,3)
Block(1,38,8,3)
Block(1,39,-7,3)
Block(1,39,-6,1)
Block(1,39,-5,1)
Block(1,39,-4,1)
Block(1,39,-3,1)
Block(1,39,-2,1)
Block(1,39,-1,3)
Block(1,39,0,3)
Block(1,39,1,3)
Block(1,39,2,3)
Block(1,39,3,3)
Block(1,39,4,3)
Block(1,39,5,3)
Block(1,39,6,3)
Block(1,39,7,3)
Block(1,39,8,3)
Block(1,40,-7,3)
Block(1,40,-6,3)
Block(1,40,-5,3)
Block(1,40,-4,3)
Block(1,40,-3,3)
Block(1,40,-2,3)
Block(1,40,-1,3)
Block(1,40,0,3)
Block(1,40,1,3)
Block(1,40,2,3)
Block(1,40,3,2)
Block(1,40,4,2)
Block(1,40,5,2)
Block(1,40,6,2)
Block(1,40,7,2)
Block(1,40,8,2)
Block(1,41,-7,3)
Block(1,41,-6,3)
Block(1,41,-5,3)
Block(1,41,-4,3)
Block(1,41,-3,3)
Block(1,41,-2,3)
Block(1,41,-1,3)
Block(1,41,0,3)
Block(1,41,1,2)
Block(1,41,2,2)
Block(1,42,-7,2)
Block(1,42,-6,3)
Block(1,42,-5,3)
Block(1,42,-4,3)
Block(1,42,-3,3)
Block(1,42,-2,3)
Block(1,42,-1,2)
Block(1,42,0,2)
Block(1,43,-6,2)
Block(1,43,-5,2)
Block(1,43,-4,2)
Block(1,43,-3,2)
Block(1,43,-2,2)
Block(2,0,8,1)
Block(2,1,8,1)
Block(2,2,8,1)
Block(2,3,8,1)
Block(2,4,8,1)
Block(2,5,8,1)
Block(2,6,8,1)
Block(2,7,8,1)
Block(2,8,8,1)
Block(2,9,8,1)
Block(2,10,8,1)
Block(2,11,8,1)
Block(2,12,7,1)
Block(2,12,8,1)
Block(2,13,6,1)
Block(2,13,7,1)
Block(2,13,8,1)
Block(2,14,6,1)
Block(2,14,7,1)
Block(2,14,8,1)
Block(2,15,7,1)
Block(2,15,8,1)
Block(2,16,8,1)
Block(2,17,7,1)
Block(2,17,8,1)
Block(2,23,8,1)
Block(2,24,7,1)
Block(2,24,8,1)
Block(2,25,6,1)
Block(2,25,7,1)
Block(2,25,8,1)
Block(2,26,5,1)
Block(2,26,6,1)
Block(2,26,7,1)
Block(2,26,8,1)
Block(2,27,4,1)
Block(2,27,5,1)
Block(2,27,6,1)
Block(2,27,7,1)
Block(2,27,8,1)
Block(2,28,-7,1)
Block(2,28,-6,1)
Block(2,28,-5,1)
Block(2,28,-4,1)
Block(2,28,4,1)
Block(2,28,5,1)
Block(2,28,6,1)
Block(2,28,7,1)
Block(2,28,8,1)
Block(2,29,-7,1)
Block(2,29,-6,1)
Block(2,29,-5,1)
Block(2,29,-4,1)
Block(2,29,4,1)
Block(2,29,5,1)
Block(2,29,6,1)
Block(2,29,7,1)
Block(2,29,8,1)
Block(2,30,-7,1)
Block(2,30,-6,1)
Block(2,30,-5,1)
Block(2,30,-4,1)
Block(2,30,-3,1)
Block(2,30,4,1)
Block(2,30,5,1)
Block(2,30,6,1)
Block(2,30,7,1)
Block(2,30,8,1)
Block(2,31,-7,1)
Block(2,31,-6,1)
Block(2,31,-5,1)
Block(2,31,-4,1)
Block(2,31,-3,1)
Block(2,31,3,1)
Block(2,31,4,1)
Block(2,31,5,1)
Block(2,31,6,1)
Block(2,31,7,1)
Block(2,31,8,1)
Block(2,32,-7,1)
Block(2,32,-6,1)
Block(2,32,-5,1)
Block(2,32,-4,1)
Block(2,32,-3,1)
Block(2,32,-2,1)
Block(2,32,-1,1)
Block(2,32,0,1)
Block(2,32,1,1)
Block(2,32,2,1)
Block(2,32,3,1)
Block(2,32,4,1)
Block(2,32,5,1)
Block(2,32,6,1)
Block(2,32,7,1)
Block(2,32,8,1)
Block(2,33,-7,1)
Block(2,33,-6,1)
Block(2,33,-5,1)
Block(2,33,-4,1)
Block(2,33,-3,1)
Block(2,33,-2,1)
Block(2,33,-1,1)
Block(2,33,0,1)
Block(2,33,1,1)
Block(2,33,2,1)
Block(2,33,3,1)
Block(2,33,4,1)
Block(2,33,5,1)
Block(2,33,6,1)
Block(2,33,7,1)
Block(2,33,8,1)
Block(2,34,-7,1)
Block(2,34,-6,1)
Block(2,34,-5,1)
Block(2,34,-4,1)
Block(2,34,-3,1)
Block(2,34,-2,1)
Block(2,34,-1,1)
Block(2,34,0,1)
Block(2,34,1,1)
Block(2,34,2,1)
Block(2,34,3,1)
Block(2,34,4,1)
Block(2,34,5,1)
Block(2,34,6,1)
Block(2,34,7,1)
Block(2,34,8,1)
Block(2,35,-7,1)
Block(2,35,-6,1)
Block(2,35,-5,1)
Block(2,35,-4,1)
Block(2,35,-3,1)
Block(2,35,-2,1)
Block(2,35,-1,1)
Block(2,35,0,1)
Block(2,35,1,1)
Block(2,35,2,1)
Block(2,35,3,1)
Block(2,35,4,1)
Block(2,35,5,1)
Block(2,35,6,1)
Block(2,35,7,1)
Block(2,35,8,1)
Block(2,36,-7,1)
Block(2,36,-6,1)
Block(2,36,-5,1)
Block(2,36,-4,1)
Block(2,36,-3,1)
Block(2,36,-2,1)
Block(2,36,-1,1)
Block(2,36,0,1)
Block(2,36,1,1)
Block(2,36,2,1)
Block(2,36,3,1)
Block(2,36,4,1)
Block(2,36,5,1)
Block(2,36,6,1)
Block(2,36,7,1)
Block(2,36,8,1)
Block(2,37,-7,1)
Block(2,37,-6,1)
Block(2,37,-5,1)
Block(2,37,-4,1)
Block(2,37,-3,1)
Block(2,37,-2,1)
Block(2,37,-1,1)
Block(2,37,0,1)
Block(2,37,1,1)
Block(2,37,2,1)
Block(2,37,3,3)
Block(2,37,4,3)
Block(2,37,5,3)
Block(2,37,6,3)
Block(2,37,7,3)
Block(2,37,8,3)
Block(2,38,-7,1)
Block(2,38,-6,1)
Block(2,38,-5,1)
Block(2,38,-4,1)
Block(2,38,-3,1)
Block(2,38,-2,1)
Block(2,38,-1,1)
Block(2,38,0,1)
Block(2,38,1,3)
Block(2,38,2,3)
Block(2,38,3,3)
Block(2,38,4,3)
Block(2,38,5,3)
Block(2,38,6,3)
Block(2,38,7,3)
Block(2,38,8,3)
Block(2,39,-7,3)
Block(2,39,-6,3)
Block(2,39,-5,3)
Block(2,39,-4,1)
Block(2,39,-3,1)
Block(2,39,-2,3)
Block(2,39,-1,3)
Block(2,39,0,3)
Block(2,39,1,3)
Block(2,39,2,3)
Block(2,39,3,3)
Block(2,39,4,3)
Block(2,39,5,3)
Block(2,39,6,3)
Block(2,39,7,3)
Block(2,39,8,3)
Block(2,40,-7,3)
Block(2,40,-6,3)
Block(2,40,-5,3)
Block(2,40,-4,3)
Block(2,40,-3,3)
Block(2,40,-2,3)
Block(2,40,-1,3)
Block(2,40,0,3)
Block(2,40,1,3)
Block(2,40,2,3)
Block(2,40,3,2)
Block(2,40,4,2)
Block(2,40,5,2)
Block(2,40,6,2)
Block(2,40,7,2)
Block(2,40,8,2)
Block(2,41,-7,3)
Block(2,41,-6,3)
Block(2,41,-5,3)
Block(2,41,-4,3)
Block(2,41,-3,3)
Block(2,41,-2,3)
Block(2,41,-1,3)
Block(2,41,0,3)
Block(2,41,1,2)
Block(2,41,2,2)
Block(2,42,-7,2)
Block(2,42,-6,2)
Block(2,42,-5,2)
Block(2,42,-4,3)
Block(2,42,-3,3)
Block(2,42,-2,2)
Block(2,42,-1,2)
Block(2,42,0,2)
Block(2,43,-4,2)
Block(2,43,-3,2)
Block(3,0,7,1)
Block(3,0,8,1)
Block(3,1,7,1)
Block(3,1,8,1)
Block(3,2,7,1)
Block(3,2,8,1)
Block(3,3,7,1)
Block(3,3,8,1)
Block(3,4,7,1)
Block(3,4,8,1)
Block(3,5,7,1)
Block(3,5,8,1)
Block(3,6,7,1)
Block(3,6,8,1)
Block(3,7,7,1)
Block(3,7,8,1)
Block(3,8,7,1)
Block(3,8,8,1)
Block(3,9,7,1)
Block(3,9,8,1)
Block(3,10,7,1)
Block(3,10,8,1)
Block(3,11,6,1)
Block(3,11,7,1)
Block(3,11,8,1)
Block(3,12,5,1)
Block(3,12,6,1)
Block(3,12,7,1)
Block(3,12,8,1)
Block(3,13,5,1)
Block(3,13,6,1)
Block(3,13,7,1)
Block(3,13,8,1)
Block(3,14,5,1)
Block(3,14,6,1)
Block(3,14,7,1)
Block(3,14,8,1)
Block(3,15,5,1)
Block(3,15,6,1)
Block(3,15,7,1)
Block(3,15,8,1)
Block(3,16,6,1)
Block(3,16,7,1)
Block(3,16,8,1)
Block(3,17,5,1)
Block(3,17,6,1)
Block(3,17,7,1)
Block(3,17,8,1)
Block(3,18,5,1)
Block(3,18,6,1)
Block(3,18,7,1)
Block(3,18,8,1)
Block(3,19,7,12)
Block(3,19,8,12)
Block(3,22,8,1)
Block(3,23,7,1)
Block(3,23,8,1)
Block(3,24,6,1)
Block(3,24,7,1)
Block(3,24,8,1)
Block(3,25,5,1)
Block(3,25,6,1)
Block(3,25,7,1)
Block(3,25,8,1)
Block(3,26,4,1)
Block(3,26,5,1)
Block(3,26,6,1)
Block(3,26,7,1)
Block(3,26,8,1)
Block(3,27,4,1)
Block(3,27,5,1)
Block(3,27,6,1)
Block(3,27,7,1)
Block(3,27,8,1)
Block(3,28,-7,1)
Block(3,28,-6,1)
Block(3,28,-5,1)
Block(3,28,-4,1)
Block(3,28,-3,1)
Block(3,28,4,1)
Block(3,28,5,1)
Block(3,28,6,1)
Block(3,28,7,1)
Block(3,28,8,1)
Block(3,29,-7,1)
Block(3,29,-6,1)
Block(3,29,-5,1)
Block(3,29,-4,1)
Block(3,29,-3,1)
Block(3,29,4,1)
Block(3,29,5,1)
Block(3,29,6,1)
Block(3,29,7,1)
Block(3,29,8,1)
Block(3,30,-7,1)
Block(3,30,-6,1)
Block(3,30,-5,1)
Block(3,30,-4,1)
Block(3,30,-3,1)
Block(3,30,4,1)
Block(3,30,5,1)
Block(3,30,6,1)
Block(3,30,7,1)
Block(3,30,8,1)
Block(3,31,-7,1)
Block(3,31,-6,1)
Block(3,31,-5,1)
Block(3,31,-4,1)
Block(3,31,-3,1)
Block(3,31,-2,1)
Block(3,31,3,1)
Block(3,31,4,1)
Block(3,31,5,1)
Block(3,31,6,1)
Block(3,31,7,1)
Block(3,31,8,1)
Block(3,32,-7,1)
Block(3,32,-6,1)
Block(3,32,-5,1)
Block(3,32,-4,1)
Block(3,32,-3,1)
Block(3,32,-2,1)
Block(3,32,-1,1)
Block(3,32,0,1)
Block(3,32,1,1)
Block(3,32,2,1)
Block(3,32,3,1)
Block(3,32,4,1)
Block(3,32,5,1)
Block(3,32,6,1)
Block(3,32,7,1)
Block(3,32,8,1)
Block(3,33,-7,1)
Block(3,33,-6,1)
Block(3,33,-5,1)
Block(3,33,-4,1)
Block(3,33,-3,1)
Block(3,33,-2,1)
Block(3,33,-1,1)
Block(3,33,0,1)
Block(3,33,1,1)
Block(3,33,2,1)
Block(3,33,3,1)
Block(3,33,4,1)
Block(3,33,5,1)
Block(3,33,6,1)
Block(3,33,7,1)
Block(3,33,8,1)
Block(3,34,-7,1)
Block(3,34,-6,1)
Block(3,34,-5,1)
Block(3,34,-4,1)
Block(3,34,-3,1)
Block(3,34,-2,1)
Block(3,34,-1,1)
Block(3,34,0,1)
Block(3,34,1,1)
Block(3,34,2,1)
Block(3,34,3,1)
Block(3,34,4,1)
Block(3,34,5,1)
Block(3,34,6,1)
Block(3,34,7,1)
Block(3,34,8,1)
Block(3,35,-7,1)
Block(3,35,-6,1)
Block(3,35,-5,1)
Block(3,35,-4,1)
Block(3,35,-3,1)
Block(3,35,-2,1)
Block(3,35,-1,1)
Block(3,35,0,1)
Block(3,35,1,1)
Block(3,35,2,1)
Block(3,35,3,1)
Block(3,35,4,1)
Block(3,35,5,1)
Block(3,35,6,1)
Block(3,35,7,1)
Block(3,35,8,1)
Block(3,36,-7,1)
Block(3,36,-6,1)
Block(3,36,-5,1)
Block(3,36,-4,1)
Block(3,36,-3,1)
Block(3,36,-2,1)
Block(3,36,-1,1)
Block(3,36,0,1)
Block(3,36,1,1)
Block(3,36,2,1)
Block(3,36,3,1)
Block(3,36,4,1)
Block(3,36,5,1)
Block(3,36,6,1)
Block(3,36,7,1)
Block(3,36,8,1)
Block(3,37,-7,1)
Block(3,37,-6,1)
Block(3,37,-5,1)
Block(3,37,-4,1)
Block(3,37,-3,1)
Block(3,37,-2,1)
Block(3,37,-1,1)
Block(3,37,0,1)
Block(3,37,1,1)
Block(3,37,2,3)
Block(3,37,3,3)
Block(3,37,4,3)
Block(3,37,5,3)
Block(3,37,6,3)
Block(3,37,7,3)
Block(3,37,8,3)
Block(3,38,-7,3)
Block(3,38,-6,1)
Block(3,38,-5,1)
Block(3,38,-4,1)
Block(3,38,-3,1)
Block(3,38,-2,1)
Block(3,38,-1,1)
Block(3,38,0,3)
Block(3,38,1,3)
Block(3,38,2,3)
Block(3,38,3,3)
Block(3,38,4,3)
Block(3,38,5,3)
Block(3,38,6,3)
Block(3,38,7,3)
Block(3,38,8,3)
Block(3,39,-7,3)
Block(3,39,-6,3)
Block(3,39,-5,3)
Block(3,39,-4,3)
Block(3,39,-3,3)
Block(3,39,-2,3)
Block(3,39,-1,3)
Block(3,39,0,3)
Block(3,39,1,3)
Block(3,39,2,3)
Block(3,39,3,3)
Block(3,39,4,3)
Block(3,39,5,3)
Block(3,39,6,3)
Block(3,39,7,3)
Block(3,39,8,3)
Block(3,40,-7,3)
Block(3,40,-6,3)
Block(3,40,-5,3)
Block(3,40,-4,3)
Block(3,40,-3,3)
Block(3,40,-2,3)
Block(3,40,-1,3)
Block(3,40,0,3)
Block(3,40,1,3)
Block(3,40,2,2)
Block(3,40,3,2)
Block(3,40,4,2)
Block(3,40,5,2)
Block(3,40,6,2)
Block(3,40,7,2)
Block(3,40,8,2)
Block(3,41,-7,2)
Block(3,41,-6,3)
Block(3,41,-5,3)
Block(3,41,-4,3)
Block(3,41,-3,3)
Block(3,41,-2,3)
Block(3,41,-1,3)
Block(3,41,0,2)
Block(3,41,1,2)
Block(3,42,-6,2)
Block(3,42,-5,2)
Block(3,42,-4,2)
Block(3,42,-3,2)
Block(3,42,-2,2)
Block(3,42,-1,2)
Block(4,0,5,1)
Block(4,0,6,1)
Block(4,0,7,1)
Block(4,0,8,1)
Block(4,1,5,1)
Block(4,1,6,1)
Block(4,1,7,1)
Block(4,1,8,1)
Block(4,2,5,1)
Block(4,2,6,1)
Block(4,2,7,1)
Block(4,2,8,1)
Block(4,3,5,1)
Block(4,3,6,1)
Block(4,3,7,1)
Block(4,3,8,1)
Block(4,4,5,1)
Block(4,4,6,1)
Block(4,4,7,1)
Block(4,4,8,1)
Block(4,5,5,1)
Block(4,5,6,1)
Block(4,5,7,1)
Block(4,5,8,1)
Block(4,6,5,1)
Block(4,6,6,1)
Block(4,6,7,1)
Block(4,6,8,1)
Block(4,7,5,1)
Block(4,7,6,1)
Block(4,7,7,1)
Block(4,7,8,1)
Block(4,8,5,1)
Block(4,8,6,1)
Block(4,8,7,1)
Block(4,8,8,1)
Block(4,9,5,1)
Block(4,9,6,1)
Block(4,9,7,1)
Block(4,9,8,1)
Block(4,10,5,1)
Block(4,10,6,1)
Block(4,10,7,1)
Block(4,10,8,1)
Block(4,11,5,1)
Block(4,11,6,1)
Block(4,11,7,1)
Block(4,11,8,1)
Block(4,12,4,1)
Block(4,12,5,1)
Block(4,12,6,1)
Block(4,12,7,1)
Block(4,12,8,1)
Block(4,13,4,1)
Block(4,13,5,1)
Block(4,13,6,1)
Block(4,13,7,1)
Block(4,13,8,1)
Block(4,14,4,1)
Block(4,14,5,1)
Block(4,14,6,1)
Block(4,14,7,1)
Block(4,14,8,1)
Block(4,15,4,1)
Block(4,15,5,1)
Block(4,15,6,1)
Block(4,15,7,1)
Block(4,15,8,1)
Block(4,16,4,1)
Block(4,16,5,1)
Block(4,16,6,1)
Block(4,16,7,1)
Block(4,16,8,1)
Block(4,17,3,1)
Block(4,17,4,1)
Block(4,17,5,1)
Block(4,17,6,1)
Block(4,17,7,1)
Block(4,17,8,1)
Block(4,18,3,1)
Block(4,18,4,1)
Block(4,18,5,1)
Block(4,18,6,1)
Block(4,18,7,1)
Block(4,18,8,1)
Block(4,19,3,1)
Block(4,19,4,1)
Block(4,19,5,1)
Block(4,19,6,1)
Block(4,19,7,1)
Block(4,19,8,1)
Block(4,20,4,12)
Block(4,20,5,12)
Block(4,20,6,12)
Block(4,20,7,12)
Block(4,20,8,1)
Block(4,21,8,1)
Block(4,22,7,1)
Block(4,22,8,1)
Block(4,23,6,1)
Block(4,23,7,1)
Block(4,23,8,1)
Block(4,24,5,1)
Block(4,24,6,1)
Block(4,24,7,1)
Block(4,24,8,1)
Block(4,25,4,1)
Block(4,25,5,1)
Block(4,25,6,1)
Block(4,25,7,1)
Block(4,25,8,1)
Block(4,26,3,1)
Block(4,26,4,1)
Block(4,26,5,1)
Block(4,26,6,1)
Block(4,26,7,1)
Block(4,26,8,1)
Block(4,27,4,1)
Block(4,27,5,1)
Block(4,27,6,1)
Block(4,27,7,1)
Block(4,27,8,1)
Block(4,28,-7,1)
Block(4,28,-6,1)
Block(4,28,-3,1)
Block(4,28,-2,1)
Block(4,28,4,1)
Block(4,28,5,1)
Block(4,28,6,1)
Block(4,28,7,1)
Block(4,28,8,1)
Block(4,29,-7,1)
Block(4,29,-6,1)
Block(4,29,-4,1)
Block(4,29,-3,1)
Block(4,29,-2,1)
Block(4,29,4,1)
Block(4,29,5,1)
Block(4,29,6,1)
Block(4,29,7,1)
Block(4,29,8,1)
Block(4,30,-7,1)
Block(4,30,-6,1)
Block(4,30,-5,1)
Block(4,30,-4,1)
Block(4,30,-3,1)
Block(4,30,-2,1)
Block(4,30,-1,1)
Block(4,30,3,1)
Block(4,30,4,1)
Block(4,30,5,1)
Block(4,30,6,1)
Block(4,30,7,1)
Block(4,30,8,1)
Block(4,31,-7,1)
Block(4,31,-6,1)
Block(4,31,-5,1)
Block(4,31,-4,1)
Block(4,31,-3,1)
Block(4,31,-2,1)
Block(4,31,-1,1)
Block(4,31,0,1)
Block(4,31,2,1)
Block(4,31,3,1)
Block(4,31,4,1)
Block(4,31,5,1)
Block(4,31,6,1)
Block(4,31,7,1)
Block(4,31,8,1)
Block(4,32,-7,1)
Block(4,32,-6,1)
Block(4,32,-5,1)
Block(4,32,-4,1)
Block(4,32,-3,1)
Block(4,32,-2,1)
Block(4,32,-1,1)
Block(4,32,0,1)
Block(4,32,1,1)
Block(4,32,2,1)
Block(4,32,3,1)
Block(4,32,4,1)
Block(4,32,5,1)
Block(4,32,6,1)
Block(4,32,7,1)
Block(4,32,8,1)
Block(4,33,-7,1)
Block(4,33,-6,1)
Block(4,33,-5,1)
Block(4,33,-4,1)
Block(4,33,-3,1)
Block(4,33,-2,1)
Block(4,33,-1,1)
Block(4,33,0,1)
Block(4,33,1,1)
Block(4,33,2,1)
Block(4,33,3,1)
Block(4,33,4,1)
Block(4,33,5,1)
Block(4,33,6,1)
Block(4,33,7,1)
Block(4,33,8,1)
Block(4,34,-7,1)
Block(4,34,-6,1)
Block(4,34,-5,1)
Block(4,34,-4,1)
Block(4,34,-3,1)
Block(4,34,-2,1)
Block(4,34,-1,1)
Block(4,34,0,1)
Block(4,34,1,1)
Block(4,34,2,1)
Block(4,34,3,1)
Block(4,34,4,1)
Block(4,34,5,1)
Block(4,34,6,1)
Block(4,34,7,1)
Block(4,34,8,1)
Block(4,35,-7,1)
Block(4,35,-6,1)
Block(4,35,-5,1)
Block(4,35,-4,1)
Block(4,35,-3,1)
Block(4,35,-2,1)
Block(4,35,-1,1)
Block(4,35,0,1)
Block(4,35,1,1)
Block(4,35,2,1)
Block(4,35,3,1)
Block(4,35,4,1)
Block(4,35,5,1)
Block(4,35,6,1)
Block(4,35,7,1)
Block(4,35,8,1)
Block(4,36,-7,1)
Block(4,36,-6,1)
Block(4,36,-5,1)
Block(4,36,-4,1)
Block(4,36,-3,1)
Block(4,36,-2,1)
Block(4,36,-1,1)
Block(4,36,0,1)
Block(4,36,1,1)
Block(4,36,2,1)
Block(4,36,3,1)
Block(4,36,4,1)
Block(4,36,5,1)
Block(4,36,6,1)
Block(4,36,7,1)
Block(4,36,8,1)
Block(4,37,-7,1)
Block(4,37,-6,1)
Block(4,37,-5,1)
Block(4,37,-4,1)
Block(4,37,-3,1)
Block(4,37,-2,1)
Block(4,37,-1,1)
Block(4,37,0,1)
Block(4,37,1,3)
Block(4,37,2,3)
Block(4,37,3,3)
Block(4,37,4,3)
Block(4,37,5,3)
Block(4,37,6,3)
Block(4,37,7,3)
Block(4,37,8,3)
Block(4,38,-7,3)
Block(4,38,-6,3)
Block(4,38,-5,3)
Block(4,38,-4,3)
Block(4,38,-3,3)
Block(4,38,-2,3)
Block(4,38,-1,3)
Block(4,38,0,3)
Block(4,38,1,3)
Block(4,38,2,3)
Block(4,38,3,3)
Block(4,38,4,3)
Block(4,38,5,3)
Block(4,38,6,3)
Block(4,38,7,3)
Block(4,38,8,3)
Block(4,39,-7,3)
Block(4,39,-6,3)
Block(4,39,-5,3)
Block(4,39,-4,3)
Block(4,39,-3,3)
Block(4,39,-2,3)
Block(4,39,-1,3)
Block(4,39,0,3)
Block(4,39,1,3)
Block(4,39,2,3)
Block(4,39,3,3)
Block(4,39,4,3)
Block(4,39,5,3)
Block(4,39,6,3)
Block(4,39,7,3)
Block(4,39,8,3)
Block(4,40,-7,3)
Block(4,40,-6,3)
Block(4,40,-5,3)
Block(4,40,-4,3)
Block(4,40,-3,3)
Block(4,40,-2,3)
Block(4,40,-1,3)
Block(4,40,0,3)
Block(4,40,1,2)
Block(4,40,2,2)
Block(4,40,3,2)
Block(4,40,4,2)
Block(4,40,5,2)
Block(4,40,6,2)
Block(4,40,7,2)
Block(4,40,8,2)
Block(4,41,-7,2)
Block(4,41,-6,2)
Block(4,41,-5,2)
Block(4,41,-4,2)
Block(4,41,-3,2)
Block(4,41,-2,2)
Block(4,41,-1,2)
Block(4,41,0,2)
Block(5,0,4,1)
Block(5,0,5,1)
Block(5,0,6,1)
Block(5,0,7,1)
Block(5,0,8,1)
Block(5,1,4,1)
Block(5,1,5,1)
Block(5,1,6,1)
Block(5,1,7,1)
Block(5,1,8,1)
Block(5,2,4,1)
Block(5,2,5,1)
Block(5,2,6,1)
Block(5,2,7,1)
Block(5,2,8,1)
Block(5,3,4,1)
Block(5,3,5,1)
Block(5,3,6,1)
Block(5,3,7,1)
Block(5,3,8,1)
Block(5,4,4,1)
Block(5,4,5,1)
Block(5,4,6,1)
Block(5,4,7,1)
Block(5,4,8,1)
Block(5,5,4,1)
Block(5,5,5,1)
Block(5,5,6,1)
Block(5,5,7,1)
Block(5,5,8,1)
Block(5,6,4,1)
Block(5,6,5,1)
Block(5,6,6,1)
Block(5,6,7,1)
Block(5,6,8,1)
Block(5,7,4,1)
Block(5,7,5,1)
Block(5,7,6,1)
Block(5,7,7,1)
Block(5,7,8,1)
Block(5,8,4,1)
Block(5,8,5,1)
Block(5,8,6,1)
Block(5,8,7,1)
Block(5,8,8,1)
Block(5,9,4,1)
Block(5,9,5,1)
Block(5,9,6,1)
Block(5,9,7,1)
Block(5,9,8,1)
Block(5,10,4,1)
Block(5,10,5,1)
Block(5,10,6,1)
Block(5,10,7,1)
Block(5,10,8,1)
Block(5,11,4,1)
Block(5,11,5,1)
Block(5,11,6,1)
Block(5,11,7,1)
Block(5,11,8,1)
Block(5,12,3,1)
Block(5,12,4,1)
Block(5,12,5,1)
Block(5,12,6,1)
Block(5,12,7,1)
Block(5,12,8,1)
Block(5,13,3,1)
Block(5,13,4,1)
Block(5,13,5,1)
Block(5,13,6,1)
Block(5,13,7,1)
Block(5,13,8,1)
Block(5,14,3,1)
Block(5,14,4,1)
Block(5,14,5,1)
Block(5,14,6,1)
Block(5,14,7,1)
Block(5,14,8,1)
Block(5,15,3,1)
Block(5,15,4,1)
Block(5,15,5,1)
Block(5,15,6,1)
Block(5,15,7,1)
Block(5,15,8,1)
Block(5,16,2,1)
Block(5,16,3,1)
Block(5,16,4,1)
Block(5,16,5,1)
Block(5,16,6,1)
Block(5,16,7,1)
Block(5,16,8,1)
Block(5,17,2,1)
Block(5,17,3,1)
Block(5,17,4,1)
Block(5,17,5,1)
Block(5,17,6,1)
Block(5,17,7,1)
Block(5,17,8,1)
Block(5,18,2,1)
Block(5,18,3,1)
Block(5,18,4,1)
Block(5,18,5,1)
Block(5,18,6,1)
Block(5,18,7,1)
Block(5,18,8,1)
Block(5,19,2,1)
Block(5,19,3,1)
Block(5,19,4,1)
Block(5,19,5,1)
Block(5,19,6,1)
Block(5,19,7,1)
Block(5,19,8,1)
Block(5,20,3,1)
Block(5,20,4,1)
Block(5,20,5,1)
Block(5,20,6,1)
Block(5,20,7,1)
Block(5,20,8,1)
Block(5,21,3,12)
Block(5,21,4,12)
Block(5,21,5,12)
Block(5,21,6,1)
Block(5,21,7,1)
Block(5,21,8,1)
Block(5,22,6,1)
Block(5,22,7,1)
Block(5,22,8,1)
Block(5,23,5,1)
Block(5,23,6,1)
Block(5,23,7,1)
Block(5,23,8,1)
Block(5,24,4,1)
Block(5,24,5,1)
Block(5,24,6,1)
Block(5,24,7,1)
Block(5,24,8,1)
Block(5,25,3,1)
Block(5,25,4,1)
Block(5,25,5,1)
Block(5,25,6,1)
Block(5,25,7,1)
Block(5,25,8,1)
Block(5,26,3,1)
Block(5,26,4,1)
Block(5,26,5,1)
Block(5,26,6,1)
Block(5,26,7,1)
Block(5,26,8,1)
Block(5,27,-1,1)
Block(5,27,3,1)
Block(5,27,4,1)
Block(5,27,5,1)
Block(5,27,6,1)
Block(5,27,7,1)
Block(5,27,8,1)
Block(5,28,-7,1)
Block(5,28,-6,1)
Block(5,28,-5,1)
Block(5,28,-2,1)
Block(5,28,-1,1)
Block(5,28,3,1)
Block(5,28,4,1)
Block(5,28,5,1)
Block(5,28,6,1)
Block(5,28,7,1)
Block(5,28,8,1)
Block(5,29,-7,1)
Block(5,29,-6,1)
Block(5,29,-5,1)
Block(5,29,-4,1)
Block(5,29,-3,1)
Block(5,29,-2,1)
Block(5,29,-1,1)
Block(5,29,0,1)
Block(5,29,1,1)
Block(5,29,2,1)
Block(5,29,3,1)
Block(5,29,4,1)
Block(5,29,5,1)
Block(5,29,6,1)
Block(5,29,7,1)
Block(5,29,8,1)
Block(5,30,-7,1)
Block(5,30,-6,1)
Block(5,30,-5,1)
Block(5,30,-4,1)
Block(5,30,-3,1)
Block(5,30,-2,1)
Block(5,30,-1,1)
Block(5,30,0,1)
Block(5,30,1,1)
Block(5,30,2,1)
Block(5,30,3,1)
Block(5,30,4,1)
Block(5,30,5,1)
Block(5,30,6,1)
Block(5,30,7,1)
Block(5,30,8,1)
Block(5,31,-7,1)
Block(5,31,-6,1)
Block(5,31,-5,1)
Block(5,31,-4,1)
Block(5,31,-3,1)
Block(5,31,-2,1)
Block(5,31,-1,1)
Block(5,31,0,1)
Block(5,31,1,1)
Block(5,31,2,1)
Block(5,31,3,1)
Block(5,31,4,1)
Block(5,31,5,1)
Block(5,31,6,1)
Block(5,31,7,1)
Block(5,31,8,1)
Block(5,32,-7,1)
Block(5,32,-6,1)
Block(5,32,-5,1)
Block(5,32,-4,1)
Block(5,32,-3,1)
Block(5,32,-2,1)
Block(5,32,-1,1)
Block(5,32,0,1)
Block(5,32,1,1)
Block(5,32,2,1)
Block(5,32,3,1)
Block(5,32,4,1)
Block(5,32,5,1)
Block(5,32,6,1)
Block(5,32,7,1)
Block(5,32,8,1)
Block(5,33,-7,1)
Block(5,33,-6,1)
Block(5,33,-5,1)
Block(5,33,-4,1)
Block(5,33,-3,1)
Block(5,33,-2,1)
Block(5,33,-1,1)
Block(5,33,0,1)
Block(5,33,1,1)
Block(5,33,2,1)
Block(5,33,3,1)
Block(5,33,4,1)
Block(5,33,5,1)
Block(5,33,6,1)
Block(5,33,7,1)
Block(5,33,8,1)
Block(5,34,-7,1)
Block(5,34,-6,1)
Block(5,34,-5,1)
Block(5,34,-4,1)
Block(5,34,-3,1)
Block(5,34,-2,1)
Block(5,34,-1,1)
Block(5,34,0,1)
Block(5,34,1,1)
Block(5,34,2,1)
Block(5,34,3,1)
Block(5,34,4,1)
Block(5,34,5,1)
Block(5,34,6,1)
Block(5,34,7,1)
Block(5,34,8,1)
Block(5,35,-7,1)
Block(5,35,-6,1)
Block(5,35,-5,1)
Block(5,35,-4,1)
Block(5,35,-3,1)
Block(5,35,-2,1)
Block(5,35,-1,1)
Block(5,35,0,1)
Block(5,35,1,1)
Block(5,35,2,1)
Block(5,35,3,1)
Block(5,35,4,1)
Block(5,35,5,1)
Block(5,35,6,1)
Block(5,35,7,1)
Block(5,35,8,1)
Block(5,36,-7,1)
Block(5,36,-6,1)
Block(5,36,-5,1)
Block(5,36,-4,1)
Block(5,36,-3,1)
Block(5,36,-2,1)
Block(5,36,-1,1)
Block(5,36,0,1)
Block(5,36,1,1)
Block(5,36,2,3)
Block(5,36,3,3)
Block(5,36,4,1)
Block(5,36,5,1)
Block(5,36,6,1)
Block(5,36,7,1)
Block(5,36,8,1)
Block(5,37,-7,1)
Block(5,37,-6,1)
Block(5,37,-5,1)
Block(5,37,-4,3)
Block(5,37,-3,3)
Block(5,37,-2,3)
Block(5,37,-1,3)
Block(5,37,0,3)
Block(5,37,1,3)
Block(5,37,2,3)
Block(5,37,3,3)
Block(5,37,4,3)
Block(5,37,5,3)
Block(5,37,6,3)
Block(5,37,7,3)
Block(5,37,8,3)
Block(5,38,-7,3)
Block(5,38,-6,3)
Block(5,38,-5,3)
Block(5,38,-4,3)
Block(5,38,-3,3)
Block(5,38,-2,3)
Block(5,38,-1,3)
Block(5,38,0,3)
Block(5,38,1,3)
Block(5,38,2,3)
Block(5,38,3,3)
Block(5,38,4,3)
Block(5,38,5,3)
Block(5,38,6,3)
Block(5,38,7,3)
Block(5,38,8,3)
Block(5,39,-7,3)
Block(5,39,-6,3)
Block(5,39,-5,3)
Block(5,39,-4,3)
Block(5,39,-3,3)
Block(5,39,-2,3)
Block(5,39,-1,3)
Block(5,39,0,3)
Block(5,39,1,3)
Block(5,39,2,2)
Block(5,39,3,2)
Block(5,39,4,3)
Block(5,39,5,3)
Block(5,39,6,3)
Block(5,39,7,3)
Block(5,39,8,3)
Block(5,40,-7,3)
Block(5,40,-6,3)
Block(5,40,-4,2)
Block(5,40,-3,2)
Block(5,40,-2,2)
Block(5,40,-1,2)
Block(5,40,0,2)
Block(5,40,1,2)
Block(5,40,4,2)
Block(5,40,5,2)
Block(5,40,6,2)
Block(5,40,7,2)
Block(5,40,8,2)
Block(5,41,-7,2)
Block(5,41,-6,2)
Block(5,41,-5,2)
Block(6,0,3,1)
Block(6,0,4,1)
Block(6,0,5,1)
Block(6,0,6,1)
Block(6,0,7,1)
Block(6,0,8,1)
Block(6,1,3,1)
Block(6,1,4,1)
Block(6,1,5,1)
Block(6,1,6,1)
Block(6,1,7,1)
Block(6,1,8,1)
Block(6,2,3,1)
Block(6,2,4,1)
Block(6,2,5,1)
Block(6,2,6,1)
Block(6,2,7,1)
Block(6,2,8,1)
Block(6,3,3,1)
Block(6,3,4,1)
Block(6,3,5,1)
Block(6,3,6,1)
Block(6,3,7,1)
Block(6,3,8,1)
Block(6,4,3,1)
Block(6,4,4,1)
Block(6,4,5,1)
Block(6,4,6,1)
Block(6,4,7,1)
Block(6,4,8,1)
Block(6,5,3,1)
Block(6,5,4,1)
Block(6,5,5,1)
Block(6,5,6,1)
Block(6,5,7,1)
Block(6,5,8,1)
Block(6,6,3,1)
Block(6,6,4,1)
Block(6,6,5,1)
Block(6,6,6,1)
Block(6,6,7,1)
Block(6,6,8,1)
Block(6,7,3,1)
Block(6,7,4,1)
Block(6,7,5,1)
Block(6,7,6,1)
Block(6,7,7,1)
Block(6,7,8,1)
Block(6,8,3,1)
Block(6,8,4,1)
Block(6,8,5,1)
Block(6,8,6,1)
Block(6,8,7,1)
Block(6,8,8,1)
Block(6,9,3,1)
Block(6,9,4,1)
Block(6,9,5,1)
Block(6,9,6,1)
Block(6,9,7,1)
Block(6,9,8,1)
Block(6,10,3,1)
Block(6,10,4,1)
Block(6,10,5,1)
Block(6,10,6,1)
Block(6,10,7,1)
Block(6,10,8,1)
Block(6,11,3,1)
Block(6,11,4,1)
Block(6,11,5,1)
Block(6,11,6,1)
Block(6,11,7,1)
Block(6,11,8,1)
Block(6,12,3,1)
Block(6,12,4,1)
Block(6,12,5,1)
Block(6,12,6,1)
Block(6,12,7,1)
Block(6,12,8,1)
Block(6,13,3,1)
Block(6,13,4,1)
Block(6,13,5,1)
Block(6,13,6,1)
Block(6,13,7,1)
Block(6,13,8,1)
Block(6,14,3,1)
Block(6,14,4,1)
Block(6,14,5,1)
Block(6,14,6,1)
Block(6,14,7,1)
Block(6,14,8,1)
Block(6,15,3,1)
Block(6,15,4,1)
Block(6,15,5,1)
Block(6,15,6,1)
Block(6,15,7,1)
Block(6,15,8,1)
Block(6,16,2,1)
Block(6,16,3,1)
Block(6,16,4,1)
Block(6,16,5,1)
Block(6,16,6,1)
Block(6,16,7,1)
Block(6,16,8,1)
Block(6,17,2,1)
Block(6,17,3,1)
Block(6,17,4,1)
Block(6,17,5,1)
Block(6,17,6,1)
Block(6,17,7,1)
Block(6,17,8,1)
Block(6,18,2,1)
Block(6,18,3,1)
Block(6,18,4,1)
Block(6,18,5,1)
Block(6,18,6,1)
Block(6,18,7,1)
Block(6,18,8,1)
Block(6,19,2,1)
Block(6,19,3,1)
Block(6,19,4,1)
Block(6,19,5,1)
Block(6,19,6,1)
Block(6,19,7,1)
Block(6,19,8,1)
Block(6,20,3,1)
Block(6,20,4,1)
Block(6,20,5,1)
Block(6,20,6,1)
Block(6,20,7,1)
Block(6,20,8,1)
Block(6,21,3,1)
Block(6,21,4,1)
Block(6,21,5,1)
Block(6,21,6,1)
Block(6,21,7,1)
Block(6,21,8,1)
Block(6,22,3,1)
Block(6,22,4,1)
Block(6,22,5,1)
Block(6,22,6,1)
Block(6,22,7,1)
Block(6,22,8,1)
Block(6,23,3,1)
Block(6,23,4,1)
Block(6,23,5,1)
Block(6,23,6,1)
Block(6,23,7,1)
Block(6,23,8,1)
Block(6,24,2,1)
Block(6,24,3,1)
Block(6,24,4,1)
Block(6,24,5,1)
Block(6,24,6,1)
Block(6,24,7,1)
Block(6,24,8,1)
Block(6,25,3,1)
Block(6,25,4,1)
Block(6,25,5,1)
Block(6,25,6,1)
Block(6,25,7,1)
Block(6,25,8,1)
Block(6,26,2,1)
Block(6,26,3,1)
Block(6,26,4,1)
Block(6,26,5,1)
Block(6,26,6,1)
Block(6,26,7,1)
Block(6,26,8,1)
Block(6,27,-7,1)
Block(6,27,2,1)
Block(6,27,3,1)
Block(6,27,4,1)
Block(6,27,5,1)
Block(6,27,6,1)
Block(6,27,7,1)
Block(6,27,8,1)
Block(6,28,-7,1)
Block(6,28,-6,1)
Block(6,28,-5,1)
Block(6,28,-3,1)
Block(6,28,-2,1)
Block(6,28,-1,1)
Block(6,28,0,1)
Block(6,28,1,1)
Block(6,28,2,1)
Block(6,28,3,1)
Block(6,28,4,1)
Block(6,28,5,1)
Block(6,28,6,1)
Block(6,28,7,1)
Block(6,28,8,1)
Block(6,29,-7,1)
Block(6,29,-6,1)
Block(6,29,-5,1)
Block(6,29,-4,1)
Block(6,29,-3,1)
Block(6,29,-2,1)
Block(6,29,-1,1)
Block(6,29,0,1)
Block(6,29,1,1)
Block(6,29,2,1)
Block(6,29,3,1)
Block(6,29,4,1)
Block(6,29,5,1)
Block(6,29,6,1)
Block(6,29,7,1)
Block(6,29,8,1)
Block(6,30,-7,1)
Block(6,30,-6,1)
Block(6,30,-5,1)
Block(6,30,-4,1)
Block(6,30,-3,1)
Block(6,30,-2,1)
Block(6,30,-1,1)
Block(6,30,0,1)
Block(6,30,1,1)
Block(6,30,2,1)
Block(6,30,3,1)
Block(6,30,4,1)
Block(6,30,5,1)
Block(6,30,6,1)
Block(6,30,7,1)
Block(6,30,8,1)
Block(6,31,-7,1)
Block(6,31,-6,1)
Block(6,31,-5,1)
Block(6,31,-4,1)
Block(6,31,-3,1)
Block(6,31,-2,1)
Block(6,31,-1,1)
Block(6,31,0,1)
Block(6,31,1,1)
Block(6,31,2,1)
Block(6,31,3,1)
Block(6,31,4,1)
Block(6,31,5,1)
Block(6,31,6,1)
Block(6,31,7,1)
Block(6,31,8,1)
Block(6,32,-7,1)
Block(6,32,-6,1)
Block(6,32,-5,1)
Block(6,32,-4,1)
Block(6,32,-3,1)
Block(6,32,-2,1)
Block(6,32,-1,1)
Block(6,32,0,1)
Block(6,32,1,1)
Block(6,32,2,1)
Block(6,32,3,1)
Block(6,32,4,1)
Block(6,32,5,1)
Block(6,32,6,1)
Block(6,32,7,1)
Block(6,32,8,1)
Block(6,33,-7,1)
Block(6,33,-6,1)
Block(6,33,-5,1)
Block(6,33,-4,1)
Block(6,33,-3,1)
Block(6,33,-2,1)
Block(6,33,-1,1)
Block(6,33,0,1)
Block(6,33,1,1)
Block(6,33,2,1)
Block(6,33,3,1)
Block(6,33,4,1)
Block(6,33,5,1)
Block(6,33,6,1)
Block(6,33,7,1)
Block(6,33,8,1)
Block(6,34,-7,1)
Block(6,34,-6,1)
Block(6,34,-5,1)
Block(6,34,-4,1)
Block(6,34,-3,1)
Block(6,34,-2,1)
Block(6,34,-1,1)
Block(6,34,0,1)
Block(6,34,1,1)
Block(6,34,2,1)
Block(6,34,3,1)
Block(6,34,4,1)
Block(6,34,5,1)
Block(6,34,6,1)
Block(6,34,7,1)
Block(6,34,8,1)
Block(6,35,-7,1)
Block(6,35,-6,1)
Block(6,35,-5,1)
Block(6,35,-4,1)
Block(6,35,-3,1)
Block(6,35,-2,1)
Block(6,35,-1,1)
Block(6,35,0,1)
Block(6,35,1,1)
Block(6,35,2,1)
Block(6,35,3,1)
Block(6,35,4,1)
Block(6,35,5,1)
Block(6,35,6,1)
Block(6,35,7,1)
Block(6,35,8,1)
Block(6,36,-7,1)
Block(6,36,-6,1)
Block(6,36,-5,1)
Block(6,36,-4,1)
Block(6,36,-3,3)
Block(6,36,-2,3)
Block(6,36,-1,3)
Block(6,36,0,3)
Block(6,36,1,3)
Block(6,36,2,3)
Block(6,36,3,3)
Block(6,36,4,3)
Block(6,36,5,3)
Block(6,36,6,1)
Block(6,36,7,1)
Block(6,36,8,1)
Block(6,37,-7,1)
Block(6,37,-6,1)
Block(6,37,-5,1)
Block(6,37,-4,3)
Block(6,37,-3,3)
Block(6,37,-2,3)
Block(6,37,-1,3)
Block(6,37,0,3)
Block(6,37,1,3)
Block(6,37,2,3)
Block(6,37,3,3)
Block(6,37,4,3)
Block(6,37,5,3)
Block(6,37,6,3)
Block(6,37,7,3)
Block(6,37,8,3)
Block(6,38,-7,3)
Block(6,38,-6,3)
Block(6,38,-5,3)
Block(6,38,-4,3)
Block(6,38,-3,3)
Block(6,38,-2,3)
Block(6,38,-1,3)
Block(6,38,0,3)
Block(6,38,1,3)
Block(6,38,2,3)
Block(6,38,3,3)
Block(6,38,4,3)
Block(6,38,5,3)
Block(6,38,6,3)
Block(6,38,7,3)
Block(6,38,8,3)
Block(6,39,-7,3)
Block(6,39,-6,3)
Block(6,39,-5,3)
Block(6,39,-4,3)
Block(6,39,-3,2)
Block(6,39,-2,2)
Block(6,39,-1,2)
Block(6,39,0,2)
Block(6,39,1,2)
Block(6,39,2,2)
Block(6,39,3,2)
Block(6,39,4,2)
Block(6,39,5,2)
Block(6,39,6,3)
Block(6,39,7,3)
Block(6,39,8,3)
Block(6,40,-7,3)
Block(6,40,-6,3)
Block(6,40,-5,3)
Block(6,40,-4,2)
Block(6,40,6,2)
Block(6,40,7,2)
Block(6,40,8,2)
Block(6,41,-7,2)
Block(6,41,-6,2)
Block(6,41,-5,2)
Block(7,0,3,1)
Block(7,0,4,1)
Block(7,0,5,1)
Block(7,0,6,1)
Block(7,0,7,1)
Block(7,0,8,1)
Block(7,1,3,1)
Block(7,1,4,1)
Block(7,1,5,1)
Block(7,1,6,1)
Block(7,1,7,1)
Block(7,1,8,1)
Block(7,2,3,1)
Block(7,2,4,1)
Block(7,2,5,1)
Block(7,2,6,1)
Block(7,2,7,1)
Block(7,2,8,1)
Block(7,3,3,1)
Block(7,3,4,1)
Block(7,3,5,1)
Block(7,3,6,1)
Block(7,3,7,1)
Block(7,3,8,1)
Block(7,4,3,1)
Block(7,4,4,1)
Block(7,4,5,1)
Block(7,4,6,1)
Block(7,4,7,1)
Block(7,4,8,1)
Block(7,5,3,1)
Block(7,5,4,1)
Block(7,5,5,1)
Block(7,5,6,1)
Block(7,5,7,1)
Block(7,5,8,1)
Block(7,6,3,1)
Block(7,6,4,1)
Block(7,6,5,1)
Block(7,6,6,1)
Block(7,6,7,1)
Block(7,6,8,1)
Block(7,7,3,1)
Block(7,7,4,1)
Block(7,7,5,1)
Block(7,7,6,1)
Block(7,7,7,1)
Block(7,7,8,1)
Block(7,8,3,1)
Block(7,8,4,1)
Block(7,8,5,1)
Block(7,8,6,1)
Block(7,8,7,1)
Block(7,8,8,1)
Block(7,9,3,1)
Block(7,9,4,1)
Block(7,9,5,1)
Block(7,9,6,1)
Block(7,9,7,1)
Block(7,9,8,1)
Block(7,10,3,1)
Block(7,10,4,1)
Block(7,10,5,1)
Block(7,10,6,1)
Block(7,10,7,1)
Block(7,10,8,1)
Block(7,11,3,1)
Block(7,11,4,1)
Block(7,11,5,1)
Block(7,11,6,1)
Block(7,11,7,1)
Block(7,11,8,1)
Block(7,12,3,1)
Block(7,12,4,1)
Block(7,12,5,1)
Block(7,12,6,1)
Block(7,12,7,1)
Block(7,12,8,1)
Block(7,13,2,1)
Block(7,13,3,1)
Block(7,13,4,1)
Block(7,13,5,1)
Block(7,13,6,1)
Block(7,13,7,1)
Block(7,13,8,1)
Block(7,14,2,1)
Block(7,14,3,1)
Block(7,14,4,1)
Block(7,14,5,1)
Block(7,14,6,1)
Block(7,14,7,1)
Block(7,14,8,1)
Block(7,15,2,1)
Block(7,15,3,1)
Block(7,15,4,1)
Block(7,15,5,1)
Block(7,15,6,1)
Block(7,15,7,1)
Block(7,15,8,1)
Block(7,16,2,1)
Block(7,16,3,1)
Block(7,16,4,1)
Block(7,16,5,1)
Block(7,16,6,1)
Block(7,16,7,1)
Block(7,16,8,1)
Block(7,17,2,1)
Block(7,17,3,1)
Block(7,17,4,1)
Block(7,17,5,1)
Block(7,17,6,1)
Block(7,17,7,1)
Block(7,17,8,1)
Block(7,18,2,1)
Block(7,18,3,1)
Block(7,18,4,1)
Block(7,18,5,1)
Block(7,18,6,1)
Block(7,18,7,1)
Block(7,18,8,1)
Block(7,19,3,1)
Block(7,19,4,1)
Block(7,19,5,1)
Block(7,19,6,1)
Block(7,19,7,1)
Block(7,19,8,1)
Block(7,20,2,1)
Block(7,20,3,1)
Block(7,20,4,1)
Block(7,20,5,1)
Block(7,20,6,1)
Block(7,20,7,1)
Block(7,20,8,1)
Block(7,21,3,1)
Block(7,21,4,1)
Block(7,21,5,1)
Block(7,21,6,1)
Block(7,21,7,1)
Block(7,21,8,1)
Block(7,22,3,1)
Block(7,22,4,1)
Block(7,22,5,1)
Block(7,22,6,1)
Block(7,22,7,1)
Block(7,22,8,1)
Block(7,23,3,1)
Block(7,23,4,1)
Block(7,23,5,1)
Block(7,23,6,1)
Block(7,23,7,1)
Block(7,23,8,1)
Block(7,24,3,1)
Block(7,24,4,1)
Block(7,24,5,1)
Block(7,24,6,1)
Block(7,24,7,1)
Block(7,24,8,1)
Block(7,25,2,1)
Block(7,25,3,1)
Block(7,25,4,1)
Block(7,25,5,1)
Block(7,25,6,1)
Block(7,25,7,1)
Block(7,25,8,1)
Block(7,26,1,1)
Block(7,26,2,1)
Block(7,26,3,1)
Block(7,26,4,1)
Block(7,26,5,1)
Block(7,26,6,1)
Block(7,26,7,1)
Block(7,26,8,1)
Block(7,27,-7,1)
Block(7,27,-6,1)
Block(7,27,-1,1)
Block(7,27,0,1)
Block(7,27,1,1)
Block(7,27,2,1)
Block(7,27,3,1)
Block(7,27,4,1)
Block(7,27,5,1)
Block(7,27,6,1)
Block(7,27,7,1)
Block(7,27,8,1)
Block(7,28,-7,1)
Block(7,28,-6,1)
Block(7,28,-5,1)
Block(7,28,-4,1)
Block(7,28,-2,1)
Block(7,28,-1,1)
Block(7,28,0,1)
Block(7,28,1,1)
Block(7,28,2,1)
Block(7,28,3,1)
Block(7,28,4,1)
Block(7,28,5,1)
Block(7,28,6,1)
Block(7,28,7,1)
Block(7,28,8,1)
Block(7,29,-7,1)
Block(7,29,-6,1)
Block(7,29,-5,1)
Block(7,29,-4,1)
Block(7,29,-3,1)
Block(7,29,-2,1)
Block(7,29,-1,1)
Block(7,29,0,1)
Block(7,29,1,1)
Block(7,29,2,1)
Block(7,29,3,1)
Block(7,29,4,1)
Block(7,29,5,1)
Block(7,29,6,1)
Block(7,29,7,1)
Block(7,29,8,1)
Block(7,30,-7,1)
Block(7,30,-6,1)
Block(7,30,-5,1)
Block(7,30,-4,1)
Block(7,30,-3,1)
Block(7,30,-2,1)
Block(7,30,-1,1)
Block(7,30,0,1)
Block(7,30,1,1)
Block(7,30,2,1)
Block(7,30,3,1)
Block(7,30,4,1)
Block(7,30,5,1)
Block(7,30,6,1)
Block(7,30,7,1)
Block(7,30,8,1)
Block(7,31,-7,1)
Block(7,31,-6,1)
Block(7,31,-5,1)
Block(7,31,-4,1)
Block(7,31,-3,1)
Block(7,31,-2,1)
Block(7,31,-1,1)
Block(7,31,0,1)
Block(7,31,1,1)
Block(7,31,2,1)
Block(7,31,3,1)
Block(7,31,4,1)
Block(7,31,5,1)
Block(7,31,6,1)
Block(7,31,7,1)
Block(7,31,8,1)
Block(7,32,-7,1)
Block(7,32,-6,1)
Block(7,32,-5,1)
Block(7,32,-4,1)
Block(7,32,-3,1)
Block(7,32,-2,1)
Block(7,32,-1,1)
Block(7,32,0,1)
Block(7,32,1,1)
Block(7,32,2,1)
Block(7,32,3,1)
Block(7,32,4,1)
Block(7,32,5,1)
Block(7,32,6,1)
Block(7,32,7,1)
Block(7,32,8,1)
Block(7,33,-7,1)
Block(7,33,-6,1)
Block(7,33,-5,1)
Block(7,33,-4,1)
Block(7,33,-3,1)
Block(7,33,-2,1)
Block(7,33,-1,1)
Block(7,33,0,1)
Block(7,33,1,1)
Block(7,33,2,1)
Block(7,33,3,1)
Block(7,33,4,1)
Block(7,33,5,1)
Block(7,33,6,1)
Block(7,33,7,1)
Block(7,33,8,1)
Block(7,34,-7,1)
Block(7,34,-6,1)
Block(7,34,-5,1)
Block(7,34,-4,1)
Block(7,34,-3,1)
Block(7,34,-2,1)
Block(7,34,-1,1)
Block(7,34,0,1)
Block(7,34,1,1)
Block(7,34,2,1)
Block(7,34,3,1)
Block(7,34,4,1)
Block(7,34,5,1)
Block(7,34,6,1)
Block(7,34,7,1)
Block(7,34,8,1)
Block(7,35,-7,1)
Block(7,35,-6,1)
Block(7,35,-5,1)
Block(7,35,-4,1)
Block(7,35,-3,1)
Block(7,35,-2,3)
Block(7,35,-1,3)
Block(7,35,0,3)
Block(7,35,1,3)
Block(7,35,2,3)
Block(7,35,3,3)
Block(7,35,4,3)
Block(7,35,5,1)
Block(7,35,6,1)
Block(7,35,7,1)
Block(7,35,8,1)
Block(7,36,-7,1)
Block(7,36,-6,1)
Block(7,36,-5,1)
Block(7,36,-4,3)
Block(7,36,-3,3)
Block(7,36,-2,3)
Block(7,36,-1,3)
Block(7,36,0,3)
Block(7,36,1,3)
Block(7,36,2,3)
Block(7,36,3,3)
Block(7,36,4,3)
Block(7,36,5,3)
Block(7,36,6,3)
Block(7,36,7,3)
Block(7,36,8,3)
Block(7,37,-7,1)
Block(7,37,-6,1)
Block(7,37,-5,3)
Block(7,37,-4,3)
Block(7,37,-3,3)
Block(7,37,-2,3)
Block(7,37,-1,3)
Block(7,37,0,3)
Block(7,37,1,3)
Block(7,37,2,3)
Block(7,37,3,3)
Block(7,37,4,3)
Block(7,37,5,3)
Block(7,37,6,3)
Block(7,37,7,3)
Block(7,37,8,3)
Block(7,38,-7,3)
Block(7,38,-6,3)
Block(7,38,-5,3)
Block(7,38,-4,3)
Block(7,38,-3,3)
Block(7,38,-2,2)
Block(7,38,-1,2)
Block(7,38,0,2)
Block(7,38,1,2)
Block(7,38,2,2)
Block(7,38,3,2)
Block(7,38,4,2)
Block(7,38,5,3)
Block(7,38,6,3)
Block(7,38,7,3)
Block(7,38,8,3)
Block(7,39,-7,3)
Block(7,39,-6,3)
Block(7,39,-5,3)
Block(7,39,-4,2)
Block(7,39,-3,2)
Block(7,39,5,2)
Block(7,39,6,2)
Block(7,39,7,2)
Block(7,39,8,2)
Block(7,40,-7,3)
Block(7,40,-6,3)
Block(7,40,-5,2)
Block(7,41,-7,2)
Block(7,41,-6,2)

# 

#######################################################################
# +-----------------------------------------------------------------+ #
# |                            BO3 checks                           | #
# +-----------------------------------------------------------------+ #
#######################################################################

# Require a condition at a certain location in order for the BO3 to be spawned.
# BlockCheck(x,y,z,BlockName[,BlockName[,...]]) - one of the blocks must be at the location
# BlockCheckNot(x,y,z,BlockName[,BlockName[,...]]) - all the blocks must not be at the location
# LightCheck(x,y,z,minLightLevel,maxLightLevel) - light must be between min and max (inclusive)

# You can use "Solid" as a BlockName for matching all solid blocks or "All" to match all blocks that aren't air.

# Examples:
#   BlockCheck(0,-1,0,GRASS,DIRT)  Require grass or dirt just below the object
#   BlockCheck(0,-1,0,Solid)       Require any solid block just below the object
#   BlockCheck(0,-1,0,WOOL)        Require any type of wool just below the object
#   BlockCheck(0,-1,0,WOOL:0)      Require white wool just below the object
#   BlockCheckNot(0,0,0,WOOL:0)   Require that there is no white wool below the object
#   LightCheck(0,0,0,0,1)          Require almost complete darkness just below the object

#######################################################################
# +-----------------------------------------------------------------+ #
# |                             Branches                            | #
# +-----------------------------------------------------------------+ #
#######################################################################

# Branches are objects that will spawn when this object spawns when it is used in
# the CustomStructure resource. Branches can also have branches, making complex
# structures possible. See the wiki for more details.

# Regular Branches spawn each branch with an independent chance of spawning.
# Branch(x,y,z,branchName,rotation,chance[,anotherBranchName,rotation,chance[,...]][IndividualChance])
# branchName - name of the object to spawn.
# rotation - NORTH, SOUTH, EAST or WEST.
# IndividualChance - The chance each branch has to spawn, assumed to be 100 when left blank

# WeightedBranch(x,y,z,branchName,rotation,chance[,anotherBranchName,rotation,chance[,...]][MaxChanceOutOf])
# MaxChanceOutOf - The chance all branches have to spawn out of, assumed to be 100 when left blank
Branch(16,0,0,GiantCave1C4R2,NORTH,100)
