
#######################################################################
# +-----------------------------------------------------------------+ #
# |                            BO3 object                           | #
# +-----------------------------------------------------------------+ #
#######################################################################

Author: LordSmellyPants

Description: No description given

Version: 3

SettingsMode: WriteWithoutComments


#######################################################################
# +-----------------------------------------------------------------+ #
# |                          Main settings                          | #
# +-----------------------------------------------------------------+ #
#######################################################################

Tree: false

Frequency: 1

Rarity: 30.0

RotateRandomly: true

SpawnHeight: randomY

SpawnHeightOffset: 0

SpawnHeightVariance: 0

##############################
# Height Limits for the BO3. #
##############################

MinHeight: 60

MaxHeight: 150

######################
# Extrusion settings #
######################

ExtrudeMode: None

ExtrudeThroughBlocks: AIR

MaxBranchDepth: 10

ExcludedBiomes: All


#######################################################################
# +-----------------------------------------------------------------+ #
# |                      Source block settings                      | #
# +-----------------------------------------------------------------+ #
#######################################################################

SourceBlocks: STONE:1,STONE:3,STONE:5,DIRT:1,STONE,DIRT

MaxPercentageOutsideSourceBlock: 30

OutsideSourceBlock: placeAnyway


#######################################################################
# +-----------------------------------------------------------------+ #
# |                              Blocks                             | #
# +-----------------------------------------------------------------+ #
#######################################################################

Block(-3,0,2,STONE)
Block(-3,1,2,STONE)
Block(-2,-2,1,STONE)
Block(-2,-1,1,STONE)
Block(-2,0,1,STONE)
Block(-2,0,2,STONE)
Block(-2,1,1,STONE)
Block(-2,1,2,STONE)
Block(-2,1,3,STONE)
Block(-2,2,2,STONE)
Block(-2,3,2,STONE)
Block(-1,-4,1,STONE)
Block(-1,-3,1,STONE)
Block(-1,-2,0,STONE)
Block(-1,-2,1,STONE)
Block(-1,-2,2,STONE)
Block(-1,-1,0,STONE)
Block(-1,-1,1,STONE)
Block(-1,-1,2,STONE)
Block(-1,0,-1,STONE)
Block(-1,0,0,STONE)
Block(-1,0,1,STONE)
Block(-1,0,2,STONE)
Block(-1,0,3,STONE)
Block(-1,1,0,STONE)
Block(-1,1,1,STONE)
Block(-1,1,2,STONE)
Block(-1,1,3,STONE)
Block(-1,1,4,STONE)
Block(-1,2,1,STONE)
Block(-1,2,2,STONE)
Block(-1,2,3,STONE)
Block(-1,3,2,STONE)
Block(-1,4,2,STONE)
Block(0,-12,1,STONE)
Block(0,-11,1,STONE)
Block(0,-10,1,STONE)
Block(0,-9,1,STONE)
Block(0,-8,1,STONE)
Block(0,-7,1,STONE)
Block(0,-6,1,STONE)
Block(0,-5,1,STONE)
Block(0,-5,2,STONE)
Block(0,-4,0,STONE)
Block(0,-4,1,STONE)
Block(0,-4,2,STONE)
Block(0,-3,0,STONE)
Block(0,-3,1,STONE)
Block(0,-3,2,STONE)
Block(0,-3,3,STONE)
Block(0,-2,-1,STONE)
Block(0,-2,0,STONE)
Block(0,-2,1,STONE)
Block(0,-2,2,STONE)
Block(0,-2,3,STONE)
Block(0,-1,-1,STONE)
Block(0,-1,0,STONE)
Block(0,-1,1,STONE)
Block(0,-1,2,STONE)
Block(0,-1,3,STONE)
Block(0,0,-1,STONE)
Block(0,0,0,STONE)
Block(0,0,1,STONE)
Block(0,0,2,STONE)
Block(0,0,3,STONE)
Block(0,1,-1,STONE)
Block(0,1,0,STONE)
Block(0,1,1,STONE)
Block(0,1,2,STONE)
Block(0,1,3,STONE)
Block(0,1,4,STONE)
Block(0,2,0,STONE)
Block(0,2,1,STONE)
Block(0,2,2,STONE)
Block(0,2,3,STONE)
Block(0,3,0,STONE)
Block(0,3,1,STONE)
Block(0,3,2,STONE)
Block(0,3,3,STONE)
Block(0,4,1,STONE)
Block(0,4,2,STONE)
Block(0,5,1,STONE)
Block(1,-5,1,STONE)
Block(1,-4,1,STONE)
Block(1,-4,2,STONE)
Block(1,-3,0,STONE)
Block(1,-3,1,STONE)
Block(1,-2,0,STONE)
Block(1,-2,1,STONE)
Block(1,-2,2,STONE)
Block(1,-1,-1,STONE)
Block(1,-1,0,STONE)
Block(1,-1,1,STONE)
Block(1,-1,2,STONE)
Block(1,-1,3,STONE)
Block(1,0,-1,STONE)
Block(1,0,0,STONE)
Block(1,0,1,STONE)
Block(1,0,2,STONE)
Block(1,0,3,STONE)
Block(1,1,-1,STONE)
Block(1,1,0,STONE)
Block(1,1,1,STONE)
Block(1,1,2,STONE)
Block(1,1,3,STONE)
Block(1,2,0,STONE)
Block(1,2,1,STONE)
Block(1,2,2,STONE)
Block(1,3,1,STONE)
Block(2,-3,1,STONE)
Block(2,-2,1,STONE)
Block(2,-1,1,STONE)
Block(2,-1,2,STONE)
Block(2,0,-1,STONE)
Block(2,0,0,STONE)
Block(2,0,1,STONE)
Block(2,0,2,STONE)
Block(2,1,1,STONE)
Block(2,1,2,STONE)
Block(2,2,1,STONE)
Block(3,0,1,STONE)
Block(3,1,1,STONE)

#######################################################################
# +-----------------------------------------------------------------+ #
# |                            BO3 checks                           | #
# +-----------------------------------------------------------------+ #
#######################################################################


#######################################################################
# +-----------------------------------------------------------------+ #
# |                             Branches                            | #
# +-----------------------------------------------------------------+ #
#######################################################################


#######################################################################
# +-----------------------------------------------------------------+ #
# |                         EntityFunctions                         | #
# +-----------------------------------------------------------------+ #
#######################################################################

