#######################################################################
# +-----------------------------------------------------------------+ #
# |                            BO3 object                           | #
# +-----------------------------------------------------------------+ #
#######################################################################

# The descriptions in this file are true only for TerrainControl. They are not true for the Minecraft Worlds mod!
# Minecraft Worlds completely reimplemented BO3s, check the MCW documentation on the mc/mctcp forums for how to use BO3s with MCW
# or watch the video's on my YT channel at https://www.youtube.com/user/PeeGee85. You can check out the "Editing and importing schematics & BO3s" 
# series of video's, in part 2 I explain BO3s. 

# This is the config file of a custom object.
# If you add this object correctly to your BiomeConfigs, it will spawn in the world.

# This is the creator of this BO3 object
Author: Unknown

# A short description of this BO3 object
Description: This BO3 was converted from a schematic using the MineCraft Worlds Editor. Unfortunately the author and description information for the schematic could not be found. If you know who the author of the schematic is then please tell the author of this BO3!

# The BO3 version, don't change this! It can be used by external applications to do a version check.
Version: 3

# The settings mode, WriteAll, WriteWithoutComments or WriteDisable. See WorldConfig.
SettingsMode: WriteDisable

#######################################################################
# +-----------------------------------------------------------------+ #
# |                          Main settings                          | #
# +-----------------------------------------------------------------+ #
#######################################################################

# This needs to be set to true to spawn the object in the Tree and Sapling resources.
Tree: false

# The frequency of the BO3 from 1 to 200. Tries this many times to spawn this BO3 when using the CustomObject(...) resource.
# Ignored by Tree(..), Sapling(..) and CustomStructure(..)
Frequency: 1

# The rarity of the BO3 from 0 to 100. Each spawn attempt has rarity% chance to succeed when using the CustomObject(...) resource.
# Ignored by Tree(..), Sapling(..) and CustomStructure(..)
Rarity: 100.0

# If you set this to true, the BO3 will be placed with a random rotation.
RotateRandomly: false

# The spawn height of the BO3 - randomY, highestBlock or highestSolidBlock.
SpawnHeight: randomY

# The height limits for the BO3.
MinHeight: 61

MaxHeight: 63

# Objects can have other objects attached to it: branches. Branches can also
# have branches attached to it, which can also have branches, etc. This is the
# maximum branch depth for this objects.
MaxBranchDepth: 10

# When spawned with the UseWorld keyword, this BO3 should NOT spawn in the following biomes.
# If you writer.write the BO3 name directly in the BiomeConfigs, this will be ignored.
ExcludedBiomes: All

#######################################################################
# +-----------------------------------------------------------------+ #
# |                      Source block settings                      | #
# +-----------------------------------------------------------------+ #
#######################################################################

# The block(s) the BO3 should spawn in.
SourceBlocks: AIR

# The maximum percentage of the BO3 that can be outside the SourceBlock.
# The BO3 won't be placed on a location with more blocks outside the SourceBlock than this percentage.
MaxPercentageOutsideSourceBlock: 100

# What to do when a block is about to be placed outside the SourceBlock? (dontPlace, placeAnyway)
OutsideSourceBlock: placeAnyway

#######################################################################
# +-----------------------------------------------------------------+ #
# |                              Blocks                             | #
# +-----------------------------------------------------------------+ #
#######################################################################

# All the blocks used in the BO3 are listed here. Possible blocks:
# Block(x,y,z,id[.data][,nbtfile.nbt)
# RandomBlock(x,y,z,id[:data][,nbtfile.nbt],chance[,id[:data][,nbtfile.nbt],chance[,...]])
# So RandomBlock(0,0,0,CHEST,chest.nbt,50,CHEST,anotherchest.nbt,100) will spawn a chest at
# the BO3 origin, and give it a 50% chance to have the contents of chest.nbt, or, if that
# fails, a 100% percent chance to have the contents of anotherchest.nbt.

Block(-8,-3,-5,80)
Block(-8,-3,-4,80)
Block(-8,-3,-3,80)
Block(-8,-3,-2,80)
Block(-8,-3,-1,80)
Block(-8,-3,1,80)
Block(-8,-3,3,80)
Block(-8,-3,4,80)
Block(-8,-3,5,80)
Block(-8,-3,6,3)
Block(-8,-3,7,80)
Block(-8,-3,8,80)
Block(-8,-2,-5,80)
Block(-8,-2,-4,80)
Block(-8,-2,-3,80)
Block(-8,-2,-2,80)
Block(-8,-2,-1,80)
Block(-8,-2,0,3)
Block(-8,-2,1,13)
Block(-8,-2,2,3)
Block(-8,-2,3,80)
Block(-8,-2,4,80)
Block(-8,-2,5,80)
Block(-8,-2,6,1)
Block(-8,-2,7,1)
Block(-8,-2,8,80)
Block(-8,-1,-5,80)
Block(-8,-1,-4,80)
Block(-8,-1,-3,80)
Block(-8,-1,-2,80)
Block(-8,-1,-1,80)
Block(-8,-1,0,1)
Block(-8,-1,1,13)
Block(-8,-1,2,1)
Block(-8,-1,3,80)
Block(-8,-1,4,80)
Block(-8,-1,5,13)
Block(-8,-1,6,80)
Block(-8,-1,7,80)
Block(-8,-1,8,80)
Block(-8,0,-5,80)
Block(-8,0,-4,80)
Block(-8,0,-3,80)
Block(-8,0,-2,1)
Block(-8,0,-1,80)
Block(-8,0,0,80)
Block(-8,0,1,1)
Block(-8,0,2,13)
Block(-8,0,3,13)
Block(-8,0,4,1)
Block(-8,0,5,1)
Block(-8,0,6,80)
Block(-8,0,7,13)
Block(-8,0,8,1)
Block(-8,1,-5,80)
Block(-8,1,-4,78:1)
Block(-8,1,-3,AIR)
Block(-8,1,-2,AIR)
Block(-8,1,-1,AIR)
Block(-8,1,0,AIR)
Block(-8,1,1,AIR)
Block(-8,1,2,AIR)
Block(-8,1,3,AIR)
Block(-8,1,4,AIR)
Block(-8,1,5,AIR)
Block(-8,1,6,AIR)
Block(-8,1,7,AIR)
Block(-8,1,8,AIR)
Block(-8,2,-5,80)
Block(-8,2,-4,AIR)
Block(-8,2,-3,AIR)
Block(-8,2,-2,AIR)
Block(-8,2,-1,AIR)
Block(-8,2,0,AIR)
Block(-8,2,1,AIR)
Block(-8,2,2,AIR)
Block(-8,2,3,AIR)
Block(-8,2,4,AIR)
Block(-8,2,5,AIR)
Block(-8,2,6,AIR)
Block(-8,2,7,AIR)
Block(-8,2,8,AIR)
Block(-8,3,-5,80)
Block(-8,3,-4,AIR)
Block(-8,3,-3,AIR)
Block(-8,3,-2,AIR)
Block(-8,3,-1,AIR)
Block(-8,3,0,AIR)
Block(-8,3,1,AIR)
Block(-8,3,2,AIR)
Block(-8,3,3,AIR)
Block(-8,3,4,AIR)
Block(-8,3,5,AIR)
Block(-8,3,6,AIR)
Block(-8,3,7,AIR)
Block(-8,3,8,AIR)
Block(-8,4,-5,80)
Block(-8,4,-4,AIR)
Block(-8,4,-3,AIR)
Block(-8,4,-2,AIR)
Block(-8,4,-1,AIR)
Block(-8,4,0,AIR)
Block(-8,4,1,AIR)
Block(-8,4,2,AIR)
Block(-8,4,3,AIR)
Block(-8,4,4,AIR)
Block(-8,4,5,AIR)
Block(-8,4,6,AIR)
Block(-8,4,7,AIR)
Block(-8,4,8,AIR)
Block(-8,5,-5,80)
Block(-8,5,-4,AIR)
Block(-8,5,-3,AIR)
Block(-8,5,-2,AIR)
Block(-8,5,-1,AIR)
Block(-8,5,0,AIR)
Block(-8,5,1,AIR)
Block(-8,5,2,AIR)
Block(-8,5,3,AIR)
Block(-8,5,4,AIR)
Block(-8,5,5,AIR)
Block(-8,5,6,AIR)
Block(-8,5,7,AIR)
Block(-8,5,8,AIR)
Block(-8,6,-5,80)
Block(-8,6,-4,AIR)
Block(-8,6,-3,AIR)
Block(-8,6,-2,AIR)
Block(-8,6,-1,AIR)
Block(-8,6,0,AIR)
Block(-8,6,1,AIR)
Block(-8,6,2,AIR)
Block(-8,6,3,AIR)
Block(-8,6,4,AIR)
Block(-8,6,5,AIR)
Block(-8,6,6,AIR)
Block(-8,6,7,AIR)
Block(-8,6,8,AIR)
Block(-8,7,-4,80)
Block(-8,7,-3,AIR)
Block(-8,7,-2,AIR)
Block(-8,7,-1,AIR)
Block(-8,7,0,AIR)
Block(-8,7,1,AIR)
Block(-8,7,2,AIR)
Block(-8,7,3,AIR)
Block(-8,7,4,AIR)
Block(-8,7,5,AIR)
Block(-8,7,6,AIR)
Block(-8,7,7,AIR)
Block(-8,7,8,AIR)
Block(-8,8,-3,80)
Block(-8,8,-2,AIR)
Block(-8,8,-1,AIR)
Block(-8,8,0,AIR)
Block(-8,8,1,AIR)
Block(-8,8,2,AIR)
Block(-8,8,3,AIR)
Block(-8,8,4,AIR)
Block(-8,8,5,174)
Block(-8,8,6,AIR)
Block(-8,8,7,AIR)
Block(-8,8,8,AIR)
Block(-8,9,-3,80)
Block(-8,9,-2,AIR)
Block(-8,9,-1,AIR)
Block(-8,9,0,AIR)
Block(-8,9,1,AIR)
Block(-8,9,2,AIR)
Block(-8,9,3,AIR)
Block(-8,9,4,AIR)
Block(-8,9,5,174)
Block(-8,9,6,AIR)
Block(-8,9,7,AIR)
Block(-8,9,8,AIR)
Block(-8,10,-2,80)
Block(-8,10,-1,80)
Block(-8,10,0,AIR)
Block(-8,10,1,AIR)
Block(-8,10,2,AIR)
Block(-8,10,3,AIR)
Block(-8,10,4,AIR)
Block(-8,10,5,174)
Block(-8,10,6,AIR)
Block(-8,10,7,AIR)
Block(-8,10,8,AIR)
Block(-8,11,0,80)
Block(-8,11,1,AIR)
Block(-8,11,2,AIR)
Block(-8,11,3,AIR)
Block(-8,11,4,AIR)
Block(-8,11,5,174)
Block(-8,11,6,174)
Block(-8,11,7,AIR)
Block(-8,11,8,AIR)
Block(-8,12,1,80)
Block(-8,12,2,80)
Block(-8,12,3,80)
Block(-8,12,4,80)
Block(-8,12,5,80)
Block(-8,12,6,80)
Block(-8,12,7,80)
Block(-8,12,8,80)
Block(-7,-3,-5,80)
Block(-7,-3,-4,80)
Block(-7,-3,-3,80)
Block(-7,-3,-2,80)
Block(-7,-3,-1,80)
Block(-7,-3,0,80)
Block(-7,-3,1,80)
Block(-7,-3,2,80)
Block(-7,-3,3,80)
Block(-7,-3,4,80)
Block(-7,-3,5,1)
Block(-7,-3,6,80)
Block(-7,-3,7,80)
Block(-7,-3,8,80)
Block(-7,-2,-5,80)
Block(-7,-2,-4,80)
Block(-7,-2,-3,80)
Block(-7,-2,-2,80)
Block(-7,-2,-1,80)
Block(-7,-2,0,80)
Block(-7,-2,1,80)
Block(-7,-2,2,80)
Block(-7,-2,3,80)
Block(-7,-2,4,80)
Block(-7,-2,5,1)
Block(-7,-2,6,80)
Block(-7,-2,7,1)
Block(-7,-2,8,80)
Block(-7,-1,-5,80)
Block(-7,-1,-4,80)
Block(-7,-1,-3,80)
Block(-7,-1,-2,80)
Block(-7,-1,-1,80)
Block(-7,-1,0,80)
Block(-7,-1,1,80)
Block(-7,-1,2,80)
Block(-7,-1,3,80)
Block(-7,-1,4,80)
Block(-7,-1,5,3)
Block(-7,-1,6,80)
Block(-7,-1,7,80)
Block(-7,-1,8,80)
Block(-7,0,-5,80)
Block(-7,0,-4,80)
Block(-7,0,-3,80)
Block(-7,0,-2,80)
Block(-7,0,-1,1)
Block(-7,0,0,80)
Block(-7,0,1,1)
Block(-7,0,2,80)
Block(-7,0,3,13)
RandomBlock(-7,0,4,CHEST,../../nbt/VanillaLoot/igloo_chest.nbt,50,CHEST,../../nbt/VanillaLoot/igloo_chest.nbt,100)
Block(-7,0,6,80)
Block(-7,0,7,80)
Block(-7,0,8,80)
Block(-7,1,-5,80)
Block(-7,1,-3,AIR)
Block(-7,1,-2,AIR)
Block(-7,1,-1,AIR)
Block(-7,1,0,AIR)
Block(-7,1,1,AIR)
Block(-7,1,2,AIR)
Block(-7,1,3,AIR)
Block(-7,1,4,AIR)
Entity(-7,1,4,SnowMan,2,PumpkinSnowGolem.txt)
Block(-7,1,-4,78)
Block(-7,1,5,AIR)
Block(-7,1,6,AIR)
Block(-7,1,7,AIR)
Block(-7,1,8,AIR)
Block(-7,2,-5,80)
Block(-7,2,-4,AIR)
Block(-7,2,-3,AIR)
Block(-7,2,-2,AIR)
Block(-7,2,-1,AIR)
Block(-7,2,0,AIR)
Block(-7,2,1,AIR)
Block(-7,2,2,AIR)
Block(-7,2,3,AIR)
Block(-7,2,4,AIR)
Block(-7,2,5,AIR)
Block(-7,2,6,AIR)
Block(-7,2,7,AIR)
Block(-7,2,8,AIR)
Block(-7,3,-5,80)
Block(-7,3,-4,AIR)
Block(-7,3,-3,AIR)
Block(-7,3,-2,AIR)
Block(-7,3,-1,AIR)
Block(-7,3,0,AIR)
Block(-7,3,1,AIR)
Block(-7,3,2,AIR)
Block(-7,3,3,AIR)
Block(-7,3,4,AIR)
Block(-7,3,5,AIR)
Block(-7,3,6,AIR)
Block(-7,3,7,AIR)
Block(-7,3,8,AIR)
Block(-7,4,-5,80)
Block(-7,4,-4,AIR)
Block(-7,4,-3,AIR)
Block(-7,4,-2,AIR)
Block(-7,4,-1,AIR)
Block(-7,4,0,AIR)
Block(-7,4,1,AIR)
Block(-7,4,2,AIR)
Block(-7,4,3,AIR)
Block(-7,4,4,AIR)
Block(-7,4,5,AIR)
Block(-7,4,6,AIR)
Block(-7,4,7,AIR)
Block(-7,4,8,AIR)
Block(-7,5,-4,80)
Block(-7,5,-3,AIR)
Block(-7,5,-2,AIR)
Block(-7,5,-1,AIR)
Block(-7,5,0,AIR)
Block(-7,5,1,AIR)
Block(-7,5,2,AIR)
Block(-7,5,3,AIR)
Block(-7,5,4,AIR)
Block(-7,5,5,AIR)
Block(-7,5,6,AIR)
Block(-7,5,7,AIR)
Block(-7,5,8,AIR)
Block(-7,6,-4,80)
Block(-7,6,-3,AIR)
Block(-7,6,-2,AIR)
Block(-7,6,-1,AIR)
Block(-7,6,0,AIR)
Block(-7,6,1,AIR)
Block(-7,6,2,AIR)
Block(-7,6,3,AIR)
Block(-7,6,4,AIR)
Block(-7,6,5,AIR)
Block(-7,6,6,AIR)
Block(-7,6,7,AIR)
Block(-7,6,8,AIR)
Block(-7,7,-4,80)
Block(-7,7,-3,AIR)
Block(-7,7,-2,AIR)
Block(-7,7,-1,AIR)
Block(-7,7,0,AIR)
Block(-7,7,1,AIR)
Block(-7,7,2,AIR)
Block(-7,7,3,AIR)
Block(-7,7,4,AIR)
Block(-7,7,5,AIR)
Block(-7,7,6,AIR)
Block(-7,7,7,AIR)
Block(-7,7,8,AIR)
Block(-7,8,-3,80)
Block(-7,8,-2,SNOW_BLOCK)
Block(-7,8,-1,AIR)
Block(-7,8,0,AIR)
Block(-7,8,1,AIR)
Block(-7,8,2,AIR)
Block(-7,8,3,AIR)
Block(-7,8,4,AIR)
Block(-7,8,5,AIR)
Block(-7,8,6,AIR)
Block(-7,8,7,AIR)
Block(-7,8,8,AIR)
Block(-7,9,-2,80)
Block(-7,9,-1,AIR)
Block(-7,9,0,AIR)
Block(-7,9,1,AIR)
Block(-7,9,2,AIR)
Block(-7,9,3,AIR)
Block(-7,9,4,AIR)
Block(-7,9,5,AIR)
Block(-7,9,6,AIR)
Block(-7,9,7,AIR)
Block(-7,9,8,AIR)
Block(-7,10,-1,80)
Block(-7,10,0,AIR)
Block(-7,10,1,AIR)
Block(-7,10,2,AIR)
Block(-7,10,3,AIR)
Block(-7,10,4,AIR)
Block(-7,10,5,AIR)
Block(-7,10,6,AIR)
Block(-7,10,7,AIR)
Block(-7,10,8,AIR)
Block(-7,11,0,80)
Block(-7,11,1,80)
Block(-7,11,2,80)
Block(-7,11,3,174)
Block(-7,11,4,AIR)
Block(-7,11,5,AIR)
Block(-7,11,6,AIR)
Block(-7,11,7,AIR)
Block(-7,11,8,80)
Block(-7,12,3,80)
Block(-7,12,4,80)
Block(-7,12,5,80)
Block(-7,12,6,80)
Block(-7,12,7,80)
Block(-6,-3,-4,80)
Block(-6,-3,-3,80)
Block(-6,-3,-2,80)
Block(-6,-3,-1,80)
Block(-6,-3,0,80)
Block(-6,-3,1,80)
Block(-6,-3,2,80)
Block(-6,-3,3,80)
Block(-6,-3,4,80)
Block(-6,-3,5,80)
Block(-6,-3,6,80)
Block(-6,-3,7,80)
Block(-6,-3,8,80)
Block(-6,-2,-4,80)
Block(-6,-2,-3,80)
Block(-6,-2,-2,80)
Block(-6,-2,-1,80)
Block(-6,-2,0,80)
Block(-6,-2,1,80)
Block(-6,-2,2,80)
Block(-6,-2,3,80)
Block(-6,-2,4,80)
Block(-6,-2,5,80)
Block(-6,-2,6,80)
Block(-6,-2,7,80)
Block(-6,-2,8,80)
Block(-6,-1,-4,80)
Block(-6,-1,-3,80)
Block(-6,-1,-2,80)
Block(-6,-1,-1,80)
Block(-6,-1,0,80)
Block(-6,-1,1,80)
Block(-6,-1,2,80)
Block(-6,-1,3,80)
Block(-6,-1,4,80)
Block(-6,-1,5,80)
Block(-6,-1,6,80)
Block(-6,-1,7,80)
Block(-6,-1,8,80)
Block(-6,0,-4,80)
Block(-6,0,-3,80)
Block(-6,0,-2,80)
Block(-6,0,-1,80)
Block(-6,0,0,80)
Block(-6,0,1,80)
Block(-6,0,2,80)
Block(-6,0,3,80)
Block(-6,0,4,80)
Block(-6,0,5,80)
Block(-6,0,6,80)
Block(-6,0,7,80)
Block(-6,0,8,80)
Block(-6,1,-4,80)
Block(-6,1,-3,78:1)
Block(-6,1,-2,AIR)
Block(-6,1,-1,AIR)
Block(-6,1,0,AIR)
Block(-6,1,1,AIR)
Block(-6,1,2,AIR)
Block(-6,1,3,AIR)
Block(-6,1,5,AIR)
Block(-6,1,6,AIR)
Block(-6,1,7,AIR)
Block(-6,1,8,AIR)
Block(-6,2,-4,80)
Block(-6,2,-3,AIR)
Block(-6,2,-2,AIR)
Block(-6,2,-1,AIR)
Block(-6,2,0,AIR)
Block(-6,2,1,AIR)
Block(-6,2,2,AIR)
Block(-6,2,3,AIR)
Block(-6,2,4,AIR)
Block(-6,2,5,AIR)
Block(-6,2,6,AIR)
Block(-6,2,7,AIR)
Block(-6,2,8,AIR)
Block(-6,3,-4,80)
Block(-6,3,-3,AIR)
Block(-6,3,-2,AIR)
Block(-6,3,-1,AIR)
Block(-6,3,0,AIR)
Block(-6,3,1,AIR)
Block(-6,3,2,AIR)
Block(-6,3,3,AIR)
Block(-6,3,4,AIR)
Block(-6,3,5,AIR)
Block(-6,3,6,AIR)
Block(-6,3,7,AIR)
Block(-6,3,8,AIR)
Block(-6,4,-4,80)
Block(-6,4,-3,AIR)
Block(-6,4,-2,AIR)
Block(-6,4,-1,AIR)
Block(-6,4,0,AIR)
Block(-6,4,1,AIR)
Block(-6,4,2,AIR)
Block(-6,4,3,AIR)
Block(-6,4,4,AIR)
Block(-6,4,5,AIR)
Block(-6,4,6,AIR)
Block(-6,4,7,AIR)
Block(-6,4,8,AIR)
Block(-6,5,-4,80)
Block(-6,5,-3,AIR)
Block(-6,5,-2,AIR)
Block(-6,5,-1,AIR)
Block(-6,5,0,AIR)
Block(-6,5,1,AIR)
Block(-6,5,2,AIR)
Block(-6,5,3,174)
Block(-6,5,4,AIR)
Block(-6,5,5,AIR)
Block(-6,5,6,AIR)
Block(-6,5,7,AIR)
Block(-6,5,8,AIR)
Block(-6,6,-3,80)
Block(-6,6,-2,AIR)
Block(-6,6,-1,AIR)
Block(-6,6,0,AIR)
Block(-6,6,1,AIR)
Block(-6,6,2,AIR)
Block(-6,6,3,174)
Block(-6,6,4,AIR)
Block(-6,6,5,AIR)
Block(-6,6,6,AIR)
Block(-6,6,7,AIR)
Block(-6,6,8,AIR)
Block(-6,7,-3,80)
Block(-6,7,-2,AIR)
Block(-6,7,-1,AIR)
Block(-6,7,0,AIR)
Block(-6,7,1,AIR)
Block(-6,7,2,AIR)
Block(-6,7,3,174)
Block(-6,7,4,AIR)
Block(-6,7,5,AIR)
Block(-6,7,6,AIR)
Block(-6,7,7,AIR)
Block(-6,7,8,AIR)
Block(-6,8,-2,80)
Block(-6,8,-1,SNOW_BLOCK)
Block(-6,8,0,AIR)
Block(-6,8,1,AIR)
Block(-6,8,2,AIR)
Block(-6,8,3,174)
Block(-6,8,4,AIR)
Block(-6,8,5,AIR)
Block(-6,8,6,AIR)
Block(-6,8,7,AIR)
Block(-6,8,8,AIR)
Block(-6,9,-1,80)
Block(-6,9,0,AIR)
Block(-6,9,1,AIR)
Block(-6,9,2,AIR)
Block(-6,9,3,174)
Block(-6,9,4,AIR)
Block(-6,9,5,AIR)
Block(-6,9,6,174)
Block(-6,9,7,174)
Block(-6,9,8,AIR)
Block(-6,10,0,80)
Block(-6,10,1,80)
Block(-6,10,2,174)
Block(-6,10,3,174)
Block(-6,10,4,AIR)
Block(-6,10,5,AIR)
Block(-6,10,6,174)
Block(-6,10,8,AIR)
Block(-6,11,2,80)
Block(-6,11,3,80)
Block(-6,11,4,80)
Block(-6,11,5,80)
Block(-6,11,6,80)
Block(-6,11,7,80)
Block(-6,11,8,80)
Block(-5,-3,-4,80)
Block(-5,-3,-3,80)
Block(-5,-3,-2,80)
Block(-5,-3,-1,80)
Block(-5,-3,0,80)
Block(-5,-3,1,80)
Block(-5,-3,2,80)
Block(-5,-3,3,80)
Block(-5,-3,4,80)
Block(-5,-3,5,80)
Block(-5,-3,6,80)
Block(-5,-3,7,80)
Block(-5,-3,8,80)
Block(-5,-2,-4,80)
Block(-5,-2,-3,80)
Block(-5,-2,-2,80)
Block(-5,-2,-1,80)
Block(-5,-2,0,80)
Block(-5,-2,1,80)
Block(-5,-2,2,80)
Block(-5,-2,3,80)
Block(-5,-2,4,80)
Block(-5,-2,5,80)
Block(-5,-2,6,80)
Block(-5,-2,7,80)
Block(-5,-2,8,80)
Block(-5,-1,-4,80)
Block(-5,-1,-3,80)
Block(-5,-1,-2,80)
Block(-5,-1,-1,80)
Block(-5,-1,0,80)
Block(-5,-1,1,80)
Block(-5,-1,2,80)
Block(-5,-1,3,80)
Block(-5,-1,4,80)
Block(-5,-1,5,80)
Block(-5,-1,6,80)
Block(-5,-1,7,80)
Block(-5,-1,8,80)
Block(-5,0,-4,80)
Block(-5,0,-3,80)
Block(-5,0,-2,80)
Block(-5,0,-1,80)
Block(-5,0,0,80)
Block(-5,0,1,80)
Block(-5,0,2,80)
Block(-5,0,3,80)
Block(-5,0,4,80)
Block(-5,0,5,80)
Block(-5,0,6,80)
Block(-5,0,7,80)
Block(-5,0,8,80)
Block(-5,1,-4,80)
Block(-5,1,-3,78:2)
Block(-5,1,-2,AIR)
Block(-5,1,-1,78)
Block(-5,1,0,AIR)
Block(-5,1,1,AIR)
Block(-5,1,2,AIR)
Block(-5,1,3,AIR)
Block(-5,1,4,AIR)
Block(-5,1,5,AIR)
Block(-5,1,6,78)
Block(-5,1,7,78)
Block(-5,1,8,78)
Block(-5,2,-4,80)
Block(-5,2,-3,AIR)
Block(-5,2,-2,AIR)
Block(-5,2,-1,AIR)
Block(-5,2,0,AIR)
Block(-5,2,1,AIR)
Block(-5,2,2,AIR)
Block(-5,2,3,AIR)
Block(-5,2,4,AIR)
Block(-5,2,5,AIR)
Block(-5,2,6,AIR)
Block(-5,2,7,AIR)
Block(-5,2,8,AIR)
Block(-5,3,-4,80)
Block(-5,3,-3,AIR)
Block(-5,3,-2,AIR)
Block(-5,3,-1,AIR)
Block(-5,3,0,AIR)
Block(-5,3,1,AIR)
Block(-5,3,2,AIR)
Block(-5,3,3,AIR)
Block(-5,3,4,AIR)
Block(-5,3,5,AIR)
Block(-5,3,6,AIR)
Block(-5,3,7,AIR)
Block(-5,3,8,AIR)
Block(-5,4,-3,80)
Block(-5,4,-2,AIR)
Block(-5,4,-1,AIR)
Block(-5,4,0,AIR)
Block(-5,4,1,AIR)
Block(-5,4,2,AIR)
Block(-5,4,3,AIR)
Block(-5,4,4,AIR)
Block(-5,4,5,AIR)
Block(-5,4,6,AIR)
Block(-5,4,7,AIR)
Block(-5,4,8,AIR)
Block(-5,5,-3,80)
Block(-5,5,-2,AIR)
Block(-5,5,-1,AIR)
Block(-5,5,0,AIR)
Block(-5,5,1,AIR)
Block(-5,5,2,AIR)
Block(-5,5,3,AIR)
Block(-5,5,4,AIR)
Block(-5,5,5,AIR)
Block(-5,5,6,AIR)
Block(-5,5,7,AIR)
Block(-5,5,8,AIR)
Block(-5,6,-3,80)
Block(-5,6,-2,SNOW_BLOCK)
Block(-5,6,-1,AIR)
Block(-5,6,0,AIR)
Block(-5,6,1,AIR)
Block(-5,6,2,AIR)
Block(-5,6,3,AIR)
Block(-5,6,4,AIR)
Block(-5,6,5,AIR)
Block(-5,6,6,AIR)
Block(-5,6,7,AIR)
Block(-5,6,8,AIR)
Block(-5,7,-2,80)
Block(-5,7,-1,AIR)
Block(-5,7,0,AIR)
Block(-5,7,1,AIR)
Block(-5,7,2,AIR)
Block(-5,7,3,AIR)
Block(-5,7,4,AIR)
Block(-5,7,5,AIR)
Block(-5,7,6,AIR)
Block(-5,7,7,174)
Block(-5,7,8,AIR)
Block(-5,8,-1,80)
Block(-5,8,0,AIR)
Block(-5,8,1,AIR)
Block(-5,8,2,AIR)
Block(-5,8,3,AIR)
Block(-5,8,4,AIR)
Block(-5,8,5,AIR)
Block(-5,8,6,AIR)
Block(-5,8,7,174)
Block(-5,8,8,AIR)
Block(-5,9,0,80)
Block(-5,9,1,AIR)
Block(-5,9,2,AIR)
Block(-5,9,3,AIR)
Block(-5,9,4,AIR)
Block(-5,9,5,AIR)
Block(-5,9,6,AIR)
Block(-5,9,7,174)
Block(-5,9,8,AIR)
Block(-5,10,1,80)
Block(-5,10,2,80)
Block(-5,10,3,80)
Block(-5,10,4,AIR)
Block(-5,10,5,174)
Block(-5,10,6,174)
Block(-5,10,7,80)
Block(-5,10,8,80)
Block(-5,11,4,80)
Block(-5,11,5,80)
Block(-5,11,6,80)
Block(-4,-3,-3,80)
Block(-4,-3,-2,80)
Block(-4,-3,-1,80)
Block(-4,-3,0,80)
Block(-4,-3,1,80)
Block(-4,-3,2,80)
Block(-4,-3,3,80)
Block(-4,-3,4,80)
Block(-4,-3,5,80)
Block(-4,-3,6,80)
Block(-4,-3,7,80)
Block(-4,-3,8,80)
Block(-4,-2,-3,80)
Block(-4,-2,-2,80)
Block(-4,-2,-1,80)
Block(-4,-2,0,80)
Block(-4,-2,1,80)
Block(-4,-2,2,80)
Block(-4,-2,3,80)
Block(-4,-2,4,80)
Block(-4,-2,5,80)
Block(-4,-2,6,80)
Block(-4,-2,7,80)
Block(-4,-2,8,80)
Block(-4,-1,-3,80)
Block(-4,-1,-2,80)
Block(-4,-1,-1,80)
Block(-4,-1,0,80)
Block(-4,-1,1,80)
Block(-4,-1,2,80)
Block(-4,-1,3,80)
Block(-4,-1,4,80)
Block(-4,-1,5,80)
Block(-4,-1,6,80)
Block(-4,-1,7,80)
Block(-4,-1,8,80)
Block(-4,0,-3,80)
Block(-4,0,-2,80)
Block(-4,0,-1,80)
Block(-4,0,0,80)
Block(-4,0,1,80)
Block(-4,0,2,80)
Block(-4,0,3,80)
Block(-4,0,4,80)
Block(-4,0,5,80)
Block(-4,0,6,80)
Block(-4,0,7,80)
Block(-4,0,8,80)
Block(-4,1,-3,80)
Block(-4,1,-2,78:1)
Block(-4,1,-1,78:1)
Block(-4,1,0,78:1)
Block(-4,1,1,AIR)
Block(-4,1,2,AIR)
Block(-4,1,3,AIR)
Block(-4,1,4,AIR)
Block(-4,1,5,AIR)
Entity(-4,1,5,SnowMan,2,PumpkinSnowGolem.txt)
Block(-4,1,6,78)
Block(-4,1,7,78:2)
Block(-4,1,8,78)
Block(-4,2,-3,80)
Block(-4,2,-2,AIR)
Block(-4,2,-1,AIR)
Block(-4,2,0,AIR)
Block(-4,2,1,AIR)
Block(-4,2,2,AIR)
Block(-4,2,3,AIR)
Block(-4,2,4,AIR)
Block(-4,2,5,AIR)
Block(-4,2,6,AIR)
Block(-4,2,7,AIR)
Block(-4,2,8,AIR)
Block(-4,3,-3,80)
Block(-4,3,-2,SNOW_BLOCK)
Block(-4,3,-1,AIR)
Block(-4,3,0,AIR)
Block(-4,3,1,AIR)
Block(-4,3,2,AIR)
Block(-4,3,3,AIR)
Block(-4,3,4,AIR)
Block(-4,3,5,AIR)
Block(-4,3,6,AIR)
Block(-4,3,7,AIR)
Block(-4,3,8,AIR)
Block(-4,4,-3,80)
Block(-4,4,-2,80)
Block(-4,4,-1,AIR)
Block(-4,4,0,AIR)
Block(-4,4,1,AIR)
Block(-4,4,2,AIR)
Block(-4,4,3,AIR)
Block(-4,4,4,AIR)
Block(-4,4,5,AIR)
Block(-4,4,6,AIR)
Block(-4,4,7,AIR)
Block(-4,4,8,AIR)
Block(-4,5,-2,80)
Block(-4,5,-1,SNOW_BLOCK)
Block(-4,5,0,AIR)
Block(-4,5,1,AIR)
Block(-4,5,2,AIR)
Block(-4,5,3,AIR)
Block(-4,5,4,AIR)
Block(-4,5,5,AIR)
Block(-4,5,6,AIR)
Block(-4,5,7,AIR)
Block(-4,5,8,AIR)
Block(-4,6,-2,80)
Block(-4,6,-1,80)
Block(-4,6,0,AIR)
Block(-4,6,1,AIR)
Block(-4,6,2,AIR)
Block(-4,6,3,AIR)
Block(-4,6,4,AIR)
Block(-4,6,5,AIR)
Block(-4,6,6,AIR)
Block(-4,6,7,AIR)
Block(-4,6,8,AIR)
Block(-4,7,-1,80)
Block(-4,7,0,AIR)
Block(-4,7,1,AIR)
Block(-4,7,2,AIR)
Block(-4,7,3,AIR)
Block(-4,7,4,AIR)
Block(-4,7,5,AIR)
Block(-4,7,6,AIR)
Block(-4,7,7,AIR)
Block(-4,7,8,AIR)
Block(-4,8,0,80)
Block(-4,8,1,80)
Block(-4,8,2,SNOW_BLOCK)
Block(-4,8,3,AIR)
Block(-4,8,4,AIR)
Block(-4,8,5,AIR)
Block(-4,8,6,AIR)
Block(-4,8,7,AIR)
Block(-4,8,8,SNOW_BLOCK)
Block(-4,9,1,80)
Block(-4,9,2,80)
Block(-4,9,3,80)
Block(-4,9,4,SNOW_BLOCK)
Block(-4,9,5,AIR)
Block(-4,9,6,SNOW_BLOCK)
Block(-4,9,7,80)
Block(-4,9,8,80)
Block(-4,10,3,80)
Block(-4,10,4,80)
Block(-4,10,5,80)
Block(-4,10,6,80)
Block(-4,10,7,80)
Block(-3,-3,-2,80)
Block(-3,-3,-1,80)
Block(-3,-3,0,80)
Block(-3,-3,1,80)
Block(-3,-3,2,80)
Block(-3,-3,3,80)
Block(-3,-3,4,80)
Block(-3,-3,5,80)
Block(-3,-3,6,80)
Block(-3,-3,7,80)
Block(-3,-3,8,80)
Block(-3,-2,-2,80)
Block(-3,-2,-1,80)
Block(-3,-2,0,80)
Block(-3,-2,1,80)
Block(-3,-2,2,80)
Block(-3,-2,3,80)
Block(-3,-2,4,80)
Block(-3,-2,5,80)
Block(-3,-2,6,80)
Block(-3,-2,7,80)
Block(-3,-2,8,80)
Block(-3,-1,-2,80)
Block(-3,-1,-1,80)
Block(-3,-1,0,80)
Block(-3,-1,1,80)
Block(-3,-1,2,80)
Block(-3,-1,3,80)
Block(-3,-1,4,80)
Block(-3,-1,5,80)
Block(-3,-1,6,80)
Block(-3,-1,7,80)
Block(-3,-1,8,80)
Block(-3,0,-2,80)
Block(-3,0,-1,80)
Block(-3,0,0,80)
Block(-3,0,1,80)
Block(-3,0,2,80)
Block(-3,0,3,80)
Block(-3,0,4,80)
Block(-3,0,5,80)
Block(-3,0,6,80)
Block(-3,0,7,80)
Block(-3,0,8,80)
Block(-3,1,-2,80)
Block(-3,1,-1,80)
Block(-3,1,0,78:1)
Block(-3,1,1,78:1)
Block(-3,1,2,AIR)
Block(-3,1,3,78:1)
Block(-3,1,4,AIR)
Block(-3,1,5,AIR)
Block(-3,1,6,AIR)
Block(-3,1,7,78:1)
Block(-3,1,8,78)
Block(-3,2,-2,80)
Block(-3,2,-1,80)
Block(-3,2,0,AIR)
Block(-3,2,1,AIR)
Block(-3,2,2,AIR)
Block(-3,2,3,AIR)
Block(-3,2,4,AIR)
Block(-3,2,5,AIR)
Block(-3,2,6,AIR)
Block(-3,2,7,AIR)
Block(-3,2,8,AIR)
Block(-3,3,-2,80)
Block(-3,3,-1,80)
Block(-3,3,0,AIR)
Block(-3,3,1,AIR)
Block(-3,3,2,AIR)
Block(-3,3,3,AIR)
Block(-3,3,4,AIR)
Block(-3,3,5,AIR)
Block(-3,3,6,AIR)
Block(-3,3,7,AIR)
Block(-3,3,8,AIR)
Block(-3,4,-1,80)
Block(-3,4,0,AIR)
Block(-3,4,1,AIR)
Block(-3,4,2,AIR)
Block(-3,4,3,AIR)
Block(-3,4,4,AIR)
Block(-3,4,5,AIR)
Block(-3,4,6,AIR)
Block(-3,4,7,AIR)
Block(-3,4,8,AIR)
Block(-3,5,-1,80)
Block(-3,5,0,80)
Block(-3,5,1,AIR)
Block(-3,5,2,AIR)
Block(-3,5,3,AIR)
Block(-3,5,4,AIR)
Block(-3,5,5,AIR)
Block(-3,5,6,AIR)
Block(-3,5,7,AIR)
Block(-3,5,8,AIR)
Block(-3,6,0,80)
Block(-3,6,1,SNOW_BLOCK)
Block(-3,6,2,AIR)
Block(-3,6,3,AIR)
Block(-3,6,4,AIR)
Block(-3,6,5,AIR)
Block(-3,6,6,AIR)
Block(-3,6,7,AIR)
Block(-3,6,8,AIR)
Block(-3,7,0,80)
Block(-3,7,1,80)
Block(-3,7,2,80)
Block(-3,7,3,SNOW_BLOCK)
Block(-3,7,4,AIR)
Block(-3,7,5,AIR)
Block(-3,7,6,SNOW_BLOCK)
Block(-3,7,7,SNOW_BLOCK)
Block(-3,7,8,80)
Block(-3,8,2,80)
Block(-3,8,3,80)
Block(-3,8,4,80)
Block(-3,8,5,80)
Block(-3,8,6,80)
Block(-3,8,7,80)
Block(-3,8,8,80)
Block(-3,9,4,80)
Block(-3,9,5,80)
Block(-3,9,6,80)
Block(-2,-3,0,80)
Block(-2,-3,1,80)
Block(-2,-3,2,80)
Block(-2,-3,3,80)
Block(-2,-3,4,80)
Block(-2,-3,5,80)
Block(-2,-3,6,80)
Block(-2,-3,7,80)
Block(-2,-3,8,80)
Block(-2,-2,0,80)
Block(-2,-2,1,80)
Block(-2,-2,2,80)
Block(-2,-2,3,80)
Block(-2,-2,4,80)
Block(-2,-2,5,80)
Block(-2,-2,6,80)
Block(-2,-2,7,80)
Block(-2,-2,8,80)
Block(-2,-1,0,80)
Block(-2,-1,1,80)
Block(-2,-1,2,80)
Block(-2,-1,3,80)
Block(-2,-1,4,80)
Block(-2,-1,5,80)
Block(-2,-1,6,80)
Block(-2,-1,7,80)
Block(-2,-1,8,80)
Block(-2,0,0,80)
Block(-2,0,1,80)
Block(-2,0,2,80)
Block(-2,0,3,80)
Block(-2,0,4,80)
Block(-2,0,5,80)
Block(-2,0,6,80)
Block(-2,0,7,80)
Block(-2,0,8,80)
Block(-2,1,0,80)
Block(-2,1,1,80)
Block(-2,1,2,78)
Block(-2,1,3,78:2)
Block(-2,1,4,AIR)
Block(-2,1,5,AIR)
Block(-2,1,6,AIR)
Block(-2,1,7,78:1)
Block(-2,1,8,78:1)
Block(-2,2,0,80)
Block(-2,2,1,80)
Block(-2,2,2,AIR)
Block(-2,2,3,AIR)
Block(-2,2,4,AIR)
Block(-2,2,5,AIR)
Block(-2,2,6,AIR)
Block(-2,2,7,AIR)
Block(-2,2,8,AIR)
Block(-2,3,0,80)
Block(-2,3,1,80)
Block(-2,3,2,AIR)
Block(-2,3,3,AIR)
Block(-2,3,4,AIR)
Block(-2,3,5,AIR)
Block(-2,3,6,AIR)
Block(-2,3,7,AIR)
Block(-2,3,8,AIR)
Block(-2,4,0,80)
Block(-2,4,1,80)
Block(-2,4,2,80)
Block(-2,4,3,AIR)
Block(-2,4,4,AIR)
Block(-2,4,5,AIR)
Block(-2,4,6,AIR)
Block(-2,4,7,AIR)
Block(-2,4,8,80)
Block(-2,5,1,80)
Block(-2,5,2,80)
Block(-2,5,3,80)
Block(-2,5,4,AIR)
Block(-2,5,5,AIR)
Block(-2,5,6,AIR)
Block(-2,5,7,80)
Block(-2,5,8,80)
Block(-2,6,1,80)
Block(-2,6,2,80)
Block(-2,6,3,80)
Block(-2,6,4,80)
Block(-2,6,5,80)
Block(-2,6,6,80)
Block(-2,6,7,80)
Block(-2,6,8,80)
Block(-2,7,3,80)
Block(-2,7,4,80)
Block(-2,7,5,80)
Block(-2,7,6,80)
Block(-2,7,7,80)
Block(-1,-3,2,80)
Block(-1,-3,3,80)
Block(-1,-3,4,80)
Block(-1,-3,5,80)
Block(-1,-3,6,80)
Block(-1,-3,7,80)
Block(-1,-3,8,80)
Block(-1,-2,2,80)
Block(-1,-2,3,80)
Block(-1,-2,4,80)
Block(-1,-2,5,80)
Block(-1,-2,6,80)
Block(-1,-2,7,80)
Block(-1,-2,8,80)
Block(-1,-1,2,80)
Block(-1,-1,3,80)
Block(-1,-1,4,80)
Block(-1,-1,5,80)
Block(-1,-1,6,80)
Block(-1,-1,7,80)
Block(-1,-1,8,80)
Block(-1,0,2,80)
Block(-1,0,3,80)
Block(-1,0,4,80)
Block(-1,0,5,80)
Block(-1,0,6,80)
Block(-1,0,7,80)
Block(-1,0,8,80)
Block(-1,1,2,80)
Block(-1,1,3,80)
Block(-1,1,4,AIR)
Block(-1,1,5,AIR)
Block(-1,1,6,AIR)
Block(-1,1,7,80)
Block(-1,1,8,80)
Block(-1,2,2,80)
Block(-1,2,3,80)
Block(-1,2,4,AIR)
Block(-1,2,5,AIR)
Block(-1,2,6,AIR)
Block(-1,2,7,80)
Block(-1,2,8,80)
Block(-1,3,2,80)
Block(-1,3,3,80)
Block(-1,3,4,80)
Block(-1,3,5,AIR)
Block(-1,3,6,80)
Block(-1,3,7,80)
Block(-1,3,8,80)
Block(-1,4,3,80)
Block(-1,4,4,80)
Block(-1,4,5,80)
Block(-1,4,6,80)
Block(-1,4,7,80)
Block(-1,5,4,80)
Block(-1,5,5,80)
Block(-1,5,6,80)
Block(0,-3,4,80)
Block(0,-3,5,80)
Block(0,-3,6,80)
Block(0,-2,4,80)
Block(0,-2,5,80)
Block(0,-2,6,80)
Block(0,-1,4,80)
Block(0,-1,5,80)
Block(0,-1,6,80)
Block(0,0,4,80)
Block(0,0,5,80)
Block(0,0,6,80)
Block(0,1,4,80)
Block(0,1,5,AIR)
Block(0,1,6,80)
Block(0,2,4,80)
Block(0,2,5,AIR)
Block(0,2,6,80)
Block(0,3,5,80)


# 

#######################################################################
# +-----------------------------------------------------------------+ #
# |                            BO3 checks                           | #
# +-----------------------------------------------------------------+ #
#######################################################################

# Require a condition at a certain location in order for the BO3 to be spawned.
# BlockCheck(x,y,z,BlockName[,BlockName[,...]]) - one of the blocks must be at the location
# BlockCheckNot(x,y,z,BlockName[,BlockName[,...]]) - all the blocks must not be at the location
# LightCheck(x,y,z,minLightLevel,maxLightLevel) - light must be between min and max (inclusive)

# You can use "Solid" as a BlockName for matching all solid blocks or "All" to match all blocks that aren't air.

# Examples:
#   BlockCheck(0,-1,0,GRASS,DIRT)  Require grass or dirt just below the object
#   BlockCheck(0,-1,0,Solid)       Require any solid block just below the object
#   BlockCheck(0,-1,0,WOOL)        Require any type of wool just below the object
#   BlockCheck(0,-1,0,WOOL:0)      Require white wool just below the object
#   BlockCheckNot(0,0,0,WOOL:0)   Require that there is no white wool below the object
#   LightCheck(0,0,0,0,1)          Require almost complete darkness just below the object

#######################################################################
# +-----------------------------------------------------------------+ #
# |                             Branches                            | #
# +-----------------------------------------------------------------+ #
#######################################################################

# Branches are objects that will spawn when this object spawns when it is used in
# the CustomStructure resource. Branches can also have branches, making complex
# structures possible. See the wiki for more details.

# Regular Branches spawn each branch with an independent chance of spawning.
# Branch(x,y,z,branchName,rotation,chance[,anotherBranchName,rotation,chance[,...]][IndividualChance])
# branchName - name of the object to spawn.
# rotation - NORTH, SOUTH, EAST or WEST.
# IndividualChance - The chance each branch has to spawn, assumed to be 100 when left blank

# WeightedBranch(x,y,z,branchName,rotation,chance[,anotherBranchName,rotation,chance[,...]][MaxChanceOutOf])
# MaxChanceOutOf - The chance all branches have to spawn out of, assumed to be 100 when left blank
