
#######################################################################
# +-----------------------------------------------------------------+ #
# |                            BO3 object                           | #
# +-----------------------------------------------------------------+ #
#######################################################################

# This is the config file of a custom object.
# If you add this object correctly to your BiomeConfigs, it will spawn in the world.

# This is the creator of this BO3 object
Author: LordSmellyPants

# A short description of this BO3 object
Description: No description given

# The BO3 version, don't change this! It can be used by external applications to do a version check.
Version: 3

# The settings mode, WriteAll, WriteWithoutComments or WriteDisable. See WorldConfig.
SettingsMode: WriteDisable


#######################################################################
# +-----------------------------------------------------------------+ #
# |                          Main settings                          | #
# +-----------------------------------------------------------------+ #
#######################################################################

# This needs to be set to true to spawn the object in the Tree and Sapling resources.
Tree: false

# The frequency of the BO3 from 1 to 200. Tries this many times to spawn this BO3 when using the CustomObject(...) resource.
# Ignored by Tree(..), Sapling(..) and CustomStructure(..)
Frequency: 1

# The rarity of the BO3 from 0 to 100. Each spawn attempt has rarity% chance to succeed when using the CustomObject(...) resource.
# Ignored by Tree(..), Sapling(..) and CustomStructure(..)
Rarity: 100.0

# If you set this to true, the BO3 will be placed with a random rotation.
RotateRandomly: false

# The spawn height of the BO3 - atMinY, randomY, highestBlock or highestSolidBlock.
SpawnHeight: highestSolidBlock

# The offset from the spawn height to spawn this BO3
# Ex. SpawnHeight = highestSolidBlock, SpawnHeightOffset = 3; This object will spawn 3 blocks above the highest solid block
SpawnHeightOffset: 0

# A random amount to offset the spawn location from the spawn offset height
# Ex. SpawnHeightOffset = 3, SpawnHeightVariance = 3; This object will spawn 3 to 6 blocks above the original spot it would have spawned
SpawnHeightVariance: 0

##############################
# Height Limits for the BO3. #
##############################

# When in randomY mode used as the minimum Y or in atMinY mode as the actual Y to spawn this BO3 at.
MinHeight: 50

# When in randomY mode used as the maximum Y to spawn this BO3 at.
MaxHeight: 75

######################
# Extrusion settings #
######################

# The style of extrusion you wish to use - BottomDown, TopUp, None (Default)
ExtrudeMode: None

# The blocks to extrude your BO3 through
ExtrudeThroughBlocks: AIR

# Objects can have other objects attacthed to it: branches. Branches can also
# have branches attached to it, which can also have branches, etc. This is the
# maximum branch depth for this objects.
MaxBranchDepth: 10

# When spawned with the UseWorld keyword, this BO3 should NOT spawn in the following biomes.
# If you write the BO3 name directly in the BiomeConfigs, this will be ignored.
ExcludedBiomes: All


#######################################################################
# +-----------------------------------------------------------------+ #
# |                      Source block settings                      | #
# +-----------------------------------------------------------------+ #
#######################################################################

# The block(s) the BO3 should spawn in.
SourceBlocks: STONE:1,STONE:3,STONE:5,DIRT:1,GRASS,DIRT,STONE,GRAVEL,SAND,CLAY,HARD_CLAY,159:14,159,175,175:1,175:2,175:3,175:4,175:5,31,31:1,31:2,1:1,1:5,1:3,AIR,SANDSTONE

# The maximum percentage of the BO3 that can be outside the SourceBlock.
# The BO3 won't be placed on a location with more blocks outside the SourceBlock than this percentage.
MaxPercentageOutsideSourceBlock: 30

# What to do when a block is about to be placed outside the SourceBlock? (dontPlace, placeAnyway)
OutsideSourceBlock: placeAnyway


#######################################################################
# +-----------------------------------------------------------------+ #
# |                              Blocks                             | #
# +-----------------------------------------------------------------+ #
#######################################################################

# All the blocks used in the BO3 are listed here. Possible blocks:
# Block(x,y,z,id[.data][,nbtfile.nbt)
# RandomBlock(x,y,z,id[:data][,nbtfile.nbt],chance[,id[:data][,nbtfile.nbt],chance[,...]])
#  So RandomBlock(0,0,0,CHEST,chest.nbt,50,CHEST,anotherchest.nbt,100) will spawn a chest at
#  the BO3 origin, and give it a 50% chance to have the contents of chest.nbt, or, if that
#  fails, a 100% percent chance to have the contents of anotherchest.nbt.
# MinecraftObject(x,y,z,name)
#  Spawns an object in the Mojang NBT structure format. For example, 
#  MinecraftObject(0,0,0,minecraft:igloo/igloo_bottom)
#  spawns the bottom part of an igloo.
Block(-25,-3,-3,DIRT)
Block(-25,-3,-2,DIRT)
Block(-25,-3,-1,DIRT)
Block(-25,-3,0,DIRT)
Block(-25,-3,1,DIRT)
Block(-25,-2,-4,DIRT)
Block(-25,-2,-3,DIRT)
Block(-25,-2,-2,DIRT)
Block(-25,-2,-1,DIRT)
Block(-25,-2,0,DIRT)
Block(-25,-2,1,DIRT)
Block(-25,-2,2,DIRT)
Block(-25,-2,3,DIRT)
Block(-25,-1,-4,GRASS)
Block(-25,-1,-3,DIRT)
Block(-25,-1,-2,DIRT)
Block(-25,-1,-1,DIRT)
Block(-25,-1,0,DIRT)
Block(-25,-1,1,DIRT)
Block(-25,-1,2,GRASS)
Block(-25,-1,3,GRASS)
Block(-25,0,-3,GRASS)
Block(-25,0,-2,GRASS)
Block(-25,0,-1,GRASS)
Block(-25,0,0,GRASS)
Block(-25,0,1,GRASS)
Block(-24,-3,-4,DIRT)
Block(-24,-3,-3,STONE)
Block(-24,-3,-2,STONE)
Block(-24,-3,-1,STONE)
Block(-24,-3,0,STONE)
Block(-24,-3,1,STONE)
Block(-24,-2,-5,DIRT)
Block(-24,-2,-4,DIRT)
Block(-24,-2,-3,DIRT)
Block(-24,-2,-2,DIRT)
Block(-24,-2,-1,DIRT)
Block(-24,-2,0,DIRT)
Block(-24,-2,1,DIRT)
Block(-24,-2,2,DIRT)
Block(-24,-2,3,DIRT)
Block(-24,-2,4,DIRT)
Block(-24,-2,5,DIRT)
Block(-24,-1,-5,GRASS)
Block(-24,-1,-4,DIRT)
Block(-24,-1,-3,DIRT)
Block(-24,-1,-2,DIRT)
Block(-24,-1,-1,DIRT)
Block(-24,-1,0,DIRT)
Block(-24,-1,1,DIRT)
Block(-24,-1,2,DIRT)
Block(-24,-1,3,DIRT)
Block(-24,-1,4,GRASS)
Block(-24,-1,5,GRASS)
Block(-24,0,-4,GRASS)
Block(-24,0,-3,DIRT)
Block(-24,0,-2,DIRT)
Block(-24,0,-1,DIRT)
Block(-24,0,0,DIRT)
Block(-24,0,1,DIRT)
Block(-24,0,2,DIRT)
Block(-24,0,3,GRASS)
Block(-24,1,-3,GRASS)
Block(-24,1,-2,GRASS)
Block(-24,1,-1,GRASS)
Block(-24,1,0,GRASS)
Block(-24,1,1,GRASS)
Block(-24,1,2,GRASS)
Block(-23,-4,-4,STONE)
Block(-23,-4,-3,STONE)
Block(-23,-4,-2,STONE)
Block(-23,-4,-1,STONE)
Block(-23,-4,0,STONE)
Block(-23,-4,1,STONE)
Block(-23,-4,2,STONE)
Block(-23,-4,3,STONE)
Block(-23,-4,5,STONE)
Block(-23,-3,-5,DIRT)
Block(-23,-3,-4,STONE)
Block(-23,-3,-3,STONE)
Block(-23,-3,-2,STONE)
Block(-23,-3,-1,STONE)
Block(-23,-3,0,STONE)
Block(-23,-3,1,STONE)
Block(-23,-3,2,STONE)
Block(-23,-3,3,STONE)
Block(-23,-3,4,STONE)
Block(-23,-3,5,DIRT)
Block(-23,-3,6,DIRT)
Block(-23,-2,-6,DIRT)
Block(-23,-2,-5,DIRT)
Block(-23,-2,-4,DIRT)
Block(-23,-2,-3,DIRT)
Block(-23,-2,-2,STONE)
Block(-23,-2,-1,STONE)
Block(-23,-2,0,STONE)
Block(-23,-2,1,STONE)
Block(-23,-2,2,STONE)
Block(-23,-2,3,DIRT)
Block(-23,-2,4,DIRT)
Block(-23,-2,5,DIRT)
Block(-23,-2,6,DIRT)
Block(-23,-2,7,DIRT)
Block(-23,-1,-6,GRASS)
Block(-23,-1,-5,DIRT)
Block(-23,-1,-4,DIRT)
Block(-23,-1,-3,DIRT)
Block(-23,-1,-2,DIRT)
Block(-23,-1,-1,DIRT)
Block(-23,-1,0,DIRT)
Block(-23,-1,1,DIRT)
Block(-23,-1,2,DIRT)
Block(-23,-1,3,DIRT)
Block(-23,-1,4,DIRT)
Block(-23,-1,5,DIRT)
Block(-23,-1,6,GRASS)
Block(-23,-1,7,GRASS)
Block(-23,0,-5,GRASS)
Block(-23,0,-4,DIRT)
Block(-23,0,-3,DIRT)
Block(-23,0,-2,DIRT)
Block(-23,0,-1,DIRT)
Block(-23,0,0,DIRT)
Block(-23,0,1,DIRT)
Block(-23,0,2,DIRT)
Block(-23,0,3,DIRT)
Block(-23,0,4,DIRT)
Block(-23,0,5,GRASS)
Block(-23,1,-4,GRASS)
Block(-23,1,-3,GRASS)
Block(-23,1,-2,DIRT)
Block(-23,1,-1,DIRT)
Block(-23,1,0,DIRT)
Block(-23,1,1,DIRT)
Block(-23,1,2,DIRT)
Block(-23,1,3,GRASS)
Block(-23,1,4,GRASS)
Block(-23,2,-2,GRASS)
Block(-23,2,-1,GRASS)
Block(-23,2,0,GRASS)
Block(-23,2,1,GRASS)
Block(-23,2,2,GRASS)
Block(-22,-5,-4,STONE)
Block(-22,-5,-3,STONE)
Block(-22,-5,-2,STONE)
Block(-22,-5,-1,STONE)
Block(-22,-5,0,STONE)
Block(-22,-5,1,STONE)
Block(-22,-5,2,STONE)
Block(-22,-5,3,STONE)
Block(-22,-5,4,STONE)
Block(-22,-4,-5,STONE)
Block(-22,-4,-4,STONE)
Block(-22,-4,-3,STONE)
Block(-22,-4,-2,STONE)
Block(-22,-4,-1,STONE)
Block(-22,-4,0,STONE)
Block(-22,-4,1,STONE)
Block(-22,-4,2,STONE)
Block(-22,-4,3,STONE)
Block(-22,-4,4,STONE)
Block(-22,-4,5,STONE)
Block(-22,-4,6,STONE)
Block(-22,-4,7,STONE)
Block(-22,-3,-6,DIRT)
Block(-22,-3,-5,STONE)
Block(-22,-3,-4,STONE)
Block(-22,-3,-3,STONE)
Block(-22,-3,-2,STONE)
Block(-22,-3,-1,STONE)
Block(-22,-3,0,STONE)
Block(-22,-3,1,STONE)
Block(-22,-3,2,STONE)
Block(-22,-3,3,STONE)
Block(-22,-3,4,STONE)
Block(-22,-3,5,STONE)
Block(-22,-3,6,DIRT)
Block(-22,-3,7,DIRT)
Block(-22,-3,8,DIRT)
Block(-22,-2,-7,DIRT)
Block(-22,-2,-6,DIRT)
Block(-22,-2,-5,DIRT)
Block(-22,-2,-4,DIRT)
Block(-22,-2,-3,STONE)
Block(-22,-2,-2,STONE)
Block(-22,-2,-1,STONE)
Block(-22,-2,0,STONE)
Block(-22,-2,1,STONE)
Block(-22,-2,2,STONE)
Block(-22,-2,3,STONE)
Block(-22,-2,4,STONE)
Block(-22,-2,5,DIRT)
Block(-22,-2,6,DIRT)
Block(-22,-2,7,DIRT)
Block(-22,-2,8,DIRT)
Block(-22,-1,-7,GRASS)
Block(-22,-1,-6,DIRT)
Block(-22,-1,-5,DIRT)
Block(-22,-1,-4,DIRT)
Block(-22,-1,-3,DIRT)
Block(-22,-1,-2,DIRT)
Block(-22,-1,-1,STONE)
Block(-22,-1,0,STONE)
Block(-22,-1,1,STONE)
Block(-22,-1,2,DIRT)
Block(-22,-1,3,DIRT)
Block(-22,-1,4,DIRT)
Block(-22,-1,5,DIRT)
Block(-22,-1,6,DIRT)
Block(-22,-1,7,DIRT)
Block(-22,-1,8,GRASS)
Block(-22,0,-6,GRASS)
Block(-22,0,-5,DIRT)
Block(-22,0,-4,DIRT)
Block(-22,0,-3,DIRT)
Block(-22,0,-2,DIRT)
Block(-22,0,-1,DIRT)
Block(-22,0,0,DIRT)
Block(-22,0,1,DIRT)
Block(-22,0,2,DIRT)
Block(-22,0,3,DIRT)
Block(-22,0,4,DIRT)
Block(-22,0,5,DIRT)
Block(-22,0,6,GRASS)
Block(-22,0,7,GRASS)
Block(-22,1,-5,GRASS)
Block(-22,1,-4,GRASS)
Block(-22,1,-3,DIRT)
Block(-22,1,-2,DIRT)
Block(-22,1,-1,DIRT)
Block(-22,1,0,DIRT)
Block(-22,1,1,DIRT)
Block(-22,1,2,DIRT)
Block(-22,1,3,DIRT)
Block(-22,1,4,DIRT)
Block(-22,1,5,GRASS)
Block(-22,2,-3,GRASS)
Block(-22,2,-2,GRASS)
Block(-22,2,-1,DIRT)
Block(-22,2,0,DIRT)
Block(-22,2,1,DIRT)
Block(-22,2,2,GRASS)
Block(-22,2,3,GRASS)
Block(-22,2,4,GRASS)
Block(-22,3,-1,GRASS)
Block(-22,3,0,GRASS)
Block(-22,3,1,GRASS)
Block(-21,-6,-5,STONE)
Block(-21,-6,-4,STONE)
Block(-21,-6,-3,STONE)
Block(-21,-5,-6,STONE)
Block(-21,-5,-5,STONE)
Block(-21,-5,-4,STONE)
Block(-21,-5,-3,STONE)
Block(-21,-5,-2,STONE)
Block(-21,-5,-1,STONE)
Block(-21,-5,0,STONE)
Block(-21,-5,1,STONE)
Block(-21,-5,2,STONE)
Block(-21,-5,3,STONE)
Block(-21,-5,4,STONE)
Block(-21,-5,5,STONE)
Block(-21,-5,6,STONE)
Block(-21,-4,-7,STONE)
Block(-21,-4,-6,STONE)
Block(-21,-4,-5,STONE)
Block(-21,-4,-4,STONE)
Block(-21,-4,-3,STONE)
Block(-21,-4,-2,STONE)
Block(-21,-4,-1,STONE)
Block(-21,-4,0,STONE)
Block(-21,-4,1,STONE)
Block(-21,-4,2,STONE)
Block(-21,-4,3,STONE)
Block(-21,-4,4,STONE)
Block(-21,-4,5,STONE)
Block(-21,-4,6,STONE)
Block(-21,-4,7,STONE)
Block(-21,-4,8,STONE)
Block(-21,-3,-7,DIRT)
Block(-21,-3,-6,STONE)
Block(-21,-3,-5,STONE)
Block(-21,-3,-4,STONE)
Block(-21,-3,-3,STONE)
Block(-21,-3,-2,STONE)
Block(-21,-3,-1,STONE)
Block(-21,-3,0,STONE)
Block(-21,-3,1,STONE)
Block(-21,-3,2,STONE)
Block(-21,-3,3,STONE)
Block(-21,-3,4,STONE)
Block(-21,-3,5,STONE)
Block(-21,-3,6,STONE)
Block(-21,-3,7,STONE)
Block(-21,-3,8,DIRT)
Block(-21,-3,9,DIRT)
Block(-21,-2,-8,DIRT)
Block(-21,-2,-7,DIRT)
Block(-21,-2,-6,DIRT)
Block(-21,-2,-5,STONE)
Block(-21,-2,-4,STONE)
Block(-21,-2,-3,STONE)
Block(-21,-2,-2,STONE)
Block(-21,-2,-1,STONE)
Block(-21,-2,0,STONE)
Block(-21,-2,1,STONE)
Block(-21,-2,2,STONE)
Block(-21,-2,3,STONE)
Block(-21,-2,4,STONE)
Block(-21,-2,5,STONE)
Block(-21,-2,6,DIRT)
Block(-21,-2,7,DIRT)
Block(-21,-2,8,DIRT)
Block(-21,-2,9,DIRT)
Block(-21,-1,-8,GRASS)
Block(-21,-1,-7,DIRT)
Block(-21,-1,-6,DIRT)
Block(-21,-1,-5,DIRT)
Block(-21,-1,-4,STONE)
Block(-21,-1,-3,STONE)
Block(-21,-1,-2,STONE)
Block(-21,-1,-1,STONE)
Block(-21,-1,0,STONE)
Block(-21,-1,1,STONE)
Block(-21,-1,2,STONE)
Block(-21,-1,3,STONE)
Block(-21,-1,4,STONE)
Block(-21,-1,5,STONE)
Block(-21,-1,6,DIRT)
Block(-21,-1,7,DIRT)
Block(-21,-1,8,DIRT)
Block(-21,-1,9,GRASS)
Block(-21,0,-7,GRASS)
Block(-21,0,-6,DIRT)
Block(-21,0,-5,DIRT)
Block(-21,0,-4,DIRT)
Block(-21,0,-3,DIRT)
Block(-21,0,-2,STONE)
Block(-21,0,-1,STONE)
Block(-21,0,0,STONE)
Block(-21,0,1,DIRT)
Block(-21,0,2,DIRT)
Block(-21,0,3,DIRT)
Block(-21,0,4,DIRT)
Block(-21,0,5,DIRT)
Block(-21,0,6,DIRT)
Block(-21,0,7,DIRT)
Block(-21,0,8,GRASS)
Block(-21,1,-6,GRASS)
Block(-21,1,-5,DIRT)
Block(-21,1,-4,DIRT)
Block(-21,1,-3,DIRT)
Block(-21,1,-2,DIRT)
Block(-21,1,-1,DIRT)
Block(-21,1,0,DIRT)
Block(-21,1,1,DIRT)
Block(-21,1,2,DIRT)
Block(-21,1,3,DIRT)
Block(-21,1,4,DIRT)
Block(-21,1,5,DIRT)
Block(-21,1,6,GRASS)
Block(-21,1,7,GRASS)
Block(-21,2,-5,GRASS)
Block(-21,2,-4,DIRT)
Block(-21,2,-3,DIRT)
Block(-21,2,-2,DIRT)
Block(-21,2,-1,DIRT)
Block(-21,2,0,DIRT)
Block(-21,2,1,DIRT)
Block(-21,2,2,DIRT)
Block(-21,2,3,DIRT)
Block(-21,2,4,DIRT)
Block(-21,2,5,DIRT)
Block(-21,3,-4,GRASS)
Block(-21,3,-3,GRASS)
Block(-21,3,-2,DIRT)
Block(-21,3,-1,DIRT)
Block(-21,3,0,DIRT)
Block(-21,3,1,GRASS)
Block(-21,3,2,GRASS)
Block(-21,3,3,GRASS)
Block(-21,3,4,GRASS)
Block(-21,3,5,GRASS)
Block(-21,4,-2,GRASS)
Block(-21,4,-1,GRASS)
Block(-21,4,0,GRASS)
Block(-20,-8,-3,STONE)
Block(-20,-7,-5,STONE)
Block(-20,-7,-4,STONE)
Block(-20,-7,-3,STONE)
Block(-20,-7,-2,STONE)
Block(-20,-6,-6,STONE)
Block(-20,-6,-5,STONE)
Block(-20,-6,-4,STONE)
Block(-20,-6,-3,STONE)
Block(-20,-6,-2,STONE)
Block(-20,-6,-1,STONE)
Block(-20,-6,0,STONE)
Block(-20,-6,1,STONE)
Block(-20,-6,2,STONE)
Block(-20,-6,3,STONE)
Block(-20,-5,-7,STONE)
Block(-20,-5,-6,STONE)
Block(-20,-5,-5,STONE)
Block(-20,-5,-4,STONE)
Block(-20,-5,-3,STONE)
Block(-20,-5,-2,STONE)
Block(-20,-5,-1,STONE)
Block(-20,-5,0,STONE)
Block(-20,-5,1,STONE)
Block(-20,-5,2,STONE)
Block(-20,-5,3,STONE)
Block(-20,-5,4,STONE)
Block(-20,-5,5,STONE)
Block(-20,-5,6,STONE)
Block(-20,-5,7,STONE)
Block(-20,-5,8,STONE)
Block(-20,-4,-8,STONE)
Block(-20,-4,-7,STONE)
Block(-20,-4,-6,STONE)
Block(-20,-4,-5,STONE)
Block(-20,-4,-4,STONE)
Block(-20,-4,-3,STONE)
Block(-20,-4,-2,STONE)
Block(-20,-4,-1,STONE)
Block(-20,-4,0,STONE)
Block(-20,-4,1,STONE)
Block(-20,-4,2,STONE)
Block(-20,-4,3,STONE)
Block(-20,-4,4,STONE)
Block(-20,-4,5,STONE)
Block(-20,-4,6,STONE)
Block(-20,-4,7,STONE)
Block(-20,-4,8,STONE)
Block(-20,-4,9,STONE)
Block(-20,-3,-8,DIRT)
Block(-20,-3,-7,STONE)
Block(-20,-3,-6,STONE)
Block(-20,-3,-5,STONE)
Block(-20,-3,-4,STONE)
Block(-20,-3,-3,STONE)
Block(-20,-3,-2,STONE)
Block(-20,-3,-1,STONE)
Block(-20,-3,0,STONE)
Block(-20,-3,1,STONE)
Block(-20,-3,2,STONE)
Block(-20,-3,3,STONE)
Block(-20,-3,4,STONE)
Block(-20,-3,5,STONE)
Block(-20,-3,6,STONE)
Block(-20,-3,7,STONE)
Block(-20,-3,8,STONE)
Block(-20,-3,9,STONE)
Block(-20,-3,10,DIRT)
Block(-20,-2,-9,DIRT)
Block(-20,-2,-8,DIRT)
Block(-20,-2,-7,DIRT)
Block(-20,-2,-6,STONE)
Block(-20,-2,-5,STONE)
Block(-20,-2,-4,STONE)
Block(-20,-2,-3,STONE)
Block(-20,-2,-2,STONE)
Block(-20,-2,-1,STONE)
Block(-20,-2,0,STONE)
Block(-20,-2,1,STONE)
Block(-20,-2,2,STONE)
Block(-20,-2,3,STONE)
Block(-20,-2,4,STONE)
Block(-20,-2,5,STONE)
Block(-20,-2,6,STONE)
Block(-20,-2,7,STONE)
Block(-20,-2,8,STONE)
Block(-20,-2,9,DIRT)
Block(-20,-2,10,DIRT)
Block(-20,-1,-9,GRASS)
Block(-20,-1,-8,DIRT)
Block(-20,-1,-7,DIRT)
Block(-20,-1,-6,DIRT)
Block(-20,-1,-5,STONE)
Block(-20,-1,-4,STONE)
Block(-20,-1,-3,STONE)
Block(-20,-1,-2,STONE)
Block(-20,-1,-1,STONE)
Block(-20,-1,0,STONE)
Block(-20,-1,1,STONE)
Block(-20,-1,2,STONE)
Block(-20,-1,3,STONE)
Block(-20,-1,4,STONE)
Block(-20,-1,5,STONE)
Block(-20,-1,6,STONE)
Block(-20,-1,7,STONE)
Block(-20,-1,8,DIRT)
Block(-20,-1,9,DIRT)
Block(-20,-1,10,GRASS)
Block(-20,0,-8,GRASS)
Block(-20,0,-7,DIRT)
Block(-20,0,-6,DIRT)
Block(-20,0,-5,DIRT)
Block(-20,0,-4,DIRT)
Block(-20,0,-3,STONE)
Block(-20,0,-2,STONE)
Block(-20,0,-1,STONE)
Block(-20,0,0,STONE)
Block(-20,0,1,STONE)
Block(-20,0,2,DIRT)
Block(-20,0,3,STONE)
Block(-20,0,4,STONE)
Block(-20,0,5,STONE)
Block(-20,0,6,DIRT)
Block(-20,0,7,DIRT)
Block(-20,0,8,DIRT)
Block(-20,0,9,DIRT)
Block(-20,1,-7,GRASS)
Block(-20,1,-6,DIRT)
Block(-20,1,-5,DIRT)
Block(-20,1,-4,DIRT)
Block(-20,1,-3,DIRT)
Block(-20,1,-2,STONE)
Block(-20,1,-1,STONE)
Block(-20,1,0,DIRT)
Block(-20,1,1,DIRT)
Block(-20,1,2,DIRT)
Block(-20,1,3,DIRT)
Block(-20,1,4,DIRT)
Block(-20,1,5,DIRT)
Block(-20,1,6,DIRT)
Block(-20,1,7,DIRT)
Block(-20,1,8,DIRT)
Block(-20,1,9,GRASS)
Block(-20,2,-6,GRASS)
Block(-20,2,-5,DIRT)
Block(-20,2,-4,DIRT)
Block(-20,2,-3,DIRT)
Block(-20,2,-2,DIRT)
Block(-20,2,-1,DIRT)
Block(-20,2,0,DIRT)
Block(-20,2,1,DIRT)
Block(-20,2,2,DIRT)
Block(-20,2,3,DIRT)
Block(-20,2,4,DIRT)
Block(-20,2,5,DIRT)
Block(-20,2,6,DIRT)
Block(-20,2,7,DIRT)
Block(-20,2,8,GRASS)
Block(-20,3,-5,GRASS)
Block(-20,3,-4,GRASS)
Block(-20,3,-3,DIRT)
Block(-20,3,-2,DIRT)
Block(-20,3,-1,DIRT)
Block(-20,3,0,DIRT)
Block(-20,3,1,DIRT)
Block(-20,3,2,GRASS)
Block(-20,3,3,DIRT)
Block(-20,3,4,DIRT)
Block(-20,3,5,DIRT)
Block(-20,3,6,GRASS)
Block(-20,3,7,GRASS)
Block(-20,4,-3,GRASS)
Block(-20,4,-2,DIRT)
Block(-20,4,-1,DIRT)
Block(-20,4,0,GRASS)
Block(-20,4,1,GRASS)
Block(-20,4,3,GRASS)
Block(-20,4,4,GRASS)
Block(-20,4,5,GRASS)
Block(-20,5,-2,GRASS)
Block(-20,5,-1,GRASS)
Block(-19,-9,-3,STONE)
Block(-19,-9,-2,STONE)
Block(-19,-8,-5,STONE)
Block(-19,-8,-4,STONE)
Block(-19,-8,-3,STONE)
Block(-19,-8,-2,STONE)
Block(-19,-8,-1,STONE)
Block(-19,-7,-6,STONE)
Block(-19,-7,-5,STONE)
Block(-19,-7,-4,STONE)
Block(-19,-7,-3,STONE)
Block(-19,-7,-2,STONE)
Block(-19,-7,-1,STONE)
Block(-19,-7,0,STONE)
Block(-19,-6,-6,STONE)
Block(-19,-6,-5,STONE)
Block(-19,-6,-4,STONE)
Block(-19,-6,-3,STONE)
Block(-19,-6,-2,STONE)
Block(-19,-6,-1,STONE)
Block(-19,-6,0,STONE)
Block(-19,-6,1,STONE)
Block(-19,-6,2,STONE)
Block(-19,-6,3,STONE)
Block(-19,-6,4,STONE)
Block(-19,-5,-7,STONE)
Block(-19,-5,-6,STONE)
Block(-19,-5,-5,STONE)
Block(-19,-5,-4,STONE)
Block(-19,-5,-3,STONE)
Block(-19,-5,-2,STONE)
Block(-19,-5,-1,STONE)
Block(-19,-5,0,STONE)
Block(-19,-5,1,STONE)
Block(-19,-5,2,STONE)
Block(-19,-5,3,STONE)
Block(-19,-5,4,STONE)
Block(-19,-5,5,STONE)
Block(-19,-5,6,STONE)
Block(-19,-5,7,STONE)
Block(-19,-5,8,STONE)
Block(-19,-5,9,STONE)
Block(-19,-4,-8,STONE)
Block(-19,-4,-7,STONE)
Block(-19,-4,-6,STONE)
Block(-19,-4,-5,STONE)
Block(-19,-4,-4,STONE)
Block(-19,-4,-3,STONE)
Block(-19,-4,-2,STONE)
Block(-19,-4,-1,STONE)
Block(-19,-4,0,STONE)
Block(-19,-4,1,STONE)
Block(-19,-4,2,STONE)
Block(-19,-4,3,STONE)
Block(-19,-4,4,STONE)
Block(-19,-4,5,STONE)
Block(-19,-4,6,STONE)
Block(-19,-4,7,STONE)
Block(-19,-4,8,STONE)
Block(-19,-4,9,STONE)
Block(-19,-4,10,STONE)
Block(-19,-3,-10,DIRT)
Block(-19,-3,-9,DIRT)
Block(-19,-3,-8,STONE)
Block(-19,-3,-7,STONE)
Block(-19,-3,-6,STONE)
Block(-19,-3,-5,STONE)
Block(-19,-3,-4,STONE)
Block(-19,-3,-3,STONE)
Block(-19,-3,-2,STONE)
Block(-19,-3,-1,STONE)
Block(-19,-3,0,STONE)
Block(-19,-3,1,STONE)
Block(-19,-3,2,STONE)
Block(-19,-3,3,STONE)
Block(-19,-3,4,STONE)
Block(-19,-3,5,STONE)
Block(-19,-3,6,STONE)
Block(-19,-3,7,STONE)
Block(-19,-3,8,STONE)
Block(-19,-3,9,STONE)
Block(-19,-3,10,STONE)
Block(-19,-3,11,DIRT)
Block(-19,-2,-10,DIRT)
Block(-19,-2,-9,DIRT)
Block(-19,-2,-8,DIRT)
Block(-19,-2,-7,STONE)
Block(-19,-2,-6,STONE)
Block(-19,-2,-5,STONE)
Block(-19,-2,-4,STONE)
Block(-19,-2,-3,STONE)
Block(-19,-2,-2,STONE)
Block(-19,-2,-1,STONE)
Block(-19,-2,0,STONE)
Block(-19,-2,1,STONE)
Block(-19,-2,2,STONE)
Block(-19,-2,3,STONE)
Block(-19,-2,4,STONE)
Block(-19,-2,5,STONE)
Block(-19,-2,6,STONE)
Block(-19,-2,7,STONE)
Block(-19,-2,8,STONE)
Block(-19,-2,9,STONE)
Block(-19,-2,10,DIRT)
Block(-19,-2,11,DIRT)
Block(-19,-1,-10,GRASS)
Block(-19,-1,-9,DIRT)
Block(-19,-1,-8,DIRT)
Block(-19,-1,-7,DIRT)
Block(-19,-1,-6,STONE)
Block(-19,-1,-5,STONE)
Block(-19,-1,-4,STONE)
Block(-19,-1,-3,STONE)
Block(-19,-1,-2,STONE)
Block(-19,-1,-1,STONE)
Block(-19,-1,0,STONE)
Block(-19,-1,1,STONE)
Block(-19,-1,2,STONE)
Block(-19,-1,3,STONE)
Block(-19,-1,4,STONE)
Block(-19,-1,5,STONE)
Block(-19,-1,6,STONE)
Block(-19,-1,7,STONE)
Block(-19,-1,8,STONE)
Block(-19,-1,9,STONE)
Block(-19,-1,10,DIRT)
Block(-19,-1,11,GRASS)
Block(-19,0,-9,GRASS)
Block(-19,0,-8,DIRT)
Block(-19,0,-7,DIRT)
Block(-19,0,-6,DIRT)
Block(-19,0,-5,STONE)
Block(-19,0,-4,STONE)
Block(-19,0,-3,STONE)
Block(-19,0,-2,STONE)
Block(-19,0,-1,STONE)
Block(-19,0,0,STONE)
Block(-19,0,1,STONE)
Block(-19,0,2,STONE)
Block(-19,0,3,STONE)
Block(-19,0,4,STONE)
Block(-19,0,5,STONE)
Block(-19,0,6,STONE)
Block(-19,0,7,STONE)
Block(-19,0,8,STONE)
Block(-19,0,9,DIRT)
Block(-19,0,10,DIRT)
Block(-19,1,-8,GRASS)
Block(-19,1,-7,DIRT)
Block(-19,1,-6,DIRT)
Block(-19,1,-5,DIRT)
Block(-19,1,-4,STONE)
Block(-19,1,-3,STONE)
Block(-19,1,-2,STONE)
Block(-19,1,-1,STONE)
Block(-19,1,0,STONE)
Block(-19,1,1,DIRT)
Block(-19,1,2,DIRT)
Block(-19,1,3,STONE)
Block(-19,1,4,STONE)
Block(-19,1,5,STONE)
Block(-19,1,6,STONE)
Block(-19,1,7,DIRT)
Block(-19,1,8,WOOD:2)
Block(-19,1,9,DIRT)
Block(-19,1,10,GRASS)
Block(-19,2,-7,GRASS)
Block(-19,2,-6,DIRT)
Block(-19,2,-5,DIRT)
Block(-19,2,-4,DIRT)
Block(-19,2,-3,STONE)
Block(-19,2,-2,STONE)
Block(-19,2,-1,STONE)
Block(-19,2,0,STONE)
Block(-19,2,1,DIRT)
Block(-19,2,2,DIRT)
Block(-19,2,3,DIRT)
Block(-19,2,4,STONE)
Block(-19,2,5,STONE)
Block(-19,2,6,WOOD:2)
Block(-19,2,7,WOOD:2)
Block(-19,2,8,DIRT)
Block(-19,2,9,DIRT)
Block(-19,3,-6,GRASS)
Block(-19,3,-5,DIRT)
Block(-19,3,-4,DIRT)
Block(-19,3,-3,DIRT)
Block(-19,3,-2,STONE)
Block(-19,3,-1,STONE)
Block(-19,3,0,DIRT)
Block(-19,3,1,DIRT)
Block(-19,3,2,DIRT)
Block(-19,3,3,DIRT)
Block(-19,3,4,DIRT)
Block(-19,3,5,DIRT)
Block(-19,3,6,WOOD:2)
Block(-19,3,7,WOOD:2)
Block(-19,3,8,DIRT)
Block(-19,3,9,GRASS)
Block(-19,4,-5,GRASS)
Block(-19,4,-4,DIRT)
Block(-19,4,-3,DIRT)
Block(-19,4,-2,DIRT)
Block(-19,4,-1,DIRT)
Block(-19,4,0,DIRT)
Block(-19,4,1,GRASS)
Block(-19,4,2,GRASS)
Block(-19,4,3,DIRT)
Block(-19,4,4,DIRT)
Block(-19,4,5,DIRT)
Block(-19,4,6,DIRT)
Block(-19,4,7,GRASS)
Block(-19,4,8,GRASS)
Block(-19,5,-4,GRASS)
Block(-19,5,-3,DIRT)
Block(-19,5,-2,DIRT)
Block(-19,5,-1,DIRT)
Block(-19,5,0,DIRT)
Block(-19,5,3,GRASS)
Block(-19,5,4,DIRT)
Block(-19,5,5,DIRT)
Block(-19,5,6,GRASS)
Block(-19,6,-3,GRASS)
Block(-19,6,-2,DIRT)
Block(-19,6,-1,DIRT)
Block(-19,6,0,GRASS)
Block(-19,6,4,GRASS)
Block(-19,6,5,GRASS)
Block(-19,7,-2,GRASS)
Block(-19,7,-1,GRASS)
Block(-18,-10,-3,STONE)
Block(-18,-10,-2,STONE)
Block(-18,-9,-5,STONE)
Block(-18,-9,-4,STONE)
Block(-18,-9,-3,STONE)
Block(-18,-9,-2,STONE)
Block(-18,-9,-1,STONE)
Block(-18,-8,-5,STONE)
Block(-18,-8,-4,STONE)
Block(-18,-8,-3,STONE)
Block(-18,-8,-2,STONE)
Block(-18,-8,-1,STONE)
Block(-18,-8,0,STONE)
Block(-18,-7,-6,STONE)
Block(-18,-7,-5,STONE)
Block(-18,-7,-4,STONE)
Block(-18,-7,-3,STONE)
Block(-18,-7,-2,STONE)
Block(-18,-7,-1,STONE)
Block(-18,-7,0,STONE)
Block(-18,-7,1,STONE)
Block(-18,-7,2,STONE)
Block(-18,-7,3,STONE)
Block(-18,-6,-7,STONE)
Block(-18,-6,-6,STONE)
Block(-18,-6,-5,STONE)
Block(-18,-6,-4,STONE)
Block(-18,-6,-3,STONE)
Block(-18,-6,-2,STONE)
Block(-18,-6,-1,STONE)
Block(-18,-6,0,STONE)
Block(-18,-6,1,STONE)
Block(-18,-6,2,STONE)
Block(-18,-6,3,STONE)
Block(-18,-6,4,STONE)
Block(-18,-6,5,STONE)
Block(-18,-6,10,STONE)
Block(-18,-5,-8,STONE)
Block(-18,-5,-7,STONE)
Block(-18,-5,-6,STONE)
Block(-18,-5,-5,STONE)
Block(-18,-5,-4,STONE)
Block(-18,-5,-3,STONE)
Block(-18,-5,-2,STONE)
Block(-18,-5,-1,STONE)
Block(-18,-5,0,STONE)
Block(-18,-5,1,STONE)
Block(-18,-5,2,STONE)
Block(-18,-5,3,STONE)
Block(-18,-5,4,STONE)
Block(-18,-5,5,STONE)
Block(-18,-5,6,STONE)
Block(-18,-5,7,STONE)
Block(-18,-5,8,STONE)
Block(-18,-5,9,STONE)
Block(-18,-5,10,STONE)
Block(-18,-5,11,STONE)
Block(-18,-4,-9,STONE)
Block(-18,-4,-8,STONE)
Block(-18,-4,-7,STONE)
Block(-18,-4,-6,STONE)
Block(-18,-4,-5,STONE)
Block(-18,-4,-4,STONE)
Block(-18,-4,-3,STONE)
Block(-18,-4,-2,STONE)
Block(-18,-4,-1,STONE)
Block(-18,-4,0,STONE)
Block(-18,-4,1,STONE)
Block(-18,-4,2,STONE)
Block(-18,-4,3,STONE)
Block(-18,-4,4,STONE)
Block(-18,-4,5,STONE)
Block(-18,-4,6,STONE)
Block(-18,-4,7,STONE)
Block(-18,-4,8,STONE)
Block(-18,-4,9,STONE)
Block(-18,-4,10,STONE)
Block(-18,-4,11,STONE)
Block(-18,-4,12,DIRT)
Block(-18,-3,-10,DIRT)
Block(-18,-3,-9,STONE)
Block(-18,-3,-8,STONE)
Block(-18,-3,-7,STONE)
Block(-18,-3,-6,STONE)
Block(-18,-3,-5,STONE)
Block(-18,-3,-4,STONE)
Block(-18,-3,-3,STONE)
Block(-18,-3,-2,STONE)
Block(-18,-3,-1,STONE)
Block(-18,-3,0,STONE)
Block(-18,-3,1,STONE)
Block(-18,-3,2,STONE)
Block(-18,-3,3,STONE)
Block(-18,-3,4,STONE)
Block(-18,-3,5,STONE)
Block(-18,-3,6,STONE)
Block(-18,-3,7,STONE)
Block(-18,-3,8,STONE)
Block(-18,-3,9,STONE)
Block(-18,-3,10,STONE)
Block(-18,-3,11,DIRT)
Block(-18,-3,12,DIRT)
Block(-18,-2,-11,DIRT)
Block(-18,-2,-10,DIRT)
Block(-18,-2,-9,DIRT)
Block(-18,-2,-8,STONE)
Block(-18,-2,-7,STONE)
Block(-18,-2,-6,STONE)
Block(-18,-2,-5,STONE)
Block(-18,-2,-4,STONE)
Block(-18,-2,-3,STONE)
Block(-18,-2,-2,STONE)
Block(-18,-2,-1,STONE)
Block(-18,-2,0,STONE)
Block(-18,-2,1,STONE)
Block(-18,-2,2,STONE)
Block(-18,-2,3,STONE)
Block(-18,-2,4,STONE)
Block(-18,-2,5,STONE)
Block(-18,-2,6,STONE)
Block(-18,-2,7,STONE)
Block(-18,-2,8,STONE)
Block(-18,-2,9,STONE)
Block(-18,-2,10,STONE)
Block(-18,-2,11,DIRT)
Block(-18,-2,12,DIRT)
Block(-18,-1,-11,GRASS)
Block(-18,-1,-10,DIRT)
Block(-18,-1,-9,DIRT)
Block(-18,-1,-8,DIRT)
Block(-18,-1,-7,STONE)
Block(-18,-1,-6,STONE)
Block(-18,-1,-5,STONE)
Block(-18,-1,-4,STONE)
Block(-18,-1,-3,STONE)
Block(-18,-1,-2,AIR)
Block(-18,-1,-1,STONE)
Block(-18,-1,0,STONE)
Block(-18,-1,1,STONE)
Block(-18,-1,2,STONE)
Block(-18,-1,3,STONE)
Block(-18,-1,4,STONE)
Block(-18,-1,5,STONE)
Block(-18,-1,6,STONE)
Block(-18,-1,7,STONE)
Block(-18,-1,8,STONE)
Block(-18,-1,9,STONE)
Block(-18,-1,10,DIRT)
Block(-18,-1,11,DIRT)
Block(-18,-1,12,GRASS)
Block(-18,0,-10,GRASS)
Block(-18,0,-9,DIRT)
Block(-18,0,-8,DIRT)
Block(-18,0,-7,DIRT)
Block(-18,0,-6,STONE)
Block(-18,0,-5,STONE)
Block(-18,0,-4,WOOD:2)
Block(-18,0,-3,WOOD:2)
Block(-18,0,-2,WOOD:2)
Block(-18,0,-1,WOOD:2)
Block(-18,0,0,WOOD:2)
Block(-18,0,1,WOOD:2)
Block(-18,0,2,STONE)
Block(-18,0,3,STONE)
Block(-18,0,4,WOOD:2)
Block(-18,0,5,WOOD:2)
Block(-18,0,6,WOOD:2)
Block(-18,0,7,WOOD:2)
Block(-18,0,8,WOOD:2)
Block(-18,0,9,STONE)
Block(-18,0,10,DIRT)
Block(-18,0,11,GRASS)
Block(-18,1,-9,GRASS)
Block(-18,1,-8,DIRT)
Block(-18,1,-7,DIRT)
Block(-18,1,-6,DIRT)
Block(-18,1,-5,WOOD:2)
Block(-18,1,-4,WOOD:2)
Block(-18,1,-3,WOOD:2)
Block(-18,1,-2,WOOD:2)
Block(-18,1,-1,WOOD:2)
Block(-18,1,0,WOOD:2)
Block(-18,1,1,WOOD:2)
Block(-18,1,2,WOOD:2)
Block(-18,1,3,WOOD:5)
Block(-18,1,4,WOOD:2)
Block(-18,1,5,WOOD:2)
Block(-18,1,6,WOOD:2)
Block(-18,1,7,WOOD:2)
Block(-18,1,8,WOOD:2)
Block(-18,1,9,DIRT)
Block(-18,1,10,DIRT)
Block(-18,2,-8,GRASS)
Block(-18,2,-7,DIRT)
Block(-18,2,-6,DIRT)
Block(-18,2,-5,WOOD:2)
Block(-18,2,-4,WOOD:2)
Block(-18,2,-3,WOOD:2)
Block(-18,2,-2,WOOD:2)
Block(-18,2,-1,WOOD:2)
Block(-18,2,0,WOOD:2)
Block(-18,2,1,WOOD:2)
Block(-18,2,2,WOOD:2)
Block(-18,2,3,WOOD:5)
Block(-18,2,4,WOOD:2)
Block(-18,2,5,WOOD:2)
Block(-18,2,6,DARK_OAK_FENCE)
Block(-18,2,7,DARK_OAK_FENCE)
Block(-18,2,8,WOOD:2)
Block(-18,2,9,DIRT)
Block(-18,2,10,GRASS)
Block(-18,3,-7,GRASS)
Block(-18,3,-6,DIRT)
Block(-18,3,-5,WOOD:2)
Block(-18,3,-4,WOOD:2)
Block(-18,3,-3,WOOD:2)
Block(-18,3,-2,WOOD:2)
Block(-18,3,-1,WOOD:2)
Block(-18,3,0,WOOD:2)
Block(-18,3,1,WOOD:2)
Block(-18,3,2,WOOD:2)
Block(-18,3,3,WOOD:2)
Block(-18,3,4,WOOD:2)
Block(-18,3,5,WOOD:2)
Block(-18,3,6,50)
Block(-18,3,7,50)
Block(-18,3,8,WOOD:2)
Block(-18,3,9,DIRT)
Block(-18,4,-6,GRASS)
Block(-18,4,-5,WOOD:2)
Block(-18,4,-4,WOOD:2)
Block(-18,4,-3,WOOD:2)
Block(-18,4,-2,WOOD:2)
Block(-18,4,-1,WOOD:2)
Block(-18,4,0,WOOD:2)
Block(-18,4,1,WOOD:2)
Block(-18,4,2,WOOD:2)
Block(-18,4,3,GOLD_BLOCK)
Block(-18,4,4,WOOD:2)
Block(-18,4,5,WOOD:2)
Block(-18,4,6,WOOD:2)
Block(-18,4,7,WOOD:2)
Block(-18,4,8,WOOD:2)
Block(-18,4,9,GRASS)
Block(-18,5,-5,GRASS)
Block(-18,5,-4,DIRT)
Block(-18,5,-3,DIRT)
Block(-18,5,-2,DIRT)
Block(-18,5,-1,DIRT)
Block(-18,5,0,DIRT)
Block(-18,5,1,DIRT)
Block(-18,5,2,GRASS)
Block(-18,5,3,WOOD:2)
Block(-18,5,4,DIRT)
Block(-18,5,5,DIRT)
Block(-18,5,6,DIRT)
Block(-18,5,7,GRASS)
Block(-18,5,8,GRASS)
Block(-18,6,-4,GRASS)
Block(-18,6,-3,DIRT)
Block(-18,6,-2,DIRT)
Block(-18,6,-1,DIRT)
Block(-18,6,0,DIRT)
Block(-18,6,1,GRASS)
Block(-18,6,3,GRASS)
Block(-18,6,4,DIRT)
Block(-18,6,5,DIRT)
Block(-18,6,6,GRASS)
Block(-18,7,-3,GRASS)
Block(-18,7,-2,GRASS)
Block(-18,7,-1,DIRT)
Block(-18,7,0,DIRT)
Block(-18,7,4,GRASS)
Block(-18,7,5,GRASS)
Block(-18,8,-1,GRASS)
Block(-18,8,0,GRASS)
Block(-17,-10,-4,STONE)
Block(-17,-10,-3,STONE)
Block(-17,-10,-2,STONE)
Block(-17,-10,-1,STONE)
Block(-17,-9,-5,STONE)
Block(-17,-9,-4,STONE)
Block(-17,-9,-3,STONE)
Block(-17,-9,-2,STONE)
Block(-17,-9,-1,STONE)
Block(-17,-8,-6,STONE)
Block(-17,-8,-5,STONE)
Block(-17,-8,-4,STONE)
Block(-17,-8,-3,STONE)
Block(-17,-8,-2,STONE)
Block(-17,-8,-1,STONE)
Block(-17,-8,0,STONE)
Block(-17,-8,1,STONE)
Block(-17,-8,2,STONE)
Block(-17,-8,3,STONE)
Block(-17,-7,-6,STONE)
Block(-17,-7,-5,STONE)
Block(-17,-7,-4,STONE)
Block(-17,-7,-3,STONE)
Block(-17,-7,-2,STONE)
Block(-17,-7,-1,STONE)
Block(-17,-7,0,STONE)
Block(-17,-7,1,STONE)
Block(-17,-7,2,STONE)
Block(-17,-7,3,STONE)
Block(-17,-7,4,STONE)
Block(-17,-7,5,STONE)
Block(-17,-6,-7,STONE)
Block(-17,-6,-6,STONE)
Block(-17,-6,-5,STONE)
Block(-17,-6,-4,STONE)
Block(-17,-6,-3,STONE)
Block(-17,-6,-2,STONE)
Block(-17,-6,-1,STONE)
Block(-17,-6,0,STONE)
Block(-17,-6,1,STONE)
Block(-17,-6,2,STONE)
Block(-17,-6,3,STONE)
Block(-17,-6,4,STONE)
Block(-17,-6,5,STONE)
Block(-17,-6,6,STONE)
Block(-17,-6,7,STONE)
Block(-17,-6,8,STONE)
Block(-17,-6,9,STONE)
Block(-17,-6,10,STONE)
Block(-17,-5,-9,STONE)
Block(-17,-5,-8,STONE)
Block(-17,-5,-7,STONE)
Block(-17,-5,-6,STONE)
Block(-17,-5,-5,STONE)
Block(-17,-5,-4,STONE)
Block(-17,-5,-3,STONE)
Block(-17,-5,-2,STONE)
Block(-17,-5,-1,STONE)
Block(-17,-5,0,STONE)
Block(-17,-5,1,STONE)
Block(-17,-5,2,STONE)
Block(-17,-5,3,STONE)
Block(-17,-5,4,STONE)
Block(-17,-5,5,STONE)
Block(-17,-5,6,STONE)
Block(-17,-5,7,STONE)
Block(-17,-5,8,STONE)
Block(-17,-5,9,STONE)
Block(-17,-5,10,STONE)
Block(-17,-5,11,STONE)
Block(-17,-5,12,STONE)
Block(-17,-4,-10,STONE)
Block(-17,-4,-9,STONE)
Block(-17,-4,-8,STONE)
Block(-17,-4,-7,STONE)
Block(-17,-4,-6,STONE)
Block(-17,-4,-5,STONE)
Block(-17,-4,-4,STONE)
Block(-17,-4,-3,STONE)
Block(-17,-4,-2,STONE)
Block(-17,-4,-1,STONE)
Block(-17,-4,0,STONE)
Block(-17,-4,1,STONE)
Block(-17,-4,2,STONE)
Block(-17,-4,3,STONE)
Block(-17,-4,4,STONE)
Block(-17,-4,5,STONE)
Block(-17,-4,6,STONE)
Block(-17,-4,7,STONE)
Block(-17,-4,8,STONE)
Block(-17,-4,9,STONE)
Block(-17,-4,10,STONE)
Block(-17,-4,11,STONE)
Block(-17,-4,12,STONE)
Block(-17,-3,-11,DIRT)
Block(-17,-3,-10,STONE)
Block(-17,-3,-9,STONE)
Block(-17,-3,-8,STONE)
Block(-17,-3,-7,STONE)
Block(-17,-3,-6,STONE)
Block(-17,-3,-5,STONE)
Block(-17,-3,-4,STONE)
Block(-17,-3,-3,STONE)
Block(-17,-3,-2,STONE)
Block(-17,-3,-1,STONE)
Block(-17,-3,0,STONE)
Block(-17,-3,1,STONE)
Block(-17,-3,2,STONE)
Block(-17,-3,3,STONE)
Block(-17,-3,4,STONE)
Block(-17,-3,5,STONE)
Block(-17,-3,6,STONE)
Block(-17,-3,7,STONE)
Block(-17,-3,8,STONE)
Block(-17,-3,9,STONE)
Block(-17,-3,10,STONE)
Block(-17,-3,11,STONE)
Block(-17,-3,12,STONE)
Block(-17,-3,13,DIRT)
Block(-17,-2,-11,DIRT)
Block(-17,-2,-10,DIRT)
Block(-17,-2,-9,STONE)
Block(-17,-2,-8,STONE)
Block(-17,-2,-7,STONE)
Block(-17,-2,-6,STONE)
Block(-17,-2,-5,STONE)
Block(-17,-2,-4,STONE)
Block(-17,-2,-3,STONE)
Block(-17,-2,-2,STONE)
Block(-17,-2,-1,STONE)
Block(-17,-2,0,STONE)
Block(-17,-2,1,STONE)
Block(-17,-2,2,STONE)
Block(-17,-2,3,STONE)
Block(-17,-2,4,STONE)
Block(-17,-2,5,STONE)
Block(-17,-2,6,STONE)
Block(-17,-2,7,STONE)
Block(-17,-2,8,STONE)
Block(-17,-2,9,STONE)
Block(-17,-2,10,STONE)
Block(-17,-2,11,STONE)
Block(-17,-2,12,DIRT)
Block(-17,-2,13,DIRT)
Block(-17,-1,-11,GRASS)
Block(-17,-1,-10,DIRT)
Block(-17,-1,-9,DIRT)
Block(-17,-1,-8,STONE)
Block(-17,-1,-7,STONE)
Block(-17,-1,-6,STONE)
Block(-17,-1,-5,STONE)
Block(-17,-1,-4,WOOD:5)
Block(-17,-1,-3,WOOD:5)
Block(-17,-1,-2,WOOD:5)
Block(-17,-1,-1,WOOD:5)
Block(-17,-1,0,WOOD:5)
Block(-17,-1,1,WOOD:5)
Block(-17,-1,2,STONE)
Block(-17,-1,3,STONE)
Block(-17,-1,4,WOOD:5)
Block(-17,-1,5,WOOD:5)
Block(-17,-1,6,WOOD:5)
Block(-17,-1,7,WOOD:5)
Block(-17,-1,8,WOOD:5)
Block(-17,-1,9,STONE)
Block(-17,-1,10,STONE)
Block(-17,-1,11,STONE)
Block(-17,-1,12,DIRT)
Block(-17,-1,13,GRASS)
Block(-17,0,-10,DIRT)
Block(-17,0,-9,DIRT)
Block(-17,0,-8,DIRT)
Block(-17,0,-7,STONE)
Block(-17,0,-6,STONE)
Block(-17,0,-5,WOOD:2)
Block(-17,0,-4,AIR)
Block(-17,0,-3,WOOD)
Block(-17,0,-2,WOOD_STEP:8)
Block(-17,0,-1,WOOD_STEP:8)
Block(-17,0,0,WOOD)
Block(-17,0,1,AIR)
Block(-17,0,2,WOOD:5)
Block(-17,0,3,WOOD:5)
Block(-17,0,4,WOOD:2)
Block(-17,0,5,WOOD:5)
Block(-17,0,6,WOOD:5)
Block(-17,0,7,WOOD:5)
Block(-17,0,8,WOOD:5)
Block(-17,0,9,WOOD:2)
Block(-17,0,10,WOOD:2)
Block(-17,0,11,DIRT)
Block(-17,0,12,DIRT)
Block(-17,1,-10,GRASS)
Block(-17,1,-9,DIRT)
Block(-17,1,-8,DIRT)
Block(-17,1,-7,DIRT)
Block(-17,1,-6,STONE)
Block(-17,1,-5,WOOD:2)
Block(-17,1,-4,AIR)
Block(-17,1,-3,JACK_O_LANTERN:3)
Block(-17,1,-2,AIR)
Block(-17,1,-1,AIR)
Block(-17,1,0,BOOKSHELF)
Block(-17,1,1,AIR)
Block(-17,1,2,WOOD:5)
Block(-17,1,3,WOOD:5)
Block(-17,1,4,WOOD:2)
Block(-17,1,5,DARK_OAK_STAIRS:1)
Block(-17,1,6,DARK_OAK_STAIRS:1)
Block(-17,1,7,DARK_OAK_STAIRS:1)
Block(-17,1,8,DARK_OAK_STAIRS:1)
Block(-17,1,9,WOOD:2)
Block(-17,1,10,DIRT)
Block(-17,1,11,DIRT)
Block(-17,1,12,GRASS)
Block(-17,2,-9,GRASS)
Block(-17,2,-8,DIRT)
Block(-17,2,-7,DIRT)
Block(-17,2,-6,DIRT)
Block(-17,2,-5,WOOD:2)
Block(-17,2,-4,AIR)
Block(-17,2,-3,AIR)
Block(-17,2,-2,AIR)
Block(-17,2,-1,AIR)
Block(-17,2,0,BOOKSHELF)
Block(-17,2,1,AIR)
Block(-17,2,2,WEB)
Block(-17,2,3,WOOD:2)
Block(-17,2,4,WOOD:2)
Block(-17,2,5,AIR)
Block(-17,2,6,AIR)
Block(-17,2,7,AIR)
Block(-17,2,8,AIR)
Block(-17,2,9,WOOD:2)
Block(-17,2,10,DIRT)
Block(-17,2,11,DIRT)
Block(-17,3,-8,GRASS)
Block(-17,3,-7,DIRT)
Block(-17,3,-6,DIRT)
Block(-17,3,-5,WOOD:2)
Block(-17,3,-4,AIR)
Block(-17,3,-3,AIR)
Block(-17,3,-2,AIR)
Block(-17,3,-1,AIR)
RandomBlock(-17,3,0,FLOWER_POT,../../nbt/Misc/FlowerPot1.nbt,20,FLOWER_POT,../../nbt/Misc/FlowerPot2.nbt,20,FLOWER_POT,../../nbt/Misc/FlowerPot3.nbt,20,FLOWER_POT,../../nbt/Misc/FlowerPot81.nbt,20,FLOWER_POT,../../nbt/Misc/FlowerPot4.nbt,20,FLOWER_POT,../../nbt/Misc/FlowerPot5.nbt,20,FLOWER_POT,../../nbt/Misc/FlowerPot6.nbt,20,FLOWER_POT,../../nbt/Misc/FlowerPot7.nbt,20,FLOWER_POT,../../nbt/Misc/FlowerPot8.nbt,100)
Block(-17,3,1,AIR)
Block(-17,3,2,AIR)
Block(-17,3,3,WOOD:2)
Block(-17,3,4,WOOD:2)
Block(-17,3,5,AIR)
Block(-17,3,6,AIR)
Block(-17,3,7,AIR)
Block(-17,3,8,AIR)
Block(-17,3,9,WOOD:2)
Block(-17,3,10,DIRT)
Block(-17,3,11,GRASS)
Block(-17,4,-7,GRASS)
Block(-17,4,-6,DIRT)
Block(-17,4,-5,WOOD:2)
Block(-17,4,-4,AIR)
Block(-17,4,-3,AIR)
Block(-17,4,-2,AIR)
Block(-17,4,-1,AIR)
Block(-17,4,0,AIR)
Block(-17,4,1,AIR)
Block(-17,4,2,AIR)
Block(-17,4,3,WOOD:2)
Block(-17,4,4,WOOD:2)
Block(-17,4,5,AIR)
Block(-17,4,6,AIR)
Block(-17,4,7,AIR)
Block(-17,4,8,AIR)
Block(-17,4,9,WOOD:2)
Block(-17,4,10,GRASS)
Block(-17,5,-6,GRASS)
Block(-17,5,-5,DIRT)
Block(-17,5,-4,STONE:6)
Block(-17,5,-3,STONE:6)
Block(-17,5,-2,STONE:6)
Block(-17,5,-1,STONE:6)
Block(-17,5,0,STONE:6)
Block(-17,5,1,STONE:6)
Block(-17,5,2,STONE:6)
Block(-17,5,3,AIR)
Block(-17,5,4,STONE:6)
Block(-17,5,5,STONE:6)
Block(-17,5,6,STONE:6)
Block(-17,5,7,STONE:6)
Block(-17,5,8,STONE:6)
Block(-17,5,9,GRASS)
Block(-17,6,-5,GRASS)
Block(-17,6,-4,DIRT)
Block(-17,6,-3,DIRT)
Block(-17,6,-2,DIRT)
Block(-17,6,-1,DIRT)
Block(-17,6,0,DIRT)
Block(-17,6,1,DIRT)
Block(-17,6,2,DIRT)
Block(-17,6,3,PISTON_STICKY_BASE:0)
Block(-17,6,4,DIRT)
Block(-17,6,5,DIRT)
Block(-17,6,6,DIRT)
Block(-17,6,7,GRASS)
Block(-17,6,8,GRASS)
Block(-17,7,-4,GRASS)
Block(-17,7,-3,GRASS)
Block(-17,7,-2,DIRT)
Block(-17,7,-1,DIRT)
Block(-17,7,0,DIRT)
Block(-17,7,1,DIRT)
Block(-17,7,2,GRASS)
Block(-17,7,3,GRASS)
Block(-17,7,4,GRASS)
Block(-17,7,5,DIRT)
Block(-17,7,6,GRASS)
Block(-17,8,-2,GRASS)
Block(-17,8,-1,DIRT)
Block(-17,8,0,DIRT)
Block(-17,8,1,GRASS)
Block(-17,8,5,GRASS)
Block(-17,9,-1,GRASS)
Block(-17,9,0,GRASS)
Block(-16,-10,-4,STONE)
Block(-16,-10,-3,STONE)
Block(-16,-10,-2,STONE)
Block(-16,-10,-1,STONE)
Block(-16,-10,0,STONE)
Block(-16,-9,-5,STONE)
Block(-16,-9,-4,STONE)
Block(-16,-9,-3,STONE)
Block(-16,-9,-2,STONE)
Block(-16,-9,-1,STONE)
Block(-16,-9,0,STONE)
Block(-16,-9,1,STONE)
Block(-16,-9,2,STONE)
Block(-16,-8,-6,STONE)
Block(-16,-8,-5,STONE)
Block(-16,-8,-4,STONE)
Block(-16,-8,-3,STONE)
Block(-16,-8,-2,STONE)
Block(-16,-8,-1,STONE)
Block(-16,-8,0,STONE)
Block(-16,-8,1,STONE)
Block(-16,-8,2,STONE)
Block(-16,-8,3,STONE)
Block(-16,-8,4,STONE)
Block(-16,-8,5,STONE)
Block(-16,-7,-7,STONE)
Block(-16,-7,-6,STONE)
Block(-16,-7,-5,STONE)
Block(-16,-7,-4,STONE)
Block(-16,-7,-3,STONE)
Block(-16,-7,-2,STONE)
Block(-16,-7,-1,STONE)
Block(-16,-7,0,STONE)
Block(-16,-7,1,STONE)
Block(-16,-7,2,STONE)
Block(-16,-7,3,STONE)
Block(-16,-7,4,STONE)
Block(-16,-7,5,STONE)
Block(-16,-7,6,STONE)
Block(-16,-7,7,STONE)
Block(-16,-7,8,STONE)
Block(-16,-6,-8,STONE)
Block(-16,-6,-7,STONE)
Block(-16,-6,-6,STONE)
Block(-16,-6,-5,STONE)
Block(-16,-6,-4,STONE)
Block(-16,-6,-3,STONE)
Block(-16,-6,-2,STONE)
Block(-16,-6,-1,STONE)
Block(-16,-6,0,STONE)
Block(-16,-6,1,STONE)
Block(-16,-6,2,STONE)
Block(-16,-6,3,STONE)
Block(-16,-6,4,STONE)
Block(-16,-6,5,STONE)
Block(-16,-6,6,STONE)
Block(-16,-6,7,STONE)
Block(-16,-6,8,STONE)
Block(-16,-6,9,STONE)
Block(-16,-6,10,STONE)
Block(-16,-5,-9,STONE)
Block(-16,-5,-8,STONE)
Block(-16,-5,-7,STONE)
Block(-16,-5,-6,STONE)
Block(-16,-5,-5,STONE)
Block(-16,-5,-4,STONE)
Block(-16,-5,-3,STONE)
Block(-16,-5,-2,STONE)
Block(-16,-5,-1,STONE)
Block(-16,-5,0,STONE)
Block(-16,-5,1,STONE)
Block(-16,-5,2,STONE)
Block(-16,-5,3,STONE)
Block(-16,-5,4,STONE)
Block(-16,-5,5,STONE)
Block(-16,-5,6,STONE)
Block(-16,-5,7,STONE)
Block(-16,-5,8,STONE)
Block(-16,-5,9,STONE)
Block(-16,-5,10,STONE)
Block(-16,-5,11,STONE)
Block(-16,-5,12,STONE)
Block(-16,-4,-10,STONE)
Block(-16,-4,-9,STONE)
Block(-16,-4,-8,STONE)
Block(-16,-4,-7,STONE)
Block(-16,-4,-6,STONE)
Block(-16,-4,-5,STONE)
Block(-16,-4,-4,STONE)
Block(-16,-4,-3,STONE)
Block(-16,-4,-2,STONE)
Block(-16,-4,-1,STONE)
Block(-16,-4,0,STONE)
Block(-16,-4,1,STONE)
Block(-16,-4,2,STONE)
Block(-16,-4,3,STONE)
Block(-16,-4,4,STONE)
Block(-16,-4,5,STONE)
Block(-16,-4,6,STONE)
Block(-16,-4,7,STONE)
Block(-16,-4,8,STONE)
Block(-16,-4,9,STONE)
Block(-16,-4,10,STONE)
Block(-16,-4,11,STONE)
Block(-16,-4,12,STONE)
Block(-16,-4,13,STONE)
Block(-16,-3,-11,DIRT)
Block(-16,-3,-10,STONE)
Block(-16,-3,-9,STONE)
Block(-16,-3,-8,STONE)
Block(-16,-3,-7,STONE)
Block(-16,-3,-6,STONE)
Block(-16,-3,-5,STONE)
Block(-16,-3,-4,STONE)
Block(-16,-3,-3,STONE)
Block(-16,-3,-2,STONE)
Block(-16,-3,-1,STONE)
Block(-16,-3,0,STONE)
Block(-16,-3,1,STONE)
Block(-16,-3,2,STONE)
Block(-16,-3,3,STONE)
Block(-16,-3,4,STONE)
Block(-16,-3,5,STONE)
Block(-16,-3,6,STONE)
Block(-16,-3,7,STONE)
Block(-16,-3,8,STONE)
Block(-16,-3,9,STONE)
Block(-16,-3,10,STONE)
Block(-16,-3,11,STONE)
Block(-16,-3,12,STONE)
Block(-16,-3,13,DIRT)
Block(-16,-2,-12,DIRT)
Block(-16,-2,-11,DIRT)
Block(-16,-2,-10,DIRT)
Block(-16,-2,-9,STONE)
Block(-16,-2,-8,STONE)
Block(-16,-2,-7,STONE)
Block(-16,-2,-6,STONE)
Block(-16,-2,-5,STONE)
Block(-16,-2,-4,STONE)
Block(-16,-2,-3,STONE)
Block(-16,-2,-2,STONE)
Block(-16,-2,-1,STONE)
Block(-16,-2,0,STONE)
Block(-16,-2,1,STONE)
Block(-16,-2,2,STONE)
Block(-16,-2,3,STONE)
Block(-16,-2,4,STONE)
Block(-16,-2,5,STONE)
Block(-16,-2,6,STONE)
Block(-16,-2,7,STONE)
Block(-16,-2,8,STONE)
Block(-16,-2,9,STONE)
Block(-16,-2,10,STONE)
Block(-16,-2,11,STONE)
Block(-16,-2,12,STONE)
Block(-16,-2,13,DIRT)
Block(-16,-2,14,DIRT)
Block(-16,-1,-12,GRASS)
Block(-16,-1,-11,DIRT)
Block(-16,-1,-10,DIRT)
Block(-16,-1,-9,STONE)
Block(-16,-1,-8,STONE)
Block(-16,-1,-7,STONE)
Block(-16,-1,-6,STONE)
Block(-16,-1,-5,STONE)
Block(-16,-1,-4,WOOD:5)
Block(-16,-1,-3,WOOD:5)
Block(-16,-1,-2,WOOL:13)
Block(-16,-1,-1,WOOL:13)
Block(-16,-1,0,WOOD:5)
Block(-16,-1,1,WOOD:5)
Block(-16,-1,2,STONE)
Block(-16,-1,3,STONE)
Block(-16,-1,4,WOOD:5)
Block(-16,-1,5,WOOD:5)
Block(-16,-1,6,WOOD:5)
Block(-16,-1,7,WOOD:5)
Block(-16,-1,8,WOOD:5)
Block(-16,-1,9,WOOD:5)
Block(-16,-1,10,STONE)
Block(-16,-1,11,STONE)
Block(-16,-1,12,DIRT)
Block(-16,-1,13,DIRT)
Block(-16,-1,14,GRASS)
Block(-16,0,-11,GRASS)
Block(-16,0,-10,DIRT)
Block(-16,0,-9,DIRT)
Block(-16,0,-8,STONE)
Block(-16,0,-7,STONE)
Block(-16,0,-6,STONE)
Block(-16,0,-5,WOOD:2)
Block(-16,0,-4,AIR)
Block(-16,0,-3,AIR)
Block(-16,0,-2,WOOD_STAIRS:0)
Block(-16,0,-1,AIR)
Block(-16,0,0,AIR)
RandomBlock(-16,0,1,JUKEBOX:1,../../nbt/Misc/RecordPlayer1.nbt,50,JUKEBOX:1,../../nbt/Misc/RecordPlayer2.nbt,50,JUKEBOX:1,../../nbt/Misc/RecordPlayer3.nbt,50,JUKEBOX:1,../../nbt/Misc/RecordPlayer4.nbt,50,JUKEBOX:1,../../nbt/Misc/RecordPlayer5.nbt,50,JUKEBOX:1,../../nbt/Misc/RecordPlayer6.nbt,50,JUKEBOX:1,../../nbt/Misc/RecordPlayer7.nbt,50,JUKEBOX:1,../../nbt/Misc/RecordPlayer8.nbt,50,JUKEBOX:1,../../nbt/Misc/RecordPlayer9.nbt,50,JUKEBOX:1,../../nbt/Misc/RecordPlayer10.nbt,50,JUKEBOX:1,../../nbt/Misc/RecordPlayer11.nbt,100)
Block(-16,0,2,WOOD:5)
Block(-16,0,3,WOOD:5)
Block(-16,0,4,WOOD:5)
Block(-16,0,5,WOOD:5)
Block(-16,0,6,WOOD:5)
Block(-16,0,7,WOOD:5)
Block(-16,0,8,WOOD:5)
Block(-16,0,9,WOOD:5)
Block(-16,0,10,WOOD:2)
Block(-16,0,11,STONE)
Block(-16,0,12,DIRT)
Block(-16,0,13,GRASS)
Block(-16,1,-10,GRASS)
Block(-16,1,-9,DIRT)
Block(-16,1,-8,DIRT)
Block(-16,1,-7,STONE)
Block(-16,1,-6,STONE)
Block(-16,1,-5,WOOD:2)
Block(-16,1,-4,AIR)
Block(-16,1,-3,AIR)
Block(-16,1,-2,AIR)
Block(-16,1,-1,AIR)
Block(-16,1,0,AIR)
Block(-16,1,1,AIR)
Block(-16,1,2,WOOD:5)
Block(-16,1,3,WOOD:5)
Block(-16,1,4,DARK_OAK_STAIRS:1)
Block(-16,1,5,DARK_OAK_STAIRS)
Block(-16,1,6,AIR)
Block(-16,1,7,AIR)
Block(-16,1,8,DARK_OAK_STAIRS:2)
Block(-16,1,9,DARK_OAK_STAIRS:1)
Block(-16,1,10,WOOD:2)
Block(-16,1,11,DIRT)
Block(-16,1,12,DIRT)
Block(-16,2,-9,DIRT)
Block(-16,2,-8,DIRT)
Block(-16,2,-7,DIRT)
Block(-16,2,-6,STONE)
Block(-16,2,-5,WOOD:2)
Block(-16,2,-4,AIR)
Block(-16,2,-3,AIR)
Block(-16,2,-2,AIR)
Block(-16,2,-1,AIR)
Block(-16,2,0,AIR)
Block(-16,2,1,AIR)
Block(-16,2,2,BOOKSHELF)
Block(-16,2,3,WOOD:2)
Block(-16,2,4,AIR)
Block(-16,2,5,AIR)
Block(-16,2,6,AIR)
Block(-16,2,7,AIR)
Block(-16,2,8,AIR)
Block(-16,2,9,AIR)
Block(-16,2,10,WOOD:2)
Block(-16,2,11,DIRT)
Block(-16,2,12,GRASS)
Block(-16,3,-9,GRASS)
Block(-16,3,-8,DIRT)
Block(-16,3,-7,DIRT)
Block(-16,3,-6,DIRT)
Block(-16,3,-5,WOOD:2)
Block(-16,3,-4,AIR)
Block(-16,3,-3,AIR)
Block(-16,3,-2,AIR)
Block(-16,3,-1,AIR)
Block(-16,3,0,AIR)
Block(-16,3,1,AIR)
Block(-16,3,2,JACK_O_LANTERN:0)
Block(-16,3,3,WOOD:2)
Block(-16,3,4,AIR)
Block(-16,3,5,AIR)
Block(-16,3,6,AIR)
Block(-16,3,7,AIR)
Block(-16,3,8,AIR)
Block(-16,3,9,AIR)
Block(-16,3,10,WOOD:2)
Block(-16,3,11,DIRT)
Block(-16,4,-8,GRASS)
Block(-16,4,-7,DIRT)
Block(-16,4,-6,DIRT)
Block(-16,4,-5,WOOD:2)
Block(-16,4,-4,AIR)
Block(-16,4,-3,AIR)
Block(-16,4,-2,AIR)
Block(-16,4,-1,AIR)
Block(-16,4,0,AIR)
Block(-16,4,1,AIR)
Block(-16,4,2,AIR)
Block(-16,4,3,WOOD:2)
Block(-16,4,4,AIR)
Block(-16,4,5,AIR)
Block(-16,4,6,AIR)
Block(-16,4,7,AIR)
Block(-16,4,8,AIR)
Block(-16,4,9,AIR)
Block(-16,4,10,WOOD:2)
Block(-16,4,11,GRASS)
Block(-16,5,-7,GRASS)
Block(-16,5,-6,DIRT)
Block(-16,5,-5,DIRT)
Block(-16,5,-4,STONE:6)
Block(-16,5,-3,STONE:6)
Block(-16,5,-2,STONE:6)
Block(-16,5,-1,STONE:6)
Block(-16,5,0,STONE:6)
Block(-16,5,1,STONE:6)
Block(-16,5,2,STONE:6)
Block(-16,5,3,STONE:6)
Block(-16,5,4,STONE:6)
Block(-16,5,5,STONE:6)
Block(-16,5,6,STONE:6)
Block(-16,5,7,STONE:6)
Block(-16,5,8,STONE:6)
Block(-16,5,9,STONE:6)
Block(-16,5,10,GRASS)
Block(-16,6,-6,GRASS)
Block(-16,6,-5,DIRT)
Block(-16,6,-4,DIRT)
Block(-16,6,-3,DIRT)
Block(-16,6,-2,STONE)
Block(-16,6,-1,STONE)
Block(-16,6,0,STONE)
Block(-16,6,1,DIRT)
Block(-16,6,2,DIRT)
Block(-16,6,3,REDSTONE_WIRE)
Block(-16,6,4,DIRT)
Block(-16,6,5,DIRT)
Block(-16,6,6,DIRT)
Block(-16,6,7,DIRT)
Block(-16,6,8,DIRT)
Block(-16,6,9,GRASS)
Block(-16,7,-5,GRASS)
Block(-16,7,-4,DIRT)
Block(-16,7,-3,DIRT)
Block(-16,7,-2,DIRT)
Block(-16,7,-1,DIRT)
Block(-16,7,0,DIRT)
Block(-16,7,1,DIRT)
Block(-16,7,2,DIRT)
Block(-16,7,3,GRASS)
Block(-16,7,4,DIRT)
Block(-16,7,5,DIRT)
Block(-16,7,6,DIRT)
Block(-16,7,7,DIRT)
Block(-16,7,8,GRASS)
Block(-16,8,-4,GRASS)
Block(-16,8,-3,DIRT)
Block(-16,8,-2,DIRT)
Block(-16,8,-1,DIRT)
Block(-16,8,0,DIRT)
Block(-16,8,1,DIRT)
Block(-16,8,2,GRASS)
Block(-16,8,4,GRASS)
Block(-16,8,5,DIRT)
Block(-16,8,6,GRASS)
Block(-16,8,7,GRASS)
Block(-16,9,-3,GRASS)
Block(-16,9,-2,DIRT)
Block(-16,9,-1,DIRT)
Block(-16,9,0,DIRT)
Block(-16,9,1,GRASS)
Block(-16,9,5,GRASS)
Block(-16,10,-2,GRASS)
Block(-16,10,-1,GRASS)
Block(-16,10,0,GRASS)
Block(-15,-10,-4,STONE)
Block(-15,-10,-3,STONE)
Block(-15,-10,-2,STONE)
Block(-15,-10,-1,STONE)
Block(-15,-10,0,STONE)
Block(-15,-10,1,STONE)
Block(-15,-9,-5,STONE)
Block(-15,-9,-4,STONE)
Block(-15,-9,-3,STONE)
Block(-15,-9,-2,STONE)
Block(-15,-9,-1,STONE)
Block(-15,-9,0,STONE)
Block(-15,-9,1,STONE)
Block(-15,-9,2,STONE)
Block(-15,-8,-6,STONE)
Block(-15,-8,-5,STONE)
Block(-15,-8,-4,STONE)
Block(-15,-8,-3,STONE)
Block(-15,-8,-2,STONE)
Block(-15,-8,-1,STONE)
Block(-15,-8,0,STONE)
Block(-15,-8,1,STONE)
Block(-15,-8,2,STONE)
Block(-15,-8,3,STONE)
Block(-15,-8,4,STONE)
Block(-15,-8,5,STONE)
Block(-15,-8,6,STONE)
Block(-15,-8,7,STONE)
Block(-15,-7,-7,STONE)
Block(-15,-7,-6,STONE)
Block(-15,-7,-5,STONE)
Block(-15,-7,-4,STONE)
Block(-15,-7,-3,STONE)
Block(-15,-7,-2,STONE)
Block(-15,-7,-1,STONE)
Block(-15,-7,0,STONE)
Block(-15,-7,1,STONE)
Block(-15,-7,2,STONE)
Block(-15,-7,3,STONE)
Block(-15,-7,4,STONE)
Block(-15,-7,5,STONE)
Block(-15,-7,6,STONE)
Block(-15,-7,7,STONE)
Block(-15,-7,8,STONE)
Block(-15,-7,9,STONE)
Block(-15,-6,-8,STONE)
Block(-15,-6,-7,STONE)
Block(-15,-6,-6,STONE)
Block(-15,-6,-5,STONE)
Block(-15,-6,-4,STONE)
Block(-15,-6,-3,STONE)
Block(-15,-6,-2,STONE)
Block(-15,-6,-1,STONE)
Block(-15,-6,0,STONE)
Block(-15,-6,1,STONE)
Block(-15,-6,2,STONE)
Block(-15,-6,3,STONE)
Block(-15,-6,4,STONE)
Block(-15,-6,5,STONE)
Block(-15,-6,6,STONE)
Block(-15,-6,7,STONE)
Block(-15,-6,8,STONE)
Block(-15,-6,9,STONE)
Block(-15,-6,10,STONE)
Block(-15,-5,-9,STONE)
Block(-15,-5,-8,STONE)
Block(-15,-5,-7,STONE)
Block(-15,-5,-6,STONE)
Block(-15,-5,-5,STONE)
Block(-15,-5,-4,STONE)
Block(-15,-5,-3,STONE)
Block(-15,-5,-2,STONE)
Block(-15,-5,-1,STONE)
Block(-15,-5,0,STONE)
Block(-15,-5,1,STONE)
Block(-15,-5,2,STONE)
Block(-15,-5,3,STONE)
Block(-15,-5,4,STONE)
Block(-15,-5,5,STONE)
Block(-15,-5,6,STONE)
Block(-15,-5,7,STONE)
Block(-15,-5,8,STONE)
Block(-15,-5,9,STONE)
Block(-15,-5,10,STONE)
Block(-15,-5,11,STONE)
Block(-15,-4,-10,STONE)
Block(-15,-4,-9,STONE)
Block(-15,-4,-8,STONE)
Block(-15,-4,-7,STONE)
Block(-15,-4,-6,STONE)
Block(-15,-4,-5,STONE)
Block(-15,-4,-4,STONE)
Block(-15,-4,-3,STONE)
Block(-15,-4,-2,STONE)
Block(-15,-4,-1,STONE)
Block(-15,-4,0,STONE)
Block(-15,-4,1,STONE)
Block(-15,-4,2,STONE)
Block(-15,-4,3,STONE)
Block(-15,-4,4,STONE)
Block(-15,-4,5,STONE)
Block(-15,-4,6,STONE)
Block(-15,-4,7,STONE)
Block(-15,-4,8,STONE)
Block(-15,-4,9,STONE)
Block(-15,-4,10,STONE)
Block(-15,-4,11,STONE)
Block(-15,-4,12,STONE)
Block(-15,-4,13,STONE)
Block(-15,-3,-11,STONE)
Block(-15,-3,-10,STONE)
Block(-15,-3,-9,STONE)
Block(-15,-3,-8,STONE)
Block(-15,-3,-7,STONE)
Block(-15,-3,-6,STONE)
Block(-15,-3,-5,STONE)
Block(-15,-3,-4,STONE)
Block(-15,-3,-3,STONE)
Block(-15,-3,-2,STONE)
Block(-15,-3,-1,STONE)
Block(-15,-3,0,STONE)
Block(-15,-3,1,STONE)
Block(-15,-3,2,STONE)
Block(-15,-3,3,STONE)
Block(-15,-3,4,STONE)
Block(-15,-3,5,STONE)
Block(-15,-3,6,STONE)
Block(-15,-3,7,STONE)
Block(-15,-3,8,STONE)
Block(-15,-3,9,STONE)
Block(-15,-3,10,STONE)
Block(-15,-3,11,STONE)
Block(-15,-3,12,STONE)
Block(-15,-3,13,STONE)
Block(-15,-2,-12,DIRT)
Block(-15,-2,-11,DIRT)
Block(-15,-2,-10,STONE)
Block(-15,-2,-9,STONE)
Block(-15,-2,-8,STONE)
Block(-15,-2,-7,STONE)
Block(-15,-2,-6,STONE)
Block(-15,-2,-5,STONE)
Block(-15,-2,-4,STONE)
Block(-15,-2,-3,STONE)
Block(-15,-2,-2,STONE)
Block(-15,-2,-1,STONE)
Block(-15,-2,0,STONE)
Block(-15,-2,1,STONE)
Block(-15,-2,2,STONE)
Block(-15,-2,3,STONE)
Block(-15,-2,4,STONE)
Block(-15,-2,5,STONE)
Block(-15,-2,6,STONE)
Block(-15,-2,7,STONE)
Block(-15,-2,8,STONE)
Block(-15,-2,9,STONE)
Block(-15,-2,10,STONE)
Block(-15,-2,11,STONE)
Block(-15,-2,12,STONE)
Block(-15,-2,13,DIRT)
Block(-15,-2,14,DIRT)
Block(-15,-1,-12,DIRT)
Block(-15,-1,-11,DIRT)
Block(-15,-1,-10,DIRT)
Block(-15,-1,-9,STONE)
Block(-15,-1,-8,STONE)
Block(-15,-1,-7,STONE)
Block(-15,-1,-6,STONE)
Block(-15,-1,-5,STONE)
Block(-15,-1,-4,WOOD:5)
Block(-15,-1,-3,WOOD:5)
Block(-15,-1,-2,WOOL:13)
Block(-15,-1,-1,WOOL:13)
Block(-15,-1,0,WOOD:5)
Block(-15,-1,1,WOOD:5)
Block(-15,-1,2,STONE)
Block(-15,-1,3,STONE)
Block(-15,-1,4,WOOD:5)
Block(-15,-1,5,WOOD:5)
Block(-15,-1,6,WOOD:5)
Block(-15,-1,7,WOOD:5)
Block(-15,-1,8,WOOD:5)
Block(-15,-1,9,WOOD:5)
Block(-15,-1,10,STONE)
Block(-15,-1,11,STONE)
Block(-15,-1,12,STONE)
Block(-15,-1,13,DIRT)
Block(-15,-1,14,GRASS)
Block(-15,0,-12,GRASS)
Block(-15,0,-11,DIRT)
Block(-15,0,-10,DIRT)
Block(-15,0,-9,DIRT)
Block(-15,0,-8,STONE)
Block(-15,0,-7,STONE)
Block(-15,0,-6,STONE)
Block(-15,0,-5,WOOD:2)
Block(-15,0,-4,WORKBENCH)
Block(-15,0,-3,AIR)
Block(-15,0,-2,AIR)
Block(-15,0,-1,AIR)
Block(-15,0,0,AIR)
Block(-15,0,1,AIR)
Block(-15,0,2,WOOD:5)
Block(-15,0,3,WOOD:5)
Block(-15,0,4,WOOD:5)
Block(-15,0,5,WOOL:14)
Block(-15,0,6,WOOL:14)
Block(-15,0,7,WOOL:14)
Block(-15,0,8,WOOL:14)
Block(-15,0,9,WOOD:5)
Block(-15,0,10,WOOD:2)
Block(-15,0,11,STONE)
Block(-15,0,12,DIRT)
Block(-15,0,13,DIRT)
Block(-15,1,-11,GRASS)
Block(-15,1,-10,DIRT)
Block(-15,1,-9,DIRT)
Block(-15,1,-8,STONE)
Block(-15,1,-7,STONE)
Block(-15,1,-6,STONE)
Block(-15,1,-5,WOOD:2)
Block(-15,1,-4,AIR)
Block(-15,1,-3,AIR)
Block(-15,1,-2,AIR)
Block(-15,1,-1,AIR)
Block(-15,1,0,AIR)
Block(-15,1,1,AIR)
Block(-15,1,2,WOOD:5)
Block(-15,1,3,WOOD:5)
Block(-15,1,4,DARK_OAK_STAIRS)
Block(-15,1,5,AIR)
Block(-15,1,6,AIR)
Block(-15,1,7,AIR)
Block(-15,1,8,AIR)
Block(-15,1,9,DARK_OAK_STAIRS:2)
Block(-15,1,10,WOOD:2)
Block(-15,1,11,DIRT)
Block(-15,1,12,DIRT)
Block(-15,1,13,GRASS)
Block(-15,2,-10,GRASS)
Block(-15,2,-9,DIRT)
Block(-15,2,-8,DIRT)
Block(-15,2,-7,STONE)
Block(-15,2,-6,STONE)
Block(-15,2,-5,WOOD:2)
Block(-15,2,-4,AIR)
Block(-15,2,-3,AIR)
Block(-15,2,-2,AIR)
Block(-15,2,-1,AIR)
Block(-15,2,0,AIR)
Block(-15,2,1,AIR)
Block(-15,2,2,BOOKSHELF)
Block(-15,2,3,WOOD:2)
Block(-15,2,4,AIR)
Block(-15,2,5,AIR)
Block(-15,2,6,AIR)
Block(-15,2,7,AIR)
Block(-15,2,8,AIR)
Block(-15,2,9,AIR)
Block(-15,2,10,WOOD:2)
Block(-15,2,11,DIRT)
Block(-15,2,12,DIRT)
Block(-15,3,-9,GRASS)
Block(-15,3,-8,DIRT)
Block(-15,3,-7,DIRT)
Block(-15,3,-6,STONE)
Block(-15,3,-5,WOOD:2)
Block(-15,3,-4,AIR)
Block(-15,3,-3,AIR)
Block(-15,3,-2,AIR)
Block(-15,3,-1,AIR)
Block(-15,3,0,AIR)
Block(-15,3,1,AIR)
Block(-15,3,2,BOOKSHELF)
Block(-15,3,3,WOOD:2)
Block(-15,3,4,AIR)
Block(-15,3,5,AIR)
Block(-15,3,6,AIR)
Block(-15,3,7,AIR)
Block(-15,3,8,AIR)
Block(-15,3,9,AIR)
Block(-15,3,10,DARK_OAK_FENCE)
Block(-15,3,11,WOOD:2)
Block(-15,3,12,GRASS)
Block(-15,4,-8,DIRT)
Block(-15,4,-7,DIRT)
Block(-15,4,-6,DIRT)
Block(-15,4,-5,WOOD:2)
Block(-15,4,-4,AIR)
Block(-15,4,-3,AIR)
Block(-15,4,-2,AIR)
Block(-15,4,-1,AIR)
Block(-15,4,0,AIR)
Block(-15,4,1,AIR)
Block(-15,4,2,BOOKSHELF)
Block(-15,4,3,WOOD:2)
Block(-15,4,4,AIR)
Block(-15,4,5,AIR)
Block(-15,4,6,AIR)
Block(-15,4,7,AIR)
Block(-15,4,8,AIR)
Block(-15,4,9,AIR)
Block(-15,4,10,WOOD:2)
Block(-15,4,11,GRASS)
Block(-15,5,-8,GRASS)
Block(-15,5,-7,DIRT)
Block(-15,5,-6,DIRT)
Block(-15,5,-5,DIRT)
Block(-15,5,-4,STONE:6)
Block(-15,5,-3,STONE:6)
Block(-15,5,-2,STONE:6)
Block(-15,5,-1,STONE:6)
Block(-15,5,0,STONE:6)
Block(-15,5,1,STONE:6)
Block(-15,5,2,STONE:6)
Block(-15,5,3,REDSTONE_WIRE)
Block(-15,5,4,STONE:6)
Block(-15,5,5,STONE:6)
Block(-15,5,6,STONE:6)
Block(-15,5,7,STONE:6)
Block(-15,5,8,STONE:6)
Block(-15,5,9,STONE:6)
Block(-15,5,10,GRASS)
Block(-15,6,-7,GRASS)
Block(-15,6,-6,DIRT)
Block(-15,6,-5,DIRT)
Block(-15,6,-4,DIRT)
Block(-15,6,-3,STONE)
Block(-15,6,-2,STONE)
Block(-15,6,-1,STONE)
Block(-15,6,0,STONE)
Block(-15,6,1,STONE)
Block(-15,6,2,STONE)
Block(-15,6,3,AIR)
Block(-15,6,4,DIRT)
Block(-15,6,5,DIRT)
Block(-15,6,6,DIRT)
Block(-15,6,7,DIRT)
Block(-15,6,8,DIRT)
Block(-15,6,9,GRASS)
Block(-15,7,-6,GRASS)
Block(-15,7,-5,DIRT)
Block(-15,7,-4,DIRT)
Block(-15,7,-3,DIRT)
Block(-15,7,-2,STONE)
Block(-15,7,-1,STONE)
Block(-15,7,0,STONE)
Block(-15,7,1,STONE)
Block(-15,7,2,DIRT)
Block(-15,7,3,DIRT)
Block(-15,7,4,DIRT)
Block(-15,7,5,DIRT)
Block(-15,7,6,DIRT)
Block(-15,7,7,DIRT)
Block(-15,7,8,DIRT)
Block(-15,8,-5,GRASS)
Block(-15,8,-4,DIRT)
Block(-15,8,-3,DIRT)
Block(-15,8,-2,DIRT)
Block(-15,8,-1,DIRT)
Block(-15,8,0,DIRT)
Block(-15,8,1,DIRT)
Block(-15,8,2,DIRT)
Block(-15,8,3,DIRT)
Block(-15,8,4,DIRT)
Block(-15,8,5,DIRT)
Block(-15,8,6,DIRT)
Block(-15,8,7,DIRT)
Block(-15,8,8,GRASS)
Block(-15,9,-4,GRASS)
Block(-15,9,-3,DIRT)
Block(-15,9,-2,DIRT)
Block(-15,9,-1,DIRT)
Block(-15,9,0,DIRT)
Block(-15,9,1,DIRT)
Block(-15,9,2,DIRT)
Block(-15,9,3,GRASS)
Block(-15,9,4,GRASS)
Block(-15,9,5,GRASS)
Block(-15,9,6,GRASS)
Block(-15,9,7,GRASS)
Block(-15,10,-3,GRASS)
Block(-15,10,-2,DIRT)
Block(-15,10,-1,DIRT)
Block(-15,10,0,DIRT)
Block(-15,10,1,DIRT)
Block(-15,10,2,GRASS)
Block(-15,11,-2,GRASS)
Block(-15,11,-1,GRASS)
Block(-15,11,0,GRASS)
Block(-15,11,1,GRASS)
Block(-14,-10,-5,STONE)
Block(-14,-10,-4,STONE)
Block(-14,-10,-3,STONE)
Block(-14,-10,-2,STONE)
Block(-14,-10,-1,STONE)
Block(-14,-10,0,STONE)
Block(-14,-10,1,STONE)
Block(-14,-10,2,STONE)
Block(-14,-9,-6,STONE)
Block(-14,-9,-5,STONE)
Block(-14,-9,-4,STONE)
Block(-14,-9,-3,STONE)
Block(-14,-9,-2,STONE)
Block(-14,-9,-1,STONE)
Block(-14,-9,0,STONE)
Block(-14,-9,1,STONE)
Block(-14,-9,2,STONE)
Block(-14,-9,3,STONE)
Block(-14,-8,-7,STONE)
Block(-14,-8,-6,STONE)
Block(-14,-8,-5,STONE)
Block(-14,-8,-4,STONE)
Block(-14,-8,-3,STONE)
Block(-14,-8,-2,STONE)
Block(-14,-8,-1,STONE)
Block(-14,-8,0,STONE)
Block(-14,-8,1,STONE)
Block(-14,-8,2,STONE)
Block(-14,-8,3,STONE)
Block(-14,-8,4,STONE)
Block(-14,-8,5,STONE)
Block(-14,-8,6,STONE)
Block(-14,-8,7,STONE)
Block(-14,-8,8,STONE)
Block(-14,-7,-8,STONE)
Block(-14,-7,-7,STONE)
Block(-14,-7,-6,STONE)
Block(-14,-7,-5,STONE)
Block(-14,-7,-4,STONE)
Block(-14,-7,-3,STONE)
Block(-14,-7,-2,STONE)
Block(-14,-7,-1,STONE)
Block(-14,-7,0,STONE)
Block(-14,-7,1,STONE)
Block(-14,-7,2,STONE)
Block(-14,-7,3,STONE)
Block(-14,-7,4,STONE)
Block(-14,-7,5,STONE)
Block(-14,-7,6,STONE)
Block(-14,-7,7,STONE)
Block(-14,-7,8,STONE)
Block(-14,-7,9,STONE)
Block(-14,-7,10,STONE)
Block(-14,-6,-9,STONE)
Block(-14,-6,-8,STONE)
Block(-14,-6,-7,STONE)
Block(-14,-6,-6,STONE)
Block(-14,-6,-5,STONE)
Block(-14,-6,-4,STONE)
Block(-14,-6,-3,STONE)
Block(-14,-6,-2,STONE)
Block(-14,-6,-1,STONE)
Block(-14,-6,0,STONE)
Block(-14,-6,1,STONE)
Block(-14,-6,2,STONE)
Block(-14,-6,3,STONE)
Block(-14,-6,4,STONE)
Block(-14,-6,5,STONE)
Block(-14,-6,6,STONE)
Block(-14,-6,7,STONE)
Block(-14,-6,8,STONE)
Block(-14,-6,9,STONE)
Block(-14,-6,10,STONE)
Block(-14,-6,11,STONE)
Block(-14,-5,-9,STONE)
Block(-14,-5,-8,STONE)
Block(-14,-5,-7,STONE)
Block(-14,-5,-6,STONE)
Block(-14,-5,-5,STONE)
Block(-14,-5,-4,STONE)
Block(-14,-5,-3,STONE)
Block(-14,-5,-2,STONE)
Block(-14,-5,-1,STONE)
Block(-14,-5,0,STONE)
Block(-14,-5,1,STONE)
Block(-14,-5,2,STONE)
Block(-14,-5,3,STONE)
Block(-14,-5,4,STONE)
Block(-14,-5,5,STONE)
Block(-14,-5,6,STONE)
Block(-14,-5,7,STONE)
Block(-14,-5,8,STONE)
Block(-14,-5,9,STONE)
Block(-14,-5,10,STONE)
Block(-14,-5,11,STONE)
Block(-14,-4,-10,STONE)
Block(-14,-4,-9,STONE)
Block(-14,-4,-8,STONE)
Block(-14,-4,-7,STONE)
Block(-14,-4,-6,STONE)
Block(-14,-4,-5,STONE)
Block(-14,-4,-4,STONE)
Block(-14,-4,-3,STONE)
Block(-14,-4,-2,STONE)
Block(-14,-4,-1,STONE)
Block(-14,-4,0,STONE)
Block(-14,-4,1,STONE)
Block(-14,-4,2,STONE)
Block(-14,-4,3,STONE)
Block(-14,-4,4,STONE)
Block(-14,-4,5,STONE)
Block(-14,-4,6,STONE)
Block(-14,-4,7,STONE)
Block(-14,-4,8,STONE)
Block(-14,-4,9,STONE)
Block(-14,-4,10,STONE)
Block(-14,-4,11,STONE)
Block(-14,-4,12,STONE)
Block(-14,-4,13,STONE)
Block(-14,-3,-12,DIRT)
Block(-14,-3,-11,STONE)
Block(-14,-3,-10,STONE)
Block(-14,-3,-9,STONE)
Block(-14,-3,-8,STONE)
Block(-14,-3,-7,STONE)
Block(-14,-3,-6,STONE)
Block(-14,-3,-5,STONE)
Block(-14,-3,-4,STONE)
Block(-14,-3,-3,STONE)
Block(-14,-3,-2,STONE)
Block(-14,-3,-1,STONE)
Block(-14,-3,0,STONE)
Block(-14,-3,1,STONE)
Block(-14,-3,2,STONE)
Block(-14,-3,3,STONE)
Block(-14,-3,4,STONE)
Block(-14,-3,5,STONE)
Block(-14,-3,6,STONE)
Block(-14,-3,7,STONE)
Block(-14,-3,8,STONE)
Block(-14,-3,9,STONE)
Block(-14,-3,10,STONE)
Block(-14,-3,11,STONE)
Block(-14,-3,12,STONE)
Block(-14,-3,13,STONE)
Block(-14,-3,14,DIRT)
Block(-14,-2,-13,DIRT)
Block(-14,-2,-12,DIRT)
Block(-14,-2,-11,STONE)
Block(-14,-2,-10,STONE)
Block(-14,-2,-9,STONE)
Block(-14,-2,-8,STONE)
Block(-14,-2,-7,STONE)
Block(-14,-2,-6,STONE)
Block(-14,-2,-5,STONE)
Block(-14,-2,-4,STONE)
Block(-14,-2,-3,STONE)
Block(-14,-2,-2,STONE)
Block(-14,-2,-1,STONE)
Block(-14,-2,0,STONE)
Block(-14,-2,1,STONE)
Block(-14,-2,2,STONE)
Block(-14,-2,3,STONE)
Block(-14,-2,4,STONE)
Block(-14,-2,5,STONE)
Block(-14,-2,6,STONE)
Block(-14,-2,7,STONE)
Block(-14,-2,8,STONE)
Block(-14,-2,9,STONE)
Block(-14,-2,10,STONE)
Block(-14,-2,11,STONE)
Block(-14,-2,12,STONE)
Block(-14,-2,13,DIRT)
Block(-14,-2,14,DIRT)
Block(-14,-1,-13,GRASS)
Block(-14,-1,-12,DIRT)
Block(-14,-1,-11,DIRT)
Block(-14,-1,-10,STONE)
Block(-14,-1,-9,STONE)
Block(-14,-1,-8,STONE)
Block(-14,-1,-7,STONE)
Block(-14,-1,-6,STONE)
Block(-14,-1,-5,WOOD:5)
Block(-14,-1,-4,WOOD:5)
Block(-14,-1,-3,WOOD:5)
Block(-14,-1,-2,WOOL:13)
Block(-14,-1,-1,WOOL:13)
Block(-14,-1,0,WOOD:5)
Block(-14,-1,1,WOOD:5)
Block(-14,-1,2,STONE)
Block(-14,-1,3,STONE)
Block(-14,-1,4,WOOD:5)
Block(-14,-1,5,WOOD:5)
Block(-14,-1,6,WOOD:5)
Block(-14,-1,7,WOOD:5)
Block(-14,-1,8,WOOD:5)
Block(-14,-1,9,WOOD:5)
Block(-14,-1,10,STONE)
Block(-14,-1,11,STONE)
Block(-14,-1,12,STONE)
Block(-14,-1,13,DIRT)
Block(-14,-1,14,DIRT)
Block(-14,0,-12,GRASS)
Block(-14,0,-11,DIRT)
Block(-14,0,-10,DIRT)
Block(-14,0,-9,STONE)
Block(-14,0,-8,STONE)
Block(-14,0,-7,STONE)
Block(-14,0,-6,WOOD:2)
Block(-14,0,-5,50)
Block(-14,0,-4,AIR)
Block(-14,0,-3,AIR)
Block(-14,0,-2,AIR)
Block(-14,0,-1,AIR)
Block(-14,0,0,AIR)
Block(-14,0,1,LADDER)
Block(-14,0,2,WOOD:5)
Block(-14,0,3,WOOD:5)
Block(-14,0,4,WOOD:5)
Block(-14,0,5,WOOL:14)
Block(-14,0,6,WOOL:14)
Block(-14,0,7,WOOL:14)
Block(-14,0,8,WOOL:14)
Block(-14,0,9,WOOD:5)
Block(-14,0,10,WOOD:2)
Block(-14,0,11,STONE)
Block(-14,0,12,DIRT)
Block(-14,0,13,DIRT)
Block(-14,0,14,GRASS)
Block(-14,1,-11,DIRT)
Block(-14,1,-10,DIRT)
Block(-14,1,-9,DIRT)
Block(-14,1,-8,STONE)
Block(-14,1,-7,STONE)
Block(-14,1,-6,WOOD:2)
Block(-14,1,-5,AIR)
Block(-14,1,-4,AIR)
Block(-14,1,-3,AIR)
Block(-14,1,-2,AIR)
Block(-14,1,-1,AIR)
Block(-14,1,0,AIR)
Block(-14,1,1,LADDER)
Block(-14,1,2,WOOD:5)
Block(-14,1,3,WOOD:5)
Block(-14,1,4,DARK_OAK_STAIRS)
Block(-14,1,5,AIR)
Block(-14,1,6,AIR)
Block(-14,1,7,AIR)
Block(-14,1,8,AIR)
Block(-14,1,9,DARK_OAK_STAIRS:2)
Block(-14,1,10,WOOD:2)
Block(-14,1,11,STONE)
Block(-14,1,12,DIRT)
Block(-14,1,13,GRASS)
Block(-14,2,-11,GRASS)
Block(-14,2,-10,DIRT)
Block(-14,2,-9,DIRT)
Block(-14,2,-8,DIRT)
Block(-14,2,-7,STONE)
Block(-14,2,-6,WOOD:2)
Block(-14,2,-5,AIR)
Block(-14,2,-4,AIR)
Block(-14,2,-3,AIR)
Block(-14,2,-2,AIR)
Block(-14,2,-1,AIR)
Block(-14,2,0,AIR)
Block(-14,2,1,LADDER)
Block(-14,2,2,BOOKSHELF)
Block(-14,2,3,WOOD:2)
Block(-14,2,4,AIR)
Block(-14,2,5,AIR)
Block(-14,2,6,AIR)
Block(-14,2,7,AIR)
Block(-14,2,8,AIR)
Block(-14,2,9,AIR)
Block(-14,2,10,WOOD:2)
Block(-14,2,11,DIRT)
Block(-14,2,12,DIRT)
Block(-14,3,-10,GRASS)
Block(-14,3,-9,DIRT)
Block(-14,3,-8,DIRT)
Block(-14,3,-7,DIRT)
Block(-14,3,-6,WOOD:2)
Block(-14,3,-5,WEB)
Block(-14,3,-4,AIR)
Block(-14,3,-3,AIR)
Block(-14,3,-2,AIR)
Block(-14,3,-1,AIR)
Block(-14,3,0,AIR)
Block(-14,3,1,LADDER)
Block(-14,3,2,BOOKSHELF)
Block(-14,3,3,WOOD:2)
Block(-14,3,4,AIR)
Block(-14,3,5,AIR)
Block(-14,3,6,AIR)
Block(-14,3,7,AIR)
Block(-14,3,8,AIR)
Block(-14,3,9,AIR)
Block(-14,3,10,DARK_OAK_FENCE)
Block(-14,3,11,WOOD:2)
Block(-14,3,12,GRASS)
Block(-14,4,-9,GRASS)
Block(-14,4,-8,DIRT)
Block(-14,4,-7,DIRT)
Block(-14,4,-6,WOOD:2)
Block(-14,4,-5,AIR)
Block(-14,4,-4,AIR)
Block(-14,4,-3,AIR)
Block(-14,4,-2,AIR)
Block(-14,4,-1,AIR)
Block(-14,4,0,AIR)
Block(-14,4,1,AIR)
Block(-14,4,2,STONE_BUTTON)
Block(-14,4,3,WOOD:2)
Block(-14,4,4,AIR)
Block(-14,4,5,AIR)
Block(-14,4,8,AIR)
Block(-14,4,9,AIR)
Block(-14,4,10,WOOD:2)
Block(-14,4,11,DIRT)
Block(-14,5,-8,GRASS)
Block(-14,5,-7,DIRT)
Block(-14,5,-6,DIRT)
Block(-14,5,-5,STONE:6)
Block(-14,5,-4,STONE:6)
Block(-14,5,-3,STONE:6)
Block(-14,5,-2,STONE:6)
Block(-14,5,-1,STONE:6)
Block(-14,5,0,STONE:6)
Block(-14,5,1,STONE:6)
Block(-14,5,2,STONE:6)
Block(-14,5,3,REDSTONE_WIRE)
Block(-14,5,4,STONE:6)
Block(-14,5,5,STONE:6)
Block(-14,5,6,STONE:6)
Block(-14,5,7,STONE:6)
Block(-14,5,8,STONE:6)
Block(-14,5,9,STONE:6)
Block(-14,5,10,DIRT)
Block(-14,5,11,GRASS)
Block(-14,6,-7,GRASS)
Block(-14,6,-6,DIRT)
Block(-14,6,-5,DIRT)
Block(-14,6,-4,STONE)
Block(-14,6,-3,STONE)
Block(-14,6,-2,STONE)
Block(-14,6,-1,STONE)
Block(-14,6,0,STONE)
Block(-14,6,1,STONE)
Block(-14,6,2,STONE)
Block(-14,6,3,AIR)
Block(-14,6,4,STONE)
Block(-14,6,5,STONE)
Block(-14,6,6,STONE)
Block(-14,6,7,DIRT)
Block(-14,6,8,DIRT)
Block(-14,6,9,DIRT)
Block(-14,6,10,GRASS)
Block(-14,7,-6,GRASS)
Block(-14,7,-5,DIRT)
Block(-14,7,-4,DIRT)
Block(-14,7,-3,STONE)
Block(-14,7,-2,STONE)
Block(-14,7,-1,STONE)
Block(-14,7,0,STONE)
Block(-14,7,1,STONE)
Block(-14,7,2,STONE)
Block(-14,7,3,DIRT)
Block(-14,7,4,DIRT)
Block(-14,7,5,DIRT)
Block(-14,7,6,DIRT)
Block(-14,7,7,DIRT)
Block(-14,7,8,DIRT)
Block(-14,7,9,GRASS)
Block(-14,8,-5,DIRT)
Block(-14,8,-4,DIRT)
Block(-14,8,-3,DIRT)
Block(-14,8,-2,DIRT)
Block(-14,8,-1,DIRT)
Block(-14,8,0,DIRT)
Block(-14,8,1,DIRT)
Block(-14,8,2,DIRT)
Block(-14,8,3,DIRT)
Block(-14,8,4,DIRT)
Block(-14,8,5,DIRT)
Block(-14,8,6,DIRT)
Block(-14,8,7,DIRT)
Block(-14,8,8,GRASS)
Block(-14,9,-5,GRASS)
Block(-14,9,-4,DIRT)
Block(-14,9,-3,DIRT)
Block(-14,9,-2,DIRT)
Block(-14,9,-1,DIRT)
Block(-14,9,0,DIRT)
Block(-14,9,1,DIRT)
Block(-14,9,2,DIRT)
Block(-14,9,3,DIRT)
Block(-14,9,4,DIRT)
Block(-14,9,5,DIRT)
Block(-14,9,6,DIRT)
Block(-14,9,7,GRASS)
Block(-14,10,-4,GRASS)
Block(-14,10,-3,DIRT)
Block(-14,10,-2,DIRT)
Block(-14,10,-1,DIRT)
Block(-14,10,0,DIRT)
Block(-14,10,1,DIRT)
Block(-14,10,2,DIRT)
Block(-14,10,3,GRASS)
Block(-14,10,4,GRASS)
Block(-14,10,5,GRASS)
Block(-14,10,6,GRASS)
Block(-14,11,-3,GRASS)
Block(-14,11,-2,GRASS)
Block(-14,11,-1,GRASS)
Block(-14,11,0,GRASS)
Block(-14,11,1,GRASS)
Block(-14,11,2,GRASS)
Block(-13,-10,-5,STONE)
Block(-13,-10,-4,STONE)
Block(-13,-10,-3,STONE)
Block(-13,-10,-2,STONE)
Block(-13,-10,-1,STONE)
Block(-13,-10,0,STONE)
Block(-13,-10,1,STONE)
Block(-13,-10,2,STONE)
Block(-13,-10,3,STONE)
Block(-13,-9,-6,STONE)
Block(-13,-9,-5,STONE)
Block(-13,-9,-4,STONE)
Block(-13,-9,-3,STONE)
Block(-13,-9,-2,STONE)
Block(-13,-9,-1,STONE)
Block(-13,-9,0,STONE)
Block(-13,-9,1,STONE)
Block(-13,-9,2,STONE)
Block(-13,-9,3,STONE)
Block(-13,-8,-7,STONE)
Block(-13,-8,-6,STONE)
Block(-13,-8,-5,STONE)
Block(-13,-8,-4,STONE)
Block(-13,-8,-3,STONE)
Block(-13,-8,-2,STONE)
Block(-13,-8,-1,STONE)
Block(-13,-8,0,STONE)
Block(-13,-8,1,STONE)
Block(-13,-8,2,STONE)
Block(-13,-8,3,STONE)
Block(-13,-8,4,STONE)
Block(-13,-8,5,STONE)
Block(-13,-8,6,STONE)
Block(-13,-8,7,STONE)
Block(-13,-8,8,STONE)
Block(-13,-8,9,STONE)
Block(-13,-7,-8,STONE)
Block(-13,-7,-7,STONE)
Block(-13,-7,-6,STONE)
Block(-13,-7,-5,STONE)
Block(-13,-7,-4,STONE)
Block(-13,-7,-3,STONE)
Block(-13,-7,-2,STONE)
Block(-13,-7,-1,STONE)
Block(-13,-7,0,STONE)
Block(-13,-7,1,STONE)
Block(-13,-7,2,STONE)
Block(-13,-7,3,STONE)
Block(-13,-7,4,STONE)
Block(-13,-7,5,STONE)
Block(-13,-7,6,STONE)
Block(-13,-7,7,STONE)
Block(-13,-7,8,STONE)
Block(-13,-7,9,STONE)
Block(-13,-7,10,STONE)
Block(-13,-6,-9,STONE)
Block(-13,-6,-8,STONE)
Block(-13,-6,-7,STONE)
Block(-13,-6,-6,STONE)
Block(-13,-6,-5,STONE)
Block(-13,-6,-4,STONE)
Block(-13,-6,-3,STONE)
Block(-13,-6,-2,STONE)
Block(-13,-6,-1,STONE)
Block(-13,-6,0,STONE)
Block(-13,-6,1,STONE)
Block(-13,-6,2,STONE)
Block(-13,-6,3,STONE)
Block(-13,-6,4,STONE)
Block(-13,-6,5,STONE)
Block(-13,-6,6,STONE)
Block(-13,-6,7,STONE)
Block(-13,-6,8,STONE)
Block(-13,-6,9,STONE)
Block(-13,-6,10,STONE)
Block(-13,-6,11,STONE)
Block(-13,-5,-10,STONE)
Block(-13,-5,-9,STONE)
Block(-13,-5,-8,STONE)
Block(-13,-5,-7,STONE)
Block(-13,-5,-6,STONE)
Block(-13,-5,-5,STONE)
Block(-13,-5,-4,STONE)
Block(-13,-5,-3,STONE)
Block(-13,-5,-2,STONE)
Block(-13,-5,-1,STONE)
Block(-13,-5,0,STONE)
Block(-13,-5,1,STONE)
Block(-13,-5,2,STONE)
Block(-13,-5,3,STONE)
Block(-13,-5,4,STONE)
Block(-13,-5,5,STONE)
Block(-13,-5,6,STONE)
Block(-13,-5,7,STONE)
Block(-13,-5,8,STONE)
Block(-13,-5,9,STONE)
Block(-13,-5,10,STONE)
Block(-13,-5,11,STONE)
Block(-13,-4,-11,STONE)
Block(-13,-4,-10,STONE)
Block(-13,-4,-9,STONE)
Block(-13,-4,-8,STONE)
Block(-13,-4,-7,STONE)
Block(-13,-4,-6,STONE)
Block(-13,-4,-5,STONE)
Block(-13,-4,-4,STONE)
Block(-13,-4,-3,STONE)
Block(-13,-4,-2,STONE)
Block(-13,-4,-1,STONE)
Block(-13,-4,0,STONE)
Block(-13,-4,1,STONE)
Block(-13,-4,2,STONE)
Block(-13,-4,3,STONE)
Block(-13,-4,4,STONE)
Block(-13,-4,5,STONE)
Block(-13,-4,6,STONE)
Block(-13,-4,7,STONE)
Block(-13,-4,8,STONE)
Block(-13,-4,9,STONE)
Block(-13,-4,10,STONE)
Block(-13,-4,11,STONE)
Block(-13,-4,12,STONE)
Block(-13,-4,13,STONE)
Block(-13,-4,14,STONE)
Block(-13,-3,-12,STONE)
Block(-13,-3,-11,STONE)
Block(-13,-3,-10,STONE)
Block(-13,-3,-9,STONE)
Block(-13,-3,-8,STONE)
Block(-13,-3,-7,STONE)
Block(-13,-3,-6,STONE)
Block(-13,-3,-5,STONE)
Block(-13,-3,-4,STONE)
Block(-13,-3,-3,STONE)
Block(-13,-3,-2,STONE)
Block(-13,-3,-1,STONE)
Block(-13,-3,0,STONE)
Block(-13,-3,1,STONE)
Block(-13,-3,2,STONE)
Block(-13,-3,3,STONE)
Block(-13,-3,4,STONE)
Block(-13,-3,5,STONE)
Block(-13,-3,6,STONE)
Block(-13,-3,7,STONE)
Block(-13,-3,8,STONE)
Block(-13,-3,9,STONE)
Block(-13,-3,10,STONE)
Block(-13,-3,11,STONE)
Block(-13,-3,12,STONE)
Block(-13,-3,13,STONE)
Block(-13,-3,14,DIRT)
Block(-13,-2,-13,DIRT)
Block(-13,-2,-12,DIRT)
Block(-13,-2,-11,STONE)
Block(-13,-2,-10,STONE)
Block(-13,-2,-9,STONE)
Block(-13,-2,-8,STONE)
Block(-13,-2,-7,STONE)
Block(-13,-2,-6,STONE)
Block(-13,-2,-5,STONE)
Block(-13,-2,-4,STONE)
Block(-13,-2,-3,STONE)
Block(-13,-2,-2,STONE)
Block(-13,-2,-1,STONE)
Block(-13,-2,0,STONE)
Block(-13,-2,1,STONE)
Block(-13,-2,2,STONE)
Block(-13,-2,3,STONE)
Block(-13,-2,4,STONE)
Block(-13,-2,5,STONE)
Block(-13,-2,6,STONE)
Block(-13,-2,7,STONE)
Block(-13,-2,8,STONE)
Block(-13,-2,9,STONE)
Block(-13,-2,10,STONE)
Block(-13,-2,11,STONE)
Block(-13,-2,12,STONE)
Block(-13,-2,13,STONE)
Block(-13,-2,14,DIRT)
Block(-13,-1,-13,GRASS)
Block(-13,-1,-12,DIRT)
Block(-13,-1,-11,DIRT)
Block(-13,-1,-10,STONE)
Block(-13,-1,-9,STONE)
Block(-13,-1,-8,STONE)
Block(-13,-1,-7,STONE)
Block(-13,-1,-6,WOOD:5)
Block(-13,-1,-5,WOOD:5)
Block(-13,-1,-4,WOOD:5)
Block(-13,-1,-3,WOOD:5)
Block(-13,-1,-2,WOOL:13)
Block(-13,-1,-1,WOOL:13)
Block(-13,-1,0,WOOD:5)
Block(-13,-1,1,WOOD:5)
Block(-13,-1,2,STONE)
Block(-13,-1,3,STONE)
Block(-13,-1,4,WOOD:5)
Block(-13,-1,5,WOOD:5)
Block(-13,-1,6,WOOD:5)
Block(-13,-1,7,WOOD:5)
Block(-13,-1,8,WOOD:5)
Block(-13,-1,9,WOOD:5)
Block(-13,-1,10,STONE)
Block(-13,-1,11,STONE)
Block(-13,-1,12,STONE)
Block(-13,-1,13,DIRT)
Block(-13,-1,14,DIRT)
Block(-13,0,-12,DIRT)
Block(-13,0,-11,DIRT)
Block(-13,0,-10,STONE)
Block(-13,0,-9,STONE)
Block(-13,0,-8,STONE)
Block(-13,0,-7,WOOD:2)
RandomBlock(-13,0,-6,CHEST,../../nbt/VanillaLoot/simple_dungeon.nbt,50,CHEST,../../nbt/VanillaLoot/abandoned_mineshaft.nbt,30,CHEST,../../nbt/VanillaLoot/stronghold_corridor.nbt,100)
Block(-13,0,-5,AIR)
Block(-13,0,-4,AIR)
Block(-13,0,-3,AIR)
Block(-13,0,-2,AIR)
Block(-13,0,-1,AIR)
Block(-13,0,0,AIR)
Block(-13,0,1,AIR)
Block(-13,0,2,WOOD:5)
Block(-13,0,3,WOOD:5)
Block(-13,0,4,WOOD:5)
Block(-13,0,5,WOOL:14)
Block(-13,0,6,WOOL:14)
Block(-13,0,7,WOOL:14)
Block(-13,0,8,WOOL:14)
Block(-13,0,9,WOOD:5)
Block(-13,0,10,WOOD:2)
Block(-13,0,11,STONE)
Block(-13,0,12,STONE)
Block(-13,0,13,DIRT)
Block(-13,0,14,GRASS)
Block(-13,1,-12,GRASS)
Block(-13,1,-11,DIRT)
Block(-13,1,-10,DIRT)
Block(-13,1,-9,STONE)
Block(-13,1,-8,STONE)
Block(-13,1,-7,WOOD:2)
Block(-13,1,-6,AIR)
Block(-13,1,-5,AIR)
Block(-13,1,-4,AIR)
Block(-13,1,-3,AIR)
Block(-13,1,-2,AIR)
Block(-13,1,-1,AIR)
Block(-13,1,0,AIR)
Block(-13,1,1,AIR)
Block(-13,1,2,WOOD:5)
Block(-13,1,3,WOOD:5)
Block(-13,1,4,DARK_OAK_STAIRS)
Block(-13,1,5,AIR)
Block(-13,1,6,AIR)
Block(-13,1,7,AIR)
Block(-13,1,8,AIR)
Block(-13,1,9,DARK_OAK_STAIRS:2)
Block(-13,1,10,WOOD:2)
Block(-13,1,11,STONE)
Block(-13,1,12,DIRT)
Block(-13,1,13,DIRT)
Block(-13,2,-11,GRASS)
Block(-13,2,-10,DIRT)
Block(-13,2,-9,DIRT)
Block(-13,2,-8,STONE)
Block(-13,2,-7,WOOD:2)
Block(-13,2,-6,AIR)
Block(-13,2,-5,AIR)
Block(-13,2,-4,AIR)
Block(-13,2,-3,AIR)
Block(-13,2,-2,AIR)
Block(-13,2,-1,AIR)
Block(-13,2,0,AIR)
Block(-13,2,1,AIR)
Block(-13,2,2,BOOKSHELF)
Block(-13,2,3,WOOD:2)
Block(-13,2,4,AIR)
Block(-13,2,5,AIR)
Block(-13,2,6,AIR)
Block(-13,2,7,AIR)
Block(-13,2,8,AIR)
Block(-13,2,9,AIR)
Block(-13,2,10,WOOD:2)
Block(-13,2,11,DIRT)
Block(-13,2,12,DIRT)
Block(-13,2,13,GRASS)
Block(-13,3,-10,DIRT)
Block(-13,3,-9,DIRT)
Block(-13,3,-8,DIRT)
Block(-13,3,-7,WOOD:2)
Block(-13,3,-6,AIR)
Block(-13,3,-5,AIR)
Block(-13,3,-4,AIR)
Block(-13,3,-3,AIR)
Block(-13,3,-2,AIR)
Block(-13,3,-1,AIR)
Block(-13,3,0,AIR)
Block(-13,3,1,AIR)
Block(-13,3,2,BOOKSHELF)
Block(-13,3,3,WOOD:2)
Block(-13,3,4,AIR)
Block(-13,3,5,AIR)
Block(-13,3,6,AIR)
Block(-13,3,7,AIR)
Block(-13,3,8,AIR)
Block(-13,3,9,AIR)
Block(-13,3,10,DARK_OAK_FENCE)
Block(-13,3,11,WOOD:2)
Block(-13,3,12,DIRT)
Block(-13,4,-10,GRASS)
Block(-13,4,-9,DIRT)
Block(-13,4,-8,DIRT)
Block(-13,4,-7,WOOD:2)
Block(-13,4,-6,AIR)
Block(-13,4,-5,AIR)
Block(-13,4,-4,AIR)
Block(-13,4,-3,AIR)
Block(-13,4,-2,AIR)
Block(-13,4,-1,AIR)
Block(-13,4,0,AIR)
Block(-13,4,1,AIR)
Block(-13,4,2,BOOKSHELF)
Block(-13,4,3,WOOD:2)
Block(-13,4,4,AIR)
Block(-13,4,5,AIR)
Block(-13,4,8,AIR)
Block(-13,4,9,AIR)
Block(-13,4,10,WOOD:2)
Block(-13,4,11,DIRT)
Block(-13,4,12,GRASS)
Block(-13,5,-9,GRASS)
Block(-13,5,-8,DIRT)
Block(-13,5,-7,DIRT)
Block(-13,5,-6,STONE:6)
Block(-13,5,-5,STONE:6)
Block(-13,5,-4,STONE:6)
Block(-13,5,-3,STONE:6)
Block(-13,5,-2,STONE:6)
Block(-13,5,-1,STONE:6)
Block(-13,5,0,STONE:6)
Block(-13,5,1,STONE:6)
Block(-13,5,2,STONE:6)
Block(-13,5,3,STONE:6)
Block(-13,5,4,STONE:6)
Block(-13,5,5,STONE:6)
Block(-13,5,6,STONE:6)
Block(-13,5,7,STONE:6)
Block(-13,5,8,STONE:6)
Block(-13,5,9,STONE:6)
Block(-13,5,10,DIRT)
Block(-13,5,11,GRASS)
Block(-13,6,-8,GRASS)
Block(-13,6,-7,DIRT)
Block(-13,6,-6,DIRT)
Block(-13,6,-5,STONE)
Block(-13,6,-4,STONE)
Block(-13,6,-3,STONE)
Block(-13,6,-2,STONE)
Block(-13,6,-1,STONE)
Block(-13,6,0,STONE)
Block(-13,6,1,STONE)
Block(-13,6,2,STONE)
Block(-13,6,3,STONE)
Block(-13,6,4,STONE)
Block(-13,6,5,STONE)
Block(-13,6,6,STONE)
Block(-13,6,7,STONE)
Block(-13,6,8,DIRT)
Block(-13,6,9,DIRT)
Block(-13,6,10,GRASS)
Block(-13,7,-7,GRASS)
Block(-13,7,-6,DIRT)
Block(-13,7,-5,DIRT)
Block(-13,7,-4,STONE)
Block(-13,7,-3,STONE)
Block(-13,7,-2,STONE)
Block(-13,7,-1,STONE)
Block(-13,7,0,STONE)
Block(-13,7,1,STONE)
Block(-13,7,2,STONE)
Block(-13,7,3,STONE)
Block(-13,7,4,STONE)
Block(-13,7,5,STONE)
Block(-13,7,6,DIRT)
Block(-13,7,7,DIRT)
Block(-13,7,8,DIRT)
Block(-13,7,9,DIRT)
Block(-13,8,-6,GRASS)
Block(-13,8,-5,DIRT)
Block(-13,8,-4,DIRT)
Block(-13,8,-3,DIRT)
Block(-13,8,-2,DIRT)
Block(-13,8,-1,DIRT)
Block(-13,8,0,DIRT)
Block(-13,8,1,DIRT)
Block(-13,8,2,DIRT)
Block(-13,8,3,DIRT)
Block(-13,8,4,DIRT)
Block(-13,8,5,DIRT)
Block(-13,8,6,DIRT)
Block(-13,8,7,DIRT)
Block(-13,8,8,DIRT)
Block(-13,8,9,GRASS)
Block(-13,9,-5,DIRT)
Block(-13,9,-4,DIRT)
Block(-13,9,-3,DIRT)
Block(-13,9,-2,DIRT)
Block(-13,9,-1,DIRT)
Block(-13,9,0,DIRT)
Block(-13,9,1,DIRT)
Block(-13,9,2,DIRT)
Block(-13,9,3,DIRT)
Block(-13,9,4,DIRT)
Block(-13,9,5,DIRT)
Block(-13,9,6,DIRT)
Block(-13,9,7,DIRT)
Block(-13,9,8,GRASS)
Block(-13,10,-5,GRASS)
Block(-13,10,-4,DIRT)
Block(-13,10,-3,DIRT)
Block(-13,10,-2,DIRT)
Block(-13,10,-1,DIRT)
Block(-13,10,0,DIRT)
Block(-13,10,1,DIRT)
Block(-13,10,2,DIRT)
Block(-13,10,3,DIRT)
Block(-13,10,4,DIRT)
Block(-13,10,5,DIRT)
Block(-13,10,6,GRASS)
Block(-13,10,7,GRASS)
Block(-13,11,-4,GRASS)
Block(-13,11,-3,GRASS)
Block(-13,11,-2,GRASS)
Block(-13,11,-1,GRASS)
Block(-13,11,0,GRASS)
Block(-13,11,1,GRASS)
Block(-13,11,2,GRASS)
Block(-13,11,3,GRASS)
Block(-13,11,4,GRASS)
Block(-13,11,5,GRASS)
Block(-12,-10,-5,STONE)
Block(-12,-10,-4,STONE)
Block(-12,-10,-3,STONE)
Block(-12,-10,-2,STONE)
Block(-12,-10,-1,STONE)
Block(-12,-10,0,STONE)
Block(-12,-10,1,STONE)
Block(-12,-10,2,STONE)
Block(-12,-10,3,STONE)
Block(-12,-10,4,STONE)
Block(-12,-9,-6,STONE)
Block(-12,-9,-5,STONE)
Block(-12,-9,-4,STONE)
Block(-12,-9,-3,STONE)
Block(-12,-9,-2,STONE)
Block(-12,-9,-1,STONE)
Block(-12,-9,0,STONE)
Block(-12,-9,1,STONE)
Block(-12,-9,2,STONE)
Block(-12,-9,3,STONE)
Block(-12,-9,4,STONE)
Block(-12,-9,5,STONE)
Block(-12,-9,6,STONE)
Block(-12,-8,-7,STONE)
Block(-12,-8,-6,STONE)
Block(-12,-8,-5,STONE)
Block(-12,-8,-4,STONE)
Block(-12,-8,-3,STONE)
Block(-12,-8,-2,STONE)
Block(-12,-8,-1,STONE)
Block(-12,-8,0,STONE)
Block(-12,-8,1,STONE)
Block(-12,-8,2,STONE)
Block(-12,-8,3,STONE)
Block(-12,-8,4,STONE)
Block(-12,-8,5,STONE)
Block(-12,-8,6,STONE)
Block(-12,-8,7,STONE)
Block(-12,-8,8,STONE)
Block(-12,-8,9,STONE)
Block(-12,-7,-8,STONE)
Block(-12,-7,-7,STONE)
Block(-12,-7,-6,STONE)
Block(-12,-7,-5,STONE)
Block(-12,-7,-4,STONE)
Block(-12,-7,-3,STONE)
Block(-12,-7,-2,STONE)
Block(-12,-7,-1,STONE)
Block(-12,-7,0,STONE)
Block(-12,-7,1,STONE)
Block(-12,-7,2,STONE)
Block(-12,-7,3,STONE)
Block(-12,-7,4,STONE)
Block(-12,-7,5,STONE)
Block(-12,-7,6,STONE)
Block(-12,-7,7,STONE)
Block(-12,-7,8,STONE)
Block(-12,-7,9,STONE)
Block(-12,-7,10,STONE)
Block(-12,-6,-9,STONE)
Block(-12,-6,-8,STONE)
Block(-12,-6,-7,STONE)
Block(-12,-6,-6,STONE)
Block(-12,-6,-5,STONE)
Block(-12,-6,-4,STONE)
Block(-12,-6,-3,STONE)
Block(-12,-6,-2,STONE)
Block(-12,-6,-1,STONE)
Block(-12,-6,0,STONE)
Block(-12,-6,1,STONE)
Block(-12,-6,2,STONE)
Block(-12,-6,3,STONE)
Block(-12,-6,4,STONE)
Block(-12,-6,5,STONE)
Block(-12,-6,6,STONE)
Block(-12,-6,7,STONE)
Block(-12,-6,8,STONE)
Block(-12,-6,9,STONE)
Block(-12,-6,10,STONE)
Block(-12,-6,11,STONE)
Block(-12,-5,-10,STONE)
Block(-12,-5,-9,STONE)
Block(-12,-5,-8,STONE)
Block(-12,-5,-7,STONE)
Block(-12,-5,-6,STONE)
Block(-12,-5,-5,STONE)
Block(-12,-5,-4,STONE)
Block(-12,-5,-3,STONE)
Block(-12,-5,-2,STONE)
Block(-12,-5,-1,STONE)
Block(-12,-5,0,STONE)
Block(-12,-5,1,STONE)
Block(-12,-5,2,STONE)
Block(-12,-5,3,STONE)
Block(-12,-5,4,STONE)
Block(-12,-5,5,STONE)
Block(-12,-5,6,STONE)
Block(-12,-5,7,STONE)
Block(-12,-5,8,STONE)
Block(-12,-5,9,STONE)
Block(-12,-5,10,STONE)
Block(-12,-5,11,STONE)
Block(-12,-5,12,STONE)
Block(-12,-5,13,STONE)
Block(-12,-4,-11,STONE)
Block(-12,-4,-10,STONE)
Block(-12,-4,-9,STONE)
Block(-12,-4,-8,STONE)
Block(-12,-4,-7,STONE)
Block(-12,-4,-6,STONE)
Block(-12,-4,-5,STONE)
Block(-12,-4,-4,STONE)
Block(-12,-4,-3,STONE)
Block(-12,-4,-2,STONE)
Block(-12,-4,-1,STONE)
Block(-12,-4,0,STONE)
Block(-12,-4,1,STONE)
Block(-12,-4,2,STONE)
Block(-12,-4,3,STONE)
Block(-12,-4,4,STONE)
Block(-12,-4,5,STONE)
Block(-12,-4,6,STONE)
Block(-12,-4,7,STONE)
Block(-12,-4,8,STONE)
Block(-12,-4,9,STONE)
Block(-12,-4,10,STONE)
Block(-12,-4,11,STONE)
Block(-12,-4,12,STONE)
Block(-12,-4,13,STONE)
Block(-12,-4,14,STONE)
Block(-12,-4,15,DIRT)
Block(-12,-3,-13,DIRT)
Block(-12,-3,-12,STONE)
Block(-12,-3,-11,STONE)
Block(-12,-3,-10,STONE)
Block(-12,-3,-9,STONE)
Block(-12,-3,-8,STONE)
Block(-12,-3,-7,STONE)
Block(-12,-3,-6,STONE)
Block(-12,-3,-5,STONE)
Block(-12,-3,-4,STONE)
Block(-12,-3,-3,STONE)
Block(-12,-3,-2,STONE)
Block(-12,-3,-1,STONE)
Block(-12,-3,0,STONE)
Block(-12,-3,1,STONE)
Block(-12,-3,2,STONE)
Block(-12,-3,3,STONE)
Block(-12,-3,4,STONE)
Block(-12,-3,5,STONE)
Block(-12,-3,6,STONE)
Block(-12,-3,7,STONE)
Block(-12,-3,8,STONE)
Block(-12,-3,9,STONE)
Block(-12,-3,10,STONE)
Block(-12,-3,11,STONE)
Block(-12,-3,12,STONE)
Block(-12,-3,13,STONE)
Block(-12,-3,14,STONE)
Block(-12,-3,15,DIRT)
Block(-12,-2,-14,DIRT)
Block(-12,-2,-13,DIRT)
Block(-12,-2,-12,STONE)
Block(-12,-2,-11,STONE)
Block(-12,-2,-10,STONE)
Block(-12,-2,-9,STONE)
Block(-12,-2,-8,STONE)
Block(-12,-2,-7,STONE)
Block(-12,-2,-6,STONE)
Block(-12,-2,-5,STONE)
Block(-12,-2,-4,STONE)
Block(-12,-2,-3,STONE)
Block(-12,-2,-2,STONE)
Block(-12,-2,-1,STONE)
Block(-12,-2,0,STONE)
Block(-12,-2,1,STONE)
Block(-12,-2,2,STONE)
Block(-12,-2,3,STONE)
Block(-12,-2,4,STONE)
Block(-12,-2,5,STONE)
Block(-12,-2,6,STONE)
Block(-12,-2,7,STONE)
Block(-12,-2,8,STONE)
Block(-12,-2,9,STONE)
Block(-12,-2,10,STONE)
Block(-12,-2,11,STONE)
Block(-12,-2,12,STONE)
Block(-12,-2,13,STONE)
Block(-12,-2,14,DIRT)
Block(-12,-2,15,DIRT)
Block(-12,-1,-14,GRASS)
Block(-12,-1,-13,DIRT)
Block(-12,-1,-12,DIRT)
Block(-12,-1,-11,STONE)
Block(-12,-1,-10,STONE)
Block(-12,-1,-9,STONE)
Block(-12,-1,-8,STONE)
Block(-12,-1,-7,WOOD:5)
Block(-12,-1,-6,WOOD:5)
Block(-12,-1,-5,WOOD:5)
Block(-12,-1,-4,WOOD:5)
Block(-12,-1,-3,WOOD:5)
Block(-12,-1,-2,WOOD:5)
Block(-12,-1,-1,WOOD:5)
Block(-12,-1,0,WOOD:5)
Block(-12,-1,1,WOOD:5)
Block(-12,-1,2,STONE)
Block(-12,-1,3,STONE)
Block(-12,-1,4,WOOD:5)
Block(-12,-1,5,WOOD:5)
Block(-12,-1,6,WOOD:5)
Block(-12,-1,7,WOOD:5)
Block(-12,-1,8,WOOD:5)
Block(-12,-1,9,WOOD:5)
Block(-12,-1,10,STONE)
Block(-12,-1,11,STONE)
Block(-12,-1,12,STONE)
Block(-12,-1,13,STONE)
Block(-12,-1,14,DIRT)
Block(-12,-1,15,GRASS)
Block(-12,0,-13,GRASS)
Block(-12,0,-12,DIRT)
Block(-12,0,-11,DIRT)
Block(-12,0,-10,STONE)
Block(-12,0,-9,STONE)
Block(-12,0,-8,WOOD:2)
Block(-12,0,-7,DARK_OAK_STAIRS:0)
Block(-12,0,-6,DARK_OAK_STAIRS:0)
Block(-12,0,-5,DARK_OAK_STAIRS:0)
Block(-12,0,-4,DARK_OAK_STAIRS:0)
Block(-12,0,-3,DARK_OAK_STAIRS:0)
Block(-12,0,-2,DARK_OAK_STAIRS:0)
Block(-12,0,-1,DARK_OAK_STAIRS:0)
Block(-12,0,0,DARK_OAK_STAIRS:0)
Block(-12,0,1,DARK_OAK_STAIRS:0)
Block(-12,0,2,WOOD:5)
Block(-12,0,3,WOOD:5)
Block(-12,0,4,WOOD:5)
Block(-12,0,5,WOOL:14)
Block(-12,0,6,WOOL:14)
Block(-12,0,7,WOOL:14)
Block(-12,0,8,WOOL:14)
Block(-12,0,9,WOOD:5)
Block(-12,0,10,WOOD:2)
Block(-12,0,11,STONE)
Block(-12,0,12,STONE)
Block(-12,0,13,DIRT)
Block(-12,0,14,DIRT)
Block(-12,1,-12,DIRT)
Block(-12,1,-11,DIRT)
Block(-12,1,-10,DIRT)
Block(-12,1,-9,STONE)
Block(-12,1,-8,WOOD:2)
Block(-12,1,-7,AIR)
Block(-12,1,-6,AIR)
Block(-12,1,-5,AIR)
Block(-12,1,-4,AIR)
Block(-12,1,-3,AIR)
Block(-12,1,-2,AIR)
Block(-12,1,-1,AIR)
Block(-12,1,0,AIR)
Block(-12,1,1,AIR)
Block(-12,1,2,WOOD:5)
Block(-12,1,3,WOOD:5)
Block(-12,1,4,DARK_OAK_FENCE)
Block(-12,1,5,AIR)
Block(-12,1,6,AIR)
Block(-12,1,7,AIR)
Block(-12,1,8,AIR)
Block(-12,1,9,DARK_OAK_STAIRS:1)
Block(-12,1,10,WOOD:2)
Block(-12,1,11,STONE)
Block(-12,1,12,DIRT)
Block(-12,1,13,DIRT)
Block(-12,1,14,GRASS)
Block(-12,2,-12,GRASS)
Block(-12,2,-11,DIRT)
Block(-12,2,-10,DIRT)
Block(-12,2,-9,DIRT)
Block(-12,2,-8,WOOD:2)
Block(-12,2,-7,AIR)
Block(-12,2,-6,AIR)
Block(-12,2,-5,AIR)
Block(-12,2,-4,AIR)
Block(-12,2,-3,AIR)
Block(-12,2,-2,AIR)
Block(-12,2,-1,AIR)
Block(-12,2,0,AIR)
Block(-12,2,1,AIR)
Block(-12,2,2,BOOKSHELF)
Block(-12,2,3,WOOD:2)
Block(-12,2,4,DARK_OAK_FENCE)
Block(-12,2,5,AIR)
Block(-12,2,6,AIR)
Block(-12,2,7,AIR)
Block(-12,2,8,AIR)
Block(-12,2,9,AIR)
Block(-12,2,10,WOOD:2)
Block(-12,2,11,STONE)
Block(-12,2,12,DIRT)
Block(-12,2,13,DIRT)
Block(-12,3,-11,GRASS)
Block(-12,3,-10,DIRT)
Block(-12,3,-9,DIRT)
Block(-12,3,-8,WOOD:2)
Block(-12,3,-7,AIR)
Block(-12,3,-6,AIR)
Block(-12,3,-5,AIR)
Block(-12,3,-4,AIR)
Block(-12,3,-3,AIR)
Block(-12,3,-2,AIR)
Block(-12,3,-1,AIR)
Block(-12,3,0,AIR)
Block(-12,3,1,AIR)
Block(-12,3,2,AIR)
Block(-12,3,3,WOOD:2)
Block(-12,3,4,DARK_OAK_FENCE)
Block(-12,3,5,AIR)
Block(-12,3,6,AIR)
Block(-12,3,7,AIR)
Block(-12,3,8,AIR)
Block(-12,3,9,AIR)
Block(-12,3,10,DARK_OAK_FENCE)
Block(-12,3,11,WOOD:2)
Block(-12,3,12,DIRT)
Block(-12,3,13,GRASS)
Block(-12,4,-10,GRASS)
Block(-12,4,-9,DIRT)
Block(-12,4,-8,WOOD:2)
Block(-12,4,-7,AIR)
Block(-12,4,-6,AIR)
Block(-12,4,-5,AIR)
Block(-12,4,-4,AIR)
Block(-12,4,-3,AIR)
Block(-12,4,-2,AIR)
Block(-12,4,-1,AIR)
Block(-12,4,0,AIR)
Block(-12,4,1,AIR)
Block(-12,4,2,WEB)
Block(-12,4,3,WOOD:2)
Block(-12,4,4,50)
Block(-12,4,5,AIR)
Block(-12,4,6,AIR)
Block(-12,4,7,AIR)
Block(-12,4,8,AIR)
Block(-12,4,9,AIR)
Block(-12,4,10,WOOD:2)
Block(-12,4,11,DIRT)
Block(-12,4,12,GRASS)
Block(-12,5,-9,GRASS)
Block(-12,5,-8,DIRT)
Block(-12,5,-7,STONE:6)
Block(-12,5,-6,STONE:6)
Block(-12,5,-5,STONE:6)
Block(-12,5,-4,STONE:6)
Block(-12,5,-3,STONE:6)
Block(-12,5,-2,STONE:6)
Block(-12,5,-1,STONE:6)
Block(-12,5,0,STONE:6)
Block(-12,5,1,STONE:6)
Block(-12,5,2,STONE:6)
Block(-12,5,3,STONE:6)
Block(-12,5,4,STONE:6)
Block(-12,5,5,STONE:6)
Block(-12,5,6,STONE:6)
Block(-12,5,7,STONE:6)
Block(-12,5,8,STONE:6)
Block(-12,5,9,STONE:6)
Block(-12,5,10,DIRT)
Block(-12,5,11,DIRT)
Block(-12,6,-8,GRASS)
Block(-12,6,-7,DIRT)
Block(-12,6,-6,DIRT)
Block(-12,6,-5,STONE)
Block(-12,6,-4,STONE)
Block(-12,6,-3,STONE)
Block(-12,6,-2,STONE)
Block(-12,6,-1,STONE)
Block(-12,6,0,STONE)
Block(-12,6,1,STONE)
Block(-12,6,2,STONE)
Block(-12,6,3,STONE)
Block(-12,6,4,STONE)
Block(-12,6,5,STONE)
Block(-12,6,6,STONE)
Block(-12,6,7,STONE)
Block(-12,6,8,DIRT)
Block(-12,6,9,DIRT)
Block(-12,6,10,DIRT)
Block(-12,6,11,GRASS)
Block(-12,7,-7,GRASS)
Block(-12,7,-6,DIRT)
Block(-12,7,-5,DIRT)
Block(-12,7,-4,STONE)
Block(-12,7,-3,STONE)
Block(-12,7,-2,STONE)
Block(-12,7,-1,STONE)
Block(-12,7,0,STONE)
Block(-12,7,1,STONE)
Block(-12,7,2,STONE)
Block(-12,7,3,STONE)
Block(-12,7,4,STONE)
Block(-12,7,5,STONE)
Block(-12,7,6,STONE)
Block(-12,7,7,DIRT)
Block(-12,7,8,DIRT)
Block(-12,7,9,DIRT)
Block(-12,7,10,GRASS)
Block(-12,8,-6,GRASS)
Block(-12,8,-5,DIRT)
Block(-12,8,-4,DIRT)
Block(-12,8,-3,DIRT)
Block(-12,8,-2,DIRT)
Block(-12,8,-1,DIRT)
Block(-12,8,0,DIRT)
Block(-12,8,1,DIRT)
Block(-12,8,2,DIRT)
Block(-12,8,3,DIRT)
Block(-12,8,4,DIRT)
Block(-12,8,5,DIRT)
Block(-12,8,6,DIRT)
Block(-12,8,7,DIRT)
Block(-12,8,8,DIRT)
Block(-12,8,9,DIRT)
Block(-12,9,-5,DIRT)
Block(-12,9,-4,DIRT)
Block(-12,9,-3,DIRT)
Block(-12,9,-2,DIRT)
Block(-12,9,-1,DIRT)
Block(-12,9,0,DIRT)
Block(-12,9,1,DIRT)
Block(-12,9,2,DIRT)
Block(-12,9,3,DIRT)
Block(-12,9,4,DIRT)
Block(-12,9,5,DIRT)
Block(-12,9,6,DIRT)
Block(-12,9,7,DIRT)
Block(-12,9,8,GRASS)
Block(-12,9,9,GRASS)
Block(-12,10,-5,GRASS)
Block(-12,10,-4,DIRT)
Block(-12,10,-3,DIRT)
Block(-12,10,-2,DIRT)
Block(-12,10,-1,DIRT)
Block(-12,10,0,DIRT)
Block(-12,10,1,DIRT)
Block(-12,10,2,DIRT)
Block(-12,10,3,DIRT)
Block(-12,10,4,DIRT)
Block(-12,10,5,DIRT)
Block(-12,10,6,DIRT)
Block(-12,10,7,GRASS)
Block(-12,11,-4,GRASS)
Block(-12,11,-3,GRASS)
Block(-12,11,-2,GRASS)
Block(-12,11,-1,GRASS)
Block(-12,11,0,GRASS)
Block(-12,11,1,GRASS)
Block(-12,11,2,GRASS)
Block(-12,11,3,GRASS)
Block(-12,11,4,GRASS)
Block(-12,11,5,GRASS)
Block(-12,11,6,GRASS)
Block(-11,-10,-5,STONE)
Block(-11,-10,-4,STONE)
Block(-11,-10,-3,STONE)
Block(-11,-10,-2,STONE)
Block(-11,-10,-1,STONE)
Block(-11,-10,0,STONE)
Block(-11,-10,1,STONE)
Block(-11,-10,2,STONE)
Block(-11,-10,3,STONE)
Block(-11,-10,4,STONE)
Block(-11,-10,5,STONE)
Block(-11,-10,6,STONE)
Block(-11,-9,-6,STONE)
Block(-11,-9,-5,STONE)
Block(-11,-9,-4,STONE)
Block(-11,-9,-3,STONE)
Block(-11,-9,-2,STONE)
Block(-11,-9,-1,STONE)
Block(-11,-9,0,STONE)
Block(-11,-9,1,STONE)
Block(-11,-9,2,STONE)
Block(-11,-9,3,STONE)
Block(-11,-9,4,STONE)
Block(-11,-9,5,STONE)
Block(-11,-9,6,STONE)
Block(-11,-9,7,STONE)
Block(-11,-9,8,STONE)
Block(-11,-8,-8,STONE)
Block(-11,-8,-7,STONE)
Block(-11,-8,-6,STONE)
Block(-11,-8,-5,STONE)
Block(-11,-8,-4,STONE)
Block(-11,-8,-3,STONE)
Block(-11,-8,-2,STONE)
Block(-11,-8,-1,STONE)
Block(-11,-8,0,STONE)
Block(-11,-8,1,STONE)
Block(-11,-8,2,STONE)
Block(-11,-8,3,STONE)
Block(-11,-8,4,STONE)
Block(-11,-8,5,STONE)
Block(-11,-8,6,STONE)
Block(-11,-8,7,STONE)
Block(-11,-8,8,STONE)
Block(-11,-8,9,STONE)
Block(-11,-7,-8,STONE)
Block(-11,-7,-7,STONE)
Block(-11,-7,-6,STONE)
Block(-11,-7,-5,STONE)
Block(-11,-7,-4,STONE)
Block(-11,-7,-3,STONE)
Block(-11,-7,-2,STONE)
Block(-11,-7,-1,STONE)
Block(-11,-7,0,STONE)
Block(-11,-7,1,STONE)
Block(-11,-7,2,STONE)
Block(-11,-7,3,STONE)
Block(-11,-7,4,STONE)
Block(-11,-7,5,STONE)
Block(-11,-7,6,STONE)
Block(-11,-7,7,STONE)
Block(-11,-7,8,STONE)
Block(-11,-7,9,STONE)
Block(-11,-7,10,STONE)
Block(-11,-6,-10,STONE)
Block(-11,-6,-9,STONE)
Block(-11,-6,-8,STONE)
Block(-11,-6,-7,STONE)
Block(-11,-6,-6,STONE)
Block(-11,-6,-5,STONE)
Block(-11,-6,-4,STONE)
Block(-11,-6,-3,STONE)
Block(-11,-6,-2,STONE)
Block(-11,-6,-1,STONE)
Block(-11,-6,0,STONE)
Block(-11,-6,1,STONE)
Block(-11,-6,2,STONE)
Block(-11,-6,3,STONE)
Block(-11,-6,4,STONE)
Block(-11,-6,5,STONE)
Block(-11,-6,6,STONE)
Block(-11,-6,7,STONE)
Block(-11,-6,8,STONE)
Block(-11,-6,9,STONE)
Block(-11,-6,10,STONE)
Block(-11,-6,11,STONE)
Block(-11,-5,-10,STONE)
Block(-11,-5,-9,STONE)
Block(-11,-5,-8,STONE)
Block(-11,-5,-7,STONE)
Block(-11,-5,-6,STONE)
Block(-11,-5,-5,STONE)
Block(-11,-5,-4,STONE)
Block(-11,-5,-3,STONE)
Block(-11,-5,-2,STONE)
Block(-11,-5,-1,STONE)
Block(-11,-5,0,STONE)
Block(-11,-5,1,STONE)
Block(-11,-5,2,STONE)
Block(-11,-5,3,STONE)
Block(-11,-5,4,STONE)
Block(-11,-5,5,STONE)
Block(-11,-5,6,STONE)
Block(-11,-5,7,STONE)
Block(-11,-5,8,STONE)
Block(-11,-5,9,STONE)
Block(-11,-5,10,STONE)
Block(-11,-5,11,STONE)
Block(-11,-5,12,STONE)
Block(-11,-4,-12,STONE)
Block(-11,-4,-11,STONE)
Block(-11,-4,-10,STONE)
Block(-11,-4,-9,STONE)
Block(-11,-4,-8,STONE)
Block(-11,-4,-7,STONE)
Block(-11,-4,-6,STONE)
Block(-11,-4,-5,STONE)
Block(-11,-4,-4,STONE)
Block(-11,-4,-3,STONE)
Block(-11,-4,-2,STONE)
Block(-11,-4,-1,STONE)
Block(-11,-4,0,STONE)
Block(-11,-4,1,STONE)
Block(-11,-4,2,STONE)
Block(-11,-4,3,STONE)
Block(-11,-4,4,STONE)
Block(-11,-4,5,STONE)
Block(-11,-4,6,STONE)
Block(-11,-4,7,STONE)
Block(-11,-4,8,STONE)
Block(-11,-4,9,STONE)
Block(-11,-4,10,STONE)
Block(-11,-4,11,STONE)
Block(-11,-4,12,STONE)
Block(-11,-4,13,STONE)
Block(-11,-4,14,STONE)
Block(-11,-3,-13,STONE)
Block(-11,-3,-12,STONE)
Block(-11,-3,-11,STONE)
Block(-11,-3,-10,STONE)
Block(-11,-3,-9,STONE)
Block(-11,-3,-8,STONE)
Block(-11,-3,-7,STONE)
Block(-11,-3,-6,STONE)
Block(-11,-3,-5,STONE)
Block(-11,-3,-4,STONE)
Block(-11,-3,-3,STONE)
Block(-11,-3,-2,STONE)
Block(-11,-3,-1,STONE)
Block(-11,-3,0,STONE)
Block(-11,-3,1,STONE)
Block(-11,-3,2,STONE)
Block(-11,-3,3,STONE)
Block(-11,-3,4,STONE)
Block(-11,-3,5,STONE)
Block(-11,-3,6,STONE)
Block(-11,-3,7,STONE)
Block(-11,-3,8,STONE)
Block(-11,-3,9,STONE)
Block(-11,-3,10,STONE)
Block(-11,-3,11,STONE)
Block(-11,-3,12,STONE)
Block(-11,-3,13,STONE)
Block(-11,-3,14,STONE)
Block(-11,-3,15,DIRT)
Block(-11,-2,-14,DIRT)
Block(-11,-2,-13,DIRT)
Block(-11,-2,-12,STONE)
Block(-11,-2,-11,STONE)
Block(-11,-2,-10,STONE)
Block(-11,-2,-9,STONE)
Block(-11,-2,-8,STONE)
Block(-11,-2,-7,STONE)
Block(-11,-2,-6,STONE)
Block(-11,-2,-5,STONE)
Block(-11,-2,-4,STONE)
Block(-11,-2,-3,STONE)
Block(-11,-2,-2,STONE)
Block(-11,-2,-1,STONE)
Block(-11,-2,0,STONE)
Block(-11,-2,1,STONE)
Block(-11,-2,2,STONE)
Block(-11,-2,3,STONE)
Block(-11,-2,4,STONE)
Block(-11,-2,5,STONE)
Block(-11,-2,6,STONE)
Block(-11,-2,7,STONE)
Block(-11,-2,8,STONE)
Block(-11,-2,9,STONE)
Block(-11,-2,10,STONE)
Block(-11,-2,11,STONE)
Block(-11,-2,12,STONE)
Block(-11,-2,13,STONE)
Block(-11,-2,14,STONE)
Block(-11,-2,15,DIRT)
Block(-11,-2,16,DIRT)
Block(-11,-1,-14,GRASS)
Block(-11,-1,-13,DIRT)
Block(-11,-1,-12,STONE)
Block(-11,-1,-11,STONE)
Block(-11,-1,-10,STONE)
Block(-11,-1,-9,STONE)
Block(-11,-1,-8,STONE)
Block(-11,-1,-7,STONE)
Block(-11,-1,-6,STONE)
Block(-11,-1,-5,STONE)
Block(-11,-1,-4,STONE)
Block(-11,-1,-3,STONE)
Block(-11,-1,-2,WOOD:5)
Block(-11,-1,-1,WOOD:5)
Block(-11,-1,0,STONE)
Block(-11,-1,1,STONE)
Block(-11,-1,2,STONE)
Block(-11,-1,3,STONE)
Block(-11,-1,4,WOOD:5)
Block(-11,-1,5,WOOD:5)
Block(-11,-1,6,WOOD:5)
Block(-11,-1,7,WOOD:5)
Block(-11,-1,8,WOOD:5)
Block(-11,-1,9,WOOD:5)
Block(-11,-1,10,STONE)
Block(-11,-1,11,STONE)
Block(-11,-1,12,STONE)
Block(-11,-1,13,STONE)
Block(-11,-1,14,DIRT)
Block(-11,-1,15,DIRT)
Block(-11,-1,16,GRASS)
Block(-11,0,-13,DIRT)
Block(-11,0,-12,DIRT)
Block(-11,0,-11,STONE)
Block(-11,0,-10,STONE)
Block(-11,0,-9,STONE)
Block(-11,0,-8,STONE)
Block(-11,0,-7,WOOD:5)
Block(-11,0,-6,WOOD:5)
Block(-11,0,-5,WOOD:5)
Block(-11,0,-4,WOOD:5)
Block(-11,0,-3,WOOD:5)
Block(-11,0,-2,WOOD:5)
Block(-11,0,-1,WOOD:5)
Block(-11,0,0,WOOD:5)
Block(-11,0,1,WOOD:5)
Block(-11,0,2,STONE)
Block(-11,0,3,WOOD:5)
Block(-11,0,4,DARK_OAK_STAIRS:1)
Block(-11,0,5,DARK_OAK_STAIRS:1)
Block(-11,0,6,DARK_OAK_STAIRS:1)
Block(-11,0,7,DARK_OAK_STAIRS:1)
Block(-11,0,8,DARK_OAK_STAIRS:1)
Block(-11,0,9,DARK_OAK_STAIRS:2)
Block(-11,0,10,WOOD:2)
Block(-11,0,11,STONE)
Block(-11,0,12,STONE)
Block(-11,0,13,DIRT)
Block(-11,0,14,DIRT)
Block(-11,0,15,GRASS)
Block(-11,1,-13,GRASS)
Block(-11,1,-12,DIRT)
Block(-11,1,-11,DIRT)
Block(-11,1,-10,WOOD:2)
Block(-11,1,-9,WOOD:2)
Block(-11,1,-8,WOOD:2)
Block(-11,1,-7,WOOD:2)
Block(-11,1,-6,WOOD:2)
Block(-11,1,-5,WOOD:2)
Block(-11,1,-4,WOOD:5)
Block(-11,1,-3,WOOD:5)
Block(-11,1,-2,DARK_OAK_STAIRS)
Block(-11,1,-1,AIR)
Block(-11,1,0,DARK_OAK_STAIRS:2)
Block(-11,1,1,WOOD:5)
Block(-11,1,2,WOOD:5)
Block(-11,1,3,WOOD:2)
Block(-11,1,4,AIR)
Block(-11,1,5,AIR)
Block(-11,1,6,AIR)
Block(-11,1,7,AIR)
Block(-11,1,8,AIR)
Block(-11,1,9,AIR)
Block(-11,1,10,WOOD:2)
Block(-11,1,11,STONE)
Block(-11,1,12,STONE)
Block(-11,1,13,DIRT)
Block(-11,1,14,DIRT)
Block(-11,2,-12,DIRT)
Block(-11,2,-11,DIRT)
Block(-11,2,-10,WOOD:2)
Block(-11,2,-9,WOOD:2)
Block(-11,2,-8,WOOD:2)
Block(-11,2,-7,DARK_OAK_FENCE)
Block(-11,2,-6,DARK_OAK_FENCE)
Block(-11,2,-5,DARK_OAK_FENCE)
Block(-11,2,-4,WOOD:2)
Block(-11,2,-3,WOOD:5)
Block(-11,2,-2,AIR)
Block(-11,2,-1,AIR)
Block(-11,2,0,AIR)
Block(-11,2,1,WOOD:5)
Block(-11,2,2,WOOD:2)
Block(-11,2,3,WOOD:2)
Block(-11,2,4,AIR)
Block(-11,2,5,AIR)
Block(-11,2,6,AIR)
Block(-11,2,7,AIR)
Block(-11,2,8,AIR)
Block(-11,2,9,AIR)
Block(-11,2,10,WOOD:2)
Block(-11,2,11,STONE)
Block(-11,2,12,DIRT)
Block(-11,2,13,DIRT)
Block(-11,2,14,GRASS)
Block(-11,3,-12,GRASS)
Block(-11,3,-11,DIRT)
Block(-11,3,-10,WOOD:2)
Block(-11,3,-9,WOOD:2)
Block(-11,3,-8,WOOD:2)
Block(-11,3,-7,DARK_OAK_FENCE)
Block(-11,3,-6,DARK_OAK_FENCE)
Block(-11,3,-5,DARK_OAK_FENCE)
Block(-11,3,-4,WOOD:2)
Block(-11,3,-3,WOOD:5)
Block(-11,3,-2,DARK_OAK_STAIRS:7)
Block(-11,3,-1,AIR)
Block(-11,3,0,DARK_OAK_STAIRS:6)
Block(-11,3,1,WOOD:5)
Block(-11,3,2,WOOD:2)
Block(-11,3,3,WOOD:2)
Block(-11,3,4,AIR)
Block(-11,3,5,AIR)
Block(-11,3,6,AIR)
Block(-11,3,7,AIR)
Block(-11,3,8,AIR)
Block(-11,3,9,AIR)
Block(-11,3,10,WOOD:2)
Block(-11,3,11,STONE)
Block(-11,3,12,DIRT)
Block(-11,3,13,GRASS)
Block(-11,4,-11,GRASS)
Block(-11,4,-10,WOOD:2)
Block(-11,4,-9,WOOD:2)
Block(-11,4,-8,WOOD:2)
Block(-11,4,-7,WOOD:2)
Block(-11,4,-6,WOOD:2)
Block(-11,4,-5,WOOD:2)
Block(-11,4,-4,WOOD:2)
Block(-11,4,-3,WOOD:5)
Block(-11,4,-2,WOOD:5)
Block(-11,4,-1,WOOD:5)
Block(-11,4,0,WOOD:5)
Block(-11,4,1,WOOD:5)
Block(-11,4,2,WOOD:5)
Block(-11,4,3,WOOD:2)
Block(-11,4,4,AIR)
Block(-11,4,5,AIR)
Block(-11,4,6,AIR)
Block(-11,4,7,AIR)
Block(-11,4,8,AIR)
Block(-11,4,9,AIR)
Block(-11,4,10,WOOD:2)
Block(-11,4,11,DIRT)
Block(-11,4,12,DIRT)
Block(-11,5,-10,GRASS)
Block(-11,5,-9,DIRT)
Block(-11,5,-8,DIRT)
Block(-11,5,-7,DIRT)
Block(-11,5,-6,STONE)
Block(-11,5,-5,STONE)
Block(-11,5,-4,STONE)
Block(-11,5,-3,STONE)
Block(-11,5,-2,STONE)
Block(-11,5,-1,STONE)
Block(-11,5,0,STONE)
Block(-11,5,1,STONE)
Block(-11,5,2,STONE)
Block(-11,5,3,STONE)
Block(-11,5,4,STONE:6)
Block(-11,5,5,STONE:6)
Block(-11,5,6,STONE:6)
Block(-11,5,7,STONE:6)
Block(-11,5,8,STONE:6)
Block(-11,5,9,STONE:6)
Block(-11,5,10,DIRT)
Block(-11,5,11,DIRT)
Block(-11,5,12,GRASS)
Block(-11,6,-9,GRASS)
Block(-11,6,-8,GRASS)
Block(-11,6,-7,DIRT)
Block(-11,6,-6,DIRT)
Block(-11,6,-5,STONE)
Block(-11,6,-4,STONE)
Block(-11,6,-3,STONE)
Block(-11,6,-2,STONE)
Block(-11,6,-1,STONE)
Block(-11,6,0,STONE)
Block(-11,6,1,STONE)
Block(-11,6,2,STONE)
Block(-11,6,3,STONE)
Block(-11,6,4,STONE)
Block(-11,6,5,STONE)
Block(-11,6,6,STONE)
Block(-11,6,7,STONE)
Block(-11,6,8,STONE)
Block(-11,6,9,DIRT)
Block(-11,6,10,DIRT)
Block(-11,6,11,DIRT)
Block(-11,7,-7,DIRT)
Block(-11,7,-6,DIRT)
Block(-11,7,-5,DIRT)
Block(-11,7,-4,STONE)
Block(-11,7,-3,STONE)
Block(-11,7,-2,STONE)
Block(-11,7,-1,STONE)
Block(-11,7,0,STONE)
Block(-11,7,1,STONE)
Block(-11,7,2,STONE)
Block(-11,7,3,STONE)
Block(-11,7,4,STONE)
Block(-11,7,5,STONE)
Block(-11,7,6,STONE)
Block(-11,7,7,STONE)
Block(-11,7,8,DIRT)
Block(-11,7,9,DIRT)
Block(-11,7,10,DIRT)
Block(-11,7,11,GRASS)
Block(-11,8,-7,GRASS)
Block(-11,8,-6,DIRT)
Block(-11,8,-5,DIRT)
Block(-11,8,-4,DIRT)
Block(-11,8,-3,DIRT)
Block(-11,8,-2,DIRT)
Block(-11,8,-1,DIRT)
Block(-11,8,0,DIRT)
Block(-11,8,1,DIRT)
Block(-11,8,2,DIRT)
Block(-11,8,3,DIRT)
Block(-11,8,4,DIRT)
Block(-11,8,5,DIRT)
Block(-11,8,6,DIRT)
Block(-11,8,7,DIRT)
Block(-11,8,8,DIRT)
Block(-11,8,9,DIRT)
Block(-11,8,10,GRASS)
Block(-11,9,-6,GRASS)
Block(-11,9,-5,DIRT)
Block(-11,9,-4,DIRT)
Block(-11,9,-3,DIRT)
Block(-11,9,-2,DIRT)
Block(-11,9,-1,DIRT)
Block(-11,9,0,DIRT)
Block(-11,9,1,DIRT)
Block(-11,9,2,DIRT)
Block(-11,9,3,DIRT)
Block(-11,9,4,DIRT)
Block(-11,9,5,DIRT)
Block(-11,9,6,DIRT)
Block(-11,9,7,DIRT)
Block(-11,9,8,DIRT)
Block(-11,9,9,GRASS)
Block(-11,10,-5,GRASS)
Block(-11,10,-4,DIRT)
Block(-11,10,-3,DIRT)
Block(-11,10,-2,DIRT)
Block(-11,10,-1,DIRT)
Block(-11,10,0,DIRT)
Block(-11,10,1,DIRT)
Block(-11,10,2,DIRT)
Block(-11,10,3,DIRT)
Block(-11,10,4,DIRT)
Block(-11,10,5,DIRT)
Block(-11,10,6,DIRT)
Block(-11,10,7,DIRT)
Block(-11,10,8,GRASS)
Block(-11,11,-4,GRASS)
Block(-11,11,-3,GRASS)
Block(-11,11,-2,GRASS)
Block(-11,11,-1,GRASS)
Block(-11,11,0,GRASS)
Block(-11,11,1,GRASS)
Block(-11,11,2,GRASS)
Block(-11,11,3,GRASS)
Block(-11,11,4,GRASS)
Block(-11,11,5,GRASS)
Block(-11,11,6,GRASS)
Block(-11,11,7,GRASS)
Block(-10,-10,-5,STONE)
Block(-10,-10,-4,STONE)
Block(-10,-10,-3,STONE)
Block(-10,-10,-2,STONE)
Block(-10,-10,-1,STONE)
Block(-10,-10,0,STONE)
Block(-10,-10,1,STONE)
Block(-10,-10,2,STONE)
Block(-10,-10,3,STONE)
Block(-10,-10,4,STONE)
Block(-10,-10,5,STONE)
Block(-10,-10,6,STONE)
Block(-10,-10,7,STONE)
Block(-10,-9,-6,STONE)
Block(-10,-9,-5,STONE)
Block(-10,-9,-4,STONE)
Block(-10,-9,-3,STONE)
Block(-10,-9,-2,STONE)
Block(-10,-9,-1,STONE)
Block(-10,-9,0,STONE)
Block(-10,-9,1,STONE)
Block(-10,-9,2,STONE)
Block(-10,-9,3,STONE)
Block(-10,-9,4,STONE)
Block(-10,-9,5,STONE)
Block(-10,-9,6,STONE)
Block(-10,-9,7,STONE)
Block(-10,-9,8,STONE)
Block(-10,-8,-8,STONE)
Block(-10,-8,-7,STONE)
Block(-10,-8,-6,STONE)
Block(-10,-8,-5,STONE)
Block(-10,-8,-4,STONE)
Block(-10,-8,-3,STONE)
Block(-10,-8,-2,STONE)
Block(-10,-8,-1,STONE)
Block(-10,-8,0,STONE)
Block(-10,-8,1,STONE)
Block(-10,-8,2,STONE)
Block(-10,-8,3,STONE)
Block(-10,-8,4,STONE)
Block(-10,-8,5,STONE)
Block(-10,-8,6,STONE)
Block(-10,-8,7,STONE)
Block(-10,-8,8,STONE)
Block(-10,-8,9,STONE)
Block(-10,-7,-9,STONE)
Block(-10,-7,-8,STONE)
Block(-10,-7,-7,STONE)
Block(-10,-7,-6,STONE)
Block(-10,-7,-5,STONE)
Block(-10,-7,-4,STONE)
Block(-10,-7,-3,STONE)
Block(-10,-7,-2,STONE)
Block(-10,-7,-1,STONE)
Block(-10,-7,0,STONE)
Block(-10,-7,1,STONE)
Block(-10,-7,2,STONE)
Block(-10,-7,3,STONE)
Block(-10,-7,4,STONE)
Block(-10,-7,5,STONE)
Block(-10,-7,6,STONE)
Block(-10,-7,7,STONE)
Block(-10,-7,8,STONE)
Block(-10,-7,9,STONE)
Block(-10,-7,10,STONE)
Block(-10,-6,-10,STONE)
Block(-10,-6,-9,STONE)
Block(-10,-6,-8,STONE)
Block(-10,-6,-7,STONE)
Block(-10,-6,-6,STONE)
Block(-10,-6,-5,STONE)
Block(-10,-6,-4,STONE)
Block(-10,-6,-3,STONE)
Block(-10,-6,-2,STONE)
Block(-10,-6,-1,STONE)
Block(-10,-6,0,STONE)
Block(-10,-6,1,STONE)
Block(-10,-6,2,STONE)
Block(-10,-6,3,STONE)
Block(-10,-6,4,STONE)
Block(-10,-6,5,STONE)
Block(-10,-6,6,STONE)
Block(-10,-6,7,STONE)
Block(-10,-6,8,STONE)
Block(-10,-6,9,STONE)
Block(-10,-6,10,STONE)
Block(-10,-6,11,STONE)
Block(-10,-5,-11,STONE)
Block(-10,-5,-10,STONE)
Block(-10,-5,-9,STONE)
Block(-10,-5,-8,STONE)
Block(-10,-5,-7,STONE)
Block(-10,-5,-6,STONE)
Block(-10,-5,-5,STONE)
Block(-10,-5,-4,STONE)
Block(-10,-5,-3,STONE)
Block(-10,-5,-2,STONE)
Block(-10,-5,-1,STONE)
Block(-10,-5,0,STONE)
Block(-10,-5,1,STONE)
Block(-10,-5,2,STONE)
Block(-10,-5,3,STONE)
Block(-10,-5,4,STONE)
Block(-10,-5,5,STONE)
Block(-10,-5,6,STONE)
Block(-10,-5,7,STONE)
Block(-10,-5,8,STONE)
Block(-10,-5,9,STONE)
Block(-10,-5,10,STONE)
Block(-10,-5,11,STONE)
Block(-10,-4,-13,STONE)
Block(-10,-4,-12,STONE)
Block(-10,-4,-11,STONE)
Block(-10,-4,-10,STONE)
Block(-10,-4,-9,STONE)
Block(-10,-4,-8,STONE)
Block(-10,-4,-7,STONE)
Block(-10,-4,-6,STONE)
Block(-10,-4,-5,STONE)
Block(-10,-4,-4,STONE)
Block(-10,-4,-3,STONE)
Block(-10,-4,-2,STONE)
Block(-10,-4,-1,STONE)
Block(-10,-4,0,STONE)
Block(-10,-4,1,STONE)
Block(-10,-4,2,STONE)
Block(-10,-4,3,STONE)
Block(-10,-4,4,STONE)
Block(-10,-4,5,STONE)
Block(-10,-4,6,STONE)
Block(-10,-4,7,STONE)
Block(-10,-4,8,STONE)
Block(-10,-4,9,STONE)
Block(-10,-4,10,STONE)
Block(-10,-4,11,STONE)
Block(-10,-4,12,STONE)
Block(-10,-4,13,STONE)
Block(-10,-4,14,STONE)
Block(-10,-3,-14,DIRT)
Block(-10,-3,-13,STONE)
Block(-10,-3,-12,STONE)
Block(-10,-3,-11,STONE)
Block(-10,-3,-10,STONE)
Block(-10,-3,-9,STONE)
Block(-10,-3,-8,STONE)
Block(-10,-3,-7,STONE)
Block(-10,-3,-6,STONE)
Block(-10,-3,-5,STONE)
Block(-10,-3,-4,STONE)
Block(-10,-3,-3,STONE)
Block(-10,-3,-2,STONE)
Block(-10,-3,-1,STONE)
Block(-10,-3,0,STONE)
Block(-10,-3,1,STONE)
Block(-10,-3,2,STONE)
Block(-10,-3,3,STONE)
Block(-10,-3,4,STONE)
Block(-10,-3,5,STONE)
Block(-10,-3,6,STONE)
Block(-10,-3,7,STONE)
Block(-10,-3,8,STONE)
Block(-10,-3,9,STONE)
Block(-10,-3,10,STONE)
Block(-10,-3,11,STONE)
Block(-10,-3,12,STONE)
Block(-10,-3,13,STONE)
Block(-10,-3,14,STONE)
Block(-10,-3,15,STONE)
Block(-10,-2,-15,DIRT)
Block(-10,-2,-14,DIRT)
Block(-10,-2,-13,STONE)
Block(-10,-2,-12,STONE)
Block(-10,-2,-11,STONE)
Block(-10,-2,-10,STONE)
Block(-10,-2,-9,STONE)
Block(-10,-2,-8,STONE)
Block(-10,-2,-7,STONE)
Block(-10,-2,-6,STONE)
Block(-10,-2,-5,STONE)
Block(-10,-2,-4,STONE)
Block(-10,-2,-3,STONE)
Block(-10,-2,-2,STONE)
Block(-10,-2,-1,STONE)
Block(-10,-2,0,STONE)
Block(-10,-2,1,STONE)
Block(-10,-2,2,STONE)
Block(-10,-2,3,STONE)
Block(-10,-2,4,STONE)
Block(-10,-2,5,STONE)
Block(-10,-2,6,STONE)
Block(-10,-2,7,STONE)
Block(-10,-2,8,STONE)
Block(-10,-2,9,STONE)
Block(-10,-2,10,STONE)
Block(-10,-2,11,STONE)
Block(-10,-2,12,STONE)
Block(-10,-2,13,STONE)
Block(-10,-2,14,STONE)
Block(-10,-2,15,DIRT)
Block(-10,-2,16,DIRT)
Block(-10,-1,-15,GRASS)
Block(-10,-1,-14,DIRT)
Block(-10,-1,-13,DIRT)
Block(-10,-1,-12,STONE)
Block(-10,-1,-11,STONE)
Block(-10,-1,-10,STONE)
Block(-10,-1,-9,STONE)
Block(-10,-1,-8,STONE)
Block(-10,-1,-7,STONE)
Block(-10,-1,-6,STONE)
Block(-10,-1,-5,STONE)
Block(-10,-1,-4,STONE)
Block(-10,-1,-3,STONE)
Block(-10,-1,-2,STONE)
Block(-10,-1,-1,STONE)
Block(-10,-1,0,STONE)
Block(-10,-1,1,STONE)
Block(-10,-1,2,STONE)
Block(-10,-1,3,STONE)
Block(-10,-1,4,WOOD:5)
Block(-10,-1,5,WOOD:5)
Block(-10,-1,6,WOOD:5)
Block(-10,-1,7,WOOD:5)
Block(-10,-1,8,WOOD:5)
Block(-10,-1,9,WOOD:5)
Block(-10,-1,10,STONE)
Block(-10,-1,11,STONE)
Block(-10,-1,12,STONE)
Block(-10,-1,13,STONE)
Block(-10,-1,14,DIRT)
Block(-10,-1,15,DIRT)
Block(-10,-1,16,GRASS)
Block(-10,0,-14,GRASS)
Block(-10,0,-13,DIRT)
Block(-10,0,-12,DIRT)
Block(-10,0,-11,STONE)
Block(-10,0,-10,STONE)
Block(-10,0,-9,BRICK)
Block(-10,0,-8,BRICK)
Block(-10,0,-7,BRICK)
Block(-10,0,-6,WOOD:5)
Block(-10,0,-5,WOOD:5)
Block(-10,0,-4,WOOD:5)
Block(-10,0,-3,WOOD:5)
Block(-10,0,-2,WOOD:5)
Block(-10,0,-1,WOOD:5)
Block(-10,0,0,WOOD:5)
Block(-10,0,1,WOOD:5)
Block(-10,0,2,STONE)
Block(-10,0,3,WOOD:5)
Block(-10,0,4,DARK_OAK_STAIRS)
Block(-10,0,5,AIR)
Block(-10,0,6,AIR)
Block(-10,0,7,AIR)
Block(-10,0,8,AIR)
Block(-10,0,9,DARK_OAK_STAIRS:2)
Block(-10,0,10,WOOD:2)
Block(-10,0,11,STONE)
Block(-10,0,12,STONE)
Block(-10,0,13,STONE)
Block(-10,0,14,DIRT)
Block(-10,0,15,DIRT)
Block(-10,1,-13,DIRT)
Block(-10,1,-12,DIRT)
Block(-10,1,-11,DIRT)
Block(-10,1,-10,COBBLESTONE)
Block(-10,1,-9,AIR)
Block(-10,1,-8,AIR)
Block(-10,1,-7,AIR)
Block(-10,1,-6,DARK_OAK_STAIRS:1)
Block(-10,1,-5,DARK_OAK_STAIRS:1)
Block(-10,1,-4,DARK_OAK_STAIRS:1)
Block(-10,1,-3,DARK_OAK_STAIRS:1)
Block(-10,1,-2,DARK_OAK_STAIRS)
Block(-10,1,-1,AIR)
Block(-10,1,0,DARK_OAK_STAIRS:2)
Block(-10,1,1,DARK_OAK_STAIRS:1)
Block(-10,1,2,DARK_OAK_STAIRS:2)
Block(-10,1,3,WOOD:2)
Block(-10,1,4,AIR)
Block(-10,1,5,AIR)
