#######################################################################
# +-----------------------------------------------------------------+ #
# |                            BO3 object                           | #
# +-----------------------------------------------------------------+ #
#######################################################################

# The descriptions in this file are true only for TerrainControl. They are not true for the Minecraft Worlds mod!
# Minecraft Worlds completely reimplemented BO3s, check the MCW documentation on the mc/mctcp forums for how to use BO3s with MCW
# or watch the video's on my YT channel at https://www.youtube.com/user/PeeGee85. You can check out the "Editing and importing schematics & BO3s" 
# series of video's, in part 2 I explain BO3s. 

# This is the config file of a custom object.
# If you add this object correctly to your BiomeConfigs, it will spawn in the world.

# This is the creator of this BO3 object
Author: Unknown

# A short description of this BO3 object
Description: This BO3 was converted from a schematic using the MineCraft Worlds Editor. Unfortunately the author and description information for the schematic could not be found. If you know who the author of the schematic is then please tell the author of this BO3!

# The BO3 version, don't change this! It can be used by external applications to do a version check.
Version: 3

# The settings mode, WriteAll, WriteWithoutComments or WriteDisable. See WorldConfig.
SettingsMode: WriteDisable

#######################################################################
# +-----------------------------------------------------------------+ #
# |                          Main settings                          | #
# +-----------------------------------------------------------------+ #
#######################################################################

# This needs to be set to true to spawn the object in the Tree and Sapling resources.
Tree: false

# The frequency of the BO3 from 1 to 200. Tries this many times to spawn this BO3 when using the CustomObject(...) resource.
# Ignored by Tree(..), Sapling(..) and CustomStructure(..)
Frequency: 40

# The rarity of the BO3 from 0 to 100. Each spawn attempt has rarity% chance to succeed when using the CustomObject(...) resource.
# Ignored by Tree(..), Sapling(..) and CustomStructure(..)
Rarity: 100.0

# If you set this to true, the BO3 will be placed with a random rotation.
RotateRandomly: false

# The spawn height of the BO3 - randomY, highestBlock or highestSolidBlock.
SpawnHeight: randomY

# The height limits for the BO3.
MinHeight: 28

MaxHeight: 32

# Objects can have other objects attached to it: branches. Branches can also
# have branches attached to it, which can also have branches, etc. This is the
# maximum branch depth for this objects.
MaxBranchDepth: 10

# When spawned with the UseWorld keyword, this BO3 should NOT spawn in the following biomes.
# If you writer.write the BO3 name directly in the BiomeConfigs, this will be ignored.
ExcludedBiomes: All

#######################################################################
# +-----------------------------------------------------------------+ #
# |                      Source block settings                      | #
# +-----------------------------------------------------------------+ #
#######################################################################

# The block(s) the BO3 should spawn in.
SourceBlocks: AIR

# The maximum percentage of the BO3 that can be outside the SourceBlock.
# The BO3 won't be placed on a location with more blocks outside the SourceBlock than this percentage.
MaxPercentageOutsideSourceBlock: 100

# What to do when a block is about to be placed outside the SourceBlock? (dontPlace, placeAnyway)
OutsideSourceBlock: placeAnyway

#######################################################################
# +-----------------------------------------------------------------+ #
# |                              Blocks                             | #
# +-----------------------------------------------------------------+ #
#######################################################################

# All the blocks used in the BO3 are listed here. Possible blocks:
# Block(x,y,z,id[.data][,nbtfile.nbt)
# RandomBlock(x,y,z,id[:data][,nbtfile.nbt],chance[,id[:data][,nbtfile.nbt],chance[,...]])
# So RandomBlock(0,0,0,CHEST,chest.nbt,50,CHEST,anotherchest.nbt,100) will spawn a chest at
# the BO3 origin, and give it a 50% chance to have the contents of chest.nbt, or, if that
# fails, a 100% percent chance to have the contents of anotherchest.nbt.

Block(-8,26,8,174)
Block(-8,27,5,174)
Block(-8,27,6,174)
Block(-8,27,7,174)
Block(-8,27,8,174)
Block(-8,28,3,174)
Block(-8,28,4,174)
Block(-8,28,5,174)
Block(-8,28,6,174)
Block(-8,28,7,174)
Block(-8,28,8,174)
Block(-8,29,2,174)
Block(-8,29,3,174)
Block(-8,29,4,174)
Block(-8,29,5,174)
Block(-8,29,6,174)
Block(-8,29,7,174)
Block(-8,29,8,174)
Block(-8,30,1,174)
Block(-8,30,2,174)
Block(-8,30,3,174)
Block(-8,30,4,174)
Block(-8,30,5,174)
Block(-8,30,6,174)
Block(-8,30,7,174)
Block(-8,30,8,174)
Block(-8,31,0,174)
Block(-8,31,1,174)
Block(-8,31,2,174)
Block(-8,31,3,174)
Block(-8,31,4,174)
Block(-8,31,5,174)
Block(-8,31,6,174)
Block(-8,31,7,174)
Block(-8,31,8,174)
Block(-8,32,0,174)
Block(-8,32,1,174)
Block(-8,32,2,174)
Block(-8,32,3,174)
Block(-8,32,4,174)
Block(-8,32,5,174)
Block(-8,32,6,174)
Block(-8,32,7,174)
Block(-8,32,8,174)
Block(-8,33,-1,174)
Block(-8,33,0,174)
Block(-8,33,1,174)
Block(-8,33,2,174)
Block(-8,33,3,174)
Block(-8,33,4,174)
Block(-8,33,5,174)
Block(-8,33,6,174)
Block(-8,33,7,174)
Block(-8,33,8,174)
Block(-8,34,-1,174)
Block(-8,34,0,174)
Block(-8,34,1,174)
Block(-8,34,2,174)
Block(-8,34,3,174)
Block(-8,34,4,174)
Block(-8,34,5,174)
Block(-8,34,6,174)
Block(-8,34,7,174)
Block(-8,34,8,174)
Block(-8,35,-3,174)
Block(-8,35,-2,174)
Block(-8,35,-1,174)
Block(-8,35,0,174)
Block(-8,35,1,174)
Block(-8,35,2,174)
Block(-8,35,3,174)
Block(-8,35,4,174)
Block(-8,35,5,174)
Block(-8,35,6,174)
Block(-8,35,7,174)
Block(-8,35,8,174)
Block(-8,36,-4,174)
Block(-8,36,-3,174)
Block(-8,36,-2,174)
Block(-8,36,-1,174)
Block(-8,36,0,174)
Block(-8,36,1,174)
Block(-8,36,2,174)
Block(-8,36,3,174)
Block(-8,36,4,174)
Block(-8,36,5,174)
Block(-8,36,6,174)
Block(-8,36,7,174)
Block(-8,36,8,174)
Block(-8,37,-5,174)
Block(-8,37,-4,174)
Block(-8,37,-3,174)
Block(-8,37,-2,174)
Block(-8,37,-1,174)
Block(-8,37,0,174)
Block(-8,37,1,174)
Block(-8,37,2,174)
Block(-8,37,3,174)
Block(-8,37,4,174)
Block(-8,37,5,174)
Block(-8,37,6,174)
Block(-8,37,7,174)
Block(-8,37,8,174)
Block(-8,38,-5,174)
Block(-8,38,-4,174)
Block(-8,38,-3,174)
Block(-8,38,-2,174)
Block(-8,38,-1,174)
Block(-8,38,0,174)
Block(-8,38,1,174)
Block(-8,38,2,174)
Block(-8,38,3,174)
Block(-8,38,4,174)
Block(-8,38,5,174)
Block(-8,38,6,174)
Block(-8,38,7,174)
Block(-8,38,8,174)
Block(-8,39,-6,174)
Block(-8,39,-5,174)
Block(-8,39,-4,174)
Block(-8,39,-3,174)
Block(-8,39,-2,174)
Block(-8,39,-1,174)
Block(-8,39,0,174)
Block(-8,39,1,174)
Block(-8,39,2,174)
Block(-8,39,3,174)
Block(-8,39,4,174)
Block(-8,39,5,174)
Block(-8,39,6,174)
Block(-8,39,7,174)
Block(-8,39,8,174)
Block(-8,40,-6,174)
Block(-8,40,-5,174)
Block(-8,40,-4,174)
Block(-8,40,-3,174)
Block(-8,40,-2,174)
Block(-8,40,-1,174)
Block(-8,40,0,174)
Block(-8,40,1,174)
Block(-8,40,2,174)
Block(-8,40,3,174)
Block(-8,40,4,174)
Block(-8,40,5,174)
Block(-8,40,6,174)
Block(-8,40,7,174)
Block(-8,40,8,174)
Block(-8,41,-6,174)
Block(-8,41,-5,174)
Block(-8,41,-4,174)
Block(-8,41,-3,174)
Block(-8,41,-2,174)
Block(-8,41,-1,174)
Block(-8,41,0,174)
Block(-8,41,1,174)
Block(-8,41,2,174)
Block(-8,41,3,174)
Block(-8,41,4,174)
Block(-8,41,5,174)
Block(-8,41,6,174)
Block(-8,41,7,174)
Block(-8,41,8,174)
Block(-8,42,-6,174)
Block(-8,42,-5,174)
Block(-8,42,-4,174)
Block(-8,42,-3,174)
Block(-8,42,-2,174)
Block(-8,42,-1,174)
Block(-8,42,0,174)
Block(-8,42,1,174)
Block(-8,42,2,174)
Block(-8,42,3,174)
Block(-8,42,4,174)
Block(-8,42,5,174)
Block(-8,42,6,174)
Block(-8,42,7,174)
Block(-8,42,8,174)
Block(-8,43,-5,174)
Block(-8,43,-4,174)
Block(-8,43,-3,174)
Block(-8,43,-2,174)
Block(-8,43,-1,174)
Block(-8,43,0,174)
Block(-8,43,1,174)
Block(-8,43,2,174)
Block(-8,43,3,174)
Block(-8,43,4,174)
Block(-8,43,5,174)
Block(-8,43,6,174)
Block(-8,43,7,174)
Block(-8,43,8,174)
Block(-8,44,-4,174)
Block(-8,44,-3,174)
Block(-8,44,-2,174)
Block(-8,44,-1,174)
Block(-8,44,0,174)
Block(-8,44,1,174)
Block(-8,44,2,174)
Block(-8,44,3,174)
Block(-8,44,4,174)
Block(-8,44,5,174)
Block(-8,44,6,174)
Block(-8,44,7,174)
Block(-8,44,8,174)
Block(-8,45,-3,174)
Block(-8,45,-2,174)
Block(-8,45,-1,174)
Block(-8,45,0,174)
Block(-8,45,1,174)
Block(-8,45,2,174)
Block(-8,45,3,174)
Block(-8,45,4,174)
Block(-8,45,5,174)
Block(-8,45,6,174)
Block(-8,45,7,174)
Block(-8,45,8,174)
Block(-8,46,-3,174)
Block(-8,46,-2,174)
Block(-8,46,-1,174)
Block(-8,46,0,174)
Block(-8,46,1,174)
Block(-8,46,2,174)
Block(-8,46,3,174)
Block(-8,46,4,174)
Block(-8,46,5,174)
Block(-8,46,6,174)
Block(-8,46,7,174)
Block(-8,46,8,174)
Block(-8,47,-2,174)
Block(-8,47,-1,174)
Block(-8,47,0,174)
Block(-8,47,1,174)
Block(-8,47,2,174)
Block(-8,47,3,174)
Block(-8,47,4,174)
Block(-8,47,5,174)
Block(-8,47,6,174)
Block(-8,47,7,174)
Block(-8,47,8,174)
Block(-8,48,-1,174)
Block(-8,48,0,174)
Block(-8,48,1,174)
Block(-8,48,2,174)
Block(-8,48,3,174)
Block(-8,48,4,174)
Block(-8,48,5,174)
Block(-8,48,6,174)
Block(-8,48,7,174)
Block(-8,48,8,174)
Block(-8,49,0,174)
Block(-8,49,1,174)
Block(-8,49,2,174)
Block(-8,49,3,174)
Block(-8,49,4,174)
Block(-8,49,5,174)
Block(-8,49,6,174)
Block(-8,49,7,174)
Block(-8,49,8,174)
Block(-8,50,0,174)
Block(-8,50,1,174)
Block(-8,50,2,174)
Block(-8,50,3,174)
Block(-8,50,4,174)
Block(-8,50,5,174)
Block(-8,50,6,174)
Block(-8,50,7,174)
Block(-8,50,8,174)
Block(-8,51,1,174)
Block(-8,51,2,174)
Block(-8,51,3,174)
Block(-8,51,4,174)
Block(-8,51,5,174)
Block(-8,51,6,174)
Block(-8,51,7,174)
Block(-8,51,8,174)
Block(-8,52,2,174)
Block(-8,52,3,174)
Block(-8,52,4,174)
Block(-8,52,5,174)
Block(-8,52,6,174)
Block(-8,52,7,174)
Block(-8,52,8,174)
Block(-8,53,3,174)
Block(-8,53,4,174)
Block(-8,53,5,174)
Block(-8,53,6,174)
Block(-8,53,7,174)
Block(-8,53,8,174)
Block(-8,54,5,174)
Block(-8,54,6,174)
Block(-8,54,7,174)
Block(-8,54,8,174)
Block(-8,55,8,174)
Block(-7,25,8,174)
Block(-7,26,6,174)
Block(-7,26,7,174)
Block(-7,26,8,174)
Block(-7,27,2,174)
Block(-7,27,3,174)
Block(-7,27,4,174)
Block(-7,27,5,174)
Block(-7,27,6,174)
Block(-7,27,7,174)
Block(-7,27,8,174)
Block(-7,28,2,174)
Block(-7,28,3,174)
Block(-7,28,4,174)
Block(-7,28,5,174)
Block(-7,28,6,174)
Block(-7,28,7,174)
Block(-7,28,8,174)
Block(-7,29,1,174)
Block(-7,29,2,174)
Block(-7,29,3,174)
Block(-7,29,4,174)
Block(-7,29,5,174)
Block(-7,29,6,174)
Block(-7,29,7,174)
Block(-7,29,8,174)
Block(-7,30,0,174)
Block(-7,30,1,174)
Block(-7,30,2,174)
Block(-7,30,3,174)
Block(-7,30,4,174)
Block(-7,30,5,174)
Block(-7,30,6,174)
Block(-7,30,7,174)
Block(-7,30,8,174)
Block(-7,31,0,174)
Block(-7,31,1,174)
Block(-7,31,2,174)
Block(-7,31,3,174)
Block(-7,31,4,174)
Block(-7,31,5,174)
Block(-7,31,6,174)
Block(-7,31,7,174)
Block(-7,31,8,174)
Block(-7,32,-2,174)
Block(-7,32,-1,174)
Block(-7,32,0,174)
Block(-7,32,1,174)
Block(-7,32,2,174)
Block(-7,32,3,174)
Block(-7,32,4,174)
Block(-7,32,5,174)
Block(-7,32,6,174)
Block(-7,32,7,174)
Block(-7,32,8,174)
Block(-7,33,-3,174)
Block(-7,33,-2,174)
Block(-7,33,-1,174)
Block(-7,33,0,174)
Block(-7,33,1,174)
Block(-7,33,2,174)
Block(-7,33,3,174)
Block(-7,33,4,174)
Block(-7,33,5,174)
Block(-7,33,6,174)
Block(-7,33,7,174)
Block(-7,33,8,174)
Block(-7,34,-5,174)
Block(-7,34,-4,174)
Block(-7,34,-3,174)
Block(-7,34,-2,174)
Block(-7,34,-1,174)
Block(-7,34,0,174)
Block(-7,34,1,174)
Block(-7,34,2,174)
Block(-7,34,3,174)
Block(-7,34,4,174)
Block(-7,34,5,174)
Block(-7,34,6,174)
Block(-7,34,7,174)
Block(-7,34,8,174)
Block(-7,35,-5,174)
Block(-7,35,-4,174)
Block(-7,35,-3,174)
Block(-7,35,-2,174)
Block(-7,35,-1,174)
Block(-7,35,0,174)
Block(-7,35,1,174)
Block(-7,35,2,174)
Block(-7,35,3,174)
Block(-7,35,4,174)
Block(-7,35,5,174)
Block(-7,35,6,174)
Block(-7,35,7,174)
Block(-7,35,8,174)
Block(-7,36,-5,174)
Block(-7,36,-4,174)
Block(-7,36,-3,174)
Block(-7,36,-2,174)
Block(-7,36,-1,174)
Block(-7,36,0,174)
Block(-7,36,1,174)
Block(-7,36,2,174)
Block(-7,36,3,174)
Block(-7,36,4,174)
Block(-7,36,5,174)
Block(-7,36,6,174)
Block(-7,36,7,174)
Block(-7,36,8,174)
Block(-7,37,-6,174)
Block(-7,37,-5,174)
Block(-7,37,-4,174)
Block(-7,37,-3,174)
Block(-7,37,-2,174)
Block(-7,37,-1,174)
Block(-7,37,0,174)
Block(-7,37,1,174)
Block(-7,37,2,174)
Block(-7,37,3,174)
Block(-7,37,4,174)
Block(-7,37,5,174)
Block(-7,37,6,174)
Block(-7,37,7,174)
Block(-7,37,8,174)
Block(-7,38,-6,174)
Block(-7,38,-5,174)
Block(-7,38,-4,174)
Block(-7,38,-3,174)
Block(-7,38,-2,174)
Block(-7,38,-1,174)
Block(-7,38,0,174)
Block(-7,38,1,174)
Block(-7,38,2,174)
Block(-7,38,3,174)
Block(-7,38,4,174)
Block(-7,38,5,174)
Block(-7,38,6,174)
Block(-7,38,7,174)
Block(-7,38,8,174)
Block(-7,39,-6,174)
Block(-7,39,-5,174)
Block(-7,39,-4,174)
Block(-7,39,-3,174)
Block(-7,39,-2,174)
Block(-7,39,-1,174)
Block(-7,39,0,174)
Block(-7,39,1,174)
Block(-7,39,2,174)
Block(-7,39,3,174)
Block(-7,39,4,174)
Block(-7,39,5,174)
Block(-7,39,6,174)
Block(-7,39,7,174)
Block(-7,39,8,174)
Block(-7,40,-7,174)
Block(-7,40,-6,174)
Block(-7,40,-5,174)
Block(-7,40,-4,174)
Block(-7,40,-3,174)
Block(-7,40,-2,174)
Block(-7,40,-1,174)
Block(-7,40,0,174)
Block(-7,40,1,174)
Block(-7,40,2,174)
Block(-7,40,3,174)
Block(-7,40,4,174)
Block(-7,40,5,174)
Block(-7,40,6,174)
Block(-7,40,7,174)
Block(-7,40,8,174)
Block(-7,41,-7,174)
Block(-7,41,-6,174)
Block(-7,41,-5,174)
Block(-7,41,-4,174)
Block(-7,41,-3,174)
Block(-7,41,-2,174)
Block(-7,41,-1,174)
Block(-7,41,0,174)
Block(-7,41,1,174)
Block(-7,41,2,174)
Block(-7,41,3,174)
Block(-7,41,4,174)
Block(-7,41,5,174)
Block(-7,41,6,174)
Block(-7,41,7,174)
Block(-7,41,8,174)
Block(-7,42,-7,174)
Block(-7,42,-6,174)
Block(-7,42,-5,174)
Block(-7,42,-4,174)
Block(-7,42,-3,174)
Block(-7,42,-2,174)
Block(-7,42,-1,174)
Block(-7,42,0,174)
Block(-7,42,1,174)
Block(-7,42,2,174)
Block(-7,42,3,174)
Block(-7,42,4,174)
Block(-7,42,5,174)
Block(-7,42,6,174)
Block(-7,42,7,174)
Block(-7,42,8,174)
Block(-7,43,-6,174)
Block(-7,43,-5,174)
Block(-7,43,-4,174)
Block(-7,43,-3,174)
Block(-7,43,-2,174)
Block(-7,43,-1,174)
Block(-7,43,0,174)
Block(-7,43,1,174)
Block(-7,43,2,174)
Block(-7,43,3,174)
Block(-7,43,4,174)
Block(-7,43,5,174)
Block(-7,43,6,174)
Block(-7,43,7,174)
Block(-7,43,8,174)
Block(-7,44,-5,174)
Block(-7,44,-4,174)
Block(-7,44,-3,174)
Block(-7,44,-2,174)
Block(-7,44,-1,174)
Block(-7,44,0,174)
Block(-7,44,1,174)
Block(-7,44,2,174)
Block(-7,44,3,174)
Block(-7,44,4,174)
Block(-7,44,5,174)
Block(-7,44,6,174)
Block(-7,44,7,174)
Block(-7,44,8,174)
Block(-7,45,-4,174)
Block(-7,45,-3,174)
Block(-7,45,-2,174)
Block(-7,45,-1,174)
Block(-7,45,0,174)
Block(-7,45,1,174)
Block(-7,45,2,174)
Block(-7,45,3,174)
Block(-7,45,4,174)
Block(-7,45,5,174)
Block(-7,45,6,174)
Block(-7,45,7,174)
Block(-7,45,8,174)
Block(-7,46,-5,174)
Block(-7,46,-4,174)
Block(-7,46,-3,174)
Block(-7,46,-2,174)
Block(-7,46,-1,174)
Block(-7,46,0,174)
Block(-7,46,1,174)
Block(-7,46,2,174)
Block(-7,46,3,174)
Block(-7,46,4,174)
Block(-7,46,5,174)
Block(-7,46,6,174)
Block(-7,46,7,174)
Block(-7,46,8,174)
Block(-7,47,-3,174)
Block(-7,47,-2,174)
Block(-7,47,-1,174)
Block(-7,47,0,174)
Block(-7,47,1,174)
Block(-7,47,2,174)
Block(-7,47,3,174)
Block(-7,47,4,174)
Block(-7,47,5,174)
Block(-7,47,6,174)
Block(-7,47,7,174)
Block(-7,47,8,174)
Block(-7,48,-3,174)
Block(-7,48,-2,174)
Block(-7,48,-1,174)
Block(-7,48,0,174)
Block(-7,48,1,174)
Block(-7,48,2,174)
Block(-7,48,3,174)
Block(-7,48,4,174)
Block(-7,48,5,174)
Block(-7,48,6,174)
Block(-7,48,7,174)
Block(-7,48,8,174)
Block(-7,49,-2,174)
Block(-7,49,-1,174)
Block(-7,49,0,174)
Block(-7,49,1,174)
Block(-7,49,2,174)
Block(-7,49,3,174)
Block(-7,49,4,174)
Block(-7,49,5,174)
Block(-7,49,6,174)
Block(-7,49,7,174)
Block(-7,49,8,174)
Block(-7,50,0,174)
Block(-7,50,1,174)
Block(-7,50,2,174)
Block(-7,50,3,174)
Block(-7,50,4,174)
Block(-7,50,5,174)
Block(-7,50,6,174)
Block(-7,50,7,174)
Block(-7,50,8,174)
Block(-7,51,0,174)
Block(-7,51,1,174)
Block(-7,51,2,174)
Block(-7,51,3,174)
Block(-7,51,4,174)
Block(-7,51,5,174)
Block(-7,51,6,174)
Block(-7,51,7,174)
Block(-7,51,8,174)
Block(-7,52,1,174)
Block(-7,52,2,174)
Block(-7,52,3,174)
Block(-7,52,4,174)
Block(-7,52,5,174)
Block(-7,52,6,174)
Block(-7,52,7,174)
Block(-7,52,8,174)
Block(-7,53,2,174)
Block(-7,53,3,174)
Block(-7,53,4,174)
Block(-7,53,5,174)
Block(-7,53,6,174)
Block(-7,53,7,174)
Block(-7,53,8,174)
Block(-7,54,2,174)
Block(-7,54,3,174)
Block(-7,54,4,174)
Block(-7,54,5,174)
Block(-7,54,6,174)
Block(-7,54,7,174)
Block(-7,54,8,174)
Block(-7,55,6,174)
Block(-7,55,7,174)
Block(-7,55,8,174)
Block(-7,56,8,174)
Block(-6,23,8,174)
Block(-6,24,6,174)
Block(-6,24,7,174)
Block(-6,24,8,174)
Block(-6,25,5,174)
Block(-6,25,6,174)
Block(-6,25,7,174)
Block(-6,25,8,174)
Block(-6,26,4,174)
Block(-6,26,5,174)
Block(-6,26,6,174)
Block(-6,26,7,174)
Block(-6,26,8,174)
Block(-6,27,1,174)
Block(-6,27,2,174)
Block(-6,27,3,174)
Block(-6,27,4,174)
Block(-6,27,5,174)
Block(-6,27,6,174)
Block(-6,27,7,174)
Block(-6,27,8,174)
Block(-6,28,0,174)
Block(-6,28,1,174)
Block(-6,28,2,174)
Block(-6,28,3,174)
Block(-6,28,4,174)
Block(-6,28,5,174)
Block(-6,28,6,174)
Block(-6,28,7,174)
Block(-6,28,8,174)
Block(-6,29,0,174)
Block(-6,29,1,174)
Block(-6,29,2,174)
Block(-6,29,3,174)
Block(-6,29,4,174)
Block(-6,29,5,174)
Block(-6,29,6,174)
Block(-6,29,7,174)
Block(-6,29,8,174)
Block(-6,30,-1,174)
Block(-6,30,0,174)
Block(-6,30,1,174)
Block(-6,30,2,174)
Block(-6,30,3,174)
Block(-6,30,4,174)
Block(-6,30,5,174)
Block(-6,30,6,174)
Block(-6,30,7,174)
Block(-6,30,8,174)
Block(-6,31,-3,174)
Block(-6,31,-2,174)
Block(-6,31,-1,174)
Block(-6,31,0,174)
Block(-6,31,1,174)
Block(-6,31,2,174)
Block(-6,31,3,174)
Block(-6,31,4,174)
Block(-6,31,5,174)
Block(-6,31,6,174)
Block(-6,31,7,174)
Block(-6,31,8,174)
Block(-6,32,-5,174)
Block(-6,32,-4,174)
Block(-6,32,-3,174)
Block(-6,32,-2,174)
Block(-6,32,-1,174)
Block(-6,32,0,174)
Block(-6,32,1,174)
Block(-6,32,2,174)
Block(-6,32,3,174)
Block(-6,32,4,174)
Block(-6,32,5,174)
Block(-6,32,6,174)
Block(-6,32,7,174)
Block(-6,32,8,174)
Block(-6,33,-5,174)
Block(-6,33,-4,174)
Block(-6,33,-3,174)
Block(-6,33,-2,174)
Block(-6,33,-1,174)
Block(-6,33,0,174)
Block(-6,33,1,174)
Block(-6,33,2,174)
Block(-6,33,3,174)
Block(-6,33,4,174)
Block(-6,33,5,174)
Block(-6,33,6,174)
Block(-6,33,7,174)
Block(-6,33,8,174)
Block(-6,34,-6,174)
Block(-6,34,-5,174)
Block(-6,34,-4,174)
Block(-6,34,-3,174)
Block(-6,34,-2,174)
Block(-6,34,-1,174)
Block(-6,34,0,174)
Block(-6,34,1,174)
Block(-6,34,2,174)
Block(-6,34,3,174)
Block(-6,34,4,174)
Block(-6,34,5,174)
Block(-6,34,6,174)
Block(-6,34,7,174)
Block(-6,34,8,174)
Block(-6,35,-6,174)
Block(-6,35,-5,174)
Block(-6,35,-4,174)
Block(-6,35,-3,174)
Block(-6,35,-2,174)
Block(-6,35,-1,174)
Block(-6,35,0,174)
Block(-6,35,1,174)
Block(-6,35,2,174)
Block(-6,35,3,174)
Block(-6,35,4,174)
Block(-6,35,5,174)
Block(-6,35,6,174)
Block(-6,35,7,174)
Block(-6,35,8,174)
Block(-6,36,-6,174)
Block(-6,36,-5,174)
Block(-6,36,-4,174)
Block(-6,36,-3,174)
Block(-6,36,-2,174)
Block(-6,36,-1,174)
Block(-6,36,0,174)
Block(-6,36,1,174)
Block(-6,36,2,174)
Block(-6,36,3,174)
Block(-6,36,4,174)
Block(-6,36,5,174)
Block(-6,36,6,174)
Block(-6,36,7,174)
Block(-6,36,8,174)
Block(-6,37,-7,174)
Block(-6,37,-6,174)
Block(-6,37,-5,174)
Block(-6,37,-4,174)
Block(-6,37,-3,174)
Block(-6,37,-2,174)
Block(-6,37,-1,174)
Block(-6,37,0,174)
Block(-6,37,1,174)
Block(-6,37,2,174)
Block(-6,37,3,174)
Block(-6,37,4,174)
Block(-6,37,5,174)
Block(-6,37,6,174)
Block(-6,37,7,174)
Block(-6,37,8,174)
Block(-6,38,-7,174)
Block(-6,38,-6,174)
Block(-6,38,-5,174)
Block(-6,38,-4,174)
Block(-6,38,-3,174)
Block(-6,38,-2,174)
Block(-6,38,-1,174)
Block(-6,38,0,174)
Block(-6,38,1,174)
Block(-6,38,2,174)
Block(-6,38,3,174)
Block(-6,38,4,174)
Block(-6,38,5,174)
Block(-6,38,6,174)
Block(-6,38,7,174)
Block(-6,38,8,174)
Block(-6,39,-7,174)
Block(-6,39,-6,174)
Block(-6,39,-5,174)
Block(-6,39,-4,174)
Block(-6,39,-3,174)
Block(-6,39,-2,174)
Block(-6,39,-1,174)
Block(-6,39,0,174)
Block(-6,39,1,174)
Block(-6,39,2,174)
Block(-6,39,3,174)
Block(-6,39,4,174)
Block(-6,39,5,174)
Block(-6,39,6,174)
Block(-6,39,7,174)
Block(-6,39,8,174)
Block(-6,40,-7,174)
Block(-6,40,-6,174)
Block(-6,40,-5,174)
Block(-6,40,-4,174)
Block(-6,40,-3,174)
Block(-6,40,-2,174)
Block(-6,40,-1,174)
Block(-6,40,0,174)
Block(-6,40,1,174)
Block(-6,40,2,174)
Block(-6,40,3,174)
Block(-6,40,4,174)
Block(-6,40,5,174)
Block(-6,40,6,174)
Block(-6,40,7,174)
Block(-6,40,8,174)
Block(-6,41,-7,174)
Block(-6,41,-6,174)
Block(-6,41,-5,174)
Block(-6,41,-4,174)
Block(-6,41,-3,174)
Block(-6,41,-2,174)
Block(-6,41,-1,174)
Block(-6,41,0,174)
Block(-6,41,1,174)
Block(-6,41,2,174)
Block(-6,41,3,174)
Block(-6,41,4,174)
Block(-6,41,5,174)
Block(-6,41,6,174)
Block(-6,41,7,174)
Block(-6,41,8,174)
Block(-6,42,-7,174)
Block(-6,42,-6,174)
Block(-6,42,-5,174)
Block(-6,42,-4,174)
Block(-6,42,-3,174)
Block(-6,42,-2,174)
Block(-6,42,-1,174)
Block(-6,42,0,174)
Block(-6,42,1,174)
Block(-6,42,2,174)
Block(-6,42,3,174)
Block(-6,42,4,174)
Block(-6,42,5,174)
Block(-6,42,6,174)
Block(-6,42,7,174)
Block(-6,42,8,174)
Block(-6,43,-7,174)
Block(-6,43,-6,174)
Block(-6,43,-5,174)
Block(-6,43,-4,174)
Block(-6,43,-3,174)
Block(-6,43,-2,174)
Block(-6,43,-1,174)
Block(-6,43,0,174)
Block(-6,43,1,174)
Block(-6,43,2,174)
Block(-6,43,3,174)
Block(-6,43,4,174)
Block(-6,43,5,174)
Block(-6,43,6,174)
Block(-6,43,7,174)
Block(-6,43,8,174)
Block(-6,44,-6,174)
Block(-6,44,-5,174)
Block(-6,44,-4,174)
Block(-6,44,-3,174)
Block(-6,44,-2,174)
Block(-6,44,-1,174)
Block(-6,44,0,174)
Block(-6,44,1,174)
Block(-6,44,2,174)
Block(-6,44,3,174)
Block(-6,44,4,174)
Block(-6,44,5,174)
Block(-6,44,6,174)
Block(-6,44,7,174)
Block(-6,44,8,174)
Block(-6,45,-5,174)
Block(-6,45,-4,174)
Block(-6,45,-3,174)
Block(-6,45,-2,174)
Block(-6,45,-1,174)
Block(-6,45,0,174)
Block(-6,45,1,174)
Block(-6,45,2,174)
Block(-6,45,3,174)
Block(-6,45,4,174)
Block(-6,45,5,174)
Block(-6,45,6,174)
Block(-6,45,7,174)
Block(-6,45,8,174)
Block(-6,46,-6,174)
Block(-6,46,-5,174)
Block(-6,46,-4,174)
Block(-6,46,-3,174)
Block(-6,46,-2,174)
Block(-6,46,-1,174)
Block(-6,46,0,174)
Block(-6,46,1,174)
Block(-6,46,2,174)
Block(-6,46,3,174)
Block(-6,46,4,174)
Block(-6,46,5,174)
Block(-6,46,6,174)
Block(-6,46,7,174)
Block(-6,46,8,174)
Block(-6,47,-5,174)
Block(-6,47,-4,174)
Block(-6,47,-3,174)
Block(-6,47,-2,174)
Block(-6,47,-1,174)
Block(-6,47,0,174)
Block(-6,47,1,174)
Block(-6,47,2,174)
Block(-6,47,3,174)
Block(-6,47,4,174)
Block(-6,47,5,174)
Block(-6,47,6,174)
Block(-6,47,7,174)
Block(-6,47,8,174)
Block(-6,48,-4,174)
Block(-6,48,-3,174)
Block(-6,48,-2,174)
Block(-6,48,-1,174)
Block(-6,48,0,174)
Block(-6,48,1,174)
Block(-6,48,2,174)
Block(-6,48,3,174)
Block(-6,48,4,174)
Block(-6,48,5,174)
Block(-6,48,6,174)
Block(-6,48,7,174)
Block(-6,48,8,174)
Block(-6,49,-3,174)
Block(-6,49,-2,174)
Block(-6,49,-1,174)
Block(-6,49,0,174)
Block(-6,49,1,174)
Block(-6,49,2,174)
Block(-6,49,3,174)
Block(-6,49,4,174)
Block(-6,49,5,174)
Block(-6,49,6,174)
Block(-6,49,7,174)
Block(-6,49,8,174)
Block(-6,50,-3,174)
Block(-6,50,-2,174)
Block(-6,50,-1,174)
Block(-6,50,0,174)
Block(-6,50,1,174)
Block(-6,50,2,174)
Block(-6,50,3,174)
Block(-6,50,4,174)
Block(-6,50,5,174)
Block(-6,50,6,174)
Block(-6,50,7,174)
Block(-6,50,8,174)
Block(-6,51,-1,174)
Block(-6,51,0,174)
Block(-6,51,1,174)
Block(-6,51,2,174)
Block(-6,51,3,174)
Block(-6,51,4,174)
Block(-6,51,5,174)
Block(-6,51,6,174)
Block(-6,51,7,174)
Block(-6,51,8,174)
Block(-6,52,0,174)
Block(-6,52,1,174)
Block(-6,52,2,174)
Block(-6,52,3,174)
Block(-6,52,4,174)
Block(-6,52,5,174)
Block(-6,52,6,174)
Block(-6,52,7,174)
Block(-6,52,8,174)
Block(-6,53,0,174)
Block(-6,53,1,174)
Block(-6,53,2,174)
Block(-6,53,3,174)
Block(-6,53,4,174)
Block(-6,53,5,174)
Block(-6,53,6,174)
Block(-6,53,7,174)
Block(-6,53,8,174)
Block(-6,54,1,174)
Block(-6,54,2,174)
Block(-6,54,3,174)
Block(-6,54,4,174)
Block(-6,54,5,174)
Block(-6,54,6,174)
Block(-6,54,7,174)
Block(-6,54,8,174)
Block(-6,55,4,174)
Block(-6,55,5,174)
Block(-6,55,6,174)
Block(-6,55,7,174)
Block(-6,55,8,174)
Block(-6,56,5,174)
Block(-6,56,6,174)
Block(-6,56,7,174)
Block(-6,56,8,174)
Block(-6,57,6,174)
Block(-6,57,7,174)
Block(-6,57,8,174)
Block(-6,58,8,174)
Block(-5,20,7,174)
Block(-5,20,8,174)
Block(-5,21,6,174)
Block(-5,21,7,174)
Block(-5,21,8,174)
Block(-5,22,6,174)
Block(-5,22,7,174)
Block(-5,22,8,174)
Block(-5,23,6,174)
Block(-5,23,7,174)
Block(-5,23,8,174)
Block(-5,24,3,174)
Block(-5,24,4,174)
Block(-5,24,5,174)
Block(-5,24,6,174)
Block(-5,24,7,174)
Block(-5,24,8,174)
Block(-5,25,1,174)
Block(-5,25,3,174)
Block(-5,25,4,174)
Block(-5,25,5,174)
Block(-5,25,6,174)
Block(-5,25,7,174)
Block(-5,25,8,174)
Block(-5,26,1,174)
Block(-5,26,2,174)
Block(-5,26,3,174)
Block(-5,26,4,174)
Block(-5,26,5,174)
Block(-5,26,6,174)
Block(-5,26,7,174)
Block(-5,26,8,174)
Block(-5,27,0,174)
Block(-5,27,1,174)
Block(-5,27,2,174)
Block(-5,27,3,174)
Block(-5,27,4,174)
Block(-5,27,5,174)
Block(-5,27,6,174)
Block(-5,27,7,174)
Block(-5,27,8,174)
Block(-5,28,-1,174)
Block(-5,28,0,174)
Block(-5,28,1,174)
Block(-5,28,2,174)
Block(-5,28,3,174)
Block(-5,28,4,174)
Block(-5,28,5,174)
Block(-5,28,6,174)
Block(-5,28,7,174)
Block(-5,28,8,174)
Block(-5,29,-4,174)
Block(-5,29,-3,174)
Block(-5,29,-2,174)
Block(-5,29,-1,174)
Block(-5,29,0,174)
Block(-5,29,1,174)
Block(-5,29,2,174)
Block(-5,29,3,174)
Block(-5,29,4,174)
Block(-5,29,5,174)
Block(-5,29,6,174)
Block(-5,29,7,174)
Block(-5,29,8,174)
Block(-5,30,-5,174)
Block(-5,30,-4,174)
Block(-5,30,-3,174)
Block(-5,30,-2,174)
Block(-5,30,-1,174)
Block(-5,30,0,174)
Block(-5,30,1,174)
Block(-5,30,2,174)
Block(-5,30,3,174)
Block(-5,30,4,174)
Block(-5,30,5,174)
Block(-5,30,6,174)
Block(-5,30,7,174)
Block(-5,30,8,174)
Block(-5,31,-5,174)
Block(-5,31,-4,174)
Block(-5,31,-3,174)
Block(-5,31,-2,174)
Block(-5,31,-1,174)
Block(-5,31,0,174)
Block(-5,31,1,174)
Block(-5,31,2,174)
Block(-5,31,3,174)
Block(-5,31,4,174)
Block(-5,31,5,174)
Block(-5,31,6,174)
Block(-5,31,7,174)
Block(-5,31,8,174)
Block(-5,32,-6,174)
Block(-5,32,-5,174)
Block(-5,32,-4,174)
Block(-5,32,-3,174)
Block(-5,32,-2,174)
Block(-5,32,-1,174)
Block(-5,32,0,174)
Block(-5,32,1,174)
Block(-5,32,2,174)
Block(-5,32,3,174)
Block(-5,32,4,174)
Block(-5,32,5,174)
Block(-5,32,6,174)
Block(-5,32,7,174)
Block(-5,32,8,174)
Block(-5,33,-6,174)
Block(-5,33,-5,174)
Block(-5,33,-4,174)
Block(-5,33,-3,174)
Block(-5,33,-2,174)
Block(-5,33,-1,174)
Block(-5,33,0,174)
Block(-5,33,1,174)
Block(-5,33,2,174)
Block(-5,33,3,174)
Block(-5,33,4,174)
Block(-5,33,5,174)
Block(-5,33,6,174)
Block(-5,33,7,174)
Block(-5,33,8,174)
Block(-5,34,-6,174)
Block(-5,34,-5,174)
Block(-5,34,-4,174)
Block(-5,34,-3,174)
Block(-5,34,-2,174)
Block(-5,34,-1,174)
Block(-5,34,0,174)
Block(-5,34,1,174)
Block(-5,34,2,174)
Block(-5,34,3,174)
Block(-5,34,4,174)
Block(-5,34,5,174)
Block(-5,34,6,174)
Block(-5,34,7,174)
Block(-5,34,8,174)
Block(-5,35,-7,174)
Block(-5,35,-6,174)
Block(-5,35,-5,174)
Block(-5,35,-4,174)
Block(-5,35,-3,174)
Block(-5,35,-2,174)
Block(-5,35,-1,174)
Block(-5,35,0,174)
Block(-5,35,1,174)
Block(-5,35,2,174)
Block(-5,35,3,174)
Block(-5,35,4,174)
Block(-5,35,5,174)
Block(-5,35,6,174)
Block(-5,35,7,174)
Block(-5,35,8,174)
Block(-5,36,-7,174)
Block(-5,36,-6,174)
Block(-5,36,-5,174)
Block(-5,36,-4,174)
Block(-5,36,-3,174)
Block(-5,36,-2,174)
Block(-5,36,-1,174)
Block(-5,36,0,174)
Block(-5,36,1,174)
Block(-5,36,2,174)
Block(-5,36,3,174)
Block(-5,36,4,174)
Block(-5,36,5,174)
Block(-5,36,6,174)
Block(-5,36,7,174)
Block(-5,36,8,174)
Block(-5,37,-7,174)
Block(-5,37,-6,174)
Block(-5,37,-5,174)
Block(-5,37,-4,174)
Block(-5,37,-3,174)
Block(-5,37,-2,174)
Block(-5,37,-1,174)
Block(-5,37,0,174)
Block(-5,37,1,174)
Block(-5,37,2,174)
Block(-5,37,3,174)
Block(-5,37,4,174)
Block(-5,37,5,174)
Block(-5,37,6,174)
Block(-5,37,7,174)
Block(-5,37,8,174)
Block(-5,38,-7,174)
Block(-5,38,-6,174)
Block(-5,38,-5,174)
Block(-5,38,-4,174)
Block(-5,38,-3,174)
Block(-5,38,-2,174)
Block(-5,38,-1,174)
Block(-5,38,0,174)
Block(-5,38,1,174)
Block(-5,38,2,174)
Block(-5,38,3,174)
Block(-5,38,4,174)
Block(-5,38,5,174)
Block(-5,38,6,174)
Block(-5,38,7,174)
Block(-5,38,8,174)
Block(-5,39,-7,174)
Block(-5,39,-6,174)
Block(-5,39,-5,174)
Block(-5,39,-4,174)
Block(-5,39,-3,174)
Block(-5,39,-2,174)
Block(-5,39,-1,174)
Block(-5,39,0,174)
Block(-5,39,1,174)
Block(-5,39,2,174)
Block(-5,39,3,174)
Block(-5,39,4,174)
Block(-5,39,5,174)
Block(-5,39,6,174)
Block(-5,39,7,174)
Block(-5,39,8,174)
Block(-5,40,-7,174)
Block(-5,40,-6,174)
Block(-5,40,-5,174)
Block(-5,40,-4,174)
Block(-5,40,-3,174)
Block(-5,40,-2,174)
Block(-5,40,-1,174)
Block(-5,40,0,174)
Block(-5,40,1,174)
Block(-5,40,2,174)
Block(-5,40,3,174)
Block(-5,40,4,174)
Block(-5,40,5,174)
Block(-5,40,6,174)
Block(-5,40,7,174)
Block(-5,40,8,174)
Block(-5,41,-7,174)
Block(-5,41,-6,174)
Block(-5,41,-5,174)
Block(-5,41,-4,174)
Block(-5,41,-3,174)
Block(-5,41,-2,174)
Block(-5,41,-1,174)
Block(-5,41,0,174)
Block(-5,41,1,174)
Block(-5,41,2,174)
Block(-5,41,3,174)
Block(-5,41,4,174)
Block(-5,41,5,174)
Block(-5,41,6,174)
Block(-5,41,7,174)
Block(-5,41,8,174)
Block(-5,42,-7,174)
Block(-5,42,-6,174)
Block(-5,42,-5,174)
Block(-5,42,-4,174)
Block(-5,42,-3,174)
Block(-5,42,-2,174)
Block(-5,42,-1,174)
Block(-5,42,0,174)
Block(-5,42,1,174)
Block(-5,42,2,174)
Block(-5,42,3,174)
Block(-5,42,4,174)
Block(-5,42,5,174)
Block(-5,42,6,174)
Block(-5,42,7,174)
Block(-5,42,8,174)
Block(-5,43,-7,174)
Block(-5,43,-6,174)
Block(-5,43,-5,174)
Block(-5,43,-4,174)
Block(-5,43,-3,174)
Block(-5,43,-2,174)
Block(-5,43,-1,174)
Block(-5,43,0,174)
Block(-5,43,1,174)
Block(-5,43,2,174)
Block(-5,43,3,174)
Block(-5,43,4,174)
Block(-5,43,5,174)
Block(-5,43,6,174)
Block(-5,43,7,174)
Block(-5,43,8,174)
Block(-5,44,-7,174)
Block(-5,44,-6,174)
Block(-5,44,-5,174)
Block(-5,44,-4,174)
Block(-5,44,-3,174)
Block(-5,44,-2,174)
Block(-5,44,-1,174)
Block(-5,44,0,174)
Block(-5,44,1,174)
Block(-5,44,2,174)
Block(-5,44,3,174)
Block(-5,44,4,174)
Block(-5,44,5,174)
Block(-5,44,6,174)
Block(-5,44,7,174)
Block(-5,44,8,174)
Block(-5,45,-6,174)
Block(-5,45,-5,174)
Block(-5,45,-4,174)
Block(-5,45,-3,174)
Block(-5,45,-2,174)
Block(-5,45,-1,174)
Block(-5,45,0,174)
Block(-5,45,1,174)
Block(-5,45,2,174)
Block(-5,45,3,174)
Block(-5,45,4,174)
Block(-5,45,5,174)
Block(-5,45,6,174)
Block(-5,45,7,174)
Block(-5,45,8,174)
Block(-5,46,-6,174)
Block(-5,46,-5,174)
Block(-5,46,-4,174)
Block(-5,46,-3,174)
Block(-5,46,-2,174)
Block(-5,46,-1,174)
Block(-5,46,0,174)
Block(-5,46,1,174)
Block(-5,46,2,174)
Block(-5,46,3,174)
Block(-5,46,4,174)
Block(-5,46,5,174)
Block(-5,46,6,174)
Block(-5,46,7,174)
Block(-5,46,8,174)
Block(-5,47,-6,174)
Block(-5,47,-5,174)
Block(-5,47,-4,174)
Block(-5,47,-3,174)
Block(-5,47,-2,174)
Block(-5,47,-1,174)
Block(-5,47,0,174)
Block(-5,47,1,174)
Block(-5,47,2,174)
Block(-5,47,3,174)
Block(-5,47,4,174)
Block(-5,47,5,174)
Block(-5,47,6,174)
Block(-5,47,7,174)
Block(-5,47,8,174)
Block(-5,48,-5,174)
Block(-5,48,-4,174)
Block(-5,48,-3,174)
Block(-5,48,-2,174)
Block(-5,48,-1,174)
Block(-5,48,0,174)
Block(-5,48,1,174)
Block(-5,48,2,174)
Block(-5,48,3,174)
Block(-5,48,4,174)
Block(-5,48,5,174)
Block(-5,48,6,174)
Block(-5,48,7,174)
Block(-5,48,8,174)
Block(-5,49,-5,174)
Block(-5,49,-4,174)
Block(-5,49,-3,174)
Block(-5,49,-2,174)
Block(-5,49,-1,174)
Block(-5,49,0,174)
Block(-5,49,1,174)
Block(-5,49,2,174)
Block(-5,49,3,174)
Block(-5,49,4,174)
Block(-5,49,5,174)
Block(-5,49,6,174)
Block(-5,49,7,174)
Block(-5,49,8,174)
Block(-5,50,-5,174)
Block(-5,50,-4,174)
Block(-5,50,-3,174)
Block(-5,50,-2,174)
Block(-5,50,-1,174)
Block(-5,50,0,174)
Block(-5,50,1,174)
Block(-5,50,2,174)
Block(-5,50,3,174)
Block(-5,50,4,174)
Block(-5,50,5,174)
Block(-5,50,6,174)
Block(-5,50,7,174)
Block(-5,50,8,174)
Block(-5,51,-5,174)
Block(-5,51,-4,174)
Block(-5,51,-3,174)
Block(-5,51,-2,174)
Block(-5,51,-1,174)
Block(-5,51,0,174)
Block(-5,51,1,174)
Block(-5,51,2,174)
Block(-5,51,3,174)
Block(-5,51,4,174)
Block(-5,51,5,174)
Block(-5,51,6,174)
Block(-5,51,7,174)
Block(-5,51,8,174)
Block(-5,52,-4,174)
Block(-5,52,-3,174)
Block(-5,52,-2,174)
Block(-5,52,-1,174)
Block(-5,52,0,174)
Block(-5,52,1,174)
Block(-5,52,2,174)
Block(-5,52,3,174)
Block(-5,52,4,174)
Block(-5,52,5,174)
Block(-5,52,6,174)
Block(-5,52,7,174)
Block(-5,52,8,174)
Block(-5,53,-1,174)
Block(-5,53,0,174)
Block(-5,53,1,174)
Block(-5,53,2,174)
Block(-5,53,3,174)
Block(-5,53,4,174)
Block(-5,53,5,174)
Block(-5,53,6,174)
Block(-5,53,7,174)
Block(-5,53,8,174)
Block(-5,54,0,174)
Block(-5,54,1,174)
Block(-5,54,2,174)
Block(-5,54,3,174)
Block(-5,54,4,174)
Block(-5,54,5,174)
Block(-5,54,6,174)
Block(-5,54,7,174)
Block(-5,54,8,174)
Block(-5,55,1,174)
Block(-5,55,2,174)
Block(-5,55,3,174)
Block(-5,55,4,174)
Block(-5,55,5,174)
Block(-5,55,6,174)
Block(-5,55,7,174)
Block(-5,55,8,174)
Block(-5,56,1,174)
Block(-5,56,3,174)
Block(-5,56,4,174)
Block(-5,56,5,174)
Block(-5,56,6,174)
Block(-5,56,7,174)
Block(-5,56,8,174)
Block(-5,57,3,174)
Block(-5,57,4,174)
Block(-5,57,5,174)
Block(-5,57,6,174)
Block(-5,57,7,174)
Block(-5,57,8,174)
Block(-5,58,6,174)
Block(-5,58,7,174)
Block(-5,58,8,174)
Block(-5,59,6,174)
Block(-5,59,7,174)
Block(-5,59,8,174)
Block(-5,60,6,174)
Block(-5,60,7,174)
Block(-5,60,8,174)
Block(-5,61,7,174)
Block(-5,61,8,174)
Block(-4,18,6,174)
Block(-4,18,7,174)
Block(-4,18,8,174)
Block(-4,19,5,174)
Block(-4,19,6,174)
Block(-4,19,7,174)
Block(-4,19,8,174)
Block(-4,20,5,174)
Block(-4,20,6,174)
Block(-4,20,7,174)
Block(-4,20,8,174)
Block(-4,21,5,174)
Block(-4,21,6,174)
Block(-4,21,7,174)
Block(-4,21,8,174)
Block(-4,22,4,174)
Block(-4,22,5,174)
Block(-4,22,6,174)
Block(-4,22,7,174)
Block(-4,22,8,174)
Block(-4,23,1,174)
Block(-4,23,2,174)
Block(-4,23,3,174)
Block(-4,23,4,174)
Block(-4,23,5,174)
Block(-4,23,6,174)
Block(-4,23,7,174)
Block(-4,23,8,174)
Block(-4,24,1,174)
Block(-4,24,2,174)
Block(-4,24,3,174)
Block(-4,24,4,174)
Block(-4,24,5,174)
Block(-4,24,6,174)
Block(-4,24,7,174)
Block(-4,24,8,174)
Block(-4,25,0,174)
Block(-4,25,1,174)
Block(-4,25,2,174)
Block(-4,25,3,174)
Block(-4,25,4,174)
Block(-4,25,5,174)
Block(-4,25,6,174)
Block(-4,25,7,174)
Block(-4,25,8,174)
Block(-4,26,0,174)
Block(-4,26,1,174)
Block(-4,26,2,174)
Block(-4,26,3,174)
Block(-4,26,4,174)
Block(-4,26,5,174)
Block(-4,26,6,174)
Block(-4,26,7,174)
Block(-4,26,8,174)
Block(-4,27,-2,174)
Block(-4,27,-1,174)
Block(-4,27,0,174)
Block(-4,27,1,174)
Block(-4,27,2,174)
Block(-4,27,3,174)
Block(-4,27,4,174)
Block(-4,27,5,174)
Block(-4,27,6,174)
Block(-4,27,7,174)
Block(-4,27,8,174)
Block(-4,28,-4,174)
Block(-4,28,-3,174)
Block(-4,28,-2,174)
Block(-4,28,-1,174)
Block(-4,28,0,174)
Block(-4,28,1,174)
Block(-4,28,2,174)
Block(-4,28,3,174)
Block(-4,28,4,174)
Block(-4,28,5,174)
Block(-4,28,6,174)
Block(-4,28,7,174)
Block(-4,28,8,174)
Block(-4,29,-5,174)
Block(-4,29,-4,174)
Block(-4,29,-3,174)
Block(-4,29,-2,174)
Block(-4,29,-1,174)
Block(-4,29,0,174)
Block(-4,29,1,174)
Block(-4,29,2,174)
Block(-4,29,3,174)
Block(-4,29,4,174)
Block(-4,29,5,174)
Block(-4,29,6,174)
Block(-4,29,7,174)
Block(-4,29,8,174)
Block(-4,30,-6,174)
Block(-4,30,-5,174)
Block(-4,30,-4,174)
Block(-4,30,-3,174)
Block(-4,30,-2,174)
Block(-4,30,-1,174)
Block(-4,30,0,174)
Block(-4,30,1,174)
Block(-4,30,2,174)
Block(-4,30,3,174)
Block(-4,30,4,174)
Block(-4,30,5,174)
Block(-4,30,6,174)
Block(-4,30,7,174)
Block(-4,30,8,174)
Block(-4,31,-6,174)
Block(-4,31,-5,174)
Block(-4,31,-4,174)
Block(-4,31,-3,174)
Block(-4,31,-2,174)
Block(-4,31,-1,174)
Block(-4,31,0,174)
Block(-4,31,1,174)
Block(-4,31,2,174)
Block(-4,31,3,174)
Block(-4,31,4,174)
Block(-4,31,5,174)
Block(-4,31,6,174)
Block(-4,31,7,174)
Block(-4,31,8,174)
Block(-4,32,-7,174)
Block(-4,32,-6,174)
Block(-4,32,-5,174)
Block(-4,32,-4,174)
Block(-4,32,-3,174)
Block(-4,32,-2,174)
Block(-4,32,-1,174)
Block(-4,32,0,174)
Block(-4,32,1,174)
Block(-4,32,2,174)
Block(-4,32,3,174)
Block(-4,32,4,174)
Block(-4,32,5,174)
Block(-4,32,6,174)
Block(-4,32,7,174)
Block(-4,32,8,174)
Block(-4,33,-6,174)
Block(-4,33,-5,174)
Block(-4,33,-4,174)
Block(-4,33,-3,174)
Block(-4,33,-2,174)
Block(-4,33,-1,174)
Block(-4,33,0,174)
Block(-4,33,1,174)
Block(-4,33,2,174)
Block(-4,33,3,174)
Block(-4,33,4,174)
Block(-4,33,5,174)
Block(-4,33,6,174)
Block(-4,33,7,174)
Block(-4,33,8,174)
Block(-4,34,-7,174)
Block(-4,34,-6,174)
Block(-4,34,-5,174)
Block(-4,34,-4,174)
Block(-4,34,-3,174)
Block(-4,34,-2,174)
Block(-4,34,-1,174)
Block(-4,34,0,174)
Block(-4,34,1,174)
Block(-4,34,2,174)
Block(-4,34,3,174)
Block(-4,34,4,174)
Block(-4,34,5,174)
Block(-4,34,6,174)
Block(-4,34,7,174)
Block(-4,34,8,174)
Block(-4,35,-7,174)
Block(-4,35,-6,174)
Block(-4,35,-5,174)
Block(-4,35,-4,174)
Block(-4,35,-3,174)
Block(-4,35,-2,174)
Block(-4,35,-1,174)
Block(-4,35,0,174)
Block(-4,35,1,174)
Block(-4,35,2,174)
Block(-4,35,3,174)
Block(-4,35,4,174)
Block(-4,35,5,174)
Block(-4,35,6,174)
Block(-4,35,7,174)
Block(-4,35,8,174)
Block(-4,36,-7,174)
Block(-4,36,-6,174)
Block(-4,36,-5,174)
Block(-4,36,-4,174)
Block(-4,36,-3,174)
Block(-4,36,-2,174)
Block(-4,36,-1,174)
Block(-4,36,0,174)
Block(-4,36,1,174)
Block(-4,36,2,174)
Block(-4,36,3,174)
Block(-4,36,4,174)
Block(-4,36,5,174)
Block(-4,36,6,174)
Block(-4,36,7,174)
Block(-4,36,8,174)
Block(-4,37,-7,174)
Block(-4,37,-6,174)
Block(-4,37,-5,174)
Block(-4,37,-4,174)
Block(-4,37,-3,174)
Block(-4,37,-2,174)
Block(-4,37,-1,174)
Block(-4,37,0,174)
Block(-4,37,1,174)
Block(-4,37,2,174)
Block(-4,37,3,174)
Block(-4,37,4,174)
Block(-4,37,5,174)
Block(-4,37,6,174)
Block(-4,37,7,174)
Block(-4,37,8,174)
Block(-4,38,-7,174)
Block(-4,38,-6,174)
Block(-4,38,-5,174)
Block(-4,38,-4,174)
Block(-4,38,-3,174)
Block(-4,38,-2,174)
Block(-4,38,-1,174)
Block(-4,38,0,174)
Block(-4,38,1,174)
Block(-4,38,2,174)
Block(-4,38,3,174)
Block(-4,38,4,174)
Block(-4,38,5,174)
Block(-4,38,6,174)
Block(-4,38,7,174)
Block(-4,38,8,174)
Block(-4,39,-7,174)
Block(-4,39,-6,174)
Block(-4,39,-5,174)
Block(-4,39,-4,174)
Block(-4,39,-3,174)
Block(-4,39,-2,174)
Block(-4,39,-1,174)
Block(-4,39,0,174)
Block(-4,39,1,174)
Block(-4,39,2,174)
Block(-4,39,3,174)
Block(-4,39,4,174)
Block(-4,39,5,174)
Block(-4,39,6,174)
Block(-4,39,7,174)
Block(-4,39,8,174)
Block(-4,40,-7,174)
Block(-4,40,-6,174)
Block(-4,40,-5,174)
Block(-4,40,-4,174)
Block(-4,40,-3,174)
Block(-4,40,-2,174)
Block(-4,40,-1,174)
Block(-4,40,0,174)
Block(-4,40,1,174)
Block(-4,40,2,174)
Block(-4,40,3,174)
Block(-4,40,4,174)
Block(-4,40,5,174)
Block(-4,40,6,174)
Block(-4,40,7,174)
Block(-4,40,8,174)
Block(-4,41,-7,174)
Block(-4,41,-6,174)
Block(-4,41,-5,174)
Block(-4,41,-4,174)
Block(-4,41,-3,174)
Block(-4,41,-2,174)
Block(-4,41,-1,174)
Block(-4,41,0,174)
Block(-4,41,1,174)
Block(-4,41,2,174)
Block(-4,41,3,174)
Block(-4,41,4,174)
Block(-4,41,5,174)
Block(-4,41,6,174)
Block(-4,41,7,174)
Block(-4,41,8,174)
Block(-4,42,-7,174)
Block(-4,42,-6,174)
Block(-4,42,-5,174)
Block(-4,42,-4,174)
Block(-4,42,-3,174)
Block(-4,42,-2,174)
Block(-4,42,-1,174)
Block(-4,42,0,174)
Block(-4,42,1,174)
Block(-4,42,2,174)
Block(-4,42,3,174)
Block(-4,42,4,174)
Block(-4,42,5,174)
Block(-4,42,6,174)
Block(-4,42,7,174)
Block(-4,42,8,174)
Block(-4,43,-7,174)
Block(-4,43,-6,174)
Block(-4,43,-5,174)
Block(-4,43,-4,174)
Block(-4,43,-3,174)
Block(-4,43,-2,174)
Block(-4,43,-1,174)
Block(-4,43,0,174)
Block(-4,43,1,174)
Block(-4,43,2,174)
Block(-4,43,3,174)
Block(-4,43,4,174)
Block(-4,43,5,174)
Block(-4,43,6,174)
Block(-4,43,7,174)
Block(-4,43,8,174)
Block(-4,44,-7,174)
Block(-4,44,-6,174)
Block(-4,44,-5,174)
Block(-4,44,-4,174)
Block(-4,44,-3,174)
Block(-4,44,-2,174)
Block(-4,44,-1,174)
Block(-4,44,0,174)
Block(-4,44,1,174)
Block(-4,44,2,174)
Block(-4,44,3,174)
Block(-4,44,4,174)
Block(-4,44,5,174)
Block(-4,44,6,174)
Block(-4,44,7,174)
Block(-4,44,8,174)
Block(-4,45,-7,174)
Block(-4,45,-6,174)
Block(-4,45,-5,174)
Block(-4,45,-4,174)
Block(-4,45,-3,174)
Block(-4,45,-2,174)
Block(-4,45,-1,174)
Block(-4,45,0,174)
Block(-4,45,1,174)
Block(-4,45,2,174)
Block(-4,45,3,174)
Block(-4,45,4,174)
Block(-4,45,5,174)
Block(-4,45,6,174)
Block(-4,45,7,174)
Block(-4,45,8,174)
Block(-4,46,-6,174)
Block(-4,46,-5,174)
Block(-4,46,-4,174)
Block(-4,46,-3,174)
Block(-4,46,-2,174)
Block(-4,46,-1,174)
Block(-4,46,0,174)
Block(-4,46,1,174)
Block(-4,46,2,174)
Block(-4,46,3,174)
Block(-4,46,4,174)
Block(-4,46,5,174)
Block(-4,46,6,174)
Block(-4,46,7,174)
Block(-4,46,8,174)
Block(-4,47,-6,174)
Block(-4,47,-5,174)
Block(-4,47,-4,174)
Block(-4,47,-3,174)
Block(-4,47,-2,174)
Block(-4,47,-1,174)
Block(-4,47,0,174)
Block(-4,47,1,174)
Block(-4,47,2,174)
Block(-4,47,3,174)
Block(-4,47,4,174)
Block(-4,47,5,174)
Block(-4,47,6,174)
Block(-4,47,7,174)
Block(-4,47,8,174)
Block(-4,48,-5,174)
Block(-4,48,-4,174)
Block(-4,48,-3,174)
Block(-4,48,-2,174)
Block(-4,48,-1,174)
Block(-4,48,0,174)
Block(-4,48,1,174)
Block(-4,48,2,174)
Block(-4,48,3,174)
Block(-4,48,4,174)
Block(-4,48,5,174)
Block(-4,48,6,174)
Block(-4,48,7,174)
Block(-4,48,8,174)
Block(-4,49,-5,174)
Block(-4,49,-4,174)
Block(-4,49,-3,174)
Block(-4,49,-2,174)
Block(-4,49,-1,174)
Block(-4,49,0,174)
Block(-4,49,1,174)
Block(-4,49,2,174)
Block(-4,49,3,174)
Block(-4,49,4,174)
Block(-4,49,5,174)
Block(-4,49,6,174)
Block(-4,49,7,174)
Block(-4,49,8,174)
Block(-4,50,-5,174)
Block(-4,50,-4,174)
Block(-4,50,-3,174)
Block(-4,50,-2,174)
Block(-4,50,-1,174)
Block(-4,50,0,174)
Block(-4,50,1,174)
Block(-4,50,2,174)
Block(-4,50,3,174)
Block(-4,50,4,174)
Block(-4,50,5,174)
Block(-4,50,6,174)
Block(-4,50,7,174)
Block(-4,50,8,174)
Block(-4,51,-6,174)
Block(-4,51,-5,174)
Block(-4,51,-4,174)
Block(-4,51,-3,174)
Block(-4,51,-2,174)
Block(-4,51,-1,174)
Block(-4,51,0,174)
Block(-4,51,1,174)
Block(-4,51,2,174)
Block(-4,51,3,174)
Block(-4,51,4,174)
Block(-4,51,5,174)
Block(-4,51,6,174)
Block(-4,51,7,174)
Block(-4,51,8,174)
Block(-4,52,-5,174)
Block(-4,52,-4,174)
Block(-4,52,-3,174)
Block(-4,52,-2,174)
Block(-4,52,-1,174)
Block(-4,52,0,174)
Block(-4,52,1,174)
Block(-4,52,2,174)
Block(-4,52,3,174)
Block(-4,52,4,174)
Block(-4,52,5,174)
Block(-4,52,6,174)
Block(-4,52,7,174)
Block(-4,52,8,174)
Block(-4,53,-4,174)
Block(-4,53,-3,174)
Block(-4,53,-2,174)
Block(-4,53,-1,174)
Block(-4,53,0,174)
Block(-4,53,1,174)
Block(-4,53,2,174)
Block(-4,53,3,174)
Block(-4,53,4,174)
Block(-4,53,5,174)
Block(-4,53,6,174)
Block(-4,53,7,174)
Block(-4,53,8,174)
Block(-4,54,-2,174)
Block(-4,54,-1,174)
Block(-4,54,0,174)
Block(-4,54,1,174)
Block(-4,54,2,174)
Block(-4,54,3,174)
Block(-4,54,4,174)
Block(-4,54,5,174)
Block(-4,54,6,174)
Block(-4,54,7,174)
Block(-4,54,8,174)
Block(-4,55,0,174)
Block(-4,55,1,174)
Block(-4,55,2,174)
Block(-4,55,3,174)
Block(-4,55,4,174)
Block(-4,55,5,174)
Block(-4,55,6,174)
Block(-4,55,7,174)
Block(-4,55,8,174)
Block(-4,56,0,174)
Block(-4,56,1,174)
Block(-4,56,2,174)
Block(-4,56,3,174)
Block(-4,56,4,174)
Block(-4,56,5,174)
Block(-4,56,6,174)
Block(-4,56,7,174)
Block(-4,56,8,174)
Block(-4,57,1,174)
Block(-4,57,2,174)
Block(-4,57,3,174)
Block(-4,57,4,174)
Block(-4,57,5,174)
Block(-4,57,6,174)
Block(-4,57,7,174)
Block(-4,57,8,174)
Block(-4,58,1,174)
Block(-4,58,2,174)
Block(-4,58,3,174)
Block(-4,58,4,174)
Block(-4,58,5,174)
Block(-4,58,6,174)
Block(-4,58,7,174)
Block(-4,58,8,174)
Block(-4,59,4,174)
Block(-4,59,5,174)
Block(-4,59,6,174)
Block(-4,59,7,174)
Block(-4,59,8,174)
Block(-4,60,5,174)
Block(-4,60,6,174)
Block(-4,60,7,174)
Block(-4,60,8,174)
Block(-4,61,5,174)
Block(-4,61,6,174)
Block(-4,61,7,174)
Block(-4,61,8,174)
Block(-4,62,5,174)
Block(-4,62,6,174)
Block(-4,62,7,174)
Block(-4,62,8,174)
Block(-4,63,6,174)
Block(-4,63,7,174)
Block(-4,63,8,174)
Block(-3,17,6,174)
Block(-3,17,7,174)
Block(-3,17,8,174)
Block(-3,18,5,174)
Block(-3,18,6,174)
Block(-3,18,7,174)
Block(-3,18,8,174)
Block(-3,19,4,174)
Block(-3,19,5,174)
Block(-3,19,6,174)
Block(-3,19,7,174)
Block(-3,19,8,174)
Block(-3,20,3,174)
Block(-3,20,4,174)
Block(-3,20,5,174)
Block(-3,20,6,174)
Block(-3,20,7,174)
Block(-3,20,8,174)
Block(-3,21,2,174)
Block(-3,21,3,174)
Block(-3,21,4,174)
Block(-3,21,5,174)
Block(-3,21,6,174)
Block(-3,21,7,174)
Block(-3,21,8,174)
Block(-3,22,1,174)
Block(-3,22,2,174)
Block(-3,22,3,174)
Block(-3,22,4,174)
Block(-3,22,5,174)
Block(-3,22,6,174)
Block(-3,22,7,174)
Block(-3,22,8,174)
Block(-3,23,0,174)
Block(-3,23,1,174)
Block(-3,23,2,174)
Block(-3,23,3,174)
Block(-3,23,4,174)
Block(-3,23,5,174)
Block(-3,23,6,174)
Block(-3,23,7,174)
Block(-3,23,8,174)
Block(-3,24,-1,174)
Block(-3,24,0,174)
Block(-3,24,1,174)
Block(-3,24,2,174)
Block(-3,24,3,174)
Block(-3,24,4,174)
Block(-3,24,5,174)
Block(-3,24,6,174)
Block(-3,24,7,174)
Block(-3,24,8,174)
Block(-3,25,-2,174)
Block(-3,25,-1,174)
Block(-3,25,0,174)
Block(-3,25,1,174)
Block(-3,25,2,174)
Block(-3,25,3,174)
Block(-3,25,4,174)
Block(-3,25,5,174)
Block(-3,25,6,174)
Block(-3,25,7,174)
Block(-3,25,8,174)
Block(-3,26,-3,174)
Block(-3,26,-2,174)
Block(-3,26,-1,174)
Block(-3,26,0,174)
Block(-3,26,1,174)
Block(-3,26,2,174)
Block(-3,26,3,174)
Block(-3,26,4,174)
Block(-3,26,5,174)
Block(-3,26,6,174)
Block(-3,26,7,174)
Block(-3,26,8,174)
Block(-3,27,-3,174)
Block(-3,27,-2,174)
Block(-3,27,-1,174)
Block(-3,27,0,174)
Block(-3,27,1,174)
Block(-3,27,2,174)
Block(-3,27,3,174)
Block(-3,27,4,174)
Block(-3,27,5,174)
Block(-3,27,6,174)
Block(-3,27,7,174)
Block(-3,27,8,174)
Block(-3,28,-6,174)
Block(-3,28,-5,174)
Block(-3,28,-4,174)
Block(-3,28,-3,174)
Block(-3,28,-2,174)
Block(-3,28,-1,174)
Block(-3,28,0,174)
Block(-3,28,1,174)
Block(-3,28,2,174)
Block(-3,28,3,174)
Block(-3,28,4,174)
Block(-3,28,5,174)
Block(-3,28,6,174)
Block(-3,28,7,174)
Block(-3,28,8,174)
Block(-3,29,-6,174)
Block(-3,29,-5,174)
Block(-3,29,-4,174)
Block(-3,29,-3,174)
Block(-3,29,-2,174)
Block(-3,29,-1,174)
Block(-3,29,0,174)
Block(-3,29,1,174)
Block(-3,29,2,174)
Block(-3,29,3,174)
Block(-3,29,4,174)
Block(-3,29,5,174)
Block(-3,29,6,174)
Block(-3,29,7,174)
Block(-3,29,8,174)
Block(-3,30,-7,174)
Block(-3,30,-6,174)
Block(-3,30,-5,174)
Block(-3,30,-4,174)
Block(-3,30,-3,174)
Block(-3,30,-2,174)
Block(-3,30,-1,174)
Block(-3,30,0,174)
Block(-3,30,1,174)
Block(-3,30,2,174)
Block(-3,30,3,174)
Block(-3,30,4,174)
Block(-3,30,5,174)
Block(-3,30,6,174)
Block(-3,30,7,174)
Block(-3,30,8,174)
Block(-3,31,-7,174)
Block(-3,31,-6,174)
Block(-3,31,-5,174)
Block(-3,31,-4,174)
Block(-3,31,-3,174)
Block(-3,31,-2,174)
Block(-3,31,-1,174)
Block(-3,31,0,174)
Block(-3,31,1,174)
Block(-3,31,2,174)
Block(-3,31,3,174)
Block(-3,31,4,174)
Block(-3,31,5,174)
Block(-3,31,6,174)
Block(-3,31,7,174)
Block(-3,31,8,174)
Block(-3,32,-7,174)
Block(-3,32,-6,174)
Block(-3,32,-5,174)
Block(-3,32,-4,174)
Block(-3,32,-3,174)
Block(-3,32,-2,174)
Block(-3,32,-1,174)
Block(-3,32,0,174)
Block(-3,32,1,174)
Block(-3,32,2,174)
Block(-3,32,3,174)
Block(-3,32,4,174)
Block(-3,32,5,174)
Block(-3,32,6,174)
Block(-3,32,7,174)
Block(-3,32,8,174)
Block(-3,33,-7,174)
Block(-3,33,-6,174)
Block(-3,33,-5,174)
Block(-3,33,-4,174)
Block(-3,33,-3,174)
Block(-3,33,-2,174)
Block(-3,33,-1,174)
Block(-3,33,0,174)
Block(-3,33,1,174)
Block(-3,33,2,174)
Block(-3,33,3,174)
Block(-3,33,4,174)
Block(-3,33,5,174)
Block(-3,33,6,174)
Block(-3,33,7,174)
Block(-3,33,8,174)
Block(-3,34,-7,174)
Block(-3,34,-6,174)
Block(-3,34,-5,174)
Block(-3,34,-4,174)
Block(-3,34,-3,174)
Block(-3,34,-2,174)
Block(-3,34,-1,174)
Block(-3,34,0,174)
Block(-3,34,1,174)
Block(-3,34,2,174)
Block(-3,34,3,174)
Block(-3,34,4,174)
Block(-3,34,5,174)
Block(-3,34,6,174)
Block(-3,34,7,174)
Block(-3,34,8,174)
Block(-3,35,-7,174)
Block(-3,35,-6,174)
Block(-3,35,-5,174)
Block(-3,35,-4,174)
Block(-3,35,-3,174)
Block(-3,35,-2,174)
Block(-3,35,-1,174)
Block(-3,35,0,174)
Block(-3,35,1,174)
Block(-3,35,2,174)
Block(-3,35,3,174)
Block(-3,35,4,174)
Block(-3,35,5,174)
Block(-3,35,6,174)
Block(-3,35,7,174)
Block(-3,35,8,174)
Block(-3,36,-7,174)
Block(-3,36,-6,174)
Block(-3,36,-5,174)
Block(-3,36,-4,174)
Block(-3,36,-3,174)
Block(-3,36,-2,174)
Block(-3,36,-1,174)
Block(-3,36,0,174)
Block(-3,36,1,174)
Block(-3,36,2,174)
Block(-3,36,3,174)
Block(-3,36,4,174)
Block(-3,36,5,174)
Block(-3,36,6,174)
Block(-3,36,7,174)
Block(-3,36,8,174)
Block(-3,37,-7,174)
Block(-3,37,-6,174)
Block(-3,37,-5,174)
Block(-3,37,-4,174)
Block(-3,37,-3,174)
Block(-3,37,-2,174)
Block(-3,37,-1,174)
Block(-3,37,0,174)
Block(-3,37,1,174)
Block(-3,37,2,174)
Block(-3,37,3,174)
Block(-3,37,4,174)
Block(-3,37,5,174)
Block(-3,37,6,174)
Block(-3,37,7,174)
Block(-3,37,8,174)
Block(-3,38,-7,174)
Block(-3,38,-6,174)
Block(-3,38,-5,174)
Block(-3,38,-4,174)
Block(-3,38,-3,174)
Block(-3,38,-2,174)
Block(-3,38,-1,174)
Block(-3,38,0,174)
Block(-3,38,1,174)
Block(-3,38,2,174)
Block(-3,38,3,174)
Block(-3,38,4,174)
Block(-3,38,5,174)
Block(-3,38,6,174)
Block(-3,38,7,174)
Block(-3,38,8,174)
Block(-3,39,-7,174)
Block(-3,39,-6,174)
Block(-3,39,-5,174)
Block(-3,39,-4,174)
Block(-3,39,-3,174)
Block(-3,39,-2,174)
Block(-3,39,-1,174)
Block(-3,39,0,174)
Block(-3,39,1,174)
Block(-3,39,2,174)
Block(-3,39,3,174)
Block(-3,39,4,174)
Block(-3,39,5,174)
Block(-3,39,6,174)
Block(-3,39,7,174)
Block(-3,39,8,174)
Block(-3,40,-7,174)
Block(-3,40,-6,174)
Block(-3,40,-5,174)
Block(-3,40,-4,174)
Block(-3,40,-3,174)
Block(-3,40,-2,174)
Block(-3,40,-1,174)
Block(-3,40,0,174)
Block(-3,40,1,174)
Block(-3,40,2,174)
Block(-3,40,3,174)
Block(-3,40,4,174)
Block(-3,40,5,174)
Block(-3,40,6,174)
Block(-3,40,7,174)
Block(-3,40,8,174)
Block(-3,41,-7,174)
Block(-3,41,-6,174)
Block(-3,41,-5,174)
Block(-3,41,-4,174)
Block(-3,41,-3,174)
Block(-3,41,-2,174)
Block(-3,41,-1,174)
Block(-3,41,0,174)
Block(-3,41,1,174)
Block(-3,41,2,174)
Block(-3,41,3,174)
Block(-3,41,4,174)
Block(-3,41,5,174)
Block(-3,41,6,174)
Block(-3,41,7,174)
Block(-3,41,8,174)
Block(-3,42,-7,174)
Block(-3,42,-6,174)
Block(-3,42,-5,174)
Block(-3,42,-4,174)
Block(-3,42,-3,174)
Block(-3,42,-2,174)
Block(-3,42,-1,174)
Block(-3,42,0,174)
Block(-3,42,1,174)
Block(-3,42,2,174)
Block(-3,42,3,174)
Block(-3,42,4,174)
Block(-3,42,5,174)
Block(-3,42,6,174)
Block(-3,42,7,174)
Block(-3,42,8,174)
Block(-3,43,-7,174)
Block(-3,43,-6,174)
Block(-3,43,-5,174)
Block(-3,43,-4,174)
Block(-3,43,-3,174)
Block(-3,43,-2,174)
Block(-3,43,-1,174)
Block(-3,43,0,174)
Block(-3,43,1,174)
Block(-3,43,2,174)
Block(-3,43,3,174)
Block(-3,43,4,174)
Block(-3,43,5,174)
Block(-3,43,6,174)
Block(-3,43,7,174)
Block(-3,43,8,174)
Block(-3,44,-7,174)
Block(-3,44,-6,174)
Block(-3,44,-5,174)
Block(-3,44,-4,174)
Block(-3,44,-3,174)
Block(-3,44,-2,174)
Block(-3,44,-1,174)
Block(-3,44,0,174)
Block(-3,44,1,174)
Block(-3,44,2,174)
Block(-3,44,3,174)
Block(-3,44,4,174)
Block(-3,44,5,174)
Block(-3,44,6,174)
Block(-3,44,7,174)
Block(-3,44,8,174)
Block(-3,45,-7,174)
Block(-3,45,-6,174)
Block(-3,45,-5,174)
Block(-3,45,-4,174)
Block(-3,45,-3,174)
Block(-3,45,-2,174)
Block(-3,45,-1,174)
Block(-3,45,0,174)
Block(-3,45,1,174)
Block(-3,45,2,174)
Block(-3,45,3,174)
Block(-3,45,4,174)
Block(-3,45,5,174)
Block(-3,45,6,174)
Block(-3,45,7,174)
Block(-3,45,8,174)
Block(-3,46,-7,174)
Block(-3,46,-6,174)
Block(-3,46,-5,174)
Block(-3,46,-4,174)
Block(-3,46,-3,174)
Block(-3,46,-2,174)
Block(-3,46,-1,174)
Block(-3,46,0,174)
Block(-3,46,1,174)
Block(-3,46,2,174)
Block(-3,46,3,174)
Block(-3,46,4,174)
Block(-3,46,5,174)
Block(-3,46,6,174)
Block(-3,46,7,174)
Block(-3,46,8,174)
Block(-3,47,-7,174)
Block(-3,47,-6,174)
Block(-3,47,-5,174)
Block(-3,47,-4,174)
Block(-3,47,-3,174)
Block(-3,47,-2,174)
Block(-3,47,-1,174)
Block(-3,47,0,174)
Block(-3,47,1,174)
Block(-3,47,2,174)
Block(-3,47,3,174)
Block(-3,47,4,174)
Block(-3,47,5,174)
Block(-3,47,6,174)
Block(-3,47,7,174)
Block(-3,47,8,174)
Block(-3,48,-7,174)
Block(-3,48,-6,174)
Block(-3,48,-5,174)
Block(-3,48,-4,174)
Block(-3,48,-3,174)
Block(-3,48,-2,174)
Block(-3,48,-1,174)
Block(-3,48,0,174)
Block(-3,48,1,174)
Block(-3,48,2,174)
Block(-3,48,3,174)
Block(-3,48,4,174)
Block(-3,48,5,174)
Block(-3,48,6,174)
Block(-3,48,7,174)
Block(-3,48,8,174)
Block(-3,49,-6,174)
Block(-3,49,-5,174)
Block(-3,49,-4,174)
Block(-3,49,-3,174)
Block(-3,49,-2,174)
Block(-3,49,-1,174)
Block(-3,49,0,174)
Block(-3,49,1,174)
Block(-3,49,2,174)
Block(-3,49,3,174)
Block(-3,49,4,174)
Block(-3,49,5,174)
Block(-3,49,6,174)
Block(-3,49,7,174)
Block(-3,49,8,174)
Block(-3,50,-6,174)
Block(-3,50,-5,174)
Block(-3,50,-4,174)
Block(-3,50,-3,174)
Block(-3,50,-2,174)
Block(-3,50,-1,174)
Block(-3,50,0,174)
Block(-3,50,1,174)
Block(-3,50,2,174)
Block(-3,50,3,174)
Block(-3,50,4,174)
Block(-3,50,5,174)
Block(-3,50,6,174)
Block(-3,50,7,174)
Block(-3,50,8,174)
Block(-3,51,-6,174)
Block(-3,51,-5,174)
Block(-3,51,-4,174)
Block(-3,51,-3,174)
Block(-3,51,-2,174)
Block(-3,51,-1,174)
Block(-3,51,0,174)
Block(-3,51,1,174)
Block(-3,51,2,174)
Block(-3,51,3,174)
Block(-3,51,4,174)
Block(-3,51,5,174)
Block(-3,51,6,174)
Block(-3,51,7,174)
Block(-3,51,8,174)
Block(-3,52,-6,174)
Block(-3,52,-5,174)
Block(-3,52,-4,174)
Block(-3,52,-3,174)
Block(-3,52,-2,174)
Block(-3,52,-1,174)
Block(-3,52,0,174)
Block(-3,52,1,174)
Block(-3,52,2,174)
Block(-3,52,3,174)
Block(-3,52,4,174)
Block(-3,52,5,174)
Block(-3,52,6,174)
Block(-3,52,7,174)
Block(-3,52,8,174)
Block(-3,53,-6,174)
Block(-3,53,-5,174)
Block(-3,53,-4,174)
Block(-3,53,-3,174)
Block(-3,53,-2,174)
Block(-3,53,-1,174)
Block(-3,53,0,174)
Block(-3,53,1,174)
Block(-3,53,2,174)
Block(-3,53,3,174)
Block(-3,53,4,174)
Block(-3,53,5,174)
Block(-3,53,6,174)
Block(-3,53,7,174)
Block(-3,53,8,174)
Block(-3,54,-3,174)
Block(-3,54,-2,174)
Block(-3,54,-1,174)
Block(-3,54,0,174)
Block(-3,54,1,174)
Block(-3,54,2,174)
Block(-3,54,3,174)
Block(-3,54,4,174)
Block(-3,54,5,174)
Block(-3,54,6,174)
Block(-3,54,7,174)
Block(-3,54,8,174)
Block(-3,55,-3,174)
Block(-3,55,-2,174)
Block(-3,55,-1,174)
Block(-3,55,0,174)
Block(-3,55,1,174)
Block(-3,55,2,174)
Block(-3,55,3,174)
Block(-3,55,4,174)
Block(-3,55,5,174)
Block(-3,55,6,174)
Block(-3,55,7,174)
Block(-3,55,8,174)
Block(-3,56,-2,174)
Block(-3,56,-1,174)
Block(-3,56,0,174)
Block(-3,56,1,174)
Block(-3,56,2,174)
Block(-3,56,3,174)
Block(-3,56,4,174)
Block(-3,56,5,174)
Block(-3,56,6,174)
Block(-3,56,7,174)
Block(-3,56,8,174)
Block(-3,57,-1,174)
Block(-3,57,0,174)
Block(-3,57,1,174)
Block(-3,57,2,174)
Block(-3,57,3,174)
Block(-3,57,4,174)
Block(-3,57,5,174)
Block(-3,57,6,174)
Block(-3,57,7,174)
Block(-3,57,8,174)
Block(-3,58,0,174)
Block(-3,58,1,174)
Block(-3,58,2,174)
Block(-3,58,3,174)
Block(-3,58,4,174)
Block(-3,58,5,174)
Block(-3,58,6,174)
Block(-3,58,7,174)
Block(-3,58,8,174)
Block(-3,59,1,174)
Block(-3,59,2,174)
Block(-3,59,3,174)
Block(-3,59,4,174)
Block(-3,59,5,174)
Block(-3,59,6,174)
Block(-3,59,7,174)
Block(-3,59,8,174)
Block(-3,60,2,174)
Block(-3,60,3,174)
Block(-3,60,4,174)
Block(-3,60,5,174)
Block(-3,60,6,174)
Block(-3,60,7,174)
Block(-3,60,8,174)
Block(-3,61,3,174)
Block(-3,61,4,174)
Block(-3,61,5,174)
Block(-3,61,6,174)
Block(-3,61,7,174)
Block(-3,61,8,174)
Block(-3,62,4,174)
Block(-3,62,5,174)
Block(-3,62,6,174)
Block(-3,62,7,174)
Block(-3,62,8,174)
Block(-3,63,5,174)
Block(-3,63,6,174)
Block(-3,63,7,174)
Block(-3,63,8,174)
Block(-3,64,6,174)
Block(-3,64,7,174)
Block(-3,64,8,174)
Block(-2,16,6,174)
Block(-2,16,7,174)
Block(-2,17,5,174)
Block(-2,17,6,174)
Block(-2,17,7,174)
Block(-2,17,8,174)
Block(-2,18,4,174)
Block(-2,18,5,174)
Block(-2,18,6,174)
Block(-2,18,7,174)
Block(-2,18,8,174)
Block(-2,19,2,174)
Block(-2,19,3,174)
Block(-2,19,4,174)
Block(-2,19,5,174)
Block(-2,19,6,174)
Block(-2,19,7,174)
Block(-2,19,8,174)
Block(-2,20,0,174)
Block(-2,20,1,174)
Block(-2,20,2,174)
Block(-2,20,3,174)
Block(-2,20,4,174)
Block(-2,20,5,174)
Block(-2,20,6,174)
Block(-2,20,7,174)
Block(-2,20,8,174)
Block(-2,21,0,174)
Block(-2,21,1,174)
Block(-2,21,2,174)
Block(-2,21,3,174)
Block(-2,21,4,174)
Block(-2,21,5,174)
Block(-2,21,6,174)
Block(-2,21,7,174)
Block(-2,21,8,174)
Block(-2,22,-1,174)
Block(-2,22,0,174)
Block(-2,22,1,174)
Block(-2,22,2,174)
Block(-2,22,3,174)
Block(-2,22,4,174)
Block(-2,22,5,174)
Block(-2,22,6,174)
Block(-2,22,7,174)
Block(-2,22,8,174)
Block(-2,23,-2,174)
Block(-2,23,-1,174)
Block(-2,23,0,174)
Block(-2,23,1,174)
Block(-2,23,2,174)
Block(-2,23,3,174)
Block(-2,23,4,174)
Block(-2,23,5,174)
Block(-2,23,6,174)
Block(-2,23,7,174)
Block(-2,23,8,174)
Block(-2,24,-3,174)
Block(-2,24,-2,174)
Block(-2,24,-1,174)
Block(-2,24,0,174)
Block(-2,24,1,174)
Block(-2,24,2,174)
Block(-2,24,3,174)
Block(-2,24,4,174)
Block(-2,24,5,174)
Block(-2,24,6,174)
Block(-2,24,7,174)
Block(-2,24,8,174)
Block(-2,25,-4,174)
Block(-2,25,-3,174)
Block(-2,25,-2,174)
Block(-2,25,-1,174)
Block(-2,25,0,174)
Block(-2,25,1,174)
Block(-2,25,2,174)
Block(-2,25,3,174)
Block(-2,25,4,174)
Block(-2,25,5,174)
Block(-2,25,6,174)
Block(-2,25,7,174)
Block(-2,25,8,174)
Block(-2,26,-5,174)
Block(-2,26,-4,174)
Block(-2,26,-3,174)
Block(-2,26,-2,174)
Block(-2,26,-1,174)
Block(-2,26,0,174)
Block(-2,26,1,174)
Block(-2,26,2,174)
Block(-2,26,3,174)
Block(-2,26,4,174)
Block(-2,26,5,174)
Block(-2,26,6,174)
Block(-2,26,7,174)
Block(-2,26,8,174)
Block(-2,27,-6,174)
Block(-2,27,-5,174)
Block(-2,27,-4,174)
Block(-2,27,-3,174)
Block(-2,27,-2,174)
Block(-2,27,-1,174)
Block(-2,27,0,174)
Block(-2,27,1,174)
Block(-2,27,2,174)
Block(-2,27,3,174)
Block(-2,27,4,174)
Block(-2,27,5,174)
Block(-2,27,6,174)
Block(-2,27,7,174)
Block(-2,27,8,174)
Block(-2,28,-6,174)
Block(-2,28,-5,174)
Block(-2,28,-4,174)
Block(-2,28,-3,174)
Block(-2,28,-2,174)
Block(-2,28,-1,174)
Block(-2,28,0,174)
Block(-2,28,1,174)
Block(-2,28,2,174)
Block(-2,28,3,174)
Block(-2,28,4,174)
Block(-2,28,5,174)
Block(-2,28,6,174)
Block(-2,28,7,174)
Block(-2,28,8,174)
Block(-2,29,-7,174)
Block(-2,29,-6,174)
Block(-2,29,-5,174)
Block(-2,29,-4,174)
Block(-2,29,-3,174)
Block(-2,29,-2,174)
Block(-2,29,-1,174)
Block(-2,29,0,174)
Block(-2,29,1,174)
Block(-2,29,2,174)
Block(-2,29,3,174)
Block(-2,29,4,174)
Block(-2,29,5,174)
Block(-2,29,6,174)
Block(-2,29,7,174)
Block(-2,29,8,174)
Block(-2,30,-7,174)
Block(-2,30,-6,174)
Block(-2,30,-5,174)
Block(-2,30,-4,174)
Block(-2,30,-3,174)
Block(-2,30,-2,174)
Block(-2,30,-1,174)
Block(-2,30,0,174)
Block(-2,30,1,174)
Block(-2,30,2,174)
Block(-2,30,3,174)
Block(-2,30,4,174)
Block(-2,30,5,174)
Block(-2,30,6,174)
Block(-2,30,7,174)
Block(-2,30,8,174)
Block(-2,31,-7,174)
Block(-2,31,-6,174)
Block(-2,31,-5,174)
Block(-2,31,-4,174)
Block(-2,31,-3,174)
Block(-2,31,-2,174)
Block(-2,31,-1,174)
Block(-2,31,0,174)
Block(-2,31,1,174)
Block(-2,31,2,174)
Block(-2,31,3,174)
Block(-2,31,4,174)
Block(-2,31,5,174)
Block(-2,31,6,174)
Block(-2,31,7,174)
Block(-2,31,8,174)
Block(-2,32,-7,174)
Block(-2,32,-6,174)
Block(-2,32,-5,174)
Block(-2,32,-4,174)
Block(-2,32,-3,174)
Block(-2,32,-2,174)
Block(-2,32,-1,174)
Block(-2,32,0,174)
Block(-2,32,1,174)
Block(-2,32,2,174)
Block(-2,32,3,174)
Block(-2,32,4,174)
Block(-2,32,5,174)
Block(-2,32,6,174)
Block(-2,32,7,174)
Block(-2,32,8,174)
Block(-2,33,-7,174)
Block(-2,33,-6,174)
Block(-2,33,-5,174)
Block(-2,33,-4,174)
Block(-2,33,-3,174)
Block(-2,33,-2,174)
Block(-2,33,-1,174)
Block(-2,33,0,174)
Block(-2,33,1,174)
Block(-2,33,2,174)
Block(-2,33,3,174)
Block(-2,33,4,174)
Block(-2,33,5,174)
Block(-2,33,6,174)
Block(-2,33,7,174)
Block(-2,33,8,174)
Block(-2,34,-7,174)
Block(-2,34,-6,174)
Block(-2,34,-5,174)
Block(-2,34,-4,174)
Block(-2,34,-3,174)
Block(-2,34,-2,174)
Block(-2,34,-1,174)
Block(-2,34,0,174)
Block(-2,34,1,174)
Block(-2,34,2,174)
Block(-2,34,3,174)
Block(-2,34,4,174)
Block(-2,34,5,174)
Block(-2,34,6,174)
Block(-2,34,7,174)
Block(-2,34,8,174)
Block(-2,35,-7,174)
Block(-2,35,-6,174)
Block(-2,35,-5,174)
Block(-2,35,-4,174)
Block(-2,35,-3,174)
Block(-2,35,-2,174)
Block(-2,35,-1,174)
Block(-2,35,0,174)
Block(-2,35,1,174)
Block(-2,35,2,174)
Block(-2,35,3,174)
Block(-2,35,4,174)
Block(-2,35,5,174)
Block(-2,35,6,174)
Block(-2,35,7,174)
Block(-2,35,8,174)
Block(-2,36,-7,174)
Block(-2,36,-6,174)
Block(-2,36,-5,174)
Block(-2,36,-4,174)
Block(-2,36,-3,174)
Block(-2,36,-2,174)
Block(-2,36,-1,174)
Block(-2,36,0,174)
Block(-2,36,1,174)
Block(-2,36,2,174)
Block(-2,36,3,174)
Block(-2,36,4,174)
Block(-2,36,5,174)
Block(-2,36,6,174)
Block(-2,36,7,174)
Block(-2,36,8,174)
Block(-2,37,-7,174)
Block(-2,37,-6,174)
Block(-2,37,-5,174)
Block(-2,37,-4,174)
Block(-2,37,-3,174)
Block(-2,37,-2,174)
Block(-2,37,-1,174)
Block(-2,37,0,174)
Block(-2,37,1,174)
Block(-2,37,2,174)
Block(-2,37,3,174)
Block(-2,37,4,174)
Block(-2,37,5,174)
Block(-2,37,6,174)
Block(-2,37,7,174)
Block(-2,37,8,174)
Block(-2,38,-7,174)
Block(-2,38,-6,174)
Block(-2,38,-5,174)
Block(-2,38,-4,174)
Block(-2,38,-3,174)
Block(-2,38,-2,174)
Block(-2,38,-1,174)
Block(-2,38,0,174)
Block(-2,38,1,174)
Block(-2,38,2,174)
Block(-2,38,3,174)
Block(-2,38,4,174)
Block(-2,38,5,174)
Block(-2,38,6,174)
Block(-2,38,7,174)
Block(-2,38,8,174)
Block(-2,39,-7,174)
Block(-2,39,-6,174)
Block(-2,39,-5,174)
Block(-2,39,-4,174)
Block(-2,39,-3,174)
Block(-2,39,-2,174)
Block(-2,39,-1,174)
Block(-2,39,0,174)
Block(-2,39,1,174)
Block(-2,39,2,174)
Block(-2,39,3,174)
Block(-2,39,4,174)
Block(-2,39,5,174)
Block(-2,39,6,174)
Block(-2,39,7,174)
Block(-2,39,8,174)
Block(-2,40,-7,174)
Block(-2,40,-6,174)
Block(-2,40,-5,174)
Block(-2,40,-4,174)
Block(-2,40,-3,174)
Block(-2,40,-2,174)
Block(-2,40,-1,174)
Block(-2,40,0,174)
Block(-2,40,1,174)
Block(-2,40,2,174)
Block(-2,40,3,174)
Block(-2,40,4,174)
Block(-2,40,5,174)
Block(-2,40,6,174)
Block(-2,40,7,174)
Block(-2,40,8,174)
Block(-2,41,-7,174)
Block(-2,41,-6,174)
Block(-2,41,-5,174)
Block(-2,41,-4,174)
Block(-2,41,-3,174)
Block(-2,41,-2,174)
Block(-2,41,-1,174)
Block(-2,41,0,174)
Block(-2,41,1,174)
Block(-2,41,2,174)
Block(-2,41,3,174)
Block(-2,41,4,174)
Block(-2,41,5,174)
Block(-2,41,6,174)
Block(-2,41,7,174)
Block(-2,41,8,174)
Block(-2,42,-7,174)
Block(-2,42,-6,174)
Block(-2,42,-5,174)
Block(-2,42,-4,174)
Block(-2,42,-3,174)
Block(-2,42,-2,174)
Block(-2,42,-1,174)
Block(-2,42,0,174)
Block(-2,42,1,174)
Block(-2,42,2,174)
Block(-2,42,3,174)
Block(-2,42,4,174)
Block(-2,42,5,174)
Block(-2,42,6,174)
Block(-2,42,7,174)
Block(-2,42,8,174)
Block(-2,43,-7,174)
Block(-2,43,-6,174)
Block(-2,43,-5,174)
Block(-2,43,-4,174)
Block(-2,43,-3,174)
Block(-2,43,-2,174)
Block(-2,43,-1,174)
Block(-2,43,0,174)
Block(-2,43,1,174)
Block(-2,43,2,174)
Block(-2,43,3,174)
Block(-2,43,4,174)
Block(-2,43,5,174)
Block(-2,43,6,174)
Block(-2,43,7,174)
Block(-2,43,8,174)
Block(-2,44,-7,174)
Block(-2,44,-6,174)
Block(-2,44,-5,174)
Block(-2,44,-4,174)
Block(-2,44,-3,174)
Block(-2,44,-2,174)
Block(-2,44,-1,174)
Block(-2,44,0,174)
Block(-2,44,1,174)
Block(-2,44,2,174)
Block(-2,44,3,174)
Block(-2,44,4,174)
Block(-2,44,5,174)
Block(-2,44,6,174)
Block(-2,44,7,174)
Block(-2,44,8,174)
Block(-2,45,-7,174)
Block(-2,45,-6,174)
Block(-2,45,-5,174)
Block(-2,45,-4,174)
Block(-2,45,-3,174)
Block(-2,45,-2,174)
Block(-2,45,-1,174)
Block(-2,45,0,174)
Block(-2,45,1,174)
Block(-2,45,2,174)
Block(-2,45,3,174)
Block(-2,45,4,174)
Block(-2,45,5,174)
Block(-2,45,6,174)
Block(-2,45,7,174)
Block(-2,45,8,174)
Block(-2,46,-7,174)
Block(-2,46,-6,174)
Block(-2,46,-5,174)
Block(-2,46,-4,174)
Block(-2,46,-3,174)
Block(-2,46,-2,174)
Block(-2,46,-1,174)
Block(-2,46,0,174)
Block(-2,46,1,174)
Block(-2,46,2,174)
Block(-2,46,3,174)
Block(-2,46,4,174)
Block(-2,46,5,174)
Block(-2,46,6,174)
Block(-2,46,7,174)
Block(-2,46,8,174)
Block(-2,47,-7,174)
Block(-2,47,-6,174)
Block(-2,47,-5,174)
Block(-2,47,-4,174)
Block(-2,47,-3,174)
Block(-2,47,-2,174)
Block(-2,47,-1,174)
Block(-2,47,0,174)
Block(-2,47,1,174)
Block(-2,47,2,174)
Block(-2,47,3,174)
Block(-2,47,4,174)
Block(-2,47,5,174)
Block(-2,47,6,174)
Block(-2,47,7,174)
Block(-2,47,8,174)
Block(-2,48,-7,174)
Block(-2,48,-6,174)
Block(-2,48,-5,174)
Block(-2,48,-4,174)
Block(-2,48,-3,174)
Block(-2,48,-2,174)
Block(-2,48,-1,174)
Block(-2,48,0,174)
Block(-2,48,1,174)
Block(-2,48,2,174)
Block(-2,48,3,174)
Block(-2,48,4,174)
Block(-2,48,5,174)
Block(-2,48,6,174)
Block(-2,48,7,174)
Block(-2,48,8,174)
Block(-2,49,-7,174)
Block(-2,49,-6,174)
Block(-2,49,-5,174)
Block(-2,49,-4,174)
Block(-2,49,-3,174)
Block(-2,49,-2,174)
Block(-2,49,-1,174)
Block(-2,49,0,174)
Block(-2,49,1,174)
Block(-2,49,2,174)
Block(-2,49,3,174)
Block(-2,49,4,174)
Block(-2,49,5,174)
Block(-2,49,6,174)
Block(-2,49,7,174)
Block(-2,49,8,174)
Block(-2,50,-7,174)
Block(-2,50,-6,174)
Block(-2,50,-5,174)
Block(-2,50,-4,174)
Block(-2,50,-3,174)
Block(-2,50,-2,174)
Block(-2,50,-1,174)
Block(-2,50,0,174)
Block(-2,50,1,174)
Block(-2,50,2,174)
Block(-2,50,3,174)
Block(-2,50,4,174)
Block(-2,50,5,174)
Block(-2,50,6,174)
Block(-2,50,7,174)
Block(-2,50,8,174)
Block(-2,51,-7,174)
Block(-2,51,-6,174)
Block(-2,51,-5,174)
Block(-2,51,-4,174)
Block(-2,51,-3,174)
Block(-2,51,-2,174)
Block(-2,51,-1,174)
Block(-2,51,0,174)
Block(-2,51,1,174)
Block(-2,51,2,174)
Block(-2,51,3,174)
Block(-2,51,4,174)
Block(-2,51,5,174)
Block(-2,51,6,174)
Block(-2,51,7,174)
Block(-2,51,8,174)
Block(-2,52,-6,174)
Block(-2,52,-5,174)
Block(-2,52,-4,174)
Block(-2,52,-3,174)
Block(-2,52,-2,174)
Block(-2,52,-1,174)
Block(-2,52,0,174)
Block(-2,52,1,174)
Block(-2,52,2,174)
Block(-2,52,3,174)
Block(-2,52,4,174)
Block(-2,52,5,174)
Block(-2,52,6,174)
Block(-2,52,7,174)
Block(-2,52,8,174)
Block(-2,53,-6,174)
Block(-2,53,-5,174)
Block(-2,53,-4,174)
Block(-2,53,-3,174)
Block(-2,53,-2,174)
Block(-2,53,-1,174)
Block(-2,53,0,174)
Block(-2,53,1,174)
Block(-2,53,2,174)
Block(-2,53,3,174)
Block(-2,53,4,174)
Block(-2,53,5,174)
Block(-2,53,6,174)
Block(-2,53,7,174)
Block(-2,53,8,174)
Block(-2,54,-6,174)
Block(-2,54,-5,174)
Block(-2,54,-4,174)
Block(-2,54,-3,174)
Block(-2,54,-2,174)
Block(-2,54,-1,174)
Block(-2,54,0,174)
Block(-2,54,1,174)
Block(-2,54,2,174)
Block(-2,54,3,174)
Block(-2,54,4,174)
Block(-2,54,5,174)
Block(-2,54,6,174)
Block(-2,54,7,174)
Block(-2,54,8,174)
Block(-2,55,-5,174)
Block(-2,55,-4,174)
Block(-2,55,-3,174)
Block(-2,55,-2,174)
Block(-2,55,-1,174)
Block(-2,55,0,174)
Block(-2,55,1,174)
Block(-2,55,2,174)
Block(-2,55,3,174)
Block(-2,55,4,174)
Block(-2,55,5,174)
Block(-2,55,6,174)
Block(-2,55,7,174)
Block(-2,55,8,174)
Block(-2,56,-4,174)
Block(-2,56,-3,174)
Block(-2,56,-2,174)
Block(-2,56,-1,174)
Block(-2,56,0,174)
Block(-2,56,1,174)
Block(-2,56,2,174)
Block(-2,56,3,174)
Block(-2,56,4,174)
Block(-2,56,5,174)
Block(-2,56,6,174)
Block(-2,56,7,174)
Block(-2,56,8,174)
Block(-2,57,-3,174)
Block(-2,57,-2,174)
Block(-2,57,-1,174)
Block(-2,57,0,174)
Block(-2,57,1,174)
Block(-2,57,2,174)
Block(-2,57,3,174)
Block(-2,57,4,174)
Block(-2,57,5,174)
Block(-2,57,6,174)
Block(-2,57,7,174)
Block(-2,57,8,174)
Block(-2,58,-2,174)
Block(-2,58,-1,174)
Block(-2,58,0,174)
Block(-2,58,1,174)
Block(-2,58,2,174)
Block(-2,58,3,174)
Block(-2,58,4,174)
Block(-2,58,5,174)
Block(-2,58,6,174)
Block(-2,58,7,174)
Block(-2,58,8,174)
Block(-2,59,-1,174)
Block(-2,59,0,174)
Block(-2,59,1,174)
Block(-2,59,2,174)
Block(-2,59,3,174)
Block(-2,59,4,174)
Block(-2,59,5,174)
Block(-2,59,6,174)
Block(-2,59,7,174)
Block(-2,59,8,174)
Block(-2,60,0,174)
Block(-2,60,1,174)
Block(-2,60,2,174)
Block(-2,60,3,174)
Block(-2,60,4,174)
Block(-2,60,5,174)
Block(-2,60,6,174)
Block(-2,60,7,174)
Block(-2,60,8,174)
Block(-2,61,0,174)
Block(-2,61,1,174)
Block(-2,61,2,174)
Block(-2,61,3,174)
Block(-2,61,4,174)
Block(-2,61,5,174)
Block(-2,61,6,174)
Block(-2,61,7,174)
Block(-2,61,8,174)
Block(-2,62,2,174)
Block(-2,62,3,174)
Block(-2,62,4,174)
Block(-2,62,5,174)
Block(-2,62,6,174)
Block(-2,62,7,174)
Block(-2,62,8,174)
Block(-2,63,4,174)
Block(-2,63,5,174)
Block(-2,63,6,174)
Block(-2,63,7,174)
Block(-2,63,8,174)
Block(-2,64,5,174)
Block(-2,64,6,174)
Block(-2,64,7,174)
Block(-2,64,8,174)
Block(-2,65,6,174)
Block(-2,65,7,174)
Block(-1,16,5,174)
Block(-1,16,6,174)
Block(-1,16,7,174)
Block(-1,16,8,174)
Block(-1,17,4,174)
Block(-1,17,5,174)
Block(-1,17,6,174)
Block(-1,17,7,174)
Block(-1,17,8,174)
Block(-1,18,3,174)
Block(-1,18,4,174)
Block(-1,18,5,174)
Block(-1,18,6,174)
Block(-1,18,7,174)
Block(-1,18,8,174)
Block(-1,19,1,174)
Block(-1,19,2,174)
Block(-1,19,3,174)
Block(-1,19,4,174)
Block(-1,19,5,174)
Block(-1,19,6,174)
Block(-1,19,7,174)
Block(-1,19,8,174)
Block(-1,20,0,174)
Block(-1,20,1,174)
Block(-1,20,2,174)
Block(-1,20,3,174)
Block(-1,20,4,174)
Block(-1,20,5,174)
Block(-1,20,6,174)
Block(-1,20,7,174)
Block(-1,20,8,174)
Block(-1,21,-1,174)
Block(-1,21,0,174)
Block(-1,21,1,174)
Block(-1,21,2,174)
Block(-1,21,3,174)
Block(-1,21,4,174)
Block(-1,21,5,174)
Block(-1,21,6,174)
Block(-1,21,7,174)
Block(-1,21,8,174)
Block(-1,22,-1,174)
Block(-1,22,0,174)
Block(-1,22,1,174)
Block(-1,22,2,174)
Block(-1,22,3,174)
Block(-1,22,4,174)
Block(-1,22,5,174)
Block(-1,22,6,174)
Block(-1,22,7,174)
Block(-1,22,8,174)
Block(-1,23,-3,174)
Block(-1,23,-2,174)
Block(-1,23,-1,174)
Block(-1,23,0,174)
Block(-1,23,1,174)
Block(-1,23,2,174)
Block(-1,23,3,174)
Block(-1,23,4,174)
Block(-1,23,5,174)
Block(-1,23,6,174)
Block(-1,23,7,174)
Block(-1,23,8,174)
Block(-1,24,-4,174)
Block(-1,24,-3,174)
Block(-1,24,-2,174)
Block(-1,24,-1,174)
Block(-1,24,0,174)
Block(-1,24,1,174)
Block(-1,24,2,174)
Block(-1,24,3,174)
Block(-1,24,4,174)
Block(-1,24,5,174)
Block(-1,24,6,174)
Block(-1,24,7,174)
Block(-1,24,8,174)
Block(-1,25,-5,174)
Block(-1,25,-4,174)
Block(-1,25,-3,174)
Block(-1,25,-2,174)
Block(-1,25,-1,174)
Block(-1,25,0,174)
Block(-1,25,1,174)
Block(-1,25,2,174)
Block(-1,25,3,174)
Block(-1,25,4,174)
Block(-1,25,5,174)
Block(-1,25,6,174)
Block(-1,25,7,174)
Block(-1,25,8,174)
Block(-1,26,-5,174)
Block(-1,26,-4,174)
Block(-1,26,-3,174)
Block(-1,26,-2,174)
Block(-1,26,-1,174)
Block(-1,26,0,174)
Block(-1,26,1,174)
Block(-1,26,2,174)
Block(-1,26,3,174)
Block(-1,26,4,174)
Block(-1,26,5,174)
Block(-1,26,6,174)
Block(-1,26,7,174)
Block(-1,26,8,174)
Block(-1,27,-6,174)
Block(-1,27,-5,174)
Block(-1,27,-4,174)
Block(-1,27,-3,174)
Block(-1,27,-2,174)
Block(-1,27,-1,174)
Block(-1,27,0,174)
Block(-1,27,1,174)
Block(-1,27,2,174)
Block(-1,27,3,174)
Block(-1,27,4,174)
Block(-1,27,5,174)
Block(-1,27,6,174)
Block(-1,27,7,174)
Block(-1,27,8,174)
Block(-1,28,-6,174)
Block(-1,28,-5,174)
Block(-1,28,-4,174)
Block(-1,28,-3,174)
Block(-1,28,-2,174)
Block(-1,28,-1,174)
Block(-1,28,0,174)
Block(-1,28,1,174)
Block(-1,28,2,174)
Block(-1,28,3,174)
Block(-1,28,4,174)
Block(-1,28,5,174)
Block(-1,28,6,174)
Block(-1,28,7,174)
Block(-1,28,8,174)
Block(-1,29,-7,174)
Block(-1,29,-6,174)
Block(-1,29,-5,174)
Block(-1,29,-4,174)
Block(-1,29,-3,174)
Block(-1,29,-2,174)
Block(-1,29,-1,174)
Block(-1,29,0,174)
Block(-1,29,1,174)
Block(-1,29,2,174)
Block(-1,29,3,174)
Block(-1,29,4,174)
Block(-1,29,5,174)
Block(-1,29,6,174)
Block(-1,29,7,174)
Block(-1,29,8,174)
Block(-1,30,-7,174)
Block(-1,30,-6,174)
Block(-1,30,-5,174)
Block(-1,30,-4,174)
Block(-1,30,-3,174)
Block(-1,30,-2,174)
Block(-1,30,-1,174)
Block(-1,30,0,174)
Block(-1,30,1,174)
Block(-1,30,2,174)
Block(-1,30,3,174)
Block(-1,30,4,174)
Block(-1,30,5,174)
Block(-1,30,6,174)
Block(-1,30,7,174)
Block(-1,30,8,174)
Block(-1,31,-7,174)
Block(-1,31,-6,174)
Block(-1,31,-5,174)
Block(-1,31,-4,174)
Block(-1,31,-3,174)
Block(-1,31,-2,174)
Block(-1,31,-1,174)
Block(-1,31,0,174)
Block(-1,31,1,174)
Block(-1,31,2,174)
Block(-1,31,3,174)
Block(-1,31,4,174)
Block(-1,31,5,174)
Block(-1,31,6,174)
Block(-1,31,7,174)
Block(-1,31,8,174)
Block(-1,32,-7,174)
Block(-1,32,-6,174)
Block(-1,32,-5,174)
Block(-1,32,-4,174)
Block(-1,32,-3,174)
Block(-1,32,-2,174)
Block(-1,32,-1,174)
Block(-1,32,0,174)
Block(-1,32,1,174)
Block(-1,32,2,174)
Block(-1,32,3,174)
Block(-1,32,4,174)
Block(-1,32,5,174)
Block(-1,32,6,174)
Block(-1,32,7,174)
Block(-1,32,8,174)
Block(-1,33,-7,174)
Block(-1,33,-6,174)
Block(-1,33,-5,174)
Block(-1,33,-4,174)
Block(-1,33,-3,174)
Block(-1,33,-2,174)
Block(-1,33,-1,174)
Block(-1,33,0,174)
Block(-1,33,1,174)
Block(-1,33,2,174)
Block(-1,33,3,174)
Block(-1,33,4,174)
Block(-1,33,5,174)
Block(-1,33,6,174)
Block(-1,33,7,174)
Block(-1,33,8,174)
Block(-1,34,-7,174)
Block(-1,34,-6,174)
Block(-1,34,-5,174)
Block(-1,34,-4,174)
Block(-1,34,-3,174)
Block(-1,34,-2,174)
Block(-1,34,-1,174)
Block(-1,34,0,174)
Block(-1,34,1,174)
Block(-1,34,2,174)
Block(-1,34,3,174)
Block(-1,34,4,174)
Block(-1,34,5,174)
Block(-1,34,6,174)
Block(-1,34,7,174)
Block(-1,34,8,174)
Block(-1,35,-7,174)
Block(-1,35,-6,174)
Block(-1,35,-5,174)
Block(-1,35,-4,174)
Block(-1,35,-3,174)
Block(-1,35,-2,174)
Block(-1,35,-1,174)
Block(-1,35,0,174)
Block(-1,35,1,174)
Block(-1,35,2,174)
Block(-1,35,3,174)
Block(-1,35,4,174)
Block(-1,35,5,174)
Block(-1,35,6,174)
Block(-1,35,7,174)
Block(-1,35,8,174)
Block(-1,36,-7,174)
Block(-1,36,-6,174)
Block(-1,36,-5,174)
Block(-1,36,-4,174)
Block(-1,36,-3,174)
Block(-1,36,-2,174)
Block(-1,36,-1,174)
Block(-1,36,0,174)
Block(-1,36,1,174)
Block(-1,36,2,174)
Block(-1,36,3,174)
Block(-1,36,4,174)
Block(-1,36,5,174)
Block(-1,36,6,174)
Block(-1,36,7,174)
Block(-1,36,8,174)
Block(-1,37,-7,174)
Block(-1,37,-6,174)
Block(-1,37,-5,174)
Block(-1,37,-4,174)
Block(-1,37,-3,174)
Block(-1,37,-2,174)
Block(-1,37,-1,174)
Block(-1,37,0,174)
Block(-1,37,1,174)
Block(-1,37,2,174)
Block(-1,37,3,174)
Block(-1,37,4,174)
Block(-1,37,5,174)
Block(-1,37,6,174)
Block(-1,37,7,174)
Block(-1,37,8,174)
Block(-1,38,-7,174)
Block(-1,38,-6,174)
Block(-1,38,-5,174)
Block(-1,38,-4,174)
Block(-1,38,-3,174)
Block(-1,38,-2,174)
Block(-1,38,-1,174)
Block(-1,38,0,174)
Block(-1,38,1,174)
Block(-1,38,2,174)
Block(-1,38,3,174)
Block(-1,38,4,174)
Block(-1,38,5,174)
Block(-1,38,6,174)
Block(-1,38,7,174)
Block(-1,38,8,174)
Block(-1,39,-7,174)
Block(-1,39,-6,174)
Block(-1,39,-5,174)
Block(-1,39,-4,174)
Block(-1,39,-3,174)
Block(-1,39,-2,174)
Block(-1,39,-1,174)
Block(-1,39,0,174)
Block(-1,39,1,174)
Block(-1,39,2,174)
Block(-1,39,3,174)
Block(-1,39,4,174)
Block(-1,39,5,174)
Block(-1,39,6,174)
Block(-1,39,7,174)
Block(-1,39,8,174)
Block(-1,40,-7,174)
Block(-1,40,-6,174)
Block(-1,40,-5,174)
Block(-1,40,-4,174)
Block(-1,40,-3,174)
Block(-1,40,-2,174)
Block(-1,40,-1,174)
Block(-1,40,0,174)
Block(-1,40,1,174)
Block(-1,40,2,174)
Block(-1,40,3,174)
Block(-1,40,4,174)
Block(-1,40,5,174)
Block(-1,40,6,174)
Block(-1,40,7,174)
Block(-1,40,8,174)
Block(-1,41,-7,174)
Block(-1,41,-6,174)
Block(-1,41,-5,174)
Block(-1,41,-4,174)
Block(-1,41,-3,174)
Block(-1,41,-2,174)
Block(-1,41,-1,174)
Block(-1,41,0,174)
Block(-1,41,1,174)
Block(-1,41,2,174)
Block(-1,41,3,174)
Block(-1,41,4,174)
Block(-1,41,5,174)
Block(-1,41,6,174)
Block(-1,41,7,174)
Block(-1,41,8,174)
Block(-1,42,-7,174)
Block(-1,42,-6,174)
Block(-1,42,-5,174)
Block(-1,42,-4,174)
Block(-1,42,-3,174)
Block(-1,42,-2,174)
Block(-1,42,-1,174)
Block(-1,42,0,174)
Block(-1,42,1,174)
Block(-1,42,2,174)
Block(-1,42,3,174)
Block(-1,42,4,174)
Block(-1,42,5,174)
Block(-1,42,6,174)
Block(-1,42,7,174)
Block(-1,42,8,174)
Block(-1,43,-7,174)
Block(-1,43,-6,174)
Block(-1,43,-5,174)
Block(-1,43,-4,174)
Block(-1,43,-3,174)
Block(-1,43,-2,174)
Block(-1,43,-1,174)
Block(-1,43,0,174)
Block(-1,43,1,174)
Block(-1,43,2,174)
Block(-1,43,3,174)
Block(-1,43,4,174)
Block(-1,43,5,174)
Block(-1,43,6,174)
Block(-1,43,7,174)
Block(-1,43,8,174)
Block(-1,44,-7,174)
Block(-1,44,-6,174)
Block(-1,44,-5,174)
Block(-1,44,-4,174)
Block(-1,44,-3,174)
Block(-1,44,-2,174)
Block(-1,44,-1,174)
Block(-1,44,0,174)
Block(-1,44,1,174)
Block(-1,44,2,174)
Block(-1,44,3,174)
Block(-1,44,4,174)
Block(-1,44,5,174)
Block(-1,44,6,174)
Block(-1,44,7,174)
Block(-1,44,8,174)
Block(-1,45,-7,174)
Block(-1,45,-6,174)
Block(-1,45,-5,174)
Block(-1,45,-4,174)
Block(-1,45,-3,174)
Block(-1,45,-2,174)
Block(-1,45,-1,174)
Block(-1,45,0,174)
Block(-1,45,1,174)
Block(-1,45,2,174)
Block(-1,45,3,174)
Block(-1,45,4,174)
Block(-1,45,5,174)
Block(-1,45,6,174)
Block(-1,45,7,174)
Block(-1,45,8,174)
Block(-1,46,-7,174)
Block(-1,46,-6,174)
Block(-1,46,-5,174)
Block(-1,46,-4,174)
Block(-1,46,-3,174)
Block(-1,46,-2,174)
Block(-1,46,-1,174)
Block(-1,46,0,174)
Block(-1,46,1,174)
Block(-1,46,2,174)
Block(-1,46,3,174)
Block(-1,46,4,174)
Block(-1,46,5,174)
Block(-1,46,6,174)
Block(-1,46,7,174)
Block(-1,46,8,174)
Block(-1,47,-7,174)
Block(-1,47,-6,174)
Block(-1,47,-5,174)
Block(-1,47,-4,174)
Block(-1,47,-3,174)
Block(-1,47,-2,174)
Block(-1,47,-1,174)
Block(-1,47,0,174)
Block(-1,47,1,174)
Block(-1,47,2,174)
Block(-1,47,3,174)
Block(-1,47,4,174)
Block(-1,47,5,174)
Block(-1,47,6,174)
Block(-1,47,7,174)
Block(-1,47,8,174)
Block(-1,48,-7,174)
Block(-1,48,-6,174)
Block(-1,48,-5,174)
Block(-1,48,-4,174)
Block(-1,48,-3,174)
Block(-1,48,-2,174)
Block(-1,48,-1,174)
Block(-1,48,0,174)
Block(-1,48,1,174)
Block(-1,48,2,174)
Block(-1,48,3,174)
Block(-1,48,4,174)
Block(-1,48,5,174)
Block(-1,48,6,174)
Block(-1,48,7,174)
Block(-1,48,8,174)
Block(-1,49,-7,174)
Block(-1,49,-6,174)
Block(-1,49,-5,174)
Block(-1,49,-4,174)
Block(-1,49,-3,174)
Block(-1,49,-2,174)
Block(-1,49,-1,174)
Block(-1,49,0,174)
Block(-1,49,1,174)
Block(-1,49,2,174)
Block(-1,49,3,174)
Block(-1,49,4,174)
Block(-1,49,5,174)
Block(-1,49,6,174)
Block(-1,49,7,174)
Block(-1,49,8,174)
Block(-1,50,-7,174)
Block(-1,50,-6,174)
Block(-1,50,-5,174)
Block(-1,50,-4,174)
Block(-1,50,-3,174)
Block(-1,50,-2,174)
Block(-1,50,-1,174)
Block(-1,50,0,174)
Block(-1,50,1,174)
Block(-1,50,2,174)
Block(-1,50,3,174)
Block(-1,50,4,174)
Block(-1,50,5,174)
Block(-1,50,6,174)
Block(-1,50,7,174)
Block(-1,50,8,174)
Block(-1,51,-7,174)
Block(-1,51,-6,174)
Block(-1,51,-5,174)
Block(-1,51,-4,174)
Block(-1,51,-3,174)
Block(-1,51,-2,174)
Block(-1,51,-1,174)
Block(-1,51,0,174)
Block(-1,51,1,174)
Block(-1,51,2,174)
Block(-1,51,3,174)
Block(-1,51,4,174)
Block(-1,51,5,174)
Block(-1,51,6,174)
Block(-1,51,7,174)
Block(-1,51,8,174)
Block(-1,52,-7,174)
Block(-1,52,-6,174)
Block(-1,52,-5,174)
Block(-1,52,-4,174)
Block(-1,52,-3,174)
Block(-1,52,-2,174)
Block(-1,52,-1,174)
Block(-1,52,0,174)
Block(-1,52,1,174)
Block(-1,52,2,174)
Block(-1,52,3,174)
Block(-1,52,4,174)
Block(-1,52,5,174)
Block(-1,52,6,174)
Block(-1,52,7,174)
Block(-1,52,8,174)
Block(-1,53,-6,174)
Block(-1,53,-5,174)
Block(-1,53,-4,174)
Block(-1,53,-3,174)
Block(-1,53,-2,174)
Block(-1,53,-1,174)
Block(-1,53,0,174)
Block(-1,53,1,174)
Block(-1,53,2,174)
Block(-1,53,3,174)
Block(-1,53,4,174)
Block(-1,53,5,174)
Block(-1,53,6,174)
Block(-1,53,7,174)
Block(-1,53,8,174)
Block(-1,54,-6,174)
Block(-1,54,-5,174)
Block(-1,54,-4,174)
Block(-1,54,-3,174)
Block(-1,54,-2,174)
Block(-1,54,-1,174)
Block(-1,54,0,174)
Block(-1,54,1,174)
Block(-1,54,2,174)
Block(-1,54,3,174)
Block(-1,54,4,174)
Block(-1,54,5,174)
Block(-1,54,6,174)
Block(-1,54,7,174)
Block(-1,54,8,174)
Block(-1,55,-5,174)
Block(-1,55,-4,174)
Block(-1,55,-3,174)
Block(-1,55,-2,174)
Block(-1,55,-1,174)
Block(-1,55,0,174)
Block(-1,55,1,174)
Block(-1,55,2,174)
Block(-1,55,3,174)
Block(-1,55,4,174)
Block(-1,55,5,174)
Block(-1,55,6,174)
Block(-1,55,7,174)
Block(-1,55,8,174)
Block(-1,56,-5,174)
Block(-1,56,-4,174)
Block(-1,56,-3,174)
Block(-1,56,-2,174)
Block(-1,56,-1,174)
Block(-1,56,0,174)
Block(-1,56,1,174)
Block(-1,56,2,174)
Block(-1,56,3,174)
Block(-1,56,4,174)
Block(-1,56,5,174)
Block(-1,56,6,174)
Block(-1,56,7,174)
Block(-1,56,8,174)
Block(-1,57,-4,174)
Block(-1,57,-3,174)
Block(-1,57,-2,174)
Block(-1,57,-1,174)
Block(-1,57,0,174)
Block(-1,57,1,174)
Block(-1,57,2,174)
Block(-1,57,3,174)
Block(-1,57,4,174)
Block(-1,57,5,174)
Block(-1,57,6,174)
Block(-1,57,7,174)
Block(-1,57,8,174)
Block(-1,58,-3,174)
Block(-1,58,-2,174)
Block(-1,58,-1,174)
Block(-1,58,0,174)
Block(-1,58,1,174)
Block(-1,58,2,174)
Block(-1,58,3,174)
Block(-1,58,4,174)
Block(-1,58,5,174)
Block(-1,58,6,174)
Block(-1,58,7,174)
Block(-1,58,8,174)
Block(-1,59,-1,174)
Block(-1,59,0,174)
Block(-1,59,1,174)
Block(-1,59,2,174)
Block(-1,59,3,174)
Block(-1,59,4,174)
Block(-1,59,5,174)
Block(-1,59,6,174)
Block(-1,59,7,174)
Block(-1,59,8,174)
Block(-1,60,-1,174)
Block(-1,60,0,174)
Block(-1,60,1,174)
Block(-1,60,2,174)
Block(-1,60,3,174)
Block(-1,60,4,174)
Block(-1,60,5,174)
Block(-1,60,6,174)
Block(-1,60,7,174)
Block(-1,60,8,174)
Block(-1,61,0,174)
Block(-1,61,1,174)
Block(-1,61,2,174)
Block(-1,61,3,174)
Block(-1,61,4,174)
Block(-1,61,5,174)
Block(-1,61,6,174)
Block(-1,61,7,174)
Block(-1,61,8,174)
Block(-1,62,1,174)
Block(-1,62,2,174)
Block(-1,62,3,174)
Block(-1,62,4,174)
Block(-1,62,5,174)
Block(-1,62,6,174)
Block(-1,62,7,174)
Block(-1,62,8,174)
Block(-1,63,3,174)
Block(-1,63,4,174)
Block(-1,63,5,174)
Block(-1,63,6,174)
Block(-1,63,7,174)
Block(-1,63,8,174)
Block(-1,64,4,174)
Block(-1,64,5,174)
Block(-1,64,6,174)
Block(-1,64,7,174)
Block(-1,64,8,174)
Block(-1,65,5,174)
Block(-1,65,6,174)
Block(-1,65,7,174)
Block(-1,65,8,174)
Block(0,15,6,174)
Block(0,15,7,174)
Block(0,15,8,174)
Block(0,16,5,174)
Block(0,16,6,174)
Block(0,16,7,174)
Block(0,16,8,174)
Block(0,17,4,174)
Block(0,17,5,174)
Block(0,17,6,174)
Block(0,17,7,174)
Block(0,17,8,174)
Block(0,18,3,174)
Block(0,18,4,174)
Block(0,18,5,174)
Block(0,18,6,174)
Block(0,18,7,174)
Block(0,18,8,174)
Block(0,19,0,174)
Block(0,19,1,174)
Block(0,19,2,174)
Block(0,19,3,174)
Block(0,19,4,174)
Block(0,19,5,174)
Block(0,19,6,174)
Block(0,19,7,174)
Block(0,19,8,174)
Block(0,20,0,174)
Block(0,20,1,174)
Block(0,20,2,174)
Block(0,20,3,174)
Block(0,20,4,174)
Block(0,20,5,174)
Block(0,20,6,174)
Block(0,20,7,174)
Block(0,20,8,174)
Block(0,21,-1,174)
Block(0,21,0,174)
Block(0,21,1,174)
Block(0,21,2,174)
Block(0,21,3,174)
Block(0,21,4,174)
Block(0,21,5,174)
Block(0,21,6,174)
Block(0,21,7,174)
Block(0,21,8,174)
Block(0,22,-2,174)
Block(0,22,-1,174)
Block(0,22,0,174)
Block(0,22,1,174)
Block(0,22,2,174)
Block(0,22,3,174)
Block(0,22,4,174)
Block(0,22,5,174)
Block(0,22,6,174)
Block(0,22,7,174)
Block(0,22,8,174)
Block(0,23,-3,174)
Block(0,23,-2,174)
Block(0,23,-1,174)
Block(0,23,0,174)
Block(0,23,1,174)
Block(0,23,2,174)
Block(0,23,3,174)
Block(0,23,4,174)
Block(0,23,5,174)
Block(0,23,6,174)
Block(0,23,7,174)
Block(0,23,8,174)
Block(0,24,-5,174)
Block(0,24,-4,174)
Block(0,24,-3,174)
Block(0,24,-2,174)
Block(0,24,-1,174)
Block(0,24,0,174)
Block(0,24,1,174)
Block(0,24,2,174)
Block(0,24,3,174)
Block(0,24,4,174)
Block(0,24,5,174)
Block(0,24,6,174)
Block(0,24,7,174)
Block(0,24,8,174)
Block(0,25,-5,174)
Block(0,25,-4,174)
Block(0,25,-3,174)
Block(0,25,-2,174)
Block(0,25,-1,174)
Block(0,25,0,174)
Block(0,25,1,174)
Block(0,25,2,174)
Block(0,25,3,174)
Block(0,25,4,174)
Block(0,25,5,174)
Block(0,25,6,174)
Block(0,25,7,174)
Block(0,25,8,174)
Block(0,26,-6,174)
Block(0,26,-5,174)
Block(0,26,-4,174)
Block(0,26,-3,174)
Block(0,26,-2,174)
Block(0,26,-1,174)
Block(0,26,0,174)
Block(0,26,1,174)
Block(0,26,2,174)
Block(0,26,3,174)
Block(0,26,4,174)
Block(0,26,5,174)
Block(0,26,6,174)
Block(0,26,7,174)
Block(0,26,8,174)
Block(0,27,-6,174)
Block(0,27,-5,174)
Block(0,27,-4,174)
Block(0,27,-3,174)
Block(0,27,-2,174)
Block(0,27,-1,174)
Block(0,27,0,174)
Block(0,27,1,174)
Block(0,27,2,174)
Block(0,27,3,174)
Block(0,27,4,174)
Block(0,27,5,174)
Block(0,27,6,174)
Block(0,27,7,174)
Block(0,27,8,174)
Block(0,28,-7,174)
Block(0,28,-6,174)
Block(0,28,-5,174)
Block(0,28,-4,174)
Block(0,28,-3,174)
Block(0,28,-2,174)
Block(0,28,-1,174)
Block(0,28,0,174)
Block(0,28,1,174)
Block(0,28,2,174)
Block(0,28,3,174)
Block(0,28,4,174)
Block(0,28,5,174)
Block(0,28,6,174)
Block(0,28,7,174)
Block(0,28,8,174)
Block(0,29,-7,174)
Block(0,29,-6,174)
Block(0,29,-5,174)
Block(0,29,-4,174)
Block(0,29,-3,174)
Block(0,29,-2,174)
Block(0,29,-1,174)
Block(0,29,0,174)
Block(0,29,1,174)
Block(0,29,2,174)
Block(0,29,3,174)
Block(0,29,4,174)
Block(0,29,5,174)
Block(0,29,6,174)
Block(0,29,7,174)
Block(0,29,8,174)
Block(0,30,-7,174)
Block(0,30,-6,174)
Block(0,30,-5,174)
Block(0,30,-4,174)
Block(0,30,-3,174)
Block(0,30,-2,174)
Block(0,30,-1,174)
Block(0,30,0,174)
Block(0,30,1,174)
Block(0,30,2,174)
Block(0,30,3,174)
Block(0,30,4,174)
Block(0,30,5,174)
Block(0,30,6,174)
Block(0,30,7,174)
Block(0,30,8,174)
Block(0,31,-7,174)
Block(0,31,-6,174)
Block(0,31,-5,174)
Block(0,31,-4,174)
Block(0,31,-3,174)
Block(0,31,-2,174)
Block(0,31,-1,174)
Block(0,31,0,174)
Block(0,31,1,174)
Block(0,31,2,174)
Block(0,31,3,174)
Block(0,31,4,174)
Block(0,31,5,174)
Block(0,31,6,174)
Block(0,31,7,174)
Block(0,31,8,174)
Block(0,32,-7,174)
Block(0,32,-6,174)
Block(0,32,-5,174)
Block(0,32,-4,174)
Block(0,32,-3,174)
Block(0,32,-2,174)
Block(0,32,-1,174)
Block(0,32,0,174)
Block(0,32,1,174)
Block(0,32,2,174)
Block(0,32,3,174)
Block(0,32,4,174)
Block(0,32,5,174)
Block(0,32,6,174)
Block(0,32,7,174)
Block(0,32,8,174)
Block(0,33,-7,174)
Block(0,33,-6,174)
Block(0,33,-5,174)
Block(0,33,-4,174)
Block(0,33,-3,174)
Block(0,33,-2,174)
Block(0,33,-1,174)
Block(0,33,0,174)
Block(0,33,1,174)
Block(0,33,2,174)
Block(0,33,3,174)
Block(0,33,4,174)
Block(0,33,5,174)
Block(0,33,6,174)
Block(0,33,7,174)
Block(0,33,8,174)
Block(0,34,-7,174)
Block(0,34,-6,174)
Block(0,34,-5,174)
Block(0,34,-4,174)
Block(0,34,-3,174)
Block(0,34,-2,174)
Block(0,34,-1,174)
Block(0,34,0,174)
Block(0,34,1,174)
Block(0,34,2,174)
Block(0,34,3,174)
Block(0,34,4,174)
Block(0,34,5,174)
Block(0,34,6,174)
Block(0,34,7,174)
Block(0,34,8,174)
Block(0,35,-7,174)
Block(0,35,-6,174)
Block(0,35,-5,174)
Block(0,35,-4,174)
Block(0,35,-3,174)
Block(0,35,-2,174)
Block(0,35,-1,174)
Block(0,35,0,174)
Block(0,35,1,174)
Block(0,35,2,174)
Block(0,35,3,174)
Block(0,35,4,174)
Block(0,35,5,174)
Block(0,35,6,174)
Block(0,35,7,174)
Block(0,35,8,174)
Block(0,36,-7,174)
Block(0,36,-6,174)
Block(0,36,-5,174)
Block(0,36,-4,174)
Block(0,36,-3,174)
Block(0,36,-2,174)
Block(0,36,-1,174)
Block(0,36,0,174)
Block(0,36,1,174)
Block(0,36,2,174)
Block(0,36,3,174)
Block(0,36,4,174)
Block(0,36,5,174)
Block(0,36,6,174)
Block(0,36,7,174)
Block(0,36,8,174)
Block(0,37,-7,174)
Block(0,37,-6,174)
Block(0,37,-5,174)
Block(0,37,-4,174)
Block(0,37,-3,174)
Block(0,37,-2,174)
Block(0,37,-1,174)
Block(0,37,0,174)
Block(0,37,1,174)
Block(0,37,2,174)
Block(0,37,3,174)
Block(0,37,4,174)
Block(0,37,5,174)
Block(0,37,6,174)
Block(0,37,7,174)
Block(0,37,8,174)
Block(0,38,-7,174)
Block(0,38,-6,174)
Block(0,38,-5,174)
Block(0,38,-4,174)
Block(0,38,-3,174)
Block(0,38,-2,174)
Block(0,38,-1,174)
Block(0,38,0,174)
Block(0,38,1,174)
Block(0,38,2,174)
Block(0,38,3,174)
Block(0,38,4,174)
Block(0,38,5,174)
Block(0,38,6,174)
Block(0,38,7,174)
Block(0,38,8,174)
Block(0,39,-7,174)
Block(0,39,-6,174)
Block(0,39,-5,174)
Block(0,39,-4,174)
Block(0,39,-3,174)
Block(0,39,-2,174)
Block(0,39,-1,174)
Block(0,39,0,174)
Block(0,39,1,174)
Block(0,39,2,174)
Block(0,39,3,174)
Block(0,39,4,174)
Block(0,39,5,174)
Block(0,39,6,174)
Block(0,39,7,174)
Block(0,39,8,174)
Block(0,40,-7,174)
Block(0,40,-6,174)
Block(0,40,-5,174)
Block(0,40,-4,174)
Block(0,40,-3,174)
Block(0,40,-2,174)
Block(0,40,-1,174)
Block(0,40,0,174)
Block(0,40,1,174)
Block(0,40,2,174)
Block(0,40,3,174)
Block(0,40,4,174)
Block(0,40,5,174)
Block(0,40,6,174)
Block(0,40,7,174)
Block(0,40,8,174)
Block(0,41,-7,174)
Block(0,41,-6,174)
Block(0,41,-5,174)
Block(0,41,-4,174)
Block(0,41,-3,174)
Block(0,41,-2,174)
Block(0,41,-1,174)
Block(0,41,0,174)
Block(0,41,1,174)
Block(0,41,2,174)
Block(0,41,3,174)
Block(0,41,4,174)
Block(0,41,5,174)
Block(0,41,6,174)
Block(0,41,7,174)
Block(0,41,8,174)
Block(0,42,-7,174)
Block(0,42,-6,174)
Block(0,42,-5,174)
Block(0,42,-4,174)
Block(0,42,-3,174)
Block(0,42,-2,174)
Block(0,42,-1,174)
Block(0,42,0,174)
Block(0,42,1,174)
Block(0,42,2,174)
Block(0,42,3,174)
Block(0,42,4,174)
Block(0,42,5,174)
Block(0,42,6,174)
Block(0,42,7,174)
Block(0,42,8,174)
Block(0,43,-7,174)
Block(0,43,-6,174)
Block(0,43,-5,174)
Block(0,43,-4,174)
Block(0,43,-3,174)
Block(0,43,-2,174)
Block(0,43,-1,174)
Block(0,43,0,174)
Block(0,43,1,174)
Block(0,43,2,174)
Block(0,43,3,174)
Block(0,43,4,174)
Block(0,43,5,174)
Block(0,43,6,174)
Block(0,43,7,174)
Block(0,43,8,174)
Block(0,44,-7,174)
Block(0,44,-6,174)
Block(0,44,-5,174)
Block(0,44,-4,174)
Block(0,44,-3,174)
Block(0,44,-2,174)
Block(0,44,-1,174)
Block(0,44,0,174)
Block(0,44,1,174)
Block(0,44,2,174)
Block(0,44,3,174)
Block(0,44,4,174)
Block(0,44,5,174)
Block(0,44,6,174)
Block(0,44,7,174)
Block(0,44,8,174)
Block(0,45,-7,174)
Block(0,45,-6,174)
Block(0,45,-5,174)
Block(0,45,-4,174)
Block(0,45,-3,174)
Block(0,45,-2,174)
Block(0,45,-1,174)
Block(0,45,0,174)
Block(0,45,1,174)
Block(0,45,2,174)
Block(0,45,3,174)
Block(0,45,4,174)
Block(0,45,5,174)
Block(0,45,6,174)
Block(0,45,7,174)
Block(0,45,8,174)
Block(0,46,-7,174)
Block(0,46,-6,174)
Block(0,46,-5,174)
Block(0,46,-4,174)
Block(0,46,-3,174)
Block(0,46,-2,174)
Block(0,46,-1,174)
Block(0,46,0,174)
Block(0,46,1,174)
Block(0,46,2,174)
Block(0,46,3,174)
Block(0,46,4,174)
Block(0,46,5,174)
Block(0,46,6,174)
Block(0,46,7,174)
Block(0,46,8,174)
Block(0,47,-7,174)
Block(0,47,-6,174)
Block(0,47,-5,174)
Block(0,47,-4,174)
Block(0,47,-3,174)
Block(0,47,-2,174)
Block(0,47,-1,174)
Block(0,47,0,174)
Block(0,47,1,174)
Block(0,47,2,174)
Block(0,47,3,174)
Block(0,47,4,174)
Block(0,47,5,174)
Block(0,47,6,174)
Block(0,47,7,174)
Block(0,47,8,174)
Block(0,48,-7,174)
Block(0,48,-6,174)
Block(0,48,-5,174)
Block(0,48,-4,174)
Block(0,48,-3,174)
Block(0,48,-2,174)
Block(0,48,-1,174)
Block(0,48,0,174)
Block(0,48,1,174)
Block(0,48,2,174)
Block(0,48,3,174)
Block(0,48,4,174)
Block(0,48,5,174)
Block(0,48,6,174)
Block(0,48,7,174)
Block(0,48,8,174)
Block(0,49,-7,174)
Block(0,49,-6,174)
Block(0,49,-5,174)
Block(0,49,-4,174)
Block(0,49,-3,174)
Block(0,49,-2,174)
Block(0,49,-1,174)
Block(0,49,0,174)
Block(0,49,1,174)
Block(0,49,2,174)
Block(0,49,3,174)
Block(0,49,4,174)
Block(0,49,5,174)
Block(0,49,6,174)
Block(0,49,7,174)
Block(0,49,8,174)
Block(0,50,-7,174)
Block(0,50,-6,174)
Block(0,50,-5,174)
Block(0,50,-4,174)
Block(0,50,-3,174)
Block(0,50,-2,174)
Block(0,50,-1,174)
Block(0,50,0,174)
Block(0,50,1,174)
Block(0,50,2,174)
Block(0,50,3,174)
Block(0,50,4,174)
Block(0,50,5,174)
Block(0,50,6,174)
Block(0,50,7,174)
Block(0,50,8,174)
Block(0,51,-7,174)
Block(0,51,-6,174)
Block(0,51,-5,174)
Block(0,51,-4,174)
Block(0,51,-3,174)
Block(0,51,-2,174)
Block(0,51,-1,174)
Block(0,51,0,174)
Block(0,51,1,174)
Block(0,51,2,174)
Block(0,51,3,174)
Block(0,51,4,174)
Block(0,51,5,174)
Block(0,51,6,174)
Block(0,51,7,174)
Block(0,51,8,174)
Block(0,52,-7,174)
Block(0,52,-6,174)
Block(0,52,-5,174)
Block(0,52,-4,174)
Block(0,52,-3,174)
Block(0,52,-2,174)
Block(0,52,-1,174)
Block(0,52,0,174)
Block(0,52,1,174)
Block(0,52,2,174)
Block(0,52,3,174)
Block(0,52,4,174)
Block(0,52,5,174)
Block(0,52,6,174)
Block(0,52,7,174)
Block(0,52,8,174)
Block(0,53,-7,174)
Block(0,53,-6,174)
Block(0,53,-5,174)
Block(0,53,-4,174)
Block(0,53,-3,174)
Block(0,53,-2,174)
Block(0,53,-1,174)
Block(0,53,0,174)
Block(0,53,1,174)
Block(0,53,2,174)
Block(0,53,3,174)
Block(0,53,4,174)
Block(0,53,5,174)
Block(0,53,6,174)
Block(0,53,7,174)
Block(0,53,8,174)
Block(0,54,-6,174)
Block(0,54,-5,174)
Block(0,54,-4,174)
Block(0,54,-3,174)
Block(0,54,-2,174)
Block(0,54,-1,174)
Block(0,54,0,174)
Block(0,54,1,174)
Block(0,54,2,174)
Block(0,54,3,174)
Block(0,54,4,174)
Block(0,54,5,174)
Block(0,54,6,174)
Block(0,54,7,174)
Block(0,54,8,174)
Block(0,55,-6,174)
Block(0,55,-5,174)
Block(0,55,-4,174)
Block(0,55,-3,174)
Block(0,55,-2,174)
Block(0,55,-1,174)
Block(0,55,0,174)
Block(0,55,1,174)
Block(0,55,2,174)
Block(0,55,3,174)
Block(0,55,4,174)
Block(0,55,5,174)
Block(0,55,6,174)
Block(0,55,7,174)
Block(0,55,8,174)
Block(0,56,-5,174)
Block(0,56,-4,174)
Block(0,56,-3,174)
Block(0,56,-2,174)
Block(0,56,-1,174)
Block(0,56,0,174)
Block(0,56,1,174)
Block(0,56,2,174)
Block(0,56,3,174)
Block(0,56,4,174)
Block(0,56,5,174)
Block(0,56,6,174)
Block(0,56,7,174)
Block(0,56,8,174)
Block(0,57,-5,174)
Block(0,57,-4,174)
Block(0,57,-3,174)
Block(0,57,-2,174)
Block(0,57,-1,174)
Block(0,57,0,174)
Block(0,57,1,174)
Block(0,57,2,174)
Block(0,57,3,174)
Block(0,57,4,174)
Block(0,57,5,174)
Block(0,57,6,174)
Block(0,57,7,174)
Block(0,57,8,174)
Block(0,58,-3,174)
Block(0,58,-2,174)
Block(0,58,-1,174)
Block(0,58,0,174)
Block(0,58,1,174)
Block(0,58,2,174)
Block(0,58,3,174)
Block(0,58,4,174)
Block(0,58,5,174)
Block(0,58,6,174)
Block(0,58,7,174)
Block(0,58,8,174)
Block(0,59,-2,174)
Block(0,59,-1,174)
Block(0,59,0,174)
Block(0,59,1,174)
Block(0,59,2,174)
Block(0,59,3,174)
Block(0,59,4,174)
Block(0,59,5,174)
Block(0,59,6,174)
Block(0,59,7,174)
Block(0,59,8,174)
Block(0,60,-1,174)
Block(0,60,0,174)
Block(0,60,1,174)
Block(0,60,2,174)
Block(0,60,3,174)
Block(0,60,4,174)
Block(0,60,5,174)
Block(0,60,6,174)
Block(0,60,7,174)
Block(0,60,8,174)
Block(0,61,0,174)
Block(0,61,1,174)
Block(0,61,2,174)
Block(0,61,3,174)
Block(0,61,4,174)
Block(0,61,5,174)
Block(0,61,6,174)
Block(0,61,7,174)
Block(0,61,8,174)
Block(0,62,0,174)
Block(0,62,1,174)
Block(0,62,2,174)
Block(0,62,3,174)
Block(0,62,4,174)
Block(0,62,5,174)
Block(0,62,6,174)
Block(0,62,7,174)
Block(0,62,8,174)
Block(0,63,2,174)
Block(0,63,3,174)
Block(0,63,4,174)
Block(0,63,5,174)
Block(0,63,6,174)
Block(0,63,7,174)
Block(0,63,8,174)
Block(0,64,4,174)
Block(0,64,5,174)
Block(0,64,6,174)
Block(0,64,7,174)
Block(0,64,8,174)
Block(0,65,5,174)
Block(0,65,6,174)
Block(0,65,7,174)
Block(0,65,8,174)
Block(0,66,6,174)
Block(0,66,7,174)
Block(0,66,8,174)
Block(1,14,6,174)
Block(1,14,7,174)
Block(1,14,8,174)
Block(1,15,5,174)
Block(1,15,6,174)
Block(1,15,7,174)
Block(1,15,8,174)
Block(1,16,5,174)
Block(1,16,6,174)
Block(1,16,7,174)
Block(1,16,8,174)
Block(1,17,3,174)
Block(1,17,4,174)
Block(1,17,5,174)
Block(1,17,6,174)
Block(1,17,7,174)
Block(1,17,8,174)
Block(1,18,1,174)
Block(1,18,2,174)
Block(1,18,3,174)
Block(1,18,4,174)
Block(1,18,5,174)
Block(1,18,6,174)
Block(1,18,7,174)
Block(1,18,8,174)
Block(1,19,0,174)
Block(1,19,1,174)
Block(1,19,2,174)
Block(1,19,3,174)
Block(1,19,4,174)
Block(1,19,5,174)
Block(1,19,6,174)
Block(1,19,7,174)
Block(1,19,8,174)
Block(1,20,0,174)
Block(1,20,1,174)
Block(1,20,2,174)
Block(1,20,3,174)
Block(1,20,4,174)
Block(1,20,5,174)
Block(1,20,6,174)
Block(1,20,7,174)
Block(1,20,8,174)
Block(1,21,-2,174)
Block(1,21,-1,174)
Block(1,21,0,174)
Block(1,21,1,174)
Block(1,21,2,174)
Block(1,21,3,174)
Block(1,21,4,174)
Block(1,21,5,174)
Block(1,21,6,174)
Block(1,21,7,174)
Block(1,21,8,174)
Block(1,22,-3,174)
Block(1,22,-2,174)
Block(1,22,-1,174)
Block(1,22,0,174)
Block(1,22,1,174)
Block(1,22,2,174)
Block(1,22,3,174)
Block(1,22,4,174)
Block(1,22,5,174)
Block(1,22,6,174)
Block(1,22,7,174)
Block(1,22,8,174)
Block(1,23,-4,174)
Block(1,23,-3,174)
Block(1,23,-2,174)
Block(1,23,-1,174)
Block(1,23,0,174)
Block(1,23,1,174)
Block(1,23,2,174)
Block(1,23,3,174)
Block(1,23,4,174)
Block(1,23,5,174)
Block(1,23,6,174)
Block(1,23,7,174)
Block(1,23,8,174)
Block(1,24,-5,174)
Block(1,24,-4,174)
Block(1,24,-3,174)
Block(1,24,-2,174)
Block(1,24,-1,174)
Block(1,24,0,174)
Block(1,24,1,174)
Block(1,24,2,174)
Block(1,24,3,174)
Block(1,24,4,174)
Block(1,24,5,174)
Block(1,24,6,174)
Block(1,24,7,174)
Block(1,24,8,174)
Block(1,25,-6,174)
Block(1,25,-5,174)
Block(1,25,-4,174)
Block(1,25,-3,174)
Block(1,25,-2,174)
Block(1,25,-1,174)
Block(1,25,0,174)
Block(1,25,1,174)
Block(1,25,2,174)
Block(1,25,3,174)
Block(1,25,4,174)
Block(1,25,5,174)
Block(1,25,6,174)
Block(1,25,7,174)
Block(1,25,8,174)
Block(1,26,-6,174)
Block(1,26,-5,174)
Block(1,26,-4,174)
Block(1,26,-3,174)
Block(1,26,-2,174)
Block(1,26,-1,174)
Block(1,26,0,174)
Block(1,26,1,174)
Block(1,26,2,174)
Block(1,26,3,174)
Block(1,26,4,174)
Block(1,26,5,174)
Block(1,26,6,174)
Block(1,26,7,174)
Block(1,26,8,174)
Block(1,27,-7,174)
Block(1,27,-6,174)
Block(1,27,-5,174)
Block(1,27,-4,174)
Block(1,27,-3,174)
Block(1,27,-2,174)
Block(1,27,-1,174)
Block(1,27,0,174)
Block(1,27,1,174)
Block(1,27,2,174)
Block(1,27,3,174)
Block(1,27,4,174)
Block(1,27,5,174)
Block(1,27,6,174)
Block(1,27,7,174)
Block(1,27,8,174)
Block(1,28,-7,174)
Block(1,28,-6,174)
Block(1,28,-5,174)
Block(1,28,-4,174)
Block(1,28,-3,174)
Block(1,28,-2,174)
Block(1,28,-1,174)
Block(1,28,0,174)
Block(1,28,1,174)
Block(1,28,2,174)
Block(1,28,3,174)
Block(1,28,4,174)
Block(1,28,5,174)
Block(1,28,6,174)
Block(1,28,7,174)
Block(1,28,8,174)
Block(1,29,-7,174)
Block(1,29,-6,174)
Block(1,29,-5,174)
Block(1,29,-4,174)
Block(1,29,-3,174)
Block(1,29,-2,174)
Block(1,29,-1,174)
Block(1,29,0,174)
Block(1,29,1,174)
Block(1,29,2,174)
Block(1,29,3,174)
Block(1,29,4,174)
Block(1,29,5,174)
Block(1,29,6,174)
Block(1,29,7,174)
Block(1,29,8,174)
Block(1,30,-7,174)
Block(1,30,-6,174)
Block(1,30,-5,174)
Block(1,30,-4,174)
Block(1,30,-3,174)
Block(1,30,-2,174)
Block(1,30,-1,174)
Block(1,30,0,174)
Block(1,30,1,174)
Block(1,30,2,174)
Block(1,30,3,174)
Block(1,30,4,174)
Block(1,30,5,174)
Block(1,30,6,174)
Block(1,30,7,174)
Block(1,30,8,174)
Block(1,31,-7,174)
Block(1,31,-6,174)
Block(1,31,-5,174)
Block(1,31,-4,174)
Block(1,31,-3,174)
Block(1,31,-2,174)
Block(1,31,-1,174)
Block(1,31,0,174)
Block(1,31,1,174)
Block(1,31,2,174)
Block(1,31,3,174)
Block(1,31,4,174)
Block(1,31,5,174)
Block(1,31,6,174)
Block(1,31,7,174)
Block(1,31,8,174)
Block(1,32,-7,174)
Block(1,32,-6,174)
Block(1,32,-5,174)
Block(1,32,-4,174)
Block(1,32,-3,174)
Block(1,32,-2,174)
Block(1,32,-1,174)
Block(1,32,0,174)
Block(1,32,1,174)
Block(1,32,2,174)
Block(1,32,3,174)
Block(1,32,4,174)
Block(1,32,5,174)
Block(1,32,6,174)
Block(1,32,7,174)
Block(1,32,8,174)
Block(1,33,-7,174)
Block(1,33,-6,174)
Block(1,33,-5,174)
Block(1,33,-4,174)
Block(1,33,-3,174)
Block(1,33,-2,174)
Block(1,33,-1,174)
Block(1,33,0,174)
Block(1,33,1,174)
Block(1,33,2,174)
Block(1,33,3,174)
Block(1,33,4,174)
Block(1,33,5,174)
Block(1,33,6,174)
Block(1,33,7,174)
Block(1,33,8,174)
Block(1,34,-7,174)
Block(1,34,-6,174)
Block(1,34,-5,174)
Block(1,34,-4,174)
Block(1,34,-3,174)
Block(1,34,-2,174)
Block(1,34,-1,174)
Block(1,34,0,174)
Block(1,34,1,174)
Block(1,34,2,174)
Block(1,34,3,174)
Block(1,34,4,174)
Block(1,34,5,174)
Block(1,34,6,174)
Block(1,34,7,174)
Block(1,34,8,174)
Block(1,35,-7,174)
Block(1,35,-6,174)
Block(1,35,-5,174)
Block(1,35,-4,174)
Block(1,35,-3,174)
Block(1,35,-2,174)
Block(1,35,-1,174)
Block(1,35,0,174)
Block(1,35,1,174)
Block(1,35,2,174)
Block(1,35,3,174)
Block(1,35,4,174)
Block(1,35,5,174)
Block(1,35,6,174)
Block(1,35,7,174)
Block(1,35,8,174)
Block(1,36,-7,174)
Block(1,36,-6,174)
Block(1,36,-5,174)
Block(1,36,-4,174)
Block(1,36,-3,174)
Block(1,36,-2,174)
Block(1,36,-1,174)
Block(1,36,0,174)
Block(1,36,1,174)
Block(1,36,2,174)
Block(1,36,3,174)
Block(1,36,4,174)
Block(1,36,5,174)
Block(1,36,6,174)
Block(1,36,7,174)
Block(1,36,8,174)
Block(1,37,-7,174)
Block(1,37,-6,174)
Block(1,37,-5,174)
Block(1,37,-4,174)
Block(1,37,-3,174)
Block(1,37,-2,174)
Block(1,37,-1,174)
Block(1,37,0,174)
Block(1,37,1,174)
Block(1,37,2,174)
Block(1,37,3,174)
Block(1,37,4,174)
Block(1,37,5,174)
Block(1,37,6,174)
Block(1,37,7,174)
Block(1,37,8,174)
Block(1,38,-7,174)
Block(1,38,-6,174)
Block(1,38,-5,174)
Block(1,38,-4,174)
Block(1,38,-3,174)
Block(1,38,-2,174)
Block(1,38,-1,174)
Block(1,38,0,174)
Block(1,38,1,174)
Block(1,38,2,174)
Block(1,38,3,174)
Block(1,38,4,174)
Block(1,38,5,174)
Block(1,38,6,174)
Block(1,38,7,174)
Block(1,38,8,174)
Block(1,39,-7,174)
Block(1,39,-6,174)
Block(1,39,-5,174)
Block(1,39,-4,174)
Block(1,39,-3,174)
Block(1,39,-2,174)
Block(1,39,-1,174)
Block(1,39,0,174)
Block(1,39,1,174)
Block(1,39,2,174)
Block(1,39,3,174)
Block(1,39,4,174)
Block(1,39,5,174)
Block(1,39,6,174)
Block(1,39,7,174)
Block(1,39,8,174)
Block(1,40,-7,174)
Block(1,40,-6,174)
Block(1,40,-5,174)
Block(1,40,-4,174)
Block(1,40,-3,174)
Block(1,40,-2,174)
Block(1,40,-1,174)
Block(1,40,0,174)
Block(1,40,1,174)
Block(1,40,2,174)
Block(1,40,3,174)
Block(1,40,4,174)
Block(1,40,5,174)
Block(1,40,6,174)
Block(1,40,7,174)
Block(1,40,8,174)
Block(1,41,-7,174)
Block(1,41,-6,174)
Block(1,41,-5,174)
Block(1,41,-4,174)
Block(1,41,-3,174)
Block(1,41,-2,174)
Block(1,41,-1,174)
Block(1,41,0,174)
Block(1,41,1,174)
Block(1,41,2,174)
Block(1,41,3,174)
Block(1,41,4,174)
Block(1,41,5,174)
Block(1,41,6,174)
Block(1,41,7,174)
Block(1,41,8,174)
Block(1,42,-7,174)
Block(1,42,-6,174)
Block(1,42,-5,174)
Block(1,42,-4,174)
Block(1,42,-3,174)
Block(1,42,-2,174)
Block(1,42,-1,174)
Block(1,42,0,174)
Block(1,42,1,174)
Block(1,42,2,174)
Block(1,42,3,174)
Block(1,42,4,174)
Block(1,42,5,174)
Block(1,42,6,174)
Block(1,42,7,174)
Block(1,42,8,174)
Block(1,43,-7,174)
Block(1,43,-6,174)
Block(1,43,-5,174)
Block(1,43,-4,174)
Block(1,43,-3,174)
Block(1,43,-2,174)
Block(1,43,-1,174)
Block(1,43,0,174)
Block(1,43,1,174)
Block(1,43,2,174)
Block(1,43,3,174)
Block(1,43,4,174)
Block(1,43,5,174)
Block(1,43,6,174)
Block(1,43,7,174)
Block(1,43,8,174)
Block(1,44,-7,174)
Block(1,44,-6,174)
Block(1,44,-5,174)
Block(1,44,-4,174)
Block(1,44,-3,174)
Block(1,44,-2,174)
Block(1,44,-1,174)
Block(1,44,0,174)
Block(1,44,1,174)
Block(1,44,2,174)
Block(1,44,3,174)
Block(1,44,4,174)
Block(1,44,5,174)
Block(1,44,6,174)
Block(1,44,7,174)
Block(1,44,8,174)
Block(1,45,-7,174)
Block(1,45,-6,174)
Block(1,45,-5,174)
Block(1,45,-4,174)
Block(1,45,-3,174)
Block(1,45,-2,174)
Block(1,45,-1,174)
Block(1,45,0,174)
Block(1,45,1,174)
Block(1,45,2,174)
Block(1,45,3,174)
Block(1,45,4,174)
Block(1,45,5,174)
Block(1,45,6,174)
Block(1,45,7,174)
Block(1,45,8,174)
Block(1,46,-7,174)
Block(1,46,-6,174)
Block(1,46,-5,174)
Block(1,46,-4,174)
Block(1,46,-3,174)
Block(1,46,-2,174)
Block(1,46,-1,174)
Block(1,46,0,174)
Block(1,46,1,174)
Block(1,46,2,174)
Block(1,46,3,174)
Block(1,46,4,174)
Block(1,46,5,174)
Block(1,46,6,174)
Block(1,46,7,174)
Block(1,46,8,174)
