#######################################################################
# +-----------------------------------------------------------------+ #
# |                            BO3 object                           | #
# +-----------------------------------------------------------------+ #
#######################################################################

# The descriptions in this file are true only for TerrainControl. They are not true for the Minecraft Worlds mod!
# Minecraft Worlds completely reimplemented BO3s, check the MCW documentation on the mc/mctcp forums for how to use BO3s with MCW
# or watch the video's on my YT channel at https://www.youtube.com/user/PeeGee85. You can check out the "Editing and importing schematics & BO3s" 
# series of video's, in part 2 I explain BO3s. 

# This is the config file of a custom object.
# If you add this object correctly to your BiomeConfigs, it will spawn in the world.

# This is the creator of this BO3 object
Author: Unknown

# A short description of this BO3 object
Description: This BO3 was converted from a schematic using the MineCraft Worlds Editor. Unfortunately the author and description information for the schematic could not be found. If you know who the author of the schematic is then please tell the author of this BO3!

# The BO3 version, don't change this! It can be used by external applications to do a version check.
Version: 3

# The settings mode, WriteAll, WriteWithoutComments or WriteDisable. See WorldConfig.
SettingsMode: WriteDisable

#######################################################################
# +-----------------------------------------------------------------+ #
# |                          Main settings                          | #
# +-----------------------------------------------------------------+ #
#######################################################################

# This needs to be set to true to spawn the object in the Tree and Sapling resources.
Tree: false

# The frequency of the BO3 from 1 to 200. Tries this many times to spawn this BO3 when using the CustomObject(...) resource.
# Ignored by Tree(..), Sapling(..) and CustomStructure(..)
Frequency: 40

# The rarity of the BO3 from 0 to 100. Each spawn attempt has rarity% chance to succeed when using the CustomObject(...) resource.
# Ignored by Tree(..), Sapling(..) and CustomStructure(..)
Rarity: 100.0

# If you set this to true, the BO3 will be placed with a random rotation.
RotateRandomly: false

# The spawn height of the BO3 - randomY, highestBlock or highestSolidBlock.
SpawnHeight: randomY

# The height limits for the BO3.
MinHeight: 28

MaxHeight: 32

# Objects can have other objects attached to it: branches. Branches can also
# have branches attached to it, which can also have branches, etc. This is the
# maximum branch depth for this objects.
MaxBranchDepth: 10

# When spawned with the UseWorld keyword, this BO3 should NOT spawn in the following biomes.
# If you writer.write the BO3 name directly in the BiomeConfigs, this will be ignored.
ExcludedBiomes: All

#######################################################################
# +-----------------------------------------------------------------+ #
# |                      Source block settings                      | #
# +-----------------------------------------------------------------+ #
#######################################################################

# The block(s) the BO3 should spawn in.
SourceBlocks: AIR

# The maximum percentage of the BO3 that can be outside the SourceBlock.
# The BO3 won't be placed on a location with more blocks outside the SourceBlock than this percentage.
MaxPercentageOutsideSourceBlock: 100

# What to do when a block is about to be placed outside the SourceBlock? (dontPlace, placeAnyway)
OutsideSourceBlock: placeAnyway

#######################################################################
# +-----------------------------------------------------------------+ #
# |                              Blocks                             | #
# +-----------------------------------------------------------------+ #
#######################################################################

# All the blocks used in the BO3 are listed here. Possible blocks:
# Block(x,y,z,id[.data][,nbtfile.nbt)
# RandomBlock(x,y,z,id[:data][,nbtfile.nbt],chance[,id[:data][,nbtfile.nbt],chance[,...]])
# So RandomBlock(0,0,0,CHEST,chest.nbt,50,CHEST,anotherchest.nbt,100) will spawn a chest at
# the BO3 origin, and give it a 50% chance to have the contents of chest.nbt, or, if that
# fails, a 100% percent chance to have the contents of anotherchest.nbt.

Block(-8,11,7,174)
Block(-8,11,8,174)
Block(-8,12,6,174)
Block(-8,12,7,174)
Block(-8,12,8,174)
Block(-8,13,4,174)
Block(-8,13,5,174)
Block(-8,13,6,174)
Block(-8,13,7,174)
Block(-8,13,8,174)
Block(-8,14,2,174)
Block(-8,14,3,174)
Block(-8,14,4,174)
Block(-8,14,5,174)
Block(-8,14,6,174)
Block(-8,14,7,174)
Block(-8,14,8,174)
Block(-8,15,0,174)
Block(-8,15,1,174)
Block(-8,15,2,174)
Block(-8,15,3,174)
Block(-8,15,4,174)
Block(-8,15,5,174)
Block(-8,15,6,174)
Block(-8,15,7,174)
Block(-8,15,8,174)
Block(-8,16,-2,174)
Block(-8,16,-1,174)
Block(-8,16,0,174)
Block(-8,16,1,174)
Block(-8,16,2,174)
Block(-8,16,3,174)
Block(-8,16,4,174)
Block(-8,16,5,174)
Block(-8,16,6,174)
Block(-8,16,7,174)
Block(-8,16,8,174)
Block(-8,17,-3,174)
Block(-8,17,-2,174)
Block(-8,17,-1,174)
Block(-8,17,0,174)
Block(-8,17,1,174)
Block(-8,17,2,174)
Block(-8,17,3,174)
Block(-8,17,4,174)
Block(-8,17,5,174)
Block(-8,17,6,174)
Block(-8,17,7,174)
Block(-8,17,8,174)
Block(-8,18,-4,174)
Block(-8,18,-3,174)
Block(-8,18,-2,174)
Block(-8,18,-1,174)
Block(-8,18,0,174)
Block(-8,18,1,174)
Block(-8,18,2,174)
Block(-8,18,3,174)
Block(-8,18,4,174)
Block(-8,18,5,174)
Block(-8,18,6,174)
Block(-8,18,7,174)
Block(-8,18,8,174)
Block(-8,19,-5,174)
Block(-8,19,-4,174)
Block(-8,19,-3,174)
Block(-8,19,-2,174)
Block(-8,19,-1,174)
Block(-8,19,0,174)
Block(-8,19,1,174)
Block(-8,19,2,174)
Block(-8,19,3,174)
Block(-8,19,4,174)
Block(-8,19,5,174)
Block(-8,19,6,174)
Block(-8,19,7,174)
Block(-8,19,8,174)
Block(-8,20,-5,174)
Block(-8,20,-4,174)
Block(-8,20,-3,174)
Block(-8,20,-2,174)
Block(-8,20,-1,174)
Block(-8,20,0,174)
Block(-8,20,1,174)
Block(-8,20,2,174)
Block(-8,20,3,174)
Block(-8,20,4,174)
Block(-8,20,5,174)
Block(-8,20,6,174)
Block(-8,20,7,174)
Block(-8,20,8,174)
Block(-8,21,-7,174)
Block(-8,21,-6,174)
Block(-8,21,-5,174)
Block(-8,21,-4,174)
Block(-8,21,-3,174)
Block(-8,21,-2,174)
Block(-8,21,-1,174)
Block(-8,21,0,174)
Block(-8,21,1,174)
Block(-8,21,2,174)
Block(-8,21,3,174)
Block(-8,21,4,174)
Block(-8,21,5,174)
Block(-8,21,6,174)
Block(-8,21,7,174)
Block(-8,21,8,174)
Block(-8,22,-7,174)
Block(-8,22,-6,174)
Block(-8,22,-5,174)
Block(-8,22,-4,174)
Block(-8,22,-3,174)
Block(-8,22,-2,174)
Block(-8,22,-1,174)
Block(-8,22,0,174)
Block(-8,22,1,174)
Block(-8,22,2,174)
Block(-8,22,3,174)
Block(-8,22,4,174)
Block(-8,22,5,174)
Block(-8,22,6,174)
Block(-8,22,7,174)
Block(-8,22,8,174)
Block(-8,23,-7,174)
Block(-8,23,-6,174)
Block(-8,23,-5,174)
Block(-8,23,-4,174)
Block(-8,23,-3,174)
Block(-8,23,-2,174)
Block(-8,23,-1,174)
Block(-8,23,0,174)
Block(-8,23,1,174)
Block(-8,23,2,174)
Block(-8,23,3,174)
Block(-8,23,4,174)
Block(-8,23,5,174)
Block(-8,23,6,174)
Block(-8,23,7,174)
Block(-8,23,8,174)
Block(-8,24,-7,174)
Block(-8,24,-6,174)
Block(-8,24,-5,174)
Block(-8,24,-4,174)
Block(-8,24,-3,174)
Block(-8,24,-2,174)
Block(-8,24,-1,174)
Block(-8,24,0,174)
Block(-8,24,1,174)
Block(-8,24,2,174)
Block(-8,24,3,174)
Block(-8,24,4,174)
Block(-8,24,5,174)
Block(-8,24,6,174)
Block(-8,24,7,174)
Block(-8,24,8,174)
Block(-8,25,-7,174)
Block(-8,25,-6,174)
Block(-8,25,-5,174)
Block(-8,25,-4,174)
Block(-8,25,-3,174)
Block(-8,25,-2,174)
Block(-8,25,-1,174)
Block(-8,25,0,174)
Block(-8,25,1,174)
Block(-8,25,2,174)
Block(-8,25,3,174)
Block(-8,25,4,174)
Block(-8,25,5,174)
Block(-8,25,6,174)
Block(-8,25,7,174)
Block(-8,26,-7,174)
Block(-8,26,-6,174)
Block(-8,26,-5,174)
Block(-8,26,-4,174)
Block(-8,26,-3,174)
Block(-8,26,-2,174)
Block(-8,26,-1,174)
Block(-8,26,0,174)
Block(-8,26,1,174)
Block(-8,26,2,174)
Block(-8,26,3,174)
Block(-8,26,4,174)
Block(-8,26,5,174)
Block(-8,26,6,174)
Block(-8,26,7,174)
Block(-8,27,-7,174)
Block(-8,27,-6,174)
Block(-8,27,-5,174)
Block(-8,27,-4,174)
Block(-8,27,-3,174)
Block(-8,27,-2,174)
Block(-8,27,-1,174)
Block(-8,27,0,174)
Block(-8,27,1,174)
Block(-8,27,2,174)
Block(-8,27,3,174)
Block(-8,27,4,174)
Block(-8,27,5,174)
Block(-8,27,6,174)
Block(-8,27,7,174)
Block(-8,28,-7,174)
Block(-8,28,-6,174)
Block(-8,28,-5,174)
Block(-8,28,-4,174)
Block(-8,28,-3,174)
Block(-8,28,-2,174)
Block(-8,28,-1,174)
Block(-8,28,0,174)
Block(-8,28,1,174)
Block(-8,28,2,174)
Block(-8,28,3,174)
Block(-8,28,4,174)
Block(-8,28,5,174)
Block(-8,28,6,174)
Block(-8,28,7,174)
Block(-8,28,8,174)
Block(-8,29,-7,174)
Block(-8,29,-6,174)
Block(-8,29,-5,174)
Block(-8,29,-4,174)
Block(-8,29,-3,174)
Block(-8,29,-2,174)
Block(-8,29,-1,174)
Block(-8,29,0,174)
Block(-8,29,1,174)
Block(-8,29,2,174)
Block(-8,29,3,174)
Block(-8,29,4,174)
Block(-8,29,5,174)
Block(-8,29,6,174)
Block(-8,29,7,174)
Block(-8,29,8,174)
Block(-8,30,-7,174)
Block(-8,30,-6,174)
Block(-8,30,-5,174)
Block(-8,30,-4,174)
Block(-8,30,-3,174)
Block(-8,30,-2,174)
Block(-8,30,-1,174)
Block(-8,30,0,174)
Block(-8,30,1,174)
Block(-8,30,2,174)
Block(-8,30,3,174)
Block(-8,30,4,174)
Block(-8,30,5,174)
Block(-8,30,6,174)
Block(-8,30,7,174)
Block(-8,30,8,174)
Block(-8,31,-7,174)
Block(-8,31,-6,174)
Block(-8,31,-5,174)
Block(-8,31,-4,174)
Block(-8,31,-3,174)
Block(-8,31,-2,174)
Block(-8,31,-1,174)
Block(-8,31,0,174)
Block(-8,31,1,174)
Block(-8,31,2,174)
Block(-8,31,3,174)
Block(-8,31,4,174)
Block(-8,31,5,174)
Block(-8,31,6,174)
Block(-8,31,7,174)
Block(-8,31,8,174)
Block(-8,32,-7,174)
Block(-8,32,-6,174)
Block(-8,32,-5,174)
Block(-8,32,-4,174)
Block(-8,32,-3,174)
Block(-8,32,-2,174)
Block(-8,32,-1,174)
Block(-8,32,0,174)
Block(-8,32,1,174)
Block(-8,32,2,174)
Block(-8,32,3,174)
Block(-8,32,4,174)
Block(-8,32,5,174)
Block(-8,32,6,174)
Block(-8,32,7,174)
Block(-8,32,8,174)
Block(-8,33,-7,174)
Block(-8,33,-6,174)
Block(-8,33,-5,174)
Block(-8,33,-4,174)
Block(-8,33,-3,174)
Block(-8,33,-2,174)
Block(-8,33,-1,174)
Block(-8,33,0,174)
Block(-8,33,1,174)
Block(-8,33,2,174)
Block(-8,33,3,174)
Block(-8,33,4,174)
Block(-8,33,5,174)
Block(-8,33,6,174)
Block(-8,33,7,174)
Block(-8,33,8,174)
Block(-8,34,-7,174)
Block(-8,34,-6,174)
Block(-8,34,-5,174)
Block(-8,34,-4,174)
Block(-8,34,-3,174)
Block(-8,34,-2,174)
Block(-8,34,-1,174)
Block(-8,34,0,174)
Block(-8,34,1,174)
Block(-8,34,2,174)
Block(-8,34,3,174)
Block(-8,34,4,174)
Block(-8,34,5,174)
Block(-8,34,6,174)
Block(-8,34,7,174)
Block(-8,34,8,174)
Block(-8,35,-7,174)
Block(-8,35,-6,174)
Block(-8,35,-5,174)
Block(-8,35,-4,174)
Block(-8,35,-3,174)
Block(-8,35,-2,174)
Block(-8,35,-1,174)
Block(-8,35,0,174)
Block(-8,35,1,174)
Block(-8,35,2,174)
Block(-8,35,3,174)
Block(-8,35,4,174)
Block(-8,35,5,174)
Block(-8,35,6,174)
Block(-8,35,7,174)
Block(-8,35,8,174)
Block(-8,36,-7,174)
Block(-8,36,-6,174)
Block(-8,36,-5,174)
Block(-8,36,-4,174)
Block(-8,36,-3,174)
Block(-8,36,-2,174)
Block(-8,36,-1,174)
Block(-8,36,0,174)
Block(-8,36,1,174)
Block(-8,36,2,174)
Block(-8,36,3,174)
Block(-8,36,4,174)
Block(-8,36,5,174)
Block(-8,36,6,174)
Block(-8,36,7,174)
Block(-8,36,8,174)
Block(-8,37,-7,174)
Block(-8,37,-6,174)
Block(-8,37,-5,174)
Block(-8,37,-4,174)
Block(-8,37,-3,174)
Block(-8,37,-2,174)
Block(-8,37,-1,174)
Block(-8,37,0,174)
Block(-8,37,1,174)
Block(-8,37,2,174)
Block(-8,37,3,174)
Block(-8,37,4,174)
Block(-8,37,5,174)
Block(-8,37,6,174)
Block(-8,37,7,174)
Block(-8,37,8,174)
Block(-8,38,-7,174)
Block(-8,38,-6,174)
Block(-8,38,-5,174)
Block(-8,38,-4,174)
Block(-8,38,-3,174)
Block(-8,38,-2,174)
Block(-8,38,-1,174)
Block(-8,38,0,174)
Block(-8,38,1,174)
Block(-8,38,2,174)
Block(-8,38,3,174)
Block(-8,38,4,174)
Block(-8,38,5,174)
Block(-8,38,6,174)
Block(-8,38,7,174)
Block(-8,38,8,174)
Block(-8,39,-7,174)
Block(-8,39,-6,174)
Block(-8,39,-5,174)
Block(-8,39,-4,174)
Block(-8,39,-3,174)
Block(-8,39,-2,174)
Block(-8,39,-1,174)
Block(-8,39,0,174)
Block(-8,39,1,174)
Block(-8,39,2,174)
Block(-8,39,3,174)
Block(-8,39,4,174)
Block(-8,39,5,174)
Block(-8,39,6,174)
Block(-8,39,7,174)
Block(-8,39,8,174)
Block(-8,40,-7,174)
Block(-8,40,-6,174)
Block(-8,40,-5,174)
Block(-8,40,-4,174)
Block(-8,40,-3,174)
Block(-8,40,-2,174)
Block(-8,40,-1,174)
Block(-8,40,0,174)
Block(-8,40,1,174)
Block(-8,40,2,174)
Block(-8,40,3,174)
Block(-8,40,4,174)
Block(-8,40,5,174)
Block(-8,40,6,174)
Block(-8,40,7,174)
Block(-8,40,8,174)
Block(-8,41,-7,174)
Block(-8,41,-6,174)
Block(-8,41,-5,174)
Block(-8,41,-4,174)
Block(-8,41,-3,174)
Block(-8,41,-2,174)
Block(-8,41,-1,174)
Block(-8,41,0,174)
Block(-8,41,1,174)
Block(-8,41,2,174)
Block(-8,41,3,174)
Block(-8,41,4,174)
Block(-8,41,5,174)
Block(-8,41,6,174)
Block(-8,41,7,174)
Block(-8,41,8,174)
Block(-8,42,-7,174)
Block(-8,42,-6,174)
Block(-8,42,-5,174)
Block(-8,42,-4,174)
Block(-8,42,-3,174)
Block(-8,42,-2,174)
Block(-8,42,-1,174)
Block(-8,42,0,174)
Block(-8,42,1,174)
Block(-8,42,2,174)
Block(-8,42,3,174)
Block(-8,42,4,174)
Block(-8,42,5,174)
Block(-8,42,6,174)
Block(-8,42,7,174)
Block(-8,42,8,174)
Block(-8,43,-7,174)
Block(-8,43,-6,174)
Block(-8,43,-5,174)
Block(-8,43,-4,174)
Block(-8,43,-3,174)
Block(-8,43,-2,174)
Block(-8,43,-1,174)
Block(-8,43,0,174)
Block(-8,43,1,174)
Block(-8,43,2,174)
Block(-8,43,3,174)
Block(-8,43,4,174)
Block(-8,43,5,174)
Block(-8,43,6,174)
Block(-8,43,7,174)
Block(-8,43,8,174)
Block(-8,44,-7,174)
Block(-8,44,-6,174)
Block(-8,44,-5,174)
Block(-8,44,-4,174)
Block(-8,44,-3,174)
Block(-8,44,-2,174)
Block(-8,44,-1,174)
Block(-8,44,0,174)
Block(-8,44,1,174)
Block(-8,44,2,174)
Block(-8,44,3,174)
Block(-8,44,4,174)
Block(-8,44,5,174)
Block(-8,44,6,174)
Block(-8,44,7,174)
Block(-8,44,8,174)
Block(-8,45,-7,174)
Block(-8,45,-6,174)
Block(-8,45,-5,174)
Block(-8,45,-4,174)
Block(-8,45,-3,174)
Block(-8,45,-2,174)
Block(-8,45,-1,174)
Block(-8,45,0,174)
Block(-8,45,1,174)
Block(-8,45,2,174)
Block(-8,45,3,174)
Block(-8,45,4,174)
Block(-8,45,5,174)
Block(-8,45,6,174)
Block(-8,45,7,174)
Block(-8,45,8,174)
Block(-8,46,-7,174)
Block(-8,46,-6,174)
Block(-8,46,-5,174)
Block(-8,46,-4,174)
Block(-8,46,-3,174)
Block(-8,46,-2,174)
Block(-8,46,-1,174)
Block(-8,46,0,174)
Block(-8,46,1,174)
Block(-8,46,2,174)
Block(-8,46,3,174)
Block(-8,46,4,174)
Block(-8,46,5,174)
Block(-8,46,6,174)
Block(-8,46,7,174)
Block(-8,46,8,174)
Block(-8,47,-7,174)
Block(-8,47,-6,174)
Block(-8,47,-5,174)
Block(-8,47,-4,174)
Block(-8,47,-3,174)
Block(-8,47,-2,174)
Block(-8,47,-1,174)
Block(-8,47,0,174)
Block(-8,47,1,174)
Block(-8,47,2,174)
Block(-8,47,3,174)
Block(-8,47,4,174)
Block(-8,47,5,174)
Block(-8,47,6,174)
Block(-8,47,7,174)
Block(-8,47,8,174)
Block(-8,48,-7,174)
Block(-8,48,-6,174)
Block(-8,48,-5,174)
Block(-8,48,-4,174)
Block(-8,48,-3,174)
Block(-8,48,-2,174)
Block(-8,48,-1,174)
Block(-8,48,0,174)
Block(-8,48,1,174)
Block(-8,48,2,174)
Block(-8,48,3,174)
Block(-8,48,4,174)
Block(-8,48,5,174)
Block(-8,48,6,174)
Block(-8,48,7,174)
Block(-8,48,8,174)
Block(-8,49,-7,174)
Block(-8,49,-6,174)
Block(-8,49,-5,174)
Block(-8,49,-4,174)
Block(-8,49,-3,174)
Block(-8,49,-2,174)
Block(-8,49,-1,174)
Block(-8,49,0,174)
Block(-8,49,1,174)
Block(-8,49,2,174)
Block(-8,49,3,174)
Block(-8,49,4,174)
Block(-8,49,5,174)
Block(-8,49,6,174)
Block(-8,49,7,174)
Block(-8,49,8,174)
Block(-8,50,-7,174)
Block(-8,50,-6,174)
Block(-8,50,-5,174)
Block(-8,50,-4,174)
Block(-8,50,-3,174)
Block(-8,50,-2,174)
Block(-8,50,-1,174)
Block(-8,50,0,174)
Block(-8,50,1,174)
Block(-8,50,2,174)
Block(-8,50,3,174)
Block(-8,50,4,174)
Block(-8,50,5,174)
Block(-8,50,6,174)
Block(-8,50,7,174)
Block(-8,50,8,174)
Block(-8,51,-7,174)
Block(-8,51,-6,174)
Block(-8,51,-5,174)
Block(-8,51,-4,174)
Block(-8,51,-3,174)
Block(-8,51,-2,174)
Block(-8,51,-1,174)
Block(-8,51,0,174)
Block(-8,51,1,174)
Block(-8,51,2,174)
Block(-8,51,3,174)
Block(-8,51,4,174)
Block(-8,51,5,174)
Block(-8,51,6,174)
Block(-8,51,7,174)
Block(-8,51,8,174)
Block(-8,52,-7,174)
Block(-8,52,-6,174)
Block(-8,52,-5,174)
Block(-8,52,-4,174)
Block(-8,52,-3,174)
Block(-8,52,-2,174)
Block(-8,52,-1,174)
Block(-8,52,0,174)
Block(-8,52,1,174)
Block(-8,52,2,174)
Block(-8,52,3,174)
Block(-8,52,4,174)
Block(-8,52,5,174)
Block(-8,52,6,174)
Block(-8,52,7,174)
Block(-8,52,8,174)
Block(-8,53,-7,174)
Block(-8,53,-6,174)
Block(-8,53,-5,174)
Block(-8,53,-4,174)
Block(-8,53,-3,174)
Block(-8,53,-2,174)
Block(-8,53,-1,174)
Block(-8,53,0,174)
Block(-8,53,1,174)
Block(-8,53,2,174)
Block(-8,53,3,174)
Block(-8,53,4,174)
Block(-8,53,5,174)
Block(-8,53,6,174)
Block(-8,53,7,174)
Block(-8,53,8,174)
Block(-8,54,-7,174)
Block(-8,54,-6,174)
Block(-8,54,-5,174)
Block(-8,54,-4,174)
Block(-8,54,-3,174)
Block(-8,54,-2,174)
Block(-8,54,-1,174)
Block(-8,54,0,174)
Block(-8,54,1,174)
Block(-8,54,2,174)
Block(-8,54,3,174)
Block(-8,54,4,174)
Block(-8,54,5,174)
Block(-8,54,6,174)
Block(-8,54,7,174)
Block(-8,55,-7,174)
Block(-8,55,-6,174)
Block(-8,55,-5,174)
Block(-8,55,-4,174)
Block(-8,55,-3,174)
Block(-8,55,-2,174)
Block(-8,55,-1,174)
Block(-8,55,0,174)
Block(-8,55,1,174)
Block(-8,55,2,174)
Block(-8,55,3,174)
Block(-8,55,4,174)
Block(-8,55,5,174)
Block(-8,55,6,174)
Block(-8,56,-7,174)
Block(-8,56,-6,174)
Block(-8,56,-5,174)
Block(-8,56,-4,174)
Block(-8,56,-3,174)
Block(-8,56,-2,174)
Block(-8,56,-1,174)
Block(-8,56,0,174)
Block(-8,56,1,174)
Block(-8,56,2,174)
Block(-8,56,3,174)
Block(-8,56,4,174)
Block(-8,56,5,174)
Block(-8,56,6,174)
Block(-8,57,-7,174)
Block(-8,57,-6,174)
Block(-8,57,-5,174)
Block(-8,57,-4,174)
Block(-8,57,-3,174)
Block(-8,57,-2,174)
Block(-8,57,-1,174)
Block(-8,57,0,174)
Block(-8,57,1,174)
Block(-8,57,2,174)
Block(-8,57,3,174)
Block(-8,57,4,174)
Block(-8,57,5,174)
Block(-8,57,6,174)
Block(-8,57,7,174)
Block(-8,58,-7,174)
Block(-8,58,-6,174)
Block(-8,58,-5,174)
Block(-8,58,-4,174)
Block(-8,58,-3,174)
Block(-8,58,-2,174)
Block(-8,58,-1,174)
Block(-8,58,0,174)
Block(-8,58,1,174)
Block(-8,58,2,174)
Block(-8,58,3,174)
Block(-8,58,4,174)
Block(-8,58,5,174)
Block(-8,58,6,174)
Block(-8,58,7,174)
Block(-8,58,8,174)
Block(-8,59,-7,174)
Block(-8,59,-6,174)
Block(-8,59,-5,174)
Block(-8,59,-4,174)
Block(-8,59,-3,174)
Block(-8,59,-2,174)
Block(-8,59,-1,174)
Block(-8,59,0,174)
Block(-8,59,1,174)
Block(-8,59,2,174)
Block(-8,59,3,174)
Block(-8,59,4,174)
Block(-8,59,5,174)
Block(-8,59,6,174)
Block(-8,59,7,174)
Block(-8,59,8,174)
Block(-8,60,-7,174)
Block(-8,60,-6,174)
Block(-8,60,-5,174)
Block(-8,60,-4,174)
Block(-8,60,-3,174)
Block(-8,60,-2,174)
Block(-8,60,-1,174)
Block(-8,60,0,174)
Block(-8,60,1,174)
Block(-8,60,2,174)
Block(-8,60,3,174)
Block(-8,60,4,174)
Block(-8,60,5,174)
Block(-8,60,6,174)
Block(-8,60,7,174)
Block(-8,60,8,174)
Block(-8,61,-5,174)
Block(-8,61,-4,174)
Block(-8,61,-3,174)
Block(-8,61,-2,174)
Block(-8,61,-1,174)
Block(-8,61,0,174)
Block(-8,61,1,174)
Block(-8,61,2,174)
Block(-8,61,3,174)
Block(-8,61,4,174)
Block(-8,61,5,174)
Block(-8,61,6,174)
Block(-8,61,7,174)
Block(-8,61,8,174)
Block(-8,62,-5,174)
Block(-8,62,-4,174)
Block(-8,62,-3,174)
Block(-8,62,-2,174)
Block(-8,62,-1,174)
Block(-8,62,0,174)
Block(-8,62,1,174)
Block(-8,62,2,174)
Block(-8,62,3,174)
Block(-8,62,4,174)
Block(-8,62,5,174)
Block(-8,62,6,174)
Block(-8,62,7,174)
Block(-8,62,8,174)
Block(-8,63,-4,174)
Block(-8,63,-3,174)
Block(-8,63,-2,174)
Block(-8,63,-1,174)
Block(-8,63,0,174)
Block(-8,63,1,174)
Block(-8,63,2,174)
Block(-8,63,3,174)
Block(-8,63,4,174)
Block(-8,63,5,174)
Block(-8,63,6,174)
Block(-8,63,7,174)
Block(-8,63,8,174)
Block(-8,64,-3,174)
Block(-8,64,-2,174)
Block(-8,64,-1,174)
Block(-8,64,0,174)
Block(-8,64,1,174)
Block(-8,64,2,174)
Block(-8,64,3,174)
Block(-8,64,4,174)
Block(-8,64,5,174)
Block(-8,64,6,174)
Block(-8,64,7,174)
Block(-8,64,8,174)
Block(-8,65,-2,174)
Block(-8,65,-1,174)
Block(-8,65,0,174)
Block(-8,65,1,174)
Block(-8,65,2,174)
Block(-8,65,3,174)
Block(-8,65,4,174)
Block(-8,65,5,174)
Block(-8,65,6,174)
Block(-8,65,7,174)
Block(-8,65,8,174)
Block(-8,66,1,174)
Block(-8,66,2,174)
Block(-8,66,3,174)
Block(-8,66,4,174)
Block(-8,66,5,174)
Block(-8,66,6,174)
Block(-8,66,7,174)
Block(-8,66,8,174)
Block(-8,67,2,174)
Block(-8,67,3,174)
Block(-8,67,4,174)
Block(-8,67,5,174)
Block(-8,67,6,174)
Block(-8,67,7,174)
Block(-8,67,8,174)
Block(-8,68,4,174)
Block(-8,68,5,174)
Block(-8,68,6,174)
Block(-8,68,7,174)
Block(-8,68,8,174)
Block(-8,69,6,174)
Block(-8,69,7,174)
Block(-8,69,8,174)
Block(-8,70,7,174)
Block(-8,70,8,174)
Block(-7,11,7,174)
Block(-7,11,8,174)
Block(-7,12,6,174)
Block(-7,12,7,174)
Block(-7,12,8,174)
Block(-7,13,4,174)
Block(-7,13,5,174)
Block(-7,13,6,174)
Block(-7,13,7,174)
Block(-7,13,8,174)
Block(-7,14,2,174)
Block(-7,14,3,174)
Block(-7,14,4,174)
Block(-7,14,5,174)
Block(-7,14,6,174)
Block(-7,14,7,174)
Block(-7,14,8,174)
Block(-7,15,1,174)
Block(-7,15,2,174)
Block(-7,15,3,174)
Block(-7,15,4,174)
Block(-7,15,5,174)
Block(-7,15,6,174)
Block(-7,15,7,174)
Block(-7,15,8,174)
Block(-7,16,-2,174)
Block(-7,16,-1,174)
Block(-7,16,0,174)
Block(-7,16,1,174)
Block(-7,16,2,174)
Block(-7,16,3,174)
Block(-7,16,4,174)
Block(-7,16,5,174)
Block(-7,16,6,174)
Block(-7,16,7,174)
Block(-7,16,8,174)
Block(-7,17,-4,174)
Block(-7,17,-3,174)
Block(-7,17,-2,174)
Block(-7,17,-1,174)
Block(-7,17,0,174)
Block(-7,17,1,174)
Block(-7,17,2,174)
Block(-7,17,3,174)
Block(-7,17,4,174)
Block(-7,17,5,174)
Block(-7,17,6,174)
Block(-7,17,7,174)
Block(-7,17,8,174)
Block(-7,18,-5,174)
Block(-7,18,-4,174)
Block(-7,18,-3,174)
Block(-7,18,-2,174)
Block(-7,18,-1,174)
Block(-7,18,0,174)
Block(-7,18,1,174)
Block(-7,18,2,174)
Block(-7,18,3,174)
Block(-7,18,4,174)
Block(-7,18,5,174)
Block(-7,18,6,174)
Block(-7,18,7,174)
Block(-7,18,8,174)
Block(-7,19,-5,174)
Block(-7,19,-4,174)
Block(-7,19,-3,174)
Block(-7,19,-2,174)
Block(-7,19,-1,174)
Block(-7,19,0,174)
Block(-7,19,1,174)
Block(-7,19,2,174)
Block(-7,19,3,174)
Block(-7,19,4,174)
Block(-7,19,5,174)
Block(-7,19,6,174)
Block(-7,19,7,174)
Block(-7,19,8,174)
Block(-7,20,-6,174)
Block(-7,20,-5,174)
Block(-7,20,-4,174)
Block(-7,20,-3,174)
Block(-7,20,-2,174)
Block(-7,20,-1,174)
Block(-7,20,0,174)
Block(-7,20,1,174)
Block(-7,20,2,174)
Block(-7,20,3,174)
Block(-7,20,4,174)
Block(-7,20,5,174)
Block(-7,20,6,174)
Block(-7,20,7,174)
Block(-7,20,8,174)
Block(-7,21,-7,174)
Block(-7,21,-6,174)
Block(-7,21,-5,174)
Block(-7,21,-4,174)
Block(-7,21,-3,174)
Block(-7,21,-2,174)
Block(-7,21,-1,174)
Block(-7,21,0,174)
Block(-7,21,1,174)
Block(-7,21,2,174)
Block(-7,21,3,174)
Block(-7,21,4,174)
Block(-7,21,5,174)
Block(-7,21,6,174)
Block(-7,21,7,174)
Block(-7,21,8,174)
Block(-7,22,-7,174)
Block(-7,22,-6,174)
Block(-7,22,-5,174)
Block(-7,22,-4,174)
Block(-7,22,-3,174)
Block(-7,22,-2,174)
Block(-7,22,-1,174)
Block(-7,22,0,174)
Block(-7,22,1,174)
Block(-7,22,2,174)
Block(-7,22,3,174)
Block(-7,22,4,174)
Block(-7,22,5,174)
Block(-7,22,6,174)
Block(-7,22,7,174)
Block(-7,22,8,174)
Block(-7,23,-7,174)
Block(-7,23,-6,174)
Block(-7,23,-5,174)
Block(-7,23,-4,174)
Block(-7,23,-3,174)
Block(-7,23,-2,174)
Block(-7,23,-1,174)
Block(-7,23,0,174)
Block(-7,23,1,174)
Block(-7,23,2,174)
Block(-7,23,3,174)
Block(-7,23,4,174)
Block(-7,23,5,174)
Block(-7,23,6,174)
Block(-7,23,7,174)
Block(-7,23,8,174)
Block(-7,24,-7,174)
Block(-7,24,-6,174)
Block(-7,24,-5,174)
Block(-7,24,-4,174)
Block(-7,24,-3,174)
Block(-7,24,-2,174)
Block(-7,24,-1,174)
Block(-7,24,0,174)
Block(-7,24,1,174)
Block(-7,24,2,174)
Block(-7,24,3,174)
Block(-7,24,4,174)
Block(-7,24,5,174)
Block(-7,24,6,174)
Block(-7,24,7,174)
Block(-7,25,-7,174)
Block(-7,25,-6,174)
Block(-7,25,-5,174)
Block(-7,25,-4,174)
Block(-7,25,-3,174)
Block(-7,25,-2,174)
Block(-7,25,-1,174)
Block(-7,25,0,174)
Block(-7,25,1,174)
Block(-7,25,2,174)
Block(-7,25,3,174)
Block(-7,25,4,174)
Block(-7,25,5,174)
Block(-7,25,6,174)
Block(-7,26,-7,174)
Block(-7,26,-6,174)
Block(-7,26,-5,174)
Block(-7,26,-4,174)
Block(-7,26,-3,174)
Block(-7,26,-2,174)
Block(-7,26,-1,174)
Block(-7,26,0,174)
Block(-7,26,1,174)
Block(-7,26,2,174)
Block(-7,26,3,174)
Block(-7,26,4,174)
Block(-7,26,5,174)
Block(-7,27,-7,174)
Block(-7,27,-6,174)
Block(-7,27,-5,174)
Block(-7,27,-4,174)
Block(-7,27,-3,174)
Block(-7,27,-2,174)
Block(-7,27,-1,174)
Block(-7,27,0,174)
Block(-7,27,1,174)
Block(-7,27,2,174)
Block(-7,27,3,174)
Block(-7,27,4,174)
Block(-7,27,5,174)
Block(-7,27,6,174)
Block(-7,28,-7,174)
Block(-7,28,-6,174)
Block(-7,28,-5,174)
Block(-7,28,-4,174)
Block(-7,28,-3,174)
Block(-7,28,-2,174)
Block(-7,28,-1,174)
Block(-7,28,0,174)
Block(-7,28,1,174)
Block(-7,28,2,174)
Block(-7,28,3,174)
Block(-7,28,4,174)
Block(-7,28,5,174)
Block(-7,28,6,174)
Block(-7,28,7,174)
Block(-7,29,-7,174)
Block(-7,29,-6,174)
Block(-7,29,-5,174)
Block(-7,29,-4,174)
Block(-7,29,-3,174)
Block(-7,29,-2,174)
Block(-7,29,-1,174)
Block(-7,29,0,174)
Block(-7,29,1,174)
Block(-7,29,2,174)
Block(-7,29,3,174)
Block(-7,29,4,174)
Block(-7,29,5,174)
Block(-7,29,6,174)
Block(-7,29,7,174)
Block(-7,29,8,174)
Block(-7,30,-7,174)
Block(-7,30,-6,174)
Block(-7,30,-5,174)
Block(-7,30,-4,174)
Block(-7,30,-3,174)
Block(-7,30,-2,174)
Block(-7,30,-1,174)
Block(-7,30,0,174)
Block(-7,30,1,174)
Block(-7,30,2,174)
Block(-7,30,3,174)
Block(-7,30,4,174)
Block(-7,30,5,174)
Block(-7,30,6,174)
Block(-7,30,7,174)
Block(-7,30,8,174)
Block(-7,31,-7,174)
Block(-7,31,-6,174)
Block(-7,31,-5,174)
Block(-7,31,-4,174)
Block(-7,31,-3,174)
Block(-7,31,-2,174)
Block(-7,31,-1,174)
Block(-7,31,0,174)
Block(-7,31,1,174)
Block(-7,31,2,174)
Block(-7,31,3,174)
Block(-7,31,4,174)
Block(-7,31,5,174)
Block(-7,31,6,174)
Block(-7,31,7,174)
Block(-7,31,8,174)
Block(-7,32,-7,174)
Block(-7,32,-6,174)
Block(-7,32,-5,174)
Block(-7,32,-4,174)
Block(-7,32,-3,174)
Block(-7,32,-2,174)
Block(-7,32,-1,174)
Block(-7,32,0,174)
Block(-7,32,1,174)
Block(-7,32,2,174)
Block(-7,32,3,174)
Block(-7,32,4,174)
Block(-7,32,5,174)
Block(-7,32,6,174)
Block(-7,32,7,174)
Block(-7,32,8,174)
Block(-7,33,-7,174)
Block(-7,33,-6,174)
Block(-7,33,-5,174)
Block(-7,33,-4,174)
Block(-7,33,-3,174)
Block(-7,33,-2,174)
Block(-7,33,-1,174)
Block(-7,33,0,174)
Block(-7,33,1,174)
Block(-7,33,2,174)
Block(-7,33,3,174)
Block(-7,33,4,174)
Block(-7,33,5,174)
Block(-7,33,6,174)
Block(-7,33,7,174)
Block(-7,33,8,174)
Block(-7,34,-7,174)
Block(-7,34,-6,174)
Block(-7,34,-5,174)
Block(-7,34,-4,174)
Block(-7,34,-3,174)
Block(-7,34,-2,174)
Block(-7,34,-1,174)
Block(-7,34,0,174)
Block(-7,34,1,174)
Block(-7,34,2,174)
Block(-7,34,3,174)
Block(-7,34,4,174)
Block(-7,34,5,174)
Block(-7,34,6,174)
Block(-7,34,7,174)
Block(-7,34,8,174)
Block(-7,35,-7,174)
Block(-7,35,-6,174)
Block(-7,35,-5,174)
Block(-7,35,-4,174)
Block(-7,35,-3,174)
Block(-7,35,-2,174)
Block(-7,35,-1,174)
Block(-7,35,0,174)
Block(-7,35,1,174)
Block(-7,35,2,174)
Block(-7,35,3,174)
Block(-7,35,4,174)
Block(-7,35,5,174)
Block(-7,35,6,174)
Block(-7,35,7,174)
Block(-7,35,8,174)
Block(-7,36,-7,174)
Block(-7,36,-6,174)
Block(-7,36,-5,174)
Block(-7,36,-4,174)
Block(-7,36,-3,174)
Block(-7,36,-2,174)
Block(-7,36,-1,174)
Block(-7,36,0,174)
Block(-7,36,1,174)
Block(-7,36,2,174)
Block(-7,36,3,174)
Block(-7,36,4,174)
Block(-7,36,5,174)
Block(-7,36,6,174)
Block(-7,36,7,174)
Block(-7,36,8,174)
Block(-7,37,-7,174)
Block(-7,37,-6,174)
Block(-7,37,-5,174)
Block(-7,37,-4,174)
Block(-7,37,-3,174)
Block(-7,37,-2,174)
Block(-7,37,-1,174)
Block(-7,37,0,174)
Block(-7,37,1,174)
Block(-7,37,2,174)
Block(-7,37,3,174)
Block(-7,37,4,174)
Block(-7,37,5,174)
Block(-7,37,6,174)
Block(-7,37,7,174)
Block(-7,37,8,174)
Block(-7,38,-7,174)
Block(-7,38,-6,174)
Block(-7,38,-5,174)
Block(-7,38,-4,174)
Block(-7,38,-3,174)
Block(-7,38,-2,174)
Block(-7,38,-1,174)
Block(-7,38,0,174)
Block(-7,38,1,174)
Block(-7,38,2,174)
Block(-7,38,3,174)
Block(-7,38,4,174)
Block(-7,38,5,174)
Block(-7,38,6,174)
Block(-7,38,7,174)
Block(-7,38,8,174)
Block(-7,39,-7,174)
Block(-7,39,-6,174)
Block(-7,39,-5,174)
Block(-7,39,-4,174)
Block(-7,39,-3,174)
Block(-7,39,-2,174)
Block(-7,39,-1,174)
Block(-7,39,0,174)
Block(-7,39,1,174)
Block(-7,39,2,174)
Block(-7,39,3,174)
Block(-7,39,4,174)
Block(-7,39,5,174)
Block(-7,39,6,174)
Block(-7,39,7,174)
Block(-7,39,8,174)
Block(-7,40,-7,174)
Block(-7,40,-6,174)
Block(-7,40,-5,174)
Block(-7,40,-4,174)
Block(-7,40,-3,174)
Block(-7,40,-2,174)
Block(-7,40,-1,174)
Block(-7,40,0,174)
Block(-7,40,1,174)
Block(-7,40,2,174)
Block(-7,40,3,174)
Block(-7,40,4,174)
Block(-7,40,5,174)
Block(-7,40,6,174)
Block(-7,40,7,174)
Block(-7,40,8,174)
Block(-7,41,-7,174)
Block(-7,41,-6,174)
Block(-7,41,-5,174)
Block(-7,41,-4,174)
Block(-7,41,-3,174)
Block(-7,41,-2,174)
Block(-7,41,-1,174)
Block(-7,41,0,174)
Block(-7,41,1,174)
Block(-7,41,2,174)
Block(-7,41,3,174)
Block(-7,41,4,174)
Block(-7,41,5,174)
Block(-7,41,6,174)
Block(-7,41,7,174)
Block(-7,41,8,174)
Block(-7,42,-7,174)
Block(-7,42,-6,174)
Block(-7,42,-5,174)
Block(-7,42,-4,174)
Block(-7,42,-3,174)
Block(-7,42,-2,174)
Block(-7,42,-1,174)
Block(-7,42,0,174)
Block(-7,42,1,174)
Block(-7,42,2,174)
Block(-7,42,3,174)
Block(-7,42,4,174)
Block(-7,42,5,174)
Block(-7,42,6,174)
Block(-7,42,7,174)
Block(-7,42,8,174)
Block(-7,43,-7,174)
Block(-7,43,-6,174)
Block(-7,43,-5,174)
Block(-7,43,-4,174)
Block(-7,43,-3,174)
Block(-7,43,-2,174)
Block(-7,43,-1,174)
Block(-7,43,0,174)
Block(-7,43,1,174)
Block(-7,43,2,174)
Block(-7,43,3,174)
Block(-7,43,4,174)
Block(-7,43,5,174)
Block(-7,43,6,174)
Block(-7,43,7,174)
Block(-7,44,-7,174)
Block(-7,44,-6,174)
Block(-7,44,-5,174)
Block(-7,44,-4,174)
Block(-7,44,-3,174)
Block(-7,44,-2,174)
Block(-7,44,-1,174)
Block(-7,44,0,174)
Block(-7,44,1,174)
Block(-7,44,2,174)
Block(-7,44,3,174)
Block(-7,44,4,174)
Block(-7,44,5,174)
Block(-7,44,6,174)
Block(-7,44,7,174)
Block(-7,45,-7,174)
Block(-7,45,-6,174)
Block(-7,45,-5,174)
Block(-7,45,-4,174)
Block(-7,45,-3,174)
Block(-7,45,-2,174)
Block(-7,45,-1,174)
Block(-7,45,0,174)
Block(-7,45,1,174)
Block(-7,45,2,174)
Block(-7,45,3,174)
Block(-7,45,4,174)
Block(-7,45,5,174)
Block(-7,45,6,174)
Block(-7,45,7,174)
Block(-7,46,-7,174)
Block(-7,46,-6,174)
Block(-7,46,-5,174)
Block(-7,46,-4,174)
Block(-7,46,-3,174)
Block(-7,46,-2,174)
Block(-7,46,-1,174)
Block(-7,46,0,174)
Block(-7,46,1,174)
Block(-7,46,2,174)
Block(-7,46,3,174)
Block(-7,46,4,174)
Block(-7,46,5,174)
Block(-7,46,6,174)
Block(-7,46,7,174)
Block(-7,46,8,174)
Block(-7,47,-7,174)
Block(-7,47,-6,174)
Block(-7,47,-5,174)
Block(-7,47,-4,174)
Block(-7,47,-3,174)
Block(-7,47,-2,174)
Block(-7,47,-1,174)
Block(-7,47,0,174)
Block(-7,47,1,174)
Block(-7,47,2,174)
Block(-7,47,3,174)
Block(-7,47,4,174)
Block(-7,47,5,174)
Block(-7,47,6,174)
Block(-7,47,7,174)
Block(-7,47,8,174)
Block(-7,48,-7,174)
Block(-7,48,-6,174)
Block(-7,48,-5,174)
Block(-7,48,-4,174)
Block(-7,48,-3,174)
Block(-7,48,-2,174)
Block(-7,48,-1,174)
Block(-7,48,0,174)
Block(-7,48,1,174)
Block(-7,48,2,174)
Block(-7,48,3,174)
Block(-7,48,4,174)
Block(-7,48,5,174)
Block(-7,48,6,174)
Block(-7,48,7,174)
Block(-7,48,8,174)
Block(-7,49,-7,174)
Block(-7,49,-6,174)
Block(-7,49,-5,174)
Block(-7,49,-4,174)
Block(-7,49,-3,174)
Block(-7,49,-2,174)
Block(-7,49,-1,174)
Block(-7,49,0,174)
Block(-7,49,1,174)
Block(-7,49,2,174)
Block(-7,49,3,174)
Block(-7,49,4,174)
Block(-7,49,5,174)
Block(-7,49,6,174)
Block(-7,49,7,174)
Block(-7,49,8,174)
Block(-7,50,-7,174)
Block(-7,50,-6,174)
Block(-7,50,-5,174)
Block(-7,50,-4,174)
Block(-7,50,-3,174)
Block(-7,50,-2,174)
Block(-7,50,-1,174)
Block(-7,50,0,174)
Block(-7,50,1,174)
Block(-7,50,2,174)
Block(-7,50,3,174)
Block(-7,50,4,174)
Block(-7,50,5,174)
Block(-7,50,6,174)
Block(-7,50,7,174)
Block(-7,50,8,174)
Block(-7,51,-7,174)
Block(-7,51,-6,174)
Block(-7,51,-5,174)
Block(-7,51,-4,174)
Block(-7,51,-3,174)
Block(-7,51,-2,174)
Block(-7,51,-1,174)
Block(-7,51,0,174)
Block(-7,51,1,174)
Block(-7,51,2,174)
Block(-7,51,3,174)
Block(-7,51,4,174)
Block(-7,51,5,174)
Block(-7,51,6,174)
Block(-7,51,7,174)
Block(-7,52,-7,174)
Block(-7,52,-6,174)
Block(-7,52,-5,174)
Block(-7,52,-4,174)
Block(-7,52,-3,174)
Block(-7,52,-2,174)
Block(-7,52,-1,174)
Block(-7,52,0,174)
Block(-7,52,1,174)
Block(-7,52,2,174)
Block(-7,52,3,174)
Block(-7,52,4,174)
Block(-7,52,5,174)
Block(-7,52,6,174)
Block(-7,52,7,174)
Block(-7,52,8,174)
Block(-7,53,-7,174)
Block(-7,53,-6,174)
Block(-7,53,-5,174)
Block(-7,53,-4,174)
Block(-7,53,-3,174)
Block(-7,53,-2,174)
Block(-7,53,-1,174)
Block(-7,53,0,174)
Block(-7,53,1,174)
Block(-7,53,2,174)
Block(-7,53,3,174)
Block(-7,53,4,174)
Block(-7,53,5,174)
Block(-7,53,6,174)
Block(-7,54,-7,174)
Block(-7,54,-6,174)
Block(-7,54,-5,174)
Block(-7,54,-4,174)
Block(-7,54,-3,174)
Block(-7,54,-2,174)
Block(-7,54,-1,174)
Block(-7,54,0,174)
Block(-7,54,1,174)
Block(-7,54,2,174)
Block(-7,54,3,174)
Block(-7,54,4,174)
Block(-7,54,5,174)
Block(-7,54,6,174)
Block(-7,55,-7,174)
Block(-7,55,-6,174)
Block(-7,55,-5,174)
Block(-7,55,-4,174)
Block(-7,55,-3,174)
Block(-7,55,-2,174)
Block(-7,55,-1,174)
Block(-7,55,0,174)
Block(-7,55,1,174)
Block(-7,55,2,174)
Block(-7,55,3,174)
Block(-7,55,4,174)
Block(-7,55,5,174)
Block(-7,56,-7,174)
Block(-7,56,-6,174)
Block(-7,56,-5,174)
Block(-7,56,-4,174)
Block(-7,56,-3,174)
Block(-7,56,-2,174)
Block(-7,56,-1,174)
Block(-7,56,0,174)
Block(-7,56,1,174)
Block(-7,56,2,174)
Block(-7,56,3,174)
Block(-7,56,4,174)
Block(-7,56,5,174)
Block(-7,57,-7,174)
Block(-7,57,-6,174)
Block(-7,57,-5,174)
Block(-7,57,-4,174)
Block(-7,57,-3,174)
Block(-7,57,-2,174)
Block(-7,57,-1,174)
Block(-7,57,0,174)
Block(-7,57,1,174)
Block(-7,57,2,174)
Block(-7,57,3,174)
Block(-7,57,4,174)
Block(-7,57,5,174)
Block(-7,57,6,174)
Block(-7,58,-7,174)
Block(-7,58,-6,174)
Block(-7,58,-5,174)
Block(-7,58,-4,174)
Block(-7,58,-3,174)
Block(-7,58,-2,174)
Block(-7,58,-1,174)
Block(-7,58,0,174)
Block(-7,58,1,174)
Block(-7,58,2,174)
Block(-7,58,3,174)
Block(-7,58,4,174)
Block(-7,58,5,174)
Block(-7,58,6,174)
Block(-7,58,7,174)
Block(-7,58,8,174)
Block(-7,59,-7,174)
Block(-7,59,-6,174)
Block(-7,59,-5,174)
Block(-7,59,-4,174)
Block(-7,59,-3,174)
Block(-7,59,-2,174)
Block(-7,59,-1,174)
Block(-7,59,0,174)
Block(-7,59,1,174)
Block(-7,59,2,174)
Block(-7,59,3,174)
Block(-7,59,4,174)
Block(-7,59,5,174)
Block(-7,59,6,174)
Block(-7,59,7,174)
Block(-7,59,8,174)
Block(-7,60,-7,174)
Block(-7,60,-6,174)
Block(-7,60,-5,174)
Block(-7,60,-4,174)
Block(-7,60,-3,174)
Block(-7,60,-2,174)
Block(-7,60,-1,174)
Block(-7,60,0,174)
Block(-7,60,1,174)
Block(-7,60,2,174)
Block(-7,60,3,174)
Block(-7,60,4,174)
Block(-7,60,5,174)
Block(-7,60,6,174)
Block(-7,60,7,174)
Block(-7,60,8,174)
Block(-7,61,-6,174)
Block(-7,61,-5,174)
Block(-7,61,-4,174)
Block(-7,61,-3,174)
Block(-7,61,-2,174)
Block(-7,61,-1,174)
Block(-7,61,0,174)
Block(-7,61,1,174)
Block(-7,61,2,174)
Block(-7,61,3,174)
Block(-7,61,4,174)
Block(-7,61,5,174)
Block(-7,61,6,174)
Block(-7,61,7,174)
Block(-7,61,8,174)
Block(-7,62,-5,174)
Block(-7,62,-4,174)
Block(-7,62,-3,174)
Block(-7,62,-2,174)
Block(-7,62,-1,174)
Block(-7,62,0,174)
Block(-7,62,1,174)
Block(-7,62,2,174)
Block(-7,62,3,174)
Block(-7,62,4,174)
Block(-7,62,5,174)
Block(-7,62,6,174)
Block(-7,62,7,174)
Block(-7,62,8,174)
Block(-7,63,-5,174)
Block(-7,63,-4,174)
Block(-7,63,-3,174)
Block(-7,63,-2,174)
Block(-7,63,-1,174)
Block(-7,63,0,174)
Block(-7,63,1,174)
Block(-7,63,2,174)
Block(-7,63,3,174)
Block(-7,63,4,174)
Block(-7,63,5,174)
Block(-7,63,6,174)
Block(-7,63,7,174)
Block(-7,63,8,174)
Block(-7,64,-4,174)
Block(-7,64,-3,174)
Block(-7,64,-2,174)
Block(-7,64,-1,174)
Block(-7,64,0,174)
Block(-7,64,1,174)
Block(-7,64,2,174)
Block(-7,64,3,174)
Block(-7,64,4,174)
Block(-7,64,5,174)
Block(-7,64,6,174)
Block(-7,64,7,174)
Block(-7,64,8,174)
Block(-7,65,-2,174)
Block(-7,65,-1,174)
Block(-7,65,0,174)
Block(-7,65,1,174)
Block(-7,65,2,174)
Block(-7,65,3,174)
Block(-7,65,4,174)
Block(-7,65,5,174)
Block(-7,65,6,174)
Block(-7,65,7,174)
Block(-7,65,8,174)
Block(-7,66,0,174)
Block(-7,66,1,174)
Block(-7,66,2,174)
Block(-7,66,3,174)
Block(-7,66,4,174)
Block(-7,66,5,174)
Block(-7,66,6,174)
Block(-7,66,7,174)
Block(-7,66,8,174)
Block(-7,67,1,174)
Block(-7,67,2,174)
Block(-7,67,3,174)
Block(-7,67,4,174)
Block(-7,67,5,174)
Block(-7,67,6,174)
Block(-7,67,7,174)
Block(-7,67,8,174)
Block(-7,68,4,174)
Block(-7,68,5,174)
Block(-7,68,6,174)
Block(-7,68,7,174)
Block(-7,68,8,174)
Block(-7,69,6,174)
Block(-7,69,7,174)
Block(-7,69,8,174)
Block(-7,70,7,174)
Block(-7,70,8,174)
Block(-6,11,7,174)
Block(-6,11,8,174)
Block(-6,12,6,174)
Block(-6,12,7,174)
Block(-6,12,8,174)
Block(-6,13,4,174)
Block(-6,13,5,174)
Block(-6,13,6,174)
Block(-6,13,7,174)
Block(-6,13,8,174)
Block(-6,14,1,174)
Block(-6,14,2,174)
Block(-6,14,3,174)
Block(-6,14,4,174)
Block(-6,14,5,174)
Block(-6,14,6,174)
Block(-6,14,7,174)
Block(-6,14,8,174)
Block(-6,15,0,174)
Block(-6,15,1,174)
Block(-6,15,2,174)
Block(-6,15,3,174)
Block(-6,15,4,174)
Block(-6,15,5,174)
Block(-6,15,6,174)
Block(-6,15,7,174)
Block(-6,15,8,174)
Block(-6,16,-3,174)
Block(-6,16,-2,174)
Block(-6,16,-1,174)
Block(-6,16,0,174)
Block(-6,16,1,174)
Block(-6,16,2,174)
Block(-6,16,3,174)
Block(-6,16,4,174)
Block(-6,16,5,174)
Block(-6,16,6,174)
Block(-6,16,7,174)
Block(-6,16,8,174)
Block(-6,17,-4,174)
Block(-6,17,-3,174)
Block(-6,17,-2,174)
Block(-6,17,-1,174)
Block(-6,17,0,174)
Block(-6,17,1,174)
Block(-6,17,2,174)
Block(-6,17,3,174)
Block(-6,17,4,174)
Block(-6,17,5,174)
Block(-6,17,6,174)
Block(-6,17,7,174)
Block(-6,17,8,174)
Block(-6,18,-5,174)
Block(-6,18,-4,174)
Block(-6,18,-3,174)
Block(-6,18,-2,174)
Block(-6,18,-1,174)
Block(-6,18,0,174)
Block(-6,18,1,174)
Block(-6,18,2,174)
Block(-6,18,3,174)
Block(-6,18,4,174)
Block(-6,18,5,174)
Block(-6,18,6,174)
Block(-6,18,7,174)
Block(-6,18,8,174)
Block(-6,19,-6,174)
Block(-6,19,-5,174)
Block(-6,19,-4,174)
Block(-6,19,-3,174)
Block(-6,19,-2,174)
Block(-6,19,-1,174)
Block(-6,19,0,174)
Block(-6,19,1,174)
Block(-6,19,2,174)
Block(-6,19,3,174)
Block(-6,19,4,174)
Block(-6,19,5,174)
Block(-6,19,6,174)
Block(-6,19,7,174)
Block(-6,19,8,174)
Block(-6,20,-7,174)
Block(-6,20,-6,174)
Block(-6,20,-5,174)
Block(-6,20,-4,174)
Block(-6,20,-3,174)
Block(-6,20,-2,174)
Block(-6,20,-1,174)
Block(-6,20,0,174)
Block(-6,20,1,174)
Block(-6,20,2,174)
Block(-6,20,3,174)
Block(-6,20,4,174)
Block(-6,20,5,174)
Block(-6,20,6,174)
Block(-6,20,7,174)
Block(-6,20,8,174)
Block(-6,21,-7,174)
Block(-6,21,-6,174)
Block(-6,21,-5,174)
Block(-6,21,-4,174)
Block(-6,21,-3,174)
Block(-6,21,-2,174)
Block(-6,21,-1,174)
Block(-6,21,0,174)
Block(-6,21,1,174)
Block(-6,21,2,174)
Block(-6,21,3,174)
Block(-6,21,4,174)
Block(-6,21,5,174)
Block(-6,21,6,174)
Block(-6,21,7,174)
Block(-6,21,8,174)
Block(-6,22,-7,174)
Block(-6,22,-6,174)
Block(-6,22,-5,174)
Block(-6,22,-4,174)
Block(-6,22,-3,174)
Block(-6,22,-2,174)
Block(-6,22,-1,174)
Block(-6,22,0,174)
Block(-6,22,1,174)
Block(-6,22,2,174)
Block(-6,22,3,174)
Block(-6,22,4,174)
Block(-6,22,5,174)
Block(-6,22,6,174)
Block(-6,22,7,174)
Block(-6,22,8,174)
Block(-6,23,-7,174)
Block(-6,23,-6,174)
Block(-6,23,-5,174)
Block(-6,23,-4,174)
Block(-6,23,-3,174)
Block(-6,23,-2,174)
Block(-6,23,-1,174)
Block(-6,23,0,174)
Block(-6,23,1,174)
Block(-6,23,2,174)
Block(-6,23,3,174)
Block(-6,23,4,174)
Block(-6,23,5,174)
Block(-6,23,6,174)
Block(-6,23,7,174)
Block(-6,23,8,174)
Block(-6,24,-7,174)
Block(-6,24,-6,174)
Block(-6,24,-5,174)
Block(-6,24,-4,174)
Block(-6,24,-3,174)
Block(-6,24,-2,174)
Block(-6,24,-1,174)
Block(-6,24,0,174)
Block(-6,24,1,174)
Block(-6,24,2,174)
Block(-6,24,3,174)
Block(-6,24,4,174)
Block(-6,24,5,174)
Block(-6,25,-7,174)
Block(-6,25,-6,174)
Block(-6,25,-5,174)
Block(-6,25,-4,174)
Block(-6,25,-3,174)
Block(-6,25,-2,174)
Block(-6,25,-1,174)
Block(-6,25,0,174)
Block(-6,25,1,174)
Block(-6,25,2,174)
Block(-6,25,3,174)
Block(-6,25,4,174)
Block(-6,26,-7,174)
Block(-6,26,-6,174)
Block(-6,26,-5,174)
Block(-6,26,-4,174)
Block(-6,26,-3,174)
Block(-6,26,-2,174)
Block(-6,26,-1,174)
Block(-6,26,0,174)
Block(-6,26,1,174)
Block(-6,26,2,174)
Block(-6,26,3,174)
Block(-6,26,4,174)
Block(-6,27,-7,174)
Block(-6,27,-6,174)
Block(-6,27,-5,174)
Block(-6,27,-4,174)
Block(-6,27,-3,174)
Block(-6,27,-2,174)
Block(-6,27,-1,174)
Block(-6,27,0,174)
Block(-6,27,1,174)
Block(-6,27,2,174)
Block(-6,27,3,174)
Block(-6,27,4,174)
Block(-6,27,5,174)
Block(-6,28,-7,174)
Block(-6,28,-6,174)
Block(-6,28,-5,174)
Block(-6,28,-4,174)
Block(-6,28,-3,174)
Block(-6,28,-2,174)
Block(-6,28,-1,174)
Block(-6,28,0,174)
Block(-6,28,1,174)
Block(-6,28,2,174)
Block(-6,28,3,174)
Block(-6,28,4,174)
Block(-6,28,5,174)
Block(-6,28,6,174)
Block(-6,29,-7,174)
Block(-6,29,-6,174)
Block(-6,29,-5,174)
Block(-6,29,-4,174)
Block(-6,29,-3,174)
Block(-6,29,-2,174)
Block(-6,29,-1,174)
Block(-6,29,0,174)
Block(-6,29,1,174)
Block(-6,29,2,174)
Block(-6,29,3,174)
Block(-6,29,4,174)
Block(-6,29,5,174)
Block(-6,29,6,174)
Block(-6,29,7,174)
Block(-6,30,-7,174)
Block(-6,30,-6,174)
Block(-6,30,-5,174)
Block(-6,30,-4,174)
Block(-6,30,-3,174)
Block(-6,30,-2,174)
Block(-6,30,-1,174)
Block(-6,30,0,174)
Block(-6,30,1,174)
Block(-6,30,2,174)
Block(-6,30,3,174)
Block(-6,30,4,174)
Block(-6,30,5,174)
Block(-6,30,6,174)
Block(-6,30,7,174)
Block(-6,31,-7,174)
Block(-6,31,-6,174)
Block(-6,31,-5,174)
Block(-6,31,-4,174)
Block(-6,31,-3,174)
Block(-6,31,-2,174)
Block(-6,31,-1,174)
Block(-6,31,0,174)
Block(-6,31,1,174)
Block(-6,31,2,174)
Block(-6,31,3,174)
Block(-6,31,4,174)
Block(-6,31,5,174)
Block(-6,31,6,174)
Block(-6,31,7,174)
Block(-6,31,8,174)
Block(-6,32,-7,174)
Block(-6,32,-6,174)
Block(-6,32,-5,174)
Block(-6,32,-4,174)
Block(-6,32,-3,174)
Block(-6,32,-2,174)
Block(-6,32,-1,174)
Block(-6,32,0,174)
Block(-6,32,1,174)
Block(-6,32,2,174)
Block(-6,32,3,174)
Block(-6,32,4,174)
Block(-6,32,5,174)
Block(-6,32,6,174)
Block(-6,32,7,174)
Block(-6,32,8,174)
Block(-6,33,-7,174)
Block(-6,33,-6,174)
Block(-6,33,-5,174)
Block(-6,33,-4,174)
Block(-6,33,-3,174)
Block(-6,33,-2,174)
Block(-6,33,-1,174)
Block(-6,33,0,174)
Block(-6,33,1,174)
Block(-6,33,2,174)
Block(-6,33,3,174)
Block(-6,33,4,174)
Block(-6,33,5,174)
Block(-6,33,6,174)
Block(-6,33,7,174)
Block(-6,33,8,174)
Block(-6,34,-7,174)
Block(-6,34,-6,174)
Block(-6,34,-5,174)
Block(-6,34,-4,174)
Block(-6,34,-3,174)
Block(-6,34,-2,174)
Block(-6,34,-1,174)
Block(-6,34,0,174)
Block(-6,34,1,174)
Block(-6,34,2,174)
Block(-6,34,3,174)
Block(-6,34,4,174)
Block(-6,34,5,174)
Block(-6,34,6,174)
Block(-6,34,7,174)
Block(-6,34,8,174)
Block(-6,35,-7,174)
Block(-6,35,-6,174)
Block(-6,35,-5,174)
Block(-6,35,-4,174)
Block(-6,35,-3,174)
Block(-6,35,-2,174)
Block(-6,35,-1,174)
Block(-6,35,0,174)
Block(-6,35,1,174)
Block(-6,35,2,174)
Block(-6,35,3,174)
Block(-6,35,4,174)
Block(-6,35,5,174)
Block(-6,35,6,174)
Block(-6,35,7,174)
Block(-6,35,8,174)
Block(-6,36,-7,174)
Block(-6,36,-6,174)
Block(-6,36,-5,174)
Block(-6,36,-4,174)
Block(-6,36,-3,174)
Block(-6,36,-2,174)
Block(-6,36,-1,174)
Block(-6,36,0,174)
Block(-6,36,1,174)
Block(-6,36,2,174)
Block(-6,36,3,174)
Block(-6,36,4,174)
Block(-6,36,5,174)
Block(-6,36,6,174)
Block(-6,36,7,174)
Block(-6,36,8,174)
Block(-6,37,-7,174)
Block(-6,37,-6,174)
Block(-6,37,-5,174)
Block(-6,37,-4,174)
Block(-6,37,-3,174)
Block(-6,37,-2,174)
Block(-6,37,-1,174)
Block(-6,37,0,174)
Block(-6,37,1,174)
Block(-6,37,2,174)
Block(-6,37,3,174)
Block(-6,37,4,174)
Block(-6,37,5,174)
Block(-6,37,6,174)
Block(-6,37,7,174)
Block(-6,37,8,174)
Block(-6,38,-7,174)
Block(-6,38,-6,174)
Block(-6,38,-5,174)
Block(-6,38,-4,174)
Block(-6,38,-3,174)
Block(-6,38,-2,174)
Block(-6,38,-1,174)
Block(-6,38,0,174)
Block(-6,38,1,174)
Block(-6,38,2,174)
Block(-6,38,3,174)
Block(-6,38,4,174)
Block(-6,38,5,174)
Block(-6,38,6,174)
Block(-6,38,7,174)
Block(-6,38,8,174)
Block(-6,39,-7,174)
Block(-6,39,-6,174)
Block(-6,39,-5,174)
Block(-6,39,-4,174)
Block(-6,39,-3,174)
Block(-6,39,-2,174)
Block(-6,39,-1,174)
Block(-6,39,0,174)
Block(-6,39,1,174)
Block(-6,39,2,174)
Block(-6,39,3,174)
Block(-6,39,4,174)
Block(-6,39,5,174)
Block(-6,39,6,174)
Block(-6,39,7,174)
Block(-6,39,8,174)
Block(-6,40,-7,174)
Block(-6,40,-6,174)
Block(-6,40,-5,174)
Block(-6,40,-4,174)
Block(-6,40,-3,174)
Block(-6,40,-2,174)
Block(-6,40,-1,174)
Block(-6,40,0,174)
Block(-6,40,1,174)
Block(-6,40,2,174)
Block(-6,40,3,174)
Block(-6,40,4,174)
Block(-6,40,5,174)
Block(-6,40,6,174)
Block(-6,40,7,174)
Block(-6,40,8,174)
Block(-6,41,-7,174)
Block(-6,41,-6,174)
Block(-6,41,-5,174)
Block(-6,41,-4,174)
Block(-6,41,-3,174)
Block(-6,41,-2,174)
Block(-6,41,-1,174)
Block(-6,41,0,174)
Block(-6,41,1,174)
Block(-6,41,2,174)
Block(-6,41,3,174)
Block(-6,41,4,174)
Block(-6,41,5,174)
Block(-6,41,6,174)
Block(-6,41,7,174)
Block(-6,41,8,174)
Block(-6,42,-7,174)
Block(-6,42,-6,174)
Block(-6,42,-5,174)
Block(-6,42,-4,174)
Block(-6,42,-3,174)
Block(-6,42,-2,174)
Block(-6,42,-1,174)
Block(-6,42,0,174)
Block(-6,42,1,174)
Block(-6,42,2,174)
Block(-6,42,3,174)
Block(-6,42,4,174)
Block(-6,42,5,174)
Block(-6,42,6,174)
Block(-6,42,7,174)
Block(-6,43,-7,174)
Block(-6,43,-6,174)
Block(-6,43,-5,174)
Block(-6,43,-4,174)
Block(-6,43,-3,174)
Block(-6,43,-2,174)
Block(-6,43,-1,174)
Block(-6,43,0,174)
Block(-6,43,1,174)
Block(-6,43,2,174)
Block(-6,43,3,174)
Block(-6,43,4,174)
Block(-6,43,5,174)
Block(-6,43,6,174)
Block(-6,44,-7,174)
Block(-6,44,-6,174)
Block(-6,44,-5,174)
Block(-6,44,-4,174)
Block(-6,44,-3,174)
Block(-6,44,-2,174)
Block(-6,44,-1,174)
Block(-6,44,0,174)
Block(-6,44,1,174)
Block(-6,44,2,174)
Block(-6,44,3,174)
Block(-6,44,4,174)
Block(-6,44,5,174)
Block(-6,44,6,174)
Block(-6,45,-7,174)
Block(-6,45,-6,174)
Block(-6,45,-5,174)
Block(-6,45,-4,174)
Block(-6,45,-3,174)
Block(-6,45,-2,174)
Block(-6,45,-1,174)
Block(-6,45,0,174)
Block(-6,45,1,174)
Block(-6,45,2,174)
Block(-6,45,3,174)
Block(-6,45,4,174)
Block(-6,45,5,174)
Block(-6,45,6,174)
Block(-6,45,7,174)
Block(-6,46,-7,174)
Block(-6,46,-6,174)
Block(-6,46,-5,174)
Block(-6,46,-4,174)
Block(-6,46,-3,174)
Block(-6,46,-2,174)
Block(-6,46,-1,174)
Block(-6,46,0,174)
Block(-6,46,1,174)
Block(-6,46,2,174)
Block(-6,46,3,174)
Block(-6,46,4,174)
Block(-6,46,5,174)
Block(-6,46,6,174)
Block(-6,46,7,174)
Block(-6,47,-7,174)
Block(-6,47,-6,174)
Block(-6,47,-5,174)
Block(-6,47,-4,174)
Block(-6,47,-3,174)
Block(-6,47,-2,174)
Block(-6,47,-1,174)
Block(-6,47,0,174)
Block(-6,47,1,174)
Block(-6,47,2,174)
Block(-6,47,3,174)
Block(-6,47,4,174)
Block(-6,47,5,174)
Block(-6,47,6,174)
Block(-6,47,7,174)
Block(-6,48,-7,174)
Block(-6,48,-6,174)
Block(-6,48,-5,174)
Block(-6,48,-4,174)
Block(-6,48,-3,174)
Block(-6,48,-2,174)
Block(-6,48,-1,174)
Block(-6,48,0,174)
Block(-6,48,1,174)
Block(-6,48,2,174)
Block(-6,48,3,174)
Block(-6,48,4,174)
Block(-6,48,5,174)
Block(-6,48,6,174)
Block(-6,48,7,174)
Block(-6,49,-7,174)
Block(-6,49,-6,174)
Block(-6,49,-5,174)
Block(-6,49,-4,174)
Block(-6,49,-3,174)
Block(-6,49,-2,174)
Block(-6,49,-1,174)
Block(-6,49,0,174)
Block(-6,49,1,174)
Block(-6,49,2,174)
Block(-6,49,3,174)
Block(-6,49,4,174)
Block(-6,49,5,174)
Block(-6,49,6,174)
Block(-6,49,7,174)
Block(-6,49,8,174)
Block(-6,50,-7,174)
Block(-6,50,-6,174)
Block(-6,50,-5,174)
Block(-6,50,-4,174)
Block(-6,50,-3,174)
Block(-6,50,-2,174)
Block(-6,50,-1,174)
Block(-6,50,0,174)
Block(-6,50,1,174)
Block(-6,50,2,174)
Block(-6,50,3,174)
Block(-6,50,4,174)
Block(-6,50,5,174)
Block(-6,50,6,174)
Block(-6,50,7,174)
Block(-6,51,-7,174)
Block(-6,51,-6,174)
Block(-6,51,-5,174)
Block(-6,51,-4,174)
Block(-6,51,-3,174)
Block(-6,51,-2,174)
Block(-6,51,-1,174)
Block(-6,51,0,174)
Block(-6,51,1,174)
Block(-6,51,2,174)
Block(-6,51,3,174)
Block(-6,51,4,174)
Block(-6,51,5,174)
Block(-6,51,6,174)
Block(-6,51,7,174)
Block(-6,52,-7,174)
Block(-6,52,-6,174)
Block(-6,52,-5,174)
Block(-6,52,-4,174)
Block(-6,52,-3,174)
Block(-6,52,-2,174)
Block(-6,52,-1,174)
Block(-6,52,0,174)
Block(-6,52,1,174)
Block(-6,52,2,174)
Block(-6,52,3,174)
Block(-6,52,4,174)
Block(-6,52,5,174)
Block(-6,52,6,174)
Block(-6,52,7,174)
Block(-6,53,-7,174)
Block(-6,53,-6,174)
Block(-6,53,-5,174)
Block(-6,53,-4,174)
Block(-6,53,-3,174)
Block(-6,53,-2,174)
Block(-6,53,-1,174)
Block(-6,53,0,174)
Block(-6,53,1,174)
Block(-6,53,2,174)
Block(-6,53,3,174)
Block(-6,53,4,174)
Block(-6,53,5,174)
Block(-6,54,-7,174)
Block(-6,54,-6,174)
Block(-6,54,-5,174)
Block(-6,54,-4,174)
Block(-6,54,-3,174)
Block(-6,54,-2,174)
Block(-6,54,-1,174)
Block(-6,54,0,174)
Block(-6,54,1,174)
Block(-6,54,2,174)
Block(-6,54,3,174)
Block(-6,54,4,174)
Block(-6,54,5,174)
Block(-6,55,-7,174)
Block(-6,55,-6,174)
Block(-6,55,-5,174)
Block(-6,55,-4,174)
Block(-6,55,-3,174)
Block(-6,55,-2,174)
Block(-6,55,-1,174)
Block(-6,55,0,174)
Block(-6,55,1,174)
Block(-6,55,2,174)
Block(-6,55,3,174)
Block(-6,55,4,174)
Block(-6,56,-7,174)
Block(-6,56,-6,174)
Block(-6,56,-5,174)
Block(-6,56,-4,174)
Block(-6,56,-3,174)
Block(-6,56,-2,174)
Block(-6,56,-1,174)
Block(-6,56,0,174)
Block(-6,56,1,174)
Block(-6,56,2,174)
Block(-6,56,3,174)
Block(-6,56,4,174)
Block(-6,57,-7,174)
Block(-6,57,-6,174)
Block(-6,57,-5,174)
Block(-6,57,-4,174)
Block(-6,57,-3,174)
Block(-6,57,-2,174)
Block(-6,57,-1,174)
Block(-6,57,0,174)
Block(-6,57,1,174)
Block(-6,57,2,174)
Block(-6,57,3,174)
Block(-6,57,4,174)
Block(-6,57,5,174)
Block(-6,58,-7,174)
Block(-6,58,-6,174)
Block(-6,58,-5,174)
Block(-6,58,-4,174)
Block(-6,58,-3,174)
Block(-6,58,-2,174)
Block(-6,58,-1,174)
Block(-6,58,0,174)
Block(-6,58,1,174)
Block(-6,58,2,174)
Block(-6,58,3,174)
Block(-6,58,4,174)
Block(-6,58,5,174)
Block(-6,58,6,174)
Block(-6,58,7,174)
Block(-6,59,-7,174)
Block(-6,59,-6,174)
Block(-6,59,-5,174)
Block(-6,59,-4,174)
Block(-6,59,-3,174)
Block(-6,59,-2,174)
Block(-6,59,-1,174)
Block(-6,59,0,174)
Block(-6,59,1,174)
Block(-6,59,2,174)
Block(-6,59,3,174)
Block(-6,59,4,174)
Block(-6,59,5,174)
Block(-6,59,6,174)
Block(-6,59,7,174)
Block(-6,59,8,174)
Block(-6,60,-7,174)
Block(-6,60,-6,174)
Block(-6,60,-5,174)
Block(-6,60,-4,174)
Block(-6,60,-3,174)
Block(-6,60,-2,174)
Block(-6,60,-1,174)
Block(-6,60,0,174)
Block(-6,60,1,174)
Block(-6,60,2,174)
Block(-6,60,3,174)
Block(-6,60,4,174)
Block(-6,60,5,174)
Block(-6,60,6,174)
Block(-6,60,7,174)
Block(-6,60,8,174)
Block(-6,61,-6,174)
Block(-6,61,-5,174)
Block(-6,61,-4,174)
Block(-6,61,-3,174)
Block(-6,61,-2,174)
Block(-6,61,-1,174)
Block(-6,61,0,174)
Block(-6,61,1,174)
Block(-6,61,2,174)
Block(-6,61,3,174)
Block(-6,61,4,174)
Block(-6,61,5,174)
Block(-6,61,6,174)
Block(-6,61,7,174)
Block(-6,61,8,174)
Block(-6,62,-6,174)
Block(-6,62,-5,174)
Block(-6,62,-4,174)
Block(-6,62,-3,174)
Block(-6,62,-2,174)
Block(-6,62,-1,174)
Block(-6,62,0,174)
Block(-6,62,1,174)
Block(-6,62,2,174)
Block(-6,62,3,174)
Block(-6,62,4,174)
Block(-6,62,5,174)
Block(-6,62,6,174)
Block(-6,62,7,174)
Block(-6,62,8,174)
Block(-6,63,-5,174)
Block(-6,63,-4,174)
Block(-6,63,-3,174)
Block(-6,63,-2,174)
Block(-6,63,-1,174)
Block(-6,63,0,174)
Block(-6,63,1,174)
Block(-6,63,2,174)
Block(-6,63,3,174)
Block(-6,63,4,174)
Block(-6,63,5,174)
Block(-6,63,6,174)
Block(-6,63,7,174)
Block(-6,63,8,174)
Block(-6,64,-4,174)
Block(-6,64,-3,174)
Block(-6,64,-2,174)
Block(-6,64,-1,174)
Block(-6,64,0,174)
Block(-6,64,1,174)
Block(-6,64,2,174)
Block(-6,64,3,174)
Block(-6,64,4,174)
Block(-6,64,5,174)
Block(-6,64,6,174)
Block(-6,64,7,174)
Block(-6,64,8,174)
Block(-6,65,-3,174)
Block(-6,65,-2,174)
Block(-6,65,-1,174)
Block(-6,65,0,174)
Block(-6,65,1,174)
Block(-6,65,2,174)
Block(-6,65,3,174)
Block(-6,65,4,174)
Block(-6,65,5,174)
Block(-6,65,6,174)
Block(-6,65,7,174)
Block(-6,65,8,174)
Block(-6,66,0,174)
Block(-6,66,1,174)
Block(-6,66,2,174)
Block(-6,66,3,174)
Block(-6,66,4,174)
Block(-6,66,5,174)
Block(-6,66,6,174)
Block(-6,66,7,174)
Block(-6,66,8,174)
Block(-6,67,1,174)
Block(-6,67,2,174)
Block(-6,67,3,174)
Block(-6,67,4,174)
Block(-6,67,5,174)
Block(-6,67,6,174)
Block(-6,67,7,174)
Block(-6,67,8,174)
Block(-6,68,4,174)
Block(-6,68,5,174)
Block(-6,68,6,174)
Block(-6,68,7,174)
Block(-6,68,8,174)
Block(-6,69,6,174)
Block(-6,69,7,174)
Block(-6,69,8,174)
Block(-6,70,7,174)
Block(-6,70,8,174)
Block(-5,10,7,174)
Block(-5,10,8,174)
Block(-5,11,5,174)
Block(-5,11,6,174)
Block(-5,11,7,174)
Block(-5,11,8,174)
Block(-5,12,4,174)
Block(-5,12,5,174)
Block(-5,12,6,174)
Block(-5,12,7,174)
Block(-5,12,8,174)
Block(-5,13,3,174)
Block(-5,13,4,174)
Block(-5,13,5,174)
Block(-5,13,6,174)
Block(-5,13,7,174)
Block(-5,13,8,174)
Block(-5,14,1,174)
Block(-5,14,2,174)
Block(-5,14,3,174)
Block(-5,14,4,174)
Block(-5,14,5,174)
Block(-5,14,6,174)
Block(-5,14,7,174)
Block(-5,14,8,174)
Block(-5,15,0,174)
Block(-5,15,1,174)
Block(-5,15,2,174)
Block(-5,15,3,174)
Block(-5,15,4,174)
Block(-5,15,5,174)
Block(-5,15,6,174)
Block(-5,15,7,174)
Block(-5,15,8,174)
Block(-5,16,-3,174)
Block(-5,16,-2,174)
Block(-5,16,-1,174)
Block(-5,16,0,174)
Block(-5,16,1,174)
Block(-5,16,2,174)
Block(-5,16,3,174)
Block(-5,16,4,174)
Block(-5,16,5,174)
Block(-5,16,6,174)
Block(-5,16,7,174)
Block(-5,16,8,174)
Block(-5,17,-5,174)
Block(-5,17,-4,174)
Block(-5,17,-3,174)
Block(-5,17,-2,174)
Block(-5,17,-1,174)
Block(-5,17,0,174)
Block(-5,17,1,174)
Block(-5,17,2,174)
Block(-5,17,3,174)
Block(-5,17,4,174)
Block(-5,17,5,174)
Block(-5,17,6,174)
Block(-5,17,7,174)
Block(-5,17,8,174)
Block(-5,18,-6,174)
Block(-5,18,-5,174)
Block(-5,18,-4,174)
Block(-5,18,-3,174)
Block(-5,18,-2,174)
Block(-5,18,-1,174)
Block(-5,18,0,174)
Block(-5,18,1,174)
Block(-5,18,2,174)
Block(-5,18,3,174)
Block(-5,18,4,174)
Block(-5,18,5,174)
Block(-5,18,6,174)
Block(-5,18,7,174)
Block(-5,18,8,174)
Block(-5,19,-6,174)
Block(-5,19,-5,174)
Block(-5,19,-4,174)
Block(-5,19,-3,174)
Block(-5,19,-2,174)
Block(-5,19,-1,174)
Block(-5,19,0,174)
Block(-5,19,1,174)
Block(-5,19,2,174)
Block(-5,19,3,174)
Block(-5,19,4,174)
Block(-5,19,5,174)
Block(-5,19,6,174)
Block(-5,19,7,174)
Block(-5,19,8,174)
Block(-5,20,-6,174)
Block(-5,20,-5,174)
Block(-5,20,-4,174)
Block(-5,20,-3,174)
Block(-5,20,-2,174)
Block(-5,20,-1,174)
Block(-5,20,0,174)
Block(-5,20,1,174)
Block(-5,20,2,174)
Block(-5,20,3,174)
Block(-5,20,4,174)
Block(-5,20,5,174)
Block(-5,20,6,174)
Block(-5,20,7,174)
Block(-5,20,8,174)
Block(-5,21,-7,174)
Block(-5,21,-6,174)
Block(-5,21,-5,174)
Block(-5,21,-4,174)
Block(-5,21,-3,174)
Block(-5,21,-2,174)
Block(-5,21,-1,174)
Block(-5,21,0,174)
Block(-5,21,1,174)
Block(-5,21,2,174)
Block(-5,21,3,174)
Block(-5,21,4,174)
Block(-5,21,5,174)
Block(-5,21,6,174)
Block(-5,21,7,174)
Block(-5,21,8,174)
Block(-5,22,-7,174)
Block(-5,22,-6,174)
Block(-5,22,-5,174)
Block(-5,22,-4,174)
Block(-5,22,-3,174)
Block(-5,22,-2,174)
Block(-5,22,-1,174)
Block(-5,22,0,174)
Block(-5,22,1,174)
Block(-5,22,2,174)
Block(-5,22,3,174)
Block(-5,22,4,174)
Block(-5,22,5,174)
Block(-5,22,6,174)
Block(-5,22,7,174)
Block(-5,22,8,174)
Block(-5,23,-7,174)
Block(-5,23,-6,174)
Block(-5,23,-5,174)
Block(-5,23,-4,174)
Block(-5,23,-3,174)
Block(-5,23,-2,174)
Block(-5,23,-1,174)
Block(-5,23,0,174)
Block(-5,23,1,174)
Block(-5,23,2,174)
Block(-5,23,3,174)
Block(-5,23,4,174)
Block(-5,23,5,174)
Block(-5,23,6,174)
Block(-5,23,7,174)
Block(-5,24,-7,174)
Block(-5,24,-6,174)
Block(-5,24,-5,174)
Block(-5,24,-4,174)
Block(-5,24,-3,174)
Block(-5,24,-2,174)
Block(-5,24,-1,174)
Block(-5,24,0,174)
Block(-5,24,1,174)
Block(-5,24,2,174)
Block(-5,24,3,174)
Block(-5,24,4,174)
Block(-5,25,-7,174)
Block(-5,25,-6,174)
Block(-5,25,-5,174)
Block(-5,25,-4,174)
Block(-5,25,-3,174)
Block(-5,25,-2,174)
Block(-5,25,-1,174)
Block(-5,25,0,174)
Block(-5,25,1,174)
Block(-5,25,2,174)
Block(-5,25,3,174)
Block(-5,26,-7,174)
Block(-5,26,-6,174)
Block(-5,26,-5,174)
Block(-5,26,-4,174)
Block(-5,26,-3,174)
Block(-5,26,-2,174)
Block(-5,26,-1,174)
Block(-5,26,0,174)
Block(-5,26,1,174)
Block(-5,26,2,174)
Block(-5,26,3,174)
Block(-5,26,4,174)
Block(-5,27,-7,174)
Block(-5,27,-6,174)
Block(-5,27,-5,174)
Block(-5,27,-4,174)
Block(-5,27,-3,174)
Block(-5,27,-2,174)
Block(-5,27,-1,174)
Block(-5,27,0,174)
Block(-5,27,1,174)
Block(-5,27,2,174)
Block(-5,27,3,174)
Block(-5,27,4,174)
Block(-5,28,-7,174)
Block(-5,28,-6,174)
Block(-5,28,-5,174)
Block(-5,28,-4,174)
Block(-5,28,-3,174)
Block(-5,28,-2,174)
Block(-5,28,-1,174)
Block(-5,28,0,174)
Block(-5,28,1,174)
Block(-5,28,2,174)
Block(-5,28,3,174)
Block(-5,28,4,174)
Block(-5,28,5,174)
Block(-5,29,-7,174)
Block(-5,29,-6,174)
Block(-5,29,-5,174)
Block(-5,29,-4,174)
Block(-5,29,-3,174)
Block(-5,29,-2,174)
Block(-5,29,-1,174)
Block(-5,29,0,174)
Block(-5,29,1,174)
Block(-5,29,2,174)
Block(-5,29,3,174)
Block(-5,29,4,174)
Block(-5,29,5,174)
Block(-5,29,6,174)
Block(-5,30,-7,174)
Block(-5,30,-6,174)
Block(-5,30,-5,174)
Block(-5,30,-4,174)
Block(-5,30,-3,174)
Block(-5,30,-2,174)
Block(-5,30,-1,174)
Block(-5,30,0,174)
Block(-5,30,1,174)
Block(-5,30,2,174)
Block(-5,30,3,174)
Block(-5,30,4,174)
Block(-5,30,5,174)
Block(-5,30,6,174)
Block(-5,30,7,174)
Block(-5,31,-7,174)
Block(-5,31,-6,174)
Block(-5,31,-5,174)
Block(-5,31,-4,174)
Block(-5,31,-3,174)
Block(-5,31,-2,174)
Block(-5,31,-1,174)
Block(-5,31,0,174)
Block(-5,31,1,174)
Block(-5,31,2,174)
Block(-5,31,3,174)
Block(-5,31,4,174)
Block(-5,31,5,174)
Block(-5,31,6,174)
Block(-5,31,7,174)
Block(-5,32,-7,174)
Block(-5,32,-6,174)
Block(-5,32,-5,174)
Block(-5,32,-4,174)
Block(-5,32,-3,174)
Block(-5,32,-2,174)
Block(-5,32,-1,174)
Block(-5,32,0,174)
Block(-5,32,1,174)
Block(-5,32,2,174)
Block(-5,32,3,174)
Block(-5,32,4,174)
Block(-5,32,5,174)
Block(-5,32,6,174)
Block(-5,32,7,174)
Block(-5,33,-7,174)
Block(-5,33,-6,174)
Block(-5,33,-5,174)
Block(-5,33,-4,174)
Block(-5,33,-3,174)
Block(-5,33,-2,174)
Block(-5,33,-1,174)
Block(-5,33,0,174)
Block(-5,33,1,174)
Block(-5,33,2,174)
Block(-5,33,3,174)
Block(-5,33,4,174)
Block(-5,33,5,174)
Block(-5,33,6,174)
Block(-5,33,7,174)
Block(-5,33,8,174)
Block(-5,34,-7,174)
Block(-5,34,-6,174)
Block(-5,34,-5,174)
Block(-5,34,-4,174)
Block(-5,34,-3,174)
Block(-5,34,-2,174)
Block(-5,34,-1,174)
Block(-5,34,0,174)
Block(-5,34,1,174)
Block(-5,34,2,174)
Block(-5,34,3,174)
Block(-5,34,4,174)
Block(-5,34,5,174)
Block(-5,34,6,174)
Block(-5,34,7,174)
Block(-5,34,8,174)
Block(-5,35,-7,174)
Block(-5,35,-6,174)
Block(-5,35,-5,174)
Block(-5,35,-4,174)
Block(-5,35,-3,174)
Block(-5,35,-2,174)
Block(-5,35,-1,174)
Block(-5,35,0,174)
Block(-5,35,1,174)
Block(-5,35,2,174)
Block(-5,35,3,174)
Block(-5,35,4,174)
Block(-5,35,5,174)
Block(-5,35,6,174)
Block(-5,35,7,174)
Block(-5,35,8,174)
Block(-5,36,-7,174)
Block(-5,36,-6,174)
Block(-5,36,-5,174)
Block(-5,36,-4,174)
Block(-5,36,-3,174)
Block(-5,36,-2,174)
Block(-5,36,-1,174)
Block(-5,36,0,174)
Block(-5,36,1,174)
Block(-5,36,2,174)
Block(-5,36,3,174)
Block(-5,36,4,174)
Block(-5,36,5,174)
Block(-5,36,6,174)
Block(-5,36,7,174)
Block(-5,36,8,174)
Block(-5,37,-7,174)
Block(-5,37,-6,174)
Block(-5,37,-5,174)
Block(-5,37,-4,174)
Block(-5,37,-3,174)
Block(-5,37,-2,174)
Block(-5,37,-1,174)
Block(-5,37,0,174)
Block(-5,37,1,174)
Block(-5,37,2,174)
Block(-5,37,3,174)
Block(-5,37,4,174)
Block(-5,37,5,174)
Block(-5,37,6,174)
Block(-5,37,7,174)
Block(-5,38,-7,174)
Block(-5,38,-6,174)
Block(-5,38,-5,174)
Block(-5,38,-4,174)
Block(-5,38,-3,174)
Block(-5,38,-2,174)
Block(-5,38,-1,174)
Block(-5,38,0,174)
Block(-5,38,1,174)
Block(-5,38,2,174)
Block(-5,38,3,174)
Block(-5,38,4,174)
Block(-5,38,5,174)
Block(-5,38,6,174)
Block(-5,38,7,174)
Block(-5,39,-7,174)
Block(-5,39,-6,174)
Block(-5,39,-5,174)
Block(-5,39,-4,174)
Block(-5,39,-3,174)
Block(-5,39,-2,174)
Block(-5,39,-1,174)
Block(-5,39,0,174)
Block(-5,39,1,174)
Block(-5,39,2,174)
Block(-5,39,3,174)
Block(-5,39,4,174)
Block(-5,39,5,174)
Block(-5,39,6,174)
Block(-5,39,7,174)
Block(-5,39,8,174)
Block(-5,40,-7,174)
Block(-5,40,-6,174)
Block(-5,40,-5,174)
Block(-5,40,-4,174)
Block(-5,40,-3,174)
Block(-5,40,-2,174)
Block(-5,40,-1,174)
Block(-5,40,0,174)
Block(-5,40,1,174)
Block(-5,40,2,174)
Block(-5,40,3,174)
Block(-5,40,4,174)
Block(-5,40,5,174)
Block(-5,40,6,174)
Block(-5,40,7,174)
Block(-5,40,8,174)
Block(-5,41,-7,174)
Block(-5,41,-6,174)
Block(-5,41,-5,174)
Block(-5,41,-4,174)
Block(-5,41,-3,174)
Block(-5,41,-2,174)
Block(-5,41,-1,174)
Block(-5,41,0,174)
Block(-5,41,1,174)
Block(-5,41,2,174)
Block(-5,41,3,174)
Block(-5,41,4,174)
Block(-5,41,5,174)
Block(-5,41,6,174)
Block(-5,41,7,174)
Block(-5,42,-7,174)
Block(-5,42,-6,174)
Block(-5,42,-5,174)
Block(-5,42,-4,174)
Block(-5,42,-3,174)
Block(-5,42,-2,174)
Block(-5,42,-1,174)
Block(-5,42,0,174)
Block(-5,42,1,174)
Block(-5,42,2,174)
Block(-5,42,3,174)
Block(-5,42,4,174)
Block(-5,42,5,174)
Block(-5,42,6,174)
Block(-5,43,-7,174)
Block(-5,43,-6,174)
Block(-5,43,-5,174)
Block(-5,43,-4,174)
Block(-5,43,-3,174)
Block(-5,43,-2,174)
Block(-5,43,-1,174)
Block(-5,43,0,174)
Block(-5,43,1,174)
Block(-5,43,2,174)
Block(-5,43,3,174)
Block(-5,43,4,174)
Block(-5,43,5,174)
Block(-5,43,6,174)
Block(-5,44,-7,174)
Block(-5,44,-6,174)
Block(-5,44,-5,174)
Block(-5,44,-4,174)
Block(-5,44,-3,174)
Block(-5,44,-2,174)
Block(-5,44,-1,174)
Block(-5,44,0,174)
Block(-5,44,1,174)
Block(-5,44,2,174)
Block(-5,44,3,174)
Block(-5,44,4,174)
Block(-5,44,5,174)
Block(-5,44,6,174)
Block(-5,45,-7,174)
Block(-5,45,-6,174)
Block(-5,45,-5,174)
Block(-5,45,-4,174)
Block(-5,45,-3,174)
Block(-5,45,-2,174)
Block(-5,45,-1,174)
Block(-5,45,0,174)
Block(-5,45,1,174)
Block(-5,45,2,174)
Block(-5,45,3,174)
Block(-5,45,4,174)
Block(-5,45,5,174)
Block(-5,45,6,174)
Block(-5,46,-7,174)
Block(-5,46,-6,174)
Block(-5,46,-5,174)
Block(-5,46,-4,174)
Block(-5,46,-3,174)
Block(-5,46,-2,174)
Block(-5,46,-1,174)
Block(-5,46,0,174)
Block(-5,46,1,174)
Block(-5,46,2,174)
Block(-5,46,3,174)
Block(-5,46,4,174)
Block(-5,46,5,174)
Block(-5,46,6,174)
Block(-5,47,-7,174)
Block(-5,47,-6,174)
Block(-5,47,-5,174)
Block(-5,47,-4,174)
Block(-5,47,-3,174)
Block(-5,47,-2,174)
Block(-5,47,-1,174)
Block(-5,47,0,174)
Block(-5,47,1,174)
Block(-5,47,2,174)
Block(-5,47,3,174)
Block(-5,47,4,174)
Block(-5,47,5,174)
Block(-5,47,6,174)
Block(-5,47,7,174)
Block(-5,48,-7,174)
Block(-5,48,-6,174)
Block(-5,48,-5,174)
Block(-5,48,-4,174)
Block(-5,48,-3,174)
Block(-5,48,-2,174)
Block(-5,48,-1,174)
Block(-5,48,0,174)
Block(-5,48,1,174)
Block(-5,48,2,174)
Block(-5,48,3,174)
Block(-5,48,4,174)
Block(-5,48,5,174)
Block(-5,48,6,174)
Block(-5,49,-7,174)
Block(-5,49,-6,174)
Block(-5,49,-5,174)
Block(-5,49,-4,174)
Block(-5,49,-3,174)
Block(-5,49,-2,174)
Block(-5,49,-1,174)
Block(-5,49,0,174)
Block(-5,49,1,174)
Block(-5,49,2,174)
Block(-5,49,3,174)
Block(-5,49,4,174)
Block(-5,49,5,174)
Block(-5,49,6,174)
Block(-5,50,-7,174)
Block(-5,50,-6,174)
Block(-5,50,-5,174)
Block(-5,50,-4,174)
Block(-5,50,-3,174)
Block(-5,50,-2,174)
Block(-5,50,-1,174)
Block(-5,50,0,174)
Block(-5,50,1,174)
Block(-5,50,2,174)
Block(-5,50,3,174)
Block(-5,50,4,174)
Block(-5,50,5,174)
Block(-5,50,6,174)
Block(-5,50,7,174)
Block(-5,51,-7,174)
Block(-5,51,-6,174)
Block(-5,51,-5,174)
Block(-5,51,-4,174)
Block(-5,51,-3,174)
Block(-5,51,-2,174)
Block(-5,51,-1,174)
Block(-5,51,0,174)
Block(-5,51,1,174)
Block(-5,51,2,174)
Block(-5,51,3,174)
Block(-5,51,4,174)
Block(-5,51,5,174)
Block(-5,51,6,174)
Block(-5,51,7,174)
Block(-5,52,-7,174)
Block(-5,52,-6,174)
Block(-5,52,-5,174)
Block(-5,52,-4,174)
Block(-5,52,-3,174)
Block(-5,52,-2,174)
Block(-5,52,-1,174)
Block(-5,52,0,174)
Block(-5,52,1,174)
Block(-5,52,2,174)
Block(-5,52,3,174)
Block(-5,52,4,174)
Block(-5,52,5,174)
Block(-5,52,6,174)
Block(-5,53,-7,174)
Block(-5,53,-6,174)
Block(-5,53,-5,174)
Block(-5,53,-4,174)
Block(-5,53,-3,174)
Block(-5,53,-2,174)
Block(-5,53,-1,174)
Block(-5,53,0,174)
Block(-5,53,1,174)
Block(-5,53,2,174)
Block(-5,53,3,174)
Block(-5,53,4,174)
Block(-5,53,5,174)
Block(-5,54,-7,174)
Block(-5,54,-6,174)
Block(-5,54,-5,174)
Block(-5,54,-4,174)
Block(-5,54,-3,174)
Block(-5,54,-2,174)
Block(-5,54,-1,174)
Block(-5,54,0,174)
Block(-5,54,1,174)
Block(-5,54,2,174)
Block(-5,54,3,174)
Block(-5,54,4,174)
Block(-5,55,-7,174)
Block(-5,55,-6,174)
Block(-5,55,-5,174)
Block(-5,55,-4,174)
Block(-5,55,-3,174)
Block(-5,55,-2,174)
Block(-5,55,-1,174)
Block(-5,55,0,174)
Block(-5,55,1,174)
Block(-5,55,2,174)
Block(-5,55,3,174)
Block(-5,56,-7,174)
Block(-5,56,-6,174)
Block(-5,56,-5,174)
Block(-5,56,-4,174)
Block(-5,56,-3,174)
Block(-5,56,-2,174)
Block(-5,56,-1,174)
Block(-5,56,0,174)
Block(-5,56,1,174)
Block(-5,56,2,174)
Block(-5,56,3,174)
Block(-5,57,-7,174)
Block(-5,57,-6,174)
Block(-5,57,-5,174)
Block(-5,57,-4,174)
Block(-5,57,-3,174)
Block(-5,57,-2,174)
Block(-5,57,-1,174)
Block(-5,57,0,174)
Block(-5,57,1,174)
Block(-5,57,2,174)
Block(-5,57,3,174)
Block(-5,58,-7,174)
Block(-5,58,-6,174)
Block(-5,58,-5,174)
Block(-5,58,-4,174)
Block(-5,58,-3,174)
Block(-5,58,-2,174)
Block(-5,58,-1,174)
Block(-5,58,0,174)
Block(-5,58,1,174)
Block(-5,58,2,174)
Block(-5,58,3,174)
Block(-5,58,4,174)
Block(-5,58,5,174)
Block(-5,58,6,174)
Block(-5,58,7,174)
Block(-5,59,-7,174)
Block(-5,59,-6,174)
Block(-5,59,-5,174)
Block(-5,59,-4,174)
Block(-5,59,-3,174)
Block(-5,59,-2,174)
Block(-5,59,-1,174)
Block(-5,59,0,174)
Block(-5,59,1,174)
Block(-5,59,2,174)
Block(-5,59,3,174)
Block(-5,59,4,174)
Block(-5,59,5,174)
Block(-5,59,6,174)
Block(-5,59,7,174)
Block(-5,59,8,174)
Block(-5,60,-7,174)
Block(-5,60,-6,174)
Block(-5,60,-5,174)
Block(-5,60,-4,174)
Block(-5,60,-3,174)
Block(-5,60,-2,174)
Block(-5,60,-1,174)
Block(-5,60,0,174)
Block(-5,60,1,174)
Block(-5,60,2,174)
Block(-5,60,3,174)
Block(-5,60,4,174)
Block(-5,60,5,174)
Block(-5,60,6,174)
Block(-5,60,7,174)
Block(-5,60,8,174)
Block(-5,61,-7,174)
Block(-5,61,-6,174)
Block(-5,61,-5,174)
Block(-5,61,-4,174)
Block(-5,61,-3,174)
Block(-5,61,-2,174)
Block(-5,61,-1,174)
Block(-5,61,0,174)
Block(-5,61,1,174)
Block(-5,61,2,174)
Block(-5,61,3,174)
Block(-5,61,4,174)
Block(-5,61,5,174)
Block(-5,61,6,174)
Block(-5,61,7,174)
Block(-5,61,8,174)
Block(-5,62,-6,174)
Block(-5,62,-5,174)
Block(-5,62,-4,174)
Block(-5,62,-3,174)
Block(-5,62,-2,174)
Block(-5,62,-1,174)
Block(-5,62,0,174)
Block(-5,62,1,174)
Block(-5,62,2,174)
Block(-5,62,3,174)
Block(-5,62,4,174)
Block(-5,62,5,174)
Block(-5,62,6,174)
Block(-5,62,7,174)
Block(-5,62,8,174)
Block(-5,63,-6,174)
Block(-5,63,-5,174)
Block(-5,63,-4,174)
Block(-5,63,-3,174)
Block(-5,63,-2,174)
Block(-5,63,-1,174)
Block(-5,63,0,174)
Block(-5,63,1,174)
Block(-5,63,2,174)
Block(-5,63,3,174)
Block(-5,63,4,174)
Block(-5,63,5,174)
Block(-5,63,6,174)
Block(-5,63,7,174)
Block(-5,63,8,174)
Block(-5,64,-5,174)
Block(-5,64,-4,174)
Block(-5,64,-3,174)
Block(-5,64,-2,174)
Block(-5,64,-1,174)
Block(-5,64,0,174)
Block(-5,64,1,174)
Block(-5,64,2,174)
Block(-5,64,3,174)
Block(-5,64,4,174)
Block(-5,64,5,174)
Block(-5,64,6,174)
Block(-5,64,7,174)
Block(-5,64,8,174)
Block(-5,65,-3,174)
Block(-5,65,-2,174)
Block(-5,65,-1,174)
Block(-5,65,0,174)
Block(-5,65,1,174)
Block(-5,65,2,174)
Block(-5,65,3,174)
Block(-5,65,4,174)
Block(-5,65,5,174)
Block(-5,65,6,174)
Block(-5,65,7,174)
Block(-5,65,8,174)
Block(-5,66,0,174)
Block(-5,66,1,174)
Block(-5,66,2,174)
Block(-5,66,3,174)
Block(-5,66,4,174)
Block(-5,66,5,174)
Block(-5,66,6,174)
Block(-5,66,7,174)
Block(-5,66,8,174)
Block(-5,67,1,174)
Block(-5,67,2,174)
Block(-5,67,3,174)
Block(-5,67,4,174)
Block(-5,67,5,174)
Block(-5,67,6,174)
Block(-5,67,7,174)
Block(-5,67,8,174)
Block(-5,68,3,174)
Block(-5,68,4,174)
Block(-5,68,5,174)
Block(-5,68,6,174)
Block(-5,68,7,174)
Block(-5,68,8,174)
Block(-5,69,4,174)
Block(-5,69,5,174)
Block(-5,69,6,174)
Block(-5,69,7,174)
Block(-5,69,8,174)
Block(-5,70,5,174)
Block(-5,70,6,174)
Block(-5,70,7,174)
Block(-5,70,8,174)
Block(-5,71,7,174)
Block(-5,71,8,174)
Block(-4,9,7,174)
Block(-4,9,8,174)
Block(-4,10,6,174)
Block(-4,10,7,174)
Block(-4,10,8,174)
Block(-4,11,5,174)
Block(-4,11,6,174)
Block(-4,11,7,174)
Block(-4,11,8,174)
Block(-4,12,4,174)
Block(-4,12,5,174)
Block(-4,12,6,174)
Block(-4,12,7,174)
Block(-4,12,8,174)
Block(-4,13,3,174)
Block(-4,13,4,174)
Block(-4,13,5,174)
Block(-4,13,6,174)
Block(-4,13,7,174)
Block(-4,13,8,174)
Block(-4,14,0,174)
Block(-4,14,1,174)
Block(-4,14,2,174)
Block(-4,14,3,174)
Block(-4,14,4,174)
Block(-4,14,5,174)
Block(-4,14,6,174)
Block(-4,14,7,174)
Block(-4,14,8,174)
Block(-4,15,-1,174)
Block(-4,15,0,174)
Block(-4,15,1,174)
Block(-4,15,2,174)
Block(-4,15,3,174)
Block(-4,15,4,174)
Block(-4,15,5,174)
Block(-4,15,6,174)
Block(-4,15,7,174)
Block(-4,15,8,174)
Block(-4,16,-3,174)
Block(-4,16,-2,174)
Block(-4,16,-1,174)
Block(-4,16,0,174)
Block(-4,16,1,174)
Block(-4,16,2,174)
Block(-4,16,3,174)
Block(-4,16,4,174)
Block(-4,16,5,174)
Block(-4,16,6,174)
Block(-4,16,7,174)
Block(-4,16,8,174)
Block(-4,17,-5,174)
Block(-4,17,-4,174)
Block(-4,17,-3,174)
Block(-4,17,-2,174)
Block(-4,17,-1,174)
Block(-4,17,0,174)
Block(-4,17,1,174)
Block(-4,17,2,174)
Block(-4,17,3,174)
Block(-4,17,4,174)
Block(-4,17,5,174)
Block(-4,17,6,174)
Block(-4,17,7,174)
Block(-4,17,8,174)
Block(-4,18,-6,174)
Block(-4,18,-5,174)
Block(-4,18,-4,174)
Block(-4,18,-3,174)
Block(-4,18,-2,174)
Block(-4,18,-1,174)
Block(-4,18,0,174)
Block(-4,18,1,174)
Block(-4,18,2,174)
Block(-4,18,3,174)
Block(-4,18,4,174)
Block(-4,18,5,174)
Block(-4,18,6,174)
Block(-4,18,7,174)
Block(-4,18,8,174)
Block(-4,19,-7,174)
Block(-4,19,-6,174)
Block(-4,19,-5,174)
Block(-4,19,-4,174)
Block(-4,19,-3,174)
Block(-4,19,-2,174)
Block(-4,19,-1,174)
Block(-4,19,0,174)
Block(-4,19,1,174)
Block(-4,19,2,174)
Block(-4,19,3,174)
Block(-4,19,4,174)
Block(-4,19,5,174)
Block(-4,19,6,174)
Block(-4,19,7,174)
Block(-4,19,8,174)
Block(-4,20,-7,174)
Block(-4,20,-6,174)
Block(-4,20,-5,174)
Block(-4,20,-4,174)
Block(-4,20,-3,174)
Block(-4,20,-2,174)
Block(-4,20,-1,174)
Block(-4,20,0,174)
Block(-4,20,1,174)
Block(-4,20,2,174)
Block(-4,20,3,174)
Block(-4,20,4,174)
Block(-4,20,5,174)
Block(-4,20,6,174)
Block(-4,20,7,174)
Block(-4,20,8,174)
Block(-4,21,-7,174)
Block(-4,21,-6,174)
Block(-4,21,-5,174)
Block(-4,21,-4,174)
Block(-4,21,-3,174)
Block(-4,21,-2,174)
Block(-4,21,-1,174)
Block(-4,21,0,174)
Block(-4,21,1,174)
Block(-4,21,2,174)
Block(-4,21,3,174)
Block(-4,21,4,174)
Block(-4,21,5,174)
Block(-4,21,6,174)
Block(-4,21,7,174)
Block(-4,21,8,174)
Block(-4,22,-7,174)
Block(-4,22,-6,174)
Block(-4,22,-5,174)
Block(-4,22,-4,174)
Block(-4,22,-3,174)
Block(-4,22,-2,174)
Block(-4,22,-1,174)
Block(-4,22,0,174)
Block(-4,22,1,174)
Block(-4,22,2,174)
Block(-4,22,3,174)
Block(-4,22,4,174)
Block(-4,22,5,174)
Block(-4,22,6,174)
Block(-4,22,7,174)
Block(-4,22,8,174)
Block(-4,23,-7,174)
Block(-4,23,-6,174)
Block(-4,23,-5,174)
Block(-4,23,-4,174)
Block(-4,23,-3,174)
Block(-4,23,-2,174)
Block(-4,23,-1,174)
Block(-4,23,0,174)
Block(-4,23,1,174)
Block(-4,23,2,174)
Block(-4,23,3,174)
Block(-4,23,4,174)
Block(-4,23,5,174)
Block(-4,23,6,174)
Block(-4,24,-7,174)
Block(-4,24,-6,174)
Block(-4,24,-5,174)
Block(-4,24,-4,174)
Block(-4,24,-3,174)
Block(-4,24,-2,174)
Block(-4,24,-1,174)
Block(-4,24,0,174)
Block(-4,24,1,174)
Block(-4,24,2,174)
Block(-4,24,3,174)
Block(-4,25,-7,174)
Block(-4,25,-6,174)
Block(-4,25,-5,174)
Block(-4,25,-4,174)
Block(-4,25,-3,174)
Block(-4,25,-2,174)
Block(-4,25,-1,174)
Block(-4,25,0,174)
Block(-4,25,1,174)
Block(-4,25,2,174)
Block(-4,25,3,174)
Block(-4,26,-7,174)
Block(-4,26,-6,174)
Block(-4,26,-5,174)
Block(-4,26,-4,174)
Block(-4,26,-3,174)
Block(-4,26,-2,174)
Block(-4,26,-1,174)
Block(-4,26,0,174)
Block(-4,26,1,174)
Block(-4,26,2,174)
Block(-4,27,-7,174)
Block(-4,27,-6,174)
Block(-4,27,-5,174)
Block(-4,27,-4,174)
Block(-4,27,-3,174)
Block(-4,27,-2,174)
Block(-4,27,-1,174)
Block(-4,27,0,174)
Block(-4,27,1,174)
Block(-4,27,2,174)
Block(-4,27,3,174)
Block(-4,28,-7,174)
Block(-4,28,-6,174)
Block(-4,28,-5,174)
Block(-4,28,-4,174)
Block(-4,28,-3,174)
Block(-4,28,-2,174)
Block(-4,28,-1,174)
Block(-4,28,0,174)
Block(-4,28,1,174)
Block(-4,28,2,174)
Block(-4,28,3,174)
Block(-4,28,4,174)
Block(-4,29,-7,174)
Block(-4,29,-6,174)
Block(-4,29,-5,174)
Block(-4,29,-4,174)
Block(-4,29,-3,174)
Block(-4,29,-2,174)
Block(-4,29,-1,174)
Block(-4,29,0,174)
Block(-4,29,1,174)
Block(-4,29,2,174)
Block(-4,29,3,174)
Block(-4,29,4,174)
Block(-4,29,5,174)
Block(-4,30,-7,174)
Block(-4,30,-6,174)
Block(-4,30,-5,174)
Block(-4,30,-4,174)
Block(-4,30,-3,174)
Block(-4,30,-2,174)
Block(-4,30,-1,174)
Block(-4,30,0,174)
Block(-4,30,1,174)
Block(-4,30,2,174)
Block(-4,30,3,174)
Block(-4,30,4,174)
Block(-4,30,5,174)
Block(-4,31,-7,174)
Block(-4,31,-6,174)
Block(-4,31,-5,174)
Block(-4,31,-4,174)
Block(-4,31,-3,174)
Block(-4,31,-2,174)
Block(-4,31,-1,174)
Block(-4,31,0,174)
Block(-4,31,1,174)
Block(-4,31,2,174)
Block(-4,31,3,174)
Block(-4,31,4,174)
Block(-4,31,5,174)
Block(-4,32,-7,174)
Block(-4,32,-6,174)
Block(-4,32,-5,174)
Block(-4,32,-4,174)
Block(-4,32,-3,174)
Block(-4,32,-2,174)
Block(-4,32,-1,174)
Block(-4,32,0,174)
Block(-4,32,1,174)
Block(-4,32,2,174)
Block(-4,32,3,174)
Block(-4,32,4,174)
Block(-4,32,5,174)
Block(-4,33,-7,174)
Block(-4,33,-6,174)
Block(-4,33,-5,174)
Block(-4,33,-4,174)
Block(-4,33,-3,174)
Block(-4,33,-2,174)
Block(-4,33,-1,174)
Block(-4,33,0,174)
Block(-4,33,1,174)
Block(-4,33,2,174)
Block(-4,33,3,174)
Block(-4,33,4,174)
Block(-4,33,5,174)
Block(-4,33,6,174)
Block(-4,34,-7,174)
Block(-4,34,-6,174)
Block(-4,34,-5,174)
Block(-4,34,-4,174)
Block(-4,34,-3,174)
Block(-4,34,-2,174)
Block(-4,34,-1,174)
Block(-4,34,0,174)
Block(-4,34,1,174)
Block(-4,34,2,174)
Block(-4,34,3,174)
Block(-4,34,4,174)
Block(-4,34,5,174)
Block(-4,34,6,174)
Block(-4,35,-7,174)
Block(-4,35,-6,174)
Block(-4,35,-5,174)
Block(-4,35,-4,174)
Block(-4,35,-3,174)
Block(-4,35,-2,174)
Block(-4,35,-1,174)
Block(-4,35,0,174)
Block(-4,35,1,174)
Block(-4,35,2,174)
Block(-4,35,3,174)
Block(-4,35,4,174)
Block(-4,35,5,174)
Block(-4,35,6,174)
Block(-4,35,7,174)
Block(-4,36,-7,174)
Block(-4,36,-6,174)
Block(-4,36,-5,174)
Block(-4,36,-4,174)
Block(-4,36,-3,174)
Block(-4,36,-2,174)
Block(-4,36,-1,174)
Block(-4,36,0,174)
Block(-4,36,1,174)
Block(-4,36,2,174)
Block(-4,36,3,174)
Block(-4,36,4,174)
Block(-4,36,5,174)
Block(-4,36,6,174)
Block(-4,36,7,174)
Block(-4,36,8,174)
Block(-4,37,-7,174)
Block(-4,37,-6,174)
Block(-4,37,-5,174)
Block(-4,37,-4,174)
Block(-4,37,-3,174)
Block(-4,37,-2,174)
Block(-4,37,-1,174)
Block(-4,37,0,174)
Block(-4,37,1,174)
Block(-4,37,2,174)
Block(-4,37,3,174)
Block(-4,37,4,174)
Block(-4,37,5,174)
Block(-4,37,6,174)
Block(-4,37,7,174)
Block(-4,38,-7,174)
Block(-4,38,-6,174)
Block(-4,38,-5,174)
Block(-4,38,-4,174)
Block(-4,38,-3,174)
Block(-4,38,-2,174)
Block(-4,38,-1,174)
Block(-4,38,0,174)
Block(-4,38,1,174)
Block(-4,38,2,174)
Block(-4,38,3,174)
Block(-4,38,4,174)
Block(-4,38,5,174)
Block(-4,38,6,174)
Block(-4,38,7,174)
Block(-4,39,-7,174)
Block(-4,39,-6,174)
Block(-4,39,-5,174)
Block(-4,39,-4,174)
Block(-4,39,-3,174)
Block(-4,39,-2,174)
Block(-4,39,-1,174)
Block(-4,39,0,174)
Block(-4,39,1,174)
Block(-4,39,2,174)
Block(-4,39,3,174)
Block(-4,39,4,174)
Block(-4,39,5,174)
Block(-4,39,6,174)
Block(-4,39,7,174)
Block(-4,40,-7,174)
Block(-4,40,-6,174)
Block(-4,40,-5,174)
Block(-4,40,-4,174)
Block(-4,40,-3,174)
Block(-4,40,-2,174)
Block(-4,40,-1,174)
Block(-4,40,0,174)
Block(-4,40,1,174)
Block(-4,40,2,174)
Block(-4,40,3,174)
Block(-4,40,4,174)
Block(-4,40,5,174)
Block(-4,40,6,174)
Block(-4,40,7,174)
Block(-4,41,-7,174)
Block(-4,41,-6,174)
Block(-4,41,-5,174)
Block(-4,41,-4,174)
Block(-4,41,-3,174)
Block(-4,41,-2,174)
Block(-4,41,-1,174)
Block(-4,41,0,174)
Block(-4,41,1,174)
Block(-4,41,2,174)
Block(-4,41,3,174)
Block(-4,41,4,174)
Block(-4,41,5,174)
Block(-4,41,6,174)
Block(-4,42,-7,174)
Block(-4,42,-6,174)
Block(-4,42,-5,174)
Block(-4,42,-4,174)
Block(-4,42,-3,174)
Block(-4,42,-2,174)
Block(-4,42,-1,174)
Block(-4,42,0,174)
Block(-4,42,1,174)
Block(-4,42,2,174)
Block(-4,42,3,174)
Block(-4,42,4,174)
Block(-4,42,5,174)
Block(-4,42,6,174)
Block(-4,43,-7,174)
Block(-4,43,-6,174)
Block(-4,43,-5,174)
Block(-4,43,-4,174)
Block(-4,43,-3,174)
Block(-4,43,-2,174)
Block(-4,43,-1,174)
Block(-4,43,0,174)
Block(-4,43,1,174)
Block(-4,43,2,174)
Block(-4,43,3,174)
Block(-4,43,4,174)
Block(-4,43,5,174)
Block(-4,43,6,174)
Block(-4,44,-7,174)
Block(-4,44,-6,174)
Block(-4,44,-5,174)
Block(-4,44,-4,174)
Block(-4,44,-3,174)
Block(-4,44,-2,174)
Block(-4,44,-1,174)
Block(-4,44,0,174)
Block(-4,44,1,174)
Block(-4,44,2,174)
Block(-4,44,3,174)
Block(-4,44,4,174)
Block(-4,44,5,174)
Block(-4,44,6,174)
Block(-4,45,-7,174)
Block(-4,45,-6,174)
Block(-4,45,-5,174)
Block(-4,45,-4,174)
Block(-4,45,-3,174)
Block(-4,45,-2,174)
Block(-4,45,-1,174)
Block(-4,45,0,174)
Block(-4,45,1,174)
Block(-4,45,2,174)
Block(-4,45,3,174)
Block(-4,45,4,174)
Block(-4,45,5,174)
Block(-4,46,-7,174)
Block(-4,46,-6,174)
Block(-4,46,-5,174)
Block(-4,46,-4,174)
Block(-4,46,-3,174)
Block(-4,46,-2,174)
Block(-4,46,-1,174)
Block(-4,46,0,174)
Block(-4,46,1,174)
Block(-4,46,2,174)
Block(-4,46,3,174)
Block(-4,46,4,174)
Block(-4,46,5,174)
Block(-4,46,6,174)
Block(-4,47,-7,174)
Block(-4,47,-6,174)
Block(-4,47,-5,174)
Block(-4,47,-4,174)
Block(-4,47,-3,174)
Block(-4,47,-2,174)
Block(-4,47,-1,174)
Block(-4,47,0,174)
Block(-4,47,1,174)
Block(-4,47,2,174)
Block(-4,47,3,174)
Block(-4,47,4,174)
Block(-4,47,5,174)
Block(-4,48,-7,174)
Block(-4,48,-6,174)
Block(-4,48,-5,174)
Block(-4,48,-4,174)
Block(-4,48,-3,174)
Block(-4,48,-2,174)
Block(-4,48,-1,174)
Block(-4,48,0,174)
Block(-4,48,1,174)
Block(-4,48,2,174)
Block(-4,48,3,174)
Block(-4,48,4,174)
Block(-4,48,5,174)
Block(-4,49,-7,174)
Block(-4,49,-6,174)
Block(-4,49,-5,174)
Block(-4,49,-4,174)
Block(-4,49,-3,174)
Block(-4,49,-2,174)
Block(-4,49,-1,174)
Block(-4,49,0,174)
Block(-4,49,1,174)
Block(-4,49,2,174)
Block(-4,49,3,174)
Block(-4,49,4,174)
Block(-4,49,5,174)
Block(-4,50,-7,174)
Block(-4,50,-6,174)
Block(-4,50,-5,174)
Block(-4,50,-4,174)
Block(-4,50,-3,174)
Block(-4,50,-2,174)
Block(-4,50,-1,174)
Block(-4,50,0,174)
Block(-4,50,1,174)
Block(-4,50,2,174)
Block(-4,50,3,174)
Block(-4,50,4,174)
Block(-4,50,5,174)
Block(-4,51,-7,174)
Block(-4,51,-6,174)
Block(-4,51,-5,174)
Block(-4,51,-4,174)
Block(-4,51,-3,174)
Block(-4,51,-2,174)
Block(-4,51,-1,174)
Block(-4,51,0,174)
Block(-4,51,1,174)
Block(-4,51,2,174)
Block(-4,51,3,174)
Block(-4,51,4,174)
Block(-4,51,5,174)
Block(-4,52,-7,174)
Block(-4,52,-6,174)
Block(-4,52,-5,174)
Block(-4,52,-4,174)
Block(-4,52,-3,174)
Block(-4,52,-2,174)
Block(-4,52,-1,174)
Block(-4,52,0,174)
Block(-4,52,1,174)
Block(-4,52,2,174)
Block(-4,52,3,174)
Block(-4,52,4,174)
Block(-4,52,5,174)
Block(-4,53,-7,174)
Block(-4,53,-6,174)
Block(-4,53,-5,174)
Block(-4,53,-4,174)
Block(-4,53,-3,174)
Block(-4,53,-2,174)
Block(-4,53,-1,174)
Block(-4,53,0,174)
Block(-4,53,1,174)
Block(-4,53,2,174)
Block(-4,53,3,174)
Block(-4,53,4,174)
Block(-4,54,-7,174)
Block(-4,54,-6,174)
Block(-4,54,-5,174)
Block(-4,54,-4,174)
Block(-4,54,-3,174)
Block(-4,54,-2,174)
Block(-4,54,-1,174)
Block(-4,54,0,174)
Block(-4,54,1,174)
Block(-4,54,2,174)
Block(-4,54,3,174)
Block(-4,55,-7,174)
Block(-4,55,-6,174)
Block(-4,55,-5,174)
Block(-4,55,-4,174)
Block(-4,55,-3,174)
Block(-4,55,-2,174)
Block(-4,55,-1,174)
Block(-4,55,0,174)
Block(-4,55,1,174)
Block(-4,55,2,174)
Block(-4,56,-7,174)
Block(-4,56,-6,174)
Block(-4,56,-5,174)
Block(-4,56,-4,174)
Block(-4,56,-3,174)
Block(-4,56,-2,174)
Block(-4,56,-1,174)
Block(-4,56,0,174)
Block(-4,56,1,174)
Block(-4,56,2,174)
Block(-4,57,-7,174)
Block(-4,57,-6,174)
Block(-4,57,-5,174)
Block(-4,57,-4,174)
Block(-4,57,-3,174)
Block(-4,57,-2,174)
Block(-4,57,-1,174)
Block(-4,57,0,174)
Block(-4,57,1,174)
Block(-4,57,2,174)
Block(-4,58,-7,174)
Block(-4,58,-6,174)
Block(-4,58,-5,174)
Block(-4,58,-4,174)
Block(-4,58,-3,174)
Block(-4,58,-2,174)
Block(-4,58,-1,174)
Block(-4,58,0,174)
Block(-4,58,1,174)
Block(-4,58,2,174)
Block(-4,58,3,174)
Block(-4,58,4,174)
Block(-4,58,5,174)
Block(-4,58,6,174)
Block(-4,59,-7,174)
Block(-4,59,-6,174)
Block(-4,59,-5,174)
Block(-4,59,-4,174)
Block(-4,59,-3,174)
Block(-4,59,-2,174)
Block(-4,59,-1,174)
Block(-4,59,0,174)
Block(-4,59,1,174)
Block(-4,59,2,174)
Block(-4,59,3,174)
Block(-4,59,4,174)
Block(-4,59,5,174)
Block(-4,59,6,174)
Block(-4,59,7,174)
Block(-4,59,8,174)
Block(-4,60,-7,174)
Block(-4,60,-6,174)
Block(-4,60,-5,174)
Block(-4,60,-4,174)
Block(-4,60,-3,174)
Block(-4,60,-2,174)
Block(-4,60,-1,174)
Block(-4,60,0,174)
Block(-4,60,1,174)
Block(-4,60,2,174)
Block(-4,60,3,174)
Block(-4,60,4,174)
Block(-4,60,5,174)
Block(-4,60,6,174)
Block(-4,60,7,174)
Block(-4,60,8,174)
Block(-4,61,-7,174)
Block(-4,61,-6,174)
Block(-4,61,-5,174)
Block(-4,61,-4,174)
Block(-4,61,-3,174)
Block(-4,61,-2,174)
Block(-4,61,-1,174)
Block(-4,61,0,174)
Block(-4,61,1,174)
Block(-4,61,2,174)
Block(-4,61,3,174)
Block(-4,61,4,174)
Block(-4,61,5,174)
Block(-4,61,6,174)
Block(-4,61,7,174)
Block(-4,61,8,174)
Block(-4,62,-7,174)
Block(-4,62,-6,174)
Block(-4,62,-5,174)
Block(-4,62,-4,174)
Block(-4,62,-3,174)
Block(-4,62,-2,174)
Block(-4,62,-1,174)
Block(-4,62,0,174)
Block(-4,62,1,174)
Block(-4,62,2,174)
Block(-4,62,3,174)
Block(-4,62,4,174)
Block(-4,62,5,174)
Block(-4,62,6,174)
Block(-4,62,7,174)
Block(-4,62,8,174)
Block(-4,63,-6,174)
Block(-4,63,-5,174)
Block(-4,63,-4,174)
Block(-4,63,-3,174)
Block(-4,63,-2,174)
Block(-4,63,-1,174)
Block(-4,63,0,174)
Block(-4,63,1,174)
Block(-4,63,2,174)
Block(-4,63,3,174)
Block(-4,63,4,174)
Block(-4,63,5,174)
Block(-4,63,6,174)
Block(-4,63,7,174)
Block(-4,63,8,174)
Block(-4,64,-5,174)
Block(-4,64,-4,174)
Block(-4,64,-3,174)
Block(-4,64,-2,174)
Block(-4,64,-1,174)
Block(-4,64,0,174)
Block(-4,64,1,174)
Block(-4,64,2,174)
Block(-4,64,3,174)
Block(-4,64,4,174)
Block(-4,64,5,174)
Block(-4,64,6,174)
Block(-4,64,7,174)
Block(-4,64,8,174)
Block(-4,65,-3,174)
Block(-4,65,-2,174)
Block(-4,65,-1,174)
Block(-4,65,0,174)
Block(-4,65,1,174)
Block(-4,65,2,174)
Block(-4,65,3,174)
Block(-4,65,4,174)
Block(-4,65,5,174)
Block(-4,65,6,174)
Block(-4,65,7,174)
Block(-4,65,8,174)
Block(-4,66,-1,174)
Block(-4,66,0,174)
Block(-4,66,1,174)
Block(-4,66,2,174)
Block(-4,66,3,174)
Block(-4,66,4,174)
Block(-4,66,5,174)
Block(-4,66,6,174)
Block(-4,66,7,174)
Block(-4,66,8,174)
Block(-4,67,0,174)
Block(-4,67,1,174)
Block(-4,67,2,174)
Block(-4,67,3,174)
Block(-4,67,4,174)
Block(-4,67,5,174)
Block(-4,67,6,174)
Block(-4,67,7,174)
Block(-4,67,8,174)
Block(-4,68,3,174)
Block(-4,68,4,174)
Block(-4,68,5,174)
Block(-4,68,6,174)
Block(-4,68,7,174)
Block(-4,68,8,174)
Block(-4,69,4,174)
Block(-4,69,5,174)
Block(-4,69,6,174)
Block(-4,69,7,174)
Block(-4,69,8,174)
Block(-4,70,5,174)
Block(-4,70,6,174)
Block(-4,70,7,174)
Block(-4,70,8,174)
Block(-4,71,6,174)
Block(-4,71,7,174)
Block(-4,71,8,174)
Block(-4,72,7,174)
Block(-4,72,8,174)
Block(-3,10,7,174)
Block(-3,10,8,174)
Block(-3,11,5,174)
Block(-3,11,6,174)
Block(-3,11,7,174)
Block(-3,11,8,174)
Block(-3,12,4,174)
Block(-3,12,5,174)
Block(-3,12,6,174)
Block(-3,12,7,174)
Block(-3,12,8,174)
Block(-3,13,3,174)
Block(-3,13,4,174)
Block(-3,13,5,174)
Block(-3,13,6,174)
Block(-3,13,7,174)
Block(-3,13,8,174)
Block(-3,14,-1,174)
Block(-3,14,0,174)
Block(-3,14,1,174)
Block(-3,14,2,174)
Block(-3,14,3,174)
Block(-3,14,4,174)
Block(-3,14,5,174)
Block(-3,14,6,174)
Block(-3,14,7,174)
Block(-3,14,8,174)
Block(-3,15,-2,174)
Block(-3,15,-1,174)
Block(-3,15,0,174)
Block(-3,15,1,174)
Block(-3,15,2,174)
Block(-3,15,3,174)
Block(-3,15,4,174)
Block(-3,15,5,174)
Block(-3,15,6,174)
Block(-3,15,7,174)
Block(-3,15,8,174)
Block(-3,16,-4,174)
Block(-3,16,-3,174)
Block(-3,16,-2,174)
Block(-3,16,-1,174)
Block(-3,16,0,174)
Block(-3,16,1,174)
Block(-3,16,2,174)
Block(-3,16,3,174)
Block(-3,16,4,174)
Block(-3,16,5,174)
Block(-3,16,6,174)
Block(-3,16,7,174)
Block(-3,16,8,174)
Block(-3,17,-6,174)
Block(-3,17,-5,174)
Block(-3,17,-4,174)
Block(-3,17,-3,174)
Block(-3,17,-2,174)
Block(-3,17,-1,174)
Block(-3,17,0,174)
Block(-3,17,1,174)
Block(-3,17,2,174)
Block(-3,17,3,174)
Block(-3,17,4,174)
Block(-3,17,5,174)
Block(-3,17,6,174)
Block(-3,17,7,174)
Block(-3,17,8,174)
Block(-3,18,-7,174)
Block(-3,18,-6,174)
Block(-3,18,-5,174)
Block(-3,18,-4,174)
Block(-3,18,-3,174)
Block(-3,18,-2,174)
Block(-3,18,-1,174)
Block(-3,18,0,174)
Block(-3,18,1,174)
Block(-3,18,2,174)
Block(-3,18,3,174)
Block(-3,18,4,174)
Block(-3,18,5,174)
Block(-3,18,6,174)
Block(-3,18,7,174)
Block(-3,18,8,174)
Block(-3,19,-7,174)
Block(-3,19,-6,174)
Block(-3,19,-5,174)
Block(-3,19,-4,174)
Block(-3,19,-3,174)
Block(-3,19,-2,174)
Block(-3,19,-1,174)
Block(-3,19,0,174)
Block(-3,19,1,174)
Block(-3,19,2,174)
Block(-3,19,3,174)
Block(-3,19,4,174)
Block(-3,19,5,174)
Block(-3,19,6,174)
Block(-3,19,7,174)
Block(-3,19,8,174)
Block(-3,20,-7,174)
Block(-3,20,-6,174)
Block(-3,20,-5,174)
Block(-3,20,-4,174)
Block(-3,20,-3,174)
Block(-3,20,-2,174)
Block(-3,20,-1,174)
Block(-3,20,0,174)
Block(-3,20,1,174)
Block(-3,20,2,174)
Block(-3,20,3,174)
Block(-3,20,4,174)
Block(-3,20,5,174)
Block(-3,20,6,174)
Block(-3,20,7,174)
Block(-3,20,8,174)
Block(-3,21,-7,174)
Block(-3,21,-6,174)
Block(-3,21,-5,174)
Block(-3,21,-4,174)
Block(-3,21,-3,174)
Block(-3,21,-2,174)
Block(-3,21,-1,174)
Block(-3,21,0,174)
Block(-3,21,1,174)
Block(-3,21,2,174)
Block(-3,21,3,174)
Block(-3,21,4,174)
Block(-3,21,5,174)
Block(-3,21,6,174)
Block(-3,21,7,174)
Block(-3,21,8,174)
Block(-3,22,-7,174)
Block(-3,22,-6,174)
Block(-3,22,-5,174)
Block(-3,22,-4,174)
Block(-3,22,-3,174)
Block(-3,22,-2,174)
Block(-3,22,-1,174)
Block(-3,22,0,174)
Block(-3,22,1,174)
Block(-3,22,2,174)
Block(-3,22,3,174)
Block(-3,22,4,174)
Block(-3,22,5,174)
Block(-3,22,6,174)
Block(-3,22,7,174)
Block(-3,22,8,174)
Block(-3,23,-7,174)
Block(-3,23,-6,174)
Block(-3,23,-5,174)
Block(-3,23,-4,174)
Block(-3,23,-3,174)
Block(-3,23,-2,174)
Block(-3,23,-1,174)
Block(-3,23,0,174)
Block(-3,23,1,174)
Block(-3,23,2,174)
Block(-3,23,3,174)
Block(-3,23,4,174)
Block(-3,24,-7,174)
Block(-3,24,-6,174)
Block(-3,24,-5,174)
Block(-3,24,-4,174)
Block(-3,24,-3,174)
Block(-3,24,-2,174)
Block(-3,24,-1,174)
Block(-3,24,0,174)
Block(-3,24,1,174)
Block(-3,25,-7,174)
Block(-3,25,-6,174)
Block(-3,25,-5,174)
Block(-3,25,-4,174)
Block(-3,25,-3,174)
Block(-3,25,-2,174)
Block(-3,25,-1,174)
Block(-3,25,0,174)
Block(-3,26,-7,174)
Block(-3,26,-6,174)
Block(-3,26,-5,174)
Block(-3,26,-4,174)
Block(-3,26,-3,174)
Block(-3,26,-2,174)
Block(-3,26,-1,174)
Block(-3,26,0,174)
Block(-3,26,1,174)
Block(-3,27,-7,174)
Block(-3,27,-6,174)
Block(-3,27,-5,174)
Block(-3,27,-4,174)
Block(-3,27,-3,174)
Block(-3,27,-2,174)
Block(-3,27,-1,174)
Block(-3,27,0,174)
Block(-3,27,1,174)
Block(-3,27,2,174)
Block(-3,28,-7,174)
Block(-3,28,-6,174)
Block(-3,28,-5,174)
Block(-3,28,-4,174)
Block(-3,28,-3,174)
Block(-3,28,-2,174)
Block(-3,28,-1,174)
Block(-3,28,0,174)
Block(-3,28,1,174)
Block(-3,28,2,174)
Block(-3,28,3,174)
Block(-3,29,-7,174)
Block(-3,29,-6,174)
Block(-3,29,-5,174)
Block(-3,29,-4,174)
Block(-3,29,-3,174)
Block(-3,29,-2,174)
Block(-3,29,-1,174)
Block(-3,29,0,174)
Block(-3,29,1,174)
Block(-3,29,2,174)
Block(-3,29,3,174)
Block(-3,29,4,174)
Block(-3,30,-7,174)
Block(-3,30,-6,174)
Block(-3,30,-5,174)
Block(-3,30,-4,174)
Block(-3,30,-3,174)
Block(-3,30,-2,174)
Block(-3,30,-1,174)
Block(-3,30,0,174)
Block(-3,30,1,174)
Block(-3,30,2,174)
Block(-3,30,3,174)
Block(-3,30,4,174)
Block(-3,31,-7,174)
Block(-3,31,-6,174)
Block(-3,31,-5,174)
Block(-3,31,-4,174)
Block(-3,31,-3,174)
Block(-3,31,-2,174)
Block(-3,31,-1,174)
Block(-3,31,0,174)
Block(-3,31,1,174)
Block(-3,31,2,174)
Block(-3,31,3,174)
Block(-3,31,4,174)
Block(-3,32,-7,174)
Block(-3,32,-6,174)
Block(-3,32,-5,174)
Block(-3,32,-4,174)
Block(-3,32,-3,174)
Block(-3,32,-2,174)
Block(-3,32,-1,174)
Block(-3,32,0,174)
Block(-3,32,1,174)
Block(-3,32,2,174)
Block(-3,32,3,174)
Block(-3,32,4,174)
Block(-3,32,5,174)
Block(-3,33,-7,174)
Block(-3,33,-6,174)
Block(-3,33,-5,174)
Block(-3,33,-4,174)
Block(-3,33,-3,174)
Block(-3,33,-2,174)
Block(-3,33,-1,174)
Block(-3,33,0,174)
Block(-3,33,1,174)
Block(-3,33,2,174)
Block(-3,33,3,174)
Block(-3,33,4,174)
Block(-3,33,5,174)
Block(-3,34,-7,174)
Block(-3,34,-6,174)
Block(-3,34,-5,174)
Block(-3,34,-4,174)
Block(-3,34,-3,174)
Block(-3,34,-2,174)
Block(-3,34,-1,174)
Block(-3,34,0,174)
Block(-3,34,1,174)
Block(-3,34,2,174)
Block(-3,34,3,174)
Block(-3,34,4,174)
Block(-3,34,5,174)
Block(-3,35,-7,174)
Block(-3,35,-6,174)
Block(-3,35,-5,174)
Block(-3,35,-4,174)
Block(-3,35,-3,174)
Block(-3,35,-2,174)
Block(-3,35,-1,174)
Block(-3,35,0,174)
Block(-3,35,1,174)
Block(-3,35,2,174)
Block(-3,35,3,174)
Block(-3,35,4,174)
Block(-3,35,5,174)
Block(-3,35,6,174)
Block(-3,36,-7,174)
Block(-3,36,-6,174)
Block(-3,36,-5,174)
Block(-3,36,-4,174)
Block(-3,36,-3,174)
Block(-3,36,-2,174)
Block(-3,36,-1,174)
Block(-3,36,0,174)
Block(-3,36,1,174)
Block(-3,36,2,174)
Block(-3,36,3,174)
Block(-3,36,4,174)
Block(-3,36,5,174)
Block(-3,36,6,174)
Block(-3,37,-7,174)
Block(-3,37,-6,174)
Block(-3,37,-5,174)
Block(-3,37,-4,174)
Block(-3,37,-3,174)
Block(-3,37,-2,174)
Block(-3,37,-1,174)
Block(-3,37,0,174)
Block(-3,37,1,174)
Block(-3,37,2,174)
Block(-3,37,3,174)
Block(-3,37,4,174)
Block(-3,37,5,174)
Block(-3,37,6,174)
Block(-3,38,-7,174)
Block(-3,38,-6,174)
Block(-3,38,-5,174)
Block(-3,38,-4,174)
Block(-3,38,-3,174)
Block(-3,38,-2,174)
Block(-3,38,-1,174)
Block(-3,38,0,174)
Block(-3,38,1,174)
Block(-3,38,2,174)
Block(-3,38,3,174)
Block(-3,38,4,174)
Block(-3,38,5,174)
Block(-3,38,6,174)
Block(-3,39,-7,174)
Block(-3,39,-6,174)
Block(-3,39,-5,174)
Block(-3,39,-4,174)
Block(-3,39,-3,174)
Block(-3,39,-2,174)
Block(-3,39,-1,174)
Block(-3,39,0,174)
Block(-3,39,1,174)
Block(-3,39,2,174)
Block(-3,39,3,174)
Block(-3,39,4,174)
Block(-3,39,5,174)
Block(-3,39,6,174)
Block(-3,40,-7,174)
Block(-3,40,-6,174)
Block(-3,40,-5,174)
Block(-3,40,-4,174)
Block(-3,40,-3,174)
Block(-3,40,-2,174)
Block(-3,40,-1,174)
Block(-3,40,0,174)
Block(-3,40,1,174)
Block(-3,40,2,174)
Block(-3,40,3,174)
Block(-3,40,4,174)
Block(-3,40,5,174)
Block(-3,40,6,174)
Block(-3,40,7,174)
Block(-3,41,-7,174)
Block(-3,41,-6,174)
Block(-3,41,-5,174)
Block(-3,41,-4,174)
Block(-3,41,-3,174)
Block(-3,41,-2,174)
Block(-3,41,-1,174)
Block(-3,41,0,174)
Block(-3,41,1,174)
Block(-3,41,2,174)
Block(-3,41,3,174)
Block(-3,41,4,174)
Block(-3,41,5,174)
Block(-3,41,6,174)
Block(-3,42,-7,174)
Block(-3,42,-6,174)
Block(-3,42,-5,174)
Block(-3,42,-4,174)
Block(-3,42,-3,174)
Block(-3,42,-2,174)
Block(-3,42,-1,174)
Block(-3,42,0,174)
Block(-3,42,1,174)
Block(-3,42,2,174)
Block(-3,42,3,174)
Block(-3,42,4,174)
Block(-3,42,5,174)
Block(-3,42,6,174)
Block(-3,43,-7,174)
Block(-3,43,-6,174)
Block(-3,43,-5,174)
Block(-3,43,-4,174)
Block(-3,43,-3,174)
Block(-3,43,-2,174)
Block(-3,43,-1,174)
Block(-3,43,0,174)
Block(-3,43,1,174)
Block(-3,43,2,174)
Block(-3,43,3,174)
Block(-3,43,4,174)
Block(-3,43,5,174)
Block(-3,43,6,174)
Block(-3,44,-7,174)
Block(-3,44,-6,174)
Block(-3,44,-5,174)
Block(-3,44,-4,174)
Block(-3,44,-3,174)
Block(-3,44,-2,174)
Block(-3,44,-1,174)
Block(-3,44,0,174)
Block(-3,44,1,174)
Block(-3,44,2,174)
Block(-3,44,3,174)
Block(-3,44,4,174)
Block(-3,44,5,174)
Block(-3,45,-7,174)
Block(-3,45,-6,174)
Block(-3,45,-5,174)
Block(-3,45,-4,174)
Block(-3,45,-3,174)
Block(-3,45,-2,174)
Block(-3,45,-1,174)
Block(-3,45,0,174)
Block(-3,45,1,174)
Block(-3,45,2,174)
Block(-3,45,3,174)
Block(-3,45,4,174)
Block(-3,46,-7,174)
Block(-3,46,-6,174)
Block(-3,46,-5,174)
Block(-3,46,-4,174)
Block(-3,46,-3,174)
Block(-3,46,-2,174)
Block(-3,46,-1,174)
Block(-3,46,0,174)
Block(-3,46,1,174)
Block(-3,46,2,174)
Block(-3,46,3,174)
Block(-3,46,4,174)
Block(-3,46,5,174)
Block(-3,47,-7,174)
Block(-3,47,-6,174)
Block(-3,47,-5,174)
Block(-3,47,-4,174)
Block(-3,47,-3,174)
Block(-3,47,-2,174)
Block(-3,47,-1,174)
Block(-3,47,0,174)
Block(-3,47,1,174)
Block(-3,47,2,174)
Block(-3,47,3,174)
Block(-3,47,4,174)
Block(-3,48,-7,174)
Block(-3,48,-6,174)
Block(-3,48,-5,174)
Block(-3,48,-4,174)
Block(-3,48,-3,174)
Block(-3,48,-2,174)
Block(-3,48,-1,174)
Block(-3,48,0,174)
Block(-3,48,1,174)
Block(-3,48,2,174)
Block(-3,48,3,174)
Block(-3,48,4,174)
Block(-3,49,-7,174)
Block(-3,49,-6,174)
Block(-3,49,-5,174)
Block(-3,49,-4,174)
Block(-3,49,-3,174)
Block(-3,49,-2,174)
Block(-3,49,-1,174)
Block(-3,49,0,174)
Block(-3,49,1,174)
Block(-3,49,2,174)
Block(-3,49,3,174)
Block(-3,49,4,174)
Block(-3,50,-7,174)
Block(-3,50,-6,174)
Block(-3,50,-5,174)
Block(-3,50,-4,174)
Block(-3,50,-3,174)
Block(-3,50,-2,174)
Block(-3,50,-1,174)
Block(-3,50,0,174)
Block(-3,50,1,174)
Block(-3,50,2,174)
Block(-3,50,3,174)
Block(-3,50,4,174)
Block(-3,51,-7,174)
Block(-3,51,-6,174)
Block(-3,51,-5,174)
Block(-3,51,-4,174)
Block(-3,51,-3,174)
Block(-3,51,-2,174)
Block(-3,51,-1,174)
Block(-3,51,0,174)
Block(-3,51,1,174)
Block(-3,51,2,174)
Block(-3,51,3,174)
Block(-3,51,4,174)
Block(-3,52,-7,174)
Block(-3,52,-6,174)
Block(-3,52,-5,174)
Block(-3,52,-4,174)
Block(-3,52,-3,174)
Block(-3,52,-2,174)
Block(-3,52,-1,174)
Block(-3,52,0,174)
Block(-3,52,1,174)
Block(-3,52,2,174)
Block(-3,52,3,174)
Block(-3,53,-7,174)
Block(-3,53,-6,174)
Block(-3,53,-5,174)
Block(-3,53,-4,174)
Block(-3,53,-3,174)
Block(-3,53,-2,174)
Block(-3,53,-1,174)
Block(-3,53,0,174)
Block(-3,53,1,174)
Block(-3,53,2,174)
Block(-3,53,3,174)
Block(-3,54,-7,174)
Block(-3,54,-6,174)
Block(-3,54,-5,174)
Block(-3,54,-4,174)
Block(-3,54,-3,174)
Block(-3,54,-2,174)
Block(-3,54,-1,174)
Block(-3,54,0,174)
Block(-3,54,1,174)
Block(-3,54,2,174)
Block(-3,55,-7,174)
Block(-3,55,-6,174)
Block(-3,55,-5,174)
Block(-3,55,-4,174)
Block(-3,55,-3,174)
Block(-3,55,-2,174)
Block(-3,55,-1,174)
Block(-3,55,0,174)
Block(-3,56,-7,174)
Block(-3,56,-6,174)
Block(-3,56,-5,174)
Block(-3,56,-4,174)
Block(-3,56,-3,174)
Block(-3,56,-2,174)
Block(-3,56,-1,174)
Block(-3,56,0,174)
Block(-3,57,-7,174)
Block(-3,57,-6,174)
Block(-3,57,-5,174)
Block(-3,57,-4,174)
Block(-3,57,-3,174)
Block(-3,57,-2,174)
Block(-3,57,-1,174)
Block(-3,57,0,174)
Block(-3,58,-7,174)
Block(-3,58,-6,174)
Block(-3,58,-5,174)
Block(-3,58,-4,174)
Block(-3,58,-3,174)
Block(-3,58,-2,174)
Block(-3,58,-1,174)
Block(-3,58,0,174)
Block(-3,58,1,174)
Block(-3,58,2,174)
Block(-3,58,6,174)
Block(-3,58,7,174)
Block(-3,59,-7,174)
Block(-3,59,-6,174)
Block(-3,59,-5,174)
Block(-3,59,-4,174)
Block(-3,59,-3,174)
Block(-3,59,-2,174)
Block(-3,59,-1,174)
Block(-3,59,0,174)
Block(-3,59,1,174)
Block(-3,59,2,174)
Block(-3,59,3,174)
Block(-3,59,4,174)
Block(-3,59,5,174)
Block(-3,59,6,174)
Block(-3,59,7,174)
Block(-3,59,8,174)
Block(-3,60,-7,174)
Block(-3,60,-6,174)
Block(-3,60,-5,174)
Block(-3,60,-4,174)
Block(-3,60,-3,174)
Block(-3,60,-2,174)
Block(-3,60,-1,174)
Block(-3,60,0,174)
Block(-3,60,1,174)
Block(-3,60,2,174)
Block(-3,60,3,174)
Block(-3,60,4,174)
Block(-3,60,5,174)
Block(-3,60,6,174)
Block(-3,60,7,174)
Block(-3,60,8,174)
Block(-3,61,-7,174)
Block(-3,61,-6,174)
Block(-3,61,-5,174)
Block(-3,61,-4,174)
Block(-3,61,-3,174)
Block(-3,61,-2,174)
Block(-3,61,-1,174)
Block(-3,61,0,174)
Block(-3,61,1,174)
Block(-3,61,2,174)
Block(-3,61,3,174)
Block(-3,61,4,174)
Block(-3,61,5,174)
Block(-3,61,6,174)
Block(-3,61,7,174)
Block(-3,61,8,174)
Block(-3,62,-7,174)
Block(-3,62,-6,174)
Block(-3,62,-5,174)
Block(-3,62,-4,174)
Block(-3,62,-3,174)
Block(-3,62,-2,174)
Block(-3,62,-1,174)
Block(-3,62,0,174)
Block(-3,62,1,174)
Block(-3,62,2,174)
Block(-3,62,3,174)
Block(-3,62,4,174)
Block(-3,62,5,174)
Block(-3,62,6,174)
Block(-3,62,7,174)
Block(-3,62,8,174)
Block(-3,63,-7,174)
Block(-3,63,-6,174)
Block(-3,63,-5,174)
Block(-3,63,-4,174)
Block(-3,63,-3,174)
Block(-3,63,-2,174)
Block(-3,63,-1,174)
Block(-3,63,0,174)
Block(-3,63,1,174)
Block(-3,63,2,174)
Block(-3,63,3,174)
Block(-3,63,4,174)
Block(-3,63,5,174)
Block(-3,63,6,174)
Block(-3,63,7,174)
Block(-3,63,8,174)
Block(-3,64,-6,174)
Block(-3,64,-5,174)
Block(-3,64,-4,174)
Block(-3,64,-3,174)
Block(-3,64,-2,174)
Block(-3,64,-1,174)
Block(-3,64,0,174)
Block(-3,64,1,174)
Block(-3,64,2,174)
Block(-3,64,3,174)
Block(-3,64,4,174)
Block(-3,64,5,174)
Block(-3,64,6,174)
Block(-3,64,7,174)
Block(-3,64,8,174)
Block(-3,65,-4,174)
Block(-3,65,-3,174)
Block(-3,65,-2,174)
Block(-3,65,-1,174)
Block(-3,65,0,174)
Block(-3,65,1,174)
Block(-3,65,2,174)
Block(-3,65,3,174)
Block(-3,65,4,174)
Block(-3,65,5,174)
Block(-3,65,6,174)
Block(-3,65,7,174)
Block(-3,65,8,174)
Block(-3,66,-2,174)
Block(-3,66,-1,174)
Block(-3,66,0,174)
Block(-3,66,1,174)
Block(-3,66,2,174)
Block(-3,66,3,174)
Block(-3,66,4,174)
Block(-3,66,5,174)
Block(-3,66,6,174)
Block(-3,66,7,174)
Block(-3,66,8,174)
Block(-3,67,-1,174)
Block(-3,67,0,174)
Block(-3,67,1,174)
Block(-3,67,2,174)
Block(-3,67,3,174)
Block(-3,67,4,174)
Block(-3,67,5,174)
Block(-3,67,6,174)
Block(-3,67,7,174)
Block(-3,67,8,174)
Block(-3,68,3,174)
Block(-3,68,4,174)
Block(-3,68,5,174)
Block(-3,68,6,174)
Block(-3,68,7,174)
Block(-3,68,8,174)
Block(-3,69,4,174)
Block(-3,69,5,174)
Block(-3,69,6,174)
Block(-3,69,7,174)
Block(-3,69,8,174)
Block(-3,70,5,174)
Block(-3,70,6,174)
Block(-3,70,7,174)
Block(-3,70,8,174)
Block(-3,71,7,174)
Block(-3,71,8,174)
Block(-2,11,5,174)
Block(-2,11,6,174)
Block(-2,11,7,174)
Block(-2,11,8,174)
Block(-2,12,4,174)
Block(-2,12,5,174)
Block(-2,12,6,174)
Block(-2,12,7,174)
Block(-2,12,8,174)
Block(-2,13,1,174)
Block(-2,13,2,174)
Block(-2,13,3,174)
Block(-2,13,4,174)
Block(-2,13,5,174)
Block(-2,13,6,174)
Block(-2,13,7,174)
Block(-2,13,8,174)
Block(-2,14,-2,174)
Block(-2,14,-1,174)
Block(-2,14,0,174)
Block(-2,14,1,174)
Block(-2,14,2,174)
Block(-2,14,3,174)
Block(-2,14,4,174)
Block(-2,14,5,174)
Block(-2,14,6,174)
Block(-2,14,7,174)
Block(-2,14,8,174)
Block(-2,15,-2,174)
Block(-2,15,-1,174)
Block(-2,15,0,174)
Block(-2,15,1,174)
Block(-2,15,2,174)
Block(-2,15,3,174)
Block(-2,15,4,174)
Block(-2,15,5,174)
Block(-2,15,6,174)
Block(-2,15,7,174)
Block(-2,15,8,174)
Block(-2,16,-5,174)
Block(-2,16,-4,174)
Block(-2,16,-3,174)
Block(-2,16,-2,174)
Block(-2,16,-1,174)
Block(-2,16,0,174)
Block(-2,16,1,174)
Block(-2,16,2,174)
Block(-2,16,3,174)
Block(-2,16,4,174)
Block(-2,16,5,174)
Block(-2,16,6,174)
Block(-2,16,7,174)
Block(-2,16,8,174)
Block(-2,17,-7,174)
Block(-2,17,-6,174)
Block(-2,17,-5,174)
Block(-2,17,-4,174)
Block(-2,17,-3,174)
Block(-2,17,-2,174)
Block(-2,17,-1,174)
Block(-2,17,0,174)
Block(-2,17,1,174)
Block(-2,17,2,174)
Block(-2,17,3,174)
Block(-2,17,4,174)
Block(-2,17,5,174)
Block(-2,17,6,174)
Block(-2,17,7,174)
Block(-2,17,8,174)
Block(-2,18,-7,174)
Block(-2,18,-6,174)
Block(-2,18,-5,174)
Block(-2,18,-4,174)
Block(-2,18,-3,174)
Block(-2,18,-2,174)
Block(-2,18,-1,174)
Block(-2,18,0,174)
Block(-2,18,1,174)
Block(-2,18,2,174)
Block(-2,18,3,174)
Block(-2,18,4,174)
Block(-2,18,5,174)
Block(-2,18,6,174)
Block(-2,18,7,174)
Block(-2,18,8,174)
Block(-2,19,-7,174)
Block(-2,19,-6,174)
Block(-2,19,-5,174)
Block(-2,19,-4,174)
Block(-2,19,-3,174)
Block(-2,19,-2,174)
Block(-2,19,-1,174)
Block(-2,19,0,174)
Block(-2,19,1,174)
Block(-2,19,2,174)
Block(-2,19,3,174)
Block(-2,19,4,174)
Block(-2,19,5,174)
Block(-2,19,6,174)
Block(-2,19,7,174)
Block(-2,19,8,174)
Block(-2,20,-7,174)
Block(-2,20,-6,174)
Block(-2,20,-5,174)
Block(-2,20,-4,174)
Block(-2,20,-3,174)
Block(-2,20,-2,174)
Block(-2,20,-1,174)
Block(-2,20,0,174)
Block(-2,20,1,174)
Block(-2,20,2,174)
Block(-2,20,3,174)
Block(-2,20,4,174)
Block(-2,20,5,174)
Block(-2,20,6,174)
Block(-2,20,7,174)
Block(-2,20,8,174)
Block(-2,21,-7,174)
Block(-2,21,-6,174)
Block(-2,21,-5,174)
Block(-2,21,-4,174)
Block(-2,21,-3,174)
Block(-2,21,-2,174)
Block(-2,21,-1,174)
Block(-2,21,1,174)
Block(-2,21,2,174)
Block(-2,21,3,174)
Block(-2,21,4,174)
Block(-2,21,5,174)
Block(-2,21,6,174)
Block(-2,21,7,174)
Block(-2,21,8,174)
Block(-2,22,-7,174)
Block(-2,22,-6,174)
Block(-2,22,-5,174)
Block(-2,22,-4,174)
Block(-2,22,-3,174)
Block(-2,22,-2,174)
Block(-2,23,-7,174)
Block(-2,23,-6,174)
Block(-2,23,-5,174)
Block(-2,23,-4,174)
Block(-2,23,-3,174)
Block(-2,23,-2,174)
Block(-2,24,-7,174)
Block(-2,24,-6,174)
Block(-2,24,-5,174)
Block(-2,24,-4,174)
Block(-2,24,-3,174)
Block(-2,25,-7,174)
Block(-2,25,-6,174)
Block(-2,25,-5,174)
Block(-2,25,-4,174)
Block(-2,25,-3,174)
Block(-2,26,-7,174)
Block(-2,26,-6,174)
Block(-2,26,-5,174)
Block(-2,26,-4,174)
Block(-2,26,-3,174)
Block(-2,27,-7,174)
Block(-2,27,-6,174)
Block(-2,27,-5,174)
Block(-2,27,-4,174)
Block(-2,27,-3,174)
Block(-2,27,-2,174)
Block(-2,28,-7,174)
Block(-2,28,-6,174)
Block(-2,28,-5,174)
Block(-2,28,-4,174)
Block(-2,28,-3,174)
Block(-2,28,-2,174)
Block(-2,28,-1,174)
Block(-2,29,-7,174)
Block(-2,29,-6,174)
Block(-2,29,-5,174)
Block(-2,29,-4,174)
Block(-2,29,-3,174)
Block(-2,29,-2,174)
Block(-2,29,-1,174)
Block(-2,29,0,174)
Block(-2,30,-7,174)
Block(-2,30,-6,174)
Block(-2,30,-5,174)
Block(-2,30,-4,174)
Block(-2,30,-3,174)
Block(-2,30,-2,174)
Block(-2,30,-1,174)
Block(-2,30,0,174)
Block(-2,30,1,174)
Block(-2,30,2,174)
Block(-2,30,3,174)
Block(-2,31,-7,174)
Block(-2,31,-6,174)
Block(-2,31,-5,174)
Block(-2,31,-4,174)
Block(-2,31,-3,174)
Block(-2,31,-2,174)
Block(-2,31,-1,174)
Block(-2,31,0,174)
Block(-2,31,1,174)
Block(-2,31,2,174)
Block(-2,31,3,174)
Block(-2,32,-7,174)
Block(-2,32,-6,174)
Block(-2,32,-5,174)
Block(-2,32,-4,174)
Block(-2,32,-3,174)
Block(-2,32,-2,174)
Block(-2,32,-1,174)
Block(-2,32,0,174)
Block(-2,32,1,174)
Block(-2,32,2,174)
Block(-2,32,3,174)
Block(-2,32,4,174)
Block(-2,33,-7,174)
Block(-2,33,-6,174)
Block(-2,33,-5,174)
Block(-2,33,-4,174)
Block(-2,33,-3,174)
Block(-2,33,-2,174)
Block(-2,33,-1,174)
Block(-2,33,0,174)
Block(-2,33,1,174)
Block(-2,33,2,174)
Block(-2,33,3,174)
Block(-2,33,4,174)
Block(-2,34,-7,174)
Block(-2,34,-6,174)
Block(-2,34,-5,174)
Block(-2,34,-4,174)
Block(-2,34,-3,174)
Block(-2,34,-2,174)
Block(-2,34,-1,174)
Block(-2,34,0,174)
Block(-2,34,1,174)
Block(-2,34,2,174)
Block(-2,34,3,174)
Block(-2,34,4,174)
Block(-2,35,-7,174)
Block(-2,35,-6,174)
Block(-2,35,-5,174)
Block(-2,35,-4,174)
Block(-2,35,-3,174)
Block(-2,35,-2,174)
Block(-2,35,-1,174)
Block(-2,35,0,174)
Block(-2,35,1,174)
Block(-2,35,2,174)
Block(-2,35,3,174)
Block(-2,35,4,174)
Block(-2,35,5,174)
Block(-2,36,-7,174)
Block(-2,36,-6,174)
Block(-2,36,-5,174)
Block(-2,36,-4,174)
