
#######################################################################
# +-----------------------------------------------------------------+ #
# |                            BO3 object                           | #
# +-----------------------------------------------------------------+ #
#######################################################################

# This is the config file of a custom object.
# If you add this object correctly to your BiomeConfigs, it will spawn in the world.

# This is the creator of this BO3 object
Author: LordSmellyPants

# A short description of this BO3 object
Description: No description given

# The BO3 version, don't change this! It can be used by external applications to do a version check.
Version: 3

# The settings mode, WriteAll, WriteWithoutComments or WriteDisable. See WorldConfig.
SettingsMode: WriteDisable


#######################################################################
# +-----------------------------------------------------------------+ #
# |                          Main settings                          | #
# +-----------------------------------------------------------------+ #
#######################################################################

# This needs to be set to true to spawn the object in the Tree and Sapling resources.
Tree: true

# The frequency of the BO3 from 1 to 200. Tries this many times to spawn this BO3 when using the CustomObject(...) resource.
# Ignored by Tree(..), Sapling(..) and CustomStructure(..)
Frequency: 1

# The rarity of the BO3 from 0 to 100. Each spawn attempt has rarity% chance to succeed when using the CustomObject(...) resource.
# Ignored by Tree(..), Sapling(..) and CustomStructure(..)
Rarity: 25.0

# If you set this to true, the BO3 will be placed with a random rotation.
RotateRandomly: true

# The spawn height of the BO3 - atMinY, randomY, highestBlock or highestSolidBlock.
SpawnHeight: randomY

# The offset from the spawn height to spawn this BO3
# Ex. SpawnHeight = highestSolidBlock, SpawnHeightOffset = 3; This object will spawn 3 blocks above the highest solid block
SpawnHeightOffset: 0

# A random amount to offset the spawn location from the spawn offset height
# Ex. SpawnHeightOffset = 3, SpawnHeightVariance = 3; This object will spawn 3 to 6 blocks above the original spot it would have spawned
SpawnHeightVariance: 0

##############################
# Height Limits for the BO3. #
##############################

# When in randomY mode used as the minimum Y or in atMinY mode as the actual Y to spawn this BO3 at.
MinHeight: 0
# When in randomY mode used as the maximum Y to spawn this BO3 at.
MaxHeight: 256


######################
# Extrusion settings #
######################

# The style of extrusion you wish to use - BottomDown, TopUp, None (Default)
ExtrudeMode: None

# The blocks to extrude your BO3 through
ExtrudeThroughBlocks: AIR

# Objects can have other objects attacthed to it: branches. Branches can also
# have branches attached to it, which can also have branches, etc. This is the
# maximum branch depth for this objects.
MaxBranchDepth: 10

# When spawned with the UseWorld keyword, this BO3 should NOT spawn in the following biomes.
# If you write the BO3 name directly in the BiomeConfigs, this will be ignored.
ExcludedBiomes: All


#######################################################################
# +-----------------------------------------------------------------+ #
# |                      Source block settings                      | #
# +-----------------------------------------------------------------+ #
#######################################################################

# The B(s) the BO3 should spawn in.
SourceBlocks: AIR

# The maximum percentage of the BO3 that can be outside the SourceBlock.
# The BO3 won't be placed on a location with more blocks outside the SourceBlock than this percentage.
MaxPercentageOutsideSourceBlock: 100

# What to do when a block is about to be placed outside the SourceBlock? (dontPlace, placeAnyway)
OutsideSourceBlock: placeAnyway


#######################################################################
# +-----------------------------------------------------------------+ #
# |                              Blocks                             | #
# +-----------------------------------------------------------------+ #
#######################################################################

# All the blocks used in the BO3 are listed here. Possible blocks:
# B(x,y,z,id[.data][,nbtfile.nbt)
# RB(x,y,z,id[:data][,nbtfile.nbt],chance[,id[:data][,nbtfile.nbt],chance[,...]])
#  So RB(0,0,0,CHEST,chest.nbt,50,CHEST,anotherchest.nbt,100) will spawn a chest at
#  the BO3 origin, and give it a 50% chance to have the contents of chest.nbt, or, if that
#  fails, a 100% percent chance to have the contents of anotherchest.nbt.
# MinecraftObject(x,y,z,name)
#  Spawns an object in the Mojang NBT structure format. For example, 
#  MinecraftObject(0,0,0,minecraft:igloo/igloo_bottom)
#  spawns the bottom part of an igloo.

B(-8,-22,-2,1)
B(-8,-22,-1,1)
B(-8,-22,0,1)
B(-8,-22,4,1)
B(-8,-22,5,1)
B(-8,-22,6,1)
B(-8,-22,7,1)
B(-8,-22,8,1)
B(-8,-21,-2,1)
B(-8,-21,-1,1)
B(-8,-21,0,1)
B(-8,-21,4,1)
B(-8,-21,5,1)
B(-8,-21,6,1)
B(-8,-21,7,1)
B(-8,-21,8,1)
B(-8,-20,-2,1)
B(-8,-20,-1,1)
B(-8,-20,0,1)
B(-8,-20,4,1)
B(-8,-20,5,1)
B(-8,-20,6,1)
B(-8,-20,7,1)
B(-8,-20,8,1)
B(-8,-19,-2,1)
B(-8,-19,-1,1)
B(-8,-19,0,1)
B(-8,-19,4,1)
B(-8,-19,5,1)
B(-8,-19,6,1)
B(-8,-19,7,1)
B(-8,-19,8,1)
B(-8,-18,-2,1)
B(-8,-18,-1,1)
B(-8,-18,0,1)
B(-8,-18,4,1)
B(-8,-18,5,1)
B(-8,-18,6,1)
B(-8,-18,7,1)
B(-8,-18,8,1)
B(-8,-17,-2,1)
B(-8,-17,-1,1)
B(-8,-17,0,1)
B(-8,-17,4,1)
B(-8,-17,5,1)
B(-8,-17,6,1)
B(-8,-17,7,1)
B(-8,-17,8,1)
B(-8,-16,-2,1)
B(-8,-16,-1,1)
B(-8,-16,0,1)
B(-8,-16,4,1)
B(-8,-16,5,1)
B(-8,-16,6,1)
B(-8,-16,7,1)
B(-8,-16,8,1)
B(-8,-15,-2,1)
B(-8,-15,-1,1)
B(-8,-15,0,1)
B(-8,-15,4,1)
B(-8,-15,5,1)
B(-8,-15,6,1)
B(-8,-15,7,1)
B(-8,-15,8,1)
B(-8,-14,-2,1)
B(-8,-14,-1,1)
B(-8,-14,0,1)
B(-8,-14,4,1)
B(-8,-14,5,1)
B(-8,-14,6,1)
B(-8,-14,7,1)
B(-8,-14,8,1)
B(-8,-13,-2,1)
B(-8,-13,-1,1)
B(-8,-13,0,1)
B(-8,-13,4,1)
B(-8,-13,5,1)
B(-8,-13,6,1)
B(-8,-13,7,1)
B(-8,-13,8,1)
B(-8,-12,-2,1)
B(-8,-12,-1,1)
B(-8,-12,0,1)
B(-8,-12,4,1)
B(-8,-12,5,1)
B(-8,-12,6,1)
B(-8,-12,7,1)
B(-8,-12,8,1)
B(-8,-11,-2,1)
B(-8,-11,-1,1)
B(-8,-11,0,1)
B(-8,-11,4,1)
B(-8,-11,5,1)
B(-8,-11,6,1)
B(-8,-11,7,1)
B(-8,-11,8,1)
B(-8,-10,-2,1)
B(-8,-10,-1,1)
B(-8,-10,0,1)
B(-8,-10,4,1)
B(-8,-10,5,1)
B(-8,-10,6,1)
B(-8,-10,7,1)
B(-8,-10,8,1)
B(-8,-9,-2,1)
B(-8,-9,-1,1)
B(-8,-9,0,1)
B(-8,-9,4,1)
B(-8,-9,5,1)
B(-8,-9,6,1)
B(-7,-22,-3,1)
B(-7,-22,-2,1)
B(-7,-22,-1,1)
B(-7,-22,0,1)
B(-7,-22,1,1)
B(-7,-22,2,1)
B(-7,-22,3,1)
B(-7,-22,4,1)
B(-7,-22,5,1)
B(-7,-22,6,1)
B(-7,-22,7,1)
B(-7,-22,8,1)
B(-7,-21,-3,1)
B(-7,-21,-2,1)
B(-7,-21,-1,1)
B(-7,-21,0,1)
B(-7,-21,1,1)
B(-7,-21,2,1)
B(-7,-21,3,1)
B(-7,-21,4,1)
B(-7,-21,5,1)
B(-7,-21,6,1)
B(-7,-21,7,1)
B(-7,-21,8,1)
B(-7,-20,-3,1)
B(-7,-20,-2,1)
B(-7,-20,-1,1)
B(-7,-20,0,1)
B(-7,-20,1,1)
B(-7,-20,2,1)
B(-7,-20,3,1)
B(-7,-20,4,1)
B(-7,-20,5,1)
B(-7,-20,6,1)
B(-7,-20,7,1)
B(-7,-20,8,1)
B(-7,-19,-3,1)
B(-7,-19,-2,1)
B(-7,-19,-1,1)
B(-7,-19,0,1)
B(-7,-19,1,1)
B(-7,-19,2,1)
B(-7,-19,3,1)
B(-7,-19,4,1)
B(-7,-19,5,1)
B(-7,-19,6,1)
B(-7,-19,7,1)
B(-7,-19,8,1)
B(-7,-18,-3,1)
B(-7,-18,-2,1)
B(-7,-18,-1,1)
B(-7,-18,0,1)
B(-7,-18,1,1)
B(-7,-18,2,1)
B(-7,-18,3,1)
B(-7,-18,4,1)
B(-7,-18,5,1)
B(-7,-18,6,1)
B(-7,-18,7,1)
B(-7,-18,8,1)
B(-7,-17,-3,1)
B(-7,-17,-2,1)
B(-7,-17,-1,1)
B(-7,-17,0,1)
B(-7,-17,1,1)
B(-7,-17,2,1)
B(-7,-17,3,1)
B(-7,-17,4,1)
B(-7,-17,5,1)
B(-7,-17,6,1)
B(-7,-17,7,1)
B(-7,-17,8,1)
B(-7,-16,-3,1)
B(-7,-16,-2,1)
B(-7,-16,-1,1)
B(-7,-16,0,1)
B(-7,-16,1,1)
B(-7,-16,2,1)
B(-7,-16,3,1)
B(-7,-16,4,1)
B(-7,-16,5,1)
B(-7,-16,6,1)
B(-7,-16,7,1)
B(-7,-16,8,1)
B(-7,-15,-3,1)
B(-7,-15,-2,1)
B(-7,-15,-1,1)
B(-7,-15,0,1)
B(-7,-15,1,1)
B(-7,-15,2,1)
B(-7,-15,3,1)
B(-7,-15,4,1)
B(-7,-15,5,1)
B(-7,-15,6,1)
B(-7,-15,7,1)
B(-7,-15,8,1)
B(-7,-14,-3,1)
B(-7,-14,-2,1)
B(-7,-14,-1,1)
B(-7,-14,0,1)
B(-7,-14,1,1)
B(-7,-14,2,1)
B(-7,-14,3,1)
B(-7,-14,4,1)
B(-7,-14,5,1)
B(-7,-14,6,1)
B(-7,-14,7,1)
B(-7,-14,8,1)
B(-7,-13,-3,1)
B(-7,-13,-2,1)
B(-7,-13,-1,1)
B(-7,-13,0,1)
B(-7,-13,1,1)
B(-7,-13,2,1)
B(-7,-13,3,1)
B(-7,-13,4,1)
B(-7,-13,5,1)
B(-7,-13,6,1)
B(-7,-13,7,1)
B(-7,-13,8,1)
B(-7,-12,-3,1)
B(-7,-12,-2,1)
B(-7,-12,-1,1)
B(-7,-12,0,1)
B(-7,-12,1,1)
B(-7,-12,2,1)
B(-7,-12,3,1)
B(-7,-12,4,1)
B(-7,-12,5,1)
B(-7,-12,6,1)
B(-7,-12,7,1)
B(-7,-12,8,1)
B(-7,-11,-3,1)
B(-7,-11,-2,1)
B(-7,-11,-1,1)
B(-7,-11,0,1)
B(-7,-11,1,1)
B(-7,-11,2,1)
B(-7,-11,3,1)
B(-7,-11,4,1)
B(-7,-11,5,1)
B(-7,-11,6,1)
B(-7,-11,7,1)
B(-7,-11,8,1)
B(-7,-10,-3,1)
B(-7,-10,-2,1)
B(-7,-10,-1,1)
B(-7,-10,0,1)
B(-7,-10,1,1)
B(-7,-10,2,1)
B(-7,-10,3,1)
B(-7,-10,4,1)
B(-7,-10,5,1)
B(-7,-10,6,1)
B(-7,-10,7,1)
B(-7,-10,8,1)
B(-7,-9,-3,1)
B(-7,-9,-2,1)
B(-7,-9,-1,1)
B(-7,-9,0,1)
B(-7,-9,1,1)
B(-7,-9,2,1)
B(-7,-9,3,1)
B(-7,-9,4,1)
B(-7,-9,5,1)
B(-7,-9,6,1)
B(-7,-9,7,1)
B(-7,-9,8,1)
B(-7,-8,-2,1)
B(-7,-8,-1,1)
B(-7,-8,0,1)
B(-7,-8,4,1)
B(-7,-8,5,1)
B(-7,-8,6,1)
B(-7,-8,7,1)
B(-7,-8,8,1)
B(-7,-7,-1,1)
B(-7,-7,0,1)
B(-6,-22,-3,1)
B(-6,-22,-2,1)
B(-6,-22,-1,1)
B(-6,-22,0,1)
B(-6,-22,1,1)
B(-6,-22,2,1)
B(-6,-22,3,1)
B(-6,-22,4,1)
B(-6,-22,5,1)
B(-6,-22,6,1)
B(-6,-22,7,1)
B(-6,-22,8,1)
B(-6,-21,-3,1)
B(-6,-21,-2,1)
B(-6,-21,-1,1)
B(-6,-21,0,1)
B(-6,-21,1,1)
B(-6,-21,2,1)
B(-6,-21,3,1)
B(-6,-21,4,1)
B(-6,-21,5,1)
B(-6,-21,6,1)
B(-6,-21,7,1)
B(-6,-21,8,1)
B(-6,-20,-3,1)
B(-6,-20,-2,1)
B(-6,-20,-1,1)
B(-6,-20,0,1)
B(-6,-20,1,1)
B(-6,-20,2,1)
B(-6,-20,3,1)
B(-6,-20,4,1)
B(-6,-20,5,1)
B(-6,-20,6,1)
B(-6,-20,7,1)
B(-6,-20,8,1)
B(-6,-19,-3,1)
B(-6,-19,-2,1)
B(-6,-19,-1,1)
B(-6,-19,0,1)
B(-6,-19,1,1)
B(-6,-19,2,1)
B(-6,-19,3,1)
B(-6,-19,4,1)
B(-6,-19,5,1)
B(-6,-19,6,1)
B(-6,-19,7,1)
B(-6,-19,8,1)
B(-6,-18,-3,1)
B(-6,-18,-2,1)
B(-6,-18,-1,1)
B(-6,-18,0,1)
B(-6,-18,1,1)
B(-6,-18,2,1)
B(-6,-18,3,1)
B(-6,-18,4,1)
B(-6,-18,5,1)
B(-6,-18,6,1)
B(-6,-18,7,1)
B(-6,-18,8,1)
B(-6,-17,-3,1)
B(-6,-17,-2,1)
B(-6,-17,-1,1)
B(-6,-17,0,1)
B(-6,-17,1,1)
B(-6,-17,2,1)
B(-6,-17,3,1)
B(-6,-17,4,1)
B(-6,-17,5,1)
B(-6,-17,6,1)
B(-6,-17,7,1)
B(-6,-17,8,1)
B(-6,-16,-3,1)
B(-6,-16,-2,1)
B(-6,-16,-1,1)
B(-6,-16,0,1)
B(-6,-16,1,1)
B(-6,-16,2,1)
B(-6,-16,3,1)
B(-6,-16,4,1)
B(-6,-16,5,1)
B(-6,-16,6,1)
B(-6,-16,7,1)
B(-6,-16,8,1)
B(-6,-15,-3,1)
B(-6,-15,-2,1)
B(-6,-15,-1,1)
B(-6,-15,0,1)
B(-6,-15,1,1)
B(-6,-15,2,1)
B(-6,-15,3,1)
B(-6,-15,4,1)
B(-6,-15,5,1)
B(-6,-15,6,1)
B(-6,-15,7,1)
B(-6,-15,8,1)
B(-6,-14,-3,1)
B(-6,-14,-2,1)
B(-6,-14,-1,1)
B(-6,-14,0,1)
B(-6,-14,1,1)
B(-6,-14,2,1)
B(-6,-14,3,1)
B(-6,-14,4,1)
B(-6,-14,5,1)
B(-6,-14,6,1)
B(-6,-14,7,1)
B(-6,-14,8,1)
B(-6,-13,-3,1)
B(-6,-13,-2,1)
B(-6,-13,-1,1)
B(-6,-13,0,1)
B(-6,-13,1,1)
B(-6,-13,2,1)
B(-6,-13,3,1)
B(-6,-13,4,1)
B(-6,-13,5,1)
B(-6,-13,6,1)
B(-6,-13,7,1)
B(-6,-13,8,1)
B(-6,-12,-3,1)
B(-6,-12,-2,1)
B(-6,-12,-1,1)
B(-6,-12,0,1)
B(-6,-12,1,1)
B(-6,-12,2,1)
B(-6,-12,3,1)
B(-6,-12,4,1)
B(-6,-12,5,1)
B(-6,-12,6,1)
B(-6,-12,7,1)
B(-6,-12,8,1)
B(-6,-11,-3,1)
B(-6,-11,-2,1)
B(-6,-11,-1,1)
B(-6,-11,0,1)
B(-6,-11,1,1)
B(-6,-11,2,1)
B(-6,-11,3,1)
B(-6,-11,4,1)
B(-6,-11,5,1)
B(-6,-11,6,1)
B(-6,-11,7,1)
B(-6,-11,8,1)
B(-6,-10,-3,1)
B(-6,-10,-2,1)
B(-6,-10,-1,1)
B(-6,-10,0,1)
B(-6,-10,1,1)
B(-6,-10,2,1)
B(-6,-10,3,1)
B(-6,-10,4,1)
B(-6,-10,5,1)
B(-6,-10,6,1)
B(-6,-10,7,1)
B(-6,-10,8,1)
B(-6,-9,-3,1)
B(-6,-9,-2,1)
B(-6,-9,-1,1)
B(-6,-9,0,1)
B(-6,-9,1,1)
B(-6,-9,2,1)
B(-6,-9,3,1)
B(-6,-9,4,1)
B(-6,-9,5,1)
B(-6,-9,6,1)
B(-6,-9,7,1)
B(-6,-9,8,1)
B(-6,-8,-2,1)
B(-6,-8,-1,1)
B(-6,-8,0,1)
B(-6,-8,1,1)
B(-6,-8,2,1)
B(-6,-8,3,1)
B(-6,-8,4,1)
B(-6,-8,5,1)
B(-6,-8,6,1)
B(-6,-8,7,1)
B(-6,-8,8,1)
B(-6,-7,-2,1)
B(-6,-7,-1,1)
B(-6,-7,0,1)
B(-6,-7,1,1)
B(-6,-7,4,1)
B(-6,-7,5,1)
B(-6,-7,6,1)
B(-6,-7,7,1)
B(-6,-7,8,1)
B(-6,-6,-2,1)
B(-6,-6,-1,1)
B(-6,-6,0,1)
B(-6,-6,4,1)
B(-6,-6,5,1)
B(-6,-6,6,1)
B(-6,-6,7,1)
B(-6,-6,8,1)
B(-6,-5,-1,1)
B(-6,-5,0,1)
B(-6,-4,-1,1)
B(-5,-22,-4,1)
B(-5,-22,-3,1)
B(-5,-22,-2,1)
B(-5,-22,-1,1)
B(-5,-22,0,1)
B(-5,-22,1,1)
B(-5,-22,2,1)
B(-5,-22,3,1)
B(-5,-22,4,1)
B(-5,-22,5,1)
B(-5,-22,6,1)
B(-5,-22,7,1)
B(-5,-22,8,1)
B(-5,-21,-4,1)
B(-5,-21,-3,1)
B(-5,-21,-2,1)
B(-5,-21,-1,1)
B(-5,-21,0,1)
B(-5,-21,1,1)
B(-5,-21,2,1)
B(-5,-21,3,1)
B(-5,-21,4,1)
B(-5,-21,5,1)
B(-5,-21,6,1)
B(-5,-21,7,1)
B(-5,-21,8,1)
B(-5,-20,-4,1)
B(-5,-20,-3,1)
B(-5,-20,-2,1)
B(-5,-20,-1,1)
B(-5,-20,0,1)
B(-5,-20,1,1)
B(-5,-20,2,1)
B(-5,-20,3,1)
B(-5,-20,4,1)
B(-5,-20,5,1)
B(-5,-20,6,1)
B(-5,-20,7,1)
B(-5,-20,8,1)
B(-5,-19,-4,1)
B(-5,-19,-3,1)
B(-5,-19,-2,1)
B(-5,-19,-1,1)
B(-5,-19,0,1)
B(-5,-19,1,1)
B(-5,-19,2,1)
B(-5,-19,3,1)
B(-5,-19,4,1)
B(-5,-19,5,1)
B(-5,-19,6,1)
B(-5,-19,7,1)
B(-5,-19,8,1)
B(-5,-18,-4,1)
B(-5,-18,-3,1)
B(-5,-18,-2,1)
B(-5,-18,-1,1)
B(-5,-18,0,1)
B(-5,-18,1,1)
B(-5,-18,2,1)
B(-5,-18,3,1)
B(-5,-18,4,1)
B(-5,-18,5,1)
B(-5,-18,6,1)
B(-5,-18,7,1)
B(-5,-18,8,1)
B(-5,-17,-4,1)
B(-5,-17,-3,1)
B(-5,-17,-2,1)
B(-5,-17,-1,1)
B(-5,-17,0,1)
B(-5,-17,1,1)
B(-5,-17,2,1)
B(-5,-17,3,1)
B(-5,-17,4,1)
B(-5,-17,5,1)
B(-5,-17,6,1)
B(-5,-17,7,1)
B(-5,-17,8,1)
B(-5,-16,-4,1)
B(-5,-16,-3,1)
B(-5,-16,-2,1)
B(-5,-16,-1,1)
B(-5,-16,0,1)
B(-5,-16,1,1)
B(-5,-16,2,1)
B(-5,-16,3,1)
B(-5,-16,4,1)
B(-5,-16,5,1)
B(-5,-16,6,1)
B(-5,-16,7,1)
B(-5,-16,8,1)
B(-5,-15,-4,1)
B(-5,-15,-3,1)
B(-5,-15,-2,1)
B(-5,-15,-1,1)
B(-5,-15,0,1)
B(-5,-15,1,1)
B(-5,-15,2,1)
B(-5,-15,3,1)
B(-5,-15,4,1)
B(-5,-15,5,1)
B(-5,-15,6,1)
B(-5,-15,7,1)
B(-5,-15,8,1)
B(-5,-14,-4,1)
B(-5,-14,-3,1)
B(-5,-14,-2,1)
B(-5,-14,-1,1)
B(-5,-14,0,1)
B(-5,-14,1,1)
B(-5,-14,2,1)
B(-5,-14,3,1)
B(-5,-14,4,1)
B(-5,-14,5,1)
B(-5,-14,6,1)
B(-5,-14,7,1)
B(-5,-14,8,1)
B(-5,-13,-4,1)
B(-5,-13,-3,1)
B(-5,-13,-2,1)
B(-5,-13,-1,1)
B(-5,-13,0,1)
B(-5,-13,1,1)
B(-5,-13,2,1)
B(-5,-13,3,1)
B(-5,-13,4,1)
B(-5,-13,5,1)
B(-5,-13,6,1)
B(-5,-13,7,1)
B(-5,-13,8,1)
B(-5,-12,-4,1)
B(-5,-12,-3,1)
B(-5,-12,-2,1)
B(-5,-12,-1,1)
B(-5,-12,0,1)
B(-5,-12,1,1)
B(-5,-12,2,1)
B(-5,-12,3,1)
B(-5,-12,4,1)
B(-5,-12,5,1)
B(-5,-12,6,1)
B(-5,-12,7,1)
B(-5,-12,8,1)
B(-5,-11,-4,1)
B(-5,-11,-3,1)
B(-5,-11,-2,1)
B(-5,-11,-1,1)
B(-5,-11,0,1)
B(-5,-11,1,1)
B(-5,-11,2,1)
B(-5,-11,3,1)
B(-5,-11,4,1)
B(-5,-11,5,1)
B(-5,-11,6,1)
B(-5,-11,7,1)
B(-5,-11,8,1)
B(-5,-10,-4,1)
B(-5,-10,-3,1)
B(-5,-10,-2,1)
B(-5,-10,-1,1)
B(-5,-10,0,1)
B(-5,-10,1,1)
B(-5,-10,2,1)
B(-5,-10,3,1)
B(-5,-10,4,1)
B(-5,-10,5,1)
B(-5,-10,6,1)
B(-5,-10,7,1)
B(-5,-10,8,1)
B(-5,-9,-4,1)
B(-5,-9,-3,1)
B(-5,-9,-2,1)
B(-5,-9,-1,1)
B(-5,-9,0,1)
B(-5,-9,1,1)
B(-5,-9,2,1)
B(-5,-9,3,1)
B(-5,-9,4,1)
B(-5,-9,5,1)
B(-5,-9,6,1)
B(-5,-9,7,1)
B(-5,-9,8,1)
B(-5,-8,-4,1)
B(-5,-8,-3,1)
B(-5,-8,-2,1)
B(-5,-8,-1,1)
B(-5,-8,0,1)
B(-5,-8,1,1)
B(-5,-8,2,1)
B(-5,-8,3,1)
B(-5,-8,4,1)
B(-5,-8,5,1)
B(-5,-8,6,1)
B(-5,-8,7,1)
B(-5,-8,8,1)
B(-5,-7,-3,1)
B(-5,-7,-2,1)
B(-5,-7,-1,1)
B(-5,-7,0,1)
B(-5,-7,1,1)
B(-5,-7,2,1)
B(-5,-7,3,1)
B(-5,-7,4,1)
B(-5,-7,5,1)
B(-5,-7,6,1)
B(-5,-7,7,1)
B(-5,-7,8,1)
B(-5,-6,-3,1)
B(-5,-6,-2,1)
B(-5,-6,-1,1)
B(-5,-6,0,1)
B(-5,-6,1,1)
B(-5,-6,2,1)
B(-5,-6,3,1)
B(-5,-6,4,1)
B(-5,-6,5,1)
B(-5,-6,6,1)
B(-5,-6,7,1)
B(-5,-6,8,1)
B(-5,-5,-3,1)
B(-5,-5,-2,1)
B(-5,-5,-1,1)
B(-5,-5,0,1)
B(-5,-5,1,1)
B(-5,-5,4,1)
B(-5,-5,5,1)
B(-5,-5,6,1)
B(-5,-5,7,1)
B(-5,-5,8,1)
B(-5,-4,-2,1)
B(-5,-4,-1,1)
B(-5,-4,0,1)
B(-5,-4,4,1)
B(-5,-4,5,1)
B(-5,-4,6,1)
B(-5,-4,7,1)
B(-5,-4,8,1)
B(-5,-3,-2,1)
B(-5,-3,-1,1)
B(-5,-3,5,1)
B(-5,-3,6,1)
B(-5,-3,7,1)
B(-5,-2,-1,1)
B(-5,-2,5,1)
B(-5,-2,6,1)
B(-5,-1,6,1)
B(-4,-22,-4,1)
B(-4,-22,-3,1)
B(-4,-22,-2,1)
B(-4,-22,-1,1)
B(-4,-22,0,1)
B(-4,-22,1,1)
B(-4,-22,2,1)
B(-4,-22,3,1)
B(-4,-22,4,1)
B(-4,-22,5,1)
B(-4,-22,6,1)
B(-4,-22,7,1)
B(-4,-22,8,1)
B(-4,-21,-5,1)
B(-4,-21,-4,1)
B(-4,-21,-3,1)
B(-4,-21,-2,1)
B(-4,-21,-1,1)
B(-4,-21,0,1)
B(-4,-21,1,1)
B(-4,-21,2,1)
B(-4,-21,3,1)
B(-4,-21,4,1)
B(-4,-21,5,1)
B(-4,-21,6,1)
B(-4,-21,7,1)
B(-4,-21,8,1)
B(-4,-20,-5,1)
B(-4,-20,-4,1)
B(-4,-20,-3,1)
B(-4,-20,-2,1)
B(-4,-20,-1,1)
B(-4,-20,0,1)
B(-4,-20,1,1)
B(-4,-20,2,1)
B(-4,-20,3,1)
B(-4,-20,4,1)
B(-4,-20,5,1)
B(-4,-20,6,1)
B(-4,-20,7,1)
B(-4,-20,8,1)
B(-4,-19,-5,1)
B(-4,-19,-4,1)
B(-4,-19,-3,1)
B(-4,-19,-2,1)
B(-4,-19,-1,1)
B(-4,-19,0,1)
B(-4,-19,1,1)
B(-4,-19,2,1)
B(-4,-19,3,1)
B(-4,-19,4,1)
B(-4,-19,5,1)
B(-4,-19,6,1)
B(-4,-19,7,1)
B(-4,-19,8,1)
B(-4,-18,-5,1)
B(-4,-18,-4,1)
B(-4,-18,-3,1)
B(-4,-18,-2,1)
B(-4,-18,-1,1)
B(-4,-18,0,1)
B(-4,-18,1,1)
B(-4,-18,2,1)
B(-4,-18,3,1)
B(-4,-18,4,1)
B(-4,-18,5,1)
B(-4,-18,6,1)
B(-4,-18,7,1)
B(-4,-18,8,1)
B(-4,-17,-5,1)
B(-4,-17,-4,1)
B(-4,-17,-3,1)
B(-4,-17,-2,1)
B(-4,-17,-1,1)
B(-4,-17,0,1)
B(-4,-17,1,1)
B(-4,-17,2,1)
B(-4,-17,3,1)
B(-4,-17,4,1)
B(-4,-17,5,1)
B(-4,-17,6,1)
B(-4,-17,7,1)
B(-4,-17,8,1)
B(-4,-16,-5,1)
B(-4,-16,-4,1)
B(-4,-16,-3,1)
B(-4,-16,-2,1)
B(-4,-16,-1,1)
B(-4,-16,0,1)
B(-4,-16,1,1)
B(-4,-16,2,1)
B(-4,-16,3,1)
B(-4,-16,4,1)
B(-4,-16,5,1)
B(-4,-16,6,1)
B(-4,-16,7,1)
B(-4,-16,8,1)
B(-4,-15,-5,1)
B(-4,-15,-4,1)
B(-4,-15,-3,1)
B(-4,-15,-2,1)
B(-4,-15,-1,1)
B(-4,-15,0,1)
B(-4,-15,1,1)
B(-4,-15,2,1)
B(-4,-15,3,1)
B(-4,-15,4,1)
B(-4,-15,5,1)
B(-4,-15,6,1)
B(-4,-15,7,1)
B(-4,-15,8,1)
B(-4,-14,-5,1)
B(-4,-14,-4,1)
B(-4,-14,-3,1)
B(-4,-14,-2,1)
B(-4,-14,-1,1)
B(-4,-14,0,1)
B(-4,-14,1,1)
B(-4,-14,2,1)
B(-4,-14,3,1)
B(-4,-14,4,1)
B(-4,-14,5,1)
B(-4,-14,6,1)
B(-4,-14,7,1)
B(-4,-14,8,1)
B(-4,-13,-5,1)
B(-4,-13,-4,1)
B(-4,-13,-3,1)
B(-4,-13,-2,1)
B(-4,-13,-1,1)
B(-4,-13,0,1)
B(-4,-13,1,1)
B(-4,-13,2,1)
B(-4,-13,3,1)
B(-4,-13,4,1)
B(-4,-13,5,1)
B(-4,-13,6,1)
B(-4,-13,7,1)
B(-4,-13,8,1)
B(-4,-12,-5,1)
B(-4,-12,-4,1)
B(-4,-12,-3,1)
B(-4,-12,-2,1)
B(-4,-12,-1,1)
B(-4,-12,0,1)
B(-4,-12,1,1)
B(-4,-12,2,1)
B(-4,-12,3,1)
B(-4,-12,4,1)
B(-4,-12,5,1)
B(-4,-12,6,1)
B(-4,-12,7,1)
B(-4,-12,8,1)
B(-4,-11,-5,1)
B(-4,-11,-4,1)
B(-4,-11,-3,1)
B(-4,-11,-2,1)
B(-4,-11,-1,1)
B(-4,-11,0,1)
B(-4,-11,1,1)
B(-4,-11,2,1)
B(-4,-11,3,1)
B(-4,-11,4,1)
B(-4,-11,5,1)
B(-4,-11,6,1)
B(-4,-11,7,1)
B(-4,-11,8,1)
B(-4,-10,-5,1)
B(-4,-10,-4,1)
B(-4,-10,-3,1)
B(-4,-10,-2,1)
B(-4,-10,-1,1)
B(-4,-10,0,1)
B(-4,-10,1,1)
B(-4,-10,2,1)
B(-4,-10,3,1)
B(-4,-10,4,1)
B(-4,-10,5,1)
B(-4,-10,6,1)
B(-4,-10,7,1)
B(-4,-10,8,1)
B(-4,-9,-5,1)
B(-4,-9,-4,1)
B(-4,-9,-3,1)
B(-4,-9,-2,1)
B(-4,-9,-1,1)
B(-4,-9,0,1)
B(-4,-9,1,1)
B(-4,-9,2,1)
B(-4,-9,3,1)
B(-4,-9,4,1)
B(-4,-9,5,1)
B(-4,-9,6,1)
B(-4,-9,7,1)
B(-4,-9,8,1)
B(-4,-8,-5,1)
B(-4,-8,-4,1)
B(-4,-8,-3,1)
B(-4,-8,-2,1)
B(-4,-8,-1,1)
B(-4,-8,0,1)
B(-4,-8,1,1)
B(-4,-8,2,1)
B(-4,-8,3,1)
B(-4,-8,4,1)
B(-4,-8,5,1)
B(-4,-8,6,1)
B(-4,-8,7,1)
B(-4,-8,8,1)
B(-4,-7,-4,1)
B(-4,-7,-3,1)
B(-4,-7,-2,1)
B(-4,-7,-1,1)
B(-4,-7,0,1)
B(-4,-7,1,1)
B(-4,-7,2,1)
B(-4,-7,3,1)
B(-4,-7,4,1)
B(-4,-7,5,1)
B(-4,-7,6,1)
B(-4,-7,7,1)
B(-4,-7,8,1)
B(-4,-6,-4,1)
B(-4,-6,-3,1)
B(-4,-6,-2,1)
B(-4,-6,-1,1)
B(-4,-6,0,1)
B(-4,-6,1,1)
B(-4,-6,2,1)
B(-4,-6,3,1)
B(-4,-6,4,1)
B(-4,-6,5,1)
B(-4,-6,6,1)
B(-4,-6,7,1)
B(-4,-6,8,1)
B(-4,-5,-3,1)
B(-4,-5,-2,1)
B(-4,-5,-1,1)
B(-4,-5,0,1)
B(-4,-5,1,1)
B(-4,-5,2,1)
B(-4,-5,3,1)
B(-4,-5,4,1)
B(-4,-5,5,1)
B(-4,-5,6,1)
B(-4,-5,7,1)
B(-4,-5,8,1)
B(-4,-4,-3,1)
B(-4,-4,-2,1)
B(-4,-4,-1,1)
B(-4,-4,0,1)
B(-4,-4,1,1)
B(-4,-4,2,1)
B(-4,-4,3,1)
B(-4,-4,4,1)
B(-4,-4,5,1)
B(-4,-4,6,1)
B(-4,-4,7,1)
B(-4,-4,8,1)
B(-4,-3,-3,1)
B(-4,-3,-2,1)
B(-4,-3,-1,1)
B(-4,-3,0,1)
B(-4,-3,3,1)
B(-4,-3,4,1)
B(-4,-3,5,1)
B(-4,-3,6,1)
B(-4,-3,7,1)
B(-4,-3,8,1)
B(-4,-2,-2,1)
B(-4,-2,-1,1)
B(-4,-2,0,1)
B(-4,-2,4,1)
B(-4,-2,5,1)
B(-4,-2,6,1)
B(-4,-2,7,1)
B(-4,-2,8,1)
B(-4,-1,-1,1)
B(-4,-1,4,1)
B(-4,-1,5,1)
B(-4,-1,6,1)
B(-4,-1,7,1)
B(-4,0,-1,1)
B(-4,0,5,1)
B(-4,0,6,1)
B(-4,0,7,1)
B(-4,1,5,1)
B(-4,1,6,1)
B(-3,-22,-6,1)
B(-3,-22,-5,1)
B(-3,-22,-4,1)
B(-3,-22,-3,1)
B(-3,-22,-2,1)
B(-3,-22,-1,1)
B(-3,-22,0,1)
B(-3,-22,1,1)
B(-3,-22,2,1)
B(-3,-22,3,1)
B(-3,-22,4,1)
B(-3,-22,5,1)
B(-3,-22,6,1)
B(-3,-22,7,1)
B(-3,-22,8,1)
B(-3,-21,-6,1)
B(-3,-21,-5,1)
B(-3,-21,-4,1)
B(-3,-21,-3,1)
B(-3,-21,-2,1)
B(-3,-21,-1,1)
B(-3,-21,0,1)
B(-3,-21,1,1)
B(-3,-21,2,1)
B(-3,-21,3,1)
B(-3,-21,4,1)
B(-3,-21,5,1)
B(-3,-21,6,1)
B(-3,-21,7,1)
B(-3,-21,8,1)
B(-3,-20,-6,1)
B(-3,-20,-5,1)
B(-3,-20,-4,1)
B(-3,-20,-3,1)
B(-3,-20,-2,1)
B(-3,-20,-1,1)
B(-3,-20,0,1)
B(-3,-20,1,1)
B(-3,-20,2,1)
B(-3,-20,3,1)
B(-3,-20,4,1)
B(-3,-20,5,1)
B(-3,-20,6,1)
B(-3,-20,7,1)
B(-3,-20,8,1)
B(-3,-19,-6,1)
B(-3,-19,-5,1)
B(-3,-19,-4,1)
B(-3,-19,-3,1)
B(-3,-19,-2,1)
B(-3,-19,-1,1)
B(-3,-19,0,1)
B(-3,-19,1,1)
B(-3,-19,2,1)
B(-3,-19,3,1)
B(-3,-19,4,1)
B(-3,-19,5,1)
B(-3,-19,6,1)
B(-3,-19,7,1)
B(-3,-19,8,1)
B(-3,-18,-6,1)
B(-3,-18,-5,1)
B(-3,-18,-4,1)
B(-3,-18,-3,1)
B(-3,-18,-2,1)
B(-3,-18,-1,1)
B(-3,-18,0,1)
B(-3,-18,1,1)
B(-3,-18,2,1)
B(-3,-18,3,1)
B(-3,-18,4,1)
B(-3,-18,5,1)
B(-3,-18,6,1)
B(-3,-18,7,1)
B(-3,-18,8,1)
B(-3,-17,-6,1)
B(-3,-17,-5,1)
B(-3,-17,-4,1)
B(-3,-17,-3,1)
B(-3,-17,-2,1)
B(-3,-17,-1,1)
B(-3,-17,0,1)
B(-3,-17,1,1)
B(-3,-17,2,1)
B(-3,-17,3,1)
B(-3,-17,4,1)
B(-3,-17,5,1)
B(-3,-17,6,1)
B(-3,-17,7,1)
B(-3,-17,8,1)
B(-3,-16,-6,1)
B(-3,-16,-5,1)
B(-3,-16,-4,1)
B(-3,-16,-3,1)
B(-3,-16,-2,1)
B(-3,-16,-1,1)
B(-3,-16,0,1)
B(-3,-16,1,1)
B(-3,-16,2,1)
B(-3,-16,3,1)
B(-3,-16,4,1)
B(-3,-16,5,1)
B(-3,-16,6,1)
B(-3,-16,7,1)
B(-3,-16,8,1)
B(-3,-15,-6,1)
B(-3,-15,-5,1)
B(-3,-15,-4,1)
B(-3,-15,-3,1)
B(-3,-15,-2,1)
B(-3,-15,-1,1)
B(-3,-15,0,1)
B(-3,-15,1,1)
B(-3,-15,2,1)
B(-3,-15,3,1)
B(-3,-15,4,1)
B(-3,-15,5,1)
B(-3,-15,6,1)
B(-3,-15,7,1)
B(-3,-15,8,1)
B(-3,-14,-6,1)
B(-3,-14,-5,1)
B(-3,-14,-4,1)
B(-3,-14,-3,1)
B(-3,-14,-2,1)
B(-3,-14,-1,1)
B(-3,-14,0,1)
B(-3,-14,1,1)
B(-3,-14,2,1)
B(-3,-14,3,1)
B(-3,-14,4,1)
B(-3,-14,5,1)
B(-3,-14,6,1)
B(-3,-14,7,1)
B(-3,-14,8,1)
B(-3,-13,-6,1)
B(-3,-13,-5,1)
B(-3,-13,-4,1)
B(-3,-13,-3,1)
B(-3,-13,-2,1)
B(-3,-13,-1,1)
B(-3,-13,0,1)
B(-3,-13,1,1)
B(-3,-13,2,1)
B(-3,-13,3,1)
B(-3,-13,4,1)
B(-3,-13,5,1)
B(-3,-13,6,1)
B(-3,-13,7,1)
B(-3,-13,8,1)
B(-3,-12,-6,1)
B(-3,-12,-5,1)
B(-3,-12,-4,1)
B(-3,-12,-3,1)
B(-3,-12,-2,1)
B(-3,-12,-1,1)
B(-3,-12,0,1)
B(-3,-12,1,1)
B(-3,-12,2,1)
B(-3,-12,3,1)
B(-3,-12,4,1)
B(-3,-12,5,1)
B(-3,-12,6,1)
B(-3,-12,7,1)
B(-3,-12,8,1)
B(-3,-11,-6,1)
B(-3,-11,-5,1)
B(-3,-11,-4,1)
B(-3,-11,-3,1)
B(-3,-11,-2,1)
B(-3,-11,-1,1)
B(-3,-11,0,1)
B(-3,-11,1,1)
B(-3,-11,2,1)
B(-3,-11,3,1)
B(-3,-11,4,1)
B(-3,-11,5,1)
B(-3,-11,6,1)
B(-3,-11,7,1)
B(-3,-11,8,1)
B(-3,-10,-6,1)
B(-3,-10,-5,1)
B(-3,-10,-4,1)
B(-3,-10,-3,1)
B(-3,-10,-2,1)
B(-3,-10,-1,1)
B(-3,-10,0,1)
B(-3,-10,1,1)
B(-3,-10,2,1)
B(-3,-10,3,1)
B(-3,-10,4,1)
B(-3,-10,5,1)
B(-3,-10,6,1)
B(-3,-10,7,1)
B(-3,-10,8,1)
B(-3,-9,-6,1)
B(-3,-9,-5,1)
B(-3,-9,-4,1)
B(-3,-9,-3,1)
B(-3,-9,-2,1)
B(-3,-9,-1,1)
B(-3,-9,0,1)
B(-3,-9,1,1)
B(-3,-9,2,1)
B(-3,-9,3,1)
B(-3,-9,4,1)
B(-3,-9,5,1)
B(-3,-9,6,1)
B(-3,-9,7,1)
B(-3,-9,8,1)
B(-3,-8,-5,1)
B(-3,-8,-4,1)
B(-3,-8,-3,1)
B(-3,-8,-2,1)
B(-3,-8,-1,1)
B(-3,-8,0,1)
B(-3,-8,1,1)
B(-3,-8,2,1)
B(-3,-8,3,1)
B(-3,-8,4,1)
B(-3,-8,5,1)
B(-3,-8,6,1)
B(-3,-8,7,1)
B(-3,-8,8,1)
B(-3,-7,-5,1)
B(-3,-7,-4,1)
B(-3,-7,-3,1)
B(-3,-7,-2,1)
B(-3,-7,-1,1)
B(-3,-7,0,1)
B(-3,-7,1,1)
B(-3,-7,2,1)
B(-3,-7,3,1)
B(-3,-7,4,1)
B(-3,-7,5,1)
B(-3,-7,6,1)
B(-3,-7,7,1)
B(-3,-7,8,1)
B(-3,-6,-5,1)
B(-3,-6,-4,1)
B(-3,-6,-3,1)
B(-3,-6,-2,1)
B(-3,-6,-1,1)
B(-3,-6,0,1)
B(-3,-6,1,1)
B(-3,-6,2,1)
B(-3,-6,3,1)
B(-3,-6,4,1)
B(-3,-6,5,1)
B(-3,-6,6,1)
B(-3,-6,7,1)
B(-3,-6,8,1)
B(-3,-5,-4,1)
B(-3,-5,-3,1)
B(-3,-5,-2,1)
B(-3,-5,-1,1)
B(-3,-5,0,1)
B(-3,-5,1,1)
B(-3,-5,2,1)
B(-3,-5,3,1)
B(-3,-5,4,1)
B(-3,-5,5,1)
B(-3,-5,6,1)
B(-3,-5,7,1)
B(-3,-5,8,1)
B(-3,-4,-4,1)
B(-3,-4,-3,1)
B(-3,-4,-2,1)
B(-3,-4,-1,1)
B(-3,-4,0,1)
B(-3,-4,1,1)
B(-3,-4,2,1)
B(-3,-4,3,1)
B(-3,-4,4,1)
B(-3,-4,5,1)
B(-3,-4,6,1)
B(-3,-4,7,1)
B(-3,-4,8,1)
B(-3,-3,-3,1)
B(-3,-3,-2,1)
B(-3,-3,-1,1)
B(-3,-3,0,1)
B(-3,-3,1,1)
B(-3,-3,2,98)
B(-3,-3,3,1)
B(-3,-3,4,1)
B(-3,-3,5,1)
B(-3,-3,6,1)
B(-3,-3,7,1)
B(-3,-3,8,1)
B(-3,-2,-3,1)
B(-3,-2,-2,1)
B(-3,-2,-1,1)
B(-3,-2,0,1)
B(-3,-2,1,1)
B(-3,-2,2,98)
B(-3,-2,3,1)
B(-3,-2,4,1)
B(-3,-2,5,1)
B(-3,-2,6,1)
B(-3,-2,7,1)
B(-3,-2,8,1)
B(-3,-1,-3,AIR)
B(-3,-1,-2,1)
B(-3,-1,-1,98)
B(-3,-1,0,1)
B(-3,-1,1,1)
B(-3,-1,2,98)
B(-3,-1,3,1)
B(-3,-1,4,1)
B(-3,-1,5,1)
B(-3,-1,6,1)
B(-3,-1,7,1)
B(-3,-1,8,1)
B(-3,0,-3,AIR)
B(-3,0,-2,AIR)
B(-3,0,-1,98)
B(-3,0,0,AIR)
B(-3,0,1,AIR)
B(-3,0,2,98)
B(-3,0,3,1)
B(-3,0,4,1)
B(-3,0,5,98)
B(-3,0,6,1)
B(-3,0,7,1)
B(-3,1,-3,AIR)
B(-3,1,-2,AIR)
B(-3,1,-1,98)
B(-3,1,0,AIR)
B(-3,1,1,AIR)
B(-3,1,2,98)
B(-3,1,3,1)
B(-3,1,4,1)
B(-3,1,5,98)
B(-3,1,6,1)
B(-3,1,7,1)
B(-3,2,-3,AIR)
B(-3,2,-2,AIR)
B(-3,2,-1,98)
B(-3,2,0,AIR)
B(-3,2,1,AIR)
B(-3,2,2,98)
B(-3,2,3,AIR)
B(-3,2,4,1)
B(-3,2,5,98)
B(-3,2,6,1)
B(-3,2,7,AIR)
B(-3,3,-3,AIR)
B(-3,3,-2,AIR)
B(-3,3,-1,98)
B(-3,3,0,AIR)
B(-3,3,1,AIR)
B(-3,3,2,98)
B(-3,3,3,AIR)
B(-3,3,4,AIR)
B(-3,3,5,98)
B(-3,3,6,AIR)
B(-3,3,7,AIR)
B(-3,3,8,AIR)
B(-3,4,-3,98)
B(-3,4,-2,98)
B(-3,4,-1,98)
B(-3,4,0,98)
B(-3,4,1,98)
B(-3,4,2,98)
B(-3,4,3,98)
B(-3,4,4,98)
B(-3,4,5,98)
B(-3,4,6,98)
B(-3,4,7,98)
B(-3,4,8,AIR)
B(-3,5,-3,AIR)
B(-3,5,-2,AIR)
B(-3,5,-1,AIR)
B(-3,5,0,AIR)
B(-3,5,1,AIR)
B(-3,5,2,AIR)
B(-3,5,3,AIR)
B(-3,5,4,AIR)
B(-3,5,5,AIR)
B(-3,5,6,AIR)
B(-3,5,7,AIR)
B(-3,5,8,AIR)
B(-3,6,-3,AIR)
B(-3,6,-2,AIR)
B(-3,6,-1,AIR)
B(-3,6,0,AIR)
B(-3,6,1,AIR)
B(-3,6,2,AIR)
B(-3,6,3,AIR)
B(-3,6,4,AIR)
B(-3,6,5,AIR)
B(-3,6,6,AIR)
B(-3,6,7,AIR)
B(-3,6,8,AIR)
B(-3,7,-3,AIR)
B(-3,7,-2,AIR)
B(-3,7,-1,AIR)
B(-3,7,0,AIR)
B(-3,7,1,AIR)
B(-3,7,2,AIR)
B(-3,7,3,AIR)
B(-3,7,4,AIR)
B(-3,7,5,AIR)
B(-3,7,6,AIR)
B(-3,7,7,AIR)
B(-3,7,8,AIR)
B(-3,8,-3,AIR)
B(-3,8,-2,AIR)
B(-3,8,-1,AIR)
B(-3,8,0,AIR)
B(-3,8,1,AIR)
B(-3,8,2,AIR)
B(-3,8,3,AIR)
B(-3,8,4,AIR)
B(-3,8,5,AIR)
B(-3,8,6,AIR)
B(-3,8,7,AIR)
B(-3,8,8,AIR)
B(-3,9,-3,AIR)
B(-3,9,-2,AIR)
B(-3,9,-1,AIR)
B(-3,9,0,AIR)
B(-3,9,1,AIR)
B(-3,9,2,AIR)
B(-3,9,3,AIR)
B(-3,9,4,AIR)
B(-3,9,5,AIR)
B(-3,9,6,AIR)
B(-3,9,7,AIR)
B(-3,9,8,AIR)
B(-3,10,-3,AIR)
B(-3,10,-2,AIR)
B(-3,10,-1,AIR)
B(-3,10,0,AIR)
B(-3,10,1,AIR)
B(-3,10,2,AIR)
B(-3,10,3,AIR)
B(-3,10,4,AIR)
B(-3,10,5,AIR)
B(-3,10,6,AIR)
B(-3,10,7,AIR)
B(-3,10,8,AIR)
B(-3,11,-3,AIR)
B(-3,11,-2,AIR)
B(-3,11,-1,AIR)
B(-3,11,0,AIR)
B(-3,11,1,AIR)
B(-3,11,2,AIR)
B(-3,11,3,AIR)
B(-3,11,4,AIR)
B(-3,11,5,AIR)
B(-3,11,6,AIR)
B(-3,11,7,AIR)
B(-3,11,8,AIR)
B(-3,12,-3,AIR)
B(-3,12,-2,AIR)
B(-3,12,-1,AIR)
B(-3,12,0,AIR)
B(-3,12,1,AIR)
B(-3,12,2,AIR)
B(-3,12,3,AIR)
B(-3,12,4,AIR)
B(-3,12,5,AIR)
B(-3,12,6,AIR)
B(-3,12,7,AIR)
B(-3,12,8,AIR)
B(-3,13,-3,AIR)
B(-3,13,-2,AIR)
B(-3,13,-1,AIR)
B(-3,13,0,AIR)
B(-3,13,1,AIR)
B(-3,13,2,AIR)
B(-3,13,3,AIR)
B(-3,13,4,AIR)
B(-3,13,5,AIR)
B(-3,13,6,AIR)
B(-3,13,7,AIR)
B(-3,13,8,AIR)
B(-3,14,-3,AIR)
B(-3,14,-2,AIR)
B(-3,14,-1,AIR)
B(-3,14,0,AIR)
B(-3,14,1,AIR)
B(-3,14,2,AIR)
B(-3,14,3,AIR)
B(-3,14,4,AIR)
B(-3,14,5,AIR)
B(-3,14,6,AIR)
B(-3,14,7,AIR)
B(-3,14,8,AIR)
B(-3,15,-3,AIR)
B(-3,15,-2,AIR)
B(-3,15,-1,AIR)
B(-3,15,0,AIR)
B(-3,15,1,AIR)
B(-3,15,2,AIR)
B(-3,15,3,AIR)
B(-3,15,4,AIR)
B(-3,15,5,AIR)
B(-3,15,6,AIR)
B(-3,15,7,AIR)
B(-3,15,8,AIR)
B(-3,16,-3,AIR)
B(-3,16,-2,AIR)
B(-3,16,-1,AIR)
B(-3,16,0,AIR)
B(-3,16,1,AIR)
B(-3,16,2,AIR)
B(-3,16,3,AIR)
B(-3,16,4,AIR)
B(-3,16,5,AIR)
B(-3,16,6,AIR)
B(-3,16,7,AIR)
B(-3,16,8,AIR)
B(-3,17,-3,AIR)
B(-3,17,-2,AIR)
B(-3,17,-1,AIR)
B(-3,17,0,AIR)
B(-3,17,1,AIR)
B(-3,17,2,AIR)
B(-3,17,3,AIR)
B(-3,17,4,AIR)
B(-3,17,5,AIR)
B(-3,17,6,AIR)
B(-3,17,7,AIR)
B(-3,17,8,AIR)
B(-3,18,-3,AIR)
B(-3,18,-2,AIR)
B(-3,18,-1,AIR)
B(-3,18,0,AIR)
B(-3,18,1,AIR)
B(-3,18,2,AIR)
B(-3,18,3,AIR)
B(-3,18,4,AIR)
B(-3,18,5,AIR)
B(-3,18,6,AIR)
B(-3,18,7,AIR)
B(-3,18,8,AIR)
B(-3,19,-3,AIR)
B(-3,19,-2,AIR)
B(-3,19,-1,AIR)
B(-3,19,0,AIR)
B(-3,19,1,AIR)
B(-3,19,2,AIR)
B(-3,19,3,AIR)
B(-3,19,4,AIR)
B(-3,19,5,AIR)
B(-3,19,6,AIR)
B(-3,19,7,AIR)
B(-3,19,8,AIR)
B(-3,20,-3,AIR)
B(-3,20,-2,AIR)
B(-3,20,-1,AIR)
B(-3,20,0,AIR)
B(-3,20,1,AIR)
B(-3,20,2,AIR)
B(-3,20,3,AIR)
B(-3,20,4,AIR)
B(-3,20,5,AIR)
B(-3,20,6,AIR)
B(-3,20,7,AIR)
B(-3,20,8,AIR)
B(-3,21,-3,AIR)
B(-3,21,-2,AIR)
B(-3,21,-1,AIR)
B(-3,21,0,AIR)
B(-3,21,1,AIR)
B(-3,21,2,AIR)
B(-3,21,3,AIR)
B(-3,21,4,AIR)
B(-3,21,5,AIR)
B(-3,21,6,AIR)
B(-3,21,7,AIR)
B(-3,21,8,AIR)
B(-3,22,-3,AIR)
B(-3,22,-2,AIR)
B(-3,22,-1,AIR)
B(-3,22,0,AIR)
B(-3,22,1,AIR)
B(-3,22,2,AIR)
B(-3,22,3,AIR)
B(-3,22,4,AIR)
B(-3,22,5,AIR)
B(-3,22,6,AIR)
B(-3,22,7,AIR)
B(-3,22,8,AIR)
B(-3,23,-3,AIR)
B(-3,23,-2,AIR)
B(-3,23,-1,AIR)
B(-3,23,0,AIR)
B(-3,23,1,AIR)
B(-3,23,2,AIR)
B(-3,23,3,AIR)
B(-3,23,4,AIR)
B(-3,23,5,AIR)
B(-3,23,6,AIR)
B(-3,23,7,AIR)
B(-3,23,8,AIR)
B(-3,24,-3,AIR)
B(-3,24,-2,AIR)
B(-3,24,-1,AIR)
B(-3,24,0,AIR)
B(-3,24,1,AIR)
B(-3,24,2,AIR)
B(-3,24,3,AIR)
B(-3,24,4,AIR)
B(-3,24,5,AIR)
B(-3,24,6,AIR)
B(-3,24,7,AIR)
B(-3,24,8,AIR)
B(-3,25,-3,AIR)
B(-3,25,-2,AIR)
B(-3,25,-1,AIR)
B(-3,25,0,AIR)
B(-3,25,1,AIR)
B(-3,25,2,AIR)
B(-3,25,3,AIR)
B(-3,25,4,AIR)
B(-3,25,5,AIR)
B(-3,25,6,AIR)
B(-3,25,7,AIR)
B(-3,25,8,AIR)
B(-3,26,-3,AIR)
B(-3,26,-2,AIR)
B(-3,26,-1,AIR)
B(-3,26,0,AIR)
B(-3,26,1,AIR)
B(-3,26,2,AIR)
B(-3,26,3,AIR)
B(-3,26,4,AIR)
B(-3,26,5,AIR)
B(-3,26,6,AIR)
B(-3,26,7,AIR)
B(-3,26,8,AIR)
B(-3,27,-3,AIR)
B(-3,27,-2,AIR)
B(-3,27,-1,AIR)
B(-3,27,0,AIR)
B(-3,27,1,AIR)
B(-3,27,2,AIR)
B(-3,27,3,AIR)
B(-3,27,4,AIR)
B(-3,27,5,AIR)
B(-3,27,6,AIR)
B(-3,27,7,AIR)
B(-3,27,8,AIR)
B(-3,28,-3,AIR)
B(-3,28,-2,AIR)
B(-3,28,-1,AIR)
B(-3,28,0,AIR)
B(-3,28,1,AIR)
B(-3,28,2,AIR)
B(-3,28,3,AIR)
B(-3,28,4,AIR)
B(-3,28,5,AIR)
B(-3,28,6,AIR)
B(-3,28,7,AIR)
B(-3,28,8,AIR)
B(-3,29,-3,AIR)
B(-3,29,-2,AIR)
B(-3,29,-1,AIR)
B(-3,29,0,AIR)
B(-3,29,1,AIR)
B(-3,29,2,AIR)
B(-3,29,3,AIR)
B(-3,29,4,AIR)
B(-3,29,5,AIR)
B(-3,29,6,AIR)
B(-3,29,7,AIR)
B(-3,29,8,AIR)
B(-3,30,-3,AIR)
B(-3,30,-2,AIR)
B(-3,30,-1,AIR)
B(-3,30,0,AIR)
B(-3,30,1,AIR)
B(-3,30,2,AIR)
B(-3,30,3,AIR)
B(-3,30,4,AIR)
B(-3,30,5,AIR)
B(-3,30,6,AIR)
B(-3,30,7,AIR)
B(-3,30,8,AIR)
B(-3,31,-3,AIR)
B(-3,31,-2,AIR)
B(-3,31,-1,AIR)
B(-3,31,0,AIR)
B(-3,31,1,AIR)
B(-3,31,2,AIR)
B(-3,31,3,AIR)
B(-3,31,4,AIR)
B(-3,31,5,AIR)
B(-3,31,6,AIR)
B(-3,31,7,AIR)
B(-3,31,8,AIR)
B(-3,32,-3,AIR)
B(-3,32,-2,AIR)
B(-3,32,-1,AIR)
B(-3,32,0,AIR)
B(-3,32,1,AIR)
B(-3,32,2,AIR)
B(-3,32,3,AIR)
B(-3,32,4,AIR)
B(-3,32,5,AIR)
B(-3,32,6,AIR)
B(-3,32,7,AIR)
B(-3,32,8,AIR)
B(-3,33,-3,AIR)
B(-3,33,-2,AIR)
B(-3,33,-1,AIR)
B(-3,33,0,AIR)
B(-3,33,1,AIR)
B(-3,33,2,AIR)
B(-3,33,3,AIR)
B(-3,33,4,AIR)
B(-3,33,5,AIR)
B(-3,33,6,AIR)
B(-3,33,7,AIR)
B(-3,33,8,AIR)
B(-3,34,-3,AIR)
B(-3,34,-2,AIR)
B(-3,34,-1,AIR)
B(-3,34,0,AIR)
B(-3,34,1,AIR)
B(-3,34,2,AIR)
B(-3,34,3,AIR)
B(-3,34,4,AIR)
B(-3,34,5,AIR)
B(-3,34,6,AIR)
B(-3,34,7,AIR)
B(-3,34,8,AIR)
B(-2,-22,-6,1)
B(-2,-22,-5,1)
B(-2,-22,-4,1)
B(-2,-22,-3,1)
B(-2,-22,-2,1)
B(-2,-22,-1,1)
B(-2,-22,0,1)
B(-2,-22,1,1)
B(-2,-22,2,1)
B(-2,-22,3,1)
B(-2,-22,4,1)
B(-2,-22,5,1)
B(-2,-22,6,1)
B(-2,-22,7,1)
B(-2,-22,8,1)
B(-2,-21,-6,1)
B(-2,-21,-5,1)
B(-2,-21,-4,1)
B(-2,-21,-3,1)
B(-2,-21,-2,1)
B(-2,-21,-1,1)
B(-2,-21,0,1)
B(-2,-21,1,1)
B(-2,-21,2,1)
B(-2,-21,3,1)
B(-2,-21,4,1)
B(-2,-21,5,1)
B(-2,-21,6,1)
B(-2,-21,7,1)
B(-2,-21,8,1)
B(-2,-20,-6,1)
B(-2,-20,-5,1)
B(-2,-20,-4,1)
B(-2,-20,-3,1)
B(-2,-20,-2,1)
B(-2,-20,-1,1)
B(-2,-20,0,1)
B(-2,-20,1,1)
B(-2,-20,2,1)
B(-2,-20,3,1)
B(-2,-20,4,1)
B(-2,-20,5,1)
B(-2,-20,6,1)
B(-2,-20,7,1)
B(-2,-20,8,1)
B(-2,-19,-6,1)
B(-2,-19,-5,1)
B(-2,-19,-4,1)
B(-2,-19,-3,1)
B(-2,-19,-2,1)
B(-2,-19,-1,1)
B(-2,-19,0,1)
B(-2,-19,1,1)
B(-2,-19,2,1)
B(-2,-19,3,1)
B(-2,-19,4,1)
B(-2,-19,5,1)
B(-2,-19,6,1)
B(-2,-19,7,1)
B(-2,-19,8,1)
B(-2,-18,-6,1)
B(-2,-18,-5,1)
B(-2,-18,-4,1)
B(-2,-18,-3,1)
B(-2,-18,-2,1)
B(-2,-18,-1,1)
B(-2,-18,0,1)
B(-2,-18,1,1)
B(-2,-18,2,1)
B(-2,-18,3,1)
B(-2,-18,4,1)
B(-2,-18,5,1)
B(-2,-18,6,1)
B(-2,-18,7,1)
B(-2,-18,8,1)
B(-2,-17,-6,1)
B(-2,-17,-5,1)
B(-2,-17,-4,1)
B(-2,-17,-3,1)
B(-2,-17,-2,1)
B(-2,-17,-1,1)
B(-2,-17,0,1)
B(-2,-17,1,1)
B(-2,-17,2,1)
B(-2,-17,3,1)
B(-2,-17,4,1)
B(-2,-17,5,1)
B(-2,-17,6,1)
B(-2,-17,7,1)
B(-2,-17,8,1)
B(-2,-16,-6,1)
B(-2,-16,-5,1)
B(-2,-16,-4,1)
B(-2,-16,-3,1)
B(-2,-16,-2,1)
B(-2,-16,-1,1)
B(-2,-16,0,1)
B(-2,-16,1,1)
B(-2,-16,2,1)
B(-2,-16,3,1)
B(-2,-16,4,1)
B(-2,-16,5,1)
B(-2,-16,6,1)
B(-2,-16,7,1)
B(-2,-16,8,1)
B(-2,-15,-6,1)
B(-2,-15,-5,1)
B(-2,-15,-4,1)
B(-2,-15,-3,1)
B(-2,-15,-2,1)
B(-2,-15,-1,1)
B(-2,-15,0,1)
B(-2,-15,1,1)
B(-2,-15,2,1)
B(-2,-15,3,1)
B(-2,-15,4,1)
B(-2,-15,5,1)
B(-2,-15,6,1)
B(-2,-15,7,1)
B(-2,-15,8,1)
B(-2,-14,-6,1)
B(-2,-14,-5,1)
B(-2,-14,-4,1)
B(-2,-14,-3,1)
B(-2,-14,-2,1)
B(-2,-14,-1,1)
B(-2,-14,0,1)
B(-2,-14,1,1)
B(-2,-14,2,1)
B(-2,-14,3,1)
B(-2,-14,4,1)
B(-2,-14,5,1)
B(-2,-14,6,1)
B(-2,-14,7,1)
B(-2,-14,8,1)
B(-2,-13,-6,1)
B(-2,-13,-5,1)
B(-2,-13,-4,1)
B(-2,-13,-3,1)
B(-2,-13,-2,1)
B(-2,-13,-1,1)
B(-2,-13,0,1)
B(-2,-13,1,1)
B(-2,-13,2,1)
B(-2,-13,3,1)
B(-2,-13,4,1)
B(-2,-13,5,1)
B(-2,-13,6,1)
B(-2,-13,7,1)
B(-2,-13,8,1)
B(-2,-12,-6,1)
B(-2,-12,-5,1)
B(-2,-12,-4,1)
B(-2,-12,-3,1)
B(-2,-12,-2,1)
B(-2,-12,-1,1)
B(-2,-12,0,1)
B(-2,-12,1,1)
B(-2,-12,2,1)
B(-2,-12,3,1)
B(-2,-12,4,1)
B(-2,-12,5,1)
B(-2,-12,6,1)
B(-2,-12,7,1)
B(-2,-12,8,1)
B(-2,-11,-6,1)
B(-2,-11,-5,1)
B(-2,-11,-4,1)
B(-2,-11,-3,1)
B(-2,-11,-2,1)
B(-2,-11,-1,1)
B(-2,-11,0,1)
B(-2,-11,1,1)
B(-2,-11,2,1)
B(-2,-11,3,1)
B(-2,-11,4,1)
B(-2,-11,5,1)
B(-2,-11,6,1)
B(-2,-11,7,1)
B(-2,-11,8,1)
B(-2,-10,-6,1)
B(-2,-10,-5,1)
B(-2,-10,-4,1)
B(-2,-10,-3,1)
B(-2,-10,-2,1)
B(-2,-10,-1,1)
B(-2,-10,0,1)
B(-2,-10,1,1)
B(-2,-10,2,1)
B(-2,-10,3,1)
B(-2,-10,4,1)
B(-2,-10,5,1)
B(-2,-10,6,1)
B(-2,-10,7,1)
B(-2,-10,8,1)
B(-2,-9,-6,1)
B(-2,-9,-5,1)
B(-2,-9,-4,1)
B(-2,-9,-3,1)
B(-2,-9,-2,1)
B(-2,-9,-1,1)
B(-2,-9,0,1)
B(-2,-9,1,1)
B(-2,-9,2,1)
B(-2,-9,3,1)
B(-2,-9,4,1)
B(-2,-9,5,1)
B(-2,-9,6,1)
B(-2,-9,7,1)
B(-2,-9,8,1)
B(-2,-8,-6,1)
B(-2,-8,-5,1)
B(-2,-8,-4,1)
B(-2,-8,-3,1)
B(-2,-8,-2,1)
B(-2,-8,-1,1)
B(-2,-8,0,1)
B(-2,-8,1,1)
B(-2,-8,2,1)
B(-2,-8,3,1)
B(-2,-8,4,1)
B(-2,-8,5,1)
B(-2,-8,6,1)
B(-2,-8,7,1)
B(-2,-8,8,1)
B(-2,-7,-5,1)
B(-2,-7,-4,1)
B(-2,-7,-3,1)
B(-2,-7,-2,1)
B(-2,-7,-1,1)
B(-2,-7,0,1)
B(-2,-7,1,1)
B(-2,-7,2,1)
B(-2,-7,3,1)
B(-2,-7,4,1)
B(-2,-7,5,1)
B(-2,-7,6,1)
B(-2,-7,7,1)
B(-2,-7,8,1)
B(-2,-6,-5,1)
B(-2,-6,-4,1)
B(-2,-6,-3,1)
B(-2,-6,-2,1)
B(-2,-6,-1,1)
B(-2,-6,0,1)
B(-2,-6,1,1)
B(-2,-6,2,1)
B(-2,-6,3,1)
B(-2,-6,4,1)
B(-2,-6,5,1)
B(-2,-6,6,1)
B(-2,-6,7,1)
B(-2,-6,8,1)
B(-2,-5,-4,1)
B(-2,-5,-3,1)
B(-2,-5,-2,1)
B(-2,-5,-1,1)
B(-2,-5,0,1)
B(-2,-5,1,1)
B(-2,-5,2,1)
B(-2,-5,3,1)
B(-2,-5,4,1)
B(-2,-5,5,1)
B(-2,-5,6,1)
B(-2,-5,7,1)
B(-2,-5,8,1)
B(-2,-4,-4,1)
B(-2,-4,-3,1)
B(-2,-4,-2,1)
B(-2,-4,-1,1)
B(-2,-4,0,1)
B(-2,-4,1,1)
B(-2,-4,2,1)
B(-2,-4,3,1)
B(-2,-4,4,1)
B(-2,-4,5,1)
B(-2,-4,6,1)
B(-2,-4,7,1)
B(-2,-4,8,1)
B(-2,-3,-4,1)
B(-2,-3,-3,1)
B(-2,-3,-2,1)
B(-2,-3,-1,1)
B(-2,-3,0,1)
B(-2,-3,1,1)
B(-2,-3,2,98)
B(-2,-3,3,1)
B(-2,-3,4,1)
B(-2,-3,5,1)
B(-2,-3,6,1)
B(-2,-3,7,1)
B(-2,-3,8,1)
B(-2,-2,-4,1)
B(-2,-2,-3,1)
B(-2,-2,-2,1)
B(-2,-2,-1,1)
B(-2,-2,0,1)
B(-2,-2,1,1)
B(-2,-2,2,98)
B(-2,-2,3,1)
B(-2,-2,4,1)
B(-2,-2,5,1)
B(-2,-2,6,1)
B(-2,-2,7,1)
B(-2,-2,8,1)
B(-2,-1,-3,1)
B(-2,-1,-2,1)
B(-2,-1,-1,1)
B(-2,-1,0,1)
B(-2,-1,1,1)
B(-2,-1,2,98)
B(-2,-1,3,1)
B(-2,-1,4,1)
B(-2,-1,5,1)
B(-2,-1,6,1)
B(-2,-1,7,1)
B(-2,-1,8,1)
B(-2,0,-3,1)
B(-2,0,-2,98)
B(-2,0,-1,98)
B(-2,0,0,98)
B(-2,0,1,98)
B(-2,0,2,98)
B(-2,0,3,1)
B(-2,0,4,1)
B(-2,0,5,1)
B(-2,0,6,1)
B(-2,0,7,1)
B(-2,0,8,1)
B(-2,1,-3,AIR)
B(-2,1,-2,98)
B(-2,1,-1,98)
B(-2,1,0,98)
B(-2,1,1,98)
B(-2,1,2,98)
B(-2,1,3,98)
B(-2,1,4,98)
B(-2,1,5,98)
B(-2,1,6,98)
B(-2,1,7,1)
B(-2,1,8,1)
B(-2,2,-3,AIR)
B(-2,2,-2,98)
B(-2,2,-1,98)
B(-2,2,0,98)
B(-2,2,1,98)
B(-2,2,2,98)
B(-2,2,3,98)
B(-2,2,4,98)
B(-2,2,5,98)
B(-2,2,6,98)
B(-2,2,7,1)
B(-2,2,8,1)
B(-2,3,-3,AIR)
B(-2,3,-2,98)
B(-2,3,-1,98)
B(-2,3,0,98)
B(-2,3,1,98)
B(-2,3,2,98)
B(-2,3,3,98)
B(-2,3,4,98)
B(-2,3,5,98)
B(-2,3,6,98)
B(-2,3,7,1)
B(-2,3,8,1)
B(-2,4,-3,98)
B(-2,4,-2,98)
B(-2,4,-1,98)
B(-2,4,0,98)
B(-2,4,1,98)
B(-2,4,2,98)
B(-2,4,3,98)
B(-2,4,4,98)
B(-2,4,5,98)
B(-2,4,6,98)
B(-2,4,7,98)
B(-2,4,8,AIR)
B(-2,5,-3,AIR)
B(-2,5,-2,98)
B(-2,5,-1,AIR)
B(-2,5,0,98)
B(-2,5,1,98)
B(-2,5,2,AIR)
B(-2,5,3,98)
B(-2,5,4,98)
B(-2,5,5,AIR)
B(-2,5,6,98)
B(-2,5,7,AIR)
B(-2,5,8,AIR)
B(-2,6,-3,AIR)
B(-2,6,-2,98)
B(-2,6,-1,AIR)
B(-2,6,0,98)
B(-2,6,1,98)
B(-2,6,2,AIR)
B(-2,6,3,98)
B(-2,6,4,98)
B(-2,6,5,AIR)
B(-2,6,6,98)
B(-2,6,7,AIR)
B(-2,6,8,AIR)
B(-2,7,-3,AIR)
B(-2,7,-2,98)
B(-2,7,-1,98)
B(-2,7,0,98)
B(-2,7,1,98)
B(-2,7,2,98)
B(-2,7,3,98)
B(-2,7,4,98)
B(-2,7,5,98)
B(-2,7,6,98)
B(-2,7,7,AIR)
B(-2,7,8,AIR)
B(-2,8,-3,AIR)
B(-2,8,-2,AIR)
B(-2,8,-1,44:5)
B(-2,8,0,AIR)
B(-2,8,1,44:5)
B(-2,8,2,AIR)
B(-2,8,3,44:5)
B(-2,8,4,AIR)
B(-2,8,5,44:5)
B(-2,8,6,AIR)
B(-2,8,7,AIR)
B(-2,8,8,AIR)
B(-2,9,-3,AIR)
B(-2,9,-2,AIR)
B(-2,9,-1,AIR)
B(-2,9,0,AIR)
B(-2,9,1,AIR)
B(-2,9,2,AIR)
B(-2,9,3,AIR)
B(-2,9,4,AIR)
B(-2,9,5,AIR)
B(-2,9,6,AIR)
B(-2,9,7,AIR)
B(-2,9,8,AIR)
B(-2,10,-3,AIR)
B(-2,10,-2,AIR)
B(-2,10,-1,AIR)
B(-2,10,0,AIR)
B(-2,10,1,AIR)
B(-2,10,2,AIR)
B(-2,10,3,AIR)
B(-2,10,4,AIR)
B(-2,10,5,AIR)
B(-2,10,6,AIR)
B(-2,10,7,AIR)
B(-2,10,8,AIR)
B(-2,11,-3,AIR)
B(-2,11,-2,AIR)
B(-2,11,-1,AIR)
B(-2,11,0,AIR)
B(-2,11,1,AIR)
B(-2,11,2,AIR)
B(-2,11,3,AIR)
B(-2,11,4,AIR)
B(-2,11,5,AIR)
B(-2,11,6,AIR)
B(-2,11,7,AIR)
B(-2,11,8,AIR)
B(-2,12,-3,AIR)
B(-2,12,-2,AIR)
B(-2,12,-1,AIR)
B(-2,12,0,AIR)
B(-2,12,1,AIR)
B(-2,12,2,AIR)
B(-2,12,3,AIR)
B(-2,12,4,AIR)
B(-2,12,5,AIR)
B(-2,12,6,AIR)
B(-2,12,7,AIR)
B(-2,12,8,AIR)
B(-2,13,-3,AIR)
B(-2,13,-2,AIR)
B(-2,13,-1,44:13)
B(-2,13,0,AIR)
B(-2,13,1,44:13)
B(-2,13,2,AIR)
B(-2,13,3,44:13)
B(-2,13,4,AIR)
B(-2,13,5,44:13)
B(-2,13,6,AIR)
B(-2,13,7,AIR)
B(-2,13,8,AIR)
B(-2,14,-3,AIR)
B(-2,14,-2,98)
B(-2,14,-1,98)
B(-2,14,0,98)
B(-2,14,1,98)
B(-2,14,2,98)
B(-2,14,3,98)
B(-2,14,4,98)
B(-2,14,5,98)
B(-2,14,6,98)
B(-2,14,7,AIR)
B(-2,14,8,AIR)
B(-2,15,-3,AIR)
B(-2,15,-2,98)
B(-2,15,-1,98)
B(-2,15,0,44:5)
B(-2,15,1,98)
B(-2,15,2,98)
B(-2,15,3,98)
B(-2,15,4,44:5)
B(-2,15,5,98)
B(-2,15,6,98)
B(-2,15,7,AIR)
B(-2,15,8,AIR)
B(-2,16,-3,AIR)
B(-2,16,-2,44)
B(-2,16,-1,44)
B(-2,16,0,AIR)
B(-2,16,1,44)
B(-2,16,2,44)
B(-2,16,3,44)
B(-2,16,4,AIR)
B(-2,16,5,44)
B(-2,16,6,44)
B(-2,16,7,AIR)
B(-2,16,8,AIR)
B(-2,17,-3,AIR)
B(-2,17,-2,AIR)
B(-2,17,-1,AIR)
B(-2,17,0,AIR)
B(-2,17,1,AIR)
B(-2,17,2,AIR)
B(-2,17,3,AIR)
B(-2,17,4,AIR)
B(-2,17,5,AIR)
B(-2,17,6,AIR)
B(-2,17,7,AIR)
B(-2,17,8,AIR)
B(-2,18,-3,AIR)
B(-2,18,-2,AIR)
B(-2,18,-1,AIR)
B(-2,18,0,AIR)
B(-2,18,1,AIR)
B(-2,18,2,AIR)
B(-2,18,3,AIR)
B(-2,18,4,AIR)
B(-2,18,5,AIR)
B(-2,18,6,AIR)
B(-2,18,7,AIR)
B(-2,18,8,AIR)
B(-2,19,-3,AIR)
B(-2,19,-2,AIR)
B(-2,19,-1,AIR)
B(-2,19,0,AIR)
B(-2,19,1,AIR)
B(-2,19,2,AIR)
B(-2,19,3,AIR)
B(-2,19,4,AIR)
B(-2,19,5,AIR)
B(-2,19,6,AIR)
B(-2,19,7,AIR)
B(-2,19,8,AIR)
B(-2,20,-3,AIR)
B(-2,20,-2,AIR)
B(-2,20,-1,AIR)
B(-2,20,0,AIR)
B(-2,20,1,AIR)
B(-2,20,2,AIR)
B(-2,20,3,AIR)
B(-2,20,4,AIR)
B(-2,20,5,AIR)
B(-2,20,6,AIR)
B(-2,20,7,AIR)
B(-2,20,8,AIR)
B(-2,21,-3,AIR)
B(-2,21,-2,AIR)
B(-2,21,-1,AIR)
B(-2,21,0,AIR)
B(-2,21,1,AIR)
B(-2,21,2,AIR)
B(-2,21,3,AIR)
B(-2,21,4,AIR)
B(-2,21,5,AIR)
B(-2,21,6,AIR)
B(-2,21,7,AIR)
B(-2,21,8,AIR)
B(-2,22,-3,AIR)
B(-2,22,-2,AIR)
B(-2,22,-1,AIR)
B(-2,22,0,AIR)
B(-2,22,1,AIR)
B(-2,22,2,AIR)
B(-2,22,3,AIR)
B(-2,22,4,AIR)
B(-2,22,5,AIR)
B(-2,22,6,AIR)
B(-2,22,7,AIR)
B(-2,22,8,AIR)
B(-2,23,-3,AIR)
B(-2,23,-2,AIR)
B(-2,23,-1,AIR)
B(-2,23,0,AIR)
B(-2,23,1,AIR)
B(-2,23,2,AIR)
B(-2,23,3,AIR)
B(-2,23,4,AIR)
B(-2,23,5,AIR)
B(-2,23,6,AIR)
B(-2,23,7,AIR)
B(-2,23,8,AIR)
B(-2,24,-3,AIR)
B(-2,24,-2,AIR)
B(-2,24,-1,AIR)
B(-2,24,0,AIR)
B(-2,24,1,AIR)
B(-2,24,2,AIR)
B(-2,24,3,AIR)
B(-2,24,4,AIR)
B(-2,24,5,AIR)
B(-2,24,6,AIR)
B(-2,24,7,AIR)
B(-2,24,8,AIR)
B(-2,25,-3,AIR)
B(-2,25,-2,AIR)
B(-2,25,-1,AIR)
B(-2,25,0,AIR)
B(-2,25,1,AIR)
B(-2,25,2,AIR)
B(-2,25,3,AIR)
B(-2,25,4,AIR)
B(-2,25,5,AIR)
B(-2,25,6,AIR)
B(-2,25,7,AIR)
B(-2,25,8,AIR)
B(-2,26,-3,AIR)
B(-2,26,-2,AIR)
B(-2,26,-1,AIR)
B(-2,26,0,AIR)
B(-2,26,1,AIR)
B(-2,26,2,AIR)
B(-2,26,3,AIR)
B(-2,26,4,AIR)
B(-2,26,5,AIR)
B(-2,26,6,AIR)
B(-2,26,7,AIR)
B(-2,26,8,AIR)
B(-2,27,-3,AIR)
B(-2,27,-2,AIR)
B(-2,27,-1,AIR)
B(-2,27,0,AIR)
B(-2,27,1,AIR)
B(-2,27,2,AIR)
B(-2,27,3,AIR)
B(-2,27,4,AIR)
B(-2,27,5,AIR)
B(-2,27,6,AIR)
B(-2,27,7,AIR)
B(-2,27,8,AIR)
B(-2,28,-3,AIR)
B(-2,28,-2,AIR)
B(-2,28,-1,AIR)
B(-2,28,0,AIR)
B(-2,28,1,AIR)
B(-2,28,2,AIR)
B(-2,28,3,AIR)
B(-2,28,4,AIR)
B(-2,28,5,AIR)
B(-2,28,6,AIR)
B(-2,28,7,AIR)
B(-2,28,8,AIR)
B(-2,29,-3,AIR)
B(-2,29,-2,AIR)
B(-2,29,-1,AIR)
B(-2,29,0,AIR)
B(-2,29,1,AIR)
B(-2,29,2,AIR)
B(-2,29,3,AIR)
B(-2,29,4,AIR)
B(-2,29,5,AIR)
B(-2,29,6,AIR)
B(-2,29,7,AIR)
B(-2,29,8,AIR)
B(-2,30,-3,AIR)
B(-2,30,-2,AIR)
B(-2,30,-1,AIR)
B(-2,30,0,AIR)
B(-2,30,1,AIR)
B(-2,30,2,AIR)
B(-2,30,3,AIR)
B(-2,30,4,AIR)
B(-2,30,5,AIR)
B(-2,30,6,AIR)
B(-2,30,7,AIR)
B(-2,30,8,AIR)
B(-2,31,-3,AIR)
B(-2,31,-2,AIR)
B(-2,31,-1,AIR)
B(-2,31,0,AIR)
B(-2,31,1,AIR)
B(-2,31,2,AIR)
B(-2,31,3,AIR)
B(-2,31,4,AIR)
B(-2,31,5,AIR)
B(-2,31,6,AIR)
B(-2,31,7,AIR)
B(-2,31,8,AIR)
B(-2,32,-3,AIR)
B(-2,32,-2,AIR)
B(-2,32,-1,AIR)
B(-2,32,0,AIR)
B(-2,32,1,AIR)
B(-2,32,2,AIR)
B(-2,32,3,AIR)
B(-2,32,4,AIR)
B(-2,32,5,AIR)
B(-2,32,6,AIR)
B(-2,32,7,AIR)
B(-2,32,8,AIR)
B(-2,33,-3,AIR)
B(-2,33,-2,AIR)
B(-2,33,-1,AIR)
B(-2,33,0,AIR)
B(-2,33,1,AIR)
B(-2,33,2,AIR)
B(-2,33,3,AIR)
B(-2,33,4,AIR)
B(-2,33,5,AIR)
B(-2,33,6,AIR)
B(-2,33,7,AIR)
B(-2,33,8,AIR)
B(-2,34,-3,AIR)
B(-2,34,-2,AIR)
B(-2,34,-1,AIR)
B(-2,34,0,AIR)
B(-2,34,1,AIR)
B(-2,34,2,AIR)
B(-2,34,3,AIR)
B(-2,34,4,AIR)
B(-2,34,5,AIR)
B(-2,34,6,AIR)
B(-2,34,7,AIR)
B(-2,34,8,AIR)
B(-1,-22,-7,1)
B(-1,-22,-6,1)
B(-1,-22,-5,1)
B(-1,-22,-4,1)
B(-1,-22,-3,1)
B(-1,-22,-2,1)
B(-1,-22,-1,1)
B(-1,-22,0,1)
B(-1,-22,1,1)
B(-1,-22,2,1)
B(-1,-22,3,1)
B(-1,-22,4,1)
B(-1,-22,5,1)
B(-1,-22,6,1)
B(-1,-22,7,1)
B(-1,-22,8,1)
B(-1,-21,-7,1)
B(-1,-21,-6,1)
B(-1,-21,-5,1)
B(-1,-21,-4,1)
B(-1,-21,-3,1)
B(-1,-21,-2,1)
B(-1,-21,-1,1)
B(-1,-21,0,1)
B(-1,-21,1,1)
B(-1,-21,2,1)
B(-1,-21,3,1)
B(-1,-21,4,1)
B(-1,-21,5,1)
B(-1,-21,6,1)
B(-1,-21,7,1)
B(-1,-21,8,1)
B(-1,-20,-7,1)
B(-1,-20,-6,1)
B(-1,-20,-5,1)
B(-1,-20,-4,1)
B(-1,-20,-3,1)
B(-1,-20,-2,1)
B(-1,-20,-1,1)
B(-1,-20,0,1)
B(-1,-20,1,1)
B(-1,-20,2,1)
B(-1,-20,3,1)
B(-1,-20,4,1)
B(-1,-20,5,1)
B(-1,-20,6,1)
B(-1,-20,7,1)
B(-1,-20,8,1)
B(-1,-19,-7,1)
B(-1,-19,-6,1)
B(-1,-19,-5,1)
B(-1,-19,-4,1)
B(-1,-19,-3,1)
B(-1,-19,-2,1)
B(-1,-19,-1,1)
B(-1,-19,0,1)
B(-1,-19,1,1)
B(-1,-19,2,1)
B(-1,-19,3,1)
B(-1,-19,4,1)
B(-1,-19,5,1)
B(-1,-19,6,1)
B(-1,-19,7,1)
B(-1,-19,8,1)
B(-1,-18,-7,1)
B(-1,-18,-6,1)
B(-1,-18,-5,1)
B(-1,-18,-4,1)
B(-1,-18,-3,1)
B(-1,-18,-2,1)
B(-1,-18,-1,1)
B(-1,-18,0,1)
B(-1,-18,1,1)
B(-1,-18,2,1)
B(-1,-18,3,1)
B(-1,-18,4,1)
B(-1,-18,5,1)
B(-1,-18,6,1)
B(-1,-18,7,1)
B(-1,-18,8,1)
B(-1,-17,-7,1)
B(-1,-17,-6,1)
B(-1,-17,-5,1)
B(-1,-17,-4,1)
B(-1,-17,-3,1)
B(-1,-17,-2,1)
B(-1,-17,-1,1)
B(-1,-17,0,1)
B(-1,-17,1,1)
B(-1,-17,2,1)
B(-1,-17,3,1)
B(-1,-17,4,1)
B(-1,-17,5,1)
B(-1,-17,6,1)
B(-1,-17,7,1)
B(-1,-17,8,1)
B(-1,-16,-7,1)
B(-1,-16,-6,1)
B(-1,-16,-5,1)
B(-1,-16,-4,1)
B(-1,-16,-3,1)
B(-1,-16,-2,1)
B(-1,-16,-1,1)
B(-1,-16,0,1)
B(-1,-16,1,1)
B(-1,-16,2,1)
B(-1,-16,3,1)
B(-1,-16,4,1)
B(-1,-16,5,1)
B(-1,-16,6,1)
B(-1,-16,7,1)
B(-1,-16,8,1)
B(-1,-15,-7,1)
B(-1,-15,-6,1)
B(-1,-15,-5,1)
B(-1,-15,-4,1)
B(-1,-15,-3,1)
B(-1,-15,-2,1)
B(-1,-15,-1,1)
B(-1,-15,0,1)
B(-1,-15,1,1)
B(-1,-15,2,1)
B(-1,-15,3,1)
B(-1,-15,4,1)
B(-1,-15,5,1)
B(-1,-15,6,1)
B(-1,-15,7,1)
B(-1,-15,8,1)
B(-1,-14,-7,1)
B(-1,-14,-6,1)
B(-1,-14,-5,1)
B(-1,-14,-4,1)
B(-1,-14,-3,1)
B(-1,-14,-2,1)
B(-1,-14,-1,1)
B(-1,-14,0,1)
B(-1,-14,1,1)
B(-1,-14,2,1)
B(-1,-14,3,1)
B(-1,-14,4,1)
B(-1,-14,5,1)
B(-1,-14,6,1)
B(-1,-14,7,1)
B(-1,-14,8,1)
B(-1,-13,-7,1)
B(-1,-13,-6,1)
B(-1,-13,-5,1)
B(-1,-13,-4,1)
B(-1,-13,-3,1)
B(-1,-13,-2,1)
B(-1,-13,-1,1)
B(-1,-13,0,1)
B(-1,-13,1,1)
B(-1,-13,2,1)
B(-1,-13,3,1)
B(-1,-13,4,1)
B(-1,-13,5,1)
B(-1,-13,6,1)
B(-1,-13,7,1)
B(-1,-13,8,1)
B(-1,-12,-7,1)
B(-1,-12,-6,1)
B(-1,-12,-5,1)
B(-1,-12,-4,1)
B(-1,-12,-3,1)
B(-1,-12,-2,1)
B(-1,-12,-1,1)
B(-1,-12,0,1)
B(-1,-12,1,1)
B(-1,-12,2,1)
B(-1,-12,3,1)
B(-1,-12,4,1)
B(-1,-12,5,1)
B(-1,-12,6,1)
B(-1,-12,7,1)
B(-1,-12,8,1)
B(-1,-11,-7,1)
B(-1,-11,-6,1)
B(-1,-11,-5,1)
B(-1,-11,-4,1)
B(-1,-11,-3,1)
B(-1,-11,-2,1)
B(-1,-11,-1,1)
B(-1,-11,0,1)
B(-1,-11,1,1)
B(-1,-11,2,1)
B(-1,-11,3,1)
B(-1,-11,4,1)
B(-1,-11,5,1)
B(-1,-11,6,1)
B(-1,-11,7,1)
B(-1,-11,8,1)
B(-1,-10,-7,1)
B(-1,-10,-6,1)
B(-1,-10,-5,1)
B(-1,-10,-4,1)
B(-1,-10,-3,1)
B(-1,-10,-2,1)
B(-1,-10,-1,1)
B(-1,-10,0,1)
B(-1,-10,1,1)
B(-1,-10,2,1)
B(-1,-10,3,1)
B(-1,-10,4,1)
B(-1,-10,5,1)
B(-1,-10,6,1)
B(-1,-10,7,1)
B(-1,-10,8,1)
B(-1,-9,-7,1)
B(-1,-9,-6,1)
B(-1,-9,-5,1)
B(-1,-9,-4,1)
B(-1,-9,-3,1)
B(-1,-9,-2,1)
B(-1,-9,-1,1)
B(-1,-9,0,1)
B(-1,-9,1,1)
B(-1,-9,2,1)
B(-1,-9,3,1)
B(-1,-9,4,1)
B(-1,-9,5,1)
B(-1,-9,6,1)
B(-1,-9,7,1)
B(-1,-9,8,1)
B(-1,-8,-6,1)
B(-1,-8,-5,1)
B(-1,-8,-4,1)
B(-1,-8,-3,1)
B(-1,-8,-2,1)
B(-1,-8,-1,1)
B(-1,-8,0,1)
B(-1,-8,1,1)
B(-1,-8,2,1)
B(-1,-8,3,1)
B(-1,-8,4,1)
B(-1,-8,5,1)
B(-1,-8,6,1)
B(-1,-8,7,1)
B(-1,-8,8,1)
B(-1,-7,-6,1)
B(-1,-7,-5,1)
B(-1,-7,-4,1)
B(-1,-7,-3,1)
B(-1,-7,-2,1)
B(-1,-7,-1,1)
B(-1,-7,0,1)
B(-1,-7,1,1)
B(-1,-7,2,1)
B(-1,-7,3,1)
B(-1,-7,4,1)
B(-1,-7,5,1)
B(-1,-7,6,1)
B(-1,-7,7,1)
B(-1,-7,8,1)
B(-1,-6,-6,1)
B(-1,-6,-5,1)
B(-1,-6,-4,1)
B(-1,-6,-3,1)
B(-1,-6,-2,1)
B(-1,-6,-1,1)
B(-1,-6,0,1)
B(-1,-6,1,1)
B(-1,-6,2,1)
B(-1,-6,3,1)
B(-1,-6,4,1)
B(-1,-6,5,1)
B(-1,-6,6,1)
B(-1,-6,7,1)
B(-1,-6,8,1)
B(-1,-5,-5,1)
B(-1,-5,-4,1)
B(-1,-5,-3,1)
B(-1,-5,-2,1)
B(-1,-5,-1,1)
B(-1,-5,0,1)
B(-1,-5,1,1)
B(-1,-5,2,1)
B(-1,-5,3,1)
B(-1,-5,4,1)
B(-1,-5,5,1)
B(-1,-5,6,1)
B(-1,-5,7,1)
B(-1,-5,8,1)
B(-1,-4,-5,1)
B(-1,-4,-4,1)
B(-1,-4,-3,1)
B(-1,-4,-2,1)
B(-1,-4,-1,1)
B(-1,-4,0,1)
B(-1,-4,1,1)
B(-1,-4,2,1)
B(-1,-4,3,1)
B(-1,-4,4,1)
B(-1,-4,5,1)
B(-1,-4,6,1)
B(-1,-4,7,1)
B(-1,-4,8,1)
B(-1,-3,-4,1)
B(-1,-3,-3,1)
B(-1,-3,-2,1)
B(-1,-3,-1,1)
B(-1,-3,0,1)
B(-1,-3,1,1)
B(-1,-3,2,1)
B(-1,-3,3,1)
B(-1,-3,4,1)
B(-1,-3,5,1)
B(-1,-3,6,1)
B(-1,-3,7,1)
B(-1,-3,8,1)
B(-1,-2,-4,1)
B(-1,-2,-3,1)
B(-1,-2,-2,1)
B(-1,-2,-1,1)
B(-1,-2,0,1)
B(-1,-2,1,1)
B(-1,-2,2,1)
B(-1,-2,3,1)
B(-1,-2,4,1)
B(-1,-2,5,1)
B(-1,-2,6,1)
B(-1,-2,7,1)
B(-1,-2,8,1)
B(-1,-1,-4,1)
B(-1,-1,-3,1)
B(-1,-1,-2,1)
B(-1,-1,-1,1)
B(-1,-1,0,1)
B(-1,-1,1,1)
B(-1,-1,2,1)
B(-1,-1,3,1)
B(-1,-1,4,1)
B(-1,-1,5,1)
B(-1,-1,6,1)
B(-1,-1,7,1)
B(-1,-1,8,1)
B(-1,0,-4,1)
B(-1,0,-3,98)
B(-1,0,-2,98)
B(-1,0,-1,1)
B(-1,0,0,1)
B(-1,0,1,1)
B(-1,0,2,1)
B(-1,0,3,1)
B(-1,0,4,1)
B(-1,0,5,1)
B(-1,0,6,1)
B(-1,0,7,1)
B(-1,0,8,1)
B(-1,1,-3,98)
B(-1,1,-2,98)
B(-1,1,-1,98)
B(-1,1,0,98)
B(-1,1,1,98)
B(-1,1,2,98)
B(-1,1,3,98)
B(-1,1,4,98)
B(-1,1,5,98)
B(-1,1,6,98)
B(-1,1,7,1)
B(-1,1,8,1)
B(-1,2,-3,98)
B(-1,2,-2,98)
B(-1,2,-1,98)
B(-1,2,0,98)
B(-1,2,1,98)
B(-1,2,2,98)
B(-1,2,3,98)
B(-1,2,4,98)
B(-1,2,5,98)
B(-1,2,6,98)
B(-1,2,7,1)
B(-1,2,8,1)
B(-1,3,-3,98)
B(-1,3,-2,98)
B(-1,3,-1,98)
B(-1,3,0,98)
B(-1,3,1,98)
B(-1,3,2,98)
B(-1,3,3,98)
B(-1,3,4,98)
B(-1,3,5,98)
B(-1,3,6,98)
B(-1,3,7,1)
B(-1,3,8,1)
B(-1,4,-3,98)
B(-1,4,-2,98)
B(-1,4,-1,98)
B(-1,4,0,98)
B(-1,4,1,98)
B(-1,4,2,98)
B(-1,4,3,98)
B(-1,4,4,98)
B(-1,4,5,98)
B(-1,4,6,98)
B(-1,4,7,98)
B(-1,4,8,AIR)
B(-1,5,-3,AIR)
B(-1,5,-2,AIR)
B(-1,5,-1,159:7)
B(-1,5,0,98)
B(-1,5,1,98)
B(-1,5,2,159:7)
B(-1,5,3,98)
B(-1,5,4,98)
B(-1,5,5,159:7)
B(-1,5,6,AIR)
B(-1,5,7,AIR)
B(-1,5,8,AIR)
B(-1,6,-3,AIR)
B(-1,6,-2,AIR)
B(-1,6,-1,159:7)
B(-1,6,0,98)
B(-1,6,1,98)
B(-1,6,2,159:7)
B(-1,6,3,98)
B(-1,6,4,98)
B(-1,6,5,159:7)
B(-1,6,6,AIR)
B(-1,6,7,AIR)
B(-1,6,8,AIR)
B(-1,7,-3,AIR)
B(-1,7,-2,98)
B(-1,7,-1,98)
B(-1,7,0,98)
B(-1,7,1,98)
B(-1,7,2,98)
B(-1,7,3,98)
B(-1,7,4,98)
B(-1,7,5,98)
B(-1,7,6,98)
B(-1,7,7,AIR)
B(-1,7,8,AIR)
B(-1,8,-3,AIR)
B(-1,8,-2,44:5)
B(-1,8,-1,98)
B(-1,8,0,98)
B(-1,8,1,98)
B(-1,8,2,98)
B(-1,8,3,98)
B(-1,8,4,98)
B(-1,8,5,98)
B(-1,8,6,44:5)
B(-1,8,7,AIR)
B(-1,8,8,AIR)
B(-1,9,-3,AIR)
B(-1,9,-2,AIR)
B(-1,9,-1,98)
B(-1,9,0,159:7)
B(-1,9,1,159:7)
B(-1,9,2,159:7)
B(-1,9,3,159:7)
B(-1,9,4,159:7)
B(-1,9,5,98)
B(-1,9,6,AIR)
B(-1,9,7,AIR)
B(-1,9,8,AIR)
B(-1,10,-3,AIR)
B(-1,10,-2,AIR)
B(-1,10,-1,98)
B(-1,10,0,98)
B(-1,10,1,159:7)
B(-1,10,2,101)
B(-1,10,3,159:7)
B(-1,10,4,98)
B(-1,10,5,98)
B(-1,10,6,AIR)
B(-1,10,7,AIR)
B(-1,10,8,AIR)
B(-1,11,-3,AIR)
B(-1,11,-2,AIR)
B(-1,11,-1,98)
B(-1,11,0,98)
B(-1,11,1,159:7)
B(-1,11,2,101)
B(-1,11,3,159:7)
B(-1,11,4,98)
B(-1,11,5,98)
B(-1,11,6,AIR)
B(-1,11,7,AIR)
B(-1,11,8,AIR)
B(-1,12,-3,AIR)
B(-1,12,-2,AIR)
B(-1,12,-1,98)
B(-1,12,0,159:7)
B(-1,12,1,159:7)
B(-1,12,2,159:7)
B(-1,12,3,159:7)
B(-1,12,4,159:7)
B(-1,12,5,98)
B(-1,12,6,AIR)
B(-1,12,7,AIR)
B(-1,12,8,AIR)
B(-1,13,-3,AIR)
B(-1,13,-2,44:13)
B(-1,13,-1,98)
B(-1,13,0,98)
B(-1,13,1,98)
B(-1,13,2,98)
B(-1,13,3,98)
B(-1,13,4,98)
B(-1,13,5,98)
B(-1,13,6,44:13)
B(-1,13,7,AIR)
B(-1,13,8,AIR)
B(-1,14,-3,AIR)
B(-1,14,-2,98)
B(-1,14,-1,98)
B(-1,14,0,98)
B(-1,14,1,98)
B(-1,14,2,98)
B(-1,14,3,98)
B(-1,14,4,98)
B(-1,14,5,98)
B(-1,14,6,98)
B(-1,14,7,AIR)
B(-1,14,8,AIR)
B(-1,15,-3,AIR)
B(-1,15,-2,98)
B(-1,15,-1,AIR)
B(-1,15,0,AIR)
B(-1,15,1,AIR)
B(-1,15,2,AIR)
B(-1,15,3,AIR)
B(-1,15,4,AIR)
B(-1,15,5,AIR)
B(-1,15,6,98)
B(-1,15,7,AIR)
B(-1,15,8,AIR)
B(-1,16,-3,AIR)
B(-1,16,-2,44)
B(-1,16,-1,AIR)
B(-1,16,0,AIR)
B(-1,16,1,AIR)
B(-1,16,2,AIR)
B(-1,16,3,AIR)
B(-1,16,4,AIR)
B(-1,16,5,AIR)
B(-1,16,6,44)
B(-1,16,7,AIR)
B(-1,16,8,AIR)
B(-1,17,-3,AIR)
B(-1,17,-2,AIR)
B(-1,17,-1,AIR)
B(-1,17,0,AIR)
B(-1,17,1,AIR)
B(-1,17,2,AIR)
B(-1,17,3,AIR)
B(-1,17,4,AIR)
B(-1,17,5,AIR)
B(-1,17,6,AIR)
B(-1,17,7,AIR)
B(-1,17,8,AIR)
B(-1,18,-3,AIR)
B(-1,18,-2,AIR)
B(-1,18,-1,AIR)
B(-1,18,0,AIR)
B(-1,18,1,AIR)
B(-1,18,2,AIR)
B(-1,18,3,AIR)
B(-1,18,4,AIR)
B(-1,18,5,AIR)
B(-1,18,6,AIR)
B(-1,18,7,AIR)
B(-1,18,8,AIR)
B(-1,19,-3,AIR)
B(-1,19,-2,AIR)
B(-1,19,-1,AIR)
B(-1,19,0,AIR)
B(-1,19,1,AIR)
B(-1,19,2,AIR)
B(-1,19,3,AIR)
B(-1,19,4,AIR)
B(-1,19,5,AIR)
B(-1,19,6,AIR)
B(-1,19,7,AIR)
B(-1,19,8,AIR)
B(-1,20,-3,AIR)
B(-1,20,-2,AIR)
B(-1,20,-1,AIR)
B(-1,20,0,AIR)
B(-1,20,1,AIR)
B(-1,20,2,AIR)
B(-1,20,3,AIR)
B(-1,20,4,AIR)
B(-1,20,5,AIR)
B(-1,20,6,AIR)
B(-1,20,7,AIR)
B(-1,20,8,AIR)
B(-1,21,-3,AIR)
B(-1,21,-2,AIR)
B(-1,21,-1,AIR)
B(-1,21,0,AIR)
B(-1,21,1,AIR)
B(-1,21,2,AIR)
B(-1,21,3,AIR)
B(-1,21,4,AIR)
B(-1,21,5,AIR)
B(-1,21,6,AIR)
B(-1,21,7,AIR)
B(-1,21,8,AIR)
B(-1,22,-3,AIR)
B(-1,22,-2,AIR)
B(-1,22,-1,AIR)
B(-1,22,0,AIR)
B(-1,22,1,AIR)
B(-1,22,2,AIR)
B(-1,22,3,AIR)
B(-1,22,4,AIR)
B(-1,22,5,AIR)
B(-1,22,6,AIR)
B(-1,22,7,AIR)
B(-1,22,8,AIR)
B(-1,23,-3,AIR)
B(-1,23,-2,AIR)
B(-1,23,-1,AIR)
B(-1,23,0,AIR)
B(-1,23,1,AIR)
B(-1,23,2,AIR)
B(-1,23,3,AIR)
B(-1,23,4,AIR)
B(-1,23,5,AIR)
B(-1,23,6,AIR)
B(-1,23,7,AIR)
B(-1,23,8,AIR)
B(-1,24,-3,AIR)
B(-1,24,-2,AIR)
B(-1,24,-1,AIR)
B(-1,24,0,44:13)
B(-1,24,1,AIR)
B(-1,24,2,44:13)
B(-1,24,3,AIR)
B(-1,24,4,44:13)
B(-1,24,5,AIR)
B(-1,24,6,AIR)
B(-1,24,7,AIR)
B(-1,24,8,AIR)
B(-1,25,-3,AIR)
B(-1,25,-2,AIR)
B(-1,25,-1,98)
B(-1,25,0,98)
B(-1,25,1,98)
B(-1,25,2,98)
B(-1,25,3,98)
B(-1,25,4,98)
B(-1,25,5,98)
B(-1,25,6,AIR)
B(-1,25,7,AIR)
B(-1,25,8,AIR)
B(-1,26,-3,AIR)
B(-1,26,-2,AIR)
B(-1,26,-1,98)
B(-1,26,0,98)
B(-1,26,1,44:5)
B(-1,26,2,98)
B(-1,26,3,44:5)
B(-1,26,4,98)
B(-1,26,5,98)
B(-1,26,6,AIR)
B(-1,26,7,AIR)
B(-1,26,8,AIR)
B(-1,27,-3,AIR)
B(-1,27,-2,AIR)
B(-1,27,-1,44)
B(-1,27,0,44)
B(-1,27,1,AIR)
B(-1,27,2,44)
B(-1,27,3,AIR)
B(-1,27,4,44)
B(-1,27,5,44)
B(-1,27,6,AIR)
B(-1,27,7,AIR)
B(-1,27,8,AIR)
B(-1,28,-3,AIR)
B(-1,28,-2,AIR)
B(-1,28,-1,AIR)
B(-1,28,0,AIR)
B(-1,28,1,AIR)
B(-1,28,2,AIR)
B(-1,28,3,AIR)
B(-1,28,4,AIR)
B(-1,28,5,AIR)
B(-1,28,6,AIR)
B(-1,28,7,AIR)
B(-1,28,8,AIR)
B(-1,29,-3,AIR)
B(-1,29,-2,AIR)
B(-1,29,-1,AIR)
B(-1,29,0,AIR)
B(-1,29,1,AIR)
B(-1,29,2,AIR)
B(-1,29,3,AIR)
B(-1,29,4,AIR)
B(-1,29,5,AIR)
B(-1,29,6,AIR)
B(-1,29,7,AIR)
B(-1,29,8,AIR)
B(-1,30,-3,AIR)
B(-1,30,-2,AIR)
B(-1,30,-1,AIR)
B(-1,30,0,AIR)
B(-1,30,1,AIR)
B(-1,30,2,AIR)
B(-1,30,3,AIR)
B(-1,30,4,AIR)
B(-1,30,5,AIR)
B(-1,30,6,AIR)
B(-1,30,7,AIR)
B(-1,30,8,AIR)
B(-1,31,-3,AIR)
B(-1,31,-2,AIR)
B(-1,31,-1,AIR)
B(-1,31,0,AIR)
B(-1,31,1,AIR)
B(-1,31,2,AIR)
B(-1,31,3,AIR)
B(-1,31,4,AIR)
B(-1,31,5,AIR)
B(-1,31,6,AIR)
B(-1,31,7,AIR)
B(-1,31,8,AIR)
B(-1,32,-3,AIR)
B(-1,32,-2,AIR)
B(-1,32,-1,AIR)
B(-1,32,0,AIR)
B(-1,32,1,AIR)
B(-1,32,2,AIR)
B(-1,32,3,AIR)
B(-1,32,4,AIR)
B(-1,32,5,AIR)
B(-1,32,6,AIR)
B(-1,32,7,AIR)
B(-1,32,8,AIR)
B(-1,33,-3,AIR)
B(-1,33,-2,AIR)
B(-1,33,-1,AIR)
B(-1,33,0,AIR)
B(-1,33,1,AIR)
B(-1,33,2,AIR)
B(-1,33,3,AIR)
B(-1,33,4,AIR)
B(-1,33,5,AIR)
B(-1,33,6,AIR)
B(-1,33,7,AIR)
B(-1,33,8,AIR)
B(-1,34,-3,AIR)
B(-1,34,-2,AIR)
B(-1,34,-1,AIR)
B(-1,34,0,AIR)
B(-1,34,1,AIR)
B(-1,34,2,AIR)
B(-1,34,3,AIR)
B(-1,34,4,AIR)
B(-1,34,5,AIR)
B(-1,34,6,AIR)
B(-1,34,7,AIR)
B(-1,34,8,AIR)
B(0,-22,-7,1)
B(0,-22,-6,1)
B(0,-22,-5,1)
B(0,-22,-4,1)
B(0,-22,-3,1)
B(0,-22,-2,1)
B(0,-22,-1,1)
B(0,-22,0,1)
B(0,-22,1,1)
B(0,-22,2,1)
B(0,-22,3,1)
B(0,-22,4,1)
B(0,-22,5,1)
B(0,-22,6,1)
B(0,-22,7,1)
B(0,-22,8,1)
B(0,-21,-7,1)
B(0,-21,-6,1)
B(0,-21,-5,1)
B(0,-21,-4,1)
B(0,-21,-3,1)
B(0,-21,-2,1)
B(0,-21,-1,1)
B(0,-21,0,1)
B(0,-21,1,1)
B(0,-21,2,1)
B(0,-21,3,1)
B(0,-21,4,1)
B(0,-21,5,1)
B(0,-21,6,1)
B(0,-21,7,1)
B(0,-21,8,1)
B(0,-20,-7,1)
B(0,-20,-6,1)
B(0,-20,-5,1)
B(0,-20,-4,1)
B(0,-20,-3,1)
B(0,-20,-2,1)
B(0,-20,-1,1)
B(0,-20,0,1)
B(0,-20,1,1)
B(0,-20,2,1)
B(0,-20,3,1)
B(0,-20,4,1)
B(0,-20,5,1)
B(0,-20,6,1)
B(0,-20,7,1)
B(0,-20,8,1)
B(0,-19,-7,1)
B(0,-19,-6,1)
B(0,-19,-5,1)
B(0,-19,-4,1)
B(0,-19,-3,1)
B(0,-19,-2,1)
B(0,-19,-1,1)
B(0,-19,0,1)
B(0,-19,1,1)
B(0,-19,2,1)
B(0,-19,3,1)
B(0,-19,4,1)
B(0,-19,5,1)
B(0,-19,6,1)
B(0,-19,7,1)
B(0,-19,8,1)
B(0,-18,-7,1)
B(0,-18,-6,1)
B(0,-18,-5,1)
B(0,-18,-4,1)
B(0,-18,-3,1)
B(0,-18,-2,1)
B(0,-18,-1,1)
B(0,-18,0,1)
B(0,-18,1,1)
B(0,-18,2,1)
B(0,-18,3,1)
B(0,-18,4,1)
B(0,-18,5,1)
B(0,-18,6,1)
B(0,-18,7,1)
B(0,-18,8,1)
B(0,-17,-7,1)
B(0,-17,-6,1)
B(0,-17,-5,1)
B(0,-17,-4,1)
B(0,-17,-3,1)
B(0,-17,-2,1)
B(0,-17,-1,1)
B(0,-17,0,1)
B(0,-17,1,1)
B(0,-17,2,1)
B(0,-17,3,1)
B(0,-17,4,1)
B(0,-17,5,1)
B(0,-17,6,1)
B(0,-17,7,1)
B(0,-17,8,1)
B(0,-16,-7,1)
B(0,-16,-6,1)
B(0,-16,-5,1)
B(0,-16,-4,1)
B(0,-16,-3,1)
B(0,-16,-2,1)
B(0,-16,-1,1)
B(0,-16,0,1)
B(0,-16,1,1)
B(0,-16,2,1)
B(0,-16,3,1)
B(0,-16,4,1)
B(0,-16,5,1)
B(0,-16,6,1)
B(0,-16,7,1)
B(0,-16,8,1)
B(0,-15,-7,1)
B(0,-15,-6,1)
B(0,-15,-5,1)
B(0,-15,-4,1)
B(0,-15,-3,1)
B(0,-15,-2,1)
B(0,-15,-1,1)
B(0,-15,0,1)
B(0,-15,1,1)
B(0,-15,2,1)
B(0,-15,3,1)
B(0,-15,4,1)
B(0,-15,5,1)
B(0,-15,6,1)
B(0,-15,7,1)
B(0,-15,8,1)
B(0,-14,-7,1)
B(0,-14,-6,1)
B(0,-14,-5,1)
B(0,-14,-4,1)
B(0,-14,-3,1)
B(0,-14,-2,1)
B(0,-14,-1,1)
B(0,-14,0,1)
B(0,-14,1,1)
B(0,-14,2,1)
B(0,-14,3,1)
B(0,-14,4,1)
B(0,-14,5,1)
B(0,-14,6,1)
B(0,-14,7,1)
B(0,-14,8,1)
B(0,-13,-7,1)
B(0,-13,-6,1)
B(0,-13,-5,1)
B(0,-13,-4,1)
B(0,-13,-3,1)
B(0,-13,-2,1)
B(0,-13,-1,1)
B(0,-13,0,1)
B(0,-13,1,1)
B(0,-13,2,1)
B(0,-13,3,1)
B(0,-13,4,1)
B(0,-13,5,1)
B(0,-13,6,1)
B(0,-13,7,1)
B(0,-13,8,1)
B(0,-12,-7,1)
B(0,-12,-6,1)
B(0,-12,-5,1)
B(0,-12,-4,1)
B(0,-12,-3,1)
B(0,-12,-2,1)
B(0,-12,-1,1)
B(0,-12,0,1)
B(0,-12,1,1)
B(0,-12,2,1)
B(0,-12,3,1)
B(0,-12,4,1)
B(0,-12,5,1)
B(0,-12,6,1)
B(0,-12,7,1)
B(0,-12,8,1)
B(0,-11,-7,1)
B(0,-11,-6,1)
B(0,-11,-5,1)
B(0,-11,-4,1)
B(0,-11,-3,1)
B(0,-11,-2,1)
B(0,-11,-1,1)
B(0,-11,0,1)
B(0,-11,1,1)
B(0,-11,2,1)
B(0,-11,3,1)
B(0,-11,4,1)
B(0,-11,5,1)
B(0,-11,6,1)
B(0,-11,7,1)
B(0,-11,8,1)
B(0,-10,-7,1)
B(0,-10,-6,1)
B(0,-10,-5,1)
B(0,-10,-4,1)
B(0,-10,-3,1)
B(0,-10,-2,1)
B(0,-10,-1,1)
B(0,-10,0,1)
B(0,-10,1,1)
B(0,-10,2,1)
B(0,-10,3,1)
B(0,-10,4,1)
B(0,-10,5,1)
B(0,-10,6,1)
B(0,-10,7,1)
B(0,-10,8,1)
B(0,-9,-7,1)
B(0,-9,-6,1)
B(0,-9,-5,1)
B(0,-9,-4,1)
B(0,-9,-3,1)
B(0,-9,-2,1)
B(0,-9,-1,1)
B(0,-9,0,1)
B(0,-9,1,1)
B(0,-9,2,1)
B(0,-9,3,1)
B(0,-9,4,1)
B(0,-9,5,1)
B(0,-9,6,1)
B(0,-9,7,1)
B(0,-9,8,1)
B(0,-8,-7,1)
B(0,-8,-6,1)
B(0,-8,-5,1)
B(0,-8,-4,1)
B(0,-8,-3,1)
B(0,-8,-2,1)
B(0,-8,-1,1)
B(0,-8,0,1)
B(0,-8,1,1)
B(0,-8,2,1)
B(0,-8,3,1)
B(0,-8,4,1)
B(0,-8,5,1)
B(0,-8,6,1)
B(0,-8,7,1)
B(0,-8,8,1)
B(0,-7,-6,1)
B(0,-7,-5,1)
B(0,-7,-4,1)
B(0,-7,-3,1)
B(0,-7,-2,1)
B(0,-7,-1,1)
B(0,-7,0,1)
B(0,-7,1,1)
B(0,-7,2,1)
B(0,-7,3,1)
B(0,-7,4,1)
B(0,-7,5,1)
B(0,-7,6,1)
B(0,-7,7,1)
B(0,-7,8,1)
B(0,-6,-6,1)
B(0,-6,-5,1)
B(0,-6,-4,1)
B(0,-6,-3,1)
B(0,-6,-2,1)
B(0,-6,-1,1)
B(0,-6,0,1)
B(0,-6,1,1)
B(0,-6,2,1)
B(0,-6,3,1)
B(0,-6,4,1)
B(0,-6,5,1)
B(0,-6,6,1)
B(0,-6,7,1)
B(0,-6,8,1)
B(0,-5,-5,1)
B(0,-5,-4,1)
B(0,-5,-3,1)
B(0,-5,-2,1)
B(0,-5,-1,1)
B(0,-5,0,1)
B(0,-5,1,1)
B(0,-5,2,1)
B(0,-5,3,1)
B(0,-5,4,1)
B(0,-5,5,1)
B(0,-5,6,1)
B(0,-5,7,1)
B(0,-5,8,1)
B(0,-4,-5,1)
B(0,-4,-4,1)
B(0,-4,-3,1)
B(0,-4,-2,1)
B(0,-4,-1,1)
B(0,-4,0,1)
B(0,-4,1,1)
B(0,-4,2,1)
B(0,-4,3,1)
B(0,-4,4,1)
B(0,-4,5,1)
B(0,-4,6,1)
B(0,-4,7,1)
B(0,-4,8,1)
B(0,-3,-4,1)
B(0,-3,-3,1)
B(0,-3,-2,1)
B(0,-3,-1,1)
B(0,-3,0,1)
B(0,-3,1,1)
B(0,-3,2,1)
B(0,-3,3,1)
B(0,-3,4,1)
B(0,-3,5,1)
B(0,-3,6,1)
B(0,-3,7,1)
B(0,-3,8,1)
B(0,-2,-4,1)
B(0,-2,-3,1)
B(0,-2,-2,1)
B(0,-2,-1,1)
B(0,-2,0,1)
B(0,-2,1,1)
B(0,-2,2,1)
B(0,-2,3,1)
B(0,-2,4,1)
B(0,-2,5,1)
B(0,-2,6,1)
B(0,-2,7,1)
B(0,-2,8,1)
B(0,-1,-4,1)
B(0,-1,-3,1)
B(0,-1,-2,1)
B(0,-1,-1,1)
B(0,-1,0,1)
B(0,-1,1,1)
B(0,-1,2,1)
B(0,-1,3,1)
B(0,-1,4,1)
B(0,-1,5,1)
B(0,-1,6,1)
B(0,-1,7,1)
B(0,-1,8,1)
B(0,0,-3,1)
B(0,0,-2,1)
B(0,0,-1,1)
B(0,0,0,1)
B(0,0,1,1)
B(0,0,2,1)
B(0,0,3,1)
B(0,0,4,1)
B(0,0,5,1)
B(0,0,6,1)
B(0,0,7,1)
B(0,0,8,1)
B(0,1,-3,AIR)
B(0,1,-2,98)
B(0,1,-1,98)
B(0,1,0,98)
B(0,1,1,98)
B(0,1,2,98)
B(0,1,3,98)
B(0,1,4,98)
B(0,1,5,98)
B(0,1,6,98)
B(0,1,7,1)
B(0,1,8,1)
B(0,2,-3,AIR)
B(0,2,-2,98)
B(0,2,-1,98)
B(0,2,0,98)
B(0,2,1,98)
B(0,2,2,98)
B(0,2,3,98)
B(0,2,4,98)
B(0,2,5,98)
B(0,2,6,98)
B(0,2,7,1)
B(0,2,8,1)
B(0,3,-3,AIR)
B(0,3,-2,98)
B(0,3,-1,98)
B(0,3,0,98)
B(0,3,1,98)
B(0,3,2,98)
B(0,3,3,98)
B(0,3,4,98)
B(0,3,5,98)
B(0,3,6,98)
B(0,3,7,1)
B(0,3,8,1)
B(0,4,-3,98)
B(0,4,-2,98)
B(0,4,-1,98)
B(0,4,0,98)
B(0,4,1,126:13)
B(0,4,2,126:13)
B(0,4,3,126:13)
B(0,4,4,126:13)
B(0,4,5,98)
B(0,4,6,98)
B(0,4,7,1)
B(0,4,8,1)
B(0,5,-3,AIR)
B(0,5,-2,98)
B(0,5,-1,98)
B(0,5,0,43:5)
B(0,5,1,43:5)
B(0,5,2,43:5)
B(0,5,3,58)
RB(0,5,4,FURNACE:3,../../nbt/Misc/Furnace.nbt,50,FURNACE:3,../../nbt/Misc/Furnace2.nbt,50,FURNACE:3,../../nbt/Misc/Furnace3.nbt,100)
B(0,5,5,98)
B(0,5,6,98)
B(0,5,7,1)
B(0,5,8,1)
B(0,6,-3,AIR)
B(0,6,-2,98)
B(0,6,-1,98)
B(0,6,0,43:5)
B(0,6,1,43:5)
B(0,6,2,43:5)
B(0,6,3,44:13)
B(0,6,4,AIR)
B(0,6,5,43:5)
B(0,6,6,98)
B(0,6,7,1)
B(0,6,8,1)
B(0,7,-3,AIR)
B(0,7,-2,98)
B(0,7,-1,98)
B(0,7,0,43:5)
B(0,7,1,43:5)
B(0,7,2,43:5)
B(0,7,3,43:5)
B(0,7,4,43:5)
B(0,7,5,98)
B(0,7,6,98)
B(0,7,7,1)
B(0,7,8,AIR)
B(0,8,-3,AIR)
B(0,8,-2,AIR)
B(0,8,-1,98)
B(0,8,0,AIR)
B(0,8,1,44:5)
B(0,8,2,43:5)
B(0,8,3,98)
B(0,8,4,98)
B(0,8,5,98)
B(0,8,6,1)
B(0,8,7,AIR)
B(0,8,8,AIR)
B(0,9,-3,AIR)
B(0,9,-2,AIR)
B(0,9,-1,159:7)
B(0,9,0,AIR)
B(0,9,1,AIR)
B(0,9,2,AIR)
B(0,9,3,AIR)
B(0,9,4,AIR)
B(0,9,5,159:7)
B(0,9,6,AIR)
B(0,9,7,AIR)
B(0,9,8,AIR)
B(0,10,-3,AIR)
B(0,10,-2,AIR)
B(0,10,-1,98)
B(0,10,0,AIR)
B(0,10,1,AIR)
B(0,10,2,AIR)
B(0,10,3,AIR)
B(0,10,4,AIR)
B(0,10,5,98)
B(0,10,6,AIR)
B(0,10,7,AIR)
B(0,10,8,AIR)
B(0,11,-3,AIR)
B(0,11,-2,AIR)
B(0,11,-1,98)
B(0,11,0,AIR)
B(0,11,1,AIR)
B(0,11,2,AIR)
B(0,11,3,AIR)
B(0,11,4,AIR)
B(0,11,5,98)
B(0,11,6,AIR)
B(0,11,7,AIR)
B(0,11,8,AIR)
B(0,12,-3,AIR)
B(0,12,-2,AIR)
B(0,12,-1,159:7)
B(0,12,0,AIR)
B(0,12,1,AIR)
B(0,12,2,AIR)
B(0,12,3,AIR)
B(0,12,4,AIR)
B(0,12,5,159:7)
B(0,12,6,AIR)
B(0,12,7,AIR)
B(0,12,8,AIR)
B(0,13,-3,AIR)
B(0,13,-2,AIR)
B(0,13,-1,98)
B(0,13,0,98:3)
B(0,13,1,AIR)
B(0,13,2,AIR)
B(0,13,3,AIR)
B(0,13,4,98:3)
B(0,13,5,98)
B(0,13,6,AIR)
B(0,13,7,AIR)
B(0,13,8,AIR)
B(0,14,-3,AIR)
B(0,14,-2,98)
B(0,14,-1,98)
B(0,14,0,98)
B(0,14,1,98)
B(0,14,2,98)
B(0,14,3,98)
B(0,14,4,98)
B(0,14,5,98)
B(0,14,6,98)
B(0,14,7,AIR)
B(0,14,8,AIR)
B(0,15,-3,AIR)
B(0,15,-2,44:5)
B(0,15,-1,AIR)
B(0,15,0,98)
B(0,15,1,159:7)
B(0,15,2,159:7)
B(0,15,3,159:7)
B(0,15,4,98)
B(0,15,5,AIR)
B(0,15,6,44:5)
B(0,15,7,AIR)
B(0,15,8,AIR)
B(0,16,-3,AIR)
B(0,16,-2,AIR)
B(0,16,-1,AIR)
B(0,16,0,98)
B(0,16,1,159:7)
B(0,16,2,159:7)
B(0,16,3,159:7)
B(0,16,4,98)
B(0,16,5,AIR)
B(0,16,6,AIR)
B(0,16,7,AIR)
B(0,16,8,AIR)
B(0,17,-3,AIR)
B(0,17,-2,AIR)
B(0,17,-1,AIR)
B(0,17,0,98)
B(0,17,1,159:7)
B(0,17,2,101)
B(0,17,3,159:7)
B(0,17,4,98)
B(0,17,5,AIR)
B(0,17,6,AIR)
B(0,17,7,AIR)
B(0,17,8,AIR)
B(0,18,-3,AIR)
B(0,18,-2,AIR)
B(0,18,-1,AIR)
B(0,18,0,98)
B(0,18,1,159:7)
B(0,18,2,101)
B(0,18,3,159:7)
B(0,18,4,98)
B(0,18,5,AIR)
B(0,18,6,AIR)
B(0,18,7,AIR)
B(0,18,8,AIR)
B(0,19,-3,AIR)
B(0,19,-2,AIR)
B(0,19,-1,AIR)
B(0,19,0,98)
B(0,19,1,159:7)
B(0,19,2,101)
B(0,19,3,159:7)
B(0,19,4,98)
B(0,19,5,AIR)
B(0,19,6,AIR)
B(0,19,7,AIR)
B(0,19,8,AIR)
B(0,20,-3,AIR)
B(0,20,-2,AIR)
B(0,20,-1,AIR)
B(0,20,0,98)
B(0,20,1,159:7)
B(0,20,2,159:7)
B(0,20,3,159:7)
B(0,20,4,98)
B(0,20,5,AIR)
B(0,20,6,AIR)
B(0,20,7,AIR)
B(0,20,8,AIR)
B(0,21,-3,AIR)
B(0,21,-2,AIR)
B(0,21,-1,AIR)
B(0,21,0,98)
B(0,21,1,159:7)
B(0,21,2,101)
B(0,21,3,159:7)
B(0,21,4,98)
B(0,21,5,AIR)
B(0,21,6,AIR)
B(0,21,7,AIR)
B(0,21,8,AIR)
B(0,22,-3,AIR)
B(0,22,-2,AIR)
B(0,22,-1,AIR)
B(0,22,0,98)
B(0,22,1,159:7)
B(0,22,2,101)
B(0,22,3,159:7)
B(0,22,4,98)
B(0,22,5,AIR)
B(0,22,6,AIR)
B(0,22,7,AIR)
B(0,22,8,AIR)
B(0,23,-3,AIR)
B(0,23,-2,AIR)
B(0,23,-1,AIR)
B(0,23,0,98)
B(0,23,1,159:7)
B(0,23,2,101)
B(0,23,3,159:7)
B(0,23,4,98)
B(0,23,5,AIR)
B(0,23,6,AIR)
B(0,23,7,AIR)
B(0,23,8,AIR)
B(0,24,-3,AIR)
B(0,24,-2,AIR)
B(0,24,-1,44:13)
B(0,24,0,98)
B(0,24,1,159:7)
B(0,24,2,159:7)
B(0,24,3,159:7)
B(0,24,4,98)
B(0,24,5,44:13)
B(0,24,6,AIR)
B(0,24,7,AIR)
B(0,24,8,AIR)
B(0,25,-3,AIR)
B(0,25,-2,AIR)
B(0,25,-1,98)
B(0,25,0,98)
B(0,25,1,98)
B(0,25,2,98)
B(0,25,3,98)
B(0,25,4,98)
B(0,25,5,98)
B(0,25,6,AIR)
B(0,25,7,AIR)
B(0,25,8,AIR)
B(0,26,-3,AIR)
B(0,26,-2,AIR)
B(0,26,-1,98)
B(0,26,0,AIR)
B(0,26,1,AIR)
B(0,26,2,AIR)
B(0,26,3,AIR)
B(0,26,4,AIR)
B(0,26,5,98)
B(0,26,6,AIR)
B(0,26,7,AIR)
B(0,26,8,AIR)
B(0,27,-3,AIR)
B(0,27,-2,AIR)
B(0,27,-1,44)
B(0,27,0,AIR)
B(0,27,1,AIR)
B(0,27,2,AIR)
B(0,27,3,AIR)
B(0,27,4,AIR)
B(0,27,5,44)
B(0,27,6,AIR)
B(0,27,7,AIR)
B(0,27,8,AIR)
B(0,28,-3,AIR)
B(0,28,-2,AIR)
B(0,28,-1,AIR)
B(0,28,0,AIR)
B(0,28,1,AIR)
B(0,28,2,AIR)
B(0,28,3,AIR)
B(0,28,4,AIR)
B(0,28,5,AIR)
B(0,28,6,AIR)
B(0,28,7,AIR)
B(0,28,8,AIR)
B(0,29,-3,AIR)
B(0,29,-2,AIR)
B(0,29,-1,AIR)
B(0,29,0,AIR)
B(0,29,1,AIR)
B(0,29,2,AIR)
B(0,29,3,AIR)
B(0,29,4,AIR)
B(0,29,5,AIR)
B(0,29,6,AIR)
B(0,29,7,AIR)
B(0,29,8,AIR)
B(0,30,-3,AIR)
B(0,30,-2,AIR)
B(0,30,-1,AIR)
B(0,30,0,AIR)
B(0,30,1,AIR)
B(0,30,2,AIR)
B(0,30,3,AIR)
B(0,30,4,AIR)
B(0,30,5,AIR)
B(0,30,6,AIR)
B(0,30,7,AIR)
B(0,30,8,AIR)
B(0,31,-3,AIR)
B(0,31,-2,AIR)
B(0,31,-1,AIR)
B(0,31,0,AIR)
B(0,31,1,44:13)
B(0,31,2,AIR)
B(0,31,3,44:13)
B(0,31,4,AIR)
B(0,31,5,AIR)
B(0,31,6,AIR)
B(0,31,7,AIR)
B(0,31,8,AIR)
B(0,32,-3,AIR)
B(0,32,-2,AIR)
B(0,32,-1,AIR)
B(0,32,0,98)
B(0,32,1,98)
B(0,32,2,98)
B(0,32,3,98)
B(0,32,4,98)
B(0,32,5,AIR)
B(0,32,6,AIR)
B(0,32,7,AIR)
B(0,32,8,AIR)
B(0,33,-3,AIR)
B(0,33,-2,AIR)
B(0,33,-1,AIR)
B(0,33,0,98)
B(0,33,1,98)
B(0,33,2,44:5)
B(0,33,3,98)
B(0,33,4,98)
B(0,33,5,AIR)
B(0,33,6,AIR)
B(0,33,7,AIR)
B(0,33,8,AIR)
B(0,34,-3,AIR)
B(0,34,-2,AIR)
B(0,34,-1,AIR)
B(0,34,0,44)
B(0,34,1,44)
B(0,34,2,AIR)
B(0,34,3,44)
B(0,34,4,44)
B(0,34,5,AIR)
B(0,34,6,AIR)
B(0,34,7,AIR)
B(0,34,8,AIR)
B(1,-22,-7,1)
B(1,-22,-6,1)
B(1,-22,-5,1)
B(1,-22,-4,1)
B(1,-22,-3,1)
B(1,-22,-2,1)
B(1,-22,-1,1)
B(1,-22,0,1)
B(1,-22,1,1)
B(1,-22,2,1)
B(1,-22,3,1)
B(1,-22,4,1)
B(1,-22,5,1)
B(1,-22,6,1)
B(1,-22,7,1)
B(1,-22,8,1)
B(1,-21,-7,1)
B(1,-21,-6,1)
B(1,-21,-5,1)
B(1,-21,-4,1)
B(1,-21,-3,1)
B(1,-21,-2,1)
B(1,-21,-1,1)
B(1,-21,0,1)
B(1,-21,1,1)
B(1,-21,2,1)
B(1,-21,3,1)
B(1,-21,4,1)
B(1,-21,5,1)
B(1,-21,6,1)
B(1,-21,7,1)
B(1,-21,8,1)
B(1,-20,-7,1)
B(1,-20,-6,1)
B(1,-20,-5,1)
B(1,-20,-4,1)
B(1,-20,-3,1)
B(1,-20,-2,1)
B(1,-20,-1,1)
B(1,-20,0,1)
B(1,-20,1,1)
B(1,-20,2,1)
B(1,-20,3,1)
B(1,-20,4,1)
B(1,-20,5,1)
B(1,-20,6,1)
B(1,-20,7,1)
B(1,-20,8,1)
B(1,-19,-7,1)
B(1,-19,-6,1)
B(1,-19,-5,1)
B(1,-19,-4,1)
B(1,-19,-3,1)
B(1,-19,-2,1)
B(1,-19,-1,1)
B(1,-19,0,1)
B(1,-19,1,1)
B(1,-19,2,1)
B(1,-19,3,1)
B(1,-19,4,1)
B(1,-19,5,1)
B(1,-19,6,1)
B(1,-19,7,1)
B(1,-19,8,1)
B(1,-18,-7,1)
B(1,-18,-6,1)
B(1,-18,-5,1)
B(1,-18,-4,1)
B(1,-18,-3,1)
B(1,-18,-2,1)
B(1,-18,-1,1)
B(1,-18,0,1)
B(1,-18,1,1)
B(1,-18,2,1)
B(1,-18,3,1)
B(1,-18,4,1)
B(1,-18,5,1)
B(1,-18,6,1)
B(1,-18,7,1)
B(1,-18,8,1)
B(1,-17,-7,1)
B(1,-17,-6,1)
B(1,-17,-5,1)
B(1,-17,-4,1)
B(1,-17,-3,1)
B(1,-17,-2,1)
B(1,-17,-1,1)
B(1,-17,0,1)
B(1,-17,1,1)
B(1,-17,2,1)
B(1,-17,3,1)
B(1,-17,4,1)
B(1,-17,5,1)
B(1,-17,6,1)
B(1,-17,7,1)
B(1,-17,8,1)
B(1,-16,-7,1)
B(1,-16,-6,1)
B(1,-16,-5,1)
B(1,-16,-4,1)
B(1,-16,-3,1)
B(1,-16,-2,1)
B(1,-16,-1,1)
B(1,-16,0,1)
B(1,-16,1,1)
B(1,-16,2,1)
B(1,-16,3,1)
B(1,-16,4,1)
B(1,-16,5,1)
B(1,-16,6,1)
B(1,-16,7,1)
B(1,-16,8,1)
B(1,-15,-7,1)
B(1,-15,-6,1)
B(1,-15,-5,1)
B(1,-15,-4,1)
B(1,-15,-3,1)
B(1,-15,-2,1)
B(1,-15,-1,1)
B(1,-15,0,1)
B(1,-15,1,1)
B(1,-15,2,1)
B(1,-15,3,1)
B(1,-15,4,1)
B(1,-15,5,1)
B(1,-15,6,1)
B(1,-15,7,1)
B(1,-15,8,1)
B(1,-14,-7,1)
B(1,-14,-6,1)
B(1,-14,-5,1)
B(1,-14,-4,1)
B(1,-14,-3,1)
B(1,-14,-2,1)
B(1,-14,-1,1)
B(1,-14,0,1)
B(1,-14,1,1)
B(1,-14,2,1)
B(1,-14,3,1)
B(1,-14,4,1)
B(1,-14,5,1)
B(1,-14,6,1)
B(1,-14,7,1)
B(1,-14,8,1)
B(1,-13,-7,1)
B(1,-13,-6,1)
B(1,-13,-5,1)
B(1,-13,-4,1)
B(1,-13,-3,1)
B(1,-13,-2,1)
B(1,-13,-1,1)
B(1,-13,0,1)
B(1,-13,1,1)
B(1,-13,2,1)
B(1,-13,3,1)
B(1,-13,4,1)
B(1,-13,5,1)
B(1,-13,6,1)
B(1,-13,7,1)
B(1,-13,8,1)
B(1,-12,-7,1)
B(1,-12,-6,1)
B(1,-12,-5,1)
B(1,-12,-4,1)
B(1,-12,-3,1)
B(1,-12,-2,1)
B(1,-12,-1,1)
B(1,-12,0,1)
B(1,-12,1,1)
B(1,-12,2,1)
B(1,-12,3,1)
B(1,-12,4,1)
B(1,-12,5,1)
B(1,-12,6,1)
B(1,-12,7,1)
B(1,-12,8,1)
B(1,-11,-7,1)
B(1,-11,-6,1)
B(1,-11,-5,1)
B(1,-11,-4,1)
B(1,-11,-3,1)
B(1,-11,-2,1)
B(1,-11,-1,1)
B(1,-11,0,1)
B(1,-11,1,1)
B(1,-11,2,1)
B(1,-11,3,1)
B(1,-11,4,1)
B(1,-11,5,1)
B(1,-11,6,1)
B(1,-11,7,1)
B(1,-11,8,1)
B(1,-10,-7,1)
B(1,-10,-6,1)
B(1,-10,-5,1)
B(1,-10,-4,1)
B(1,-10,-3,1)
B(1,-10,-2,1)
B(1,-10,-1,1)
B(1,-10,0,1)
B(1,-10,1,1)
B(1,-10,2,1)
B(1,-10,3,1)
B(1,-10,4,1)
B(1,-10,5,1)
B(1,-10,6,1)
B(1,-10,7,1)
B(1,-10,8,1)
B(1,-9,-7,1)
B(1,-9,-6,1)
B(1,-9,-5,1)
B(1,-9,-4,1)
B(1,-9,-3,1)
B(1,-9,-2,1)
B(1,-9,-1,1)
B(1,-9,0,1)
B(1,-9,1,1)
B(1,-9,2,1)
B(1,-9,3,1)
B(1,-9,4,1)
B(1,-9,5,1)
B(1,-9,6,1)
B(1,-9,7,1)
B(1,-9,8,1)
B(1,-8,-7,1)
B(1,-8,-6,1)
B(1,-8,-5,1)
B(1,-8,-4,1)
B(1,-8,-3,1)
B(1,-8,-2,1)
B(1,-8,-1,1)
B(1,-8,0,1)
B(1,-8,1,1)
B(1,-8,2,1)
B(1,-8,3,1)
B(1,-8,4,1)
B(1,-8,5,1)
B(1,-8,6,1)
B(1,-8,7,1)
B(1,-8,8,1)
B(1,-7,-7,1)
B(1,-7,-6,1)
B(1,-7,-5,1)
B(1,-7,-4,1)
B(1,-7,-3,1)
B(1,-7,-2,1)
B(1,-7,-1,1)
B(1,-7,0,1)
B(1,-7,1,1)
B(1,-7,2,1)
B(1,-7,3,1)
B(1,-7,4,1)
B(1,-7,5,1)
B(1,-7,6,1)
B(1,-7,7,1)
B(1,-7,8,1)
B(1,-6,-6,1)
B(1,-6,-5,1)
B(1,-6,-4,1)
B(1,-6,-3,1)
B(1,-6,-2,1)
B(1,-6,-1,1)
B(1,-6,0,1)
B(1,-6,1,1)
B(1,-6,2,1)
B(1,-6,3,1)
B(1,-6,4,1)
B(1,-6,5,1)
B(1,-6,6,1)
B(1,-6,7,1)
B(1,-6,8,1)
B(1,-5,-6,1)
B(1,-5,-5,1)
B(1,-5,-4,1)
B(1,-5,-3,1)
B(1,-5,-2,1)
B(1,-5,-1,1)
B(1,-5,0,1)
B(1,-5,1,1)
B(1,-5,2,1)
B(1,-5,3,1)
B(1,-5,4,1)
B(1,-5,5,1)
B(1,-5,6,1)
B(1,-5,7,1)
B(1,-5,8,1)
B(1,-4,-6,1)
B(1,-4,-5,1)
B(1,-4,-4,1)
B(1,-4,-3,1)
B(1,-4,-2,1)
B(1,-4,-1,1)
B(1,-4,0,1)
B(1,-4,1,1)
B(1,-4,2,1)
B(1,-4,3,1)
B(1,-4,4,1)
B(1,-4,5,1)
B(1,-4,6,1)
B(1,-4,7,1)
B(1,-4,8,1)
B(1,-3,-5,1)
B(1,-3,-4,1)
B(1,-3,-3,1)
B(1,-3,-2,1)
B(1,-3,-1,1)
B(1,-3,0,1)
B(1,-3,1,1)
B(1,-3,2,1)
B(1,-3,3,1)
B(1,-3,4,1)
B(1,-3,5,1)
B(1,-3,6,1)
B(1,-3,7,1)
B(1,-3,8,1)
B(1,-2,-5,1)
B(1,-2,-4,1)
B(1,-2,-3,1)
B(1,-2,-2,1)
B(1,-2,-1,1)
B(1,-2,0,1)
B(1,-2,1,1)
B(1,-2,2,1)
B(1,-2,3,1)
B(1,-2,4,1)
B(1,-2,5,1)
B(1,-2,6,1)
B(1,-2,7,1)
B(1,-2,8,1)
B(1,-1,-4,1)
B(1,-1,-3,1)
B(1,-1,-2,1)
B(1,-1,-1,1)
B(1,-1,0,1)
B(1,-1,1,1)
B(1,-1,2,1)
B(1,-1,3,1)
B(1,-1,4,1)
B(1,-1,5,1)
B(1,-1,6,1)
B(1,-1,7,1)
B(1,-1,8,1)
B(1,0,-3,1)
B(1,0,-2,1)
B(1,0,-1,1)
B(1,0,0,1)
B(1,0,1,1)
B(1,0,2,1)
B(1,0,3,1)
B(1,0,4,1)
B(1,0,5,1)
B(1,0,6,1)
B(1,0,7,1)
B(1,0,8,1)
B(1,1,-3,AIR)
B(1,1,-2,98)
B(1,1,-1,98)
B(1,1,0,98)
B(1,1,1,98)
B(1,1,2,98)
B(1,1,3,98)
B(1,1,4,98)
B(1,1,5,98)
B(1,1,6,98)
B(1,1,7,1)
B(1,1,8,1)
B(1,2,-3,AIR)
B(1,2,-2,98)
B(1,2,-1,98)
B(1,2,0,98)
B(1,2,1,98)
B(1,2,2,98)
B(1,2,3,98)
B(1,2,4,98)
B(1,2,5,98)
B(1,2,6,98)
B(1,2,7,1)
B(1,2,8,1)
B(1,3,-3,AIR)
B(1,3,-2,98)
B(1,3,-1,98)
B(1,3,0,98)
B(1,3,1,98)
B(1,3,2,98)
B(1,3,3,98)
B(1,3,4,98)
B(1,3,5,98)
B(1,3,6,98)
B(1,3,7,1)
B(1,3,8,1)
B(1,4,-3,98)
B(1,4,-2,98)
B(1,4,-1,98)
B(1,4,0,98)
B(1,4,1,126:13)
B(1,4,2,126:13)
B(1,4,3,126:13)
B(1,4,4,126:13)
B(1,4,5,98)
B(1,4,6,98)
B(1,4,7,1)
B(1,4,8,1)
B(1,5,-3,AIR)
B(1,5,-2,98)
B(1,5,-1,98)
B(1,5,0,43:5)
B(1,5,1,AIR)
B(1,5,2,AIR)
B(1,5,3,AIR)
B(1,5,4,AIR)
B(1,5,5,98)
B(1,5,6,98)
B(1,5,7,1)
B(1,5,8,1)
B(1,6,-3,AIR)
B(1,6,-2,98)
B(1,6,-1,98)
B(1,6,0,43:5)
B(1,6,1,AIR)
B(1,6,2,AIR)
B(1,6,3,AIR)
B(1,6,4,AIR)
RB(1,6,5,FLOWER_POT,../../nbt/Misc/FlowerPot1.nbt,20,FLOWER_POT,../../nbt/Misc/FlowerPot2.nbt,20,FLOWER_POT,../../nbt/Misc/FlowerPot3.nbt,20,FLOWER_POT,../../nbt/Misc/FlowerPot8.nbt,20,FLOWER_POT,../../nbt/Misc/FlowerPot4.nbt,20,FLOWER_POT,../../nbt/Misc/FlowerPot5.nbt,20,FLOWER_POT,../../nbt/Misc/FlowerPot6.nbt,20,FLOWER_POT,../../nbt/Misc/FlowerPot7.nbt,20,FLOWER_POT,../../nbt/Misc/FlowerPot8.nbt,100)
B(1,6,6,98)
B(1,6,7,1)
B(1,6,8,1)
B(1,7,-3,AIR)
B(1,7,-2,98)
B(1,7,-1,98)
B(1,7,0,44:5)
B(1,7,1,AIR)
B(1,7,2,AIR)
B(1,7,3,AIR)
B(1,7,4,AIR)
B(1,7,5,126:13)
B(1,7,6,98)
B(1,7,7,1)
B(1,7,8,1)
B(1,8,-3,AIR)
B(1,8,-2,44:5)
B(1,8,-1,98)
B(1,8,0,AIR)
B(1,8,1,98)
B(1,8,2,98)
B(1,8,3,98)
B(1,8,4,98)
B(1,8,5,98)
B(1,8,6,1)
B(1,8,7,1)
B(1,8,8,1)
B(1,9,-3,AIR)
B(1,9,-2,AIR)
B(1,9,-1,159:7)
B(1,9,0,AIR)
B(1,9,1,AIR)
B(1,9,2,171:1)
B(1,9,3,171:1)
B(1,9,4,AIR)
B(1,9,5,126:13)
B(1,9,6,1)
B(1,9,7,1)
B(1,9,8,1)
B(1,10,-3,AIR)
B(1,10,-2,AIR)
B(1,10,-1,159:7)
B(1,10,0,AIR)
B(1,10,1,AIR)
B(1,10,2,AIR)
B(1,10,3,AIR)
B(1,10,4,AIR)
RB(1,10,5,CHEST,../../nbt/Chests/Epic1.nbt,25,CHEST,../../nbt/Chests/Epic2.nbt,25,CHEST,../../nbt/Chests/Epic3.nbt,25,CHEST,../../nbt/Chests/Epic4.nbt,25,CHEST,../../nbt/Chests/Epic5.nbt,25,CHEST,../../nbt/Chests/Epic6.nbt,25,CHEST,../../nbt/Chests/Epic7.nbt,25,CHEST,../../nbt/Chests/Epic8.nbt,25,CHEST,../../nbt/Chests/Epic9.nbt,25,CHEST,../../nbt/Chests/Epic10.nbt,25,CHEST,../../nbt/Chests/Epic11.nbt,25,CHEST,../../nbt/Chests/Epic12.nbt,25,CHEST,../../nbt/Chests/Epic13.nbt,25,CHEST,../../nbt/Chests/Epic14.nbt,25,CHEST,../../nbt/Chests/Epic15.nbt,100)
B(1,10,6,1)
B(1,10,7,1)
B(1,10,8,AIR)
B(1,11,-3,AIR)
B(1,11,-2,AIR)
B(1,11,-1,159:7)
B(1,11,0,AIR)
B(1,11,1,AIR)
B(1,11,2,AIR)
B(1,11,3,AIR)
B(1,11,4,AIR)
B(1,11,5,126:13)
B(1,11,6,1)
B(1,11,7,AIR)
B(1,11,8,AIR)
B(1,12,-3,AIR)
B(1,12,-2,AIR)
B(1,12,-1,159:7)
B(1,12,0,AIR)
B(1,12,1,AIR)
B(1,12,2,AIR)
B(1,12,3,AIR)
B(1,12,4,AIR)
B(1,12,5,159:7)
B(1,12,6,AIR)
B(1,12,7,AIR)
B(1,12,8,AIR)
B(1,13,-3,AIR)
B(1,13,-2,44:13)
B(1,13,-1,98)
B(1,13,0,AIR)
B(1,13,1,AIR)
B(1,13,2,AIR)
B(1,13,3,AIR)
B(1,13,4,AIR)
B(1,13,5,98)
B(1,13,6,44:13)
B(1,13,7,AIR)
B(1,13,8,AIR)
B(1,14,-3,AIR)
B(1,14,-2,98)
B(1,14,-1,98)
B(1,14,0,98)
B(1,14,1,AIR)
B(1,14,2,AIR)
B(1,14,3,AIR)
B(1,14,4,98)
B(1,14,5,98)
B(1,14,6,98)
B(1,14,7,AIR)
B(1,14,8,AIR)
B(1,15,-3,AIR)
B(1,15,-2,98)
B(1,15,-1,AIR)
B(1,15,0,159:7)
B(1,15,1,AIR)
B(1,15,2,AIR)
B(1,15,3,AIR)
B(1,15,4,159:7)
B(1,15,5,AIR)
B(1,15,6,98)
B(1,15,7,AIR)
B(1,15,8,AIR)
B(1,16,-3,AIR)
B(1,16,-2,44)
B(1,16,-1,AIR)
B(1,16,0,159:7)
B(1,16,1,AIR)
B(1,16,2,AIR)
B(1,16,3,AIR)
B(1,16,4,159:7)
B(1,16,5,AIR)
B(1,16,6,44)
B(1,16,7,AIR)
B(1,16,8,AIR)
B(1,17,-3,AIR)
B(1,17,-2,AIR)
B(1,17,-1,AIR)
B(1,17,0,159:7)
B(1,17,1,AIR)
B(1,17,2,AIR)
B(1,17,3,AIR)
B(1,17,4,159:7)
B(1,17,5,AIR)
B(1,17,6,AIR)
B(1,17,7,AIR)
B(1,17,8,AIR)
B(1,18,-3,AIR)
B(1,18,-2,AIR)
B(1,18,-1,AIR)
B(1,18,0,159:7)
B(1,18,1,AIR)
B(1,18,2,AIR)
B(1,18,3,AIR)
B(1,18,4,159:7)
B(1,18,5,AIR)
B(1,18,6,AIR)
B(1,18,7,AIR)
B(1,18,8,AIR)
B(1,19,-3,AIR)
B(1,19,-2,AIR)
B(1,19,-1,AIR)
B(1,19,0,159:7)
B(1,19,1,AIR)
B(1,19,2,AIR)
B(1,19,3,AIR)
B(1,19,4,159:7)
B(1,19,5,AIR)
B(1,19,6,AIR)
B(1,19,7,AIR)
B(1,19,8,AIR)
B(1,20,-3,AIR)
B(1,20,-2,AIR)
B(1,20,-1,AIR)
B(1,20,0,159:7)
B(1,20,1,AIR)
B(1,20,2,AIR)
B(1,20,3,AIR)
B(1,20,4,159:7)
B(1,20,5,AIR)
B(1,20,6,AIR)
B(1,20,7,AIR)
B(1,20,8,AIR)
B(1,21,-3,AIR)
B(1,21,-2,AIR)
B(1,21,-1,AIR)
B(1,21,0,159:7)
B(1,21,1,AIR)
B(1,21,2,AIR)
B(1,21,3,AIR)
B(1,21,4,159:7)
B(1,21,5,AIR)
B(1,21,6,AIR)
B(1,21,7,AIR)
B(1,21,8,AIR)
B(1,22,-3,AIR)
B(1,22,-2,AIR)
B(1,22,-1,AIR)
B(1,22,0,159:7)
B(1,22,1,AIR)
B(1,22,2,AIR)
B(1,22,3,AIR)
B(1,22,4,159:7)
B(1,22,5,AIR)
B(1,22,6,AIR)
B(1,22,7,AIR)
B(1,22,8,AIR)
B(1,23,-3,AIR)
B(1,23,-2,AIR)
B(1,23,-1,AIR)
B(1,23,0,159:7)
B(1,23,1,AIR)
B(1,23,2,AIR)
B(1,23,3,AIR)
B(1,23,4,159:7)
B(1,23,5,AIR)
B(1,23,6,AIR)
B(1,23,7,AIR)
B(1,23,8,AIR)
B(1,24,-3,AIR)
B(1,24,-2,AIR)
B(1,24,-1,AIR)
B(1,24,0,159:7)
B(1,24,1,AIR)
B(1,24,2,AIR)
B(1,24,3,AIR)
B(1,24,4,159:7)
B(1,24,5,AIR)
B(1,24,6,AIR)
B(1,24,7,AIR)
B(1,24,8,AIR)
B(1,25,-3,AIR)
B(1,25,-2,AIR)
B(1,25,-1,98)
B(1,25,0,98)
B(1,25,1,AIR)
B(1,25,2,AIR)
B(1,25,3,AIR)
B(1,25,4,98)
B(1,25,5,98)
B(1,25,6,AIR)
B(1,25,7,AIR)
B(1,25,8,AIR)
B(1,26,-3,AIR)
B(1,26,-2,AIR)
B(1,26,-1,44:5)
B(1,26,0,AIR)
B(1,26,1,98)
B(1,26,2,98:3)
B(1,26,3,98)
B(1,26,4,AIR)
B(1,26,5,44:5)
B(1,26,6,AIR)
B(1,26,7,AIR)
B(1,26,8,AIR)
B(1,27,-3,AIR)
B(1,27,-2,AIR)
B(1,27,-1,AIR)
B(1,27,0,AIR)
B(1,27,1,98)
B(1,27,2,98)
B(1,27,3,98)
B(1,27,4,AIR)
B(1,27,5,AIR)
B(1,27,6,AIR)
B(1,27,7,AIR)
B(1,27,8,AIR)
B(1,28,-3,AIR)
B(1,28,-2,AIR)
B(1,28,-1,AIR)
B(1,28,0,AIR)
B(1,28,1,98)
B(1,28,2,101)
B(1,28,3,98)
B(1,28,4,AIR)
B(1,28,5,AIR)
B(1,28,6,AIR)
B(1,28,7,AIR)
B(1,28,8,AIR)
B(1,29,-3,AIR)
B(1,29,-2,AIR)
B(1,29,-1,AIR)
B(1,29,0,AIR)
B(1,29,1,98)
B(1,29,2,101)
B(1,29,3,98)
B(1,29,4,AIR)
B(1,29,5,AIR)
B(1,29,6,AIR)
B(1,29,7,AIR)
B(1,29,8,AIR)
B(1,30,-3,AIR)
B(1,30,-2,AIR)
B(1,30,-1,AIR)
B(1,30,0,AIR)
B(1,30,1,98)
B(1,30,2,101)
B(1,30,3,98)
B(1,30,4,AIR)
B(1,30,5,AIR)
B(1,30,6,AIR)
B(1,30,7,AIR)
B(1,30,8,AIR)
B(1,31,-3,AIR)
B(1,31,-2,AIR)
B(1,31,-1,AIR)
B(1,31,0,44:13)
B(1,31,1,98)
B(1,31,2,98)
B(1,31,3,98)
B(1,31,4,44:13)
B(1,31,5,AIR)
B(1,31,6,AIR)
B(1,31,7,AIR)
B(1,31,8,AIR)
B(1,32,-3,AIR)
B(1,32,-2,AIR)
B(1,32,-1,AIR)
B(1,32,0,98)
B(1,32,1,98)
B(1,32,2,98)
B(1,32,3,98)
B(1,32,4,98)
B(1,32,5,AIR)
B(1,32,6,AIR)
B(1,32,7,AIR)
B(1,32,8,AIR)
B(1,33,-3,AIR)
B(1,33,-2,AIR)
B(1,33,-1,AIR)
B(1,33,0,98)
B(1,33,1,98)
B(1,33,2,98)
B(1,33,3,98)
B(1,33,4,98)
B(1,33,5,AIR)
B(1,33,6,AIR)
B(1,33,7,AIR)
B(1,33,8,AIR)
B(1,34,-3,AIR)
B(1,34,-2,AIR)
B(1,34,-1,AIR)
B(1,34,0,44)
B(1,34,1,44)
B(1,34,2,44)
B(1,34,3,44)
B(1,34,4,44)
B(1,34,5,AIR)
B(1,34,6,AIR)
B(1,34,7,AIR)
B(1,34,8,AIR)
B(2,-22,-7,1)
B(2,-22,-6,1)
B(2,-22,-5,1)
B(2,-22,-4,1)
B(2,-22,-3,1)
B(2,-22,-2,1)
B(2,-22,-1,1)
B(2,-22,0,1)
B(2,-22,1,1)
B(2,-22,2,1)
B(2,-22,3,1)
B(2,-22,4,1)
B(2,-22,5,1)
B(2,-22,6,1)
B(2,-22,7,1)
B(2,-22,8,1)
B(2,-21,-7,1)
B(2,-21,-6,1)
B(2,-21,-5,1)
B(2,-21,-4,1)
B(2,-21,-3,1)
B(2,-21,-2,1)
B(2,-21,-1,1)
B(2,-21,0,1)
B(2,-21,1,1)
B(2,-21,2,1)
B(2,-21,3,1)
B(2,-21,4,1)
B(2,-21,5,1)
B(2,-21,6,1)
B(2,-21,7,1)
B(2,-21,8,1)
B(2,-20,-7,1)
B(2,-20,-6,1)
B(2,-20,-5,1)
B(2,-20,-4,1)
B(2,-20,-3,1)
B(2,-20,-2,1)
B(2,-20,-1,1)
B(2,-20,0,1)
B(2,-20,1,1)
B(2,-20,2,1)
B(2,-20,3,1)
B(2,-20,4,1)
B(2,-20,5,1)
B(2,-20,6,1)
B(2,-20,7,1)
B(2,-20,8,1)
B(2,-19,-7,1)
B(2,-19,-6,1)
B(2,-19,-5,1)
B(2,-19,-4,1)
B(2,-19,-3,1)
B(2,-19,-2,1)
B(2,-19,-1,1)
B(2,-19,0,1)
B(2,-19,1,1)
B(2,-19,2,1)
B(2,-19,3,1)
B(2,-19,4,1)
B(2,-19,5,1)
B(2,-19,6,1)
B(2,-19,7,1)
B(2,-19,8,1)
B(2,-18,-7,1)
B(2,-18,-6,1)
B(2,-18,-5,1)
B(2,-18,-4,1)
B(2,-18,-3,1)
B(2,-18,-2,1)
B(2,-18,-1,1)
B(2,-18,0,1)
B(2,-18,1,1)
B(2,-18,2,1)
B(2,-18,3,1)
B(2,-18,4,1)
B(2,-18,5,1)
B(2,-18,6,1)
B(2,-18,7,1)
B(2,-18,8,1)
B(2,-17,-7,1)
B(2,-17,-6,1)
B(2,-17,-5,1)
B(2,-17,-4,1)
B(2,-17,-3,1)
B(2,-17,-2,1)
B(2,-17,-1,1)
B(2,-17,0,1)
B(2,-17,1,1)
B(2,-17,2,1)
B(2,-17,3,1)
B(2,-17,4,1)
B(2,-17,5,1)
B(2,-17,6,1)
B(2,-17,7,1)
B(2,-17,8,1)
B(2,-16,-7,1)
B(2,-16,-6,1)
B(2,-16,-5,1)
B(2,-16,-4,1)
B(2,-16,-3,1)
B(2,-16,-2,1)
B(2,-16,-1,1)
B(2,-16,0,1)
B(2,-16,1,1)
B(2,-16,2,1)
B(2,-16,3,1)
B(2,-16,4,1)
B(2,-16,5,1)
B(2,-16,6,1)
B(2,-16,7,1)
B(2,-16,8,1)
B(2,-15,-7,1)
B(2,-15,-6,1)
B(2,-15,-5,1)
B(2,-15,-4,1)
B(2,-15,-3,1)
B(2,-15,-2,1)
B(2,-15,-1,1)
B(2,-15,0,1)
B(2,-15,1,1)
B(2,-15,2,1)
B(2,-15,3,1)
B(2,-15,4,1)
B(2,-15,5,1)
B(2,-15,6,1)
B(2,-15,7,1)
B(2,-15,8,1)
B(2,-14,-7,1)
B(2,-14,-6,1)
B(2,-14,-5,1)
B(2,-14,-4,1)
B(2,-14,-3,1)
B(2,-14,-2,1)
B(2,-14,-1,1)
B(2,-14,0,1)
B(2,-14,1,1)
B(2,-14,2,1)
B(2,-14,3,1)
B(2,-14,4,1)
B(2,-14,5,1)
B(2,-14,6,1)
B(2,-14,7,1)
B(2,-14,8,1)
B(2,-13,-7,1)
B(2,-13,-6,1)
B(2,-13,-5,1)
B(2,-13,-4,1)
B(2,-13,-3,1)
B(2,-13,-2,1)
B(2,-13,-1,1)
B(2,-13,0,1)
B(2,-13,1,1)
B(2,-13,2,1)
B(2,-13,3,1)
B(2,-13,4,1)
B(2,-13,5,1)
B(2,-13,6,1)
B(2,-13,7,1)
B(2,-13,8,1)
B(2,-12,-7,1)
B(2,-12,-6,1)
B(2,-12,-5,1)
B(2,-12,-4,1)
B(2,-12,-3,1)
B(2,-12,-2,1)
B(2,-12,-1,1)
B(2,-12,0,1)
B(2,-12,1,1)
B(2,-12,2,1)
B(2,-12,3,1)
B(2,-12,4,1)
B(2,-12,5,1)
B(2,-12,6,1)
B(2,-12,7,1)
B(2,-12,8,1)
B(2,-11,-7,1)
B(2,-11,-6,1)
B(2,-11,-5,1)
B(2,-11,-4,1)
B(2,-11,-3,1)
B(2,-11,-2,1)
B(2,-11,-1,1)
B(2,-11,0,1)
B(2,-11,1,1)
B(2,-11,2,1)
B(2,-11,3,1)
B(2,-11,4,1)
B(2,-11,5,1)
B(2,-11,6,1)
B(2,-11,7,1)
B(2,-11,8,1)
B(2,-10,-7,1)
B(2,-10,-6,1)
B(2,-10,-5,1)
B(2,-10,-4,1)
B(2,-10,-3,1)
B(2,-10,-2,1)
B(2,-10,-1,1)
B(2,-10,0,1)
B(2,-10,1,1)
B(2,-10,2,1)
B(2,-10,3,1)
B(2,-10,4,1)
B(2,-10,5,1)
B(2,-10,6,1)
B(2,-10,7,1)
B(2,-10,8,1)
B(2,-9,-7,1)
B(2,-9,-6,1)
B(2,-9,-5,1)
B(2,-9,-4,1)
B(2,-9,-3,1)
B(2,-9,-2,1)
B(2,-9,-1,1)
B(2,-9,0,1)
B(2,-9,1,1)
B(2,-9,2,1)
B(2,-9,3,1)
B(2,-9,4,1)
B(2,-9,5,1)
B(2,-9,6,1)
B(2,-9,7,1)
B(2,-9,8,1)
B(2,-8,-7,1)
B(2,-8,-6,1)
B(2,-8,-5,1)
B(2,-8,-4,1)
B(2,-8,-3,1)
B(2,-8,-2,1)
B(2,-8,-1,1)
B(2,-8,0,1)
B(2,-8,1,1)
B(2,-8,2,1)
B(2,-8,3,1)
B(2,-8,4,1)
B(2,-8,5,1)
B(2,-8,6,1)
B(2,-8,7,1)
B(2,-8,8,1)
B(2,-7,-7,1)
B(2,-7,-6,1)
B(2,-7,-5,1)
B(2,-7,-4,1)
B(2,-7,-3,1)
B(2,-7,-2,1)
B(2,-7,-1,1)
B(2,-7,0,1)
B(2,-7,1,1)
B(2,-7,2,1)
B(2,-7,3,1)
B(2,-7,4,1)
B(2,-7,5,1)
B(2,-7,6,1)
B(2,-7,7,1)
B(2,-7,8,1)
B(2,-6,-7,1)
B(2,-6,-6,1)
B(2,-6,-5,1)
B(2,-6,-4,1)
B(2,-6,-3,1)
B(2,-6,-2,1)
B(2,-6,-1,1)
B(2,-6,0,1)
B(2,-6,1,1)
B(2,-6,2,1)
B(2,-6,3,1)
B(2,-6,4,1)
B(2,-6,5,1)
B(2,-6,6,1)
B(2,-6,7,1)
B(2,-6,8,1)
B(2,-5,-7,1)
B(2,-5,-6,1)
B(2,-5,-5,1)
B(2,-5,-4,1)
B(2,-5,-3,1)
B(2,-5,-2,1)
B(2,-5,-1,1)
B(2,-5,0,1)
B(2,-5,1,1)
B(2,-5,2,1)
B(2,-5,3,1)
B(2,-5,4,1)
B(2,-5,5,1)
B(2,-5,6,1)
B(2,-5,7,1)
B(2,-5,8,1)
B(2,-4,-6,1)
B(2,-4,-5,1)
B(2,-4,-4,1)
B(2,-4,-3,1)
B(2,-4,-2,1)
B(2,-4,-1,1)
B(2,-4,0,1)
B(2,-4,1,1)
B(2,-4,2,1)
B(2,-4,3,1)
B(2,-4,4,1)
B(2,-4,5,1)
B(2,-4,6,1)
B(2,-4,7,1)
B(2,-4,8,1)
B(2,-3,-6,1)
B(2,-3,-5,1)
B(2,-3,-4,1)
B(2,-3,-3,1)
B(2,-3,-2,1)
B(2,-3,-1,1)
B(2,-3,0,1)
B(2,-3,1,1)
B(2,-3,2,1)
B(2,-3,3,1)
B(2,-3,4,1)
B(2,-3,5,1)
B(2,-3,6,1)
B(2,-3,7,1)
B(2,-3,8,1)
B(2,-2,-5,1)
B(2,-2,-4,1)
B(2,-2,-3,1)
B(2,-2,-2,1)
B(2,-2,-1,1)
B(2,-2,0,1)
B(2,-2,1,1)
B(2,-2,2,1)
B(2,-2,3,1)
B(2,-2,4,1)
B(2,-2,5,1)
B(2,-2,6,1)
B(2,-2,7,1)
B(2,-2,8,1)
B(2,-1,-5,1)
B(2,-1,-4,1)
B(2,-1,-3,1)
B(2,-1,-2,1)
B(2,-1,-1,1)
B(2,-1,0,1)
B(2,-1,1,1)
B(2,-1,2,1)
B(2,-1,3,1)
B(2,-1,4,1)
B(2,-1,5,1)
B(2,-1,6,1)
B(2,-1,7,1)
B(2,-1,8,1)
B(2,0,-4,1)
B(2,0,-3,98)
B(2,0,-2,1)
B(2,0,-1,1)
B(2,0,0,1)
B(2,0,1,1)
B(2,0,2,1)
B(2,0,3,1)
B(2,0,4,1)
B(2,0,5,1)
B(2,0,6,1)
B(2,0,7,1)
B(2,0,8,1)
B(2,1,-3,98)
B(2,1,-2,98)
B(2,1,-1,98)
B(2,1,0,98)
B(2,1,1,98)
B(2,1,2,98)
B(2,1,3,98)
B(2,1,4,98)
B(2,1,5,98)
B(2,1,6,98)
B(2,1,7,1)
B(2,1,8,1)
B(2,2,-3,98)
B(2,2,-2,98)
B(2,2,-1,98)
B(2,2,0,98)
B(2,2,1,98)
B(2,2,2,98)
B(2,2,3,98)
B(2,2,4,98)
B(2,2,5,98)
B(2,2,6,98)
B(2,2,7,1)
B(2,2,8,1)
B(2,3,-3,98)
B(2,3,-2,98)
B(2,3,-1,98)
B(2,3,0,98)
B(2,3,1,98)
B(2,3,2,98)
B(2,3,3,98)
B(2,3,4,98)
B(2,3,5,98)
B(2,3,6,98)
B(2,3,7,1)
B(2,3,8,1)
B(2,4,-3,98)
B(2,4,-2,98)
B(2,4,-1,98)
B(2,4,0,98)
B(2,4,1,126:13)
B(2,4,2,126:13)
B(2,4,3,126:13)
B(2,4,4,126:13)
B(2,4,5,98)
B(2,4,6,98)
B(2,4,7,1)
B(2,4,8,1)
B(2,5,-3,AIR)
B(2,5,-2,AIR)
B(2,5,-1,159:7)
B(2,5,0,43:5)
B(2,5,1,AIR)
B(2,5,2,AIR)
B(2,5,3,AIR)
B(2,5,4,AIR)
B(2,5,5,98)
B(2,5,6,98)
B(2,5,7,1)
B(2,5,8,1)
B(2,6,-3,AIR)
B(2,6,-2,AIR)
B(2,6,-1,159:7)
B(2,6,0,43:5)
B(2,6,1,AIR)
B(2,6,2,AIR)
B(2,6,3,AIR)
B(2,6,4,AIR)
B(2,6,5,AIR)
B(2,6,6,98)
B(2,6,7,1)
B(2,6,8,1)
B(2,7,-3,AIR)
B(2,7,-2,98)
B(2,7,-1,98)
B(2,7,0,AIR)
B(2,7,1,AIR)
B(2,7,2,AIR)
B(2,7,3,AIR)
B(2,7,4,AIR)
B(2,7,5,126:13)
B(2,7,6,98)
B(2,7,7,1)
B(2,7,8,1)
B(2,8,-3,AIR)
B(2,8,-2,AIR)
B(2,8,-1,98)
B(2,8,0,AIR)
B(2,8,1,98)
B(2,8,2,98)
B(2,8,3,98)
B(2,8,4,98)
B(2,8,5,98)
B(2,8,6,1)
B(2,8,7,1)
B(2,8,8,1)
B(2,9,-3,AIR)
B(2,9,-2,AIR)
B(2,9,-1,159:7)
B(2,9,0,AIR)
B(2,9,1,AIR)
B(2,9,2,171:13)
B(2,9,3,171:13)
B(2,9,4,AIR)
B(2,9,5,126:13)
B(2,9,6,98)
B(2,9,7,1)
B(2,9,8,1)
B(2,10,-3,AIR)
B(2,10,-2,AIR)
B(2,10,-1,101)
B(2,10,0,AIR)
B(2,10,1,AIR)
B(2,10,2,AIR)
B(2,10,3,AIR)
B(2,10,4,AIR)
B(2,10,5,AIR)
B(2,10,6,98:3)
B(2,10,7,1)
B(2,10,8,1)
B(2,11,-3,AIR)
B(2,11,-2,AIR)
B(2,11,-1,101)
B(2,11,0,AIR)
B(2,11,1,AIR)
B(2,11,2,AIR)
B(2,11,3,AIR)
B(2,11,4,AIR)
B(2,11,5,126:13)
B(2,11,6,98)
B(2,11,7,1)
B(2,11,8,1)
B(2,12,-3,AIR)
B(2,12,-2,AIR)
B(2,12,-1,159:7)
B(2,12,0,AIR)
B(2,12,1,AIR)
B(2,12,2,AIR)
B(2,12,3,AIR)
B(2,12,4,AIR)
B(2,12,5,159:7)
B(2,12,6,AIR)
B(2,12,7,AIR)
B(2,12,8,1)
B(2,13,-3,AIR)
B(2,13,-2,AIR)
B(2,13,-1,98)
B(2,13,0,AIR)
B(2,13,1,AIR)
B(2,13,2,AIR)
B(2,13,3,AIR)
B(2,13,4,AIR)
B(2,13,5,98)
B(2,13,6,AIR)
B(2,13,7,AIR)
B(2,13,8,AIR)
B(2,14,-3,AIR)
B(2,14,-2,98)
B(2,14,-1,98)
B(2,14,0,98)
B(2,14,1,AIR)
B(2,14,2,AIR)
B(2,14,3,AIR)
B(2,14,4,98)
B(2,14,5,98)
B(2,14,6,98)
B(2,14,7,AIR)
B(2,14,8,AIR)
B(2,15,-3,AIR)
B(2,15,-2,98)
B(2,15,-1,AIR)
B(2,15,0,159:7)
B(2,15,1,AIR)
B(2,15,2,AIR)
B(2,15,3,AIR)
B(2,15,4,159:7)
B(2,15,5,AIR)
B(2,15,6,98)
B(2,15,7,AIR)
B(2,15,8,AIR)
B(2,16,-3,AIR)
B(2,16,-2,44)
B(2,16,-1,AIR)
B(2,16,0,159:7)
B(2,16,1,AIR)
B(2,16,2,AIR)
B(2,16,3,AIR)
B(2,16,4,159:7)
B(2,16,5,AIR)
B(2,16,6,44)
B(2,16,7,AIR)
B(2,16,8,AIR)
B(2,17,-3,AIR)
B(2,17,-2,AIR)
B(2,17,-1,AIR)
B(2,17,0,101)
B(2,17,1,AIR)
B(2,17,2,AIR)
B(2,17,3,AIR)
B(2,17,4,101)
B(2,17,5,AIR)
B(2,17,6,AIR)
B(2,17,7,AIR)
B(2,17,8,AIR)
B(2,18,-3,AIR)
B(2,18,-2,AIR)
B(2,18,-1,AIR)
B(2,18,0,101)
B(2,18,1,AIR)
B(2,18,2,AIR)
B(2,18,3,AIR)
B(2,18,4,101)
B(2,18,5,AIR)
B(2,18,6,AIR)
B(2,18,7,AIR)
B(2,18,8,AIR)
B(2,19,-3,AIR)
B(2,19,-2,AIR)
B(2,19,-1,AIR)
B(2,19,0,101)
B(2,19,1,AIR)
B(2,19,2,AIR)
B(2,19,3,AIR)
B(2,19,4,101)
B(2,19,5,AIR)
B(2,19,6,AIR)
B(2,19,7,AIR)
B(2,19,8,AIR)
B(2,20,-3,AIR)
B(2,20,-2,AIR)
B(2,20,-1,AIR)
B(2,20,0,159:7)
B(2,20,1,AIR)
B(2,20,2,AIR)
B(2,20,3,AIR)
B(2,20,4,159:7)
B(2,20,5,AIR)
B(2,20,6,AIR)
B(2,20,7,AIR)
B(2,20,8,AIR)
B(2,21,-3,AIR)
B(2,21,-2,AIR)
B(2,21,-1,AIR)
B(2,21,0,101)
B(2,21,1,AIR)
B(2,21,2,AIR)
B(2,21,3,AIR)
B(2,21,4,101)
B(2,21,5,AIR)
B(2,21,6,AIR)
B(2,21,7,AIR)
B(2,21,8,AIR)
B(2,22,-3,AIR)
B(2,22,-2,AIR)
B(2,22,-1,AIR)
B(2,22,0,101)
B(2,22,1,AIR)
B(2,22,2,AIR)
B(2,22,3,AIR)
B(2,22,4,101)
B(2,22,5,AIR)
B(2,22,6,AIR)
B(2,22,7,AIR)
B(2,22,8,AIR)
B(2,23,-3,AIR)
B(2,23,-2,AIR)
B(2,23,-1,AIR)
B(2,23,0,101)
B(2,23,1,AIR)
B(2,23,2,AIR)
B(2,23,3,AIR)
B(2,23,4,101)
B(2,23,5,AIR)
B(2,23,6,AIR)
B(2,23,7,AIR)
B(2,23,8,AIR)
B(2,24,-3,AIR)
B(2,24,-2,AIR)
B(2,24,-1,44:13)
B(2,24,0,159:7)
B(2,24,1,AIR)
B(2,24,2,AIR)
B(2,24,3,AIR)
B(2,24,4,159:7)
B(2,24,5,44:13)
B(2,24,6,AIR)
B(2,24,7,AIR)
B(2,24,8,AIR)
B(2,25,-3,AIR)
B(2,25,-2,AIR)
B(2,25,-1,98)
B(2,25,0,98)
B(2,25,1,AIR)
B(2,25,2,AIR)
B(2,25,3,AIR)
B(2,25,4,98)
B(2,25,5,98)
B(2,25,6,AIR)
B(2,25,7,AIR)
B(2,25,8,AIR)
B(2,26,-3,AIR)
B(2,26,-2,AIR)
B(2,26,-1,98)
B(2,26,0,AIR)
B(2,26,1,98:3)
B(2,26,2,AIR)
B(2,26,3,98:3)
B(2,26,4,AIR)
B(2,26,5,98)
B(2,26,6,AIR)
B(2,26,7,AIR)
B(2,26,8,AIR)
B(2,27,-3,AIR)
B(2,27,-2,AIR)
B(2,27,-1,44)
B(2,27,0,AIR)
B(2,27,1,98)
B(2,27,2,AIR)
B(2,27,3,98)
B(2,27,4,AIR)
B(2,27,5,44)
B(2,27,6,AIR)
B(2,27,7,AIR)
B(2,27,8,AIR)
B(2,28,-3,AIR)
B(2,28,-2,AIR)
B(2,28,-1,AIR)
B(2,28,0,AIR)
B(2,28,1,101)
B(2,28,2,AIR)
B(2,28,3,101)
B(2,28,4,AIR)
B(2,28,5,AIR)
B(2,28,6,AIR)
B(2,28,7,AIR)
B(2,28,8,AIR)
B(2,29,-3,AIR)
B(2,29,-2,AIR)
B(2,29,-1,AIR)
B(2,29,0,AIR)
B(2,29,1,101)
B(2,29,2,AIR)
B(2,29,3,101)
B(2,29,4,AIR)
B(2,29,5,AIR)
B(2,29,6,AIR)
B(2,29,7,AIR)
B(2,29,8,AIR)
B(2,30,-3,AIR)
B(2,30,-2,AIR)
B(2,30,-1,AIR)
B(2,30,0,AIR)
B(2,30,1,101)
B(2,30,2,AIR)
B(2,30,3,101)
B(2,30,4,AIR)
B(2,30,5,AIR)
B(2,30,6,AIR)
B(2,30,7,AIR)
B(2,30,8,AIR)
B(2,31,-3,AIR)
B(2,31,-2,AIR)
B(2,31,-1,AIR)
B(2,31,0,AIR)
B(2,31,1,98)
B(2,31,2,124)
B(2,31,3,98)
B(2,31,4,AIR)
B(2,31,5,AIR)
B(2,31,6,AIR)
B(2,31,7,AIR)
B(2,31,8,AIR)
B(2,32,-3,AIR)
B(2,32,-2,AIR)
B(2,32,-1,AIR)
B(2,32,0,98)
B(2,32,1,98)
B(2,32,2,76:4)
B(2,32,3,98)
B(2,32,4,98)
B(2,32,5,AIR)
B(2,32,6,AIR)
B(2,32,7,AIR)
B(2,32,8,AIR)
B(2,33,-3,AIR)
B(2,33,-2,AIR)
B(2,33,-1,AIR)
B(2,33,0,44:5)
B(2,33,1,98)
B(2,33,2,98)
B(2,33,3,98)
B(2,33,4,44:5)
B(2,33,5,AIR)
B(2,33,6,AIR)
B(2,33,7,AIR)
B(2,33,8,AIR)
B(2,34,-3,AIR)
B(2,34,-2,AIR)
B(2,34,-1,AIR)
B(2,34,0,AIR)
B(2,34,1,44)
B(2,34,2,44)
B(2,34,3,44)
B(2,34,4,AIR)
B(2,34,5,AIR)
B(2,34,6,AIR)
B(2,34,7,AIR)
B(2,34,8,AIR)
B(3,-22,-7,1)
B(3,-22,-6,1)
B(3,-22,-5,1)
B(3,-22,-4,1)
B(3,-22,-3,1)
B(3,-22,-2,1)
B(3,-22,-1,1)
B(3,-22,0,1)
B(3,-22,1,1)
B(3,-22,2,1)
B(3,-22,3,1)
B(3,-22,4,1)
B(3,-22,5,1)
B(3,-22,6,1)
B(3,-22,7,1)
B(3,-22,8,1)
B(3,-21,-7,1)
B(3,-21,-6,1)
B(3,-21,-5,1)
B(3,-21,-4,1)
B(3,-21,-3,1)
B(3,-21,-2,1)
B(3,-21,-1,1)
B(3,-21,0,1)
B(3,-21,1,1)
B(3,-21,2,1)
B(3,-21,3,1)
B(3,-21,4,1)
B(3,-21,5,1)
B(3,-21,6,1)
B(3,-21,7,1)
B(3,-21,8,1)
B(3,-20,-7,1)
B(3,-20,-6,1)
B(3,-20,-5,1)
B(3,-20,-4,1)
B(3,-20,-3,1)
B(3,-20,-2,1)
B(3,-20,-1,1)
B(3,-20,0,1)
B(3,-20,1,1)
B(3,-20,2,1)
B(3,-20,3,1)
B(3,-20,4,1)
B(3,-20,5,1)
B(3,-20,6,1)
B(3,-20,7,1)
B(3,-20,8,1)
B(3,-19,-7,1)
B(3,-19,-6,1)
B(3,-19,-5,1)
B(3,-19,-4,1)
B(3,-19,-3,1)
B(3,-19,-2,1)
B(3,-19,-1,1)
B(3,-19,0,1)
B(3,-19,1,1)
B(3,-19,2,1)
B(3,-19,3,1)
B(3,-19,4,1)
B(3,-19,5,1)
B(3,-19,6,1)
B(3,-19,7,1)
B(3,-19,8,1)
B(3,-18,-7,1)
B(3,-18,-6,1)
B(3,-18,-5,1)
B(3,-18,-4,1)
B(3,-18,-3,1)
B(3,-18,-2,1)
B(3,-18,-1,1)
B(3,-18,0,1)
B(3,-18,1,1)
B(3,-18,2,1)
B(3,-18,3,1)
B(3,-18,4,1)
B(3,-18,5,1)
B(3,-18,6,1)
B(3,-18,7,1)
B(3,-18,8,1)
B(3,-17,-7,1)
B(3,-17,-6,1)
B(3,-17,-5,1)
B(3,-17,-4,1)
B(3,-17,-3,1)
B(3,-17,-2,1)
B(3,-17,-1,1)
B(3,-17,0,1)
B(3,-17,1,1)
B(3,-17,2,1)
B(3,-17,3,1)
B(3,-17,4,1)
B(3,-17,5,1)
B(3,-17,6,1)
B(3,-17,7,1)
B(3,-17,8,1)
B(3,-16,-7,1)
B(3,-16,-6,1)
B(3,-16,-5,1)
B(3,-16,-4,1)
B(3,-16,-3,1)
B(3,-16,-2,1)
B(3,-16,-1,1)
B(3,-16,0,1)
B(3,-16,1,1)
B(3,-16,2,1)
B(3,-16,3,1)
B(3,-16,4,1)
B(3,-16,5,1)
B(3,-16,6,1)
B(3,-16,7,1)
B(3,-16,8,1)
B(3,-15,-7,1)
B(3,-15,-6,1)
B(3,-15,-5,1)
B(3,-15,-4,1)
B(3,-15,-3,1)
B(3,-15,-2,1)
B(3,-15,-1,1)
B(3,-15,0,1)
B(3,-15,1,1)
B(3,-15,2,1)
B(3,-15,3,1)
B(3,-15,4,1)
B(3,-15,5,1)
B(3,-15,6,1)
B(3,-15,7,1)
B(3,-15,8,1)
B(3,-14,-7,1)
B(3,-14,-6,1)
B(3,-14,-5,1)
B(3,-14,-4,1)
B(3,-14,-3,1)
B(3,-14,-2,1)
B(3,-14,-1,1)
B(3,-14,0,1)
B(3,-14,1,1)
B(3,-14,2,1)
B(3,-14,3,1)
B(3,-14,4,1)
B(3,-14,5,1)
B(3,-14,6,1)
B(3,-14,7,1)
B(3,-14,8,1)
B(3,-13,-7,1)
B(3,-13,-6,1)
B(3,-13,-5,1)
B(3,-13,-4,1)
B(3,-13,-3,1)
B(3,-13,-2,1)
B(3,-13,-1,1)
B(3,-13,0,1)
B(3,-13,1,1)
B(3,-13,2,1)
B(3,-13,3,1)
B(3,-13,4,1)
B(3,-13,5,1)
B(3,-13,6,1)
B(3,-13,7,1)
B(3,-13,8,1)
B(3,-12,-7,1)
B(3,-12,-6,1)
B(3,-12,-5,1)
B(3,-12,-4,1)
B(3,-12,-3,1)
B(3,-12,-2,1)
B(3,-12,-1,1)
B(3,-12,0,1)
B(3,-12,1,1)
B(3,-12,2,1)
B(3,-12,3,1)
B(3,-12,4,1)
B(3,-12,5,1)
B(3,-12,6,1)
B(3,-12,7,1)
B(3,-12,8,1)
B(3,-11,-7,1)
B(3,-11,-6,1)
B(3,-11,-5,1)
B(3,-11,-4,1)
B(3,-11,-3,1)
B(3,-11,-2,1)
B(3,-11,-1,1)
B(3,-11,0,1)
B(3,-11,1,1)
B(3,-11,2,1)
B(3,-11,3,1)
B(3,-11,4,1)
B(3,-11,5,1)
B(3,-11,6,1)
B(3,-11,7,1)
B(3,-11,8,1)
B(3,-10,-7,1)
B(3,-10,-6,1)
B(3,-10,-5,1)
B(3,-10,-4,1)
B(3,-10,-3,1)
B(3,-10,-2,1)
B(3,-10,-1,1)
B(3,-10,0,1)
B(3,-10,1,1)
B(3,-10,2,1)
B(3,-10,3,1)
B(3,-10,4,1)
B(3,-10,5,1)
B(3,-10,6,1)
B(3,-10,7,1)
B(3,-10,8,1)
B(3,-9,-7,1)
B(3,-9,-6,1)
B(3,-9,-5,1)
B(3,-9,-4,1)
B(3,-9,-3,1)
B(3,-9,-2,1)
B(3,-9,-1,1)
B(3,-9,0,1)
B(3,-9,1,1)
B(3,-9,2,1)
B(3,-9,3,1)
B(3,-9,4,1)
B(3,-9,5,1)
B(3,-9,6,1)
B(3,-9,7,1)
B(3,-9,8,1)
B(3,-8,-7,1)
B(3,-8,-6,1)
B(3,-8,-5,1)
B(3,-8,-4,1)
B(3,-8,-3,1)
B(3,-8,-2,1)
B(3,-8,-1,1)
B(3,-8,0,1)
B(3,-8,1,1)
B(3,-8,2,1)
B(3,-8,3,1)
B(3,-8,4,1)
B(3,-8,5,1)
B(3,-8,6,1)
B(3,-8,7,1)
B(3,-8,8,1)
B(3,-7,-7,1)
B(3,-7,-6,1)
B(3,-7,-5,1)
B(3,-7,-4,1)
B(3,-7,-3,1)
B(3,-7,-2,1)
B(3,-7,-1,1)
B(3,-7,0,1)
B(3,-7,1,1)
B(3,-7,2,1)
B(3,-7,3,1)
B(3,-7,4,1)
B(3,-7,5,1)
B(3,-7,6,1)
B(3,-7,7,1)
B(3,-7,8,1)
B(3,-6,-7,1)
B(3,-6,-6,1)
B(3,-6,-5,1)
B(3,-6,-4,1)
B(3,-6,-3,1)
B(3,-6,-2,1)
B(3,-6,-1,1)
B(3,-6,0,1)
B(3,-6,1,1)
B(3,-6,2,1)
B(3,-6,3,1)
B(3,-6,4,1)
B(3,-6,5,1)
B(3,-6,6,1)
B(3,-6,7,1)
B(3,-6,8,1)
B(3,-5,-6,1)
B(3,-5,-5,1)
B(3,-5,-4,1)
B(3,-5,-3,1)
B(3,-5,-2,1)
B(3,-5,-1,1)
B(3,-5,0,1)
B(3,-5,1,1)
B(3,-5,2,1)
B(3,-5,3,1)
B(3,-5,4,1)
B(3,-5,5,1)
B(3,-5,6,1)
B(3,-5,7,1)
B(3,-5,8,1)
B(3,-4,-6,1)
B(3,-4,-5,1)
B(3,-4,-4,1)
B(3,-4,-3,1)
B(3,-4,-2,1)
B(3,-4,-1,1)
B(3,-4,0,1)
B(3,-4,1,1)
B(3,-4,2,1)
B(3,-4,3,1)
B(3,-4,4,1)
B(3,-4,5,1)
B(3,-4,6,1)
B(3,-4,7,1)
B(3,-4,8,1)
B(3,-3,-6,1)
B(3,-3,-5,1)
B(3,-3,-4,1)
B(3,-3,-3,1)
B(3,-3,-2,1)
B(3,-3,-1,1)
B(3,-3,0,1)
B(3,-3,1,1)
B(3,-3,2,1)
B(3,-3,3,1)
B(3,-3,4,1)
B(3,-3,5,1)
B(3,-3,6,1)
B(3,-3,7,1)
B(3,-3,8,1)
B(3,-2,-5,1)
B(3,-2,-4,1)
B(3,-2,-3,1)
B(3,-2,-2,1)
B(3,-2,-1,1)
B(3,-2,0,1)
B(3,-2,1,1)
B(3,-2,2,1)
B(3,-2,3,1)
B(3,-2,4,1)
B(3,-2,5,1)
B(3,-2,6,1)
B(3,-2,7,1)
B(3,-2,8,1)
B(3,-1,-5,1)
B(3,-1,-4,1)
B(3,-1,-3,1)
B(3,-1,-2,1)
B(3,-1,-1,1)
B(3,-1,0,1)
B(3,-1,1,1)
B(3,-1,2,1)
B(3,-1,3,1)
B(3,-1,4,1)
B(3,-1,5,1)
B(3,-1,6,1)
B(3,-1,7,1)
B(3,-1,8,1)
B(3,0,-5,1)
B(3,0,-4,1)
B(3,0,-3,1)
B(3,0,-2,1)
B(3,0,-1,1)
B(3,0,0,1)
B(3,0,1,1)
B(3,0,2,1)
B(3,0,3,1)
B(3,0,4,1)
B(3,0,5,1)
B(3,0,6,1)
B(3,0,7,1)
B(3,0,8,1)
B(3,1,-3,1)
B(3,1,-2,98)
B(3,1,-1,98)
B(3,1,0,98)
B(3,1,1,98)
B(3,1,2,98)
B(3,1,3,98)
B(3,1,4,98)
B(3,1,5,98)
B(3,1,6,98)
B(3,1,7,1)
B(3,1,8,1)
B(3,2,-3,AIR)
B(3,2,-2,98)
B(3,2,-1,98)
B(3,2,0,98)
B(3,2,1,98)
B(3,2,2,98)
B(3,2,3,98)
B(3,2,4,98)
B(3,2,5,98)
B(3,2,6,98)
B(3,2,7,1)
B(3,2,8,1)
B(3,3,-3,AIR)
B(3,3,-2,98)
B(3,3,-1,98)
B(3,3,0,98)
B(3,3,1,98)
B(3,3,2,98)
B(3,3,3,98)
B(3,3,4,98)
B(3,3,5,98)
B(3,3,6,98)
B(3,3,7,1)
B(3,3,8,1)
B(3,4,-3,98)
B(3,4,-2,98)
B(3,4,-1,98)
B(3,4,0,98)
B(3,4,1,98)
B(3,4,2,98)
B(3,4,3,98)
B(3,4,4,98)
B(3,4,5,98)
B(3,4,6,98)
B(3,4,7,1)
B(3,4,8,1)
B(3,5,-3,AIR)
B(3,5,-2,98)
B(3,5,-1,98)
B(3,5,0,43:5)
B(3,5,1,AIR)
B(3,5,2,AIR)
B(3,5,3,AIR)
B(3,5,4,AIR)
B(3,5,5,98)
B(3,5,6,98)
B(3,5,7,1)
B(3,5,8,1)
B(3,6,-3,AIR)
B(3,6,-2,98)
B(3,6,-1,98)
B(3,6,0,44:5)
B(3,6,1,AIR)
B(3,6,2,AIR)
B(3,6,3,AIR)
B(3,6,4,AIR)
RB(3,6,5,FLOWER_POT,../../nbt/Misc/FlowerPot1.nbt,20,FLOWER_POT,../../nbt/Misc/FlowerPot2.nbt,20,FLOWER_POT,../../nbt/Misc/FlowerPot3.nbt,20,FLOWER_POT,../../nbt/Misc/FlowerPot8.nbt,20,FLOWER_POT,../../nbt/Misc/FlowerPot4.nbt,20,FLOWER_POT,../../nbt/Misc/FlowerPot5.nbt,20,FLOWER_POT,../../nbt/Misc/FlowerPot6.nbt,20,FLOWER_POT,../../nbt/Misc/FlowerPot7.nbt,20,FLOWER_POT,../../nbt/Misc/FlowerPot8.nbt,100)
B(3,6,6,98)
B(3,6,7,1)
B(3,6,8,1)
B(3,7,-3,AIR)
B(3,7,-2,98)
B(3,7,-1,98)
B(3,7,0,AIR)
B(3,7,1,AIR)
B(3,7,2,AIR)
B(3,7,3,AIR)
B(3,7,4,AIR)
B(3,7,5,126:13)
B(3,7,6,98)
B(3,7,7,1)
B(3,7,8,1)
B(3,8,-3,AIR)
B(3,8,-2,44:5)
B(3,8,-1,98)
B(3,8,0,AIR)
B(3,8,1,98)
B(3,8,2,98)
B(3,8,3,98)
B(3,8,4,98)
B(3,8,5,98)
B(3,8,6,1)
B(3,8,7,1)
B(3,8,8,1)
B(3,9,-3,AIR)
B(3,9,-2,AIR)
B(3,9,-1,159:7)
B(3,9,0,AIR)
B(3,9,1,AIR)
B(3,9,2,171:13)
B(3,9,3,171:13)
B(3,9,4,AIR)
B(3,9,5,126:13)
B(3,9,6,1)
B(3,9,7,1)
B(3,9,8,1)
B(3,10,-3,AIR)
B(3,10,-2,AIR)
B(3,10,-1,159:7)
B(3,10,0,AIR)
B(3,10,1,AIR)
B(3,10,2,AIR)
B(3,10,3,AIR)
B(3,10,4,AIR)
RB(3,10,5,FLOWER_POT,../../nbt/Misc/FlowerPot1.nbt,20,FLOWER_POT,../../nbt/Misc/FlowerPot2.nbt,20,FLOWER_POT,../../nbt/Misc/FlowerPot3.nbt,20,FLOWER_POT,../../nbt/Misc/FlowerPot8.nbt,20,FLOWER_POT,../../nbt/Misc/FlowerPot4.nbt,20,FLOWER_POT,../../nbt/Misc/FlowerPot5.nbt,20,FLOWER_POT,../../nbt/Misc/FlowerPot6.nbt,20,FLOWER_POT,../../nbt/Misc/FlowerPot7.nbt,20,FLOWER_POT,../../nbt/Misc/FlowerPot8.nbt,100)
B(3,10,6,1)
B(3,10,7,1)
B(3,10,8,1)
B(3,11,-3,AIR)
B(3,11,-2,AIR)
B(3,11,-1,159:7)
B(3,11,0,AIR)
B(3,11,1,AIR)
B(3,11,2,AIR)
B(3,11,3,AIR)
B(3,11,4,AIR)
B(3,11,5,126:13)
B(3,11,6,1)
B(3,11,7,1)
B(3,11,8,AIR)
B(3,12,-3,AIR)
B(3,12,-2,AIR)
B(3,12,-1,159:7)
B(3,12,0,AIR)
B(3,12,1,AIR)
B(3,12,2,AIR)
B(3,12,3,AIR)
B(3,12,4,AIR)
B(3,12,5,159:7)
B(3,12,6,AIR)
B(3,12,7,AIR)
B(3,12,8,AIR)
B(3,13,-3,AIR)
B(3,13,-2,44:13)
B(3,13,-1,98)
B(3,13,0,AIR)
B(3,13,1,AIR)
B(3,13,2,AIR)
B(3,13,3,AIR)
B(3,13,4,AIR)
B(3,13,5,98)
B(3,13,6,44:13)
B(3,13,7,AIR)
B(3,13,8,AIR)
B(3,14,-3,AIR)
B(3,14,-2,98)
B(3,14,-1,98)
B(3,14,0,98)
B(3,14,1,AIR)
B(3,14,2,AIR)
B(3,14,3,AIR)
B(3,14,4,98)
B(3,14,5,98)
B(3,14,6,98)
B(3,14,7,AIR)
B(3,14,8,AIR)
B(3,15,-3,AIR)
B(3,15,-2,98)
B(3,15,-1,AIR)
B(3,15,0,159:7)
B(3,15,1,AIR)
B(3,15,2,AIR)
B(3,15,3,AIR)
B(3,15,4,159:7)
B(3,15,5,AIR)
B(3,15,6,98)
B(3,15,7,AIR)
B(3,15,8,AIR)
B(3,16,-3,AIR)
B(3,16,-2,44)
B(3,16,-1,AIR)
B(3,16,0,159:7)
B(3,16,1,AIR)
B(3,16,2,AIR)
B(3,16,3,AIR)
B(3,16,4,159:7)
B(3,16,5,AIR)
B(3,16,6,44)
B(3,16,7,AIR)
B(3,16,8,AIR)
B(3,17,-3,AIR)
B(3,17,-2,AIR)
B(3,17,-1,AIR)
B(3,17,0,159:7)
B(3,17,1,AIR)
B(3,17,2,AIR)
B(3,17,3,AIR)
B(3,17,4,159:7)
B(3,17,5,AIR)
B(3,17,6,AIR)
B(3,17,7,AIR)
B(3,17,8,AIR)
B(3,18,-3,AIR)
B(3,18,-2,AIR)
B(3,18,-1,AIR)
B(3,18,0,159:7)
B(3,18,1,AIR)
B(3,18,2,AIR)
B(3,18,3,AIR)
B(3,18,4,159:7)
B(3,18,5,AIR)
B(3,18,6,AIR)
B(3,18,7,AIR)
B(3,18,8,AIR)
B(3,19,-3,AIR)
B(3,19,-2,AIR)
B(3,19,-1,AIR)
B(3,19,0,159:7)
B(3,19,1,AIR)
B(3,19,2,AIR)
B(3,19,3,AIR)
B(3,19,4,159:7)
B(3,19,5,AIR)
B(3,19,6,AIR)
B(3,19,7,AIR)
B(3,19,8,AIR)
B(3,20,-3,AIR)
B(3,20,-2,AIR)
B(3,20,-1,AIR)
B(3,20,0,159:7)
B(3,20,1,AIR)
B(3,20,2,AIR)
B(3,20,3,AIR)
B(3,20,4,159:7)
B(3,20,5,AIR)
B(3,20,6,AIR)
B(3,20,7,AIR)
B(3,20,8,AIR)
B(3,21,-3,AIR)
B(3,21,-2,AIR)
B(3,21,-1,AIR)
B(3,21,0,159:7)
B(3,21,1,AIR)
B(3,21,2,AIR)
B(3,21,3,AIR)
B(3,21,4,159:7)
B(3,21,5,AIR)
B(3,21,6,AIR)
B(3,21,7,AIR)
B(3,21,8,AIR)
B(3,22,-3,AIR)
B(3,22,-2,AIR)
B(3,22,-1,AIR)
B(3,22,0,159:7)
B(3,22,1,AIR)
B(3,22,2,AIR)
B(3,22,3,AIR)
B(3,22,4,159:7)
B(3,22,5,AIR)
B(3,22,6,AIR)
B(3,22,7,AIR)
B(3,22,8,AIR)
B(3,23,-3,AIR)
B(3,23,-2,AIR)
B(3,23,-1,AIR)
B(3,23,0,159:7)
B(3,23,1,AIR)
B(3,23,2,AIR)
B(3,23,3,AIR)
B(3,23,4,159:7)
B(3,23,5,AIR)
B(3,23,6,AIR)
B(3,23,7,AIR)
B(3,23,8,AIR)
B(3,24,-3,AIR)
B(3,24,-2,AIR)
B(3,24,-1,AIR)
B(3,24,0,159:7)
B(3,24,1,AIR)
B(3,24,2,AIR)
B(3,24,3,AIR)
B(3,24,4,159:7)
B(3,24,5,AIR)
B(3,24,6,AIR)
B(3,24,7,AIR)
B(3,24,8,AIR)
B(3,25,-3,AIR)
B(3,25,-2,AIR)
B(3,25,-1,98)
B(3,25,0,98)
B(3,25,1,AIR)
B(3,25,2,AIR)
B(3,25,3,AIR)
B(3,25,4,98)
B(3,25,5,98)
B(3,25,6,AIR)
B(3,25,7,AIR)
B(3,25,8,AIR)
B(3,26,-3,AIR)
B(3,26,-2,AIR)
B(3,26,-1,44:5)
B(3,26,0,AIR)
B(3,26,1,98)
B(3,26,2,98:3)
B(3,26,3,98)
B(3,26,4,AIR)
B(3,26,5,44:5)
B(3,26,6,AIR)
B(3,26,7,AIR)
B(3,26,8,AIR)
B(3,27,-3,AIR)
B(3,27,-2,AIR)
B(3,27,-1,AIR)
B(3,27,0,AIR)
B(3,27,1,98)
B(3,27,2,98)
B(3,27,3,98)
B(3,27,4,AIR)
B(3,27,5,AIR)
B(3,27,6,AIR)
B(3,27,7,AIR)
B(3,27,8,AIR)
B(3,28,-3,AIR)
B(3,28,-2,AIR)
B(3,28,-1,AIR)
B(3,28,0,AIR)
B(3,28,1,98)
B(3,28,2,101)
B(3,28,3,98)
B(3,28,4,AIR)
B(3,28,5,AIR)
B(3,28,6,AIR)
B(3,28,7,AIR)
B(3,28,8,AIR)
B(3,29,-3,AIR)
B(3,29,-2,AIR)
B(3,29,-1,AIR)
B(3,29,0,AIR)
B(3,29,1,98)
B(3,29,2,101)
B(3,29,3,98)
B(3,29,4,AIR)
B(3,29,5,AIR)
B(3,29,6,AIR)
B(3,29,7,AIR)
B(3,29,8,AIR)
B(3,30,-3,AIR)
B(3,30,-2,AIR)
B(3,30,-1,AIR)
B(3,30,0,AIR)
B(3,30,1,98)
B(3,30,2,101)
B(3,30,3,98)
B(3,30,4,AIR)
B(3,30,5,AIR)
B(3,30,6,AIR)
B(3,30,7,AIR)
B(3,30,8,AIR)
B(3,31,-3,AIR)
B(3,31,-2,AIR)
B(3,31,-1,AIR)
B(3,31,0,44:13)
B(3,31,1,98)
B(3,31,2,98)
B(3,31,3,98)
B(3,31,4,44:13)
B(3,31,5,AIR)
B(3,31,6,AIR)
B(3,31,7,AIR)
B(3,31,8,AIR)
B(3,32,-3,AIR)
B(3,32,-2,AIR)
B(3,32,-1,AIR)
B(3,32,0,98)
B(3,32,1,98)
B(3,32,2,98)
B(3,32,3,98)
B(3,32,4,98)
B(3,32,5,AIR)
B(3,32,6,AIR)
B(3,32,7,AIR)
B(3,32,8,AIR)
B(3,33,-3,AIR)
B(3,33,-2,AIR)
B(3,33,-1,AIR)
B(3,33,0,98)
B(3,33,1,98)
B(3,33,2,98)
B(3,33,3,98)
B(3,33,4,98)
B(3,33,5,AIR)
B(3,33,6,AIR)
B(3,33,7,AIR)
B(3,33,8,AIR)
B(3,34,-3,AIR)
B(3,34,-2,AIR)
B(3,34,-1,AIR)
B(3,34,0,44)
B(3,34,1,44)
B(3,34,2,44)
B(3,34,3,44)
B(3,34,4,44)
B(3,34,5,AIR)
B(3,34,6,AIR)
B(3,34,7,AIR)
B(3,34,8,AIR)
B(4,-22,-7,1)
B(4,-22,-6,1)
B(4,-22,-5,1)
B(4,-22,-4,1)
B(4,-22,-3,1)
B(4,-22,-2,1)
B(4,-22,-1,1)
B(4,-22,0,1)
B(4,-22,1,1)
B(4,-22,2,1)
B(4,-22,3,1)
B(4,-22,4,1)
B(4,-22,5,1)
B(4,-22,6,1)
B(4,-22,7,1)
B(4,-22,8,1)
B(4,-21,-7,1)
B(4,-21,-6,1)
B(4,-21,-5,1)
B(4,-21,-4,1)
B(4,-21,-3,1)
B(4,-21,-2,1)
B(4,-21,-1,1)
B(4,-21,0,1)
B(4,-21,1,1)
B(4,-21,2,1)
B(4,-21,3,1)
B(4,-21,4,1)
B(4,-21,5,1)
B(4,-21,6,1)
B(4,-21,7,1)
B(4,-21,8,1)
B(4,-20,-7,1)
B(4,-20,-6,1)
B(4,-20,-5,1)
B(4,-20,-4,1)
B(4,-20,-3,1)
B(4,-20,-2,1)
B(4,-20,-1,1)
B(4,-20,0,1)
B(4,-20,1,1)
B(4,-20,2,1)
B(4,-20,3,1)
B(4,-20,4,1)
B(4,-20,5,1)
B(4,-20,6,1)
B(4,-20,7,1)
B(4,-20,8,1)
B(4,-19,-7,1)
B(4,-19,-6,1)
B(4,-19,-5,1)
B(4,-19,-4,1)
B(4,-19,-3,1)
B(4,-19,-2,1)
B(4,-19,-1,1)
B(4,-19,0,1)
B(4,-19,1,1)
B(4,-19,2,1)
B(4,-19,3,1)
B(4,-19,4,1)
B(4,-19,5,1)
B(4,-19,6,1)
B(4,-19,7,1)
B(4,-19,8,1)
B(4,-18,-7,1)
B(4,-18,-6,1)
B(4,-18,-5,1)
B(4,-18,-4,1)
B(4,-18,-3,1)
B(4,-18,-2,1)
B(4,-18,-1,1)
B(4,-18,0,1)
B(4,-18,1,1)
B(4,-18,2,1)
B(4,-18,3,1)
B(4,-18,4,1)
B(4,-18,5,1)
B(4,-18,6,1)
B(4,-18,7,1)
B(4,-18,8,1)
B(4,-17,-7,1)
B(4,-17,-6,1)
B(4,-17,-5,1)
B(4,-17,-4,1)
B(4,-17,-3,1)
B(4,-17,-2,1)
B(4,-17,-1,1)
B(4,-17,0,1)
B(4,-17,1,1)
B(4,-17,2,1)
B(4,-17,3,1)
B(4,-17,4,1)
B(4,-17,5,1)
B(4,-17,6,1)
B(4,-17,7,1)
B(4,-17,8,1)
B(4,-16,-7,1)
B(4,-16,-6,1)
B(4,-16,-5,1)
B(4,-16,-4,1)
B(4,-16,-3,1)
B(4,-16,-2,1)
B(4,-16,-1,1)
B(4,-16,0,1)
B(4,-16,1,1)
B(4,-16,2,1)
B(4,-16,3,1)
B(4,-16,4,1)
B(4,-16,5,1)
B(4,-16,6,1)
B(4,-16,7,1)
B(4,-16,8,1)
B(4,-15,-7,1)
B(4,-15,-6,1)
B(4,-15,-5,1)
B(4,-15,-4,1)
B(4,-15,-3,1)
B(4,-15,-2,1)
B(4,-15,-1,1)
B(4,-15,0,1)
B(4,-15,1,1)
B(4,-15,2,1)
B(4,-15,3,1)
B(4,-15,4,1)
B(4,-15,5,1)
B(4,-15,6,1)
B(4,-15,7,1)
B(4,-15,8,1)
B(4,-14,-7,1)
B(4,-14,-6,1)
B(4,-14,-5,1)
B(4,-14,-4,1)
B(4,-14,-3,1)
B(4,-14,-2,1)
B(4,-14,-1,1)
B(4,-14,0,1)
B(4,-14,1,1)
B(4,-14,2,1)
B(4,-14,3,1)
B(4,-14,4,1)
B(4,-14,5,1)
B(4,-14,6,1)
B(4,-14,7,1)
B(4,-14,8,1)
B(4,-13,-7,1)
B(4,-13,-6,1)
B(4,-13,-5,1)
B(4,-13,-4,1)
B(4,-13,-3,1)
B(4,-13,-2,1)
B(4,-13,-1,1)
B(4,-13,0,1)
B(4,-13,1,1)
B(4,-13,2,1)
B(4,-13,3,1)
B(4,-13,4,1)
B(4,-13,5,1)
B(4,-13,6,1)
B(4,-13,7,1)
B(4,-13,8,1)
B(4,-12,-7,1)
B(4,-12,-6,1)
B(4,-12,-5,1)
B(4,-12,-4,1)
B(4,-12,-3,1)
B(4,-12,-2,1)
B(4,-12,-1,1)
B(4,-12,0,1)
B(4,-12,1,1)
B(4,-12,2,1)
B(4,-12,3,1)
B(4,-12,4,1)
B(4,-12,5,1)
B(4,-12,6,1)
B(4,-12,7,1)
B(4,-12,8,1)
B(4,-11,-7,1)
B(4,-11,-6,1)
B(4,-11,-5,1)
B(4,-11,-4,1)
B(4,-11,-3,1)
B(4,-11,-2,1)
B(4,-11,-1,1)
B(4,-11,0,1)
B(4,-11,1,1)
B(4,-11,2,1)
B(4,-11,3,1)
B(4,-11,4,1)
B(4,-11,5,1)
B(4,-11,6,1)
B(4,-11,7,1)
B(4,-11,8,1)
B(4,-10,-7,1)
B(4,-10,-6,1)
B(4,-10,-5,1)
B(4,-10,-4,1)
B(4,-10,-3,1)
B(4,-10,-2,1)
B(4,-10,-1,1)
B(4,-10,0,1)
B(4,-10,1,1)
B(4,-10,2,1)
B(4,-10,3,1)
B(4,-10,4,1)
B(4,-10,5,1)
B(4,-10,6,1)
B(4,-10,7,1)
B(4,-10,8,1)
B(4,-9,-7,1)
B(4,-9,-6,1)
B(4,-9,-5,1)
B(4,-9,-4,1)
B(4,-9,-3,1)
B(4,-9,-2,1)
B(4,-9,-1,1)
B(4,-9,0,1)
B(4,-9,1,1)
B(4,-9,2,1)
B(4,-9,3,1)
B(4,-9,4,1)
B(4,-9,5,1)
B(4,-9,6,1)
B(4,-9,7,1)
B(4,-9,8,1)
B(4,-8,-7,1)
B(4,-8,-6,1)
B(4,-8,-5,1)
B(4,-8,-4,1)
B(4,-8,-3,1)
B(4,-8,-2,1)
B(4,-8,-1,1)
B(4,-8,0,1)
B(4,-8,1,1)
B(4,-8,2,1)
B(4,-8,3,1)
B(4,-8,4,1)
B(4,-8,5,1)
B(4,-8,6,1)
B(4,-8,7,1)
B(4,-8,8,1)
B(4,-7,-6,1)
B(4,-7,-5,1)
B(4,-7,-4,1)
B(4,-7,-3,1)
B(4,-7,-2,1)
B(4,-7,-1,1)
B(4,-7,0,1)
B(4,-7,1,1)
B(4,-7,2,1)
B(4,-7,3,1)
B(4,-7,4,1)
B(4,-7,5,1)
B(4,-7,6,1)
B(4,-7,7,1)
B(4,-7,8,1)
B(4,-6,-6,1)
B(4,-6,-5,1)
B(4,-6,-4,1)
B(4,-6,-3,1)
B(4,-6,-2,1)
B(4,-6,-1,1)
B(4,-6,0,1)
B(4,-6,1,1)
B(4,-6,2,1)
B(4,-6,3,1)
B(4,-6,4,1)
B(4,-6,5,1)
B(4,-6,6,1)
B(4,-6,7,1)
B(4,-6,8,1)
B(4,-5,-6,1)
B(4,-5,-5,1)
B(4,-5,-4,1)
B(4,-5,-3,1)
B(4,-5,-2,1)
B(4,-5,-1,1)
B(4,-5,0,1)
B(4,-5,1,1)
B(4,-5,2,1)
B(4,-5,3,1)
B(4,-5,4,1)
B(4,-5,5,1)
B(4,-5,6,1)
B(4,-5,7,1)
B(4,-5,8,1)
B(4,-4,-6,1)
B(4,-4,-5,1)
B(4,-4,-4,1)
B(4,-4,-3,1)
B(4,-4,-2,1)
B(4,-4,-1,1)
B(4,-4,0,1)
B(4,-4,1,1)
B(4,-4,2,1)
B(4,-4,3,1)
B(4,-4,4,1)
B(4,-4,5,1)
B(4,-4,6,1)
B(4,-4,7,1)
B(4,-4,8,1)
B(4,-3,-6,1)
B(4,-3,-5,1)
B(4,-3,-4,1)
B(4,-3,-3,1)
B(4,-3,-2,1)
B(4,-3,-1,1)
B(4,-3,0,1)
B(4,-3,1,1)
B(4,-3,2,1)
B(4,-3,3,1)
B(4,-3,4,1)
B(4,-3,5,1)
B(4,-3,6,1)
B(4,-3,7,1)
B(4,-3,8,1)
B(4,-2,-5,1)
B(4,-2,-4,1)
B(4,-2,-3,1)
B(4,-2,-2,1)
B(4,-2,-1,1)
B(4,-2,0,1)
B(4,-2,1,1)
B(4,-2,2,1)
B(4,-2,3,1)
B(4,-2,4,1)
B(4,-2,5,1)
B(4,-2,6,1)
B(4,-2,7,1)
B(4,-2,8,1)
B(4,-1,-5,1)
B(4,-1,-4,1)
B(4,-1,-3,1)
B(4,-1,-2,1)
B(4,-1,-1,1)
B(4,-1,0,1)
B(4,-1,1,1)
B(4,-1,2,1)
B(4,-1,3,1)
B(4,-1,4,1)
B(4,-1,5,1)
B(4,-1,6,1)
B(4,-1,7,1)
B(4,-1,8,1)
B(4,0,-4,1)
B(4,0,-3,1)
B(4,0,-2,1)
B(4,0,-1,1)
B(4,0,0,1)
B(4,0,1,1)
B(4,0,2,1)
B(4,0,3,1)
B(4,0,4,1)
B(4,0,5,1)
B(4,0,6,1)
B(4,0,7,1)
B(4,0,8,1)
B(4,1,-3,AIR)
B(4,1,-2,98)
B(4,1,-1,98)
B(4,1,0,98)
B(4,1,1,98)
B(4,1,2,98)
B(4,1,3,98)
B(4,1,4,98)
B(4,1,5,98)
B(4,1,6,98)
B(4,1,7,1)
B(4,1,8,1)
B(4,2,-3,AIR)
B(4,2,-2,98)
B(4,2,-1,98)
B(4,2,0,98)
B(4,2,1,98)
B(4,2,2,98)
B(4,2,3,98)
B(4,2,4,98)
B(4,2,5,98)
B(4,2,6,98)
B(4,2,7,1)
B(4,2,8,1)
B(4,3,-3,AIR)
B(4,3,-2,98)
B(4,3,-1,98)
B(4,3,0,98)
B(4,3,1,98)
B(4,3,2,98)
B(4,3,3,98)
B(4,3,4,98)
B(4,3,5,98)
B(4,3,6,98)
B(4,3,7,1)
B(4,3,8,1)
B(4,4,-3,98)
B(4,4,-2,98)
B(4,4,-1,98)
B(4,4,0,98)
B(4,4,1,98)
B(4,4,2,98)
B(4,4,3,98)
B(4,4,4,98)
B(4,4,5,98)
B(4,4,6,98)
B(4,4,7,1)
B(4,4,8,1)
B(4,5,-3,AIR)
B(4,5,-2,98)
B(4,5,-1,98)
B(4,5,0,43:5)
B(4,5,1,44:5)
B(4,5,2,AIR)
B(4,5,3,AIR)
B(4,5,4,AIR)
B(4,5,5,98)
B(4,5,6,98)
B(4,5,7,1)
B(4,5,8,1)
B(4,6,-3,AIR)
B(4,6,-2,98)
B(4,6,-1,98)
B(4,6,0,AIR)
B(4,6,1,AIR)
B(4,6,2,AIR)
B(4,6,3,AIR)
B(4,6,4,AIR)
B(4,6,5,98)
B(4,6,6,98)
B(4,6,7,1)
B(4,6,8,1)
B(4,7,-3,AIR)
B(4,7,-2,98)
B(4,7,-1,98)
B(4,7,0,AIR)
B(4,7,1,AIR)
B(4,7,2,AIR)
B(4,7,3,AIR)
B(4,7,4,AIR)
