
#######################################################################
# +-----------------------------------------------------------------+ #
# |                            BO3 object                           | #
# +-----------------------------------------------------------------+ #
#######################################################################

# This is the config file of a custom object.
# If you add this object correctly to your BiomeConfigs, it will spawn in the world.

# This is the creator of this BO3 object
Author: LordSmellyPants

# A short description of this BO3 object
Description: No description given

# The BO3 version, don't change this! It can be used by external applications to do a version check.
Version: 3

# The settings mode, WriteAll, WriteWithoutComments or WriteDisable. See WorldConfig.
SettingsMode: WriteDisable


#######################################################################
# +-----------------------------------------------------------------+ #
# |                          Main settings                          | #
# +-----------------------------------------------------------------+ #
#######################################################################

# This needs to be set to true to spawn the object in the Tree and Sapling resources.
Tree: false

# The frequency of the BO3 from 1 to 200. Tries this many times to spawn this BO3 when using the CustomObject(...) resource.
# Ignored by Tree(..), Sapling(..) and CustomStructure(..)
Frequency: 1

# The rarity of the BO3 from 0 to 100. Each spawn attempt has rarity% chance to succeed when using the CustomObject(...) resource.
# Ignored by Tree(..), Sapling(..) and CustomStructure(..)
Rarity: 0.5

# If you set this to true, the BO3 will be placed with a random rotation.
RotateRandomly: false

# The spawn height of the BO3 - randomY, highestBlock or highestSolidBlock.
SpawnHeight: highestSolidBlock

# The height limits for the BO3.
MinHeight: 0

MaxHeight: 256

# Objects can have other objects attacthed to it: branches. Branches can also
# have branches attached to it, which can also have branches, etc. This is the
# maximum branch depth for this objects.
MaxBranchDepth: 10

# When spawned with the UseWorld keyword, this BO3 should NOT spawn in the following biomes.
# If you writer.write the BO3 name directly in the BiomeConfigs, this will be ignored.
ExcludedBiomes: All


#######################################################################
# +-----------------------------------------------------------------+ #
# |                      Source block settings                      | #
# +-----------------------------------------------------------------+ #
#######################################################################

# The block(s) the BO3 should spawn in.
SourceBlocks: AIR

# The maximum percentage of the BO3 that can be outside the SourceBlock.
# The BO3 won't be placed on a location with more blocks outside the SourceBlock than this percentage.
MaxPercentageOutsideSourceBlock: 100

# What to do when a block is about to be placed outside the SourceBlock? (dontPlace, placeAnyway)
OutsideSourceBlock: placeAnyway


#######################################################################
# +-----------------------------------------------------------------+ #
# |                              Blocks                             | #
# +-----------------------------------------------------------------+ #
#######################################################################

# All the blocks used in the BO3 are listed here. Possible blocks:
# Block(x,y,z,id[.data][,nbtfile.nbt)
# RandomBlock(x,y,z,id[:data][,nbtfile.nbt],chance[,id[:data][,nbtfile.nbt],chance[,...]])
# So RandomBlock(0,0,0,CHEST,chest.nbt,50,CHEST,anotherchest.nbt,100) will spawn a chest at
# the BO3 origin, and give it a 50% chance to have the contents of chest.nbt, or, if that
# fails, a 100% percent chance to have the contents of anotherchest.nbt.
Block(-13,3,0,WOOD_STAIRS:4)
Block(-13,4,0,WOOD_STAIRS)
Block(-12,1,0,WOOD_STAIRS:4)
Block(-12,2,0,WOOD:2)
Block(-12,3,0,WOOD:1)
Block(-12,4,0,WOOD_STEP)
Block(-11,0,0,WOOD:1)
Block(-11,1,0,WOOD:1)
Block(-11,2,0,WOOD:1)
Block(-11,3,0,FENCE)
Block(-11,4,0,FENCE)
Block(-10,-1,-1,SPRUCE_WOOD_STAIRS:4)
Block(-10,-1,0,WOOD_STAIRS:4)
Block(-10,-1,1,SPRUCE_WOOD_STAIRS:4)
Block(-10,0,-1,WOOD:1)
RandomBlock(-10,0,0,CHEST,../../nbt/Chests/Epic1.nbt,25,CHEST,../../nbt/Chests/Epic2.nbt,25,CHEST,../../nbt/Chests/Epic3.nbt,25,CHEST,../../nbt/Chests/Epic4.nbt,25,CHEST,../../nbt/Chests/Epic5.nbt,25,CHEST,../../nbt/Chests/Epic6.nbt,25,CHEST,../../nbt/Chests/Epic7.nbt,25,CHEST,../../nbt/Chests/Epic8.nbt,25,CHEST,../../nbt/Chests/Epic9.nbt,25,CHEST,../../nbt/Chests/Epic10.nbt,25,CHEST,../../nbt/Chests/Epic11.nbt,25,CHEST,../../nbt/Chests/Epic12.nbt,25,CHEST,../../nbt/Chests/Epic13.nbt,25,CHEST,../../nbt/Chests/Epic14.nbt,25,CHEST,../../nbt/Chests/Epic15.nbt,100)
Block(-10,0,1,WOOD)
Block(-10,1,-1,WOOD:1)
Block(-10,1,0,WOOL)
Block(-10,1,1,WOOD:1)
Block(-10,2,-1,WOOD:1)
Block(-10,2,0,WOOD_STEP)
Block(-10,2,1,WOOD:1)
Block(-10,3,-1,FENCE)
Block(-10,3,1,FENCE)
Block(-9,-2,-1,SPRUCE_WOOD_STAIRS:6)
Block(-9,-2,0,WOOD_STAIRS:4)
Block(-9,-2,1,SPRUCE_WOOD_STAIRS:7)
Block(-9,-1,-2,SPRUCE_WOOD_STAIRS:6)
Block(-9,-1,-1,TNT)
Block(-9,-1,0,WOOL)
Block(-9,-1,1,WOOL)
Block(-9,-1,2,SPRUCE_WOOD_STAIRS:7)
Block(-9,0,-2,WOOD:1)
Block(-9,0,-1,TNT)
Block(-9,0,0,WOOL)
Block(-9,0,1,WOOL)
Block(-9,0,2,WOOD:1)
Block(-9,1,-2,WOOD)
Block(-9,1,-1,WOOL)
Block(-9,1,0,WOOL)
Block(-9,1,1,WOOL)
Block(-9,1,2,WOOD:1)
Block(-9,2,-2,WOOD:1)
Block(-9,2,-1,WOOD_STEP)
Block(-9,2,0,WOOD_STEP)
Block(-9,2,1,WOOD_STEP)
Block(-9,2,2,WOOD:1)
Block(-8,-2,-1,SPRUCE_WOOD_STAIRS:6)
Block(-8,-2,0,WOOD)
Block(-8,-2,1,SPRUCE_WOOD_STAIRS:7)
Block(-8,-1,-2,SPRUCE_WOOD_STAIRS:6)
Block(-8,-1,-1,WOOL)
Block(-8,-1,0,WOOL)
Block(-8,-1,1,WOOL)
Block(-8,-1,2,SPRUCE_WOOD_STAIRS:7)
Block(-8,0,-2,WOOD:1)
Block(-8,0,-1,WOOL)
Block(-8,0,0,WOOL)
Block(-8,0,1,WOOL)
Block(-8,0,2,WOOD:1)
Block(-8,1,-2,WOOD)
Block(-8,1,-1,WOOL)
Block(-8,1,0,WOOL)
Block(-8,1,1,WOOL)
Block(-8,1,2,WOOD:1)
Block(-8,2,-2,WOOD:1)
Block(-8,2,-1,WOOD_STEP)
Block(-8,2,0,WOOD_STEP)
Block(-8,2,1,WOOD_STEP)
Block(-8,2,2,WOOD:1)
Block(-8,3,-2,FENCE)
Block(-8,3,2,FENCE)
Block(-7,-2,-1,SPRUCE_WOOD_STAIRS:6)
Block(-7,-2,0,WOOD)
Block(-7,-2,1,SPRUCE_WOOD_STAIRS:7)
Block(-7,-1,-2,SPRUCE_WOOD_STAIRS:6)
Block(-7,-1,-1,TNT)
Block(-7,-1,0,WOOL)
Block(-7,-1,1,WOOL)
Block(-7,-1,2,SPRUCE_WOOD_STAIRS:7)
Block(-7,0,-2,WOOD:1)
Block(-7,0,-1,WOOL)
Block(-7,0,0,WOOL)
Block(-7,0,1,WOOL)
Block(-7,0,2,WOOD:1)
Block(-7,1,-2,WOOD:1)
Block(-7,1,-1,WOOL)
Block(-7,1,0,WOOL)
Block(-7,1,1,WOOL)
Block(-7,1,2,WOOD)
Block(-7,2,-2,WOOD:1)
Block(-7,2,-1,WOOD_STEP)
Block(-7,2,0,WOOD_STEP)
Block(-7,2,1,WOOD_STEP)
Block(-7,2,2,WOOD:1)
Block(-6,-2,-1,SPRUCE_WOOD_STAIRS:6)
Block(-6,-2,0,WOOD)
Block(-6,-2,1,SPRUCE_WOOD_STAIRS:7)
Block(-6,-1,-2,SPRUCE_WOOD_STAIRS:6)
Block(-6,-1,-1,WOOL)
Block(-6,-1,0,WOOL)
Block(-6,-1,1,WOOL)
Block(-6,-1,2,SPRUCE_WOOD_STAIRS:7)
Block(-6,0,-2,WOOD:1)
Block(-6,0,-1,WOOL)
Block(-6,0,0,WOOL)
Block(-6,0,1,WOOL)
Block(-6,0,2,WOOD)
Block(-6,1,-2,WOOD)
Block(-6,1,-1,WOOD_STEP:8)
Block(-6,1,0,WOOD_STEP:8)
Block(-6,1,1,WOOD_STEP:8)
Block(-6,1,2,WOOD:1)
Block(-6,2,-2,WOOD:1)
Block(-6,2,2,WOOD:1)
Block(-6,3,-2,FENCE)
Block(-6,3,2,FENCE)
Block(-5,-2,-1,SPRUCE_WOOD_STAIRS:6)
Block(-5,-2,0,WOOD)
Block(-5,-2,1,SPRUCE_WOOD_STAIRS:7)
Block(-5,-1,-2,SPRUCE_WOOD_STAIRS:6)
Block(-5,-1,-1,WOOL)
Block(-5,-1,0,WOOL)
Block(-5,-1,1,TNT)
Block(-5,-1,2,SPRUCE_WOOD_STAIRS:7)
Block(-5,0,-2,WOOD:1)
Block(-5,0,-1,WOOL)
Block(-5,0,0,WOOL)
Block(-5,0,1,WOOL)
Block(-5,0,2,WOOD:1)
Block(-5,1,-2,WOOD)
Block(-5,1,-1,WOOD_STEP)
Block(-5,1,0,WOOD_STEP)
Block(-5,1,1,WOOD_STEP)
Block(-5,1,2,WOOD)
Block(-4,-2,-1,SPRUCE_WOOD_STAIRS:6)
Block(-4,-2,0,WOOD)
Block(-4,-2,1,SPRUCE_WOOD_STAIRS:7)
Block(-4,-1,-2,SPRUCE_WOOD_STAIRS:6)
Block(-4,-1,-1,WOOL)
Block(-4,-1,0,WOOL)
Block(-4,-1,1,TNT)
Block(-4,-1,2,SPRUCE_WOOD_STAIRS:7)
Block(-4,0,-2,WOOD:1)
Block(-4,0,-1,WOOL)
Block(-4,0,0,WOOL)
Block(-4,0,1,WOOL)
Block(-4,0,2,WOOD:1)
Block(-4,1,-2,WOOD)
Block(-4,1,-1,WOOD_STEP)
Block(-4,1,0,WOOD_STEP)
Block(-4,1,1,WOOD_STEP)
Block(-4,1,2,WOOD)
Block(-4,12,0,WOOD:1)
Block(-4,13,0,FENCE)
Block(-3,-2,-1,SPRUCE_WOOD_STAIRS:6)
Block(-3,-2,0,WOOD)
Block(-3,-2,1,SPRUCE_WOOD_STAIRS:7)
Block(-3,-1,-2,SPRUCE_WOOD_STAIRS:6)
Block(-3,-1,-1,TRIPWIRE_HOOK:4)
Block(-3,-1,0,TRIPWIRE:4)
Block(-3,-1,1,TRIPWIRE_HOOK:6)
Block(-3,-1,2,SPRUCE_WOOD_STAIRS:7)
Block(-3,0,-2,WOOD:1)
Block(-3,0,-1,WOOL)
Block(-3,0,0,WOOL)
Block(-3,0,1,WOOL)
Block(-3,0,2,WOOD:1)
Block(-3,1,-2,WOOD)
Block(-3,1,-1,WOOD_STEP)
Block(-3,1,0,WOOD_STEP)
Block(-3,1,1,WOOD_STEP)
Block(-3,1,2,WOOD)
Block(-3,6,-2,WOOD:1)
Block(-3,6,-1,WOOD:1)
Block(-3,6,0,WOOD:1)
Block(-3,6,1,WOOD:1)
Block(-3,6,2,WOOD:1)
Block(-3,10,-4,WOOD:1)
Block(-3,10,-3,WOOD:1)
Block(-3,10,-2,WOOD:1)
Block(-3,10,-1,WOOD:1)
Block(-3,10,0,WOOD:1)
Block(-3,10,1,WOOD:1)
Block(-3,10,2,WOOD:1)
Block(-3,10,3,WOOD:1)
Block(-3,10,4,WOOD:1)
Block(-3,11,0,WOOD:1)
Block(-3,12,-1,WOOD:1)
Block(-3,12,0,WOOD)
Block(-3,12,1,WOOD:1)
Block(-3,13,-1,FENCE)
Block(-3,13,1,FENCE)
Block(-2,-2,-1,SPRUCE_WOOD_STAIRS:6)
Block(-2,-2,0,WOOD)
Block(-2,-2,1,SPRUCE_WOOD_STAIRS:7)
Block(-2,-1,-2,SPRUCE_WOOD_STAIRS:6)
Block(-2,-1,-1,WOOD)
Block(-2,-1,0,WOOL)
Block(-2,-1,1,WOOD)
Block(-2,-1,2,SPRUCE_WOOD_STAIRS:7)
Block(-2,0,-2,WOOD:1)
Block(-2,0,-1,WOOD:1)
Block(-2,0,0,WOOL)
Block(-2,0,1,WOOD:1)
Block(-2,0,2,WOOD:1)
Block(-2,1,-2,WOOD)
Block(-2,1,0,WOOD:1)
Block(-2,1,2,WOOD)
Block(-2,2,0,WOOD:1)
Block(-2,3,0,WOOD:1)
Block(-2,4,0,WOOD:1)
Block(-2,5,0,WOOD:1)
Block(-2,6,-3,WOOL:15)
Block(-2,6,-2,WOOL:15)
Block(-2,6,-1,WOOL:15)
Block(-2,6,0,WOOD:1)
Block(-2,6,1,WOOL:15)
Block(-2,6,2,WOOL:15)
Block(-2,6,3,WOOL:15)
Block(-2,7,0,WOOD:1)
Block(-2,8,0,WOOD:1)
Block(-2,9,0,WOOD:1)
Block(-2,10,-4,WOOL:15)
Block(-2,10,-3,WOOL:15)
Block(-2,10,-2,WOOL:15)
Block(-2,10,-1,WOOL:15)
Block(-2,10,0,WOOL:15)
Block(-2,10,1,WOOL:15)
Block(-2,10,2,WOOL:15)
Block(-2,10,3,WOOL:15)
Block(-2,10,4,WOOL:15)
Block(-2,11,-3,WOOL:15)
Block(-2,11,-2,WOOL:15)
Block(-2,11,-1,WOOL:14)
Block(-2,11,0,WOOL:14)
Block(-2,11,1,WOOL:14)
Block(-2,11,2,WOOL:15)
Block(-2,11,3,WOOL:15)
Block(-2,12,0,WOOD:1)
Block(-2,13,0,FENCE)
Block(-1,-2,0,WOOD)
Block(-1,-1,-1,SPRUCE_WOOD_STAIRS:6)
Block(-1,-1,0,WOOL)
Block(-1,-1,1,SPRUCE_WOOD_STAIRS:7)
Block(-1,0,-2,SPRUCE_WOOD_STAIRS:6)
Block(-1,0,-1,WOOD:1)
Block(-1,0,0,TRAP_DOOR:8)
Block(-1,0,1,WOOD:1)
Block(-1,0,2,SPRUCE_WOOD_STAIRS:7)
Block(-1,1,-2,WOOD:1)
Block(-1,1,2,WOOD:1)
Block(-1,7,-4,WOOL:15)
Block(-1,7,-3,WOOL:15)
Block(-1,7,-2,WOOL:15)
Block(-1,7,-1,WOOL:14)
Block(-1,7,0,WOOL:14)
Block(-1,7,1,WOOL:14)
Block(-1,7,2,WOOL:15)
Block(-1,7,3,WOOL:15)
Block(-1,7,4,WOOL:15)
Block(-1,10,-4,WOOL:15)
Block(-1,10,-3,WOOL:15)
Block(-1,10,-2,WOOL:14)
Block(-1,10,-1,WOOL:15)
Block(-1,10,0,WOOL:14)
Block(-1,10,1,WOOL:15)
Block(-1,10,2,WOOL:14)
Block(-1,10,3,WOOL:15)
Block(-1,10,4,WOOL:15)
Block(0,-2,0,WOOD)
Block(0,-1,-1,SPRUCE_WOOD_STAIRS:6)
Block(0,-1,0,WOOD)
Block(0,-1,1,SPRUCE_WOOD_STAIRS:7)
Block(0,0,-2,SPRUCE_WOOD_STAIRS:6)
Block(0,0,-1,WOOD)
Block(0,0,0,WOOD:1)
Block(0,0,1,WOOD:1)
Block(0,0,2,SPRUCE_WOOD_STAIRS:7)
Block(0,1,-2,WOOD:1)
Block(0,1,2,WOOD)
Block(0,8,-4,WOOL:15)
Block(0,8,-3,WOOL:15)
Block(0,8,-2,WOOL:14)
Block(0,8,-1,WOOL:15)
Block(0,8,0,WOOL:14)
Block(0,8,1,WOOL:15)
Block(0,8,2,WOOL:14)
Block(0,8,3,WOOL:15)
Block(0,8,4,WOOL:15)
Block(0,9,-4,WOOL:15)
Block(0,9,-3,WOOL:14)
Block(0,9,-2,WOOL:14)
Block(0,9,-1,WOOL:14)
Block(0,9,0,WOOL:14)
Block(0,9,1,WOOL:14)
Block(0,9,2,WOOL:14)
Block(0,9,3,WOOL:14)
Block(0,9,4,WOOL:15)
Block(1,-2,0,WOOD)
Block(1,-1,-1,SPRUCE_WOOD_STAIRS:6)
Block(1,-1,0,WOOD)
Block(1,-1,1,SPRUCE_WOOD_STAIRS:7)
Block(1,0,-2,SPRUCE_WOOD_STAIRS:6)
Block(1,0,-1,WOOD:1)
Block(1,0,0,WOOD:1)
Block(1,0,1,WOOD)
Block(1,0,2,SPRUCE_WOOD_STAIRS:7)
Block(1,1,-2,WOOD)
Block(1,1,2,WOOD)
Block(2,-2,0,WOOD)
Block(2,-1,-1,SPRUCE_WOOD_STAIRS:6)
Block(2,-1,0,WOOD)
Block(2,-1,1,SPRUCE_WOOD_STAIRS:7)
Block(2,0,-2,SPRUCE_WOOD_STAIRS:6)
Block(2,0,-1,WOOD:1)
Block(2,0,0,WOOD:1)
Block(2,0,1,WOOD)
Block(2,0,2,SPRUCE_WOOD_STAIRS:7)
Block(2,1,-2,WOOD)
Block(2,1,2,WOOD)
Block(2,2,-2,WOOD_STEP)
Block(2,2,2,WOOD_STEP)
Block(3,-2,0,WOOD:1)
Block(3,-1,-1,SPRUCE_WOOD_STAIRS:6)
Block(3,-1,0,WOOD)
Block(3,-1,1,SPRUCE_WOOD_STAIRS:7)
Block(3,0,-2,SPRUCE_WOOD_STAIRS:6)
Block(3,0,-1,WOOD)
Block(3,0,0,WOOD:1)
Block(3,0,1,WOOD:1)
Block(3,0,2,SPRUCE_WOOD_STAIRS:7)
Block(3,1,-2,WOOD)
Block(3,1,2,WOOD)
Block(3,2,-2,WOOD_STEP)
Block(3,2,2,WOOD_STEP)
Block(4,-2,0,WOOD:1)
Block(4,-1,-1,SPRUCE_WOOD_STAIRS:6)
Block(4,-1,0,WOOD:1)
Block(4,-1,1,SPRUCE_WOOD_STAIRS:7)
Block(4,0,-2,SPRUCE_WOOD_STAIRS:6)
Block(4,0,-1,WOOD)
Block(4,0,0,WOOD:1)
Block(4,0,1,WOOD:2)
Block(4,0,2,SPRUCE_WOOD_STAIRS:7)
Block(4,1,-2,WOOD:1)
Block(4,1,2,WOOD:1)
Block(4,2,-2,WOOD_STEP)
Block(4,2,2,WOOD_STEP)
Block(5,-2,0,WOOD:1)
Block(5,-1,-1,SPRUCE_WOOD_STAIRS:6)
Block(5,-1,0,WOOD:1)
Block(5,-1,1,SPRUCE_WOOD_STAIRS:7)
Block(5,0,-2,SPRUCE_WOOD_STAIRS:6)
Block(5,0,-1,WOOD)
Block(5,0,0,WOOD:1)
Block(5,0,1,WOOD:1)
Block(5,0,2,SPRUCE_WOOD_STAIRS:7)
Block(5,1,-2,WOOD:1)
Block(5,1,-1,FENCE)
Block(5,1,0,WOOD_STEP:1)
Block(5,1,1,FENCE)
Block(5,1,2,WOOD:1)
Block(5,2,-2,WOOD_STEP)
Block(5,2,-1,FENCE)
Block(5,2,1,FENCE)
Block(5,2,2,WOOD_STEP)
Block(6,-1,0,WOOD_STAIRS:5)
Block(6,0,-1,WOOD:1)
Block(6,0,0,WOOD)
Block(6,0,1,WOOD)
Block(6,1,-1,WOOD:1)
Block(6,1,0,WOOD:1)
Block(6,1,1,WOOD)
Block(6,2,-1,WOOD_STEP)
Block(6,2,1,WOOD_STEP)
Block(7,0,0,WOOD_STAIRS:5)
Block(7,1,0,WOOD:1)
Block(7,2,0,WOOD_STEP)
Block(8,1,0,WOOD_STAIRS:5)
Block(8,2,0,WOOD:2)
Block(8,3,0,WOOD:1)
Block(8,4,0,WOOD_STEP)
Block(9,3,0,WOOD_STEP:8)
Block(9,4,0,WOOD_STAIRS:1)

#######################################################################
# +-----------------------------------------------------------------+ #
# |                            BO3 checks                           | #
# +-----------------------------------------------------------------+ #
#######################################################################

# Require a condition at a certain location in order for the BO3 to be spawned.
# BlockCheck(x,y,z,BlockName[,BlockName[,...]]) - one of the blocks must be at the location
# BlockCheckNot(x,y,z,BlockName[,BlockName[,...]]) - all the blocks must not be at the location
# LightCheck(x,y,z,minLightLevel,maxLightLevel) - light must be between min and max (inclusive)

# You can use "Solid" as a BlockName for matching all solid blocks or "All" to match all blocks that aren't air.

# Examples:
#   BlockCheck(0,-1,0,GRASS,DIRT)  Require grass or dirt just below the object
#   BlockCheck(0,-1,0,Solid)       Require any solid block just below the object
#   BlockCheck(0,-1,0,WOOL)        Require any type of wool just below the object
#   BlockCheck(0,-1,0,WOOL:0)      Require white wool just below the object
#   BlockCheckNot(0,0,0,WOOL:0)   Require that there is no white wool below the object
#   LightCheck(0,0,0,0,1)          Require almost complete darkness just below the object
BlockCheck(0,-1,0,WATER)
#######################################################################
# +-----------------------------------------------------------------+ #
# |                             Branches                            | #
# +-----------------------------------------------------------------+ #
#######################################################################

# Branches are objects that will spawn when this object spawns when it is used in
# the CustomStructure resource. Branches can also have branches, making complex
# structures possible. See the wiki for more details.

# Regular Branches spawn each branch with an independent chance of spawning.
# Branch(x,y,z,branchName,rotation,chance[,anotherBranchName,rotation,chance[,...]][IndividualChance])
# branchName - name of the object to spawn.
# rotation - NORTH, SOUTH, EAST or WEST.
# IndividualChance - The chance each branch has to spawn, assumed to be 100 when left blank

# Weighted Branches spawn branches with a dependent chance of spawning.
# WeightedBranch(x,y,z,branchName,rotation,chance[,anotherBranchName,rotation,chance[,...]][MaxChanceOutOf])
# MaxChanceOutOf - The chance all branches have to spawn out of, assumed to be 100 when left blank
