
#######################################################################
# +-----------------------------------------------------------------+ #
# |                            BO3 object                           | #
# +-----------------------------------------------------------------+ #
#######################################################################

Author: MC_Pitman

Description: No description given

Version: 3

SettingsMode: WriteWithoutComments


#######################################################################
# +-----------------------------------------------------------------+ #
# |                          Main settings                          | #
# +-----------------------------------------------------------------+ #
#######################################################################

Tree: true

Frequency: 1

Rarity: 20.0

RotateRandomly: true

SpawnHeight: highestSolidBlock

SpawnHeightOffset: 0

SpawnHeightVariance: 0

##############################
# Height Limits for the BO3. #
##############################

MinHeight: 62

MaxHeight: 256

######################
# Extrusion settings #
######################

ExtrudeMode: None

ExtrudeThroughBlocks: AIR

MaxBranchDepth: 10

ExcludedBiomes: All


#######################################################################
# +-----------------------------------------------------------------+ #
# |                      Source block settings                      | #
# +-----------------------------------------------------------------+ #
#######################################################################

SourceBlocks: STONE:1,STONE:3,STONE:5,DIRT:1,DIRT,SAND,GRASS,DIRT:2,STATIONARY_WATER,HARD_CLAY,STAINED_CLAY,CLAY,SANDSTONE,SAND:1,AIR,STONE,GRAVEL,LONG_GRASS,LONG_GRASS:1,LONG_GRASS:2,DEAD_BUSH,YELLOW_FLOWER,RED_ROSE,BROWN_MUSHROOM,RED_MUSHROOM

MaxPercentageOutsideSourceBlock: 0

OutsideSourceBlock: placeAnyway

IsOTGPlus: false

InheritBO3: 

InheritBO3Rotation: NORTH

OverrideChildSettings: true

OverrideParentHeight: false

CanOverride: false

BranchFrequency: 0

BranchFrequencyGroup: 

MustBeBelowOther: false

MustBeInside: 

CannotBeInside: 

ReplacesBO3: 

CanSpawnOnWater: true

SpawnOnWaterOnly: false

SpawnUnderWater: false

SpawnAtWaterLevel: false

HeightOffset: 0

RemoveAir: true

ReplaceAbove: 

ReplaceBelow: 

ReplaceWithBiomeBlocks: true

ReplaceWithGroundBlock: DIRT

ReplaceWithSurfaceBlock: GRASS

SmoothRadius: 0

SmoothHeightOffset: 0

SmoothStartTop: false

SmoothStartWood: false

SmoothingSurfaceBlock: 

SmoothingGroundBlock: 

BO3Group: 

IsSpawnPoint: false


#######################################################################
# +-----------------------------------------------------------------+ #
# |                              Blocks                             | #
# +-----------------------------------------------------------------+ #
#######################################################################

Block(-4,16,0,LEAVES:3)
Block(-4,16,1,LEAVES:3)
Block(-3,3,2,VINE:8)
Block(-3,4,1,VINE:8)
Block(-3,4,2,VINE:8)
Block(-3,5,1,VINE:8)
Block(-3,5,2,VINE:8)
Block(-3,12,0,VINE:8)
Block(-3,16,-1,LEAVES:3)
Block(-3,16,0,LEAVES:3)
Block(-3,16,1,LEAVES:3)
Block(-3,16,2,LEAVES:3)
Block(-3,17,0,LEAVES:3)
Block(-3,17,1,LEAVES:3)
Block(-2,5,1,LEAVES:3)
Block(-2,5,2,LEAVES:3)
Block(-2,5,3,LEAVES:3)
Block(-2,5,4,VINE:4)
Block(-2,6,2,LEAVES:3)
Block(-2,6,3,VINE:8)
Block(-2,11,1,VINE:8)
Block(-2,12,-1,HUGE_MUSHROOM_2:1)
Block(-2,12,0,HUGE_MUSHROOM_2:7)
Block(-2,12,1,VINE:8)
Block(-2,13,0,VINE:8)
Block(-2,16,-2,LEAVES:3)
Block(-2,16,-1,LEAVES:3)
Block(-2,16,0,LEAVES:3)
Block(-2,16,1,LEAVES:3)
Block(-2,16,2,LEAVES:3)
Block(-2,16,3,LEAVES:3)
Block(-2,16,4,LEAVES:3)
Block(-2,17,-1,LEAVES:3)
Block(-2,17,0,LEAVES:3)
Block(-2,17,1,LEAVES:3)
Block(-2,17,2,LEAVES:3)
Block(-2,18,1,LEAVES:3)
Block(-1,2,0,VINE:8)
Block(-1,2,1,VINE:8)
Block(-1,3,0,VINE:8)
Block(-1,3,1,VINE:8)
Block(-1,4,0,VINE:8)
Block(-1,4,1,VINE:8)
Block(-1,5,0,LEAVES:3)
Block(-1,5,1,LEAVES:3)
Block(-1,5,2,LOG:3)
Block(-1,5,3,LEAVES:3)
Block(-1,5,4,VINE:4)
Block(-1,6,0,VINE:8)
Block(-1,6,1,LEAVES:3)
Block(-1,6,2,LEAVES:3)
Block(-1,6,3,LEAVES:3)
Block(-1,6,4,VINE:4)
Block(-1,7,0,VINE:8)
Block(-1,7,1,VINE:8)
Block(-1,8,0,VINE:8)
Block(-1,8,1,VINE:8)
Block(-1,9,0,VINE:8)
Block(-1,9,1,VINE:8)
Block(-1,10,0,VINE:8)
Block(-1,10,1,VINE:8)
Block(-1,11,0,VINE:8)
Block(-1,11,1,VINE:8)
Block(-1,12,-2,HUGE_MUSHROOM_2:1)
Block(-1,12,-1,HUGE_MUSHROOM_2)
Block(-1,12,0,HUGE_MUSHROOM_2)
Block(-1,12,1,HUGE_MUSHROOM_2:7)
Block(-1,13,-1,HUGE_MUSHROOM_2:1)
Block(-1,13,0,HUGE_MUSHROOM_2:7)
Block(-1,13,1,VINE:8)
Block(-1,14,0,VINE:8)
Block(-1,14,1,VINE:8)
Block(-1,15,0,VINE:8)
Block(-1,15,1,VINE:8)
Block(-1,16,-3,LEAVES:3)
Block(-1,16,-2,LEAVES:3)
Block(-1,16,-1,LEAVES:3)
Block(-1,16,0,LEAVES:3)
Block(-1,16,1,LEAVES:3)
Block(-1,16,2,LEAVES:3)
Block(-1,16,3,LEAVES:3)
Block(-1,16,4,LEAVES:3)
Block(-1,16,5,LEAVES:3)
Block(-1,17,-2,LEAVES:3)
Block(-1,17,-1,LEAVES:3)
Block(-1,17,0,LEAVES:3)
Block(-1,17,1,LEAVES:3)
Block(-1,17,2,LEAVES:3)
Block(-1,17,3,LEAVES:3)
Block(-1,18,0,LEAVES:3)
Block(-1,18,1,LEAVES:3)
Block(-1,18,2,LEAVES:3)
Block(0,-2,0,LOG:3)
Block(0,-2,1,LOG:3)
Block(0,-1,0,LOG:3)
Block(0,-1,1,LOG:3)
Block(0,0,0,LOG:3)
Block(0,0,1,LOG:3)
Block(0,1,0,LOG:3)
Block(0,1,1,LOG:3)
Block(0,2,-1,VINE:1)
Block(0,2,0,LOG:3)
Block(0,2,1,LOG:3)
Block(0,2,2,VINE:4)
Block(0,3,-1,VINE:1)
Block(0,3,0,LOG:3)
Block(0,3,1,LOG:3)
Block(0,3,2,VINE:4)
Block(0,4,-1,VINE:1)
Block(0,4,0,LOG:3)
Block(0,4,1,LOG:3)
Block(0,5,-1,VINE:1)
Block(0,5,0,LOG:3)
Block(0,5,1,LOG:3)
Block(0,5,2,LEAVES:3)
Block(0,5,3,LEAVES:3)
Block(0,6,-1,VINE:1)
Block(0,6,0,LOG:3)
Block(0,6,1,LOG:3)
Block(0,6,2,LEAVES:3)
Block(0,7,-1,VINE:1)
Block(0,7,0,LOG:3)
Block(0,7,1,LOG:3)
Block(0,7,2,VINE:4)
Block(0,8,-1,VINE:1)
Block(0,8,0,LOG:3)
Block(0,8,1,LOG:3)
Block(0,8,2,VINE:4)
Block(0,9,-1,VINE:1)
Block(0,9,0,LOG:3)
Block(0,9,1,LOG:3)
Block(0,9,2,VINE:4)
Block(0,10,-1,VINE:1)
Block(0,10,0,LOG:3)
Block(0,10,1,LOG:3)
Block(0,10,2,VINE:4)
Block(0,11,-1,VINE:1)
Block(0,11,0,LOG:3)
Block(0,11,1,LOG:3)
Block(0,11,2,VINE:4)
Block(0,12,-2,HUGE_MUSHROOM_2:3)
Block(0,12,-1,HUGE_MUSHROOM_2)
Block(0,12,0,LOG:3)
Block(0,12,1,LOG:3)
Block(0,12,2,VINE:4)
Block(0,13,-1,HUGE_MUSHROOM_2:3)
Block(0,13,0,LOG:3)
Block(0,13,1,LOG:3)
Block(0,13,2,VINE:4)
Block(0,14,-1,VINE:1)
Block(0,14,0,LOG:3)
Block(0,14,1,LOG:3)
Block(0,14,2,LEAVES:3)
Block(0,15,-1,VINE:1)
Block(0,15,0,LOG:3)
Block(0,15,1,LOG:3)
Block(0,16,-4,LEAVES:3)
Block(0,16,-3,LEAVES:3)
Block(0,16,-2,LEAVES:3)
Block(0,16,-1,LEAVES:3)
Block(0,16,0,LEAVES:3)
Block(0,16,1,LEAVES:3)
Block(0,16,2,LEAVES:3)
Block(0,16,3,LEAVES:3)
Block(0,16,4,LEAVES:3)
Block(0,16,5,LEAVES:3)
Block(0,17,-3,LEAVES:3)
Block(0,17,-2,LEAVES:3)
Block(0,17,-1,LEAVES:3)
Block(0,17,0,LEAVES:3)
Block(0,17,1,LEAVES:3)
Block(0,17,2,LEAVES:3)
Block(0,17,3,LEAVES:3)
Block(0,17,4,LEAVES:3)
Block(0,18,-1,LEAVES:3)
Block(0,18,0,LEAVES:3)
Block(0,18,1,LEAVES:3)
Block(0,18,2,LEAVES:3)
Block(0,18,3,LEAVES:3)
Block(1,-2,0,LOG:3)
Block(1,-2,1,LOG:3)
Block(1,-1,0,LOG:3)
Block(1,-1,1,LOG:3)
Block(1,0,0,LOG:3)
Block(1,0,1,LOG:3)
Block(1,1,0,LOG:3)
Block(1,1,1,LOG:3)
Block(1,2,-1,VINE:1)
Block(1,2,0,LOG:3)
Block(1,2,1,LOG:3)
Block(1,2,2,VINE:4)
Block(1,3,-1,VINE:1)
Block(1,3,0,LOG:3)
Block(1,3,1,LOG:3)
Block(1,3,2,VINE:4)
Block(1,4,-2,VINE:1)
Block(1,4,-1,VINE:1)
Block(1,4,0,LOG:3)
Block(1,4,1,LOG:3)
Block(1,4,2,VINE:4)
Block(1,5,-2,VINE:1)
Block(1,5,-1,VINE:1)
Block(1,5,0,LOG:3)
Block(1,5,1,LOG:3)
Block(1,5,2,LEAVES:3)
Block(1,6,-2,VINE:1)
Block(1,6,-1,HUGE_MUSHROOM_2:1)
Block(1,6,0,LOG:3)
Block(1,6,1,LOG:3)
Block(1,6,2,VINE:4)
Block(1,7,-1,VINE:1)
Block(1,7,0,LOG:3)
Block(1,7,1,LOG:3)
Block(1,7,2,VINE:4)
Block(1,8,-1,VINE:1)
Block(1,8,0,LOG:3)
Block(1,8,1,LOG:3)
Block(1,8,2,VINE:4)
Block(1,9,-1,VINE:1)
Block(1,9,0,LOG:3)
Block(1,9,1,LOG:3)
Block(1,9,2,VINE:4)
Block(1,10,-1,VINE:1)
Block(1,10,0,LOG:3)
Block(1,10,1,LOG:3)
Block(1,10,2,VINE:4)
Block(1,11,-2,VINE:1)
Block(1,11,-1,VINE:1)
Block(1,11,0,LOG:3)
Block(1,11,1,LOG:3)
Block(1,11,2,VINE:4)
Block(1,12,-2,VINE:1)
Block(1,12,-1,HUGE_MUSHROOM_2:3)
Block(1,12,0,LOG:3)
Block(1,12,1,LOG:3)
Block(1,12,2,VINE:4)
Block(1,13,-1,VINE:1)
Block(1,13,0,LOG:3)
Block(1,13,1,LOG:3)
Block(1,13,2,VINE:4)
Block(1,14,-1,VINE:1)
Block(1,14,0,LOG:3)
Block(1,14,1,LOG:3)
Block(1,14,2,LEAVES:3)
Block(1,14,3,LEAVES:3)
Block(1,15,-1,VINE:1)
Block(1,15,0,LOG:3)
Block(1,15,1,LOG:3)
Block(1,15,2,LEAVES:3)
Block(1,16,-4,LEAVES:3)
Block(1,16,-3,LEAVES:3)
Block(1,16,-2,LEAVES:3)
Block(1,16,-1,LEAVES:3)
Block(1,16,0,LEAVES:3)
Block(1,16,1,LEAVES:3)
Block(1,16,2,LEAVES:3)
Block(1,16,3,LEAVES:3)
Block(1,16,4,LEAVES:3)
Block(1,16,5,LEAVES:3)
Block(1,17,-2,LEAVES:3)
Block(1,17,-1,LEAVES:3)
Block(1,17,0,LEAVES:3)
Block(1,17,1,LEAVES:3)
Block(1,17,2,LEAVES:3)
Block(1,17,3,LEAVES:3)
Block(1,18,-1,LEAVES:3)
Block(1,18,0,LEAVES:3)
Block(1,18,1,LEAVES:3)
Block(1,18,2,LEAVES:3)
Block(2,2,0,VINE:2)
Block(2,2,1,VINE:2)
Block(2,3,0,VINE:2)
Block(2,3,1,VINE:2)
Block(2,4,0,VINE:2)
Block(2,4,1,VINE:2)
Block(2,5,0,VINE:2)
Block(2,5,1,VINE:2)
Block(2,6,-1,HUGE_MUSHROOM_2:3)
Block(2,6,0,HUGE_MUSHROOM_2:9)
Block(2,6,1,VINE:2)
Block(2,7,0,VINE:2)
Block(2,7,1,VINE:2)
Block(2,8,0,VINE:2)
Block(2,8,1,VINE:2)
Block(2,9,0,VINE:2)
Block(2,9,1,VINE:2)
Block(2,10,0,VINE:2)
Block(2,10,1,VINE:2)
Block(2,11,0,VINE:2)
Block(2,11,1,VINE:2)
Block(2,12,0,VINE:2)
Block(2,12,1,VINE:2)
Block(2,13,0,VINE:2)
Block(2,13,1,VINE:2)
Block(2,14,0,LEAVES:3)
Block(2,14,1,LEAVES:3)
Block(2,14,2,LOG:3)
Block(2,14,3,LEAVES:3)
Block(2,14,4,LEAVES:3)
Block(2,15,1,LEAVES:3)
Block(2,15,2,LEAVES:3)
Block(2,16,-3,LEAVES:3)
Block(2,16,-2,LEAVES:3)
Block(2,16,-1,LEAVES:3)
Block(2,16,0,LEAVES:3)
Block(2,16,1,LEAVES:3)
Block(2,16,2,LEAVES:3)
Block(2,16,3,LEAVES:3)
Block(2,16,4,LEAVES:3)
Block(2,17,-1,LEAVES:3)
Block(2,17,0,LEAVES:3)
Block(2,17,1,LEAVES:3)
Block(2,17,2,LEAVES:3)
Block(2,18,0,LEAVES:3)
Block(2,18,1,LEAVES:3)
Block(3,14,1,LEAVES:3)
Block(3,14,2,LEAVES:3)
Block(3,14,3,LEAVES:3)
Block(3,16,-3,VINE:2)
Block(3,16,-2,LEAVES:3)
Block(3,16,-1,LEAVES:3)
Block(3,16,0,LEAVES:3)
Block(3,16,1,LEAVES:3)
Block(3,16,2,LEAVES:3)
Block(3,16,3,LEAVES:3)
Block(3,17,0,LEAVES:3)
Block(3,17,1,LEAVES:3)
Block(4,14,2,LEAVES:3)
Block(4,16,-2,VINE:2)
Block(4,16,-1,LEAVES:3)
Block(4,16,0,LEAVES:3)
Block(4,16,1,LEAVES:3)
Block(4,16,2,LEAVES:3)
Block(5,16,0,LEAVES:3)
Block(5,16,1,LEAVES:3)

#######################################################################
# +-----------------------------------------------------------------+ #
# |                            BO3 checks                           | #
# +-----------------------------------------------------------------+ #
#######################################################################

BlockCheck(0,-1,0,GRASS,DIRT,DIRT:2,HARD_CLAY,STAINED_CLAY,CLAY,SANDSTONE,SAND:1,SAND)

#######################################################################
# +-----------------------------------------------------------------+ #
# |                             Branches                            | #
# +-----------------------------------------------------------------+ #
#######################################################################


#######################################################################
# +-----------------------------------------------------------------+ #
# |                             Entities                            | #
# +-----------------------------------------------------------------+ #
#######################################################################


#######################################################################
# +-----------------------------------------------------------------+ #
# |                            Particles                            | #
# +-----------------------------------------------------------------+ #
#######################################################################


#######################################################################
# +-----------------------------------------------------------------+ #
# |                             Spawners                            | #
# +-----------------------------------------------------------------+ #
#######################################################################


#######################################################################
# +-----------------------------------------------------------------+ #
# |                             ModData                             | #
# +-----------------------------------------------------------------+ #
#######################################################################

