
#######################################################################
# +-----------------------------------------------------------------+ #
# |                            BO3 object                           | #
# +-----------------------------------------------------------------+ #
#######################################################################

# This is the config file of a custom object.
# If you add this object correctly to your BiomeConfigs, it will spawn in the world.

# This is the creator of this BO3 object
Author: LordSmellyPants

# A short description of this BO3 object
Description: No description given

# The BO3 version, don't change this! It can be used by external applications to do a version check.
Version: 3

# The settings mode, WriteAll, WriteWithoutComments or WriteDisable. See WorldConfig.
SettingsMode: WriteDisable


#######################################################################
# +-----------------------------------------------------------------+ #
# |                          Main settings                          | #
# +-----------------------------------------------------------------+ #
#######################################################################

# This needs to be set to true to spawn the object in the Tree and Sapling resources.
Tree: true

# The frequency of the BO3 from 1 to 200. Tries this many times to spawn this BO3 when using the CustomObject(...) resource.
# Ignored by Tree(..), Sapling(..) and CustomStructure(..)
Frequency: 1

# The rarity of the BO3 from 0 to 100. Each spawn attempt has rarity% chance to succeed when using the CustomObject(...) resource.
# Ignored by Tree(..), Sapling(..) and CustomStructure(..)
Rarity: 100.0

# If you set this to true, the BO3 will be placed with a random rotation.
RotateRandomly: false

# The spawn height of the BO3 - atMinY, randomY, highestBlock or highestSolidBlock.
SpawnHeight: randomY

# The offset from the spawn height to spawn this BO3
# Ex. SpawnHeight = highestSolidBlock, SpawnHeightOffset = 3; This object will spawn 3 blocks above the highest solid block
SpawnHeightOffset: 0

# A random amount to offset the spawn location from the spawn offset height
# Ex. SpawnHeightOffset = 3, SpawnHeightVariance = 3; This object will spawn 3 to 6 blocks above the original spot it would have spawned
SpawnHeightVariance: 0

##############################
# Height Limits for the BO3. #
##############################

# When in randomY mode used as the minimum Y or in atMinY mode as the actual Y to spawn this BO3 at.
MinHeight: 0

# When in randomY mode used as the maximum Y to spawn this BO3 at.
MaxHeight: 256

######################
# Extrusion settings #
######################

# The style of extrusion you wish to use - BottomDown, TopUp, None (Default)
ExtrudeMode: None

# The blocks to extrude your BO3 through
ExtrudeThroughBlocks: AIR

# Objects can have other objects attacthed to it: branches. Branches can also
# have branches attached to it, which can also have branches, etc. This is the
# maximum branch depth for this objects.
MaxBranchDepth: 10

# When spawned with the UseWorld keyword, this BO3 should NOT spawn in the following biomes.
# If you write the BO3 name directly in the BiomeConfigs, this will be ignored.
ExcludedBiomes: All


#######################################################################
# +-----------------------------------------------------------------+ #
# |                      Source block settings                      | #
# +-----------------------------------------------------------------+ #
#######################################################################

# The B(s) the BO3 should spawn in.
SourceBlocks: AIR

# The maximum percentage of the BO3 that can be outside the SourceBlock.
# The BO3 won't be placed on a location with more blocks outside the SourceBlock than this percentage.
MaxPercentageOutsideSourceBlock: 100

# What to do when a block is about to be placed outside the SourceBlock? (dontPlace, placeAnyway)
OutsideSourceBlock: placeAnyway


#######################################################################
# +-----------------------------------------------------------------+ #
# |                              Blocks                             | #
# +-----------------------------------------------------------------+ #
#######################################################################

# All the blocks used in the BO3 are listed here. Possible blocks:
# B(x,y,z,id[.data][,nbtfile.nbt)
# RB(x,y,z,id[:data][,nbtfile.nbt],chance[,id[:data][,nbtfile.nbt],chance[,...]])
#  So RB(0,0,0,CHEST,chest.nbt,50,CHEST,anotherchest.nbt,100) will spawn a chest at
#  the BO3 origin, and give it a 50% chance to have the contents of chest.nbt, or, if that
#  fails, a 100% percent chance to have the contents of anotherchest.nbt.
# MinecraftObject(x,y,z,name)
#  Spawns an object in the Mojang NBT structure format. For example, 
#  MinecraftObject(0,0,0,minecraft:igloo/igloo_bottom)
#  spawns the bottom part of an igloo.
B(-8,6,-9,LEAVES:3)
B(-8,7,-9,LEAVES:3)
B(-8,8,-9,LEAVES:3)
B(-8,9,-10,COBBLESTONE_STAIRS:6)
B(-8,9,-8,COBBLESTONE_STAIRS:4)
B(-8,9,-7,COBBLESTONE_STAIRS:4)
B(-8,9,10,COBBLESTONE_STAIRS:4)
B(-8,9,11,COBBLESTONE_STAIRS:4)
B(-8,10,-10,DOUBLE_STEP:5)
B(-8,10,-9,STEP:5)
B(-8,10,-8,DOUBLE_STEP:5)
B(-8,10,-7,DOUBLE_STEP:5)
B(-8,10,8,STEP:5)
B(-8,10,9,STEP:5)
B(-8,10,10,DOUBLE_STEP:5)
B(-8,10,11,STEP:5)
B(-8,11,-8,DOUBLE_STEP:5)
B(-7,-16,-9,COBBLESTONE)
B(-7,-16,-5,COBBLESTONE)
B(-7,-16,-2,COBBLESTONE)
B(-7,-16,2,COBBLESTONE)
B(-7,-16,5,COBBLESTONE)
B(-7,-16,10,COBBLESTONE)
B(-7,-15,-9,COBBLESTONE)
B(-7,-15,-5,COBBLESTONE)
B(-7,-15,-2,COBBLESTONE)
B(-7,-15,2,COBBLESTONE)
B(-7,-15,5,COBBLESTONE)
B(-7,-15,10,COBBLESTONE)
B(-7,-14,-9,COBBLESTONE)
B(-7,-14,-5,COBBLESTONE)
B(-7,-14,-2,COBBLESTONE)
B(-7,-14,2,COBBLESTONE)
B(-7,-14,5,COBBLESTONE)
B(-7,-14,10,COBBLESTONE)
B(-7,-13,-9,COBBLESTONE)
B(-7,-13,-5,COBBLESTONE)
B(-7,-13,-2,COBBLESTONE)
B(-7,-13,2,COBBLESTONE)
B(-7,-13,5,COBBLESTONE)
B(-7,-13,10,COBBLESTONE)
B(-7,-12,-9,COBBLESTONE)
B(-7,-12,-5,COBBLESTONE)
B(-7,-12,-2,COBBLESTONE)
B(-7,-12,2,COBBLESTONE)
B(-7,-12,5,COBBLESTONE)
B(-7,-12,10,COBBLESTONE)
B(-7,-11,-9,COBBLESTONE)
B(-7,-11,-5,COBBLESTONE)
B(-7,-11,-2,COBBLESTONE)
B(-7,-11,2,COBBLESTONE)
B(-7,-11,5,COBBLESTONE)
B(-7,-11,10,COBBLESTONE)
B(-7,-10,-9,COBBLESTONE)
B(-7,-10,-5,COBBLESTONE)
B(-7,-10,-2,COBBLESTONE)
B(-7,-10,2,COBBLESTONE)
B(-7,-10,5,COBBLESTONE)
B(-7,-10,10,COBBLESTONE)
B(-7,-9,-9,COBBLESTONE)
B(-7,-9,-5,COBBLESTONE)
B(-7,-9,-2,COBBLESTONE)
B(-7,-9,2,COBBLESTONE)
B(-7,-9,5,COBBLESTONE)
B(-7,-9,10,COBBLESTONE)
B(-7,-8,-9,COBBLESTONE)
B(-7,-8,-5,COBBLESTONE)
B(-7,-8,-2,COBBLESTONE)
B(-7,-8,2,COBBLESTONE)
B(-7,-8,5,COBBLESTONE)
B(-7,-8,10,COBBLESTONE)
B(-7,-7,-9,COBBLESTONE)
B(-7,-7,-5,COBBLESTONE)
B(-7,-7,-2,COBBLESTONE)
B(-7,-7,2,COBBLESTONE)
B(-7,-7,5,COBBLESTONE)
B(-7,-7,10,COBBLESTONE)
B(-7,-6,-9,COBBLESTONE)
B(-7,-6,-5,COBBLESTONE)
B(-7,-6,-2,COBBLESTONE)
B(-7,-6,2,COBBLESTONE)
B(-7,-6,5,COBBLESTONE)
B(-7,-6,10,COBBLESTONE)
B(-7,-5,-9,COBBLESTONE)
B(-7,-5,-5,COBBLESTONE)
B(-7,-5,-2,COBBLESTONE)
B(-7,-5,2,COBBLESTONE)
B(-7,-5,5,COBBLESTONE)
B(-7,-5,10,COBBLESTONE)
B(-7,-4,-9,COBBLESTONE)
B(-7,-4,-5,COBBLESTONE)
B(-7,-4,-2,COBBLESTONE)
B(-7,-4,2,COBBLESTONE)
B(-7,-4,5,COBBLESTONE)
B(-7,-4,10,COBBLESTONE)
B(-7,-3,-9,COBBLESTONE)
B(-7,-3,-5,COBBLESTONE)
B(-7,-3,-2,COBBLESTONE)
B(-7,-3,2,COBBLESTONE)
B(-7,-3,5,COBBLESTONE)
B(-7,-3,10,COBBLESTONE)
B(-7,-2,-9,COBBLESTONE)
B(-7,-2,-8,COBBLESTONE)
B(-7,-2,-7,COBBLESTONE)
B(-7,-2,-6,COBBLESTONE)
B(-7,-2,-5,COBBLESTONE)
B(-7,-2,-4,COBBLESTONE)
B(-7,-2,-3,COBBLESTONE)
B(-7,-2,-2,COBBLESTONE)
B(-7,-2,-1,COBBLESTONE)
B(-7,-2,0,COBBLESTONE)
B(-7,-2,1,COBBLESTONE)
B(-7,-2,2,COBBLESTONE)
B(-7,-2,3,COBBLESTONE)
B(-7,-2,4,COBBLESTONE)
B(-7,-2,5,COBBLESTONE)
B(-7,-2,6,COBBLESTONE)
B(-7,-2,7,COBBLESTONE)
B(-7,-2,8,COBBLESTONE)
B(-7,-2,9,COBBLESTONE)
B(-7,-2,10,COBBLESTONE)
B(-7,-1,-9,COBBLESTONE)
B(-7,-1,-5,COBBLESTONE)
B(-7,-1,-2,COBBLESTONE)
B(-7,-1,2,COBBLESTONE)
B(-7,-1,5,COBBLESTONE)
B(-7,-1,10,COBBLESTONE)
B(-7,0,-9,COBBLESTONE)
B(-7,0,-5,COBBLESTONE)
B(-7,0,-2,COBBLESTONE)
B(-7,0,2,COBBLESTONE)
B(-7,0,10,COBBLESTONE)
B(-7,1,-9,COBBLESTONE)
B(-7,1,-5,COBBLESTONE)
B(-7,1,-2,COBBLESTONE)
B(-7,1,2,COBBLESTONE)
B(-7,1,10,COBBLESTONE)
B(-7,2,-9,COBBLESTONE)
B(-7,2,-8,COBBLESTONE_STAIRS:4)
B(-7,2,-7,COBBLESTONE_STAIRS:4)
B(-7,2,-6,COBBLESTONE_STAIRS:4)
B(-7,2,-5,COBBLESTONE)
B(-7,2,-4,COBBLESTONE)
B(-7,2,2,COBBLESTONE)
B(-7,2,8,COBBLESTONE_STAIRS:4)
B(-7,2,9,COBBLESTONE_STAIRS:4)
B(-7,2,10,COBBLESTONE)
B(-7,3,-9,COBBLESTONE)
B(-7,3,-8,COBBLESTONE)
B(-7,3,-7,COBBLESTONE)
B(-7,3,-6,COBBLESTONE)
B(-7,3,-5,COBBLESTONE)
B(-7,3,8,COBBLESTONE)
B(-7,3,9,COBBLESTONE)
B(-7,3,10,COBBLESTONE)
B(-7,4,-9,COBBLESTONE)
B(-7,4,-8,COBBLESTONE_STAIRS:0)
B(-7,4,-7,STEP:5)
B(-7,4,-6,COBBLESTONE_STAIRS:2)
B(-7,4,-5,COBBLESTONE_STAIRS:2)
B(-7,4,8,COBBLESTONE_STAIRS:2)
B(-7,4,9,COBBLESTONE_STAIRS:2)
B(-7,4,10,COBBLESTONE)
B(-7,5,-9,COBBLESTONE)
B(-7,5,-8,LEAVES:3)
B(-7,5,-7,LEAVES:3)
B(-7,5,-6,COBBLESTONE_STAIRS:2)
B(-7,5,10,COBBLESTONE)
B(-7,6,-9,COBBLESTONE)
B(-7,6,-8,LEAVES:3)
B(-7,6,10,COBBLESTONE)
B(-7,7,-9,COBBLESTONE)
B(-7,7,10,COBBLESTONE)
B(-7,8,-10,LEAVES:3)
B(-7,8,-9,COBBLESTONE)
B(-7,8,-8,COBBLESTONE_STAIRS:7)
B(-7,8,-7,COBBLESTONE_STAIRS:4)
B(-7,8,-6,COBBLESTONE_STAIRS:4)
B(-7,8,8,COBBLESTONE_STAIRS:6)
B(-7,8,9,COBBLESTONE_STAIRS:6)
B(-7,8,10,COBBLESTONE)
B(-7,9,-10,LEAVES:3)
B(-7,9,-9,COBBLESTONE)
B(-7,9,-8,COBBLESTONE)
B(-7,9,-7,GRASS)
B(-7,9,-6,LEAVES:3)
B(-7,9,8,COBBLESTONE)
B(-7,9,9,COBBLESTONE)
B(-7,9,10,COBBLESTONE)
B(-7,9,11,COBBLESTONE_STAIRS:7)
B(-7,10,-10,LEAVES:3)
B(-7,10,-8,LEAVES:3)
B(-7,10,-7,LEAVES:3)
B(-7,10,9,STEP:5)
B(-7,10,11,DOUBLE_STEP:5)
B(-7,11,-7,LEAVES:3)
B(-6,-16,-8,COBBLESTONE)
B(-6,-16,-7,COBBLESTONE)
B(-6,-16,-6,COBBLESTONE)
B(-6,-16,-5,COBBLESTONE)
B(-6,-16,-4,COBBLESTONE)
B(-6,-16,-3,COBBLESTONE)
B(-6,-16,-2,COBBLESTONE)
B(-6,-16,-1,COBBLESTONE)
B(-6,-16,0,COBBLESTONE)
B(-6,-16,1,COBBLESTONE)
B(-6,-16,2,COBBLESTONE)
B(-6,-16,3,COBBLESTONE)
B(-6,-16,4,COBBLESTONE)
B(-6,-16,5,COBBLESTONE)
B(-6,-16,6,COBBLESTONE)
B(-6,-16,7,COBBLESTONE)
B(-6,-16,8,COBBLESTONE)
B(-6,-16,9,COBBLESTONE)
B(-6,-15,-8,COBBLESTONE)
B(-6,-15,-7,COBBLESTONE)
B(-6,-15,-6,COBBLESTONE)
B(-6,-15,-5,COBBLESTONE)
B(-6,-15,-4,COBBLESTONE)
B(-6,-15,-3,COBBLESTONE)
B(-6,-15,-2,COBBLESTONE)
B(-6,-15,-1,COBBLESTONE)
B(-6,-15,0,COBBLESTONE)
B(-6,-15,1,COBBLESTONE)
B(-6,-15,2,COBBLESTONE)
B(-6,-15,3,COBBLESTONE)
B(-6,-15,4,COBBLESTONE)
B(-6,-15,5,COBBLESTONE)
B(-6,-15,6,COBBLESTONE)
B(-6,-15,7,COBBLESTONE)
B(-6,-15,8,COBBLESTONE)
B(-6,-15,9,COBBLESTONE)
B(-6,-14,-8,COBBLESTONE)
B(-6,-14,-7,COBBLESTONE)
B(-6,-14,-6,COBBLESTONE)
B(-6,-14,-5,COBBLESTONE)
B(-6,-14,-4,COBBLESTONE)
B(-6,-14,-3,COBBLESTONE)
B(-6,-14,-2,COBBLESTONE)
B(-6,-14,-1,COBBLESTONE)
B(-6,-14,0,COBBLESTONE)
B(-6,-14,1,COBBLESTONE)
B(-6,-14,2,COBBLESTONE)
B(-6,-14,3,COBBLESTONE)
B(-6,-14,4,COBBLESTONE)
B(-6,-14,5,COBBLESTONE)
B(-6,-14,6,COBBLESTONE)
B(-6,-14,7,COBBLESTONE)
B(-6,-14,8,COBBLESTONE)
B(-6,-14,9,COBBLESTONE)
B(-6,-13,-8,COBBLESTONE)
B(-6,-13,-7,COBBLESTONE)
B(-6,-13,-6,COBBLESTONE)
B(-6,-13,-5,COBBLESTONE)
B(-6,-13,-4,COBBLESTONE)
B(-6,-13,-3,COBBLESTONE)
B(-6,-13,-2,COBBLESTONE)
B(-6,-13,-1,COBBLESTONE)
B(-6,-13,0,COBBLESTONE)
B(-6,-13,1,COBBLESTONE)
B(-6,-13,2,COBBLESTONE)
B(-6,-13,3,COBBLESTONE)
B(-6,-13,4,COBBLESTONE)
B(-6,-13,5,COBBLESTONE)
B(-6,-13,6,COBBLESTONE)
B(-6,-13,7,COBBLESTONE)
B(-6,-13,8,COBBLESTONE)
B(-6,-13,9,COBBLESTONE)
B(-6,-12,-8,COBBLESTONE)
B(-6,-12,-7,COBBLESTONE)
B(-6,-12,-6,COBBLESTONE)
B(-6,-12,-5,COBBLESTONE)
B(-6,-12,-4,COBBLESTONE)
B(-6,-12,-3,COBBLESTONE)
B(-6,-12,-2,COBBLESTONE)
B(-6,-12,-1,COBBLESTONE)
B(-6,-12,0,COBBLESTONE)
B(-6,-12,1,COBBLESTONE)
B(-6,-12,2,COBBLESTONE)
B(-6,-12,3,COBBLESTONE)
B(-6,-12,4,COBBLESTONE)
B(-6,-12,5,COBBLESTONE)
B(-6,-12,6,COBBLESTONE)
B(-6,-12,7,COBBLESTONE)
B(-6,-12,8,COBBLESTONE)
B(-6,-12,9,COBBLESTONE)
B(-6,-11,-8,COBBLESTONE)
B(-6,-11,-7,COBBLESTONE)
B(-6,-11,-6,COBBLESTONE)
B(-6,-11,-5,COBBLESTONE)
B(-6,-11,-4,COBBLESTONE)
B(-6,-11,-3,COBBLESTONE)
B(-6,-11,-2,COBBLESTONE)
B(-6,-11,-1,COBBLESTONE)
B(-6,-11,0,COBBLESTONE)
B(-6,-11,1,COBBLESTONE)
B(-6,-11,2,COBBLESTONE)
B(-6,-11,3,COBBLESTONE)
B(-6,-11,4,COBBLESTONE)
B(-6,-11,5,COBBLESTONE)
B(-6,-11,6,COBBLESTONE)
B(-6,-11,7,COBBLESTONE)
B(-6,-11,8,COBBLESTONE)
B(-6,-11,9,COBBLESTONE)
B(-6,-10,-8,COBBLESTONE)
B(-6,-10,-7,COBBLESTONE)
B(-6,-10,-6,COBBLESTONE)
B(-6,-10,-5,COBBLESTONE)
B(-6,-10,-4,COBBLESTONE)
B(-6,-10,-3,COBBLESTONE)
B(-6,-10,-2,COBBLESTONE)
B(-6,-10,-1,COBBLESTONE)
B(-6,-10,0,COBBLESTONE)
B(-6,-10,1,COBBLESTONE)
B(-6,-10,2,COBBLESTONE)
B(-6,-10,3,COBBLESTONE)
B(-6,-10,4,COBBLESTONE)
B(-6,-10,5,COBBLESTONE)
B(-6,-10,6,COBBLESTONE)
B(-6,-10,7,COBBLESTONE)
B(-6,-10,8,COBBLESTONE)
B(-6,-10,9,COBBLESTONE)
B(-6,-9,-8,COBBLESTONE)
B(-6,-9,-7,COBBLESTONE)
B(-6,-9,-6,COBBLESTONE)
B(-6,-9,-5,COBBLESTONE)
B(-6,-9,-4,COBBLESTONE)
B(-6,-9,-3,COBBLESTONE)
B(-6,-9,-2,COBBLESTONE)
B(-6,-9,-1,COBBLESTONE)
B(-6,-9,0,COBBLESTONE)
B(-6,-9,1,COBBLESTONE)
B(-6,-9,2,COBBLESTONE)
B(-6,-9,3,COBBLESTONE)
B(-6,-9,4,COBBLESTONE)
B(-6,-9,5,COBBLESTONE)
B(-6,-9,6,COBBLESTONE)
B(-6,-9,7,COBBLESTONE)
B(-6,-9,8,COBBLESTONE)
B(-6,-9,9,COBBLESTONE)
B(-6,-8,-8,COBBLESTONE)
B(-6,-8,-7,COBBLESTONE)
B(-6,-8,-6,COBBLESTONE)
B(-6,-8,-5,COBBLESTONE)
B(-6,-8,-4,COBBLESTONE)
B(-6,-8,-3,COBBLESTONE)
B(-6,-8,-2,COBBLESTONE)
B(-6,-8,-1,COBBLESTONE)
B(-6,-8,0,COBBLESTONE)
B(-6,-8,1,COBBLESTONE)
B(-6,-8,2,COBBLESTONE)
B(-6,-8,3,COBBLESTONE)
B(-6,-8,4,COBBLESTONE)
B(-6,-8,5,COBBLESTONE)
B(-6,-8,6,COBBLESTONE)
B(-6,-8,7,COBBLESTONE)
B(-6,-8,8,COBBLESTONE)
B(-6,-8,9,COBBLESTONE)
B(-6,-7,-8,COBBLESTONE)
B(-6,-7,-7,COBBLESTONE)
B(-6,-7,-6,COBBLESTONE)
B(-6,-7,-5,COBBLESTONE)
B(-6,-7,-4,COBBLESTONE)
B(-6,-7,-3,COBBLESTONE)
B(-6,-7,-2,COBBLESTONE)
B(-6,-7,-1,COBBLESTONE)
B(-6,-7,0,COBBLESTONE)
B(-6,-7,1,COBBLESTONE)
B(-6,-7,2,COBBLESTONE)
B(-6,-7,3,COBBLESTONE)
B(-6,-7,4,COBBLESTONE)
B(-6,-7,5,COBBLESTONE)
B(-6,-7,6,COBBLESTONE)
B(-6,-7,7,COBBLESTONE)
B(-6,-7,8,COBBLESTONE)
B(-6,-7,9,COBBLESTONE)
B(-6,-6,-8,COBBLESTONE)
B(-6,-6,-7,COBBLESTONE)
B(-6,-6,-6,COBBLESTONE)
B(-6,-6,-5,COBBLESTONE)
B(-6,-6,-4,COBBLESTONE)
B(-6,-6,-3,COBBLESTONE)
B(-6,-6,-2,COBBLESTONE)
B(-6,-6,-1,COBBLESTONE)
B(-6,-6,0,COBBLESTONE)
B(-6,-6,1,COBBLESTONE)
B(-6,-6,2,COBBLESTONE)
B(-6,-6,3,COBBLESTONE)
B(-6,-6,4,COBBLESTONE)
B(-6,-6,5,COBBLESTONE)
B(-6,-6,6,COBBLESTONE)
B(-6,-6,7,COBBLESTONE)
B(-6,-6,8,COBBLESTONE)
B(-6,-6,9,COBBLESTONE)
B(-6,-5,-8,COBBLESTONE)
B(-6,-5,-7,COBBLESTONE)
B(-6,-5,-6,COBBLESTONE)
B(-6,-5,-5,COBBLESTONE)
B(-6,-5,-4,COBBLESTONE)
B(-6,-5,-3,COBBLESTONE)
B(-6,-5,-2,COBBLESTONE)
B(-6,-5,-1,COBBLESTONE)
B(-6,-5,0,COBBLESTONE)
B(-6,-5,1,COBBLESTONE)
B(-6,-5,2,COBBLESTONE)
B(-6,-5,3,COBBLESTONE)
B(-6,-5,4,COBBLESTONE)
B(-6,-5,5,COBBLESTONE)
B(-6,-5,6,COBBLESTONE)
B(-6,-5,7,COBBLESTONE)
B(-6,-5,8,COBBLESTONE)
B(-6,-5,9,COBBLESTONE)
B(-6,-4,-8,COBBLESTONE)
B(-6,-4,-7,COBBLESTONE)
B(-6,-4,-6,COBBLESTONE)
B(-6,-4,-5,COBBLESTONE)
B(-6,-4,-4,COBBLESTONE)
B(-6,-4,-3,COBBLESTONE)
B(-6,-4,-2,COBBLESTONE)
B(-6,-4,-1,COBBLESTONE)
B(-6,-4,0,COBBLESTONE)
B(-6,-4,1,COBBLESTONE)
B(-6,-4,2,COBBLESTONE)
B(-6,-4,3,COBBLESTONE)
B(-6,-4,4,COBBLESTONE)
B(-6,-4,5,COBBLESTONE)
B(-6,-4,6,COBBLESTONE)
B(-6,-4,7,COBBLESTONE)
B(-6,-4,8,COBBLESTONE)
B(-6,-4,9,COBBLESTONE)
B(-6,-3,-8,COBBLESTONE)
B(-6,-3,-7,COBBLESTONE)
B(-6,-3,-6,COBBLESTONE)
B(-6,-3,-5,COBBLESTONE)
B(-6,-3,-4,COBBLESTONE)
B(-6,-3,-3,COBBLESTONE)
B(-6,-3,-2,COBBLESTONE)
B(-6,-3,-1,COBBLESTONE)
B(-6,-3,0,COBBLESTONE)
B(-6,-3,1,COBBLESTONE)
B(-6,-3,2,COBBLESTONE)
B(-6,-3,3,COBBLESTONE)
B(-6,-3,4,COBBLESTONE)
B(-6,-3,5,COBBLESTONE)
B(-6,-3,6,COBBLESTONE)
B(-6,-3,7,COBBLESTONE)
B(-6,-3,8,COBBLESTONE)
B(-6,-3,9,COBBLESTONE)
B(-6,-2,-9,COBBLESTONE)
B(-6,-2,-8,COBBLESTONE)
B(-6,-2,-7,COBBLESTONE)
B(-6,-2,-6,COBBLESTONE)
B(-6,-2,-5,COBBLESTONE)
B(-6,-2,-4,COBBLESTONE)
B(-6,-2,-3,COBBLESTONE)
B(-6,-2,-2,COBBLESTONE)
B(-6,-2,-1,COBBLESTONE)
B(-6,-2,0,COBBLESTONE)
B(-6,-2,1,COBBLESTONE)
B(-6,-2,2,COBBLESTONE)
B(-6,-2,3,COBBLESTONE)
B(-6,-2,4,COBBLESTONE)
B(-6,-2,5,COBBLESTONE)
B(-6,-2,6,COBBLESTONE)
B(-6,-2,7,COBBLESTONE)
B(-6,-2,8,COBBLESTONE)
B(-6,-2,9,COBBLESTONE)
B(-6,-2,10,COBBLESTONE)
B(-6,-1,-8,COBBLESTONE)
B(-6,-1,-7,COBBLESTONE)
B(-6,-1,-6,COBBLESTONE)
B(-6,-1,-5,COBBLESTONE)
B(-6,-1,-4,COBBLESTONE)
B(-6,-1,-3,COBBLESTONE)
B(-6,-1,-2,COBBLESTONE)
B(-6,-1,-1,COBBLESTONE)
B(-6,-1,0,COBBLESTONE)
B(-6,-1,1,COBBLESTONE)
B(-6,-1,2,COBBLESTONE)
B(-6,-1,3,COBBLESTONE)
B(-6,-1,4,COBBLESTONE)
B(-6,-1,5,COBBLESTONE)
B(-6,-1,6,COBBLESTONE)
B(-6,-1,7,COBBLESTONE)
B(-6,-1,8,COBBLESTONE)
B(-6,-1,9,COBBLESTONE)
B(-6,0,-8,COBBLESTONE)
B(-6,0,-7,COBBLESTONE)
B(-6,0,-6,COBBLESTONE)
B(-6,0,-5,COBBLESTONE)
B(-6,0,-4,COBBLESTONE)
B(-6,0,-3,COBBLESTONE)
B(-6,0,-2,COBBLESTONE)
B(-6,0,-1,COBBLESTONE)
B(-6,0,0,COBBLESTONE)
B(-6,0,1,COBBLESTONE)
B(-6,0,2,COBBLESTONE)
B(-6,0,3,COBBLESTONE)
B(-6,0,4,COBBLESTONE)
B(-6,0,5,COBBLESTONE)
B(-6,0,6,GRASS)
B(-6,0,7,COBBLESTONE)
B(-6,0,8,COBBLESTONE)
B(-6,0,9,COBBLESTONE)
B(-6,1,-8,COBBLESTONE)
B(-6,1,-7,COBBLESTONE)
B(-6,1,-6,COBBLESTONE)
B(-6,1,-5,COBBLESTONE)
B(-6,1,-4,COBBLESTONE)
B(-6,1,-3,COBBLESTONE)
B(-6,1,0,STEP)
B(-6,1,1,COBBLESTONE)
B(-6,1,2,COBBLESTONE)
B(-6,1,3,STEP)
B(-6,1,8,COBBLESTONE)
B(-6,1,9,COBBLESTONE)
B(-6,2,-9,COBBLESTONE_STAIRS:5)
B(-6,2,-8,COBBLESTONE)
B(-6,2,-7,COBBLESTONE)
B(-6,2,-6,COBBLESTONE)
B(-6,2,-5,COBBLESTONE)
B(-6,2,-4,STEP:8)
B(-6,2,-3,COBBLESTONE)
B(-6,2,1,STEP)
B(-6,2,2,STEP)
B(-6,2,8,COBBLESTONE)
B(-6,2,9,COBBLESTONE)
B(-6,3,-9,COBBLESTONE)
B(-6,3,-8,GRASS)
B(-6,3,-7,COBBLESTONE)
B(-6,3,-6,COBBLESTONE)
B(-6,3,-5,COBBLESTONE)
B(-6,3,-4,STEP)
B(-6,3,8,COBBLESTONE)
B(-6,3,9,COBBLESTONE)
B(-6,3,10,COBBLESTONE)
B(-6,4,-8,LEAVES:3)
B(-6,4,-7,COBBLESTONE)
B(-6,4,-6,COBBLESTONE)
B(-6,4,8,STEP)
B(-6,4,9,DOUBLE_STEP)
B(-6,5,-8,LEAVES:3)
B(-6,5,-7,LEAVES:3)
B(-6,5,-6,COBBLESTONE)
B(-6,5,-5,LEAVES:3)
B(-6,6,-7,AIR)
B(-6,6,-6,LEAVES:3)
B(-6,6,5,LEAVES:3)
B(-6,6,6,LEAVES:3)
B(-6,6,7,LEAVES:3)
B(-6,7,-7,AIR)
B(-6,7,-6,AIR)
B(-6,8,-9,COBBLESTONE_STAIRS:5)
B(-6,8,-8,STEP:8)
B(-6,8,-7,STEP:8)
B(-6,8,-6,STEP:8)
B(-6,8,-5,STEP:8)
B(-6,8,8,STEP:8)
B(-6,8,9,STEP:8)
B(-6,8,10,COBBLESTONE_STAIRS:5)
B(-6,9,-10,COBBLESTONE_STAIRS:6)
B(-6,9,-9,COBBLESTONE)
B(-6,9,-8,COBBLESTONE)
B(-6,9,-7,GRASS)
B(-6,9,-6,COBBLESTONE)
B(-6,9,-5,LEAVES:3)
B(-6,9,8,DIRT:1)
B(-6,9,9,DIRT:1)
B(-6,9,10,COBBLESTONE)
B(-6,10,-10,LEAVES:3)
B(-6,10,-9,LEAVES:3)
B(-6,10,-8,LEAVES:3)
B(-6,10,-7,COBBLESTONE_STAIRS:2)
B(-6,10,-6,LEAVES:3)
B(-6,10,9,GRASS)
B(-6,10,11,STEP:5)
B(-6,11,-8,LEAVES:3)
B(-5,-16,-8,COBBLESTONE)
B(-5,-16,-7,COBBLESTONE)
B(-5,-16,-6,COBBLESTONE)
B(-5,-16,-5,COBBLESTONE)
B(-5,-16,-4,COBBLESTONE)
B(-5,-16,-3,COBBLESTONE)
B(-5,-16,-2,COBBLESTONE)
B(-5,-16,-1,COBBLESTONE)
B(-5,-16,0,COBBLESTONE)
B(-5,-16,1,COBBLESTONE)
B(-5,-16,2,COBBLESTONE)
B(-5,-16,3,COBBLESTONE)
B(-5,-16,4,COBBLESTONE)
B(-5,-16,5,COBBLESTONE)
B(-5,-16,6,COBBLESTONE)
B(-5,-16,7,COBBLESTONE)
B(-5,-16,8,COBBLESTONE)
B(-5,-16,9,COBBLESTONE)
B(-5,-15,-8,COBBLESTONE)
B(-5,-15,-7,COBBLESTONE)
B(-5,-15,-6,COBBLESTONE)
B(-5,-15,-5,COBBLESTONE)
B(-5,-15,-4,COBBLESTONE)
B(-5,-15,-3,COBBLESTONE)
B(-5,-15,-2,COBBLESTONE)
B(-5,-15,-1,COBBLESTONE)
B(-5,-15,0,COBBLESTONE)
B(-5,-15,1,COBBLESTONE)
B(-5,-15,2,COBBLESTONE)
B(-5,-15,3,COBBLESTONE)
B(-5,-15,4,COBBLESTONE)
B(-5,-15,5,COBBLESTONE)
B(-5,-15,6,COBBLESTONE)
B(-5,-15,7,COBBLESTONE)
B(-5,-15,8,COBBLESTONE)
B(-5,-15,9,COBBLESTONE)
B(-5,-14,-8,COBBLESTONE)
B(-5,-14,-7,COBBLESTONE)
B(-5,-14,-6,COBBLESTONE)
B(-5,-14,-5,COBBLESTONE)
B(-5,-14,-4,COBBLESTONE)
B(-5,-14,-3,COBBLESTONE)
B(-5,-14,-2,COBBLESTONE)
B(-5,-14,-1,COBBLESTONE)
B(-5,-14,0,COBBLESTONE)
B(-5,-14,1,COBBLESTONE)
B(-5,-14,2,COBBLESTONE)
B(-5,-14,3,COBBLESTONE)
B(-5,-14,4,COBBLESTONE)
B(-5,-14,5,COBBLESTONE)
B(-5,-14,6,COBBLESTONE)
B(-5,-14,7,COBBLESTONE)
B(-5,-14,8,COBBLESTONE)
B(-5,-14,9,COBBLESTONE)
B(-5,-13,-8,COBBLESTONE)
B(-5,-13,-7,COBBLESTONE)
B(-5,-13,-6,COBBLESTONE)
B(-5,-13,-5,COBBLESTONE)
B(-5,-13,-4,COBBLESTONE)
B(-5,-13,-3,COBBLESTONE)
B(-5,-13,-2,COBBLESTONE)
B(-5,-13,-1,COBBLESTONE)
B(-5,-13,0,COBBLESTONE)
B(-5,-13,1,COBBLESTONE)
B(-5,-13,2,COBBLESTONE)
B(-5,-13,3,COBBLESTONE)
B(-5,-13,4,COBBLESTONE)
B(-5,-13,5,COBBLESTONE)
B(-5,-13,6,COBBLESTONE)
B(-5,-13,7,COBBLESTONE)
B(-5,-13,8,COBBLESTONE)
B(-5,-13,9,COBBLESTONE)
B(-5,-12,-8,COBBLESTONE)
B(-5,-12,-7,COBBLESTONE)
B(-5,-12,-6,COBBLESTONE)
B(-5,-12,-5,COBBLESTONE)
B(-5,-12,-4,COBBLESTONE)
B(-5,-12,-3,COBBLESTONE)
B(-5,-12,-2,COBBLESTONE)
B(-5,-12,-1,COBBLESTONE)
B(-5,-12,0,COBBLESTONE)
B(-5,-12,1,COBBLESTONE)
B(-5,-12,2,COBBLESTONE)
B(-5,-12,3,COBBLESTONE)
B(-5,-12,4,COBBLESTONE)
B(-5,-12,5,COBBLESTONE)
B(-5,-12,6,COBBLESTONE)
B(-5,-12,7,COBBLESTONE)
B(-5,-12,8,COBBLESTONE)
B(-5,-12,9,COBBLESTONE)
B(-5,-11,-8,COBBLESTONE)
B(-5,-11,-7,COBBLESTONE)
B(-5,-11,-6,COBBLESTONE)
B(-5,-11,-5,COBBLESTONE)
B(-5,-11,-4,COBBLESTONE)
B(-5,-11,-3,COBBLESTONE)
B(-5,-11,-2,COBBLESTONE)
B(-5,-11,-1,COBBLESTONE)
B(-5,-11,0,COBBLESTONE)
B(-5,-11,1,COBBLESTONE)
B(-5,-11,2,COBBLESTONE)
B(-5,-11,3,COBBLESTONE)
B(-5,-11,4,COBBLESTONE)
B(-5,-11,5,COBBLESTONE)
B(-5,-11,6,COBBLESTONE)
B(-5,-11,7,COBBLESTONE)
B(-5,-11,8,COBBLESTONE)
B(-5,-11,9,COBBLESTONE)
B(-5,-10,-8,COBBLESTONE)
B(-5,-10,-7,COBBLESTONE)
B(-5,-10,-6,COBBLESTONE)
B(-5,-10,-5,COBBLESTONE)
B(-5,-10,-4,COBBLESTONE)
B(-5,-10,-3,COBBLESTONE)
B(-5,-10,-2,COBBLESTONE)
B(-5,-10,-1,COBBLESTONE)
B(-5,-10,0,COBBLESTONE)
B(-5,-10,1,COBBLESTONE)
B(-5,-10,2,COBBLESTONE)
B(-5,-10,3,COBBLESTONE)
B(-5,-10,4,COBBLESTONE)
B(-5,-10,5,COBBLESTONE)
B(-5,-10,6,COBBLESTONE)
B(-5,-10,7,COBBLESTONE)
B(-5,-10,8,COBBLESTONE)
B(-5,-10,9,COBBLESTONE)
B(-5,-9,-8,COBBLESTONE)
B(-5,-9,-7,COBBLESTONE)
B(-5,-9,-6,COBBLESTONE)
B(-5,-9,-5,COBBLESTONE)
B(-5,-9,-4,COBBLESTONE)
B(-5,-9,-3,COBBLESTONE)
B(-5,-9,-2,COBBLESTONE)
B(-5,-9,-1,COBBLESTONE)
B(-5,-9,0,COBBLESTONE)
B(-5,-9,1,COBBLESTONE)
B(-5,-9,2,COBBLESTONE)
B(-5,-9,3,COBBLESTONE)
B(-5,-9,4,COBBLESTONE)
B(-5,-9,5,COBBLESTONE)
B(-5,-9,6,COBBLESTONE)
B(-5,-9,7,COBBLESTONE)
B(-5,-9,8,COBBLESTONE)
B(-5,-9,9,COBBLESTONE)
B(-5,-8,-8,COBBLESTONE)
B(-5,-8,-7,COBBLESTONE)
B(-5,-8,-6,COBBLESTONE)
B(-5,-8,-5,COBBLESTONE)
B(-5,-8,-4,COBBLESTONE)
B(-5,-8,-3,COBBLESTONE)
B(-5,-8,-2,COBBLESTONE)
B(-5,-8,-1,COBBLESTONE)
B(-5,-8,0,COBBLESTONE)
B(-5,-8,1,COBBLESTONE)
B(-5,-8,2,COBBLESTONE)
B(-5,-8,3,COBBLESTONE)
B(-5,-8,4,COBBLESTONE)
B(-5,-8,5,COBBLESTONE)
B(-5,-8,6,COBBLESTONE)
B(-5,-8,7,COBBLESTONE)
B(-5,-8,8,COBBLESTONE)
B(-5,-8,9,COBBLESTONE)
B(-5,-7,-8,COBBLESTONE)
B(-5,-7,-7,COBBLESTONE)
B(-5,-7,-6,COBBLESTONE)
B(-5,-7,-5,COBBLESTONE)
B(-5,-7,-4,COBBLESTONE)
B(-5,-7,-3,COBBLESTONE)
B(-5,-7,-2,COBBLESTONE)
B(-5,-7,-1,COBBLESTONE)
B(-5,-7,0,COBBLESTONE)
B(-5,-7,1,COBBLESTONE)
B(-5,-7,2,COBBLESTONE)
B(-5,-7,3,COBBLESTONE)
B(-5,-7,4,COBBLESTONE)
B(-5,-7,5,COBBLESTONE)
B(-5,-7,6,COBBLESTONE)
B(-5,-7,7,COBBLESTONE)
B(-5,-7,8,COBBLESTONE)
B(-5,-7,9,COBBLESTONE)
B(-5,-6,-8,COBBLESTONE)
B(-5,-6,-7,COBBLESTONE)
B(-5,-6,-6,COBBLESTONE)
B(-5,-6,-5,COBBLESTONE)
B(-5,-6,-4,COBBLESTONE)
B(-5,-6,-3,COBBLESTONE)
B(-5,-6,-2,COBBLESTONE)
B(-5,-6,-1,COBBLESTONE)
B(-5,-6,0,COBBLESTONE)
B(-5,-6,1,COBBLESTONE)
B(-5,-6,2,COBBLESTONE)
B(-5,-6,3,COBBLESTONE)
B(-5,-6,4,COBBLESTONE)
B(-5,-6,5,COBBLESTONE)
B(-5,-6,6,COBBLESTONE)
B(-5,-6,7,COBBLESTONE)
B(-5,-6,8,COBBLESTONE)
B(-5,-6,9,COBBLESTONE)
B(-5,-5,-8,COBBLESTONE)
B(-5,-5,-7,COBBLESTONE)
B(-5,-5,-6,COBBLESTONE)
B(-5,-5,-5,COBBLESTONE)
B(-5,-5,-4,COBBLESTONE)
B(-5,-5,-3,COBBLESTONE)
B(-5,-5,-2,COBBLESTONE)
B(-5,-5,-1,COBBLESTONE)
B(-5,-5,0,COBBLESTONE)
B(-5,-5,1,COBBLESTONE)
B(-5,-5,2,COBBLESTONE)
B(-5,-5,3,COBBLESTONE)
B(-5,-5,4,COBBLESTONE)
B(-5,-5,5,COBBLESTONE)
B(-5,-5,6,COBBLESTONE)
B(-5,-5,7,COBBLESTONE)
B(-5,-5,8,COBBLESTONE)
B(-5,-5,9,COBBLESTONE)
B(-5,-4,-8,COBBLESTONE)
B(-5,-4,-7,COBBLESTONE)
B(-5,-4,-6,COBBLESTONE)
B(-5,-4,-5,COBBLESTONE)
B(-5,-4,-4,COBBLESTONE)
B(-5,-4,-3,COBBLESTONE)
B(-5,-4,-2,COBBLESTONE)
B(-5,-4,-1,COBBLESTONE)
B(-5,-4,0,COBBLESTONE)
B(-5,-4,1,COBBLESTONE)
B(-5,-4,2,COBBLESTONE)
B(-5,-4,3,COBBLESTONE)
B(-5,-4,4,COBBLESTONE)
B(-5,-4,5,COBBLESTONE)
B(-5,-4,6,COBBLESTONE)
B(-5,-4,7,COBBLESTONE)
B(-5,-4,8,COBBLESTONE)
B(-5,-4,9,COBBLESTONE)
B(-5,-3,-8,COBBLESTONE)
B(-5,-3,-7,COBBLESTONE)
B(-5,-3,-6,COBBLESTONE)
B(-5,-3,-5,COBBLESTONE)
B(-5,-3,-4,COBBLESTONE)
B(-5,-3,-3,COBBLESTONE)
B(-5,-3,-2,COBBLESTONE)
B(-5,-3,-1,COBBLESTONE)
B(-5,-3,0,COBBLESTONE)
B(-5,-3,1,COBBLESTONE)
B(-5,-3,2,COBBLESTONE)
B(-5,-3,3,COBBLESTONE)
B(-5,-3,4,COBBLESTONE)
B(-5,-3,5,COBBLESTONE)
B(-5,-3,6,COBBLESTONE)
B(-5,-3,7,COBBLESTONE)
B(-5,-3,8,COBBLESTONE)
B(-5,-3,9,COBBLESTONE)
B(-5,-2,-9,COBBLESTONE)
B(-5,-2,-8,COBBLESTONE)
B(-5,-2,-7,COBBLESTONE)
B(-5,-2,-6,STEP:8)
B(-5,-2,-5,STEP:8)
B(-5,-2,-4,STEP:8)
B(-5,-2,-3,STEP:8)
B(-5,-2,-2,STEP:8)
B(-5,-2,-1,STEP:8)
B(-5,-2,0,STEP:8)
B(-5,-2,1,STEP:8)
B(-5,-2,2,COBBLESTONE)
B(-5,-2,3,STEP:8)
B(-5,-2,4,STEP:8)
B(-5,-2,5,STEP:8)
B(-5,-2,6,STEP:8)
B(-5,-2,7,STEP:8)
B(-5,-2,8,STEP:8)
B(-5,-2,9,STEP:8)
B(-5,-2,10,COBBLESTONE)
B(-5,-1,-8,COBBLESTONE)
B(-5,-1,-7,COBBLESTONE)
B(-5,-1,-6,GRAVEL)
B(-5,-1,-5,GRAVEL)
B(-5,-1,-4,COBBLESTONE)
B(-5,-1,-3,COBBLESTONE)
B(-5,-1,-2,COBBLESTONE)
B(-5,-1,-1,COBBLESTONE)
B(-5,-1,0,COBBLESTONE)
B(-5,-1,1,AIR)
B(-5,-1,2,COBBLESTONE)
B(-5,-1,3,COBBLESTONE)
B(-5,-1,4,COBBLESTONE)
B(-5,-1,5,COBBLESTONE)
B(-5,-1,6,DIRT)
B(-5,-1,7,DIRT)
B(-5,-1,8,DIRT)
B(-5,-1,9,COBBLESTONE)
B(-5,0,-8,COBBLESTONE)
B(-5,0,-7,COBBLESTONE)
B(-5,0,-6,GRAVEL)
B(-5,0,-5,AIR)
B(-5,0,-4,COBBLESTONE)
B(-5,0,-3,COBBLESTONE)
B(-5,0,-2,AIR)
B(-5,0,-1,COBBLESTONE)
B(-5,0,0,COBBLESTONE)
B(-5,0,1,COBBLESTONE)
B(-5,0,2,COBBLESTONE)
B(-5,0,3,STEP)
B(-5,0,4,LEAVES:3)
B(-5,0,5,GRASS)
B(-5,0,6,GRASS)
B(-5,0,7,GRASS)
B(-5,0,8,DIRT)
B(-5,0,9,COBBLESTONE)
B(-5,1,-8,COBBLESTONE)
B(-5,1,-7,COBBLESTONE)
B(-5,1,-6,GRAVEL)
B(-5,1,-4,COBBLESTONE)
B(-5,1,1,STEP)
B(-5,1,5,LEAVES:3)
B(-5,1,8,COBBLESTONE)
B(-5,1,9,COBBLESTONE)
B(-5,2,-8,COBBLESTONE)
B(-5,2,-7,COBBLESTONE)
B(-5,2,-6,STEP:8)
B(-5,2,-5,DOUBLE_STEP)
B(-5,2,-4,DOUBLE_STEP)
B(-5,2,-3,STEP:8)
B(-5,2,8,COBBLESTONE)
B(-5,2,9,COBBLESTONE)
B(-5,3,-9,COBBLESTONE)
B(-5,3,-8,GRASS)
B(-5,3,-7,COBBLESTONE)
B(-5,3,-6,COBBLESTONE)
B(-5,3,-5,COBBLESTONE)
B(-5,3,-4,STEP)
B(-5,3,9,COBBLESTONE)
B(-5,3,10,COBBLESTONE)
B(-5,4,-7,LEAVES:3)
B(-5,4,-6,AIR)
B(-5,4,-5,COBBLESTONE)
B(-5,5,-7,LEAVES:3)
B(-5,5,-6,AIR)
B(-5,5,-5,STEP)
B(-5,6,-8,LEAVES:3)
B(-5,6,-7,AIR)
B(-5,6,-6,AIR)
B(-5,6,-5,LEAVES:3)
B(-5,6,4,LEAVES:3)
B(-5,6,5,LEAVES:3)
B(-5,6,6,LEAVES:3)
B(-5,6,7,LEAVES:3)
B(-5,6,8,LEAVES:3)
B(-5,7,-9,LEAVES:3)
B(-5,7,-7,AIR)
B(-5,7,-6,AIR)
B(-5,7,5,LEAVES:3)
B(-5,7,6,LEAVES:3)
B(-5,7,7,LEAVES:3)
B(-5,8,-10,LEAVES:3)
B(-5,8,-9,COBBLESTONE_STAIRS:4)
B(-5,8,-8,STEP:8)
B(-5,8,-7,STEP:8)
B(-5,8,-6,STEP:8)
B(-5,8,-5,STEP:8)
B(-5,8,7,STEP:8)
B(-5,8,8,STEP:8)
B(-5,8,9,STEP:8)
B(-5,8,10,COBBLESTONE_STAIRS:4)
B(-5,9,-10,LEAVES:3)
B(-5,9,-9,COBBLESTONE)
B(-5,9,-8,COBBLESTONE)
B(-5,9,-7,COBBLESTONE)
B(-5,9,-6,COBBLESTONE)
B(-5,9,-5,COBBLESTONE)
B(-5,9,-4,LEAVES:3)
B(-5,9,7,GRASS)
B(-5,9,8,COBBLESTONE)
B(-5,9,9,COBBLESTONE)
B(-5,9,10,COBBLESTONE)
B(-5,9,11,COBBLESTONE_STAIRS:7)
B(-5,10,-10,STEP:5)
B(-5,10,-9,LEAVES:3)
B(-5,10,-8,GRASS)
B(-5,10,-7,COBBLESTONE_STAIRS:2)
B(-5,10,-6,COBBLESTONE)
B(-5,10,-5,COBBLESTONE_STAIRS:1)
B(-5,10,8,GRASS)
B(-5,10,9,GRASS)
B(-5,10,11,DOUBLE_STEP:5)
B(-5,11,-9,LEAVES:3)
B(-5,11,-6,COBBLESTONE)
B(-4,-16,-8,COBBLESTONE)
B(-4,-16,-7,COBBLESTONE)
B(-4,-16,-6,COBBLESTONE)
B(-4,-16,-5,COBBLESTONE)
B(-4,-16,-4,COBBLESTONE)
B(-4,-16,-3,COBBLESTONE)
B(-4,-16,-2,COBBLESTONE)
B(-4,-16,-1,COBBLESTONE)
B(-4,-16,0,COBBLESTONE)
B(-4,-16,1,COBBLESTONE)
B(-4,-16,2,COBBLESTONE)
B(-4,-16,3,COBBLESTONE)
B(-4,-16,4,COBBLESTONE)
B(-4,-16,5,COBBLESTONE)
B(-4,-16,6,COBBLESTONE)
B(-4,-16,7,COBBLESTONE)
B(-4,-16,8,COBBLESTONE)
B(-4,-16,9,COBBLESTONE)
B(-4,-16,10,COBBLESTONE)
B(-4,-15,-8,COBBLESTONE)
B(-4,-15,-7,COBBLESTONE)
B(-4,-15,-6,COBBLESTONE)
B(-4,-15,-5,COBBLESTONE)
B(-4,-15,-4,COBBLESTONE)
B(-4,-15,-3,COBBLESTONE)
B(-4,-15,-2,COBBLESTONE)
B(-4,-15,-1,COBBLESTONE)
B(-4,-15,0,COBBLESTONE)
B(-4,-15,1,COBBLESTONE)
B(-4,-15,2,COBBLESTONE)
B(-4,-15,3,COBBLESTONE)
B(-4,-15,4,COBBLESTONE)
B(-4,-15,5,COBBLESTONE)
B(-4,-15,6,COBBLESTONE)
B(-4,-15,7,COBBLESTONE)
B(-4,-15,8,COBBLESTONE)
B(-4,-15,9,COBBLESTONE)
B(-4,-15,10,COBBLESTONE)
B(-4,-14,-8,COBBLESTONE)
B(-4,-14,-7,COBBLESTONE)
B(-4,-14,-6,COBBLESTONE)
B(-4,-14,-5,COBBLESTONE)
B(-4,-14,-4,COBBLESTONE)
B(-4,-14,-3,COBBLESTONE)
B(-4,-14,-2,COBBLESTONE)
B(-4,-14,-1,COBBLESTONE)
B(-4,-14,0,COBBLESTONE)
B(-4,-14,1,COBBLESTONE)
B(-4,-14,2,COBBLESTONE)
B(-4,-14,3,COBBLESTONE)
B(-4,-14,4,COBBLESTONE)
B(-4,-14,5,COBBLESTONE)
B(-4,-14,6,COBBLESTONE)
B(-4,-14,7,COBBLESTONE)
B(-4,-14,8,COBBLESTONE)
B(-4,-14,9,COBBLESTONE)
B(-4,-14,10,COBBLESTONE)
B(-4,-13,-8,COBBLESTONE)
B(-4,-13,-7,COBBLESTONE)
B(-4,-13,-6,COBBLESTONE)
B(-4,-13,-5,COBBLESTONE)
B(-4,-13,-4,COBBLESTONE)
B(-4,-13,-3,COBBLESTONE)
B(-4,-13,-2,COBBLESTONE)
B(-4,-13,-1,COBBLESTONE)
B(-4,-13,0,COBBLESTONE)
B(-4,-13,1,COBBLESTONE)
B(-4,-13,2,COBBLESTONE)
B(-4,-13,3,COBBLESTONE)
B(-4,-13,4,COBBLESTONE)
B(-4,-13,5,COBBLESTONE)
B(-4,-13,6,COBBLESTONE)
B(-4,-13,7,COBBLESTONE)
B(-4,-13,8,COBBLESTONE)
B(-4,-13,9,COBBLESTONE)
B(-4,-13,10,COBBLESTONE)
B(-4,-12,-8,COBBLESTONE)
B(-4,-12,-7,COBBLESTONE)
B(-4,-12,-6,COBBLESTONE)
B(-4,-12,-5,COBBLESTONE)
B(-4,-12,-4,COBBLESTONE)
B(-4,-12,-3,COBBLESTONE)
B(-4,-12,-2,COBBLESTONE)
B(-4,-12,-1,COBBLESTONE)
B(-4,-12,0,COBBLESTONE)
B(-4,-12,1,COBBLESTONE)
B(-4,-12,2,COBBLESTONE)
B(-4,-12,3,COBBLESTONE)
B(-4,-12,4,COBBLESTONE)
B(-4,-12,5,COBBLESTONE)
B(-4,-12,6,COBBLESTONE)
B(-4,-12,7,COBBLESTONE)
B(-4,-12,8,COBBLESTONE)
B(-4,-12,9,COBBLESTONE)
B(-4,-12,10,COBBLESTONE)
B(-4,-11,-8,COBBLESTONE)
B(-4,-11,-7,COBBLESTONE)
B(-4,-11,-6,COBBLESTONE)
B(-4,-11,-5,COBBLESTONE)
B(-4,-11,-4,COBBLESTONE)
B(-4,-11,-3,COBBLESTONE)
B(-4,-11,-2,COBBLESTONE)
B(-4,-11,-1,COBBLESTONE)
B(-4,-11,0,COBBLESTONE)
B(-4,-11,1,COBBLESTONE)
B(-4,-11,2,COBBLESTONE)
B(-4,-11,3,COBBLESTONE)
B(-4,-11,4,COBBLESTONE)
B(-4,-11,5,COBBLESTONE)
B(-4,-11,6,COBBLESTONE)
B(-4,-11,7,COBBLESTONE)
B(-4,-11,8,COBBLESTONE)
B(-4,-11,9,COBBLESTONE)
B(-4,-11,10,COBBLESTONE)
B(-4,-10,-8,COBBLESTONE)
B(-4,-10,-7,COBBLESTONE)
B(-4,-10,-6,COBBLESTONE)
B(-4,-10,-5,COBBLESTONE)
B(-4,-10,-4,COBBLESTONE)
B(-4,-10,-3,COBBLESTONE)
B(-4,-10,-2,COBBLESTONE)
B(-4,-10,-1,COBBLESTONE)
B(-4,-10,0,COBBLESTONE)
B(-4,-10,1,COBBLESTONE)
B(-4,-10,2,COBBLESTONE)
B(-4,-10,3,COBBLESTONE)
B(-4,-10,4,COBBLESTONE)
B(-4,-10,5,COBBLESTONE)
B(-4,-10,6,COBBLESTONE)
B(-4,-10,7,COBBLESTONE)
B(-4,-10,8,COBBLESTONE)
B(-4,-10,9,COBBLESTONE)
B(-4,-10,10,COBBLESTONE)
B(-4,-9,-8,COBBLESTONE)
B(-4,-9,-7,COBBLESTONE)
B(-4,-9,-6,COBBLESTONE)
B(-4,-9,-5,COBBLESTONE)
B(-4,-9,-4,COBBLESTONE)
B(-4,-9,-3,COBBLESTONE)
B(-4,-9,-2,COBBLESTONE)
B(-4,-9,-1,COBBLESTONE)
B(-4,-9,0,COBBLESTONE)
B(-4,-9,1,COBBLESTONE)
B(-4,-9,2,COBBLESTONE)
B(-4,-9,3,COBBLESTONE)
B(-4,-9,4,COBBLESTONE)
B(-4,-9,5,COBBLESTONE)
B(-4,-9,6,COBBLESTONE)
B(-4,-9,7,COBBLESTONE)
B(-4,-9,8,COBBLESTONE)
B(-4,-9,9,COBBLESTONE)
B(-4,-9,10,COBBLESTONE)
B(-4,-8,-8,COBBLESTONE)
B(-4,-8,-7,COBBLESTONE)
B(-4,-8,-6,COBBLESTONE)
B(-4,-8,-5,COBBLESTONE)
B(-4,-8,-4,COBBLESTONE)
B(-4,-8,-3,COBBLESTONE)
B(-4,-8,-2,COBBLESTONE)
B(-4,-8,-1,COBBLESTONE)
B(-4,-8,0,COBBLESTONE)
B(-4,-8,1,COBBLESTONE)
B(-4,-8,2,COBBLESTONE)
B(-4,-8,3,COBBLESTONE)
B(-4,-8,4,COBBLESTONE)
B(-4,-8,5,COBBLESTONE)
B(-4,-8,6,COBBLESTONE)
B(-4,-8,7,COBBLESTONE)
B(-4,-8,8,COBBLESTONE)
B(-4,-8,9,COBBLESTONE)
B(-4,-8,10,COBBLESTONE)
B(-4,-7,-8,COBBLESTONE)
B(-4,-7,-7,COBBLESTONE)
B(-4,-7,-6,COBBLESTONE)
B(-4,-7,-5,COBBLESTONE)
B(-4,-7,-4,COBBLESTONE)
B(-4,-7,-3,COBBLESTONE)
B(-4,-7,-2,COBBLESTONE)
B(-4,-7,-1,COBBLESTONE)
B(-4,-7,0,COBBLESTONE)
B(-4,-7,1,COBBLESTONE)
B(-4,-7,2,COBBLESTONE)
B(-4,-7,3,COBBLESTONE)
B(-4,-7,4,COBBLESTONE)
B(-4,-7,5,COBBLESTONE)
B(-4,-7,6,COBBLESTONE)
B(-4,-7,7,COBBLESTONE)
B(-4,-7,8,COBBLESTONE)
B(-4,-7,9,COBBLESTONE)
B(-4,-7,10,COBBLESTONE)
B(-4,-6,-8,COBBLESTONE)
B(-4,-6,-7,COBBLESTONE)
B(-4,-6,-6,COBBLESTONE)
B(-4,-6,-5,COBBLESTONE)
B(-4,-6,-4,COBBLESTONE)
B(-4,-6,-3,COBBLESTONE)
B(-4,-6,-2,COBBLESTONE)
B(-4,-6,-1,COBBLESTONE)
B(-4,-6,0,COBBLESTONE)
B(-4,-6,1,COBBLESTONE)
B(-4,-6,2,COBBLESTONE)
B(-4,-6,3,COBBLESTONE)
B(-4,-6,4,COBBLESTONE)
B(-4,-6,5,COBBLESTONE)
B(-4,-6,6,COBBLESTONE)
B(-4,-6,7,COBBLESTONE)
B(-4,-6,8,COBBLESTONE)
B(-4,-6,9,COBBLESTONE)
B(-4,-6,10,COBBLESTONE)
B(-4,-5,-8,COBBLESTONE)
B(-4,-5,-7,COBBLESTONE)
B(-4,-5,-6,COBBLESTONE)
B(-4,-5,-5,COBBLESTONE)
B(-4,-5,-4,COBBLESTONE)
B(-4,-5,-3,COBBLESTONE)
B(-4,-5,-2,COBBLESTONE)
B(-4,-5,-1,COBBLESTONE)
B(-4,-5,0,COBBLESTONE)
B(-4,-5,1,COBBLESTONE)
B(-4,-5,2,COBBLESTONE)
B(-4,-5,3,COBBLESTONE)
B(-4,-5,4,COBBLESTONE)
B(-4,-5,5,COBBLESTONE)
B(-4,-5,6,COBBLESTONE)
B(-4,-5,7,COBBLESTONE)
B(-4,-5,8,COBBLESTONE)
B(-4,-5,9,COBBLESTONE)
B(-4,-5,10,COBBLESTONE)
B(-4,-4,-8,COBBLESTONE)
B(-4,-4,-7,COBBLESTONE)
B(-4,-4,-6,COBBLESTONE)
B(-4,-4,-5,COBBLESTONE)
B(-4,-4,-4,COBBLESTONE)
B(-4,-4,-3,COBBLESTONE)
B(-4,-4,-2,COBBLESTONE)
B(-4,-4,-1,COBBLESTONE)
B(-4,-4,0,COBBLESTONE)
B(-4,-4,1,COBBLESTONE)
B(-4,-4,2,COBBLESTONE)
B(-4,-4,3,COBBLESTONE)
B(-4,-4,4,COBBLESTONE)
B(-4,-4,5,COBBLESTONE)
B(-4,-4,6,COBBLESTONE)
B(-4,-4,7,COBBLESTONE)
B(-4,-4,8,COBBLESTONE)
B(-4,-4,9,COBBLESTONE)
B(-4,-4,10,COBBLESTONE)
B(-4,-3,-8,COBBLESTONE)
B(-4,-3,-7,COBBLESTONE)
B(-4,-3,-6,COBBLESTONE)
B(-4,-3,-5,COBBLESTONE)
B(-4,-3,-4,COBBLESTONE)
B(-4,-3,-3,COBBLESTONE)
B(-4,-3,-2,COBBLESTONE)
B(-4,-3,-1,COBBLESTONE)
B(-4,-3,0,COBBLESTONE)
B(-4,-3,1,COBBLESTONE)
B(-4,-3,2,COBBLESTONE)
B(-4,-3,3,COBBLESTONE)
B(-4,-3,4,COBBLESTONE)
B(-4,-3,5,COBBLESTONE)
B(-4,-3,6,COBBLESTONE)
B(-4,-3,7,COBBLESTONE)
B(-4,-3,8,COBBLESTONE)
B(-4,-3,9,COBBLESTONE)
B(-4,-3,10,COBBLESTONE)
B(-4,-2,-9,COBBLESTONE)
B(-4,-2,-8,COBBLESTONE)
B(-4,-2,-7,COBBLESTONE)
B(-4,-2,-6,STEP:8)
B(-4,-2,-5,STEP:8)
B(-4,-2,-4,STEP:8)
B(-4,-2,-3,STEP:8)
B(-4,-2,-2,STEP:8)
B(-4,-2,-1,COBBLESTONE)
B(-4,-2,0,STEP:8)
B(-4,-2,1,STEP:8)
B(-4,-2,2,COBBLESTONE)
B(-4,-2,3,STEP:8)
B(-4,-2,4,STEP:8)
B(-4,-2,5,STEP:8)
B(-4,-2,6,STEP:8)
B(-4,-2,7,STEP:8)
B(-4,-2,8,STEP:8)
B(-4,-2,9,STEP:8)
B(-4,-2,10,COBBLESTONE)
B(-4,-1,-8,COBBLESTONE)
B(-4,-1,-7,COBBLESTONE)
B(-4,-1,-6,GRAVEL)
B(-4,-1,-5,STEP)
B(-4,-1,-4,COBBLESTONE)
B(-4,-1,-3,COBBLESTONE)
B(-4,-1,-2,COBBLESTONE)
B(-4,-1,-1,COBBLESTONE)
B(-4,-1,0,COBBLESTONE)
B(-4,-1,1,AIR)
B(-4,-1,2,COBBLESTONE)
B(-4,-1,3,COBBLESTONE)
B(-4,-1,4,GRASS)
B(-4,-1,5,GRASS)
B(-4,-1,6,DIRT)
B(-4,-1,7,DIRT)
B(-4,-1,8,DIRT)
B(-4,-1,9,COBBLESTONE)
B(-4,-1,10,COBBLESTONE)
B(-4,0,-8,COBBLESTONE)
B(-4,0,-7,COBBLESTONE)
B(-4,0,-6,GRAVEL)
B(-4,0,-5,AIR)
B(-4,0,-4,AIR)
B(-4,0,-3,AIR)
B(-4,0,-2,AIR)
B(-4,0,-1,GRAVEL)
B(-4,0,0,COBBLESTONE)
B(-4,0,1,COBBLESTONE)
B(-4,0,2,COBBLESTONE)
B(-4,0,3,LEAVES:3)
B(-4,0,4,LEAVES:3)
B(-4,0,5,LEAVES:3)
B(-4,0,6,DIRT)
B(-4,0,7,GRASS)
B(-4,0,8,DIRT)
B(-4,0,9,COBBLESTONE)
B(-4,0,10,COBBLESTONE)
B(-4,1,-8,COBBLESTONE)
B(-4,1,-7,COBBLESTONE)
B(-4,1,-6,AIR)
B(-4,1,-5,AIR)
B(-4,1,-4,AIR)
B(-4,1,-1,GRAVEL)
B(-4,1,4,LEAVES:3)
B(-4,1,5,LEAVES:3)
B(-4,1,6,LOG:3)
B(-4,1,7,LEAVES:3)
B(-4,1,8,COBBLESTONE)
B(-4,1,9,COBBLESTONE)
B(-4,1,10,COBBLESTONE)
B(-4,2,-8,COBBLESTONE)
B(-4,2,-7,COBBLESTONE)
B(-4,2,-6,STEP:8)
B(-4,2,-5,STEP:8)
B(-4,2,-4,DOUBLE_STEP)
B(-4,2,-3,STEP:8)
B(-4,2,6,LOG:3)
B(-4,2,8,COBBLESTONE)
B(-4,2,9,COBBLESTONE)
B(-4,2,10,COBBLESTONE)
B(-4,3,-9,COBBLESTONE)
B(-4,3,-8,COBBLESTONE)
B(-4,3,-7,COBBLESTONE)
B(-4,3,-6,COBBLESTONE)
B(-4,3,-5,COBBLESTONE)
B(-4,3,-4,GRASS)
B(-4,3,6,LOG:3)
B(-4,3,8,GRASS)
B(-4,3,9,GRASS)
B(-4,3,10,COBBLESTONE)
B(-4,4,-9,COBBLESTONE)
B(-4,4,-8,COBBLESTONE)
B(-4,4,-7,COBBLESTONE)
B(-4,4,-6,LEAVES:3)
B(-4,4,-5,LEAVES:3)
B(-4,4,-4,AIR)
B(-4,4,6,LOG:3)
B(-4,5,-9,COBBLESTONE)
B(-4,5,-8,COBBLESTONE)
B(-4,5,-7,LEAVES:3)
B(-4,5,-6,LEAVES:3)
B(-4,5,6,LOG:3)
B(-4,6,-9,COBBLESTONE)
B(-4,6,-8,COBBLESTONE)
B(-4,6,-7,AIR)
B(-4,6,-6,AIR)
B(-4,6,4,LEAVES:3)
B(-4,6,5,LEAVES:3)
B(-4,6,6,LEAVES:3)
B(-4,6,7,LEAVES:3)
B(-4,6,8,LEAVES:3)
B(-4,7,-10,LEAVES:3)
B(-4,7,-9,COBBLESTONE)
B(-4,7,-7,AIR)
B(-4,7,-6,AIR)
B(-4,7,5,LEAVES:3)
B(-4,7,6,LEAVES:3)
B(-4,7,7,LEAVES:3)
B(-4,8,-10,LEAVES:3)
B(-4,8,-9,COBBLESTONE)
B(-4,8,-8,STEP:8)
B(-4,8,-7,STEP:8)
B(-4,8,-6,STEP:8)
B(-4,8,-5,STEP:8)
B(-4,8,8,STEP:8)
B(-4,8,9,STEP:8)
B(-4,8,10,COBBLESTONE)
B(-4,9,-10,COBBLESTONE_STAIRS:6)
B(-4,9,-9,COBBLESTONE)
B(-4,9,-8,COBBLESTONE)
B(-4,9,-7,COBBLESTONE)
B(-4,9,-6,COBBLESTONE)
B(-4,9,-5,LEAVES:3)
B(-4,9,8,GRASS)
B(-4,9,9,DIRT:1)
B(-4,9,10,COBBLESTONE)
B(-4,10,-10,DOUBLE_STEP:5)
B(-4,10,-9,LEAVES:3)
B(-4,10,-8,GRASS)
B(-4,10,-7,GRASS)
B(-4,10,-6,COBBLESTONE_STAIRS:1)
B(-4,10,-5,LEAVES:3)
B(-4,10,9,GRASS)
B(-4,10,10,GRASS)
B(-4,10,11,STEP:5)
B(-4,11,-8,LEAVES:3)
B(-4,11,-6,COBBLESTONE)
B(-4,11,7,LEAVES:3)
B(-4,11,8,LEAVES:3)
B(-3,-16,-8,COBBLESTONE)
B(-3,-16,-7,COBBLESTONE)
B(-3,-16,-6,COBBLESTONE)
B(-3,-16,-5,COBBLESTONE)
B(-3,-16,-4,COBBLESTONE)
B(-3,-16,-3,COBBLESTONE)
B(-3,-16,-2,COBBLESTONE)
B(-3,-16,-1,COBBLESTONE)
B(-3,-16,0,COBBLESTONE)
B(-3,-16,1,COBBLESTONE)
B(-3,-16,2,COBBLESTONE)
B(-3,-16,3,COBBLESTONE)
B(-3,-16,4,COBBLESTONE)
B(-3,-16,5,COBBLESTONE)
B(-3,-16,6,COBBLESTONE)
B(-3,-16,7,COBBLESTONE)
B(-3,-16,8,COBBLESTONE)
B(-3,-16,9,COBBLESTONE)
B(-3,-15,-8,COBBLESTONE)
B(-3,-15,-7,COBBLESTONE)
B(-3,-15,-6,COBBLESTONE)
B(-3,-15,-5,COBBLESTONE)
B(-3,-15,-4,COBBLESTONE)
B(-3,-15,-3,COBBLESTONE)
B(-3,-15,-2,COBBLESTONE)
B(-3,-15,-1,COBBLESTONE)
B(-3,-15,0,COBBLESTONE)
B(-3,-15,1,COBBLESTONE)
B(-3,-15,2,COBBLESTONE)
B(-3,-15,3,COBBLESTONE)
B(-3,-15,4,COBBLESTONE)
B(-3,-15,5,COBBLESTONE)
B(-3,-15,6,COBBLESTONE)
B(-3,-15,7,COBBLESTONE)
B(-3,-15,8,COBBLESTONE)
B(-3,-15,9,COBBLESTONE)
B(-3,-14,-8,COBBLESTONE)
B(-3,-14,-7,COBBLESTONE)
B(-3,-14,-6,COBBLESTONE)
B(-3,-14,-5,COBBLESTONE)
B(-3,-14,-4,COBBLESTONE)
B(-3,-14,-3,COBBLESTONE)
B(-3,-14,-2,COBBLESTONE)
B(-3,-14,-1,COBBLESTONE)
B(-3,-14,0,COBBLESTONE)
B(-3,-14,1,COBBLESTONE)
B(-3,-14,2,COBBLESTONE)
B(-3,-14,3,COBBLESTONE)
B(-3,-14,4,COBBLESTONE)
B(-3,-14,5,COBBLESTONE)
B(-3,-14,6,COBBLESTONE)
B(-3,-14,7,COBBLESTONE)
B(-3,-14,8,COBBLESTONE)
B(-3,-14,9,COBBLESTONE)
B(-3,-13,-8,COBBLESTONE)
B(-3,-13,-7,COBBLESTONE)
B(-3,-13,-6,COBBLESTONE)
B(-3,-13,-5,COBBLESTONE)
B(-3,-13,-4,COBBLESTONE)
B(-3,-13,-3,COBBLESTONE)
B(-3,-13,-2,COBBLESTONE)
B(-3,-13,-1,COBBLESTONE)
B(-3,-13,0,COBBLESTONE)
B(-3,-13,1,COBBLESTONE)
B(-3,-13,2,COBBLESTONE)
B(-3,-13,3,COBBLESTONE)
B(-3,-13,4,COBBLESTONE)
B(-3,-13,5,COBBLESTONE)
B(-3,-13,6,COBBLESTONE)
B(-3,-13,7,COBBLESTONE)
B(-3,-13,8,COBBLESTONE)
B(-3,-13,9,COBBLESTONE)
B(-3,-12,-8,COBBLESTONE)
B(-3,-12,-7,COBBLESTONE)
B(-3,-12,-6,COBBLESTONE)
B(-3,-12,-5,COBBLESTONE)
B(-3,-12,-4,COBBLESTONE)
B(-3,-12,-3,COBBLESTONE)
B(-3,-12,-2,COBBLESTONE)
B(-3,-12,-1,COBBLESTONE)
B(-3,-12,0,COBBLESTONE)
B(-3,-12,1,COBBLESTONE)
B(-3,-12,2,COBBLESTONE)
B(-3,-12,3,COBBLESTONE)
B(-3,-12,4,COBBLESTONE)
B(-3,-12,5,COBBLESTONE)
B(-3,-12,6,COBBLESTONE)
B(-3,-12,7,COBBLESTONE)
B(-3,-12,8,COBBLESTONE)
B(-3,-12,9,COBBLESTONE)
B(-3,-11,-8,COBBLESTONE)
B(-3,-11,-7,COBBLESTONE)
B(-3,-11,-6,COBBLESTONE)
B(-3,-11,-5,COBBLESTONE)
B(-3,-11,-4,COBBLESTONE)
B(-3,-11,-3,COBBLESTONE)
B(-3,-11,-2,COBBLESTONE)
B(-3,-11,-1,COBBLESTONE)
B(-3,-11,0,COBBLESTONE)
B(-3,-11,1,COBBLESTONE)
B(-3,-11,2,COBBLESTONE)
B(-3,-11,3,COBBLESTONE)
B(-3,-11,4,COBBLESTONE)
B(-3,-11,5,COBBLESTONE)
B(-3,-11,6,COBBLESTONE)
B(-3,-11,7,COBBLESTONE)
B(-3,-11,8,COBBLESTONE)
B(-3,-11,9,COBBLESTONE)
B(-3,-10,-8,COBBLESTONE)
B(-3,-10,-7,COBBLESTONE)
B(-3,-10,-6,COBBLESTONE)
B(-3,-10,-5,COBBLESTONE)
B(-3,-10,-4,COBBLESTONE)
B(-3,-10,-3,COBBLESTONE)
B(-3,-10,-2,COBBLESTONE)
B(-3,-10,-1,COBBLESTONE)
B(-3,-10,0,COBBLESTONE)
B(-3,-10,1,COBBLESTONE)
B(-3,-10,2,COBBLESTONE)
B(-3,-10,3,COBBLESTONE)
B(-3,-10,4,COBBLESTONE)
B(-3,-10,5,COBBLESTONE)
B(-3,-10,6,COBBLESTONE)
B(-3,-10,7,COBBLESTONE)
B(-3,-10,8,COBBLESTONE)
B(-3,-10,9,COBBLESTONE)
B(-3,-9,-8,COBBLESTONE)
B(-3,-9,-7,COBBLESTONE)
B(-3,-9,-6,COBBLESTONE)
B(-3,-9,-5,COBBLESTONE)
B(-3,-9,-4,COBBLESTONE)
B(-3,-9,-3,COBBLESTONE)
B(-3,-9,-2,COBBLESTONE)
B(-3,-9,-1,COBBLESTONE)
B(-3,-9,0,COBBLESTONE)
B(-3,-9,1,COBBLESTONE)
B(-3,-9,2,COBBLESTONE)
B(-3,-9,3,COBBLESTONE)
B(-3,-9,4,COBBLESTONE)
B(-3,-9,5,COBBLESTONE)
B(-3,-9,6,COBBLESTONE)
B(-3,-9,7,COBBLESTONE)
B(-3,-9,8,COBBLESTONE)
B(-3,-9,9,COBBLESTONE)
B(-3,-8,-8,COBBLESTONE)
B(-3,-8,-7,COBBLESTONE)
B(-3,-8,-6,COBBLESTONE)
B(-3,-8,-5,COBBLESTONE)
B(-3,-8,-4,COBBLESTONE)
B(-3,-8,-3,COBBLESTONE)
B(-3,-8,-2,COBBLESTONE)
B(-3,-8,-1,COBBLESTONE)
B(-3,-8,0,COBBLESTONE)
B(-3,-8,1,COBBLESTONE)
B(-3,-8,2,COBBLESTONE)
B(-3,-8,3,COBBLESTONE)
B(-3,-8,4,COBBLESTONE)
B(-3,-8,5,COBBLESTONE)
B(-3,-8,6,COBBLESTONE)
B(-3,-8,7,COBBLESTONE)
B(-3,-8,8,COBBLESTONE)
B(-3,-8,9,COBBLESTONE)
B(-3,-7,-8,COBBLESTONE)
B(-3,-7,-7,COBBLESTONE)
B(-3,-7,-6,COBBLESTONE)
B(-3,-7,-5,COBBLESTONE)
B(-3,-7,-4,COBBLESTONE)
B(-3,-7,-3,COBBLESTONE)
B(-3,-7,-2,COBBLESTONE)
B(-3,-7,-1,COBBLESTONE)
B(-3,-7,0,COBBLESTONE)
B(-3,-7,1,COBBLESTONE)
B(-3,-7,2,COBBLESTONE)
B(-3,-7,3,COBBLESTONE)
B(-3,-7,4,COBBLESTONE)
B(-3,-7,5,COBBLESTONE)
B(-3,-7,6,COBBLESTONE)
B(-3,-7,7,COBBLESTONE)
B(-3,-7,8,COBBLESTONE)
B(-3,-7,9,COBBLESTONE)
B(-3,-6,-8,COBBLESTONE)
B(-3,-6,-7,COBBLESTONE)
B(-3,-6,-6,COBBLESTONE)
B(-3,-6,-5,COBBLESTONE)
B(-3,-6,-4,COBBLESTONE)
B(-3,-6,-3,COBBLESTONE)
B(-3,-6,-2,COBBLESTONE)
B(-3,-6,-1,COBBLESTONE)
B(-3,-6,0,COBBLESTONE)
B(-3,-6,1,COBBLESTONE)
B(-3,-6,2,COBBLESTONE)
B(-3,-6,3,COBBLESTONE)
B(-3,-6,4,COBBLESTONE)
B(-3,-6,5,COBBLESTONE)
B(-3,-6,6,COBBLESTONE)
B(-3,-6,7,COBBLESTONE)
B(-3,-6,8,COBBLESTONE)
B(-3,-6,9,COBBLESTONE)
B(-3,-5,-8,COBBLESTONE)
B(-3,-5,-7,COBBLESTONE)
B(-3,-5,-6,COBBLESTONE)
B(-3,-5,-5,COBBLESTONE)
B(-3,-5,-4,COBBLESTONE)
B(-3,-5,-3,COBBLESTONE)
B(-3,-5,-2,COBBLESTONE)
B(-3,-5,-1,COBBLESTONE)
B(-3,-5,0,COBBLESTONE)
B(-3,-5,1,COBBLESTONE)
B(-3,-5,2,COBBLESTONE)
B(-3,-5,3,COBBLESTONE)
B(-3,-5,4,COBBLESTONE)
B(-3,-5,5,COBBLESTONE)
B(-3,-5,6,COBBLESTONE)
B(-3,-5,7,COBBLESTONE)
B(-3,-5,8,COBBLESTONE)
B(-3,-5,9,COBBLESTONE)
B(-3,-4,-8,COBBLESTONE)
B(-3,-4,-7,COBBLESTONE)
B(-3,-4,-6,COBBLESTONE)
B(-3,-4,-5,COBBLESTONE)
B(-3,-4,-4,COBBLESTONE)
B(-3,-4,-3,COBBLESTONE)
B(-3,-4,-2,COBBLESTONE)
B(-3,-4,-1,COBBLESTONE)
B(-3,-4,0,COBBLESTONE)
B(-3,-4,1,COBBLESTONE)
B(-3,-4,2,COBBLESTONE)
B(-3,-4,3,COBBLESTONE)
B(-3,-4,4,COBBLESTONE)
B(-3,-4,5,COBBLESTONE)
B(-3,-4,6,COBBLESTONE)
B(-3,-4,7,COBBLESTONE)
B(-3,-4,8,COBBLESTONE)
B(-3,-4,9,COBBLESTONE)
B(-3,-3,-8,COBBLESTONE)
B(-3,-3,-7,COBBLESTONE)
B(-3,-3,-6,COBBLESTONE)
B(-3,-3,-5,COBBLESTONE)
B(-3,-3,-4,COBBLESTONE)
B(-3,-3,-3,COBBLESTONE)
B(-3,-3,-2,COBBLESTONE)
B(-3,-3,-1,COBBLESTONE)
B(-3,-3,0,COBBLESTONE)
B(-3,-3,1,COBBLESTONE)
B(-3,-3,2,COBBLESTONE)
B(-3,-3,3,COBBLESTONE)
B(-3,-3,4,COBBLESTONE)
B(-3,-3,5,COBBLESTONE)
B(-3,-3,6,COBBLESTONE)
B(-3,-3,7,COBBLESTONE)
B(-3,-3,8,COBBLESTONE)
B(-3,-3,9,COBBLESTONE)
B(-3,-2,-9,COBBLESTONE)
B(-3,-2,-8,COBBLESTONE)
B(-3,-2,-7,COBBLESTONE)
B(-3,-2,-6,STEP:8)
B(-3,-2,-5,STEP:8)
B(-3,-2,-4,STEP:8)
B(-3,-2,-3,STEP:8)
B(-3,-2,-2,STEP:8)
B(-3,-2,-1,STEP:8)
B(-3,-2,0,STEP:8)
B(-3,-2,1,STEP:8)
B(-3,-2,2,COBBLESTONE)
B(-3,-2,3,STEP:8)
B(-3,-2,4,STEP:8)
B(-3,-2,5,STEP:8)
B(-3,-2,6,STEP:8)
B(-3,-2,7,STEP:8)
B(-3,-2,8,STEP:8)
B(-3,-2,9,STEP:8)
B(-3,-2,10,COBBLESTONE)
B(-3,-1,-8,COBBLESTONE)
B(-3,-1,-7,COBBLESTONE)
B(-3,-1,-6,GRAVEL)
B(-3,-1,-5,GRAVEL)
B(-3,-1,-4,STEP)
B(-3,-1,-3,AIR)
B(-3,-1,-2,STEP)
B(-3,-1,-1,COBBLESTONE)
B(-3,-1,0,DOUBLE_STEP)
B(-3,-1,1,COBBLESTONE)
B(-3,-1,2,STEP)
B(-3,-1,3,GRAVEL)
B(-3,-1,4,STEP)
B(-3,-1,5,GRASS)
B(-3,-1,6,GRASS)
B(-3,-1,7,DIRT)
B(-3,-1,8,DIRT)
B(-3,-1,9,COBBLESTONE)
B(-3,0,-8,COBBLESTONE)
B(-3,0,-7,COBBLESTONE)
B(-3,0,-6,AIR)
B(-3,0,-5,AIR)
B(-3,0,-4,AIR)
B(-3,0,-3,AIR)
B(-3,0,-2,AIR)
B(-3,0,-1,GRAVEL)
B(-3,0,0,AIR)
B(-3,0,1,STEP)
B(-3,0,2,AIR)
B(-3,0,3,AIR)
B(-3,0,4,LEAVES:3)
B(-3,0,5,LEAVES:3)
B(-3,0,6,AIR)
B(-3,0,7,GRASS)
B(-3,0,8,GRASS)
B(-3,0,9,COBBLESTONE)
B(-3,1,-8,COBBLESTONE)
B(-3,1,-7,COBBLESTONE)
B(-3,1,-6,AIR)
Entity(-3,1,-6,Zombie,3,Husk.txt)
B(-3,1,-5,AIR)
B(-3,1,-4,AIR)
B(-3,1,-3,AIR)
B(-3,1,-2,AIR)
B(-3,1,-1,AIR)
B(-3,1,0,AIR)
B(-3,1,1,AIR)
B(-3,1,2,AIR)
B(-3,1,3,AIR)
B(-3,1,4,AIR)
B(-3,1,5,LEAVES:3)
B(-3,1,9,COBBLESTONE)
B(-3,2,-9,COBBLESTONE_STAIRS:4)
B(-3,2,-8,COBBLESTONE)
B(-3,2,-7,COBBLESTONE)
B(-3,2,-6,DOUBLE_STEP)
B(-3,2,-5,DOUBLE_STEP)
B(-3,2,-4,STEP:8)
B(-3,2,-3,AIR)
B(-3,2,-2,AIR)
B(-3,2,-1,AIR)
B(-3,2,0,AIR)
B(-3,2,1,AIR)
B(-3,2,2,AIR)
B(-3,2,3,AIR)
B(-3,2,4,AIR)
B(-3,2,5,LEAVES:3)
B(-3,2,6,AIR)
B(-3,2,7,AIR)
B(-3,2,8,STEP:8)
B(-3,2,9,COBBLESTONE)
B(-3,3,-9,COBBLESTONE)
B(-3,3,-8,COBBLESTONE)
B(-3,3,-7,COBBLESTONE)
B(-3,3,-6,GRASS)
B(-3,3,-5,GRASS)
B(-3,3,-4,GRASS)
B(-3,3,-3,AIR)
B(-3,3,-2,AIR)
B(-3,3,-1,AIR)
B(-3,3,0,AIR)
B(-3,3,1,AIR)
B(-3,3,2,AIR)
B(-3,3,3,AIR)
B(-3,3,4,AIR)
B(-3,3,5,AIR)
B(-3,3,6,AIR)
B(-3,3,7,AIR)
B(-3,3,8,DIRT:1)
B(-3,3,9,COBBLESTONE)
B(-3,3,10,COBBLESTONE)
B(-3,4,-8,COBBLESTONE)
B(-3,4,-7,AIR)
B(-3,4,-6,LEAVES:3)
B(-3,4,-5,LEAVES:3)
B(-3,4,-4,LEAVES:3)
B(-3,4,-3,AIR)
B(-3,4,-2,AIR)
B(-3,4,-1,AIR)
B(-3,4,0,AIR)
B(-3,4,1,AIR)
B(-3,4,2,AIR)
B(-3,4,3,AIR)
B(-3,4,4,AIR)
B(-3,4,5,AIR)
B(-3,4,6,AIR)
B(-3,4,7,AIR)
B(-3,4,8,AIR)
B(-3,4,9,STEP)
B(-3,5,-8,LEAVES:3)
B(-3,5,-7,AIR)
B(-3,5,-6,AIR)
B(-3,5,-5,LEAVES:3)
B(-3,5,-4,AIR)
B(-3,5,-3,AIR)
B(-3,5,-2,AIR)
B(-3,5,-1,AIR)
B(-3,5,0,AIR)
B(-3,5,1,AIR)
B(-3,5,2,AIR)
B(-3,5,3,AIR)
B(-3,5,4,AIR)
B(-3,5,5,AIR)
B(-3,5,6,AIR)
B(-3,5,7,AIR)
B(-3,5,8,AIR)
B(-3,5,9,AIR)
B(-3,6,-9,LEAVES:3)
B(-3,6,-8,LEAVES:3)
B(-3,6,-7,AIR)
B(-3,6,-6,AIR)
B(-3,6,-5,AIR)
B(-3,6,-4,AIR)
B(-3,6,-3,AIR)
B(-3,6,-2,AIR)
B(-3,6,-1,AIR)
B(-3,6,0,AIR)
B(-3,6,1,AIR)
B(-3,6,2,AIR)
B(-3,6,3,AIR)
B(-3,6,4,LEAVES:3)
B(-3,6,5,LEAVES:3)
B(-3,6,6,LEAVES:3)
B(-3,6,7,LEAVES:3)
B(-3,6,8,LEAVES:3)
B(-3,6,9,AIR)
B(-3,7,-9,LEAVES:3)
B(-3,7,-7,AIR)
B(-3,7,-6,AIR)
B(-3,7,-5,AIR)
B(-3,7,-4,AIR)
B(-3,7,-3,AIR)
B(-3,7,-2,AIR)
B(-3,7,-1,AIR)
B(-3,7,0,AIR)
B(-3,7,1,AIR)
B(-3,7,2,AIR)
B(-3,7,3,AIR)
B(-3,7,4,AIR)
B(-3,7,5,LEAVES:3)
B(-3,7,6,LEAVES:3)
B(-3,7,7,LEAVES:3)
B(-3,7,8,AIR)
B(-3,7,9,AIR)
B(-3,8,-9,COBBLESTONE_STAIRS:5)
B(-3,8,-8,STEP:8)
B(-3,8,-7,STEP:8)
B(-3,8,-6,STEP:8)
B(-3,8,-5,AIR)
B(-3,8,-4,AIR)
B(-3,8,-3,AIR)
B(-3,8,-2,AIR)
B(-3,8,-1,AIR)
B(-3,8,0,AIR)
B(-3,8,1,AIR)
B(-3,8,2,AIR)
B(-3,8,3,AIR)
B(-3,8,4,AIR)
B(-3,8,5,AIR)
B(-3,8,6,AIR)
B(-3,8,7,STEP:8)
B(-3,8,8,STEP:8)
B(-3,8,9,STEP:8)
B(-3,8,10,COBBLESTONE_STAIRS:5)
B(-3,9,-9,COBBLESTONE)
B(-3,9,-8,COBBLESTONE)
B(-3,9,-7,COBBLESTONE)
B(-3,9,-6,LEAVES:3)
B(-3,9,7,COBBLESTONE)
B(-3,9,8,COBBLESTONE)
B(-3,9,9,COBBLESTONE)
B(-3,9,10,COBBLESTONE)
B(-3,9,11,COBBLESTONE_STAIRS:7)
B(-3,10,-10,STEP:5)
B(-3,10,-9,GRASS)
B(-3,10,-8,GRASS)
B(-3,10,-7,GRASS)
B(-3,10,7,GRASS)
B(-3,10,8,GRASS)
B(-3,10,9,GRASS)
B(-3,10,10,GRASS)
B(-3,10,11,DOUBLE_STEP:5)
B(-3,11,-9,LEAVES:3)
B(-3,11,-8,LEAVES:3)
B(-3,11,6,LEAVES:3)
B(-3,11,7,LEAVES:3)
B(-3,11,8,LEAVES:3)
B(-3,11,9,LEAVES:3)
B(-3,12,7,LEAVES:3)
B(-3,12,8,LEAVES:3)
B(-2,-16,-9,COBBLESTONE)
B(-2,-16,-8,COBBLESTONE)
B(-2,-16,-7,COBBLESTONE)
B(-2,-16,-6,COBBLESTONE)
B(-2,-16,-5,COBBLESTONE)
B(-2,-16,-4,COBBLESTONE)
B(-2,-16,-3,COBBLESTONE)
B(-2,-16,-2,COBBLESTONE)
B(-2,-16,-1,COBBLESTONE)
B(-2,-16,0,COBBLESTONE)
B(-2,-16,1,COBBLESTONE)
B(-2,-16,2,COBBLESTONE)
B(-2,-16,3,COBBLESTONE)
B(-2,-16,4,COBBLESTONE)
B(-2,-16,5,COBBLESTONE)
B(-2,-16,6,COBBLESTONE)
B(-2,-16,7,COBBLESTONE)
B(-2,-16,8,COBBLESTONE)
B(-2,-16,9,COBBLESTONE)
B(-2,-15,-9,COBBLESTONE)
B(-2,-15,-8,COBBLESTONE)
B(-2,-15,-7,COBBLESTONE)
B(-2,-15,-6,COBBLESTONE)
B(-2,-15,-5,COBBLESTONE)
B(-2,-15,-4,COBBLESTONE)
B(-2,-15,-3,COBBLESTONE)
B(-2,-15,-2,COBBLESTONE)
B(-2,-15,-1,COBBLESTONE)
B(-2,-15,0,COBBLESTONE)
B(-2,-15,1,COBBLESTONE)
B(-2,-15,2,COBBLESTONE)
B(-2,-15,3,COBBLESTONE)
B(-2,-15,4,COBBLESTONE)
B(-2,-15,5,COBBLESTONE)
B(-2,-15,6,COBBLESTONE)
B(-2,-15,7,COBBLESTONE)
B(-2,-15,8,COBBLESTONE)
B(-2,-15,9,COBBLESTONE)
B(-2,-14,-9,COBBLESTONE)
B(-2,-14,-8,COBBLESTONE)
B(-2,-14,-7,COBBLESTONE)
B(-2,-14,-6,COBBLESTONE)
B(-2,-14,-5,COBBLESTONE)
B(-2,-14,-4,COBBLESTONE)
B(-2,-14,-3,COBBLESTONE)
B(-2,-14,-2,COBBLESTONE)
B(-2,-14,-1,COBBLESTONE)
B(-2,-14,0,COBBLESTONE)
B(-2,-14,1,COBBLESTONE)
B(-2,-14,2,COBBLESTONE)
B(-2,-14,3,COBBLESTONE)
B(-2,-14,4,COBBLESTONE)
B(-2,-14,5,COBBLESTONE)
B(-2,-14,6,COBBLESTONE)
B(-2,-14,7,COBBLESTONE)
B(-2,-14,8,COBBLESTONE)
B(-2,-14,9,COBBLESTONE)
B(-2,-13,-9,COBBLESTONE)
B(-2,-13,-8,COBBLESTONE)
B(-2,-13,-7,COBBLESTONE)
B(-2,-13,-6,COBBLESTONE)
B(-2,-13,-5,COBBLESTONE)
B(-2,-13,-4,COBBLESTONE)
B(-2,-13,-3,COBBLESTONE)
B(-2,-13,-2,COBBLESTONE)
B(-2,-13,-1,COBBLESTONE)
B(-2,-13,0,COBBLESTONE)
B(-2,-13,1,COBBLESTONE)
B(-2,-13,2,COBBLESTONE)
B(-2,-13,3,COBBLESTONE)
B(-2,-13,4,COBBLESTONE)
B(-2,-13,5,COBBLESTONE)
B(-2,-13,6,COBBLESTONE)
B(-2,-13,7,COBBLESTONE)
B(-2,-13,8,COBBLESTONE)
B(-2,-13,9,COBBLESTONE)
B(-2,-12,-9,COBBLESTONE)
B(-2,-12,-8,COBBLESTONE)
B(-2,-12,-7,COBBLESTONE)
B(-2,-12,-6,COBBLESTONE)
B(-2,-12,-5,COBBLESTONE)
B(-2,-12,-4,COBBLESTONE)
B(-2,-12,-3,COBBLESTONE)
B(-2,-12,-2,COBBLESTONE)
B(-2,-12,-1,COBBLESTONE)
B(-2,-12,0,COBBLESTONE)
B(-2,-12,1,COBBLESTONE)
B(-2,-12,2,COBBLESTONE)
B(-2,-12,3,COBBLESTONE)
B(-2,-12,4,COBBLESTONE)
B(-2,-12,5,COBBLESTONE)
B(-2,-12,6,COBBLESTONE)
B(-2,-12,7,COBBLESTONE)
B(-2,-12,8,COBBLESTONE)
B(-2,-12,9,COBBLESTONE)
B(-2,-11,-9,COBBLESTONE)
B(-2,-11,-8,COBBLESTONE)
B(-2,-11,-7,COBBLESTONE)
B(-2,-11,-6,COBBLESTONE)
B(-2,-11,-5,COBBLESTONE)
B(-2,-11,-4,COBBLESTONE)
B(-2,-11,-3,COBBLESTONE)
B(-2,-11,-2,COBBLESTONE)
B(-2,-11,-1,COBBLESTONE)
B(-2,-11,0,COBBLESTONE)
B(-2,-11,1,COBBLESTONE)
B(-2,-11,2,COBBLESTONE)
B(-2,-11,3,COBBLESTONE)
B(-2,-11,4,COBBLESTONE)
B(-2,-11,5,COBBLESTONE)
B(-2,-11,6,COBBLESTONE)
B(-2,-11,7,COBBLESTONE)
B(-2,-11,8,COBBLESTONE)
B(-2,-11,9,COBBLESTONE)
B(-2,-10,-9,COBBLESTONE)
B(-2,-10,-8,COBBLESTONE)
B(-2,-10,-7,COBBLESTONE)
B(-2,-10,-6,COBBLESTONE)
B(-2,-10,-5,COBBLESTONE)
B(-2,-10,-4,COBBLESTONE)
B(-2,-10,-3,COBBLESTONE)
B(-2,-10,-2,COBBLESTONE)
B(-2,-10,-1,COBBLESTONE)
B(-2,-10,0,COBBLESTONE)
B(-2,-10,1,COBBLESTONE)
B(-2,-10,2,COBBLESTONE)
B(-2,-10,3,COBBLESTONE)
B(-2,-10,4,COBBLESTONE)
B(-2,-10,5,COBBLESTONE)
B(-2,-10,6,COBBLESTONE)
B(-2,-10,7,COBBLESTONE)
B(-2,-10,8,COBBLESTONE)
B(-2,-10,9,COBBLESTONE)
B(-2,-9,-9,COBBLESTONE)
B(-2,-9,-8,COBBLESTONE)
B(-2,-9,-7,COBBLESTONE)
B(-2,-9,-6,COBBLESTONE)
B(-2,-9,-5,COBBLESTONE)
B(-2,-9,-4,COBBLESTONE)
B(-2,-9,-3,COBBLESTONE)
B(-2,-9,-2,COBBLESTONE)
B(-2,-9,-1,COBBLESTONE)
B(-2,-9,0,COBBLESTONE)
B(-2,-9,1,COBBLESTONE)
B(-2,-9,2,COBBLESTONE)
B(-2,-9,3,COBBLESTONE)
B(-2,-9,4,COBBLESTONE)
B(-2,-9,5,COBBLESTONE)
B(-2,-9,6,COBBLESTONE)
B(-2,-9,7,COBBLESTONE)
B(-2,-9,8,COBBLESTONE)
B(-2,-9,9,COBBLESTONE)
B(-2,-8,-9,COBBLESTONE)
B(-2,-8,-8,COBBLESTONE)
B(-2,-8,-7,COBBLESTONE)
B(-2,-8,-6,COBBLESTONE)
B(-2,-8,-5,COBBLESTONE)
B(-2,-8,-4,COBBLESTONE)
B(-2,-8,-3,COBBLESTONE)
B(-2,-8,-2,COBBLESTONE)
B(-2,-8,-1,COBBLESTONE)
B(-2,-8,0,COBBLESTONE)
B(-2,-8,1,COBBLESTONE)
B(-2,-8,2,COBBLESTONE)
B(-2,-8,3,COBBLESTONE)
B(-2,-8,4,COBBLESTONE)
B(-2,-8,5,COBBLESTONE)
B(-2,-8,6,COBBLESTONE)
B(-2,-8,7,COBBLESTONE)
B(-2,-8,8,COBBLESTONE)
B(-2,-8,9,COBBLESTONE)
B(-2,-7,-9,COBBLESTONE)
B(-2,-7,-8,COBBLESTONE)
B(-2,-7,-7,COBBLESTONE)
B(-2,-7,-6,COBBLESTONE)
B(-2,-7,-5,COBBLESTONE)
B(-2,-7,-4,COBBLESTONE)
B(-2,-7,-3,COBBLESTONE)
B(-2,-7,-2,COBBLESTONE)
B(-2,-7,-1,COBBLESTONE)
B(-2,-7,0,COBBLESTONE)
B(-2,-7,1,COBBLESTONE)
B(-2,-7,2,COBBLESTONE)
B(-2,-7,3,COBBLESTONE)
B(-2,-7,4,COBBLESTONE)
B(-2,-7,5,COBBLESTONE)
B(-2,-7,6,COBBLESTONE)
B(-2,-7,7,COBBLESTONE)
B(-2,-7,8,COBBLESTONE)
B(-2,-7,9,COBBLESTONE)
B(-2,-6,-9,COBBLESTONE)
B(-2,-6,-8,COBBLESTONE)
B(-2,-6,-7,COBBLESTONE)
B(-2,-6,-6,COBBLESTONE)
B(-2,-6,-5,COBBLESTONE)
B(-2,-6,-4,COBBLESTONE)
B(-2,-6,-3,COBBLESTONE)
B(-2,-6,-2,COBBLESTONE)
B(-2,-6,-1,COBBLESTONE)
B(-2,-6,0,COBBLESTONE)
B(-2,-6,1,COBBLESTONE)
B(-2,-6,2,COBBLESTONE)
B(-2,-6,3,COBBLESTONE)
B(-2,-6,4,COBBLESTONE)
B(-2,-6,5,COBBLESTONE)
B(-2,-6,6,COBBLESTONE)
B(-2,-6,7,COBBLESTONE)
B(-2,-6,8,COBBLESTONE)
B(-2,-6,9,COBBLESTONE)
B(-2,-5,-9,COBBLESTONE)
B(-2,-5,-8,COBBLESTONE)
B(-2,-5,-7,COBBLESTONE)
B(-2,-5,-6,COBBLESTONE)
B(-2,-5,-5,COBBLESTONE)
B(-2,-5,-4,COBBLESTONE)
B(-2,-5,-3,COBBLESTONE)
B(-2,-5,-2,COBBLESTONE)
B(-2,-5,-1,COBBLESTONE)
B(-2,-5,0,COBBLESTONE)
B(-2,-5,1,COBBLESTONE)
B(-2,-5,2,COBBLESTONE)
B(-2,-5,3,COBBLESTONE)
B(-2,-5,4,COBBLESTONE)
B(-2,-5,5,COBBLESTONE)
B(-2,-5,6,COBBLESTONE)
B(-2,-5,7,COBBLESTONE)
B(-2,-5,8,COBBLESTONE)
B(-2,-5,9,COBBLESTONE)
B(-2,-4,-9,COBBLESTONE)
B(-2,-4,-8,COBBLESTONE)
B(-2,-4,-7,COBBLESTONE)
B(-2,-4,-6,COBBLESTONE)
B(-2,-4,-5,COBBLESTONE)
B(-2,-4,-4,COBBLESTONE)
B(-2,-4,-3,COBBLESTONE)
B(-2,-4,-2,COBBLESTONE)
B(-2,-4,-1,COBBLESTONE)
B(-2,-4,0,COBBLESTONE)
B(-2,-4,1,COBBLESTONE)
B(-2,-4,2,COBBLESTONE)
B(-2,-4,3,COBBLESTONE)
B(-2,-4,4,COBBLESTONE)
B(-2,-4,5,COBBLESTONE)
B(-2,-4,6,COBBLESTONE)
B(-2,-4,7,COBBLESTONE)
B(-2,-4,8,COBBLESTONE)
B(-2,-4,9,COBBLESTONE)
B(-2,-3,-9,COBBLESTONE)
B(-2,-3,-8,COBBLESTONE)
B(-2,-3,-7,COBBLESTONE)
B(-2,-3,-6,COBBLESTONE)
B(-2,-3,-5,COBBLESTONE)
B(-2,-3,-4,COBBLESTONE)
B(-2,-3,-3,COBBLESTONE)
B(-2,-3,-2,COBBLESTONE)
B(-2,-3,-1,COBBLESTONE)
B(-2,-3,0,COBBLESTONE)
B(-2,-3,1,COBBLESTONE)
B(-2,-3,2,COBBLESTONE)
B(-2,-3,3,COBBLESTONE)
B(-2,-3,4,COBBLESTONE)
B(-2,-3,5,COBBLESTONE)
B(-2,-3,6,COBBLESTONE)
B(-2,-3,7,COBBLESTONE)
B(-2,-3,8,COBBLESTONE)
B(-2,-3,9,COBBLESTONE)
B(-2,-2,-9,COBBLESTONE)
B(-2,-2,-8,COBBLESTONE)
B(-2,-2,-7,COBBLESTONE)
B(-2,-2,-6,COBBLESTONE)
B(-2,-2,-5,COBBLESTONE)
B(-2,-2,-4,COBBLESTONE)
B(-2,-2,-3,COBBLESTONE)
B(-2,-2,-2,COBBLESTONE)
B(-2,-2,-1,COBBLESTONE)
B(-2,-2,0,COBBLESTONE)
B(-2,-2,1,COBBLESTONE)
B(-2,-2,2,COBBLESTONE)
B(-2,-2,3,STEP:8)
B(-2,-2,4,STEP:8)
B(-2,-2,5,STEP:8)
B(-2,-2,6,STEP:8)
B(-2,-2,7,STEP:8)
B(-2,-2,8,STEP:8)
B(-2,-2,9,STEP:8)
B(-2,-2,10,COBBLESTONE)
B(-2,-1,-9,COBBLESTONE)
B(-2,-1,-8,COBBLESTONE)
B(-2,-1,-7,COBBLESTONE)
B(-2,-1,-6,AIR)
B(-2,-1,-5,GRAVEL)
B(-2,-1,-4,GRAVEL)
B(-2,-1,-3,GRAVEL)
B(-2,-1,-2,GRAVEL)
B(-2,-1,-1,STEP)
B(-2,-1,0,STEP)
B(-2,-1,1,COBBLESTONE)
B(-2,-1,2,COBBLESTONE)
B(-2,-1,3,STEP)
B(-2,-1,4,GRAVEL)
B(-2,-1,5,GRAVEL)
B(-2,-1,6,GRASS)
B(-2,-1,7,GRASS)
B(-2,-1,8,GRASS)
B(-2,-1,9,COBBLESTONE)
B(-2,0,-9,COBBLESTONE)
B(-2,0,-8,COBBLESTONE)
B(-2,0,-7,COBBLESTONE)
B(-2,0,-6,AIR)
B(-2,0,-5,AIR)
B(-2,0,-4,AIR)
B(-2,0,-3,AIR)
B(-2,0,-2,AIR)
B(-2,0,-1,AIR)
B(-2,0,0,AIR)
B(-2,0,1,AIR)
B(-2,0,2,STEP)
B(-2,0,3,AIR)
B(-2,0,4,AIR)
B(-2,0,5,LEAVES:3)
B(-2,0,6,AIR)
B(-2,0,7,AIR)
B(-2,0,8,AIR)
B(-2,0,9,COBBLESTONE)
B(-2,1,-9,COBBLESTONE)
B(-2,1,-8,COBBLESTONE)
B(-2,1,-7,COBBLESTONE)
B(-2,1,-6,AIR)
B(-2,1,-5,AIR)
B(-2,1,-4,AIR)
B(-2,1,-3,AIR)
B(-2,1,-2,AIR)
B(-2,1,-1,AIR)
B(-2,1,0,AIR)
B(-2,1,1,AIR)
B(-2,1,2,AIR)
B(-2,1,3,AIR)
B(-2,1,4,AIR)
B(-2,1,9,COBBLESTONE)
B(-2,2,-9,COBBLESTONE)
B(-2,2,-8,COBBLESTONE)
B(-2,2,-7,COBBLESTONE)
B(-2,2,-6,DOUBLE_STEP)
B(-2,2,-5,DOUBLE_STEP)
B(-2,2,-4,AIR)
B(-2,2,-3,AIR)
B(-2,2,-2,AIR)
B(-2,2,-1,AIR)
B(-2,2,0,AIR)
B(-2,2,1,AIR)
B(-2,2,2,AIR)
B(-2,2,3,AIR)
B(-2,2,4,AIR)
B(-2,2,5,STEP:8)
B(-2,2,6,STEP:8)
B(-2,2,7,STEP:8)
B(-2,2,8,AIR)
B(-2,2,9,COBBLESTONE)
B(-2,3,-9,COBBLESTONE)
B(-2,3,-8,COBBLESTONE)
B(-2,3,-7,COBBLESTONE)
B(-2,3,-6,COBBLESTONE)
B(-2,3,-5,GRASS)
B(-2,3,-4,AIR)
B(-2,3,-3,AIR)
B(-2,3,-2,AIR)
B(-2,3,-1,AIR)
B(-2,3,0,AIR)
B(-2,3,1,AIR)
B(-2,3,2,AIR)
B(-2,3,3,AIR)
B(-2,3,4,AIR)
B(-2,3,5,LEAVES:3)
B(-2,3,6,GRASS)
B(-2,3,7,DIRT:1)
B(-2,3,8,DIRT:1)
B(-2,3,9,COBBLESTONE)
B(-2,3,10,COBBLESTONE)
B(-2,4,-8,LEAVES:3)
B(-2,4,-7,AIR)
B(-2,4,-6,COBBLESTONE)
B(-2,4,-5,LEAVES:3)
B(-2,4,-4,AIR)
B(-2,4,-3,AIR)
B(-2,4,-2,AIR)
B(-2,4,-1,AIR)
B(-2,4,0,AIR)
B(-2,4,1,AIR)
B(-2,4,2,AIR)
B(-2,4,3,AIR)
B(-2,4,4,AIR)
B(-2,4,5,AIR)
B(-2,4,6,AIR)
B(-2,4,7,AIR)
B(-2,4,8,AIR)
B(-2,4,9,COBBLESTONE)
B(-2,4,10,LEAVES:3)
B(-2,5,-9,LEAVES:3)
B(-2,5,-7,AIR)
B(-2,5,-6,COBBLESTONE)
B(-2,5,-5,AIR)
B(-2,5,-4,AIR)
B(-2,5,-3,AIR)
B(-2,5,-2,AIR)
B(-2,5,-1,AIR)
B(-2,5,0,AIR)
B(-2,5,1,AIR)
B(-2,5,2,AIR)
B(-2,5,3,AIR)
B(-2,5,4,AIR)
B(-2,5,5,AIR)
B(-2,5,6,AIR)
B(-2,5,7,AIR)
B(-2,5,8,AIR)
B(-2,5,9,AIR)
B(-2,5,10,LEAVES:3)
B(-2,6,-7,AIR)
B(-2,6,-6,STEP)
B(-2,6,-5,AIR)
B(-2,6,-4,AIR)
B(-2,6,-3,AIR)
B(-2,6,-2,AIR)
B(-2,6,-1,AIR)
B(-2,6,0,AIR)
B(-2,6,1,AIR)
B(-2,6,2,AIR)
B(-2,6,3,AIR)
B(-2,6,4,AIR)
B(-2,6,5,LEAVES:3)
B(-2,6,6,LEAVES:3)
B(-2,6,7,LEAVES:3)
B(-2,6,8,AIR)
B(-2,6,9,AIR)
B(-2,6,10,LEAVES:3)
B(-2,7,-7,AIR)
B(-2,7,-6,AIR)
B(-2,7,-5,AIR)
B(-2,7,-4,AIR)
B(-2,7,-3,AIR)
B(-2,7,-2,AIR)
B(-2,7,-1,AIR)
B(-2,7,0,AIR)
B(-2,7,1,AIR)
B(-2,7,2,AIR)
B(-2,7,3,AIR)
B(-2,7,4,AIR)
B(-2,7,5,AIR)
B(-2,7,6,AIR)
B(-2,7,7,AIR)
B(-2,7,8,AIR)
B(-2,7,9,AIR)
B(-2,8,-9,COBBLESTONE_STAIRS:4)
B(-2,8,-8,STEP:8)
B(-2,8,-7,STEP:8)
B(-2,8,-6,STEP:8)
B(-2,8,-5,AIR)
B(-2,8,-4,AIR)
B(-2,8,-3,AIR)
B(-2,8,-2,AIR)
B(-2,8,-1,AIR)
B(-2,8,0,AIR)
B(-2,8,1,AIR)
B(-2,8,2,AIR)
B(-2,8,3,AIR)
B(-2,8,4,AIR)
B(-2,8,5,AIR)
B(-2,8,6,AIR)
B(-2,8,7,STEP:8)
B(-2,8,8,STEP:8)
B(-2,8,9,STEP:8)
B(-2,8,10,COBBLESTONE_STAIRS:4)
B(-2,9,-10,COBBLESTONE_STAIRS:6)
B(-2,9,-9,COBBLESTONE)
B(-2,9,-8,COBBLESTONE)
B(-2,9,-7,COBBLESTONE)
B(-2,9,-6,COBBLESTONE)
B(-2,9,-5,LEAVES:3)
B(-2,9,7,COBBLESTONE)
B(-2,9,8,COBBLESTONE)
B(-2,9,9,COBBLESTONE)
B(-2,9,10,COBBLESTONE)
B(-2,9,11,LEAVES:3)
B(-2,10,-10,DOUBLE_STEP:5)
B(-2,10,-9,GRASS)
B(-2,10,-8,GRASS)
B(-2,10,-7,COBBLESTONE_STAIRS:2)
B(-2,10,-6,LEAVES:3)
B(-2,10,8,DIRT)
B(-2,10,9,GRASS)
B(-2,10,10,LEAVES:3)
B(-2,11,-8,LEAVES:3)
B(-2,11,-7,COBBLESTONE_STAIRS:2)
B(-2,11,6,LEAVES:3)
B(-2,11,7,LEAVES:3)
B(-2,11,8,LOG:3)
B(-2,11,9,LEAVES:3)
B(-2,11,10,LEAVES:3)
B(-2,12,-7,COBBLESTONE_STAIRS:2)
B(-2,12,7,LEAVES:3)
B(-2,12,8,LEAVES:3)
B(-2,12,9,LEAVES:3)
B(-1,-16,-8,COBBLESTONE)
B(-1,-16,-7,COBBLESTONE)
B(-1,-16,-6,COBBLESTONE)
B(-1,-16,-5,COBBLESTONE)
B(-1,-16,-4,COBBLESTONE)
B(-1,-16,-3,COBBLESTONE)
B(-1,-16,-2,COBBLESTONE)
B(-1,-16,-1,COBBLESTONE)
B(-1,-16,0,COBBLESTONE)
B(-1,-16,1,COBBLESTONE)
B(-1,-16,2,COBBLESTONE)
B(-1,-16,3,COBBLESTONE)
B(-1,-16,4,COBBLESTONE)
B(-1,-16,5,COBBLESTONE)
B(-1,-16,6,COBBLESTONE)
B(-1,-16,7,COBBLESTONE)
B(-1,-16,8,COBBLESTONE)
B(-1,-16,9,COBBLESTONE)
B(-1,-16,10,COBBLESTONE)
B(-1,-15,-8,COBBLESTONE)
B(-1,-15,-7,COBBLESTONE)
B(-1,-15,-6,COBBLESTONE)
B(-1,-15,-5,COBBLESTONE)
B(-1,-15,-4,COBBLESTONE)
B(-1,-15,-3,COBBLESTONE)
B(-1,-15,-2,COBBLESTONE)
B(-1,-15,-1,COBBLESTONE)
B(-1,-15,0,COBBLESTONE)
B(-1,-15,1,COBBLESTONE)
B(-1,-15,2,COBBLESTONE)
B(-1,-15,3,COBBLESTONE)
B(-1,-15,4,COBBLESTONE)
B(-1,-15,5,COBBLESTONE)
B(-1,-15,6,COBBLESTONE)
B(-1,-15,7,COBBLESTONE)
B(-1,-15,8,COBBLESTONE)
B(-1,-15,9,COBBLESTONE)
B(-1,-15,10,COBBLESTONE)
B(-1,-14,-8,COBBLESTONE)
B(-1,-14,-7,COBBLESTONE)
B(-1,-14,-6,COBBLESTONE)
B(-1,-14,-5,COBBLESTONE)
B(-1,-14,-4,COBBLESTONE)
B(-1,-14,-3,COBBLESTONE)
B(-1,-14,-2,COBBLESTONE)
B(-1,-14,-1,COBBLESTONE)
B(-1,-14,0,COBBLESTONE)
B(-1,-14,1,COBBLESTONE)
B(-1,-14,2,COBBLESTONE)
B(-1,-14,3,COBBLESTONE)
B(-1,-14,4,COBBLESTONE)
B(-1,-14,5,COBBLESTONE)
B(-1,-14,6,COBBLESTONE)
B(-1,-14,7,COBBLESTONE)
B(-1,-14,8,COBBLESTONE)
B(-1,-14,9,COBBLESTONE)
B(-1,-14,10,COBBLESTONE)
B(-1,-13,-8,COBBLESTONE)
B(-1,-13,-7,COBBLESTONE)
B(-1,-13,-6,COBBLESTONE)
B(-1,-13,-5,COBBLESTONE)
B(-1,-13,-4,COBBLESTONE)
B(-1,-13,-3,COBBLESTONE)
B(-1,-13,-2,COBBLESTONE)
B(-1,-13,-1,COBBLESTONE)
B(-1,-13,0,COBBLESTONE)
B(-1,-13,1,COBBLESTONE)
B(-1,-13,2,COBBLESTONE)
B(-1,-13,3,COBBLESTONE)
B(-1,-13,4,COBBLESTONE)
B(-1,-13,5,COBBLESTONE)
B(-1,-13,6,COBBLESTONE)
B(-1,-13,7,COBBLESTONE)
B(-1,-13,8,COBBLESTONE)
B(-1,-13,9,COBBLESTONE)
B(-1,-13,10,COBBLESTONE)
B(-1,-12,-8,COBBLESTONE)
B(-1,-12,-7,COBBLESTONE)
B(-1,-12,-6,COBBLESTONE)
B(-1,-12,-5,COBBLESTONE)
B(-1,-12,-4,COBBLESTONE)
B(-1,-12,-3,COBBLESTONE)
B(-1,-12,-2,COBBLESTONE)
B(-1,-12,-1,COBBLESTONE)
B(-1,-12,0,COBBLESTONE)
B(-1,-12,1,COBBLESTONE)
B(-1,-12,2,COBBLESTONE)
B(-1,-12,3,COBBLESTONE)
B(-1,-12,4,COBBLESTONE)
B(-1,-12,5,COBBLESTONE)
B(-1,-12,6,COBBLESTONE)
B(-1,-12,7,COBBLESTONE)
B(-1,-12,8,COBBLESTONE)
B(-1,-12,9,COBBLESTONE)
B(-1,-12,10,COBBLESTONE)
B(-1,-11,-8,COBBLESTONE)
B(-1,-11,-7,COBBLESTONE)
B(-1,-11,-6,COBBLESTONE)
B(-1,-11,-5,COBBLESTONE)
B(-1,-11,-4,COBBLESTONE)
B(-1,-11,-3,COBBLESTONE)
B(-1,-11,-2,COBBLESTONE)
B(-1,-11,-1,COBBLESTONE)
B(-1,-11,0,COBBLESTONE)
B(-1,-11,1,COBBLESTONE)
B(-1,-11,2,COBBLESTONE)
B(-1,-11,3,COBBLESTONE)
B(-1,-11,4,COBBLESTONE)
B(-1,-11,5,COBBLESTONE)
B(-1,-11,6,COBBLESTONE)
B(-1,-11,7,COBBLESTONE)
B(-1,-11,8,COBBLESTONE)
B(-1,-11,9,COBBLESTONE)
B(-1,-11,10,COBBLESTONE)
B(-1,-10,-8,COBBLESTONE)
B(-1,-10,-7,COBBLESTONE)
B(-1,-10,-6,COBBLESTONE)
B(-1,-10,-5,COBBLESTONE)
B(-1,-10,-4,COBBLESTONE)
B(-1,-10,-3,COBBLESTONE)
B(-1,-10,-2,COBBLESTONE)
B(-1,-10,-1,COBBLESTONE)
B(-1,-10,0,COBBLESTONE)
B(-1,-10,1,COBBLESTONE)
B(-1,-10,2,COBBLESTONE)
B(-1,-10,3,COBBLESTONE)
B(-1,-10,4,COBBLESTONE)
B(-1,-10,5,COBBLESTONE)
B(-1,-10,6,COBBLESTONE)
B(-1,-10,7,COBBLESTONE)
B(-1,-10,8,COBBLESTONE)
B(-1,-10,9,COBBLESTONE)
B(-1,-10,10,COBBLESTONE)
B(-1,-9,-8,COBBLESTONE)
B(-1,-9,-7,COBBLESTONE)
B(-1,-9,-6,COBBLESTONE)
B(-1,-9,-5,COBBLESTONE)
B(-1,-9,-4,COBBLESTONE)
B(-1,-9,-3,COBBLESTONE)
B(-1,-9,-2,COBBLESTONE)
B(-1,-9,-1,COBBLESTONE)
B(-1,-9,0,COBBLESTONE)
B(-1,-9,1,COBBLESTONE)
B(-1,-9,2,COBBLESTONE)
B(-1,-9,3,COBBLESTONE)
B(-1,-9,4,COBBLESTONE)
B(-1,-9,5,COBBLESTONE)
B(-1,-9,6,COBBLESTONE)
B(-1,-9,7,COBBLESTONE)
B(-1,-9,8,COBBLESTONE)
B(-1,-9,9,COBBLESTONE)
B(-1,-9,10,COBBLESTONE)
B(-1,-8,-8,COBBLESTONE)
B(-1,-8,-7,COBBLESTONE)
B(-1,-8,-6,COBBLESTONE)
B(-1,-8,-5,COBBLESTONE)
B(-1,-8,-4,COBBLESTONE)
B(-1,-8,-3,COBBLESTONE)
B(-1,-8,-2,COBBLESTONE)
B(-1,-8,-1,COBBLESTONE)
B(-1,-8,0,COBBLESTONE)
B(-1,-8,1,COBBLESTONE)
B(-1,-8,2,COBBLESTONE)
B(-1,-8,3,COBBLESTONE)
B(-1,-8,4,COBBLESTONE)
B(-1,-8,5,COBBLESTONE)
B(-1,-8,6,COBBLESTONE)
B(-1,-8,7,COBBLESTONE)
B(-1,-8,8,COBBLESTONE)
B(-1,-8,9,COBBLESTONE)
B(-1,-8,10,COBBLESTONE)
B(-1,-7,-8,COBBLESTONE)
B(-1,-7,-7,COBBLESTONE)
B(-1,-7,-6,COBBLESTONE)
B(-1,-7,-5,COBBLESTONE)
B(-1,-7,-4,COBBLESTONE)
B(-1,-7,-3,COBBLESTONE)
B(-1,-7,-2,COBBLESTONE)
B(-1,-7,-1,COBBLESTONE)
B(-1,-7,0,COBBLESTONE)
B(-1,-7,1,COBBLESTONE)
B(-1,-7,2,COBBLESTONE)
B(-1,-7,3,COBBLESTONE)
B(-1,-7,4,COBBLESTONE)
B(-1,-7,5,COBBLESTONE)
B(-1,-7,6,COBBLESTONE)
B(-1,-7,7,COBBLESTONE)
B(-1,-7,8,COBBLESTONE)
B(-1,-7,9,COBBLESTONE)
B(-1,-7,10,COBBLESTONE)
B(-1,-6,-8,COBBLESTONE)
B(-1,-6,-7,COBBLESTONE)
B(-1,-6,-6,COBBLESTONE)
B(-1,-6,-5,COBBLESTONE)
B(-1,-6,-4,COBBLESTONE)
B(-1,-6,-3,COBBLESTONE)
B(-1,-6,-2,COBBLESTONE)
B(-1,-6,-1,COBBLESTONE)
B(-1,-6,0,COBBLESTONE)
B(-1,-6,1,COBBLESTONE)
B(-1,-6,2,COBBLESTONE)
B(-1,-6,3,COBBLESTONE)
B(-1,-6,4,COBBLESTONE)
B(-1,-6,5,COBBLESTONE)
B(-1,-6,6,COBBLESTONE)
B(-1,-6,7,COBBLESTONE)
B(-1,-6,8,COBBLESTONE)
B(-1,-6,9,COBBLESTONE)
B(-1,-6,10,COBBLESTONE)
B(-1,-5,-8,COBBLESTONE)
B(-1,-5,-7,COBBLESTONE)
B(-1,-5,-6,COBBLESTONE)
B(-1,-5,-5,COBBLESTONE)
B(-1,-5,-4,COBBLESTONE)
B(-1,-5,-3,COBBLESTONE)
B(-1,-5,-2,COBBLESTONE)
B(-1,-5,-1,COBBLESTONE)
B(-1,-5,0,COBBLESTONE)
B(-1,-5,1,COBBLESTONE)
B(-1,-5,2,COBBLESTONE)
B(-1,-5,3,COBBLESTONE)
B(-1,-5,4,COBBLESTONE)
B(-1,-5,5,COBBLESTONE)
B(-1,-5,6,COBBLESTONE)
B(-1,-5,7,COBBLESTONE)
B(-1,-5,8,COBBLESTONE)
B(-1,-5,9,COBBLESTONE)
B(-1,-5,10,COBBLESTONE)
B(-1,-4,-8,COBBLESTONE)
B(-1,-4,-7,COBBLESTONE)
B(-1,-4,-6,COBBLESTONE)
B(-1,-4,-5,COBBLESTONE)
B(-1,-4,-4,COBBLESTONE)
B(-1,-4,-3,COBBLESTONE)
B(-1,-4,-2,COBBLESTONE)
B(-1,-4,-1,COBBLESTONE)
B(-1,-4,0,COBBLESTONE)
B(-1,-4,1,COBBLESTONE)
B(-1,-4,2,COBBLESTONE)
B(-1,-4,3,COBBLESTONE)
B(-1,-4,4,COBBLESTONE)
B(-1,-4,5,COBBLESTONE)
B(-1,-4,6,COBBLESTONE)
B(-1,-4,7,COBBLESTONE)
B(-1,-4,8,COBBLESTONE)
B(-1,-4,9,COBBLESTONE)
B(-1,-4,10,COBBLESTONE)
B(-1,-3,-8,COBBLESTONE)
B(-1,-3,-7,COBBLESTONE)
B(-1,-3,-6,COBBLESTONE)
B(-1,-3,-5,COBBLESTONE)
B(-1,-3,-4,COBBLESTONE)
B(-1,-3,-3,COBBLESTONE)
B(-1,-3,-2,COBBLESTONE)
B(-1,-3,-1,COBBLESTONE)
B(-1,-3,0,COBBLESTONE)
B(-1,-3,1,COBBLESTONE)
B(-1,-3,2,COBBLESTONE)
B(-1,-3,3,COBBLESTONE)
B(-1,-3,4,COBBLESTONE)
B(-1,-3,5,COBBLESTONE)
B(-1,-3,6,COBBLESTONE)
B(-1,-3,7,COBBLESTONE)
B(-1,-3,8,COBBLESTONE)
B(-1,-3,9,COBBLESTONE)
B(-1,-3,10,COBBLESTONE)
B(-1,-2,-9,COBBLESTONE)
B(-1,-2,-8,COBBLESTONE)
B(-1,-2,-7,COBBLESTONE)
B(-1,-2,-6,AIR)
B(-1,-2,-5,STEP)
B(-1,-2,-4,DOUBLE_STEP)
B(-1,-2,-3,DOUBLE_STEP)
B(-1,-2,-2,STEP:8)
B(-1,-2,-1,STEP:8)
B(-1,-2,0,STEP:8)
B(-1,-2,1,STEP:8)
B(-1,-2,2,COBBLESTONE)
B(-1,-2,3,STEP:8)
B(-1,-2,4,STEP:8)
B(-1,-2,5,STEP:8)
B(-1,-2,6,STEP:8)
B(-1,-2,7,STEP:8)
B(-1,-2,8,STEP:8)
B(-1,-2,9,STEP:8)
B(-1,-2,10,COBBLESTONE)
B(-1,-1,-8,COBBLESTONE)
B(-1,-1,-7,COBBLESTONE)
B(-1,-1,-6,AIR)
B(-1,-1,-5,AIR)
B(-1,-1,-4,GRAVEL)
B(-1,-1,-3,AIR)
B(-1,-1,-2,AIR)
B(-1,-1,-1,GRAVEL)
B(-1,-1,0,AIR)
B(-1,-1,1,COBBLESTONE)
B(-1,-1,2,GRAVEL)
B(-1,-1,3,STEP)
B(-1,-1,4,GRAVEL)
B(-1,-1,5,STEP)
B(-1,-1,6,STEP)
B(-1,-1,7,AIR)
B(-1,-1,8,AIR)
B(-1,-1,9,COBBLESTONE)
B(-1,-1,10,COBBLESTONE)
B(-1,0,-8,COBBLESTONE)
B(-1,0,-7,COBBLESTONE)
B(-1,0,-6,AIR)
B(-1,0,-5,AIR)
B(-1,0,-4,AIR)
B(-1,0,-3,AIR)
B(-1,0,-2,AIR)
B(-1,0,-1,AIR)
B(-1,0,0,AIR)
B(-1,0,1,AIR)
B(-1,0,2,AIR)
B(-1,0,3,AIR)
B(-1,0,4,AIR)
B(-1,0,5,AIR)
B(-1,0,6,AIR)
B(-1,0,7,AIR)
B(-1,0,8,AIR)
B(-1,0,9,COBBLESTONE)
B(-1,0,10,COBBLESTONE)
B(-1,1,-8,COBBLESTONE)
B(-1,1,-7,COBBLESTONE)
B(-1,1,-6,AIR)
B(-1,1,-5,AIR)
B(-1,1,-4,AIR)
B(-1,1,-3,AIR)
B(-1,1,-2,AIR)
B(-1,1,-1,AIR)
B(-1,1,0,AIR)
B(-1,1,1,AIR)
B(-1,1,2,AIR)
B(-1,1,3,AIR)
B(-1,1,4,AIR)
B(-1,1,9,COBBLESTONE)
B(-1,1,10,COBBLESTONE)
B(-1,2,-9,COBBLESTONE_STAIRS:5)
B(-1,2,-8,COBBLESTONE)
B(-1,2,-7,COBBLESTONE)
B(-1,2,-6,DOUBLE_STEP)
B(-1,2,-5,AIR)
B(-1,2,-4,AIR)
B(-1,2,-3,AIR)
B(-1,2,-2,AIR)
B(-1,2,-1,AIR)
B(-1,2,0,AIR)
B(-1,2,1,AIR)
B(-1,2,2,AIR)
B(-1,2,3,AIR)
B(-1,2,4,AIR)
B(-1,2,5,STEP:8)
B(-1,2,6,AIR)
B(-1,2,7,STEP:8)
B(-1,2,8,STEP:8)
B(-1,2,9,COBBLESTONE)
B(-1,2,10,COBBLESTONE)
B(-1,3,-9,COBBLESTONE)
B(-1,3,-8,COBBLESTONE)
B(-1,3,-7,COBBLESTONE)
B(-1,3,-6,GRASS)
B(-1,3,-5,GRASS)
B(-1,3,-4,AIR)
B(-1,3,-3,AIR)
B(-1,3,-2,AIR)
B(-1,3,-1,AIR)
B(-1,3,0,AIR)
B(-1,3,1,AIR)
B(-1,3,2,AIR)
B(-1,3,3,LEAVES:3)
B(-1,3,4,LEAVES:3)
B(-1,3,5,GRASS)
B(-1,3,6,COBBLESTONE)
B(-1,3,7,DIRT:1)
B(-1,3,8,DIRT:1)
B(-1,3,9,COBBLESTONE)
B(-1,3,10,COBBLESTONE)
B(-1,4,-9,COBBLESTONE)
B(-1,4,-8,AIR)
B(-1,4,-7,AIR)
B(-1,4,-6,AIR)
B(-1,4,-5,AIR)
B(-1,4,-4,AIR)
B(-1,4,-3,AIR)
B(-1,4,-2,AIR)
B(-1,4,-1,AIR)
B(-1,4,0,AIR)
B(-1,4,1,AIR)
B(-1,4,2,AIR)
B(-1,4,3,AIR)
B(-1,4,4,AIR)
B(-1,4,5,LEAVES:3)
B(-1,4,6,AIR)
B(-1,4,7,GRASS)
B(-1,4,8,AIR)
B(-1,4,9,AIR)
B(-1,4,10,COBBLESTONE)
B(-1,5,-9,COBBLESTONE)
B(-1,5,-7,AIR)
B(-1,5,-6,AIR)
B(-1,5,-5,AIR)
B(-1,5,-4,LEAVES:3)
B(-1,5,-3,AIR)
B(-1,5,-2,AIR)
B(-1,5,-1,AIR)
B(-1,5,0,AIR)
B(-1,5,1,AIR)
B(-1,5,2,AIR)
B(-1,5,3,AIR)
B(-1,5,4,AIR)
B(-1,5,5,AIR)
B(-1,5,6,AIR)
B(-1,5,7,AIR)
B(-1,5,8,AIR)
B(-1,5,9,AIR)
B(-1,5,10,COBBLESTONE)
B(-1,6,-9,LEAVES:3)
B(-1,6,-7,AIR)
B(-1,6,-6,AIR)
B(-1,6,-5,AIR)
B(-1,6,-4,AIR)
B(-1,6,-3,AIR)
B(-1,6,-2,AIR)
B(-1,6,-1,AIR)
B(-1,6,0,AIR)
B(-1,6,1,AIR)
B(-1,6,2,AIR)
B(-1,6,3,AIR)
B(-1,6,4,AIR)
B(-1,6,5,AIR)
B(-1,6,6,AIR)
B(-1,6,7,AIR)
B(-1,6,8,AIR)
B(-1,6,9,LEAVES:3)
B(-1,6,10,COBBLESTONE)
B(-1,6,11,LEAVES:3)
B(-1,7,-7,AIR)
B(-1,7,-6,AIR)
B(-1,7,-5,AIR)
B(-1,7,-4,AIR)
B(-1,7,-3,AIR)
B(-1,7,-2,AIR)
B(-1,7,-1,AIR)
B(-1,7,0,AIR)
B(-1,7,1,AIR)
B(-1,7,2,AIR)
B(-1,7,3,AIR)
B(-1,7,4,AIR)
B(-1,7,5,AIR)
B(-1,7,6,AIR)
B(-1,7,7,AIR)
B(-1,7,8,AIR)
B(-1,7,9,AIR)
B(-1,7,10,COBBLESTONE)
B(-1,7,11,LEAVES:3)
B(-1,8,-9,COBBLESTONE)
B(-1,8,-8,STEP:8)
B(-1,8,-7,STEP:8)
B(-1,8,-6,STEP:8)
B(-1,8,-5,LEAVES:3)
B(-1,8,-4,AIR)
B(-1,8,-3,AIR)
B(-1,8,-2,AIR)
B(-1,8,-1,AIR)
B(-1,8,0,AIR)
B(-1,8,1,AIR)
B(-1,8,2,AIR)
B(-1,8,3,AIR)
B(-1,8,4,AIR)
B(-1,8,5,AIR)
B(-1,8,6,AIR)
B(-1,8,7,STEP:8)
B(-1,8,8,STEP:8)
B(-1,8,9,STEP:8)
B(-1,8,10,COBBLESTONE)
B(-1,8,11,LEAVES:3)
B(-1,9,-10,LEAVES:3)
B(-1,9,-9,COBBLESTONE)
B(-1,9,-8,DIRT:1)
B(-1,9,-7,COBBLESTONE)
B(-1,9,-6,COBBLESTONE)
B(-1,9,-5,LEAVES:3)
B(-1,9,7,GRASS)
B(-1,9,8,COBBLESTONE)
B(-1,9,9,COBBLESTONE)
B(-1,9,10,LEAVES:3)
B(-1,9,11,LEAVES:3)
B(-1,10,-10,LEAVES:3)
B(-1,10,-9,LEAVES:3)
B(-1,10,-8,LEAVES:3)
B(-1,10,-7,GRASS)
B(-1,10,-6,COBBLESTONE_STAIRS:1)
B(-1,10,8,GRASS)
B(-1,10,9,GRASS)
B(-1,11,-8,LEAVES:3)
B(-1,11,-7,COBBLESTONE_STAIRS:2)
B(-1,11,7,LEAVES:3)
B(-1,11,8,LEAVES:3)
B(-1,11,9,LEAVES:3)
B(-1,12,-7,LEAVES:3)
B(-1,12,8,LEAVES:3)
B(0,-16,-8,COBBLESTONE)
B(0,-16,-7,COBBLESTONE)
B(0,-16,-6,COBBLESTONE)
B(0,-16,-5,COBBLESTONE)
B(0,-16,-4,COBBLESTONE)
B(0,-16,-3,COBBLESTONE)
B(0,-16,-2,COBBLESTONE)
B(0,-16,-1,COBBLESTONE)
B(0,-16,0,COBBLESTONE)
B(0,-16,1,COBBLESTONE)
B(0,-16,2,COBBLESTONE)
B(0,-16,3,COBBLESTONE)
B(0,-16,4,COBBLESTONE)
B(0,-16,5,COBBLESTONE)
B(0,-16,6,COBBLESTONE)
B(0,-16,7,COBBLESTONE)
B(0,-16,8,COBBLESTONE)
B(0,-16,9,COBBLESTONE)
B(0,-15,-8,COBBLESTONE)
B(0,-15,-7,COBBLESTONE)
B(0,-15,-6,COBBLESTONE)
B(0,-15,-5,COBBLESTONE)
B(0,-15,-4,COBBLESTONE)
B(0,-15,-3,COBBLESTONE)
B(0,-15,-2,COBBLESTONE)
B(0,-15,-1,COBBLESTONE)
B(0,-15,0,COBBLESTONE)
B(0,-15,1,COBBLESTONE)
B(0,-15,2,COBBLESTONE)
B(0,-15,3,COBBLESTONE)
B(0,-15,4,COBBLESTONE)
B(0,-15,5,COBBLESTONE)
B(0,-15,6,COBBLESTONE)
B(0,-15,7,COBBLESTONE)
B(0,-15,8,COBBLESTONE)
B(0,-15,9,COBBLESTONE)
B(0,-14,-8,COBBLESTONE)
B(0,-14,-7,COBBLESTONE)
B(0,-14,-6,COBBLESTONE)
B(0,-14,-5,COBBLESTONE)
B(0,-14,-4,COBBLESTONE)
B(0,-14,-3,COBBLESTONE)
B(0,-14,-2,COBBLESTONE)
B(0,-14,-1,COBBLESTONE)
B(0,-14,0,COBBLESTONE)
B(0,-14,1,COBBLESTONE)
B(0,-14,2,COBBLESTONE)
B(0,-14,3,COBBLESTONE)
B(0,-14,4,COBBLESTONE)
B(0,-14,5,COBBLESTONE)
B(0,-14,6,COBBLESTONE)
B(0,-14,7,COBBLESTONE)
B(0,-14,8,COBBLESTONE)
B(0,-14,9,COBBLESTONE)
B(0,-13,-8,COBBLESTONE)
B(0,-13,-7,COBBLESTONE)
B(0,-13,-6,COBBLESTONE)
B(0,-13,-5,COBBLESTONE)
B(0,-13,-4,COBBLESTONE)
B(0,-13,-3,COBBLESTONE)
B(0,-13,-2,COBBLESTONE)
B(0,-13,-1,COBBLESTONE)
B(0,-13,0,COBBLESTONE)
B(0,-13,1,COBBLESTONE)
B(0,-13,2,COBBLESTONE)
B(0,-13,3,COBBLESTONE)
B(0,-13,4,COBBLESTONE)
B(0,-13,5,COBBLESTONE)
B(0,-13,6,COBBLESTONE)
B(0,-13,7,COBBLESTONE)
B(0,-13,8,COBBLESTONE)
B(0,-13,9,COBBLESTONE)
B(0,-12,-8,COBBLESTONE)
B(0,-12,-7,COBBLESTONE)
B(0,-12,-6,COBBLESTONE)
B(0,-12,-5,COBBLESTONE)
B(0,-12,-4,COBBLESTONE)
B(0,-12,-3,COBBLESTONE)
B(0,-12,-2,COBBLESTONE)
B(0,-12,-1,COBBLESTONE)
B(0,-12,0,COBBLESTONE)
B(0,-12,1,COBBLESTONE)
B(0,-12,2,COBBLESTONE)
B(0,-12,3,COBBLESTONE)
B(0,-12,4,COBBLESTONE)
B(0,-12,5,COBBLESTONE)
B(0,-12,6,COBBLESTONE)
B(0,-12,7,COBBLESTONE)
B(0,-12,8,COBBLESTONE)
B(0,-12,9,COBBLESTONE)
B(0,-11,-8,COBBLESTONE)
B(0,-11,-7,COBBLESTONE)
B(0,-11,-6,COBBLESTONE)
B(0,-11,-5,COBBLESTONE)
B(0,-11,-4,COBBLESTONE)
B(0,-11,-3,COBBLESTONE)
B(0,-11,-2,COBBLESTONE)
B(0,-11,-1,COBBLESTONE)
B(0,-11,0,COBBLESTONE)
B(0,-11,1,COBBLESTONE)
B(0,-11,2,COBBLESTONE)
B(0,-11,3,COBBLESTONE)
B(0,-11,4,COBBLESTONE)
B(0,-11,5,COBBLESTONE)
B(0,-11,6,COBBLESTONE)
B(0,-11,7,COBBLESTONE)
B(0,-11,8,COBBLESTONE)
B(0,-11,9,COBBLESTONE)
B(0,-10,-8,COBBLESTONE)
B(0,-10,-7,COBBLESTONE)
B(0,-10,-6,COBBLESTONE)
B(0,-10,-5,COBBLESTONE)
B(0,-10,-4,COBBLESTONE)
B(0,-10,-3,COBBLESTONE)
B(0,-10,-2,COBBLESTONE)
B(0,-10,-1,COBBLESTONE)
B(0,-10,0,COBBLESTONE)
B(0,-10,1,COBBLESTONE)
B(0,-10,2,COBBLESTONE)
B(0,-10,3,COBBLESTONE)
B(0,-10,4,COBBLESTONE)
B(0,-10,5,COBBLESTONE)
B(0,-10,6,COBBLESTONE)
B(0,-10,7,COBBLESTONE)
B(0,-10,8,COBBLESTONE)
B(0,-10,9,COBBLESTONE)
B(0,-9,-8,COBBLESTONE)
B(0,-9,-7,COBBLESTONE)
B(0,-9,-6,COBBLESTONE)
B(0,-9,-5,COBBLESTONE)
B(0,-9,-4,COBBLESTONE)
B(0,-9,-3,COBBLESTONE)
B(0,-9,-2,COBBLESTONE)
B(0,-9,-1,COBBLESTONE)
B(0,-9,0,COBBLESTONE)
B(0,-9,1,COBBLESTONE)
B(0,-9,2,COBBLESTONE)
B(0,-9,3,COBBLESTONE)
B(0,-9,4,COBBLESTONE)
B(0,-9,5,COBBLESTONE)
B(0,-9,6,COBBLESTONE)
B(0,-9,7,COBBLESTONE)
B(0,-9,8,COBBLESTONE)
B(0,-9,9,COBBLESTONE)
B(0,-8,-8,COBBLESTONE)
B(0,-8,-7,COBBLESTONE)
B(0,-8,-6,COBBLESTONE)
B(0,-8,-5,COBBLESTONE)
B(0,-8,-4,COBBLESTONE)
B(0,-8,-3,COBBLESTONE)
B(0,-8,-2,COBBLESTONE)
B(0,-8,-1,COBBLESTONE)
B(0,-8,0,COBBLESTONE)
B(0,-8,1,COBBLESTONE)
B(0,-8,2,COBBLESTONE)
B(0,-8,3,COBBLESTONE)
B(0,-8,4,COBBLESTONE)
B(0,-8,5,COBBLESTONE)
B(0,-8,6,COBBLESTONE)
B(0,-8,7,COBBLESTONE)
B(0,-8,8,COBBLESTONE)
B(0,-8,9,COBBLESTONE)
B(0,-7,-8,COBBLESTONE)
B(0,-7,-7,COBBLESTONE)
B(0,-7,-6,COBBLESTONE)
B(0,-7,-5,COBBLESTONE)
B(0,-7,-4,COBBLESTONE)
B(0,-7,-3,COBBLESTONE)
B(0,-7,-2,COBBLESTONE)
B(0,-7,-1,COBBLESTONE)
B(0,-7,0,COBBLESTONE)
B(0,-7,1,COBBLESTONE)
B(0,-7,2,COBBLESTONE)
B(0,-7,3,COBBLESTONE)
B(0,-7,4,COBBLESTONE)
B(0,-7,5,COBBLESTONE)
B(0,-7,6,COBBLESTONE)
B(0,-7,7,COBBLESTONE)
B(0,-7,8,COBBLESTONE)
B(0,-7,9,COBBLESTONE)
B(0,-6,-8,COBBLESTONE)
B(0,-6,-7,COBBLESTONE)
B(0,-6,-6,COBBLESTONE)
B(0,-6,-5,COBBLESTONE)
B(0,-6,-4,COBBLESTONE)
B(0,-6,-3,COBBLESTONE)
B(0,-6,-2,COBBLESTONE)
B(0,-6,-1,COBBLESTONE)
B(0,-6,0,COBBLESTONE)
B(0,-6,1,COBBLESTONE)
B(0,-6,2,COBBLESTONE)
B(0,-6,3,COBBLESTONE)
B(0,-6,4,COBBLESTONE)
B(0,-6,5,COBBLESTONE)
B(0,-6,6,COBBLESTONE)
B(0,-6,7,COBBLESTONE)
B(0,-6,8,COBBLESTONE)
B(0,-6,9,COBBLESTONE)
B(0,-5,-8,COBBLESTONE)
B(0,-5,-7,COBBLESTONE)
B(0,-5,-6,COBBLESTONE)
B(0,-5,-5,COBBLESTONE)
B(0,-5,-4,COBBLESTONE)
B(0,-5,-3,COBBLESTONE)
B(0,-5,-2,COBBLESTONE)
B(0,-5,-1,COBBLESTONE)
B(0,-5,0,COBBLESTONE)
B(0,-5,1,COBBLESTONE)
B(0,-5,2,COBBLESTONE)
B(0,-5,3,COBBLESTONE)
B(0,-5,4,COBBLESTONE)
B(0,-5,5,COBBLESTONE)
B(0,-5,6,COBBLESTONE)
B(0,-5,7,COBBLESTONE)
B(0,-5,8,COBBLESTONE)
B(0,-5,9,COBBLESTONE)
B(0,-4,-8,COBBLESTONE)
B(0,-4,-7,COBBLESTONE)
B(0,-4,-6,COBBLESTONE)
B(0,-4,-5,COBBLESTONE)
B(0,-4,-4,COBBLESTONE)
B(0,-4,-3,COBBLESTONE)
B(0,-4,-2,COBBLESTONE)
B(0,-4,-1,COBBLESTONE)
B(0,-4,0,COBBLESTONE)
B(0,-4,1,COBBLESTONE)
B(0,-4,2,COBBLESTONE)
B(0,-4,3,COBBLESTONE)
B(0,-4,4,COBBLESTONE)
B(0,-4,5,COBBLESTONE)
B(0,-4,6,COBBLESTONE)
B(0,-4,7,COBBLESTONE)
B(0,-4,8,COBBLESTONE)
B(0,-4,9,COBBLESTONE)
B(0,-3,-8,COBBLESTONE)
B(0,-3,-7,COBBLESTONE)
B(0,-3,-6,COBBLESTONE)
B(0,-3,-5,COBBLESTONE)
B(0,-3,-4,COBBLESTONE)
B(0,-3,-3,COBBLESTONE)
B(0,-3,-2,COBBLESTONE)
B(0,-3,-1,COBBLESTONE)
B(0,-3,0,COBBLESTONE)
B(0,-3,1,COBBLESTONE)
B(0,-3,2,COBBLESTONE)
B(0,-3,3,COBBLESTONE)
B(0,-3,4,COBBLESTONE)
B(0,-3,5,COBBLESTONE)
B(0,-3,6,COBBLESTONE)
B(0,-3,7,COBBLESTONE)
B(0,-3,8,COBBLESTONE)
B(0,-3,9,COBBLESTONE)
B(0,-2,-9,COBBLESTONE)
B(0,-2,-8,COBBLESTONE)
B(0,-2,-7,COBBLESTONE)
B(0,-2,-6,AIR)
B(0,-2,-5,AIR)
B(0,-2,-4,STEP)
B(0,-2,-3,DOUBLE_STEP)
B(0,-2,-2,STEP:8)
B(0,-2,-1,STEP:8)
B(0,-2,0,STEP:8)
B(0,-2,1,STEP:8)
B(0,-2,2,COBBLESTONE)
B(0,-2,3,STEP:8)
B(0,-2,4,STEP:8)
B(0,-2,5,STEP:8)
B(0,-2,6,STEP:8)
B(0,-2,7,STEP:8)
B(0,-2,8,STEP:8)
B(0,-2,9,STEP:8)
B(0,-2,10,COBBLESTONE)
B(0,-1,-8,COBBLESTONE)
B(0,-1,-7,COBBLESTONE)
B(0,-1,-6,AIR)
B(0,-1,-5,AIR)
B(0,-1,-4,AIR)
B(0,-1,-3,AIR)
B(0,-1,-2,GRAVEL)
B(0,-1,-1,GRAVEL)
B(0,-1,0,GRAVEL)
B(0,-1,1,AIR)
B(0,-1,2,GRAVEL)
B(0,-1,3,AIR)
B(0,-1,4,STEP)
B(0,-1,5,AIR)
B(0,-1,6,AIR)
B(0,-1,7,AIR)
B(0,-1,8,AIR)
B(0,-1,9,COBBLESTONE)
B(0,0,-8,COBBLESTONE)
B(0,0,-7,COBBLESTONE)
B(0,0,-6,AIR)
B(0,0,-5,AIR)
B(0,0,-4,AIR)
B(0,0,-3,AIR)
B(0,0,-2,GRAVEL)
B(0,0,-1,AIR)
B(0,0,0,AIR)
B(0,0,1,AIR)
B(0,0,2,AIR)
B(0,0,3,AIR)
B(0,0,4,AIR)
B(0,0,5,AIR)
B(0,0,6,AIR)
B(0,0,7,AIR)
B(0,0,8,AIR)
B(0,0,9,COBBLESTONE)
B(0,1,-8,COBBLESTONE)
B(0,1,-7,COBBLESTONE)
B(0,1,-6,AIR)
B(0,1,-5,AIR)
B(0,1,-4,AIR)
B(0,1,-3,AIR)
B(0,1,-2,AIR)
B(0,1,-1,AIR)
B(0,1,0,AIR)
B(0,1,1,AIR)
B(0,1,2,AIR)
B(0,1,3,AIR)
B(0,1,4,AIR)
B(0,1,9,COBBLESTONE)
B(0,2,-8,COBBLESTONE)
B(0,2,-7,COBBLESTONE)
B(0,2,-6,DOUBLE_STEP)
B(0,2,-5,STEP:8)
B(0,2,-4,AIR)
B(0,2,-3,AIR)
B(0,2,-2,AIR)
B(0,2,-1,AIR)
B(0,2,0,AIR)
B(0,2,1,AIR)
B(0,2,2,AIR)
B(0,2,3,AIR)
B(0,2,4,AIR)
B(0,2,5,STEP:8)
B(0,2,6,AIR)
B(0,2,7,AIR)
B(0,2,8,DOUBLE_STEP)
B(0,2,9,COBBLESTONE)
B(0,3,-9,COBBLESTONE)
B(0,3,-8,COBBLESTONE)
B(0,3,-7,COBBLESTONE)
B(0,3,-6,DIRT:1)
B(0,3,-5,GRASS)
B(0,3,-4,DIRT)
B(0,3,-3,AIR)
B(0,3,-2,AIR)
B(0,3,-1,AIR)
B(0,3,0,AIR)
B(0,3,1,AIR)
B(0,3,2,LEAVES:3)
B(0,3,3,LEAVES:3)
B(0,3,4,GRASS)
B(0,3,5,GRASS)
B(0,3,6,COBBLESTONE)
B(0,3,7,COBBLESTONE)
B(0,3,8,COBBLESTONE)
B(0,3,9,DIRT:1)
B(0,3,10,COBBLESTONE)
B(0,4,-9,LEAVES:3)
B(0,4,-8,AIR)
B(0,4,-7,AIR)
B(0,4,-6,AIR)
B(0,4,-5,AIR)
B(0,4,-4,LOG:3)
B(0,4,-3,AIR)
B(0,4,-2,AIR)
B(0,4,-1,AIR)
B(0,4,0,AIR)
B(0,4,1,AIR)
B(0,4,2,AIR)
B(0,4,3,LEAVES:3)
B(0,4,4,LEAVES:3)
B(0,4,5,LEAVES:3)
B(0,4,6,GRASS)
B(0,4,7,GRASS)
B(0,4,8,AIR)
B(0,4,9,AIR)
B(0,4,10,LEAVES:3)
B(0,5,-7,AIR)
B(0,5,-6,AIR)
B(0,5,-5,LEAVES:3)
B(0,5,-4,LOG:3)
B(0,5,-3,LEAVES:3)
B(0,5,-2,AIR)
B(0,5,-1,AIR)
B(0,5,0,AIR)
B(0,5,1,AIR)
B(0,5,2,AIR)
B(0,5,3,AIR)
B(0,5,4,AIR)
B(0,5,5,AIR)
B(0,5,6,AIR)
B(0,5,7,LEAVES:3)
B(0,5,8,AIR)
B(0,5,9,AIR)
B(0,5,10,LEAVES:3)
B(0,6,-7,AIR)
B(0,6,-6,AIR)
B(0,6,-5,AIR)
B(0,6,-4,LEAVES:3)
B(0,6,-3,AIR)
B(0,6,-2,AIR)
B(0,6,-1,AIR)
B(0,6,0,AIR)
B(0,6,1,AIR)
B(0,6,2,AIR)
B(0,6,3,AIR)
B(0,6,4,AIR)
B(0,6,5,AIR)
B(0,6,6,AIR)
B(0,6,7,AIR)
B(0,6,8,AIR)
B(0,6,9,AIR)
B(0,7,-7,AIR)
B(0,7,-6,AIR)
B(0,7,-5,LEAVES:3)
B(0,7,-4,LEAVES:3)
B(0,7,-3,AIR)
B(0,7,-2,AIR)
B(0,7,-1,AIR)
B(0,7,0,AIR)
B(0,7,1,AIR)
B(0,7,2,AIR)
B(0,7,3,AIR)
B(0,7,4,AIR)
B(0,7,5,AIR)
B(0,7,6,AIR)
B(0,7,7,AIR)
B(0,7,8,AIR)
B(0,7,9,AIR)
B(0,7,10,LEAVES:3)
B(0,8,-9,COBBLESTONE_STAIRS:5)
B(0,8,-8,STEP:8)
B(0,8,-7,STEP:8)
B(0,8,-6,LEAVES:3)
B(0,8,-5,LEAVES:3)
B(0,8,-4,AIR)
B(0,8,-3,AIR)
B(0,8,-2,AIR)
B(0,8,-1,AIR)
B(0,8,0,AIR)
B(0,8,1,AIR)
B(0,8,2,AIR)
B(0,8,3,AIR)
B(0,8,4,AIR)
B(0,8,5,AIR)
B(0,8,6,AIR)
B(0,8,7,STEP:8)
B(0,8,8,STEP:8)
B(0,8,9,STEP:8)
B(0,8,10,COBBLESTONE_STAIRS:5)
B(0,9,-10,LEAVES:3)
B(0,9,-9,COBBLESTONE)
B(0,9,-8,GRASS)
B(0,9,-7,COBBLESTONE)
B(0,9,-6,LEAVES:3)
B(0,9,7,COBBLESTONE)
B(0,9,8,COBBLESTONE)
B(0,9,9,COBBLESTONE)
B(0,9,10,COBBLESTONE)
B(0,10,-10,STEP:5)
B(0,10,-9,LEAVES:3)
B(0,10,-8,LEAVES:3)
B(0,10,-7,GRASS)
B(0,10,7,GRASS)
B(0,10,8,GRASS)
B(0,10,9,GRASS)
B(0,10,10,GRASS)
B(0,10,11,STEP:5)
B(0,11,-7,LEAVES:3)
B(0,11,8,LEAVES:3)
B(1,-16,-8,COBBLESTONE)
B(1,-16,-7,COBBLESTONE)
B(1,-16,-6,COBBLESTONE)
B(1,-16,-5,COBBLESTONE)
B(1,-16,-4,COBBLESTONE)
B(1,-16,-3,COBBLESTONE)
B(1,-16,-2,COBBLESTONE)
B(1,-16,-1,COBBLESTONE)
B(1,-16,0,COBBLESTONE)
B(1,-16,1,COBBLESTONE)
B(1,-16,2,COBBLESTONE)
B(1,-16,3,COBBLESTONE)
B(1,-16,4,COBBLESTONE)
B(1,-16,5,COBBLESTONE)
B(1,-16,6,COBBLESTONE)
B(1,-16,7,COBBLESTONE)
B(1,-16,8,COBBLESTONE)
B(1,-16,9,COBBLESTONE)
B(1,-15,-8,COBBLESTONE)
B(1,-15,-7,COBBLESTONE)
B(1,-15,-6,COBBLESTONE)
B(1,-15,-5,COBBLESTONE)
B(1,-15,-4,COBBLESTONE)
B(1,-15,-3,COBBLESTONE)
B(1,-15,-2,COBBLESTONE)
B(1,-15,-1,COBBLESTONE)
B(1,-15,0,COBBLESTONE)
B(1,-15,1,COBBLESTONE)
B(1,-15,2,COBBLESTONE)
B(1,-15,3,COBBLESTONE)
B(1,-15,4,COBBLESTONE)
B(1,-15,5,COBBLESTONE)
B(1,-15,6,COBBLESTONE)
B(1,-15,7,COBBLESTONE)
B(1,-15,8,COBBLESTONE)
B(1,-15,9,COBBLESTONE)
B(1,-14,-8,COBBLESTONE)
B(1,-14,-7,COBBLESTONE)
B(1,-14,-6,COBBLESTONE)
B(1,-14,-5,COBBLESTONE)
B(1,-14,-4,COBBLESTONE)
B(1,-14,-3,COBBLESTONE)
B(1,-14,-2,COBBLESTONE)
B(1,-14,-1,COBBLESTONE)
B(1,-14,0,COBBLESTONE)
B(1,-14,1,COBBLESTONE)
B(1,-14,2,COBBLESTONE)
B(1,-14,3,COBBLESTONE)
B(1,-14,4,COBBLESTONE)
B(1,-14,5,COBBLESTONE)
B(1,-14,6,COBBLESTONE)
B(1,-14,7,COBBLESTONE)
B(1,-14,8,COBBLESTONE)
B(1,-14,9,COBBLESTONE)
B(1,-13,-8,COBBLESTONE)
B(1,-13,-7,COBBLESTONE)
B(1,-13,-6,COBBLESTONE)
B(1,-13,-5,COBBLESTONE)
B(1,-13,-4,COBBLESTONE)
B(1,-13,-3,COBBLESTONE)
B(1,-13,-2,COBBLESTONE)
B(1,-13,-1,COBBLESTONE)
B(1,-13,0,COBBLESTONE)
B(1,-13,1,COBBLESTONE)
B(1,-13,2,COBBLESTONE)
B(1,-13,3,COBBLESTONE)
B(1,-13,4,COBBLESTONE)
B(1,-13,5,COBBLESTONE)
B(1,-13,6,COBBLESTONE)
B(1,-13,7,COBBLESTONE)
B(1,-13,8,COBBLESTONE)
B(1,-13,9,COBBLESTONE)
B(1,-12,-8,COBBLESTONE)
B(1,-12,-7,COBBLESTONE)
B(1,-12,-6,COBBLESTONE)
B(1,-12,-5,COBBLESTONE)
B(1,-12,-4,COBBLESTONE)
B(1,-12,-3,COBBLESTONE)
B(1,-12,-2,COBBLESTONE)
B(1,-12,-1,COBBLESTONE)
B(1,-12,0,COBBLESTONE)
B(1,-12,1,COBBLESTONE)
B(1,-12,2,COBBLESTONE)
B(1,-12,3,COBBLESTONE)
B(1,-12,4,COBBLESTONE)
B(1,-12,5,COBBLESTONE)
B(1,-12,6,COBBLESTONE)
B(1,-12,7,COBBLESTONE)
B(1,-12,8,COBBLESTONE)
B(1,-12,9,COBBLESTONE)
B(1,-11,-8,COBBLESTONE)
B(1,-11,-7,COBBLESTONE)
B(1,-11,-6,COBBLESTONE)
B(1,-11,-5,COBBLESTONE)
B(1,-11,-4,COBBLESTONE)
B(1,-11,-3,COBBLESTONE)
B(1,-11,-2,COBBLESTONE)
B(1,-11,-1,COBBLESTONE)
B(1,-11,0,COBBLESTONE)
B(1,-11,1,COBBLESTONE)
B(1,-11,2,COBBLESTONE)
B(1,-11,3,COBBLESTONE)
B(1,-11,4,COBBLESTONE)
B(1,-11,5,COBBLESTONE)
B(1,-11,6,COBBLESTONE)
B(1,-11,7,COBBLESTONE)
B(1,-11,8,COBBLESTONE)
B(1,-11,9,COBBLESTONE)
B(1,-10,-8,COBBLESTONE)
B(1,-10,-7,COBBLESTONE)
B(1,-10,-6,COBBLESTONE)
B(1,-10,-5,COBBLESTONE)
B(1,-10,-4,COBBLESTONE)
B(1,-10,-3,COBBLESTONE)
B(1,-10,-2,COBBLESTONE)
B(1,-10,-1,COBBLESTONE)
B(1,-10,0,COBBLESTONE)
B(1,-10,1,COBBLESTONE)
B(1,-10,2,COBBLESTONE)
B(1,-10,3,COBBLESTONE)
B(1,-10,4,COBBLESTONE)
B(1,-10,5,COBBLESTONE)
B(1,-10,6,COBBLESTONE)
B(1,-10,7,COBBLESTONE)
B(1,-10,8,COBBLESTONE)
B(1,-10,9,COBBLESTONE)
B(1,-9,-8,COBBLESTONE)
B(1,-9,-7,COBBLESTONE)
B(1,-9,-6,COBBLESTONE)
B(1,-9,-5,COBBLESTONE)
B(1,-9,-4,COBBLESTONE)
B(1,-9,-3,COBBLESTONE)
B(1,-9,-2,COBBLESTONE)
B(1,-9,-1,COBBLESTONE)
B(1,-9,0,COBBLESTONE)
B(1,-9,1,COBBLESTONE)
B(1,-9,2,COBBLESTONE)
B(1,-9,3,COBBLESTONE)
B(1,-9,4,COBBLESTONE)
B(1,-9,5,COBBLESTONE)
B(1,-9,6,COBBLESTONE)
B(1,-9,7,COBBLESTONE)
B(1,-9,8,COBBLESTONE)
B(1,-9,9,COBBLESTONE)
B(1,-8,-8,COBBLESTONE)
B(1,-8,-7,COBBLESTONE)
B(1,-8,-6,COBBLESTONE)
B(1,-8,-5,COBBLESTONE)
B(1,-8,-4,COBBLESTONE)
B(1,-8,-3,COBBLESTONE)
B(1,-8,-2,COBBLESTONE)
B(1,-8,-1,COBBLESTONE)
B(1,-8,0,COBBLESTONE)
B(1,-8,1,COBBLESTONE)
B(1,-8,2,COBBLESTONE)
B(1,-8,3,COBBLESTONE)
B(1,-8,4,COBBLESTONE)
B(1,-8,5,COBBLESTONE)
B(1,-8,6,COBBLESTONE)
B(1,-8,7,COBBLESTONE)
B(1,-8,8,COBBLESTONE)
B(1,-8,9,COBBLESTONE)
B(1,-7,-8,COBBLESTONE)
B(1,-7,-7,COBBLESTONE)
B(1,-7,-6,COBBLESTONE)
B(1,-7,-5,COBBLESTONE)
B(1,-7,-4,COBBLESTONE)
B(1,-7,-3,COBBLESTONE)
B(1,-7,-2,COBBLESTONE)
B(1,-7,-1,COBBLESTONE)
B(1,-7,0,COBBLESTONE)
B(1,-7,1,COBBLESTONE)
B(1,-7,2,COBBLESTONE)
B(1,-7,3,COBBLESTONE)
B(1,-7,4,COBBLESTONE)
B(1,-7,5,COBBLESTONE)
B(1,-7,6,COBBLESTONE)
B(1,-7,7,COBBLESTONE)
B(1,-7,8,COBBLESTONE)
B(1,-7,9,COBBLESTONE)
B(1,-6,-8,COBBLESTONE)
B(1,-6,-7,COBBLESTONE)
B(1,-6,-6,COBBLESTONE)
B(1,-6,-5,COBBLESTONE)
B(1,-6,-4,COBBLESTONE)
B(1,-6,-3,COBBLESTONE)
B(1,-6,-2,COBBLESTONE)
B(1,-6,-1,COBBLESTONE)
B(1,-6,0,COBBLESTONE)
B(1,-6,1,COBBLESTONE)
B(1,-6,2,COBBLESTONE)
B(1,-6,3,COBBLESTONE)
B(1,-6,4,COBBLESTONE)
B(1,-6,5,COBBLESTONE)
B(1,-6,6,COBBLESTONE)
B(1,-6,7,COBBLESTONE)
B(1,-6,8,COBBLESTONE)
B(1,-6,9,COBBLESTONE)
B(1,-5,-8,COBBLESTONE)
B(1,-5,-7,COBBLESTONE)
B(1,-5,-6,COBBLESTONE)
B(1,-5,-5,COBBLESTONE)
B(1,-5,-4,COBBLESTONE)
B(1,-5,-3,COBBLESTONE)
B(1,-5,-2,COBBLESTONE)
B(1,-5,-1,COBBLESTONE)
B(1,-5,0,COBBLESTONE)
B(1,-5,1,COBBLESTONE)
B(1,-5,2,COBBLESTONE)
B(1,-5,3,COBBLESTONE)
B(1,-5,4,COBBLESTONE)
B(1,-5,5,COBBLESTONE)
B(1,-5,6,COBBLESTONE)
B(1,-5,7,COBBLESTONE)
B(1,-5,8,COBBLESTONE)
B(1,-5,9,COBBLESTONE)
B(1,-4,-8,COBBLESTONE)
B(1,-4,-7,COBBLESTONE)
B(1,-4,-6,COBBLESTONE)
B(1,-4,-5,COBBLESTONE)
B(1,-4,-4,COBBLESTONE)
B(1,-4,-3,COBBLESTONE)
B(1,-4,-2,COBBLESTONE)
B(1,-4,-1,COBBLESTONE)
B(1,-4,0,COBBLESTONE)
B(1,-4,1,COBBLESTONE)
B(1,-4,2,COBBLESTONE)
B(1,-4,3,COBBLESTONE)
B(1,-4,4,COBBLESTONE)
B(1,-4,5,COBBLESTONE)
B(1,-4,6,COBBLESTONE)
B(1,-4,7,COBBLESTONE)
B(1,-4,8,COBBLESTONE)
B(1,-4,9,COBBLESTONE)
B(1,-3,-8,COBBLESTONE)
B(1,-3,-7,COBBLESTONE)
B(1,-3,-6,COBBLESTONE)
B(1,-3,-5,COBBLESTONE)
B(1,-3,-4,COBBLESTONE)
B(1,-3,-3,COBBLESTONE)
B(1,-3,-2,COBBLESTONE)
B(1,-3,-1,COBBLESTONE)
B(1,-3,0,COBBLESTONE)
B(1,-3,1,COBBLESTONE)
B(1,-3,2,COBBLESTONE)
B(1,-3,3,COBBLESTONE)
B(1,-3,4,COBBLESTONE)
B(1,-3,5,COBBLESTONE)
B(1,-3,6,COBBLESTONE)
B(1,-3,7,COBBLESTONE)
B(1,-3,8,COBBLESTONE)
B(1,-3,9,COBBLESTONE)
B(1,-2,-9,COBBLESTONE)
B(1,-2,-8,COBBLESTONE)
B(1,-2,-7,COBBLESTONE)
B(1,-2,-6,AIR)
B(1,-2,-5,COBBLESTONE_STAIRS:1)
B(1,-2,-4,AIR)
B(1,-2,-3,STEP)
B(1,-2,-2,DOUBLE_STEP)
B(1,-2,-1,DOUBLE_STEP)
B(1,-2,0,DOUBLE_STEP)
B(1,-2,1,STEP:8)
B(1,-2,2,COBBLESTONE)
B(1,-2,3,STEP:8)
B(1,-2,4,STEP:8)
B(1,-2,5,STEP:8)
B(1,-2,6,STEP:8)
B(1,-2,7,STEP:8)
B(1,-2,8,STEP:8)
B(1,-2,9,STEP:8)
B(1,-2,10,COBBLESTONE)
B(1,-1,-8,COBBLESTONE)
B(1,-1,-7,COBBLESTONE)
B(1,-1,-6,AIR)
B(1,-1,-5,AIR)
B(1,-1,-4,AIR)
B(1,-1,-3,AIR)
B(1,-1,-2,AIR)
B(1,-1,-1,GRAVEL)
B(1,-1,0,AIR)
B(1,-1,1,AIR)
B(1,-1,2,STEP)
B(1,-1,3,AIR)
B(1,-1,4,AIR)
B(1,-1,5,AIR)
B(1,-1,6,GRAVEL)
B(1,-1,7,AIR)
B(1,-1,8,AIR)
B(1,-1,9,COBBLESTONE)
B(1,0,-8,COBBLESTONE)
B(1,0,-7,COBBLESTONE)
B(1,0,-6,AIR)
B(1,0,-5,AIR)
B(1,0,-4,AIR)
B(1,0,-3,AIR)
B(1,0,-2,AIR)
B(1,0,-1,AIR)
B(1,0,0,AIR)
B(1,0,1,AIR)
B(1,0,2,AIR)
B(1,0,3,AIR)
B(1,0,4,AIR)
B(1,0,5,AIR)
B(1,0,6,AIR)
B(1,0,7,AIR)
B(1,0,8,AIR)
B(1,0,9,COBBLESTONE)
B(1,1,-8,COBBLESTONE)
B(1,1,-7,COBBLESTONE)
B(1,1,-6,AIR)
B(1,1,-5,AIR)
B(1,1,-4,AIR)
B(1,1,-3,AIR)
B(1,1,-2,AIR)
B(1,1,-1,AIR)
B(1,1,0,AIR)
B(1,1,1,AIR)
B(1,1,2,AIR)
B(1,1,3,AIR)
B(1,1,4,AIR)
B(1,1,9,COBBLESTONE)
B(1,2,-8,COBBLESTONE)
B(1,2,-7,COBBLESTONE)
B(1,2,-6,STEP:8)
B(1,2,-5,DOUBLE_STEP)
B(1,2,-4,STEP:8)
B(1,2,-3,AIR)
B(1,2,-2,AIR)
B(1,2,-1,AIR)
B(1,2,0,AIR)
B(1,2,1,STEP:8)
B(1,2,2,AIR)
B(1,2,3,DOUBLE_STEP)
B(1,2,4,STEP:8)
B(1,2,5,STEP:8)
B(1,2,6,AIR)
B(1,2,7,STEP:8)
B(1,2,8,STEP:8)
B(1,2,9,COBBLESTONE)
B(1,3,-9,COBBLESTONE)
B(1,3,-8,COBBLESTONE)
B(1,3,-7,COBBLESTONE)
B(1,3,-6,DIRT:1)
B(1,3,-5,DIRT:1)
B(1,3,-4,GRASS)
B(1,3,-3,GRASS)
B(1,3,-2,GRASS)
B(1,3,-1,AIR)
B(1,3,0,AIR)
B(1,3,1,COBBLESTONE)
B(1,3,2,LEAVES:3)
B(1,3,3,DIRT:1)
B(1,3,4,GRASS)
B(1,3,5,STONE)
B(1,3,6,COBBLESTONE)
B(1,3,7,COBBLESTONE)
B(1,3,8,COBBLESTONE)
B(1,3,9,COBBLESTONE)
B(1,3,10,COBBLESTONE)
B(1,4,-8,LEAVES:3)
B(1,4,-7,AIR)
B(1,4,-6,AIR)
B(1,4,-5,AIR)
B(1,4,-4,AIR)
B(1,4,-3,STEP)
B(1,4,-2,AIR)
B(1,4,-1,AIR)
B(1,4,0,AIR)
B(1,4,1,AIR)
B(1,4,2,AIR)
B(1,4,3,AIR)
B(1,4,4,LEAVES:3)
B(1,4,5,COBBLESTONE)
B(1,4,6,GRASS)
B(1,4,7,GRASS)
B(1,4,8,GRASS)
B(1,4,9,AIR)
B(1,4,10,LEAVES:3)
B(1,5,-7,AIR)
B(1,5,-6,AIR)
B(1,5,-5,AIR)
B(1,5,-4,LEAVES:3)
B(1,5,-3,AIR)
B(1,5,-2,AIR)
B(1,5,-1,AIR)
B(1,5,0,AIR)
B(1,5,1,AIR)
B(1,5,2,AIR)
B(1,5,3,AIR)
B(1,5,4,AIR)
B(1,5,5,COBBLESTONE)
B(1,5,6,LEAVES:3)
B(1,5,7,LEAVES:3)
B(1,5,8,LEAVES:3)
B(1,5,9,AIR)
B(1,6,-7,AIR)
B(1,6,-6,AIR)
B(1,6,-5,AIR)
B(1,6,-4,AIR)
B(1,6,-3,AIR)
B(1,6,-2,AIR)
B(1,6,-1,AIR)
B(1,6,0,AIR)
B(1,6,1,AIR)
B(1,6,2,AIR)
B(1,6,3,AIR)
B(1,6,4,AIR)
B(1,6,5,COBBLESTONE)
B(1,6,6,AIR)
B(1,6,7,LEAVES:3)
B(1,6,8,AIR)
B(1,6,9,AIR)
B(1,7,-7,AIR)
B(1,7,-6,AIR)
B(1,7,-5,AIR)
B(1,7,-4,AIR)
B(1,7,-3,AIR)
B(1,7,-2,AIR)
B(1,7,-1,AIR)
B(1,7,0,AIR)
B(1,7,1,AIR)
B(1,7,2,AIR)
B(1,7,3,AIR)
B(1,7,4,AIR)
B(1,7,5,AIR)
B(1,7,6,AIR)
B(1,7,7,AIR)
B(1,7,8,AIR)
B(1,7,9,AIR)
B(1,8,-10,LEAVES:3)
B(1,8,-9,COBBLESTONE_STAIRS:4)
B(1,8,-8,STEP:8)
B(1,8,-7,STEP:8)
B(1,8,-6,STEP:8)
B(1,8,-5,AIR)
B(1,8,-4,AIR)
B(1,8,-3,AIR)
B(1,8,-2,AIR)
B(1,8,-1,AIR)
B(1,8,0,AIR)
B(1,8,1,LEAVES:3)
B(1,8,2,AIR)
B(1,8,3,AIR)
B(1,8,4,AIR)
B(1,8,5,AIR)
B(1,8,6,STEP:8)
B(1,8,7,STEP:8)
B(1,8,8,STEP:8)
B(1,8,9,STEP:8)
B(1,8,10,COBBLESTONE_STAIRS:4)
B(1,9,-10,COBBLESTONE_STAIRS:6)
B(1,9,-9,COBBLESTONE)
B(1,9,-8,COBBLESTONE)
B(1,9,-7,COBBLESTONE)
B(1,9,-6,COBBLESTONE)
B(1,9,6,COBBLESTONE)
B(1,9,7,COBBLESTONE)
B(1,9,8,COBBLESTONE)
B(1,9,9,COBBLESTONE)
B(1,9,10,COBBLESTONE)
B(1,9,11,COBBLESTONE_STAIRS:7)
B(1,10,-10,DOUBLE_STEP:5)
B(1,10,-9,LEAVES:3)
B(1,10,-8,GRASS)
B(1,10,-7,GRASS)
B(1,10,-6,STEP:5)
B(1,10,6,COBBLESTONE)
B(1,10,7,COBBLESTONE)
B(1,10,8,GRASS)
B(1,10,9,GRASS)
B(1,10,10,GRASS)
B(1,10,11,DOUBLE_STEP:5)
B(1,11,-8,LEAVES:3)
B(1,11,7,LEAVES:3)
B(1,11,8,LEAVES:3)
B(1,11,9,LEAVES:3)
B(2,-16,-8,COBBLESTONE)
B(2,-16,-7,COBBLESTONE)
B(2,-16,-6,COBBLESTONE)
B(2,-16,-5,COBBLESTONE)
B(2,-16,-4,COBBLESTONE)
B(2,-16,-3,COBBLESTONE)
B(2,-16,-2,COBBLESTONE)
B(2,-16,-1,COBBLESTONE)
B(2,-16,0,COBBLESTONE)
B(2,-16,1,COBBLESTONE)
B(2,-16,2,COBBLESTONE)
B(2,-16,3,COBBLESTONE)
B(2,-16,4,COBBLESTONE)
B(2,-16,5,COBBLESTONE)
B(2,-16,6,COBBLESTONE)
B(2,-16,7,COBBLESTONE)
B(2,-16,8,COBBLESTONE)
B(2,-16,9,COBBLESTONE)
B(2,-16,10,COBBLESTONE)
B(2,-15,-8,COBBLESTONE)
B(2,-15,-7,COBBLESTONE)
B(2,-15,-6,COBBLESTONE)
B(2,-15,-5,COBBLESTONE)
B(2,-15,-4,COBBLESTONE)
B(2,-15,-3,COBBLESTONE)
B(2,-15,-2,COBBLESTONE)
B(2,-15,-1,COBBLESTONE)
B(2,-15,0,COBBLESTONE)
B(2,-15,1,COBBLESTONE)
B(2,-15,2,COBBLESTONE)
B(2,-15,3,COBBLESTONE)
B(2,-15,4,COBBLESTONE)
B(2,-15,5,COBBLESTONE)
B(2,-15,6,COBBLESTONE)
B(2,-15,7,COBBLESTONE)
B(2,-15,8,COBBLESTONE)
B(2,-15,9,COBBLESTONE)
B(2,-15,10,COBBLESTONE)
B(2,-14,-8,COBBLESTONE)
B(2,-14,-7,COBBLESTONE)
B(2,-14,-6,COBBLESTONE)
B(2,-14,-5,COBBLESTONE)
B(2,-14,-4,COBBLESTONE)
B(2,-14,-3,COBBLESTONE)
B(2,-14,-2,COBBLESTONE)
B(2,-14,-1,COBBLESTONE)
B(2,-14,0,COBBLESTONE)
B(2,-14,1,COBBLESTONE)
B(2,-14,2,COBBLESTONE)
B(2,-14,3,COBBLESTONE)
B(2,-14,4,COBBLESTONE)
B(2,-14,5,COBBLESTONE)
B(2,-14,6,COBBLESTONE)
B(2,-14,7,COBBLESTONE)
B(2,-14,8,COBBLESTONE)
B(2,-14,9,COBBLESTONE)
B(2,-14,10,COBBLESTONE)
B(2,-13,-8,COBBLESTONE)
B(2,-13,-7,COBBLESTONE)
B(2,-13,-6,COBBLESTONE)
B(2,-13,-5,COBBLESTONE)
B(2,-13,-4,COBBLESTONE)
B(2,-13,-3,COBBLESTONE)
B(2,-13,-2,COBBLESTONE)
B(2,-13,-1,COBBLESTONE)
B(2,-13,0,COBBLESTONE)
B(2,-13,1,COBBLESTONE)
B(2,-13,2,COBBLESTONE)
B(2,-13,3,COBBLESTONE)
B(2,-13,4,COBBLESTONE)
B(2,-13,5,COBBLESTONE)
B(2,-13,6,COBBLESTONE)
B(2,-13,7,COBBLESTONE)
B(2,-13,8,COBBLESTONE)
B(2,-13,9,COBBLESTONE)
B(2,-13,10,COBBLESTONE)
B(2,-12,-8,COBBLESTONE)
B(2,-12,-7,COBBLESTONE)
B(2,-12,-6,COBBLESTONE)
B(2,-12,-5,COBBLESTONE)
B(2,-12,-4,COBBLESTONE)
B(2,-12,-3,COBBLESTONE)
B(2,-12,-2,COBBLESTONE)
B(2,-12,-1,COBBLESTONE)
B(2,-12,0,COBBLESTONE)
B(2,-12,1,COBBLESTONE)
B(2,-12,2,COBBLESTONE)
B(2,-12,3,COBBLESTONE)
B(2,-12,4,COBBLESTONE)
B(2,-12,5,COBBLESTONE)
B(2,-12,6,COBBLESTONE)
B(2,-12,7,COBBLESTONE)
B(2,-12,8,COBBLESTONE)
B(2,-12,9,COBBLESTONE)
B(2,-12,10,COBBLESTONE)
B(2,-11,-8,COBBLESTONE)
B(2,-11,-7,COBBLESTONE)
B(2,-11,-6,COBBLESTONE)
B(2,-11,-5,COBBLESTONE)
B(2,-11,-4,COBBLESTONE)
B(2,-11,-3,COBBLESTONE)
B(2,-11,-2,COBBLESTONE)
B(2,-11,-1,COBBLESTONE)
B(2,-11,0,COBBLESTONE)
B(2,-11,1,COBBLESTONE)
B(2,-11,2,COBBLESTONE)
B(2,-11,3,COBBLESTONE)
B(2,-11,4,COBBLESTONE)
B(2,-11,5,COBBLESTONE)
B(2,-11,6,COBBLESTONE)
B(2,-11,7,COBBLESTONE)
B(2,-11,8,COBBLESTONE)
B(2,-11,9,COBBLESTONE)
B(2,-11,10,COBBLESTONE)
B(2,-10,-8,COBBLESTONE)
B(2,-10,-7,COBBLESTONE)
B(2,-10,-6,COBBLESTONE)
B(2,-10,-5,COBBLESTONE)
B(2,-10,-4,COBBLESTONE)
B(2,-10,-3,COBBLESTONE)
B(2,-10,-2,COBBLESTONE)
B(2,-10,-1,COBBLESTONE)
B(2,-10,0,COBBLESTONE)
B(2,-10,1,COBBLESTONE)
B(2,-10,2,COBBLESTONE)
B(2,-10,3,COBBLESTONE)
B(2,-10,4,COBBLESTONE)
B(2,-10,5,COBBLESTONE)
B(2,-10,6,COBBLESTONE)
B(2,-10,7,COBBLESTONE)
B(2,-10,8,COBBLESTONE)
B(2,-10,9,COBBLESTONE)
B(2,-10,10,COBBLESTONE)
B(2,-9,-8,COBBLESTONE)
B(2,-9,-7,COBBLESTONE)
B(2,-9,-6,COBBLESTONE)
B(2,-9,-5,COBBLESTONE)
B(2,-9,-4,COBBLESTONE)
B(2,-9,-3,COBBLESTONE)
B(2,-9,-2,COBBLESTONE)
B(2,-9,-1,COBBLESTONE)
B(2,-9,0,COBBLESTONE)
B(2,-9,1,COBBLESTONE)
B(2,-9,2,COBBLESTONE)
B(2,-9,3,COBBLESTONE)
B(2,-9,4,COBBLESTONE)
B(2,-9,5,COBBLESTONE)
B(2,-9,6,COBBLESTONE)
B(2,-9,7,COBBLESTONE)
B(2,-9,8,COBBLESTONE)
B(2,-9,9,COBBLESTONE)
B(2,-9,10,COBBLESTONE)
B(2,-8,-8,COBBLESTONE)
B(2,-8,-7,COBBLESTONE)
B(2,-8,-6,COBBLESTONE)
B(2,-8,-5,COBBLESTONE)
B(2,-8,-4,COBBLESTONE)
B(2,-8,-3,COBBLESTONE)
B(2,-8,-2,COBBLESTONE)
B(2,-8,-1,COBBLESTONE)
B(2,-8,0,COBBLESTONE)
B(2,-8,1,COBBLESTONE)
B(2,-8,2,COBBLESTONE)
B(2,-8,3,COBBLESTONE)
B(2,-8,4,COBBLESTONE)
B(2,-8,5,COBBLESTONE)
B(2,-8,6,COBBLESTONE)
B(2,-8,7,COBBLESTONE)
B(2,-8,8,COBBLESTONE)
B(2,-8,9,COBBLESTONE)
B(2,-8,10,COBBLESTONE)
B(2,-7,-8,COBBLESTONE)
B(2,-7,-7,COBBLESTONE)
B(2,-7,-6,COBBLESTONE)
B(2,-7,-5,COBBLESTONE)
B(2,-7,-4,COBBLESTONE)
B(2,-7,-3,COBBLESTONE)
B(2,-7,-2,COBBLESTONE)
B(2,-7,-1,COBBLESTONE)
B(2,-7,0,COBBLESTONE)
B(2,-7,1,COBBLESTONE)
B(2,-7,2,COBBLESTONE)
B(2,-7,3,COBBLESTONE)
B(2,-7,4,COBBLESTONE)
B(2,-7,5,COBBLESTONE)
B(2,-7,6,COBBLESTONE)
B(2,-7,7,COBBLESTONE)
B(2,-7,8,COBBLESTONE)
B(2,-7,9,COBBLESTONE)
B(2,-7,10,COBBLESTONE)
B(2,-6,-8,COBBLESTONE)
B(2,-6,-7,COBBLESTONE)
B(2,-6,-6,COBBLESTONE)
B(2,-6,-5,COBBLESTONE)
B(2,-6,-4,COBBLESTONE)
B(2,-6,-3,COBBLESTONE)
B(2,-6,-2,COBBLESTONE)
B(2,-6,-1,COBBLESTONE)
B(2,-6,0,COBBLESTONE)
B(2,-6,1,COBBLESTONE)
B(2,-6,2,COBBLESTONE)
B(2,-6,3,COBBLESTONE)
B(2,-6,4,COBBLESTONE)
B(2,-6,5,COBBLESTONE)
B(2,-6,6,COBBLESTONE)
B(2,-6,7,COBBLESTONE)
B(2,-6,8,COBBLESTONE)
B(2,-6,9,COBBLESTONE)
B(2,-6,10,COBBLESTONE)
B(2,-5,-8,COBBLESTONE)
B(2,-5,-7,COBBLESTONE)
B(2,-5,-6,COBBLESTONE)
B(2,-5,-5,COBBLESTONE)
B(2,-5,-4,COBBLESTONE)
B(2,-5,-3,COBBLESTONE)
B(2,-5,-2,COBBLESTONE)
B(2,-5,-1,COBBLESTONE)
B(2,-5,0,COBBLESTONE)
B(2,-5,1,COBBLESTONE)
B(2,-5,2,COBBLESTONE)
B(2,-5,3,COBBLESTONE)
B(2,-5,4,COBBLESTONE)
B(2,-5,5,COBBLESTONE)
B(2,-5,6,COBBLESTONE)
B(2,-5,7,COBBLESTONE)
B(2,-5,8,COBBLESTONE)
B(2,-5,9,COBBLESTONE)
B(2,-5,10,COBBLESTONE)
B(2,-4,-8,COBBLESTONE)
B(2,-4,-7,COBBLESTONE)
B(2,-4,-6,COBBLESTONE)
B(2,-4,-5,COBBLESTONE)
B(2,-4,-4,COBBLESTONE)
B(2,-4,-3,COBBLESTONE)
B(2,-4,-2,COBBLESTONE)
B(2,-4,-1,COBBLESTONE)
B(2,-4,0,COBBLESTONE)
B(2,-4,1,COBBLESTONE)
B(2,-4,2,COBBLESTONE)
B(2,-4,3,COBBLESTONE)
B(2,-4,4,COBBLESTONE)
B(2,-4,5,COBBLESTONE)
B(2,-4,6,COBBLESTONE)
B(2,-4,7,COBBLESTONE)
B(2,-4,8,COBBLESTONE)
B(2,-4,9,COBBLESTONE)
B(2,-4,10,COBBLESTONE)
B(2,-3,-8,COBBLESTONE)
B(2,-3,-7,COBBLESTONE)
B(2,-3,-6,COBBLESTONE)
B(2,-3,-5,COBBLESTONE)
B(2,-3,-4,COBBLESTONE)
B(2,-3,-3,COBBLESTONE)
B(2,-3,-2,COBBLESTONE)
B(2,-3,-1,COBBLESTONE)
B(2,-3,0,STEP:8)
B(2,-3,1,COBBLESTONE)
B(2,-3,2,COBBLESTONE)
B(2,-3,3,COBBLESTONE)
B(2,-3,4,COBBLESTONE)
B(2,-3,5,COBBLESTONE)
B(2,-3,6,COBBLESTONE)
B(2,-3,7,COBBLESTONE)
B(2,-3,8,COBBLESTONE)
B(2,-3,9,COBBLESTONE)
B(2,-3,10,COBBLESTONE)
B(2,-2,-9,COBBLESTONE)
B(2,-2,-8,COBBLESTONE)
B(2,-2,-7,COBBLESTONE)
B(2,-2,-6,AIR)
B(2,-2,-5,AIR)
B(2,-2,-4,AIR)
B(2,-2,-3,AIR)
B(2,-2,-2,AIR)
B(2,-2,-1,AIR)
B(2,-2,0,STEP)
B(2,-2,1,DOUBLE_STEP)
B(2,-2,2,COBBLESTONE)
B(2,-2,3,STEP:8)
B(2,-2,4,STEP:8)
B(2,-2,5,STEP:8)
B(2,-2,6,STEP:8)
B(2,-2,7,STEP:8)
B(2,-2,8,STEP:8)
B(2,-2,9,STEP:8)
B(2,-2,10,COBBLESTONE)
B(2,-1,-8,COBBLESTONE)
B(2,-1,-7,COBBLESTONE)
B(2,-1,-6,AIR)
B(2,-1,-5,AIR)
B(2,-1,-4,AIR)
B(2,-1,-3,AIR)
B(2,-1,-2,AIR)
B(2,-1,-1,AIR)
B(2,-1,0,AIR)
B(2,-1,1,AIR)
B(2,-1,2,AIR)
B(2,-1,3,AIR)
B(2,-1,4,AIR)
B(2,-1,5,GRAVEL)
B(2,-1,6,GRAVEL)
B(2,-1,7,GRAVEL)
B(2,-1,8,AIR)
B(2,-1,9,COBBLESTONE)
B(2,-1,10,COBBLESTONE)
B(2,0,-8,COBBLESTONE)
B(2,0,-7,COBBLESTONE)
B(2,0,-6,AIR)
B(2,0,-5,AIR)
B(2,0,-4,AIR)
B(2,0,-3,AIR)
B(2,0,-2,AIR)
B(2,0,-1,AIR)
B(2,0,0,AIR)
B(2,0,1,AIR)
B(2,0,2,AIR)
B(2,0,3,AIR)
B(2,0,4,AIR)
B(2,0,5,AIR)
B(2,0,6,GRAVEL)
B(2,0,7,AIR)
B(2,0,8,AIR)
B(2,0,9,COBBLESTONE)
B(2,0,10,COBBLESTONE)
B(2,1,-8,COBBLESTONE)
B(2,1,-7,COBBLESTONE)
B(2,1,-6,STEP:8)
B(2,1,-5,AIR)
B(2,1,-4,AIR)
B(2,1,-3,AIR)
B(2,1,-2,AIR)
B(2,1,-1,AIR)
B(2,1,0,AIR)
B(2,1,1,AIR)
B(2,1,2,AIR)
B(2,1,3,AIR)
B(2,1,4,AIR)
B(2,1,9,COBBLESTONE)
B(2,1,10,COBBLESTONE)
B(2,2,-9,COBBLESTONE_STAIRS:4)
B(2,2,-8,COBBLESTONE)
B(2,2,-7,COBBLESTONE)
B(2,2,-6,DOUBLE_STEP)
B(2,2,-5,DOUBLE_STEP)
B(2,2,-4,STEP:8)
B(2,2,-3,STEP:8)
B(2,2,-2,STEP:8)
B(2,2,-1,AIR)
B(2,2,0,STEP:8)
B(2,2,1,STEP:8)
B(2,2,2,STEP:8)
B(2,2,3,DOUBLE_STEP)
B(2,2,4,STEP:8)
B(2,2,5,STEP:8)
B(2,2,6,DOUBLE_STEP)
B(2,2,7,STEP:8)
B(2,2,8,DOUBLE_STEP)
B(2,2,9,COBBLESTONE)
B(2,2,10,COBBLESTONE)
B(2,3,-9,COBBLESTONE)
B(2,3,-8,COBBLESTONE)
B(2,3,-7,DIRT:1)
B(2,3,-6,DIRT:1)
B(2,3,-5,GRASS)
B(2,3,-4,GRASS)
B(2,3,-3,COBBLESTONE)
B(2,3,-2,DIRT)
B(2,3,-1,DIRT)
B(2,3,0,GRASS)
B(2,3,1,COBBLESTONE)
B(2,3,2,GRASS)
B(2,3,3,DIRT:1)
B(2,3,4,COBBLESTONE)
B(2,3,5,COBBLESTONE)
B(2,3,6,COBBLESTONE)
B(2,3,7,COBBLESTONE)
B(2,3,8,DIRT:1)
B(2,3,9,DIRT)
B(2,3,10,COBBLESTONE)
B(2,4,-9,COBBLESTONE)
B(2,4,-8,LEAVES:3)
B(2,4,-7,AIR)
B(2,4,-6,AIR)
B(2,4,-5,AIR)
B(2,4,-4,AIR)
B(2,4,-3,COBBLESTONE)
B(2,4,-2,COBBLESTONE)
B(2,4,-1,GRAVEL)
B(2,4,0,AIR)
B(2,4,1,AIR)
B(2,4,2,AIR)
B(2,4,3,AIR)
B(2,4,4,STEP)
B(2,4,5,GRASS)
B(2,4,6,GRASS)
B(2,4,7,DIRT)
B(2,4,8,GRASS)
B(2,4,9,GRASS)
B(2,4,10,COBBLESTONE)
B(2,4,11,LEAVES:3)
B(2,5,-9,COBBLESTONE)
B(2,5,-8,LEAVES:3)
B(2,5,-7,AIR)
B(2,5,-6,AIR)
B(2,5,-5,AIR)
B(2,5,-4,AIR)
B(2,5,-3,AIR)
B(2,5,-2,GRAVEL)
B(2,5,-1,AIR)
B(2,5,0,AIR)
B(2,5,1,AIR)
B(2,5,2,AIR)
B(2,5,3,AIR)
B(2,5,4,AIR)
B(2,5,5,LEAVES:3)
B(2,5,6,LEAVES:3)
B(2,5,7,LOG:3)
B(2,5,8,LEAVES:3)
B(2,5,9,AIR)
B(2,5,10,COBBLESTONE)
B(2,5,11,LEAVES:3)
B(2,6,-9,COBBLESTONE)
B(2,6,-7,AIR)
B(2,6,-6,AIR)
B(2,6,-5,AIR)
B(2,6,-4,AIR)
B(2,6,-3,AIR)
B(2,6,-2,LEAVES:3)
B(2,6,-1,AIR)
B(2,6,0,AIR)
B(2,6,1,AIR)
B(2,6,2,AIR)
B(2,6,3,AIR)
B(2,6,4,AIR)
B(2,6,5,AIR)
B(2,6,6,LEAVES:3)
B(2,6,7,LEAVES:3)
B(2,6,8,AIR)
B(2,6,9,AIR)
B(2,6,10,COBBLESTONE)
B(2,7,-10,LEAVES:3)
B(2,7,-9,COBBLESTONE)
B(2,7,-7,AIR)
B(2,7,-6,AIR)
B(2,7,-5,AIR)
B(2,7,-4,AIR)
B(2,7,-3,AIR)
B(2,7,-2,AIR)
B(2,7,-1,AIR)
B(2,7,0,AIR)
B(2,7,1,AIR)
B(2,7,2,AIR)
B(2,7,3,AIR)
B(2,7,4,AIR)
B(2,7,5,AIR)
B(2,7,6,AIR)
B(2,7,7,AIR)
B(2,7,8,AIR)
B(2,7,9,AIR)
B(2,7,10,COBBLESTONE)
B(2,8,-10,LEAVES:3)
B(2,8,-9,COBBLESTONE)
B(2,8,-8,STEP:8)
B(2,8,-7,STEP:8)
B(2,8,-6,STEP:8)
B(2,8,-5,STEP:8)
B(2,8,-4,STEP:8)
B(2,8,-3,AIR)
B(2,8,-2,AIR)
B(2,8,-1,AIR)
B(2,8,0,LEAVES:3)
B(2,8,1,LEAVES:3)
B(2,8,2,LEAVES:3)
B(2,8,3,AIR)
B(2,8,4,AIR)
B(2,8,5,STEP:8)
B(2,8,6,STEP:8)
B(2,8,7,STEP:8)
B(2,8,8,STEP:8)
B(2,8,9,STEP:8)
B(2,8,10,COBBLESTONE)
B(2,9,-9,COBBLESTONE)
B(2,9,-8,COBBLESTONE)
B(2,9,-7,COBBLESTONE)
B(2,9,-6,COBBLESTONE)
B(2,9,-5,GRASS)
B(2,9,-4,GRASS)
B(2,9,1,LEAVES:3)
B(2,9,5,GRASS)
B(2,9,6,DIRT:1)
B(2,9,7,COBBLESTONE)
B(2,9,8,STONE)
B(2,9,9,COBBLESTONE)
B(2,9,10,COBBLESTONE)
B(2,10,-10,STEP:5)
B(2,10,-9,LEAVES:3)
B(2,10,-8,GRASS)
B(2,10,-7,COBBLESTONE_STAIRS:2)
B(2,10,-6,COBBLESTONE)
B(2,10,6,DIRT:1)
B(2,10,7,COBBLESTONE_STAIRS:1)
B(2,10,8,COBBLESTONE_STAIRS:0)
B(2,10,9,GRASS)
B(2,10,10,GRASS)
B(2,10,11,STEP:5)
B(2,11,-8,LEAVES:3)
B(2,11,-7,COBBLESTONE_STAIRS:2)
B(2,11,-6,COBBLESTONE)
B(2,11,7,COBBLESTONE)
B(2,11,8,COBBLESTONE_STAIRS:0)
B(2,11,9,LEAVES:3)
B(2,11,10,LEAVES:3)
B(2,12,7,LEAVES:3)
B(2,12,8,LEAVES:3)
B(3,-16,-9,COBBLESTONE)
B(3,-16,-8,COBBLESTONE)
B(3,-16,-7,COBBLESTONE)
B(3,-16,-6,COBBLESTONE)
B(3,-16,-5,COBBLESTONE)
B(3,-16,-4,COBBLESTONE)
B(3,-16,-3,COBBLESTONE)
B(3,-16,-2,COBBLESTONE)
B(3,-16,-1,COBBLESTONE)
B(3,-16,0,COBBLESTONE)
B(3,-16,1,COBBLESTONE)
B(3,-16,2,COBBLESTONE)
B(3,-16,3,COBBLESTONE)
B(3,-16,4,COBBLESTONE)
B(3,-16,5,COBBLESTONE)
B(3,-16,6,COBBLESTONE)
B(3,-16,7,COBBLESTONE)
B(3,-16,8,COBBLESTONE)
B(3,-16,9,COBBLESTONE)
B(3,-15,-9,COBBLESTONE)
B(3,-15,-8,COBBLESTONE)
B(3,-15,-7,COBBLESTONE)
B(3,-15,-6,COBBLESTONE)
B(3,-15,-5,COBBLESTONE)
B(3,-15,-4,COBBLESTONE)
B(3,-15,-3,COBBLESTONE)
B(3,-15,-2,COBBLESTONE)
B(3,-15,-1,COBBLESTONE)
B(3,-15,0,COBBLESTONE)
B(3,-15,1,COBBLESTONE)
B(3,-15,2,COBBLESTONE)
B(3,-15,3,COBBLESTONE)
B(3,-15,4,COBBLESTONE)
B(3,-15,5,COBBLESTONE)
B(3,-15,6,COBBLESTONE)
B(3,-15,7,COBBLESTONE)
B(3,-15,8,COBBLESTONE)
B(3,-15,9,COBBLESTONE)
B(3,-14,-9,COBBLESTONE)
B(3,-14,-8,COBBLESTONE)
B(3,-14,-7,COBBLESTONE)
B(3,-14,-6,COBBLESTONE)
B(3,-14,-5,COBBLESTONE)
B(3,-14,-4,COBBLESTONE)
B(3,-14,-3,COBBLESTONE)
B(3,-14,-2,COBBLESTONE)
B(3,-14,-1,COBBLESTONE)
B(3,-14,0,COBBLESTONE)
B(3,-14,1,COBBLESTONE)
B(3,-14,2,COBBLESTONE)
B(3,-14,3,COBBLESTONE)
B(3,-14,4,COBBLESTONE)
B(3,-14,5,COBBLESTONE)
B(3,-14,6,COBBLESTONE)
B(3,-14,7,COBBLESTONE)
B(3,-14,8,COBBLESTONE)
B(3,-14,9,COBBLESTONE)
B(3,-13,-9,COBBLESTONE)
B(3,-13,-8,COBBLESTONE)
B(3,-13,-7,COBBLESTONE)
B(3,-13,-6,COBBLESTONE)
B(3,-13,-5,COBBLESTONE)
B(3,-13,-4,COBBLESTONE)
B(3,-13,-3,COBBLESTONE)
B(3,-13,-2,COBBLESTONE)
B(3,-13,-1,COBBLESTONE)
B(3,-13,0,COBBLESTONE)
B(3,-13,1,COBBLESTONE)
B(3,-13,2,COBBLESTONE)
B(3,-13,3,COBBLESTONE)
B(3,-13,4,COBBLESTONE)
B(3,-13,5,COBBLESTONE)
B(3,-13,6,COBBLESTONE)
B(3,-13,7,COBBLESTONE)
B(3,-13,8,COBBLESTONE)
B(3,-13,9,COBBLESTONE)
B(3,-12,-9,COBBLESTONE)
B(3,-12,-8,COBBLESTONE)
B(3,-12,-7,COBBLESTONE)
B(3,-12,-6,COBBLESTONE)
B(3,-12,-5,COBBLESTONE)
B(3,-12,-4,COBBLESTONE)
B(3,-12,-3,COBBLESTONE)
B(3,-12,-2,COBBLESTONE)
B(3,-12,-1,COBBLESTONE)
B(3,-12,0,COBBLESTONE)
B(3,-12,1,COBBLESTONE)
B(3,-12,2,COBBLESTONE)
B(3,-12,3,COBBLESTONE)
B(3,-12,4,COBBLESTONE)
B(3,-12,5,COBBLESTONE)
B(3,-12,6,COBBLESTONE)
B(3,-12,7,COBBLESTONE)
B(3,-12,8,COBBLESTONE)
B(3,-12,9,COBBLESTONE)
B(3,-11,-9,COBBLESTONE)
B(3,-11,-8,COBBLESTONE)
B(3,-11,-7,COBBLESTONE)
B(3,-11,-6,COBBLESTONE)
B(3,-11,-5,COBBLESTONE)
B(3,-11,-4,COBBLESTONE)
B(3,-11,-3,COBBLESTONE)
B(3,-11,-2,COBBLESTONE)
B(3,-11,-1,COBBLESTONE)
B(3,-11,0,COBBLESTONE)
B(3,-11,1,COBBLESTONE)
B(3,-11,2,COBBLESTONE)
B(3,-11,3,COBBLESTONE)
B(3,-11,4,COBBLESTONE)
B(3,-11,5,COBBLESTONE)
B(3,-11,6,COBBLESTONE)
B(3,-11,7,COBBLESTONE)
B(3,-11,8,COBBLESTONE)
B(3,-11,9,COBBLESTONE)
B(3,-10,-9,COBBLESTONE)
B(3,-10,-8,COBBLESTONE)
B(3,-10,-7,COBBLESTONE)
B(3,-10,-6,COBBLESTONE)
B(3,-10,-5,COBBLESTONE)
B(3,-10,-4,COBBLESTONE)
