#######################################################################
# +-----------------------------------------------------------------+ #
# |                            BO3 object                           | #
# +-----------------------------------------------------------------+ #
#######################################################################

# The descriptions in this file are true only for TerrainControl. They are not true for the Minecraft Worlds mod!
# Minecraft Worlds completely reimplemented BO3s, check the MCW documentation on the mc/mctcp forums for how to use BO3s with MCW
# or watch the video's on my YT channel at https://www.youtube.com/user/PeeGee85. You can check out the "Editing and importing schematics & BO3s" 
# series of video's, in part 2 I explain BO3s. 

# This is the config file of a custom object.
# If you add this object correctly to your BiomeConfigs, it will spawn in the world.

# This is the creator of this BO3 object
Author: Unknown

# A short description of this BO3 object
Description: This BO3 was converted from a schematic using the MineCraft Worlds Editor. Unfortunately the author and description information for the schematic could not be found. If you know who the author of the schematic is then please tell the author of this BO3!

# The BO3 version, don't change this! It can be used by external applications to do a version check.
Version: 3

# The settings mode, WriteAll, WriteWithoutComments or WriteDisable. See WorldConfig.
SettingsMode: WriteDisable

#######################################################################
# +-----------------------------------------------------------------+ #
# |                          Main settings                          | #
# +-----------------------------------------------------------------+ #
#######################################################################

# This needs to be set to true to spawn the object in the Tree and Sapling resources.
Tree: false

# The frequency of the BO3 from 1 to 200. Tries this many times to spawn this BO3 when using the CustomObject(...) resource.
# Ignored by Tree(..), Sapling(..) and CustomStructure(..)
Frequency: 1

# The rarity of the BO3 from 0 to 100. Each spawn attempt has rarity% chance to succeed when using the CustomObject(...) resource.
# Ignored by Tree(..), Sapling(..) and CustomStructure(..)
Rarity: 100.0

# If you set this to true, the BO3 will be placed with a random rotation.
RotateRandomly: false

# The spawn height of the BO3 - randomY, highestBlock or highestSolidBlock.
SpawnHeight: randomY

# The height limits for the BO3.
MinHeight: 25

MaxHeight: 29

# Objects can have other objects attached to it: branches. Branches can also
# have branches attached to it, which can also have branches, etc. This is the
# maximum branch depth for this objects.
MaxBranchDepth: 10

# When spawned with the UseWorld keyword, this BO3 should NOT spawn in the following biomes.
# If you writer.write the BO3 name directly in the BiomeConfigs, this will be ignored.
ExcludedBiomes: All

#######################################################################
# +-----------------------------------------------------------------+ #
# |                      Source block settings                      | #
# +-----------------------------------------------------------------+ #
#######################################################################

# The block(s) the BO3 should spawn in.
SourceBlocks: AIR

# The maximum percentage of the BO3 that can be outside the SourceBlock.
# The BO3 won't be placed on a location with more blocks outside the SourceBlock than this percentage.
MaxPercentageOutsideSourceBlock: 100

# What to do when a block is about to be placed outside the SourceBlock? (dontPlace, placeAnyway)
OutsideSourceBlock: placeAnyway

#######################################################################
# +-----------------------------------------------------------------+ #
# |                              Blocks                             | #
# +-----------------------------------------------------------------+ #
#######################################################################

# All the blocks used in the BO3 are listed here. Possible blocks:
# Block(x,y,z,id[.data][,nbtfile.nbt)
# RandomBlock(x,y,z,id[:data][,nbtfile.nbt],chance[,id[:data][,nbtfile.nbt],chance[,...]])
# So RandomBlock(0,0,0,CHEST,chest.nbt,50,CHEST,anotherchest.nbt,100) will spawn a chest at
# the BO3 origin, and give it a 50% chance to have the contents of chest.nbt, or, if that
# fails, a 100% percent chance to have the contents of anotherchest.nbt.

Block(-8,0,-7,4)
Block(-8,0,-6,4)
Block(-8,0,-5,4)
Block(-8,0,-3,4)
Block(-8,0,-1,4)
Block(-8,0,1,4)
Block(-8,0,2,4)
Block(-8,0,3,4)
Block(-8,1,-7,4)
Block(-8,1,-6,4)
Block(-8,1,-5,4)
Block(-8,1,-3,4)
Block(-8,1,-1,4)
Block(-8,1,1,4)
Block(-8,1,2,4)
Block(-8,1,3,4)
Block(-8,2,-7,4)
Block(-8,2,-6,4)
Block(-8,2,-5,4)
Block(-8,2,-3,4)
Block(-8,2,-1,4)
Block(-8,2,1,4)
Block(-8,2,2,4)
Block(-8,2,3,4)
Block(-8,3,-7,4)
Block(-8,3,-6,4)
Block(-8,3,-5,4)
Block(-8,3,-3,4)
Block(-8,3,-1,4)
Block(-8,3,1,4)
Block(-8,3,2,4)
Block(-8,3,3,4)
Block(-8,4,-7,4)
Block(-8,4,-6,4)
Block(-8,4,-5,4)
Block(-8,4,-3,4)
Block(-8,4,-1,4)
Block(-8,4,1,4)
Block(-8,4,2,4)
Block(-8,4,3,4)
Block(-8,5,-7,4)
Block(-8,5,-6,4)
Block(-8,5,-5,4)
Block(-8,5,-3,4)
Block(-8,5,-1,4)
Block(-8,5,1,4)
Block(-8,5,2,4)
Block(-8,5,3,4)
Block(-8,6,-7,4)
Block(-8,6,-6,4)
Block(-8,6,-5,4)
Block(-8,6,-3,4)
Block(-8,6,-1,4)
Block(-8,6,1,4)
Block(-8,6,2,4)
Block(-8,6,3,4)
Block(-8,7,-7,4)
Block(-8,7,-6,4)
Block(-8,7,-5,4)
Block(-8,7,-3,4)
Block(-8,7,-1,4)
Block(-8,7,1,4)
Block(-8,7,2,4)
Block(-8,7,3,4)
Block(-8,8,-7,4)
Block(-8,8,-6,4)
Block(-8,8,-5,4)
Block(-8,8,-3,4)
Block(-8,8,-1,4)
Block(-8,8,1,4)
Block(-8,8,2,4)
Block(-8,8,3,4)
Block(-8,9,-7,4)
Block(-8,9,-6,4)
Block(-8,9,-5,4)
Block(-8,9,-3,4)
Block(-8,9,-1,4)
Block(-8,9,1,4)
Block(-8,9,2,4)
Block(-8,9,3,4)
Block(-8,10,-7,4)
Block(-8,10,-6,4)
Block(-8,10,-5,4)
Block(-8,10,-3,4)
Block(-8,10,-1,4)
Block(-8,10,1,4)
Block(-8,10,2,4)
Block(-8,10,3,4)
Block(-8,11,-7,4)
Block(-8,11,-6,4)
Block(-8,11,-5,4)
Block(-8,11,-3,4)
Block(-8,11,-1,4)
Block(-8,11,1,4)
Block(-8,11,2,4)
Block(-8,11,3,4)
Block(-8,12,-7,4)
Block(-8,12,-6,4)
Block(-8,12,-5,4)
Block(-8,12,-3,4)
Block(-8,12,-1,4)
Block(-8,12,1,4)
Block(-8,12,2,4)
Block(-8,12,3,4)
Block(-8,13,-7,4)
Block(-8,13,-6,4)
Block(-8,13,-5,4)
Block(-8,13,-3,4)
Block(-8,13,-1,4)
Block(-8,13,1,4)
Block(-8,13,2,4)
Block(-8,13,3,4)
Block(-8,14,-7,4)
Block(-8,14,-6,4)
Block(-8,14,-5,4)
Block(-8,14,-3,4)
Block(-8,14,-1,4)
Block(-8,14,1,4)
Block(-8,14,2,4)
Block(-8,14,3,4)
Block(-8,15,-7,4)
Block(-8,15,-6,4)
Block(-8,15,-5,4)
Block(-8,15,-3,4)
Block(-8,15,-1,4)
Block(-8,15,1,4)
Block(-8,15,2,4)
Block(-8,15,3,4)
Block(-8,16,-7,4)
Block(-8,16,-6,4)
Block(-8,16,-5,4)
Block(-8,16,-3,4)
Block(-8,16,-1,4)
Block(-8,16,1,4)
Block(-8,16,2,4)
Block(-8,16,3,4)
Block(-8,17,-7,4)
Block(-8,17,-6,4)
Block(-8,17,-5,4)
Block(-8,17,-3,4)
Block(-8,17,-1,4)
Block(-8,17,1,4)
Block(-8,17,2,4)
Block(-8,17,3,4)
Block(-8,18,-7,4)
Block(-8,18,-6,4)
Block(-8,18,-5,4)
Block(-8,18,-3,4)
Block(-8,18,-1,4)
Block(-8,18,1,4)
Block(-8,18,2,4)
Block(-8,18,3,4)
Block(-8,19,-6,4)
Block(-8,19,-3,4)
Block(-8,19,-1,4)
Block(-8,19,1,18:7)
Block(-8,19,2,4)
Block(-8,20,-6,4)
Block(-8,20,-3,4)
Block(-8,20,-2,18:7)
Block(-8,20,-1,4)
Block(-8,20,0,18:15)
Block(-8,20,1,18:7)
Block(-8,20,2,4)
Block(-8,21,-7,67:6)
Block(-8,21,-6,4)
Block(-8,21,-5,67:7)
Block(-8,21,-1,18:7)
Block(-8,21,0,18:15)
Block(-8,21,1,67:6)
Block(-8,21,2,4)
Block(-8,21,3,67:7)
Block(-8,27,-6,139)
Block(-8,27,-5,18:7)
Block(-8,27,-4,139)
Block(-8,27,-2,139)
Block(-8,27,0,139)
Block(-8,27,2,139)
Block(-8,27,4,139)
Block(-8,27,6,139)
Block(-8,28,-6,18:7)
Block(-8,28,-5,18:7)
Block(-7,0,-7,4)
Block(-7,0,-6,4)
Block(-7,0,-5,4)
Block(-7,0,-4,4)
Block(-7,0,-3,4)
Block(-7,0,-2,4)
Block(-7,0,-1,4)
Block(-7,0,0,4)
Block(-7,0,1,4)
Block(-7,0,2,4)
Block(-7,0,3,4)
Block(-7,0,4,4)
Block(-7,0,5,98)
Block(-7,0,6,98)
Block(-7,1,-7,4)
Block(-7,1,-6,4)
Block(-7,1,-5,4)
Block(-7,1,-4,4)
Block(-7,1,-3,4)
Block(-7,1,-2,4)
Block(-7,1,-1,4)
Block(-7,1,0,4)
Block(-7,1,1,4)
Block(-7,1,2,4)
Block(-7,1,3,4)
Block(-7,1,4,4)
Block(-7,1,5,98)
Block(-7,1,6,98)
Block(-7,2,-7,4)
Block(-7,2,-6,4)
Block(-7,2,-5,4)
Block(-7,2,-4,4)
Block(-7,2,-3,4)
Block(-7,2,-2,4)
Block(-7,2,-1,4)
Block(-7,2,0,4)
Block(-7,2,1,4)
Block(-7,2,2,4)
Block(-7,2,3,4)
Block(-7,2,4,4)
Block(-7,2,5,98)
Block(-7,2,6,98)
Block(-7,3,-7,4)
Block(-7,3,-6,4)
Block(-7,3,-5,4)
Block(-7,3,-4,4)
Block(-7,3,-3,4)
Block(-7,3,-2,4)
Block(-7,3,-1,4)
Block(-7,3,0,4)
Block(-7,3,1,4)
Block(-7,3,2,4)
Block(-7,3,3,4)
Block(-7,3,4,4)
Block(-7,3,5,98)
Block(-7,3,6,98)
Block(-7,4,-7,4)
Block(-7,4,-6,4)
Block(-7,4,-5,4)
Block(-7,4,-4,4)
Block(-7,4,-3,4)
Block(-7,4,-2,4)
Block(-7,4,-1,4)
Block(-7,4,0,4)
Block(-7,4,1,4)
Block(-7,4,2,4)
Block(-7,4,3,4)
Block(-7,4,4,4)
Block(-7,4,5,98)
Block(-7,4,6,98)
Block(-7,5,-7,4)
Block(-7,5,-6,4)
Block(-7,5,-5,4)
Block(-7,5,-4,4)
Block(-7,5,-3,4)
Block(-7,5,-2,4)
Block(-7,5,-1,4)
Block(-7,5,0,4)
Block(-7,5,1,4)
Block(-7,5,2,4)
Block(-7,5,3,4)
Block(-7,5,4,4)
Block(-7,5,5,98)
Block(-7,5,6,98)
Block(-7,6,-7,4)
Block(-7,6,-6,4)
Block(-7,6,-5,4)
Block(-7,6,-4,4)
Block(-7,6,-3,4)
Block(-7,6,-2,4)
Block(-7,6,-1,4)
Block(-7,6,0,4)
Block(-7,6,1,4)
Block(-7,6,2,4)
Block(-7,6,3,4)
Block(-7,6,4,4)
Block(-7,6,5,98)
Block(-7,6,6,98)
Block(-7,7,-7,4)
Block(-7,7,-6,4)
Block(-7,7,-5,4)
Block(-7,7,-4,4)
Block(-7,7,-3,4)
Block(-7,7,-2,4)
Block(-7,7,-1,4)
Block(-7,7,0,4)
Block(-7,7,1,4)
Block(-7,7,2,4)
Block(-7,7,3,4)
Block(-7,7,4,4)
Block(-7,7,5,98)
Block(-7,7,6,98)
Block(-7,8,-7,4)
Block(-7,8,-6,4)
Block(-7,8,-5,4)
Block(-7,8,-4,4)
Block(-7,8,-3,4)
Block(-7,8,-2,4)
Block(-7,8,-1,4)
Block(-7,8,0,4)
Block(-7,8,1,4)
Block(-7,8,2,4)
Block(-7,8,3,4)
Block(-7,8,4,4)
Block(-7,8,5,98)
Block(-7,8,6,98)
Block(-7,9,-7,4)
Block(-7,9,-6,4)
Block(-7,9,-5,4)
Block(-7,9,-4,4)
Block(-7,9,-3,4)
Block(-7,9,-2,4)
Block(-7,9,-1,4)
Block(-7,9,0,4)
Block(-7,9,1,4)
Block(-7,9,2,4)
Block(-7,9,3,4)
Block(-7,9,4,4)
Block(-7,9,5,98)
Block(-7,9,6,98)
Block(-7,10,-7,4)
Block(-7,10,-6,4)
Block(-7,10,-5,4)
Block(-7,10,-4,4)
Block(-7,10,-3,4)
Block(-7,10,-2,4)
Block(-7,10,-1,4)
Block(-7,10,0,4)
Block(-7,10,1,4)
Block(-7,10,2,4)
Block(-7,10,3,4)
Block(-7,10,4,4)
Block(-7,10,5,98)
Block(-7,10,6,98)
Block(-7,11,-7,4)
Block(-7,11,-6,4)
Block(-7,11,-5,4)
Block(-7,11,-4,4)
Block(-7,11,-3,4)
Block(-7,11,-2,4)
Block(-7,11,-1,4)
Block(-7,11,0,4)
Block(-7,11,1,4)
Block(-7,11,2,4)
Block(-7,11,3,4)
Block(-7,11,4,4)
Block(-7,11,5,98)
Block(-7,11,6,98)
Block(-7,12,-7,4)
Block(-7,12,-6,4)
Block(-7,12,-5,4)
Block(-7,12,-4,4)
Block(-7,12,-3,4)
Block(-7,12,-2,4)
Block(-7,12,-1,4)
Block(-7,12,0,4)
Block(-7,12,1,4)
Block(-7,12,2,4)
Block(-7,12,3,4)
Block(-7,12,4,4)
Block(-7,12,5,98)
Block(-7,12,6,98)
Block(-7,13,-7,4)
Block(-7,13,-6,4)
Block(-7,13,-5,4)
Block(-7,13,-4,4)
Block(-7,13,-3,4)
Block(-7,13,-2,4)
Block(-7,13,-1,4)
Block(-7,13,0,4)
Block(-7,13,1,4)
Block(-7,13,2,4)
Block(-7,13,3,4)
Block(-7,13,4,4)
Block(-7,13,5,98)
Block(-7,13,6,98)
Block(-7,14,-7,4)
Block(-7,14,-6,4)
Block(-7,14,-5,4)
Block(-7,14,-4,4)
Block(-7,14,-3,4)
Block(-7,14,-2,4)
Block(-7,14,-1,4)
Block(-7,14,0,4)
Block(-7,14,1,4)
Block(-7,14,2,4)
Block(-7,14,3,4)
Block(-7,14,4,4)
Block(-7,14,5,98)
Block(-7,14,6,98)
Block(-7,15,-7,4)
Block(-7,15,-6,4)
Block(-7,15,-5,4)
Block(-7,15,-4,4)
Block(-7,15,-3,4)
Block(-7,15,-2,4)
Block(-7,15,-1,4)
Block(-7,15,0,4)
Block(-7,15,1,4)
Block(-7,15,2,4)
Block(-7,15,3,4)
Block(-7,15,4,4)
Block(-7,15,5,98)
Block(-7,15,6,98)
Block(-7,16,-7,4)
Block(-7,16,-6,4)
Block(-7,16,-5,4)
Block(-7,16,-4,4)
Block(-7,16,-3,4)
Block(-7,16,-2,4)
Block(-7,16,-1,4)
Block(-7,16,0,4)
Block(-7,16,1,4)
Block(-7,16,2,4)
Block(-7,16,3,4)
Block(-7,16,4,4)
Block(-7,16,5,98)
Block(-7,16,6,98)
Block(-7,17,-7,4)
Block(-7,17,-6,4)
Block(-7,17,-5,4)
Block(-7,17,-4,4)
Block(-7,17,-3,4)
Block(-7,17,-2,4)
Block(-7,17,-1,4)
Block(-7,17,0,4)
Block(-7,17,1,4)
Block(-7,17,2,4)
Block(-7,17,3,4)
Block(-7,17,4,4)
Block(-7,17,5,98)
Block(-7,17,6,98)
Block(-7,18,-7,4)
Block(-7,18,-6,4)
Block(-7,18,-5,4)
Block(-7,18,-4,4)
Block(-7,18,-3,4)
Block(-7,18,-2,4)
Block(-7,18,-1,4)
Block(-7,18,0,4)
Block(-7,18,1,4)
Block(-7,18,2,4)
Block(-7,18,3,4)
Block(-7,18,4,4)
Block(-7,18,5,4)
Block(-7,18,6,98)
Block(-7,19,-7,4)
Block(-7,19,-6,4)
Block(-7,19,-5,4)
Block(-7,19,-4,4)
Block(-7,19,-3,4)
Block(-7,19,-2,4)
Block(-7,19,-1,4)
Block(-7,19,0,4)
Block(-7,19,1,4)
Block(-7,19,2,4)
Block(-7,19,3,4)
Block(-7,19,4,4)
Block(-7,19,5,98)
Block(-7,19,6,98)
Block(-7,20,-7,4)
Block(-7,20,-6,4)
Block(-7,20,-5,4)
Block(-7,20,-4,4)
Block(-7,20,-3,4)
Block(-7,20,-2,4)
Block(-7,20,-1,4)
Block(-7,20,0,4)
Block(-7,20,1,4)
Block(-7,20,2,4)
Block(-7,20,3,4)
Block(-7,20,4,4)
Block(-7,20,5,4)
Block(-7,20,6,98)
Block(-7,21,-7,4)
Block(-7,21,-6,4)
Block(-7,21,-5,4)
Block(-7,21,-4,4)
Block(-7,21,-3,4)
Block(-7,21,-2,4)
Block(-7,21,-1,4)
Block(-7,21,0,4)
Block(-7,21,1,4)
Block(-7,21,2,4)
Block(-7,21,3,4)
Block(-7,21,4,4)
Block(-7,21,5,98)
Block(-7,21,6,98)
Block(-7,22,-6,67:0)
Block(-7,22,-3,106:12)
Block(-7,22,-1,18:7)
Block(-7,22,0,18:15)
Block(-7,22,1,18:15)
Block(-7,22,2,67:0)
Block(-7,22,3,18:7)
Block(-7,23,-3,106:12)
Block(-7,23,-1,106:8)
Block(-7,23,1,18:7)
Block(-7,23,2,18:7)
Block(-7,24,-3,106:12)
Block(-7,24,-1,106:8)
Block(-7,24,1,106:8)
Block(-7,24,2,18:7)
Block(-7,25,-3,106:12)
Block(-7,25,-1,106:8)
Block(-7,25,1,106:8)
Block(-7,25,2,18:7)
Block(-7,26,-6,67:4)
Block(-7,26,-3,106:12)
Block(-7,26,-1,106:8)
Block(-7,26,1,106:8)
Block(-7,26,2,67:4)
Block(-7,26,3,18:7)
Block(-7,26,4,18:7)
Block(-7,27,-7,18:15)
Block(-7,27,-6,4)
Block(-7,27,-5,18:7)
Block(-7,27,-4,4)
Block(-7,27,-3,106:12)
Block(-7,27,-2,4)
Block(-7,27,-1,106:8)
Block(-7,27,0,4)
Block(-7,27,1,106:8)
Block(-7,27,2,4)
Block(-7,27,3,18:7)
Block(-7,27,4,4)
Block(-7,27,5,18:7)
Block(-7,27,6,4)
Block(-7,28,-7,18:15)
Block(-7,28,-6,18:7)
Block(-7,28,-5,18:7)
Block(-7,28,-4,18:7)
Block(-7,28,-3,106:8)
Block(-7,28,-2,106:8)
Block(-7,28,-1,106:8)
Block(-7,28,1,106:8)
Block(-7,28,3,18:7)
Block(-7,28,4,18:7)
Block(-7,28,5,18:7)
Block(-7,28,6,106:8)
Block(-7,29,-7,106:8)
Block(-7,29,-5,18:7)
Block(-7,29,-1,106:8)
Block(-7,29,1,106:8)
Block(-7,29,5,106:8)
Block(-7,29,6,106:8)
Block(-7,30,-7,106:8)
Block(-7,30,-1,106:8)
Block(-7,30,1,106:8)
Block(-7,30,5,106:8)
Block(-7,30,6,106:8)
Block(-7,31,-7,106:8)
Block(-7,31,-1,106:8)
Block(-7,31,1,106:8)
Block(-7,31,5,106:8)
Block(-7,31,6,106:8)
Block(-7,32,-7,106:8)
Block(-7,32,-1,106:8)
Block(-7,32,1,106:8)
Block(-7,32,5,106:8)
Block(-7,32,6,106:8)
Block(-7,33,-7,106:8)
Block(-7,33,-1,106:8)
Block(-7,33,1,106:8)
Block(-7,33,5,106:8)
Block(-7,33,6,106:8)
Block(-7,34,-7,18:7)
Block(-7,34,-6,139)
Block(-7,34,-4,139)
Block(-7,34,-2,139)
Block(-7,34,-1,106:8)
Block(-7,34,0,139)
Block(-7,34,1,106:8)
Block(-7,34,2,139)
Block(-7,34,4,139)
Block(-7,34,5,106:8)
Block(-7,34,6,106:8)
Block(-7,35,-7,18:7)
Block(-7,35,-6,18:7)
Block(-7,35,-1,106:8)
Block(-7,35,1,106:8)
Block(-7,35,4,106:8)
Block(-7,35,5,106:8)
Block(-7,35,6,106:8)
Block(-7,36,-7,106:8)
Block(-7,36,-6,18:7)
Block(-7,36,-1,106:8)
Block(-7,37,-7,106:8)
Block(-7,37,-1,106:8)
Block(-7,38,-7,106:8)
Block(-7,38,-1,106:8)
Block(-7,39,-7,106:8)
Block(-7,39,-1,106:8)
Block(-7,40,-7,106:8)
Block(-7,40,-1,106:8)
Block(-7,40,2,18:15)
Block(-7,41,-7,106:8)
Block(-7,41,-6,139)
Block(-7,41,-4,139)
Block(-7,41,-2,139)
Block(-7,41,-1,106:8)
Block(-7,41,0,139)
Block(-7,41,1,18:7)
Block(-7,41,2,139)
Block(-7,41,4,139)
Block(-7,42,-7,106:8)
Block(-7,42,-6,18:7)
Block(-7,42,-5,18:7)
Block(-7,42,-4,18:7)
Block(-7,42,-3,18:7)
Block(-7,42,-2,18:7)
Block(-7,42,-1,18:15)
Block(-7,42,0,18:7)
Block(-7,43,-7,106:8)
Block(-7,43,-6,106:8)
Block(-7,43,-5,106:8)
Block(-7,44,-7,106:8)
Block(-7,44,-6,106:8)
Block(-7,44,-5,106:8)
Block(-7,45,-7,106:8)
Block(-7,45,-5,106:8)
Block(-7,46,-7,106:8)
Block(-7,46,-5,106:8)
Block(-7,47,-7,106:8)
Block(-7,47,-5,106:8)
Block(-7,48,-7,106:8)
Block(-7,48,-6,139)
Block(-7,48,-5,106:8)
Block(-7,48,-4,139)
Block(-7,48,-2,139)
Block(-7,48,0,139)
Block(-7,48,2,139)
Block(-7,48,4,139)
Block(-7,49,-7,106:8)
Block(-7,49,-6,106:8)
Block(-7,49,-5,106:8)
Block(-7,49,-4,106:8)
Block(-6,0,-7,4)
Block(-6,0,-6,4)
Block(-6,0,-5,4)
Block(-6,0,-4,4)
Block(-6,0,-3,4)
Block(-6,0,-2,4)
Block(-6,0,-1,4)
Block(-6,0,0,4)
Block(-6,0,1,4)
Block(-6,0,2,4)
Block(-6,0,3,4)
Block(-6,0,4,4)
Block(-6,0,5,4)
Block(-6,0,6,4)
Block(-6,0,7,98)
Block(-6,1,-7,4)
Block(-6,1,-6,4)
Block(-6,1,-5,4)
Block(-6,1,-4,4)
Block(-6,1,-3,4)
Block(-6,1,-2,4)
Block(-6,1,-1,4)
Block(-6,1,0,4)
Block(-6,1,1,4)
Block(-6,1,2,4)
Block(-6,1,3,4)
Block(-6,1,4,4)
Block(-6,1,5,4)
Block(-6,1,6,4)
Block(-6,1,7,98)
Block(-6,2,-7,4)
Block(-6,2,-6,4)
Block(-6,2,-5,4)
Block(-6,2,-4,4)
Block(-6,2,-3,4)
Block(-6,2,-2,4)
Block(-6,2,-1,4)
Block(-6,2,0,4)
Block(-6,2,1,4)
Block(-6,2,2,4)
Block(-6,2,3,4)
Block(-6,2,4,4)
Block(-6,2,5,4)
Block(-6,2,6,4)
Block(-6,2,7,98)
Block(-6,3,-7,4)
Block(-6,3,-6,4)
Block(-6,3,-5,4)
Block(-6,3,-4,4)
Block(-6,3,-3,4)
Block(-6,3,-2,4)
Block(-6,3,-1,4)
Block(-6,3,0,4)
Block(-6,3,1,4)
Block(-6,3,2,4)
Block(-6,3,3,4)
Block(-6,3,4,4)
Block(-6,3,5,4)
Block(-6,3,6,4)
Block(-6,3,7,98)
Block(-6,4,-7,4)
Block(-6,4,-6,4)
Block(-6,4,-5,4)
Block(-6,4,-4,4)
Block(-6,4,-3,4)
Block(-6,4,-2,4)
Block(-6,4,-1,4)
Block(-6,4,0,4)
Block(-6,4,1,4)
Block(-6,4,2,4)
Block(-6,4,3,4)
Block(-6,4,4,4)
Block(-6,4,5,4)
Block(-6,4,6,4)
Block(-6,4,7,98)
Block(-6,5,-7,4)
Block(-6,5,-6,4)
Block(-6,5,-5,4)
Block(-6,5,-4,4)
Block(-6,5,-3,4)
Block(-6,5,-2,4)
Block(-6,5,-1,4)
Block(-6,5,0,4)
Block(-6,5,1,4)
Block(-6,5,2,4)
Block(-6,5,3,4)
Block(-6,5,4,4)
Block(-6,5,5,4)
Block(-6,5,6,4)
Block(-6,5,7,98)
Block(-6,6,-7,4)
Block(-6,6,-6,4)
Block(-6,6,-5,4)
Block(-6,6,-4,4)
Block(-6,6,-3,4)
Block(-6,6,-2,4)
Block(-6,6,-1,4)
Block(-6,6,0,4)
Block(-6,6,1,4)
Block(-6,6,2,4)
Block(-6,6,3,4)
Block(-6,6,4,4)
Block(-6,6,5,4)
Block(-6,6,6,4)
Block(-6,6,7,98)
Block(-6,7,-7,4)
Block(-6,7,-6,4)
Block(-6,7,-5,4)
Block(-6,7,-4,4)
Block(-6,7,-3,4)
Block(-6,7,-2,4)
Block(-6,7,-1,4)
Block(-6,7,0,4)
Block(-6,7,1,4)
Block(-6,7,2,4)
Block(-6,7,3,4)
Block(-6,7,4,4)
Block(-6,7,5,4)
Block(-6,7,6,4)
Block(-6,7,7,98)
Block(-6,8,-7,4)
Block(-6,8,-6,4)
Block(-6,8,-5,4)
Block(-6,8,-4,4)
Block(-6,8,-3,4)
Block(-6,8,-2,4)
Block(-6,8,-1,4)
Block(-6,8,0,4)
Block(-6,8,1,4)
Block(-6,8,2,4)
Block(-6,8,3,4)
Block(-6,8,4,4)
Block(-6,8,5,4)
Block(-6,8,6,4)
Block(-6,8,7,98)
Block(-6,9,-7,4)
Block(-6,9,-6,4)
Block(-6,9,-5,4)
Block(-6,9,-4,4)
Block(-6,9,-3,4)
Block(-6,9,-2,4)
Block(-6,9,-1,4)
Block(-6,9,0,4)
Block(-6,9,1,4)
Block(-6,9,2,4)
Block(-6,9,3,4)
Block(-6,9,4,4)
Block(-6,9,5,4)
Block(-6,9,6,4)
Block(-6,9,7,98)
Block(-6,10,-7,4)
Block(-6,10,-6,4)
Block(-6,10,-5,4)
Block(-6,10,-4,4)
Block(-6,10,-3,4)
Block(-6,10,-2,4)
Block(-6,10,-1,4)
Block(-6,10,0,4)
Block(-6,10,1,4)
Block(-6,10,2,4)
Block(-6,10,3,4)
Block(-6,10,4,4)
Block(-6,10,5,4)
Block(-6,10,6,4)
Block(-6,10,7,98)
Block(-6,11,-7,4)
Block(-6,11,-6,4)
Block(-6,11,-5,4)
Block(-6,11,-4,4)
Block(-6,11,-3,4)
Block(-6,11,-2,4)
Block(-6,11,-1,4)
Block(-6,11,0,4)
Block(-6,11,1,4)
Block(-6,11,2,4)
Block(-6,11,3,4)
Block(-6,11,4,4)
Block(-6,11,5,4)
Block(-6,11,6,4)
Block(-6,11,7,98)
Block(-6,12,-7,4)
Block(-6,12,-6,4)
Block(-6,12,-5,4)
Block(-6,12,-4,4)
Block(-6,12,-3,4)
Block(-6,12,-2,4)
Block(-6,12,-1,4)
Block(-6,12,0,4)
Block(-6,12,1,4)
Block(-6,12,2,4)
Block(-6,12,3,4)
Block(-6,12,4,4)
Block(-6,12,5,4)
Block(-6,12,6,4)
Block(-6,12,7,98)
Block(-6,13,-7,4)
Block(-6,13,-6,4)
Block(-6,13,-5,4)
Block(-6,13,-4,4)
Block(-6,13,-3,4)
Block(-6,13,-2,4)
Block(-6,13,-1,4)
Block(-6,13,0,4)
Block(-6,13,1,4)
Block(-6,13,2,4)
Block(-6,13,3,4)
Block(-6,13,4,4)
Block(-6,13,5,4)
Block(-6,13,6,4)
Block(-6,13,7,98)
Block(-6,14,-7,4)
Block(-6,14,-6,4)
Block(-6,14,-5,4)
Block(-6,14,-4,4)
Block(-6,14,-3,4)
Block(-6,14,-2,4)
Block(-6,14,-1,4)
Block(-6,14,0,4)
Block(-6,14,1,4)
Block(-6,14,2,4)
Block(-6,14,3,4)
Block(-6,14,4,4)
Block(-6,14,5,4)
Block(-6,14,6,4)
Block(-6,14,7,98)
Block(-6,15,-7,4)
Block(-6,15,-6,4)
Block(-6,15,-5,4)
Block(-6,15,-4,4)
Block(-6,15,-3,4)
Block(-6,15,-2,4)
Block(-6,15,-1,4)
Block(-6,15,0,4)
Block(-6,15,1,4)
Block(-6,15,2,4)
Block(-6,15,3,4)
Block(-6,15,4,4)
Block(-6,15,5,4)
Block(-6,15,6,4)
Block(-6,15,7,98)
Block(-6,16,-7,4)
Block(-6,16,-6,4)
Block(-6,16,-5,4)
Block(-6,16,-4,4)
Block(-6,16,-3,4)
Block(-6,16,-2,4)
Block(-6,16,-1,4)
Block(-6,16,0,4)
Block(-6,16,1,4)
Block(-6,16,2,4)
Block(-6,16,3,4)
Block(-6,16,4,4)
Block(-6,16,5,4)
Block(-6,16,6,4)
Block(-6,16,7,98)
Block(-6,17,-7,4)
Block(-6,17,-6,4)
Block(-6,17,-5,4)
Block(-6,17,-4,4)
Block(-6,17,-3,4)
Block(-6,17,-2,4)
Block(-6,17,-1,4)
Block(-6,17,0,4)
Block(-6,17,1,4)
Block(-6,17,2,4)
Block(-6,17,3,4)
Block(-6,17,4,4)
Block(-6,17,5,4)
Block(-6,17,6,4)
Block(-6,17,7,98)
Block(-6,18,-7,5:3)
Block(-6,18,-6,126:11)
Block(-6,18,-5,126:11)
Block(-6,18,-4,5:3)
Block(-6,18,-3,4)
Block(-6,18,-2,4)
Block(-6,18,-1,4)
Block(-6,18,0,4)
Block(-6,18,1,4)
Block(-6,18,2,4)
Block(-6,18,3,4)
Block(-6,18,4,4)
Block(-6,18,5,4)
Block(-6,18,6,4)
Block(-6,18,7,98)
Block(-6,19,-7,5:3)
Block(-6,19,-6,47)
Block(-6,19,-5,47)
Block(-6,19,-4,5:3)
Block(-6,19,-3,4)
Block(-6,19,-2,4)
Block(-6,19,-1,4)
Block(-6,19,0,4)
Block(-6,19,1,4)
Block(-6,19,2,4)
Block(-6,19,3,4)
Block(-6,19,4,4)
Block(-6,19,5,4)
Block(-6,19,6,4)
Block(-6,19,7,98)
Block(-6,20,-7,5:3)
Block(-6,20,-6,126:11)
Block(-6,20,-5,126:11)
Block(-6,20,-4,5:3)
Block(-6,20,-3,4)
Block(-6,20,-2,4)
Block(-6,20,-1,4)
Block(-6,20,0,4)
Block(-6,20,1,4)
Block(-6,20,2,4)
Block(-6,20,3,4)
Block(-6,20,4,4)
Block(-6,20,5,4)
Block(-6,20,6,4)
Block(-6,20,7,98)
Block(-6,21,-7,4)
Block(-6,21,-6,4)
Block(-6,21,-5,4)
Block(-6,21,-4,44:5)
Block(-6,21,-3,44:5)
Block(-6,21,-2,4)
Block(-6,21,-1,44:5)
Block(-6,21,0,44:5)
Block(-6,21,1,4)
Block(-6,21,2,4)
Block(-6,21,3,4)
Block(-6,21,4,44:5)
Block(-6,21,5,44:5)
Block(-6,21,6,98)
Block(-6,21,7,98)
Block(-6,22,-7,67:2)
Block(-6,22,-6,4)
Block(-6,22,-5,67:3)
Block(-6,22,-2,106:8)
Block(-6,22,-1,106:8)
Block(-6,22,0,18:7)
Block(-6,22,1,67:2)
Block(-6,22,2,4)
Block(-6,22,3,67:3)
Block(-6,23,-7,106:8)
Block(-6,23,-6,4)
Block(-6,23,-2,4)
Block(-6,23,-1,106:8)
Block(-6,23,0,18:7)
Block(-6,23,1,18:15)
Block(-6,23,2,4)
Block(-6,23,3,18:7)
Block(-6,24,-7,106:8)
Block(-6,24,-6,4)
Block(-6,24,-2,4)
Block(-6,24,-1,106:8)
Block(-6,24,1,18:15)
Block(-6,24,2,4)
Block(-6,24,3,18:7)
Block(-6,25,-7,106:8)
Block(-6,25,-6,4)
Block(-6,25,-2,4)
Block(-6,25,-1,106:8)
Block(-6,25,2,4)
Block(-6,25,3,18:7)
Block(-6,26,-7,67:6)
Block(-6,26,-6,4)
Block(-6,26,-5,67:7)
Block(-6,26,-1,106:8)
Block(-6,26,1,67:6)
Block(-6,26,2,4)
Block(-6,26,3,67:7)
Block(-6,26,4,18:7)
Block(-6,27,-7,4)
Block(-6,27,-6,4)
Block(-6,27,-5,4)
Block(-6,27,-4,4)
Block(-6,27,-3,4)
Block(-6,27,-2,4)
Block(-6,27,-1,4)
Block(-6,27,0,4)
Block(-6,27,1,4)
Block(-6,27,2,4)
Block(-6,27,3,4)
Block(-6,27,4,4)
Block(-6,27,5,4)
Block(-6,27,6,4)
Block(-6,27,7,4)
Block(-6,27,8,139)
Block(-6,28,-7,4)
Block(-6,28,-6,4)
Block(-6,28,-5,4)
Block(-6,28,-4,4)
Block(-6,28,-3,4)
Block(-6,28,-2,4)
Block(-6,28,-1,4)
Block(-6,28,0,4)
Block(-6,28,1,4)
Block(-6,28,2,4)
Block(-6,28,3,4)
Block(-6,28,4,4)
Block(-6,28,5,98)
Block(-6,28,6,98)
Block(-6,28,7,106:4)
Block(-6,29,-7,18:7)
Block(-6,29,-6,67:0)
Block(-6,29,-4,18:7)
Block(-6,29,2,67:0)
Block(-6,29,4,18:7)
Block(-6,29,5,18:7)
Block(-6,29,7,106:4)
Block(-6,30,7,106:4)
Block(-6,31,7,106:4)
Block(-6,32,7,106:4)
Block(-6,33,-7,18:7)
Block(-6,33,-6,67:4)
Block(-6,33,-5,18:7)
Block(-6,33,2,67:4)
Block(-6,33,7,106:4)
Block(-6,34,-7,18:7)
Block(-6,34,-6,4)
Block(-6,34,-5,18:7)
Block(-6,34,-4,4)
Block(-6,34,-2,4)
Block(-6,34,0,4)
Block(-6,34,2,4)
Block(-6,34,4,4)
Block(-6,34,7,106:4)
Block(-6,35,-7,4)
Block(-6,35,-6,4)
Block(-6,35,-5,4)
Block(-6,35,-4,4)
Block(-6,35,-3,4)
Block(-6,35,-2,4)
Block(-6,35,-1,4)
Block(-6,35,0,4)
Block(-6,35,1,4)
Block(-6,35,2,4)
Block(-6,35,3,4)
Block(-6,35,4,4)
Block(-6,35,5,98)
Block(-6,35,6,98)
Block(-6,35,7,106:4)
Block(-6,36,-6,67:0)
Block(-6,36,-5,18:7)
Block(-6,36,2,67:0)
Block(-6,36,3,18:7)
Block(-6,37,-6,18:7)
Block(-6,38,2,18:7)
Block(-6,39,-5,18:7)
Block(-6,39,2,18:15)
Block(-6,40,-6,67:4)
Block(-6,40,-5,18:7)
Block(-6,40,1,18:7)
Block(-6,40,2,67:4)
Block(-6,40,3,18:7)
Block(-6,41,-6,4)
Block(-6,41,-5,18:7)
Block(-6,41,-4,4)
Block(-6,41,-2,4)
Block(-6,41,-1,18:7)
Block(-6,41,0,4)
Block(-6,41,1,18:15)
Block(-6,41,2,4)
Block(-6,41,3,18:7)
Block(-6,41,4,4)
Block(-6,42,-7,4)
Block(-6,42,-6,4)
Block(-6,42,-5,4)
Block(-6,42,-4,4)
Block(-6,42,-3,4)
Block(-6,42,-2,4)
Block(-6,42,-1,4)
Block(-6,42,0,4)
Block(-6,42,1,4)
Block(-6,42,2,4)
Block(-6,42,3,4)
Block(-6,42,4,4)
Block(-6,42,5,98)
Block(-6,42,6,98)
Block(-6,43,-7,18:7)
Block(-6,43,-6,67:0)
Block(-6,43,-5,18:7)
Block(-6,43,-3,18:7)
Block(-6,43,-2,18:7)
Block(-6,43,2,67:0)
Block(-6,43,4,106:8)
Block(-6,43,5,106:8)
Block(-6,43,6,106:8)
Block(-6,44,-7,106:4)
Block(-6,44,-6,18:7)
Block(-6,44,4,106:8)
Block(-6,44,5,106:8)
Block(-6,44,6,106:8)
Block(-6,45,-7,106:4)
Block(-6,45,-6,18:7)
Block(-6,45,4,106:8)
Block(-6,45,5,106:8)
Block(-6,45,6,106:8)
Block(-6,46,-7,106:4)
Block(-6,46,-6,18:7)
Block(-6,46,4,106:8)
Block(-6,46,5,106:8)
Block(-6,46,6,106:8)
Block(-6,47,-7,18:15)
Block(-6,47,-6,67:4)
Block(-6,47,2,67:4)
Block(-6,47,4,106:8)
Block(-6,47,5,106:8)
Block(-6,47,6,106:8)
Block(-6,48,-6,4)
Block(-6,48,-4,4)
Block(-6,48,-2,4)
Block(-6,48,0,4)
Block(-6,48,2,4)
Block(-6,48,4,4)
Block(-6,48,5,106:8)
Block(-6,48,6,106:8)
Block(-6,49,-7,4)
Block(-6,49,-6,4)
Block(-6,49,-5,4)
Block(-6,49,-4,4)
Block(-6,49,-3,4)
Block(-6,49,-2,4)
Block(-6,49,-1,4)
Block(-6,49,0,4)
Block(-6,49,1,4)
Block(-6,49,2,4)
Block(-6,49,3,4)
Block(-6,49,4,4)
Block(-6,49,5,44:11)
Block(-6,49,6,44:11)
Block(-6,50,-7,44:3)
Block(-6,50,-6,4)
Block(-6,50,-5,44:3)
Block(-6,50,-4,4)
Block(-6,50,-3,44:3)
Block(-6,50,-2,4)
Block(-6,50,-1,44:3)
Block(-6,50,0,4)
Block(-6,50,1,44:3)
Block(-6,50,2,4)
Block(-6,50,3,44:3)
Block(-6,50,4,4)
Block(-6,50,5,44:3)
Block(-6,50,6,43:3)
Block(-6,51,6,18:7)
Block(-5,0,-7,4)
Block(-5,0,-6,4)
Block(-5,0,-5,4)
Block(-5,0,-4,4)
Block(-5,0,-3,4)
Block(-5,0,-2,4)
Block(-5,0,-1,4)
Block(-5,0,0,4)
Block(-5,0,1,4)
Block(-5,0,2,4)
Block(-5,0,3,4)
Block(-5,0,4,4)
Block(-5,0,5,4)
Block(-5,0,6,4)
Block(-5,0,7,98)
Block(-5,1,-7,4)
Block(-5,1,-6,4)
Block(-5,1,-5,4)
Block(-5,1,-4,4)
Block(-5,1,-3,4)
Block(-5,1,-2,4)
Block(-5,1,-1,4)
Block(-5,1,0,4)
Block(-5,1,1,4)
Block(-5,1,2,4)
Block(-5,1,3,4)
Block(-5,1,4,4)
Block(-5,1,5,4)
Block(-5,1,6,4)
Block(-5,1,7,98)
Block(-5,2,-7,4)
Block(-5,2,-6,4)
Block(-5,2,-5,4)
Block(-5,2,-4,4)
Block(-5,2,-3,4)
Block(-5,2,-2,4)
Block(-5,2,-1,4)
Block(-5,2,0,4)
Block(-5,2,1,4)
Block(-5,2,2,4)
Block(-5,2,3,4)
Block(-5,2,4,4)
Block(-5,2,5,4)
Block(-5,2,6,4)
Block(-5,2,7,98)
Block(-5,3,-7,4)
Block(-5,3,-6,4)
Block(-5,3,-5,4)
Block(-5,3,-4,4)
Block(-5,3,-3,4)
Block(-5,3,-2,4)
Block(-5,3,-1,4)
Block(-5,3,0,4)
Block(-5,3,1,4)
Block(-5,3,2,4)
Block(-5,3,3,4)
Block(-5,3,4,4)
Block(-5,3,5,4)
Block(-5,3,6,4)
Block(-5,3,7,98)
Block(-5,4,-7,4)
Block(-5,4,-6,4)
Block(-5,4,-5,4)
Block(-5,4,-4,4)
Block(-5,4,-3,4)
Block(-5,4,-2,4)
Block(-5,4,-1,4)
Block(-5,4,0,4)
Block(-5,4,1,4)
Block(-5,4,2,4)
Block(-5,4,3,4)
Block(-5,4,4,4)
Block(-5,4,5,4)
Block(-5,4,6,4)
Block(-5,4,7,98)
Block(-5,5,-7,4)
Block(-5,5,-6,4)
Block(-5,5,-5,4)
Block(-5,5,-4,4)
Block(-5,5,-3,4)
Block(-5,5,-2,4)
Block(-5,5,-1,4)
Block(-5,5,0,4)
Block(-5,5,1,4)
Block(-5,5,2,4)
Block(-5,5,3,4)
Block(-5,5,4,4)
Block(-5,5,5,4)
Block(-5,5,6,4)
Block(-5,5,7,98)
Block(-5,6,-7,4)
Block(-5,6,-6,4)
Block(-5,6,-5,4)
Block(-5,6,-4,4)
Block(-5,6,-3,4)
Block(-5,6,-2,4)
Block(-5,6,-1,4)
Block(-5,6,0,4)
Block(-5,6,1,4)
Block(-5,6,2,4)
Block(-5,6,3,4)
Block(-5,6,4,4)
Block(-5,6,5,4)
Block(-5,6,6,4)
Block(-5,6,7,98)
Block(-5,7,-7,4)
Block(-5,7,-6,4)
Block(-5,7,-5,4)
Block(-5,7,-4,4)
Block(-5,7,-3,4)
Block(-5,7,-2,4)
Block(-5,7,-1,4)
Block(-5,7,0,4)
Block(-5,7,1,4)
Block(-5,7,2,4)
Block(-5,7,3,4)
Block(-5,7,4,4)
Block(-5,7,5,4)
Block(-5,7,6,4)
Block(-5,7,7,98)
Block(-5,8,-7,4)
Block(-5,8,-6,4)
Block(-5,8,-5,4)
Block(-5,8,-4,4)
Block(-5,8,-3,4)
Block(-5,8,-2,4)
Block(-5,8,-1,4)
Block(-5,8,0,4)
Block(-5,8,1,4)
Block(-5,8,2,4)
Block(-5,8,3,4)
Block(-5,8,4,4)
Block(-5,8,5,4)
Block(-5,8,6,4)
Block(-5,8,7,98)
Block(-5,9,-7,4)
Block(-5,9,-6,4)
Block(-5,9,-5,4)
Block(-5,9,-4,4)
Block(-5,9,-3,4)
Block(-5,9,-2,4)
Block(-5,9,-1,4)
Block(-5,9,0,4)
Block(-5,9,1,4)
Block(-5,9,2,4)
Block(-5,9,3,4)
Block(-5,9,4,4)
Block(-5,9,5,4)
Block(-5,9,6,4)
Block(-5,9,7,98)
Block(-5,10,-7,4)
Block(-5,10,-6,4)
Block(-5,10,-5,4)
Block(-5,10,-4,4)
Block(-5,10,-3,4)
Block(-5,10,-2,4)
Block(-5,10,-1,4)
Block(-5,10,0,4)
Block(-5,10,1,4)
Block(-5,10,2,4)
Block(-5,10,3,4)
Block(-5,10,4,4)
Block(-5,10,5,4)
Block(-5,10,6,4)
Block(-5,10,7,98)
Block(-5,11,-7,4)
Block(-5,11,-6,4)
Block(-5,11,-5,4)
Block(-5,11,-4,4)
Block(-5,11,-3,4)
Block(-5,11,-2,4)
Block(-5,11,-1,4)
Block(-5,11,0,4)
Block(-5,11,1,4)
Block(-5,11,2,4)
Block(-5,11,3,4)
Block(-5,11,4,4)
Block(-5,11,5,4)
Block(-5,11,6,4)
Block(-5,11,7,98)
Block(-5,12,-7,4)
Block(-5,12,-6,4)
Block(-5,12,-5,4)
Block(-5,12,-4,4)
Block(-5,12,-3,4)
Block(-5,12,-2,4)
Block(-5,12,-1,4)
Block(-5,12,0,4)
Block(-5,12,1,4)
Block(-5,12,2,4)
Block(-5,12,3,4)
Block(-5,12,4,4)
Block(-5,12,5,4)
Block(-5,12,6,4)
Block(-5,12,7,98)
Block(-5,13,-7,4)
Block(-5,13,-6,4)
Block(-5,13,-5,4)
Block(-5,13,-4,4)
Block(-5,13,-3,4)
Block(-5,13,-2,4)
Block(-5,13,-1,4)
Block(-5,13,0,4)
Block(-5,13,1,4)
Block(-5,13,2,4)
Block(-5,13,3,4)
Block(-5,13,4,4)
Block(-5,13,5,4)
Block(-5,13,6,4)
Block(-5,13,7,98)
Block(-5,14,-7,4)
Block(-5,14,-6,4)
Block(-5,14,-5,4)
Block(-5,14,-4,4)
Block(-5,14,-3,4)
Block(-5,14,-2,4)
Block(-5,14,-1,4)
Block(-5,14,0,4)
Block(-5,14,1,4)
Block(-5,14,2,4)
Block(-5,14,3,4)
Block(-5,14,4,4)
Block(-5,14,5,4)
Block(-5,14,6,4)
Block(-5,14,7,98)
Block(-5,15,-7,4)
Block(-5,15,-6,4)
Block(-5,15,-5,4)
Block(-5,15,-4,4)
Block(-5,15,-3,4)
Block(-5,15,-2,4)
Block(-5,15,-1,4)
Block(-5,15,0,4)
Block(-5,15,1,4)
Block(-5,15,2,4)
Block(-5,15,3,4)
Block(-5,15,4,4)
Block(-5,15,5,4)
Block(-5,15,6,4)
Block(-5,15,7,98)
Block(-5,16,-7,4)
Block(-5,16,-6,4)
Block(-5,16,-5,4)
Block(-5,16,-4,4)
Block(-5,16,-3,4)
Block(-5,16,-2,4)
Block(-5,16,-1,4)
Block(-5,16,0,4)
Block(-5,16,1,4)
Block(-5,16,2,4)
Block(-5,16,3,4)
Block(-5,16,4,4)
Block(-5,16,5,4)
Block(-5,16,6,4)
Block(-5,16,7,98)
Block(-5,17,-7,4)
Block(-5,17,-6,4)
Block(-5,17,-5,4)
Block(-5,17,-4,4)
Block(-5,17,-3,4)
Block(-5,17,-2,4)
Block(-5,17,-1,4)
Block(-5,17,0,4)
Block(-5,17,1,4)
Block(-5,17,2,4)
Block(-5,17,3,4)
Block(-5,17,4,4)
Block(-5,17,5,4)
Block(-5,17,6,4)
Block(-5,17,7,98)
Block(-5,18,-7,AIR)
Block(-5,18,-6,AIR)
Block(-5,18,-5,AIR)
Block(-5,18,-4,AIR)
Block(-5,18,-3,4)
Block(-5,18,-2,4)
Block(-5,18,-1,4)
Block(-5,18,0,4)
Block(-5,18,1,4)
Block(-5,18,2,4)
Block(-5,18,3,4)
Block(-5,18,4,4)
Block(-5,18,5,4)
Block(-5,18,6,4)
Block(-5,18,7,4)
Block(-5,19,-7,AIR)
Block(-5,19,-6,AIR)
Block(-5,19,-5,AIR)
Block(-5,19,-4,AIR)
Block(-5,19,-3,4)
Block(-5,19,-2,4)
Block(-5,19,-1,4)
Block(-5,19,0,4)
Block(-5,19,1,4)
Block(-5,19,2,4)
Block(-5,19,3,4)
Block(-5,19,4,4)
Block(-5,19,5,4)
Block(-5,19,6,4)
Block(-5,19,7,98)
Block(-5,20,-7,AIR)
Block(-5,20,-6,AIR)
Block(-5,20,-5,AIR)
Block(-5,20,-4,AIR)
Block(-5,20,-3,4)
Block(-5,20,-2,4)
Block(-5,20,-1,4)
Block(-5,20,0,4)
Block(-5,20,1,4)
Block(-5,20,2,4)
Block(-5,20,3,4)
Block(-5,20,4,4)
Block(-5,20,5,4)
Block(-5,20,6,4)
Block(-5,20,7,4)
Block(-5,21,-7,4)
Block(-5,21,-6,4)
Block(-5,21,-5,4)
Block(-5,21,-4,4)
Block(-5,21,-3,4)
Block(-5,21,-2,4)
Block(-5,21,-1,4)
Block(-5,21,0,4)
Block(-5,21,1,4)
Block(-5,21,2,4)
Block(-5,21,3,4)
Block(-5,21,4,4)
Block(-5,21,5,98)
Block(-5,21,6,44:5)
Block(-5,21,7,98)
Block(-5,22,-7,4)
Block(-5,22,-6,4)
Block(-5,22,-5,4)
Block(-5,22,-4,4)
Block(-5,22,-3,4)
Block(-5,22,-2,4)
Block(-5,22,-1,4)
Block(-5,22,0,4)
Block(-5,22,1,4)
Block(-5,22,2,4)
Block(-5,22,3,4)
Block(-5,22,4,98)
Block(-5,22,5,98)
Block(-5,23,-7,4)
Block(-5,23,-6,4)
Block(-5,23,-5,4)
Block(-5,23,-4,4)
Block(-5,23,-3,4)
Block(-5,23,-2,4)
Block(-5,23,-1,4)
Block(-5,23,0,4)
Block(-5,23,1,4)
Block(-5,23,2,4)
Block(-5,23,3,4)
Block(-5,23,4,4)
Block(-5,23,5,98)
Block(-5,24,-7,4)
Block(-5,24,-6,4)
Block(-5,24,-5,4)
Block(-5,24,-4,4)
Block(-5,24,-3,4)
Block(-5,24,-2,4)
Block(-5,24,-1,4)
Block(-5,24,0,4)
Block(-5,24,1,4)
Block(-5,24,2,4)
Block(-5,24,3,4)
Block(-5,24,4,98)
Block(-5,24,5,98)
Block(-5,25,-7,4)
Block(-5,25,-6,4)
Block(-5,25,-5,4)
Block(-5,25,-4,4)
Block(-5,25,-3,4)
Block(-5,25,-2,4)
Block(-5,25,-1,4)
Block(-5,25,0,4)
Block(-5,25,1,4)
Block(-5,25,2,4)
Block(-5,25,3,4)
Block(-5,25,4,4)
Block(-5,25,5,98)
Block(-5,26,-7,4)
Block(-5,26,-6,4)
Block(-5,26,-5,4)
Block(-5,26,-4,4)
Block(-5,26,-3,4)
Block(-5,26,-2,4)
Block(-5,26,-1,4)
Block(-5,26,0,4)
Block(-5,26,1,4)
Block(-5,26,2,4)
Block(-5,26,3,4)
Block(-5,26,4,98)
Block(-5,26,5,98)
Block(-5,27,-7,4)
Block(-5,27,-6,4)
Block(-5,27,-5,4)
Block(-5,27,-4,4)
Block(-5,27,-3,4)
Block(-5,27,-2,4)
Block(-5,27,-1,4)
Block(-5,27,0,4)
Block(-5,27,1,4)
Block(-5,27,2,4)
Block(-5,27,3,4)
Block(-5,27,4,4)
Block(-5,27,5,4)
Block(-5,27,6,4)
Block(-5,28,-7,98)
Block(-5,28,-6,98)
Block(-5,28,-5,98)
Block(-5,28,-4,98)
Block(-5,28,-3,98)
Block(-5,28,-2,98)
Block(-5,28,-1,98)
Block(-5,28,0,98)
Block(-5,28,1,98)
Block(-5,28,2,98)
Block(-5,28,3,98)
Block(-5,28,4,98)
Block(-5,28,5,98)
Block(-5,28,6,98)
Block(-5,29,-7,67:2)
Block(-5,29,-6,4)
Block(-5,29,-5,67:3)
Block(-5,29,-4,18:7)
Block(-5,29,-3,18:7)
Block(-5,29,-2,AIR)
Block(-5,29,-1,AIR)
Block(-5,29,0,AIR)
Block(-5,29,1,67:2)
Block(-5,29,2,4)
Block(-5,29,3,67:3)
Block(-5,29,4,18:7)
Block(-5,29,5,18:7)
Block(-5,30,-7,AIR)
Block(-5,30,-6,4)
Block(-5,30,-5,18:7)
Block(-5,30,-4,AIR)
Block(-5,30,-3,AIR)
Block(-5,30,-2,AIR)
Block(-5,30,-1,AIR)
Block(-5,30,0,AIR)
Block(-5,30,1,AIR)
Block(-5,30,2,4)
Block(-5,30,3,AIR)
Block(-5,30,4,106:8)
Block(-5,30,5,AIR)
Block(-5,31,-7,AIR)
Block(-5,31,-6,4)
Block(-5,31,-5,AIR)
Block(-5,31,-4,AIR)
Block(-5,31,-3,AIR)
Block(-5,31,-2,AIR)
Block(-5,31,-1,AIR)
Block(-5,31,0,AIR)
Block(-5,31,1,AIR)
Block(-5,31,2,4)
Block(-5,31,3,AIR)
Block(-5,31,4,106:8)
Block(-5,31,5,AIR)
Block(-5,32,-7,18:7)
Block(-5,32,-6,4)
Block(-5,32,-5,AIR)
Block(-5,32,-4,AIR)
Block(-5,32,-3,AIR)
Block(-5,32,-2,AIR)
Block(-5,32,-1,AIR)
Block(-5,32,0,AIR)
Block(-5,32,1,AIR)
Block(-5,32,2,4)
Block(-5,32,3,AIR)
Block(-5,32,4,106:8)
Block(-5,32,5,AIR)
Block(-5,33,-7,67:6)
Block(-5,33,-6,4)
Block(-5,33,-5,67:7)
Block(-5,33,-4,AIR)
Block(-5,33,-3,AIR)
Block(-5,33,-2,AIR)
Block(-5,33,-1,AIR)
Block(-5,33,0,AIR)
Block(-5,33,1,67:6)
Block(-5,33,2,4)
Block(-5,33,3,67:7)
Block(-5,33,4,106:8)
Block(-5,33,5,AIR)
Block(-5,34,-7,4)
Block(-5,34,-6,4)
Block(-5,34,-5,4)
Block(-5,34,-4,4)
Block(-5,34,-3,4)
Block(-5,34,-2,4)
Block(-5,34,-1,4)
Block(-5,34,0,4)
Block(-5,34,1,4)
Block(-5,34,2,4)
Block(-5,34,3,4)
Block(-5,34,4,4)
Block(-5,34,5,4)
Block(-5,35,-7,98)
Block(-5,35,-6,98)
Block(-5,35,-5,98)
Block(-5,35,-4,98)
Block(-5,35,-3,98)
Block(-5,35,-2,98)
Block(-5,35,-1,98)
Block(-5,35,0,98)
Block(-5,35,1,98)
Block(-5,35,2,98)
Block(-5,35,3,98)
Block(-5,35,4,98)
Block(-5,35,5,98)
Block(-5,35,6,98)
Block(-5,36,-7,67:2)
Block(-5,36,-6,4)
Block(-5,36,-5,67:3)
Block(-5,36,-4,18:7)
Block(-5,36,-3,AIR)
Block(-5,36,-2,106:8)
Block(-5,36,-1,106:8)
Block(-5,36,0,106:8)
Block(-5,36,1,67:2)
Block(-5,36,2,4)
Block(-5,36,3,67:3)
Block(-5,36,4,18:7)
Block(-5,36,5,18:7)
Block(-5,37,-7,106:8)
Block(-5,37,-6,4)
Block(-5,37,-5,18:7)
Block(-5,37,-4,AIR)
Block(-5,37,-3,AIR)
Block(-5,37,-2,AIR)
Block(-5,37,-1,AIR)
Block(-5,37,0,AIR)
Block(-5,37,1,106:8)
Block(-5,37,2,4)
Block(-5,37,3,18:7)
Block(-5,37,4,18:7)
Block(-5,37,5,AIR)
Block(-5,38,-7,106:8)
Block(-5,38,-6,4)
Block(-5,38,-5,18:7)
Block(-5,38,-4,AIR)
Block(-5,38,-3,AIR)
Block(-5,38,-2,AIR)
Block(-5,38,-1,AIR)
Block(-5,38,0,AIR)
Block(-5,38,1,106:8)
Block(-5,38,2,4)
Block(-5,38,3,18:7)
Block(-5,38,4,AIR)
Block(-5,38,5,AIR)
Block(-5,39,-7,106:8)
Block(-5,39,-6,4)
Block(-5,39,-5,18:7)
Block(-5,39,-4,AIR)
Block(-5,39,-3,AIR)
Block(-5,39,-2,AIR)
Block(-5,39,-1,AIR)
Block(-5,39,0,AIR)
Block(-5,39,1,18:7)
Block(-5,39,2,4)
Block(-5,39,3,18:7)
Block(-5,39,4,AIR)
Block(-5,39,5,AIR)
Block(-5,40,-7,67:6)
Block(-5,40,-6,4)
Block(-5,40,-5,67:7)
Block(-5,40,-4,18:7)
Block(-5,40,-3,AIR)
Block(-5,40,-2,AIR)
Block(-5,40,-1,AIR)
Block(-5,40,0,18:7)
Block(-5,40,1,67:6)
Block(-5,40,2,4)
Block(-5,40,3,67:7)
Block(-5,40,4,AIR)
Block(-5,40,5,AIR)
Block(-5,41,-7,4)
Block(-5,41,-6,4)
Block(-5,41,-5,4)
Block(-5,41,-4,4)
Block(-5,41,-3,4)
Block(-5,41,-2,4)
Block(-5,41,-1,4)
Block(-5,41,0,4)
Block(-5,41,1,4)
Block(-5,41,2,4)
Block(-5,41,3,4)
Block(-5,41,4,4)
Block(-5,41,5,4)
Block(-5,42,-7,98)
Block(-5,42,-6,98)
Block(-5,42,-5,98)
Block(-5,42,-4,98)
Block(-5,42,-3,98)
Block(-5,42,-2,98)
Block(-5,42,-1,98)
Block(-5,42,0,98)
Block(-5,42,1,98)
Block(-5,42,2,98)
Block(-5,42,3,98)
Block(-5,42,4,98)
Block(-5,42,5,98)
Block(-5,42,6,98)
Block(-5,43,-7,67:2)
Block(-5,43,-6,4)
Block(-5,43,-5,67:3)
Block(-5,43,-4,18:7)
Block(-5,43,-3,18:7)
Block(-5,43,-2,18:7)
Block(-5,43,-1,AIR)
Block(-5,43,0,AIR)
Block(-5,43,1,67:2)
Block(-5,43,2,4)
Block(-5,43,3,67:3)
Block(-5,43,4,18:7)
Block(-5,43,5,18:7)
Block(-5,44,-7,AIR)
Block(-5,44,-6,4)
Block(-5,44,-5,18:7)
Block(-5,44,-4,AIR)
Block(-5,44,-3,AIR)
Block(-5,44,-2,AIR)
Block(-5,44,-1,AIR)
Block(-5,44,0,AIR)
Block(-5,44,1,AIR)
Block(-5,44,2,4)
Block(-5,44,3,AIR)
Block(-5,44,4,AIR)
Block(-5,44,5,AIR)
Block(-5,45,-7,18:7)
Block(-5,45,-6,4)
Block(-5,45,-5,AIR)
Block(-5,45,-4,AIR)
Block(-5,45,-3,AIR)
Block(-5,45,-2,AIR)
Block(-5,45,-1,AIR)
Block(-5,45,0,AIR)
Block(-5,45,1,AIR)
Block(-5,45,2,4)
Block(-5,45,3,AIR)
Block(-5,45,4,AIR)
Block(-5,45,5,AIR)
Block(-5,46,-7,18:7)
Block(-5,46,-6,4)
Block(-5,46,-5,AIR)
Block(-5,46,-4,AIR)
Block(-5,46,-3,AIR)
Block(-5,46,-2,AIR)
Block(-5,46,-1,AIR)
Block(-5,46,0,AIR)
Block(-5,46,1,AIR)
Block(-5,46,2,4)
Block(-5,46,3,AIR)
Block(-5,46,4,AIR)
Block(-5,46,5,AIR)
Block(-5,47,-7,67:6)
Block(-5,47,-6,4)
Block(-5,47,-5,67:7)
Block(-5,47,-4,AIR)
Block(-5,47,-3,AIR)
Block(-5,47,-2,AIR)
Block(-5,47,-1,AIR)
Block(-5,47,0,AIR)
Block(-5,47,1,67:6)
Block(-5,47,2,4)
Block(-5,47,3,67:7)
Block(-5,47,4,18:7)
Block(-5,47,5,18:7)
Block(-5,48,-7,4)
Block(-5,48,-6,4)
Block(-5,48,-5,4)
Block(-5,48,-4,4)
Block(-5,48,-3,4)
Block(-5,48,-2,4)
Block(-5,48,-1,4)
Block(-5,48,0,4)
Block(-5,48,1,4)
Block(-5,48,2,4)
Block(-5,48,3,4)
Block(-5,48,4,4)
Block(-5,48,5,4)
Block(-5,48,6,18:7)
Block(-5,49,-7,4)
Block(-5,49,-6,4)
Block(-5,49,-5,4)
Block(-5,49,-4,4)
Block(-5,49,-3,4)
Block(-5,49,-2,4)
Block(-5,49,-1,4)
Block(-5,49,0,4)
Block(-5,49,1,4)
Block(-5,49,2,4)
Block(-5,49,3,3:1)
Block(-5,49,4,4)
Block(-5,49,5,3:1)
Block(-5,49,6,44:11)
Block(-5,50,-7,44:3)
Block(-5,50,-6,4)
Block(-5,50,2,18:7)
Block(-5,50,3,18:7)
Block(-5,50,4,18:15)
Block(-5,50,5,18:7)
Block(-5,50,6,44:3)
Block(-5,50,7,18:7)
Block(-5,51,4,18:15)
Block(-5,51,5,18:7)
Block(-4,0,-7,4)
Block(-4,0,-6,4)
Block(-4,0,-5,4)
Block(-4,0,-4,4)
Block(-4,0,-3,4)
Block(-4,0,-2,4)
Block(-4,0,-1,4)
Block(-4,0,0,4)
Block(-4,0,1,4)
Block(-4,0,2,4)
Block(-4,0,3,4)
Block(-4,0,4,4)
Block(-4,0,5,4)
Block(-4,0,6,4)
Block(-4,0,7,4)
Block(-4,1,-7,4)
Block(-4,1,-6,4)
Block(-4,1,-5,4)
Block(-4,1,-4,4)
Block(-4,1,-3,4)
Block(-4,1,-2,4)
Block(-4,1,-1,4)
Block(-4,1,0,4)
Block(-4,1,1,4)
Block(-4,1,2,4)
Block(-4,1,3,4)
Block(-4,1,4,4)
Block(-4,1,5,4)
Block(-4,1,6,4)
Block(-4,1,7,4)
Block(-4,2,-7,4)
Block(-4,2,-6,4)
Block(-4,2,-5,4)
Block(-4,2,-4,4)
Block(-4,2,-3,4)
Block(-4,2,-2,4)
Block(-4,2,-1,4)
Block(-4,2,0,4)
Block(-4,2,1,4)
Block(-4,2,2,4)
Block(-4,2,3,4)
Block(-4,2,4,4)
Block(-4,2,5,4)
Block(-4,2,6,4)
Block(-4,2,7,4)
Block(-4,3,-7,4)
Block(-4,3,-6,4)
Block(-4,3,-5,4)
Block(-4,3,-4,4)
Block(-4,3,-3,4)
Block(-4,3,-2,4)
Block(-4,3,-1,4)
Block(-4,3,0,4)
Block(-4,3,1,4)
Block(-4,3,2,4)
Block(-4,3,3,4)
Block(-4,3,4,4)
Block(-4,3,5,4)
Block(-4,3,6,4)
Block(-4,3,7,4)
Block(-4,4,-7,4)
Block(-4,4,-6,4)
Block(-4,4,-5,4)
Block(-4,4,-4,4)
Block(-4,4,-3,4)
Block(-4,4,-2,4)
Block(-4,4,-1,4)
Block(-4,4,0,4)
Block(-4,4,1,4)
Block(-4,4,2,4)
Block(-4,4,3,4)
Block(-4,4,4,4)
Block(-4,4,5,4)
Block(-4,4,6,4)
Block(-4,4,7,4)
Block(-4,5,-7,4)
Block(-4,5,-6,4)
Block(-4,5,-5,4)
Block(-4,5,-4,4)
Block(-4,5,-3,4)
Block(-4,5,-2,4)
Block(-4,5,-1,4)
Block(-4,5,0,4)
Block(-4,5,1,4)
Block(-4,5,2,4)
Block(-4,5,3,4)
Block(-4,5,4,4)
Block(-4,5,5,4)
Block(-4,5,6,4)
Block(-4,5,7,4)
Block(-4,6,-7,4)
Block(-4,6,-6,4)
Block(-4,6,-5,4)
Block(-4,6,-4,4)
Block(-4,6,-3,4)
Block(-4,6,-2,4)
Block(-4,6,-1,4)
Block(-4,6,0,4)
Block(-4,6,1,4)
Block(-4,6,2,4)
Block(-4,6,3,4)
Block(-4,6,4,4)
Block(-4,6,5,4)
Block(-4,6,6,4)
Block(-4,6,7,4)
Block(-4,7,-7,4)
Block(-4,7,-6,4)
Block(-4,7,-5,4)
Block(-4,7,-4,4)
Block(-4,7,-3,4)
Block(-4,7,-2,4)
Block(-4,7,-1,4)
Block(-4,7,0,4)
Block(-4,7,1,4)
Block(-4,7,2,4)
Block(-4,7,3,4)
Block(-4,7,4,4)
Block(-4,7,5,4)
Block(-4,7,6,4)
Block(-4,7,7,4)
Block(-4,8,-7,4)
Block(-4,8,-6,4)
Block(-4,8,-5,4)
Block(-4,8,-4,4)
Block(-4,8,-3,4)
Block(-4,8,-2,4)
Block(-4,8,-1,4)
Block(-4,8,0,4)
Block(-4,8,1,4)
Block(-4,8,2,4)
Block(-4,8,3,4)
Block(-4,8,4,4)
Block(-4,8,5,4)
Block(-4,8,6,4)
Block(-4,8,7,4)
Block(-4,9,-7,4)
Block(-4,9,-6,4)
Block(-4,9,-5,4)
Block(-4,9,-4,4)
Block(-4,9,-3,4)
Block(-4,9,-2,4)
Block(-4,9,-1,4)
Block(-4,9,0,4)
Block(-4,9,1,4)
Block(-4,9,2,4)
Block(-4,9,3,4)
Block(-4,9,4,4)
Block(-4,9,5,4)
Block(-4,9,6,4)
Block(-4,9,7,4)
Block(-4,10,-7,4)
Block(-4,10,-6,4)
Block(-4,10,-5,4)
Block(-4,10,-4,4)
Block(-4,10,-3,4)
Block(-4,10,-2,4)
Block(-4,10,-1,4)
Block(-4,10,0,4)
Block(-4,10,1,4)
Block(-4,10,2,4)
Block(-4,10,3,4)
Block(-4,10,4,4)
Block(-4,10,5,4)
Block(-4,10,6,4)
Block(-4,10,7,4)
Block(-4,11,-7,4)
Block(-4,11,-6,4)
Block(-4,11,-5,4)
Block(-4,11,-4,4)
Block(-4,11,-3,4)
Block(-4,11,-2,4)
Block(-4,11,-1,4)
Block(-4,11,0,4)
Block(-4,11,1,4)
Block(-4,11,2,4)
Block(-4,11,3,4)
Block(-4,11,4,4)
Block(-4,11,5,4)
Block(-4,11,6,4)
Block(-4,11,7,4)
Block(-4,12,-7,4)
Block(-4,12,-6,4)
Block(-4,12,-5,4)
Block(-4,12,-4,4)
Block(-4,12,-3,4)
Block(-4,12,-2,4)
Block(-4,12,-1,4)
Block(-4,12,0,4)
Block(-4,12,1,4)
Block(-4,12,2,4)
Block(-4,12,3,4)
Block(-4,12,4,4)
Block(-4,12,5,4)
Block(-4,12,6,4)
Block(-4,12,7,4)
Block(-4,13,-7,4)
Block(-4,13,-6,4)
Block(-4,13,-5,4)
Block(-4,13,-4,4)
Block(-4,13,-3,4)
Block(-4,13,-2,4)
Block(-4,13,-1,4)
Block(-4,13,0,4)
Block(-4,13,1,4)
Block(-4,13,2,4)
Block(-4,13,3,4)
Block(-4,13,4,4)
Block(-4,13,5,4)
Block(-4,13,6,4)
Block(-4,13,7,4)
Block(-4,14,-7,4)
Block(-4,14,-6,4)
Block(-4,14,-5,4)
Block(-4,14,-4,4)
Block(-4,14,-3,4)
Block(-4,14,-2,4)
Block(-4,14,-1,4)
Block(-4,14,0,4)
Block(-4,14,1,4)
Block(-4,14,2,4)
Block(-4,14,3,4)
Block(-4,14,4,4)
Block(-4,14,5,4)
Block(-4,14,6,4)
Block(-4,14,7,4)
Block(-4,15,-7,4)
Block(-4,15,-6,4)
Block(-4,15,-5,4)
Block(-4,15,-4,4)
Block(-4,15,-3,4)
Block(-4,15,-2,4)
Block(-4,15,-1,4)
Block(-4,15,0,4)
Block(-4,15,1,4)
Block(-4,15,2,4)
Block(-4,15,3,4)
Block(-4,15,4,4)
Block(-4,15,5,4)
Block(-4,15,6,4)
Block(-4,15,7,4)
Block(-4,16,-7,4)
Block(-4,16,-6,4)
Block(-4,16,-5,4)
Block(-4,16,-4,4)
Block(-4,16,-3,4)
Block(-4,16,-2,4)
Block(-4,16,-1,4)
Block(-4,16,0,4)
Block(-4,16,1,4)
Block(-4,16,2,4)
Block(-4,16,3,4)
Block(-4,16,4,4)
Block(-4,16,5,4)
Block(-4,16,6,4)
Block(-4,16,7,4)
Block(-4,17,-7,4)
Block(-4,17,-6,4)
Block(-4,17,-5,4)
Block(-4,17,-4,4)
Block(-4,17,-3,4)
Block(-4,17,-2,4)
Block(-4,17,-1,4)
Block(-4,17,0,4)
Block(-4,17,1,4)
Block(-4,17,2,4)
Block(-4,17,3,4)
Block(-4,17,4,4)
Block(-4,17,5,4)
Block(-4,17,6,4)
Block(-4,17,7,4)
Block(-4,18,-7,AIR)
Block(-4,18,-6,AIR)
Block(-4,18,-5,AIR)
Block(-4,18,-4,5:3)
Block(-4,18,-3,4)
Block(-4,18,-2,4)
Block(-4,18,-1,4)
Block(-4,18,0,4)
Block(-4,18,1,4)
Block(-4,18,2,4)
Block(-4,18,3,4)
Block(-4,18,4,4)
Block(-4,18,5,4)
Block(-4,18,6,4)
Block(-4,18,7,4)
Block(-4,19,-7,AIR)
Block(-4,19,-6,AIR)
Block(-4,19,-5,AIR)
Block(-4,19,-4,76:5)
Block(-4,19,-3,4)
Block(-4,19,-2,4)
Block(-4,19,-1,4)
Block(-4,19,0,4)
Block(-4,19,1,4)
Block(-4,19,2,4)
Block(-4,19,3,4)
Block(-4,19,4,4)
Block(-4,19,5,4)
Block(-4,19,6,4)
Block(-4,19,7,4)
Block(-4,20,-7,126:11)
Block(-4,20,-6,126:11)
Block(-4,20,-5,126:11)
Block(-4,20,-4,126:11)
Block(-4,20,-3,4)
Block(-4,20,-2,4)
Block(-4,20,-1,4)
Block(-4,20,0,4)
Block(-4,20,1,4)
Block(-4,20,2,4)
Block(-4,20,3,4)
Block(-4,20,4,4)
Block(-4,20,5,4)
Block(-4,20,6,4)
Block(-4,20,7,4)
Block(-4,21,-7,4)
Block(-4,21,-6,4)
Block(-4,21,-5,4)
Block(-4,21,-4,4)
Block(-4,21,-3,4)
Block(-4,21,-2,4)
Block(-4,21,-1,4)
Block(-4,21,0,4)
Block(-4,21,1,4)
Block(-4,21,2,4)
Block(-4,21,3,4)
Block(-4,21,4,4)
Block(-4,21,5,4)
Block(-4,21,6,44:5)
Block(-4,21,7,4)
Block(-4,22,-7,4)
Block(-4,22,-6,4)
Block(-4,22,-5,4)
Block(-4,22,-4,4)
Block(-4,22,-3,4)
Block(-4,22,-2,4)
Block(-4,22,-1,4)
Block(-4,22,0,4)
Block(-4,22,1,4)
Block(-4,22,2,4)
Block(-4,22,3,4)
Block(-4,22,4,4)
Block(-4,22,5,98)
Block(-4,22,6,18:7)
Block(-4,23,-7,4)
Block(-4,23,-6,4)
Block(-4,23,-5,4)
Block(-4,23,-4,4)
Block(-4,23,-3,4)
Block(-4,23,-2,4)
Block(-4,23,-1,4)
Block(-4,23,0,4)
Block(-4,23,1,4)
Block(-4,23,2,4)
Block(-4,23,3,4)
Block(-4,23,4,4)
Block(-4,23,5,4)
Block(-4,24,-7,4)
Block(-4,24,-6,4)
Block(-4,24,-5,4)
Block(-4,24,-4,4)
Block(-4,24,-3,4)
Block(-4,24,-2,4)
Block(-4,24,-1,4)
Block(-4,24,0,4)
Block(-4,24,1,4)
Block(-4,24,2,4)
Block(-4,24,3,4)
Block(-4,24,4,4)
Block(-4,24,5,98)
Block(-4,25,-7,4)
Block(-4,25,-6,4)
Block(-4,25,-5,4)
Block(-4,25,-4,4)
Block(-4,25,-3,4)
Block(-4,25,-2,4)
Block(-4,25,-1,4)
Block(-4,25,0,4)
Block(-4,25,1,4)
Block(-4,25,2,4)
Block(-4,25,3,4)
Block(-4,25,4,4)
Block(-4,25,5,4)
Block(-4,26,-7,4)
Block(-4,26,-6,4)
Block(-4,26,-5,4)
Block(-4,26,-4,4)
Block(-4,26,-3,4)
Block(-4,26,-2,4)
Block(-4,26,-1,4)
Block(-4,26,0,4)
Block(-4,26,1,4)
Block(-4,26,2,4)
Block(-4,26,3,4)
Block(-4,26,4,4)
Block(-4,26,5,98)
Block(-4,27,-7,4)
Block(-4,27,-6,4)
Block(-4,27,-5,4)
Block(-4,27,-4,4)
Block(-4,27,-3,4)
Block(-4,27,-2,4)
Block(-4,27,-1,4)
Block(-4,27,0,4)
Block(-4,27,1,4)
Block(-4,27,2,4)
Block(-4,27,3,4)
Block(-4,27,4,4)
Block(-4,27,5,4)
Block(-4,27,6,4)
Block(-4,27,7,4)
Block(-4,27,8,139)
Block(-4,28,-7,4)
Block(-4,28,-6,4)
Block(-4,28,-5,4)
Block(-4,28,-4,4)
Block(-4,28,-3,4)
Block(-4,28,-2,4)
Block(-4,28,-1,4)
Block(-4,28,0,4)
Block(-4,28,1,4)
Block(-4,28,2,4)
Block(-4,28,3,4)
Block(-4,28,4,98)
Block(-4,28,5,98)
Block(-4,28,6,4)
Block(-4,28,7,18:7)
Block(-4,29,-7,4)
Block(-4,29,-6,4)
Block(-4,29,-5,4)
Block(-4,29,-4,4)
Block(-4,29,-3,4)
Block(-4,29,-2,4)
Block(-4,29,-1,4)
Block(-4,29,0,4)
Block(-4,29,1,4)
Block(-4,29,2,4)
Block(-4,29,3,98)
Block(-4,29,4,98)
Block(-4,29,5,18:7)
Block(-4,30,-7,4)
Block(-4,30,-6,4)
Block(-4,30,-5,4)
Block(-4,30,-4,67:3)
Block(-4,30,-3,AIR)
Block(-4,30,-2,39)
Block(-4,30,-1,AIR)
Block(-4,30,0,67:2)
Block(-4,30,1,4)
Block(-4,30,2,4)
Block(-4,30,3,4)
Block(-4,30,4,98)
Block(-4,30,5,18:7)
Block(-4,31,-7,4)
Block(-4,31,-6,4)
Block(-4,31,-5,4)
Block(-4,31,-4,AIR)
Block(-4,31,-3,AIR)
Block(-4,31,-2,AIR)
Block(-4,31,-1,AIR)
Block(-4,31,0,AIR)
Block(-4,31,1,4)
Block(-4,31,2,4)
Block(-4,31,3,98)
Block(-4,31,4,98)
Block(-4,31,5,AIR)
Block(-4,32,-7,4)
Block(-4,32,-6,4)
Block(-4,32,-5,4)
Block(-4,32,-4,67:7)
Block(-4,32,-3,AIR)
Block(-4,32,-2,AIR)
Block(-4,32,-1,AIR)
Block(-4,32,0,67:6)
Block(-4,32,1,4)
Block(-4,32,2,4)
Block(-4,32,3,4)
Block(-4,32,4,98)
Block(-4,32,5,18:7)
Block(-4,33,-7,4)
Block(-4,33,-6,4)
Block(-4,33,-5,4)
Block(-4,33,-4,4)
Block(-4,33,-3,4)
Block(-4,33,-2,4)
Block(-4,33,-1,4)
Block(-4,33,0,4)
Block(-4,33,1,4)
Block(-4,33,2,4)
Block(-4,33,3,98)
Block(-4,33,4,98)
Block(-4,33,5,18:7)
Block(-4,34,-7,4)
Block(-4,34,-6,4)
Block(-4,34,-5,4)
Block(-4,34,-4,4)
Block(-4,34,-3,4)
Block(-4,34,-2,4)
Block(-4,34,-1,4)
Block(-4,34,0,4)
Block(-4,34,1,4)
Block(-4,34,2,4)
Block(-4,34,3,4)
Block(-4,34,4,4)
Block(-4,34,5,4)
Block(-4,34,6,4)
Block(-4,34,7,139)
Block(-4,35,-7,4)
Block(-4,35,-6,4)
Block(-4,35,-5,4)
Block(-4,35,-4,4)
Block(-4,35,-3,4)
Block(-4,35,-2,4)
Block(-4,35,-1,4)
Block(-4,35,0,4)
Block(-4,35,1,4)
Block(-4,35,2,4)
Block(-4,35,3,4)
Block(-4,35,4,98)
Block(-4,35,5,98)
Block(-4,35,6,4)
Block(-4,35,7,18:7)
Block(-4,36,-7,4)
Block(-4,36,-6,4)
Block(-4,36,-5,4)
Block(-4,36,-4,4)
Block(-4,36,-3,4)
Block(-4,36,-2,4)
Block(-4,36,-1,4)
Block(-4,36,0,4)
Block(-4,36,1,4)
Block(-4,36,2,4)
Block(-4,36,3,98)
Block(-4,36,4,98)
Block(-4,36,5,18:7)
Block(-4,36,6,18:7)
Block(-4,37,-7,4)
Block(-4,37,-6,4)
Block(-4,37,-5,4)
Block(-4,37,-4,67:3)
Block(-4,37,-3,AIR)
Block(-4,37,-2,AIR)
Block(-4,37,-1,AIR)
Block(-4,37,0,67:2)
Block(-4,37,1,4)
Block(-4,37,2,4)
Block(-4,37,3,4)
Block(-4,37,4,98)
Block(-4,37,5,18:7)
Block(-4,38,-7,4)
Block(-4,38,-6,4)
Block(-4,38,-5,4)
Block(-4,38,-4,AIR)
Block(-4,38,-3,AIR)
Block(-4,38,-2,AIR)
Block(-4,38,-1,AIR)
Block(-4,38,0,106:1)
Block(-4,38,1,4)
Block(-4,38,2,4)
Block(-4,38,3,98)
Block(-4,38,4,98)
Block(-4,38,5,AIR)
Block(-4,39,-7,4)
Block(-4,39,-6,4)
Block(-4,39,-5,4)
Block(-4,39,-4,67:7)
Block(-4,39,-3,AIR)
Block(-4,39,-2,AIR)
Block(-4,39,-1,AIR)
Block(-4,39,0,67:6)
Block(-4,39,1,4)
Block(-4,39,2,4)
Block(-4,39,3,4)
Block(-4,39,4,98)
Block(-4,39,5,AIR)
Block(-4,40,-7,4)
Block(-4,40,-6,4)
Block(-4,40,-5,4)
Block(-4,40,-4,4)
Block(-4,40,-3,4)
Block(-4,40,-2,4)
Block(-4,40,-1,4)
Block(-4,40,0,4)
Block(-4,40,1,4)
Block(-4,40,2,4)
Block(-4,40,3,98)
Block(-4,40,4,98)
Block(-4,40,5,AIR)
Block(-4,41,-7,4)
Block(-4,41,-6,4)
Block(-4,41,-5,4)
Block(-4,41,-4,4)
Block(-4,41,-3,4)
Block(-4,41,-2,4)
Block(-4,41,-1,4)
Block(-4,41,0,4)
Block(-4,41,1,4)
Block(-4,41,2,4)
Block(-4,41,3,4)
Block(-4,41,4,4)
Block(-4,41,5,4)
Block(-4,41,6,4)
Block(-4,41,7,139)
Block(-4,42,-7,4)
Block(-4,42,-6,4)
Block(-4,42,-5,4)
Block(-4,42,-4,4)
Block(-4,42,-3,4)
Block(-4,42,-2,4)
Block(-4,42,-1,4)
Block(-4,42,0,4)
Block(-4,42,1,4)
Block(-4,42,2,4)
Block(-4,42,3,4)
Block(-4,42,4,98)
Block(-4,42,5,98)
Block(-4,42,6,4)
Block(-4,42,7,18:7)
Block(-4,43,-7,4)
Block(-4,43,-6,4)
Block(-4,43,-5,4)
Block(-4,43,-4,4)
Block(-4,43,-3,4)
Block(-4,43,-2,4)
Block(-4,43,-1,4)
Block(-4,43,0,4)
Block(-4,43,1,4)
Block(-4,43,2,4)
Block(-4,43,3,98)
Block(-4,43,4,98)
Block(-4,43,5,18:7)
Block(-4,43,6,18:7)
Block(-4,44,-7,4)
Block(-4,44,-6,4)
Block(-4,44,-5,4)
Block(-4,44,-4,67:3)
Block(-4,44,-3,AIR)
Block(-4,44,-2,AIR)
Block(-4,44,-1,AIR)
Block(-4,44,0,67:2)
Block(-4,44,1,4)
Block(-4,44,2,4)
Block(-4,44,3,4)
Block(-4,44,4,98)
Block(-4,44,5,18:7)
Block(-4,45,-7,4)
Block(-4,45,-6,4)
Block(-4,45,-5,4)
Block(-4,45,-4,AIR)
Block(-4,45,-3,AIR)
Block(-4,45,-2,AIR)
Block(-4,45,-1,AIR)
Block(-4,45,0,AIR)
Block(-4,45,1,4)
Block(-4,45,2,4)
Block(-4,45,3,98)
Block(-4,45,4,98)
Block(-4,45,5,AIR)
Block(-4,46,-7,4)
Block(-4,46,-6,4)
Block(-4,46,-5,4)
Block(-4,46,-4,67:7)
Block(-4,46,-3,AIR)
Block(-4,46,-2,AIR)
Block(-4,46,-1,AIR)
Block(-4,46,0,67:6)
Block(-4,46,1,4)
Block(-4,46,2,4)
Block(-4,46,3,4)
Block(-4,46,4,98)
Block(-4,46,5,18:7)
Block(-4,47,-7,4)
Block(-4,47,-6,4)
Block(-4,47,-5,4)
Block(-4,47,-4,4)
Block(-4,47,-3,4)
Block(-4,47,-2,4)
Block(-4,47,-1,4)
Block(-4,47,0,4)
Block(-4,47,1,4)
Block(-4,47,2,4)
Block(-4,47,3,98)
Block(-4,47,4,98)
Block(-4,47,5,18:7)
Block(-4,47,6,18:7)
Block(-4,48,-7,4)
Block(-4,48,-6,4)
Block(-4,48,-5,4)
Block(-4,48,-4,4)
Block(-4,48,-3,4)
Block(-4,48,-2,4)
Block(-4,48,-1,4)
Block(-4,48,0,4)
Block(-4,48,1,4)
Block(-4,48,2,4)
Block(-4,48,3,4)
Block(-4,48,4,4)
Block(-4,48,5,4)
Block(-4,48,6,4)
Block(-4,48,7,139)
Block(-4,49,-7,4)
Block(-4,49,-6,4)
Block(-4,49,-5,4)
Block(-4,49,-4,4)
Block(-4,49,-3,4)
Block(-4,49,-2,4)
Block(-4,49,-1,4)
Block(-4,49,0,4)
Block(-4,49,1,4)
Block(-4,49,2,4)
Block(-4,49,3,2)
Block(-4,49,4,3:1)
Block(-4,49,5,4)
Block(-4,49,6,4)
Block(-4,49,7,18:7)
Block(-4,50,-7,44:3)
Block(-4,50,-6,4)
Block(-4,50,2,18:7)
Block(-4,50,3,18:7)
Block(-4,50,4,18:15)
Block(-4,50,5,18:15)
Block(-4,50,6,4)
Block(-4,50,7,18:7)
Block(-4,51,3,18:7)
Block(-4,51,4,18:15)
Block(-4,51,6,18:15)
Block(-4,52,3,18:7)
Block(-3,0,-7,4)
Block(-3,0,-6,4)
Block(-3,0,-5,4)
Block(-3,0,-4,4)
Block(-3,0,-3,4)
Block(-3,0,-2,4)
Block(-3,0,-1,4)
Block(-3,0,0,4)
Block(-3,0,1,4)
Block(-3,0,2,4)
Block(-3,0,3,4)
Block(-3,0,4,4)
Block(-3,0,5,4)
Block(-3,0,6,4)
Block(-3,0,7,4)
Block(-3,0,8,4)
Block(-3,1,-7,4)
Block(-3,1,-6,4)
Block(-3,1,-5,4)
Block(-3,1,-4,4)
Block(-3,1,-3,4)
Block(-3,1,-2,4)
Block(-3,1,-1,4)
Block(-3,1,0,4)
Block(-3,1,1,4)
Block(-3,1,2,4)
Block(-3,1,3,4)
Block(-3,1,4,4)
Block(-3,1,5,4)
Block(-3,1,6,4)
Block(-3,1,7,4)
Block(-3,1,8,4)
Block(-3,2,-7,4)
Block(-3,2,-6,4)
Block(-3,2,-5,4)
Block(-3,2,-4,4)
Block(-3,2,-3,4)
Block(-3,2,-2,4)
Block(-3,2,-1,4)
Block(-3,2,0,4)
Block(-3,2,1,4)
Block(-3,2,2,4)
Block(-3,2,3,4)
Block(-3,2,4,4)
Block(-3,2,5,4)
Block(-3,2,6,4)
Block(-3,2,7,4)
Block(-3,2,8,4)
Block(-3,3,-7,4)
Block(-3,3,-6,4)
Block(-3,3,-5,4)
Block(-3,3,-4,4)
Block(-3,3,-3,4)
Block(-3,3,-2,4)
Block(-3,3,-1,4)
Block(-3,3,0,4)
Block(-3,3,1,4)
Block(-3,3,2,4)
Block(-3,3,3,4)
Block(-3,3,4,4)
Block(-3,3,5,4)
Block(-3,3,6,4)
Block(-3,3,7,4)
Block(-3,3,8,4)
Block(-3,4,-7,4)
Block(-3,4,-6,4)
Block(-3,4,-5,4)
Block(-3,4,-4,4)
Block(-3,4,-3,4)
Block(-3,4,-2,4)
Block(-3,4,-1,4)
Block(-3,4,0,4)
Block(-3,4,1,4)
Block(-3,4,2,4)
Block(-3,4,3,4)
Block(-3,4,4,4)
Block(-3,4,5,4)
Block(-3,4,6,4)
Block(-3,4,7,4)
Block(-3,4,8,4)
Block(-3,5,-7,4)
Block(-3,5,-6,4)
Block(-3,5,-5,4)
Block(-3,5,-4,4)
Block(-3,5,-3,4)
Block(-3,5,-2,4)
Block(-3,5,-1,4)
Block(-3,5,0,4)
Block(-3,5,1,4)
Block(-3,5,2,4)
Block(-3,5,3,4)
Block(-3,5,4,4)
Block(-3,5,5,4)
Block(-3,5,6,4)
Block(-3,5,7,4)
Block(-3,5,8,4)
Block(-3,6,-7,4)
Block(-3,6,-6,4)
Block(-3,6,-5,4)
Block(-3,6,-4,4)
Block(-3,6,-3,4)
Block(-3,6,-2,4)
Block(-3,6,-1,4)
Block(-3,6,0,4)
Block(-3,6,1,4)
Block(-3,6,2,4)
Block(-3,6,3,4)
Block(-3,6,4,4)
Block(-3,6,5,4)
Block(-3,6,6,4)
Block(-3,6,7,4)
Block(-3,6,8,4)
Block(-3,7,-7,4)
Block(-3,7,-6,4)
Block(-3,7,-5,4)
Block(-3,7,-4,4)
Block(-3,7,-3,4)
Block(-3,7,-2,4)
Block(-3,7,-1,4)
Block(-3,7,0,4)
Block(-3,7,1,4)
Block(-3,7,2,4)
Block(-3,7,3,4)
Block(-3,7,4,4)
Block(-3,7,5,4)
Block(-3,7,6,4)
Block(-3,7,7,4)
Block(-3,7,8,4)
Block(-3,8,-7,4)
Block(-3,8,-6,4)
Block(-3,8,-5,4)
Block(-3,8,-4,4)
Block(-3,8,-3,4)
Block(-3,8,-2,4)
Block(-3,8,-1,4)
Block(-3,8,0,4)
Block(-3,8,1,4)
Block(-3,8,2,4)
Block(-3,8,3,4)
Block(-3,8,4,4)
Block(-3,8,5,4)
Block(-3,8,6,4)
Block(-3,8,7,4)
Block(-3,8,8,4)
Block(-3,9,-7,4)
Block(-3,9,-6,4)
Block(-3,9,-5,4)
Block(-3,9,-4,4)
Block(-3,9,-3,4)
Block(-3,9,-2,4)
Block(-3,9,-1,4)
Block(-3,9,0,4)
Block(-3,9,1,4)
Block(-3,9,2,4)
Block(-3,9,3,4)
Block(-3,9,4,4)
Block(-3,9,5,4)
Block(-3,9,6,4)
Block(-3,9,7,4)
Block(-3,9,8,4)
Block(-3,10,-7,4)
Block(-3,10,-6,4)
Block(-3,10,-5,4)
Block(-3,10,-4,4)
Block(-3,10,-3,4)
Block(-3,10,-2,4)
Block(-3,10,-1,4)
Block(-3,10,0,4)
Block(-3,10,1,4)
Block(-3,10,2,4)
Block(-3,10,3,4)
Block(-3,10,4,4)
Block(-3,10,5,4)
Block(-3,10,6,4)
Block(-3,10,7,4)
Block(-3,10,8,4)
Block(-3,11,-7,4)
Block(-3,11,-6,4)
Block(-3,11,-5,4)
Block(-3,11,-4,4)
Block(-3,11,-3,4)
Block(-3,11,-2,4)
Block(-3,11,-1,4)
Block(-3,11,0,4)
Block(-3,11,1,4)
Block(-3,11,2,4)
Block(-3,11,3,4)
Block(-3,11,4,4)
Block(-3,11,5,4)
Block(-3,11,6,4)
Block(-3,11,7,4)
Block(-3,11,8,4)
Block(-3,12,-7,4)
Block(-3,12,-6,4)
Block(-3,12,-5,4)
Block(-3,12,-4,4)
Block(-3,12,-3,4)
Block(-3,12,-2,4)
Block(-3,12,-1,4)
Block(-3,12,0,4)
Block(-3,12,1,4)
Block(-3,12,2,4)
Block(-3,12,3,4)
Block(-3,12,4,4)
Block(-3,12,5,4)
Block(-3,12,6,4)
Block(-3,12,7,4)
Block(-3,12,8,4)
Block(-3,13,-7,4)
Block(-3,13,-6,4)
Block(-3,13,-5,4)
Block(-3,13,-4,4)
Block(-3,13,-3,4)
Block(-3,13,-2,4)
Block(-3,13,-1,4)
Block(-3,13,0,4)
Block(-3,13,1,4)
Block(-3,13,2,4)
Block(-3,13,3,4)
Block(-3,13,4,4)
Block(-3,13,5,4)
Block(-3,13,6,4)
Block(-3,13,7,4)
Block(-3,13,8,4)
Block(-3,14,-7,4)
Block(-3,14,-6,4)
Block(-3,14,-5,4)
Block(-3,14,-4,4)
Block(-3,14,-3,4)
Block(-3,14,-2,4)
Block(-3,14,-1,4)
Block(-3,14,0,4)
Block(-3,14,1,4)
Block(-3,14,2,4)
Block(-3,14,3,4)
Block(-3,14,4,4)
Block(-3,14,5,4)
Block(-3,14,6,4)
Block(-3,14,7,4)
Block(-3,14,8,4)
Block(-3,15,-7,4)
Block(-3,15,-6,4)
Block(-3,15,-5,4)
Block(-3,15,-4,4)
Block(-3,15,-3,4)
Block(-3,15,-2,4)
Block(-3,15,-1,4)
Block(-3,15,0,4)
Block(-3,15,1,4)
Block(-3,15,2,4)
Block(-3,15,3,4)
Block(-3,15,4,4)
Block(-3,15,5,4)
Block(-3,15,6,4)
Block(-3,15,7,4)
Block(-3,15,8,4)
Block(-3,16,-7,4)
Block(-3,16,-6,4)
Block(-3,16,-5,4)
Block(-3,16,-4,4)
Block(-3,16,-3,4)
Block(-3,16,-2,4)
Block(-3,16,-1,4)
Block(-3,16,0,4)
Block(-3,16,1,4)
Block(-3,16,2,4)
Block(-3,16,3,4)
Block(-3,16,4,4)
Block(-3,16,5,4)
Block(-3,16,6,4)
Block(-3,16,7,4)
Block(-3,16,8,4)
Block(-3,17,-7,4)
Block(-3,17,-6,4)
Block(-3,17,-5,4)
Block(-3,17,-4,4)
Block(-3,17,-3,4)
Block(-3,17,-2,4)
Block(-3,17,-1,4)
Block(-3,17,0,87)
Block(-3,17,1,87)
Block(-3,17,2,4)
Block(-3,17,3,4)
Block(-3,17,4,4)
Block(-3,17,5,4)
Block(-3,17,6,4)
Block(-3,17,7,4)
Block(-3,17,8,4)
Block(-3,18,-7,AIR)
Block(-3,18,-6,AIR)
Block(-3,18,-5,AIR)
Block(-3,18,-4,126:11)
Block(-3,18,-3,4)
Block(-3,18,-2,4)
Block(-3,18,-1,4)
Block(-3,18,0,51)
Block(-3,18,1,51)
Block(-3,18,2,4)
Block(-3,18,3,4)
Block(-3,18,4,4)
Block(-3,18,5,4)
Block(-3,18,6,4)
Block(-3,18,7,4)
Block(-3,18,8,4)
Block(-3,19,-7,AIR)
Block(-3,19,-6,AIR)
Block(-3,19,-5,AIR)
Block(-3,19,-4,173)
Block(-3,19,-3,4)
Block(-3,19,-2,4)
Block(-3,19,-1,4)
Block(-3,19,0,AIR)
Block(-3,19,1,AIR)
Block(-3,19,2,4)
Block(-3,19,3,4)
Block(-3,19,4,4)
Block(-3,19,5,4)
Block(-3,19,6,4)
Block(-3,19,7,4)
Block(-3,20,-7,AIR)
Block(-3,20,-6,AIR)
Block(-3,20,-5,AIR)
Block(-3,20,-4,AIR)
Block(-3,20,-3,4)
Block(-3,20,-2,4)
Block(-3,20,-1,4)
Block(-3,20,0,67:7)
Block(-3,20,1,67:6)
Block(-3,20,2,4)
Block(-3,20,3,4)
Block(-3,20,4,4)
Block(-3,20,5,4)
Block(-3,20,6,4)
Block(-3,20,7,4)
Block(-3,21,-7,4)
Block(-3,21,-6,4)
Block(-3,21,-5,4)
Block(-3,21,-4,4)
Block(-3,21,-3,4)
Block(-3,21,-2,4)
Block(-3,21,-1,4)
Block(-3,21,0,4)
Block(-3,21,1,4)
Block(-3,21,2,4)
Block(-3,21,3,4)
Block(-3,21,4,4)
Block(-3,21,5,4)
Block(-3,21,6,4)
Block(-3,21,7,4)
Block(-3,21,8,67:4)
Block(-3,22,-7,4)
Block(-3,22,-6,4)
Block(-3,22,-5,4)
Block(-3,22,-4,4)
Block(-3,22,-3,4)
Block(-3,22,-2,4)
Block(-3,22,-1,4)
Block(-3,22,0,4)
Block(-3,22,1,4)
Block(-3,22,2,4)
Block(-3,22,3,4)
Block(-3,22,4,4)
Block(-3,22,5,4)
Block(-3,22,6,67:0)
Block(-3,22,7,18:7)
Block(-3,23,-7,1:6)
Block(-3,23,-6,98:3)
Block(-3,23,-5,1:6)
Block(-3,23,-4,98:3)
Block(-3,23,-3,1:6)
Block(-3,23,-2,98:3)
Block(-3,23,-1,1:6)
Block(-3,23,0,98:3)
Block(-3,23,1,1:6)
Block(-3,23,2,98:3)
Block(-3,23,3,1:6)
Block(-3,23,4,4)
Block(-3,23,5,4)
Block(-3,23,6,18:7)
Block(-3,24,-7,98:3)
Block(-3,24,-6,1:6)
Block(-3,24,-5,98:3)
Block(-3,24,-4,1:6)
Block(-3,24,-3,98:3)
Block(-3,24,-2,1:6)
Block(-3,24,-1,98:3)
Block(-3,24,0,1:6)
Block(-3,24,1,98:3)
Block(-3,24,2,1:6)
Block(-3,24,3,98:3)
Block(-3,24,4,4)
Block(-3,24,5,4)
Block(-3,25,-7,4)
Block(-3,25,-6,4)
Block(-3,25,-5,4)
Block(-3,25,-4,4)
Block(-3,25,-3,4)
Block(-3,25,-2,4)
Block(-3,25,-1,4)
Block(-3,25,0,4)
Block(-3,25,1,4)
Block(-3,25,2,4)
Block(-3,25,3,4)
Block(-3,25,4,4)
Block(-3,25,5,4)
Block(-3,26,-7,4)
Block(-3,26,-6,4)
Block(-3,26,-5,4)
Block(-3,26,-4,4)
Block(-3,26,-3,4)
Block(-3,26,-2,4)
Block(-3,26,-1,4)
Block(-3,26,0,4)
Block(-3,26,1,4)
Block(-3,26,2,4)
Block(-3,26,3,4)
Block(-3,26,4,4)
Block(-3,26,5,4)
Block(-3,26,6,67:4)
Block(-3,27,-7,4)
Block(-3,27,-6,4)
Block(-3,27,-5,4)
Block(-3,27,-4,4)
Block(-3,27,-3,4)
Block(-3,27,-2,4)
Block(-3,27,-1,4)
Block(-3,27,0,4)
Block(-3,27,1,4)
Block(-3,27,2,4)
Block(-3,27,3,4)
Block(-3,27,4,4)
Block(-3,27,5,4)
Block(-3,27,6,4)
Block(-3,28,-7,4)
Block(-3,28,-6,4)
Block(-3,28,-5,4)
Block(-3,28,-4,4)
Block(-3,28,-3,4)
Block(-3,28,-2,4)
Block(-3,28,-1,4)
Block(-3,28,0,4)
Block(-3,28,1,4)
Block(-3,28,2,4)
Block(-3,28,3,4)
Block(-3,28,4,4)
Block(-3,28,5,98)
Block(-3,28,6,4)
Block(-3,28,7,18:7)
Block(-3,29,-7,4)
Block(-3,29,-6,4)
Block(-3,29,-5,4)
Block(-3,29,-4,4)
Block(-3,29,-3,4)
Block(-3,29,-2,4)
Block(-3,29,-1,4)
Block(-3,29,0,4)
Block(-3,29,1,97:2)
Block(-3,29,2,97:2)
Block(-3,29,3,4)
Block(-3,29,4,98)
Block(-3,29,5,67:0)
Block(-3,29,6,18:7)
Block(-3,30,-7,4)
Block(-3,30,-6,4)
Block(-3,30,-5,4)
Block(-3,30,-4,67:3)
Block(-3,30,-3,39)
Block(-3,30,-2,AIR)
Block(-3,30,-1,AIR)
Block(-3,30,0,67:2)
Block(-3,30,1,4)
Block(-3,30,2,97:2)
Block(-3,30,3,4)
Block(-3,30,4,4)
Block(-3,30,5,18:7)
Block(-3,31,-7,4)
Block(-3,31,-6,4)
Block(-3,31,-5,4)
Block(-3,31,-4,AIR)
Block(-3,31,-3,AIR)
Block(-3,31,-2,AIR)
Block(-3,31,-1,AIR)
Block(-3,31,0,AIR)
Block(-3,31,1,97:2)
Block(-3,31,2,97:2)
Block(-3,31,3,4)
Block(-3,31,4,98)
Block(-3,31,5,18:7)
Block(-3,32,-7,4)
Block(-3,32,-6,4)
Block(-3,32,-5,4)
Block(-3,32,-4,67:7)
Block(-3,32,-3,AIR)
Block(-3,32,-2,AIR)
Block(-3,32,-1,AIR)
Block(-3,32,0,67:6)
Block(-3,32,1,4)
Block(-3,32,2,97:2)
Block(-3,32,3,4)
Block(-3,32,4,4)
Block(-3,32,5,18:7)
Block(-3,33,-7,4)
Block(-3,33,-6,4)
Block(-3,33,-5,4)
Block(-3,33,-4,4)
Block(-3,33,-3,4)
Block(-3,33,-2,4)
Block(-3,33,-1,4)
Block(-3,33,0,4)
Block(-3,33,1,97:2)
Block(-3,33,2,97:2)
Block(-3,33,3,4)
Block(-3,33,4,98)
Block(-3,33,5,67:4)
Block(-3,33,6,18:7)
Block(-3,34,-7,4)
Block(-3,34,-6,4)
Block(-3,34,-5,4)
Block(-3,34,-4,4)
Block(-3,34,-3,4)
Block(-3,34,-2,4)
Block(-3,34,-1,4)
Block(-3,34,0,4)
Block(-3,34,1,4)
Block(-3,34,2,4)
Block(-3,34,3,4)
Block(-3,34,4,4)
Block(-3,34,5,4)
Block(-3,34,6,18:7)
Block(-3,35,-7,4)
Block(-3,35,-6,4)
Block(-3,35,-5,4)
Block(-3,35,-4,4)
Block(-3,35,-3,4)
Block(-3,35,-2,4)
Block(-3,35,-1,4)
Block(-3,35,0,4)
Block(-3,35,1,4)
Block(-3,35,2,4)
Block(-3,35,3,4)
Block(-3,35,4,4)
Block(-3,35,5,98)
Block(-3,35,6,4)
Block(-3,35,7,18:7)
Block(-3,36,-7,4)
Block(-3,36,-6,4)
Block(-3,36,-5,4)
Block(-3,36,-4,4)
Block(-3,36,-3,4)
Block(-3,36,-2,4)
Block(-3,36,-1,4)
Block(-3,36,0,4)
Block(-3,36,1,4)
Block(-3,36,2,97:2)
Block(-3,36,3,4)
Block(-3,36,4,98)
Block(-3,36,5,67:0)
Block(-3,36,6,18:7)
Block(-3,36,7,18:7)
Block(-3,37,-7,4)
Block(-3,37,-6,4)
Block(-3,37,-5,4)
Block(-3,37,-4,67:3)
Block(-3,37,-3,AIR)
Block(-3,37,-2,AIR)
Block(-3,37,-1,AIR)
Block(-3,37,0,67:2)
Block(-3,37,1,4)
Block(-3,37,2,97:2)
Block(-3,37,3,4)
Block(-3,37,4,4)
Block(-3,37,5,18:7)
Block(-3,37,6,18:7)
Block(-3,38,-7,4)
Block(-3,38,-6,4)
Block(-3,38,-5,4)
Block(-3,38,-4,AIR)
Block(-3,38,-3,AIR)
Block(-3,38,-2,AIR)
Block(-3,38,-1,AIR)
Block(-3,38,0,AIR)
Block(-3,38,1,4)
Block(-3,38,2,97:2)
Block(-3,38,3,4)
Block(-3,38,4,98)
Block(-3,38,5,18:7)
Block(-3,39,-7,4)
Block(-3,39,-6,4)
Block(-3,39,-5,4)
Block(-3,39,-4,67:7)
Block(-3,39,-3,AIR)
Block(-3,39,-2,AIR)
Block(-3,39,-1,AIR)
Block(-3,39,0,67:6)
Block(-3,39,1,4)
Block(-3,39,2,97:2)
Block(-3,39,3,4)
Block(-3,39,4,4)
Block(-3,39,5,AIR)
Block(-3,40,-7,4)
Block(-3,40,-6,4)
Block(-3,40,-5,4)
Block(-3,40,-4,4)
Block(-3,40,-3,4)
Block(-3,40,-2,4)
Block(-3,40,-1,4)
Block(-3,40,0,4)
Block(-3,40,1,4)
Block(-3,40,2,97:2)
Block(-3,40,3,4)
Block(-3,40,4,98)
Block(-3,40,5,67:4)
Block(-3,41,-7,4)
Block(-3,41,-6,4)
Block(-3,41,-5,4)
Block(-3,41,-4,4)
Block(-3,41,-3,4)
Block(-3,41,-2,4)
Block(-3,41,-1,4)
Block(-3,41,0,4)
Block(-3,41,1,4)
Block(-3,41,2,4)
Block(-3,41,3,4)
Block(-3,41,4,4)
Block(-3,41,5,4)
Block(-3,41,6,18:7)
Block(-3,42,-7,4)
Block(-3,42,-6,4)
Block(-3,42,-5,4)
Block(-3,42,-4,4)
Block(-3,42,-3,4)
Block(-3,42,-2,4)
Block(-3,42,-1,4)
Block(-3,42,0,4)
Block(-3,42,1,4)
Block(-3,42,2,97:2)
Block(-3,42,3,4)
Block(-3,42,4,4)
Block(-3,42,5,98)
Block(-3,42,6,4)
Block(-3,42,7,18:7)
Block(-3,43,-7,4)
Block(-3,43,-6,4)
Block(-3,43,-5,4)
Block(-3,43,-4,4)
Block(-3,43,-3,4)
Block(-3,43,-2,4)
Block(-3,43,-1,4)
Block(-3,43,0,4)
Block(-3,43,1,4)
Block(-3,43,2,97:2)
Block(-3,43,3,4)
Block(-3,43,4,98)
Block(-3,43,5,67:0)
Block(-3,43,6,18:7)
Block(-3,44,-7,4)
Block(-3,44,-6,4)
Block(-3,44,-5,4)
Block(-3,44,-4,67:3)
Block(-3,44,-3,AIR)
Block(-3,44,-2,AIR)
Block(-3,44,-1,AIR)
Block(-3,44,0,67:2)
Block(-3,44,1,4)
Block(-3,44,2,97:2)
Block(-3,44,3,4)
Block(-3,44,4,4)
Block(-3,44,5,18:7)
Block(-3,45,-7,4)
Block(-3,45,-6,4)
Block(-3,45,-5,4)
Block(-3,45,-4,AIR)
Block(-3,45,-3,AIR)
Block(-3,45,-2,AIR)
Block(-3,45,-1,AIR)
Block(-3,45,0,AIR)
Block(-3,45,1,4)
Block(-3,45,2,97:2)
Block(-3,45,3,4)
Block(-3,45,4,98)
Block(-3,45,5,18:7)
Block(-3,46,-7,4)
Block(-3,46,-6,4)
Block(-3,46,-5,4)
Block(-3,46,-4,67:7)
Block(-3,46,-3,AIR)
Block(-3,46,-2,AIR)
Block(-3,46,-1,AIR)
Block(-3,46,0,67:6)
Block(-3,46,1,4)
Block(-3,46,2,97:2)
Block(-3,46,3,4)
Block(-3,46,4,4)
Block(-3,46,5,18:7)
Block(-3,47,-7,4)
Block(-3,47,-6,4)
Block(-3,47,-5,4)
Block(-3,47,-4,4)
Block(-3,47,-3,4)
Block(-3,47,-2,4)
Block(-3,47,-1,4)
Block(-3,47,0,4)
Block(-3,47,1,4)
Block(-3,47,2,97:2)
Block(-3,47,3,4)
Block(-3,47,4,98)
Block(-3,47,5,67:4)
Block(-3,47,6,18:7)
Block(-3,48,-7,4)
Block(-3,48,-6,4)
Block(-3,48,-5,4)
Block(-3,48,-4,4)
Block(-3,48,-3,4)
Block(-3,48,-2,4)
Block(-3,48,-1,4)
Block(-3,48,0,4)
Block(-3,48,1,4)
Block(-3,48,2,4)
Block(-3,48,3,4)
Block(-3,48,4,4)
Block(-3,48,5,4)
Block(-3,49,-7,4)
Block(-3,49,-6,4)
Block(-3,49,-5,4)
Block(-3,49,-4,4)
Block(-3,49,-3,4)
Block(-3,49,-2,4)
Block(-3,49,-1,4)
Block(-3,49,0,4)
Block(-3,49,1,2)
Block(-3,49,2,4)
Block(-3,49,3,3)
Block(-3,49,4,2)
Block(-3,49,5,4)
Block(-3,49,6,4)
Block(-3,49,7,18:7)
Block(-3,50,-7,44:3)
Block(-3,50,-6,4)
Block(-3,50,2,18:7)
Block(-3,50,3,17:3)
Block(-3,50,4,18:15)
Block(-3,50,5,18:15)
Block(-3,50,6,44:3)
Block(-3,50,7,18:15)
Block(-3,51,2,18:7)
Block(-3,51,3,17:3)
Block(-3,51,4,18:15)
Block(-3,52,3,18:7)
Block(-2,0,-7,4)
Block(-2,0,-6,4)
Block(-2,0,-5,4)
Block(-2,0,-4,4)
Block(-2,0,-3,97:2)
Block(-2,0,-2,97:2)
Block(-2,0,-1,97:2)
Block(-2,0,0,97:2)
Block(-2,0,1,97:2)
Block(-2,0,2,97:2)
Block(-2,0,3,4)
Block(-2,0,4,4)
Block(-2,0,5,4)
Block(-2,0,6,4)
Block(-2,0,7,4)
Block(-2,0,8,4)
Block(-2,1,-7,4)
Block(-2,1,-6,4)
Block(-2,1,-5,4)
Block(-2,1,-4,4)
Block(-2,1,-3,97:2)
Block(-2,1,-2,97:2)
Block(-2,1,-1,97:2)
Block(-2,1,0,97:2)
Block(-2,1,1,97:2)
Block(-2,1,2,97:2)
Block(-2,1,3,4)
Block(-2,1,4,4)
Block(-2,1,5,4)
Block(-2,1,6,4)
Block(-2,1,7,4)
Block(-2,1,8,4)
Block(-2,2,-7,4)
Block(-2,2,-6,4)
Block(-2,2,-5,4)
Block(-2,2,-4,4)
Block(-2,2,-3,97:2)
Block(-2,2,-2,97:2)
Block(-2,2,-1,97:2)
Block(-2,2,0,97:2)
Block(-2,2,1,97:2)
Block(-2,2,2,97:2)
Block(-2,2,3,4)
Block(-2,2,4,4)
Block(-2,2,5,4)
Block(-2,2,6,4)
Block(-2,2,7,4)
Block(-2,2,8,4)
Block(-2,3,-7,4)
Block(-2,3,-6,4)
Block(-2,3,-5,4)
Block(-2,3,-4,4)
Block(-2,3,-3,97:2)
Block(-2,3,-2,97:2)
Block(-2,3,-1,97:2)
Block(-2,3,0,97:2)
Block(-2,3,1,97:2)
Block(-2,3,2,97:2)
Block(-2,3,3,4)
Block(-2,3,4,4)
Block(-2,3,5,4)
Block(-2,3,6,4)
Block(-2,3,7,4)
Block(-2,3,8,4)
Block(-2,4,-7,4)
Block(-2,4,-6,4)
Block(-2,4,-5,4)
Block(-2,4,-4,4)
Block(-2,4,-3,97:2)
Block(-2,4,-2,97:2)
Block(-2,4,-1,97:2)
Block(-2,4,0,97:2)
Block(-2,4,1,97:2)
Block(-2,4,2,97:2)
Block(-2,4,3,4)
Block(-2,4,4,4)
Block(-2,4,5,4)
Block(-2,4,6,4)
Block(-2,4,7,4)
Block(-2,4,8,4)
Block(-2,5,-7,4)
Block(-2,5,-6,4)
Block(-2,5,-5,4)
Block(-2,5,-4,4)
Block(-2,5,-3,97:2)
Block(-2,5,-2,97:2)
Block(-2,5,-1,97:2)
Block(-2,5,0,97:2)
Block(-2,5,1,97:2)
Block(-2,5,2,97:2)
Block(-2,5,3,4)
Block(-2,5,4,4)
Block(-2,5,5,4)
Block(-2,5,6,4)
Block(-2,5,7,4)
Block(-2,5,8,4)
Block(-2,6,-7,4)
Block(-2,6,-6,4)
Block(-2,6,-5,4)
Block(-2,6,-4,4)
Block(-2,6,-3,97:2)
Block(-2,6,-2,97:2)
Block(-2,6,-1,97:2)
Block(-2,6,0,97:2)
Block(-2,6,1,97:2)
Block(-2,6,2,97:2)
Block(-2,6,3,4)
Block(-2,6,4,4)
Block(-2,6,5,4)
Block(-2,6,6,4)
Block(-2,6,7,4)
Block(-2,6,8,4)
Block(-2,7,-7,4)
Block(-2,7,-6,4)
Block(-2,7,-5,4)
Block(-2,7,-4,4)
Block(-2,7,-3,97:2)
Block(-2,7,-2,97:2)
Block(-2,7,-1,97:2)
Block(-2,7,0,97:2)
Block(-2,7,1,97:2)
Block(-2,7,2,97:2)
Block(-2,7,3,4)
Block(-2,7,4,4)
Block(-2,7,5,4)
Block(-2,7,6,4)
Block(-2,7,7,4)
Block(-2,7,8,4)
Block(-2,8,-7,4)
Block(-2,8,-6,4)
Block(-2,8,-5,4)
Block(-2,8,-4,4)
Block(-2,8,-3,97:2)
Block(-2,8,-2,97:2)
Block(-2,8,-1,97:2)
Block(-2,8,0,97:2)
Block(-2,8,1,97:2)
Block(-2,8,2,97:2)
Block(-2,8,3,4)
Block(-2,8,4,4)
Block(-2,8,5,4)
Block(-2,8,6,4)
Block(-2,8,7,4)
Block(-2,8,8,4)
Block(-2,9,-7,4)
Block(-2,9,-6,4)
Block(-2,9,-5,4)
Block(-2,9,-4,4)
Block(-2,9,-3,97:2)
Block(-2,9,-2,97:2)
Block(-2,9,-1,97:2)
Block(-2,9,0,97:2)
Block(-2,9,1,97:2)
Block(-2,9,2,97:2)
Block(-2,9,3,4)
Block(-2,9,4,4)
Block(-2,9,5,4)
Block(-2,9,6,4)
Block(-2,9,7,4)
Block(-2,9,8,4)
Block(-2,10,-7,4)
Block(-2,10,-6,4)
Block(-2,10,-5,4)
Block(-2,10,-4,4)
Block(-2,10,-3,97:2)
Block(-2,10,-2,97:2)
Block(-2,10,-1,97:2)
Block(-2,10,0,97:2)
Block(-2,10,1,97:2)
Block(-2,10,2,97:2)
Block(-2,10,3,4)
Block(-2,10,4,4)
Block(-2,10,5,4)
Block(-2,10,6,4)
Block(-2,10,7,4)
Block(-2,10,8,4)
Block(-2,11,-7,4)
Block(-2,11,-6,4)
Block(-2,11,-5,4)
Block(-2,11,-4,4)
Block(-2,11,-3,97:2)
Block(-2,11,-2,97:2)
Block(-2,11,-1,97:2)
Block(-2,11,0,97:2)
Block(-2,11,1,97:2)
Block(-2,11,2,97:2)
Block(-2,11,3,4)
Block(-2,11,4,4)
Block(-2,11,5,4)
Block(-2,11,6,4)
Block(-2,11,7,4)
Block(-2,11,8,4)
Block(-2,12,-7,4)
Block(-2,12,-6,4)
Block(-2,12,-5,4)
Block(-2,12,-4,4)
Block(-2,12,-3,97:2)
Block(-2,12,-2,97:2)
Block(-2,12,-1,97:2)
Block(-2,12,0,97:2)
Block(-2,12,1,97:2)
Block(-2,12,2,97:2)
Block(-2,12,3,4)
Block(-2,12,4,4)
Block(-2,12,5,4)
Block(-2,12,6,4)
Block(-2,12,7,4)
Block(-2,12,8,4)
Block(-2,13,-7,4)
Block(-2,13,-6,4)
Block(-2,13,-5,4)
Block(-2,13,-4,4)
Block(-2,13,-3,97:2)
Block(-2,13,-2,97:2)
Block(-2,13,-1,97:2)
Block(-2,13,0,97:2)
Block(-2,13,1,97:2)
Block(-2,13,2,97:2)
Block(-2,13,3,4)
Block(-2,13,4,4)
Block(-2,13,5,4)
Block(-2,13,6,4)
Block(-2,13,7,4)
Block(-2,13,8,4)
Block(-2,14,-7,4)
Block(-2,14,-6,4)
Block(-2,14,-5,4)
Block(-2,14,-4,4)
Block(-2,14,-3,97:2)
Block(-2,14,-2,97:2)
Block(-2,14,-1,97:2)
Block(-2,14,0,97:2)
Block(-2,14,1,97:2)
Block(-2,14,2,97:2)
Block(-2,14,3,4)
Block(-2,14,4,4)
Block(-2,14,5,4)
Block(-2,14,6,4)
Block(-2,14,7,4)
Block(-2,14,8,4)
Block(-2,15,-7,4)
Block(-2,15,-6,4)
Block(-2,15,-5,4)
Block(-2,15,-4,4)
Block(-2,15,-3,97:2)
Block(-2,15,-2,97:2)
Block(-2,15,-1,97:2)
Block(-2,15,0,97:2)
Block(-2,15,1,97:2)
Block(-2,15,2,97:2)
Block(-2,15,3,4)
Block(-2,15,4,4)
Block(-2,15,5,4)
Block(-2,15,6,4)
Block(-2,15,7,4)
Block(-2,15,8,4)
Block(-2,16,-7,4)
Block(-2,16,-6,4)
Block(-2,16,-5,4)
Block(-2,16,-4,4)
Block(-2,16,-3,97:2)
Block(-2,16,-2,97:2)
Block(-2,16,-1,97:2)
Block(-2,16,0,97:2)
Block(-2,16,1,97:2)
Block(-2,16,2,97:2)
Block(-2,16,3,4)
Block(-2,16,4,4)
Block(-2,16,5,4)
Block(-2,16,6,4)
Block(-2,16,7,4)
Block(-2,16,8,4)
Block(-2,17,-7,4)
Block(-2,17,-6,4)
Block(-2,17,-5,4)
Block(-2,17,-4,4)
Block(-2,17,-3,97:2)
Block(-2,17,-2,4)
Block(-2,17,-1,4)
Block(-2,17,0,4)
Block(-2,17,1,4)
Block(-2,17,2,4)
Block(-2,17,3,4)
Block(-2,17,4,4)
Block(-2,17,5,4)
Block(-2,17,6,4)
Block(-2,17,7,4)
Block(-2,17,8,4)
Block(-2,18,-7,AIR)
Block(-2,18,-6,AIR)
Block(-2,18,-5,AIR)
Block(-2,18,-4,5:3)
Block(-2,18,-3,4)
Block(-2,18,-2,AIR)
Block(-2,18,-1,AIR)
Block(-2,18,0,AIR)
Block(-2,18,1,AIR)
Block(-2,18,2,AIR)
Block(-2,18,3,AIR)
Block(-2,18,4,4)
Block(-2,18,5,4)
Block(-2,18,6,4)
Block(-2,18,7,4)
Block(-2,18,8,4)
Block(-2,19,-7,AIR)
Block(-2,19,-6,AIR)
Block(-2,19,-5,AIR)
Block(-2,19,-4,AIR)
Block(-2,19,-3,4)
Block(-2,19,-2,AIR)
Block(-2,19,-1,AIR)
Block(-2,19,0,AIR)
Block(-2,19,1,AIR)
Block(-2,19,2,AIR)
Block(-2,19,3,AIR)
Block(-2,19,4,4)
Block(-2,19,5,4)
Block(-2,19,6,4)
Block(-2,19,7,4)
Block(-2,19,8,4)
Block(-2,20,-7,126:11)
Block(-2,20,-6,126:11)
Block(-2,20,-5,126:11)
Block(-2,20,-4,126:11)
Block(-2,20,-3,4)
Block(-2,20,-2,AIR)
Block(-2,20,-1,AIR)
Block(-2,20,0,AIR)
Block(-2,20,1,AIR)
Block(-2,20,2,AIR)
Block(-2,20,3,AIR)
Block(-2,20,4,4)
Block(-2,20,5,4)
Block(-2,20,6,4)
Block(-2,20,7,4)
Block(-2,20,8,4)
Block(-2,21,-7,67:0)
Block(-2,21,-6,67:0)
Block(-2,21,-5,67:0)
Block(-2,21,-4,67:0)
Block(-2,21,-3,4)
Block(-2,21,-2,AIR)
Block(-2,21,-1,AIR)
Block(-2,21,0,AIR)
Block(-2,21,1,AIR)
Block(-2,21,2,AIR)
Block(-2,21,3,AIR)
Block(-2,21,4,4)
Block(-2,21,5,4)
Block(-2,21,6,4)
Block(-2,21,7,4)
Block(-2,21,8,4)
Block(-2,22,-7,AIR)
Block(-2,22,-6,AIR)
Block(-2,22,-5,AIR)
Block(-2,22,-4,AIR)
Block(-2,22,-3,67:0)
Block(-2,22,-2,AIR)
Block(-2,22,-1,AIR)
Block(-2,22,0,AIR)
Block(-2,22,1,AIR)
Block(-2,22,2,AIR)
Block(-2,22,3,AIR)
Block(-2,22,4,4)
Block(-2,22,5,4)
Block(-2,22,6,4)
Block(-2,22,7,67:3)
Block(-2,23,-7,AIR)
Block(-2,23,-6,AIR)
Block(-2,23,-5,AIR)
Block(-2,23,-4,AIR)
Block(-2,23,-3,AIR)
Block(-2,23,-2,AIR)
Block(-2,23,-1,AIR)
Block(-2,23,0,AIR)
Block(-2,23,1,AIR)
Block(-2,23,2,AIR)
Block(-2,23,3,AIR)
Block(-2,23,4,98:3)
Block(-2,23,5,4)
Block(-2,23,6,4)
Block(-2,24,-7,AIR)
Block(-2,24,-6,AIR)
Block(-2,24,-5,AIR)
Block(-2,24,-4,AIR)
Block(-2,24,-3,AIR)
Block(-2,24,-2,AIR)
Block(-2,24,-1,AIR)
Block(-2,24,0,AIR)
Block(-2,24,1,AIR)
Block(-2,24,2,AIR)
Block(-2,24,3,AIR)
Block(-2,24,4,1:6)
Block(-2,24,5,4)
Block(-2,24,6,4)
Block(-2,25,-7,AIR)
Block(-2,25,-6,AIR)
Block(-2,25,-5,AIR)
Block(-2,25,-4,AIR)
Block(-2,25,-3,AIR)
Block(-2,25,-2,AIR)
Block(-2,25,-1,AIR)
Block(-2,25,0,AIR)
Block(-2,25,1,AIR)
Block(-2,25,2,AIR)
Block(-2,25,3,AIR)
Block(-2,25,4,4)
Block(-2,25,5,4)
Block(-2,25,6,4)
Block(-2,26,-7,97:2)
Block(-2,26,-6,97:2)
Block(-2,26,-5,97:2)
Block(-2,26,-4,97:2)
Block(-2,26,-3,97:2)
Block(-2,26,-2,97:2)
Block(-2,26,-1,97:2)
Block(-2,26,0,97:2)
Block(-2,26,1,97:2)
Block(-2,26,2,97:2)
Block(-2,26,3,97:2)
Block(-2,26,4,4)
Block(-2,26,5,4)
Block(-2,26,6,4)
Block(-2,26,7,67:7)
Block(-2,27,-7,4)
Block(-2,27,-6,4)
Block(-2,27,-5,4)
Block(-2,27,-4,4)
Block(-2,27,-3,4)
Block(-2,27,-2,4)
Block(-2,27,-1,4)
Block(-2,27,0,4)
Block(-2,27,1,4)
Block(-2,27,2,4)
Block(-2,27,3,4)
Block(-2,27,4,4)
Block(-2,27,5,4)
Block(-2,27,6,4)
Block(-2,27,7,4)
Block(-2,27,8,139)
Block(-2,28,-7,4)
Block(-2,28,-6,44:3)
Block(-2,28,-5,4)
Block(-2,28,-4,4)
Block(-2,28,-3,4)
Block(-2,28,-2,3:1)
Block(-2,28,-1,4)
Block(-2,28,0,3:1)
Block(-2,28,1,4)
Block(-2,28,2,4)
Block(-2,28,3,4)
Block(-2,28,4,4)
Block(-2,28,5,4)
Block(-2,28,6,4)
Block(-2,28,7,18:7)
Block(-2,29,-7,4)
Block(-2,29,-6,AIR)
Block(-2,29,-5,106:7)
Block(-2,29,-4,3)
Block(-2,29,-3,3)
Block(-2,29,-2,AIR)
Block(-2,29,-1,39)
Block(-2,29,0,39)
Block(-2,29,1,3:1)
Block(-2,29,2,3:1)
Block(-2,29,3,97:2)
Block(-2,29,4,4)
Block(-2,29,5,4)
Block(-2,29,6,67:3)
Block(-2,29,7,18:7)
Block(-2,30,-7,4)
Block(-2,30,-6,AIR)
Block(-2,30,-5,106:4)
Block(-2,30,-4,AIR)
Block(-2,30,-3,AIR)
Block(-2,30,-2,AIR)
Block(-2,30,-1,AIR)
Block(-2,30,0,AIR)
Block(-2,30,1,AIR)
Block(-2,30,2,AIR)
Block(-2,30,3,97:2)
Block(-2,30,4,4)
Block(-2,30,5,4)
Block(-2,30,6,18:7)
Block(-2,31,-7,4)
Block(-2,31,-6,AIR)
Block(-2,31,-5,106:4)
Block(-2,31,-4,AIR)
Block(-2,31,-3,AIR)
Block(-2,31,-2,AIR)
Block(-2,31,-1,AIR)
Block(-2,31,0,AIR)
Block(-2,31,1,AIR)
Block(-2,31,2,AIR)
Block(-2,31,3,97:2)
Block(-2,31,4,4)
Block(-2,31,5,4)
Block(-2,31,6,18:7)
Block(-2,32,-7,4)
Block(-2,32,-6,67:5)
Block(-2,32,-5,106:4)
Block(-2,32,-4,AIR)
Block(-2,32,-3,AIR)
Block(-2,32,-2,AIR)
Block(-2,32,-1,AIR)
Block(-2,32,0,AIR)
Block(-2,32,1,AIR)
Block(-2,32,2,AIR)
Block(-2,32,3,97:2)
Block(-2,32,4,4)
Block(-2,32,5,4)
Block(-2,32,6,18:7)
Block(-2,33,-7,4)
Block(-2,33,-6,4)
Block(-2,33,-5,106:4)
Block(-2,33,-4,AIR)
Block(-2,33,-3,AIR)
Block(-2,33,-2,AIR)
Block(-2,33,-1,AIR)
Block(-2,33,0,AIR)
Block(-2,33,1,AIR)
Block(-2,33,2,30)
Block(-2,33,3,97:2)
Block(-2,33,4,4)
Block(-2,33,5,4)
Block(-2,33,6,67:7)
Block(-2,34,-7,4)
Block(-2,34,-6,4)
Block(-2,34,-5,4)
Block(-2,34,-4,4)
Block(-2,34,-3,4)
Block(-2,34,-2,126:11)
Block(-2,34,-1,4)
Block(-2,34,0,4)
Block(-2,34,1,4)
Block(-2,34,2,4)
Block(-2,34,3,4)
Block(-2,34,4,4)
Block(-2,34,5,4)
Block(-2,34,6,4)
Block(-2,34,7,139)
Block(-2,35,-7,4)
Block(-2,35,-6,4)
Block(-2,35,-5,3:1)
Block(-2,35,-4,3:1)
Block(-2,35,-3,3)
Block(-2,35,-2,3)
Block(-2,35,-1,4)
Block(-2,35,0,13)
Block(-2,35,1,3)
Block(-2,35,2,4)
Block(-2,35,3,4)
Block(-2,35,4,4)
Block(-2,35,5,4)
Block(-2,35,6,4)
Block(-2,35,7,18:7)
Block(-2,36,-7,4)
Block(-2,36,-6,4)
Block(-2,36,-5,3:1)
Block(-2,36,-4,AIR)
Block(-2,36,-3,AIR)
Block(-2,36,-2,AIR)
Block(-2,36,-1,AIR)
Block(-2,36,0,AIR)
Block(-2,36,1,AIR)
Block(-2,36,2,13)
Block(-2,36,3,97:2)
Block(-2,36,4,4)
Block(-2,36,5,4)
Block(-2,36,6,67:3)
Block(-2,36,7,106:4)
Block(-2,37,-7,4)
Block(-2,37,-6,4)
Block(-2,37,-5,AIR)
Block(-2,37,-4,AIR)
Block(-2,37,-3,AIR)
Block(-2,37,-2,AIR)
Block(-2,37,-1,AIR)
Block(-2,37,0,AIR)
Block(-2,37,1,AIR)
Block(-2,37,2,AIR)
Block(-2,37,3,97:2)
Block(-2,37,4,4)
Block(-2,37,5,4)
Block(-2,37,7,106:4)
Block(-2,38,-7,4)
Block(-2,38,-6,4)
Block(-2,38,-5,AIR)
Block(-2,38,-4,AIR)
Block(-2,38,-3,AIR)
Block(-2,38,-2,AIR)
Block(-2,38,-1,AIR)
Block(-2,38,0,AIR)
Block(-2,38,1,AIR)
Block(-2,38,2,AIR)
Block(-2,38,3,97:2)
Block(-2,38,4,4)
Block(-2,38,5,4)
Block(-2,38,7,106:4)
Block(-2,39,-7,4)
Block(-2,39,-6,4)
Block(-2,39,-5,AIR)
Block(-2,39,-4,AIR)
Block(-2,39,-3,AIR)
Block(-2,39,-2,AIR)
Block(-2,39,-1,AIR)
Block(-2,39,0,AIR)
Block(-2,39,1,AIR)
Block(-2,39,2,AIR)
Block(-2,39,3,97:2)
Block(-2,39,4,4)
Block(-2,39,5,4)
Block(-2,39,6,18:7)
Block(-2,39,7,106:4)
Block(-2,40,-7,4)
Block(-2,40,-6,67:5)
Block(-2,40,-5,AIR)
Block(-2,40,-4,AIR)
Block(-2,40,-3,AIR)
Block(-2,40,-2,AIR)
Block(-2,40,-1,AIR)
Block(-2,40,0,AIR)
Block(-2,40,1,AIR)
Block(-2,40,2,AIR)
Block(-2,40,3,97:2)
Block(-2,40,4,4)
Block(-2,40,5,4)
Block(-2,40,6,67:7)
Block(-2,41,-7,4)
Block(-2,41,-6,4)
Block(-2,41,-5,4)
Block(-2,41,-4,4)
Block(-2,41,-3,4)
Block(-2,41,-2,126:11)
Block(-2,41,-1,4)
Block(-2,41,0,4)
Block(-2,41,1,4)
Block(-2,41,2,4)
Block(-2,41,3,4)
Block(-2,41,4,4)
Block(-2,41,5,4)
Block(-2,41,6,4)
Block(-2,41,7,139)
Block(-2,42,-7,4)
Block(-2,42,-6,97:2)
Block(-2,42,-5,97:2)
Block(-2,42,-4,97:2)
Block(-2,42,-3,97:2)
Block(-2,42,-2,97:2)
Block(-2,42,-1,97:2)
Block(-2,42,0,97:2)
Block(-2,42,1,97:2)
Block(-2,42,2,97:2)
Block(-2,42,3,97:2)
Block(-2,42,4,4)
Block(-2,42,5,4)
Block(-2,42,6,4)
Block(-2,42,7,18:7)
Block(-2,43,-7,4)
Block(-2,43,-6,AIR)
Block(-2,43,-5,13)
Block(-2,43,-4,AIR)
Block(-2,43,-3,AIR)
Block(-2,43,-2,AIR)
Block(-2,43,-1,AIR)
Block(-2,43,0,AIR)
Block(-2,43,1,43:5)
Block(-2,43,2,43:5)
Block(-2,43,3,97:2)
Block(-2,43,4,4)
Block(-2,43,5,4)
Block(-2,43,6,67:3)
Block(-2,44,-7,4)
Block(-2,44,-6,AIR)
Block(-2,44,-5,AIR)
Block(-2,44,-4,AIR)
Block(-2,44,-3,AIR)
Block(-2,44,-2,AIR)
Block(-2,44,-1,AIR)
Block(-2,44,0,AIR)
Block(-2,44,1,AIR)
Block(-2,44,2,126:11)
Block(-2,44,3,97:2)
Block(-2,44,4,4)
Block(-2,44,5,4)
Block(-2,45,-7,4)
Block(-2,45,-6,AIR)
Block(-2,45,-5,AIR)
Block(-2,45,-4,AIR)
Block(-2,45,-3,AIR)
Block(-2,45,-2,AIR)
Block(-2,45,-1,AIR)
Block(-2,45,0,AIR)
Block(-2,45,1,AIR)
RandomBlock(-2,45,2,CHEST,../../nbt/VanillaLoot/jungle_temple.nbt,50,CHEST,../../nbt/VanillaLoot/jungle_temple.nbt,100)
Block(-2,45,3,97:2)
Block(-2,45,4,4)
Block(-2,45,5,4)
Block(-2,46,-7,4)
Block(-2,46,-6,AIR)
Block(-2,46,-5,AIR)
Block(-2,46,-4,AIR)
Block(-2,46,-3,AIR)
Block(-2,46,-2,AIR)
Block(-2,46,-1,AIR)
Block(-2,46,0,AIR)
Block(-2,46,1,AIR)
Block(-2,46,2,AIR)
Block(-2,46,3,97:2)
Block(-2,46,4,4)
Block(-2,46,5,4)
Block(-2,47,-7,4)
Block(-2,47,-6,AIR)
Block(-2,47,-5,AIR)
Block(-2,47,-4,AIR)
Block(-2,47,-3,AIR)
Block(-2,47,-2,44:11)
Block(-2,47,-1,AIR)
Block(-2,47,0,AIR)
Block(-2,47,1,AIR)
Block(-2,47,2,AIR)
Block(-2,47,3,97:2)
Block(-2,47,4,4)
Block(-2,47,5,4)
Block(-2,47,6,67:7)
Block(-2,48,-7,4)
Block(-2,48,-6,4)
Block(-2,48,-5,4)
Block(-2,48,-4,4)
Block(-2,48,-3,4)
Block(-2,48,-2,4)
Block(-2,48,-1,4)
Block(-2,48,0,4)
Block(-2,48,1,4)
Block(-2,48,2,4)
Block(-2,48,3,4)
Block(-2,48,4,4)
Block(-2,48,5,4)
Block(-2,48,6,4)
Block(-2,48,7,139)
Block(-2,49,-7,4)
Block(-2,49,-6,4)
Block(-2,49,-5,4)
Block(-2,49,-4,4)
Block(-2,49,-3,4)
Block(-2,49,-2,4)
Block(-2,49,-1,4)
Block(-2,49,0,4)
Block(-2,49,1,4)
Block(-2,49,2,2)
Block(-2,49,3,4)
Block(-2,49,4,3:1)
Block(-2,49,5,3:1)
Block(-2,49,6,4)
Block(-2,49,7,18:7)
Block(-2,50,-7,44:3)
Block(-2,50,-6,4)
Block(-2,50,2,18:7)
Block(-2,50,3,18:7)
Block(-2,50,4,18:7)
Block(-2,50,6,4)
Block(-2,50,7,18:15)
Block(-2,51,3,18:7)
Block(-1,0,-7,4)
Block(-1,0,-6,4)
Block(-1,0,-5,4)
Block(-1,0,-4,4)
Block(-1,0,-3,4)
Block(-1,0,-2,4)
Block(-1,0,-1,4)
Block(-1,0,0,4)
Block(-1,0,1,97:2)
Block(-1,0,2,97:2)
Block(-1,0,3,4)
Block(-1,0,4,4)
Block(-1,0,5,4)
Block(-1,0,6,4)
Block(-1,0,7,4)
Block(-1,0,8,4)
Block(-1,1,-7,4)
Block(-1,1,-6,4)
Block(-1,1,-5,4)
Block(-1,1,-4,4)
Block(-1,1,-3,4)
Block(-1,1,-2,4)
Block(-1,1,-1,4)
Block(-1,1,0,4)
Block(-1,1,1,97:2)
Block(-1,1,2,97:2)
Block(-1,1,3,4)
Block(-1,1,4,4)
Block(-1,1,5,4)
Block(-1,1,6,4)
Block(-1,1,7,4)
Block(-1,1,8,4)
Block(-1,2,-7,4)
Block(-1,2,-6,4)
Block(-1,2,-5,4)
Block(-1,2,-4,4)
Block(-1,2,-3,4)
Block(-1,2,-2,4)
Block(-1,2,-1,4)
Block(-1,2,0,4)
Block(-1,2,1,97:2)
Block(-1,2,2,97:2)
Block(-1,2,3,4)
Block(-1,2,4,4)
Block(-1,2,5,4)
Block(-1,2,6,4)
Block(-1,2,7,4)
Block(-1,2,8,4)
Block(-1,3,-7,4)
Block(-1,3,-6,4)
Block(-1,3,-5,4)
Block(-1,3,-4,4)
Block(-1,3,-3,4)
Block(-1,3,-2,4)
Block(-1,3,-1,4)
Block(-1,3,0,4)
Block(-1,3,1,97:2)
Block(-1,3,2,97:2)
Block(-1,3,3,4)
Block(-1,3,4,4)
Block(-1,3,5,4)
Block(-1,3,6,4)
Block(-1,3,7,4)
Block(-1,3,8,4)
Block(-1,4,-7,4)
Block(-1,4,-6,4)
Block(-1,4,-5,4)
Block(-1,4,-4,4)
Block(-1,4,-3,4)
Block(-1,4,-2,4)
Block(-1,4,-1,4)
Block(-1,4,0,4)
Block(-1,4,1,97:2)
Block(-1,4,2,97:2)
Block(-1,4,3,4)
Block(-1,4,4,4)
Block(-1,4,5,4)
Block(-1,4,6,4)
Block(-1,4,7,4)
Block(-1,4,8,4)
Block(-1,5,-7,4)
Block(-1,5,-6,4)
Block(-1,5,-5,4)
Block(-1,5,-4,4)
Block(-1,5,-3,4)
Block(-1,5,-2,4)
Block(-1,5,-1,4)
Block(-1,5,0,4)
Block(-1,5,1,97:2)
Block(-1,5,2,97:2)
Block(-1,5,3,4)
Block(-1,5,4,4)
Block(-1,5,5,4)
Block(-1,5,6,4)
Block(-1,5,7,4)
Block(-1,5,8,4)
Block(-1,6,-7,4)
Block(-1,6,-6,4)
Block(-1,6,-5,4)
Block(-1,6,-4,4)
Block(-1,6,-3,4)
Block(-1,6,-2,4)
Block(-1,6,-1,4)
Block(-1,6,0,4)
Block(-1,6,1,97:2)
Block(-1,6,2,97:2)
Block(-1,6,3,4)
Block(-1,6,4,4)
Block(-1,6,5,4)
Block(-1,6,6,4)
Block(-1,6,7,4)
Block(-1,6,8,4)
Block(-1,7,-7,4)
Block(-1,7,-6,4)
Block(-1,7,-5,4)
Block(-1,7,-4,4)
Block(-1,7,-3,4)
Block(-1,7,-2,4)
Block(-1,7,-1,4)
Block(-1,7,0,4)
Block(-1,7,1,97:2)
Block(-1,7,2,97:2)
Block(-1,7,3,4)
Block(-1,7,4,4)
Block(-1,7,5,4)
Block(-1,7,6,4)
Block(-1,7,7,4)
Block(-1,7,8,4)
Block(-1,8,-7,4)
Block(-1,8,-6,4)
Block(-1,8,-5,4)
Block(-1,8,-4,4)
Block(-1,8,-3,4)
Block(-1,8,-2,4)
Block(-1,8,-1,4)
Block(-1,8,0,4)
Block(-1,8,1,97:2)
Block(-1,8,2,97:2)
Block(-1,8,3,4)
Block(-1,8,4,4)
Block(-1,8,5,4)
Block(-1,8,6,4)
Block(-1,8,7,4)
Block(-1,8,8,4)
Block(-1,9,-7,4)
Block(-1,9,-6,4)
Block(-1,9,-5,4)
Block(-1,9,-4,4)
Block(-1,9,-3,4)
Block(-1,9,-2,4)
Block(-1,9,-1,4)
Block(-1,9,0,4)
Block(-1,9,1,97:2)
Block(-1,9,2,97:2)
Block(-1,9,3,4)
Block(-1,9,4,4)
Block(-1,9,5,4)
Block(-1,9,6,4)
Block(-1,9,7,4)
Block(-1,9,8,4)
Block(-1,10,-7,4)
Block(-1,10,-6,4)
Block(-1,10,-5,4)
Block(-1,10,-4,4)
Block(-1,10,-3,4)
Block(-1,10,-2,4)
Block(-1,10,-1,4)
Block(-1,10,0,4)
Block(-1,10,1,97:2)
Block(-1,10,2,97:2)
Block(-1,10,3,4)
Block(-1,10,4,4)
Block(-1,10,5,4)
Block(-1,10,6,4)
Block(-1,10,7,4)
Block(-1,10,8,4)
Block(-1,11,-7,4)
Block(-1,11,-6,4)
Block(-1,11,-5,4)
Block(-1,11,-4,4)
Block(-1,11,-3,4)
Block(-1,11,-2,4)
Block(-1,11,-1,4)
Block(-1,11,0,4)
Block(-1,11,1,97:2)
Block(-1,11,2,97:2)
Block(-1,11,3,4)
Block(-1,11,4,4)
Block(-1,11,5,4)
Block(-1,11,6,4)
Block(-1,11,7,4)
Block(-1,11,8,4)
Block(-1,12,-7,4)
Block(-1,12,-6,4)
Block(-1,12,-5,4)
Block(-1,12,-4,4)
Block(-1,12,-3,4)
Block(-1,12,-2,4)
Block(-1,12,-1,4)
Block(-1,12,0,4)
Block(-1,12,1,97:2)
Block(-1,12,2,97:2)
Block(-1,12,3,4)
Block(-1,12,4,4)
Block(-1,12,5,4)
Block(-1,12,6,4)
Block(-1,12,7,4)
Block(-1,12,8,4)
Block(-1,13,-7,4)
Block(-1,13,-6,4)
Block(-1,13,-5,4)
Block(-1,13,-4,4)
Block(-1,13,-3,4)
Block(-1,13,-2,4)
Block(-1,13,-1,4)
Block(-1,13,0,4)
Block(-1,13,1,97:2)
Block(-1,13,2,97:2)
Block(-1,13,3,4)
Block(-1,13,4,4)
Block(-1,13,5,4)
Block(-1,13,6,4)
Block(-1,13,7,4)
Block(-1,13,8,4)
Block(-1,14,-7,4)
Block(-1,14,-6,4)
Block(-1,14,-5,4)
Block(-1,14,-4,4)
Block(-1,14,-3,4)
Block(-1,14,-2,4)
Block(-1,14,-1,4)
Block(-1,14,0,4)
Block(-1,14,1,97:2)
Block(-1,14,2,97:2)
Block(-1,14,3,4)
Block(-1,14,4,4)
Block(-1,14,5,4)
Block(-1,14,6,4)
Block(-1,14,7,4)
Block(-1,14,8,4)
Block(-1,15,-7,4)
Block(-1,15,-6,4)
Block(-1,15,-5,4)
Block(-1,15,-4,4)
Block(-1,15,-3,4)
Block(-1,15,-2,4)
Block(-1,15,-1,4)
Block(-1,15,0,4)
Block(-1,15,1,97:2)
Block(-1,15,2,97:2)
Block(-1,15,3,4)
Block(-1,15,4,4)
Block(-1,15,5,4)
Block(-1,15,6,4)
Block(-1,15,7,4)
Block(-1,15,8,4)
Block(-1,16,-7,4)
Block(-1,16,-6,4)
Block(-1,16,-5,4)
Block(-1,16,-4,4)
Block(-1,16,-3,4)
Block(-1,16,-2,4)
Block(-1,16,-1,4)
Block(-1,16,0,4)
Block(-1,16,1,97:2)
Block(-1,16,2,97:2)
Block(-1,16,3,4)
Block(-1,16,4,4)
Block(-1,16,5,4)
Block(-1,16,6,4)
Block(-1,16,7,4)
Block(-1,16,8,4)
Block(-1,17,-7,4)
Block(-1,17,-6,4)
Block(-1,17,-5,4)
Block(-1,17,-4,4)
Block(-1,17,-3,4)
Block(-1,17,-2,4)
Block(-1,17,-1,4)
Block(-1,17,0,4)
Block(-1,17,1,4)
Block(-1,17,2,4)
Block(-1,17,3,4)
Block(-1,17,4,4)
Block(-1,17,5,4)
Block(-1,17,6,4)
Block(-1,17,7,4)
Block(-1,17,8,4)
Block(-1,18,-7,AIR)
Block(-1,18,-6,AIR)
Block(-1,18,-5,AIR)
Block(-1,18,-4,AIR)
Block(-1,18,-3,4)
Block(-1,18,-2,AIR)
Block(-1,18,-1,AIR)
Block(-1,18,0,AIR)
Block(-1,18,1,AIR)
Block(-1,18,2,AIR)
Block(-1,18,3,AIR)
Block(-1,18,4,4)
Block(-1,18,5,4)
Block(-1,18,6,4)
Block(-1,18,7,4)
Block(-1,18,8,4)
Block(-1,19,-7,AIR)
Block(-1,19,-6,AIR)
Block(-1,19,-5,AIR)
Block(-1,19,-4,AIR)
Block(-1,19,-3,4)
Block(-1,19,-2,AIR)
Block(-1,19,-1,AIR)
Block(-1,19,0,AIR)
Block(-1,19,1,AIR)
Block(-1,19,2,AIR)
Block(-1,19,3,AIR)
Block(-1,19,4,4)
Block(-1,19,5,4)
Block(-1,19,6,4)
Block(-1,19,7,4)
Block(-1,20,-7,AIR)
Block(-1,20,-6,AIR)
Block(-1,20,-5,AIR)
Block(-1,20,-4,AIR)
Block(-1,20,-3,4)
Block(-1,20,-2,AIR)
Block(-1,20,-1,AIR)
Block(-1,20,0,AIR)
Block(-1,20,1,AIR)
Block(-1,20,2,AIR)
Block(-1,20,3,AIR)
Block(-1,20,4,4)
Block(-1,20,5,4)
Block(-1,20,6,4)
Block(-1,20,7,4)
Block(-1,21,-7,67:5)
Block(-1,21,-6,67:5)
Block(-1,21,-5,67:5)
Block(-1,21,-4,67:5)
Block(-1,21,-3,4)
Block(-1,21,-2,AIR)
Block(-1,21,-1,AIR)
Block(-1,21,0,AIR)
Block(-1,21,1,AIR)
Block(-1,21,2,AIR)
Block(-1,21,3,AIR)
Block(-1,21,4,4)
Block(-1,21,5,4)
Block(-1,21,6,4)
Block(-1,21,7,4)
Block(-1,21,8,67:5)
Block(-1,22,-7,67:0)
Block(-1,22,-6,67:0)
Block(-1,22,-5,67:0)
Block(-1,22,-4,67:0)
Block(-1,22,-3,4)
Block(-1,22,-2,AIR)
Block(-1,22,-1,AIR)
Block(-1,22,0,AIR)
Block(-1,22,1,AIR)
Block(-1,22,2,AIR)
Block(-1,22,3,AIR)
Block(-1,22,4,4)
Block(-1,22,5,4)
Block(-1,22,6,67:1)
Block(-1,22,7,18:15)
Block(-1,23,-7,AIR)
Block(-1,23,-6,AIR)
Block(-1,23,-5,AIR)
Block(-1,23,-4,AIR)
Block(-1,23,-3,67:0)
Block(-1,23,-2,AIR)
Block(-1,23,-1,AIR)
Block(-1,23,0,AIR)
Block(-1,23,1,AIR)
Block(-1,23,2,AIR)
Block(-1,23,3,AIR)
Block(-1,23,4,1:6)
Block(-1,23,5,4)
Block(-1,24,-7,AIR)
Block(-1,24,-6,AIR)
Block(-1,24,-5,AIR)
Block(-1,24,-4,AIR)
Block(-1,24,-3,AIR)
Block(-1,24,-2,AIR)
Block(-1,24,-1,AIR)
Block(-1,24,0,AIR)
Block(-1,24,1,AIR)
Block(-1,24,2,AIR)
Block(-1,24,3,AIR)
Block(-1,24,4,98:3)
Block(-1,24,5,4)
Block(-1,25,-7,AIR)
Block(-1,25,-6,AIR)
Block(-1,25,-5,AIR)
Block(-1,25,-4,AIR)
Block(-1,25,-3,AIR)
Block(-1,25,-2,AIR)
Block(-1,25,-1,AIR)
Block(-1,25,0,AIR)
Block(-1,25,1,AIR)
Block(-1,25,2,AIR)
Block(-1,25,3,AIR)
Block(-1,25,4,4)
Block(-1,25,5,4)
Block(-1,26,-7,AIR)
Block(-1,26,-6,AIR)
Block(-1,26,-5,AIR)
Block(-1,26,-4,AIR)
Block(-1,26,-3,AIR)
Block(-1,26,-2,97:2)
Block(-1,26,-1,AIR)
Block(-1,26,0,AIR)
Block(-1,26,1,AIR)
Block(-1,26,2,AIR)
Block(-1,26,3,97:2)
Block(-1,26,4,4)
Block(-1,26,5,4)
Block(-1,26,6,67:5)
Block(-1,26,7,18:7)
Block(-1,27,-7,4)
Block(-1,27,-6,4)
Block(-1,27,-5,4)
Block(-1,27,-4,4)
Block(-1,27,-3,4)
Block(-1,27,-2,4)
Block(-1,27,-1,4)
Block(-1,27,0,4)
Block(-1,27,1,4)
Block(-1,27,2,4)
Block(-1,27,3,4)
Block(-1,27,4,4)
Block(-1,27,5,4)
Block(-1,27,6,4)
Block(-1,27,7,18:7)
Block(-1,27,8,18:7)
Block(-1,28,-7,44:3)
Block(-1,28,-6,44:3)
Block(-1,28,-5,4)
Block(-1,28,-4,3:1)
Block(-1,28,-3,4)
Block(-1,28,-2,4)
Block(-1,28,-1,4)
Block(-1,28,0,3:1)
Block(-1,28,1,4)
Block(-1,28,2,4)
Block(-1,28,3,4)
Block(-1,28,4,4)
Block(-1,28,5,98)
Block(-1,28,6,4)
Block(-1,28,7,18:7)
Block(-1,29,-7,AIR)
Block(-1,29,-6,AIR)
Block(-1,29,-5,106:4)
Block(-1,29,-4,AIR)
Block(-1,29,-3,AIR)
Block(-1,29,-2,39)
Block(-1,29,-1,AIR)
Block(-1,29,0,AIR)
Block(-1,29,1,3:1)
Block(-1,29,2,3:1)
Block(-1,29,3,97:2)
Block(-1,29,4,4)
Block(-1,29,5,67:1)
Block(-1,29,6,18:7)
Block(-1,29,7,106:4)
Block(-1,30,-7,AIR)
Block(-1,30,-6,AIR)
Block(-1,30,-5,106:4)
Block(-1,30,-4,AIR)
Block(-1,30,-3,AIR)
Block(-1,30,-2,AIR)
Block(-1,30,-1,AIR)
Block(-1,30,0,AIR)
Block(-1,30,1,AIR)
Block(-1,30,2,AIR)
Block(-1,30,3,4)
Block(-1,30,4,4)
Block(-1,30,5,18:7)
Block(-1,30,6,18:7)
Block(-1,30,7,106:4)
Block(-1,31,-7,AIR)
Block(-1,31,-6,AIR)
Block(-1,31,-5,106:4)
Block(-1,31,-4,AIR)
Block(-1,31,-3,AIR)
Block(-1,31,-2,AIR)
Block(-1,31,-1,AIR)
Block(-1,31,0,AIR)
Block(-1,31,1,AIR)
Block(-1,31,2,AIR)
Block(-1,31,3,97:2)
Block(-1,31,4,4)
Block(-1,31,5,18:7)
Block(-1,31,7,106:4)
Block(-1,32,-7,AIR)
Block(-1,32,-6,AIR)
Block(-1,32,-5,106:4)
Block(-1,32,-4,AIR)
Block(-1,32,-3,AIR)
Block(-1,32,-2,AIR)
Block(-1,32,-1,AIR)
Block(-1,32,0,AIR)
Block(-1,32,1,AIR)
Block(-1,32,2,AIR)
Block(-1,32,3,4)
Block(-1,32,4,4)
Block(-1,32,5,18:7)
Block(-1,32,7,106:4)
Block(-1,33,-7,AIR)
Block(-1,33,-6,4)
Block(-1,33,-5,106:4)
Block(-1,33,-4,AIR)
Block(-1,33,-3,AIR)
Block(-1,33,-2,AIR)
Block(-1,33,-1,AIR)
Block(-1,33,0,AIR)
Block(-1,33,1,AIR)
Block(-1,33,2,AIR)
Block(-1,33,3,97:2)
Block(-1,33,4,4)
Block(-1,33,5,67:5)
Block(-1,33,6,18:7)
Block(-1,33,7,106:4)
Block(-1,34,-7,4)
Block(-1,34,-6,4)
Block(-1,34,-5,4)
Block(-1,34,-4,4)
Block(-1,34,-3,4)
Block(-1,34,-2,126:11)
Block(-1,34,-1,4)
Block(-1,34,0,4)
Block(-1,34,1,4)
Block(-1,34,2,4)
Block(-1,34,3,4)
Block(-1,34,4,4)
Block(-1,34,5,4)
Block(-1,34,6,18:7)
Block(-1,34,7,106:4)
Block(-1,35,-7,4)
Block(-1,35,-6,43:3)
Block(-1,35,-5,4)
Block(-1,35,-4,2)
Block(-1,35,-3,2)
Block(-1,35,-2,13)
Block(-1,35,-1,4)
Block(-1,35,0,2)
Block(-1,35,1,3:1)
Block(-1,35,2,4)
Block(-1,35,3,4)
Block(-1,35,4,4)
Block(-1,35,5,98)
Block(-1,35,6,4)
Block(-1,35,7,106:4)
Block(-1,36,-7,4)
Block(-1,36,-6,13)
Block(-1,36,-5,13)
Block(-1,36,-4,31:2)
Block(-1,36,-3,31:1)
Block(-1,36,-2,AIR)
Block(-1,36,-1,AIR)
Block(-1,36,0,31:2)
Block(-1,36,1,AIR)
Block(-1,36,2,AIR)
Block(-1,36,3,4)
Block(-1,36,4,4)
Block(-1,36,5,67:1)
Block(-1,36,7,106:4)
Block(-1,37,-7,4)
Block(-1,37,-6,13)
Block(-1,37,-5,AIR)
Block(-1,37,-4,AIR)
Block(-1,37,-3,AIR)
Block(-1,37,-2,AIR)
Block(-1,37,-1,AIR)
Block(-1,37,0,AIR)
Block(-1,37,1,AIR)
Block(-1,37,2,AIR)
Block(-1,37,3,4)
Block(-1,37,4,4)
Block(-1,37,5,AIR)
Block(-1,37,7,106:4)
Block(-1,38,-7,4)
Block(-1,38,-6,AIR)
Block(-1,38,-5,AIR)
Block(-1,38,-4,AIR)
Block(-1,38,-3,AIR)
Block(-1,38,-2,AIR)
Block(-1,38,-1,AIR)
Block(-1,38,0,AIR)
Block(-1,38,1,AIR)
Block(-1,38,2,AIR)
Block(-1,38,3,4)
Block(-1,38,4,4)
Block(-1,38,5,AIR)
Block(-1,38,7,106:4)
Block(-1,39,-7,4)
Block(-1,39,-6,AIR)
Block(-1,39,-5,AIR)
Block(-1,39,-4,AIR)
Block(-1,39,-3,AIR)
Block(-1,39,-2,AIR)
Block(-1,39,-1,AIR)
Block(-1,39,0,AIR)
Block(-1,39,1,AIR)
Block(-1,39,2,AIR)
Block(-1,39,3,4)
Block(-1,39,4,4)
Block(-1,39,5,AIR)
Block(-1,39,7,106:4)
Block(-1,40,-7,4)
Block(-1,40,-6,AIR)
Block(-1,40,-5,AIR)
Block(-1,40,-4,AIR)
Block(-1,40,-3,AIR)
Block(-1,40,-2,AIR)
Block(-1,40,-1,AIR)
Block(-1,40,0,AIR)
Block(-1,40,1,AIR)
Block(-1,40,2,AIR)
Block(-1,40,3,4)
Block(-1,40,4,4)
Block(-1,40,5,67:5)
Block(-1,40,7,106:4)
Block(-1,41,-7,4)
Block(-1,41,-6,4)
Block(-1,41,-5,4)
Block(-1,41,-4,4)
Block(-1,41,-3,4)
Block(-1,41,-2,126:11)
Block(-1,41,-1,4)
Block(-1,41,0,4)
Block(-1,41,1,4)
Block(-1,41,2,4)
Block(-1,41,3,4)
Block(-1,41,4,4)
Block(-1,41,5,4)
Block(-1,41,7,106:4)
Block(-1,42,-7,17:3)
Block(-1,42,-6,97:2)
Block(-1,42,-5,4)
Block(-1,42,-4,4)
Block(-1,42,-3,4)
Block(-1,42,-2,4)
Block(-1,42,-1,4)
Block(-1,42,0,4)
Block(-1,42,1,1:6)
Block(-1,42,2,97:2)
Block(-1,42,3,4)
Block(-1,42,4,4)
Block(-1,42,5,98)
Block(-1,42,6,4)
Block(-1,42,7,106:4)
Block(-1,43,-7,AIR)
Block(-1,43,-6,AIR)
Block(-1,43,-5,AIR)
Block(-1,43,-4,AIR)
Block(-1,43,-3,39)
Block(-1,43,-2,39)
Block(-1,43,-1,AIR)
Block(-1,43,0,AIR)
Block(-1,43,1,AIR)
Block(-1,43,2,43:5)
Block(-1,43,3,4)
Block(-1,43,4,4)
Block(-1,43,5,67:1)
Block(-1,43,7,106:4)
Block(-1,44,-7,AIR)
Block(-1,44,-6,AIR)
Block(-1,44,-5,AIR)
Block(-1,44,-4,AIR)
Block(-1,44,-3,AIR)
Block(-1,44,-2,AIR)
Block(-1,44,-1,AIR)
Block(-1,44,0,AIR)
Block(-1,44,1,AIR)
Block(-1,44,2,AIR)
Block(-1,44,3,4)
Block(-1,44,4,4)
Block(-1,44,5,AIR)
Block(-1,44,7,106:4)
Block(-1,45,-7,AIR)
Block(-1,45,-6,AIR)
Block(-1,45,-5,AIR)
Block(-1,45,-4,AIR)
Block(-1,45,-3,AIR)
Block(-1,45,-2,AIR)
Block(-1,45,-1,AIR)
Block(-1,45,0,AIR)
Block(-1,45,1,AIR)
Block(-1,45,2,AIR)
Block(-1,45,3,4)
Block(-1,45,4,4)
Block(-1,45,5,AIR)
Block(-1,45,7,106:4)
Block(-1,46,-7,67:5)
Block(-1,46,-6,AIR)
Block(-1,46,-5,AIR)
Block(-1,46,-4,AIR)
Block(-1,46,-3,AIR)
Block(-1,46,-2,AIR)
Block(-1,46,-1,AIR)
Block(-1,46,0,AIR)
Block(-1,46,1,AIR)
Block(-1,46,2,AIR)
Block(-1,46,3,4)
Block(-1,46,4,4)
Block(-1,46,5,AIR)
Block(-1,46,7,106:4)
Block(-1,47,-7,4)
Block(-1,47,-6,AIR)
Block(-1,47,-5,AIR)
Block(-1,47,-4,AIR)
Block(-1,47,-3,AIR)
Block(-1,47,-2,44:11)
Block(-1,47,-1,AIR)
Block(-1,47,0,AIR)
Block(-1,47,1,AIR)
Block(-1,47,2,AIR)
Block(-1,47,3,4)
Block(-1,47,4,4)
Block(-1,47,5,67:5)
Block(-1,47,7,106:4)
Block(-1,48,-7,4)
Block(-1,48,-6,4)
Block(-1,48,-5,4)
Block(-1,48,-4,4)
Block(-1,48,-3,4)
Block(-1,48,-2,4)
Block(-1,48,-1,4)
Block(-1,48,0,4)
Block(-1,48,1,4)
Block(-1,48,2,4)
Block(-1,48,3,4)
Block(-1,48,4,4)
Block(-1,48,5,4)
Block(-1,48,7,106:4)
Block(-1,49,-7,4)
Block(-1,49,-6,4)
Block(-1,49,-5,4)
Block(-1,49,-4,4)
Block(-1,49,-3,4)
Block(-1,49,-2,4)
Block(-1,49,-1,4)
Block(-1,49,0,4)
Block(-1,49,1,4)
Block(-1,49,2,4)
Block(-1,49,3,2)
Block(-1,49,4,3:1)
Block(-1,49,5,4)
Block(-1,49,6,4)
Block(-1,49,7,106:4)
Block(-1,50,-7,44:3)
Block(-1,50,-6,4)
Block(-1,50,3,18:7)
Block(-1,50,6,44:3)
Block(0,0,-7,4)
Block(0,0,-6,4)
Block(0,0,-5,4)
Block(0,0,-4,4)
Block(0,0,-3,4)
Block(0,0,-2,4)
Block(0,0,-1,4)
Block(0,0,0,4)
Block(0,0,1,97:2)
Block(0,0,2,97:2)
Block(0,0,3,4)
Block(0,0,4,4)
Block(0,0,5,4)
Block(0,0,6,4)
Block(0,0,7,4)
Block(0,1,-7,4)
Block(0,1,-6,4)
Block(0,1,-5,4)
Block(0,1,-4,4)
Block(0,1,-3,4)
Block(0,1,-2,4)
Block(0,1,-1,4)
Block(0,1,0,4)
Block(0,1,1,97:2)
Block(0,1,2,97:2)
Block(0,1,3,4)
Block(0,1,4,4)
Block(0,1,5,4)
Block(0,1,6,4)
Block(0,1,7,4)
Block(0,2,-7,4)
Block(0,2,-6,4)
Block(0,2,-5,4)
Block(0,2,-4,4)
Block(0,2,-3,4)
Block(0,2,-2,4)
Block(0,2,-1,4)
Block(0,2,0,4)
Block(0,2,1,97:2)
Block(0,2,2,97:2)
Block(0,2,3,4)
Block(0,2,4,4)
Block(0,2,5,4)
Block(0,2,6,4)
Block(0,2,7,4)
Block(0,3,-7,4)
Block(0,3,-6,4)
Block(0,3,-5,4)
Block(0,3,-4,4)
Block(0,3,-3,4)
Block(0,3,-2,4)
Block(0,3,-1,4)
Block(0,3,0,4)
Block(0,3,1,97:2)
Block(0,3,2,97:2)
Block(0,3,3,4)
Block(0,3,4,4)
Block(0,3,5,4)
Block(0,3,6,4)
Block(0,3,7,4)
Block(0,4,-7,4)
Block(0,4,-6,4)
Block(0,4,-5,4)
Block(0,4,-4,4)
Block(0,4,-3,4)
Block(0,4,-2,4)
Block(0,4,-1,4)
Block(0,4,0,4)
Block(0,4,1,97:2)
Block(0,4,2,97:2)
Block(0,4,3,4)
Block(0,4,4,4)
Block(0,4,5,4)
Block(0,4,6,4)
Block(0,4,7,4)
Block(0,5,-7,4)
Block(0,5,-6,4)
Block(0,5,-5,4)
Block(0,5,-4,4)
Block(0,5,-3,4)
Block(0,5,-2,4)
Block(0,5,-1,4)
Block(0,5,0,4)
Block(0,5,1,97:2)
Block(0,5,2,97:2)
Block(0,5,3,4)
Block(0,5,4,4)
Block(0,5,5,4)
Block(0,5,6,4)
Block(0,5,7,4)
Block(0,6,-7,4)
Block(0,6,-6,4)
Block(0,6,-5,4)
Block(0,6,-4,4)
Block(0,6,-3,4)
Block(0,6,-2,4)
Block(0,6,-1,4)
Block(0,6,0,4)
Block(0,6,1,97:2)
Block(0,6,2,97:2)
Block(0,6,3,4)
Block(0,6,4,4)
Block(0,6,5,4)
Block(0,6,6,4)
Block(0,6,7,4)
Block(0,7,-7,4)
Block(0,7,-6,4)
Block(0,7,-5,4)
Block(0,7,-4,4)
Block(0,7,-3,4)
Block(0,7,-2,4)
Block(0,7,-1,4)
Block(0,7,0,4)
Block(0,7,1,97:2)
Block(0,7,2,97:2)
Block(0,7,3,4)
Block(0,7,4,4)
Block(0,7,5,4)
Block(0,7,6,4)
Block(0,7,7,4)
Block(0,8,-7,4)
Block(0,8,-6,4)
Block(0,8,-5,4)
Block(0,8,-4,4)
Block(0,8,-3,4)
Block(0,8,-2,4)
Block(0,8,-1,4)
Block(0,8,0,4)
Block(0,8,1,97:2)
Block(0,8,2,97:2)
Block(0,8,3,4)
Block(0,8,4,4)
Block(0,8,5,4)
Block(0,8,6,4)
Block(0,8,7,4)
Block(0,9,-7,4)
Block(0,9,-6,4)
Block(0,9,-5,4)
Block(0,9,-4,4)
Block(0,9,-3,4)
Block(0,9,-2,4)
Block(0,9,-1,4)
Block(0,9,0,4)
Block(0,9,1,97:2)
Block(0,9,2,97:2)
Block(0,9,3,4)
Block(0,9,4,4)
Block(0,9,5,4)
Block(0,9,6,4)
Block(0,9,7,4)
Block(0,10,-7,4)
Block(0,10,-6,4)
Block(0,10,-5,4)
Block(0,10,-4,4)
Block(0,10,-3,4)
Block(0,10,-2,4)
Block(0,10,-1,4)
Block(0,10,0,4)
Block(0,10,1,97:2)
Block(0,10,2,97:2)
Block(0,10,3,4)
Block(0,10,4,4)
Block(0,10,5,4)
Block(0,10,6,4)
Block(0,10,7,4)
Block(0,11,-7,4)
Block(0,11,-6,4)
Block(0,11,-5,4)
Block(0,11,-4,4)
Block(0,11,-3,4)
Block(0,11,-2,4)
Block(0,11,-1,4)
Block(0,11,0,4)
Block(0,11,1,97:2)
Block(0,11,2,97:2)
Block(0,11,3,4)
Block(0,11,4,4)
Block(0,11,5,4)
Block(0,11,6,4)
Block(0,11,7,4)
Block(0,12,-7,4)
Block(0,12,-6,4)
Block(0,12,-5,4)
Block(0,12,-4,4)
Block(0,12,-3,4)
Block(0,12,-2,4)
Block(0,12,-1,4)
Block(0,12,0,4)
Block(0,12,1,97:2)
Block(0,12,2,97:2)
Block(0,12,3,4)
Block(0,12,4,4)
Block(0,12,5,4)
Block(0,12,6,4)
Block(0,12,7,4)
Block(0,13,-7,4)
Block(0,13,-6,4)
Block(0,13,-5,4)
Block(0,13,-4,4)
Block(0,13,-3,4)
Block(0,13,-2,97:2)
Block(0,13,-1,97:2)
Block(0,13,0,97:2)
Block(0,13,1,97:2)
Block(0,13,2,97:2)
Block(0,13,3,4)
Block(0,13,4,4)
Block(0,13,5,4)
Block(0,13,6,4)
Block(0,13,7,4)
Block(0,14,-7,4)
Block(0,14,-6,4)
Block(0,14,-5,4)
Block(0,14,-4,4)
Block(0,14,-3,4)
Block(0,14,-2,97:2)
Block(0,14,-1,97:2)
Block(0,14,0,97:2)
Block(0,14,1,97:2)
Block(0,14,2,97:2)
Block(0,14,3,4)
Block(0,14,4,4)
Block(0,14,5,4)
Block(0,14,6,4)
Block(0,14,7,4)
Block(0,15,-7,4)
Block(0,15,-6,4)
Block(0,15,-5,4)
Block(0,15,-4,4)
Block(0,15,-3,4)
Block(0,15,-2,97:2)
Block(0,15,-1,97:2)
Block(0,15,0,97:2)
Block(0,15,1,97:2)
Block(0,15,2,97:2)
Block(0,15,3,4)
Block(0,15,4,4)
Block(0,15,5,4)
Block(0,15,6,4)
Block(0,15,7,4)
Block(0,16,-7,4)
Block(0,16,-6,4)
Block(0,16,-5,4)
Block(0,16,-4,4)
Block(0,16,-3,4)
Block(0,16,-2,4)
Block(0,16,-1,4)
Block(0,16,0,4)
Block(0,16,1,97:2)
Block(0,16,2,97:2)
Block(0,16,3,4)
Block(0,16,4,4)
Block(0,16,5,4)
Block(0,16,6,4)
Block(0,16,7,4)
Block(0,17,-7,4)
Block(0,17,-6,4)
Block(0,17,-5,4)
Block(0,17,-4,4)
Block(0,17,-3,4)
Block(0,17,-2,4)
Block(0,17,-1,4)
Block(0,17,0,4)
Block(0,17,1,4)
Block(0,17,2,4)
Block(0,17,3,4)
Block(0,17,4,4)
Block(0,17,5,4)
Block(0,17,6,4)
Block(0,17,7,4)
Block(0,18,-7,139)
Block(0,18,-6,AIR)
Block(0,18,-5,AIR)
Block(0,18,-4,139)
Block(0,18,-3,AIR)
Block(0,18,-2,AIR)
Block(0,18,-1,AIR)
Block(0,18,0,AIR)
Block(0,18,1,AIR)
Block(0,18,2,AIR)
Block(0,18,3,AIR)
Block(0,18,4,4)
Block(0,18,5,4)
Block(0,18,6,4)
Block(0,18,7,4)
Block(0,19,-7,139)
Block(0,19,-6,AIR)
Block(0,19,-5,AIR)
Block(0,19,-4,139)
Block(0,19,-3,AIR)
Block(0,19,-2,AIR)
Block(0,19,-1,AIR)
Block(0,19,0,AIR)
Block(0,19,1,AIR)
Block(0,19,2,AIR)
Block(0,19,3,AIR)
Block(0,19,4,4)
Block(0,19,5,4)
Block(0,19,6,4)
Block(0,19,7,4)
Block(0,20,-7,139)
Block(0,20,-6,AIR)
Block(0,20,-5,AIR)
Block(0,20,-4,139)
Block(0,20,-3,AIR)
Block(0,20,-2,AIR)
Block(0,20,-1,AIR)
Block(0,20,0,AIR)
Block(0,20,1,AIR)
Block(0,20,2,AIR)
Block(0,20,3,AIR)
Block(0,20,4,4)
Block(0,20,5,4)
Block(0,20,6,4)
Block(0,20,7,4)
Block(0,21,-7,4)
Block(0,21,-6,AIR)
Block(0,21,-5,AIR)
Block(0,21,-4,4)
Block(0,21,-3,67:5)
Block(0,21,-2,AIR)
Block(0,21,-1,AIR)
Block(0,21,0,AIR)
Block(0,21,1,AIR)
Block(0,21,2,AIR)
Block(0,21,3,AIR)
Block(0,21,4,4)
Block(0,21,5,4)
Block(0,21,6,44:5)
Block(0,21,7,4)
Block(0,22,-7,4)
Block(0,22,-6,67:5)
Block(0,22,-5,67:5)
Block(0,22,-4,4)
Block(0,22,-3,4)
Block(0,22,-2,AIR)
Block(0,22,-1,AIR)
Block(0,22,0,AIR)
Block(0,22,1,AIR)
Block(0,22,2,AIR)
Block(0,22,3,AIR)
Block(0,22,4,4)
Block(0,22,5,4)
Block(0,22,6,18:7)
Block(0,23,-7,67:0)
Block(0,23,-6,67:0)
Block(0,23,-5,67:0)
Block(0,23,-4,67:0)
Block(0,23,-3,4)
Block(0,23,-2,AIR)
Block(0,23,-1,AIR)
Block(0,23,0,AIR)
Block(0,23,1,AIR)
Block(0,23,2,AIR)
Block(0,23,3,AIR)
Block(0,23,4,98:3)
Block(0,23,5,4)
Block(0,24,-7,AIR)
Block(0,24,-6,AIR)
Block(0,24,-5,AIR)
Block(0,24,-4,AIR)
Block(0,24,-3,67:0)
Block(0,24,-2,AIR)
Block(0,24,-1,AIR)
Block(0,24,0,AIR)
Block(0,24,1,AIR)
Block(0,24,2,AIR)
Block(0,24,3,AIR)
Block(0,24,4,1:6)
Block(0,24,5,4)
Block(0,25,-7,AIR)
Block(0,25,-6,AIR)
Block(0,25,-5,AIR)
Block(0,25,-4,AIR)
Block(0,25,-3,AIR)
Block(0,25,-2,AIR)
Block(0,25,-1,AIR)
Block(0,25,0,AIR)
Block(0,25,1,AIR)
Block(0,25,2,AIR)
Block(0,25,3,AIR)
Block(0,25,4,4)
Block(0,25,5,4)
Block(0,25,6,18:7)
Block(0,26,-7,AIR)
Block(0,26,-6,AIR)
Block(0,26,-5,AIR)
Block(0,26,-4,AIR)
Block(0,26,-3,AIR)
Block(0,26,-2,97:2)
Block(0,26,-1,AIR)
Block(0,26,0,AIR)
Block(0,26,1,AIR)
Block(0,26,2,AIR)
Block(0,26,3,97:2)
Block(0,26,4,4)
Block(0,26,5,4)
Block(0,26,6,18:7)
Block(0,27,-7,4)
Block(0,27,-6,4)
Block(0,27,-5,4)
Block(0,27,-4,4)
Block(0,27,-3,4)
Block(0,27,-2,4)
Block(0,27,-1,4)
Block(0,27,0,4)
Block(0,27,1,4)
