
#######################################################################
# +-----------------------------------------------------------------+ #
# |                            BO3 object                           | #
# +-----------------------------------------------------------------+ #
#######################################################################

# This is the config file of a custom object.
# If you add this object correctly to your BiomeConfigs, it will spawn in the world.

# This is the creator of this BO3 object
Author: LordSmellyPants

# A short description of this BO3 object
Description: No description given

# The BO3 version, don't change this! It can be used by external applications to do a version check.
Version: 3

# The settings mode, WriteAll, WriteWithoutComments or WriteDisable. See WorldConfig.
SettingsMode: WriteDisable


#######################################################################
# +-----------------------------------------------------------------+ #
# |                          Main settings                          | #
# +-----------------------------------------------------------------+ #
#######################################################################

# This needs to be set to true to spawn the object in the Tree and Sapling resources.
Tree: false

# The frequency of the BO3 from 1 to 200. Tries this many times to spawn this BO3 when using the CustomObject(...) resource.
# Ignored by Tree(..), Sapling(..) and CustomStructure(..)
Frequency: 1

# The rarity of the BO3 from 0 to 100. Each spawn attempt has rarity% chance to succeed when using the CustomObject(...) resource.
# Ignored by Tree(..), Sapling(..) and CustomStructure(..)
Rarity: 0.1

# If you set this to true, the BO3 will be placed with a random rotation.
RotateRandomly: false

# The spawn height of the BO3 - randomY, highestBlock or highestSolidBlock.
SpawnHeight: highestSolidBlock

# The height limits for the BO3.
MinHeight: 0

MaxHeight: 58

# Objects can have other objects attacthed to it: branches. Branches can also
# have branches attached to it, which can also have branches, etc. This is the
# maximum branch depth for this objects.
MaxBranchDepth: 10

# When spawned with the UseWorld keyword, this BO3 should NOT spawn in the following biomes.
# If you writer.write the BO3 name directly in the BiomeConfigs, this will be ignored.
ExcludedBiomes: All


#######################################################################
# +-----------------------------------------------------------------+ #
# |                      Source block settings                      | #
# +-----------------------------------------------------------------+ #
#######################################################################

# The block(s) the BO3 should spawn in.
SourceBlocks: AIR,STONE,DIRT,GRASS,DIRT:2,HARD_CLAY,CLAY,STONE:1,STONE:3,STONE:5,SAND,GRAVEL,COBBLESTONE,MOSSY_COBBLESTONE

# The maximum percentage of the BO3 that can be outside the SourceBlock.
# The BO3 won't be placed on a location with more blocks outside the SourceBlock than this percentage.
MaxPercentageOutsideSourceBlock: 10

# What to do when a block is about to be placed outside the SourceBlock? (dontPlace, placeAnyway)
OutsideSourceBlock: placeAnyway


#######################################################################
# +-----------------------------------------------------------------+ #
# |                              Blocks                             | #
# +-----------------------------------------------------------------+ #
#######################################################################

# All the blocks used in the BO3 are listed here. Possible blocks:
# Block(x,y,z,id[.data][,nbtfile.nbt)
# RandomBlock(x,y,z,id[:data][,nbtfile.nbt],chance[,id[:data][,nbtfile.nbt],chance[,...]])
# So RandomBlock(0,0,0,CHEST,chest.nbt,50,CHEST,anotherchest.nbt,100) will spawn a chest at
# the BO3 origin, and give it a 50% chance to have the contents of chest.nbt, or, if that
# fails, a 100% percent chance to have the contents of anotherchest.nbt.
Block(-5,-8,-4,STONE)
Block(-5,-8,-3,STONE)
Block(-5,-8,-2,STONE)
Block(-5,-8,-1,STONE)
Block(-5,-8,0,STONE)
Block(-5,-8,1,STONE)
Block(-5,-8,2,STONE)
Block(-5,-8,3,STONE)
Block(-5,-8,4,STONE)
Block(-5,-8,5,STONE)
Block(-5,-7,-4,STONE)
Block(-5,-7,-3,STONE)
Block(-5,-7,-2,STONE)
Block(-5,-7,-1,STONE)
Block(-5,-7,0,STONE)
Block(-5,-7,1,STONE)
Block(-5,-7,2,STONE)
Block(-5,-7,3,STONE)
Block(-5,-7,4,STONE)
Block(-5,-7,5,STONE)
Block(-5,-6,-4,STONE)
Block(-5,-6,-3,STONE)
Block(-5,-6,-2,STONE)
Block(-5,-6,-1,STONE)
Block(-5,-6,0,STONE)
Block(-5,-6,1,STONE)
Block(-5,-6,2,STONE)
Block(-5,-6,3,STONE)
Block(-5,-6,4,STONE)
Block(-5,-6,5,STONE)
Block(-5,-5,-4,STONE)
Block(-5,-5,-3,STONE)
Block(-5,-5,-2,STONE)
Block(-5,-5,-1,STONE)
Block(-5,-5,0,STONE)
Block(-5,-5,1,STONE)
Block(-5,-5,2,STONE)
Block(-5,-5,3,STONE)
Block(-5,-5,4,STONE)
Block(-5,-5,5,STONE)
Block(-5,-4,-4,STONE)
Block(-5,-4,-3,STONE)
Block(-5,-4,-2,STONE)
Block(-5,-4,-1,STONE)
Block(-5,-4,0,STONE)
Block(-5,-4,1,STONE)
Block(-5,-4,2,STONE)
Block(-5,-4,3,STONE)
Block(-5,-4,4,STONE)
Block(-5,-4,5,STONE)
Block(-5,-3,-4,STONE)
Block(-5,-3,-3,STONE)
Block(-5,-3,-2,STONE)
Block(-5,-3,-1,STONE)
Block(-5,-3,0,STONE)
Block(-5,-3,1,STONE)
Block(-5,-3,2,STONE)
Block(-5,-3,3,STONE)
Block(-5,-3,4,STONE)
Block(-5,-3,5,STONE)
Block(-5,-2,-4,DIRT)
Block(-5,-2,-3,DIRT)
Block(-5,-2,-2,DIRT)
Block(-5,-2,-1,DIRT)
Block(-5,-2,0,DIRT)
Block(-5,-2,1,DIRT)
Block(-5,-2,2,DIRT)
Block(-5,-2,3,DIRT)
Block(-5,-2,4,DIRT)
Block(-5,-2,5,DIRT)
Block(-5,-1,-4,DIRT)
Block(-5,-1,-3,DIRT)
Block(-5,-1,-2,DIRT)
Block(-5,-1,-1,DIRT)
Block(-5,-1,0,DIRT)
Block(-5,-1,1,DIRT)
Block(-5,-1,2,DIRT)
Block(-5,-1,3,DIRT)
Block(-5,-1,4,DIRT)
Block(-5,-1,5,DIRT)
Block(-5,0,-4,DIRT:2)
Block(-5,0,-3,DIRT:2)
Block(-5,0,-2,DIRT:2)
Block(-5,0,-1,GRAVEL)
Block(-5,0,0,GRAVEL)
Block(-5,0,1,GRAVEL)
Block(-5,0,2,DIRT:2)
Block(-5,0,3,GRASS)
Block(-5,0,4,GRASS)
Block(-5,0,5,DIRT)
Block(-5,1,-4,SMOOTH_BRICK:1)
Block(-5,1,-3,IRON_FENCE)
Block(-5,1,-2,IRON_FENCE)
Block(-5,1,-1,SMOOTH_BRICK:2)
Block(-5,1,0,AIR)
Block(-5,1,1,AIR)
Block(-5,1,2,SMOOTH_BRICK:2)
Block(-5,1,3,IRON_FENCE)
Block(-5,1,4,IRON_FENCE)
Block(-5,1,5,SMOOTH_BRICK:2)
Block(-5,2,-4,SMOOTH_BRICK:2)
Block(-5,2,-3,IRON_FENCE)
Block(-5,2,-2,IRON_FENCE)
Block(-5,2,-1,SMOOTH_BRICK:2)
Block(-5,2,0,AIR)
Block(-5,2,1,AIR)
Block(-5,2,2,SMOOTH_BRICK:1)
Block(-5,2,3,IRON_FENCE)
Block(-5,2,4,IRON_FENCE)
Block(-5,2,5,SMOOTH_BRICK)
Block(-5,3,-4,SMOOTH_BRICK)
Block(-5,3,-3,IRON_FENCE)
Block(-5,3,-2,IRON_FENCE)
Block(-5,3,-1,SMOOTH_BRICK)
Block(-5,3,0,STEP:13)
Block(-5,3,1,STEP:13)
Block(-5,3,2,SMOOTH_BRICK)
Block(-5,3,3,IRON_FENCE)
Block(-5,3,4,IRON_FENCE)
Block(-5,3,5,SMOOTH_BRICK)
Block(-5,4,-4,AIR)
Block(-5,4,-3,STEP:5)
Block(-5,4,-2,STEP:5)
Block(-5,4,-1,STEP:5)
Block(-5,4,0,DOUBLE_STEP:5)
Block(-5,4,1,DOUBLE_STEP:5)
Block(-5,4,2,STEP:5)
Block(-5,4,3,STEP:5)
Block(-5,4,4,STEP:5)
Block(-5,4,5,AIR)
Block(-5,5,-4,AIR)
Block(-5,5,-3,AIR)
Block(-5,5,-2,AIR)
Block(-5,5,-1,AIR)
Block(-5,5,0,AIR)
Block(-5,5,1,AIR)
Block(-5,5,2,AIR)
Block(-5,5,3,AIR)
Block(-5,5,4,AIR)
Block(-5,5,5,AIR)
Block(-4,-8,-4,STONE)
Block(-4,-8,-3,STONE)
Block(-4,-8,-2,STONE)
Block(-4,-8,-1,STONE)
Block(-4,-8,0,STONE)
Block(-4,-8,1,STONE)
Block(-4,-8,2,STONE)
Block(-4,-8,3,STONE)
Block(-4,-8,4,STONE)
Block(-4,-8,5,STONE)
Block(-4,-7,-4,STONE)
Block(-4,-7,-3,STONE)
Block(-4,-7,-2,STONE)
Block(-4,-7,-1,STONE)
Block(-4,-7,0,STONE)
Block(-4,-7,1,STONE)
Block(-4,-7,2,STONE)
Block(-4,-7,3,STONE)
Block(-4,-7,4,STONE)
Block(-4,-7,5,STONE)
Block(-4,-6,-4,STONE)
Block(-4,-6,-3,STONE)
Block(-4,-6,-2,STONE)
Block(-4,-6,-1,STONE)
Block(-4,-6,0,STONE)
Block(-4,-6,1,STONE)
Block(-4,-6,2,STONE)
Block(-4,-6,3,STONE)
Block(-4,-6,4,STONE)
Block(-4,-6,5,STONE)
Block(-4,-5,-4,STONE)
Block(-4,-5,-3,STONE)
Block(-4,-5,-2,STONE)
Block(-4,-5,-1,STONE)
Block(-4,-5,0,STONE)
Block(-4,-5,1,STONE)
Block(-4,-5,2,STONE)
Block(-4,-5,3,STONE)
Block(-4,-5,4,STONE)
Block(-4,-5,5,STONE)
Block(-4,-4,-4,STONE)
Block(-4,-4,-3,STONE)
Block(-4,-4,-2,STONE)
Block(-4,-4,-1,STONE)
Block(-4,-4,0,STONE)
Block(-4,-4,1,STONE)
Block(-4,-4,2,STONE)
Block(-4,-4,3,STONE)
Block(-4,-4,4,STONE)
Block(-4,-4,5,STONE)
Block(-4,-3,-4,STONE)
Block(-4,-3,-3,STONE)
Block(-4,-3,-2,STONE)
Block(-4,-3,-1,STONE)
Block(-4,-3,0,STONE)
Block(-4,-3,1,STONE)
Block(-4,-3,2,STONE)
Block(-4,-3,3,STONE)
Block(-4,-3,4,STONE)
Block(-4,-3,5,STONE)
Block(-4,-2,-4,DIRT)
Block(-4,-2,-3,DIRT)
Block(-4,-2,-2,DIRT)
Block(-4,-2,-1,DIRT)
Block(-4,-2,0,DIRT)
Block(-4,-2,1,DIRT)
Block(-4,-2,2,DIRT)
Block(-4,-2,3,DIRT)
Block(-4,-2,4,DIRT)
Block(-4,-2,5,DIRT)
Block(-4,-1,-4,DIRT)
Block(-4,-1,-3,DIRT)
Block(-4,-1,-2,DIRT)
Block(-4,-1,-1,DIRT)
Block(-4,-1,0,DIRT)
Block(-4,-1,1,DIRT)
Block(-4,-1,2,DIRT)
Block(-4,-1,3,DIRT)
Block(-4,-1,4,DIRT)
Block(-4,-1,5,DIRT)
Block(-4,0,-4,GRAVEL)
Block(-4,0,-3,DIRT:2)
Block(-4,0,-2,STONE)
Block(-4,0,-1,DIRT)
Block(-4,0,0,GRAVEL)
Block(-4,0,1,GRAVEL)
Block(-4,0,2,DIRT:2)
Block(-4,0,3,DIRT:2)
Block(-4,0,4,GRASS)
Block(-4,0,5,GRASS)
Block(-4,1,-4,IRON_FENCE)
Block(-4,1,-3,AIR)
Block(-4,1,-2,AIR)
Block(-4,1,-1,AIR)
Block(-4,1,0,AIR)
Block(-4,1,1,AIR)
Block(-4,1,2,AIR)
Block(-4,1,3,AIR)
Block(-4,1,4,DOUBLE_PLANT:2)
Block(-4,1,5,IRON_FENCE)
Block(-4,2,-4,IRON_FENCE)
Block(-4,2,-3,AIR)
Block(-4,2,-2,AIR)
Block(-4,2,-1,AIR)
Block(-4,2,0,AIR)
Block(-4,2,1,AIR)
Block(-4,2,2,AIR)
Block(-4,2,3,AIR)
Block(-4,2,4,DOUBLE_PLANT:10)
Block(-4,2,5,IRON_FENCE)
Block(-4,3,-4,IRON_FENCE)
Block(-4,3,-3,AIR)
Block(-4,3,-2,AIR)
Block(-4,3,-1,AIR)
Block(-4,3,0,AIR)
Block(-4,3,1,AIR)
Block(-4,3,2,AIR)
Block(-4,3,3,AIR)
Block(-4,3,4,AIR)
Block(-4,3,5,IRON_FENCE)
Block(-4,4,-4,STEP:5)
Block(-4,4,-3,AIR)
Block(-4,4,-2,AIR)
Block(-4,4,-1,AIR)
Block(-4,4,0,AIR)
Block(-4,4,1,AIR)
Block(-4,4,2,AIR)
Block(-4,4,3,AIR)
Block(-4,4,4,AIR)
Block(-4,4,5,STEP:5)
Block(-4,5,-4,AIR)
Block(-4,5,-3,AIR)
Block(-4,5,-2,AIR)
Block(-4,5,-1,AIR)
Block(-4,5,0,AIR)
Block(-4,5,1,AIR)
Block(-4,5,2,AIR)
Block(-4,5,3,AIR)
Block(-4,5,4,AIR)
Block(-4,5,5,AIR)
Block(-3,-8,-4,STONE)
Block(-3,-8,-3,STONE)
Block(-3,-8,-2,STONE)
Block(-3,-8,-1,STONE)
Block(-3,-8,0,STONE)
Block(-3,-8,1,STONE)
Block(-3,-8,2,STONE)
Block(-3,-8,3,STONE)
Block(-3,-8,4,STONE)
Block(-3,-8,5,STONE)
Block(-3,-7,-4,STONE)
Block(-3,-7,-3,STONE)
Block(-3,-7,-2,STONE)
Block(-3,-7,-1,STONE)
Block(-3,-7,0,STONE)
Block(-3,-7,1,STONE)
Block(-3,-7,2,STONE)
Block(-3,-7,3,STONE)
Block(-3,-7,4,STONE)
Block(-3,-7,5,STONE)
Block(-3,-6,-4,STONE)
Block(-3,-6,-3,STONE)
Block(-3,-6,-2,STONE)
Block(-3,-6,-1,STONE)
Block(-3,-6,0,STONE)
Block(-3,-6,1,STONE)
Block(-3,-6,2,STONE)
Block(-3,-6,3,STONE)
Block(-3,-6,4,STONE)
Block(-3,-6,5,STONE)
Block(-3,-5,-4,STONE)
Block(-3,-5,-3,STONE)
Block(-3,-5,-2,STONE)
Block(-3,-5,-1,STONE)
Block(-3,-5,0,STONE)
Block(-3,-5,1,STONE)
Block(-3,-5,2,STONE)
Block(-3,-5,3,STONE)
Block(-3,-5,4,STONE)
Block(-3,-5,5,STONE)
Block(-3,-4,-4,STONE)
Block(-3,-4,-3,STONE)
Block(-3,-4,-2,STONE)
Block(-3,-4,-1,STONE)
Block(-3,-4,0,STONE)
Block(-3,-4,1,STONE)
Block(-3,-4,2,STONE)
Block(-3,-4,3,STONE)
Block(-3,-4,4,STONE)
Block(-3,-4,5,STONE)
Block(-3,-3,-4,STONE)
Block(-3,-3,-3,STONE)
Block(-3,-3,-2,STONE)
Block(-3,-3,-1,STONE)
Block(-3,-3,0,STONE)
Block(-3,-3,1,STONE)
Block(-3,-3,2,STONE)
Block(-3,-3,3,STONE)
Block(-3,-3,4,STONE)
Block(-3,-3,5,STONE)
Block(-3,-2,-4,DIRT)
Block(-3,-2,-3,DIRT)
Block(-3,-2,-2,DIRT)
Block(-3,-2,-1,DIRT)
Block(-3,-2,0,DIRT)
Block(-3,-2,1,DIRT)
Block(-3,-2,2,DIRT)
Block(-3,-2,3,DIRT)
Block(-3,-2,4,DIRT)
Block(-3,-2,5,DIRT)
Block(-3,-1,-4,DIRT)
Block(-3,-1,-3,DIRT)
Block(-3,-1,-2,DIRT)
Block(-3,-1,-1,DIRT)
Block(-3,-1,0,DIRT)
Block(-3,-1,1,DIRT)
Block(-3,-1,2,DIRT)
Block(-3,-1,3,DIRT)
Block(-3,-1,4,DIRT)
Block(-3,-1,5,DIRT)
Block(-3,0,-4,GRAVEL)
Block(-3,0,-3,GRASS)
Block(-3,0,-2,GRAVEL)
Block(-3,0,-1,DIRT)
Block(-3,0,0,GRAVEL)
Block(-3,0,1,GRAVEL)
Block(-3,0,2,GRASS)
Block(-3,0,3,GRASS)
Block(-3,0,4,DIRT:2)
Block(-3,0,5,GRAVEL)
Block(-3,1,-4,SMOOTH_BRICK:1)
Block(-3,1,-3,AIR)
Block(-3,1,-2,AIR)
Block(-3,1,-1,GRASS)
Block(-3,1,0,AIR)
Block(-3,1,1,AIR)
Block(-3,1,2,AIR)
Block(-3,1,3,DOUBLE_PLANT:2)
Block(-3,1,4,AIR)
Block(-3,1,5,SMOOTH_BRICK)
Block(-3,2,-4,SMOOTH_BRICK:2)
Block(-3,2,-3,AIR)
Block(-3,2,-2,AIR)
Block(-3,2,-1,DOUBLE_PLANT:2)
Block(-3,2,0,AIR)
Block(-3,2,1,AIR)
Block(-3,2,2,AIR)
Block(-3,2,3,DOUBLE_PLANT:10)
Block(-3,2,4,AIR)
Block(-3,2,5,SMOOTH_BRICK)
Block(-3,3,-4,SMOOTH_BRICK)
Block(-3,3,-3,AIR)
Block(-3,3,-2,AIR)
Block(-3,3,-1,DOUBLE_PLANT:8)
Block(-3,3,0,AIR)
Block(-3,3,1,AIR)
Block(-3,3,2,AIR)
Block(-3,3,3,COBBLE_WALL:1)
Block(-3,3,4,AIR)
Block(-3,3,5,SMOOTH_BRICK:1)
Block(-3,4,-4,AIR)
Block(-3,4,-3,AIR)
Block(-3,4,-2,AIR)
Block(-3,4,-1,AIR)
Block(-3,4,0,AIR)
Block(-3,4,1,AIR)
Block(-3,4,2,AIR)
Block(-3,4,3,AIR)
Block(-3,4,4,AIR)
Block(-3,4,5,AIR)
Block(-3,5,-4,AIR)
Block(-3,5,-3,AIR)
Block(-3,5,-2,AIR)
Block(-3,5,-1,AIR)
Block(-3,5,0,AIR)
Block(-3,5,1,AIR)
Block(-3,5,2,AIR)
Block(-3,5,3,AIR)
Block(-3,5,4,AIR)
Block(-3,5,5,AIR)
Block(-2,-8,-4,STONE)
Block(-2,-8,-3,STONE)
Block(-2,-8,-2,STONE)
Block(-2,-8,-1,STONE)
Block(-2,-8,0,STONE)
Block(-2,-8,1,STONE)
Block(-2,-8,2,STONE)
Block(-2,-8,3,STONE)
Block(-2,-8,4,STONE)
Block(-2,-8,5,STONE)
Block(-2,-7,-4,STONE)
Block(-2,-7,-3,STONE)
Block(-2,-7,-2,STONE)
Block(-2,-7,-1,STONE)
Block(-2,-7,0,STONE)
Block(-2,-7,1,STONE)
Block(-2,-7,2,STONE)
Block(-2,-7,3,STONE)
Block(-2,-7,4,STONE)
Block(-2,-7,5,STONE)
Block(-2,-6,-4,STONE)
Block(-2,-6,-3,STONE)
Block(-2,-6,-2,STONE)
Block(-2,-6,-1,STONE)
Block(-2,-6,0,STONE)
Block(-2,-6,1,STONE)
Block(-2,-6,2,STONE)
Block(-2,-6,3,STONE)
Block(-2,-6,4,STONE)
Block(-2,-6,5,STONE)
Block(-2,-5,-4,STONE)
Block(-2,-5,-3,STONE)
Block(-2,-5,-2,STONE)
Block(-2,-5,-1,STONE)
Block(-2,-5,0,STONE)
Block(-2,-5,1,STONE)
Block(-2,-5,2,STONE)
Block(-2,-5,3,STONE)
Block(-2,-5,4,STONE)
Block(-2,-5,5,STONE)
Block(-2,-4,-4,STONE)
Block(-2,-4,-3,STONE)
Block(-2,-4,-2,STONE)
Block(-2,-4,-1,STONE)
Block(-2,-4,0,STONE)
Block(-2,-4,1,STONE)
Block(-2,-4,2,STONE)
Block(-2,-4,3,STONE)
Block(-2,-4,4,STONE)
Block(-2,-4,5,STONE)
Block(-2,-3,-4,STONE)
Block(-2,-3,-3,STONE)
Block(-2,-3,-2,STONE)
Block(-2,-3,-1,STONE)
Block(-2,-3,0,STONE)
Block(-2,-3,1,STONE)
Block(-2,-3,2,STONE)
Block(-2,-3,3,STONE)
Block(-2,-3,4,STONE)
Block(-2,-3,5,STONE)
Block(-2,-2,-4,DIRT)
Block(-2,-2,-3,DIRT)
Block(-2,-2,-2,DIRT)
Block(-2,-2,-1,DIRT)
Block(-2,-2,0,DIRT)
Block(-2,-2,1,DIRT)
Block(-2,-2,2,DIRT)
Block(-2,-2,3,DIRT)
Block(-2,-2,4,DIRT)
Block(-2,-2,5,DIRT)
Block(-2,-1,-4,DIRT)
Block(-2,-1,-3,DIRT)
Block(-2,-1,-2,DIRT)
Block(-2,-1,-1,DIRT)
Block(-2,-1,0,DIRT)
Block(-2,-1,1,DIRT)
RandomBlock(-2,-1,2,CHEST,../../nbt/Chests/Common1.nbt,25,CHEST,../../nbt/Chests/Common2.nbt,25,CHEST,../../nbt/Chests/Common3.nbt,25,CHEST,../../nbt/Chests/Common4.nbt,25,CHEST,../../nbt/Chests/Common5.nbt,25,CHEST,../../nbt/Chests/Common6.nbt,25,CHEST,../../nbt/Chests/Common7.nbt,25,CHEST,../../nbt/Chests/Common8.nbt,25,CHEST,../../nbt/Chests/Common9.nbt,25,CHEST,../../nbt/Chests/Common10.nbt,25,CHEST,../../nbt/Chests/Common11.nbt,25,CHEST,../../nbt/Chests/Common12.nbt,25,CHEST,../../nbt/Chests/Common13.nbt,25,CHEST,../../nbt/Chests/Common14.nbt,25,CHEST,../../nbt/Chests/Common15.nbt,100)
Block(-2,-1,3,DIRT)
Block(-2,-1,4,DIRT)
Block(-2,-1,5,DIRT)
Block(-2,0,-4,DIRT:2)
Block(-2,0,-3,GRAVEL)
Block(-2,0,-2,GRASS)
Block(-2,0,-1,GRAVEL)
Block(-2,0,0,GRAVEL)
Block(-2,0,1,GRAVEL)
Block(-2,0,2,DIRT:2)
Block(-2,0,3,DIRT)
Block(-2,0,4,GRAVEL)
Block(-2,0,5,GRAVEL)
Block(-2,1,-4,IRON_FENCE)
Block(-2,1,-3,AIR)
Block(-2,1,-2,AIR)
Block(-2,1,-1,AIR)
Block(-2,1,0,AIR)
Block(-2,1,1,AIR)
RandomBlock(-2,1,2,WALL_SIGN:2,../../nbt/Misc/GraveSign1.nbt,50,WALL_SIGN:2,../../nbt/Misc/GraveSign2.nbt,50,WALL_SIGN:2,../../nbt/Misc/GraveSign3.nbt,100)
Block(-2,1,3,SMOOTH_BRICK:3)
Block(-2,1,4,AIR)
Block(-2,1,5,IRON_FENCE)
Block(-2,2,-4,IRON_FENCE)
Block(-2,2,-3,AIR)
Block(-2,2,-2,AIR)
Block(-2,2,-1,AIR)
Block(-2,2,0,AIR)
Block(-2,2,1,AIR)
Block(-2,2,2,AIR)
Block(-2,2,3,COBBLE_WALL)
Block(-2,2,4,AIR)
Block(-2,2,5,IRON_FENCE)
Block(-2,3,-4,IRON_FENCE)
Block(-2,3,-3,AIR)
Block(-2,3,-2,AIR)
Block(-2,3,-1,AIR)
Block(-2,3,0,AIR)
Block(-2,3,1,AIR)
Block(-2,3,2,AIR)
Block(-2,3,3,COBBLE_WALL)
Block(-2,3,4,AIR)
Block(-2,3,5,IRON_FENCE)
Block(-2,4,-4,STEP:5)
Block(-2,4,-3,AIR)
Block(-2,4,-2,AIR)
Block(-2,4,-1,AIR)
Block(-2,4,0,AIR)
Block(-2,4,1,AIR)
Block(-2,4,2,AIR)
Block(-2,4,3,COBBLE_WALL:1)
Block(-2,4,4,AIR)
Block(-2,4,5,STEP:5)
Block(-2,5,-4,AIR)
Block(-2,5,-3,AIR)
Block(-2,5,-2,AIR)
Block(-2,5,-1,AIR)
Block(-2,5,0,AIR)
Block(-2,5,1,AIR)
Block(-2,5,2,AIR)
Block(-2,5,3,AIR)
Block(-2,5,4,AIR)
Block(-2,5,5,AIR)
Block(-1,-8,-4,STONE)
Block(-1,-8,-3,STONE)
Block(-1,-8,-2,STONE)
Block(-1,-8,-1,STONE)
Block(-1,-8,0,STONE)
Block(-1,-8,1,STONE)
Block(-1,-8,2,STONE)
Block(-1,-8,3,STONE)
Block(-1,-8,4,STONE)
Block(-1,-8,5,STONE)
Block(-1,-7,-4,STONE)
Block(-1,-7,-3,STONE)
Block(-1,-7,-2,STONE)
Block(-1,-7,-1,STONE)
Block(-1,-7,0,STONE)
Block(-1,-7,1,STONE)
Block(-1,-7,2,STONE)
Block(-1,-7,3,STONE)
Block(-1,-7,4,STONE)
Block(-1,-7,5,STONE)
Block(-1,-6,-4,STONE)
Block(-1,-6,-3,STONE)
Block(-1,-6,-2,STONE)
Block(-1,-6,-1,STONE)
Block(-1,-6,0,STONE)
Block(-1,-6,1,STONE)
Block(-1,-6,2,STONE)
Block(-1,-6,3,STONE)
Block(-1,-6,4,STONE)
Block(-1,-6,5,STONE)
Block(-1,-5,-4,STONE)
Block(-1,-5,-3,STONE)
Block(-1,-5,-2,STONE)
Block(-1,-5,-1,STONE)
Block(-1,-5,0,STONE)
Block(-1,-5,1,STONE)
Block(-1,-5,2,STONE)
Block(-1,-5,3,STONE)
Block(-1,-5,4,STONE)
Block(-1,-5,5,STONE)
Block(-1,-4,-4,STONE)
Block(-1,-4,-3,STONE)
Block(-1,-4,-2,STONE)
Block(-1,-4,-1,STONE)
Block(-1,-4,0,STONE)
Block(-1,-4,1,STONE)
Block(-1,-4,2,STONE)
Block(-1,-4,3,STONE)
Block(-1,-4,4,STONE)
Block(-1,-4,5,STONE)
Block(-1,-3,-4,STONE)
Block(-1,-3,-3,STONE)
Block(-1,-3,-2,STONE)
Block(-1,-3,-1,STONE)
Block(-1,-3,0,STONE)
Block(-1,-3,1,STONE)
Block(-1,-3,2,STONE)
Block(-1,-3,3,STONE)
Block(-1,-3,4,STONE)
Block(-1,-3,5,STONE)
Block(-1,-2,-4,DIRT)
Block(-1,-2,-3,DIRT)
Block(-1,-2,-2,DIRT)
Block(-1,-2,-1,DIRT)
Block(-1,-2,0,DIRT)
Block(-1,-2,1,DIRT)
Block(-1,-2,2,DIRT)
Block(-1,-2,3,DIRT)
Block(-1,-2,4,DIRT)
Block(-1,-2,5,DIRT)
Block(-1,-1,-4,DIRT)
Block(-1,-1,-3,DIRT)
Block(-1,-1,-2,DIRT)
Block(-1,-1,-1,DIRT)
Block(-1,-1,0,DIRT)
Block(-1,-1,1,DIRT)
Block(-1,-1,2,DIRT)
Block(-1,-1,3,DIRT)
Block(-1,-1,4,DIRT)
Block(-1,-1,5,DIRT)
Block(-1,0,-4,DIRT:2)
Block(-1,0,-3,GRASS)
Block(-1,0,-2,DIRT:2)
Block(-1,0,-1,DIRT:2)
Block(-1,0,0,GRAVEL)
Block(-1,0,1,GRAVEL)
Block(-1,0,2,GRAVEL)
Block(-1,0,3,GRAVEL)
Block(-1,0,4,GRAVEL)
Block(-1,0,5,GRASS)
Block(-1,1,-4,IRON_FENCE)
Block(-1,1,-3,AIR)
Block(-1,1,-2,GRASS)
Block(-1,1,-1,AIR)
Block(-1,1,0,AIR)
Block(-1,1,1,AIR)
Block(-1,1,2,AIR)
RandomBlock(-1,1,3,FLOWER_POT,../../nbt/Misc/FlowerPot2.nbt,22,FLOWER_POT,../../nbt/Misc/FlowerPot3.nbt,22,FLOWER_POT,../../nbt/Misc/FlowerPot81.nbt,22,FLOWER_POT,../../nbt/Misc/FlowerPot4.nbt,22,FLOWER_POT,../../nbt/Misc/FlowerPot5.nbt,22,FLOWER_POT,../../nbt/Misc/FlowerPot6.nbt,22,FLOWER_POT,../../nbt/Misc/FlowerPot7.nbt,22,FLOWER_POT,../../nbt/Misc/FlowerPot8.nbt,100)
Block(-1,1,4,AIR)
Block(-1,1,5,IRON_FENCE)
Block(-1,2,-4,IRON_FENCE)
Block(-1,2,-3,AIR)
RandomBlock(-1,2,-2,FLOWER_POT,../../nbt/Misc/FlowerPot2.nbt,22,FLOWER_POT,../../nbt/Misc/FlowerPot3.nbt,22,FLOWER_POT,../../nbt/Misc/FlowerPot81.nbt,22,FLOWER_POT,../../nbt/Misc/FlowerPot4.nbt,22,FLOWER_POT,../../nbt/Misc/FlowerPot5.nbt,22,FLOWER_POT,../../nbt/Misc/FlowerPot6.nbt,22,FLOWER_POT,../../nbt/Misc/FlowerPot7.nbt,22,FLOWER_POT,../../nbt/Misc/FlowerPot8.nbt,100)
Block(-1,2,-1,AIR)
Block(-1,2,0,AIR)
Block(-1,2,1,AIR)
Block(-1,2,2,AIR)
Block(-1,2,3,AIR)
Block(-1,2,4,AIR)
Block(-1,2,5,IRON_FENCE)
Block(-1,3,-4,IRON_FENCE)
Block(-1,3,-3,AIR)
Block(-1,3,-2,AIR)
Block(-1,3,-1,AIR)
Block(-1,3,0,AIR)
Block(-1,3,1,AIR)
Block(-1,3,2,AIR)
Block(-1,3,3,COBBLE_WALL)
Block(-1,3,4,AIR)
Block(-1,3,5,IRON_FENCE)
Block(-1,4,-4,STEP:5)
Block(-1,4,-3,AIR)
Block(-1,4,-2,AIR)
Block(-1,4,-1,AIR)
Block(-1,4,0,AIR)
Block(-1,4,1,AIR)
Block(-1,4,2,AIR)
Block(-1,4,3,AIR)
Block(-1,4,4,AIR)
Block(-1,4,5,STEP:5)
Block(-1,5,-4,AIR)
Block(-1,5,-3,AIR)
Block(-1,5,-2,AIR)
Block(-1,5,-1,AIR)
Block(-1,5,0,AIR)
Block(-1,5,1,AIR)
Block(-1,5,2,AIR)
Block(-1,5,3,AIR)
Block(-1,5,4,AIR)
Block(-1,5,5,AIR)
Block(0,-8,-4,STONE)
Block(0,-8,-3,STONE)
Block(0,-8,-2,STONE)
Block(0,-8,-1,STONE)
Block(0,-8,0,STONE)
Block(0,-8,1,STONE)
Block(0,-8,2,STONE)
Block(0,-8,3,STONE)
Block(0,-8,4,STONE)
Block(0,-8,5,STONE)
Block(0,-7,-4,STONE)
Block(0,-7,-3,STONE)
Block(0,-7,-2,STONE)
Block(0,-7,-1,STONE)
Block(0,-7,0,STONE)
Block(0,-7,1,STONE)
Block(0,-7,2,STONE)
Block(0,-7,3,STONE)
Block(0,-7,4,STONE)
Block(0,-7,5,STONE)
Block(0,-6,-4,STONE)
Block(0,-6,-3,STONE)
Block(0,-6,-2,STONE)
Block(0,-6,-1,STONE)
Block(0,-6,0,STONE)
Block(0,-6,1,STONE)
Block(0,-6,2,STONE)
Block(0,-6,3,STONE)
Block(0,-6,4,STONE)
Block(0,-6,5,STONE)
Block(0,-5,-4,STONE)
Block(0,-5,-3,STONE)
Block(0,-5,-2,STONE)
Block(0,-5,-1,STONE)
Block(0,-5,0,STONE)
Block(0,-5,1,STONE)
Block(0,-5,2,STONE)
Block(0,-5,3,STONE)
Block(0,-5,4,STONE)
Block(0,-5,5,STONE)
Block(0,-4,-4,STONE)
Block(0,-4,-3,STONE)
Block(0,-4,-2,STONE)
Block(0,-4,-1,STONE)
Block(0,-4,0,STONE)
Block(0,-4,1,STONE)
Block(0,-4,2,STONE)
Block(0,-4,3,STONE)
Block(0,-4,4,STONE)
Block(0,-4,5,STONE)
Block(0,-3,-4,STONE)
Block(0,-3,-3,STONE)
Block(0,-3,-2,STONE)
Block(0,-3,-1,STONE)
Block(0,-3,0,STONE)
Block(0,-3,1,STONE)
Block(0,-3,2,STONE)
Block(0,-3,3,STONE)
Block(0,-3,4,STONE)
Block(0,-3,5,STONE)
Block(0,-2,-4,DIRT)
Block(0,-2,-3,DIRT)
Block(0,-2,-2,DIRT)
Block(0,-2,-1,DIRT)
Block(0,-2,0,DIRT)
Block(0,-2,1,DIRT)
Block(0,-2,2,DIRT)
Block(0,-2,3,DIRT)
Block(0,-2,4,DIRT)
Block(0,-2,5,DIRT)
Block(0,-1,-4,DIRT)
Block(0,-1,-3,DIRT)
Block(0,-1,-2,DIRT)
Block(0,-1,-1,DIRT)
Block(0,-1,0,DIRT)
Block(0,-1,1,DIRT)
Block(0,-1,2,DIRT)
Block(0,-1,3,DIRT)
Block(0,-1,4,DIRT)
Block(0,-1,5,DIRT)
Block(0,0,-4,DIRT:2)
Block(0,0,-3,DIRT:2)
Block(0,0,-2,GRASS)
Block(0,0,-1,GRASS)
Block(0,0,0,GRAVEL)
Block(0,0,1,GRAVEL)
Block(0,0,2,GRASS)
Block(0,0,3,GRASS)
Block(0,0,4,GRASS)
Block(0,0,5,GRAVEL)
Block(0,1,-4,IRON_FENCE)
Block(0,1,-3,AIR)
Block(0,1,-2,AIR)
Block(0,1,-1,DOUBLE_PLANT:2)
Block(0,1,0,AIR)
Block(0,1,1,AIR)
Block(0,1,2,DOUBLE_PLANT:2)
Block(0,1,3,DOUBLE_PLANT:2)
Block(0,1,4,LONG_GRASS:1)
Block(0,1,5,IRON_FENCE)
Block(0,2,-4,IRON_FENCE)
Block(0,2,-3,AIR)
Block(0,2,-2,AIR)
Block(0,2,-1,DOUBLE_PLANT:9)
Block(0,2,0,AIR)
Block(0,2,1,AIR)
Block(0,2,2,DOUBLE_PLANT:10)
Block(0,2,3,DOUBLE_PLANT:11)
Block(0,2,4,AIR)
Block(0,2,5,IRON_FENCE)
Block(0,3,-4,IRON_FENCE)
Block(0,3,-3,AIR)
Block(0,3,-2,AIR)
Block(0,3,-1,AIR)
Block(0,3,0,AIR)
Block(0,3,1,AIR)
Block(0,3,2,AIR)
Block(0,3,3,AIR)
Block(0,3,4,AIR)
Block(0,3,5,IRON_FENCE)
Block(0,4,-4,STEP:5)
Block(0,4,-3,AIR)
Block(0,4,-2,AIR)
Block(0,4,-1,AIR)
Block(0,4,0,AIR)
Block(0,4,1,AIR)
Block(0,4,2,AIR)
Block(0,4,3,AIR)
Block(0,4,4,AIR)
Block(0,4,5,STEP:5)
Block(0,5,-4,AIR)
Block(0,5,-3,AIR)
Block(0,5,-2,AIR)
Block(0,5,-1,AIR)
Block(0,5,0,AIR)
Block(0,5,1,AIR)
Block(0,5,2,AIR)
Block(0,5,3,AIR)
Block(0,5,4,AIR)
Block(0,5,5,AIR)
Block(1,-8,-4,STONE)
Block(1,-8,-3,STONE)
Block(1,-8,-2,STONE)
Block(1,-8,-1,STONE)
Block(1,-8,0,STONE)
Block(1,-8,1,STONE)
Block(1,-8,2,STONE)
Block(1,-8,3,STONE)
Block(1,-8,4,STONE)
Block(1,-8,5,STONE)
Block(1,-7,-4,STONE)
Block(1,-7,-3,STONE)
Block(1,-7,-2,STONE)
Block(1,-7,-1,STONE)
Block(1,-7,0,STONE)
Block(1,-7,1,STONE)
Block(1,-7,2,STONE)
Block(1,-7,3,STONE)
Block(1,-7,4,STONE)
Block(1,-7,5,STONE)
Block(1,-6,-4,STONE)
Block(1,-6,-3,STONE)
Block(1,-6,-2,STONE)
Block(1,-6,-1,STONE)
Block(1,-6,0,STONE)
Block(1,-6,1,STONE)
Block(1,-6,2,STONE)
Block(1,-6,3,STONE)
Block(1,-6,4,STONE)
Block(1,-6,5,STONE)
Block(1,-5,-4,STONE)
Block(1,-5,-3,STONE)
Block(1,-5,-2,STONE)
Block(1,-5,-1,STONE)
Block(1,-5,0,STONE)
Block(1,-5,1,STONE)
Block(1,-5,2,STONE)
Block(1,-5,3,STONE)
Block(1,-5,4,STONE)
Block(1,-5,5,STONE)
Block(1,-4,-4,STONE)
Block(1,-4,-3,STONE)
Block(1,-4,-2,STONE)
Block(1,-4,-1,STONE)
Block(1,-4,0,STONE)
Block(1,-4,1,STONE)
Block(1,-4,2,STONE)
Block(1,-4,3,STONE)
Block(1,-4,4,STONE)
Block(1,-4,5,STONE)
Block(1,-3,-4,STONE)
Block(1,-3,-3,STONE)
Block(1,-3,-2,STONE)
Block(1,-3,-1,STONE)
Block(1,-3,0,STONE)
Block(1,-3,1,STONE)
Block(1,-3,2,STONE)
Block(1,-3,3,STONE)
Block(1,-3,4,STONE)
Block(1,-3,5,STONE)
Block(1,-2,-4,DIRT)
Block(1,-2,-3,DIRT)
Block(1,-2,-2,DIRT)
Block(1,-2,-1,DIRT)
Block(1,-2,0,DIRT)
Block(1,-2,1,DIRT)
Block(1,-2,2,DIRT)
Block(1,-2,3,DIRT)
Block(1,-2,4,DIRT)
Block(1,-2,5,DIRT)
Block(1,-1,-4,DIRT)
Block(1,-1,-3,DIRT)
Block(1,-1,-2,DIRT)
RandomBlock(1,-1,-1,CHEST,../../nbt/Chests/Common1.nbt,25,CHEST,../../nbt/Chests/Common2.nbt,25,CHEST,../../nbt/Chests/Common3.nbt,25,CHEST,../../nbt/Chests/Common4.nbt,25,CHEST,../../nbt/Chests/Common5.nbt,25,CHEST,../../nbt/Chests/Common6.nbt,25,CHEST,../../nbt/Chests/Common7.nbt,25,CHEST,../../nbt/Chests/Common8.nbt,25,CHEST,../../nbt/Chests/Common9.nbt,25,CHEST,../../nbt/Chests/Common10.nbt,25,CHEST,../../nbt/Chests/Common11.nbt,25,CHEST,../../nbt/Chests/Common12.nbt,25,CHEST,../../nbt/Chests/Common13.nbt,25,CHEST,../../nbt/Chests/Common14.nbt,25,CHEST,../../nbt/Chests/Common15.nbt,100)
Block(1,-1,0,DIRT)
Block(1,-1,1,DIRT)
RandomBlock(1,-1,2,CHEST,../../nbt/Chests/Common1.nbt,25,CHEST,../../nbt/Chests/Common2.nbt,25,CHEST,../../nbt/Chests/Common3.nbt,25,CHEST,../../nbt/Chests/Common4.nbt,25,CHEST,../../nbt/Chests/Common5.nbt,25,CHEST,../../nbt/Chests/Common6.nbt,25,CHEST,../../nbt/Chests/Common7.nbt,25,CHEST,../../nbt/Chests/Common8.nbt,25,CHEST,../../nbt/Chests/Common9.nbt,25,CHEST,../../nbt/Chests/Common10.nbt,25,CHEST,../../nbt/Chests/Common11.nbt,25,CHEST,../../nbt/Chests/Common12.nbt,25,CHEST,../../nbt/Chests/Common13.nbt,25,CHEST,../../nbt/Chests/Common14.nbt,25,CHEST,../../nbt/Chests/Common15.nbt,100)
RandomBlock(1,-1,3,CHEST,../../nbt/Chests/Common1.nbt,25,CHEST,../../nbt/Chests/Common2.nbt,25,CHEST,../../nbt/Chests/Common3.nbt,25,CHEST,../../nbt/Chests/Common4.nbt,25,CHEST,../../nbt/Chests/Common5.nbt,25,CHEST,../../nbt/Chests/Common6.nbt,25,CHEST,../../nbt/Chests/Common7.nbt,25,CHEST,../../nbt/Chests/Common8.nbt,25,CHEST,../../nbt/Chests/Common9.nbt,25,CHEST,../../nbt/Chests/Common10.nbt,25,CHEST,../../nbt/Chests/Common11.nbt,25,CHEST,../../nbt/Chests/Common12.nbt,25,CHEST,../../nbt/Chests/Common13.nbt,25,CHEST,../../nbt/Chests/Common14.nbt,25,CHEST,../../nbt/Chests/Common15.nbt,100)
Block(1,-1,4,DIRT)
Block(1,-1,5,DIRT)
Block(1,0,-4,GRASS)
Block(1,0,-3,GRAVEL)
Block(1,0,-2,GRAVEL)
Block(1,0,-1,DIRT:2)
Block(1,0,0,GRAVEL)
Block(1,0,1,GRAVEL)
Block(1,0,2,DIRT:2)
Block(1,0,3,STEP:13)
Block(1,0,4,GRASS)
Block(1,0,5,GRASS)
Block(1,1,-4,IRON_FENCE)
Block(1,1,-3,AIR)
Block(1,1,-2,AIR)
RandomBlock(1,1,-1,WALL_SIGN:4,../../nbt/Misc/GraveSign1.nbt,50,WALL_SIGN:4,../../nbt/Misc/GraveSign2.nbt,50,WALL_SIGN:4,../../nbt/Misc/GraveSign3.nbt,100)
Block(1,1,0,AIR)
Block(1,1,1,AIR)
RandomBlock(1,1,2,WALL_SIGN:2,../../nbt/Misc/GraveSign1.nbt,50,WALL_SIGN:2,../../nbt/Misc/GraveSign2.nbt,50,WALL_SIGN:2,../../nbt/Misc/GraveSign3.nbt,100)
Block(1,1,3,SMOOTH_BRICK)
Block(1,1,4,LONG_GRASS:1)
Block(1,1,5,IRON_FENCE)
Block(1,2,-4,IRON_FENCE)
Block(1,2,-3,AIR)
Block(1,2,-2,AIR)
Block(1,2,-1,AIR)
Block(1,2,0,AIR)
Block(1,2,1,AIR)
Block(1,2,2,AIR)
Block(1,2,3,AIR)
Block(1,2,4,AIR)
Block(1,2,5,IRON_FENCE)
Block(1,3,-4,IRON_FENCE)
Block(1,3,-3,AIR)
Block(1,3,-2,AIR)
Block(1,3,-1,AIR)
Block(1,3,0,AIR)
Block(1,3,1,AIR)
Block(1,3,2,AIR)
Block(1,3,3,AIR)
Block(1,3,4,AIR)
Block(1,3,5,IRON_FENCE)
Block(1,4,-4,STEP:5)
Block(1,4,-3,AIR)
Block(1,4,-2,AIR)
Block(1,4,-1,AIR)
Block(1,4,0,AIR)
Block(1,4,1,AIR)
Block(1,4,2,AIR)
Block(1,4,3,AIR)
Block(1,4,4,AIR)
Block(1,4,5,STEP:5)
Block(1,5,-4,AIR)
Block(1,5,-3,AIR)
Block(1,5,-2,AIR)
Block(1,5,-1,AIR)
Block(1,5,0,AIR)
Block(1,5,1,AIR)
Block(1,5,2,AIR)
Block(1,5,3,AIR)
Block(1,5,4,AIR)
Block(1,5,5,AIR)
Block(2,-8,-4,STONE)
Block(2,-8,-3,STONE)
Block(2,-8,-2,STONE)
Block(2,-8,-1,STONE)
Block(2,-8,0,STONE)
Block(2,-8,1,STONE)
Block(2,-8,2,STONE)
Block(2,-8,3,STONE)
Block(2,-8,4,STONE)
Block(2,-8,5,STONE)
Block(2,-7,-4,STONE)
Block(2,-7,-3,STONE)
Block(2,-7,-2,STONE)
Block(2,-7,-1,STONE)
Block(2,-7,0,STONE)
Block(2,-7,1,STONE)
Block(2,-7,2,STONE)
Block(2,-7,3,STONE)
Block(2,-7,4,STONE)
Block(2,-7,5,STONE)
Block(2,-6,-4,STONE)
Block(2,-6,-3,STONE)
Block(2,-6,-2,STONE)
Block(2,-6,-1,STONE)
Block(2,-6,0,STONE)
Block(2,-6,1,STONE)
Block(2,-6,2,STONE)
Block(2,-6,3,STONE)
Block(2,-6,4,STONE)
Block(2,-6,5,STONE)
Block(2,-5,-4,STONE)
Block(2,-5,-3,STONE)
Block(2,-5,-2,STONE)
Block(2,-5,-1,STONE)
Block(2,-5,0,STONE)
Block(2,-5,1,STONE)
Block(2,-5,2,STONE)
Block(2,-5,3,STONE)
Block(2,-5,4,STONE)
Block(2,-5,5,STONE)
Block(2,-4,-4,STONE)
Block(2,-4,-3,STONE)
Block(2,-4,-2,STONE)
Block(2,-4,-1,STONE)
Block(2,-4,0,STONE)
Block(2,-4,1,STONE)
Block(2,-4,2,STONE)
Block(2,-4,3,STONE)
Block(2,-4,4,STONE)
Block(2,-4,5,STONE)
Block(2,-3,-4,STONE)
Block(2,-3,-3,STONE)
Block(2,-3,-2,STONE)
Block(2,-3,-1,STONE)
Block(2,-3,0,STONE)
Block(2,-3,1,STONE)
Block(2,-3,2,STONE)
Block(2,-3,3,STONE)
Block(2,-3,4,STONE)
Block(2,-3,5,STONE)
Block(2,-2,-4,DIRT)
Block(2,-2,-3,DIRT)
Block(2,-2,-2,DIRT)
Block(2,-2,-1,DIRT)
Block(2,-2,0,DIRT)
Block(2,-2,1,DIRT)
Block(2,-2,2,DIRT)
Block(2,-2,3,DIRT)
Block(2,-2,4,DIRT)
Block(2,-2,5,DIRT)
Block(2,-1,-4,DIRT)
Block(2,-1,-3,DIRT)
Block(2,-1,-2,DIRT)
Block(2,-1,-1,DIRT)
Block(2,-1,0,DIRT)
Block(2,-1,1,DIRT)
Block(2,-1,2,DIRT)
Block(2,-1,3,DIRT)
Block(2,-1,4,DIRT)
Block(2,-1,5,DIRT)
Block(2,0,-4,DIRT)
Block(2,0,-3,GRASS)
Block(2,0,-2,GRASS)
RandomBlock(2,0,-1,FLOWER_POT,../../nbt/Misc/FlowerPot2.nbt,22,FLOWER_POT,../../nbt/Misc/FlowerPot3.nbt,22,FLOWER_POT,../../nbt/Misc/FlowerPot81.nbt,22,FLOWER_POT,../../nbt/Misc/FlowerPot4.nbt,22,FLOWER_POT,../../nbt/Misc/FlowerPot5.nbt,22,FLOWER_POT,../../nbt/Misc/FlowerPot6.nbt,22,FLOWER_POT,../../nbt/Misc/FlowerPot7.nbt,22,FLOWER_POT,../../nbt/Misc/FlowerPot8.nbt,100)
Block(2,0,0,GRAVEL)
Block(2,0,1,GRAVEL)
Block(2,0,2,GRAVEL)
Block(2,0,3,GRAVEL)
Block(2,0,4,GRASS)
Block(2,0,5,DIRT)
Block(2,1,-4,SMOOTH_BRICK:2)
Block(2,1,-3,AIR)
RandomBlock(2,1,-2,FLOWER_POT,../../nbt/Misc/FlowerPot2.nbt,22,FLOWER_POT,../../nbt/Misc/FlowerPot3.nbt,22,FLOWER_POT,../../nbt/Misc/FlowerPot81.nbt,22,FLOWER_POT,../../nbt/Misc/FlowerPot4.nbt,22,FLOWER_POT,../../nbt/Misc/FlowerPot5.nbt,22,FLOWER_POT,../../nbt/Misc/FlowerPot6.nbt,22,FLOWER_POT,../../nbt/Misc/FlowerPot7.nbt,22,FLOWER_POT,../../nbt/Misc/FlowerPot8.nbt,100)
Block(2,1,-1,SMOOTH_BRICK:3)
Block(2,1,0,AIR)
Block(2,1,1,AIR)
Block(2,1,2,AIR)
RandomBlock(2,1,3,FLOWER_POT,../../nbt/Misc/FlowerPot2.nbt,22,FLOWER_POT,../../nbt/Misc/FlowerPot3.nbt,22,FLOWER_POT,../../nbt/Misc/FlowerPot81.nbt,22,FLOWER_POT,../../nbt/Misc/FlowerPot4.nbt,22,FLOWER_POT,../../nbt/Misc/FlowerPot5.nbt,22,FLOWER_POT,../../nbt/Misc/FlowerPot6.nbt,22,FLOWER_POT,../../nbt/Misc/FlowerPot7.nbt,22,FLOWER_POT,../../nbt/Misc/FlowerPot8.nbt,100)
Block(2,1,4,LONG_GRASS:1)
Block(2,1,5,SMOOTH_BRICK:1)
Block(2,2,-4,SMOOTH_BRICK:1)
Block(2,2,-3,AIR)
Block(2,2,-2,AIR)
Block(2,2,-1,COBBLE_WALL)
Block(2,2,0,AIR)
Block(2,2,1,AIR)
Block(2,2,2,AIR)
Block(2,2,3,AIR)
Block(2,2,4,AIR)
Block(2,2,5,SMOOTH_BRICK)
Block(2,3,-4,SMOOTH_BRICK:2)
Block(2,3,-3,AIR)
Block(2,3,-2,AIR)
Block(2,3,-1,COBBLE_WALL:1)
Block(2,3,0,AIR)
Block(2,3,1,AIR)
Block(2,3,2,AIR)
Block(2,3,3,AIR)
Block(2,3,4,AIR)
Block(2,3,5,SMOOTH_BRICK)
Block(2,4,-4,AIR)
Block(2,4,-3,AIR)
Block(2,4,-2,COBBLE_WALL:1)
Block(2,4,-1,COBBLE_WALL:1)
Block(2,4,0,COBBLE_WALL)
Block(2,4,1,AIR)
Block(2,4,2,AIR)
Block(2,4,3,AIR)
Block(2,4,4,AIR)
Block(2,4,5,AIR)
Block(2,5,-4,AIR)
Block(2,5,-3,AIR)
Block(2,5,-2,AIR)
Block(2,5,-1,COBBLE_WALL)
Block(2,5,0,AIR)
Block(2,5,1,AIR)
Block(2,5,2,AIR)
Block(2,5,3,AIR)
Block(2,5,4,AIR)
Block(2,5,5,AIR)
Block(3,-8,-4,STONE)
Block(3,-8,-3,STONE)
Block(3,-8,-2,STONE)
Block(3,-8,-1,STONE)
Block(3,-8,0,STONE)
Block(3,-8,1,STONE)
Block(3,-8,2,STONE)
Block(3,-8,3,STONE)
Block(3,-8,4,STONE)
Block(3,-8,5,STONE)
Block(3,-7,-4,STONE)
Block(3,-7,-3,STONE)
Block(3,-7,-2,STONE)
Block(3,-7,-1,STONE)
Block(3,-7,0,STONE)
Block(3,-7,1,STONE)
Block(3,-7,2,STONE)
Block(3,-7,3,STONE)
Block(3,-7,4,STONE)
Block(3,-7,5,STONE)
Block(3,-6,-4,STONE)
Block(3,-6,-3,STONE)
Block(3,-6,-2,STONE)
Block(3,-6,-1,STONE)
Block(3,-6,0,STONE)
Block(3,-6,1,STONE)
Block(3,-6,2,STONE)
Block(3,-6,3,STONE)
Block(3,-6,4,STONE)
Block(3,-6,5,STONE)
Block(3,-5,-4,STONE)
Block(3,-5,-3,STONE)
Block(3,-5,-2,STONE)
Block(3,-5,-1,STONE)
Block(3,-5,0,STONE)
Block(3,-5,1,STONE)
Block(3,-5,2,STONE)
Block(3,-5,3,STONE)
Block(3,-5,4,STONE)
Block(3,-5,5,STONE)
Block(3,-4,-4,STONE)
Block(3,-4,-3,STONE)
Block(3,-4,-2,STONE)
Block(3,-4,-1,STONE)
Block(3,-4,0,STONE)
Block(3,-4,1,STONE)
Block(3,-4,2,STONE)
Block(3,-4,3,STONE)
Block(3,-4,4,STONE)
Block(3,-4,5,STONE)
Block(3,-3,-4,STONE)
Block(3,-3,-3,STONE)
Block(3,-3,-2,STONE)
Block(3,-3,-1,STONE)
Block(3,-3,0,STONE)
Block(3,-3,1,STONE)
Block(3,-3,2,STONE)
Block(3,-3,3,STONE)
Block(3,-3,4,STONE)
Block(3,-3,5,STONE)
Block(3,-2,-4,DIRT)
Block(3,-2,-3,DIRT)
Block(3,-2,-2,DIRT)
Block(3,-2,-1,DIRT)
Block(3,-2,0,DIRT)
Block(3,-2,1,DIRT)
Block(3,-2,2,DIRT)
Block(3,-2,3,DIRT)
Block(3,-2,4,DIRT)
Block(3,-2,5,DIRT)
Block(3,-1,-4,DIRT)
Block(3,-1,-3,DIRT)
Block(3,-1,-2,DIRT)
Block(3,-1,-1,DIRT)
Block(3,-1,0,DIRT)
Block(3,-1,1,DIRT)
Block(3,-1,2,DIRT)
Block(3,-1,3,DIRT)
Block(3,-1,4,DIRT)
Block(3,-1,5,DIRT)
Block(3,0,-4,DIRT:2)
Block(3,0,-3,GRASS)
Block(3,0,-2,DIRT:2)
Block(3,0,-1,GRASS)
Block(3,0,0,GRAVEL)
Block(3,0,1,GRAVEL)
Block(3,0,2,DIRT:2)
Block(3,0,3,DIRT:2)
Block(3,0,4,GRASS)
Block(3,0,5,GRAVEL)
Block(3,1,-4,IRON_FENCE)
Block(3,1,-3,DOUBLE_PLANT:2)
Block(3,1,-2,AIR)
Block(3,1,-1,DOUBLE_PLANT:2)
Block(3,1,0,AIR)
Block(3,1,1,AIR)
Block(3,1,2,AIR)
Block(3,1,3,AIR)
Block(3,1,4,LONG_GRASS:1)
Block(3,1,5,IRON_FENCE)
Block(3,2,-4,IRON_FENCE)
Block(3,2,-3,DOUBLE_PLANT:8)
Block(3,2,-2,AIR)
Block(3,2,-1,DOUBLE_PLANT:8)
Block(3,2,0,AIR)
Block(3,2,1,AIR)
Block(3,2,2,AIR)
Block(3,2,3,AIR)
Block(3,2,4,AIR)
Block(3,2,5,IRON_FENCE)
Block(3,3,-4,IRON_FENCE)
Block(3,3,-3,AIR)
Block(3,3,-2,AIR)
Block(3,3,-1,AIR)
Block(3,3,0,AIR)
Block(3,3,1,AIR)
Block(3,3,2,AIR)
Block(3,3,3,AIR)
Block(3,3,4,AIR)
Block(3,3,5,IRON_FENCE)
Block(3,4,-4,STEP:5)
Block(3,4,-3,AIR)
Block(3,4,-2,AIR)
Block(3,4,-1,AIR)
Block(3,4,0,AIR)
Block(3,4,1,AIR)
Block(3,4,2,AIR)
Block(3,4,3,AIR)
Block(3,4,4,AIR)
Block(3,4,5,STEP:5)
Block(3,5,-4,AIR)
Block(3,5,-3,AIR)
Block(3,5,-2,AIR)
Block(3,5,-1,AIR)
Block(3,5,0,AIR)
Block(3,5,1,AIR)
Block(3,5,2,AIR)
Block(3,5,3,AIR)
Block(3,5,4,AIR)
Block(3,5,5,AIR)
Block(4,-8,-4,STONE)
Block(4,-8,-3,STONE)
Block(4,-8,-2,STONE)
Block(4,-8,-1,STONE)
Block(4,-8,0,STONE)
Block(4,-8,1,STONE)
Block(4,-8,2,STONE)
Block(4,-8,3,STONE)
Block(4,-8,4,STONE)
Block(4,-8,5,STONE)
Block(4,-7,-4,STONE)
Block(4,-7,-3,STONE)
Block(4,-7,-2,STONE)
Block(4,-7,-1,STONE)
Block(4,-7,0,STONE)
Block(4,-7,1,STONE)
Block(4,-7,2,STONE)
Block(4,-7,3,STONE)
Block(4,-7,4,STONE)
Block(4,-7,5,STONE)
Block(4,-6,-4,STONE)
Block(4,-6,-3,STONE)
Block(4,-6,-2,STONE)
Block(4,-6,-1,STONE)
Block(4,-6,0,STONE)
Block(4,-6,1,STONE)
Block(4,-6,2,STONE)
Block(4,-6,3,STONE)
Block(4,-6,4,STONE)
Block(4,-6,5,STONE)
Block(4,-5,-4,STONE)
Block(4,-5,-3,STONE)
Block(4,-5,-2,STONE)
Block(4,-5,-1,STONE)
Block(4,-5,0,STONE)
Block(4,-5,1,STONE)
Block(4,-5,2,STONE)
Block(4,-5,3,STONE)
Block(4,-5,4,STONE)
Block(4,-5,5,STONE)
Block(4,-4,-4,STONE)
Block(4,-4,-3,STONE)
Block(4,-4,-2,STONE)
Block(4,-4,-1,STONE)
Block(4,-4,0,STONE)
Block(4,-4,1,STONE)
Block(4,-4,2,STONE)
Block(4,-4,3,STONE)
Block(4,-4,4,STONE)
Block(4,-4,5,STONE)
Block(4,-3,-4,STONE)
Block(4,-3,-3,STONE)
Block(4,-3,-2,STONE)
Block(4,-3,-1,STONE)
Block(4,-3,0,STONE)
Block(4,-3,1,STONE)
Block(4,-3,2,STONE)
Block(4,-3,3,STONE)
Block(4,-3,4,STONE)
Block(4,-3,5,STONE)
Block(4,-2,-4,DIRT)
Block(4,-2,-3,DIRT)
Block(4,-2,-2,DIRT)
Block(4,-2,-1,DIRT)
Block(4,-2,0,DIRT)
Block(4,-2,1,DIRT)
Block(4,-2,2,DIRT)
Block(4,-2,3,DIRT)
Block(4,-2,4,DIRT)
Block(4,-2,5,DIRT)
Block(4,-1,-4,DIRT)
Block(4,-1,-3,DIRT)
Block(4,-1,-2,DIRT)
Block(4,-1,-1,DIRT)
Block(4,-1,0,DIRT)
Block(4,-1,1,DIRT)
Block(4,-1,2,DIRT)
Block(4,-1,3,DIRT)
Block(4,-1,4,DIRT)
Block(4,-1,5,DIRT)
Block(4,0,-4,GRAVEL)
Block(4,0,-3,GRASS)
Block(4,0,-2,STONE)
Block(4,0,-1,GRAVEL)
Block(4,0,0,DIRT:2)
Block(4,0,1,DIRT)
Block(4,0,2,DIRT:2)
Block(4,0,3,GRAVEL)
Block(4,0,4,GRASS)
Block(4,0,5,GRAVEL)
Block(4,1,-4,SMOOTH_BRICK:2)
Block(4,1,-3,IRON_FENCE)
Block(4,1,-2,SMOOTH_BRICK)
Block(4,1,-1,IRON_FENCE)
Block(4,1,0,IRON_FENCE)
Block(4,1,1,IRON_FENCE)
Block(4,1,2,IRON_FENCE)
Block(4,1,3,SMOOTH_BRICK:2)
Block(4,1,4,IRON_FENCE)
Block(4,1,5,SMOOTH_BRICK:1)
Block(4,2,-4,SMOOTH_BRICK:2)
Block(4,2,-3,IRON_FENCE)
Block(4,2,-2,SMOOTH_BRICK:2)
Block(4,2,-1,IRON_FENCE)
Block(4,2,0,IRON_FENCE)
Block(4,2,1,IRON_FENCE)
Block(4,2,2,IRON_FENCE)
Block(4,2,3,SMOOTH_BRICK:2)
Block(4,2,4,IRON_FENCE)
Block(4,2,5,SMOOTH_BRICK:2)
Block(4,3,-4,SMOOTH_BRICK)
Block(4,3,-3,IRON_FENCE)
Block(4,3,-2,SMOOTH_BRICK:1)
Block(4,3,-1,IRON_FENCE)
Block(4,3,0,IRON_FENCE)
Block(4,3,1,IRON_FENCE)
Block(4,3,2,IRON_FENCE)
Block(4,3,3,SMOOTH_BRICK)
Block(4,3,4,IRON_FENCE)
Block(4,3,5,SMOOTH_BRICK:1)
Block(4,4,-4,AIR)
Block(4,4,-3,STEP:5)
Block(4,4,-2,AIR)
Block(4,4,-1,STEP:5)
Block(4,4,0,STEP:5)
Block(4,4,1,STEP:5)
Block(4,4,2,STEP:5)
Block(4,4,3,AIR)
Block(4,4,4,STEP:5)
Block(4,4,5,AIR)
Block(4,5,-4,AIR)
Block(4,5,-3,AIR)
Block(4,5,-2,AIR)
Block(4,5,-1,AIR)
Block(4,5,0,AIR)
Block(4,5,1,AIR)
Block(4,5,2,AIR)
Block(4,5,3,AIR)
Block(4,5,4,AIR)
Block(4,5,5,AIR)

#######################################################################
# +-----------------------------------------------------------------+ #
# |                            BO3 checks                           | #
# +-----------------------------------------------------------------+ #
#######################################################################

# Require a condition at a certain location in order for the BO3 to be spawned.
# BlockCheck(x,y,z,BlockName[,BlockName[,...]]) - one of the blocks must be at the location
# BlockCheckNot(x,y,z,BlockName[,BlockName[,...]]) - all the blocks must not be at the location
# LightCheck(x,y,z,minLightLevel,maxLightLevel) - light must be between min and max (inclusive)

# You can use "Solid" as a BlockName for matching all solid blocks or "All" to match all blocks that aren't air.

# Examples:
#   BlockCheck(0,-1,0,GRASS,DIRT)  Require grass or dirt just below the object
#   BlockCheck(0,-1,0,Solid)       Require any solid block just below the object
#   BlockCheck(0,-1,0,WOOL)        Require any type of wool just below the object
#   BlockCheck(0,-1,0,WOOL:0)      Require white wool just below the object
#   BlockCheckNot(0,0,0,WOOL:0)   Require that there is no white wool below the object
#   LightCheck(0,0,0,0,1)          Require almost complete darkness just below the object
BlockCheck(0,-1,0,GRASS,DIRT)
#######################################################################
# +-----------------------------------------------------------------+ #
# |                             Branches                            | #
# +-----------------------------------------------------------------+ #
#######################################################################

# Branches are objects that will spawn when this object spawns when it is used in
# the CustomStructure resource. Branches can also have branches, making complex
# structures possible. See the wiki for more details.

# Regular Branches spawn each branch with an independent chance of spawning.
# Branch(x,y,z,branchName,rotation,chance[,anotherBranchName,rotation,chance[,...]][IndividualChance])
# branchName - name of the object to spawn.
# rotation - NORTH, SOUTH, EAST or WEST.
# IndividualChance - The chance each branch has to spawn, assumed to be 100 when left blank

# Weighted Branches spawn branches with a dependent chance of spawning.
# WeightedBranch(x,y,z,branchName,rotation,chance[,anotherBranchName,rotation,chance[,...]][MaxChanceOutOf])
# MaxChanceOutOf - The chance all branches have to spawn out of, assumed to be 100 when left blank
