
#######################################################################
# +-----------------------------------------------------------------+ #
# |                            BO3 object                           | #
# +-----------------------------------------------------------------+ #
#######################################################################

# This is the config file of a custom object.
# If you add this object correctly to your BiomeConfigs, it will spawn in the world.

# This is the creator of this BO3 object
Author: LordSmellyPants

# A short description of this BO3 object
Description: Converted version of the BO2 RedCap3G

# The BO3 version, don't change this! It can be used by external applications to do a version check.
Version: 3

# The settings mode, WriteAll, WriteWithoutComments or WriteDisable. See WorldConfig.
SettingsMode: WriteDisable


#######################################################################
# +-----------------------------------------------------------------+ #
# |                          Main settings                          | #
# +-----------------------------------------------------------------+ #
#######################################################################

# This needs to be set to true to spawn the object in the Tree and Sapling resources.
Tree: false

# The frequency of the BO3 from 1 to 200. Tries this many times to spawn this BO3 when using the CustomObject(...) resource.
# Ignored by Tree(..), Sapling(..) and CustomStructure(..)
Frequency: 1

# The rarity of the BO3 from 0 to 100. Each spawn attempt has rarity% chance to succeed when using the CustomObject(...) resource.
# Ignored by Tree(..), Sapling(..) and CustomStructure(..)
Rarity: 1.0

# If you set this to true, the BO3 will be placed with a random rotation.
RotateRandomly: true

# The spawn height of the BO3 - randomY, highestBlock or highestSolidBlock.
SpawnHeight: highestSolidBlock

# The height limits for the BO3.
MinHeight: 50

MaxHeight: 150

# Objects can have other objects attacthed to it: branches. Branches can also
# have branches attached to it, which can also have branches, etc. This is the
# maximum branch depth for this objects.
MaxBranchDepth: 10

# When spawned with the UseWorld keyword, this BO3 should NOT spawn in the following biomes.
# If you writer.write the BO3 name directly in the BiomeConfigs, this will be ignored.
ExcludedBiomes: All 


#######################################################################
# +-----------------------------------------------------------------+ #
# |                      Source block settings                      | #
# +-----------------------------------------------------------------+ #
#######################################################################

# The block(s) the BO3 should spawn in.
SourceBlocks: AIR

# The maximum percentage of the BO3 that can be outside the SourceBlock.
# The BO3 won't be placed on a location with more blocks outside the SourceBlock than this percentage.
MaxPercentageOutsideSourceBlock: 60

# What to do when a block is about to be placed outside the SourceBlock? (dontPlace, placeAnyway)
OutsideSourceBlock: placeAnyway


#######################################################################
# +-----------------------------------------------------------------+ #
# |                              Blocks                             | #
# +-----------------------------------------------------------------+ #
#######################################################################

# All the blocks used in the BO3 are listed here. Possible blocks:
# Block(x,y,z,id[.data][,nbtfile.nbt)
# RandomBlock(x,y,z,id[:data][,nbtfile.nbt],chance[,id[:data][,nbtfile.nbt],chance[,...]])
# So RandomBlock(0,0,0,CHEST,chest.nbt,50,CHEST,anotherchest.nbt,100) will spawn a chest at
# the BO3 origin, and give it a 50% chance to have the contents of chest.nbt, or, if that
# fails, a 100% percent chance to have the contents of anotherchest.nbt.
Block(-11,19,-1,HUGE_MUSHROOM_2:14)
Block(7,20,-5,HUGE_MUSHROOM_2:14)
Block(-11,15,-1,HUGE_MUSHROOM_2:14)
Block(-11,16,-1,HUGE_MUSHROOM_2:14)
Block(-11,17,-1,HUGE_MUSHROOM_2:14)
Block(3,15,-12,HUGE_MUSHROOM_2:14)
Block(6,17,5,HUGE_MUSHROOM_2:14)
Block(3,18,-12,HUGE_MUSHROOM_2:14)
Block(3,16,-12,HUGE_MUSHROOM_2:14)
Block(6,18,5,HUGE_MUSHROOM_2:14)
Block(3,17,-12,HUGE_MUSHROOM_2:14)
Block(6,19,5,HUGE_MUSHROOM_2:14)
Block(2,20,4,HUGE_MUSHROOM_2:14)
Block(2,21,4,HUGE_MUSHROOM_2:14)
Block(-5,19,7,HUGE_MUSHROOM_2:14)
Block(-8,17,6,HUGE_MUSHROOM_2:14)
Block(-8,16,6,HUGE_MUSHROOM_2:14)
Block(-8,19,6,HUGE_MUSHROOM_2:14)
Block(-8,15,6,HUGE_MUSHROOM_2:14)
Block(-5,20,7,HUGE_MUSHROOM_2:14)
Block(-4,21,5,HUGE_MUSHROOM_2:14)
Block(-4,20,5,HUGE_MUSHROOM_2:14)
Block(4,21,-2,HUGE_MUSHROOM_2:14)
Block(12,15,-4,HUGE_MUSHROOM_2:14)
Block(12,16,-4,HUGE_MUSHROOM_2:14)
Block(4,20,-2,HUGE_MUSHROOM_2:14)
Block(-5,17,7,HUGE_MUSHROOM_2:14)
Block(1,10,2,HUGE_MUSHROOM_1:10)
Block(1,11,2,HUGE_MUSHROOM_1:10)
Block(2,21,-5,HUGE_MUSHROOM_2:14)
Block(2,20,-5,HUGE_MUSHROOM_2:14)
Block(-4,19,5,HUGE_MUSHROOM_2:14)
Block(6,20,5,HUGE_MUSHROOM_2:14)
Block(7,15,7,HUGE_MUSHROOM_2:14)
Block(7,16,7,HUGE_MUSHROOM_2:14)
Block(7,17,7,HUGE_MUSHROOM_2:14)
Block(7,19,7,HUGE_MUSHROOM_2:14)
Block(-4,15,-10,HUGE_MUSHROOM_2:14)
Block(-4,17,-10,HUGE_MUSHROOM_2:14)
Block(-4,16,-10,HUGE_MUSHROOM_2:14)
Block(0,5,0,HUGE_MUSHROOM_1:10)
Block(-4,19,-10,HUGE_MUSHROOM_2:14)
Block(0,4,0,HUGE_MUSHROOM_1:10)
Block(0,7,0,HUGE_MUSHROOM_1:10)
Block(-5,21,-4,HUGE_MUSHROOM_2:14)
Block(0,6,0,HUGE_MUSHROOM_1:10)
Block(-1,17,-10,HUGE_MUSHROOM_2:14)
Block(-1,16,-10,HUGE_MUSHROOM_2:14)
Block(-10,15,-6,HUGE_MUSHROOM_2:14)
Block(-1,19,-10,HUGE_MUSHROOM_2:14)
Block(-11,15,0,HUGE_MUSHROOM_2:14)
Block(9,20,-2,HUGE_MUSHROOM_2:14)
Block(-10,16,-6,HUGE_MUSHROOM_2:14)
Block(-10,17,-6,HUGE_MUSHROOM_2:14)
Block(-3,21,3,HUGE_MUSHROOM_2:14)
Block(-10,18,-6,HUGE_MUSHROOM_2:14)
Block(-3,20,3,HUGE_MUSHROOM_2:14)
Block(-10,19,-6,HUGE_MUSHROOM_2:14)
Block(-1,20,-10,HUGE_MUSHROOM_2:14)
Block(-11,19,0,HUGE_MUSHROOM_2:14)
Block(-8,20,-7,HUGE_MUSHROOM_2:14)
Block(-11,16,0,HUGE_MUSHROOM_2:14)
Block(-11,17,0,HUGE_MUSHROOM_2:14)
Block(-5,19,-4,HUGE_MUSHROOM_2:14)
Block(9,17,-2,HUGE_MUSHROOM_2:14)
Block(-8,19,-7,HUGE_MUSHROOM_2:14)
Block(1,20,2,HUGE_MUSHROOM_2:14)
Block(1,21,2,HUGE_MUSHROOM_2:14)
Block(9,19,-2,HUGE_MUSHROOM_2:14)
Block(-5,20,-4,HUGE_MUSHROOM_2:14)
Block(3,18,6,HUGE_MUSHROOM_2:14)
Block(3,19,6,HUGE_MUSHROOM_2:14)
Block(-8,16,-7,HUGE_MUSHROOM_2:14)
Block(7,17,-11,HUGE_MUSHROOM_2:14)
Block(-8,17,-7,HUGE_MUSHROOM_2:14)
Block(7,16,-11,HUGE_MUSHROOM_2:14)
Block(6,18,-3,HUGE_MUSHROOM_2:14)
Block(5,19,-8,HUGE_MUSHROOM_2:14)
Block(3,20,6,HUGE_MUSHROOM_2:14)
Block(3,21,6,HUGE_MUSHROOM_2:14)
Block(5,17,-8,HUGE_MUSHROOM_2:14)
Block(8,19,2,HUGE_MUSHROOM_2:14)
Block(4,19,1,HUGE_MUSHROOM_2:14)
Block(8,17,2,HUGE_MUSHROOM_2:14)
Block(-2,21,-5,HUGE_MUSHROOM_2:14)
Block(10,19,-3,HUGE_MUSHROOM_2:14)
Block(6,19,-3,HUGE_MUSHROOM_2:14)
Block(-2,20,-5,HUGE_MUSHROOM_2:14)
Block(-9,20,-2,HUGE_MUSHROOM_2:14)
Block(8,18,-10,HUGE_MUSHROOM_2:14)
Block(10,20,-3,HUGE_MUSHROOM_2:14)
Block(8,17,-10,HUGE_MUSHROOM_2:14)
Block(8,16,-10,HUGE_MUSHROOM_2:14)
Block(8,15,-10,HUGE_MUSHROOM_2:14)
Block(-1,21,6,HUGE_MUSHROOM_2:14)
Block(-1,20,6,HUGE_MUSHROOM_2:14)
Block(-9,19,-2,HUGE_MUSHROOM_2:14)
Block(-9,17,-2,HUGE_MUSHROOM_2:14)
Block(10,17,-3,HUGE_MUSHROOM_2:14)
Block(10,16,-3,HUGE_MUSHROOM_2:14)
Block(10,15,-3,HUGE_MUSHROOM_2:14)
Block(0,9,0,HUGE_MUSHROOM_1:10)
Block(0,8,0,HUGE_MUSHROOM_1:10)
Block(5,20,-8,HUGE_MUSHROOM_2:14)
Block(-1,19,6,HUGE_MUSHROOM_2:14)
Block(8,20,2,HUGE_MUSHROOM_2:14)
Block(9,20,0,HUGE_MUSHROOM_2:14)
Block(4,0,1,HUGE_MUSHROOM_1:10)
Block(-2,21,1,HUGE_MUSHROOM_2:14)
Block(-2,20,1,HUGE_MUSHROOM_2:14)
Block(4,2,1,HUGE_MUSHROOM_1:10)
Block(4,1,1,HUGE_MUSHROOM_1:10)
Block(3,1,3,HUGE_MUSHROOM_1:10)
Block(3,0,3,HUGE_MUSHROOM_1:10)
Block(-7,19,-1,HUGE_MUSHROOM_2:14)
Block(7,19,0,HUGE_MUSHROOM_2:14)
Block(7,18,0,HUGE_MUSHROOM_2:14)
Block(10,17,2,HUGE_MUSHROOM_2:14)
Block(10,16,2,HUGE_MUSHROOM_2:14)
Block(10,19,2,HUGE_MUSHROOM_2:14)
Block(10,18,2,HUGE_MUSHROOM_2:14)
Block(9,19,-6,HUGE_MUSHROOM_2:14)
Block(10,15,2,HUGE_MUSHROOM_2:14)
Block(3,18,-7,HUGE_MUSHROOM_2:14)
Block(3,19,-7,HUGE_MUSHROOM_2:14)
Block(6,21,-3,HUGE_MUSHROOM_2:14)
Block(6,20,-3,HUGE_MUSHROOM_2:14)
Block(9,17,-6,HUGE_MUSHROOM_2:14)
Block(9,16,-6,HUGE_MUSHROOM_2:14)
Block(9,15,-6,HUGE_MUSHROOM_2:14)
Block(3,20,-7,HUGE_MUSHROOM_2:14)
Block(5,19,-4,HUGE_MUSHROOM_2:14)
Block(0,19,0,HUGE_MUSHROOM_1:10)
Block(-2,20,-1,HUGE_MUSHROOM_2:14)
Block(3,21,-7,HUGE_MUSHROOM_2:14)
Block(0,21,0,HUGE_MUSHROOM_2:14)
Block(0,20,0,HUGE_MUSHROOM_2:14)
Block(-2,18,1,HUGE_MUSHROOM_1:10)
Block(-2,17,1,HUGE_MUSHROOM_1:10)
Block(-2,19,1,HUGE_MUSHROOM_1:10)
Block(0,14,0,HUGE_MUSHROOM_1:10)
Block(0,13,0,HUGE_MUSHROOM_1:10)
Block(10,18,-7,HUGE_MUSHROOM_2:14)
Block(9,19,0,HUGE_MUSHROOM_2:14)
Block(0,12,0,HUGE_MUSHROOM_1:10)
Block(9,16,0,HUGE_MUSHROOM_2:14)
Block(0,11,0,HUGE_MUSHROOM_1:10)
Block(9,17,0,HUGE_MUSHROOM_2:14)
Block(10,15,-7,HUGE_MUSHROOM_2:14)
Block(0,18,0,HUGE_MUSHROOM_1:10)
Block(-7,21,-1,HUGE_MUSHROOM_2:14)
Block(0,17,0,HUGE_MUSHROOM_1:10)
Block(-7,20,-1,HUGE_MUSHROOM_2:14)
Block(0,16,0,HUGE_MUSHROOM_1:10)
Block(10,17,-7,HUGE_MUSHROOM_2:14)
Block(0,15,0,HUGE_MUSHROOM_1:10)
Block(10,16,-7,HUGE_MUSHROOM_2:14)
Block(4,15,-11,HUGE_MUSHROOM_2:14)
Block(0,10,0,HUGE_MUSHROOM_1:10)
Block(4,18,-11,HUGE_MUSHROOM_2:14)
Block(5,21,-4,HUGE_MUSHROOM_2:14)
Block(4,19,-11,HUGE_MUSHROOM_2:14)
Block(5,20,-4,HUGE_MUSHROOM_2:14)
Block(4,16,-11,HUGE_MUSHROOM_2:14)
Block(4,17,-11,HUGE_MUSHROOM_2:14)
Block(2,10,0,HUGE_MUSHROOM_1:10)
Block(2,11,0,HUGE_MUSHROOM_1:10)
Block(2,12,0,HUGE_MUSHROOM_1:10)
Block(2,13,0,HUGE_MUSHROOM_1:10)
Block(2,14,0,HUGE_MUSHROOM_1:10)
Block(2,15,0,HUGE_MUSHROOM_1:10)
Block(0,18,-8,HUGE_MUSHROOM_2:14)
Block(0,19,-8,HUGE_MUSHROOM_2:14)
Block(5,20,3,HUGE_MUSHROOM_2:14)
Block(5,21,3,HUGE_MUSHROOM_2:14)
Block(-4,21,-2,HUGE_MUSHROOM_2:14)
Block(-4,20,-2,HUGE_MUSHROOM_2:14)
Block(3,19,10,HUGE_MUSHROOM_2:14)
Block(2,20,0,HUGE_MUSHROOM_2:14)
Block(2,21,0,HUGE_MUSHROOM_2:14)
Block(5,18,3,HUGE_MUSHROOM_2:14)
Block(3,15,10,HUGE_MUSHROOM_2:14)
Block(-9,17,-9,HUGE_MUSHROOM_2:14)
Block(3,16,10,HUGE_MUSHROOM_2:14)
Block(-9,18,-9,HUGE_MUSHROOM_2:14)
Block(3,17,10,HUGE_MUSHROOM_2:14)
Block(-9,20,1,HUGE_MUSHROOM_2:14)
Block(-9,16,-9,HUGE_MUSHROOM_2:14)
Block(5,19,3,HUGE_MUSHROOM_2:14)
Block(-7,20,4,HUGE_MUSHROOM_2:14)
Block(0,21,-8,HUGE_MUSHROOM_2:14)
Block(-1,21,-3,HUGE_MUSHROOM_2:14)
Block(-1,20,-3,HUGE_MUSHROOM_2:14)
Block(6,16,10,HUGE_MUSHROOM_2:14)
Block(-2,21,-1,HUGE_MUSHROOM_2:14)
Block(6,17,10,HUGE_MUSHROOM_2:14)
Block(-4,19,-2,AIR)
Block(-7,19,4,HUGE_MUSHROOM_2:14)
Block(-7,17,4,HUGE_MUSHROOM_2:14)
Block(0,20,-8,HUGE_MUSHROOM_2:14)
Block(12,17,-4,HUGE_MUSHROOM_2:14)
Block(-6,17,9,HUGE_MUSHROOM_2:14)
Block(12,18,-4,HUGE_MUSHROOM_2:14)
Block(-6,18,9,HUGE_MUSHROOM_2:14)
Block(0,16,11,HUGE_MUSHROOM_2:14)
Block(-9,19,1,HUGE_MUSHROOM_2:14)
Block(0,15,11,HUGE_MUSHROOM_2:14)
Block(-6,15,9,HUGE_MUSHROOM_2:14)
Block(-9,17,1,HUGE_MUSHROOM_2:14)
Block(0,18,11,HUGE_MUSHROOM_2:14)
Block(-6,16,9,HUGE_MUSHROOM_2:14)
Block(0,17,11,HUGE_MUSHROOM_2:14)
Block(4,20,-6,HUGE_MUSHROOM_2:14)
Block(4,21,-6,HUGE_MUSHROOM_2:14)
Block(-4,21,1,HUGE_MUSHROOM_2:14)
Block(-4,20,1,HUGE_MUSHROOM_2:14)
Block(11,18,-5,HUGE_MUSHROOM_2:14)
Block(11,17,-5,HUGE_MUSHROOM_2:14)
Block(7,21,0,HUGE_MUSHROOM_2:14)
Block(11,16,-5,HUGE_MUSHROOM_2:14)
Block(11,15,-5,HUGE_MUSHROOM_2:14)
Block(4,17,8,HUGE_MUSHROOM_2:14)
Block(7,20,0,HUGE_MUSHROOM_2:14)
Block(8,17,-4,HUGE_MUSHROOM_2:14)
Block(4,19,8,HUGE_MUSHROOM_2:14)
Block(1,19,6,HUGE_MUSHROOM_2:14)
Block(8,19,-4,HUGE_MUSHROOM_2:14)
Block(4,20,8,HUGE_MUSHROOM_2:14)
Block(7,19,-5,HUGE_MUSHROOM_2:14)
Block(7,17,-5,HUGE_MUSHROOM_2:14)
Block(8,20,-4,HUGE_MUSHROOM_2:14)
Block(11,19,-5,HUGE_MUSHROOM_2:14)
Block(4,18,-6,HUGE_MUSHROOM_2:14)
Block(4,19,-6,HUGE_MUSHROOM_2:14)
Block(-6,19,5,HUGE_MUSHROOM_2:14)
Block(-7,16,8,HUGE_MUSHROOM_2:14)
Block(-7,15,8,HUGE_MUSHROOM_2:14)
Block(-6,18,5,HUGE_MUSHROOM_2:14)
Block(-7,18,8,HUGE_MUSHROOM_2:14)
Block(-7,17,8,HUGE_MUSHROOM_2:14)
Block(-7,19,8,HUGE_MUSHROOM_2:14)
Block(-7,17,-9,HUGE_MUSHROOM_2:14)
Block(6,20,-6,HUGE_MUSHROOM_2:14)
Block(-7,19,-9,HUGE_MUSHROOM_2:14)
Block(-7,16,-9,HUGE_MUSHROOM_2:14)
Block(-7,15,-9,HUGE_MUSHROOM_2:14)
Block(-6,20,5,HUGE_MUSHROOM_2:14)
Block(0,21,-1,HUGE_MUSHROOM_2:14)
Block(0,20,-1,HUGE_MUSHROOM_2:14)
Block(5,20,7,HUGE_MUSHROOM_2:14)
Block(-10,19,-2,HUGE_MUSHROOM_2:14)
Block(-10,16,-2,HUGE_MUSHROOM_2:14)
Block(-10,17,-2,HUGE_MUSHROOM_2:14)
Block(5,19,7,HUGE_MUSHROOM_2:14)
Block(5,17,7,HUGE_MUSHROOM_2:14)
Block(6,17,-6,HUGE_MUSHROOM_2:14)
Block(6,19,-6,HUGE_MUSHROOM_2:14)
Block(-8,19,-3,HUGE_MUSHROOM_2:14)
Block(-8,18,-3,HUGE_MUSHROOM_2:14)
Block(1,19,-11,HUGE_MUSHROOM_2:14)
Block(1,17,-11,HUGE_MUSHROOM_2:14)
Block(5,21,-1,HUGE_MUSHROOM_2:14)
Block(-2,20,-9,HUGE_MUSHROOM_2:14)
Block(-1,19,10,HUGE_MUSHROOM_2:14)
Block(-1,15,10,HUGE_MUSHROOM_2:14)
Block(-1,16,10,HUGE_MUSHROOM_2:14)
Block(-1,17,10,HUGE_MUSHROOM_2:14)
Block(4,18,4,HUGE_MUSHROOM_2:14)
Block(-2,19,-9,HUGE_MUSHROOM_2:14)
Block(4,19,4,HUGE_MUSHROOM_2:14)
Block(-8,20,-3,HUGE_MUSHROOM_2:14)
Block(-8,21,-3,HUGE_MUSHROOM_2:14)
Block(2,16,-10,HUGE_MUSHROOM_2:14)
Block(5,20,-1,HUGE_MUSHROOM_2:14)
Block(0,16,-1,HUGE_MUSHROOM_1:10)
Block(0,15,-1,HUGE_MUSHROOM_1:10)
Block(0,18,-1,HUGE_MUSHROOM_1:10)
Block(0,17,-1,HUGE_MUSHROOM_1:10)
Block(0,19,-1,HUGE_MUSHROOM_1:10)
Block(7,19,-1,HUGE_MUSHROOM_2:14)
Block(-3,21,-3,HUGE_MUSHROOM_2:14)
Block(7,18,-1,HUGE_MUSHROOM_2:14)
Block(-3,20,-3,HUGE_MUSHROOM_2:14)
Block(-2,17,-9,HUGE_MUSHROOM_2:14)
Block(4,20,4,HUGE_MUSHROOM_2:14)
Block(4,21,4,HUGE_MUSHROOM_2:14)
Block(-1,19,2,HUGE_MUSHROOM_1:10)
Block(1,19,10,HUGE_MUSHROOM_2:14)
Block(1,17,10,HUGE_MUSHROOM_2:14)
Block(1,16,10,HUGE_MUSHROOM_2:14)
Block(1,15,10,HUGE_MUSHROOM_2:14)
Block(0,10,-1,HUGE_MUSHROOM_1:10)
Block(0,12,-1,HUGE_MUSHROOM_1:10)
Block(0,11,-1,HUGE_MUSHROOM_1:10)
Block(0,14,-1,HUGE_MUSHROOM_1:10)
Block(0,13,-1,HUGE_MUSHROOM_1:10)
Block(9,16,7,HUGE_MUSHROOM_2:14)
Block(9,17,7,HUGE_MUSHROOM_2:14)
Block(7,20,-1,HUGE_MUSHROOM_2:14)
Block(-10,18,5,HUGE_MUSHROOM_2:14)
Block(-6,20,-3,HUGE_MUSHROOM_2:14)
Block(-10,17,5,HUGE_MUSHROOM_2:14)
Block(-6,21,-3,HUGE_MUSHROOM_2:14)
Block(-10,16,5,HUGE_MUSHROOM_2:14)
Block(7,21,-1,HUGE_MUSHROOM_2:14)
Block(3,6,2,HUGE_MUSHROOM_1:10)
Block(2,17,-10,HUGE_MUSHROOM_2:14)
Block(3,5,2,HUGE_MUSHROOM_1:10)
Block(3,4,2,HUGE_MUSHROOM_1:10)
Block(2,19,-10,HUGE_MUSHROOM_2:14)
Block(3,3,2,HUGE_MUSHROOM_1:10)
Block(3,7,2,HUGE_MUSHROOM_1:10)
Block(7,19,4,HUGE_MUSHROOM_2:14)
Block(7,17,4,HUGE_MUSHROOM_2:14)
Block(-4,20,8,HUGE_MUSHROOM_2:14)
Block(2,20,-10,HUGE_MUSHROOM_2:14)
Block(-9,15,5,HUGE_MUSHROOM_2:14)
Block(-4,19,8,HUGE_MUSHROOM_2:14)
Block(-9,17,5,HUGE_MUSHROOM_2:14)
Block(-9,16,5,HUGE_MUSHROOM_2:14)
Block(-9,19,5,HUGE_MUSHROOM_2:14)
Block(3,21,-3,HUGE_MUSHROOM_2:14)
Block(4,0,0,HUGE_MUSHROOM_1:10)
Block(3,20,-3,HUGE_MUSHROOM_2:14)
Block(2,20,7,HUGE_MUSHROOM_2:14)
Block(5,15,-10,HUGE_MUSHROOM_2:14)
Block(3,2,2,HUGE_MUSHROOM_1:10)
Block(5,19,-10,HUGE_MUSHROOM_2:14)
Block(3,1,2,HUGE_MUSHROOM_1:10)
Block(3,0,2,HUGE_MUSHROOM_1:10)
Block(5,17,-10,HUGE_MUSHROOM_2:14)
Block(0,20,4,HUGE_MUSHROOM_2:14)
Block(5,16,-10,HUGE_MUSHROOM_2:14)
Block(0,21,4,HUGE_MUSHROOM_2:14)
Block(-4,19,-9,HUGE_MUSHROOM_2:14)
Block(-4,16,-9,HUGE_MUSHROOM_2:14)
Block(-4,17,-9,HUGE_MUSHROOM_2:14)
Block(-6,19,-3,HUGE_MUSHROOM_2:14)
Block(-2,19,5,HUGE_MUSHROOM_2:14)
Block(-2,21,5,HUGE_MUSHROOM_2:14)
Block(-2,20,5,HUGE_MUSHROOM_2:14)
Block(-4,20,-9,HUGE_MUSHROOM_2:14)
Block(11,19,0,HUGE_MUSHROOM_2:14)
Block(1,16,-3,HUGE_MUSHROOM_1:10)
Block(1,20,9,HUGE_MUSHROOM_2:14)
Block(1,17,-3,HUGE_MUSHROOM_1:10)
Block(1,18,-3,HUGE_MUSHROOM_1:10)
Block(7,20,-8,HUGE_MUSHROOM_2:14)
Block(1,19,-3,HUGE_MUSHROOM_1:10)
Block(-10,15,1,HUGE_MUSHROOM_2:14)
Block(-3,15,10,HUGE_MUSHROOM_2:14)
Block(11,16,0,HUGE_MUSHROOM_2:14)
Block(-3,16,10,HUGE_MUSHROOM_2:14)
Block(11,15,0,HUGE_MUSHROOM_2:14)
Block(-3,17,10,HUGE_MUSHROOM_2:14)
Block(11,18,0,HUGE_MUSHROOM_2:14)
Block(-3,18,10,HUGE_MUSHROOM_2:14)
Block(11,17,0,HUGE_MUSHROOM_2:14)
Block(-3,19,10,HUGE_MUSHROOM_2:14)
Block(0,15,-12,HUGE_MUSHROOM_2:14)
Block(0,16,-12,HUGE_MUSHROOM_2:14)
Block(-9,16,-5,HUGE_MUSHROOM_2:14)
Block(-9,17,-5,HUGE_MUSHROOM_2:14)
Block(-9,19,-5,HUGE_MUSHROOM_2:14)
Block(-1,19,-7,HUGE_MUSHROOM_2:14)
Block(2,18,7,HUGE_MUSHROOM_2:14)
Block(2,19,7,HUGE_MUSHROOM_2:14)
Block(-11,15,-4,HUGE_MUSHROOM_2:14)
Block(-10,17,1,HUGE_MUSHROOM_2:14)
Block(1,17,9,HUGE_MUSHROOM_2:14)
Block(7,16,-8,HUGE_MUSHROOM_2:14)
Block(-11,16,-4,HUGE_MUSHROOM_2:14)
Block(-10,16,1,HUGE_MUSHROOM_2:14)
Block(7,17,-8,HUGE_MUSHROOM_2:14)
Block(-10,19,1,HUGE_MUSHROOM_2:14)
Block(1,19,9,HUGE_MUSHROOM_2:14)
Block(7,19,-8,HUGE_MUSHROOM_2:14)
Block(-11,17,-4,HUGE_MUSHROOM_2:14)
Block(-1,21,-7,HUGE_MUSHROOM_2:14)
Block(-11,18,-4,HUGE_MUSHROOM_2:14)
Block(-1,20,-7,HUGE_MUSHROOM_2:14)
Block(-9,20,-5,HUGE_MUSHROOM_2:14)
Block(-4,17,8,HUGE_MUSHROOM_2:14)
Block(8,19,-8,HUGE_MUSHROOM_2:14)
Block(8,16,-8,HUGE_MUSHROOM_2:14)
Block(12,17,-1,HUGE_MUSHROOM_2:14)
Block(12,16,-1,HUGE_MUSHROOM_2:14)
Block(8,17,-8,HUGE_MUSHROOM_2:14)
Block(7,20,4,HUGE_MUSHROOM_2:14)
Block(8,15,-8,HUGE_MUSHROOM_2:14)
Block(-4,19,-5,HUGE_MUSHROOM_2:14)
Block(-6,18,-7,HUGE_MUSHROOM_2:14)
Block(-6,19,-7,HUGE_MUSHROOM_2:14)
Block(11,16,-1,HUGE_MUSHROOM_2:14)
Block(11,15,-1,HUGE_MUSHROOM_2:14)
Block(1,20,-3,HUGE_MUSHROOM_2:14)
Block(11,18,-1,HUGE_MUSHROOM_2:14)
Block(1,21,-3,HUGE_MUSHROOM_2:14)
Block(11,17,-1,HUGE_MUSHROOM_2:14)
Block(-6,20,-7,HUGE_MUSHROOM_2:14)
Block(11,19,-1,HUGE_MUSHROOM_2:14)
Block(8,16,9,HUGE_MUSHROOM_2:14)
Block(-4,20,-5,HUGE_MUSHROOM_2:14)
Block(-4,21,-5,HUGE_MUSHROOM_2:14)
Block(1,9,2,HUGE_MUSHROOM_1:10)
Block(1,8,2,HUGE_MUSHROOM_1:10)
Block(1,7,2,HUGE_MUSHROOM_1:10)
Block(-8,16,-10,HUGE_MUSHROOM_2:14)
Block(-8,17,-10,HUGE_MUSHROOM_2:14)
Block(-5,18,-7,HUGE_MUSHROOM_2:14)
Block(-5,19,-7,HUGE_MUSHROOM_2:14)
Block(6,18,1,HUGE_MUSHROOM_2:14)
Block(6,19,1,HUGE_MUSHROOM_2:14)
Block(2,7,0,HUGE_MUSHROOM_1:10)
Block(-5,20,-7,HUGE_MUSHROOM_2:14)
Block(2,6,0,HUGE_MUSHROOM_1:10)
Block(-5,21,-7,HUGE_MUSHROOM_2:14)
Block(2,9,0,HUGE_MUSHROOM_1:10)
Block(2,8,0,HUGE_MUSHROOM_1:10)
Block(-1,21,2,HUGE_MUSHROOM_2:14)
Block(-7,19,-5,HUGE_MUSHROOM_2:14)
Block(-1,20,2,HUGE_MUSHROOM_2:14)
Block(-7,18,-5,HUGE_MUSHROOM_2:14)
Block(2,18,-1,HUGE_MUSHROOM_1:10)
Block(2,17,-1,HUGE_MUSHROOM_1:10)
Block(5,19,-1,HUGE_MUSHROOM_2:14)
Block(2,19,-1,HUGE_MUSHROOM_1:10)
Block(2,14,-1,HUGE_MUSHROOM_1:10)
Block(2,13,-1,HUGE_MUSHROOM_1:10)
Block(2,16,-1,HUGE_MUSHROOM_1:10)
Block(2,15,-1,HUGE_MUSHROOM_1:10)
Block(2,10,-1,HUGE_MUSHROOM_1:10)
Block(2,12,-1,HUGE_MUSHROOM_1:10)
Block(2,11,-1,HUGE_MUSHROOM_1:10)
Block(1,16,-11,HUGE_MUSHROOM_2:14)
Block(1,15,-11,HUGE_MUSHROOM_2:14)
Block(-8,19,2,HUGE_MUSHROOM_2:14)
Block(-8,17,2,HUGE_MUSHROOM_2:14)
Block(2,21,-1,HUGE_MUSHROOM_2:14)
Block(2,20,-1,HUGE_MUSHROOM_2:14)
Block(-8,20,2,HUGE_MUSHROOM_2:14)
Block(-5,21,0,HUGE_MUSHROOM_2:14)
Block(-5,20,0,HUGE_MUSHROOM_2:14)
Block(0,19,-12,HUGE_MUSHROOM_2:14)
Block(0,17,-12,HUGE_MUSHROOM_2:14)
Block(0,18,-12,HUGE_MUSHROOM_2:14)
Block(-3,21,-7,HUGE_MUSHROOM_2:14)
Block(-3,20,-7,HUGE_MUSHROOM_2:14)
Block(6,20,1,HUGE_MUSHROOM_2:14)
Block(2,3,0,HUGE_MUSHROOM_1:10)
Block(2,2,0,HUGE_MUSHROOM_1:10)
Block(2,5,0,HUGE_MUSHROOM_1:10)
Block(2,4,0,HUGE_MUSHROOM_1:10)
Block(2,1,0,HUGE_MUSHROOM_1:10)
Block(2,0,0,HUGE_MUSHROOM_1:10)
Block(-7,21,-5,HUGE_MUSHROOM_2:14)
Block(-7,20,-5,HUGE_MUSHROOM_2:14)
Block(-10,20,-2,HUGE_MUSHROOM_2:14)
Block(-3,18,-7,HUGE_MUSHROOM_2:14)
Block(6,21,1,HUGE_MUSHROOM_2:14)
Block(1,1,2,HUGE_MUSHROOM_1:10)
Block(1,0,2,HUGE_MUSHROOM_1:10)
Block(-3,19,-7,HUGE_MUSHROOM_2:14)
Block(-11,19,1,HUGE_MUSHROOM_2:14)
Block(-11,17,1,HUGE_MUSHROOM_2:14)
Block(-11,18,1,HUGE_MUSHROOM_2:14)
Block(5,18,2,HUGE_MUSHROOM_2:14)
Block(7,15,8,HUGE_MUSHROOM_2:14)
Block(5,19,2,HUGE_MUSHROOM_2:14)
Block(7,16,8,HUGE_MUSHROOM_2:14)
Block(7,17,8,HUGE_MUSHROOM_2:14)
Block(7,19,8,HUGE_MUSHROOM_2:14)
Block(-8,19,-8,HUGE_MUSHROOM_2:14)
Block(1,20,1,HUGE_MUSHROOM_2:14)
Block(1,21,1,HUGE_MUSHROOM_2:14)
Block(12,16,-3,HUGE_MUSHROOM_2:14)
Block(12,17,-3,HUGE_MUSHROOM_2:14)
Block(3,18,7,HUGE_MUSHROOM_2:14)
Block(12,18,-3,HUGE_MUSHROOM_2:14)
Block(3,19,7,HUGE_MUSHROOM_2:14)
Block(-8,17,-8,HUGE_MUSHROOM_2:14)
Block(-8,16,-8,HUGE_MUSHROOM_2:14)
Block(-8,15,-8,HUGE_MUSHROOM_2:14)
Block(-4,17,-11,HUGE_MUSHROOM_2:14)
Block(3,20,7,HUGE_MUSHROOM_2:14)
Block(-4,18,-11,HUGE_MUSHROOM_2:14)
Block(-4,15,-11,HUGE_MUSHROOM_2:14)
Block(-4,16,-11,HUGE_MUSHROOM_2:14)
Block(-4,20,4,HUGE_MUSHROOM_2:14)
Block(-4,21,4,HUGE_MUSHROOM_2:14)
Block(12,15,-3,HUGE_MUSHROOM_2:14)
Block(-10,16,-7,HUGE_MUSHROOM_2:14)
Block(-10,15,-7,HUGE_MUSHROOM_2:14)
Block(1,10,1,HUGE_MUSHROOM_1:10)
Block(1,11,1,HUGE_MUSHROOM_1:10)
Block(1,12,1,HUGE_MUSHROOM_1:10)
Block(1,13,1,HUGE_MUSHROOM_1:10)
Block(-9,20,-1,HUGE_MUSHROOM_2:14)
Block(1,14,1,HUGE_MUSHROOM_1:10)
Block(1,15,1,HUGE_MUSHROOM_1:10)
Block(1,16,1,HUGE_MUSHROOM_1:10)
Block(-10,18,-7,HUGE_MUSHROOM_2:14)
Block(-3,21,2,HUGE_MUSHROOM_2:14)
Block(-10,17,-7,HUGE_MUSHROOM_2:14)
Block(-4,19,4,HUGE_MUSHROOM_2:14)
Block(-3,20,2,HUGE_MUSHROOM_2:14)
Block(1,19,1,HUGE_MUSHROOM_1:10)
Block(-1,20,7,HUGE_MUSHROOM_2:14)
Block(2,21,3,HUGE_MUSHROOM_2:14)
Block(-3,20,-8,HUGE_MUSHROOM_2:14)
Block(-3,21,-8,HUGE_MUSHROOM_2:14)
Block(2,20,3,HUGE_MUSHROOM_2:14)
Block(-1,21,7,HUGE_MUSHROOM_2:14)
Block(7,19,-6,HUGE_MUSHROOM_2:14)
Block(7,17,-6,HUGE_MUSHROOM_2:14)
Block(-9,19,-1,HUGE_MUSHROOM_2:14)
Block(-5,19,-5,HUGE_MUSHROOM_2:14)
Block(-9,17,-1,HUGE_MUSHROOM_2:14)
Block(-7,21,-4,HUGE_MUSHROOM_2:14)
Block(-7,20,-4,HUGE_MUSHROOM_2:14)
Block(-5,21,-5,HUGE_MUSHROOM_2:14)
Block(-5,20,-5,HUGE_MUSHROOM_2:14)
Block(-3,18,-8,HUGE_MUSHROOM_2:14)
Block(-1,19,7,HUGE_MUSHROOM_2:14)
Block(-1,18,7,HUGE_MUSHROOM_2:14)
Block(-3,19,-8,HUGE_MUSHROOM_2:14)
Block(10,19,-4,HUGE_MUSHROOM_2:14)
Block(7,20,-6,HUGE_MUSHROOM_2:14)
Block(-11,15,1,HUGE_MUSHROOM_2:14)
Block(-7,19,-4,HUGE_MUSHROOM_2:14)
Block(-11,16,1,HUGE_MUSHROOM_2:14)
Block(-7,18,-4,HUGE_MUSHROOM_2:14)
Block(10,20,-4,HUGE_MUSHROOM_2:14)
Block(-2,17,0,HUGE_MUSHROOM_1:10)
Block(-2,16,0,HUGE_MUSHROOM_1:10)
Block(-2,18,0,HUGE_MUSHROOM_1:10)
Block(6,21,-2,HUGE_MUSHROOM_2:14)
Block(10,19,1,HUGE_MUSHROOM_2:14)
Block(10,15,-4,HUGE_MUSHROOM_2:14)
Block(10,15,1,HUGE_MUSHROOM_2:14)
Block(10,16,-4,HUGE_MUSHROOM_2:14)
Block(10,16,1,HUGE_MUSHROOM_2:14)
Block(10,17,-4,HUGE_MUSHROOM_2:14)
Block(10,17,1,HUGE_MUSHROOM_2:14)
Block(10,18,1,HUGE_MUSHROOM_2:14)
Block(0,21,-5,HUGE_MUSHROOM_2:14)
Block(0,20,-5,HUGE_MUSHROOM_2:14)
Block(6,20,-2,HUGE_MUSHROOM_2:14)
Block(5,19,-9,HUGE_MUSHROOM_2:14)
Block(-2,20,-4,HUGE_MUSHROOM_2:14)
Block(-2,21,-4,HUGE_MUSHROOM_2:14)
Block(-2,20,0,HUGE_MUSHROOM_2:14)
Block(6,19,-2,HUGE_MUSHROOM_2:14)
Block(-2,21,0,HUGE_MUSHROOM_2:14)
Block(0,8,1,HUGE_MUSHROOM_1:10)
Block(8,18,-1,HUGE_MUSHROOM_2:14)
Block(1,20,-9,HUGE_MUSHROOM_2:14)
Block(8,17,-1,HUGE_MUSHROOM_2:14)
Block(5,16,-9,HUGE_MUSHROOM_2:14)
Block(0,9,1,HUGE_MUSHROOM_1:10)
Block(5,17,-9,HUGE_MUSHROOM_2:14)
Block(8,19,-1,HUGE_MUSHROOM_2:14)
Block(6,20,4,HUGE_MUSHROOM_2:14)
Block(-5,19,8,HUGE_MUSHROOM_2:14)
Block(-8,16,5,HUGE_MUSHROOM_2:14)
Block(9,19,1,HUGE_MUSHROOM_2:14)
Block(8,20,-1,HUGE_MUSHROOM_2:14)
Block(1,9,-1,HUGE_MUSHROOM_1:10)
Block(-8,17,5,HUGE_MUSHROOM_2:14)
Block(9,17,1,HUGE_MUSHROOM_2:14)
Block(1,7,-1,HUGE_MUSHROOM_1:10)
Block(9,16,1,HUGE_MUSHROOM_2:14)
Block(1,8,-1,HUGE_MUSHROOM_1:10)
Block(9,15,1,HUGE_MUSHROOM_2:14)
Block(1,5,-1,HUGE_MUSHROOM_1:10)
Block(1,6,-1,HUGE_MUSHROOM_1:10)
Block(1,4,-1,HUGE_MUSHROOM_1:10)
Block(1,0,-1,HUGE_MUSHROOM_1:10)
Block(9,20,1,HUGE_MUSHROOM_2:14)
Block(-8,19,5,HUGE_MUSHROOM_2:14)
Block(-5,17,8,HUGE_MUSHROOM_2:14)
Block(-5,16,8,HUGE_MUSHROOM_2:14)
Block(9,20,-1,HUGE_MUSHROOM_2:14)
Block(-8,20,5,HUGE_MUSHROOM_2:14)
Block(6,19,4,HUGE_MUSHROOM_2:14)
Block(6,17,4,HUGE_MUSHROOM_2:14)
Block(6,18,4,HUGE_MUSHROOM_2:14)
Block(10,17,-8,HUGE_MUSHROOM_2:14)
Block(10,18,-8,HUGE_MUSHROOM_2:14)
Block(10,15,-8,HUGE_MUSHROOM_2:14)
Block(0,21,-9,HUGE_MUSHROOM_2:14)
Block(10,16,-8,HUGE_MUSHROOM_2:14)
Block(0,20,-9,HUGE_MUSHROOM_2:14)
Block(4,16,-12,HUGE_MUSHROOM_2:14)
Block(4,17,-12,HUGE_MUSHROOM_2:14)
Block(8,17,3,HUGE_MUSHROOM_2:14)
Block(8,16,3,HUGE_MUSHROOM_2:14)
Block(5,18,-5,HUGE_MUSHROOM_2:14)
Block(8,19,3,HUGE_MUSHROOM_2:14)
Block(4,20,-5,HUGE_MUSHROOM_2:14)
Block(5,19,-5,HUGE_MUSHROOM_2:14)
Block(4,21,-5,HUGE_MUSHROOM_2:14)
Block(4,3,2,HUGE_MUSHROOM_1:10)
Block(4,2,2,HUGE_MUSHROOM_1:10)
Block(4,4,2,HUGE_MUSHROOM_1:10)
Block(-3,16,-12,HUGE_MUSHROOM_2:14)
Block(-3,17,-12,HUGE_MUSHROOM_2:14)
Block(-5,19,4,HUGE_MUSHROOM_2:14)
Block(4,1,2,HUGE_MUSHROOM_1:10)
Block(4,0,2,HUGE_MUSHROOM_1:10)
Block(1,17,-9,HUGE_MUSHROOM_2:14)
Block(1,19,-9,HUGE_MUSHROOM_2:14)
Block(-5,21,4,HUGE_MUSHROOM_2:14)
Block(1,18,-9,HUGE_MUSHROOM_2:14)
Block(-5,20,4,HUGE_MUSHROOM_2:14)
Block(4,19,-5,HUGE_MUSHROOM_2:14)
Block(8,20,3,HUGE_MUSHROOM_2:14)
Block(6,16,8,HUGE_MUSHROOM_2:14)
Block(9,20,-5,HUGE_MUSHROOM_2:14)
Block(6,15,8,HUGE_MUSHROOM_2:14)
Block(-8,18,-1,HUGE_MUSHROOM_2:14)
Block(-8,19,-1,HUGE_MUSHROOM_2:14)
Block(0,19,-9,HUGE_MUSHROOM_2:14)
Block(6,19,8,HUGE_MUSHROOM_2:14)
Block(6,17,8,HUGE_MUSHROOM_2:14)
Block(0,18,-9,HUGE_MUSHROOM_2:14)
Block(-5,18,-10,HUGE_MUSHROOM_2:14)
Block(-5,17,-10,HUGE_MUSHROOM_2:14)
Block(-5,16,-10,HUGE_MUSHROOM_2:14)
Block(-5,15,-10,HUGE_MUSHROOM_2:14)
Block(7,19,1,HUGE_MUSHROOM_2:14)
Block(-5,19,-10,HUGE_MUSHROOM_2:14)
Block(2,20,-6,HUGE_MUSHROOM_2:14)
Block(2,21,-6,HUGE_MUSHROOM_2:14)
Block(7,18,1,HUGE_MUSHROOM_2:14)
Block(3,19,3,HUGE_MUSHROOM_2:14)
Block(9,19,-5,HUGE_MUSHROOM_2:14)
Block(1,20,5,HUGE_MUSHROOM_2:14)
Block(1,21,5,HUGE_MUSHROOM_2:14)
Block(-4,21,0,HUGE_MUSHROOM_2:14)
Block(9,17,-5,HUGE_MUSHROOM_2:14)
Block(9,16,-5,HUGE_MUSHROOM_2:14)
Block(-9,16,2,HUGE_MUSHROOM_2:14)
Block(-9,17,2,HUGE_MUSHROOM_2:14)
Block(-3,19,6,HUGE_MUSHROOM_2:14)
Block(-9,19,2,HUGE_MUSHROOM_2:14)
Block(-5,21,-1,HUGE_MUSHROOM_2:14)
Block(-3,18,6,HUGE_MUSHROOM_2:14)
Block(-5,20,-1,HUGE_MUSHROOM_2:14)
Block(-4,20,0,HUGE_MUSHROOM_2:14)
Block(4,15,9,HUGE_MUSHROOM_2:14)
Block(2,19,-6,HUGE_MUSHROOM_2:14)
Block(4,19,9,HUGE_MUSHROOM_2:14)
Block(4,16,9,HUGE_MUSHROOM_2:14)
Block(4,17,9,HUGE_MUSHROOM_2:14)
Block(7,20,1,HUGE_MUSHROOM_2:14)
Block(1,19,5,HUGE_MUSHROOM_2:14)
Block(-9,20,2,HUGE_MUSHROOM_2:14)
Block(3,21,3,HUGE_MUSHROOM_2:14)
Block(3,20,3,HUGE_MUSHROOM_2:14)
Block(-3,20,6,HUGE_MUSHROOM_2:14)
Block(-3,21,6,HUGE_MUSHROOM_2:14)
Block(-7,20,3,HUGE_MUSHROOM_2:14)
Block(9,16,-10,HUGE_MUSHROOM_2:14)
Block(9,17,-10,HUGE_MUSHROOM_2:14)
Block(-7,18,3,HUGE_MUSHROOM_2:14)
Block(3,19,-6,HUGE_MUSHROOM_2:14)
Block(-7,19,3,HUGE_MUSHROOM_2:14)
Block(-3,20,-1,HUGE_MUSHROOM_2:14)
Block(5,20,-5,HUGE_MUSHROOM_2:14)
Block(-3,21,-1,HUGE_MUSHROOM_2:14)
Block(5,21,-5,HUGE_MUSHROOM_2:14)
Block(5,21,2,HUGE_MUSHROOM_2:14)
Block(3,20,-6,HUGE_MUSHROOM_2:14)
Block(3,21,-6,HUGE_MUSHROOM_2:14)
Block(5,20,2,HUGE_MUSHROOM_2:14)
Block(-4,21,-1,HUGE_MUSHROOM_2:14)
Block(-4,20,-1,HUGE_MUSHROOM_2:14)
Block(5,19,-2,HUGE_MUSHROOM_2:14)
Block(-1,21,-4,HUGE_MUSHROOM_2:14)
Block(-2,21,4,HUGE_MUSHROOM_2:14)
Block(-2,20,4,HUGE_MUSHROOM_2:14)
Block(11,19,-4,HUGE_MUSHROOM_2:14)
Block(10,17,5,HUGE_MUSHROOM_2:14)
Block(-1,20,-4,HUGE_MUSHROOM_2:14)
Block(10,16,5,HUGE_MUSHROOM_2:14)
Block(9,18,-9,HUGE_MUSHROOM_2:14)
Block(9,15,-9,HUGE_MUSHROOM_2:14)
Block(9,17,-9,HUGE_MUSHROOM_2:14)
Block(9,16,-9,HUGE_MUSHROOM_2:14)
Block(2,2,1,HUGE_MUSHROOM_1:10)
Block(2,1,1,HUGE_MUSHROOM_1:10)
Block(2,4,1,HUGE_MUSHROOM_1:10)
Block(2,3,1,HUGE_MUSHROOM_1:10)
Block(-10,18,4,HUGE_MUSHROOM_2:14)
Block(-2,21,-8,HUGE_MUSHROOM_2:14)
Block(-10,17,4,HUGE_MUSHROOM_2:14)
Block(-2,20,-8,HUGE_MUSHROOM_2:14)
Block(2,0,1,HUGE_MUSHROOM_1:10)
Block(-10,16,4,HUGE_MUSHROOM_2:14)
Block(-10,15,4,HUGE_MUSHROOM_2:14)
Block(8,16,-5,HUGE_MUSHROOM_2:14)
Block(8,17,-5,HUGE_MUSHROOM_2:14)
Block(-2,18,-8,HUGE_MUSHROOM_2:14)
Block(4,18,5,HUGE_MUSHROOM_2:14)
Block(-2,19,-8,HUGE_MUSHROOM_2:14)
Block(4,19,5,HUGE_MUSHROOM_2:14)
Block(0,21,3,HUGE_MUSHROOM_2:14)
Block(8,19,-5,HUGE_MUSHROOM_2:14)
Block(5,21,-2,HUGE_MUSHROOM_2:14)
Block(5,20,-2,HUGE_MUSHROOM_2:14)
Block(0,20,3,HUGE_MUSHROOM_2:14)
Block(-9,15,-8,HUGE_MUSHROOM_2:14)
Block(8,17,6,HUGE_MUSHROOM_2:14)
Block(-9,17,-8,HUGE_MUSHROOM_2:14)
Block(8,19,6,HUGE_MUSHROOM_2:14)
Block(-9,16,-8,HUGE_MUSHROOM_2:14)
Block(-6,19,-4,HUGE_MUSHROOM_2:14)
Block(-9,19,-8,HUGE_MUSHROOM_2:14)
Block(-9,18,-8,HUGE_MUSHROOM_2:14)
Block(8,20,-5,HUGE_MUSHROOM_2:14)
Block(-10,19,4,HUGE_MUSHROOM_2:14)
Block(6,17,-10,HUGE_MUSHROOM_2:14)
Block(6,20,0,HUGE_MUSHROOM_2:14)
Block(6,21,0,HUGE_MUSHROOM_2:14)
Block(8,15,6,HUGE_MUSHROOM_2:14)
Block(6,19,-10,HUGE_MUSHROOM_2:14)
Block(8,16,6,HUGE_MUSHROOM_2:14)
Block(-6,17,6,HUGE_MUSHROOM_2:14)
Block(6,15,-10,HUGE_MUSHROOM_2:14)
Block(1,19,-12,HUGE_MUSHROOM_2:14)
Block(1,21,-6,HUGE_MUSHROOM_2:14)
Block(6,16,-10,HUGE_MUSHROOM_2:14)
Block(1,18,-12,HUGE_MUSHROOM_2:14)
Block(1,20,-6,HUGE_MUSHROOM_2:14)
Block(1,17,-12,HUGE_MUSHROOM_2:14)
Block(1,16,-12,HUGE_MUSHROOM_2:14)
Block(1,15,-12,HUGE_MUSHROOM_2:14)
Block(-8,17,1,HUGE_MUSHROOM_2:14)
Block(1,19,-6,HUGE_MUSHROOM_2:14)
Block(-5,19,1,HUGE_MUSHROOM_2:14)
Block(11,16,-4,HUGE_MUSHROOM_2:14)
Block(-6,21,-4,HUGE_MUSHROOM_2:14)
Block(11,17,-4,HUGE_MUSHROOM_2:14)
Block(-6,20,-4,HUGE_MUSHROOM_2:14)
Block(-8,19,1,HUGE_MUSHROOM_2:14)
Block(11,15,-4,HUGE_MUSHROOM_2:14)
Block(-8,20,1,HUGE_MUSHROOM_2:14)
Block(6,18,0,HUGE_MUSHROOM_2:14)
Block(-5,20,1,HUGE_MUSHROOM_2:14)
Block(6,19,0,HUGE_MUSHROOM_2:14)
Block(-5,21,1,HUGE_MUSHROOM_2:14)
Block(5,20,6,HUGE_MUSHROOM_2:14)
Block(-4,18,-8,HUGE_MUSHROOM_2:14)
Block(5,19,6,HUGE_MUSHROOM_2:14)
Block(5,17,6,HUGE_MUSHROOM_2:14)
Block(-4,19,-8,HUGE_MUSHROOM_2:14)
Block(2,17,-9,HUGE_MUSHROOM_2:14)
Block(2,19,-9,HUGE_MUSHROOM_2:14)
Block(1,19,8,HUGE_MUSHROOM_2:14)
Block(1,17,8,HUGE_MUSHROOM_2:14)
Block(-4,20,-8,HUGE_MUSHROOM_2:14)
Block(3,20,0,HUGE_MUSHROOM_2:14)
Block(3,21,0,HUGE_MUSHROOM_2:14)
Block(-6,19,6,HUGE_MUSHROOM_2:14)
Block(-7,16,7,HUGE_MUSHROOM_2:14)
Block(-7,17,7,HUGE_MUSHROOM_2:14)
Block(-7,19,7,HUGE_MUSHROOM_2:14)
Block(4,20,-9,HUGE_MUSHROOM_2:14)
Block(-6,20,6,HUGE_MUSHROOM_2:14)
Block(5,16,-11,HUGE_MUSHROOM_2:14)
Block(-3,16,9,HUGE_MUSHROOM_2:14)
Block(5,15,-11,HUGE_MUSHROOM_2:14)
Block(-3,17,9,HUGE_MUSHROOM_2:14)
Block(-3,15,9,HUGE_MUSHROOM_2:14)
Block(5,18,-11,HUGE_MUSHROOM_2:14)
Block(5,17,-11,HUGE_MUSHROOM_2:14)
Block(4,16,-9,HUGE_MUSHROOM_2:14)
Block(2,19,-11,HUGE_MUSHROOM_2:14)
Block(4,17,-9,HUGE_MUSHROOM_2:14)
Block(7,18,-2,HUGE_MUSHROOM_2:14)
Block(-3,21,-4,HUGE_MUSHROOM_2:14)
Block(7,19,-2,HUGE_MUSHROOM_2:14)
Block(-3,19,9,HUGE_MUSHROOM_2:14)
Block(-3,20,-4,HUGE_MUSHROOM_2:14)
Block(4,20,5,HUGE_MUSHROOM_2:14)
Block(4,21,5,HUGE_MUSHROOM_2:14)
Block(4,19,-9,HUGE_MUSHROOM_2:14)
Block(3,2,3,HUGE_MUSHROOM_1:10)
Block(2,20,-9,HUGE_MUSHROOM_2:14)
Block(-7,20,-8,HUGE_MUSHROOM_2:14)
Block(7,21,-2,HUGE_MUSHROOM_2:14)
Block(7,20,-2,HUGE_MUSHROOM_2:14)
Block(1,20,8,HUGE_MUSHROOM_2:14)
Block(-7,17,-8,HUGE_MUSHROOM_2:14)
Block(-7,19,-8,HUGE_MUSHROOM_2:14)
Block(2,15,-11,HUGE_MUSHROOM_2:14)
Block(2,16,-11,HUGE_MUSHROOM_2:14)
Block(2,17,-11,HUGE_MUSHROOM_2:14)
Block(-2,17,11,HUGE_MUSHROOM_2:14)
Block(-2,16,11,HUGE_MUSHROOM_2:14)
Block(-4,20,7,HUGE_MUSHROOM_2:14)
Block(6,19,-9,HUGE_MUSHROOM_2:14)
Block(-4,19,-4,HUGE_MUSHROOM_2:14)
Block(6,17,-9,HUGE_MUSHROOM_2:14)
Block(2,18,-2,HUGE_MUSHROOM_1:10)
Block(7,19,5,HUGE_MUSHROOM_2:14)
Block(2,16,-2,HUGE_MUSHROOM_1:10)
Block(2,17,-2,HUGE_MUSHROOM_1:10)
Block(7,17,5,HUGE_MUSHROOM_2:14)
Block(7,16,5,HUGE_MUSHROOM_2:14)
Block(2,15,-2,HUGE_MUSHROOM_1:10)
Block(6,15,-9,HUGE_MUSHROOM_2:14)
Block(6,16,-9,HUGE_MUSHROOM_2:14)
Block(-4,19,7,HUGE_MUSHROOM_2:14)
Block(-9,16,6,HUGE_MUSHROOM_2:14)
Block(-4,17,7,HUGE_MUSHROOM_2:14)
Block(-9,15,6,HUGE_MUSHROOM_2:14)
Block(-9,18,6,HUGE_MUSHROOM_2:14)
Block(-9,20,-4,HUGE_MUSHROOM_2:14)
Block(-9,17,6,HUGE_MUSHROOM_2:14)
Block(-4,20,-4,HUGE_MUSHROOM_2:14)
Block(-4,21,-4,HUGE_MUSHROOM_2:14)
Block(-6,19,2,HUGE_MUSHROOM_2:14)
Block(-7,21,0,HUGE_MUSHROOM_2:14)
Block(-7,20,0,HUGE_MUSHROOM_2:14)
Block(-5,17,-8,HUGE_MUSHROOM_2:14)
Block(4,21,1,HUGE_MUSHROOM_2:14)
Block(-5,19,-8,HUGE_MUSHROOM_2:14)
Block(4,20,1,HUGE_MUSHROOM_2:14)
Block(-9,19,-4,HUGE_MUSHROOM_2:14)
Block(2,21,-2,HUGE_MUSHROOM_2:14)
Block(-7,19,0,HUGE_MUSHROOM_2:14)
Block(-5,20,-8,HUGE_MUSHROOM_2:14)
Block(-9,17,-4,HUGE_MUSHROOM_2:14)
Block(2,20,-2,HUGE_MUSHROOM_2:14)
Block(7,20,5,HUGE_MUSHROOM_2:14)
Block(-6,20,2,HUGE_MUSHROOM_2:14)
Block(-6,21,2,HUGE_MUSHROOM_2:14)
Block(0,0,1,HUGE_MUSHROOM_1:10)
Block(2,18,6,HUGE_MUSHROOM_2:14)
Block(7,15,-9,HUGE_MUSHROOM_2:14)
Block(2,19,6,HUGE_MUSHROOM_2:14)
Block(7,16,-9,HUGE_MUSHROOM_2:14)
Block(7,17,-9,HUGE_MUSHROOM_2:14)
Block(-11,15,-3,HUGE_MUSHROOM_2:14)
Block(7,19,-9,HUGE_MUSHROOM_2:14)
Block(5,20,-9,HUGE_MUSHROOM_2:14)
Block(-11,17,-3,HUGE_MUSHROOM_2:14)
Block(-11,16,-3,HUGE_MUSHROOM_2:14)
Block(-11,19,-3,HUGE_MUSHROOM_2:14)
Block(-11,18,-3,HUGE_MUSHROOM_2:14)
Block(3,20,-2,HUGE_MUSHROOM_2:14)
Block(-1,19,-11,HUGE_MUSHROOM_2:14)
Block(3,21,-2,HUGE_MUSHROOM_2:14)
Block(-1,16,-11,HUGE_MUSHROOM_2:14)
Block(-1,17,-11,HUGE_MUSHROOM_2:14)
Block(-1,15,-11,HUGE_MUSHROOM_2:14)
Block(-12,17,-3,HUGE_MUSHROOM_2:14)
Block(-12,16,-3,HUGE_MUSHROOM_2:14)
Block(6,20,-9,HUGE_MUSHROOM_2:14)
Block(2,21,6,HUGE_MUSHROOM_2:14)
Block(2,20,6,HUGE_MUSHROOM_2:14)
Block(3,11,0,HUGE_MUSHROOM_1:10)
Block(3,10,0,HUGE_MUSHROOM_1:10)
Block(-2,19,-10,HUGE_MUSHROOM_2:14)
Block(-2,20,8,HUGE_MUSHROOM_2:14)
Block(-2,17,-10,HUGE_MUSHROOM_2:14)
Block(-2,16,-10,HUGE_MUSHROOM_2:14)
Block(-1,19,-8,HUGE_MUSHROOM_2:14)
Block(-1,18,-8,HUGE_MUSHROOM_2:14)
Block(-2,17,8,HUGE_MUSHROOM_2:14)
Block(-8,18,-4,HUGE_MUSHROOM_2:14)
Block(-8,17,-4,HUGE_MUSHROOM_2:14)
Block(-2,19,8,HUGE_MUSHROOM_2:14)
Block(-8,19,-4,HUGE_MUSHROOM_2:14)
Block(-1,21,-8,HUGE_MUSHROOM_2:14)
Block(-1,20,-8,HUGE_MUSHROOM_2:14)
Block(0,20,7,HUGE_MUSHROOM_2:14)
Block(-1,15,11,HUGE_MUSHROOM_2:14)
Block(-1,16,11,HUGE_MUSHROOM_2:14)
Block(-1,17,11,HUGE_MUSHROOM_2:14)
Block(-1,18,11,HUGE_MUSHROOM_2:14)
Block(8,19,-9,HUGE_MUSHROOM_2:14)
Block(8,17,-9,HUGE_MUSHROOM_2:14)
Block(8,15,-9,HUGE_MUSHROOM_2:14)
Block(8,16,-9,HUGE_MUSHROOM_2:14)
Block(-10,16,-3,HUGE_MUSHROOM_2:14)
Block(-10,15,-3,HUGE_MUSHROOM_2:14)
Block(-8,20,-4,HUGE_MUSHROOM_2:14)
Block(-10,19,-3,HUGE_MUSHROOM_2:14)
Block(0,21,7,HUGE_MUSHROOM_2:14)
Block(-10,17,-3,HUGE_MUSHROOM_2:14)
Block(0,17,-2,HUGE_MUSHROOM_1:10)
Block(0,16,-2,HUGE_MUSHROOM_1:10)
Block(0,19,-2,HUGE_MUSHROOM_1:10)
Block(0,18,-2,HUGE_MUSHROOM_1:10)
Block(-1,20,3,HUGE_MUSHROOM_2:14)
Block(2,9,1,HUGE_MUSHROOM_1:10)
Block(1,20,-2,HUGE_MUSHROOM_2:14)
Block(1,21,-2,HUGE_MUSHROOM_2:14)
Block(2,6,1,HUGE_MUSHROOM_1:10)
Block(2,5,1,HUGE_MUSHROOM_1:10)
Block(2,8,1,HUGE_MUSHROOM_1:10)
Block(0,18,7,HUGE_MUSHROOM_2:14)
Block(2,7,1,HUGE_MUSHROOM_1:10)
Block(0,19,7,HUGE_MUSHROOM_2:14)
Block(0,13,-2,HUGE_MUSHROOM_1:10)
Block(0,15,-2,HUGE_MUSHROOM_1:10)
Block(0,14,-2,HUGE_MUSHROOM_1:10)
Block(-2,20,-10,HUGE_MUSHROOM_2:14)
Block(9,15,4,HUGE_MUSHROOM_2:14)
Block(1,15,-2,HUGE_MUSHROOM_1:10)
Block(1,16,-2,HUGE_MUSHROOM_1:10)
Block(1,17,-2,HUGE_MUSHROOM_1:10)
Block(1,18,-2,HUGE_MUSHROOM_1:10)
Block(1,19,-2,HUGE_MUSHROOM_1:10)
Block(1,10,-2,HUGE_MUSHROOM_1:10)
Block(1,11,-2,HUGE_MUSHROOM_1:10)
Block(1,12,-2,HUGE_MUSHROOM_1:10)
Block(1,13,-2,HUGE_MUSHROOM_1:10)
Block(1,14,-2,HUGE_MUSHROOM_1:10)
Block(9,16,4,HUGE_MUSHROOM_2:14)
Block(0,20,-2,HUGE_MUSHROOM_2:14)
Block(9,17,4,HUGE_MUSHROOM_2:14)
Block(-1,21,3,HUGE_MUSHROOM_2:14)
Block(9,18,4,HUGE_MUSHROOM_2:14)
Block(9,19,4,HUGE_MUSHROOM_2:14)
Block(0,21,-2,HUGE_MUSHROOM_2:14)
Block(2,15,10,HUGE_MUSHROOM_2:14)
Block(3,20,-9,HUGE_MUSHROOM_2:14)
Block(8,17,0,HUGE_MUSHROOM_2:14)
Block(8,19,0,HUGE_MUSHROOM_2:14)
Block(2,17,10,HUGE_MUSHROOM_2:14)
Block(6,19,-1,HUGE_MUSHROOM_2:14)
Block(2,16,10,HUGE_MUSHROOM_2:14)
Block(-2,21,-3,HUGE_MUSHROOM_2:14)
Block(2,19,10,HUGE_MUSHROOM_2:14)
Block(-2,20,-3,HUGE_MUSHROOM_2:14)
Block(0,19,9,HUGE_MUSHROOM_2:14)
Block(0,17,9,HUGE_MUSHROOM_2:14)
Block(10,16,-5,HUGE_MUSHROOM_2:14)
Block(-7,20,-3,HUGE_MUSHROOM_2:14)
Block(10,17,-5,HUGE_MUSHROOM_2:14)
Block(-7,21,-3,HUGE_MUSHROOM_2:14)
Block(10,19,-5,HUGE_MUSHROOM_2:14)
Block(10,15,-5,HUGE_MUSHROOM_2:14)
Block(8,20,0,HUGE_MUSHROOM_2:14)
Block(1,19,-1,HUGE_MUSHROOM_1:10)
Block(5,21,1,HUGE_MUSHROOM_2:14)
Block(1,18,-1,HUGE_MUSHROOM_1:10)
Block(5,20,1,HUGE_MUSHROOM_2:14)
Block(1,17,-1,HUGE_MUSHROOM_1:10)
Block(1,16,-1,HUGE_MUSHROOM_1:10)
Block(1,15,-1,HUGE_MUSHROOM_1:10)
Block(1,14,-1,HUGE_MUSHROOM_1:10)
Block(1,13,-1,HUGE_MUSHROOM_1:10)
Block(1,12,-1,HUGE_MUSHROOM_1:10)
Block(1,11,-1,HUGE_MUSHROOM_1:10)
Block(1,10,-1,HUGE_MUSHROOM_1:10)
Block(6,20,-1,HUGE_MUSHROOM_2:14)
Block(-6,19,0,HUGE_MUSHROOM_2:14)
Block(6,21,-1,HUGE_MUSHROOM_2:14)
Block(5,19,1,HUGE_MUSHROOM_2:14)
Block(-7,20,2,HUGE_MUSHROOM_2:14)
Block(-7,21,2,HUGE_MUSHROOM_2:14)
Block(-7,19,2,HUGE_MUSHROOM_2:14)
Block(-7,18,2,HUGE_MUSHROOM_2:14)
Block(0,21,-6,HUGE_MUSHROOM_2:14)
Block(0,20,-6,HUGE_MUSHROOM_2:14)
Block(-8,15,-9,HUGE_MUSHROOM_2:14)
Block(3,19,8,HUGE_MUSHROOM_2:14)
Block(-8,19,-9,HUGE_MUSHROOM_2:14)
Block(-8,18,-9,HUGE_MUSHROOM_2:14)
Block(-6,20,0,HUGE_MUSHROOM_2:14)
Block(-8,17,-9,HUGE_MUSHROOM_2:14)
Block(3,17,8,HUGE_MUSHROOM_2:14)
Block(-6,21,0,HUGE_MUSHROOM_2:14)
Block(-8,16,-9,HUGE_MUSHROOM_2:14)
Block(4,20,-4,HUGE_MUSHROOM_2:14)
Block(-4,20,3,HUGE_MUSHROOM_2:14)
Block(-4,21,3,HUGE_MUSHROOM_2:14)
Block(0,20,-10,HUGE_MUSHROOM_2:14)
Block(4,21,-4,HUGE_MUSHROOM_2:14)
Block(-8,19,4,HUGE_MUSHROOM_2:14)
Block(-5,19,9,HUGE_MUSHROOM_2:14)
Block(-5,18,9,HUGE_MUSHROOM_2:14)
Block(-5,17,9,HUGE_MUSHROOM_2:14)
Block(-5,16,9,HUGE_MUSHROOM_2:14)
Block(-5,15,9,HUGE_MUSHROOM_2:14)
Block(2,20,-3,HUGE_MUSHROOM_2:14)
Block(2,21,-3,HUGE_MUSHROOM_2:14)
Block(0,19,-10,HUGE_MUSHROOM_2:14)
Block(-8,20,4,HUGE_MUSHROOM_2:14)
Block(-4,19,3,HUGE_MUSHROOM_2:14)
Block(0,17,-10,HUGE_MUSHROOM_2:14)
Block(-3,20,-9,HUGE_MUSHROOM_2:14)
Block(6,20,3,HUGE_MUSHROOM_2:14)
Block(7,19,-7,HUGE_MUSHROOM_2:14)
Block(7,16,9,HUGE_MUSHROOM_2:14)
Block(7,17,-7,HUGE_MUSHROOM_2:14)
Block(7,15,9,HUGE_MUSHROOM_2:14)
Block(7,16,-7,HUGE_MUSHROOM_2:14)
Block(7,18,9,HUGE_MUSHROOM_2:14)
Block(7,17,9,HUGE_MUSHROOM_2:14)
Block(9,19,2,HUGE_MUSHROOM_2:14)
Block(9,17,2,HUGE_MUSHROOM_2:14)
Block(9,16,2,HUGE_MUSHROOM_2:14)
Block(9,15,2,HUGE_MUSHROOM_2:14)
Block(-3,17,-9,HUGE_MUSHROOM_2:14)
Block(-3,19,-9,HUGE_MUSHROOM_2:14)
Block(4,19,-4,HUGE_MUSHROOM_2:14)
Block(-6,19,-8,HUGE_MUSHROOM_2:14)
Block(-6,17,-8,HUGE_MUSHROOM_2:14)
Block(-10,20,0,HUGE_MUSHROOM_2:14)
Block(-10,16,0,HUGE_MUSHROOM_2:14)
Block(-6,20,-8,HUGE_MUSHROOM_2:14)
Block(-10,17,0,HUGE_MUSHROOM_2:14)
Block(7,20,-7,HUGE_MUSHROOM_2:14)
Block(-10,19,0,HUGE_MUSHROOM_2:14)
Block(-7,18,-3,HUGE_MUSHROOM_2:14)
Block(-7,19,-3,HUGE_MUSHROOM_2:14)
Block(0,20,9,HUGE_MUSHROOM_2:14)
Block(2,21,2,HUGE_MUSHROOM_2:14)
Block(2,20,2,HUGE_MUSHROOM_2:14)
Block(3,19,-9,HUGE_MUSHROOM_2:14)
Block(3,17,-9,HUGE_MUSHROOM_2:14)
Block(10,19,0,HUGE_MUSHROOM_2:14)
Block(10,15,0,HUGE_MUSHROOM_2:14)
Block(10,16,0,HUGE_MUSHROOM_2:14)
Block(10,17,0,HUGE_MUSHROOM_2:14)
Block(12,18,-2,HUGE_MUSHROOM_2:14)
Block(12,17,-2,HUGE_MUSHROOM_2:14)
Block(12,16,-2,HUGE_MUSHROOM_2:14)
Block(12,15,-2,HUGE_MUSHROOM_2:14)
Block(3,20,4,HUGE_MUSHROOM_2:14)
Block(11,16,-7,HUGE_MUSHROOM_2:14)
Block(11,18,-7,HUGE_MUSHROOM_2:14)
Block(11,17,-7,HUGE_MUSHROOM_2:14)
Block(8,19,-2,HUGE_MUSHROOM_2:14)
Block(8,18,-2,HUGE_MUSHROOM_2:14)
Block(8,17,-2,HUGE_MUSHROOM_2:14)
Block(3,21,4,HUGE_MUSHROOM_2:14)
Block(1,20,-8,HUGE_MUSHROOM_2:14)
Block(1,21,-8,HUGE_MUSHROOM_2:14)
Block(6,20,7,HUGE_MUSHROOM_2:14)
Block(7,19,-3,HUGE_MUSHROOM_2:14)
Block(7,18,-3,HUGE_MUSHROOM_2:14)
Block(2,20,-7,HUGE_MUSHROOM_2:14)
Block(2,21,-7,HUGE_MUSHROOM_2:14)
Block(8,20,-2,HUGE_MUSHROOM_2:14)
Block(1,19,-8,HUGE_MUSHROOM_2:14)
Block(1,18,-8,HUGE_MUSHROOM_2:14)
Block(-3,19,5,HUGE_MUSHROOM_2:14)
Block(-5,20,-2,HUGE_MUSHROOM_2:14)
Block(-5,21,-2,HUGE_MUSHROOM_2:14)
Block(-6,20,-1,HUGE_MUSHROOM_2:14)
Block(-6,21,-1,HUGE_MUSHROOM_2:14)
Block(7,20,-3,HUGE_MUSHROOM_2:14)
Block(-3,21,5,HUGE_MUSHROOM_2:14)
Block(3,15,-10,HUGE_MUSHROOM_2:14)
Block(3,17,-10,HUGE_MUSHROOM_2:14)
Block(3,16,-10,HUGE_MUSHROOM_2:14)
Block(-3,20,5,HUGE_MUSHROOM_2:14)
Block(3,19,-10,HUGE_MUSHROOM_2:14)
Block(-5,17,-11,HUGE_MUSHROOM_2:14)
Block(-5,16,-11,HUGE_MUSHROOM_2:14)
Block(-1,19,-1,HUGE_MUSHROOM_1:10)
Block(-1,15,-1,HUGE_MUSHROOM_1:10)
Block(-1,16,-1,HUGE_MUSHROOM_1:10)
Block(-1,17,-1,HUGE_MUSHROOM_1:10)
Block(-1,18,-1,HUGE_MUSHROOM_1:10)
Block(-5,19,-2,HUGE_MUSHROOM_2:14)
Block(1,20,4,HUGE_MUSHROOM_2:14)
Block(4,1,3,HUGE_MUSHROOM_1:10)
Block(-1,20,-1,HUGE_MUSHROOM_2:14)
Block(-1,21,-1,HUGE_MUSHROOM_2:14)
Block(1,21,4,HUGE_MUSHROOM_2:14)
Block(3,20,-10,HUGE_MUSHROOM_2:14)
Block(5,17,-6,AIR)
Block(8,17,4,HUGE_MUSHROOM_2:14)
Block(5,18,-6,HUGE_MUSHROOM_2:14)
Block(8,16,4,HUGE_MUSHROOM_2:14)
Block(8,15,4,HUGE_MUSHROOM_2:14)
Block(5,19,-6,HUGE_MUSHROOM_2:14)
Block(8,19,4,HUGE_MUSHROOM_2:14)
Block(3,20,-5,HUGE_MUSHROOM_2:14)
Block(6,18,-5,HUGE_MUSHROOM_2:14)
Block(4,0,3,HUGE_MUSHROOM_1:10)
Block(6,19,-5,HUGE_MUSHROOM_2:14)
Block(3,21,-5,HUGE_MUSHROOM_2:14)
Block(0,20,2,HUGE_MUSHROOM_2:14)
Block(0,21,2,HUGE_MUSHROOM_2:14)
Block(-6,19,-1,HUGE_MUSHROOM_2:14)
Block(-1,20,8,HUGE_MUSHROOM_2:14)
Block(-2,20,3,HUGE_MUSHROOM_2:14)
Block(-2,21,3,HUGE_MUSHROOM_2:14)
Block(-1,19,8,HUGE_MUSHROOM_2:14)
Block(5,20,-6,HUGE_MUSHROOM_2:14)
Block(8,20,4,HUGE_MUSHROOM_2:14)
Block(-1,17,8,HUGE_MUSHROOM_2:14)
Block(2,18,-7,HUGE_MUSHROOM_2:14)
Block(2,19,-7,HUGE_MUSHROOM_2:14)
Block(-10,17,-8,HUGE_MUSHROOM_2:14)
Block(-10,16,-8,HUGE_MUSHROOM_2:14)
Block(-11,17,2,HUGE_MUSHROOM_2:14)
Block(6,19,7,HUGE_MUSHROOM_2:14)
Block(-11,16,2,HUGE_MUSHROOM_2:14)
Block(-11,15,2,HUGE_MUSHROOM_2:14)
Block(6,17,7,HUGE_MUSHROOM_2:14)
Block(9,20,-4,HUGE_MUSHROOM_2:14)
Block(6,16,7,HUGE_MUSHROOM_2:14)
Block(-11,18,2,HUGE_MUSHROOM_2:14)
Block(-5,18,5,HUGE_MUSHROOM_2:14)
Block(-5,19,5,HUGE_MUSHROOM_2:14)
Block(9,19,-4,HUGE_MUSHROOM_2:14)
Block(-8,18,8,HUGE_MUSHROOM_2:14)
Block(9,17,-4,HUGE_MUSHROOM_2:14)
Block(3,19,4,HUGE_MUSHROOM_2:14)
Block(6,20,-5,HUGE_MUSHROOM_2:14)
Block(-5,21,5,HUGE_MUSHROOM_2:14)
Block(-8,17,8,HUGE_MUSHROOM_2:14)
Block(-8,16,8,HUGE_MUSHROOM_2:14)
Block(-5,20,5,HUGE_MUSHROOM_2:14)
Block(9,16,-4,HUGE_MUSHROOM_2:14)
Block(-9,19,3,HUGE_MUSHROOM_2:14)
Block(-5,19,2,HUGE_MUSHROOM_2:14)
Block(4,20,-8,HUGE_MUSHROOM_2:14)
Block(-8,18,0,HUGE_MUSHROOM_2:14)
Block(-8,19,0,HUGE_MUSHROOM_2:14)
Block(2,9,2,HUGE_MUSHROOM_1:10)
Block(-5,20,2,HUGE_MUSHROOM_2:14)
Block(7,20,2,HUGE_MUSHROOM_2:14)
Block(2,8,2,HUGE_MUSHROOM_1:10)
Block(-8,20,0,HUGE_MUSHROOM_2:14)
Block(-5,21,2,HUGE_MUSHROOM_2:14)
Block(2,20,9,HUGE_MUSHROOM_2:14)
Block(2,5,2,HUGE_MUSHROOM_1:10)
Block(2,4,2,HUGE_MUSHROOM_1:10)
Block(2,7,2,HUGE_MUSHROOM_1:10)
Block(-8,21,0,HUGE_MUSHROOM_2:14)
Block(2,6,2,HUGE_MUSHROOM_1:10)
Block(-9,20,3,HUGE_MUSHROOM_2:14)
Block(3,8,0,HUGE_MUSHROOM_1:10)
Block(3,7,0,HUGE_MUSHROOM_1:10)
Block(4,17,-8,HUGE_MUSHROOM_2:14)
Block(-4,19,-7,HUGE_MUSHROOM_2:14)
Block(-6,19,-5,HUGE_MUSHROOM_2:14)
Block(-4,18,-7,HUGE_MUSHROOM_2:14)
Block(-6,18,-5,HUGE_MUSHROOM_2:14)
Block(3,9,0,HUGE_MUSHROOM_1:10)
Block(-2,19,-11,HUGE_MUSHROOM_2:14)
Block(-2,18,-11,HUGE_MUSHROOM_2:14)
Block(-2,17,-11,HUGE_MUSHROOM_2:14)
Block(-2,16,-11,HUGE_MUSHROOM_2:14)
Block(-2,15,-11,HUGE_MUSHROOM_2:14)
Block(1,21,-5,HUGE_MUSHROOM_2:14)
Block(-6,20,-5,HUGE_MUSHROOM_2:14)
Block(-4,20,-7,HUGE_MUSHROOM_2:14)
Block(4,19,-8,HUGE_MUSHROOM_2:14)
Block(-4,21,-7,HUGE_MUSHROOM_2:14)
Block(1,20,-5,HUGE_MUSHROOM_2:14)
Block(1,21,7,HUGE_MUSHROOM_2:14)
Block(1,20,7,HUGE_MUSHROOM_2:14)
Block(3,0,0,HUGE_MUSHROOM_1:10)
Block(3,4,0,HUGE_MUSHROOM_1:10)
Block(3,3,0,HUGE_MUSHROOM_1:10)
Block(3,2,0,HUGE_MUSHROOM_1:10)
Block(3,1,0,HUGE_MUSHROOM_1:10)
Block(-3,17,8,HUGE_MUSHROOM_2:14)
Block(-3,19,8,HUGE_MUSHROOM_2:14)
Block(2,1,2,HUGE_MUSHROOM_1:10)
Block(7,17,2,HUGE_MUSHROOM_2:14)
Block(2,0,2,HUGE_MUSHROOM_1:10)
Block(2,3,2,HUGE_MUSHROOM_1:10)
Block(2,16,9,HUGE_MUSHROOM_2:14)
Block(7,19,2,HUGE_MUSHROOM_2:14)
Block(2,2,2,HUGE_MUSHROOM_1:10)
Block(2,17,9,HUGE_MUSHROOM_2:14)
Block(2,19,9,HUGE_MUSHROOM_2:14)
Block(-11,17,-6,HUGE_MUSHROOM_2:14)
Block(-11,16,-6,HUGE_MUSHROOM_2:14)
Block(10,18,4,HUGE_MUSHROOM_2:14)
Block(10,16,4,HUGE_MUSHROOM_2:14)
Block(1,18,7,HUGE_MUSHROOM_2:14)
Block(10,17,4,HUGE_MUSHROOM_2:14)
Block(3,19,-5,HUGE_MUSHROOM_2:14)
Block(10,15,4,HUGE_MUSHROOM_2:14)
Block(9,17,-8,HUGE_MUSHROOM_2:14)
Block(9,19,-8,HUGE_MUSHROOM_2:14)
Block(1,19,7,HUGE_MUSHROOM_2:14)
Block(-3,20,8,HUGE_MUSHROOM_2:14)
Block(9,15,-8,HUGE_MUSHROOM_2:14)
Block(-9,16,3,HUGE_MUSHROOM_2:14)
Block(9,16,-8,HUGE_MUSHROOM_2:14)
Block(-9,17,3,HUGE_MUSHROOM_2:14)
Block(-3,15,-10,HUGE_MUSHROOM_2:14)
Block(-3,16,-10,HUGE_MUSHROOM_2:14)
Block(-6,16,-10,HUGE_MUSHROOM_2:14)
Block(-12,16,0,HUGE_MUSHROOM_2:14)
Block(-3,17,-10,HUGE_MUSHROOM_2:14)
Block(-12,15,0,HUGE_MUSHROOM_2:14)
Block(-6,17,-10,HUGE_MUSHROOM_2:14)
Block(-6,18,-10,HUGE_MUSHROOM_2:14)
Block(-3,19,-10,HUGE_MUSHROOM_2:14)
Block(-6,19,-10,HUGE_MUSHROOM_2:14)
Block(-6,15,-10,HUGE_MUSHROOM_2:14)
Block(11,15,-3,HUGE_MUSHROOM_2:14)
Block(11,16,-3,HUGE_MUSHROOM_2:14)
Block(8,17,-6,HUGE_MUSHROOM_2:14)
Block(8,16,-6,HUGE_MUSHROOM_2:14)
Block(8,19,-6,HUGE_MUSHROOM_2:14)
Block(4,18,6,HUGE_MUSHROOM_2:14)
Block(4,19,6,HUGE_MUSHROOM_2:14)
Block(5,20,-3,HUGE_MUSHROOM_2:14)
Block(-8,20,-1,HUGE_MUSHROOM_2:14)
Block(-8,21,-1,HUGE_MUSHROOM_2:14)
Block(5,21,-3,HUGE_MUSHROOM_2:14)
Block(8,19,7,HUGE_MUSHROOM_2:14)
Block(8,18,7,HUGE_MUSHROOM_2:14)
Block(8,20,-6,HUGE_MUSHROOM_2:14)
Block(4,20,6,HUGE_MUSHROOM_2:14)
Block(-1,15,0,HUGE_MUSHROOM_1:10)
Block(11,19,-3,HUGE_MUSHROOM_2:14)
Block(-1,16,0,HUGE_MUSHROOM_1:10)
Block(11,17,-3,HUGE_MUSHROOM_2:14)
Block(-1,17,0,HUGE_MUSHROOM_1:10)
Block(-1,18,0,HUGE_MUSHROOM_1:10)
Block(-1,19,0,HUGE_MUSHROOM_1:10)
Block(8,15,7,HUGE_MUSHROOM_2:14)
Block(8,17,7,HUGE_MUSHROOM_2:14)
Block(8,16,7,HUGE_MUSHROOM_2:14)
Block(-1,11,0,HUGE_MUSHROOM_1:10)
Block(-1,12,0,HUGE_MUSHROOM_1:10)
Block(-1,13,0,HUGE_MUSHROOM_1:10)
Block(-1,14,0,HUGE_MUSHROOM_1:10)
Block(-6,19,7,HUGE_MUSHROOM_2:14)
Block(-7,17,6,HUGE_MUSHROOM_2:14)
Block(-5,16,-9,HUGE_MUSHROOM_2:14)
Block(1,19,-5,AIR)
Block(-5,17,-9,HUGE_MUSHROOM_2:14)
Block(-5,19,-9,HUGE_MUSHROOM_2:14)
Block(6,20,-8,HUGE_MUSHROOM_2:14)
Block(-5,20,-9,HUGE_MUSHROOM_2:14)
Block(-6,20,7,HUGE_MUSHROOM_2:14)
Block(3,19,1,AIR)
Block(3,10,1,HUGE_MUSHROOM_1:10)
Block(5,20,5,HUGE_MUSHROOM_2:14)
Block(-1,20,0,HUGE_MUSHROOM_2:14)
Block(-1,21,0,HUGE_MUSHROOM_2:14)
Block(5,18,5,HUGE_MUSHROOM_2:14)
Block(5,17,5,AIR)
Block(5,19,5,HUGE_MUSHROOM_2:14)
Block(-9,16,-7,HUGE_MUSHROOM_2:14)
Block(5,19,-3,HUGE_MUSHROOM_2:14)
Block(-9,15,-7,HUGE_MUSHROOM_2:14)
Block(6,17,-8,HUGE_MUSHROOM_2:14)
Block(-9,17,-7,HUGE_MUSHROOM_2:14)
Block(6,19,-8,HUGE_MUSHROOM_2:14)
Block(-9,19,-7,HUGE_MUSHROOM_2:14)
Block(-7,20,6,HUGE_MUSHROOM_2:14)
Block(-1,20,-5,HUGE_MUSHROOM_2:14)
Block(-1,21,-5,HUGE_MUSHROOM_2:14)
Block(-7,19,6,HUGE_MUSHROOM_2:14)
Block(3,20,1,HUGE_MUSHROOM_2:14)
Block(3,21,1,HUGE_MUSHROOM_2:14)
Block(-6,17,7,HUGE_MUSHROOM_2:14)
Block(1,9,0,HUGE_MUSHROOM_1:10)
Block(1,8,0,HUGE_MUSHROOM_1:10)
Block(1,7,0,HUGE_MUSHROOM_1:10)
Block(3,20,-1,HUGE_MUSHROOM_2:14)
Block(3,21,-1,HUGE_MUSHROOM_2:14)
Block(9,17,-1,HUGE_MUSHROOM_2:14)
Block(9,19,-1,HUGE_MUSHROOM_2:14)
Block(-8,20,-5,HUGE_MUSHROOM_2:14)
Block(0,21,6,HUGE_MUSHROOM_2:14)
Block(0,20,6,HUGE_MUSHROOM_2:14)
Block(-1,20,4,HUGE_MUSHROOM_2:14)
Block(-1,21,4,HUGE_MUSHROOM_2:14)
Block(-3,20,-5,HUGE_MUSHROOM_2:14)
Block(-3,21,-5,HUGE_MUSHROOM_2:14)
Block(-2,20,7,HUGE_MUSHROOM_2:14)
Block(-2,17,7,AIR)
Block(-2,18,7,HUGE_MUSHROOM_2:14)
Block(-2,19,7,HUGE_MUSHROOM_2:14)
Block(0,19,6,HUGE_MUSHROOM_2:14)
Block(-3,19,-5,HUGE_MUSHROOM_2:14)
Block(9,16,5,HUGE_MUSHROOM_2:14)
Block(-6,19,3,HUGE_MUSHROOM_2:14)
Block(9,15,5,HUGE_MUSHROOM_2:14)
Block(-7,20,-7,HUGE_MUSHROOM_2:14)
Block(4,21,2,HUGE_MUSHROOM_2:14)
Block(4,20,2,HUGE_MUSHROOM_2:14)
Block(-7,17,-7,HUGE_MUSHROOM_2:14)
Block(-10,17,-4,HUGE_MUSHROOM_2:14)
Block(9,18,5,HUGE_MUSHROOM_2:14)
Block(7,19,-10,HUGE_MUSHROOM_2:14)
Block(-6,20,3,HUGE_MUSHROOM_2:14)
Block(-10,16,-4,HUGE_MUSHROOM_2:14)
Block(9,17,5,HUGE_MUSHROOM_2:14)
Block(7,18,-10,HUGE_MUSHROOM_2:14)
Block(-6,21,3,HUGE_MUSHROOM_2:14)
Block(-10,15,-4,HUGE_MUSHROOM_2:14)
Block(0,20,-3,HUGE_MUSHROOM_2:14)
Block(9,19,5,HUGE_MUSHROOM_2:14)
Block(0,21,-3,HUGE_MUSHROOM_2:14)
Block(7,15,-10,HUGE_MUSHROOM_2:14)
Block(-7,19,-7,HUGE_MUSHROOM_2:14)
Block(7,17,-10,HUGE_MUSHROOM_2:14)
Block(-10,19,-4,HUGE_MUSHROOM_2:14)
Block(6,19,3,HUGE_MUSHROOM_2:14)
Block(7,16,-10,HUGE_MUSHROOM_2:14)
Block(6,18,3,HUGE_MUSHROOM_2:14)
Block(-2,15,10,HUGE_MUSHROOM_2:14)
Block(-2,16,10,HUGE_MUSHROOM_2:14)
Block(-2,19,10,HUGE_MUSHROOM_2:14)
Block(4,19,2,HUGE_MUSHROOM_2:14)
Block(5,19,9,HUGE_MUSHROOM_2:14)
Block(-2,17,10,HUGE_MUSHROOM_2:14)
Block(5,17,9,HUGE_MUSHROOM_2:14)
Block(-2,18,10,HUGE_MUSHROOM_2:14)
Block(-8,16,4,AIR)
Block(-8,17,4,HUGE_MUSHROOM_2:14)
Block(1,6,0,HUGE_MUSHROOM_1:10)
Block(5,16,9,HUGE_MUSHROOM_2:14)
Block(1,5,0,HUGE_MUSHROOM_1:10)
Block(5,15,9,HUGE_MUSHROOM_2:14)
Block(1,4,0,HUGE_MUSHROOM_1:10)
Block(-12,18,0,HUGE_MUSHROOM_2:14)
Block(1,3,0,HUGE_MUSHROOM_1:10)
Block(-12,17,0,HUGE_MUSHROOM_2:14)
Block(-9,20,-3,HUGE_MUSHROOM_2:14)
Block(1,2,0,HUGE_MUSHROOM_1:10)
Block(1,1,0,HUGE_MUSHROOM_1:10)
Block(1,0,0,HUGE_MUSHROOM_1:10)
Block(3,20,8,HUGE_MUSHROOM_2:14)
Block(2,21,5,HUGE_MUSHROOM_2:14)
Block(10,19,-1,HUGE_MUSHROOM_2:14)
Block(10,17,-1,HUGE_MUSHROOM_2:14)
Block(10,16,-1,HUGE_MUSHROOM_2:14)
Block(-2,20,-7,HUGE_MUSHROOM_2:14)
Block(-2,21,-7,HUGE_MUSHROOM_2:14)
Block(10,20,-1,HUGE_MUSHROOM_2:14)
Block(-2,19,-7,HUGE_MUSHROOM_2:14)
Block(7,20,6,HUGE_MUSHROOM_2:14)
Block(-2,18,-7,HUGE_MUSHROOM_2:14)
Block(2,20,5,HUGE_MUSHROOM_2:14)
Block(0,19,-3,HUGE_MUSHROOM_1:10)
Block(1,19,0,HUGE_MUSHROOM_1:10)
Block(1,18,0,HUGE_MUSHROOM_1:10)
Block(1,17,0,HUGE_MUSHROOM_1:10)
Block(1,16,0,HUGE_MUSHROOM_1:10)
Block(0,18,-3,HUGE_MUSHROOM_1:10)
Block(1,15,0,HUGE_MUSHROOM_1:10)
Block(4,20,-1,HUGE_MUSHROOM_2:14)
Block(1,14,0,HUGE_MUSHROOM_1:10)
Block(4,21,-1,HUGE_MUSHROOM_2:14)
Block(1,13,0,HUGE_MUSHROOM_1:10)
Block(1,12,0,HUGE_MUSHROOM_1:10)
Block(1,11,0,HUGE_MUSHROOM_1:10)
Block(1,10,0,HUGE_MUSHROOM_1:10)
Block(10,15,-1,HUGE_MUSHROOM_2:14)
Block(-4,18,10,HUGE_MUSHROOM_2:14)
Block(-4,17,10,HUGE_MUSHROOM_2:14)
Block(-4,16,10,HUGE_MUSHROOM_2:14)
Block(-4,15,10,HUGE_MUSHROOM_2:14)
Block(1,21,-1,HUGE_MUSHROOM_2:14)
Block(1,20,-1,HUGE_MUSHROOM_2:14)
Block(1,21,0,HUGE_MUSHROOM_2:14)
Block(-1,18,-12,HUGE_MUSHROOM_2:14)
Block(1,20,0,HUGE_MUSHROOM_2:14)
Block(-1,17,-12,HUGE_MUSHROOM_2:14)
Block(-1,16,-12,HUGE_MUSHROOM_2:14)
Block(-10,16,3,HUGE_MUSHROOM_2:14)
Block(-1,15,-12,HUGE_MUSHROOM_2:14)
Block(-10,17,3,HUGE_MUSHROOM_2:14)
Block(-6,21,-5,HUGE_MUSHROOM_2:14)
Block(-10,15,3,HUGE_MUSHROOM_2:14)
Block(-12,18,-2,HUGE_MUSHROOM_2:14)
Block(-12,17,-2,HUGE_MUSHROOM_2:14)
Block(-12,16,-2,HUGE_MUSHROOM_2:14)
Block(-12,15,-2,HUGE_MUSHROOM_2:14)
Block(-5,17,10,HUGE_MUSHROOM_2:14)
Block(-5,16,10,HUGE_MUSHROOM_2:14)
Block(11,16,2,HUGE_MUSHROOM_2:14)
Block(-3,20,1,HUGE_MUSHROOM_2:14)
Block(11,17,2,HUGE_MUSHROOM_2:14)
Block(-4,20,6,HUGE_MUSHROOM_2:14)
Block(-3,21,1,HUGE_MUSHROOM_2:14)
Block(-11,19,-2,HUGE_MUSHROOM_2:14)
Block(7,19,6,HUGE_MUSHROOM_2:14)
Block(7,17,6,HUGE_MUSHROOM_2:14)
Block(2,19,5,HUGE_MUSHROOM_2:14)
Block(7,16,6,HUGE_MUSHROOM_2:14)
Block(-8,17,-5,HUGE_MUSHROOM_2:14)
Block(-10,18,3,HUGE_MUSHROOM_2:14)
Block(-8,19,-5,HUGE_MUSHROOM_2:14)
Block(-10,19,3,HUGE_MUSHROOM_2:14)
Block(-11,16,-2,HUGE_MUSHROOM_2:14)
Block(-11,15,-2,HUGE_MUSHROOM_2:14)
Block(-11,18,-2,HUGE_MUSHROOM_2:14)
Block(-11,17,-2,HUGE_MUSHROOM_2:14)
Block(-9,16,7,HUGE_MUSHROOM_2:14)
Block(-9,17,7,HUGE_MUSHROOM_2:14)
Block(6,18,-11,HUGE_MUSHROOM_2:14)
Block(-4,19,6,HUGE_MUSHROOM_2:14)
Block(-4,18,6,HUGE_MUSHROOM_2:14)
Block(6,17,-11,HUGE_MUSHROOM_2:14)
Block(6,16,-11,HUGE_MUSHROOM_2:14)
Block(9,15,3,HUGE_MUSHROOM_2:14)
Block(9,16,3,HUGE_MUSHROOM_2:14)
Block(9,17,3,HUGE_MUSHROOM_2:14)
Block(5,20,-7,HUGE_MUSHROOM_2:14)
Block(9,19,3,HUGE_MUSHROOM_2:14)
Block(4,19,-3,HUGE_MUSHROOM_2:14)
Block(0,19,-7,HUGE_MUSHROOM_2:14)
Block(9,20,-3,HUGE_MUSHROOM_2:14)
Block(0,20,8,HUGE_MUSHROOM_2:14)
Block(-1,16,-9,AIR)
Block(-2,16,9,HUGE_MUSHROOM_2:14)
Block(-1,18,-9,HUGE_MUSHROOM_2:14)
Block(9,19,-3,HUGE_MUSHROOM_2:14)
Block(9,17,-3,HUGE_MUSHROOM_2:14)
Block(5,19,-7,HUGE_MUSHROOM_2:14)
Block(5,18,-7,HUGE_MUSHROOM_2:14)
Block(8,19,1,HUGE_MUSHROOM_2:14)
Block(-1,20,-9,HUGE_MUSHROOM_2:14)
Block(8,17,1,HUGE_MUSHROOM_2:14)
Block(-1,21,-9,HUGE_MUSHROOM_2:14)
Block(-2,20,9,HUGE_MUSHROOM_2:14)
Block(-1,19,-9,HUGE_MUSHROOM_2:14)
Block(-2,17,9,HUGE_MUSHROOM_2:14)
Block(-2,19,9,HUGE_MUSHROOM_2:14)
Block(0,19,8,HUGE_MUSHROOM_2:14)
Block(0,17,8,HUGE_MUSHROOM_2:14)
Block(-1,21,5,HUGE_MUSHROOM_2:14)
Block(-6,19,1,HUGE_MUSHROOM_2:14)
Block(-1,20,5,HUGE_MUSHROOM_2:14)
Block(3,17,-8,HUGE_MUSHROOM_2:14)
Block(-7,21,1,HUGE_MUSHROOM_2:14)
Block(4,20,0,HUGE_MUSHROOM_2:14)
Block(4,21,0,HUGE_MUSHROOM_2:14)
Block(-7,20,1,HUGE_MUSHROOM_2:14)
Block(-7,19,1,HUGE_MUSHROOM_2:14)
Block(-7,18,1,HUGE_MUSHROOM_2:14)
Block(-9,19,-3,HUGE_MUSHROOM_2:14)
Block(-7,20,-2,HUGE_MUSHROOM_2:14)
Block(-9,17,-3,HUGE_MUSHROOM_2:14)
Block(-7,21,-2,HUGE_MUSHROOM_2:14)
Block(3,19,-8,HUGE_MUSHROOM_2:14)
Block(-6,21,1,HUGE_MUSHROOM_2:14)
Block(-1,19,5,HUGE_MUSHROOM_2:14)
Block(-6,20,1,HUGE_MUSHROOM_2:14)
Block(8,20,1,HUGE_MUSHROOM_2:14)
Block(3,20,-8,HUGE_MUSHROOM_2:14)
Block(5,21,0,HUGE_MUSHROOM_2:14)
Block(5,20,0,HUGE_MUSHROOM_2:14)
Block(-6,19,-9,HUGE_MUSHROOM_2:14)
Block(-6,17,-9,HUGE_MUSHROOM_2:14)
Block(-6,16,-9,HUGE_MUSHROOM_2:14)
Block(-6,15,-9,HUGE_MUSHROOM_2:14)
Block(2,1,-1,HUGE_MUSHROOM_1:10)
Block(2,0,-1,HUGE_MUSHROOM_1:10)
Block(2,5,-1,HUGE_MUSHROOM_1:10)
Block(2,4,-1,HUGE_MUSHROOM_1:10)
Block(2,3,-1,HUGE_MUSHROOM_1:10)
Block(2,2,-1,HUGE_MUSHROOM_1:10)
Block(2,9,-1,HUGE_MUSHROOM_1:10)
Block(-7,18,-2,HUGE_MUSHROOM_2:14)
Block(-7,19,-2,HUGE_MUSHROOM_2:14)
Block(-4,20,-3,HUGE_MUSHROOM_2:14)
Block(-4,21,-3,HUGE_MUSHROOM_2:14)
Block(5,19,0,HUGE_MUSHROOM_2:14)
Block(1,21,3,HUGE_MUSHROOM_2:14)
Block(1,20,3,HUGE_MUSHROOM_2:14)
Block(-3,19,4,HUGE_MUSHROOM_2:14)
Block(-5,20,-3,HUGE_MUSHROOM_2:14)
Block(4,21,-3,HUGE_MUSHROOM_2:14)
Block(4,20,-3,HUGE_MUSHROOM_2:14)
Block(-5,21,-3,HUGE_MUSHROOM_2:14)
Block(2,21,-4,HUGE_MUSHROOM_2:14)
Block(2,20,-4,HUGE_MUSHROOM_2:14)
Block(-10,19,-5,HUGE_MUSHROOM_2:14)
Block(-10,15,-5,HUGE_MUSHROOM_2:14)
Block(-10,16,-5,HUGE_MUSHROOM_2:14)
Block(-10,17,-5,HUGE_MUSHROOM_2:14)
Block(-3,21,4,HUGE_MUSHROOM_2:14)
Block(-3,20,4,HUGE_MUSHROOM_2:14)
Block(-6,19,-2,HUGE_MUSHROOM_2:14)
Block(-7,20,5,HUGE_MUSHROOM_2:14)
Block(2,21,1,HUGE_MUSHROOM_2:14)
Block(-9,20,0,HUGE_MUSHROOM_2:14)
Block(-1,20,9,HUGE_MUSHROOM_2:14)
Block(2,20,1,HUGE_MUSHROOM_2:14)
Block(4,20,7,HUGE_MUSHROOM_2:14)
Block(-5,19,-3,HUGE_MUSHROOM_2:14)
Block(0,15,1,HUGE_MUSHROOM_1:10)
Block(0,14,1,HUGE_MUSHROOM_1:10)
Block(0,13,1,HUGE_MUSHROOM_1:10)
Block(5,15,10,HUGE_MUSHROOM_2:14)
Block(0,12,1,HUGE_MUSHROOM_1:10)
Block(5,16,10,HUGE_MUSHROOM_2:14)
Block(5,17,10,HUGE_MUSHROOM_2:14)
Block(0,19,1,HUGE_MUSHROOM_1:10)
Block(0,18,1,HUGE_MUSHROOM_1:10)
Block(5,18,10,HUGE_MUSHROOM_2:14)
Block(0,17,1,HUGE_MUSHROOM_1:10)
Block(-7,19,5,HUGE_MUSHROOM_2:14)
Block(0,16,1,HUGE_MUSHROOM_1:10)
Block(-6,16,8,HUGE_MUSHROOM_2:14)
Block(-6,17,8,HUGE_MUSHROOM_2:14)
Block(-9,19,0,HUGE_MUSHROOM_2:14)
Block(-6,19,8,HUGE_MUSHROOM_2:14)
Block(0,11,1,HUGE_MUSHROOM_1:10)
Block(2,15,-12,HUGE_MUSHROOM_2:14)
Block(-1,16,9,HUGE_MUSHROOM_2:14)
Block(0,10,1,HUGE_MUSHROOM_1:10)
Block(2,16,-12,HUGE_MUSHROOM_2:14)
Block(-9,17,0,HUGE_MUSHROOM_2:14)
Block(-1,17,9,HUGE_MUSHROOM_2:14)
Block(2,17,-12,HUGE_MUSHROOM_2:14)
Block(-6,15,8,HUGE_MUSHROOM_2:14)
Block(2,18,-12,HUGE_MUSHROOM_2:14)
Block(-1,19,9,HUGE_MUSHROOM_2:14)
Block(-6,20,-2,HUGE_MUSHROOM_2:14)
Block(-6,21,-2,HUGE_MUSHROOM_2:14)
Block(5,20,4,HUGE_MUSHROOM_2:14)
Block(5,21,4,HUGE_MUSHROOM_2:14)
Block(5,19,4,HUGE_MUSHROOM_2:14)
Block(5,18,4,HUGE_MUSHROOM_2:14)
Block(2,20,-8,HUGE_MUSHROOM_2:14)
Block(2,21,-8,HUGE_MUSHROOM_2:14)
Block(0,19,10,HUGE_MUSHROOM_2:14)
Block(3,19,5,HUGE_MUSHROOM_2:14)
Block(6,20,-4,HUGE_MUSHROOM_2:14)
Block(6,21,-4,HUGE_MUSHROOM_2:14)
Block(0,15,10,HUGE_MUSHROOM_2:14)
Block(0,17,10,HUGE_MUSHROOM_2:14)
Block(0,16,10,HUGE_MUSHROOM_2:14)
Block(2,11,1,HUGE_MUSHROOM_1:10)
Block(2,10,1,HUGE_MUSHROOM_1:10)
Block(2,13,1,HUGE_MUSHROOM_1:10)
Block(2,12,1,HUGE_MUSHROOM_1:10)
Block(3,21,5,HUGE_MUSHROOM_2:14)
Block(3,20,5,HUGE_MUSHROOM_2:14)
Block(-7,17,5,HUGE_MUSHROOM_2:14)
Block(-4,21,2,HUGE_MUSHROOM_2:14)
Block(-4,20,2,HUGE_MUSHROOM_2:14)
Block(2,14,1,HUGE_MUSHROOM_1:10)
Block(6,18,-4,HUGE_MUSHROOM_2:14)
Block(2,19,-8,HUGE_MUSHROOM_2:14)
Block(2,18,-8,HUGE_MUSHROOM_2:14)
Block(6,19,-4,HUGE_MUSHROOM_2:14)
Block(4,17,7,HUGE_MUSHROOM_2:14)
Block(4,19,7,HUGE_MUSHROOM_2:14)
Block(8,17,-3,HUGE_MUSHROOM_2:14)
Block(8,19,-3,HUGE_MUSHROOM_2:14)
Block(6,20,6,HUGE_MUSHROOM_2:14)
Block(7,19,-4,HUGE_MUSHROOM_2:14)
Block(7,17,-4,HUGE_MUSHROOM_2:14)
Block(3,0,-1,HUGE_MUSHROOM_1:10)
Block(3,1,-1,HUGE_MUSHROOM_1:10)
Block(-5,19,6,HUGE_MUSHROOM_2:14)
Block(-5,18,6,HUGE_MUSHROOM_2:14)
Block(-8,18,7,HUGE_MUSHROOM_2:14)
Block(-8,17,7,HUGE_MUSHROOM_2:14)
Block(-8,19,7,HUGE_MUSHROOM_2:14)
Block(8,20,-3,HUGE_MUSHROOM_2:14)
Block(1,19,-7,HUGE_MUSHROOM_2:14)
Block(-8,16,7,HUGE_MUSHROOM_2:14)
Block(-5,20,6,HUGE_MUSHROOM_2:14)
Block(-8,15,7,HUGE_MUSHROOM_2:14)
Block(4,18,-7,HUGE_MUSHROOM_2:14)
Block(4,19,-7,HUGE_MUSHROOM_2:14)
Block(4,19,-10,HUGE_MUSHROOM_2:14)
Block(11,15,-6,HUGE_MUSHROOM_2:14)
Block(11,18,-6,HUGE_MUSHROOM_2:14)
Block(11,17,-6,HUGE_MUSHROOM_2:14)
Block(11,16,-6,HUGE_MUSHROOM_2:14)
Block(7,20,-4,HUGE_MUSHROOM_2:14)
Block(4,0,4,HUGE_MUSHROOM_1:10)
Block(6,17,6,HUGE_MUSHROOM_2:14)
Block(-11,17,3,HUGE_MUSHROOM_2:14)
Block(-11,16,3,HUGE_MUSHROOM_2:14)
Block(3,16,-11,HUGE_MUSHROOM_2:14)
Block(3,15,-11,HUGE_MUSHROOM_2:14)
Block(6,19,6,HUGE_MUSHROOM_2:14)
Block(3,17,-11,HUGE_MUSHROOM_2:14)
Block(5,0,2,HUGE_MUSHROOM_1:10)
Block(3,19,-11,HUGE_MUSHROOM_2:14)
Block(3,16,11,HUGE_MUSHROOM_2:14)
Block(3,17,11,HUGE_MUSHROOM_2:14)
Block(3,18,11,HUGE_MUSHROOM_2:14)
Block(-1,17,-2,HUGE_MUSHROOM_1:10)
Block(-1,18,-2,HUGE_MUSHROOM_1:10)
Block(10,18,3,HUGE_MUSHROOM_2:14)
Block(0,20,-7,HUGE_MUSHROOM_2:14)
Block(10,17,-6,HUGE_MUSHROOM_2:14)
Block(10,17,3,HUGE_MUSHROOM_2:14)
Block(-1,20,-2,HUGE_MUSHROOM_2:14)
Block(-2,20,2,HUGE_MUSHROOM_2:14)
Block(0,21,-7,HUGE_MUSHROOM_2:14)
Block(-1,21,-2,HUGE_MUSHROOM_2:14)
Block(10,19,-6,HUGE_MUSHROOM_2:14)
Block(10,16,-6,HUGE_MUSHROOM_2:14)
Block(10,16,3,HUGE_MUSHROOM_2:14)
Block(10,15,-6,HUGE_MUSHROOM_2:14)
Block(10,15,3,HUGE_MUSHROOM_2:14)
Block(4,17,-10,HUGE_MUSHROOM_2:14)
Block(4,15,-10,HUGE_MUSHROOM_2:14)
Block(4,16,-10,HUGE_MUSHROOM_2:14)
Block(2,15,11,HUGE_MUSHROOM_2:14)
Block(2,16,11,HUGE_MUSHROOM_2:14)
Block(8,16,5,HUGE_MUSHROOM_2:14)
Block(8,17,5,HUGE_MUSHROOM_2:14)
Block(12,17,-5,HUGE_MUSHROOM_2:14)
Block(12,16,-5,HUGE_MUSHROOM_2:14)
Block(8,19,5,HUGE_MUSHROOM_2:14)
Block(2,19,11,HUGE_MUSHROOM_2:14)
Block(-2,21,-2,HUGE_MUSHROOM_2:14)
Block(-2,20,-2,HUGE_MUSHROOM_2:14)
Block(2,17,11,HUGE_MUSHROOM_2:14)
Block(-2,21,2,HUGE_MUSHROOM_2:14)
Block(2,18,11,HUGE_MUSHROOM_2:14)
Block(4,16,10,HUGE_MUSHROOM_2:14)
Block(4,17,10,HUGE_MUSHROOM_2:14)
Block(8,15,5,HUGE_MUSHROOM_2:14)
Block(4,15,10,HUGE_MUSHROOM_2:14)
Block(1,21,-7,HUGE_MUSHROOM_2:14)
Block(0,21,1,HUGE_MUSHROOM_2:14)
Block(4,18,10,HUGE_MUSHROOM_2:14)
Block(0,20,1,HUGE_MUSHROOM_2:14)
Block(4,19,10,HUGE_MUSHROOM_2:14)
Block(1,20,-7,HUGE_MUSHROOM_2:14)
Block(1,15,11,HUGE_MUSHROOM_2:14)
Block(1,16,11,HUGE_MUSHROOM_2:14)
Block(-3,19,7,HUGE_MUSHROOM_2:14)
Block(-3,20,-2,HUGE_MUSHROOM_2:14)
Block(1,17,11,HUGE_MUSHROOM_2:14)
Block(-3,18,7,HUGE_MUSHROOM_2:14)
Block(1,18,11,HUGE_MUSHROOM_2:14)
Block(1,19,11,HUGE_MUSHROOM_2:14)
Block(-1,16,1,HUGE_MUSHROOM_1:10)
Block(-1,17,1,HUGE_MUSHROOM_1:10)
Block(-1,18,1,HUGE_MUSHROOM_1:10)
Block(-1,19,1,HUGE_MUSHROOM_1:10)
Block(-3,20,7,HUGE_MUSHROOM_2:14)
Block(-1,14,1,HUGE_MUSHROOM_1:10)
Block(-1,15,1,HUGE_MUSHROOM_1:10)
Block(1,20,6,HUGE_MUSHROOM_2:14)
Block(3,21,-4,HUGE_MUSHROOM_2:14)
Block(3,20,-4,HUGE_MUSHROOM_2:14)
Block(1,21,6,HUGE_MUSHROOM_2:14)
Block(-1,20,1,HUGE_MUSHROOM_2:14)
Block(-3,21,-2,HUGE_MUSHROOM_2:14)
Block(-1,21,1,HUGE_MUSHROOM_2:14)
Block(-2,15,-12,HUGE_MUSHROOM_2:14)
Block(0,7,-1,HUGE_MUSHROOM_1:10)
Block(-2,16,-12,HUGE_MUSHROOM_2:14)
Block(-2,17,-12,HUGE_MUSHROOM_2:14)
Block(0,9,-1,HUGE_MUSHROOM_1:10)
Block(-2,18,-12,HUGE_MUSHROOM_2:14)
Block(0,8,-1,HUGE_MUSHROOM_1:10)
Block(6,17,-7,HUGE_MUSHROOM_2:14)
Block(6,19,-7,HUGE_MUSHROOM_2:14)
Block(-10,20,-1,HUGE_MUSHROOM_2:14)
Block(3,21,2,HUGE_MUSHROOM_2:14)
Block(3,20,2,HUGE_MUSHROOM_2:14)
Block(3,7,1,HUGE_MUSHROOM_1:10)
Block(3,6,1,HUGE_MUSHROOM_1:10)
Block(3,5,1,HUGE_MUSHROOM_1:10)
Block(-10,19,-1,HUGE_MUSHROOM_2:14)
Block(3,4,1,HUGE_MUSHROOM_1:10)
Block(4,21,-7,HUGE_MUSHROOM_2:14)
Block(4,20,-7,HUGE_MUSHROOM_2:14)
Block(3,9,1,HUGE_MUSHROOM_1:10)
Block(3,8,1,HUGE_MUSHROOM_1:10)
Block(-10,17,-1,HUGE_MUSHROOM_2:14)
Block(-10,16,-1,HUGE_MUSHROOM_2:14)
Block(6,15,9,HUGE_MUSHROOM_2:14)
Block(6,16,9,HUGE_MUSHROOM_2:14)
Block(6,17,9,HUGE_MUSHROOM_2:14)
Block(-9,15,-6,HUGE_MUSHROOM_2:14)
Block(-9,16,-6,HUGE_MUSHROOM_2:14)
Block(-9,17,-6,HUGE_MUSHROOM_2:14)
Block(-9,19,-6,HUGE_MUSHROOM_2:14)
Block(2,17,8,HUGE_MUSHROOM_2:14)
Block(2,19,8,HUGE_MUSHROOM_2:14)
Block(-11,16,-5,HUGE_MUSHROOM_2:14)
Block(1,21,-4,HUGE_MUSHROOM_2:14)
Block(-11,17,-5,HUGE_MUSHROOM_2:14)
Block(1,20,-4,HUGE_MUSHROOM_2:14)
Block(-11,15,-5,HUGE_MUSHROOM_2:14)
Block(-11,18,-5,HUGE_MUSHROOM_2:14)
Block(3,3,1,HUGE_MUSHROOM_1:10)
Block(6,18,9,HUGE_MUSHROOM_2:14)
Block(3,2,1,HUGE_MUSHROOM_1:10)
Block(6,19,9,HUGE_MUSHROOM_2:14)
Block(3,1,1,HUGE_MUSHROOM_1:10)
Block(3,0,1,HUGE_MUSHROOM_1:10)
Block(2,0,3,HUGE_MUSHROOM_1:10)
Block(-5,19,3,HUGE_MUSHROOM_2:14)
Block(-5,21,3,HUGE_MUSHROOM_2:14)
Block(6,20,-7,HUGE_MUSHROOM_2:14)
Block(2,20,8,HUGE_MUSHROOM_2:14)
Block(10,16,-9,HUGE_MUSHROOM_2:14)
Block(-5,20,3,HUGE_MUSHROOM_2:14)
Block(7,19,3,HUGE_MUSHROOM_2:14)
Block(7,17,3,HUGE_MUSHROOM_2:14)
Block(11,17,-2,HUGE_MUSHROOM_2:14)
Block(11,16,-2,HUGE_MUSHROOM_2:14)
Block(11,19,-2,HUGE_MUSHROOM_2:14)
Block(-8,18,-2,HUGE_MUSHROOM_2:14)
Block(-8,19,-2,HUGE_MUSHROOM_2:14)
Block(9,16,-7,HUGE_MUSHROOM_2:14)
Block(9,17,-7,HUGE_MUSHROOM_2:14)
Block(9,19,-7,HUGE_MUSHROOM_2:14)
Block(-4,19,9,HUGE_MUSHROOM_2:14)
Block(-9,15,4,HUGE_MUSHROOM_2:14)
Block(-9,16,4,HUGE_MUSHROOM_2:14)
Block(-9,17,4,HUGE_MUSHROOM_2:14)
Block(9,15,-7,HUGE_MUSHROOM_2:14)
Block(-3,15,-11,HUGE_MUSHROOM_2:14)
Block(-9,19,4,HUGE_MUSHROOM_2:14)
Block(-3,17,-11,HUGE_MUSHROOM_2:14)
Block(-3,16,-11,HUGE_MUSHROOM_2:14)
Block(-3,19,-11,HUGE_MUSHROOM_2:14)
Block(-4,17,9,HUGE_MUSHROOM_2:14)
Block(-3,18,-11,HUGE_MUSHROOM_2:14)
Block(-4,16,9,HUGE_MUSHROOM_2:14)
Block(-4,15,9,HUGE_MUSHROOM_2:14)
Block(8,17,-7,HUGE_MUSHROOM_2:14)
Block(7,20,3,HUGE_MUSHROOM_2:14)
Block(8,19,-7,HUGE_MUSHROOM_2:14)
Block(8,16,-7,HUGE_MUSHROOM_2:14)
Block(-8,20,-2,HUGE_MUSHROOM_2:14)
Block(-8,21,-2,HUGE_MUSHROOM_2:14)
Block(6,21,2,HUGE_MUSHROOM_2:14)
Block(6,20,2,HUGE_MUSHROOM_2:14)
Block(8,20,-7,HUGE_MUSHROOM_2:14)
Block(8,16,8,HUGE_MUSHROOM_2:14)
Block(8,15,8,HUGE_MUSHROOM_2:14)
Block(8,18,8,HUGE_MUSHROOM_2:14)
Block(8,17,8,HUGE_MUSHROOM_2:14)
Block(9,15,6,HUGE_MUSHROOM_2:14)
Block(-12,17,1,HUGE_MUSHROOM_2:14)
Block(-12,16,1,HUGE_MUSHROOM_2:14)
Block(9,17,6,HUGE_MUSHROOM_2:14)
Block(9,16,6,HUGE_MUSHROOM_2:14)
Block(10,19,-2,HUGE_MUSHROOM_2:14)
Block(-8,19,3,HUGE_MUSHROOM_2:14)
Block(10,17,-2,HUGE_MUSHROOM_2:14)
Block(-8,17,3,HUGE_MUSHROOM_2:14)
Block(-7,20,-6,HUGE_MUSHROOM_2:14)
Block(11,15,-2,HUGE_MUSHROOM_2:14)
Block(6,19,2,HUGE_MUSHROOM_2:14)
Block(-7,17,-6,HUGE_MUSHROOM_2:14)
Block(10,20,-2,HUGE_MUSHROOM_2:14)
Block(-8,20,3,HUGE_MUSHROOM_2:14)
Block(0,20,-4,HUGE_MUSHROOM_2:14)
Block(9,18,6,HUGE_MUSHROOM_2:14)
Block(0,21,-4,HUGE_MUSHROOM_2:14)
Block(-7,19,-6,HUGE_MUSHROOM_2:14)
Block(6,18,2,HUGE_MUSHROOM_2:14)
Block(0,15,-11,HUGE_MUSHROOM_2:14)
Block(1,9,1,HUGE_MUSHROOM_1:10)
Block(1,8,1,HUGE_MUSHROOM_1:10)
Block(1,7,1,HUGE_MUSHROOM_1:10)
Block(1,6,1,HUGE_MUSHROOM_1:10)
Block(-2,19,6,HUGE_MUSHROOM_2:14)
Block(-2,18,6,HUGE_MUSHROOM_2:14)
Block(-1,19,-6,HUGE_MUSHROOM_2:14)
Block(-8,19,-6,HUGE_MUSHROOM_2:14)
Block(-8,17,-6,HUGE_MUSHROOM_2:14)
Block(-2,21,6,HUGE_MUSHROOM_2:14)
Block(10,16,-2,HUGE_MUSHROOM_2:14)
Block(-2,20,6,HUGE_MUSHROOM_2:14)
Block(-1,21,-6,HUGE_MUSHROOM_2:14)
Block(10,15,-2,HUGE_MUSHROOM_2:14)
Block(-1,20,-6,HUGE_MUSHROOM_2:14)
Block(-8,16,-6,AIR)
Block(-10,15,2,HUGE_MUSHROOM_2:14)
Block(-10,16,2,HUGE_MUSHROOM_2:14)
Block(-2,21,-6,HUGE_MUSHROOM_2:14)
Block(-2,20,-6,HUGE_MUSHROOM_2:14)
Block(-2,19,-6,HUGE_MUSHROOM_2:14)
Block(-8,20,-6,HUGE_MUSHROOM_2:14)
Block(0,20,5,HUGE_MUSHROOM_2:14)
Block(0,19,-11,HUGE_MUSHROOM_2:14)
Block(0,16,-11,HUGE_MUSHROOM_2:14)
Block(0,17,-11,HUGE_MUSHROOM_2:14)
Block(0,21,5,HUGE_MUSHROOM_2:14)
Block(-3,20,-6,HUGE_MUSHROOM_2:14)
Block(-3,20,0,HUGE_MUSHROOM_2:14)
Block(-3,21,0,HUGE_MUSHROOM_2:14)
Block(-7,18,-10,HUGE_MUSHROOM_2:14)
Block(-7,17,-10,HUGE_MUSHROOM_2:14)
Block(-6,19,-6,HUGE_MUSHROOM_2:14)
Block(4,19,3,HUGE_MUSHROOM_2:14)
Block(1,20,-10,HUGE_MUSHROOM_2:14)
Block(-3,21,-6,HUGE_MUSHROOM_2:14)
Block(-7,16,-10,HUGE_MUSHROOM_2:14)
Block(-6,18,-6,HUGE_MUSHROOM_2:14)
Block(-7,15,-10,HUGE_MUSHROOM_2:14)
Block(-10,19,2,HUGE_MUSHROOM_2:14)
Block(-10,17,2,HUGE_MUSHROOM_2:14)
Block(-6,21,-6,HUGE_MUSHROOM_2:14)
Block(-6,20,-6,HUGE_MUSHROOM_2:14)
Block(1,19,-10,HUGE_MUSHROOM_2:14)
Block(1,16,-10,HUGE_MUSHROOM_2:14)
Block(-3,19,-6,HUGE_MUSHROOM_2:14)
Block(1,17,-10,HUGE_MUSHROOM_2:14)
Block(-12,17,-1,HUGE_MUSHROOM_2:14)
Block(-12,18,-1,HUGE_MUSHROOM_2:14)
Block(-12,15,-1,HUGE_MUSHROOM_2:14)
Block(-12,16,-1,HUGE_MUSHROOM_2:14)
Block(1,5,1,HUGE_MUSHROOM_1:10)
Block(1,4,1,HUGE_MUSHROOM_1:10)
Block(1,3,1,HUGE_MUSHROOM_1:10)
Block(11,15,1,HUGE_MUSHROOM_2:14)
Block(1,2,1,HUGE_MUSHROOM_1:10)
Block(1,1,1,HUGE_MUSHROOM_1:10)
Block(11,17,1,HUGE_MUSHROOM_2:14)
Block(1,0,1,HUGE_MUSHROOM_1:10)
Block(11,16,1,HUGE_MUSHROOM_2:14)
Block(5,20,8,HUGE_MUSHROOM_2:14)
Block(11,18,1,HUGE_MUSHROOM_2:14)
Block(-4,18,-6,HUGE_MUSHROOM_2:14)
Block(5,19,8,HUGE_MUSHROOM_2:14)
Block(5,17,8,HUGE_MUSHROOM_2:14)
Block(5,16,8,HUGE_MUSHROOM_2:14)
Block(-4,19,-6,HUGE_MUSHROOM_2:14)
Block(3,19,9,HUGE_MUSHROOM_2:14)
Block(3,16,9,HUGE_MUSHROOM_2:14)
Block(-4,21,-6,HUGE_MUSHROOM_2:14)
Block(-4,20,-6,HUGE_MUSHROOM_2:14)
Block(3,17,9,HUGE_MUSHROOM_2:14)
Block(-6,18,4,HUGE_MUSHROOM_2:14)
Block(-5,19,-6,HUGE_MUSHROOM_2:14)
Block(-5,18,-6,HUGE_MUSHROOM_2:14)
Block(-6,19,4,HUGE_MUSHROOM_2:14)
Block(-7,17,9,HUGE_MUSHROOM_2:14)
Block(-7,16,9,HUGE_MUSHROOM_2:14)
Block(3,20,9,HUGE_MUSHROOM_2:14)
Block(4,21,3,HUGE_MUSHROOM_2:14)
Block(4,20,3,HUGE_MUSHROOM_2:14)
Block(-6,21,4,HUGE_MUSHROOM_2:14)
Block(-5,21,-6,HUGE_MUSHROOM_2:14)
Block(-5,20,-6,HUGE_MUSHROOM_2:14)
Block(-6,20,4,HUGE_MUSHROOM_2:14)

#######################################################################
# +-----------------------------------------------------------------+ #
# |                            BO3 checks                           | #
# +-----------------------------------------------------------------+ #
#######################################################################

# Require a condition at a certain location in order for the BO3 to be spawned.
# BlockCheck(x,y,z,BlockName[,BlockName[,...]]) - one of the blocks must be at the location
# BlockCheckNot(x,y,z,BlockName[,BlockName[,...]]) - all the blocks must not be at the location
# LightCheck(x,y,z,minLightLevel,maxLightLevel) - light must be between min and max (inclusive)

# You can use "Solid" as a BlockName for matching all solid blocks or "All" to match all blocks that aren't air.

# Examples:
#   BlockCheck(0,-1,0,GRASS,DIRT)  Require grass or dirt just below the object
#   BlockCheck(0,-1,0,Solid)       Require any solid block just below the object
#   BlockCheck(0,-1,0,WOOL)        Require any type of wool just below the object
#   BlockCheck(0,-1,0,WOOL:0)      Require white wool just below the object
#   BlockCheckNot(0,0,0,WOOL:0)   Require that there is no white wool below the object
#   LightCheck(0,0,0,0,1)          Require almost complete darkness just below the object 
BlockCheck(0,-2,0,DIRT)

#######################################################################
# +-----------------------------------------------------------------+ #
# |                             Branches                            | #
# +-----------------------------------------------------------------+ #
#######################################################################

# Branches are objects that will spawn when this object spawns when it is used in
# the CustomStructure resource. Branches can also have branches, making complex
# structures possible. See the wiki for more details.

# Regular Branches spawn each branch with an independent chance of spawning.
# Branch(x,y,z,branchName,rotation,chance[,anotherBranchName,rotation,chance[,...]][IndividualChance])
# branchName - name of the object to spawn.
# rotation - NORTH, SOUTH, EAST or WEST.
# IndividualChance - The chance each branch has to spawn, assumed to be 100 when left blank

# Weighted Branches spawn branches with a dependent chance of spawning.
# WeightedBranch(x,y,z,branchName,rotation,chance[,anotherBranchName,rotation,chance[,...]][MaxChanceOutOf])
# MaxChanceOutOf - The chance all branches have to spawn out of, assumed to be 100 when left blank
