[META]
version=2.0
spawnOnBlockType=2
spawnSunlight=True
spawnDarkness=True
spawnWater=False
spawnLava=False
underFill=False
randomRotation=True
dig=True
tree=True
branch=False
needsFoundation=True
rarity=3
collisionPercentage=25
spawnElevationMin=0
spawnElevationMax=200
spawnInBiome=Custom
[DATA]
2,-5,-3:161.1
3,-5,-3:161.1
2,-4,-3:161.1
3,-4,-3:162.1
4,-4,-3:161.1
0,-3,-3:161.1
4,-3,-3:161.1
5,-3,-3:161.1
-2,-2,-3:161.1
-1,-2,-3:161.1
0,-2,-3:161.1
1,-2,-3:161.1
4,-2,-3:162.1
5,-2,-3:161.1
-3,-1,-3:161.1
-2,-1,-3:162.1
-1,-1,-3:161.1
0,-1,-3:162.1
1,-1,-3:161.1
4,-1,-3:162.9
5,-1,-3:161.1
-4,0,-3:161.1
4,0,-3:162.1
5,0,-3:162.5
-5,1,-3:161.1
-4,1,-3:162.1
-2,1,-3:162.1
0,1,-3:162.1
2,1,-3:161.1
3,1,-3:161.1
4,1,-3:161.1
-4,2,-3:161.1
2,2,-3:162.1
3,2,-3:162.1
5,2,-3:161.1
-3,3,-3:161.1
-2,3,-3:162.1
3,3,-3:162.9
4,3,-3:162.5
5,3,-3:161.1
-2,4,-3:161.1
-1,4,-3:161.1
0,4,-3:162.1
3,4,-3:162.9
4,4,-3:161.1
-1,5,-3:161.1
3,5,-3:161.1
1,-5,-2:161.1
3,-5,-2:161.1
-1,-4,-2:161.1
0,-4,-2:161.1
1,-4,-2:162.1
2,-4,-2:161.1
3,-4,-2:162.9
4,-4,-2:161.1
-2,-3,-2:161.1
-1,-3,-2:162.1
2,-3,-2:161.1
3,-3,-2:162.9
4,-3,-2:161.1
5,-3,-2:161.1
-3,-2,-2:161.1
1,-2,-2:162.1
2,-2,-2:161.1
3,-2,-2:162.9
4,-2,-2:162.5
5,-2,-2:161.1
-4,-1,-2:161.1
-3,-1,-2:162.1
-2,-1,-2:162.1
0,-1,-2:162.5
1,-1,-2:162.9
3,-1,-2:162.9
4,-1,-2:161.1
5,-1,-2:161.1
-4,0,-2:161.1
0,0,-2:162.9
1,0,-2:162.5
2,0,-2:162.1
3,0,-2:162.1
4,0,-2:162.5
5,0,-2:161.1
-5,1,-2:161.1
-4,1,-2:162.1
-2,1,-2:162.1
0,1,-2:162.9
1,1,-2:161.1
3,1,-2:162.1
4,1,-2:161.1
-5,2,-2:161.1
-4,2,-2:161.1
0,2,-2:162.1
1,2,-2:162.1
2,2,-2:162.5
3,2,-2:162.1
4,2,-2:161.1
-4,3,-2:161.1
-3,3,-2:161.1
-2,3,-2:162.9
0,3,-2:162.9
3,3,-2:162.9
4,3,-2:162.5
5,3,-2:161.1
-3,4,-2:161.1
-2,4,-2:161.1
-1,4,-2:161.1
0,4,-2:162.9
1,4,-2:161.1
2,4,-2:161.1
3,4,-2:162.9
4,4,-2:161.1
-1,5,-2:161.1
0,5,-2:161.1
2,5,-2:161.1
3,5,-2:161.1
1,-5,-1:161.1
-1,-4,-1:161.1
0,-4,-1:161.1
1,-4,-1:162.9
2,-4,-1:161.1
3,-4,-1:161.1
-3,-3,-1:161.1
-2,-3,-1:161.1
-1,-3,-1:162.9
0,-3,-1:161.1
1,-3,-1:162.9
2,-3,-1:161.1
3,-3,-1:162.9
4,-3,-1:161.1
-4,-2,-1:161.1
-3,-2,-1:161.1
-2,-2,-1:161.1
-1,-2,-1:162.1
0,-2,-1:162.1
1,-2,-1:162.1
3,-2,-1:162.9
4,-2,-1:162.5
5,-2,-1:161.1
-4,-1,-1:161.1
-3,-1,-1:162.5
-2,-1,-1:162.1
2,-1,-1:161.1
3,-1,-1:86.3
4,-1,-1:161.1
-5,0,-1:161.1
-4,0,-1:161.1
-2,0,-1:162.1
-1,0,-1:162.5
0,0,-1:162.1
2,0,-1:162.5
3,0,-1:162.1
4,0,-1:161.1
-5,1,-1:161.1
-4,1,-1:161.1
-3,1,-1:162.5
-2,1,-1:162.1
-1,1,-1:162.5
0,1,-1:162.1
2,1,-1:162.9
3,1,-1:86.3
4,1,-1:161.1
-4,2,-1:161.1
-3,2,-1:161.1
-2,2,-1:162.1
-1,2,-1:162.1
0,2,-1:162.1
1,2,-1:162.1
3,2,-1:161.1
-3,3,-1:161.1
-2,3,-1:162.9
-1,3,-1:162.9
0,3,-1:162.1
1,3,-1:162.9
3,3,-1:162.9
4,3,-1:161.1
-3,4,-1:161.1
-2,4,-1:161.1
-1,4,-1:161.1
0,4,-1:161.1
1,4,-1:161.1
3,4,-1:161.1
-3,5,-1:161.1
0,5,-1:161.1
2,5,-1:161.1
3,5,-1:161.1
-1,-4,0:30.0
1,-4,0:161.1
-1,-3,0:161.1
0,-3,0:161.1
1,-3,0:161.1
2,-3,0:161.1
3,-3,0:161.1
-3,-2,0:161.1
-2,-2,0:161.1
-1,-2,0:86.0
0,-2,0:86.0
1,-2,0:86.0
2,-2,0:161.1
3,-2,0:86.1
4,-2,0:161.1
-4,-1,0:161.1
-3,-1,0:162.5
-2,-1,0:86.0
-1,-1,0:86.0
0,-1,0:86.0
1,-1,0:86.0
2,-1,0:159.15
-4,0,0:161.1
-3,0,0:162.5
-2,0,0:86.0
-1,0,0:162.1
0,0,0:86.0
1,0,0:86.0
2,0,0:86.0
3,0,0:86.1
-5,1,0:161.1
-4,1,0:162.1
-2,1,0:86.0
-1,1,0:86.3
0,1,0:86.0
1,1,0:86.0
2,1,0:159.15
-4,2,0:161.1
-3,2,0:162.5
-2,2,0:86.0
-1,2,0:86.0
0,2,0:86.0
1,2,0:86.0
2,2,0:162.5
3,2,0:86.0
-4,3,0:161.1
-3,3,0:161.1
-2,3,0:162.9
-1,3,0:162.1
0,3,0:162.1
1,3,0:162.1
2,3,0:162.9
3,3,0:161.1
4,3,0:161.1
-2,4,0:161.1
-1,4,0:162.9
0,4,0:161.1
1,4,0:161.1
2,4,0:161.1
3,4,0:161.1
4,4,0:161.1
-1,5,0:161.1
1,5,0:161.1
2,5,0:161.1
3,5,0:161.1
1,-3,1:161.1
2,-3,1:161.1
-2,-2,1:86.0
-1,-2,1:86.0
0,-2,1:86.0
1,-2,1:86.0
2,-2,1:161.1
3,-2,1:86.1
-2,-1,1:86.0
2,-1,1:159.15
-3,0,1:86.0
-1,0,1:162.1
2,0,1:159.15
-4,1,1:161.1
-3,1,1:86.0
2,1,1:159.15
-3,2,1:161.1
-2,2,1:86.0
1,2,1:86.0
2,2,1:86.0
3,2,1:86.1
-2,3,1:161.1
-1,3,1:86.2
0,3,1:86.2
1,3,1:162.1
2,3,1:161.1
3,3,1:161.1
-1,4,1:161.1
0,4,1:162.1
1,4,1:162.1
2,4,1:161.1
3,4,1:161.1
0,5,1:161.1
1,5,1:161.1
-1,-3,2:86.0
0,-3,2:86.0
1,-3,2:86.0
2,-3,2:30.0
-2,-2,2:86.0
0,-2,2:162.5
1,-2,2:86.0
2,-2,2:86.0
3,-2,2:86.0
-2,-1,2:86.0
0,-1,2:162.9
2,-1,2:86.0
3,-1,2:86.0
-3,0,2:30.0
-2,0,2:86.0
-1,0,2:162.1
1,0,2:30.0
3,0,2:86.0
-3,1,2:86.0
1,1,2:159.15
2,1,2:86.0
3,1,2:86.0
-3,2,2:86.2
-2,2,2:86.1
0,2,2:162.5
1,2,2:86.0
2,2,2:86.0
3,2,2:86.1
-1,3,2:86.2
0,3,2:86.2
1,3,2:86.1
2,3,2:86.1
3,3,2:161.1
0,4,2:161.1
1,4,2:161.1
-1,-3,3:86.0
0,-3,3:86.0
1,-3,3:86.0
2,-3,3:86.0
3,-3,3:86.1
-2,-2,3:86.0
1,-2,3:86.0
2,-2,3:159.15
-3,-1,3:86.0
-2,-1,3:162.1
-1,-1,3:30.0
3,-1,3:86.0
-3,0,3:86.0
-1,0,3:162.1
3,0,3:86.1
-3,1,3:86.0
-2,1,3:162.9
0,1,3:162.9
2,1,3:159.15
-3,2,3:86.2
-2,2,3:86.1
0,2,3:86.1
1,2,3:86.1
2,2,3:86.0
3,2,3:86.0
-1,3,3:86.2
1,3,3:30.0
2,3,3:86.2
3,3,3:86.1
-1,-3,4:86.3
0,-3,4:86.0
1,-3,4:86.0
2,-3,4:86.0
3,-3,4:86.1
-2,-2,4:86.0
1,-2,4:86.0
2,-2,4:86.0
3,-2,4:86.2
-3,-1,4:86.0
-2,-1,4:162.9
-1,-1,4:162.9
3,-1,4:86.0
-3,0,4:86.2
-2,0,4:162.5
-1,0,4:162.5
0,0,4:162.1
3,0,4:86.1
-3,1,4:30.0
-2,1,4:86.0
1,1,4:30.0
2,1,4:159.15
-2,2,4:86.2
-1,2,4:162.5
0,2,4:162.5
1,2,4:86.1
2,2,4:159.15
-1,3,4:86.2
0,3,4:86.1
2,3,4:86.2
3,3,4:86.1
0,-3,5:86.0
1,-3,5:86.0
-2,-2,5:86.0
-1,-2,5:86.0
0,-2,5:86.0
1,-2,5:86.0
2,-2,5:86.0
-2,-1,5:86.0
-1,-1,5:91.3
0,-1,5:162.9
1,-1,5:86.0
2,-1,5:86.0
3,-1,5:86.0
-2,0,5:86.0
0,0,5:162.1
2,0,5:86.0
3,0,5:86.0
-2,1,5:86.0
1,1,5:86.0
2,1,5:86.0
3,1,5:86.0
-2,2,5:86.2
-1,2,5:86.1
0,2,5:86.0
1,2,5:86.0
2,2,5:86.1
3,2,5:86.1
0,3,5:86.2
1,3,5:86.1
-1,-2,6:86.0
0,-2,6:86.0
1,-2,6:86.0
-2,-1,6:86.0
-1,-1,6:86.0
0,-1,6:91.2
1,-1,6:86.0
2,-1,6:86.0
-2,0,6:86.0
-1,0,6:86.0
0,0,6:162.1
1,0,6:86.0
2,0,6:86.0
3,0,6:86.1
-2,1,6:86.2
-1,1,6:86.0
0,1,6:86.0
1,1,6:86.1
2,1,6:86.1
-1,2,6:86.2
0,2,6:86.1
0,0,7:162.1
0,1,7:30.0
-1,-1,8:161.1
0,-1,8:162.1
-1,0,8:161.1
0,0,8:162.1
1,0,8:161.1
0,1,8:161.1
-1,-2,9:161.1
0,-2,9:30.0
-1,-1,9:161.1
0,-1,9:162.1
1,-1,9:161.1
0,0,9:161.1
0,-4,10:161.1
-1,-3,10:161.1
0,-3,10:162.1
1,-3,10:161.1
-1,-2,10:30.0
0,-2,10:161.1
1,-2,10:161.1
0,-1,10:161.1
3,-4,0:40.0
4,1,0:40.0
-1,-3,1:40.0
0,1,4:40.0
0,-2,3:40.0
4,-2,1:40.0
-1,1,1:40.0
-4,2,1:39.0
-2,4,1:39.0
2,0,2:39.0
0,0,1:39.0
-1,-1,1:39.0
-4,1,2:39.0
3,-2,5:39.0
-2,0,7:39.0
-4,-2,0:39.0
-3,-3,0:39.0
2,0,7:39.0
