
#######################################################################
# +-----------------------------------------------------------------+ #
# |                            BO3 object                           | #
# +-----------------------------------------------------------------+ #
#######################################################################

Author: LordSmellyPants

Description: Converted version of the BO2 ancientjungle2R4

Version: 3

SettingsMode: WriteWithoutComments


#######################################################################
# +-----------------------------------------------------------------+ #
# |                          Main settings                          | #
# +-----------------------------------------------------------------+ #
#######################################################################

Tree: true

Frequency: 1

Rarity: 10.0

RotateRandomly: true

SpawnHeight: highestSolidBlock

SpawnHeightOffset: 0

SpawnHeightVariance: 0

##############################
# Height Limits for the BO3. #
##############################

MinHeight: 62

MaxHeight: 210

######################
# Extrusion settings #
######################

ExtrudeMode: None

ExtrudeThroughBlocks: AIR

MaxBranchDepth: 10

ExcludedBiomes: 


#######################################################################
# +-----------------------------------------------------------------+ #
# |                      Source block settings                      | #
# +-----------------------------------------------------------------+ #
#######################################################################

SourceBlocks: STONE:1,STONE:3,STONE:5,DIRT:1,DIRT,SAND,GRASS,DIRT:2,STATIONARY_WATER,HARD_CLAY,STAINED_CLAY,CLAY,SANDSTONE,SAND:1,AIR,STONE,GRAVEL,LONG_GRASS,LONG_GRASS:1,LONG_GRASS:2,DEAD_BUSH,YELLOW_FLOWER,RED_ROSE,BROWN_MUSHROOM,RED_MUSHROOM

MaxPercentageOutsideSourceBlock: 20

OutsideSourceBlock: placeAnyway

IsOTGPlus: false

InheritBO3: 

InheritBO3Rotation: NORTH

OverrideChildSettings: true

OverrideParentHeight: false

CanOverride: false

BranchFrequency: 0

BranchFrequencyGroup: 

MustBeBelowOther: false

MustBeInside: 

CannotBeInside: 

ReplacesBO3: 

CanSpawnOnWater: true

SpawnOnWaterOnly: false

SpawnUnderWater: false

SpawnAtWaterLevel: false

HeightOffset: 0

RemoveAir: true

ReplaceAbove: 

ReplaceBelow: 

ReplaceWithBiomeBlocks: true

ReplaceWithGroundBlock: DIRT

ReplaceWithSurfaceBlock: GRASS

SmoothRadius: 0

SmoothHeightOffset: 0

SmoothStartTop: false

SmoothStartWood: false

SmoothingSurfaceBlock: 

SmoothingGroundBlock: 

BO3Group: 

IsSpawnPoint: false


#######################################################################
# +-----------------------------------------------------------------+ #
# |                              Blocks                             | #
# +-----------------------------------------------------------------+ #
#######################################################################

Block(5,12,-2,LEAVES:3)
Block(5,11,-2,LOG:15)
Block(5,13,-2,LEAVES:3)
Block(6,11,-1,LEAVES:3)
Block(2,11,4,LEAVES:3)
Block(4,12,-3,LEAVES:3)
Block(4,11,-3,LEAVES:3)
Block(5,11,2,LEAVES:3)
Block(6,12,-1,LEAVES:3)
Block(5,12,2,LEAVES:3)
Block(6,10,-1,LEAVES:3)
Block(2,10,4,LEAVES:3)
Block(3,12,-4,LEAVES:3)
Block(3,11,-4,LOG:15)
Block(-1,11,1,LEAVES:3)
Block(-1,12,1,LEAVES:3)
Block(3,9,0,LOG:15)
Block(2,2,1,LOG:15)
Block(2,1,1,LOG:15)
Block(-2,11,-3,LEAVES:3)
Block(2,12,-5,LEAVES:3)
Block(2,11,-5,LEAVES:3)
Block(1,12,1,LEAVES:3)
Block(3,11,2,LEAVES:3)
Block(-1,1,0,LOG:15)
Block(-1,0,0,LOG:15)
Block(3,13,2,LEAVES:3)
Block(3,9,-2,LOG:15)
Block(0,9,-1,LEAVES:3)
Block(1,12,2,LEAVES:3)
Block(0,11,3,LEAVES:3)
Block(1,12,-1,LEAVES:3)
Block(1,11,-1,LEAVES:3)
Block(1,10,-1,LOG:15)
Block(5,12,1,LEAVES:3)
Block(5,11,1,LEAVES:3)
Block(5,10,1,LEAVES:3)
Block(4,11,-2,LOG:15)
Block(5,13,1,LEAVES:3)
Block(1,-1,-2,LOG:15)
Block(1,-2,-2,LOG:15)
Block(3,11,-5,LOG:15)
Block(7,11,-1,LEAVES:3)
Block(-1,11,-4,LEAVES:3)
Block(1,11,-6,LEAVES:3)
Block(0,10,-1,LEAVES:3)
Block(6,11,0,LEAVES:3)
Block(4,12,-2,LEAVES:3)
Block(6,12,0,LEAVES:3)
Block(4,13,-2,LEAVES:3)
Block(0,12,-1,LEAVES:3)
Block(0,11,-1,LEAVES:3)
Block(0,3,0,LOG:15)
Block(0,2,0,LOG:15)
Block(0,4,0,LOG:15)
Block(3,0,1,LOG:15)
Block(2,12,3,LEAVES:3)
Block(4,12,-4,LEAVES:3)
Block(4,11,-4,LEAVES:3)
Block(3,11,-3,LEAVES:3)
Block(4,13,0,LEAVES:3)
Block(3,10,-3,LOG:15)
Block(4,11,0,LEAVES:3)
Block(3,12,-3,LEAVES:3)
Block(4,12,0,LEAVES:3)
Block(1,12,-4,LEAVES:3)
Block(1,11,-4,LEAVES:3)
Block(2,9,-1,LOG:15)
Block(2,8,-1,LOG:15)
Block(2,7,-1,LOG:15)
Block(2,6,-1,LOG:15)
Block(5,11,0,LEAVES:3)
Block(2,12,2,LEAVES:3)
Block(2,11,2,LOG:15)
Block(6,12,-3,LEAVES:3)
Block(5,13,0,LEAVES:3)
Block(6,11,-3,LEAVES:3)
Block(5,12,0,LEAVES:3)
Block(4,12,1,LEAVES:3)
Block(4,13,1,LEAVES:3)
Block(4,11,1,LOG:15)
Block(7,11,-2,LEAVES:3)
Block(1,11,-5,LEAVES:3)
Block(1,10,-5,LEAVES:3)
Block(2,12,-4,LEAVES:3)
Block(2,11,-4,LEAVES:3)
Block(2,10,-4,LEAVES:3)
Block(1,5,-1,LOG:15)
Block(1,4,-1,LOG:15)
Block(1,1,-1,LOG:15)
Block(3,13,1,LEAVES:3)
Block(1,0,-1,LOG:15)
Block(3,11,1,LEAVES:3)
Block(5,12,-3,LEAVES:3)
Block(1,11,3,LEAVES:3)
Block(5,11,-3,LEAVES:3)
Block(5,10,-3,LEAVES:3)
Block(0,1,2,LOG:15)
Block(0,0,2,LOG:15)
Block(2,12,-2,LEAVES:3)
Block(1,11,-3,LEAVES:3)
Block(2,11,-2,LOG:15)
Block(0,12,1,LEAVES:3)
Block(0,11,1,LOG:15)
Block(7,11,-3,LEAVES:3)
Block(-1,11,-2,LEAVES:3)
Block(6,12,2,LEAVES:3)
Block(6,11,2,LEAVES:3)
Block(6,9,-1,LEAVES:3)
Block(4,12,-5,LEAVES:3)
Block(0,2,1,LOG:15)
Block(0,1,1,LOG:3)
Block(0,3,1,LOG:15)
Block(3,10,-2,LOG:15)
Block(3,-1,1,LOG:15)
Block(-2,11,-1,LEAVES:3)
Block(3,13,-2,LEAVES:3)
Block(5,12,-4,LEAVES:3)
Block(-3,11,0,LEAVES:3)
Block(2,11,1,LOG:15)
Block(-2,10,1,LEAVES:3)
Block(4,12,2,LEAVES:3)
Block(4,11,2,LOG:15)
Block(-2,11,1,LEAVES:3)
Block(2,11,-3,LEAVES:3)
Block(0,12,0,LEAVES:3)
Block(2,12,-3,LEAVES:3)
Block(6,11,-4,LEAVES:3)
Block(1,6,0,LOG:15)
Block(1,5,0,LOG:15)
Block(4,9,3,LEAVES:3)
Block(1,4,0,LOG:15)
Block(0,9,2,LEAVES:3)
Block(1,3,0,LOG:15)
Block(1,2,0,LOG:15)
Block(3,11,0,LEAVES:3)
Block(1,1,0,LOG:3)
Block(2,9,-4,LEAVES:3)
Block(3,10,0,LOG:15)
Block(3,12,0,LEAVES:3)
Block(2,11,0,LEAVES:3)
Block(2,12,0,LEAVES:3)
Block(4,12,3,LEAVES:3)
Block(4,11,3,LEAVES:3)
Block(4,10,3,LEAVES:3)
Block(-1,10,-3,LEAVES:3)
Block(-1,11,-3,LEAVES:3)
Block(2,7,0,LOG:15)
Block(2,6,0,LOG:15)
Block(3,12,3,LEAVES:3)
Block(6,11,1,LEAVES:3)
Block(3,11,3,LEAVES:3)
Block(5,11,-1,LEAVES:3)
Block(5,11,3,LEAVES:3)
Block(1,12,0,LEAVES:3)
Block(1,11,0,LOG:15)
Block(2,11,-6,LEAVES:3)
Block(2,12,-6,LEAVES:3)
Block(2,13,-1,LEAVES:3)
Block(2,11,-1,LEAVES:3)
Block(1,4,1,LOG:15)
Block(0,10,2,LEAVES:3)
Block(1,3,1,LOG:15)
Block(0,11,2,LEAVES:3)
Block(1,2,1,LOG:15)
Block(-3,11,1,LEAVES:3)
Block(-1,12,-2,LEAVES:3)
Block(3,12,-6,LEAVES:3)
Block(-2,11,2,LEAVES:3)
Block(0,-1,3,LOG:15)
Block(0,11,-2,LOG:15)
Block(4,12,-1,LEAVES:3)
Block(0,12,-2,LEAVES:3)
Block(2,5,0,LOG:15)
Block(2,4,0,LOG:15)
Block(3,11,-1,LEAVES:3)
Block(-2,11,-2,LEAVES:3)
Block(3,12,-1,LEAVES:3)
Block(3,13,-1,LEAVES:3)
Block(3,11,4,LEAVES:3)

#######################################################################
# +-----------------------------------------------------------------+ #
# |                            BO3 checks                           | #
# +-----------------------------------------------------------------+ #
#######################################################################

BlockCheck(0,-1,0,GRASS,DIRT)

#######################################################################
# +-----------------------------------------------------------------+ #
# |                             Branches                            | #
# +-----------------------------------------------------------------+ #
#######################################################################


#######################################################################
# +-----------------------------------------------------------------+ #
# |                             Entities                            | #
# +-----------------------------------------------------------------+ #
#######################################################################


#######################################################################
# +-----------------------------------------------------------------+ #
# |                            Particles                            | #
# +-----------------------------------------------------------------+ #
#######################################################################


#######################################################################
# +-----------------------------------------------------------------+ #
# |                             Spawners                            | #
# +-----------------------------------------------------------------+ #
#######################################################################


#######################################################################
# +-----------------------------------------------------------------+ #
# |                             ModData                             | #
# +-----------------------------------------------------------------+ #
#######################################################################

