
#######################################################################
# +-----------------------------------------------------------------+ #
# |                            BO3 object                           | #
# +-----------------------------------------------------------------+ #
#######################################################################

Author: LordSmellyPants

Description: Converted version of the BO2 ancientjungle3R4

Version: 3

SettingsMode: WriteWithoutComments


#######################################################################
# +-----------------------------------------------------------------+ #
# |                          Main settings                          | #
# +-----------------------------------------------------------------+ #
#######################################################################

Tree: true

Frequency: 1

Rarity: 10.0

RotateRandomly: true

SpawnHeight: highestSolidBlock

SpawnHeightOffset: 0

SpawnHeightVariance: 0

##############################
# Height Limits for the BO3. #
##############################

MinHeight: 62

MaxHeight: 210

######################
# Extrusion settings #
######################

ExtrudeMode: None

ExtrudeThroughBlocks: AIR

MaxBranchDepth: 10

ExcludedBiomes: 


#######################################################################
# +-----------------------------------------------------------------+ #
# |                      Source block settings                      | #
# +-----------------------------------------------------------------+ #
#######################################################################

SourceBlocks: STONE:1,STONE:3,STONE:5,DIRT:1,DIRT,SAND,GRASS,DIRT:2,STATIONARY_WATER,HARD_CLAY,STAINED_CLAY,CLAY,SANDSTONE,SAND:1,AIR,STONE,GRAVEL,LONG_GRASS,LONG_GRASS:1,LONG_GRASS:2,DEAD_BUSH,YELLOW_FLOWER,RED_ROSE,BROWN_MUSHROOM,RED_MUSHROOM

MaxPercentageOutsideSourceBlock: 20

OutsideSourceBlock: placeAnyway

IsOTGPlus: false

InheritBO3: 

InheritBO3Rotation: NORTH

OverrideChildSettings: true

OverrideParentHeight: false

CanOverride: false

BranchFrequency: 0

BranchFrequencyGroup: 

MustBeBelowOther: false

MustBeInside: 

CannotBeInside: 

ReplacesBO3: 

CanSpawnOnWater: true

SpawnOnWaterOnly: false

SpawnUnderWater: false

SpawnAtWaterLevel: false

HeightOffset: 0

RemoveAir: true

ReplaceAbove: 

ReplaceBelow: 

ReplaceWithBiomeBlocks: true

ReplaceWithGroundBlock: DIRT

ReplaceWithSurfaceBlock: GRASS

SmoothRadius: 0

SmoothHeightOffset: 0

SmoothStartTop: false

SmoothStartWood: false

SmoothingSurfaceBlock: 

SmoothingGroundBlock: 

BO3Group: 

IsSpawnPoint: false


#######################################################################
# +-----------------------------------------------------------------+ #
# |                              Blocks                             | #
# +-----------------------------------------------------------------+ #
#######################################################################

Block(2,15,4,LEAVES:3)
Block(-4,9,2,LOG:15)
Block(2,16,4,LEAVES:3)
Block(-4,8,2,LOG:15)
Block(2,14,4,LEAVES:3)
Block(-2,-1,0,LOG:15)
Block(-4,17,-1,LEAVES:3)
Block(-2,16,-3,LEAVES:3)
Block(-4,16,-1,LEAVES:3)
Block(-3,10,2,LOG:15)
Block(-4,10,-1,LEAVES:3)
Block(-6,10,0,LEAVES:3)
Block(-3,14,2,LOG:15)
Block(-3,13,2,LOG:15)
Block(-3,12,2,LOG:15)
Block(-3,11,2,LOG:15)
Block(-3,18,2,LEAVES:3)
Block(-3,17,2,LEAVES:3)
Block(-3,19,2,LEAVES:3)
Block(-8,15,6,LEAVES:3)
Block(1,16,1,LEAVES:3)
Block(-4,18,4,LEAVES:3)
Block(-4,19,4,LEAVES:3)
Block(-4,9,1,LOG:15)
Block(-4,3,1,LOG:15)
Block(-4,2,1,LOG:15)
Block(-4,1,1,LOG:15)
Block(-4,0,1,LOG:15)
Block(-4,4,1,LOG:15)
Block(-2,15,9,LEAVES:3)
Block(-5,16,7,LEAVES:3)
Block(-5,14,7,LEAVES:3)
Block(-9,15,-1,LEAVES:3)
Block(-5,15,7,LEAVES:3)
Block(-9,16,-1,LEAVES:3)
Block(-5,13,7,LEAVES:3)
Block(-3,9,3,LOG:15)
Block(-1,17,7,LEAVES:3)
Block(1,15,2,LEAVES:3)
Block(-1,16,7,LEAVES:3)
Block(-1,15,7,LEAVES:3)
Block(1,16,2,LEAVES:3)
Block(-4,18,5,LEAVES:3)
Block(-3,2,3,LOG:15)
Block(-3,1,3,LOG:15)
Block(-6,15,0,LEAVES:3)
Block(-6,16,0,LEAVES:3)
Block(-6,17,0,LEAVES:3)
Block(-6,18,0,LEAVES:3)
Block(-3,2,-1,LOG:15)
Block(-3,3,-1,LOG:15)
Block(-7,15,2,LOG:15)
Block(-7,16,2,LEAVES:3)
Block(0,15,8,LEAVES:3)
Block(-7,16,-4,LEAVES:3)
Block(-3,11,3,LOG:15)
Block(-3,10,3,LOG:15)
Block(0,1,0,LOG:15)
Block(-3,15,3,LOG:15)
Block(-3,14,3,LOG:15)
Block(-3,13,3,LOG:15)
Block(-6,16,1,LEAVES:3)
Block(0,2,0,LOG:15)
Block(-3,12,3,LOG:15)
Block(-6,15,1,LOG:15)
Block(-6,18,1,LEAVES:3)
Block(-3,19,3,LEAVES:3)
Block(-2,16,0,LOG:15)
Block(-3,18,3,LEAVES:3)
Block(-2,18,0,LEAVES:3)
Block(-7,15,1,LEAVES:3)
Block(-7,16,1,LEAVES:3)
Block(-4,13,3,LOG:15)
Block(-1,14,5,LEAVES:3)
Block(-4,14,3,LOG:15)
Block(-1,15,5,LEAVES:3)
Block(-4,16,3,LEAVES:3)
Block(-1,16,5,LEAVES:3)
Block(-4,19,3,LEAVES:3)
Block(2,15,3,LEAVES:3)
Block(-4,16,-3,LEAVES:3)
Block(-4,12,3,LOG:15)
Block(2,16,3,LEAVES:3)
Block(-2,16,-4,LEAVES:3)
Block(-7,16,-2,LEAVES:3)
Block(-7,17,-2,LEAVES:3)
Block(-4,2,-1,LOG:15)
Block(-7,14,-2,LEAVES:3)
Block(-4,1,-1,LOG:15)
Block(-7,15,-2,LEAVES:3)
Block(-6,10,1,LEAVES:3)
Block(-4,0,3,LOG:15)
Block(2,16,2,LEAVES:3)
Block(2,15,2,LEAVES:3)
Block(-8,15,5,LEAVES:3)
Block(-7,16,-3,LEAVES:3)
Block(-6,11,2,LEAVES:3)
Block(-6,10,2,LEAVES:3)
Block(-3,14,4,LOG:15)
Block(-3,13,4,LOG:15)
Block(-3,19,4,LEAVES:3)
Block(-3,18,4,LEAVES:3)
Block(-3,17,4,LEAVES:3)
Block(-7,10,1,LEAVES:3)
Block(-9,16,-2,LEAVES:3)
Block(-5,15,8,LEAVES:3)
Block(1,16,3,LEAVES:3)
Block(-1,16,6,LOG:15)
Block(1,15,3,LOG:15)
Block(-1,15,6,LEAVES:3)
Block(-1,17,6,LEAVES:3)
Block(-6,16,-2,LOG:7)
Block(-6,17,-2,LEAVES:3)
Block(-4,11,2,LOG:15)
Block(-4,10,2,LOG:15)
Block(-6,10,-2,LEAVES:3)
Block(-5,14,5,LEAVES:3)
Block(0,15,1,LEAVES:3)
Block(0,14,1,LEAVES:3)
Block(-5,15,5,LEAVES:3)
Block(-5,13,5,LEAVES:3)
Block(-7,10,-1,LEAVES:3)
Block(1,15,4,LEAVES:3)
Block(0,17,1,LEAVES:3)
Block(0,16,1,LEAVES:3)
Block(1,16,4,LEAVES:3)
Block(-4,-1,3,LOG:15)
Block(-7,16,-1,LOG:15)
Block(-9,16,0,LEAVES:3)
Block(-6,15,8,LEAVES:3)
Block(-3,14,5,LOG:15)
Block(-3,15,5,LEAVES:3)
Block(-3,17,5,LEAVES:3)
Block(-5,19,4,LEAVES:3)
Block(-5,18,4,LEAVES:3)
Block(-2,16,-1,LOG:15)
Block(-7,9,0,LEAVES:3)
Block(-2,18,1,LEAVES:3)
Block(-2,17,1,LEAVES:3)
Block(-5,10,-2,LEAVES:3)
Block(-1,15,-1,LEAVES:3)
Block(-1,16,-1,LEAVES:3)
Block(-7,16,5,LEAVES:3)
Block(-7,15,5,LEAVES:3)
Block(-2,16,1,LEAVES:3)
Block(-1,17,-1,LEAVES:3)
Block(-7,14,5,LEAVES:3)
Block(-2,15,1,LOG:15)
Block(-5,16,-2,LEAVES:3)
Block(-2,11,1,LEAVES:3)
Block(2,16,1,LEAVES:3)
Block(-5,14,4,LOG:15)
Block(-4,16,2,LOG:15)
Block(-4,15,2,LOG:15)
Block(-4,14,2,LOG:15)
Block(-8,17,-1,LEAVES:3)
Block(0,17,0,LEAVES:3)
Block(-4,13,2,LOG:15)
Block(-4,12,2,LOG:15)
Block(-8,15,7,LEAVES:3)
Block(-2,2,-1,LOG:15)
Block(-2,1,-1,LOG:15)
Block(3,16,3,LEAVES:3)
Block(3,15,3,LEAVES:3)
Block(-9,15,2,LEAVES:3)
Block(-9,16,2,LEAVES:3)
Block(-6,17,-1,LEAVES:3)
Block(-6,16,-1,LEAVES:3)
Block(-3,15,6,LOG:15)
Block(-3,16,6,LEAVES:3)
Block(-3,17,6,LEAVES:3)
Block(-2,19,3,LEAVES:3)
Block(-2,17,3,LOG:15)
Block(-2,18,3,LEAVES:3)
Block(-2,16,3,LOG:15)
Block(-2,13,3,LOG:15)
Block(-2,14,3,LOG:15)
Block(-2,11,3,LOG:15)
Block(-6,10,-1,LEAVES:3)
Block(-2,12,3,LOG:15)
Block(-5,15,6,LEAVES:3)
Block(-4,16,0,LEAVES:3)
Block(-3,17,-1,LEAVES:3)
Block(-5,16,6,LEAVES:3)
Block(-4,15,0,LOG:15)
Block(1,15,5,LEAVES:3)
Block(1,16,5,LEAVES:3)
Block(0,15,2,LEAVES:3)
Block(-3,10,-1,LEAVES:3)
Block(-1,15,8,LEAVES:3)
Block(-1,16,8,LEAVES:3)
Block(-4,18,0,LEAVES:3)
Block(-3,16,-1,LEAVES:3)
Block(-9,16,1,LEAVES:3)
Block(-5,10,-1,LEAVES:3)
Block(-2,18,2,LEAVES:3)
Block(-2,19,2,LEAVES:3)
Block(-1,16,-2,LEAVES:3)
Block(-2,16,2,LEAVES:3)
Block(-2,12,2,LOG:15)
Block(-5,16,-1,LEAVES:3)
Block(-2,10,2,LOG:15)
Block(-2,11,2,LOG:15)
Block(-5,17,-1,LEAVES:3)
Block(-4,17,1,LEAVES:3)
Block(-4,14,1,LOG:15)
Block(1,16,6,LEAVES:3)
Block(-7,18,3,LEAVES:3)
Block(-4,13,1,LOG:15)
Block(1,17,6,LEAVES:3)
Block(-2,0,-2,LOG:15)
Block(-1,15,9,LEAVES:3)
Block(-4,10,1,LEAVES:3)
Block(-2,14,-2,LEAVES:3)
Block(-2,17,-2,LEAVES:3)
Block(-2,16,-2,LEAVES:3)
Block(-2,15,-2,LEAVES:3)
Block(-3,15,7,LOG:15)
Block(3,15,4,LEAVES:3)
Block(-7,15,8,LEAVES:3)
Block(-3,16,7,LEAVES:3)
Block(-8,16,0,LEAVES:3)
Block(-5,17,2,LOG:15)
Block(-8,17,0,LEAVES:3)
Block(-5,18,2,LOG:15)
Block(-2,18,4,LEAVES:3)
Block(-2,17,4,LEAVES:3)
Block(-5,19,2,LEAVES:3)
Block(-8,15,0,LEAVES:3)
Block(-2,16,4,LEAVES:3)
Block(-5,13,2,LOG:15)
Block(-5,14,2,LOG:15)
Block(-5,15,2,LEAVES:3)
Block(-1,16,-4,LEAVES:3)
Block(-1,16,1,LEAVES:3)
Block(-1,17,1,LEAVES:3)
Block(-10,16,-2,LEAVES:3)
Block(-3,17,-2,LEAVES:3)
Block(-3,16,-2,LEAVES:3)
Block(-5,11,2,LEAVES:3)
Block(3,16,2,LEAVES:3)
Block(-8,16,-3,LEAVES:3)
Block(3,14,2,LEAVES:3)
Block(-6,15,5,LOG:15)
Block(3,15,2,LEAVES:3)
Block(-6,16,5,LEAVES:3)
Block(-1,3,0,LOG:15)
Block(-1,2,0,LOG:15)
Block(3,13,2,LEAVES:3)
Block(0,15,3,LOG:15)
Block(0,16,3,LEAVES:3)
Block(-3,16,8,LEAVES:3)
Block(-1,-1,3,LOG:15)
Block(-6,15,6,LOG:15)
Block(0,16,-1,LEAVES:3)
Block(-5,16,1,LEAVES:3)
Block(-5,17,1,LEAVES:3)
Block(-5,15,1,LEAVES:3)
Block(-1,17,2,LEAVES:3)
Block(1,16,7,LEAVES:3)
Block(-9,13,3,LEAVES:3)
Block(-9,14,3,LEAVES:3)
Block(-9,15,3,LEAVES:3)
Block(-9,16,3,LEAVES:3)
Block(-10,16,-1,LEAVES:3)
Block(0,16,5,LEAVES:3)
Block(0,15,5,LEAVES:3)
Block(-1,3,2,LOG:15)
Block(-1,2,2,LOG:15)
Block(-1,5,2,LOG:15)
Block(-1,4,2,LOG:15)
Block(-7,15,7,LEAVES:3)
Block(-1,7,2,LOG:15)
Block(-1,6,2,LOG:15)
Block(-5,19,3,LEAVES:3)
Block(-5,15,3,LEAVES:3)
Block(-2,4,0,LOG:15)
Block(-2,3,0,LOG:15)
Block(-2,2,0,LOG:15)
Block(-2,1,0,LOG:15)
Block(-1,16,0,LEAVES:3)
Block(-2,0,0,LOG:15)
Block(-1,17,0,LEAVES:3)
Block(-3,15,9,LEAVES:3)
Block(-1,1,2,LOG:15)
Block(-1,0,2,LOG:15)
Block(-7,16,6,LEAVES:3)
Block(-5,11,3,LEAVES:3)
Block(-8,16,-2,LEAVES:3)
Block(-8,17,-2,LEAVES:3)
Block(-9,15,4,LEAVES:3)
Block(-5,8,-1,LEAVES:3)
Block(-5,9,-1,LEAVES:3)
Block(-1,4,1,LOG:15)
Block(-1,3,1,LOG:15)
Block(-1,5,1,LOG:15)
Block(-6,16,-3,LEAVES:3)
Block(-2,17,5,LEAVES:3)
Block(-2,16,5,LEAVES:3)
Block(-2,15,5,LOG:15)
Block(0,15,4,LEAVES:3)
Block(0,16,4,LEAVES:3)
Block(0,17,4,LEAVES:3)
Block(-1,2,1,LOG:15)
Block(-6,16,7,LEAVES:3)
Block(-6,15,7,LEAVES:3)
Block(-7,10,0,LEAVES:3)
Block(-10,15,1,LEAVES:3)
Block(-8,16,3,LEAVES:3)
Block(-8,15,3,LEAVES:3)
Block(-3,6,0,LOG:15)
Block(-3,9,0,LEAVES:3)
Block(-3,3,0,LOG:15)
Block(-3,2,0,LOG:15)
Block(-3,5,0,LOG:15)
Block(-3,4,0,LOG:15)
Block(-6,15,2,LOG:15)
Block(-6,17,2,LEAVES:3)
Block(1,-1,0,LOG:15)
Block(-6,19,2,LEAVES:3)
Block(-4,16,7,LEAVES:3)
Block(-6,18,2,LEAVES:3)
Block(-2,9,2,LOG:15)
Block(-2,8,2,LOG:15)
Block(-2,7,2,LOG:15)
Block(-2,6,2,LOG:15)
Block(-2,5,2,LOG:15)
Block(-2,4,2,LOG:15)
Block(-2,3,2,LOG:15)
Block(-2,2,2,LOG:15)
Block(-2,15,7,LEAVES:3)
Block(-2,16,7,LEAVES:3)
Block(-2,17,7,LEAVES:3)
Block(0,17,6,LEAVES:3)
Block(-7,16,0,LOG:15)
Block(-7,15,0,LEAVES:3)
Block(0,16,6,LEAVES:3)
Block(0,15,6,LEAVES:3)
Block(-1,15,4,LEAVES:3)
Block(-1,16,4,LEAVES:3)
Block(-6,18,3,LEAVES:3)
Block(0,2,1,LOG:15)
Block(-4,16,8,LEAVES:3)
Block(0,3,1,LOG:15)
Block(-6,19,3,LEAVES:3)
Block(-2,17,6,LEAVES:3)
Block(-2,16,6,LEAVES:3)
Block(-3,11,0,LEAVES:3)
Block(-3,10,0,LEAVES:3)
Block(-3,15,0,LEAVES:3)
Block(-3,16,0,LEAVES:3)
Block(-3,14,0,LEAVES:3)
Block(-2,8,1,LOG:15)
Block(4,15,2,LEAVES:3)
Block(-2,7,1,LOG:15)
Block(-3,17,0,LEAVES:3)
Block(-2,6,1,LOG:15)
Block(-3,18,0,LEAVES:3)
Block(-2,5,1,LOG:15)
Block(-10,15,2,LEAVES:3)
Block(-2,4,1,LOG:15)
Block(-2,3,1,LOG:15)
Block(-2,2,1,LOG:15)
Block(-2,1,1,LOG:15)
Block(-8,15,4,LEAVES:3)
Block(-8,16,4,LEAVES:3)
Block(1,0,0,LOG:15)
Block(-4,15,6,LEAVES:3)
Block(-4,3,0,LOG:15)
Block(-4,2,0,LOG:15)
Block(4,15,3,LEAVES:3)
Block(-5,10,1,LEAVES:3)
Block(-5,11,1,LEAVES:3)
Block(-3,9,2,LOG:15)
Block(-3,8,2,LOG:15)
Block(-3,5,2,LOG:15)
Block(-3,4,2,LOG:15)
Block(-3,7,2,LOG:15)
Block(-3,6,2,LOG:15)
Block(-6,15,4,LEAVES:3)
Block(-3,3,2,LOG:15)
Block(-3,2,2,LOG:15)
Block(1,16,0,LEAVES:3)
Block(-8,15,2,LEAVES:3)
Block(0,16,-3,LEAVES:3)
Block(0,16,-2,LEAVES:3)
Block(-3,10,1,LOG:15)
Block(-3,11,1,LEAVES:3)
Block(-5,19,0,LEAVES:3)
Block(-3,16,1,LEAVES:3)
Block(-3,17,1,LEAVES:3)
Block(-5,11,0,LEAVES:3)
Block(-8,16,2,LEAVES:3)
Block(-5,18,0,LEAVES:3)
Block(-5,17,0,LEAVES:3)
Block(-10,15,3,LEAVES:3)
Block(-1,18,3,LEAVES:3)
Block(-3,9,1,LOG:15)
Block(-3,6,1,LOG:15)
Block(0,16,7,LEAVES:3)
Block(-3,5,1,LOG:15)
Block(0,17,7,LEAVES:3)
Block(-3,8,1,LOG:15)
Block(0,14,7,LEAVES:3)
Block(-3,7,1,LOG:15)
Block(0,15,7,LEAVES:3)
Block(-3,2,1,LOG:15)
Block(0,13,7,LEAVES:3)
Block(-1,14,3,LOG:15)
Block(-3,4,1,LOG:15)
Block(-1,17,3,LEAVES:3)
Block(-3,3,1,LOG:15)
Block(-6,18,4,LEAVES:3)
Block(2,15,5,LEAVES:3)
Block(-2,8,3,LOG:15)
Block(-5,-2,1,LOG:15)
Block(-2,7,3,LOG:15)
Block(-2,6,3,LOG:15)
Block(-2,5,3,LOG:15)
Block(-2,2,3,LOG:15)
Block(-5,-1,1,LOG:15)
Block(-2,15,8,LEAVES:3)
Block(-5,10,0,LOG:15)

#######################################################################
# +-----------------------------------------------------------------+ #
# |                            BO3 checks                           | #
# +-----------------------------------------------------------------+ #
#######################################################################

BlockCheck(0,-1,0,GRASS,DIRT)

#######################################################################
# +-----------------------------------------------------------------+ #
# |                             Branches                            | #
# +-----------------------------------------------------------------+ #
#######################################################################


#######################################################################
# +-----------------------------------------------------------------+ #
# |                             Entities                            | #
# +-----------------------------------------------------------------+ #
#######################################################################


#######################################################################
# +-----------------------------------------------------------------+ #
# |                            Particles                            | #
# +-----------------------------------------------------------------+ #
#######################################################################


#######################################################################
# +-----------------------------------------------------------------+ #
# |                             Spawners                            | #
# +-----------------------------------------------------------------+ #
#######################################################################


#######################################################################
# +-----------------------------------------------------------------+ #
# |                             ModData                             | #
# +-----------------------------------------------------------------+ #
#######################################################################

