
#######################################################################
# +-----------------------------------------------------------------+ #
# |                            BO3 object                           | #
# +-----------------------------------------------------------------+ #
#######################################################################

Author: MC_Pitman

Description: No description given

Version: 3

SettingsMode: WriteWithoutComments


#######################################################################
# +-----------------------------------------------------------------+ #
# |                          Main settings                          | #
# +-----------------------------------------------------------------+ #
#######################################################################

Tree: true

Frequency: 1

Rarity: 50.0

RotateRandomly: true

SpawnHeight: highestSolidBlock

SpawnHeightOffset: 0

SpawnHeightVariance: 0

##############################
# Height Limits for the BO3. #
##############################

MinHeight: 62

MaxHeight: 210

######################
# Extrusion settings #
######################

ExtrudeMode: None

ExtrudeThroughBlocks: AIR

MaxBranchDepth: 10

ExcludedBiomes: All


#######################################################################
# +-----------------------------------------------------------------+ #
# |                      Source block settings                      | #
# +-----------------------------------------------------------------+ #
#######################################################################

SourceBlocks: STONE:1,STONE:3,STONE:5,DIRT:1,DIRT,SAND,GRASS,DIRT:2,STATIONARY_WATER,HARD_CLAY,STAINED_CLAY,CLAY,SANDSTONE,SAND:1,AIR,STONE,GRAVEL,LONG_GRASS,LONG_GRASS:1,LONG_GRASS:2,DEAD_BUSH,YELLOW_FLOWER,RED_ROSE,BROWN_MUSHROOM,RED_MUSHROOM

MaxPercentageOutsideSourceBlock: 0

OutsideSourceBlock: placeAnyway

IsOTGPlus: false

InheritBO3: 

InheritBO3Rotation: NORTH

OverrideChildSettings: true

OverrideParentHeight: false

CanOverride: false

BranchFrequency: 0

BranchFrequencyGroup: 

MustBeBelowOther: false

MustBeInside: 

CannotBeInside: 

ReplacesBO3: 

CanSpawnOnWater: true

SpawnOnWaterOnly: false

SpawnUnderWater: false

SpawnAtWaterLevel: false

HeightOffset: 0

RemoveAir: true

ReplaceAbove: 

ReplaceBelow: 

ReplaceWithBiomeBlocks: true

ReplaceWithGroundBlock: DIRT

ReplaceWithSurfaceBlock: GRASS

SmoothRadius: 0

SmoothHeightOffset: 0

SmoothStartTop: false

SmoothStartWood: false

SmoothingSurfaceBlock: 

SmoothingGroundBlock: 

BO3Group: 

IsSpawnPoint: false


#######################################################################
# +-----------------------------------------------------------------+ #
# |                              Blocks                             | #
# +-----------------------------------------------------------------+ #
#######################################################################

Block(-10,7,-2,LEAVES:3)
Block(-10,7,3,LEAVES:3)
Block(-10,8,-2,LEAVES:3)
Block(-10,8,3,LEAVES:3)
Block(-10,9,-2,LEAVES:3)
Block(-10,9,3,LEAVES:3)
Block(-10,10,-2,LEAVES:3)
Block(-10,10,3,LEAVES:3)
Block(-10,11,-2,LEAVES:3)
Block(-10,11,3,LEAVES:3)
Block(-9,4,-2,LEAVES:3)
Block(-9,4,3,LEAVES:3)
Block(-9,5,-2,LEAVES:3)
Block(-9,5,3,LEAVES:3)
Block(-9,5,7,LEAVES:3)
Block(-9,6,-3,LEAVES:3)
Block(-9,6,-2,LEAVES:3)
Block(-9,6,-1,LEAVES:3)
Block(-9,6,3,LEAVES:3)
Block(-9,6,7,LEAVES:3)
Block(-9,7,-3,LEAVES:3)
Block(-9,7,-2,LEAVES:3)
Block(-9,7,-1,LEAVES:3)
Block(-9,7,2,LEAVES:3)
Block(-9,7,3,LEAVES:3)
Block(-9,7,4,LEAVES:3)
Block(-9,7,7,LEAVES:3)
Block(-9,8,-3,LEAVES:3)
Block(-9,8,-2,LEAVES:3)
Block(-9,8,-1,LEAVES:3)
Block(-9,8,2,LEAVES:3)
Block(-9,8,3,LOG:15)
Block(-9,8,4,LEAVES:3)
Block(-9,8,7,LEAVES:3)
Block(-9,9,-3,LEAVES:3)
Block(-9,9,-2,LOG:15)
Block(-9,9,-1,LEAVES:3)
Block(-9,9,2,LEAVES:3)
Block(-9,9,3,LOG:15)
Block(-9,9,4,LEAVES:3)
Block(-9,9,7,LEAVES:3)
Block(-9,10,-3,LEAVES:3)
Block(-9,10,-2,LOG:15)
Block(-9,10,-1,LEAVES:3)
Block(-9,10,2,LEAVES:3)
Block(-9,10,3,LOG:15)
Block(-9,10,4,LEAVES:3)
Block(-9,11,-3,LEAVES:3)
Block(-9,11,-2,LOG:15)
Block(-9,11,-1,LEAVES:3)
Block(-9,11,2,LEAVES:3)
Block(-9,11,3,LOG:15)
Block(-9,11,4,LEAVES:3)
Block(-9,12,-2,LEAVES:3)
Block(-9,12,2,LEAVES:3)
Block(-9,12,3,LEAVES:3)
Block(-8,3,7,LEAVES:3)
Block(-8,4,7,LEAVES:3)
Block(-8,4,8,LEAVES:3)
Block(-8,5,-2,LEAVES:3)
Block(-8,5,4,LEAVES:3)
Block(-8,5,6,LEAVES:3)
Block(-8,5,7,LEAVES:3)
Block(-8,5,8,LEAVES:3)
Block(-8,6,-2,LEAVES:3)
Block(-8,6,3,LEAVES:3)
Block(-8,6,4,LEAVES:3)
Block(-8,6,6,LEAVES:3)
Block(-8,6,7,LEAVES:3)
Block(-8,6,8,LEAVES:3)
Block(-8,7,-2,LEAVES:3)
Block(-8,7,3,LEAVES:3)
Block(-8,7,4,LEAVES:3)
Block(-8,7,6,LEAVES:3)
Block(-8,7,7,LOG:15)
Block(-8,7,8,LEAVES:3)
Block(-8,8,-2,LEAVES:3)
Block(-8,8,-1,LEAVES:3)
Block(-8,8,3,LEAVES:3)
Block(-8,8,4,LEAVES:3)
Block(-8,8,6,LEAVES:3)
Block(-8,8,7,LOG:15)
Block(-8,8,8,LEAVES:3)
Block(-8,9,-2,LEAVES:3)
Block(-8,9,-1,LEAVES:3)
Block(-8,9,0,LEAVES:3)
Block(-8,9,1,LEAVES:3)
Block(-8,9,3,LEAVES:3)
Block(-8,9,6,LEAVES:3)
Block(-8,9,7,LOG:15)
Block(-8,9,8,LEAVES:3)
Block(-8,10,-3,LEAVES:3)
Block(-8,10,-2,LEAVES:3)
Block(-8,10,-1,LEAVES:3)
Block(-8,10,0,LEAVES:3)
Block(-8,10,1,LEAVES:3)
Block(-8,10,2,LEAVES:3)
Block(-8,10,3,LEAVES:3)
Block(-8,10,7,LEAVES:3)
Block(-8,11,-3,LEAVES:3)
Block(-8,11,-2,LEAVES:3)
Block(-8,11,-1,LEAVES:3)
Block(-8,11,0,LEAVES:3)
Block(-8,11,1,LEAVES:3)
Block(-8,11,2,LEAVES:3)
Block(-8,11,3,LEAVES:3)
Block(-8,12,-3,LEAVES:3)
Block(-8,12,-2,LOG:15)
Block(-8,12,-1,LEAVES:3)
Block(-8,12,0,LEAVES:3)
Block(-8,12,1,LEAVES:3)
Block(-8,12,2,LOG:15)
Block(-8,12,3,LEAVES:3)
Block(-8,13,-2,LEAVES:3)
Block(-8,13,1,LEAVES:3)
Block(-8,13,2,LEAVES:3)
Block(-7,3,5,LEAVES:3)
Block(-7,4,0,LEAVES:3)
Block(-7,4,5,LEAVES:3)
Block(-7,5,0,LEAVES:3)
Block(-7,5,5,LEAVES:3)
Block(-7,6,0,LEAVES:3)
Block(-7,6,5,LEAVES:3)
Block(-7,6,7,LEAVES:3)
Block(-7,7,-1,LEAVES:3)
Block(-7,7,0,LEAVES:3)
Block(-7,7,1,LEAVES:3)
Block(-7,7,5,LEAVES:3)
Block(-7,7,6,LEAVES:3)
Block(-7,7,7,LEAVES:3)
Block(-7,8,-2,LEAVES:3)
Block(-7,8,-1,LEAVES:3)
Block(-7,8,0,LEAVES:3)
Block(-7,8,1,LEAVES:3)
Block(-7,8,4,LEAVES:3)
Block(-7,8,5,LEAVES:3)
Block(-7,8,6,LEAVES:3)
Block(-7,8,7,LEAVES:3)
Block(-7,9,-5,LEAVES:3)
Block(-7,9,-3,LEAVES:3)
Block(-7,9,-2,LEAVES:3)
Block(-7,9,-1,LEAVES:3)
Block(-7,9,0,LEAVES:3)
Block(-7,9,1,LEAVES:3)
Block(-7,9,4,LEAVES:3)
Block(-7,9,5,LEAVES:3)
Block(-7,9,6,LEAVES:3)
Block(-7,9,7,LOG:15)
Block(-7,9,8,LEAVES:3)
Block(-7,10,-5,LEAVES:3)
Block(-7,10,-3,LEAVES:3)
Block(-7,10,-2,LEAVES:3)
Block(-7,10,-1,LEAVES:3)
Block(-7,10,0,LOG:15)
Block(-7,10,1,LEAVES:3)
Block(-7,10,2,LEAVES:3)
Block(-7,10,3,LEAVES:3)
Block(-7,10,4,LEAVES:3)
Block(-7,10,5,LEAVES:3)
Block(-7,10,7,LEAVES:3)
Block(-7,11,-5,LEAVES:3)
Block(-7,11,-2,LEAVES:3)
Block(-7,11,-1,LEAVES:3)
Block(-7,11,0,LOG:15)
Block(-7,11,1,LEAVES:3)
Block(-7,11,2,LEAVES:3)
Block(-7,11,3,LEAVES:3)
Block(-7,12,-5,LEAVES:3)
Block(-7,12,-2,LEAVES:3)
Block(-7,12,-1,LOG:15)
Block(-7,12,0,LOG:15)
Block(-7,12,1,LEAVES:3)
Block(-7,12,2,LEAVES:3)
Block(-7,13,-1,LEAVES:3)
Block(-7,13,0,LEAVES:3)
Block(-7,13,1,LOG:15)
Block(-7,13,2,LEAVES:3)
Block(-7,14,1,LEAVES:3)
Block(-6,3,-2,LEAVES:3)
Block(-6,4,-2,LEAVES:3)
Block(-6,5,-3,LEAVES:3)
Block(-6,5,-2,LEAVES:3)
Block(-6,5,-1,LEAVES:3)
Block(-6,5,6,LEAVES:3)
Block(-6,6,-5,LEAVES:3)
Block(-6,6,-3,LEAVES:3)
Block(-6,6,-2,LEAVES:3)
Block(-6,6,-1,LEAVES:3)
Block(-6,6,4,LEAVES:3)
Block(-6,6,6,LEAVES:3)
Block(-6,7,-5,LEAVES:3)
Block(-6,7,-3,LEAVES:3)
Block(-6,7,-2,LEAVES:3)
Block(-6,7,-1,LEAVES:3)
Block(-6,7,4,LEAVES:3)
Block(-6,7,5,LEAVES:3)
Block(-6,7,6,LEAVES:3)
Block(-6,7,7,LEAVES:3)
Block(-6,8,-6,LEAVES:3)
Block(-6,8,-5,LEAVES:3)
Block(-6,8,-4,LEAVES:3)
Block(-6,8,-3,LEAVES:3)
Block(-6,8,-2,LOG:15)
Block(-6,8,-1,LEAVES:3)
Block(-6,8,0,LEAVES:3)
Block(-6,8,4,LEAVES:3)
Block(-6,8,5,LOG:15)
Block(-6,8,6,LEAVES:3)
Block(-6,8,7,LEAVES:3)
Block(-6,9,-6,LEAVES:3)
Block(-6,9,-5,LOG:15)
Block(-6,9,-4,LEAVES:3)
Block(-6,9,-3,LEAVES:3)
Block(-6,9,-2,LOG:15)
Block(-6,9,-1,LEAVES:3)
Block(-6,9,0,LEAVES:3)
Block(-6,9,2,LEAVES:3)
Block(-6,9,4,LEAVES:3)
Block(-6,9,5,LOG:15)
Block(-6,9,6,LOG:15)
Block(-6,9,7,LEAVES:3)
Block(-6,10,-6,LEAVES:3)
Block(-6,10,-5,LOG:15)
Block(-6,10,-4,LEAVES:3)
Block(-6,10,-3,LEAVES:3)
Block(-6,10,-2,LOG:15)
Block(-6,10,-1,LEAVES:3)
Block(-6,10,0,LEAVES:3)
Block(-6,10,1,LEAVES:3)
Block(-6,10,2,LEAVES:3)
Block(-6,10,3,LEAVES:3)
Block(-6,10,4,LEAVES:3)
Block(-6,10,5,LOG:15)
Block(-6,10,6,LEAVES:3)
Block(-6,11,-6,LEAVES:3)
Block(-6,11,-5,LOG:15)
Block(-6,11,-4,LEAVES:3)
Block(-6,11,-3,LEAVES:3)
Block(-6,11,-2,LOG:15)
Block(-6,11,-1,LEAVES:3)
Block(-6,11,0,LEAVES:3)
Block(-6,11,1,LEAVES:3)
Block(-6,11,2,LEAVES:3)
Block(-6,11,3,LEAVES:3)
Block(-6,11,5,LEAVES:3)
Block(-6,12,-6,LEAVES:3)
Block(-6,12,-5,LOG:15)
Block(-6,12,-4,LEAVES:3)
Block(-6,12,-3,LEAVES:3)
Block(-6,12,-2,LEAVES:3)
Block(-6,12,-1,LOG:15)
Block(-6,12,0,LEAVES:3)
Block(-6,12,1,LEAVES:3)
Block(-6,12,2,LEAVES:3)
Block(-6,12,3,LEAVES:3)
Block(-6,13,-5,LEAVES:3)
Block(-6,13,-1,LEAVES:3)
Block(-6,13,0,LOG:15)
Block(-6,13,1,LOG:15)
Block(-6,13,2,LEAVES:3)
Block(-6,13,3,LEAVES:3)
Block(-6,14,0,LEAVES:3)
Block(-6,14,1,LEAVES:3)
Block(-5,4,5,LEAVES:3)
Block(-5,5,5,LEAVES:3)
Block(-5,6,5,LEAVES:3)
Block(-5,6,8,LEAVES:3)
Block(-5,7,-5,LEAVES:3)
Block(-5,7,-2,LEAVES:3)
Block(-5,7,2,LEAVES:3)
Block(-5,7,5,LEAVES:3)
Block(-5,7,8,LEAVES:3)
Block(-5,8,-5,LEAVES:3)
Block(-5,8,-2,LEAVES:3)
Block(-5,8,2,LEAVES:3)
Block(-5,8,5,LEAVES:3)
Block(-5,8,6,LEAVES:3)
Block(-5,8,7,LEAVES:3)
Block(-5,8,8,LEAVES:3)
Block(-5,9,-5,LEAVES:3)
Block(-5,9,-4,LEAVES:3)
Block(-5,9,-2,LEAVES:3)
Block(-5,9,-1,LEAVES:3)
Block(-5,9,1,LEAVES:3)
Block(-5,9,2,LEAVES:3)
Block(-5,9,3,LEAVES:3)
Block(-5,9,4,LEAVES:3)
Block(-5,9,5,LEAVES:3)
Block(-5,9,6,LEAVES:3)
Block(-5,9,7,LEAVES:3)
Block(-5,9,8,LEAVES:3)
Block(-5,10,-5,LEAVES:3)
Block(-5,10,-4,LEAVES:3)
Block(-5,10,-3,LEAVES:3)
Block(-5,10,-2,LEAVES:3)
Block(-5,10,-1,LEAVES:3)
Block(-5,10,0,LEAVES:3)
Block(-5,10,1,LEAVES:3)
Block(-5,10,2,LEAVES:3)
Block(-5,10,3,LEAVES:3)
Block(-5,10,4,LEAVES:3)
Block(-5,10,5,LOG:15)
Block(-5,10,6,LEAVES:3)
Block(-5,10,7,LEAVES:3)
Block(-5,11,-5,LEAVES:3)
Block(-5,11,-4,LEAVES:3)
Block(-5,11,-3,LEAVES:3)
Block(-5,11,-2,LEAVES:3)
Block(-5,11,-1,LEAVES:3)
Block(-5,11,0,LEAVES:3)
Block(-5,11,1,LEAVES:3)
Block(-5,11,2,LOG:15)
Block(-5,11,3,LEAVES:3)
Block(-5,11,4,LEAVES:3)
Block(-5,11,5,LEAVES:3)
Block(-5,11,6,LEAVES:3)
Block(-5,12,-5,LEAVES:3)
Block(-5,12,-4,LOG:15)
Block(-5,12,-3,LEAVES:3)
Block(-5,12,-2,LEAVES:3)
Block(-5,12,-1,LEAVES:3)
Block(-5,12,0,LEAVES:3)
Block(-5,12,1,LOG:15)
Block(-5,12,2,LOG:15)
Block(-5,12,3,LEAVES:3)
Block(-5,13,-4,LEAVES:3)
Block(-5,13,-3,LEAVES:3)
Block(-5,13,0,LEAVES:3)
Block(-5,13,1,LEAVES:3)
Block(-5,13,2,LEAVES:3)
Block(-5,14,1,LEAVES:3)
Block(-5,14,2,LEAVES:3)
Block(-4,3,8,LEAVES:3)
Block(-4,4,8,LEAVES:3)
Block(-4,5,8,LEAVES:3)
Block(-4,5,9,LEAVES:3)
Block(-4,6,8,LEAVES:3)
Block(-4,6,9,LEAVES:3)
Block(-4,7,-3,LEAVES:3)
Block(-4,7,4,LEAVES:3)
Block(-4,7,7,LEAVES:3)
Block(-4,7,8,LOG:15)
Block(-4,7,9,LEAVES:3)
Block(-4,8,-4,LEAVES:3)
Block(-4,8,-3,LEAVES:3)
Block(-4,8,4,LEAVES:3)
Block(-4,8,5,LEAVES:3)
Block(-4,8,6,LEAVES:3)
Block(-4,8,7,LEAVES:3)
Block(-4,8,8,LOG:15)
Block(-4,8,9,LEAVES:3)
Block(-4,9,-4,LEAVES:3)
Block(-4,9,-3,LEAVES:3)
Block(-4,9,-2,LEAVES:3)
Block(-4,9,2,LEAVES:3)
Block(-4,9,3,LEAVES:3)
Block(-4,9,4,LEAVES:3)
Block(-4,9,5,LEAVES:3)
Block(-4,9,6,LEAVES:3)
Block(-4,9,7,LOG:15)
Block(-4,9,8,LOG:15)
Block(-4,9,9,LEAVES:3)
Block(-4,10,-4,LEAVES:3)
Block(-4,10,-3,LEAVES:3)
Block(-4,10,-2,LEAVES:3)
Block(-4,10,-1,LEAVES:3)
Block(-4,10,0,LEAVES:3)
Block(-4,10,1,LEAVES:3)
Block(-4,10,2,LEAVES:3)
Block(-4,10,3,LEAVES:3)
Block(-4,10,4,LEAVES:3)
Block(-4,10,5,LOG:15)
Block(-4,10,6,LOG:15)
Block(-4,10,7,LEAVES:3)
Block(-4,10,8,LEAVES:3)
Block(-4,11,-4,LEAVES:3)
Block(-4,11,-3,LOG:15)
Block(-4,11,-2,LEAVES:3)
Block(-4,11,-1,LEAVES:3)
Block(-4,11,0,LEAVES:3)
Block(-4,11,1,LEAVES:3)
Block(-4,11,2,LEAVES:3)
Block(-4,11,3,LEAVES:3)
Block(-4,11,4,LOG:15)
Block(-4,11,5,LEAVES:3)
Block(-4,11,6,LEAVES:3)
Block(-4,12,-4,LEAVES:3)
Block(-4,12,-3,LOG:15)
Block(-4,12,-2,LEAVES:3)
Block(-4,12,-1,LEAVES:3)
Block(-4,12,0,LEAVES:3)
Block(-4,12,1,LOG:15)
Block(-4,12,2,LEAVES:3)
Block(-4,12,3,LEAVES:3)
Block(-4,12,4,LEAVES:3)
Block(-4,12,5,LEAVES:3)
Block(-4,13,-4,LEAVES:3)
Block(-4,13,-3,LOG:15)
Block(-4,13,-2,LEAVES:3)
Block(-4,13,-1,LEAVES:3)
Block(-4,13,0,LEAVES:3)
Block(-4,13,1,LEAVES:3)
Block(-4,13,2,LEAVES:3)
Block(-4,14,-3,LEAVES:3)
Block(-4,14,-2,LEAVES:3)
Block(-4,14,0,LEAVES:3)
Block(-3,-1,-1,LOG:15)
Block(-3,5,4,LEAVES:3)
Block(-3,5,6,LEAVES:3)
Block(-3,6,4,LEAVES:3)
Block(-3,6,6,LEAVES:3)
Block(-3,6,8,LEAVES:3)
Block(-3,7,3,LEAVES:3)
Block(-3,7,4,LEAVES:3)
Block(-3,7,6,LEAVES:3)
Block(-3,7,8,LEAVES:3)
Block(-3,8,-3,LEAVES:3)
Block(-3,8,0,LEAVES:3)
Block(-3,8,3,LEAVES:3)
Block(-3,8,4,LOG:15)
Block(-3,8,5,LEAVES:3)
Block(-3,8,6,LEAVES:3)
Block(-3,8,8,LEAVES:3)
Block(-3,8,12,LEAVES:3)
Block(-3,9,-4,LEAVES:3)
Block(-3,9,-3,LEAVES:3)
Block(-3,9,-2,LEAVES:3)
Block(-3,9,-1,LEAVES:3)
Block(-3,9,0,LEAVES:3)
Block(-3,9,1,LOG:15)
Block(-3,9,2,LEAVES:3)
Block(-3,9,3,LEAVES:3)
Block(-3,9,4,LOG:15)
Block(-3,9,5,LEAVES:3)
Block(-3,9,6,LEAVES:3)
Block(-3,9,7,LEAVES:3)
Block(-3,9,8,LEAVES:3)
Block(-3,9,12,LEAVES:3)
Block(-3,10,-4,LEAVES:3)
Block(-3,10,-3,LEAVES:3)
Block(-3,10,-2,LEAVES:3)
Block(-3,10,-1,LEAVES:3)
Block(-3,10,0,LEAVES:3)
Block(-3,10,1,LOG:15)
Block(-3,10,2,LOG:15)
Block(-3,10,3,LEAVES:3)
Block(-3,10,4,LOG:15)
Block(-3,10,5,LEAVES:3)
Block(-3,10,6,LEAVES:3)
Block(-3,10,7,LEAVES:3)
Block(-3,11,-4,LEAVES:3)
Block(-3,11,-3,LEAVES:3)
Block(-3,11,-2,LEAVES:3)
Block(-3,11,-1,LEAVES:3)
Block(-3,11,0,LOG:15)
Block(-3,11,1,LOG:15)
Block(-3,11,2,LEAVES:3)
Block(-3,11,3,LOG:15)
Block(-3,11,4,LOG:15)
Block(-3,11,5,LEAVES:3)
Block(-3,11,6,LEAVES:3)
Block(-3,12,-3,LEAVES:3)
Block(-3,12,-2,LEAVES:3)
Block(-3,12,-1,LOG:15)
Block(-3,12,0,LEAVES:3)
Block(-3,12,1,LEAVES:3)
Block(-3,12,2,LEAVES:3)
Block(-3,12,3,LEAVES:3)
Block(-3,12,4,LEAVES:3)
Block(-3,12,5,LEAVES:3)
Block(-3,12,6,LEAVES:3)
Block(-3,13,-3,LEAVES:3)
Block(-3,13,-2,LOG:15)
Block(-3,13,-1,LEAVES:3)
Block(-3,13,2,LEAVES:3)
Block(-3,13,3,LEAVES:3)
Block(-3,14,-2,LEAVES:3)
Block(-3,14,2,LEAVES:3)
Block(-2,-1,-2,LOG:15)
Block(-2,-1,-1,LOG:15)
Block(-2,-1,0,LOG:15)
Block(-2,-1,2,LOG:15)
Block(-2,0,-1,LOG:15)
Block(-2,5,-1,LEAVES:3)
Block(-2,6,-4,LEAVES:3)
Block(-2,6,-1,LEAVES:3)
Block(-2,6,5,LEAVES:3)
Block(-2,7,-4,LEAVES:3)
Block(-2,7,-2,LEAVES:3)
Block(-2,7,-1,LEAVES:3)
Block(-2,7,1,LOG:15)
Block(-2,7,5,LEAVES:3)
Block(-2,8,-4,LEAVES:3)
Block(-2,8,-3,LEAVES:3)
Block(-2,8,-2,LEAVES:3)
Block(-2,8,-1,LEAVES:3)
Block(-2,8,1,LOG:15)
Block(-2,8,2,LEAVES:3)
Block(-2,8,3,LEAVES:3)
Block(-2,8,4,LEAVES:3)
Block(-2,8,5,LEAVES:3)
Block(-2,8,7,LEAVES:3)
Block(-2,8,13,LEAVES:3)
Block(-2,9,-4,LEAVES:3)
Block(-2,9,-3,LEAVES:3)
Block(-2,9,-2,LEAVES:3)
Block(-2,9,-1,LEAVES:3)
Block(-2,9,0,LEAVES:3)
Block(-2,9,1,LOG:15)
Block(-2,9,2,LEAVES:3)
Block(-2,9,3,LEAVES:3)
Block(-2,9,4,LEAVES:3)
Block(-2,9,5,LEAVES:3)
Block(-2,9,7,LEAVES:3)
Block(-2,9,13,LEAVES:3)
Block(-2,10,-4,LEAVES:3)
Block(-2,10,-3,LEAVES:3)
Block(-2,10,-2,LEAVES:3)
Block(-2,10,-1,LOG:15)
Block(-2,10,0,LEAVES:3)
Block(-2,10,2,LEAVES:3)
Block(-2,10,3,LEAVES:3)
Block(-2,10,4,LEAVES:3)
Block(-2,10,5,LEAVES:3)
Block(-2,10,6,LOG:15)
Block(-2,10,7,LEAVES:3)
Block(-2,10,11,LEAVES:3)
Block(-2,10,12,LEAVES:3)
Block(-2,10,13,LEAVES:3)
Block(-2,11,-3,LEAVES:3)
Block(-2,11,-2,LEAVES:3)
Block(-2,11,-1,LOG:15)
Block(-2,11,0,LEAVES:3)
Block(-2,11,1,LEAVES:3)
Block(-2,11,2,LEAVES:3)
Block(-2,11,3,LEAVES:3)
Block(-2,11,4,LEAVES:3)
Block(-2,11,5,LEAVES:3)
Block(-2,11,6,LOG:15)
Block(-2,11,7,LEAVES:3)
Block(-2,11,11,LEAVES:3)
Block(-2,11,12,LEAVES:3)
Block(-2,11,13,LEAVES:3)
Block(-2,12,-3,LEAVES:3)
Block(-2,12,-2,LOG:15)
Block(-2,12,-1,LOG:15)
Block(-2,12,0,LEAVES:3)
Block(-2,12,2,LEAVES:3)
Block(-2,12,3,LEAVES:3)
Block(-2,12,4,LOG:15)
Block(-2,12,5,LOG:15)
Block(-2,12,6,LOG:15)
Block(-2,12,7,LEAVES:3)
Block(-2,13,-2,LEAVES:3)
Block(-2,13,-1,LEAVES:3)
Block(-2,13,2,LEAVES:3)
Block(-2,13,4,LEAVES:3)
Block(-2,13,5,LEAVES:3)
Block(-2,13,6,LEAVES:3)
Block(-1,-1,-1,LOG:15)
Block(-1,-1,0,LOG:15)
Block(-1,-1,1,LOG:15)
Block(-1,0,-1,LOG:15)
Block(-1,0,0,LOG:15)
Block(-1,0,1,LOG:15)
Block(-1,1,-1,LOG:15)
Block(-1,1,0,LOG:15)
Block(-1,2,0,LOG:15)
Block(-1,3,-4,LEAVES:3)
Block(-1,4,-4,LEAVES:3)
Block(-1,5,-5,LEAVES:3)
Block(-1,5,-4,LEAVES:3)
Block(-1,5,1,LOG:15)
Block(-1,5,3,LEAVES:3)
Block(-1,5,7,LEAVES:3)
Block(-1,6,-5,LEAVES:3)
Block(-1,6,-4,LEAVES:3)
Block(-1,6,-3,LEAVES:3)
Block(-1,6,1,LOG:15)
Block(-1,6,3,LEAVES:3)
Block(-1,6,7,LEAVES:3)
Block(-1,6,13,LEAVES:3)
Block(-1,7,-5,LEAVES:3)
Block(-1,7,-4,LOG:15)
Block(-1,7,-3,LEAVES:3)
Block(-1,7,0,LEAVES:3)
Block(-1,7,1,LOG:15)
Block(-1,7,3,LEAVES:3)
Block(-1,7,4,LEAVES:3)
Block(-1,7,7,LEAVES:3)
Block(-1,7,11,LEAVES:3)
Block(-1,7,13,LEAVES:3)
Block(-1,7,14,LEAVES:3)
Block(-1,8,-5,LEAVES:3)
Block(-1,8,-4,LOG:15)
Block(-1,8,-3,LEAVES:3)
Block(-1,8,-1,LEAVES:3)
Block(-1,8,0,LEAVES:3)
Block(-1,8,3,LEAVES:3)
Block(-1,8,4,LEAVES:3)
Block(-1,8,5,LEAVES:3)
Block(-1,8,7,LEAVES:3)
Block(-1,8,9,LEAVES:3)
Block(-1,8,11,LEAVES:3)
Block(-1,8,12,LEAVES:3)
Block(-1,8,13,LOG:15)
Block(-1,8,14,LEAVES:3)
Block(-1,9,-5,LEAVES:3)
Block(-1,9,-4,LOG:15)
Block(-1,9,-3,LEAVES:3)
Block(-1,9,-1,LEAVES:3)
Block(-1,9,0,LEAVES:3)
Block(-1,9,1,LEAVES:3)
Block(-1,9,3,LEAVES:3)
Block(-1,9,4,LOG:15)
Block(-1,9,5,LEAVES:3)
Block(-1,9,6,LEAVES:3)
Block(-1,9,7,LEAVES:3)
Block(-1,9,9,LEAVES:3)
Block(-1,9,11,LEAVES:3)
Block(-1,9,12,LEAVES:3)
Block(-1,9,13,LOG:15)
Block(-1,9,14,LEAVES:3)
Block(-1,10,-5,LEAVES:3)
Block(-1,10,-4,LOG:15)
Block(-1,10,-3,LEAVES:3)
Block(-1,10,-2,LEAVES:3)
Block(-1,10,-1,LEAVES:3)
Block(-1,10,1,LEAVES:3)
Block(-1,10,3,LEAVES:3)
Block(-1,10,4,LOG:15)
Block(-1,10,5,LEAVES:3)
Block(-1,10,6,LEAVES:3)
Block(-1,10,7,LEAVES:3)
Block(-1,10,9,LEAVES:3)
Block(-1,10,10,LEAVES:3)
Block(-1,10,11,LOG:15)
Block(-1,10,12,LEAVES:3)
Block(-1,10,13,LOG:15)
Block(-1,10,14,LEAVES:3)
Block(-1,11,-4,LEAVES:3)
Block(-1,11,-3,LOG:15)
Block(-1,11,-2,LEAVES:3)
Block(-1,11,-1,LEAVES:3)
Block(-1,11,1,LEAVES:3)
Block(-1,11,3,LEAVES:3)
Block(-1,11,4,LOG:15)
Block(-1,11,5,LEAVES:3)
Block(-1,11,6,LOG:15)
Block(-1,11,7,LEAVES:3)
Block(-1,11,10,LEAVES:3)
Block(-1,11,11,LOG:15)
Block(-1,11,12,LOG:15)
Block(-1,11,13,LOG:15)
Block(-1,11,14,LEAVES:3)
Block(-1,12,-3,LEAVES:3)
Block(-1,12,-2,LEAVES:3)
Block(-1,12,-1,LEAVES:3)
Block(-1,12,3,LEAVES:3)
Block(-1,12,4,LOG:15)
Block(-1,12,5,LEAVES:3)
Block(-1,12,6,LEAVES:3)
Block(-1,12,10,LEAVES:3)
Block(-1,12,11,LEAVES:3)
Block(-1,12,12,LEAVES:3)
Block(-1,12,13,LEAVES:3)
Block(-1,13,4,LEAVES:3)
Block(0,-1,-2,LOG:15)
Block(0,-1,-1,LOG:15)
Block(0,-1,0,LOG:15)
Block(0,0,-1,LOG:15)
Block(0,0,0,LOG:15)
Block(0,1,0,LOG:15)
Block(0,2,0,LOG:15)
Block(0,2,1,LOG:15)
Block(0,3,0,LOG:15)
Block(0,3,1,LOG:15)
Block(0,3,7,LEAVES:3)
Block(0,4,1,LOG:15)
Block(0,4,7,LEAVES:3)
Block(0,5,1,LOG:15)
Block(0,5,7,LEAVES:3)
Block(0,5,14,LEAVES:3)
Block(0,6,4,LEAVES:3)
Block(0,6,7,LEAVES:3)
Block(0,6,14,LEAVES:3)
Block(0,7,-4,LEAVES:3)
Block(0,7,-2,LEAVES:3)
Block(0,7,4,LEAVES:3)
Block(0,7,7,LEAVES:3)
Block(0,7,8,LEAVES:3)
Block(0,7,13,LEAVES:3)
Block(0,7,14,LEAVES:3)
Block(0,8,-4,LEAVES:3)
Block(0,8,-2,LEAVES:3)
Block(0,8,4,LEAVES:3)
Block(0,8,6,LEAVES:3)
Block(0,8,7,LOG:15)
Block(0,8,8,LEAVES:3)
Block(0,8,11,LEAVES:3)
Block(0,8,13,LEAVES:3)
Block(0,8,14,LEAVES:3)
Block(0,9,-4,LEAVES:3)
Block(0,9,-3,LEAVES:3)
Block(0,9,-2,LEAVES:3)
Block(0,9,4,LEAVES:3)
Block(0,9,6,LEAVES:3)
Block(0,9,7,LOG:15)
Block(0,9,8,LEAVES:3)
Block(0,9,9,LEAVES:3)
Block(0,9,11,LEAVES:3)
Block(0,9,12,LEAVES:3)
Block(0,9,13,LEAVES:3)
Block(0,9,14,LEAVES:3)
Block(0,10,-4,LEAVES:3)
Block(0,10,-3,LEAVES:3)
Block(0,10,-2,LEAVES:3)
Block(0,10,4,LEAVES:3)
Block(0,10,6,LEAVES:3)
Block(0,10,7,LOG:15)
Block(0,10,8,LEAVES:3)
Block(0,10,9,LEAVES:3)
Block(0,10,10,LEAVES:3)
Block(0,10,11,LEAVES:3)
Block(0,10,12,LEAVES:3)
Block(0,10,13,LEAVES:3)
Block(0,10,14,LEAVES:3)
Block(0,11,-3,LEAVES:3)
Block(0,11,4,LEAVES:3)
Block(0,11,6,LEAVES:3)
Block(0,11,7,LEAVES:3)
Block(0,11,8,LEAVES:3)
Block(0,11,9,LEAVES:3)
Block(0,11,10,LEAVES:3)
Block(0,11,11,LOG:15)
Block(0,11,12,LEAVES:3)
Block(0,11,13,LEAVES:3)
Block(0,12,4,LEAVES:3)
Block(0,12,8,LEAVES:3)
Block(0,12,10,LEAVES:3)
Block(0,12,11,LEAVES:3)
Block(0,12,12,LEAVES:3)
Block(0,13,12,LEAVES:3)
Block(1,-1,0,LOG:15)
Block(1,-1,1,LOG:15)
Block(1,0,0,LOG:15)
Block(1,3,1,LOG:15)
Block(1,4,1,LOG:15)
Block(1,4,2,LOG:15)
Block(1,5,2,LOG:15)
Block(1,6,7,LEAVES:3)
Block(1,6,10,LEAVES:3)
Block(1,6,15,LEAVES:3)
Block(1,7,7,LEAVES:3)
Block(1,7,10,LEAVES:3)
Block(1,7,13,LEAVES:3)
Block(1,7,14,LEAVES:3)
Block(1,7,15,LEAVES:3)
Block(1,8,7,LEAVES:3)
Block(1,8,10,LEAVES:3)
Block(1,8,13,LEAVES:3)
Block(1,8,14,LEAVES:3)
Block(1,8,15,LEAVES:3)
Block(1,9,7,LEAVES:3)
Block(1,9,10,LEAVES:3)
Block(1,9,13,LEAVES:3)
Block(1,9,14,LEAVES:3)
Block(1,9,15,LEAVES:3)
Block(1,9,16,LEAVES:3)
Block(1,10,7,LEAVES:3)
Block(1,10,8,LEAVES:3)
Block(1,10,10,LEAVES:3)
Block(1,10,11,LEAVES:3)
Block(1,10,12,LEAVES:3)
Block(1,10,13,LEAVES:3)
Block(1,10,14,LEAVES:3)
Block(1,10,15,LEAVES:3)
Block(1,10,16,LEAVES:3)
Block(1,11,8,LEAVES:3)
Block(1,11,9,LEAVES:3)
Block(1,11,10,LEAVES:3)
Block(1,11,11,LEAVES:3)
Block(1,11,12,LEAVES:3)
Block(1,11,13,LEAVES:3)
Block(1,11,14,LEAVES:3)
Block(1,11,15,LEAVES:3)
Block(1,11,16,LEAVES:3)
Block(1,12,9,LEAVES:3)
Block(1,12,10,LOG:15)
Block(1,12,11,LEAVES:3)
Block(1,12,12,LEAVES:3)
Block(1,12,13,LEAVES:3)
Block(1,12,14,LEAVES:3)
Block(1,12,15,LEAVES:3)
Block(1,12,16,LEAVES:3)
Block(1,13,10,LEAVES:3)
Block(1,13,12,LEAVES:3)
Block(1,13,14,LEAVES:3)
Block(2,5,2,LOG:15)
Block(2,5,3,LOG:15)
Block(2,5,16,LEAVES:3)
Block(2,6,2,LOG:15)
Block(2,6,3,LOG:15)
Block(2,6,16,LEAVES:3)
Block(2,7,10,LEAVES:3)
Block(2,7,15,LEAVES:3)
Block(2,7,16,LEAVES:3)
Block(2,8,-4,LEAVES:3)
Block(2,8,7,LEAVES:3)
Block(2,8,10,LEAVES:3)
Block(2,8,15,LEAVES:3)
Block(2,8,16,LEAVES:3)
Block(2,8,17,LEAVES:3)
Block(2,9,-4,LEAVES:3)
Block(2,9,7,LEAVES:3)
Block(2,9,10,LEAVES:3)
Block(2,9,11,LEAVES:3)
Block(2,9,14,LEAVES:3)
Block(2,9,15,LEAVES:3)
Block(2,9,16,LOG:15)
Block(2,9,17,LEAVES:3)
Block(2,10,-4,LEAVES:3)
Block(2,10,7,LEAVES:3)
Block(2,10,8,LEAVES:3)
Block(2,10,9,LEAVES:3)
Block(2,10,10,LOG:15)
Block(2,10,11,LEAVES:3)
Block(2,10,12,LEAVES:3)
Block(2,10,13,LEAVES:3)
Block(2,10,14,LEAVES:3)
Block(2,10,15,LEAVES:3)
Block(2,10,16,LOG:15)
Block(2,10,17,LEAVES:3)
Block(2,11,-4,LEAVES:3)
Block(2,11,7,LEAVES:3)
Block(2,11,8,LEAVES:3)
Block(2,11,9,LEAVES:3)
Block(2,11,10,LOG:15)
Block(2,11,11,LEAVES:3)
Block(2,11,12,LEAVES:3)
Block(2,11,13,LEAVES:3)
Block(2,11,14,LEAVES:3)
Block(2,11,15,LEAVES:3)
Block(2,11,16,LOG:15)
Block(2,11,17,LEAVES:3)
Block(2,12,-4,LEAVES:3)
Block(2,12,7,LEAVES:3)
Block(2,12,8,LEAVES:3)
Block(2,12,9,LEAVES:3)
Block(2,12,10,LOG:15)
Block(2,12,11,LEAVES:3)
Block(2,12,12,LEAVES:3)
Block(2,12,13,LEAVES:3)
Block(2,12,14,LEAVES:3)
Block(2,12,15,LOG:15)
Block(2,12,16,LOG:15)
Block(2,12,17,LEAVES:3)
Block(2,13,8,LEAVES:3)
Block(2,13,10,LEAVES:3)
Block(2,13,11,LEAVES:3)
Block(2,13,12,LEAVES:3)
Block(2,13,13,LEAVES:3)
Block(2,13,14,LEAVES:3)
Block(2,13,15,LEAVES:3)
Block(2,13,16,LEAVES:3)
Block(2,14,12,LEAVES:3)
Block(2,14,13,LEAVES:3)
Block(3,4,-4,LEAVES:3)
Block(3,5,-4,LEAVES:3)
Block(3,5,7,LEAVES:3)
Block(3,6,-4,LEAVES:3)
Block(3,6,-3,LEAVES:3)
Block(3,6,3,LOG:15)
Block(3,6,4,LOG:15)
Block(3,6,7,LEAVES:3)
Block(3,7,-5,LEAVES:3)
Block(3,7,-4,LEAVES:3)
Block(3,7,-3,LEAVES:3)
Block(3,7,3,LOG:15)
Block(3,7,4,LOG:15)
Block(3,7,7,LEAVES:3)
Block(3,8,-5,LEAVES:3)
Block(3,8,-4,LEAVES:3)
Block(3,8,-3,LEAVES:3)
Block(3,8,3,LOG:15)
Block(3,8,7,LEAVES:3)
Block(3,8,12,LEAVES:3)
Block(3,8,14,LEAVES:3)
Block(3,9,-5,LEAVES:3)
Block(3,9,-4,LOG:15)
Block(3,9,-3,LEAVES:3)
Block(3,9,6,LEAVES:3)
Block(3,9,7,LOG:15)
Block(3,9,8,LEAVES:3)
Block(3,9,12,LEAVES:3)
Block(3,9,14,LEAVES:3)
Block(3,9,16,LEAVES:3)
Block(3,10,-5,LEAVES:3)
Block(3,10,-4,LOG:15)
Block(3,10,-3,LEAVES:3)
Block(3,10,6,LEAVES:3)
Block(3,10,7,LOG:15)
Block(3,10,8,LEAVES:3)
Block(3,10,9,LEAVES:3)
Block(3,10,10,LEAVES:3)
Block(3,10,11,LEAVES:3)
Block(3,10,12,LEAVES:3)
Block(3,10,13,LEAVES:3)
Block(3,10,14,LEAVES:3)
Block(3,10,15,LEAVES:3)
Block(3,10,16,LEAVES:3)
Block(3,11,-5,LEAVES:3)
Block(3,11,-4,LOG:15)
Block(3,11,-3,LEAVES:3)
Block(3,11,6,LEAVES:3)
Block(3,11,7,LOG:15)
Block(3,11,8,LEAVES:3)
Block(3,11,9,LEAVES:3)
Block(3,11,10,LEAVES:3)
Block(3,11,11,LEAVES:3)
Block(3,11,12,LEAVES:3)
Block(3,11,13,LEAVES:3)
Block(3,11,14,LOG:15)
Block(3,11,15,LEAVES:3)
Block(3,11,16,LEAVES:3)
Block(3,12,-5,LEAVES:3)
Block(3,12,-4,LOG:15)
Block(3,12,-3,LEAVES:3)
Block(3,12,6,LEAVES:3)
Block(3,12,7,LOG:15)
Block(3,12,8,LEAVES:3)
Block(3,12,9,LEAVES:3)
Block(3,12,10,LEAVES:3)
Block(3,12,11,LEAVES:3)
Block(3,12,12,LEAVES:3)
Block(3,12,13,LEAVES:3)
Block(3,12,14,LOG:15)
Block(3,12,15,LEAVES:3)
Block(3,12,16,LEAVES:3)
Block(3,13,-4,LEAVES:3)
Block(3,13,-3,LEAVES:3)
Block(3,13,7,LEAVES:3)
Block(3,13,8,LEAVES:3)
Block(3,13,9,LEAVES:3)
Block(3,13,10,LEAVES:3)
Block(3,13,11,LOG:15)
Block(3,13,12,LEAVES:3)
Block(3,13,13,LEAVES:3)
Block(3,13,14,LEAVES:3)
Block(3,14,9,LEAVES:3)
Block(3,14,11,LEAVES:3)
Block(3,14,12,LEAVES:3)
Block(3,14,13,LEAVES:3)
Block(3,14,14,LEAVES:3)
Block(3,14,15,LEAVES:3)
Block(4,6,12,LEAVES:3)
Block(4,7,-4,LEAVES:3)
Block(4,7,4,LOG:15)
Block(4,7,5,LOG:15)
Block(4,7,12,LEAVES:3)
Block(4,7,20,LEAVES:3)
Block(4,8,-4,LEAVES:3)
Block(4,8,-2,LEAVES:3)
Block(4,8,2,LOG:15)
Block(4,8,4,LOG:15)
Block(4,8,5,LOG:15)
Block(4,8,12,LEAVES:3)
Block(4,8,17,LEAVES:3)
Block(4,8,20,LEAVES:3)
Block(4,9,-4,LEAVES:3)
Block(4,9,-3,LEAVES:3)
Block(4,9,-2,LEAVES:3)
Block(4,9,2,LOG:15)
Block(4,9,9,LEAVES:3)
Block(4,9,11,LEAVES:3)
Block(4,9,12,LOG:15)
Block(4,9,13,LEAVES:3)
Block(4,9,17,LEAVES:3)
Block(4,9,19,LEAVES:3)
Block(4,9,20,LEAVES:3)
Block(4,10,-6,LEAVES:3)
Block(4,10,-4,LEAVES:3)
Block(4,10,-3,LEAVES:3)
Block(4,10,-2,LEAVES:3)
Block(4,10,2,LOG:15)
Block(4,10,8,LEAVES:3)
Block(4,10,9,LEAVES:3)
Block(4,10,10,LEAVES:3)
Block(4,10,11,LEAVES:3)
Block(4,10,12,LOG:15)
Block(4,10,13,LEAVES:3)
Block(4,10,14,LEAVES:3)
Block(4,10,15,LEAVES:3)
Block(4,10,16,LEAVES:3)
Block(4,10,17,LEAVES:3)
Block(4,11,-6,LEAVES:3)
Block(4,11,-5,LEAVES:3)
Block(4,11,-4,LEAVES:3)
Block(4,11,-3,LEAVES:3)
Block(4,11,-2,LEAVES:3)
Block(4,11,8,LEAVES:3)
Block(4,11,9,LEAVES:3)
Block(4,11,10,LEAVES:3)
Block(4,11,11,LEAVES:3)
Block(4,11,12,LOG:15)
Block(4,11,13,LEAVES:3)
Block(4,11,14,LEAVES:3)
Block(4,11,15,LEAVES:3)
Block(4,11,16,LEAVES:3)
Block(4,11,17,LEAVES:3)
Block(4,12,-6,LEAVES:3)
Block(4,12,-5,LEAVES:3)
Block(4,12,-4,LEAVES:3)
Block(4,12,-3,LEAVES:3)
Block(4,12,-2,LEAVES:3)
Block(4,12,7,LEAVES:3)
Block(4,12,8,LOG:15)
Block(4,12,9,LEAVES:3)
Block(4,12,10,LEAVES:3)
Block(4,12,11,LEAVES:3)
Block(4,12,12,LOG:15)
Block(4,12,13,LEAVES:3)
Block(4,12,14,LEAVES:3)
Block(4,12,15,LEAVES:3)
Block(4,12,16,LEAVES:3)
Block(4,12,17,LEAVES:3)
Block(4,13,-6,LEAVES:3)
Block(4,13,-4,LEAVES:3)
Block(4,13,-3,LOG:15)
Block(4,13,-2,LEAVES:3)
Block(4,13,8,LEAVES:3)
Block(4,13,9,LEAVES:3)
Block(4,13,10,LEAVES:3)
Block(4,13,11,LEAVES:3)
Block(4,13,12,LOG:15)
Block(4,13,13,LOG:15)
Block(4,13,14,LEAVES:3)
Block(4,13,15,LEAVES:3)
Block(4,13,16,LEAVES:3)
Block(4,14,-3,LEAVES:3)
Block(4,14,11,LEAVES:3)
Block(4,14,12,LEAVES:3)
Block(4,14,13,LEAVES:3)
Block(4,14,14,LEAVES:3)
Block(4,14,15,LEAVES:3)
Block(4,14,16,LEAVES:3)
Block(4,15,14,LEAVES:3)
Block(4,15,16,LEAVES:3)
Block(4,16,16,LEAVES:3)
Block(5,4,20,LEAVES:3)
Block(5,5,20,LEAVES:3)
Block(5,6,20,LEAVES:3)
Block(5,6,21,LEAVES:3)
Block(5,7,9,LEAVES:3)
Block(5,7,17,LEAVES:3)
Block(5,7,19,LEAVES:3)
Block(5,7,20,LOG:15)
Block(5,7,21,LEAVES:3)
Block(5,8,-7,LEAVES:3)
Block(5,8,5,LOG:15)
Block(5,8,6,LOG:15)
Block(5,8,9,LEAVES:3)
Block(5,8,10,LEAVES:3)
Block(5,8,14,LEAVES:3)
Block(5,8,17,LEAVES:3)
Block(5,8,19,LEAVES:3)
Block(5,8,20,LOG:15)
Block(5,8,21,LEAVES:3)
Block(5,9,-7,LEAVES:3)
Block(5,9,-6,LEAVES:3)
Block(5,9,6,LOG:15)
Block(5,9,9,LEAVES:3)
Block(5,9,10,LEAVES:3)
Block(5,9,12,LEAVES:3)
Block(5,9,14,LEAVES:3)
Block(5,9,15,LEAVES:3)
Block(5,9,17,LEAVES:3)
Block(5,9,18,LEAVES:3)
Block(5,9,19,LOG:15)
Block(5,9,20,LOG:15)
Block(5,9,21,LEAVES:3)
Block(5,10,-8,LEAVES:3)
Block(5,10,-7,LEAVES:3)
Block(5,10,-6,LEAVES:3)
Block(5,10,-4,LEAVES:3)
Block(5,10,-3,LEAVES:3)
Block(5,10,-2,LEAVES:3)
Block(5,10,1,LOG:15)
Block(5,10,9,LEAVES:3)
Block(5,10,10,LEAVES:3)
Block(5,10,12,LEAVES:3)
Block(5,10,14,LEAVES:3)
Block(5,10,15,LEAVES:3)
Block(5,10,16,LEAVES:3)
Block(5,10,17,LEAVES:3)
Block(5,10,18,LEAVES:3)
Block(5,10,19,LEAVES:3)
Block(5,10,20,LEAVES:3)
Block(5,11,-8,LEAVES:3)
Block(5,11,-7,LEAVES:3)
Block(5,11,-6,LEAVES:3)
Block(5,11,-4,LEAVES:3)
Block(5,11,-3,LEAVES:3)
Block(5,11,-2,LEAVES:3)
Block(5,11,1,LOG:15)
Block(5,11,8,LEAVES:3)
Block(5,11,9,LOG:15)
Block(5,11,10,LEAVES:3)
Block(5,11,11,LEAVES:3)
Block(5,11,12,LEAVES:3)
Block(5,11,14,LEAVES:3)
Block(5,11,15,LEAVES:3)
Block(5,11,16,LEAVES:3)
Block(5,11,17,LEAVES:3)
Block(5,11,18,LEAVES:3)
Block(5,12,-8,LEAVES:3)
Block(5,12,-7,LEAVES:3)
Block(5,12,-6,LEAVES:3)
Block(5,12,-5,LEAVES:3)
Block(5,12,-4,LEAVES:3)
Block(5,12,-3,LOG:15)
Block(5,12,-2,LEAVES:3)
Block(5,12,-1,LEAVES:3)
Block(5,12,1,LOG:15)
Block(5,12,8,LEAVES:3)
Block(5,12,9,LOG:15)
Block(5,12,10,LEAVES:3)
Block(5,12,11,LEAVES:3)
Block(5,12,12,LEAVES:3)
Block(5,12,13,LEAVES:3)
Block(5,12,14,LEAVES:3)
Block(5,12,15,LEAVES:3)
Block(5,12,16,LEAVES:3)
Block(5,12,17,LEAVES:3)
Block(5,12,18,LEAVES:3)
Block(5,13,-8,LEAVES:3)
Block(5,13,-7,LEAVES:3)
Block(5,13,-6,LEAVES:3)
Block(5,13,-5,LEAVES:3)
Block(5,13,-4,LEAVES:3)
Block(5,13,-3,LOG:15)
Block(5,13,-2,LOG:15)
Block(5,13,-1,LEAVES:3)
Block(5,13,8,LEAVES:3)
Block(5,13,9,LOG:15)
Block(5,13,10,LEAVES:3)
Block(5,13,11,LEAVES:3)
Block(5,13,12,LEAVES:3)
Block(5,13,13,LEAVES:3)
Block(5,13,14,LEAVES:3)
Block(5,13,15,LEAVES:3)
Block(5,13,16,LOG:15)
Block(5,13,17,LEAVES:3)
Block(5,14,-6,LEAVES:3)
Block(5,14,-4,LEAVES:3)
Block(5,14,-3,LEAVES:3)
Block(5,14,-2,LEAVES:3)
Block(5,14,9,LEAVES:3)
Block(5,14,10,LEAVES:3)
Block(5,14,11,LOG:15)
Block(5,14,12,LEAVES:3)
Block(5,14,13,LEAVES:3)
Block(5,14,14,LEAVES:3)
Block(5,14,15,LEAVES:3)
Block(5,14,16,LOG:15)
Block(5,14,17,LEAVES:3)
Block(5,15,-4,LEAVES:3)
Block(5,15,11,LEAVES:3)
Block(5,15,14,LEAVES:3)
Block(5,15,15,LEAVES:3)
Block(5,15,16,LOG:15)
Block(5,15,17,LEAVES:3)
Block(5,16,14,LEAVES:3)
Block(5,16,15,LEAVES:3)
Block(5,16,16,LOG:15)
Block(5,16,17,LEAVES:3)
Block(5,17,14,LEAVES:3)
Block(5,17,16,LEAVES:3)
Block(6,4,17,LEAVES:3)
Block(6,5,17,LEAVES:3)
Block(6,6,-8,LEAVES:3)
Block(6,6,17,LEAVES:3)
Block(6,6,18,LEAVES:3)
Block(6,7,-8,LEAVES:3)
Block(6,7,16,LEAVES:3)
Block(6,7,17,LOG:15)
Block(6,7,18,LEAVES:3)
Block(6,7,20,LEAVES:3)
Block(6,8,-8,LEAVES:3)
Block(6,8,16,LEAVES:3)
Block(6,8,17,LOG:15)
Block(6,8,18,LEAVES:3)
Block(6,8,19,LEAVES:3)
Block(6,8,20,LEAVES:3)
Block(6,9,-9,LEAVES:3)
Block(6,9,-8,LEAVES:3)
Block(6,9,-7,LEAVES:3)
Block(6,9,-3,LEAVES:3)
Block(6,9,6,LOG:15)
Block(6,9,7,LOG:15)
Block(6,9,16,LEAVES:3)
Block(6,9,17,LOG:15)
Block(6,9,18,LOG:15)
Block(6,9,19,LEAVES:3)
Block(6,9,20,LEAVES:3)
Block(6,10,-9,LEAVES:3)
Block(6,10,-8,LOG:15)
Block(6,10,-7,LEAVES:3)
Block(6,10,-6,LEAVES:3)
Block(6,10,-5,LEAVES:3)
Block(6,10,-3,LEAVES:3)
Block(6,10,-1,LEAVES:3)
Block(6,10,7,LOG:15)
Block(6,10,9,LEAVES:3)
Block(6,10,13,LEAVES:3)
Block(6,10,14,LEAVES:3)
Block(6,10,15,LEAVES:3)
Block(6,10,16,LEAVES:3)
Block(6,10,17,LOG:15)
Block(6,10,18,LEAVES:3)
Block(6,11,-9,LEAVES:3)
Block(6,11,-8,LOG:15)
Block(6,11,-7,LEAVES:3)
Block(6,11,-6,LEAVES:3)
Block(6,11,-5,LEAVES:3)
Block(6,11,-3,LEAVES:3)
Block(6,11,-1,LEAVES:3)
Block(6,11,0,LEAVES:3)
Block(6,11,9,LEAVES:3)
Block(6,11,10,LEAVES:3)
Block(6,11,12,LEAVES:3)
Block(6,11,13,LEAVES:3)
Block(6,11,14,LEAVES:3)
Block(6,11,15,LEAVES:3)
Block(6,11,16,LEAVES:3)
Block(6,11,17,LEAVES:3)
Block(6,12,-9,LEAVES:3)
Block(6,12,-8,LOG:15)
Block(6,12,-7,LEAVES:3)
Block(6,12,-6,LEAVES:3)
Block(6,12,-5,LEAVES:3)
Block(6,12,-4,LEAVES:3)
Block(6,12,-3,LEAVES:3)
Block(6,12,-1,LEAVES:3)
Block(6,12,0,LOG:15)
Block(6,12,8,LEAVES:3)
Block(6,12,9,LEAVES:3)
Block(6,12,10,LEAVES:3)
Block(6,12,11,LEAVES:3)
Block(6,12,12,LEAVES:3)
Block(6,12,13,LEAVES:3)
Block(6,12,14,LEAVES:3)
Block(6,12,15,LEAVES:3)
Block(6,12,16,LEAVES:3)
Block(6,13,-9,LEAVES:3)
Block(6,13,-8,LOG:15)
Block(6,13,-7,LOG:15)
Block(6,13,-6,LEAVES:3)
Block(6,13,-5,LEAVES:3)
Block(6,13,-4,LEAVES:3)
Block(6,13,-3,LEAVES:3)
Block(6,13,-2,LEAVES:3)
Block(6,13,-1,LEAVES:3)
Block(6,13,0,LOG:15)
Block(6,13,8,LEAVES:3)
Block(6,13,9,LEAVES:3)
Block(6,13,10,LEAVES:3)
Block(6,13,11,LEAVES:3)
Block(6,13,12,LEAVES:3)
Block(6,13,13,LEAVES:3)
Block(6,13,14,LEAVES:3)
Block(6,13,15,LEAVES:3)
Block(6,13,16,LEAVES:3)
Block(6,14,-8,LEAVES:3)
Block(6,14,-7,LEAVES:3)
Block(6,14,-6,LOG:15)
Block(6,14,-5,LEAVES:3)
Block(6,14,-4,LEAVES:3)
Block(6,14,-3,LEAVES:3)
Block(6,14,-2,LOG:15)
Block(6,14,-1,LEAVES:3)
Block(6,14,0,LEAVES:3)
Block(6,14,9,LEAVES:3)
Block(6,14,10,LOG:15)
Block(6,14,11,LEAVES:3)
Block(6,14,12,LEAVES:3)
Block(6,14,13,LEAVES:3)
Block(6,14,14,LEAVES:3)
Block(6,14,15,LEAVES:3)
Block(6,14,16,LEAVES:3)
Block(6,15,-6,LEAVES:3)
Block(6,15,-5,LEAVES:3)
Block(6,15,-4,LEAVES:3)
Block(6,15,-3,LEAVES:3)
Block(6,15,-2,LEAVES:3)
Block(6,15,10,LEAVES:3)
Block(6,15,11,LEAVES:3)
Block(6,15,12,LEAVES:3)
Block(6,15,13,LEAVES:3)
Block(6,15,14,LEAVES:3)
Block(6,15,15,LEAVES:3)
Block(6,15,16,LEAVES:3)
Block(6,16,-5,LEAVES:3)
Block(6,16,-4,LEAVES:3)
Block(6,16,-3,LEAVES:3)
Block(6,16,12,LEAVES:3)
Block(6,16,13,LEAVES:3)
Block(6,16,14,LEAVES:3)
Block(6,16,15,LOG:15)
Block(6,16,16,LEAVES:3)
Block(6,17,13,LEAVES:3)
Block(6,17,14,LOG:15)
Block(6,17,15,LEAVES:3)
Block(6,18,14,LEAVES:3)
Block(7,7,17,LEAVES:3)
Block(7,8,-8,LEAVES:3)
Block(7,8,10,LEAVES:3)
Block(7,8,17,LEAVES:3)
Block(7,8,18,LEAVES:3)
Block(7,9,-8,LEAVES:3)
Block(7,9,-6,LEAVES:3)
Block(7,9,-1,LEAVES:3)
Block(7,9,10,LEAVES:3)
Block(7,9,14,LEAVES:3)
Block(7,9,16,LEAVES:3)
Block(7,9,17,LEAVES:3)
Block(7,9,18,LEAVES:3)
Block(7,10,-8,LEAVES:3)
Block(7,10,-7,LEAVES:3)
Block(7,10,-6,LEAVES:3)
Block(7,10,-1,LEAVES:3)
Block(7,10,4,LEAVES:3)
Block(7,10,7,LOG:15)
Block(7,10,10,LEAVES:3)
Block(7,10,11,LEAVES:3)
Block(7,10,14,LEAVES:3)
Block(7,10,15,LEAVES:3)
Block(7,10,16,LEAVES:3)
Block(7,10,17,LEAVES:3)
Block(7,11,-8,LEAVES:3)
Block(7,11,-7,LEAVES:3)
Block(7,11,-6,LEAVES:3)
Block(7,11,-2,LEAVES:3)
Block(7,11,-1,LEAVES:3)
Block(7,11,4,LEAVES:3)
Block(7,11,7,LOG:15)
Block(7,11,8,LOG:15)
Block(7,11,9,LEAVES:3)
Block(7,11,10,LOG:15)
Block(7,11,11,LEAVES:3)
Block(7,11,14,LEAVES:3)
Block(7,11,15,LOG:15)
Block(7,11,16,LOG:15)
Block(7,11,17,LEAVES:3)
Block(7,12,-8,LEAVES:3)
Block(7,12,-7,LEAVES:3)
Block(7,12,-6,LEAVES:3)
Block(7,12,-5,LEAVES:3)
Block(7,12,-2,LEAVES:3)
Block(7,12,-1,LOG:15)
Block(7,12,4,LEAVES:3)
Block(7,12,8,LEAVES:3)
Block(7,12,9,LEAVES:3)
Block(7,12,10,LOG:15)
Block(7,12,11,LEAVES:3)
Block(7,12,12,LEAVES:3)
Block(7,12,13,LEAVES:3)
Block(7,12,14,LEAVES:3)
Block(7,12,15,LEAVES:3)
Block(7,12,16,LEAVES:3)
Block(7,13,-8,LEAVES:3)
Block(7,13,-7,LEAVES:3)
Block(7,13,-6,LEAVES:3)
Block(7,13,-5,LEAVES:3)
Block(7,13,-3,LEAVES:3)
Block(7,13,-2,LEAVES:3)
Block(7,13,-1,LOG:15)
Block(7,13,4,LEAVES:3)
Block(7,13,6,LEAVES:3)
Block(7,13,8,LEAVES:3)
Block(7,13,9,LEAVES:3)
Block(7,13,10,LOG:15)
Block(7,13,11,LEAVES:3)
Block(7,13,12,LEAVES:3)
Block(7,13,13,LEAVES:3)
Block(7,13,14,LEAVES:3)
Block(7,13,15,LEAVES:3)
Block(7,13,16,LEAVES:3)
Block(7,14,-7,LEAVES:3)
Block(7,14,-6,LEAVES:3)
Block(7,14,-5,LOG:15)
Block(7,14,-4,LEAVES:3)
Block(7,14,-3,LEAVES:3)
Block(7,14,-2,LEAVES:3)
Block(7,14,-1,LOG:15)
Block(7,14,0,LEAVES:3)
Block(7,14,4,LEAVES:3)
Block(7,14,8,LEAVES:3)
Block(7,14,9,LEAVES:3)
Block(7,14,10,LEAVES:3)
Block(7,14,11,LEAVES:3)
Block(7,14,12,LEAVES:3)
Block(7,14,13,LEAVES:3)
Block(7,14,14,LEAVES:3)
Block(7,14,15,LEAVES:3)
Block(7,14,16,LEAVES:3)
Block(7,15,-5,LEAVES:3)
Block(7,15,-4,LEAVES:3)
Block(7,15,-3,LEAVES:3)
Block(7,15,-2,LEAVES:3)
Block(7,15,-1,LEAVES:3)
Block(7,15,0,LEAVES:3)
Block(7,15,9,LEAVES:3)
Block(7,15,10,LEAVES:3)
Block(7,15,11,LEAVES:3)
Block(7,15,12,LEAVES:3)
Block(7,15,13,LOG:15)
Block(7,15,14,LEAVES:3)
Block(7,15,15,LEAVES:3)
Block(7,15,16,LEAVES:3)
Block(7,16,-4,LEAVES:3)
Block(7,16,12,LEAVES:3)
Block(7,16,13,LOG:15)
Block(7,16,14,LEAVES:3)
Block(7,16,15,LEAVES:3)
Block(7,17,12,LEAVES:3)
Block(7,17,13,LOG:15)
Block(7,17,14,LEAVES:3)
Block(7,18,13,LEAVES:3)
Block(8,4,16,LEAVES:3)
Block(8,5,15,LEAVES:3)
Block(8,5,16,LEAVES:3)
Block(8,6,15,LEAVES:3)
Block(8,6,16,LEAVES:3)
Block(8,6,17,LEAVES:3)
Block(8,7,14,LEAVES:3)
Block(8,7,15,LEAVES:3)
Block(8,7,16,LEAVES:3)
Block(8,7,17,LEAVES:3)
Block(8,8,-6,LEAVES:3)
Block(8,8,13,LEAVES:3)
Block(8,8,14,LEAVES:3)
Block(8,8,15,LEAVES:3)
Block(8,8,16,LOG:15)
Block(8,8,17,LEAVES:3)
Block(8,9,-6,LEAVES:3)
Block(8,9,3,LEAVES:3)
Block(8,9,13,LEAVES:3)
Block(8,9,14,LOG:15)
Block(8,9,15,LEAVES:3)
Block(8,9,16,LOG:15)
Block(8,9,17,LEAVES:3)
Block(8,10,-7,LEAVES:3)
Block(8,10,-6,LEAVES:3)
Block(8,10,3,LEAVES:3)
Block(8,10,4,LEAVES:3)
Block(8,10,13,LEAVES:3)
Block(8,10,14,LOG:15)
Block(8,10,15,LEAVES:3)
Block(8,10,16,LOG:15)
Block(8,10,17,LEAVES:3)
Block(8,11,-7,LEAVES:3)
Block(8,11,-6,LOG:15)
Block(8,11,-5,LEAVES:3)
Block(8,11,1,LEAVES:3)
Block(8,11,3,LEAVES:3)
Block(8,11,4,LEAVES:3)
Block(8,11,5,LEAVES:3)
Block(8,11,7,LEAVES:3)
Block(8,11,8,LOG:15)
Block(8,11,9,LOG:15)
Block(8,11,10,LEAVES:3)
Block(8,11,12,LEAVES:3)
Block(8,11,13,LEAVES:3)
Block(8,11,14,LOG:15)
Block(8,11,16,LEAVES:3)
Block(8,12,-7,LEAVES:3)
Block(8,12,-6,LOG:15)
Block(8,12,-5,LEAVES:3)
Block(8,12,-3,LEAVES:3)
Block(8,12,-2,LEAVES:3)
Block(8,12,-1,LEAVES:3)
Block(8,12,1,LEAVES:3)
Block(8,12,3,LEAVES:3)
Block(8,12,4,LOG:15)
Block(8,12,5,LEAVES:3)
Block(8,12,6,LEAVES:3)
Block(8,12,7,LEAVES:3)
Block(8,12,8,LEAVES:3)
Block(8,12,9,LOG:15)
Block(8,12,10,LEAVES:3)
Block(8,12,11,LEAVES:3)
Block(8,12,12,LEAVES:3)
Block(8,12,13,LOG:15)
Block(8,12,14,LOG:15)
Block(8,12,15,LEAVES:3)
Block(8,12,16,LEAVES:3)
Block(8,13,-7,LEAVES:3)
Block(8,13,-6,LOG:15)
Block(8,13,-5,LEAVES:3)
Block(8,13,-4,LEAVES:3)
Block(8,13,-3,LEAVES:3)
Block(8,13,-2,LEAVES:3)
Block(8,13,-1,LEAVES:3)
Block(8,13,0,LEAVES:3)
Block(8,13,1,LEAVES:3)
Block(8,13,3,LEAVES:3)
Block(8,13,4,LOG:15)
Block(8,13,5,LEAVES:3)
Block(8,13,6,LEAVES:3)
Block(8,13,7,LEAVES:3)
Block(8,13,8,LEAVES:3)
Block(8,13,9,LEAVES:3)
Block(8,13,10,LOG:15)
Block(8,13,11,LEAVES:3)
Block(8,13,12,LOG:15)
Block(8,13,13,LEAVES:3)
Block(8,13,14,LEAVES:3)
Block(8,13,15,LEAVES:3)
Block(8,14,-7,LEAVES:3)
Block(8,14,-6,LOG:15)
Block(8,14,-5,LEAVES:3)
Block(8,14,-4,LEAVES:3)
Block(8,14,-3,LEAVES:3)
Block(8,14,-2,LEAVES:3)
Block(8,14,-1,LEAVES:3)
Block(8,14,0,LEAVES:3)
Block(8,14,1,LEAVES:3)
Block(8,14,3,LEAVES:3)
Block(8,14,4,LOG:15)
Block(8,14,5,LEAVES:3)
Block(8,14,6,LEAVES:3)
Block(8,14,7,LEAVES:3)
Block(8,14,8,LEAVES:3)
Block(8,14,9,LEAVES:3)
Block(8,14,10,LOG:15)
Block(8,14,11,LEAVES:3)
Block(8,14,12,LEAVES:3)
Block(8,14,13,LEAVES:3)
Block(8,14,14,LEAVES:3)
Block(8,15,-6,LEAVES:3)
Block(8,15,-5,LEAVES:3)
Block(8,15,-4,LOG:15)
Block(8,15,-3,LEAVES:3)
Block(8,15,-2,LOG:15)
Block(8,15,-1,LEAVES:3)
Block(8,15,0,LOG:15)
Block(8,15,1,LEAVES:3)
Block(8,15,4,LEAVES:3)
Block(8,15,5,LEAVES:3)
Block(8,15,6,LEAVES:3)
Block(8,15,8,LEAVES:3)
Block(8,15,9,LEAVES:3)
Block(8,15,10,LOG:15)
Block(8,15,11,LEAVES:3)
Block(8,15,12,LEAVES:3)
Block(8,15,13,LEAVES:3)
Block(8,15,14,LEAVES:3)
Block(8,16,-4,LEAVES:3)
Block(8,16,-2,LEAVES:3)
Block(8,16,0,LEAVES:3)
Block(8,16,8,LEAVES:3)
Block(8,16,10,LEAVES:3)
Block(8,16,11,LEAVES:3)
Block(8,16,12,LOG:15)
Block(8,16,13,LEAVES:3)
Block(8,16,14,LEAVES:3)
Block(8,17,12,LEAVES:3)
Block(8,17,13,LEAVES:3)
Block(9,7,-7,LEAVES:3)
Block(9,7,16,LEAVES:3)
Block(9,8,-8,LEAVES:3)
Block(9,8,-7,LEAVES:3)
Block(9,8,15,LEAVES:3)
Block(9,8,16,LEAVES:3)
Block(9,8,17,LEAVES:3)
Block(9,9,-8,LEAVES:3)
Block(9,9,-7,LEAVES:3)
Block(9,9,1,LEAVES:3)
Block(9,9,14,LEAVES:3)
Block(9,9,15,LEAVES:3)
Block(9,9,16,LEAVES:3)
Block(9,9,17,LEAVES:3)
Block(9,9,18,LEAVES:3)
Block(9,10,-8,LEAVES:3)
Block(9,10,-7,LEAVES:3)
Block(9,10,-6,LEAVES:3)
Block(9,10,-3,LEAVES:3)
Block(9,10,-1,LEAVES:3)
Block(9,10,1,LEAVES:3)
Block(9,10,14,LEAVES:3)
Block(9,10,15,LEAVES:3)
Block(9,10,16,LEAVES:3)
Block(9,10,17,LOG:15)
Block(9,10,18,LEAVES:3)
Block(9,11,-8,LEAVES:3)
Block(9,11,-7,LEAVES:3)
Block(9,11,-6,LEAVES:3)
Block(9,11,-5,LEAVES:3)
Block(9,11,-4,LEAVES:3)
Block(9,11,-3,LEAVES:3)
Block(9,11,-2,LEAVES:3)
Block(9,11,-1,LEAVES:3)
Block(9,11,1,LEAVES:3)
Block(9,11,3,LEAVES:3)
Block(9,11,4,LEAVES:3)
Block(9,11,8,LEAVES:3)
Block(9,11,13,LEAVES:3)
Block(9,11,14,LEAVES:3)
Block(9,11,15,LEAVES:3)
Block(9,11,17,LEAVES:3)
Block(9,12,-8,LEAVES:3)
Block(9,12,-7,LEAVES:3)
Block(9,12,-6,LEAVES:3)
Block(9,12,-5,LEAVES:3)
Block(9,12,-4,LEAVES:3)
Block(9,12,-3,LEAVES:3)
Block(9,12,-2,LEAVES:3)
Block(9,12,-1,LEAVES:3)
Block(9,12,0,LEAVES:3)
Block(9,12,1,LEAVES:3)
Block(9,12,2,LEAVES:3)
Block(9,12,3,LEAVES:3)
Block(9,12,4,LEAVES:3)
Block(9,12,5,LEAVES:3)
Block(9,12,6,LEAVES:3)
Block(9,12,7,LEAVES:3)
Block(9,12,8,LEAVES:3)
Block(9,12,9,LEAVES:3)
Block(9,12,10,LOG:15)
Block(9,12,11,LEAVES:3)
Block(9,12,12,LEAVES:3)
Block(9,12,13,LEAVES:3)
Block(9,12,14,LEAVES:3)
Block(9,12,15,LOG:15)
Block(9,12,16,LEAVES:3)
Block(9,13,-8,LEAVES:3)
Block(9,13,-7,LOG:15)
Block(9,13,-6,LEAVES:3)
Block(9,13,-5,LEAVES:3)
Block(9,13,-4,LEAVES:3)
Block(9,13,-3,LOG:15)
Block(9,13,-2,LEAVES:3)
Block(9,13,-1,LEAVES:3)
Block(9,13,0,LEAVES:3)
Block(9,13,1,LOG:15)
Block(9,13,2,LEAVES:3)
Block(9,13,3,LEAVES:3)
Block(9,13,4,LEAVES:3)
Block(9,13,5,LEAVES:3)
Block(9,13,6,LEAVES:3)
Block(9,13,7,LEAVES:3)
Block(9,13,8,LEAVES:3)
Block(9,13,9,LEAVES:3)
Block(9,13,10,LEAVES:3)
Block(9,13,11,LOG:15)
Block(9,13,12,LEAVES:3)
Block(9,13,13,LEAVES:3)
Block(9,13,15,LEAVES:3)
Block(9,14,-8,LEAVES:3)
Block(9,14,-7,LEAVES:3)
Block(9,14,-6,LEAVES:3)
Block(9,14,-5,LEAVES:3)
Block(9,14,-4,LEAVES:3)
Block(9,14,-3,LOG:15)
Block(9,14,-2,LEAVES:3)
Block(9,14,-1,LEAVES:3)
Block(9,14,0,LEAVES:3)
Block(9,14,1,LOG:15)
Block(9,14,2,LEAVES:3)
Block(9,14,3,LEAVES:3)
Block(9,14,4,LEAVES:3)
Block(9,14,5,LEAVES:3)
Block(9,14,6,LEAVES:3)
Block(9,14,7,LEAVES:3)
Block(9,14,8,LEAVES:3)
Block(9,14,9,LEAVES:3)
Block(9,14,10,LEAVES:3)
Block(9,14,11,LOG:15)
Block(9,14,13,LEAVES:3)
Block(9,14,14,LEAVES:3)
Block(9,14,15,LEAVES:3)
Block(9,15,-4,LEAVES:3)
Block(9,15,-3,LOG:15)
Block(9,15,-2,LEAVES:3)
Block(9,15,-1,LEAVES:3)
Block(9,15,0,LOG:15)
Block(9,15,1,LOG:15)
Block(9,15,2,LEAVES:3)
Block(9,15,4,LEAVES:3)
Block(9,15,5,LOG:15)
Block(9,15,6,LOG:15)
Block(9,15,7,LEAVES:3)
Block(9,15,8,LEAVES:3)
Block(9,15,9,LOG:15)
Block(9,15,10,LEAVES:3)
Block(9,15,11,LOG:15)
Block(9,15,12,LEAVES:3)
Block(9,15,13,LEAVES:3)
Block(9,15,14,LEAVES:3)
Block(9,15,15,LEAVES:3)
Block(9,16,-3,LEAVES:3)
Block(9,16,-2,LEAVES:3)
Block(9,16,-1,LEAVES:3)
Block(9,16,0,LEAVES:3)
Block(9,16,1,LEAVES:3)
Block(9,16,5,LEAVES:3)
Block(9,16,6,LEAVES:3)
Block(9,16,7,LEAVES:3)
Block(9,16,8,LEAVES:3)
Block(9,16,9,LEAVES:3)
Block(9,16,10,LEAVES:3)
Block(9,16,11,LEAVES:3)
Block(9,16,12,LEAVES:3)
Block(9,16,13,LEAVES:3)
Block(9,16,14,LEAVES:3)
Block(10,6,-8,LEAVES:3)
Block(10,7,-8,LEAVES:3)
Block(10,7,6,LEAVES:3)
Block(10,7,16,LEAVES:3)
Block(10,7,17,LEAVES:3)
Block(10,8,-8,LEAVES:3)
Block(10,8,-1,LEAVES:3)
Block(10,8,6,LEAVES:3)
Block(10,8,15,LEAVES:3)
Block(10,8,16,LEAVES:3)
Block(10,8,17,LEAVES:3)
Block(10,8,18,LEAVES:3)
Block(10,9,-8,LEAVES:3)
Block(10,9,-1,LEAVES:3)
Block(10,9,6,LEAVES:3)
Block(10,9,8,LEAVES:3)
Block(10,9,15,LEAVES:3)
Block(10,9,16,LEAVES:3)
Block(10,9,17,LEAVES:3)
Block(10,9,18,LEAVES:3)
Block(10,10,-9,LEAVES:3)
Block(10,10,-8,LOG:15)
Block(10,10,-7,LEAVES:3)
Block(10,10,-5,LEAVES:3)
Block(10,10,-4,LEAVES:3)
Block(10,10,-1,LEAVES:3)
Block(10,10,3,LEAVES:3)
Block(10,10,6,LEAVES:3)
Block(10,10,8,LEAVES:3)
Block(10,10,14,LEAVES:3)
Block(10,10,15,LEAVES:3)
Block(10,10,16,LEAVES:3)
Block(10,10,17,LEAVES:3)
Block(10,10,18,LEAVES:3)
Block(10,10,19,LEAVES:3)
Block(10,11,-9,LEAVES:3)
Block(10,11,-8,LOG:15)
Block(10,11,-7,LEAVES:3)
Block(10,11,-5,LEAVES:3)
Block(10,11,-4,LEAVES:3)
Block(10,11,-3,LEAVES:3)
Block(10,11,-2,LEAVES:3)
Block(10,11,-1,LEAVES:3)
Block(10,11,1,LEAVES:3)
Block(10,11,2,LEAVES:3)
Block(10,11,3,LEAVES:3)
Block(10,11,5,LEAVES:3)
Block(10,11,6,LEAVES:3)
Block(10,11,7,LEAVES:3)
Block(10,11,8,LEAVES:3)
Block(10,11,9,LEAVES:3)
Block(10,11,10,LEAVES:3)
Block(10,11,11,LEAVES:3)
Block(10,11,13,LEAVES:3)
Block(10,11,14,LEAVES:3)
Block(10,11,15,LEAVES:3)
Block(10,11,16,LEAVES:3)
Block(10,11,17,LEAVES:3)
Block(10,11,19,LEAVES:3)
Block(10,12,-9,LEAVES:3)
Block(10,12,-8,LOG:15)
Block(10,12,-7,LEAVES:3)
Block(10,12,-6,LEAVES:3)
Block(10,12,-5,LEAVES:3)
Block(10,12,-4,LEAVES:3)
Block(10,12,-3,LEAVES:3)
Block(10,12,-2,LEAVES:3)
Block(10,12,-1,LEAVES:3)
Block(10,12,0,LEAVES:3)
Block(10,12,1,LEAVES:3)
Block(10,12,2,LEAVES:3)
Block(10,12,3,LEAVES:3)
Block(10,12,4,LEAVES:3)
Block(10,12,5,LEAVES:3)
Block(10,12,6,LOG:15)
Block(10,12,7,LEAVES:3)
Block(10,12,8,LEAVES:3)
Block(10,12,9,LEAVES:3)
Block(10,12,10,LEAVES:3)
Block(10,12,11,LEAVES:3)
Block(10,12,12,LEAVES:3)
Block(10,12,13,LEAVES:3)
Block(10,12,14,LEAVES:3)
Block(10,12,15,LEAVES:3)
Block(10,12,16,LOG:15)
Block(10,12,17,LEAVES:3)
Block(10,13,-9,LEAVES:3)
Block(10,13,-8,LOG:15)
Block(10,13,-7,LEAVES:3)
Block(10,13,-6,LEAVES:3)
Block(10,13,-5,LEAVES:3)
Block(10,13,-4,LEAVES:3)
Block(10,13,-3,LEAVES:3)
Block(10,13,-2,LEAVES:3)
Block(10,13,-1,LEAVES:3)
Block(10,13,0,LEAVES:3)
Block(10,13,1,LEAVES:3)
Block(10,13,2,LEAVES:3)
Block(10,13,3,LEAVES:3)
Block(10,13,4,LEAVES:3)
Block(10,13,5,LEAVES:3)
Block(10,13,6,LOG:15)
Block(10,13,7,LEAVES:3)
Block(10,13,8,LEAVES:3)
Block(10,13,9,LEAVES:3)
Block(10,13,10,LEAVES:3)
Block(10,13,11,LOG:15)
Block(10,13,12,LEAVES:3)
Block(10,13,13,LEAVES:3)
Block(10,13,14,LEAVES:3)
Block(10,13,15,LEAVES:3)
Block(10,13,16,LEAVES:3)
Block(10,14,-8,LEAVES:3)
Block(10,14,-7,LEAVES:3)
Block(10,14,-6,LEAVES:3)
Block(10,14,-5,LEAVES:3)
Block(10,14,-4,LEAVES:3)
Block(10,14,-3,LEAVES:3)
Block(10,14,-2,LEAVES:3)
Block(10,14,-1,LEAVES:3)
Block(10,14,0,LOG:15)
Block(10,14,1,LEAVES:3)
Block(10,14,2,LEAVES:3)
Block(10,14,3,LEAVES:3)
Block(10,14,5,LEAVES:3)
Block(10,14,6,LOG:15)
Block(10,14,7,LEAVES:3)
Block(10,14,8,LEAVES:3)
Block(10,14,9,LEAVES:3)
Block(10,14,10,LEAVES:3)
Block(10,14,11,LEAVES:3)
Block(10,14,13,LEAVES:3)
Block(10,14,14,LOG:15)
Block(10,14,15,LEAVES:3)
Block(10,14,16,LEAVES:3)
Block(10,15,-5,LEAVES:3)
Block(10,15,-4,LOG:15)
Block(10,15,-3,LEAVES:3)
Block(10,15,-2,LEAVES:3)
Block(10,15,-1,LEAVES:3)
Block(10,15,0,LEAVES:3)
Block(10,15,1,LEAVES:3)
Block(10,15,5,LEAVES:3)
Block(10,15,6,LOG:15)
Block(10,15,7,LEAVES:3)
Block(10,15,8,LEAVES:3)
Block(10,15,9,LEAVES:3)
Block(10,15,10,LEAVES:3)
Block(10,15,11,LEAVES:3)
Block(10,15,12,LEAVES:3)
Block(10,15,13,LEAVES:3)
Block(10,15,14,LOG:15)
Block(10,15,16,LEAVES:3)
Block(10,16,-4,LEAVES:3)
Block(10,16,-1,LEAVES:3)
Block(10,16,0,LEAVES:3)
Block(10,16,6,LEAVES:3)
Block(10,16,7,LOG:15)
Block(10,16,8,LOG:15)
Block(10,16,9,LEAVES:3)
Block(10,16,11,LEAVES:3)
Block(10,16,12,LOG:15)
Block(10,16,13,LOG:15)
Block(10,16,14,LOG:15)
Block(10,16,15,LEAVES:3)
Block(10,17,7,LEAVES:3)
Block(10,17,8,LEAVES:3)
Block(10,17,12,LEAVES:3)
Block(10,17,13,LEAVES:3)
Block(10,17,14,LEAVES:3)
Block(11,5,17,LEAVES:3)
Block(11,6,8,LEAVES:3)
Block(11,6,17,LEAVES:3)
Block(11,6,20,LEAVES:3)
Block(11,7,-1,LEAVES:3)
Block(11,7,8,LEAVES:3)
Block(11,7,17,LEAVES:3)
Block(11,7,18,LEAVES:3)
Block(11,7,20,LEAVES:3)
Block(11,8,-4,LEAVES:3)
Block(11,8,-1,LEAVES:3)
Block(11,8,1,LEAVES:3)
Block(11,8,8,LEAVES:3)
Block(11,8,16,LEAVES:3)
Block(11,8,17,LEAVES:3)
Block(11,8,18,LEAVES:3)
Block(11,8,19,LEAVES:3)
Block(11,8,20,LEAVES:3)
Block(11,9,-8,LEAVES:3)
Block(11,9,-4,LEAVES:3)
Block(11,9,-1,LEAVES:3)
Block(11,9,1,LEAVES:3)
Block(11,9,4,LEAVES:3)
Block(11,9,7,LEAVES:3)
Block(11,9,8,LEAVES:3)
Block(11,9,14,LEAVES:3)
Block(11,9,15,LEAVES:3)
Block(11,9,16,LEAVES:3)
Block(11,9,17,LOG:15)
Block(11,9,18,LEAVES:3)
Block(11,9,19,LEAVES:3)
Block(11,9,20,LEAVES:3)
Block(11,10,-8,LEAVES:3)
Block(11,10,-4,LEAVES:3)
Block(11,10,-2,LEAVES:3)
Block(11,10,-1,LOG:15)
Block(11,10,0,LEAVES:3)
Block(11,10,1,LEAVES:3)
Block(11,10,2,LEAVES:3)
Block(11,10,3,LEAVES:3)
Block(11,10,4,LEAVES:3)
Block(11,10,5,LEAVES:3)
Block(11,10,7,LEAVES:3)
Block(11,10,8,LOG:15)
Block(11,10,9,LEAVES:3)
Block(11,10,12,LEAVES:3)
Block(11,10,13,LEAVES:3)
Block(11,10,14,LEAVES:3)
Block(11,10,15,LEAVES:3)
Block(11,10,16,LEAVES:3)
Block(11,10,17,LOG:15)
Block(11,10,18,LEAVES:3)
Block(11,10,19,LEAVES:3)
Block(11,10,20,LEAVES:3)
Block(11,11,-8,LEAVES:3)
Block(11,11,-6,LEAVES:3)
Block(11,11,-5,LEAVES:3)
Block(11,11,-4,LEAVES:3)
Block(11,11,-3,LEAVES:3)
Block(11,11,-2,LEAVES:3)
Block(11,11,-1,LOG:15)
Block(11,11,0,LEAVES:3)
Block(11,11,1,LEAVES:3)
Block(11,11,2,LEAVES:3)
Block(11,11,3,LEAVES:3)
Block(11,11,4,LEAVES:3)
Block(11,11,5,LEAVES:3)
Block(11,11,6,LEAVES:3)
Block(11,11,7,LEAVES:3)
Block(11,11,8,LOG:15)
Block(11,11,9,LEAVES:3)
Block(11,11,10,LEAVES:3)
Block(11,11,11,LEAVES:3)
Block(11,11,12,LEAVES:3)
Block(11,11,13,LEAVES:3)
Block(11,11,14,LEAVES:3)
Block(11,11,15,LEAVES:3)
Block(11,11,16,LEAVES:3)
Block(11,11,17,LOG:15)
Block(11,11,18,LEAVES:3)
Block(11,11,19,LEAVES:3)
Block(11,11,20,LEAVES:3)
Block(11,12,-8,LEAVES:3)
Block(11,12,-7,LEAVES:3)
Block(11,12,-6,LEAVES:3)
Block(11,12,-5,LEAVES:3)
Block(11,12,-4,LOG:15)
Block(11,12,-3,LEAVES:3)
Block(11,12,-2,LEAVES:3)
Block(11,12,-1,LOG:15)
Block(11,12,0,LEAVES:3)
Block(11,12,1,LOG:15)
Block(11,12,2,LEAVES:3)
Block(11,12,3,LEAVES:3)
Block(11,12,4,LEAVES:3)
Block(11,12,5,LEAVES:3)
Block(11,12,6,LEAVES:3)
Block(11,12,7,LEAVES:3)
Block(11,12,8,LOG:15)
Block(11,12,9,LOG:15)
Block(11,12,10,LEAVES:3)
Block(11,12,11,LEAVES:3)
Block(11,12,12,LEAVES:3)
Block(11,12,13,LEAVES:3)
Block(11,12,14,LEAVES:3)
Block(11,12,15,LEAVES:3)
Block(11,12,16,LEAVES:3)
Block(11,12,17,LEAVES:3)
Block(11,13,-8,LEAVES:3)
Block(11,13,-7,LEAVES:3)
Block(11,13,-6,LEAVES:3)
Block(11,13,-5,LEAVES:3)
Block(11,13,-4,LOG:15)
Block(11,13,-3,LEAVES:3)
Block(11,13,-2,LEAVES:3)
Block(11,13,-1,LOG:15)
Block(11,13,0,LEAVES:3)
Block(11,13,1,LOG:15)
Block(11,13,2,LEAVES:3)
Block(11,13,3,LEAVES:3)
Block(11,13,4,LEAVES:3)
Block(11,13,5,LEAVES:3)
Block(11,13,6,LEAVES:3)
Block(11,13,7,LEAVES:3)
Block(11,13,8,LEAVES:3)
Block(11,13,9,LEAVES:3)
Block(11,13,10,LOG:15)
Block(11,13,11,LEAVES:3)
Block(11,13,12,LOG:15)
Block(11,13,13,LEAVES:3)
Block(11,13,14,LEAVES:3)
Block(11,13,15,LEAVES:3)
Block(11,13,16,LEAVES:3)
Block(11,14,-6,LEAVES:3)
Block(11,14,-5,LEAVES:3)
Block(11,14,-4,LOG:15)
Block(11,14,-3,LEAVES:3)
Block(11,14,-2,LEAVES:3)
Block(11,14,-1,LEAVES:3)
Block(11,14,0,LEAVES:3)
Block(11,14,1,LOG:15)
Block(11,14,2,LEAVES:3)
Block(11,14,5,LEAVES:3)
Block(11,14,6,LEAVES:3)
Block(11,14,7,LEAVES:3)
Block(11,14,8,LEAVES:3)
Block(11,14,9,LEAVES:3)
Block(11,14,10,LEAVES:3)
Block(11,14,11,LEAVES:3)
Block(11,14,12,LEAVES:3)
Block(11,14,14,LEAVES:3)
Block(11,14,15,LEAVES:3)
Block(11,15,-4,LEAVES:3)
Block(11,15,-2,LEAVES:3)
Block(11,15,-1,LEAVES:3)
Block(11,15,0,LEAVES:3)
Block(11,15,1,LEAVES:3)
Block(11,15,6,LEAVES:3)
Block(11,15,7,LEAVES:3)
Block(11,15,8,LEAVES:3)
Block(11,15,9,LEAVES:3)
Block(11,15,10,LEAVES:3)
Block(11,15,11,LEAVES:3)
Block(11,15,12,LEAVES:3)
Block(11,15,14,LEAVES:3)
Block(11,15,15,LEAVES:3)
Block(11,16,0,LEAVES:3)
Block(11,16,1,LEAVES:3)
Block(11,16,7,LEAVES:3)
Block(11,16,8,LEAVES:3)
Block(11,16,12,LEAVES:3)
Block(11,16,13,LEAVES:3)
Block(11,16,14,LOG:15)
Block(11,16,15,LEAVES:3)
Block(11,17,14,LEAVES:3)
Block(12,3,20,LEAVES:3)
Block(12,4,20,LEAVES:3)
Block(12,5,20,LEAVES:3)
Block(12,5,21,LEAVES:3)
Block(12,6,0,LEAVES:3)
Block(12,6,18,LEAVES:3)
Block(12,6,20,LEAVES:3)
Block(12,6,21,LEAVES:3)
Block(12,7,0,LEAVES:3)
Block(12,7,2,LEAVES:3)
Block(12,7,16,LEAVES:3)
Block(12,7,17,LEAVES:3)
Block(12,7,18,LEAVES:3)
Block(12,7,19,LEAVES:3)
Block(12,7,20,LOG:15)
Block(12,7,21,LEAVES:3)
Block(12,8,-6,LEAVES:3)
Block(12,8,-1,LEAVES:3)
Block(12,8,0,LEAVES:3)
Block(12,8,2,LEAVES:3)
Block(12,8,11,LEAVES:3)
Block(12,8,15,LEAVES:3)
Block(12,8,17,LEAVES:3)
Block(12,8,18,LEAVES:3)
Block(12,8,19,LEAVES:3)
Block(12,8,20,LOG:15)
Block(12,8,21,LEAVES:3)
Block(12,9,-6,LEAVES:3)
Block(12,9,-5,LEAVES:3)
Block(12,9,-3,LEAVES:3)
Block(12,9,-1,LEAVES:3)
Block(12,9,0,LEAVES:3)
Block(12,9,1,LEAVES:3)
Block(12,9,2,LEAVES:3)
Block(12,9,3,LEAVES:3)
Block(12,9,4,LEAVES:3)
Block(12,9,5,LEAVES:3)
Block(12,9,6,LEAVES:3)
Block(12,9,7,LEAVES:3)
Block(12,9,8,LEAVES:3)
Block(12,9,11,LEAVES:3)
Block(12,9,12,LEAVES:3)
Block(12,9,13,LEAVES:3)
Block(12,9,14,LEAVES:3)
Block(12,9,15,LEAVES:3)
Block(12,9,16,LEAVES:3)
Block(12,9,17,LEAVES:3)
Block(12,9,18,LEAVES:3)
Block(12,9,19,LEAVES:3)
Block(12,9,20,LOG:15)
Block(12,9,21,LEAVES:3)
Block(12,10,-6,LEAVES:3)
Block(12,10,-5,LEAVES:3)
Block(12,10,-4,LEAVES:3)
Block(12,10,-3,LEAVES:3)
Block(12,10,-2,LEAVES:3)
Block(12,10,-1,LEAVES:3)
Block(12,10,0,LEAVES:3)
Block(12,10,1,LEAVES:3)
Block(12,10,2,LEAVES:3)
Block(12,10,3,LEAVES:3)
Block(12,10,4,LEAVES:3)
Block(12,10,5,LEAVES:3)
Block(12,10,6,LEAVES:3)
Block(12,10,7,LEAVES:3)
Block(12,10,8,LEAVES:3)
Block(12,10,10,LEAVES:3)
Block(12,10,11,LEAVES:3)
Block(12,10,12,LEAVES:3)
Block(12,10,13,LEAVES:3)
Block(12,10,14,LEAVES:3)
Block(12,10,15,LEAVES:3)
Block(12,10,16,LEAVES:3)
Block(12,10,17,LEAVES:3)
Block(12,10,18,LEAVES:3)
Block(12,10,19,LEAVES:3)
Block(12,10,20,LOG:15)
Block(12,10,21,LEAVES:3)
Block(12,11,-6,LEAVES:3)
Block(12,11,-5,LEAVES:3)
Block(12,11,-4,LEAVES:3)
Block(12,11,-3,LEAVES:3)
Block(12,11,-2,LEAVES:3)
Block(12,11,-1,LEAVES:3)
Block(12,11,0,LEAVES:3)
Block(12,11,1,LEAVES:3)
Block(12,11,2,LEAVES:3)
Block(12,11,3,LEAVES:3)
Block(12,11,4,LEAVES:3)
Block(12,11,5,LEAVES:3)
Block(12,11,6,LEAVES:3)
Block(12,11,7,LOG:15)
Block(12,11,8,LEAVES:3)
Block(12,11,9,LEAVES:3)
Block(12,11,10,LEAVES:3)
Block(12,11,11,LEAVES:3)
Block(12,11,12,LEAVES:3)
Block(12,11,13,LEAVES:3)
Block(12,11,14,LEAVES:3)
Block(12,11,15,LEAVES:3)
Block(12,11,16,LEAVES:3)
Block(12,11,17,LEAVES:3)
Block(12,11,18,LOG:15)
Block(12,11,19,LOG:15)
Block(12,11,20,LOG:15)
Block(12,11,21,LEAVES:3)
Block(12,12,-6,LEAVES:3)
Block(12,12,-5,LEAVES:3)
Block(12,12,-4,LEAVES:3)
Block(12,12,-3,LEAVES:3)
Block(12,12,-2,LEAVES:3)
Block(12,12,-1,LEAVES:3)
Block(12,12,0,LEAVES:3)
Block(12,12,1,LEAVES:3)
Block(12,12,2,LEAVES:3)
Block(12,12,3,LEAVES:3)
Block(12,12,4,LEAVES:3)
Block(12,12,5,LEAVES:3)
Block(12,12,6,LEAVES:3)
Block(12,12,7,LEAVES:3)
Block(12,12,8,LEAVES:3)
Block(12,12,9,LEAVES:3)
Block(12,12,10,LEAVES:3)
Block(12,12,11,LEAVES:3)
Block(12,12,13,LEAVES:3)
Block(12,12,14,LEAVES:3)
Block(12,12,15,LEAVES:3)
Block(12,12,16,LEAVES:3)
Block(12,12,17,LEAVES:3)
Block(12,12,18,LEAVES:3)
Block(12,12,19,LEAVES:3)
Block(12,12,20,LEAVES:3)
Block(12,13,-5,LEAVES:3)
Block(12,13,-4,LEAVES:3)
Block(12,13,-3,LEAVES:3)
Block(12,13,-2,LEAVES:3)
Block(12,13,-1,LOG:15)
Block(12,13,0,LEAVES:3)
Block(12,13,1,LEAVES:3)
Block(12,13,2,LOG:15)
Block(12,13,3,LEAVES:3)
Block(12,13,4,LEAVES:3)
Block(12,13,5,LEAVES:3)
Block(12,13,6,LEAVES:3)
Block(12,13,7,LEAVES:3)
Block(12,13,8,LEAVES:3)
Block(12,13,10,LEAVES:3)
Block(12,13,11,LEAVES:3)
Block(12,13,12,LEAVES:3)
Block(12,13,13,LOG:15)
Block(12,13,14,LEAVES:3)
Block(12,13,15,LEAVES:3)
Block(12,13,16,LEAVES:3)
Block(12,13,17,LEAVES:3)
Block(12,14,-5,LEAVES:3)
Block(12,14,-4,LOG:15)
Block(12,14,-3,LEAVES:3)
Block(12,14,-2,LEAVES:3)
Block(12,14,-1,LEAVES:3)
Block(12,14,0,LEAVES:3)
Block(12,14,1,LEAVES:3)
Block(12,14,2,LEAVES:3)
Block(12,14,7,LEAVES:3)
Block(12,14,11,LEAVES:3)
Block(12,14,12,LEAVES:3)
Block(12,14,13,LEAVES:3)
Block(12,14,14,LEAVES:3)
Block(12,14,15,LEAVES:3)
Block(12,14,16,LEAVES:3)
Block(12,15,-4,LEAVES:3)
Block(12,15,0,LEAVES:3)
Block(12,15,1,LEAVES:3)
Block(12,15,11,LEAVES:3)
Block(12,15,12,LEAVES:3)
Block(12,15,13,LEAVES:3)
Block(12,15,14,LEAVES:3)
Block(12,15,15,LOG:15)
Block(12,15,16,LEAVES:3)
Block(12,16,14,LEAVES:3)
Block(12,16,15,LEAVES:3)
Block(13,4,15,LEAVES:3)
Block(13,5,15,LEAVES:3)
Block(13,5,20,LEAVES:3)
Block(13,6,3,LEAVES:3)
Block(13,6,14,LEAVES:3)
Block(13,6,15,LEAVES:3)
Block(13,6,16,LEAVES:3)
Block(13,6,20,LEAVES:3)
Block(13,7,-5,LEAVES:3)
Block(13,7,-4,LEAVES:3)
Block(13,7,-2,LEAVES:3)
Block(13,7,3,LEAVES:3)
Block(13,7,6,LEAVES:3)
Block(13,7,8,LEAVES:3)
Block(13,7,12,LEAVES:3)
Block(13,7,14,LEAVES:3)
Block(13,7,15,LEAVES:3)
Block(13,7,16,LEAVES:3)
Block(13,7,18,LEAVES:3)
Block(13,7,20,LEAVES:3)
Block(13,8,-5,LEAVES:3)
Block(13,8,-4,LEAVES:3)
Block(13,8,-2,LEAVES:3)
Block(13,8,-1,LEAVES:3)
Block(13,8,0,LEAVES:3)
Block(13,8,3,LEAVES:3)
Block(13,8,5,LEAVES:3)
Block(13,8,6,LEAVES:3)
Block(13,8,8,LEAVES:3)
Block(13,8,10,LEAVES:3)
Block(13,8,11,LEAVES:3)
Block(13,8,12,LEAVES:3)
Block(13,8,13,LEAVES:3)
Block(13,8,14,LEAVES:3)
Block(13,8,15,LOG:15)
Block(13,8,16,LEAVES:3)
Block(13,8,18,LEAVES:3)
Block(13,8,19,LEAVES:3)
Block(13,8,20,LEAVES:3)
Block(13,9,-6,LEAVES:3)
Block(13,9,-5,LEAVES:3)
Block(13,9,-4,LEAVES:3)
Block(13,9,-3,LEAVES:3)
Block(13,9,-2,LEAVES:3)
Block(13,9,-1,LEAVES:3)
Block(13,9,0,LEAVES:3)
Block(13,9,2,LEAVES:3)
Block(13,9,3,LOG:15)
Block(13,9,4,LEAVES:3)
Block(13,9,5,LEAVES:3)
Block(13,9,6,LEAVES:3)
Block(13,9,7,LEAVES:3)
Block(13,9,8,LEAVES:3)
Block(13,9,10,LEAVES:3)
Block(13,9,11,LEAVES:3)
Block(13,9,12,LEAVES:3)
Block(13,9,13,LEAVES:3)
Block(13,9,14,LEAVES:3)
Block(13,9,15,LOG:15)
Block(13,9,16,LEAVES:3)
Block(13,9,17,LEAVES:3)
Block(13,9,18,LEAVES:3)
Block(13,9,19,LEAVES:3)
Block(13,9,20,LEAVES:3)
Block(13,10,-6,LEAVES:3)
Block(13,10,-5,LOG:15)
Block(13,10,-4,LEAVES:3)
Block(13,10,-3,LEAVES:3)
Block(13,10,-2,LEAVES:3)
Block(13,10,-1,LEAVES:3)
Block(13,10,0,LEAVES:3)
Block(13,10,1,LEAVES:3)
Block(13,10,2,LEAVES:3)
Block(13,10,3,LOG:15)
Block(13,10,4,LEAVES:3)
Block(13,10,5,LEAVES:3)
Block(13,10,6,LEAVES:3)
Block(13,10,7,LEAVES:3)
Block(13,10,8,LEAVES:3)
Block(13,10,9,LEAVES:3)
Block(13,10,10,LEAVES:3)
Block(13,10,11,LEAVES:3)
Block(13,10,12,LEAVES:3)
Block(13,10,13,LEAVES:3)
Block(13,10,14,LEAVES:3)
Block(13,10,15,LOG:15)
Block(13,10,16,LEAVES:3)
Block(13,10,17,LEAVES:3)
Block(13,10,18,LEAVES:3)
Block(13,10,19,LEAVES:3)
Block(13,10,20,LEAVES:3)
Block(13,11,-6,LEAVES:3)
Block(13,11,-5,LOG:15)
Block(13,11,-4,LEAVES:3)
Block(13,11,-3,LEAVES:3)
Block(13,11,-2,LEAVES:3)
Block(13,11,-1,LEAVES:3)
Block(13,11,0,LEAVES:3)
Block(13,11,1,LEAVES:3)
Block(13,11,2,LEAVES:3)
Block(13,11,3,LOG:15)
Block(13,11,4,LEAVES:3)
Block(13,11,5,LEAVES:3)
Block(13,11,6,LOG:15)
Block(13,11,7,LEAVES:3)
Block(13,11,8,LEAVES:3)
Block(13,11,9,LEAVES:3)
Block(13,11,10,LEAVES:3)
Block(13,11,11,LOG:15)
Block(13,11,12,LOG:15)
Block(13,11,13,LEAVES:3)
Block(13,11,14,LEAVES:3)
Block(13,11,15,LEAVES:3)
Block(13,11,16,LEAVES:3)
Block(13,11,17,LEAVES:3)
Block(13,11,18,LEAVES:3)
Block(13,11,19,LEAVES:3)
Block(13,11,20,LEAVES:3)
Block(13,12,-6,LEAVES:3)
Block(13,12,-5,LOG:15)
Block(13,12,-4,LEAVES:3)
Block(13,12,-3,LEAVES:3)
Block(13,12,-2,LEAVES:3)
Block(13,12,-1,LOG:15)
Block(13,12,0,LEAVES:3)
Block(13,12,1,LEAVES:3)
Block(13,12,2,LEAVES:3)
Block(13,12,3,LOG:15)
Block(13,12,4,LEAVES:3)
Block(13,12,5,LEAVES:3)
Block(13,12,6,LEAVES:3)
Block(13,12,7,LEAVES:3)
Block(13,12,8,LEAVES:3)
Block(13,12,11,LEAVES:3)
Block(13,12,12,LEAVES:3)
Block(13,12,13,LOG:15)
Block(13,12,14,LEAVES:3)
Block(13,12,15,LEAVES:3)
Block(13,12,16,LEAVES:3)
Block(13,12,17,LEAVES:3)
Block(13,13,-6,LEAVES:3)
Block(13,13,-5,LOG:15)
Block(13,13,-4,LEAVES:3)
Block(13,13,-2,LEAVES:3)
Block(13,13,-1,LOG:15)
Block(13,13,0,LEAVES:3)
Block(13,13,1,LEAVES:3)
Block(13,13,2,LEAVES:3)
Block(13,13,3,LOG:15)
Block(13,13,4,LEAVES:3)
Block(13,13,7,LEAVES:3)
Block(13,13,12,LEAVES:3)
Block(13,13,13,LEAVES:3)
Block(13,13,14,LEAVES:3)
Block(13,13,15,LOG:15)
Block(13,13,16,LEAVES:3)
Block(13,14,-5,LEAVES:3)
Block(13,14,-4,LEAVES:3)
Block(13,14,-1,LEAVES:3)
Block(13,14,1,LEAVES:3)
Block(13,14,2,LEAVES:3)
Block(13,14,3,LEAVES:3)
Block(13,14,12,LEAVES:3)
Block(13,14,13,LEAVES:3)
Block(13,14,14,LEAVES:3)
Block(13,14,15,LOG:15)
Block(13,14,16,LEAVES:3)
Block(13,15,14,LEAVES:3)
Block(13,15,15,LOG:15)
Block(13,15,16,LEAVES:3)
Block(13,16,15,LEAVES:3)
Block(14,5,5,LEAVES:3)
Block(14,5,10,LEAVES:3)
Block(14,6,-5,LEAVES:3)
Block(14,6,5,LEAVES:3)
Block(14,6,10,LEAVES:3)
Block(14,7,-5,LEAVES:3)
Block(14,7,4,LEAVES:3)
Block(14,7,5,LEAVES:3)
Block(14,7,9,LEAVES:3)
Block(14,7,10,LEAVES:3)
Block(14,7,11,LEAVES:3)
Block(14,7,15,LEAVES:3)
Block(14,7,17,LEAVES:3)
Block(14,7,19,LEAVES:3)
Block(14,8,-5,LEAVES:3)
Block(14,8,3,LEAVES:3)
Block(14,8,4,LEAVES:3)
Block(14,8,5,LOG:15)
Block(14,8,6,LEAVES:3)
Block(14,8,9,LEAVES:3)
Block(14,8,10,LEAVES:3)
Block(14,8,11,LEAVES:3)
Block(14,8,13,LEAVES:3)
Block(14,8,14,LEAVES:3)
Block(14,8,15,LEAVES:3)
Block(14,8,16,LEAVES:3)
Block(14,8,17,LEAVES:3)
Block(14,8,18,LEAVES:3)
Block(14,8,19,LEAVES:3)
Block(14,9,-5,LEAVES:3)
Block(14,9,-3,LEAVES:3)
Block(14,9,-1,LEAVES:3)
Block(14,9,1,LEAVES:3)
Block(14,9,3,LEAVES:3)
Block(14,9,4,LEAVES:3)
Block(14,9,5,LOG:15)
Block(14,9,6,LEAVES:3)
Block(14,9,7,LEAVES:3)
Block(14,9,8,LEAVES:3)
Block(14,9,9,LEAVES:3)
Block(14,9,10,LOG:15)
Block(14,9,11,LEAVES:3)
Block(14,9,12,LEAVES:3)
Block(14,9,13,LEAVES:3)
Block(14,9,14,LEAVES:3)
Block(14,9,15,LEAVES:3)
Block(14,9,16,LEAVES:3)
Block(14,9,17,LEAVES:3)
Block(14,9,18,LEAVES:3)
Block(14,10,-5,LEAVES:3)
Block(14,10,-3,LEAVES:3)
Block(14,10,-2,LEAVES:3)
Block(14,10,-1,LEAVES:3)
Block(14,10,1,LEAVES:3)
Block(14,10,2,LEAVES:3)
Block(14,10,3,LEAVES:3)
Block(14,10,4,LEAVES:3)
Block(14,10,5,LOG:15)
Block(14,10,6,LEAVES:3)
Block(14,10,7,LEAVES:3)
Block(14,10,8,LEAVES:3)
Block(14,10,9,LEAVES:3)
Block(14,10,10,LOG:15)
Block(14,10,11,LEAVES:3)
Block(14,10,12,LEAVES:3)
Block(14,10,13,LEAVES:3)
Block(14,10,14,LEAVES:3)
Block(14,10,15,LEAVES:3)
Block(14,10,16,LOG:15)
Block(14,10,17,LEAVES:3)
Block(14,10,18,LEAVES:3)
Block(14,11,-5,LEAVES:3)
Block(14,11,-3,LEAVES:3)
Block(14,11,-2,LEAVES:3)
Block(14,11,-1,LEAVES:3)
Block(14,11,1,LEAVES:3)
Block(14,11,2,LEAVES:3)
Block(14,11,3,LEAVES:3)
Block(14,11,4,LEAVES:3)
Block(14,11,5,LOG:15)
Block(14,11,6,LEAVES:3)
Block(14,11,7,LEAVES:3)
Block(14,11,8,LEAVES:3)
Block(14,11,9,LEAVES:3)
Block(14,11,10,LEAVES:3)
Block(14,11,11,LEAVES:3)
Block(14,11,12,LEAVES:3)
Block(14,11,13,LEAVES:3)
Block(14,11,14,LOG:15)
Block(14,11,15,LEAVES:3)
Block(14,11,16,LEAVES:3)
Block(14,11,17,LEAVES:3)
Block(14,11,18,LEAVES:3)
Block(14,12,-5,LEAVES:3)
Block(14,12,-2,LEAVES:3)
Block(14,12,-1,LEAVES:3)
Block(14,12,1,LEAVES:3)
Block(14,12,3,LEAVES:3)
Block(14,12,5,LEAVES:3)
Block(14,12,8,LEAVES:3)
Block(14,12,12,LEAVES:3)
Block(14,12,13,LOG:15)
Block(14,12,14,LEAVES:3)
Block(14,12,15,LEAVES:3)
Block(14,13,-5,LEAVES:3)
Block(14,13,-1,LEAVES:3)
Block(14,13,3,LEAVES:3)
Block(14,13,13,LEAVES:3)
Block(14,13,14,LEAVES:3)
Block(14,13,15,LEAVES:3)
Block(14,14,15,LEAVES:3)
Block(14,15,15,LEAVES:3)
Block(15,3,17,LEAVES:3)
Block(15,4,9,LEAVES:3)
Block(15,4,17,LEAVES:3)
Block(15,4,18,LEAVES:3)
Block(15,5,9,LEAVES:3)
Block(15,5,13,LEAVES:3)
Block(15,5,17,LEAVES:3)
Block(15,5,18,LEAVES:3)
Block(15,6,9,LEAVES:3)
Block(15,6,13,LEAVES:3)
Block(15,6,17,LEAVES:3)
Block(15,6,18,LEAVES:3)
Block(15,7,8,LEAVES:3)
Block(15,7,9,LEAVES:3)
Block(15,7,11,LEAVES:3)
Block(15,7,13,LEAVES:3)
Block(15,7,14,LEAVES:3)
Block(15,7,16,LEAVES:3)
Block(15,7,17,LOG:15)
Block(15,7,18,LEAVES:3)
Block(15,8,5,LEAVES:3)
Block(15,8,8,LEAVES:3)
Block(15,8,9,LEAVES:3)
Block(15,8,10,LEAVES:3)
Block(15,8,11,LEAVES:3)
Block(15,8,12,LEAVES:3)
Block(15,8,13,LOG:15)
Block(15,8,14,LEAVES:3)
Block(15,8,16,LEAVES:3)
Block(15,8,17,LOG:15)
Block(15,8,18,LEAVES:3)
Block(15,9,5,LEAVES:3)
Block(15,9,7,LEAVES:3)
Block(15,9,8,LEAVES:3)
Block(15,9,9,LEAVES:3)
Block(15,9,10,LEAVES:3)
Block(15,9,11,LEAVES:3)
Block(15,9,12,LEAVES:3)
Block(15,9,13,LOG:15)
Block(15,9,14,LEAVES:3)
Block(15,9,16,LEAVES:3)
Block(15,9,17,LOG:15)
Block(15,9,18,LEAVES:3)
Block(15,10,5,LEAVES:3)
Block(15,10,7,LEAVES:3)
Block(15,10,8,LEAVES:3)
Block(15,10,9,LOG:15)
Block(15,10,10,LEAVES:3)
Block(15,10,11,LEAVES:3)
Block(15,10,12,LEAVES:3)
Block(15,10,13,LOG:15)
Block(15,10,14,LEAVES:3)
Block(15,10,16,LEAVES:3)
Block(15,10,17,LOG:15)
Block(15,10,18,LEAVES:3)
Block(15,11,5,LEAVES:3)
Block(15,11,7,LEAVES:3)
Block(15,11,8,LEAVES:3)
Block(15,11,9,LEAVES:3)
Block(15,11,12,LEAVES:3)
Block(15,11,13,LOG:15)
Block(15,11,14,LEAVES:3)
Block(15,11,17,LEAVES:3)
Block(15,12,13,LEAVES:3)
Block(16,3,8,LEAVES:3)
Block(16,4,8,LEAVES:3)
Block(16,5,8,LEAVES:3)
Block(16,6,7,LEAVES:3)
Block(16,6,8,LEAVES:3)
Block(16,6,17,LEAVES:3)
Block(16,7,7,LEAVES:3)
Block(16,7,8,LOG:15)
Block(16,7,9,LEAVES:3)
Block(16,7,12,LEAVES:3)
Block(16,7,17,LEAVES:3)
Block(16,8,7,LEAVES:3)
Block(16,8,8,LOG:15)
Block(16,8,9,LEAVES:3)
Block(16,8,11,LEAVES:3)
Block(16,8,12,LEAVES:3)
Block(16,8,13,LEAVES:3)
Block(16,8,17,LEAVES:3)
Block(16,9,7,LEAVES:3)
Block(16,9,8,LOG:15)
Block(16,9,9,LEAVES:3)
Block(16,9,11,LEAVES:3)
Block(16,9,12,LEAVES:3)
Block(16,9,13,LEAVES:3)
Block(16,9,17,LEAVES:3)
Block(16,10,7,LEAVES:3)
Block(16,10,8,LOG:15)
Block(16,10,9,LEAVES:3)
Block(16,10,12,LEAVES:3)
Block(16,10,13,LEAVES:3)
Block(16,10,14,LEAVES:3)
Block(16,10,17,LEAVES:3)
Block(16,11,8,LEAVES:3)
Block(16,11,12,LEAVES:3)
Block(16,11,13,LOG:15)
Block(16,11,14,LEAVES:3)
Block(16,12,13,LEAVES:3)
Block(17,6,14,LEAVES:3)
Block(17,7,8,LEAVES:3)
Block(17,7,14,LEAVES:3)
Block(17,8,8,LEAVES:3)
Block(17,8,14,LEAVES:3)
Block(17,9,8,LEAVES:3)
Block(17,9,13,LEAVES:3)
Block(17,9,14,LEAVES:3)
Block(17,10,8,LEAVES:3)
Block(17,10,13,LEAVES:3)
Block(17,10,14,LOG:15)
Block(17,10,15,LEAVES:3)
Block(17,11,13,LEAVES:3)
Block(17,11,14,LEAVES:3)
Block(18,3,14,LEAVES:3)
Block(18,4,14,LEAVES:3)
Block(18,5,14,LEAVES:3)
Block(18,5,15,LEAVES:3)
Block(18,6,13,LEAVES:3)
Block(18,6,14,LOG:15)
Block(18,6,15,LEAVES:3)
Block(18,7,13,LEAVES:3)
Block(18,7,14,LOG:15)
Block(18,7,15,LEAVES:3)
Block(18,8,13,LEAVES:3)
Block(18,8,14,LOG:15)
Block(18,8,15,LEAVES:3)
Block(18,9,13,LEAVES:3)
Block(18,9,14,LOG:15)
Block(18,9,15,LEAVES:3)
Block(18,10,13,LEAVES:3)
Block(18,10,14,LOG:15)
Block(18,10,15,LEAVES:3)
Block(18,11,14,LEAVES:3)

#######################################################################
# +-----------------------------------------------------------------+ #
# |                            BO3 checks                           | #
# +-----------------------------------------------------------------+ #
#######################################################################


#######################################################################
# +-----------------------------------------------------------------+ #
# |                             Branches                            | #
# +-----------------------------------------------------------------+ #
#######################################################################


#######################################################################
# +-----------------------------------------------------------------+ #
# |                             Entities                            | #
# +-----------------------------------------------------------------+ #
#######################################################################


#######################################################################
# +-----------------------------------------------------------------+ #
# |                            Particles                            | #
# +-----------------------------------------------------------------+ #
#######################################################################


#######################################################################
# +-----------------------------------------------------------------+ #
# |                             Spawners                            | #
# +-----------------------------------------------------------------+ #
#######################################################################


#######################################################################
# +-----------------------------------------------------------------+ #
# |                             ModData                             | #
# +-----------------------------------------------------------------+ #
#######################################################################

