
#######################################################################
# +-----------------------------------------------------------------+ #
# |                            BO3 object                           | #
# +-----------------------------------------------------------------+ #
#######################################################################

Author: LordSmellyPants

Description: Converted version of the BO2 JungleRainforest5

Version: 3

SettingsMode: WriteWithoutComments


#######################################################################
# +-----------------------------------------------------------------+ #
# |                          Main settings                          | #
# +-----------------------------------------------------------------+ #
#######################################################################

Tree: true

Frequency: 1

Rarity: 20.0

RotateRandomly: true

SpawnHeight: highestSolidBlock

SpawnHeightOffset: 0

SpawnHeightVariance: 0

##############################
# Height Limits for the BO3. #
##############################

MinHeight: 60

MaxHeight: 81

######################
# Extrusion settings #
######################

ExtrudeMode: None

ExtrudeThroughBlocks: AIR

MaxBranchDepth: 10

ExcludedBiomes: All


#######################################################################
# +-----------------------------------------------------------------+ #
# |                      Source block settings                      | #
# +-----------------------------------------------------------------+ #
#######################################################################

SourceBlocks: STONE:1,STONE:3,STONE:5,DIRT:1,DIRT,SAND,GRASS,DIRT:2,STATIONARY_WATER,HARD_CLAY,STAINED_CLAY,CLAY,SANDSTONE,SAND:1,AIR,STONE,GRAVEL,LONG_GRASS,LONG_GRASS:1,LONG_GRASS:2,DEAD_BUSH,YELLOW_FLOWER,RED_ROSE,BROWN_MUSHROOM,RED_MUSHROOM

MaxPercentageOutsideSourceBlock: 0

OutsideSourceBlock: placeAnyway

IsOTGPlus: false

InheritBO3: 

InheritBO3Rotation: NORTH

OverrideChildSettings: true

OverrideParentHeight: false

CanOverride: false

BranchFrequency: 0

BranchFrequencyGroup: 

MustBeBelowOther: false

MustBeInside: 

CannotBeInside: 

ReplacesBO3: 

CanSpawnOnWater: true

SpawnOnWaterOnly: false

SpawnUnderWater: false

SpawnAtWaterLevel: false

HeightOffset: 0

RemoveAir: true

ReplaceAbove: 

ReplaceBelow: 

ReplaceWithBiomeBlocks: true

ReplaceWithGroundBlock: DIRT

ReplaceWithSurfaceBlock: GRASS

SmoothRadius: 0

SmoothHeightOffset: 0

SmoothStartTop: false

SmoothStartWood: false

SmoothingSurfaceBlock: 

SmoothingGroundBlock: 

BO3Group: 

IsSpawnPoint: false


#######################################################################
# +-----------------------------------------------------------------+ #
# |                              Blocks                             | #
# +-----------------------------------------------------------------+ #
#######################################################################

Block(3,14,-4,LEAVES:3)
Block(3,0,-3,LOG:3)
Block(-1,15,-4,LEAVES:3)
Block(-1,14,-4,LEAVES:3)
Block(-1,16,-4,LEAVES:3)
Block(-2,15,-3,LEAVES:3)
Block(-2,14,-3,LEAVES:3)
Block(-2,13,-3,LEAVES:3)
Block(-2,12,-3,LEAVES:3)
Block(1,4,-4,LOG:3)
Block(1,2,-4,LOG:3)
Block(1,3,-4,LOG:3)
Block(-3,11,-2,LEAVES:3)
Block(1,1,-4,LOG:3)
Block(-3,10,-2,LEAVES:3)
Block(4,14,-3,LEAVES:3)
Block(-3,12,-2,LEAVES:3)
Block(4,13,-3,LEAVES:3)
Block(-1,14,1,LEAVES:3)
Block(3,8,0,LEAVES:3)
Block(3,7,0,LOG:3)
Block(0,-3,-3,LOG:3)
Block(3,6,0,LOG:3)
Block(3,5,0,LOG:3)
Block(3,9,0,LEAVES:3)
Block(-2,11,-3,LEAVES:3)
Block(2,-1,-1,LOG:3)
Block(2,16,-5,LEAVES:3)
Block(1,16,1,LEAVES:3)
Block(0,-2,-3,LOG:3)
Block(0,-2,-2,LOG:3)
Block(1,16,-1,LEAVES:3)
Block(1,15,-1,LEAVES:3)
Block(1,14,-1,LEAVES:3)
Block(3,0,-2,LOG:3)
Block(1,9,-3,LOG:3)
Block(1,7,-3,LOG:3)
Block(1,8,-3,LOG:3)
Block(1,5,-3,LOG:3)
Block(1,6,-3,LOG:3)
Block(1,4,-3,LOG:3)
Block(1,1,-3,LOG:3)
Block(1,13,-1,LEAVES:3)
Block(1,2,-3,LOG:3)
Block(1,12,-1,LEAVES:3)
Block(1,11,-1,LEAVES:3)
Block(1,0,-3,LOG:3)
Block(3,4,0,LOG:3)
Block(3,3,0,LOG:3)
Block(0,16,-1,LEAVES:3)
Block(0,15,-1,LEAVES:3)
Block(3,9,1,LEAVES:3)
Block(3,8,1,LEAVES:3)
Block(1,-1,-2,LOG:3)
Block(1,-3,-2,LOG:3)
Block(-1,13,-4,LEAVES:3)
Block(1,16,-6,LEAVES:3)
Block(4,14,-2,LEAVES:3)
Block(-1,12,2,LEAVES:3)
Block(-3,14,-3,LEAVES:3)
Block(4,13,-2,LEAVES:3)
Block(-1,13,2,LEAVES:3)
Block(0,14,-1,LEAVES:3)
Block(0,13,-1,LEAVES:3)
Block(1,8,-2,LOG:3)
Block(1,9,-2,LOG:3)
Block(1,6,-2,LOG:3)
Block(1,7,-2,LOG:3)
Block(1,4,-2,LOG:3)
Block(1,5,-2,LOG:3)
Block(1,2,-2,LOG:3)
Block(1,3,-2,LOG:3)
Block(1,0,-2,LOG:3)
Block(1,1,-2,LOG:3)
Block(4,13,-4,LEAVES:3)
Block(4,10,0,LEAVES:3)
Block(-1,14,-6,LEAVES:3)
Block(-1,15,0,LEAVES:3)
Block(2,0,-1,LOG:3)
Block(4,7,0,LOG:3)
Block(4,6,0,LOG:3)
Block(4,9,0,LEAVES:3)
Block(1,14,-4,LEAVES:3)
Block(3,15,-3,LEAVES:3)
Block(4,8,0,LEAVES:3)
Block(1,13,-4,LEAVES:3)
Block(3,14,-3,LEAVES:3)
Block(-2,15,-4,LEAVES:3)
Block(1,16,-4,LEAVES:3)
Block(1,15,-4,LEAVES:3)
Block(4,14,-4,LEAVES:3)
Block(4,10,1,LEAVES:3)
Block(1,11,-5,LEAVES:3)
Block(2,15,-4,LEAVES:3)
Block(1,10,-5,LEAVES:3)
Block(-1,14,-5,LEAVES:3)
Block(2,14,-4,LEAVES:3)
Block(1,13,-5,LEAVES:3)
Block(2,13,-4,LEAVES:3)
Block(1,12,-5,LEAVES:3)
Block(2,12,-4,LEAVES:3)
Block(-2,14,-5,LEAVES:3)
Block(-2,15,-5,LEAVES:3)
Block(1,16,-5,LEAVES:3)
Block(1,3,-1,LOG:3)
Block(-3,14,-4,LEAVES:3)
Block(3,10,1,LEAVES:3)
Block(1,2,-1,LOG:3)
Block(-3,13,-4,LEAVES:3)
Block(5,13,-3,LEAVES:3)
Block(5,12,-3,LEAVES:3)
Block(-1,15,-5,LEAVES:3)
Block(2,0,-2,LOG:3)
Block(2,4,-2,LOG:3)
Block(4,8,1,LEAVES:3)
Block(2,3,-2,LOG:3)
Block(2,2,-2,LOG:3)
Block(2,1,-2,LOG:3)
Block(4,9,1,LEAVES:3)
Block(0,14,-5,LEAVES:3)
Block(0,13,-5,LEAVES:3)
Block(0,12,-5,LEAVES:3)
Block(2,5,-2,LOG:3)
Block(0,11,-5,LEAVES:3)
Block(0,16,-5,LEAVES:3)
Block(0,2,-4,LOG:3)
Block(1,16,-3,LEAVES:3)
Block(-2,14,-6,LEAVES:3)
Block(-2,13,-6,LEAVES:3)
Block(2,14,-2,LEAVES:3)
Block(2,15,-2,LEAVES:3)
Block(2,12,-2,LEAVES:3)
Block(2,13,-2,LEAVES:3)
Block(0,14,1,LEAVES:3)
Block(1,10,-3,LOG:3)
Block(0,13,1,LEAVES:3)
Block(1,11,-3,LEAVES:3)
Block(2,11,-2,LEAVES:3)
Block(1,12,-3,LEAVES:3)
Block(1,13,-3,LEAVES:3)
Block(1,14,-3,LEAVES:3)
Block(1,15,-3,LEAVES:3)
Block(0,12,-4,LEAVES:3)
Block(0,13,-4,LEAVES:3)
Block(0,16,-4,LEAVES:3)
Block(0,14,-4,LEAVES:3)
Block(0,15,-4,LEAVES:3)
Block(2,3,-3,LOG:3)
Block(2,2,-3,LOG:3)
Block(2,1,-3,LOG:3)
Block(1,-1,-4,LOG:3)
Block(2,0,-3,LOG:3)
Block(5,9,0,LEAVES:3)
Block(-3,13,-5,LEAVES:3)
Block(2,4,-3,LOG:3)
Block(-3,14,-5,LEAVES:3)
Block(-2,12,-1,LEAVES:3)
Block(-2,13,-1,LEAVES:3)
Block(-2,11,-1,LEAVES:3)
Block(3,14,-2,LEAVES:3)
Block(-2,14,-1,LEAVES:3)
Block(3,15,-2,LEAVES:3)
Block(5,12,-4,LEAVES:3)
Block(-3,13,-6,LEAVES:3)
Block(-3,12,-6,LEAVES:3)
Block(-2,14,1,LEAVES:3)
Block(-1,15,-1,LEAVES:3)
Block(-2,13,1,LEAVES:3)
Block(-1,13,-1,LEAVES:3)
Block(2,15,-3,LEAVES:3)
Block(-1,14,-1,LEAVES:3)
Block(2,16,1,LEAVES:3)
Block(2,13,-3,LEAVES:3)
Block(0,14,0,LEAVES:3)
Block(0,13,0,LEAVES:3)
Block(2,14,-3,LEAVES:3)
Block(2,2,-4,LOG:3)
Block(2,0,-4,LOG:3)
Block(0,16,0,LEAVES:3)
Block(0,15,0,LEAVES:3)
Block(5,9,1,LEAVES:3)
Block(3,10,0,LEAVES:3)
Block(0,4,-2,LOG:3)
Block(0,3,-2,LOG:3)
Block(2,10,0,LEAVES:3)
Block(0,6,-2,LOG:3)
Block(3,9,-1,LEAVES:3)
Block(2,11,0,LEAVES:3)
Block(0,5,-2,LOG:3)
Block(2,12,0,LEAVES:3)
Block(0,8,-2,LOG:3)
Block(0,7,-2,LOG:3)
Block(0,9,-2,LOG:3)
Block(1,-2,-3,LOG:3)
Block(1,-3,-3,LOG:3)
Block(3,0,-1,LOG:3)
Block(-2,10,-2,LEAVES:3)
Block(0,2,-2,LOG:3)
Block(2,16,0,LEAVES:3)
Block(-1,12,-3,LEAVES:3)
Block(4,9,-1,LEAVES:3)
Block(4,8,-1,LEAVES:3)
Block(1,-1,-3,LOG:3)
Block(0,-2,-4,LOG:3)
Block(1,16,0,LEAVES:3)
Block(1,14,0,LEAVES:3)
Block(1,13,0,LEAVES:3)
Block(1,12,0,LEAVES:3)
Block(1,11,0,LEAVES:3)
Block(-1,14,-3,LEAVES:3)
Block(2,14,-1,LEAVES:3)
Block(-1,13,-3,LEAVES:3)
Block(2,13,-1,LEAVES:3)
Block(2,16,-1,LEAVES:3)
Block(-1,15,-3,LEAVES:3)
Block(2,12,-1,LEAVES:3)
Block(2,11,-1,LEAVES:3)
Block(0,13,2,LEAVES:3)
Block(0,11,-3,LOG:3)
Block(0,12,-3,LOG:3)
Block(0,10,-3,LOG:3)
Block(0,15,-3,LEAVES:3)
Block(0,16,-3,LEAVES:3)
Block(0,13,-3,LOG:3)
Block(0,14,-3,LEAVES:3)
Block(0,3,-3,LOG:3)
Block(0,2,-3,LOG:3)
Block(0,16,-2,LEAVES:3)
Block(0,5,-3,LOG:3)
Block(0,4,-3,LOG:3)
Block(0,7,-3,LOG:3)
Block(0,6,-3,LOG:3)
Block(4,10,-1,LEAVES:3)
Block(0,9,-3,LOG:3)
Block(0,8,-3,LOG:3)
Block(-2,12,2,LEAVES:3)
Block(-1,13,-2,LOG:3)
Block(-2,13,2,LEAVES:3)
Block(0,1,-3,LOG:3)
Block(-1,14,-2,LEAVES:3)
Block(0,0,-3,LOG:3)
Block(-1,15,-2,LEAVES:3)
Block(2,9,1,LEAVES:3)
Block(0,11,-2,LOG:3)
Block(0,10,-2,LOG:3)
Block(0,13,-2,LOG:3)
Block(0,12,-2,LOG:3)
Block(0,15,-2,LEAVES:3)
Block(0,14,-2,LOG:3)
Block(2,3,0,LOG:3)
Block(1,15,-2,LEAVES:3)
Block(2,2,0,LOG:3)
Block(1,16,-2,LEAVES:3)
Block(3,10,-1,LEAVES:3)
Block(2,4,0,LOG:3)
Block(2,-1,-3,LOG:3)
Block(2,-2,-3,LOG:3)
Block(-2,14,-2,LEAVES:3)
Block(-2,13,-2,LEAVES:3)
Block(-2,12,-2,LEAVES:3)
Block(1,10,-2,LEAVES:3)
Block(1,11,-2,LEAVES:3)
Block(1,12,-2,LEAVES:3)
Block(1,13,-2,LEAVES:3)
Block(3,14,-1,LEAVES:3)
Block(1,14,-2,LEAVES:3)
Block(-2,15,-2,LEAVES:3)

#######################################################################
# +-----------------------------------------------------------------+ #
# |                            BO3 checks                           | #
# +-----------------------------------------------------------------+ #
#######################################################################

BlockCheck(1,-1,-2,GRASS,DIRT,SAND)

#######################################################################
# +-----------------------------------------------------------------+ #
# |                             Branches                            | #
# +-----------------------------------------------------------------+ #
#######################################################################


#######################################################################
# +-----------------------------------------------------------------+ #
# |                             Entities                            | #
# +-----------------------------------------------------------------+ #
#######################################################################


#######################################################################
# +-----------------------------------------------------------------+ #
# |                            Particles                            | #
# +-----------------------------------------------------------------+ #
#######################################################################


#######################################################################
# +-----------------------------------------------------------------+ #
# |                             Spawners                            | #
# +-----------------------------------------------------------------+ #
#######################################################################


#######################################################################
# +-----------------------------------------------------------------+ #
# |                             ModData                             | #
# +-----------------------------------------------------------------+ #
#######################################################################

