
#######################################################################
# +-----------------------------------------------------------------+ #
# |                            BO3 object                           | #
# +-----------------------------------------------------------------+ #
#######################################################################

Author: LordSmellyPants

Description: Converted version of the BO2 JungleRainforest6

Version: 3

SettingsMode: WriteWithoutComments


#######################################################################
# +-----------------------------------------------------------------+ #
# |                          Main settings                          | #
# +-----------------------------------------------------------------+ #
#######################################################################

Tree: true

Frequency: 1

Rarity: 20.0

RotateRandomly: true

SpawnHeight: highestSolidBlock

SpawnHeightOffset: 0

SpawnHeightVariance: 0

##############################
# Height Limits for the BO3. #
##############################

MinHeight: 60

MaxHeight: 81

######################
# Extrusion settings #
######################

ExtrudeMode: None

ExtrudeThroughBlocks: AIR

MaxBranchDepth: 10

ExcludedBiomes: All


#######################################################################
# +-----------------------------------------------------------------+ #
# |                      Source block settings                      | #
# +-----------------------------------------------------------------+ #
#######################################################################

SourceBlocks: STONE:1,STONE:3,STONE:5,DIRT:1,DIRT,SAND,GRASS,DIRT:2,STATIONARY_WATER,HARD_CLAY,STAINED_CLAY,CLAY,SANDSTONE,SAND:1,AIR,STONE,GRAVEL,LONG_GRASS,LONG_GRASS:1,LONG_GRASS:2,DEAD_BUSH,YELLOW_FLOWER,RED_ROSE,BROWN_MUSHROOM,RED_MUSHROOM

MaxPercentageOutsideSourceBlock: 0

OutsideSourceBlock: placeAnyway

IsOTGPlus: false

InheritBO3: 

InheritBO3Rotation: NORTH

OverrideChildSettings: true

OverrideParentHeight: false

CanOverride: false

BranchFrequency: 0

BranchFrequencyGroup: 

MustBeBelowOther: false

MustBeInside: 

CannotBeInside: 

ReplacesBO3: 

CanSpawnOnWater: true

SpawnOnWaterOnly: false

SpawnUnderWater: false

SpawnAtWaterLevel: false

HeightOffset: 0

RemoveAir: true

ReplaceAbove: 

ReplaceBelow: 

ReplaceWithBiomeBlocks: true

ReplaceWithGroundBlock: DIRT

ReplaceWithSurfaceBlock: GRASS

SmoothRadius: 0

SmoothHeightOffset: 0

SmoothStartTop: false

SmoothStartWood: false

SmoothingSurfaceBlock: 

SmoothingGroundBlock: 

BO3Group: 

IsSpawnPoint: false


#######################################################################
# +-----------------------------------------------------------------+ #
# |                              Blocks                             | #
# +-----------------------------------------------------------------+ #
#######################################################################

Block(6,13,-1,LEAVES:3)
Block(2,13,4,LEAVES:3)
Block(6,14,-1,LEAVES:3)
Block(2,11,4,LEAVES:3)
Block(6,12,5,LEAVES:3)
Block(6,9,1,LEAVES:3)
Block(2,12,4,LEAVES:3)
Block(6,13,5,LEAVES:3)
Block(-6,9,-6,LOG:3)
Block(-6,8,-6,LOG:3)
Block(6,6,1,LEAVES:3)
Block(-6,7,-6,LOG:3)
Block(6,5,1,LEAVES:7)
Block(6,8,1,LOG:3)
Block(6,7,1,LOG:3)
Block(1,8,-4,LEAVES:3)
Block(-2,14,-3,LEAVES:3)
Block(1,7,-4,LEAVES:3)
Block(-2,12,-3,LEAVES:3)
Block(-5,11,-6,LEAVES:3)
Block(-5,10,-6,COCOA:9)
Block(-6,11,0,LEAVES:3)
Block(-2,11,-3,LEAVES:3)
Block(-2,10,-3,LEAVES:3)
Block(10,13,-5,LEAVES:3)
Block(-4,-4,-2,LOG:3)
Block(-4,-3,-2,LOG:3)
Block(1,14,-1,LEAVES:3)
Block(-2,-4,-5,LOG:3)
Block(-2,-5,-5,LOG:3)
Block(-2,-6,-5,LOG:3)
Block(-5,14,7,LEAVES:3)
Block(-5,12,7,LOG:3)
Block(-2,-1,-5,LOG:3)
Block(-5,13,7,LOG:3)
Block(-2,-2,-5,LOG:3)
Block(1,12,2,LEAVES:3)
Block(-2,-3,-5,LOG:3)
Block(-5,11,7,LEAVES:3)
Block(1,13,2,LEAVES:3)
Block(1,13,-1,LEAVES:3)
Block(1,14,2,LEAVES:3)
Block(-4,16,5,LEAVES:3)
Block(1,12,-1,LOG:3)
Block(1,15,2,LEAVES:3)
Block(-4,15,5,LEAVES:3)
Block(1,11,-1,LEAVES:3)
Block(-5,-5,-6,LOG:3)
Block(5,12,1,LEAVES:3)
Block(-5,-4,-6,LOG:3)
Block(5,11,1,LEAVES:3)
Block(5,10,1,LOG:3)
Block(-4,12,5,LEAVES:3)
Block(-4,14,5,LEAVES:3)
Block(-4,13,5,LEAVES:3)
Block(7,11,7,LEAVES:7)
Block(7,12,7,LOG:3)
Block(7,13,7,LEAVES:7)
Block(4,14,-2,LEAVES:3)
Block(-8,15,-9,LEAVES:3)
Block(-8,14,-9,LEAVES:3)
Block(4,15,-2,LEAVES:3)
Block(4,13,-2,LEAVES:3)
Block(-3,15,3,LEAVES:3)
Block(-4,14,-10,LEAVES:3)
Block(-3,14,-9,LEAVES:7)
Block(-3,14,3,LOG:3)
Block(0,3,0,LOG:3)
Block(-3,15,-9,LEAVES:3)
Block(0,2,0,LOG:3)
Block(-4,-1,-4,LOG:3)
Block(0,5,0,LOG:3)
Block(-4,-2,-4,LOG:3)
Block(0,4,0,LOG:3)
Block(-9,14,-10,LEAVES:3)
Block(-9,13,-10,LEAVES:7)
Block(-4,13,-10,LEAVES:3)
Block(-2,9,-5,LEAVES:3)
Block(-2,1,-5,LOG:3)
Block(-4,13,3,LEAVES:3)
Block(-2,2,-5,LOG:3)
Block(0,7,-6,LEAVES:3)
Block(-5,10,9,LEAVES:3)
Block(-4,14,3,LEAVES:3)
Block(-2,0,-5,LOG:3)
Block(-5,14,-4,LEAVES:3)
Block(3,11,6,LEAVES:3)
Block(-5,15,-4,LEAVES:3)
Block(4,13,-4,LEAVES:3)
Block(-5,13,-4,LEAVES:7)
Block(7,10,9,LEAVES:3)
Block(7,11,9,LEAVES:3)
Block(7,14,-7,LEAVES:3)
Block(7,13,-7,LEAVES:7)
Block(4,14,-4,LEAVES:3)
Block(3,12,6,LEAVES:3)
Block(-8,14,-7,LEAVES:3)
Block(-8,15,-7,LEAVES:3)
Block(2,12,2,LOG:3)
Block(2,11,2,LOG:3)
Block(1,-5,-1,LOG:3)
Block(6,16,-3,LEAVES:7)
Block(1,-4,-1,LOG:3)
Block(2,13,2,LEAVES:3)
Block(6,15,-3,LOG:3)
Block(6,14,-3,LEAVES:3)
Block(4,12,1,LEAVES:3)
Block(4,10,1,LEAVES:3)
Block(4,11,1,LOG:3)
Block(-6,13,-8,LEAVES:3)
Block(-7,14,-3,LEAVES:7)
Block(-6,11,2,LEAVES:3)
Block(-1,-7,-1,LOG:3)
Block(-2,10,-5,LEAVES:3)
Block(-2,11,-5,LEAVES:3)
Block(-9,14,-2,LEAVES:3)
Block(0,9,0,LEAVES:3)
Block(-1,15,6,LEAVES:3)
Block(-1,14,6,LEAVES:3)
Block(0,6,-4,LEAVES:3)
Block(0,8,-4,LEAVES:3)
Block(0,7,-4,LOG:3)
Block(1,13,4,LEAVES:3)
Block(1,14,4,LEAVES:3)
Block(-2,1,-3,LOG:3)
Block(0,9,-4,LEAVES:3)
Block(-2,0,-3,LOG:3)
Block(-5,-2,-4,LOG:3)
Block(-5,-3,-4,LOG:3)
Block(-1,-4,-3,LOG:3)
Block(7,15,-3,LEAVES:3)
Block(-1,-3,-3,LOG:3)
Block(7,14,-3,LEAVES:7)
Block(-1,-5,-3,LOG:3)
Block(-5,-4,-4,LOG:3)
Block(-1,-2,-3,LOG:3)
Block(-1,-1,-3,LOG:3)
Block(9,14,-6,LEAVES:3)
Block(9,13,-6,LOG:3)
Block(9,12,-6,LEAVES:3)
Block(5,14,-4,LEAVES:3)
Block(-3,15,5,LEAVES:3)
Block(-3,16,5,LOG:3)
Block(-3,17,5,LEAVES:3)
Block(-2,13,-1,LEAVES:3)
Block(-2,13,1,LEAVES:3)
Block(-2,12,1,LEAVES:3)
Block(-1,13,-1,LEAVES:3)
Block(-1,14,-1,LEAVES:3)
Block(0,14,0,LEAVES:3)
Block(0,12,0,LEAVES:3)
Block(0,11,0,LEAVES:3)
Block(5,9,1,LOG:3)
Block(5,8,1,LEAVES:3)
Block(5,7,1,LEAVES:3)
Block(10,13,-7,LEAVES:3)
Block(10,12,-7,LEAVES:7)
Block(0,10,0,LEAVES:3)
Block(2,7,-4,LEAVES:3)
Block(0,4,-2,LOG:3)
Block(0,3,-2,LOG:3)
Block(-2,0,-1,LOG:3)
Block(6,14,-5,LEAVES:3)
Block(0,0,-2,LOG:3)
Block(0,2,-2,LOG:3)
Block(0,1,-2,LOG:3)
Block(-2,-1,-3,LOG:3)
Block(7,9,1,LEAVES:3)
Block(-1,12,-3,LOG:3)
Block(7,8,1,LEAVES:7)
Block(-2,-3,-3,LOG:3)
Block(-2,-2,-3,LOG:3)
Block(7,7,1,LEAVES:7)
Block(7,6,1,LEAVES:7)
Block(-3,-3,-2,LOG:3)
Block(-3,-2,-2,LOG:3)
Block(-4,4,-5,LOG:3)
Block(-9,13,-9,LEAVES:3)
Block(-4,3,-5,LOG:3)
Block(-9,14,-9,LOG:3)
Block(-4,0,-5,LOG:3)
Block(5,11,3,LEAVES:3)
Block(5,12,3,LEAVES:3)
Block(-4,2,-5,LOG:3)
Block(-9,15,-9,LEAVES:3)
Block(-4,1,-5,LOG:3)
Block(-2,15,3,LOG:3)
Block(-2,16,3,LEAVES:3)
Block(-1,13,-3,LEAVES:3)
Block(-6,10,9,LEAVES:3)
Block(-6,11,9,LEAVES:7)
Block(0,13,2,LEAVES:3)
Block(0,14,2,LEAVES:3)
Block(0,15,2,LOG:3)
Block(0,16,2,LEAVES:3)
Block(0,10,2,LEAVES:3)
Block(-4,9,9,LEAVES:7)
Block(0,11,2,LEAVES:3)
Block(-4,8,9,LEAVES:7)
Block(0,12,2,LEAVES:3)
Block(6,11,7,LEAVES:3)
Block(6,13,7,LEAVES:7)
Block(6,12,7,LEAVES:3)
Block(1,12,6,LEAVES:3)
Block(8,14,-4,LEAVES:3)
Block(1,13,6,LEAVES:3)
Block(-10,14,-8,LEAVES:7)
Block(8,15,-4,LEAVES:3)
Block(-4,13,1,LEAVES:3)
Block(-4,12,1,LEAVES:3)
Block(-10,13,-8,LEAVES:7)
Block(-4,11,1,LEAVES:3)
Block(7,14,-5,LEAVES:3)
Block(7,15,-5,LEAVES:7)
Block(-5,-5,-2,LOG:3)
Block(3,13,4,LEAVES:3)
Block(-3,13,7,LEAVES:3)
Block(-8,10,8,LEAVES:3)
Block(9,12,-4,LEAVES:3)
Block(3,12,4,LEAVES:3)
Block(-3,12,7,LEAVES:3)
Block(-3,14,7,LEAVES:3)
Block(-3,11,7,LEAVES:3)
Block(9,13,-4,LEAVES:3)
Block(9,14,-4,LEAVES:3)
Block(-6,10,10,LEAVES:3)
Block(-7,10,8,LEAVES:3)
Block(-5,13,2,LEAVES:7)
Block(-7,11,8,LEAVES:3)
Block(2,9,2,LEAVES:3)
Block(2,8,2,LEAVES:3)
Block(-7,14,-9,LEAVES:3)
Block(2,7,2,LEAVES:3)
Block(-4,13,-7,LEAVES:3)
Block(-4,15,-7,LEAVES:3)
Block(-1,4,0,LOG:3)
Block(-4,14,-7,LEAVES:3)
Block(-4,4,-7,LOG:3)
Block(-1,7,0,LEAVES:3)
Block(-4,3,-7,LOG:3)
Block(-1,8,0,LEAVES:3)
Block(-6,15,-5,LEAVES:7)
Block(6,14,-6,LEAVES:3)
Block(-6,14,-5,LEAVES:3)
Block(-6,11,-5,LEAVES:3)
Block(-6,12,-5,LEAVES:3)
Block(-8,15,-3,LEAVES:3)
Block(-8,14,-3,LEAVES:3)
Block(-5,12,2,LEAVES:3)
Block(6,13,-6,LEAVES:3)
Block(5,11,7,LEAVES:3)
Block(5,12,7,LEAVES:7)
Block(0,-1,-3,LOG:3)
Block(5,10,7,LEAVES:3)
Block(-5,9,9,LEAVES:3)
Block(4,12,4,LEAVES:3)
Block(4,13,4,LOG:3)
Block(4,14,4,LEAVES:3)
Block(-1,3,-2,LOG:3)
Block(-1,2,-2,LOG:3)
Block(-1,1,-2,LOG:3)
Block(-1,0,-2,LOG:3)
Block(-2,14,-9,LEAVES:3)
Block(-1,-3,-5,LOG:3)
Block(-1,-4,-5,LOG:3)
Block(-2,13,-9,LEAVES:3)
Block(-1,-2,-5,LOG:3)
Block(-7,8,10,LEAVES:3)
Block(-3,12,-3,LEAVES:3)
Block(-3,11,-3,LEAVES:3)
Block(-1,12,2,LEAVES:3)
Block(-3,14,-3,LOG:3)
Block(-7,9,10,LEAVES:3)
Block(-3,13,-3,LEAVES:3)
Block(-1,14,2,LEAVES:3)
Block(0,12,-1,COCOA:11)
Block(-1,13,2,LEAVES:3)
Block(-3,15,-3,LEAVES:3)
Block(0,14,-1,LEAVES:3)
Block(-1,16,2,LEAVES:3)
Block(0,13,-1,LEAVES:3)
Block(-1,15,2,LEAVES:3)
Block(-3,13,-10,LEAVES:3)
Block(9,11,7,LEAVES:3)
Block(-3,14,-10,LEAVES:3)
Block(9,10,7,LEAVES:3)
Block(4,12,6,LEAVES:3)
Block(4,11,6,LEAVES:3)
Block(4,13,6,LEAVES:7)
Block(8,13,-6,LEAVES:3)
Block(8,14,-6,LEAVES:3)
Block(-1,7,2,LEAVES:3)
Block(-6,-7,-5,LOG:3)
Block(-6,-6,-5,LOG:3)
Block(-1,8,2,LEAVES:3)
Block(3,13,-3,LEAVES:3)
Block(3,12,-3,LEAVES:3)
Block(7,10,4,LEAVES:3)
Block(7,11,4,LEAVES:3)
Block(-3,-1,-5,LOG:3)
Block(-3,-2,-5,LOG:3)
Block(8,11,7,LEAVES:3)
Block(-1,12,0,LEAVES:3)
Block(-3,-3,-5,LOG:3)
Block(-1,13,0,LEAVES:3)
Block(-3,-4,-5,LOG:3)
Block(8,12,7,LEAVES:7)
Block(-1,14,0,LEAVES:3)
Block(-5,15,-9,LEAVES:3)
Block(-1,11,-5,LEAVES:7)
Block(-1,12,-5,LEAVES:7)
Block(3,10,1,LEAVES:3)
Block(-4,14,-9,LEAVES:3)
Block(-4,15,-9,LEAVES:3)
Block(3,11,1,LOG:3)
Block(5,15,-3,LEAVES:3)
Block(5,14,-3,LEAVES:3)
Block(0,-6,-1,LOG:3)
Block(-1,0,-4,LOG:3)
Block(-9,14,-7,LEAVES:7)
Block(5,14,5,LEAVES:3)
Block(-9,13,-7,LEAVES:7)
Block(5,13,5,LOG:3)
Block(-7,9,7,LEAVES:3)
Block(-1,9,-4,LOG:3)
Block(-1,8,-4,LOG:3)
Block(-2,16,5,LEAVES:3)
Block(-1,7,-4,LEAVES:3)
Block(-6,10,7,LEAVES:3)
Block(0,15,4,LEAVES:3)
Block(0,16,4,LEAVES:3)
Block(-3,2,-7,LOG:3)
Block(-5,14,-9,LEAVES:3)
Block(-3,3,-7,LOG:3)
Block(-5,13,-9,LEAVES:3)
Block(-6,13,7,LEAVES:3)
Block(5,12,5,LEAVES:3)
Block(-6,12,7,LEAVES:3)
Block(-6,11,7,LEAVES:3)
Block(0,14,4,LEAVES:3)
Block(-3,11,-5,LEAVES:3)
Block(1,7,0,LOG:3)
Block(-3,10,-5,LEAVES:3)
Block(-5,7,-6,LOG:3)
Block(-5,8,-6,LOG:3)
Block(-2,-3,-7,LOG:3)
Block(-2,-5,-7,LOG:3)
Block(-2,-4,-7,LOG:3)
Block(-5,5,-6,LOG:3)
Block(-5,6,-6,LOG:3)
Block(-5,4,-6,LOG:3)
Block(0,14,6,LEAVES:3)
Block(0,13,6,LEAVES:3)
Block(-3,14,-5,LEAVES:3)
Block(-1,16,4,LEAVES:3)
Block(-4,12,8,LEAVES:7)
Block(-4,10,8,LEAVES:7)
Block(-4,11,8,LEAVES:7)
Block(6,11,3,LEAVES:3)
Block(-6,10,-7,LEAVES:3)
Block(-7,15,-7,LEAVES:3)
Block(-6,11,-7,LEAVES:3)
Block(-7,11,-7,LEAVES:3)
Block(-10,13,-4,LEAVES:3)
Block(-7,13,-7,LEAVES:3)
Block(-7,14,-7,LOG:3)
Block(6,12,3,LEAVES:3)
Block(-10,14,-4,LEAVES:3)
Block(1,-7,0,LOG:3)
Block(1,-6,0,LOG:3)
Block(-7,9,9,LEAVES:3)
Block(0,-6,-5,LOG:3)
Block(-4,15,-5,LEAVES:3)
Block(0,-5,-5,LOG:3)
Block(-4,14,-5,LEAVES:3)
Block(4,12,2,LEAVES:3)
Block(-6,14,-7,LEAVES:7)
Block(4,11,2,LEAVES:3)
Block(-6,15,-7,LEAVES:7)
Block(-6,12,-7,LEAVES:3)
Block(-6,13,-7,LEAVES:3)
Block(-3,0,-5,LOG:3)
Block(-3,1,-5,LOG:3)
Block(-3,2,-5,LOG:3)
Block(-3,3,-5,LOG:3)
Block(1,6,0,LOG:3)
Block(1,5,0,LOG:3)
Block(1,4,0,LOG:3)
Block(0,9,2,LEAVES:3)
Block(-6,11,3,LEAVES:7)
Block(-6,12,3,LEAVES:7)
Block(-4,13,6,LEAVES:3)
Block(-4,15,6,LOG:3)
Block(-4,14,6,LOG:3)
Block(-5,13,-7,LEAVES:3)
Block(-5,14,-7,LOG:3)
Block(-5,15,-7,LEAVES:3)
Block(-7,11,-5,LEAVES:3)
Block(-7,10,-5,LEAVES:3)
Block(2,7,0,LOG:3)
Block(2,6,0,LOG:3)
Block(-7,15,-5,LEAVES:7)
Block(2,9,0,LEAVES:3)
Block(-7,14,-5,LOG:3)
Block(2,8,0,LEAVES:3)
Block(-7,13,-5,LEAVES:3)
Block(6,10,1,LEAVES:3)
Block(5,13,-1,LEAVES:3)
Block(5,14,-1,LEAVES:3)
Block(1,14,0,LEAVES:3)
Block(5,15,-1,LEAVES:3)
Block(1,13,0,LEAVES:3)
Block(1,12,0,LOG:3)
Block(1,11,0,COCOA:8)
Block(2,14,-1,LEAVES:3)
Block(2,13,-1,LEAVES:3)
Block(2,12,-1,LEAVES:3)
Block(-5,12,-7,LEAVES:3)
Block(0,12,-3,LEAVES:3)
Block(0,13,-3,LEAVES:3)
Block(0,14,-3,LEAVES:3)
Block(-3,12,1,LEAVES:3)
Block(-3,13,1,LEAVES:3)
Block(-3,14,-7,LEAVES:3)
Block(-3,13,-7,LEAVES:3)
Block(-3,14,1,LEAVES:3)
Block(-5,12,0,LEAVES:3)
Block(-5,11,0,LEAVES:3)
Block(4,13,-1,LOG:3)
Block(4,14,-1,LOG:3)
Block(4,12,-1,LEAVES:3)
Block(4,15,-1,LEAVES:3)
Block(2,13,5,LEAVES:3)
Block(2,12,5,LEAVES:3)
Block(-6,-6,-7,LOG:3)
Block(2,11,5,LEAVES:3)
Block(-6,-5,-7,LOG:3)
Block(2,5,0,LOG:3)
Block(3,11,-1,LEAVES:3)
Block(-3,0,-3,LOG:3)
Block(-8,8,9,LEAVES:7)
Block(-3,1,-3,LOG:3)
Block(-8,9,9,LEAVES:7)
Block(7,13,6,LEAVES:7)
Block(7,12,6,LEAVES:3)
Block(7,11,6,LEAVES:3)
Block(3,12,-1,LEAVES:3)
Block(3,13,-1,LEAVES:3)
Block(3,14,-1,LEAVES:3)
Block(-4,16,6,LEAVES:3)
Block(-8,13,-5,LEAVES:3)
Block(-8,15,-5,LEAVES:3)
Block(-8,14,-5,LEAVES:3)
Block(-2,-6,0,LOG:3)
Block(-5,8,10,LEAVES:7)
Block(3,12,7,LEAVES:3)
Block(-2,-3,0,LOG:3)
Block(5,10,2,LEAVES:3)
Block(5,11,2,LEAVES:3)
Block(-2,-5,0,LOG:3)
Block(-2,-4,0,LOG:3)
Block(7,11,8,LEAVES:3)
Block(7,12,8,LEAVES:3)
Block(-8,14,-8,LEAVES:3)
Block(4,14,-3,LEAVES:3)
Block(-5,9,10,LEAVES:3)
Block(-8,16,-8,LEAVES:7)
Block(-8,15,-8,LOG:3)
Block(-3,14,2,LEAVES:3)
Block(-3,14,-8,LEAVES:3)
Block(-3,15,-8,LEAVES:3)
Block(-4,-3,-3,LOG:3)
Block(-4,-4,-3,LOG:3)
Block(-3,0,-2,LOG:3)
Block(-2,-3,-4,LOG:3)
Block(-2,-4,-4,LOG:3)
Block(1,10,1,LEAVES:3)
Block(-2,-1,-4,LOG:3)
Block(1,11,1,LOG:3)
Block(-2,-2,-4,LOG:3)
Block(1,12,1,LOG:3)
Block(1,13,1,LOG:3)
Block(1,14,1,LOG:3)
Block(1,15,1,LEAVES:3)
Block(-5,15,-5,LEAVES:3)
Block(-5,14,-5,LOG:3)
Block(-5,13,-5,LEAVES:3)
Block(-5,12,-5,LEAVES:3)
Block(6,7,0,LEAVES:3)
Block(-6,8,-5,LOG:3)
Block(6,6,0,LEAVES:7)
Block(-6,7,-5,LOG:3)
Block(-2,10,-4,LOG:3)
Block(-6,6,-5,LOG:3)
Block(6,9,0,LEAVES:3)
Block(-2,11,-4,LOG:3)
Block(-6,5,-5,LOG:3)
Block(6,8,0,LEAVES:3)
Block(-2,12,-4,LEAVES:3)
Block(7,14,-6,LEAVES:3)
Block(1,7,-3,LEAVES:3)
Block(9,14,-3,LEAVES:7)
Block(9,13,-3,LEAVES:3)
Block(-7,15,-4,LEAVES:3)
Block(-7,14,-4,LEAVES:3)
Block(-7,13,-4,LEAVES:7)
Block(-2,13,0,LEAVES:3)
Block(-2,12,0,LEAVES:3)
Block(-2,14,0,LEAVES:3)
Block(-4,-6,-1,LOG:3)
Block(-4,-5,-1,LOG:3)
Block(10,12,-4,LEAVES:3)
Block(-9,15,-3,LEAVES:3)
Block(10,13,-4,LEAVES:3)
Block(-9,14,-3,LOG:3)
Block(-9,13,-3,LEAVES:3)
Block(10,14,-4,LEAVES:7)
Block(-1,15,5,LEAVES:3)
Block(-1,16,5,LEAVES:3)
Block(2,12,3,LEAVES:3)
Block(6,15,-2,LEAVES:3)
Block(2,13,3,LEAVES:3)
Block(6,14,-2,LEAVES:3)
Block(-4,14,-3,LEAVES:3)
Block(2,11,3,LEAVES:3)
Block(-4,15,-3,LEAVES:3)
Block(4,13,0,LEAVES:3)
Block(4,14,0,LEAVES:3)
Block(4,11,0,LEAVES:3)
Block(4,12,0,LEAVES:3)
Block(0,8,1,LEAVES:3)
Block(0,7,1,LEAVES:3)
Block(0,9,1,LOG:3)
Block(-6,10,1,LEAVES:7)
Block(-6,12,1,LEAVES:3)
Block(-6,11,1,LOG:3)
Block(5,10,0,LEAVES:3)
Block(5,13,0,LEAVES:3)
Block(5,12,0,LEAVES:3)
Block(-2,9,-6,LEAVES:3)
Block(1,5,-1,LOG:3)
Block(1,6,-1,LOG:3)
Block(-2,0,-6,LOG:3)
Block(1,3,-1,LOG:3)
Block(1,4,-1,LOG:3)
Block(-3,16,4,LEAVES:3)
Block(-3,15,4,LEAVES:3)
Block(6,12,4,LEAVES:3)
Block(-7,11,1,LEAVES:3)
Block(1,10,3,LEAVES:3)
Block(-2,-2,-6,LOG:3)
Block(-2,-1,-6,LOG:3)
Block(1,11,3,LEAVES:3)
Block(-5,13,8,LEAVES:7)
Block(-5,12,8,LEAVES:7)
Block(1,14,3,LEAVES:3)
Block(-2,-3,-6,LOG:3)
Block(-5,11,8,LEAVES:7)
Block(1,13,3,LEAVES:3)
Block(-5,10,8,LEAVES:3)
Block(1,15,3,LEAVES:3)
Block(6,13,4,LEAVES:3)
Block(0,11,-5,LEAVES:7)
Block(-5,14,-3,LEAVES:7)
Block(0,15,1,LEAVES:3)
Block(0,14,1,LEAVES:3)
Block(-6,10,8,LOG:3)
Block(0,13,1,LEAVES:3)
Block(-6,11,8,LOG:3)
Block(0,12,1,LOG:3)
Block(0,11,1,LOG:3)
Block(-6,12,8,LEAVES:7)
Block(0,10,1,LOG:3)
Block(5,14,-5,LEAVES:3)
Block(-6,9,10,LEAVES:3)
Block(5,9,0,LEAVES:3)
Block(5,7,0,LEAVES:3)
Block(5,13,-5,LEAVES:3)
Block(5,13,4,LEAVES:3)
Block(0,7,-5,LEAVES:3)
Block(-1,-1,-2,LOG:3)
Block(7,8,2,LEAVES:7)
Block(-2,8,-4,LEAVES:3)
Block(-2,9,-4,LEAVES:3)
Block(3,13,5,LEAVES:3)
Block(3,12,5,LEAVES:3)
Block(-2,0,-4,LOG:3)
Block(-2,1,-4,LOG:3)
Block(2,10,1,LOG:3)
Block(6,11,8,LEAVES:3)
Block(6,10,8,LEAVES:3)
Block(2,13,1,LEAVES:3)
Block(2,12,1,COCOA:8)
Block(-1,8,-6,LEAVES:3)
Block(6,14,-4,LEAVES:7)
Block(6,15,-4,LEAVES:3)
Block(4,11,7,LEAVES:3)
Block(2,14,1,LEAVES:3)
Block(4,12,7,LEAVES:3)
Block(-5,12,4,LEAVES:7)
Block(8,13,-3,LEAVES:3)
Block(-5,11,4,LEAVES:7)
Block(8,14,-3,LEAVES:3)
Block(-10,14,-9,LEAVES:3)
Block(-4,14,2,LEAVES:3)
Block(-2,-2,-2,LOG:3)
Block(-4,13,2,LOG:3)
Block(-2,-1,-2,LOG:3)
Block(7,15,-4,LOG:3)
Block(7,16,-4,LEAVES:7)
Block(-1,-1,-4,LOG:3)
Block(7,14,-4,LEAVES:3)
Block(-5,-4,-3,LOG:3)
Block(-1,-2,-4,LOG:3)
Block(3,12,3,LOG:3)
Block(9,13,-5,LEAVES:3)
Block(3,11,3,LEAVES:3)
Block(-3,14,6,LEAVES:3)
Block(3,14,3,LEAVES:3)
Block(3,13,3,LOG:3)
Block(9,14,-5,LEAVES:3)
Block(6,13,6,LEAVES:3)
Block(-3,15,6,LEAVES:3)
Block(6,11,6,LEAVES:3)
Block(6,12,6,LOG:3)
Block(-5,15,6,LEAVES:3)
Block(1,12,5,LEAVES:3)
Block(-5,13,6,LEAVES:3)
Block(-5,14,6,LEAVES:3)
Block(-5,11,6,LEAVES:3)
Block(-4,12,0,LEAVES:3)
Block(-5,12,6,LEAVES:3)
Block(-4,13,0,LEAVES:3)
Block(1,13,5,LEAVES:3)
Block(5,9,2,LEAVES:3)
Block(-5,10,6,LEAVES:3)
Block(-3,13,-1,LEAVES:3)
Block(0,7,-3,LEAVES:3)
Block(6,9,2,LEAVES:3)
Block(6,8,2,LEAVES:3)
Block(-6,9,-7,LOG:3)
Block(-6,8,-7,LOG:3)
Block(-6,7,-7,LOG:3)
Block(-6,6,-7,LOG:3)
Block(6,7,2,LEAVES:3)
Block(-2,14,2,LEAVES:3)
Block(-2,15,2,LEAVES:3)
Block(-1,12,-2,LEAVES:3)
Block(-1,13,-2,LEAVES:3)
Block(-2,13,2,LEAVES:3)
Block(0,0,-3,LOG:3)
Block(10,13,-6,LEAVES:3)
Block(-2,1,-2,LOG:3)
Block(-2,0,-2,LOG:3)
Block(-4,0,-4,LOG:3)
Block(-2,12,-2,LEAVES:3)
Block(-4,9,8,LEAVES:7)
Block(-3,-2,-3,LOG:3)
Block(-3,-1,-3,LOG:3)
Block(8,10,5,LEAVES:3)
Block(8,11,5,LEAVES:3)
Block(5,14,-2,LEAVES:3)
Block(5,16,-2,LEAVES:3)
Block(5,15,-2,LOG:3)
Block(-2,17,4,LEAVES:3)
Block(-2,16,4,LOG:3)
Block(-2,15,4,LEAVES:3)
Block(-6,9,6,LEAVES:3)
Block(-1,10,1,LEAVES:3)
Block(-1,11,1,LEAVES:3)
Block(-1,12,1,LEAVES:3)
Block(-1,13,1,LEAVES:3)
Block(-3,14,-2,LEAVES:3)
Block(-1,14,1,LEAVES:3)
Block(-1,1,-3,LOG:3)
Block(-1,0,-3,LOG:3)
Block(-1,9,-3,LEAVES:3)
Block(-1,8,-3,LEAVES:3)
Block(4,13,5,LEAVES:3)
Block(8,15,-5,LEAVES:3)
Block(8,14,-5,LOG:3)
Block(8,13,-5,LEAVES:3)
Block(3,12,2,LEAVES:3)
Block(3,13,2,LEAVES:3)
Block(0,-3,-2,LOG:3)
Block(0,5,-1,LOG:3)
Block(0,4,-1,LOG:3)
Block(0,-4,-2,LOG:3)
Block(-9,15,-8,LEAVES:3)
Block(-9,14,-8,LEAVES:3)
Block(-6,14,-4,LEAVES:3)
Block(0,1,-1,LOG:3)
Block(0,3,-1,LOG:3)
Block(0,2,-1,LOG:3)
Block(0,14,3,LEAVES:3)
Block(0,15,3,LEAVES:3)
Block(0,16,3,LEAVES:3)
Block(-3,-1,-4,LOG:3)
Block(-6,10,6,LEAVES:3)
Block(8,10,6,LEAVES:3)
Block(-3,-2,-4,LOG:3)
Block(8,11,6,LEAVES:3)
Block(-3,-3,-4,LOG:3)
Block(8,12,6,LEAVES:7)
Block(-4,3,-6,LOG:3)
Block(3,7,1,LEAVES:3)
Block(-4,2,-6,LOG:3)
Block(-4,5,-6,LOG:3)
Block(-4,4,-6,LOG:3)
Block(3,9,1,LEAVES:3)
Block(3,8,1,LEAVES:3)
Block(-5,12,1,LOG:3)
Block(-4,6,-6,LOG:3)
Block(-5,13,1,LEAVES:3)
Block(-1,11,-4,LEAVES:3)
Block(-1,10,-4,LEAVES:3)
Block(-1,13,-4,LEAVES:3)
Block(-1,12,-4,LEAVES:3)
Block(-4,14,-8,LEAVES:3)
Block(-4,15,-8,LOG:3)
Block(-4,16,-8,LEAVES:3)
Block(-6,9,8,LEAVES:7)
Block(5,12,6,LEAVES:3)
Block(0,12,5,LEAVES:3)
Block(5,13,6,LEAVES:3)
Block(0,15,5,LEAVES:3)
Block(0,14,5,LEAVES:3)
Block(-3,10,-4,LEAVES:3)
Block(-3,11,-4,LEAVES:3)
Block(-1,9,-5,LEAVES:3)
Block(-1,8,-5,LEAVES:3)
Block(-7,10,7,LEAVES:3)
Block(-2,13,6,LEAVES:3)
Block(-6,-4,-4,LOG:3)
Block(-6,-6,-4,LOG:3)
Block(-6,-5,-4,LOG:3)
Block(7,14,-2,LEAVES:7)
Block(7,13,-2,LEAVES:3)
Block(-1,-5,-6,LOG:3)
Block(-5,11,3,LEAVES:7)
Block(-8,13,-2,LEAVES:7)
Block(-8,14,-2,LEAVES:7)
Block(-5,13,3,LEAVES:7)
Block(-5,12,3,LEAVES:7)
Block(-2,-2,-1,LOG:3)
Block(-2,-3,-1,LOG:3)
Block(-2,-1,-1,LOG:3)
Block(-3,14,-4,LEAVES:3)
Block(-3,15,-4,LEAVES:3)
Block(9,13,-7,LEAVES:3)
Block(-1,6,1,LEAVES:7)
Block(-1,8,1,LOG:3)
Block(-1,7,1,LOG:3)
Block(-1,9,1,LEAVES:3)
Block(-3,-6,0,LOG:3)
Block(8,12,-7,LEAVES:7)
Block(-3,-7,0,LOG:3)
Block(8,13,-7,LEAVES:7)
Block(-7,15,-8,LEAVES:3)
Block(4,9,1,LEAVES:3)
Block(-7,14,-8,LEAVES:3)
Block(-4,14,-4,LEAVES:3)
Block(-4,15,-4,LOG:3)
Block(-4,16,-4,LEAVES:7)
Block(-2,10,-6,LEAVES:3)
Block(2,14,-2,LEAVES:3)
Block(2,12,-2,LEAVES:3)
Block(2,13,-2,LEAVES:3)
Block(8,10,8,LEAVES:3)
Block(7,12,5,LEAVES:3)
Block(2,11,-2,LEAVES:3)
Block(7,11,5,LEAVES:3)
Block(-3,-3,-6,LOG:3)
Block(0,12,-4,LEAVES:3)
Block(0,11,-4,LEAVES:3)
Block(8,11,8,LEAVES:3)
Block(9,10,6,LEAVES:3)
Block(-4,12,7,LEAVES:3)
Block(-4,15,7,LEAVES:3)
Block(-4,13,7,LEAVES:3)
Block(-4,14,7,LEAVES:3)
Block(1,-4,-4,LOG:3)
Block(-5,14,-8,LEAVES:3)
Block(1,-3,-4,LOG:3)
Block(-5,15,-8,LEAVES:3)
Block(-7,14,-6,LEAVES:3)
Block(-6,12,-8,LEAVES:3)
Block(-7,15,-6,LEAVES:7)
Block(-3,0,-6,LOG:3)
Block(-3,1,-6,LOG:3)
Block(-7,10,-6,LOG:3)
Block(-3,2,-6,LOG:3)
Block(-7,11,-6,LOG:3)
Block(-3,3,-6,LOG:3)
Block(-7,12,-6,LEAVES:3)
Block(-9,15,-4,LEAVES:3)
Block(-3,4,-6,LOG:3)
Block(-7,13,-6,LEAVES:3)
Block(-9,14,-4,LEAVES:3)
Block(-4,-4,-6,LOG:3)
Block(0,4,1,LOG:3)
Block(1,9,1,LEAVES:3)
Block(-4,-3,-6,LOG:3)
Block(1,8,1,LEAVES:3)
Block(1,7,1,LOG:3)
Block(2,12,6,LEAVES:3)
Block(1,6,1,LOG:3)
Block(2,11,6,LEAVES:3)
Block(2,-6,-4,LOG:3)
Block(2,-5,-4,LOG:3)
Block(2,-4,-4,LOG:3)
Block(-2,16,6,LEAVES:3)
Block(-2,15,6,LEAVES:3)
Block(-2,14,6,LEAVES:3)
Block(-5,6,-7,LOG:3)
Block(-5,7,-7,LOG:3)
Block(3,13,-2,LEAVES:3)
Block(3,14,-2,LEAVES:3)
Block(-8,11,-6,LEAVES:3)
Block(-8,12,-6,LEAVES:7)
Block(-8,10,-6,LEAVES:7)
Block(-5,5,-7,LOG:3)
Block(-3,12,0,LEAVES:3)
Block(-7,8,-6,LOG:3)
Block(-3,13,0,LEAVES:3)
Block(-3,14,0,LEAVES:3)
Block(-2,8,1,LEAVES:3)
Block(-2,7,1,LEAVES:3)
Block(-7,9,-6,LOG:3)
Block(3,11,0,LOG:3)
Block(3,10,0,LEAVES:3)
Block(3,13,0,LEAVES:3)
Block(3,12,0,LOG:3)
Block(2,-6,-2,LOG:3)
Block(-7,14,-10,LEAVES:3)
Block(-6,16,-6,LEAVES:7)
Block(2,-7,-2,LOG:3)
Block(-7,13,-10,LEAVES:3)
Block(-6,15,-6,LEAVES:7)
Block(2,-5,-2,LOG:3)
Block(-6,12,-6,LOG:3)
Block(4,13,3,LEAVES:3)
Block(-6,11,-6,LOG:3)
Block(4,12,3,LEAVES:3)
Block(-6,14,-6,LEAVES:7)
Block(-6,13,-6,LOG:3)
Block(-8,16,-4,LEAVES:3)
Block(-8,15,-4,LOG:3)
Block(-5,11,1,LEAVES:3)
Block(0,-2,-4,LOG:3)
Block(0,-3,-4,LOG:3)
Block(-8,14,-4,LEAVES:3)
Block(0,-1,-4,LOG:3)
Block(-1,4,-1,LOG:3)
Block(-1,3,-1,LOG:3)
Block(-1,2,-1,LOG:3)
Block(-1,1,-1,LOG:3)
Block(-1,0,-1,LOG:3)
Block(-8,9,8,LEAVES:7)
Block(-3,0,-4,LOG:3)
Block(-3,1,-4,LOG:3)
Block(-3,2,-4,LOG:3)
Block(-2,-6,-8,LOG:3)
Block(-2,-5,-8,LOG:3)
Block(1,5,1,LOG:3)
Block(-10,14,-3,LEAVES:3)
Block(-2,14,-8,LEAVES:3)
Block(-2,13,-8,LEAVES:3)
Block(1,7,-5,LEAVES:3)
Block(2,9,1,LOG:3)
Block(-5,8,-5,COCOA:5)
Block(2,8,1,LOG:3)
Block(2,7,1,LOG:3)
Block(-5,3,-5,LOG:3)
Block(-1,13,3,LEAVES:3)
Block(-5,6,-5,LOG:3)
Block(0,13,-2,LOG:3)
Block(-1,15,3,LEAVES:3)
Block(5,10,8,LEAVES:3)
Block(-1,14,3,LEAVES:3)
Block(-5,4,-5,LOG:3)
Block(-1,17,3,LEAVES:3)
Block(-5,5,-5,LOG:3)
Block(0,14,-2,LEAVES:3)
Block(-1,16,3,LOG:3)
Block(-5,15,-6,LEAVES:7)
Block(-5,14,-6,LEAVES:3)
Block(-5,12,-6,LEAVES:3)
Block(-7,10,9,LEAVES:3)
Block(-6,10,-6,LOG:3)
Block(1,12,-2,COCOA:8)
Block(1,13,-2,LEAVES:3)
Block(1,14,-2,LEAVES:3)

#######################################################################
# +-----------------------------------------------------------------+ #
# |                            BO3 checks                           | #
# +-----------------------------------------------------------------+ #
#######################################################################

BlockCheck(0,-1,-2,GRASS,DIRT,SAND)

#######################################################################
# +-----------------------------------------------------------------+ #
# |                             Branches                            | #
# +-----------------------------------------------------------------+ #
#######################################################################


#######################################################################
# +-----------------------------------------------------------------+ #
# |                             Entities                            | #
# +-----------------------------------------------------------------+ #
#######################################################################


#######################################################################
# +-----------------------------------------------------------------+ #
# |                            Particles                            | #
# +-----------------------------------------------------------------+ #
#######################################################################


#######################################################################
# +-----------------------------------------------------------------+ #
# |                             Spawners                            | #
# +-----------------------------------------------------------------+ #
#######################################################################


#######################################################################
# +-----------------------------------------------------------------+ #
# |                             ModData                             | #
# +-----------------------------------------------------------------+ #
#######################################################################

