
#######################################################################
# +-----------------------------------------------------------------+ #
# |                            BO3 object                           | #
# +-----------------------------------------------------------------+ #
#######################################################################

Author: LordSmellyPants

Description: Converted version of the BO2 JungleRainforest10

Version: 3

SettingsMode: WriteWithoutComments


#######################################################################
# +-----------------------------------------------------------------+ #
# |                          Main settings                          | #
# +-----------------------------------------------------------------+ #
#######################################################################

Tree: true

Frequency: 1

Rarity: 20.0

RotateRandomly: true

SpawnHeight: highestSolidBlock

SpawnHeightOffset: 0

SpawnHeightVariance: 0

##############################
# Height Limits for the BO3. #
##############################

MinHeight: 60

MaxHeight: 81

######################
# Extrusion settings #
######################

ExtrudeMode: None

ExtrudeThroughBlocks: AIR

MaxBranchDepth: 10

ExcludedBiomes: All


#######################################################################
# +-----------------------------------------------------------------+ #
# |                      Source block settings                      | #
# +-----------------------------------------------------------------+ #
#######################################################################

SourceBlocks: STONE:1,STONE:3,STONE:5,DIRT:1,DIRT,SAND,GRASS,DIRT:2,STATIONARY_WATER,HARD_CLAY,STAINED_CLAY,CLAY,SANDSTONE,SAND:1,AIR,STONE,GRAVEL,LONG_GRASS,LONG_GRASS:1,LONG_GRASS:2,DEAD_BUSH,YELLOW_FLOWER,RED_ROSE,BROWN_MUSHROOM,RED_MUSHROOM

MaxPercentageOutsideSourceBlock: 0

OutsideSourceBlock: placeAnyway

IsOTGPlus: false

InheritBO3: 

InheritBO3Rotation: NORTH

OverrideChildSettings: true

OverrideParentHeight: false

CanOverride: false

BranchFrequency: 0

BranchFrequencyGroup: 

MustBeBelowOther: false

MustBeInside: 

CannotBeInside: 

ReplacesBO3: 

CanSpawnOnWater: true

SpawnOnWaterOnly: false

SpawnUnderWater: false

SpawnAtWaterLevel: false

HeightOffset: 0

RemoveAir: true

ReplaceAbove: 

ReplaceBelow: 

ReplaceWithBiomeBlocks: true

ReplaceWithGroundBlock: DIRT

ReplaceWithSurfaceBlock: GRASS

SmoothRadius: 0

SmoothHeightOffset: 0

SmoothStartTop: false

SmoothStartWood: false

SmoothingSurfaceBlock: 

SmoothingGroundBlock: 

BO3Group: 

IsSpawnPoint: false


#######################################################################
# +-----------------------------------------------------------------+ #
# |                              Blocks                             | #
# +-----------------------------------------------------------------+ #
#######################################################################

Block(18,23,-14,LEAVES:3)
Block(18,24,-14,LEAVES:3)
Block(7,1,-13,LOG:3)
Block(7,0,-13,LOG:3)
Block(18,27,-14,LEAVES:3)
Block(18,28,-14,LEAVES:3)
Block(18,25,-14,LEAVES:3)
Block(18,26,-14,LEAVES:3)
Block(9,0,-16,LOG:3)
Block(9,1,-16,LOG:3)
Block(-2,20,-3,LEAVES:3)
Block(-2,15,-3,LEAVES:3)
Block(13,3,-10,LOG:3)
Block(13,2,-10,LOG:3)
Block(-2,18,-3,LEAVES:3)
Block(13,5,-10,LOG:3)
Block(-2,17,-3,LEAVES:3)
Block(13,4,-10,LOG:3)
Block(-2,16,-3,LEAVES:3)
Block(20,21,-17,LEAVES:3)
Block(20,22,-17,LEAVES:3)
Block(23,22,-5,LEAVES:7)
Block(13,1,-10,LOG:3)
Block(0,8,-8,LOG:3)
Block(23,23,-5,LOG:3)
Block(20,20,-17,LEAVES:3)
Block(23,24,-5,LEAVES:3)
Block(0,9,-8,LOG:3)
Block(19,23,-11,LEAVES:3)
Block(11,-4,-13,LOG:3)
Block(11,-7,-13,LOG:3)
Block(11,-1,-13,LOG:3)
Block(11,-3,-13,LOG:3)
Block(11,-2,-13,LOG:3)
Block(15,8,-13,LOG:3)
Block(7,3,-13,LOG:3)
Block(7,2,-13,LOG:3)
Block(18,23,-8,LEAVES:3)
Block(15,9,-13,LOG:3)
Block(22,21,-1,LEAVES:3)
Block(22,22,-1,LOG:3)
Block(22,23,-1,LEAVES:7)
Block(14,25,-13,LEAVES:3)
Block(2,21,-5,LEAVES:3)
Block(15,23,-5,LEAVES:3)
Block(14,26,-13,LEAVES:3)
Block(2,20,-5,LEAVES:3)
Block(17,23,-4,LEAVES:7)
Block(14,27,-13,LEAVES:3)
Block(9,-5,-18,LOG:3)
Block(9,-4,-18,LOG:3)
Block(9,-3,-18,LOG:3)
Block(0,19,-6,LEAVES:3)
Block(0,18,-6,LEAVES:3)
Block(9,-6,-18,LOG:3)
Block(10,3,-15,LOG:3)
Block(17,25,-17,LEAVES:3)
Block(10,2,-15,LOG:3)
Block(10,1,-15,LOG:3)
Block(10,0,-15,LOG:3)
Block(17,24,-17,LEAVES:3)
Block(12,5,-16,LOG:3)
Block(17,22,-4,LEAVES:3)
Block(19,19,-3,LEAVES:3)
Block(17,21,-4,LOG:3)
Block(17,20,-4,LEAVES:3)
Block(-4,21,-10,LEAVES:3)
Block(20,25,-2,LEAVES:3)
Block(0,22,-6,LEAVES:3)
Block(0,21,-6,LEAVES:3)
Block(13,21,-8,LEAVES:3)
Block(20,23,-2,LEAVES:7)
Block(13,22,-8,LEAVES:3)
Block(20,24,-2,LOG:3)
Block(12,4,-16,LOG:3)
Block(12,3,-16,LOG:3)
Block(14,10,-13,LOG:3)
Block(12,2,-16,LOG:3)
Block(12,1,-16,LOG:3)
Block(12,0,-16,LOG:3)
Block(19,23,-3,LEAVES:7)
Block(19,22,-3,LOG:3)
Block(-4,17,-10,LEAVES:3)
Block(19,21,-3,LOG:3)
Block(19,20,-3,LEAVES:3)
Block(-4,19,-10,LEAVES:3)
Block(-4,18,-10,LEAVES:3)
Block(0,21,-10,LEAVES:3)
Block(-5,21,-4,LEAVES:3)
Block(0,20,-10,LEAVES:3)
Block(-1,17,-10,LEAVES:3)
Block(-1,18,-10,LEAVES:3)
Block(19,18,-13,LEAVES:3)
Block(19,19,-13,LEAVES:3)
Block(13,1,-12,LOG:3)
Block(2,20,-3,LEAVES:3)
Block(13,0,-12,LOG:3)
Block(-1,19,-10,LEAVES:3)
Block(15,22,-7,LEAVES:7)
Block(13,2,-12,LOG:3)
Block(15,23,-7,LEAVES:3)
Block(0,16,-10,LEAVES:3)
Block(0,15,-10,LEAVES:3)
Block(19,20,-13,LEAVES:3)
Block(0,18,-10,LEAVES:3)
Block(0,17,-10,LEAVES:3)
Block(-5,16,-4,LEAVES:3)
Block(17,22,-15,LEAVES:3)
Block(-5,17,-4,LEAVES:3)
Block(17,21,-15,LEAVES:3)
Block(-1,21,-10,LEAVES:3)
Block(17,24,-15,LEAVES:3)
Block(17,23,-15,LEAVES:3)
Block(-3,20,-9,LEAVES:3)
Block(23,21,1,LEAVES:7)
Block(17,26,-15,LEAVES:3)
Block(-8,20,-7,LEAVES:3)
Block(23,20,1,LEAVES:7)
Block(17,25,-15,LEAVES:3)
Block(-3,22,-9,LEAVES:3)
Block(17,27,-15,LEAVES:3)
Block(-5,18,-4,LEAVES:3)
Block(-8,19,-7,LEAVES:3)
Block(15,10,-7,LOG:3)
Block(15,11,-7,LOG:3)
Block(15,12,-7,LOG:3)
Block(21,22,-6,LEAVES:3)
Block(17,11,-6,LOG:3)
Block(17,12,-6,LOG:3)
Block(17,13,-6,LOG:3)
Block(12,-6,-12,LOG:3)
Block(-6,19,-8,LEAVES:3)
Block(-2,21,-5,LEAVES:3)
Block(-2,22,-5,LEAVES:3)
Block(12,-4,-12,LOG:3)
Block(-6,17,-8,LEAVES:3)
Block(12,-5,-12,LOG:3)
Block(-6,18,-8,LEAVES:3)
Block(-2,20,-5,LEAVES:3)
Block(-2,18,-5,LEAVES:3)
Block(-2,19,-5,LEAVES:3)
Block(10,-1,-16,LOG:3)
Block(-6,21,-8,LEAVES:3)
Block(10,-3,-16,LOG:3)
Block(-2,14,-5,LEAVES:3)
Block(10,-2,-16,LOG:3)
Block(-2,15,-5,LEAVES:3)
Block(-2,16,-5,LEAVES:3)
Block(12,-1,-12,LOG:3)
Block(-2,17,-5,LEAVES:3)
Block(-7,19,-3,LEAVES:3)
Block(10,0,-17,LOG:3)
Block(13,3,-9,LOG:3)
Block(13,5,-9,LOG:3)
Block(13,4,-9,LOG:3)
Block(-2,13,-5,LEAVES:3)
Block(14,-4,-13,LOG:3)
Block(14,-5,-13,LOG:3)
Block(14,-6,-13,LOG:3)
Block(25,20,-4,LEAVES:7)
Block(25,21,-4,LEAVES:7)
Block(-2,17,-14,LEAVES:3)
Block(-2,19,-14,LEAVES:3)
Block(-2,18,-14,LEAVES:3)
Block(-5,20,-11,LEAVES:3)
Block(21,22,-4,LEAVES:3)
Block(13,7,-14,LOG:3)
Block(13,6,-14,LOG:3)
Block(-3,21,-11,LEAVES:3)
Block(13,9,-14,LOG:3)
Block(5,2,-14,LOG:3)
Block(13,8,-14,LOG:3)
Block(13,3,-14,LOG:3)
Block(14,8,-15,LOG:3)
Block(13,2,-14,LOG:3)
Block(14,9,-15,LOG:3)
Block(13,5,-14,LOG:3)
Block(13,4,-14,LOG:3)
Block(10,-6,-18,LOG:3)
Block(15,23,-3,LEAVES:3)
Block(10,-7,-18,LOG:3)
Block(14,5,-15,LOG:3)
Block(13,1,-14,LOG:3)
Block(14,6,-15,LOG:3)
Block(14,24,-11,LEAVES:3)
Block(10,-5,-18,LOG:3)
Block(14,7,-15,LOG:3)
Block(3,4,-11,LOG:3)
Block(3,5,-11,LOG:3)
Block(3,6,-11,LOG:3)
Block(3,3,-11,LOG:3)
Block(16,8,-8,LOG:3)
Block(2,20,-7,LEAVES:3)
Block(18,17,-12,LEAVES:3)
Block(18,19,-12,LEAVES:3)
Block(18,18,-12,LEAVES:3)
Block(1,15,-8,LEAVES:3)
Block(1,16,-8,LEAVES:3)
Block(16,23,-2,LEAVES:3)
Block(16,24,-2,LOG:3)
Block(1,14,-8,LEAVES:3)
Block(16,25,-2,LEAVES:7)
Block(1,19,-8,LEAVES:3)
Block(1,17,-8,LEAVES:3)
Block(1,18,-8,LEAVES:3)
Block(18,20,-12,LEAVES:3)
Block(16,21,-16,LEAVES:3)
Block(16,22,-16,LEAVES:3)
Block(18,22,-12,LEAVES:3)
Block(16,23,-16,LEAVES:3)
Block(18,21,-12,LEAVES:3)
Block(16,24,-16,LEAVES:3)
Block(18,24,-12,LEAVES:3)
Block(16,25,-16,LEAVES:3)
Block(18,23,-12,LEAVES:3)
Block(16,26,-16,LEAVES:3)
Block(16,27,-16,LEAVES:3)
Block(18,25,-12,LEAVES:3)
Block(22,20,1,LEAVES:7)
Block(22,21,1,LEAVES:7)
Block(14,5,-9,LOG:3)
Block(14,6,-9,LOG:3)
Block(14,3,-9,LOG:3)
Block(14,4,-9,LOG:3)
Block(17,20,-15,LEAVES:3)
Block(23,21,-1,LEAVES:3)
Block(23,22,-1,LEAVES:7)
Block(23,20,-1,LEAVES:3)
Block(14,9,-9,LOG:3)
Block(17,22,0,LEAVES:7)
Block(14,7,-9,LOG:3)
Block(14,8,-9,LOG:3)
Block(12,0,-12,LOG:3)
Block(11,-1,-15,LOG:3)
Block(11,-4,-15,LOG:3)
Block(11,-5,-15,LOG:3)
Block(11,-2,-15,LOG:3)
Block(11,-3,-15,LOG:3)
Block(14,24,-5,LEAVES:3)
Block(18,21,-10,LEAVES:3)
Block(18,22,-10,LEAVES:3)
Block(9,0,-14,LOG:3)
Block(17,17,-13,LOG:3)
Block(9,2,-14,LOG:3)
Block(17,18,-13,LOG:3)
Block(9,1,-14,LOG:3)
Block(17,19,-13,LOG:3)
Block(5,2,-12,LOG:3)
Block(5,4,-12,LOG:3)
Block(12,-1,-14,LOG:3)
Block(0,10,-8,LOG:3)
Block(0,11,-8,LOG:3)
Block(12,-5,-14,LOG:3)
Block(17,24,-2,LEAVES:7)
Block(12,-4,-14,LOG:3)
Block(12,-3,-14,LOG:3)
Block(11,0,-13,LOG:3)
Block(12,-2,-14,LOG:3)
Block(0,19,-8,LEAVES:3)
Block(8,1,-16,LOG:3)
Block(8,0,-16,LOG:3)
Block(-3,19,-13,LEAVES:3)
Block(12,21,-4,LEAVES:3)
Block(12,22,-4,LOG:3)
Block(12,23,-4,LEAVES:3)
Block(16,19,-16,LEAVES:3)
Block(-4,20,-12,LEAVES:3)
Block(0,21,-8,LEAVES:3)
Block(-1,21,-3,LEAVES:3)
Block(11,-2,-17,LOG:3)
Block(-1,20,-3,LEAVES:3)
Block(11,-1,-17,LOG:3)
Block(0,20,-8,LEAVES:3)
Block(20,20,-4,LEAVES:3)
Block(20,21,-4,LEAVES:3)
Block(14,24,-3,LEAVES:7)
Block(7,-1,-15,LOG:3)
Block(7,1,-15,LOG:3)
Block(15,9,-15,LOG:3)
Block(7,0,-15,LOG:3)
Block(15,7,-15,LOG:3)
Block(7,2,-15,LOG:3)
Block(15,8,-15,LOG:3)
Block(16,20,-16,LEAVES:3)
Block(2,6,-11,LOG:3)
Block(2,5,-11,LOG:3)
Block(-4,19,-12,LEAVES:3)
Block(13,24,-4,LEAVES:3)
Block(2,7,-11,LOG:3)
Block(13,23,-4,LOG:3)
Block(13,22,-4,LEAVES:3)
Block(2,4,-11,LOG:3)
Block(19,23,-1,LEAVES:3)
Block(0,7,-10,LOG:3)
Block(0,6,-10,LOG:3)
Block(-3,20,-13,LEAVES:3)
Block(0,9,-10,LOG:3)
Block(0,8,-10,LOG:3)
Block(6,3,-13,LOG:3)
Block(-1,9,-9,LOG:3)
Block(6,4,-13,LOG:3)
Block(-1,8,-9,LOG:3)
Block(15,25,-17,LEAVES:3)
Block(8,-1,-14,LOG:3)
Block(15,24,-17,LEAVES:3)
Block(17,20,-13,LOG:3)
Block(17,21,-13,LOG:3)
Block(17,22,-13,LOG:3)
Block(17,23,-13,LOG:3)
Block(17,24,-13,LOG:3)
Block(17,25,-13,LEAVES:3)
Block(12,7,-14,LOG:3)
Block(17,26,-13,LEAVES:3)
Block(6,1,-13,LOG:3)
Block(17,27,-13,LEAVES:3)
Block(1,9,-10,LOG:3)
Block(17,28,-13,LEAVES:3)
Block(1,8,-10,LOG:3)
Block(1,7,-10,LOG:3)
Block(1,6,-10,LOG:3)
Block(1,5,-10,LOG:3)
Block(4,4,-12,LOG:3)
Block(4,5,-12,LOG:3)
Block(4,2,-12,LOG:3)
Block(4,3,-12,LOG:3)
Block(12,6,-14,LOG:3)
Block(12,5,-14,LOG:3)
Block(12,4,-14,LOG:3)
Block(12,3,-14,LOG:3)
Block(12,2,-14,LOG:3)
Block(12,1,-14,LOG:3)
Block(12,0,-14,LOG:3)
Block(19,19,-17,LEAVES:3)
Block(-1,17,-14,LEAVES:3)
Block(-2,21,-11,LEAVES:3)
Block(15,9,-8,LOG:3)
Block(-1,18,-14,LEAVES:3)
Block(-1,19,-14,LEAVES:3)
Block(16,9,-14,LOG:3)
Block(6,4,-12,LOG:3)
Block(-7,16,-9,LEAVES:3)
Block(-7,15,-9,LEAVES:3)
Block(11,0,-15,LOG:3)
Block(19,21,-17,LEAVES:3)
Block(19,22,-17,LEAVES:3)
Block(19,23,-17,LEAVES:3)
Block(8,-1,-16,LOG:3)
Block(19,24,-17,LEAVES:3)
Block(11,4,-15,LOG:3)
Block(11,3,-15,LOG:3)
Block(11,5,-15,LOG:3)
Block(19,20,-17,LEAVES:3)
Block(8,2,-14,LOG:3)
Block(-4,19,-7,LEAVES:3)
Block(-4,18,-7,LOG:3)
Block(6,2,-12,LOG:3)
Block(6,3,-12,LOG:3)
Block(6,1,-12,LOG:3)
Block(12,-2,-15,LOG:3)
Block(12,-1,-15,LOG:3)
Block(1,21,-5,LEAVES:3)
Block(-8,19,-3,LEAVES:3)
Block(12,-5,-15,LOG:3)
Block(-8,18,-3,LEAVES:3)
Block(12,-4,-15,LOG:3)
Block(12,-3,-15,LOG:3)
Block(-4,20,-7,LEAVES:3)
Block(-4,22,-7,LEAVES:3)
Block(-4,21,-7,LEAVES:3)
Block(-2,20,-9,LEAVES:3)
Block(17,20,-12,LEAVES:7)
Block(17,22,-12,LEAVES:3)
Block(17,23,-12,LEAVES:3)
Block(17,24,-12,LEAVES:3)
Block(17,25,-12,LEAVES:3)
Block(14,4,-10,LOG:3)
Block(17,26,-12,LEAVES:3)
Block(14,3,-10,LOG:3)
Block(21,23,-2,LEAVES:7)
Block(17,27,-12,LEAVES:3)
Block(14,2,-10,LOG:3)
Block(16,21,-4,LEAVES:3)
Block(14,6,-10,LOG:3)
Block(16,23,-4,LEAVES:3)
Block(21,24,-2,LEAVES:7)
Block(14,5,-10,LOG:3)
Block(-2,22,-9,LEAVES:3)
Block(16,22,-4,LOG:3)
Block(24,22,0,LEAVES:7)
Block(24,20,0,LEAVES:7)
Block(24,21,0,LEAVES:7)
Block(-2,19,-9,LEAVES:3)
Block(13,23,-3,LEAVES:7)
Block(17,17,-12,LEAVES:3)
Block(17,18,-12,LEAVES:3)
Block(-2,12,-9,LOG:3)
Block(17,19,-12,LEAVES:3)
Block(-2,13,-9,LOG:3)
Block(-2,11,-9,LOG:3)
Block(16,24,-4,LEAVES:7)
Block(3,19,-5,LEAVES:3)
Block(3,18,-5,LEAVES:3)
Block(16,22,1,LEAVES:7)
Block(15,26,-16,LEAVES:3)
Block(-3,14,-3,LEAVES:3)
Block(15,25,-16,LEAVES:3)
Block(-3,16,-3,LEAVES:3)
Block(9,-1,-13,LOG:3)
Block(-3,15,-3,LEAVES:3)
Block(-3,18,-3,LEAVES:3)
Block(-3,17,-3,LEAVES:3)
Block(18,20,-4,LOG:3)
Block(18,21,-4,LEAVES:3)
Block(-6,16,-10,LEAVES:3)
Block(-6,17,-10,LEAVES:3)
Block(-3,18,-10,LEAVES:3)
Block(-6,18,-10,LEAVES:3)
Block(-3,19,-10,LEAVES:3)
Block(-6,14,-10,LEAVES:3)
Block(-6,15,-10,LEAVES:3)
Block(-6,20,-3,LEAVES:3)
Block(16,22,-6,LEAVES:3)
Block(16,23,-6,LEAVES:3)
Block(13,-3,-14,LOG:3)
Block(13,-4,-14,LOG:3)
Block(17,19,-10,LEAVES:3)
Block(13,-5,-14,LOG:3)
Block(16,15,-6,LOG:3)
Block(18,19,-4,LOG:3)
Block(13,-2,-14,LOG:3)
Block(18,17,-4,LOG:3)
Block(18,18,-4,LOG:3)
Block(18,16,-4,LOG:3)
Block(15,23,-1,LEAVES:3)
Block(-3,21,-10,LEAVES:3)
Block(-3,22,-10,LEAVES:3)
Block(3,19,-3,LEAVES:3)
Block(3,18,-3,LEAVES:3)
Block(3,17,-3,LEAVES:3)
Block(17,24,-10,LEAVES:3)
Block(9,-1,-15,LOG:3)
Block(17,23,-10,LEAVES:3)
Block(17,22,-10,LEAVES:3)
Block(17,21,-10,LEAVES:3)
Block(17,20,-10,LEAVES:3)
Block(24,22,-5,LOG:3)
Block(24,23,-5,LEAVES:3)
Block(9,-3,-15,LOG:3)
Block(9,-4,-15,LOG:3)
Block(24,21,-5,LEAVES:7)
Block(15,22,0,LEAVES:7)
Block(22,24,-5,LEAVES:7)
Block(22,22,-5,LEAVES:7)
Block(22,23,-5,LOG:3)
Block(-5,15,-9,LEAVES:3)
Block(-2,20,-13,LEAVES:3)
Block(-5,19,-9,LEAVES:3)
Block(-5,21,-9,LEAVES:3)
Block(-5,20,-9,LEAVES:3)
Block(16,27,-13,LEAVES:3)
Block(16,26,-13,LEAVES:3)
Block(16,25,-13,LOG:3)
Block(16,24,-13,LOG:3)
Block(16,23,-13,LOG:3)
Block(14,24,-17,LEAVES:3)
Block(16,22,-13,LOG:3)
Block(-4,14,-9,LEAVES:3)
Block(16,21,-13,LOG:3)
Block(16,20,-13,LOG:3)
Block(-4,13,-9,LEAVES:3)
Block(-4,18,-9,LEAVES:3)
Block(-4,19,-9,LEAVES:3)
Block(-4,16,-9,LEAVES:3)
Block(-4,17,-9,LEAVES:3)
Block(-1,19,-5,LEAVES:3)
Block(-9,19,-7,LEAVES:3)
Block(16,13,-6,LOG:3)
Block(16,14,-6,LOG:3)
Block(16,11,-6,LOG:3)
Block(16,12,-6,LOG:3)
Block(12,2,-10,LOG:3)
Block(-1,22,-5,LEAVES:3)
Block(16,19,-13,LOG:3)
Block(12,-1,-17,LOG:3)
Block(16,18,-13,LOG:3)
Block(-1,20,-5,LEAVES:3)
Block(16,17,-13,LOG:3)
Block(16,16,-13,LOG:3)
Block(16,15,-13,LOG:3)
Block(16,14,-13,LOG:3)
Block(-4,21,-9,LEAVES:3)
Block(16,13,-13,LOG:3)
Block(16,12,-13,LOG:3)
Block(16,11,-13,LOG:3)
Block(-4,20,-9,LEAVES:3)
Block(12,4,-10,LOG:3)
Block(12,3,-10,LOG:3)
Block(1,19,-3,LEAVES:3)
Block(15,19,-14,LOG:3)
Block(15,17,-14,LOG:3)
Block(16,26,-11,LEAVES:3)
Block(15,18,-14,LOG:3)
Block(16,27,-11,LEAVES:3)
Block(15,15,-14,LOG:3)
Block(16,24,-11,LEAVES:3)
Block(15,16,-14,LOG:3)
Block(16,25,-11,LEAVES:3)
Block(15,13,-14,LOG:3)
Block(-8,20,-5,LEAVES:3)
Block(16,22,-11,LEAVES:3)
Block(15,14,-14,LOG:3)
Block(16,23,-11,LEAVES:3)
Block(16,20,-11,LEAVES:3)
Block(15,12,-14,LOG:3)
Block(16,21,-11,LEAVES:3)
Block(-8,21,-5,LEAVES:3)
Block(17,20,-6,LEAVES:3)
Block(17,21,-6,LEAVES:3)
Block(17,22,-6,LEAVES:7)
Block(-3,20,-5,LEAVES:3)
Block(17,23,-6,LEAVES:7)
Block(-3,21,-5,LEAVES:3)
Block(16,12,-8,LOG:3)
Block(16,11,-8,LOG:3)
Block(-9,18,-5,LEAVES:3)
Block(-9,19,-5,LEAVES:3)
Block(-1,19,-7,LEAVES:3)
Block(16,13,-8,LOG:3)
Block(16,19,-11,LEAVES:3)
Block(16,18,-11,LEAVES:3)
Block(15,22,-8,LOG:3)
Block(15,21,-8,LEAVES:3)
Block(-1,22,-7,LEAVES:3)
Block(-1,21,-7,LEAVES:3)
Block(15,26,-14,LEAVES:3)
Block(-1,20,-7,LEAVES:3)
Block(15,23,-8,LEAVES:3)
Block(15,27,-14,LEAVES:3)
Block(17,14,-6,LOG:3)
Block(-3,15,-5,LEAVES:3)
Block(15,24,-14,LOG:3)
Block(17,15,-6,LOG:3)
Block(-3,16,-5,LEAVES:3)
Block(17,16,-6,LOG:3)
Block(15,22,-14,LEAVES:7)
Block(15,23,-14,LOG:3)
Block(-3,19,-5,LEAVES:3)
Block(15,20,-14,LOG:3)
Block(-3,17,-5,LEAVES:3)
Block(-3,18,-5,LEAVES:3)
Block(18,22,-6,LEAVES:3)
Block(-9,20,-5,LEAVES:3)
Block(18,21,-6,LOG:3)
Block(18,20,-6,LOG:11)
Block(-7,20,-7,LEAVES:3)
Block(-7,21,-7,LEAVES:3)
Block(15,11,-8,LOG:3)
Block(25,20,-5,LOG:3)
Block(20,22,-15,LEAVES:3)
Block(15,10,-8,LOG:3)
Block(20,21,-15,LEAVES:3)
Block(25,22,-5,LEAVES:7)
Block(25,21,-5,LOG:3)
Block(20,23,-15,LEAVES:3)
Block(-10,17,-4,LEAVES:3)
Block(8,-4,-18,LOG:3)
Block(18,19,-6,LEAVES:3)
Block(0,20,-3,LEAVES:3)
Block(18,17,-6,LOG:3)
Block(0,21,-3,LEAVES:3)
Block(18,16,-6,LOG:3)
Block(18,15,-6,LOG:3)
Block(18,14,-6,LOG:3)
Block(-10,18,-4,LEAVES:3)
Block(19,24,-13,LEAVES:3)
Block(19,21,-13,LEAVES:3)
Block(19,25,-13,LEAVES:3)
Block(-6,18,-7,LEAVES:3)
Block(26,21,-5,LEAVES:7)
Block(-6,19,-7,LEAVES:3)
Block(26,20,-5,LEAVES:7)
Block(2,19,-3,LEAVES:3)
Block(-6,17,-7,LEAVES:3)
Block(-6,15,-7,LEAVES:3)
Block(-6,21,-7,LEAVES:3)
Block(1,20,-3,LEAVES:3)
Block(18,21,-18,LEAVES:3)
Block(10,-4,-14,LOG:3)
Block(-5,13,-7,LEAVES:3)
Block(10,-5,-14,LOG:3)
Block(-5,14,-7,LEAVES:3)
Block(-5,15,-7,LEAVES:3)
Block(-5,16,-7,LEAVES:3)
Block(-5,17,-7,LEAVES:3)
Block(-2,20,-7,LOG:3)
Block(-5,18,-7,LEAVES:3)
Block(-5,19,-7,LEAVES:3)
Block(-2,22,-7,LEAVES:3)
Block(-2,21,-7,LEAVES:3)
Block(21,20,0,LEAVES:3)
Block(-2,17,-7,LOG:3)
Block(-5,20,-7,LEAVES:3)
Block(10,-1,-14,LOG:3)
Block(-2,16,-7,LOG:3)
Block(-5,21,-7,LEAVES:3)
Block(14,26,-15,LEAVES:3)
Block(10,-2,-14,LOG:3)
Block(-2,19,-7,LOG:3)
Block(-5,22,-7,LEAVES:3)
Block(10,-3,-14,LOG:3)
Block(-2,18,-7,LOG:3)
Block(19,20,-6,LEAVES:3)
Block(14,25,-15,LEAVES:3)
Block(19,21,-6,LEAVES:3)
Block(21,23,0,LEAVES:7)
Block(21,22,0,LOG:3)
Block(14,23,-8,LEAVES:3)
Block(21,21,0,LEAVES:3)
Block(14,22,-8,LEAVES:3)
Block(19,26,-15,LEAVES:3)
Block(19,25,-15,LEAVES:3)
Block(19,24,-15,LEAVES:3)
Block(-2,13,-7,LOG:3)
Block(-2,12,-7,LOG:3)
Block(-2,15,-7,LOG:3)
Block(-2,14,-7,LOG:3)
Block(-5,11,-7,LEAVES:3)
Block(-5,12,-7,LEAVES:3)
Block(14,11,-15,LOG:3)
Block(14,10,-15,LOG:3)
Block(18,26,-16,LEAVES:3)
Block(18,25,-16,LEAVES:3)
Block(-3,14,-7,LOG:3)
Block(-3,13,-7,LOG:3)
Block(0,20,-12,LEAVES:3)
Block(16,23,-8,LEAVES:3)
Block(16,22,-8,LEAVES:3)
Block(-6,21,-5,LEAVES:3)
Block(0,19,-12,LEAVES:3)
Block(-3,21,-7,LEAVES:3)
Block(-1,21,-12,LEAVES:3)
Block(17,22,-8,LEAVES:3)
Block(-1,20,-12,LEAVES:3)
Block(17,24,-8,LEAVES:3)
Block(17,23,-8,LOG:3)
Block(-3,22,-7,LEAVES:3)
Block(-7,21,-5,LEAVES:3)
Block(15,25,-12,LEAVES:3)
Block(15,27,-12,LEAVES:3)
Block(15,26,-12,LEAVES:3)
Block(9,-4,-17,LOG:3)
Block(-3,18,-7,LOG:3)
Block(9,-3,-17,LOG:3)
Block(-3,17,-7,LOG:3)
Block(9,-2,-17,LOG:3)
Block(-3,16,-7,LOG:3)
Block(9,-1,-17,LOG:3)
Block(-3,15,-7,LOG:3)
Block(15,8,-8,LOG:3)
Block(15,7,-8,LOG:3)
Block(15,6,-8,LOG:3)
Block(9,-5,-17,LOG:3)
Block(15,5,-8,LOG:3)
Block(-3,19,-14,LEAVES:3)
Block(-3,17,-14,LEAVES:3)
Block(-3,18,-14,LEAVES:3)
Block(12,22,-3,LEAVES:7)
Block(-4,20,-11,LEAVES:3)
Block(-4,21,-11,LEAVES:3)
Block(15,24,-11,LEAVES:3)
Block(15,23,-11,LEAVES:3)
Block(15,26,-11,LEAVES:3)
Block(15,25,-11,LEAVES:3)
Block(14,11,-14,LOG:3)
Block(14,10,-14,LOG:3)
Block(14,13,-14,LOG:3)
Block(14,12,-14,LOG:3)
Block(4,17,-3,LEAVES:3)
Block(-4,17,-11,LEAVES:3)
Block(19,22,-2,LEAVES:7)
Block(-3,13,-8,LOG:3)
Block(19,21,-2,LEAVES:3)
Block(10,2,-14,LOG:3)
Block(-3,14,-8,LOG:3)
Block(10,1,-14,LOG:3)
Block(-3,15,-8,LOG:3)
Block(19,24,-2,LEAVES:7)
Block(-5,22,-5,LEAVES:3)
Block(19,23,-2,LOG:3)
Block(10,-5,-15,LOG:3)
Block(10,0,-14,LOG:3)
Block(15,-7,-13,LOG:3)
Block(10,-2,-15,LOG:3)
Block(10,-1,-15,LOG:3)
Block(17,24,-3,LEAVES:7)
Block(10,-4,-15,LOG:3)
Block(17,23,-3,LEAVES:7)
Block(10,-3,-15,LOG:3)
Block(0,19,-7,LEAVES:3)
Block(-5,18,-5,LEAVES:3)
Block(7,2,-12,LOG:3)
Block(-5,15,-5,LEAVES:3)
Block(-5,14,-5,LEAVES:3)
Block(-5,13,-5,LEAVES:3)
Block(-3,20,-8,LOG:3)
Block(-3,21,-8,LEAVES:3)
Block(-1,10,-9,LOG:3)
Block(-3,22,-8,LEAVES:3)
Block(-1,11,-9,LOG:3)
Block(-1,12,-9,LOG:3)
Block(9,0,-17,LOG:3)
Block(5,3,-11,LOG:3)
Block(5,4,-11,LOG:3)
Block(-5,19,-5,LEAVES:3)
Block(-7,21,-4,LEAVES:3)
Block(7,-1,-14,LOG:3)
Block(-7,20,-4,LEAVES:3)
Block(11,-1,-12,LOG:3)
Block(-5,21,-5,LEAVES:3)
Block(0,7,-9,LOG:3)
Block(0,6,-9,LOG:3)
Block(18,22,-9,LEAVES:3)
Block(0,9,-9,LOG:3)
Block(-3,16,-8,LOG:3)
Block(0,8,-9,LOG:3)
Block(-3,17,-8,LOG:3)
Block(18,21,-15,LEAVES:3)
Block(-3,18,-8,LOG:3)
Block(-3,19,-8,LOG:3)
Block(18,24,-15,LEAVES:3)
Block(18,25,-15,LEAVES:3)
Block(18,22,-15,LEAVES:3)
Block(18,23,-15,LEAVES:3)
Block(-1,20,-9,LEAVES:3)
Block(18,26,-15,LEAVES:3)
Block(-1,21,-9,LEAVES:3)
Block(18,27,-15,LEAVES:3)
Block(-1,19,-9,LEAVES:3)
Block(23,23,-6,LEAVES:7)
Block(15,7,-14,LOG:3)
Block(15,8,-14,LOG:3)
Block(15,9,-14,LOG:3)
Block(17,21,-5,LEAVES:3)
Block(17,22,-5,LEAVES:7)
Block(11,-6,-14,LOG:3)
Block(18,18,-13,LEAVES:3)
Block(18,17,-13,LEAVES:3)
Block(18,19,-13,LEAVES:3)
Block(14,-5,-14,LOG:3)
Block(20,24,-1,LEAVES:3)
Block(14,-7,-14,LOG:3)
Block(14,-6,-14,LOG:3)
Block(11,-2,-14,LOG:3)
Block(0,21,-5,LEAVES:3)
Block(11,-1,-14,LOG:3)
Block(11,-4,-14,LOG:3)
Block(11,-3,-14,LOG:3)
Block(20,23,-1,LEAVES:3)
Block(17,13,-5,LOG:3)
Block(17,14,-5,LOG:3)
Block(17,15,-5,LOG:3)
Block(17,16,-5,LOG:3)
Block(0,22,-5,LEAVES:3)
Block(17,17,-5,LOG:3)
Block(17,18,-5,LOG:3)
Block(10,2,-16,LOG:3)
Block(18,21,-13,LEAVES:3)
Block(10,1,-16,LOG:3)
Block(10,0,-16,LOG:3)
Block(21,21,-5,LEAVES:3)
Block(18,23,-13,LEAVES:3)
Block(18,22,-13,LEAVES:3)
Block(21,22,-5,LOG:3)
Block(-4,14,-3,LEAVES:3)
Block(18,25,-13,LEAVES:3)
Block(-4,15,-3,LEAVES:3)
Block(18,24,-13,LEAVES:3)
Block(-4,16,-3,LEAVES:3)
Block(-4,17,-3,LEAVES:3)
Block(18,26,-13,LEAVES:3)
Block(-4,18,-3,LEAVES:3)
Block(-2,21,-4,LEAVES:3)
Block(-6,19,-9,LEAVES:3)
Block(-6,18,-9,LEAVES:3)
Block(-6,17,-9,LEAVES:3)
Block(21,23,-5,LEAVES:3)
Block(-6,16,-9,LEAVES:3)
Block(-6,15,-9,LEAVES:3)
Block(-6,14,-9,LEAVES:3)
Block(-2,18,-4,LEAVES:3)
Block(-2,19,-4,LEAVES:3)
Block(14,24,-12,LEAVES:3)
Block(14,25,-12,LEAVES:3)
Block(23,23,-4,LEAVES:3)
Block(17,23,-16,LEAVES:3)
Block(17,22,-16,LEAVES:3)
Block(17,25,-16,LEAVES:3)
Block(17,24,-16,LEAVES:3)
Block(17,27,-16,LEAVES:3)
Block(17,26,-16,LEAVES:3)
Block(19,24,-12,LEAVES:3)
Block(19,18,-4,LOG:3)
Block(19,19,-4,LOG:3)
Block(13,2,-11,LOG:3)
Block(13,1,-11,LOG:3)
Block(13,4,-11,LOG:3)
Block(13,3,-11,LOG:3)
Block(13,0,-11,LOG:3)
Block(19,20,-4,LOG:3)
Block(0,19,-5,LEAVES:3)
Block(19,22,-4,LEAVES:3)
Block(-5,20,-3,LEAVES:3)
Block(19,23,-4,LEAVES:7)
Block(17,19,-16,LEAVES:3)
Block(2,21,-4,LEAVES:3)
Block(2,20,-4,LEAVES:3)
Block(20,22,-16,LEAVES:3)
Block(20,23,-16,LEAVES:3)
Block(20,20,-16,LEAVES:3)
Block(20,21,-16,LEAVES:3)
Block(-10,17,-5,LEAVES:3)
Block(17,21,-16,LEAVES:3)
Block(-10,18,-5,LEAVES:3)
Block(17,20,-16,LEAVES:3)
Block(2,7,-10,LOG:3)
Block(17,20,-14,LOG:3)
Block(2,6,-10,LOG:3)
Block(17,21,-14,LOG:3)
Block(17,22,-14,LOG:3)
Block(17,23,-14,LOG:3)
Block(17,24,-14,LOG:3)
Block(17,25,-14,LOG:3)
Block(2,5,-10,LOG:3)
Block(17,26,-14,LEAVES:3)
Block(2,4,-10,LOG:3)
Block(17,27,-14,LEAVES:3)
Block(17,28,-14,LEAVES:3)
Block(14,6,-8,LOG:3)
Block(14,7,-8,LOG:3)
Block(14,5,-8,LOG:3)
Block(0,21,-9,LEAVES:3)
Block(-1,9,-8,LOG:3)
Block(20,21,-5,LOG:3)
Block(14,23,-4,LEAVES:3)
Block(20,20,-5,LEAVES:3)
Block(20,23,-5,LEAVES:7)
Block(14,25,-4,LEAVES:3)
Block(20,22,-5,LEAVES:3)
Block(14,24,-4,LOG:3)
Block(16,25,-17,LEAVES:3)
Block(16,24,-17,LEAVES:3)
Block(20,20,1,LEAVES:3)
Block(13,23,-5,LEAVES:3)
Block(17,15,-14,LOG:3)
Block(17,16,-14,LOG:3)
Block(17,17,-14,LOG:3)
Block(17,18,-14,LOG:3)
Block(17,19,-14,LOG:3)
Block(20,21,1,LEAVES:7)
Block(14,8,-8,LOG:3)
Block(14,9,-8,LOG:3)
Block(4,3,-13,LOG:3)
Block(4,4,-13,LOG:3)
Block(4,2,-13,LOG:3)
Block(8,-1,-13,LOG:3)
Block(12,0,-13,LOG:3)
Block(9,1,-13,LOG:3)
Block(9,0,-13,LOG:3)
Block(14,4,-14,LOG:3)
Block(15,24,-2,LEAVES:7)
Block(14,-6,-12,LOG:3)
Block(14,-7,-12,LOG:3)
Block(14,9,-14,LOG:3)
Block(1,17,-9,LEAVES:3)
Block(1,16,-9,LEAVES:3)
Block(16,22,-1,LEAVES:3)
Block(1,15,-9,LEAVES:3)
Block(16,23,-1,LOG:3)
Block(14,-5,-12,LOG:3)
Block(1,14,-9,LEAVES:3)
Block(16,24,-1,LEAVES:7)
Block(14,5,-14,LOG:3)
Block(14,6,-14,LOG:3)
Block(14,7,-14,LOG:3)
Block(11,0,-12,LOG:3)
Block(1,18,-9,LEAVES:3)
Block(3,5,-10,LOG:3)
Block(3,6,-10,LOG:3)
Block(1,13,-9,LEAVES:3)
Block(3,4,-10,LOG:3)
Block(22,23,-4,LEAVES:7)
Block(-4,19,-13,LEAVES:3)
Block(-4,18,-13,LEAVES:3)
Block(16,7,-7,LOG:3)
Block(16,8,-7,LOG:3)
Block(16,9,-7,LOG:3)
Block(12,-5,-13,LOG:3)
Block(-3,21,-12,LEAVES:3)
Block(12,-6,-13,LOG:3)
Block(-3,20,-12,LEAVES:3)
Block(10,-1,-17,LOG:3)
Block(0,11,-9,LOG:3)
Block(10,-5,-17,LOG:3)
Block(12,-3,-13,LOG:3)
Block(12,-4,-13,LOG:3)
Block(17,23,-1,LEAVES:3)
Block(10,-3,-17,LOG:3)
Block(12,-1,-13,LOG:3)
Block(0,10,-9,LOG:3)
Block(0,19,-9,LEAVES:3)
Block(0,18,-9,LEAVES:3)
Block(0,17,-9,LEAVES:3)
Block(-5,18,-10,LEAVES:3)
Block(-5,17,-10,LEAVES:3)
Block(-5,16,-10,LEAVES:3)
Block(-5,15,-10,LEAVES:3)
Block(-5,19,-10,LEAVES:3)
Block(-5,14,-10,LEAVES:3)
Block(16,24,-3,LEAVES:7)
Block(1,15,-7,LEAVES:3)
Block(16,23,-3,LOG:3)
Block(1,18,-7,LEAVES:3)
Block(6,2,-14,LOG:3)
Block(1,16,-7,LEAVES:3)
Block(6,3,-14,LOG:3)
Block(1,17,-7,LEAVES:3)
Block(-2,17,-15,LEAVES:3)
Block(22,22,-2,LEAVES:7)
Block(12,7,-15,LOG:3)
Block(12,6,-15,LOG:3)
Block(-5,21,-10,LEAVES:3)
Block(6,1,-14,LOG:3)
Block(-5,20,-10,LEAVES:3)
Block(1,7,-11,LOG:3)
Block(1,6,-11,LOG:3)
Block(1,5,-11,LOG:3)
Block(4,5,-11,LOG:3)
Block(15,24,-4,LEAVES:3)
Block(15,23,-4,LOG:3)
Block(4,3,-11,LOG:3)
Block(15,22,-4,LEAVES:3)
Block(4,4,-11,LOG:3)
Block(12,5,-15,LOG:3)
Block(12,1,-15,LOG:3)
Block(12,0,-15,LOG:3)
Block(12,22,-5,LEAVES:3)
Block(7,0,-14,LOG:3)
Block(16,11,-15,LOG:3)
Block(16,12,-15,LOG:3)
Block(16,13,-15,LOG:3)
Block(16,14,-15,LOG:3)
Block(16,15,-15,LOG:3)
Block(16,16,-15,LOG:3)
Block(17,21,-3,LEAVES:3)
Block(9,1,-15,LOG:3)
Block(9,0,-15,LOG:3)
Block(13,6,-15,LOG:3)
Block(5,1,-13,LOG:3)
Block(9,2,-15,LOG:3)
Block(13,5,-15,LOG:3)
Block(5,2,-13,LOG:3)
Block(13,8,-15,LOG:3)
Block(5,3,-13,LOG:3)
Block(13,7,-15,LOG:3)
Block(11,-1,-16,LOG:3)
Block(13,2,-15,LOG:3)
Block(0,20,-7,LEAVES:3)
Block(11,-2,-16,LOG:3)
Block(13,1,-15,LOG:3)
Block(-1,20,-2,LEAVES:3)
Block(0,21,-7,LEAVES:3)
Block(13,4,-15,LOG:3)
Block(13,3,-15,LOG:3)
Block(3,19,-6,LEAVES:3)
Block(11,-3,-16,LOG:3)
Block(13,0,-15,LOG:3)
Block(11,-4,-16,LOG:3)
Block(20,24,-3,LEAVES:7)
Block(11,1,-14,LOG:3)
Block(3,3,-12,LOG:3)
Block(11,0,-14,LOG:3)
Block(3,4,-12,LOG:3)
Block(11,3,-14,LOG:3)
Block(3,5,-12,LOG:3)
Block(20,21,-3,LEAVES:3)
Block(11,2,-14,LOG:3)
Block(11,4,-14,LOG:3)
Block(8,2,-15,LOG:3)
Block(8,1,-15,LOG:3)
Block(18,21,-11,LEAVES:3)
Block(16,23,-15,LOG:3)
Block(18,22,-11,LEAVES:3)
Block(22,22,0,LEAVES:7)
Block(16,24,-15,LOG:3)
Block(18,23,-11,LEAVES:3)
Block(16,25,-15,LEAVES:3)
Block(18,24,-11,LEAVES:3)
Block(16,26,-15,LEAVES:3)
Block(16,27,-15,LEAVES:3)
Block(16,28,-15,LEAVES:3)
Block(22,20,0,LEAVES:3)
Block(16,22,-3,LEAVES:3)
Block(5,4,-13,LOG:3)
Block(7,2,-14,LOG:3)
Block(1,21,-7,LEAVES:3)
Block(18,23,-2,LEAVES:7)
Block(7,3,-14,LOG:3)
Block(1,20,-7,LEAVES:3)
Block(17,22,-9,LOG:3)
Block(17,23,-9,LEAVES:3)
Block(17,21,-9,LEAVES:3)
Block(-1,18,-4,LEAVES:3)
Block(11,22,-4,LEAVES:3)
Block(-1,17,-4,LEAVES:3)
Block(3,19,-4,LEAVES:3)
Block(-1,21,-4,LEAVES:3)
Block(16,19,-14,LOG:3)
Block(16,18,-14,LOG:3)
Block(16,17,-14,LOG:3)
Block(3,18,-4,LEAVES:3)
Block(17,26,-11,LEAVES:3)
Block(16,16,-14,LOG:3)
Block(17,25,-11,LEAVES:3)
Block(16,15,-14,LOG:3)
Block(17,24,-11,LEAVES:3)
Block(16,14,-14,LOG:3)
Block(16,13,-14,LOG:3)
Block(17,22,-11,LEAVES:3)
Block(16,12,-14,LOG:3)
Block(17,21,-11,LEAVES:3)
Block(16,11,-14,LOG:3)
Block(-3,15,-2,LEAVES:3)
Block(17,20,-11,LEAVES:3)
Block(16,10,-14,LOG:3)
Block(24,22,-4,LEAVES:7)
Block(-3,16,-2,LEAVES:3)
Block(22,23,-6,LEAVES:7)
Block(21,22,-1,LEAVES:7)
Block(13,-6,-13,LOG:3)
Block(-2,21,-8,LEAVES:3)
Block(-2,20,-8,LOG:3)
Block(21,23,-1,LOG:3)
Block(-2,22,-8,LEAVES:3)
Block(16,22,-5,LEAVES:3)
Block(21,24,-1,LEAVES:7)
Block(13,-5,-13,LOG:3)
Block(-2,18,-8,LOG:3)
Block(13,-4,-13,LOG:3)
Block(-2,17,-8,LOG:3)
Block(13,-3,-13,LOG:3)
Block(-2,19,-8,LOG:3)
Block(15,9,-7,LOG:3)
Block(15,8,-7,LOG:3)
Block(15,7,-7,LOG:3)
Block(15,6,-7,LOG:3)
Block(14,22,-7,LEAVES:3)
Block(-1,20,-13,LEAVES:3)
Block(19,24,-16,LEAVES:3)
Block(19,25,-16,LEAVES:3)
Block(12,-2,-16,LOG:3)
Block(12,-1,-16,LOG:3)
Block(11,1,-16,LOG:3)
Block(11,0,-16,LOG:3)
Block(8,0,-13,LOG:3)
Block(11,3,-16,LOG:3)
Block(18,22,-3,LEAVES:7)
Block(11,2,-16,LOG:3)
Block(1,21,-6,LEAVES:3)
Block(18,23,-3,LEAVES:7)
Block(8,2,-13,LOG:3)
Block(8,1,-13,LOG:3)
Block(-6,21,-4,LEAVES:3)
Block(-6,20,-4,LEAVES:3)
Block(1,18,-6,LEAVES:3)
Block(16,28,-14,LEAVES:3)
Block(1,17,-6,LEAVES:3)
Block(16,27,-14,LEAVES:3)
Block(16,25,-14,LOG:3)
Block(8,-1,-15,LOG:3)
Block(16,24,-14,LOG:3)
Block(19,23,-16,LEAVES:3)
Block(16,23,-14,LOG:3)
Block(8,-3,-15,LOG:3)
Block(-4,13,-8,LEAVES:3)
Block(16,22,-14,LOG:3)
Block(16,21,-14,LOG:3)
Block(16,20,-14,LOG:3)
Block(-4,12,-8,LEAVES:3)
Block(-4,18,-8,LEAVES:3)
Block(-4,19,-8,LEAVES:3)
Block(20,22,0,LEAVES:7)
Block(2,16,-9,LEAVES:3)
Block(-9,18,-6,LEAVES:3)
Block(-9,19,-6,LEAVES:3)
Block(1,21,-4,LEAVES:3)
Block(14,7,-13,LOG:3)
Block(14,8,-13,LOG:3)
Block(14,9,-13,LOG:3)
Block(15,27,-15,LEAVES:3)
Block(-4,20,-8,LEAVES:3)
Block(15,26,-15,LEAVES:3)
Block(-4,21,-8,LEAVES:3)
Block(15,25,-15,LEAVES:3)
Block(15,24,-15,LEAVES:3)
Block(15,23,-15,LEAVES:3)
Block(15,22,-15,LEAVES:3)
Block(15,21,-15,LEAVES:3)
Block(2,7,-9,LOG:3)
Block(2,6,-9,LOG:3)
Block(-2,21,-12,LEAVES:3)
Block(12,1,-11,LOG:3)
Block(-1,14,-6,LEAVES:3)
Block(12,0,-11,LOG:3)
Block(-1,15,-6,LEAVES:3)
Block(16,27,-12,LEAVES:3)
Block(16,25,-12,LEAVES:3)
Block(16,26,-12,LEAVES:3)
Block(8,-3,-17,LOG:3)
Block(16,24,-12,LEAVES:3)
Block(16,20,-12,LEAVES:7)
Block(12,3,-11,LOG:3)
Block(8,-5,-17,LOG:3)
Block(12,2,-11,LOG:3)
Block(-3,21,-4,LEAVES:3)
Block(-3,20,-4,LEAVES:3)
Block(1,9,-9,LOG:3)
Block(1,7,-9,LOG:3)
Block(1,8,-9,LOG:3)
Block(1,6,-9,LOG:3)
Block(9,-1,-14,LOG:3)
Block(16,22,0,LOG:3)
Block(16,21,0,LEAVES:3)
Block(-3,19,-4,LEAVES:3)
Block(16,23,0,LEAVES:7)
Block(18,21,-5,LEAVES:3)
Block(18,22,-5,LEAVES:7)
Block(18,20,-5,LOG:3)
Block(-7,20,-8,LEAVES:3)
Block(-7,16,-8,LEAVES:3)
Block(17,19,-11,LEAVES:3)
Block(-7,15,-8,LEAVES:3)
Block(18,18,-5,LOG:3)
Block(15,14,-15,LOG:3)
Block(18,19,-5,LOG:3)
Block(15,13,-15,LOG:3)
Block(18,16,-5,LOG:3)
Block(20,21,-6,LEAVES:3)
Block(15,12,-15,LOG:3)
Block(18,17,-5,LOG:3)
Block(15,11,-15,LOG:3)
Block(15,10,-15,LOG:3)
Block(18,15,-5,LOG:3)
Block(-1,21,-11,LEAVES:3)
Block(19,25,-14,LEAVES:3)
Block(19,24,-14,LEAVES:3)
Block(19,22,-14,LEAVES:3)
Block(-4,17,-4,LEAVES:3)
Block(19,27,-14,LEAVES:3)
Block(-4,18,-4,LEAVES:3)
Block(-4,19,-4,LEAVES:3)
Block(2,18,-2,LEAVES:3)
Block(2,19,-2,LEAVES:3)
Block(-7,21,-6,LEAVES:3)
Block(9,-2,-16,LOG:3)
Block(9,-3,-16,LOG:3)
Block(9,-1,-16,LOG:3)
Block(18,23,-17,LEAVES:3)
Block(18,22,-17,LEAVES:3)
Block(9,-4,-16,LOG:3)
Block(18,21,-17,LEAVES:3)
Block(-4,21,-4,LEAVES:3)
Block(19,17,-5,LOG:3)
Block(19,18,-5,LOG:3)
Block(18,24,-17,LEAVES:3)
Block(-5,14,-8,LEAVES:3)
Block(-5,15,-8,LEAVES:3)
Block(-5,16,-8,LEAVES:3)
Block(-5,17,-8,LEAVES:3)
Block(19,19,-5,LOG:3)
Block(-5,19,-8,LEAVES:3)
Block(23,19,0,LEAVES:3)
Block(20,24,-14,LEAVES:3)
Block(-9,19,-4,LEAVES:3)
Block(-9,18,-4,LEAVES:3)
Block(-5,20,-8,LEAVES:3)
Block(-9,17,-4,LEAVES:3)
Block(-5,21,-8,LEAVES:3)
Block(25,21,-6,LEAVES:7)
Block(25,20,-6,LEAVES:7)
Block(20,23,-14,LEAVES:3)
Block(14,25,-16,LEAVES:3)
Block(19,20,-5,LOG:3)
Block(0,21,-4,LEAVES:3)
Block(19,21,-5,LEAVES:3)
Block(19,21,-14,LEAVES:3)
Block(17,21,-7,LEAVES:3)
Block(23,20,0,LOG:3)
Block(19,22,-5,LEAVES:7)
Block(17,23,-7,LEAVES:3)
Block(17,22,-7,LOG:3)
Block(23,22,0,LEAVES:7)
Block(23,21,0,LOG:3)
Block(16,11,-7,LOG:3)
Block(16,10,-7,LOG:3)
Block(-1,18,-6,LEAVES:3)
Block(16,14,-7,LOG:3)
Block(-1,19,-6,LEAVES:3)
Block(16,13,-7,LOG:3)
Block(-1,16,-6,LEAVES:3)
Block(16,12,-7,LOG:3)
Block(-1,17,-6,LEAVES:3)
Block(3,17,-2,LEAVES:3)
Block(-8,19,-6,LEAVES:3)
Block(3,18,-2,LEAVES:3)
Block(15,27,-13,LEAVES:3)
Block(-1,22,-6,LEAVES:3)
Block(15,28,-13,LEAVES:3)
Block(-5,12,-8,LEAVES:3)
Block(-5,13,-8,LEAVES:3)
Block(-1,20,-6,LEAVES:3)
Block(15,26,-13,LEAVES:3)
Block(15,23,-13,LEAVES:3)
Block(17,15,-7,LOG:3)
Block(15,24,-13,LOG:3)
Block(24,22,-6,LEAVES:7)
Block(17,10,-7,LOG:3)
Block(17,11,-7,LOG:3)
Block(17,14,-7,LOG:3)
Block(0,20,-11,LEAVES:3)
Block(16,22,-7,LEAVES:3)
Block(-2,22,-6,LEAVES:3)
Block(-2,21,-6,LEAVES:3)
Block(-2,20,-6,LEAVES:3)
Block(16,23,-7,LEAVES:3)
Block(-2,19,-6,LEAVES:3)
Block(-2,18,-6,LOG:3)
Block(-8,20,-6,LEAVES:3)
Block(-8,21,-6,LEAVES:3)
Block(-3,20,-6,LOG:3)
Block(-6,19,-6,LEAVES:3)
Block(-3,22,-6,LEAVES:3)
Block(-3,21,-6,LEAVES:3)
Block(-2,19,-10,LEAVES:3)
Block(16,19,-10,LEAVES:3)
Block(-6,21,-6,LEAVES:3)
Block(-8,19,-4,LEAVES:3)
Block(-1,21,-8,LEAVES:3)
Block(-1,20,-8,LEAVES:3)
Block(-3,19,-6,LOG:3)
Block(-3,18,-6,LOG:3)
Block(18,22,-7,LEAVES:3)
Block(18,20,-7,LEAVES:3)
Block(-1,19,-13,LEAVES:3)
Block(-1,18,-13,LEAVES:3)
Block(16,22,-9,LEAVES:3)
Block(-6,22,-6,LEAVES:3)
Block(15,16,-13,LOG:3)
Block(15,17,-13,LOG:3)
Block(15,14,-13,LOG:3)
Block(15,15,-13,LOG:3)
Block(15,12,-13,LOG:3)
Block(15,13,-13,LOG:3)
Block(15,10,-13,LOG:3)
Block(15,11,-13,LOG:3)
Block(-8,20,-4,LEAVES:3)
Block(15,7,-9,LOG:3)
Block(15,6,-9,LOG:3)
Block(17,23,-18,LEAVES:3)
Block(15,5,-9,LOG:3)
Block(0,19,-13,LEAVES:3)
Block(15,4,-9,LOG:3)
Block(0,18,-13,LEAVES:3)
Block(0,19,-2,LEAVES:3)
Block(15,8,-9,LOG:3)
Block(-4,18,-6,LEAVES:3)
Block(-4,17,-6,LEAVES:3)
Block(-4,19,-6,LEAVES:3)
Block(-2,14,-8,LOG:3)
Block(21,19,1,LEAVES:7)
Block(-2,13,-8,LOG:3)
Block(-2,16,-8,LOG:3)
Block(-2,15,-8,LOG:3)
Block(-2,10,-8,LOG:3)
Block(-2,12,-8,LOG:3)
Block(-2,11,-8,LOG:3)
Block(14,10,-9,LOG:3)
Block(15,22,-9,LEAVES:3)
Block(15,21,-9,LEAVES:3)
Block(15,20,-9,LEAVES:3)
Block(-4,20,-6,LEAVES:3)
Block(-4,22,-6,LEAVES:3)
Block(-5,19,-6,LEAVES:3)
Block(-2,22,-10,LEAVES:3)
Block(-2,21,-10,LEAVES:3)
Block(-5,17,-6,LEAVES:3)
Block(-5,16,-6,LEAVES:3)
Block(-5,15,-6,LEAVES:3)
Block(-5,14,-6,LEAVES:3)
Block(-5,13,-6,LEAVES:3)
Block(-5,12,-6,LEAVES:3)
Block(1,18,-2,LEAVES:3)
Block(1,19,-2,LEAVES:3)
Block(14,22,-9,LEAVES:3)
Block(21,22,1,LEAVES:7)
Block(14,21,-9,LEAVES:3)
Block(-1,14,-8,LOG:3)
Block(-1,13,-8,LOG:3)
Block(16,24,-10,LEAVES:3)
Block(14,26,-14,LEAVES:3)
Block(-1,12,-8,LOG:3)
Block(16,23,-10,LEAVES:3)
Block(14,25,-14,LEAVES:3)
Block(-1,11,-8,LOG:3)
Block(-1,10,-8,LOG:3)
Block(16,20,-10,LEAVES:3)
Block(-5,22,-6,LEAVES:3)
Block(-5,20,-6,LEAVES:3)
Block(16,22,-10,LEAVES:3)
Block(14,24,-14,LEAVES:3)
Block(16,21,-10,LEAVES:3)
Block(14,23,-14,LEAVES:3)
Block(21,20,1,LOG:3)
Block(21,21,1,LOG:3)

#######################################################################
# +-----------------------------------------------------------------+ #
# |                            BO3 checks                           | #
# +-----------------------------------------------------------------+ #
#######################################################################

BlockCheck(7,-1,-13,GRASS,DIRT,SAND)

#######################################################################
# +-----------------------------------------------------------------+ #
# |                             Branches                            | #
# +-----------------------------------------------------------------+ #
#######################################################################


#######################################################################
# +-----------------------------------------------------------------+ #
# |                             Entities                            | #
# +-----------------------------------------------------------------+ #
#######################################################################


#######################################################################
# +-----------------------------------------------------------------+ #
# |                            Particles                            | #
# +-----------------------------------------------------------------+ #
#######################################################################


#######################################################################
# +-----------------------------------------------------------------+ #
# |                             Spawners                            | #
# +-----------------------------------------------------------------+ #
#######################################################################


#######################################################################
# +-----------------------------------------------------------------+ #
# |                             ModData                             | #
# +-----------------------------------------------------------------+ #
#######################################################################

