#######################################################################
# +-----------------------------------------------------------------+ #
# |                            BO3 object                           | #
# +-----------------------------------------------------------------+ #
#######################################################################

# The descriptions in this file are true only for TerrainControl. They are not true for the Minecraft Worlds mod!
# Minecraft Worlds completely reimplemented BO3s, check the MCW documentation on the mc/mctcp forums for how to use BO3s with MCW
# or watch the video's on my YT channel at https://www.youtube.com/user/PeeGee85. You can check out the "Editing and importing schematics & BO3s" 
# series of video's, in part 2 I explain BO3s. 

# This is the config file of a custom object.
# If you add this object correctly to your BiomeConfigs, it will spawn in the world.

# This is the creator of this BO3 object
Author: Unknown

# A short description of this BO3 object
Description: This BO3 was converted from a schematic using the MineCraft Worlds Editor. Unfortunately the author and description information for the schematic could not be found. If you know who the author of the schematic is then please tell the author of this BO3!

# The BO3 version, don't change this! It can be used by external applications to do a version check.
Version: 3

# The settings mode, WriteAll, WriteWithoutComments or WriteDisable. See WorldConfig.
SettingsMode: WriteDisable

#######################################################################
# +-----------------------------------------------------------------+ #
# |                          Main settings                          | #
# +-----------------------------------------------------------------+ #
#######################################################################

# This needs to be set to true to spawn the object in the Tree and Sapling resources.
Tree: false

# The frequency of the BO3 from 1 to 200. Tries this many times to spawn this BO3 when using the CustomObject(...) resource.
# Ignored by Tree(..), Sapling(..) and CustomStructure(..)
Frequency: 40

# The rarity of the BO3 from 0 to 100. Each spawn attempt has rarity% chance to succeed when using the CustomObject(...) resource.
# Ignored by Tree(..), Sapling(..) and CustomStructure(..)
Rarity: 100.0

# If you set this to true, the BO3 will be placed with a random rotation.
RotateRandomly: false

# The spawn height of the BO3 - randomY, highestBlock or highestSolidBlock.
SpawnHeight: randomY

# The height limits for the BO3.
MinHeight: 44

MaxHeight: 46

# Objects can have other objects attached to it: branches. Branches can also
# have branches attached to it, which can also have branches, etc. This is the
# maximum branch depth for this objects.
MaxBranchDepth: 10

# When spawned with the UseWorld keyword, this BO3 should NOT spawn in the following biomes.
# If you writer.write the BO3 name directly in the BiomeConfigs, this will be ignored.
ExcludedBiomes: All

#######################################################################
# +-----------------------------------------------------------------+ #
# |                      Source block settings                      | #
# +-----------------------------------------------------------------+ #
#######################################################################

# The block(s) the BO3 should spawn in.
SourceBlocks: AIR

# The maximum percentage of the BO3 that can be outside the SourceBlock.
# The BO3 won't be placed on a location with more blocks outside the SourceBlock than this percentage.
MaxPercentageOutsideSourceBlock: 100

# What to do when a block is about to be placed outside the SourceBlock? (dontPlace, placeAnyway)
OutsideSourceBlock: placeAnyway

#######################################################################
# +-----------------------------------------------------------------+ #
# |                              Blocks                             | #
# +-----------------------------------------------------------------+ #
#######################################################################

# All the blocks used in the BO3 are listed here. Possible blocks:
# Block(x,y,z,id[.data][,nbtfile.nbt)
# RandomBlock(x,y,z,id[:data][,nbtfile.nbt],chance[,id[:data][,nbtfile.nbt],chance[,...]])
# So RandomBlock(0,0,0,CHEST,chest.nbt,50,CHEST,anotherchest.nbt,100) will spawn a chest at
# the BO3 origin, and give it a 50% chance to have the contents of chest.nbt, or, if that
# fails, a 100% percent chance to have the contents of anotherchest.nbt.

Block(-4,0,-6,24)
Block(-4,0,-5,24)
Block(-4,0,-4,24)
Block(-4,0,-3,24)
Block(-4,0,-2,24)
Block(-4,0,-1,24)
Block(-4,0,0,24)
Block(-4,0,1,24)
Block(-4,0,2,24)
Block(-4,0,3,24)
Block(-4,0,4,24)
Block(-4,0,5,24)
Block(-4,0,6,24)
Block(-4,0,7,24)
Block(-4,0,8,24)
Block(-4,1,-6,24)
Block(-4,1,-5,24)
Block(-4,1,-4,24)
Block(-4,1,-3,24)
Block(-4,1,-2,24)
Block(-4,1,-1,24)
Block(-4,1,0,24)
Block(-4,1,1,24)
Block(-4,1,2,24)
Block(-4,1,3,24)
Block(-4,1,4,24)
Block(-4,1,5,24)
Block(-4,1,6,24)
Block(-4,1,7,24)
Block(-4,1,8,24)
Block(-4,2,-6,24)
Block(-4,2,-5,24)
Block(-4,2,-4,24)
Block(-4,2,-3,24)
Block(-4,2,-2,24)
Block(-4,2,-1,24)
Block(-4,2,0,24)
Block(-4,2,1,24)
Block(-4,2,2,24)
Block(-4,2,3,24)
Block(-4,2,4,24)
Block(-4,2,5,24)
Block(-4,2,6,24)
Block(-4,2,7,24)
Block(-4,2,8,24)
Block(-4,3,-6,24)
Block(-4,3,-5,24)
Block(-4,3,-4,24)
Block(-4,3,-3,24)
Block(-4,3,-2,24)
Block(-4,3,-1,24)
Block(-4,3,0,24)
Block(-4,3,1,24)
Block(-4,3,2,24)
Block(-4,3,3,24)
Block(-4,3,4,24)
Block(-4,3,5,24)
Block(-4,3,6,24)
Block(-4,3,7,24)
Block(-4,3,8,24)
Block(-4,4,-6,24)
Block(-4,4,-5,24)
Block(-4,4,-4,24)
Block(-4,4,-3,24)
Block(-4,4,-2,24)
Block(-4,4,-1,24)
Block(-4,4,0,24)
Block(-4,4,1,24)
Block(-4,4,2,24)
Block(-4,4,3,24)
Block(-4,4,4,24)
Block(-4,4,5,24)
Block(-4,4,6,24)
Block(-4,4,7,24)
Block(-4,4,8,24)
Block(-4,5,-6,24)
Block(-4,5,-5,24)
Block(-4,5,-4,24)
Block(-4,5,-3,24)
Block(-4,5,-2,24)
Block(-4,5,-1,24)
Block(-4,5,0,24)
Block(-4,5,1,24)
Block(-4,5,2,24)
Block(-4,5,3,24)
Block(-4,5,4,24)
Block(-4,5,5,24)
Block(-4,5,6,24)
Block(-4,5,7,24)
Block(-4,5,8,24)
Block(-4,6,-6,24)
Block(-4,6,-5,24)
Block(-4,6,-4,24)
Block(-4,6,-3,24)
Block(-4,6,-2,24)
Block(-4,6,-1,24)
Block(-4,6,0,24)
Block(-4,6,1,24)
Block(-4,6,2,24)
Block(-4,6,3,24)
Block(-4,6,4,24)
Block(-4,6,5,24)
Block(-4,6,6,24)
Block(-4,6,7,24)
Block(-4,6,8,24)
Block(-4,7,-6,24)
Block(-4,7,-5,24)
Block(-4,7,-4,24)
Block(-4,7,-3,24)
Block(-4,7,-2,24)
Block(-4,7,-1,24)
Block(-4,7,0,24)
Block(-4,7,1,24)
Block(-4,7,2,24)
Block(-4,7,3,24)
Block(-4,7,4,24)
Block(-4,7,5,24)
Block(-4,7,6,24)
Block(-4,7,7,24)
Block(-4,7,8,24)
Block(-4,8,-6,24)
Block(-4,8,-5,24)
Block(-4,8,-4,24)
Block(-4,8,-3,24)
Block(-4,8,-2,24)
Block(-4,8,-1,24)
Block(-4,8,0,24)
Block(-4,8,1,24)
Block(-4,8,2,24)
Block(-4,8,3,24)
Block(-4,8,4,24)
Block(-4,8,5,24)
Block(-4,8,6,24)
Block(-4,8,7,24)
Block(-4,8,8,24)
Block(-4,9,-6,24)
Block(-4,9,-5,24)
Block(-4,9,-4,24)
Block(-4,9,-3,24)
Block(-4,9,-2,24)
Block(-4,9,-1,24)
Block(-4,9,0,24)
Block(-4,9,1,24)
Block(-4,9,2,24)
Block(-4,9,3,24)
Block(-4,9,4,24)
Block(-4,9,5,24)
Block(-4,9,6,24)
Block(-4,9,7,24)
Block(-4,9,8,24)
Block(-4,10,-6,24)
Block(-4,10,-5,24)
Block(-4,10,-4,24)
Block(-4,10,-3,24)
Block(-4,10,-2,24)
Block(-4,10,-1,24)
Block(-4,10,0,24)
Block(-4,10,1,24)
Block(-4,10,2,24)
Block(-4,10,3,24)
Block(-4,10,4,24)
Block(-4,10,5,24)
Block(-4,10,6,24)
Block(-4,10,7,24)
Block(-4,10,8,24)
Block(-4,11,-5,24)
Block(-4,11,-4,24)
Block(-4,11,-3,24)
Block(-4,11,-2,24)
Block(-4,11,-1,24)
Block(-4,11,0,24)
Block(-4,11,1,24)
Block(-4,11,2,24)
Block(-4,11,3,24)
Block(-4,11,4,24)
Block(-4,11,5,24)
Block(-4,11,6,24)
Block(-4,11,7,24)
Block(-4,11,8,24)
Block(-4,12,-4,24)
Block(-4,12,-3,24)
Block(-4,12,-2,24)
Block(-4,12,-1,24)
Block(-4,12,0,24)
Block(-4,12,1,24)
Block(-4,12,2,24)
Block(-4,12,3,24)
Block(-4,12,4,24)
Block(-4,12,5,24)
Block(-4,12,6,24)
Block(-4,12,7,24)
Block(-4,12,8,24)
Block(-4,13,-4,24)
Block(-4,13,-3,24)
Block(-4,13,-2,24)
Block(-4,13,-1,24)
Block(-4,13,0,24)
Block(-4,13,1,24)
Block(-4,13,2,24)
Block(-4,13,3,24)
Block(-4,13,4,24)
Block(-4,13,5,24)
Block(-4,13,6,24)
Block(-4,13,7,24)
Block(-4,13,8,24)
Block(-4,14,-4,24)
Block(-4,14,-3,24)
Block(-4,14,-2,24)
Block(-4,14,-1,24)
Block(-4,14,0,24)
Block(-4,14,1,24)
Block(-4,14,2,24)
Block(-4,14,3,24)
Block(-4,14,4,24)
Block(-4,14,5,24)
Block(-4,14,6,24)
Block(-4,14,7,24)
Block(-4,14,8,24)
Block(-4,15,-4,24)
Block(-4,15,-3,24)
Block(-4,15,-2,24)
Block(-4,15,-1,24)
Block(-4,15,0,24)
Block(-4,15,1,24)
Block(-4,15,2,24)
Block(-4,15,3,24)
Block(-4,15,4,24)
Block(-4,15,5,24)
Block(-4,15,6,24)
Block(-4,15,7,24)
Block(-4,15,8,24)
Block(-4,16,-4,24)
Block(-4,16,-3,24)
Block(-4,16,-2,24)
Block(-4,16,-1,24)
Block(-4,16,0,24)
Block(-4,16,1,24)
Block(-4,16,2,24)
Block(-4,16,3,24)
Block(-4,16,4,24)
Block(-4,16,5,24)
Block(-4,16,6,24)
Block(-4,16,7,24)
Block(-4,16,8,24)
Block(-4,17,-4,24)
Block(-4,17,-3,24)
Block(-4,17,-2,24)
Block(-4,17,-1,24)
Block(-4,17,0,24)
Block(-4,17,1,24)
Block(-4,17,2,24)
Block(-4,17,3,24)
Block(-4,17,4,24)
Block(-4,17,5,192)
Block(-4,17,6,192)
Block(-4,17,7,24)
Block(-4,17,8,24)
Block(-4,18,-4,24)
Block(-4,18,-3,24)
Block(-4,18,-2,24)
Block(-4,18,-1,24)
Block(-4,18,0,192)
Block(-4,18,1,192)
Block(-4,18,2,24)
Block(-4,18,3,24)
Block(-4,18,4,24)
Block(-4,18,5,24)
Block(-4,18,6,24)
Block(-4,18,7,24)
Block(-4,18,8,24)
Block(-4,19,-4,24)
Block(-4,19,-3,24)
Block(-4,19,-2,24)
Block(-4,19,-1,24)
Block(-4,19,0,24)
Block(-4,19,1,24)
Block(-4,19,2,24)
Block(-4,19,3,24)
Block(-4,19,4,24)
Block(-4,19,5,24)
Block(-4,19,6,24)
Block(-4,19,7,24)
Block(-4,19,8,24)
Block(-4,20,-4,126:4)
Block(-4,20,-3,126:4)
Block(-4,20,-2,126:4)
Block(-4,20,-1,126:4)
Block(-4,20,0,126:4)
Block(-4,20,1,126:4)
Block(-4,20,2,126:4)
Block(-4,20,3,126:4)
Block(-4,20,4,126:4)
Block(-4,20,5,126:4)
Block(-4,20,6,126:4)
Block(-4,20,7,126:4)
Block(-4,20,8,126:4)
Block(-4,21,-4,AIR)
Block(-4,21,-3,AIR)
Block(-4,21,-2,AIR)
Block(-4,21,-1,AIR)
Block(-4,21,0,AIR)
Block(-4,21,1,AIR)
Block(-4,21,2,AIR)
Block(-4,21,3,AIR)
Block(-4,21,4,AIR)
Block(-4,21,5,AIR)
Block(-4,21,6,AIR)
Block(-4,21,7,AIR)
Block(-4,21,8,AIR)
Block(-4,22,-4,AIR)
Block(-4,22,-3,AIR)
Block(-4,22,-2,AIR)
Block(-4,22,-1,AIR)
Block(-4,22,0,AIR)
Block(-4,22,1,AIR)
Block(-4,22,2,AIR)
Block(-4,22,3,AIR)
Block(-4,22,4,AIR)
Block(-4,22,5,AIR)
Block(-4,22,6,AIR)
Block(-4,22,7,AIR)
Block(-4,22,8,AIR)
Block(-4,23,-4,AIR)
Block(-4,23,-3,AIR)
Block(-4,23,-2,AIR)
Block(-4,23,-1,AIR)
Block(-4,23,0,AIR)
Block(-4,23,1,AIR)
Block(-4,23,2,AIR)
Block(-4,23,3,AIR)
Block(-4,23,4,AIR)
Block(-4,23,5,AIR)
Block(-4,23,6,AIR)
Block(-4,23,7,AIR)
Block(-4,23,8,AIR)
Block(-4,24,-4,AIR)
Block(-4,24,-3,AIR)
Block(-4,24,-2,AIR)
Block(-4,24,-1,AIR)
Block(-4,24,0,AIR)
Block(-4,24,1,AIR)
Block(-4,24,2,AIR)
Block(-4,24,3,AIR)
Block(-4,24,4,AIR)
Block(-4,24,5,AIR)
Block(-4,24,6,AIR)
Block(-4,24,7,AIR)
Block(-4,24,8,AIR)
Block(-4,25,-4,AIR)
Block(-4,25,-3,AIR)
Block(-4,25,-2,AIR)
Block(-4,25,-1,AIR)
Block(-4,25,0,AIR)
Block(-4,25,1,AIR)
Block(-4,25,2,AIR)
Block(-4,25,3,AIR)
Block(-4,25,4,AIR)
Block(-4,25,5,AIR)
Block(-4,25,6,AIR)
Block(-4,25,7,AIR)
Block(-4,25,8,AIR)
Block(-4,26,-3,AIR)
Block(-4,26,-2,AIR)
Block(-4,26,-1,AIR)
Block(-4,26,0,AIR)
Block(-4,26,1,AIR)
Block(-4,26,2,AIR)
Block(-4,26,3,AIR)
Block(-4,26,4,AIR)
Block(-4,26,5,AIR)
Block(-4,26,6,AIR)
Block(-4,26,7,AIR)
Block(-4,27,-2,AIR)
Block(-4,27,0,AIR)
Block(-4,27,1,AIR)
Block(-4,27,2,AIR)
Block(-4,27,3,AIR)
Block(-4,27,4,AIR)
Block(-3,0,-6,24)
Block(-3,0,-5,24)
Block(-3,0,-4,24)
Block(-3,0,-3,24)
Block(-3,0,-2,24)
Block(-3,0,-1,24)
Block(-3,0,0,24)
Block(-3,0,1,24)
Block(-3,0,2,24)
Block(-3,0,3,24)
Block(-3,0,4,24)
Block(-3,0,5,24)
Block(-3,0,6,24)
Block(-3,0,7,24)
Block(-3,0,8,24)
Block(-3,1,-6,24)
Block(-3,1,-5,24)
Block(-3,1,-4,24)
Block(-3,1,-3,24)
Block(-3,1,-2,24)
Block(-3,1,-1,24)
Block(-3,1,0,24)
Block(-3,1,1,24)
Block(-3,1,2,24)
Block(-3,1,3,24)
Block(-3,1,4,24)
Block(-3,1,5,24)
Block(-3,1,6,24)
Block(-3,1,7,24)
Block(-3,1,8,24)
Block(-3,2,-6,24)
Block(-3,2,-5,24)
Block(-3,2,-4,24)
Block(-3,2,-3,24)
Block(-3,2,-2,24)
Block(-3,2,-1,24)
Block(-3,2,0,24)
Block(-3,2,1,24)
Block(-3,2,2,24)
Block(-3,2,3,24)
Block(-3,2,4,24)
Block(-3,2,5,24)
Block(-3,2,6,24)
Block(-3,2,7,24)
Block(-3,2,8,24)
Block(-3,3,-6,24)
Block(-3,3,-5,24)
Block(-3,3,-4,24)
Block(-3,3,-3,24)
Block(-3,3,-2,24)
Block(-3,3,-1,24)
Block(-3,3,0,24)
Block(-3,3,1,24)
Block(-3,3,2,24)
Block(-3,3,3,24)
Block(-3,3,4,24)
Block(-3,3,5,24)
Block(-3,3,6,24)
Block(-3,3,7,24)
Block(-3,3,8,24)
Block(-3,4,-6,24)
Block(-3,4,-5,24)
Block(-3,4,-4,24)
Block(-3,4,-3,24)
Block(-3,4,-2,24)
Block(-3,4,-1,24)
Block(-3,4,0,24)
Block(-3,4,1,24)
Block(-3,4,2,24)
Block(-3,4,3,24)
Block(-3,4,4,24)
Block(-3,4,5,24)
Block(-3,4,6,24)
Block(-3,4,7,24)
Block(-3,4,8,24)
Block(-3,5,-6,24)
Block(-3,5,-5,24)
Block(-3,5,-4,24)
Block(-3,5,-3,24)
Block(-3,5,-2,24)
Block(-3,5,-1,24)
Block(-3,5,0,24)
Block(-3,5,1,24)
Block(-3,5,2,24)
Block(-3,5,3,24)
Block(-3,5,4,24)
Block(-3,5,5,24)
Block(-3,5,6,24)
Block(-3,5,7,24)
Block(-3,5,8,24)
Block(-3,6,-6,24)
Block(-3,6,-5,24)
Block(-3,6,-4,24)
Block(-3,6,-3,24)
Block(-3,6,-2,24)
Block(-3,6,-1,24)
Block(-3,6,0,24)
Block(-3,6,1,24)
Block(-3,6,2,24)
Block(-3,6,3,24)
Block(-3,6,4,24)
Block(-3,6,5,24)
Block(-3,6,6,24)
Block(-3,6,7,24)
Block(-3,6,8,24)
Block(-3,7,-6,24)
Block(-3,7,-5,24)
Block(-3,7,-4,24)
Block(-3,7,-3,24)
Block(-3,7,-2,24)
Block(-3,7,-1,24)
Block(-3,7,0,24)
Block(-3,7,1,24)
Block(-3,7,2,24)
Block(-3,7,3,24)
Block(-3,7,4,24)
Block(-3,7,5,24)
Block(-3,7,6,24)
Block(-3,7,7,24)
Block(-3,7,8,24)
Block(-3,8,-6,24)
Block(-3,8,-5,24)
Block(-3,8,-4,24)
Block(-3,8,-3,24)
Block(-3,8,-2,24)
Block(-3,8,-1,24)
Block(-3,8,0,24)
Block(-3,8,1,24)
Block(-3,8,2,24)
Block(-3,8,3,24)
Block(-3,8,4,24)
Block(-3,8,5,24)
Block(-3,8,6,24)
Block(-3,8,7,24)
Block(-3,8,8,24)
Block(-3,9,-6,24)
Block(-3,9,-5,24)
Block(-3,9,-4,24)
Block(-3,9,-3,24)
Block(-3,9,-2,24)
Block(-3,9,-1,24)
Block(-3,9,0,24)
Block(-3,9,1,24)
Block(-3,9,2,24)
Block(-3,9,3,24)
Block(-3,9,4,24)
Block(-3,9,5,24)
Block(-3,9,6,24)
Block(-3,9,7,24)
Block(-3,9,8,24)
Block(-3,10,-6,24)
Block(-3,10,-5,24)
Block(-3,10,-4,24)
Block(-3,10,-3,24)
Block(-3,10,-2,24)
Block(-3,10,-1,24)
Block(-3,10,0,24)
Block(-3,10,1,24)
Block(-3,10,2,24)
Block(-3,10,3,24)
Block(-3,10,4,24)
Block(-3,10,5,24)
Block(-3,10,6,24)
Block(-3,10,7,24)
Block(-3,10,8,24)
Block(-3,11,-5,24)
Block(-3,11,-4,24)
Block(-3,11,-3,24)
Block(-3,11,-2,24)
Block(-3,11,-1,24)
Block(-3,11,0,24)
Block(-3,11,1,24)
Block(-3,11,2,24)
Block(-3,11,3,24)
Block(-3,11,4,24)
Block(-3,11,5,24)
Block(-3,11,6,24)
Block(-3,11,7,24)
Block(-3,11,8,24)
Block(-3,12,-4,24)
Block(-3,12,-3,24)
Block(-3,12,-2,24)
Block(-3,12,-1,24)
Block(-3,12,0,24)
Block(-3,12,1,24)
Block(-3,12,2,24)
Block(-3,12,3,24)
Block(-3,12,4,24)
Block(-3,12,5,24)
Block(-3,12,6,24)
Block(-3,12,7,24)
Block(-3,12,8,24)
Block(-3,13,-4,24)
Block(-3,13,-3,24)
Block(-3,13,-2,24)
Block(-3,13,-1,24)
Block(-3,13,0,24)
Block(-3,13,1,24)
Block(-3,13,2,24)
Block(-3,13,3,24)
Block(-3,13,4,24)
Block(-3,13,5,24)
Block(-3,13,6,24)
Block(-3,13,7,24)
Block(-3,13,8,24)
Block(-3,14,-4,24)
Block(-3,14,-3,24)
Block(-3,14,-2,24)
Block(-3,14,-1,24)
Block(-3,14,0,24)
Block(-3,14,1,24)
Block(-3,14,2,24)
Block(-3,14,3,24)
Block(-3,14,4,24)
Block(-3,14,5,24)
Block(-3,14,6,24)
Block(-3,14,7,24)
Block(-3,14,8,24)
Block(-3,15,-4,24)
Block(-3,15,-3,24)
Block(-3,15,-2,24)
Block(-3,15,-1,24)
Block(-3,15,0,24)
Block(-3,15,1,24)
Block(-3,15,2,24)
Block(-3,15,3,24)
Block(-3,15,4,24)
Block(-3,15,5,24)
Block(-3,15,6,24)
Block(-3,15,7,24)
Block(-3,15,8,24)
Block(-3,16,-4,24)
Block(-3,16,-3,AIR)
Block(-3,16,-2,AIR)
Block(-3,16,-1,AIR)
Block(-3,16,0,AIR)
Block(-3,16,1,AIR)
Block(-3,16,2,AIR)
Block(-3,16,3,24)
Block(-3,16,4,135:7)
Block(-3,16,5,135:5)
Block(-3,16,6,135:5)
Block(-3,16,7,135:6)
Block(-3,16,8,24)
Block(-3,17,-4,24)
Block(-3,17,-3,AIR)
Block(-3,17,-2,AIR)
Block(-3,17,-1,AIR)
Block(-3,17,0,AIR)
Block(-3,17,1,AIR)
Block(-3,17,2,AIR)
Block(-3,17,3,24)
Block(-3,17,4,AIR)
Block(-3,17,5,AIR)
Block(-3,17,6,AIR)
Block(-3,17,7,AIR)
Block(-3,17,8,24)
Block(-3,18,-4,24)
Block(-3,18,-3,AIR)
Block(-3,18,-2,AIR)
Block(-3,18,-1,AIR)
Block(-3,18,0,AIR)
Block(-3,18,1,AIR)
Block(-3,18,2,AIR)
Block(-3,18,3,24)
Block(-3,18,4,126:12)
Block(-3,18,5,126:12)
Block(-3,18,6,126:12)
Block(-3,18,7,126:12)
Block(-3,18,8,24)
Block(-3,19,-4,24)
Block(-3,19,-3,AIR)
Block(-3,19,-2,AIR)
Block(-3,19,-1,AIR)
Block(-3,19,0,AIR)
Block(-3,19,1,AIR)
Block(-3,19,2,AIR)
Block(-3,19,3,24)
Block(-3,19,4,AIR)
Block(-3,19,5,47)
Block(-3,19,6,47)
Block(-3,19,7,47)
Block(-3,19,8,24)
Block(-3,20,-4,126:4)
Block(-3,20,-3,5:4)
Block(-3,20,-2,5:4)
Block(-3,20,-1,5:4)
Block(-3,20,0,5:4)
Block(-3,20,1,5:4)
Block(-3,20,2,5:4)
Block(-3,20,3,5:4)
Block(-3,20,4,5:4)
Block(-3,20,5,5:4)
Block(-3,20,6,5:4)
Block(-3,20,7,5:4)
Block(-3,20,8,126:4)
Block(-3,21,-4,AIR)
Block(-3,21,-3,AIR)
Block(-3,21,-2,AIR)
Block(-3,21,-1,AIR)
Block(-3,21,0,AIR)
Block(-3,21,1,AIR)
Block(-3,21,2,AIR)
Block(-3,21,3,AIR)
Block(-3,21,4,AIR)
Block(-3,21,5,AIR)
Block(-3,21,6,AIR)
Block(-3,21,7,AIR)
Block(-3,21,8,AIR)
Block(-3,22,-4,AIR)
Block(-3,22,-3,AIR)
Block(-3,22,-2,AIR)
Block(-3,22,-1,AIR)
Block(-3,22,0,AIR)
Block(-3,22,1,AIR)
Block(-3,22,2,AIR)
Block(-3,22,3,AIR)
Block(-3,22,4,AIR)
Block(-3,22,5,AIR)
Block(-3,22,6,AIR)
Block(-3,22,7,AIR)
Block(-3,22,8,AIR)
Block(-3,23,-4,AIR)
Block(-3,23,-3,AIR)
Block(-3,23,-2,AIR)
Block(-3,23,-1,AIR)
Block(-3,23,0,AIR)
Block(-3,23,1,AIR)
Block(-3,23,2,AIR)
Block(-3,23,3,AIR)
Block(-3,23,4,AIR)
Block(-3,23,5,AIR)
Block(-3,23,6,AIR)
Block(-3,23,7,AIR)
Block(-3,23,8,AIR)
Block(-3,24,-4,AIR)
Block(-3,24,-3,AIR)
Block(-3,24,-2,AIR)
Block(-3,24,-1,AIR)
Block(-3,24,0,AIR)
Block(-3,24,1,AIR)
Block(-3,24,2,AIR)
Block(-3,24,3,AIR)
Block(-3,24,4,AIR)
Block(-3,24,5,AIR)
Block(-3,24,6,AIR)
Block(-3,24,7,AIR)
Block(-3,24,8,AIR)
Block(-3,25,-4,AIR)
Block(-3,25,-3,AIR)
Block(-3,25,-2,AIR)
Block(-3,25,-1,AIR)
Block(-3,25,0,AIR)
Block(-3,25,1,AIR)
Block(-3,25,2,AIR)
Block(-3,25,3,AIR)
Block(-3,25,4,AIR)
Block(-3,25,5,AIR)
Block(-3,25,6,AIR)
Block(-3,25,7,AIR)
Block(-3,25,8,AIR)
Block(-3,26,-4,AIR)
Block(-3,26,-3,AIR)
Block(-3,26,-2,AIR)
Block(-3,26,-1,AIR)
Block(-3,26,0,AIR)
Block(-3,26,1,AIR)
Block(-3,26,2,AIR)
Block(-3,26,3,AIR)
Block(-3,26,4,AIR)
Block(-3,26,5,AIR)
Block(-3,26,6,AIR)
Block(-3,26,7,AIR)
Block(-3,26,8,AIR)
Block(-3,27,-3,AIR)
Block(-3,27,-2,AIR)
Block(-3,27,-1,AIR)
Block(-3,27,0,AIR)
Block(-3,27,1,AIR)
Block(-3,27,2,AIR)
Block(-3,27,3,AIR)
Block(-3,27,4,AIR)
Block(-3,27,5,AIR)
Block(-3,27,6,AIR)
Block(-3,27,7,AIR)
Block(-3,28,-2,AIR)
Block(-3,28,-1,AIR)
Block(-3,28,0,AIR)
Block(-3,28,1,AIR)
Block(-3,28,2,AIR)
Block(-3,28,3,AIR)
Block(-3,28,4,AIR)
Block(-3,28,5,AIR)
Block(-3,28,6,AIR)
Block(-3,29,-1,AIR)
Block(-3,29,0,AIR)
Block(-3,29,1,AIR)
Block(-3,29,2,AIR)
Block(-3,29,3,AIR)
Block(-3,29,4,AIR)
Block(-3,29,5,AIR)
Block(-3,30,0,AIR)
Block(-3,30,1,AIR)
Block(-3,30,2,AIR)
Block(-3,30,3,AIR)
Block(-3,30,4,AIR)
Block(-3,31,1,AIR)
Block(-3,31,2,AIR)
Block(-3,31,3,AIR)
Block(-2,0,-6,24)
Block(-2,0,-5,24)
Block(-2,0,-4,24)
Block(-2,0,-3,24)
Block(-2,0,-2,24)
Block(-2,0,-1,24)
Block(-2,0,0,24)
Block(-2,0,1,24)
Block(-2,0,2,24)
Block(-2,0,3,24)
Block(-2,0,4,24)
Block(-2,0,5,24)
Block(-2,0,6,24)
Block(-2,0,7,24)
Block(-2,0,8,24)
Block(-2,1,-6,24)
Block(-2,1,-5,24)
Block(-2,1,-4,24)
Block(-2,1,-3,24)
Block(-2,1,-2,24)
Block(-2,1,-1,24)
Block(-2,1,0,24)
Block(-2,1,1,24)
Block(-2,1,2,24)
Block(-2,1,3,24)
Block(-2,1,4,24)
Block(-2,1,5,24)
Block(-2,1,6,24)
Block(-2,1,7,24)
Block(-2,1,8,24)
Block(-2,2,-6,24)
Block(-2,2,-5,24)
Block(-2,2,-4,24)
Block(-2,2,-3,24)
Block(-2,2,-2,24)
Block(-2,2,-1,24)
Block(-2,2,0,24)
Block(-2,2,1,24)
Block(-2,2,2,24)
Block(-2,2,3,24)
Block(-2,2,4,24)
Block(-2,2,5,24)
Block(-2,2,6,24)
Block(-2,2,7,24)
Block(-2,2,8,24)
Block(-2,3,-6,24)
Block(-2,3,-5,24)
Block(-2,3,-4,24)
Block(-2,3,-3,24)
Block(-2,3,-2,24)
Block(-2,3,-1,24)
Block(-2,3,0,24)
Block(-2,3,1,24)
Block(-2,3,2,24)
Block(-2,3,3,24)
Block(-2,3,4,24)
Block(-2,3,5,24)
Block(-2,3,6,24)
Block(-2,3,7,24)
Block(-2,3,8,24)
Block(-2,4,-6,24)
Block(-2,4,-5,24)
Block(-2,4,-4,24)
Block(-2,4,-3,24)
Block(-2,4,-2,24)
Block(-2,4,-1,24)
Block(-2,4,0,24)
Block(-2,4,1,24)
Block(-2,4,2,24)
Block(-2,4,3,24)
Block(-2,4,4,24)
Block(-2,4,5,24)
Block(-2,4,6,24)
Block(-2,4,7,24)
Block(-2,4,8,24)
Block(-2,5,-6,24)
Block(-2,5,-5,24)
Block(-2,5,-4,24)
Block(-2,5,-3,24)
Block(-2,5,-2,24)
Block(-2,5,-1,24)
Block(-2,5,0,24)
Block(-2,5,1,24)
Block(-2,5,2,24)
Block(-2,5,3,24)
Block(-2,5,4,24)
Block(-2,5,5,24)
Block(-2,5,6,24)
Block(-2,5,7,24)
Block(-2,5,8,24)
Block(-2,6,-6,24)
Block(-2,6,-5,24)
Block(-2,6,-4,24)
Block(-2,6,-3,24)
Block(-2,6,-2,24)
Block(-2,6,-1,24)
Block(-2,6,0,24)
Block(-2,6,1,24)
Block(-2,6,2,24)
Block(-2,6,3,24)
Block(-2,6,4,24)
Block(-2,6,5,24)
Block(-2,6,6,24)
Block(-2,6,7,24)
Block(-2,6,8,24)
Block(-2,7,-6,24)
Block(-2,7,-5,24)
Block(-2,7,-4,24)
Block(-2,7,-3,24)
Block(-2,7,-2,24)
Block(-2,7,-1,24)
Block(-2,7,0,24)
Block(-2,7,1,24)
Block(-2,7,2,24)
Block(-2,7,3,24)
Block(-2,7,4,24)
Block(-2,7,5,24)
Block(-2,7,6,24)
Block(-2,7,7,24)
Block(-2,7,8,24)
Block(-2,8,-6,24)
Block(-2,8,-5,24)
Block(-2,8,-4,24)
Block(-2,8,-3,24)
Block(-2,8,-2,24)
Block(-2,8,-1,24)
Block(-2,8,0,24)
Block(-2,8,1,24)
Block(-2,8,2,24)
Block(-2,8,3,24)
Block(-2,8,4,24)
Block(-2,8,5,24)
Block(-2,8,6,24)
Block(-2,8,7,24)
Block(-2,8,8,24)
Block(-2,9,-6,24)
Block(-2,9,-5,24)
Block(-2,9,-4,24)
Block(-2,9,-3,24)
Block(-2,9,-2,24)
Block(-2,9,-1,24)
Block(-2,9,0,24)
Block(-2,9,1,24)
Block(-2,9,2,24)
Block(-2,9,3,24)
Block(-2,9,4,24)
Block(-2,9,5,24)
Block(-2,9,6,24)
Block(-2,9,7,24)
Block(-2,9,8,24)
Block(-2,10,-6,24)
Block(-2,10,-5,24)
Block(-2,10,-4,24)
Block(-2,10,-3,24)
Block(-2,10,-2,24)
Block(-2,10,-1,24)
Block(-2,10,0,24)
Block(-2,10,1,24)
Block(-2,10,2,24)
Block(-2,10,3,24)
Block(-2,10,4,24)
Block(-2,10,5,24)
Block(-2,10,6,24)
Block(-2,10,7,24)
Block(-2,10,8,24)
Block(-2,11,-5,24)
Block(-2,11,-4,24)
Block(-2,11,-3,24)
Block(-2,11,-2,24)
Block(-2,11,-1,24)
Block(-2,11,0,24)
Block(-2,11,1,24)
Block(-2,11,2,24)
Block(-2,11,3,24)
Block(-2,11,4,24)
Block(-2,11,5,24)
Block(-2,11,6,24)
Block(-2,11,7,24)
Block(-2,11,8,24)
Block(-2,12,-4,24)
Block(-2,12,-3,24)
Block(-2,12,-2,24)
Block(-2,12,-1,24)
Block(-2,12,0,24)
Block(-2,12,1,24)
Block(-2,12,2,24)
Block(-2,12,3,24)
Block(-2,12,4,24)
Block(-2,12,5,24)
Block(-2,12,6,24)
Block(-2,12,7,24)
Block(-2,12,8,24)
Block(-2,13,-4,24)
Block(-2,13,-3,24)
Block(-2,13,-2,24)
Block(-2,13,-1,24)
Block(-2,13,0,24)
Block(-2,13,1,24)
Block(-2,13,2,24)
Block(-2,13,3,24)
Block(-2,13,4,24)
Block(-2,13,5,24)
Block(-2,13,6,24)
Block(-2,13,7,24)
Block(-2,13,8,24)
Block(-2,14,-4,24)
Block(-2,14,-3,24)
Block(-2,14,-2,24)
Block(-2,14,-1,24)
Block(-2,14,0,24)
Block(-2,14,1,24)
Block(-2,14,2,24)
Block(-2,14,3,24)
Block(-2,14,4,24)
Block(-2,14,5,24)
Block(-2,14,6,24)
Block(-2,14,7,24)
Block(-2,14,8,24)
Block(-2,15,-4,24)
Block(-2,15,-3,24)
Block(-2,15,-2,24)
Block(-2,15,-1,24)
Block(-2,15,0,24)
Block(-2,15,1,24)
Block(-2,15,2,24)
Block(-2,15,3,24)
Block(-2,15,4,24)
Block(-2,15,5,24)
Block(-2,15,6,24)
Block(-2,15,7,24)
Block(-2,15,8,24)
Block(-2,16,-4,24)
Block(-2,16,-3,58)
Block(-2,16,-2,AIR)
Block(-2,16,-1,AIR)
Block(-2,16,0,AIR)
Block(-2,16,1,AIR)
Block(-2,16,2,AIR)
Block(-2,16,3,24)
Block(-2,16,4,135:7)
Block(-2,16,5,AIR)
Block(-2,16,6,AIR)
Block(-2,16,7,AIR)
Block(-2,16,8,24)
Block(-2,17,-4,24)
Block(-2,17,-3,140,DeadBush.nbt)
Block(-2,17,-2,AIR)
Block(-2,17,-1,AIR)
Block(-2,17,0,AIR)
Block(-2,17,1,AIR)
Block(-2,17,2,AIR)
Block(-2,17,3,24)
Block(-2,17,4,AIR)
Block(-2,17,5,AIR)
Block(-2,17,6,AIR)
Block(-2,17,7,AIR)
Block(-2,17,8,24)
Block(-2,18,-4,192)
Block(-2,18,-3,AIR)
Block(-2,18,-2,AIR)
Block(-2,18,-1,AIR)
Block(-2,18,0,AIR)
Block(-2,18,1,AIR)
Block(-2,18,2,AIR)
Block(-2,18,3,24)
Block(-2,18,4,126:12)
Block(-2,18,5,AIR)
Block(-2,18,6,AIR)
Block(-2,18,7,AIR)
Block(-2,18,8,24)
Block(-2,19,-4,24)
Block(-2,19,-3,AIR)
Block(-2,19,-2,AIR)
Block(-2,19,-1,AIR)
Block(-2,19,0,AIR)
Block(-2,19,1,AIR)
Block(-2,19,2,AIR)
Block(-2,19,3,24)
Block(-2,19,4,47)
Block(-2,19,5,AIR)
Block(-2,19,6,AIR)
Block(-2,19,7,AIR)
Block(-2,19,8,24)
Block(-2,20,-4,126:4)
Block(-2,20,-3,5:4)
Block(-2,20,-2,5:4)
Block(-2,20,-1,5:4)
Block(-2,20,0,5:4)
Block(-2,20,1,5:4)
Block(-2,20,2,5:4)
Block(-2,20,3,5:4)
Block(-2,20,4,5:4)
Block(-2,20,5,5:4)
Block(-2,20,6,5:4)
Block(-2,20,7,5:4)
Block(-2,20,8,126:4)
Block(-2,21,-4,AIR)
Block(-2,21,-3,AIR)
Block(-2,21,-2,AIR)
Block(-2,21,-1,AIR)
Block(-2,21,0,AIR)
Block(-2,21,1,AIR)
Block(-2,21,2,AIR)
Block(-2,21,3,AIR)
Block(-2,21,4,AIR)
Block(-2,21,5,AIR)
Block(-2,21,6,AIR)
Block(-2,21,7,AIR)
Block(-2,21,8,AIR)
Block(-2,22,-4,AIR)
Block(-2,22,-3,AIR)
Block(-2,22,-2,AIR)
Block(-2,22,-1,AIR)
Block(-2,22,0,AIR)
Block(-2,22,1,AIR)
Block(-2,22,2,AIR)
Block(-2,22,3,AIR)
Block(-2,22,4,AIR)
Block(-2,22,5,AIR)
Block(-2,22,6,AIR)
Block(-2,22,7,AIR)
Block(-2,22,8,AIR)
Block(-2,23,-4,AIR)
Block(-2,23,-3,AIR)
Block(-2,23,-2,AIR)
Block(-2,23,-1,AIR)
Block(-2,23,0,AIR)
Block(-2,23,1,AIR)
Block(-2,23,2,AIR)
Block(-2,23,3,AIR)
Block(-2,23,4,AIR)
Block(-2,23,5,AIR)
Block(-2,23,6,AIR)
Block(-2,23,7,AIR)
Block(-2,23,8,AIR)
Block(-2,24,-4,AIR)
Block(-2,24,-3,AIR)
Block(-2,24,-2,AIR)
Block(-2,24,-1,AIR)
Block(-2,24,0,AIR)
Block(-2,24,1,AIR)
Block(-2,24,2,AIR)
Block(-2,24,3,AIR)
Block(-2,24,4,AIR)
Block(-2,24,5,AIR)
Block(-2,24,6,AIR)
Block(-2,24,7,AIR)
Block(-2,24,8,AIR)
Block(-2,25,-4,AIR)
Block(-2,25,-3,AIR)
Block(-2,25,-2,AIR)
Block(-2,25,-1,AIR)
Block(-2,25,0,AIR)
Block(-2,25,1,AIR)
Block(-2,25,2,AIR)
Block(-2,25,3,AIR)
Block(-2,25,4,AIR)
Block(-2,25,5,AIR)
Block(-2,25,6,AIR)
Block(-2,25,7,AIR)
Block(-2,25,8,AIR)
Block(-2,26,-4,AIR)
Block(-2,26,-3,AIR)
Block(-2,26,-2,AIR)
Block(-2,26,-1,AIR)
Block(-2,26,0,AIR)
Block(-2,26,1,AIR)
Block(-2,26,2,AIR)
Block(-2,26,3,AIR)
Block(-2,26,4,AIR)
Block(-2,26,5,AIR)
Block(-2,26,6,AIR)
Block(-2,26,7,AIR)
Block(-2,26,8,AIR)
Block(-2,27,-4,AIR)
Block(-2,27,-3,AIR)
Block(-2,27,-2,AIR)
Block(-2,27,-1,AIR)
Block(-2,27,0,AIR)
Block(-2,27,1,AIR)
Block(-2,27,2,AIR)
Block(-2,27,3,AIR)
Block(-2,27,4,AIR)
Block(-2,27,5,AIR)
Block(-2,27,6,AIR)
Block(-2,27,7,AIR)
Block(-2,28,-3,AIR)
Block(-2,28,-2,AIR)
Block(-2,28,-1,AIR)
Block(-2,28,0,AIR)
Block(-2,28,1,AIR)
Block(-2,28,2,AIR)
Block(-2,28,3,AIR)
Block(-2,28,4,AIR)
Block(-2,28,5,AIR)
Block(-2,28,6,AIR)
Block(-2,28,7,AIR)
Block(-2,29,-2,AIR)
Block(-2,29,-1,AIR)
Block(-2,29,0,AIR)
Block(-2,29,1,AIR)
Block(-2,29,2,AIR)
Block(-2,29,3,AIR)
Block(-2,29,4,AIR)
Block(-2,29,5,AIR)
Block(-2,29,6,AIR)
Block(-2,29,7,AIR)
Block(-2,30,-2,AIR)
Block(-2,30,-1,AIR)
Block(-2,30,0,AIR)
Block(-2,30,1,AIR)
Block(-2,30,2,AIR)
Block(-2,30,3,AIR)
Block(-2,30,4,AIR)
Block(-2,30,5,AIR)
Block(-2,30,6,AIR)
Block(-2,31,-1,AIR)
Block(-2,31,0,AIR)
Block(-2,31,1,AIR)
Block(-2,31,2,AIR)
Block(-2,31,3,AIR)
Block(-2,31,4,AIR)
Block(-2,31,5,AIR)
Block(-2,31,6,AIR)
Block(-2,32,-1,AIR)
Block(-2,32,0,AIR)
Block(-2,32,1,AIR)
Block(-2,32,2,AIR)
Block(-2,32,3,AIR)
Block(-2,32,4,AIR)
Block(-2,32,5,AIR)
Block(-2,33,0,AIR)
Block(-2,33,1,AIR)
Block(-2,33,2,AIR)
Block(-2,33,3,AIR)
Block(-2,33,4,AIR)
Block(-2,34,1,AIR)
Block(-2,34,2,AIR)
Block(-2,34,3,AIR)
Block(-2,34,4,AIR)
Block(-2,35,2,AIR)
Block(-1,0,-6,24)
Block(-1,0,-5,24)
Block(-1,0,-4,24)
Block(-1,0,-3,24)
Block(-1,0,-2,24)
Block(-1,0,-1,24)
Block(-1,0,0,24)
Block(-1,0,1,24)
Block(-1,0,2,24)
Block(-1,0,3,24)
Block(-1,0,4,24)
Block(-1,0,5,24)
Block(-1,0,6,24)
Block(-1,0,7,24)
Block(-1,0,8,24)
Block(-1,1,-6,24)
Block(-1,1,-5,24)
Block(-1,1,-4,24)
Block(-1,1,-3,24)
Block(-1,1,-2,24)
Block(-1,1,-1,24)
Block(-1,1,0,24)
Block(-1,1,1,24)
Block(-1,1,2,24)
Block(-1,1,3,24)
Block(-1,1,4,24)
Block(-1,1,5,24)
Block(-1,1,6,24)
Block(-1,1,7,24)
Block(-1,1,8,24)
Block(-1,2,-6,24)
Block(-1,2,-5,24)
Block(-1,2,-4,24)
Block(-1,2,-3,24)
Block(-1,2,-2,24)
Block(-1,2,-1,24)
Block(-1,2,0,24)
Block(-1,2,1,24)
Block(-1,2,2,24)
Block(-1,2,3,24)
Block(-1,2,4,24)
Block(-1,2,5,24)
Block(-1,2,6,24)
Block(-1,2,7,24)
Block(-1,2,8,24)
Block(-1,3,-6,24)
Block(-1,3,-5,24)
Block(-1,3,-4,24)
Block(-1,3,-3,24)
Block(-1,3,-2,24)
Block(-1,3,-1,24)
Block(-1,3,0,24)
Block(-1,3,1,24)
Block(-1,3,2,24)
Block(-1,3,3,24)
Block(-1,3,4,24)
Block(-1,3,5,24)
Block(-1,3,6,24)
Block(-1,3,7,24)
Block(-1,3,8,24)
Block(-1,4,-6,24)
Block(-1,4,-5,24)
Block(-1,4,-4,24)
Block(-1,4,-3,24)
Block(-1,4,-2,24)
Block(-1,4,-1,24)
Block(-1,4,0,24)
Block(-1,4,1,24)
Block(-1,4,2,24)
Block(-1,4,3,24)
Block(-1,4,4,24)
Block(-1,4,5,24)
Block(-1,4,6,24)
Block(-1,4,7,24)
Block(-1,4,8,24)
Block(-1,5,-6,24)
Block(-1,5,-5,24)
Block(-1,5,-4,24)
Block(-1,5,-3,24)
Block(-1,5,-2,24)
Block(-1,5,-1,24)
Block(-1,5,0,24)
Block(-1,5,1,24)
Block(-1,5,2,24)
Block(-1,5,3,24)
Block(-1,5,4,24)
Block(-1,5,5,24)
Block(-1,5,6,24)
Block(-1,5,7,24)
Block(-1,5,8,24)
Block(-1,6,-6,24)
Block(-1,6,-5,24)
Block(-1,6,-4,24)
Block(-1,6,-3,24)
Block(-1,6,-2,24)
Block(-1,6,-1,24)
Block(-1,6,0,24)
Block(-1,6,1,24)
Block(-1,6,2,24)
Block(-1,6,3,24)
Block(-1,6,4,24)
Block(-1,6,5,24)
Block(-1,6,6,24)
Block(-1,6,7,24)
Block(-1,6,8,24)
Block(-1,7,-6,24)
Block(-1,7,-5,24)
Block(-1,7,-4,24)
Block(-1,7,-3,24)
Block(-1,7,-2,24)
Block(-1,7,-1,24)
Block(-1,7,0,24)
Block(-1,7,1,24)
Block(-1,7,2,24)
Block(-1,7,3,24)
Block(-1,7,4,24)
Block(-1,7,5,24)
Block(-1,7,6,24)
Block(-1,7,7,24)
Block(-1,7,8,24)
Block(-1,8,-6,24)
Block(-1,8,-5,24)
Block(-1,8,-4,24)
Block(-1,8,-3,24)
Block(-1,8,-2,24)
Block(-1,8,-1,24)
Block(-1,8,0,24)
Block(-1,8,1,24)
Block(-1,8,2,24)
Block(-1,8,3,24)
Block(-1,8,4,24)
Block(-1,8,5,24)
Block(-1,8,6,24)
Block(-1,8,7,24)
Block(-1,8,8,24)
Block(-1,9,-6,24)
Block(-1,9,-5,24)
Block(-1,9,-4,24)
Block(-1,9,-3,24)
Block(-1,9,-2,24)
Block(-1,9,-1,24)
Block(-1,9,0,24)
Block(-1,9,1,24)
Block(-1,9,2,24)
Block(-1,9,3,24)
Block(-1,9,4,24)
Block(-1,9,5,24)
Block(-1,9,6,24)
Block(-1,9,7,24)
Block(-1,9,8,24)
Block(-1,10,-6,24)
Block(-1,10,-5,24)
Block(-1,10,-4,24)
Block(-1,10,-3,24)
Block(-1,10,-2,24)
Block(-1,10,-1,24)
Block(-1,10,0,24)
Block(-1,10,1,24)
Block(-1,10,2,24)
Block(-1,10,3,24)
Block(-1,10,4,24)
Block(-1,10,5,24)
Block(-1,10,6,24)
Block(-1,10,7,24)
Block(-1,10,8,24)
Block(-1,11,-5,24)
Block(-1,11,-4,24)
Block(-1,11,-3,24)
Block(-1,11,-2,24)
Block(-1,11,-1,24)
Block(-1,11,0,24)
Block(-1,11,1,24)
Block(-1,11,2,24)
Block(-1,11,3,24)
Block(-1,11,4,24)
Block(-1,11,5,24)
Block(-1,11,6,24)
Block(-1,11,7,24)
Block(-1,11,8,24)
Block(-1,12,-4,24)
Block(-1,12,-3,24)
Block(-1,12,-2,24)
Block(-1,12,-1,24)
Block(-1,12,0,24)
Block(-1,12,1,24)
Block(-1,12,2,24)
Block(-1,12,3,24)
Block(-1,12,4,24)
Block(-1,12,5,24)
Block(-1,12,6,24)
Block(-1,12,7,24)
Block(-1,12,8,24)
Block(-1,13,-4,24)
Block(-1,13,-3,24)
Block(-1,13,-2,24)
Block(-1,13,-1,24)
Block(-1,13,0,24)
Block(-1,13,1,24)
Block(-1,13,2,24)
Block(-1,13,3,24)
Block(-1,13,4,24)
Block(-1,13,5,24)
Block(-1,13,6,24)
Block(-1,13,7,24)
Block(-1,13,8,24)
Block(-1,14,-4,24)
Block(-1,14,-3,24)
Block(-1,14,-2,24)
Block(-1,14,-1,24)
Block(-1,14,0,24)
Block(-1,14,1,24)
Block(-1,14,2,24)
Block(-1,14,3,24)
Block(-1,14,4,24)
Block(-1,14,5,24)
Block(-1,14,6,24)
Block(-1,14,7,24)
Block(-1,14,8,24)
Block(-1,15,-4,24)
Block(-1,15,-3,24)
Block(-1,15,-2,24)
Block(-1,15,-1,24)
Block(-1,15,0,24)
Block(-1,15,1,24)
Block(-1,15,2,24)
Block(-1,15,3,24)
Block(-1,15,4,24)
Block(-1,15,5,24)
Block(-1,15,6,24)
Block(-1,15,7,24)
Block(-1,15,8,24)
Block(-1,16,-4,24)
Block(-1,16,-3,AIR)
Block(-1,16,-2,AIR)
Block(-1,16,-1,AIR)
Block(-1,16,0,AIR)
Entity(-1,16,0,Villager,1,Nitwit.txt)
Block(-1,16,1,AIR)
Block(-1,16,2,AIR)
Block(-1,16,3,24)
Block(-1,16,4,135:7)
Block(-1,16,5,53:2)
Block(-1,16,6,AIR)
Block(-1,16,7,AIR)
Block(-1,16,8,24)
Block(-1,17,-4,24)
Block(-1,17,-3,AIR)
Block(-1,17,-2,AIR)
Block(-1,17,-1,AIR)
Block(-1,17,0,AIR)
Block(-1,17,1,AIR)
Block(-1,17,2,AIR)
Block(-1,17,3,24)
Block(-1,17,4,AIR)
Block(-1,17,5,AIR)
Block(-1,17,6,AIR)
Block(-1,17,7,AIR)
Block(-1,17,8,24)
Block(-1,18,-4,24)
Block(-1,18,-3,AIR)
Block(-1,18,-2,AIR)
Block(-1,18,-1,AIR)
Block(-1,18,0,AIR)
Block(-1,18,1,AIR)
Block(-1,18,2,AIR)
Block(-1,18,3,24)
Block(-1,18,4,126:12)
Block(-1,18,5,AIR)
Block(-1,18,6,AIR)
Block(-1,18,7,AIR)
Block(-1,18,8,24)
Block(-1,19,-4,24)
Block(-1,19,-3,AIR)
Block(-1,19,-2,AIR)
Block(-1,19,-1,AIR)
Block(-1,19,0,AIR)
Block(-1,19,1,AIR)
Block(-1,19,2,AIR)
Block(-1,19,3,24)
Block(-1,19,4,47)
Block(-1,19,5,AIR)
Block(-1,19,6,AIR)
Block(-1,19,7,AIR)
Block(-1,19,8,24)
Block(-1,20,-4,126:4)
Block(-1,20,-3,5:4)
Block(-1,20,-2,5:4)
Block(-1,20,-1,5:4)
Block(-1,20,0,5:4)
Block(-1,20,1,5:4)
Block(-1,20,2,5:4)
Block(-1,20,3,5:4)
Block(-1,20,4,5:4)
Block(-1,20,5,5:4)
Block(-1,20,6,5:4)
Block(-1,20,7,5:4)
Block(-1,20,8,126:4)
Block(-1,21,-4,AIR)
Block(-1,21,-3,AIR)
Block(-1,21,-2,AIR)
Block(-1,21,-1,AIR)
Block(-1,21,0,AIR)
Block(-1,21,1,AIR)
Block(-1,21,2,AIR)
Block(-1,21,3,AIR)
Block(-1,21,4,AIR)
Block(-1,21,5,AIR)
Block(-1,21,6,AIR)
Block(-1,21,7,AIR)
Block(-1,21,8,AIR)
Block(-1,22,-4,AIR)
Block(-1,22,-3,AIR)
Block(-1,22,-2,AIR)
Block(-1,22,-1,AIR)
Block(-1,22,0,AIR)
Block(-1,22,1,AIR)
Block(-1,22,2,AIR)
Block(-1,22,3,AIR)
Block(-1,22,4,AIR)
Block(-1,22,5,AIR)
Block(-1,22,6,AIR)
Block(-1,22,7,AIR)
Block(-1,22,8,AIR)
Block(-1,23,-4,AIR)
Block(-1,23,-3,AIR)
Block(-1,23,-2,AIR)
Block(-1,23,-1,AIR)
Block(-1,23,0,AIR)
Block(-1,23,1,AIR)
Block(-1,23,2,AIR)
Block(-1,23,3,AIR)
Block(-1,23,4,AIR)
Block(-1,23,5,AIR)
Block(-1,23,6,AIR)
Block(-1,23,7,AIR)
Block(-1,23,8,AIR)
Block(-1,24,-4,AIR)
Block(-1,24,-3,AIR)
Block(-1,24,-2,AIR)
Block(-1,24,-1,AIR)
Block(-1,24,0,AIR)
Block(-1,24,1,AIR)
Block(-1,24,2,AIR)
Block(-1,24,3,AIR)
Block(-1,24,4,AIR)
Block(-1,24,5,AIR)
Block(-1,24,6,AIR)
Block(-1,24,7,AIR)
Block(-1,24,8,AIR)
Block(-1,25,-4,AIR)
Block(-1,25,-3,AIR)
Block(-1,25,-2,AIR)
Block(-1,25,-1,AIR)
Block(-1,25,0,AIR)
Block(-1,25,1,AIR)
Block(-1,25,2,AIR)
Block(-1,25,3,AIR)
Block(-1,25,4,AIR)
Block(-1,25,5,AIR)
Block(-1,25,6,AIR)
Block(-1,25,7,AIR)
Block(-1,25,8,AIR)
Block(-1,26,-4,AIR)
Block(-1,26,-3,AIR)
Block(-1,26,-2,AIR)
Block(-1,26,-1,AIR)
Block(-1,26,0,AIR)
Block(-1,26,1,AIR)
Block(-1,26,2,AIR)
Block(-1,26,3,AIR)
Block(-1,26,4,AIR)
Block(-1,26,5,AIR)
Block(-1,26,6,AIR)
Block(-1,26,7,AIR)
Block(-1,26,8,AIR)
Block(-1,27,-4,AIR)
Block(-1,27,-3,AIR)
Block(-1,27,-2,AIR)
Block(-1,27,-1,AIR)
Block(-1,27,0,AIR)
Block(-1,27,1,AIR)
Block(-1,27,2,AIR)
Block(-1,27,3,AIR)
Block(-1,27,4,AIR)
Block(-1,27,5,AIR)
Block(-1,27,6,AIR)
Block(-1,27,7,AIR)
Block(-1,27,8,AIR)
Block(-1,28,-3,AIR)
Block(-1,28,-2,AIR)
Block(-1,28,-1,AIR)
Block(-1,28,0,AIR)
Block(-1,28,1,AIR)
Block(-1,28,2,AIR)
Block(-1,28,3,AIR)
Block(-1,28,4,AIR)
Block(-1,28,5,AIR)
Block(-1,28,6,AIR)
Block(-1,28,7,AIR)
Block(-1,29,-3,AIR)
Block(-1,29,-2,AIR)
Block(-1,29,-1,AIR)
Block(-1,29,0,AIR)
Block(-1,29,1,AIR)
Block(-1,29,2,AIR)
Block(-1,29,3,AIR)
Block(-1,29,4,AIR)
Block(-1,29,5,AIR)
Block(-1,29,6,AIR)
Block(-1,29,7,AIR)
Block(-1,30,-3,AIR)
Block(-1,30,-2,AIR)
Block(-1,30,-1,AIR)
Block(-1,30,0,AIR)
Block(-1,30,1,AIR)
Block(-1,30,2,AIR)
Block(-1,30,3,AIR)
Block(-1,30,4,AIR)
Block(-1,30,5,AIR)
Block(-1,30,6,AIR)
Block(-1,30,7,AIR)
Block(-1,31,-2,AIR)
Block(-1,31,-1,AIR)
Block(-1,31,0,AIR)
Block(-1,31,1,AIR)
Block(-1,31,2,AIR)
Block(-1,31,3,AIR)
Block(-1,31,4,AIR)
Block(-1,31,5,AIR)
Block(-1,31,6,AIR)
Block(-1,31,7,AIR)
Block(-1,32,-2,AIR)
Block(-1,32,-1,AIR)
Block(-1,32,0,AIR)
Block(-1,32,1,AIR)
Block(-1,32,2,AIR)
Block(-1,32,3,AIR)
Block(-1,32,4,AIR)
Block(-1,32,5,AIR)
Block(-1,32,6,AIR)
Block(-1,33,-1,AIR)
Block(-1,33,0,AIR)
Block(-1,33,1,AIR)
Block(-1,33,2,AIR)
Block(-1,33,3,AIR)
Block(-1,33,4,AIR)
Block(-1,33,5,AIR)
Block(-1,33,6,AIR)
Block(-1,34,-1,AIR)
Block(-1,34,0,AIR)
Block(-1,34,1,AIR)
Block(-1,34,2,AIR)
Block(-1,34,3,AIR)
Block(-1,34,4,AIR)
Block(-1,34,5,AIR)
Block(-1,35,-1,AIR)
Block(-1,35,0,AIR)
Block(-1,35,1,AIR)
Block(-1,35,2,AIR)
Block(-1,35,3,AIR)
Block(-1,35,4,AIR)
Block(-1,35,5,AIR)
Block(-1,36,0,AIR)
Block(-1,36,1,AIR)
Block(-1,36,2,AIR)
Block(-1,36,3,AIR)
Block(-1,36,4,AIR)
Block(-1,37,1,AIR)
Block(-1,37,2,AIR)
Block(-1,37,3,AIR)
Block(0,0,-6,24)
Block(0,0,-5,24)
Block(0,0,-4,24)
Block(0,0,-3,24)
Block(0,0,-2,24)
Block(0,0,-1,24)
Block(0,0,0,24)
Block(0,0,1,24)
Block(0,0,2,24)
Block(0,0,3,24)
Block(0,0,4,24)
Block(0,0,5,24)
Block(0,0,6,24)
Block(0,0,7,24)
Block(0,0,8,24)
Block(0,1,-6,24)
Block(0,1,-5,24)
Block(0,1,-4,24)
Block(0,1,-3,24)
Block(0,1,-2,24)
Block(0,1,-1,24)
Block(0,1,0,24)
Block(0,1,1,24)
Block(0,1,2,24)
Block(0,1,3,24)
Block(0,1,4,24)
Block(0,1,5,24)
Block(0,1,6,24)
Block(0,1,7,24)
Block(0,1,8,24)
Block(0,2,-6,24)
Block(0,2,-5,24)
Block(0,2,-4,24)
Block(0,2,-3,24)
Block(0,2,-2,24)
Block(0,2,-1,24)
Block(0,2,0,24)
Block(0,2,1,24)
Block(0,2,2,24)
Block(0,2,3,24)
Block(0,2,4,24)
Block(0,2,5,24)
Block(0,2,6,24)
Block(0,2,7,24)
Block(0,2,8,24)
Block(0,3,-6,24)
Block(0,3,-5,24)
Block(0,3,-4,24)
Block(0,3,-3,24)
Block(0,3,-2,24)
Block(0,3,-1,24)
Block(0,3,0,24)
Block(0,3,1,24)
Block(0,3,2,24)
Block(0,3,3,24)
Block(0,3,4,24)
Block(0,3,5,24)
Block(0,3,6,24)
Block(0,3,7,24)
Block(0,3,8,24)
Block(0,4,-6,24)
Block(0,4,-5,24)
Block(0,4,-4,24)
Block(0,4,-3,24)
Block(0,4,-2,24)
Block(0,4,-1,24)
Block(0,4,0,24)
Block(0,4,1,24)
Block(0,4,2,24)
Block(0,4,3,24)
Block(0,4,4,24)
Block(0,4,5,24)
Block(0,4,6,24)
Block(0,4,7,24)
Block(0,4,8,24)
Block(0,5,-6,24)
Block(0,5,-5,24)
Block(0,5,-4,24)
Block(0,5,-3,24)
Block(0,5,-2,24)
Block(0,5,-1,24)
Block(0,5,0,24)
Block(0,5,1,24)
Block(0,5,2,24)
Block(0,5,3,24)
Block(0,5,4,24)
Block(0,5,5,24)
Block(0,5,6,24)
Block(0,5,7,24)
Block(0,5,8,24)
Block(0,6,-6,24)
Block(0,6,-5,24)
Block(0,6,-4,24)
Block(0,6,-3,24)
Block(0,6,-2,24)
Block(0,6,-1,24)
Block(0,6,0,24)
Block(0,6,1,24)
Block(0,6,2,24)
Block(0,6,3,24)
Block(0,6,4,24)
Block(0,6,5,24)
Block(0,6,6,24)
Block(0,6,7,24)
Block(0,6,8,24)
Block(0,7,-6,24)
Block(0,7,-5,24)
Block(0,7,-4,24)
Block(0,7,-3,24)
Block(0,7,-2,24)
Block(0,7,-1,24)
Block(0,7,0,24)
Block(0,7,1,24)
Block(0,7,2,24)
Block(0,7,3,24)
Block(0,7,4,24)
Block(0,7,5,24)
Block(0,7,6,24)
Block(0,7,7,24)
Block(0,7,8,24)
Block(0,8,-6,24)
Block(0,8,-5,24)
Block(0,8,-4,24)
Block(0,8,-3,24)
Block(0,8,-2,24)
Block(0,8,-1,24)
Block(0,8,0,24)
Block(0,8,1,24)
Block(0,8,2,24)
Block(0,8,3,24)
Block(0,8,4,24)
Block(0,8,5,24)
Block(0,8,6,24)
Block(0,8,7,24)
Block(0,8,8,24)
Block(0,9,-6,24)
Block(0,9,-5,24)
Block(0,9,-4,24)
Block(0,9,-3,24)
Block(0,9,-2,24)
Block(0,9,-1,24)
Block(0,9,0,24)
Block(0,9,1,24)
Block(0,9,2,24)
Block(0,9,3,24)
Block(0,9,4,24)
Block(0,9,5,24)
Block(0,9,6,24)
Block(0,9,7,24)
Block(0,9,8,24)
Block(0,10,-6,24)
Block(0,10,-5,24)
Block(0,10,-4,24)
Block(0,10,-3,24)
Block(0,10,-2,24)
Block(0,10,-1,24)
Block(0,10,0,24)
Block(0,10,1,24)
Block(0,10,2,24)
Block(0,10,3,24)
Block(0,10,4,24)
Block(0,10,5,24)
Block(0,10,6,24)
Block(0,10,7,24)
Block(0,10,8,24)
Block(0,11,-5,24)
Block(0,11,-4,24)
Block(0,11,-3,24)
Block(0,11,-2,24)
Block(0,11,-1,24)
Block(0,11,0,24)
Block(0,11,1,24)
Block(0,11,2,24)
Block(0,11,3,24)
Block(0,11,4,24)
Block(0,11,5,24)
Block(0,11,6,24)
Block(0,11,7,24)
Block(0,11,8,24)
Block(0,12,-4,24)
Block(0,12,-3,24)
Block(0,12,-2,24)
Block(0,12,-1,24)
Block(0,12,0,24)
Block(0,12,1,24)
Block(0,12,2,24)
Block(0,12,3,24)
Block(0,12,4,24)
Block(0,12,5,24)
Block(0,12,6,24)
Block(0,12,7,24)
Block(0,12,8,24)
Block(0,13,-4,24)
Block(0,13,-3,24)
Block(0,13,-2,24)
Block(0,13,-1,24)
Block(0,13,0,24)
Block(0,13,1,24)
Block(0,13,2,24)
Block(0,13,3,24)
Block(0,13,4,24)
Block(0,13,5,24)
Block(0,13,6,24)
Block(0,13,7,24)
Block(0,13,8,24)
Block(0,14,-4,24)
Block(0,14,-3,24)
Block(0,14,-2,24)
Block(0,14,-1,24)
Block(0,14,0,24)
Block(0,14,1,24)
Block(0,14,2,24)
Block(0,14,3,24)
Block(0,14,4,24)
Block(0,14,5,24)
Block(0,14,6,24)
Block(0,14,7,24)
Block(0,14,8,24)
Block(0,15,-4,24)
Block(0,15,-3,24)
Block(0,15,-2,24)
Block(0,15,-1,24)
Block(0,15,0,24)
Block(0,15,1,24)
Block(0,15,2,24)
Block(0,15,3,24)
Block(0,15,4,24)
Block(0,15,5,24)
Block(0,15,6,24)
Block(0,15,7,24)
Block(0,15,8,24)
Block(0,16,-4,24)
Block(0,16,-3,AIR)
Block(0,16,-2,AIR)
Block(0,16,-1,AIR)
Block(0,16,0,AIR)
Block(0,16,1,AIR)
Block(0,16,2,AIR)
Block(0,16,3,24)
Block(0,16,4,135:7)
Block(0,16,5,AIR)
Block(0,16,6,AIR)
Block(0,16,7,AIR)
Block(0,16,8,24)
Block(0,17,-4,24)
Block(0,17,-3,AIR)
Block(0,17,-2,AIR)
Block(0,17,-1,AIR)
Block(0,17,0,AIR)
Block(0,17,1,AIR)
Block(0,17,2,AIR)
Block(0,17,3,24)
Block(0,17,4,AIR)
Block(0,17,5,AIR)
Block(0,17,6,AIR)
Block(0,17,7,AIR)
Block(0,17,8,24)
Block(0,18,-4,24)
Block(0,18,-3,AIR)
Block(0,18,-2,AIR)
Block(0,18,-1,AIR)
Block(0,18,0,AIR)
Block(0,18,1,AIR)
Block(0,18,2,AIR)
Block(0,18,3,24)
Block(0,18,4,126:12)
Block(0,18,5,AIR)
Block(0,18,6,AIR)
Block(0,18,7,AIR)
Block(0,18,8,24)
Block(0,19,-4,24)
Block(0,19,-3,AIR)
Block(0,19,-2,AIR)
Block(0,19,-1,AIR)
Block(0,19,0,AIR)
Block(0,19,1,AIR)
Block(0,19,2,AIR)
Block(0,19,3,24)
Block(0,19,4,47)
Block(0,19,5,AIR)
Block(0,19,6,AIR)
Block(0,19,7,AIR)
Block(0,19,8,24)
Block(0,20,-4,126:4)
Block(0,20,-3,5:4)
Block(0,20,-2,5:4)
Block(0,20,-1,5:4)
Block(0,20,0,5:4)
Block(0,20,1,5:4)
Block(0,20,2,5:4)
Block(0,20,3,5:4)
Block(0,20,4,5:4)
Block(0,20,5,5:4)
Block(0,20,6,5:4)
Block(0,20,7,5:4)
Block(0,20,8,126:4)
Block(0,21,-4,AIR)
Block(0,21,-3,AIR)
Block(0,21,-2,AIR)
Block(0,21,-1,AIR)
Block(0,21,0,AIR)
Block(0,21,1,AIR)
Block(0,21,2,AIR)
Block(0,21,3,AIR)
Block(0,21,4,AIR)
Block(0,21,5,AIR)
Block(0,21,6,AIR)
Block(0,21,7,AIR)
Block(0,21,8,AIR)
Block(0,22,-4,AIR)
Block(0,22,-3,AIR)
Block(0,22,-2,AIR)
Block(0,22,-1,AIR)
Block(0,22,0,AIR)
Block(0,22,1,AIR)
Block(0,22,2,AIR)
Block(0,22,3,AIR)
Block(0,22,4,AIR)
Block(0,22,5,AIR)
Block(0,22,6,AIR)
Block(0,22,7,AIR)
Block(0,22,8,AIR)
Block(0,23,-4,AIR)
Block(0,23,-3,AIR)
Block(0,23,-2,AIR)
Block(0,23,-1,AIR)
Block(0,23,0,AIR)
Block(0,23,1,AIR)
Block(0,23,2,AIR)
Block(0,23,3,AIR)
Block(0,23,4,AIR)
Block(0,23,5,AIR)
Block(0,23,6,AIR)
Block(0,23,7,AIR)
Block(0,23,8,AIR)
Block(0,24,-4,AIR)
Block(0,24,-3,AIR)
Block(0,24,-2,AIR)
Block(0,24,-1,AIR)
Block(0,24,0,AIR)
Block(0,24,1,AIR)
Block(0,24,2,AIR)
Block(0,24,3,AIR)
Block(0,24,4,AIR)
Block(0,24,5,AIR)
Block(0,24,6,AIR)
Block(0,24,7,AIR)
Block(0,24,8,AIR)
Block(0,25,-4,AIR)
Block(0,25,-3,AIR)
Block(0,25,-2,AIR)
Block(0,25,-1,AIR)
Block(0,25,0,AIR)
Block(0,25,1,AIR)
Block(0,25,2,AIR)
Block(0,25,3,AIR)
Block(0,25,4,AIR)
Block(0,25,5,AIR)
Block(0,25,6,AIR)
Block(0,25,7,AIR)
Block(0,25,8,AIR)
Block(0,26,-4,AIR)
Block(0,26,-3,AIR)
Block(0,26,-2,AIR)
Block(0,26,-1,AIR)
Block(0,26,0,AIR)
Block(0,26,1,AIR)
Block(0,26,2,AIR)
Block(0,26,3,AIR)
Block(0,26,4,AIR)
Block(0,26,5,AIR)
Block(0,26,6,AIR)
Block(0,26,7,AIR)
Block(0,26,8,AIR)
Block(0,27,-4,AIR)
Block(0,27,-3,AIR)
Block(0,27,-2,AIR)
Block(0,27,-1,AIR)
Block(0,27,0,AIR)
Block(0,27,1,AIR)
Block(0,27,2,AIR)
Block(0,27,3,AIR)
Block(0,27,4,AIR)
Block(0,27,5,AIR)
Block(0,27,6,AIR)
Block(0,27,7,AIR)
Block(0,27,8,AIR)
Block(0,28,-3,AIR)
Block(0,28,-2,AIR)
Block(0,28,-1,AIR)
Block(0,28,0,AIR)
Block(0,28,1,AIR)
Block(0,28,2,AIR)
Block(0,28,3,AIR)
Block(0,28,4,AIR)
Block(0,28,5,AIR)
Block(0,28,6,AIR)
Block(0,28,7,AIR)
Block(0,28,8,AIR)
Block(0,29,-3,AIR)
Block(0,29,-2,AIR)
Block(0,29,-1,AIR)
Block(0,29,0,AIR)
Block(0,29,1,AIR)
Block(0,29,2,AIR)
Block(0,29,3,AIR)
Block(0,29,4,AIR)
Block(0,29,5,AIR)
Block(0,29,6,AIR)
Block(0,29,7,AIR)
Block(0,30,-3,AIR)
Block(0,30,-2,AIR)
Block(0,30,-1,AIR)
Block(0,30,0,AIR)
Block(0,30,1,AIR)
Block(0,30,2,AIR)
Block(0,30,3,AIR)
Block(0,30,4,AIR)
Block(0,30,5,AIR)
Block(0,30,6,AIR)
Block(0,30,7,AIR)
Block(0,31,-3,AIR)
Block(0,31,-2,AIR)
Block(0,31,-1,AIR)
Block(0,31,0,AIR)
Block(0,31,1,AIR)
Block(0,31,2,AIR)
Block(0,31,3,AIR)
Block(0,31,4,AIR)
Block(0,31,5,AIR)
Block(0,31,6,AIR)
Block(0,31,7,AIR)
Block(0,32,-2,AIR)
Block(0,32,-1,AIR)
Block(0,32,0,AIR)
Block(0,32,1,AIR)
Block(0,32,2,AIR)
Block(0,32,3,AIR)
Block(0,32,4,AIR)
Block(0,32,5,AIR)
Block(0,32,6,AIR)
Block(0,32,7,AIR)
Block(0,33,-2,AIR)
Block(0,33,-1,AIR)
Block(0,33,0,AIR)
Block(0,33,1,AIR)
Block(0,33,2,AIR)
Block(0,33,3,AIR)
Block(0,33,4,AIR)
Block(0,33,5,AIR)
Block(0,33,6,AIR)
Block(0,34,-2,AIR)
Block(0,34,-1,AIR)
Block(0,34,0,AIR)
Block(0,34,1,AIR)
Block(0,34,2,AIR)
Block(0,34,3,AIR)
Block(0,34,4,AIR)
Block(0,34,5,AIR)
Block(0,34,6,AIR)
Block(0,35,-1,AIR)
Block(0,35,0,AIR)
Block(0,35,1,AIR)
Block(0,35,2,AIR)
Block(0,35,3,AIR)
Block(0,35,4,AIR)
Block(0,35,5,AIR)
Block(0,35,6,AIR)
Block(0,36,-1,AIR)
Block(0,36,0,AIR)
Block(0,36,1,AIR)
Block(0,36,2,AIR)
Block(0,36,3,AIR)
Block(0,36,4,AIR)
Block(0,36,5,AIR)
Block(0,36,6,AIR)
Block(0,37,0,AIR)
Block(0,37,1,AIR)
Block(0,37,2,AIR)
Block(0,37,3,AIR)
Block(0,37,4,AIR)
Block(0,37,5,AIR)
Block(0,38,0,AIR)
Block(0,38,1,AIR)
Block(0,38,2,AIR)
Block(0,38,3,AIR)
Block(0,38,4,AIR)
Block(0,38,5,AIR)
Block(0,39,2,AIR)
Block(0,39,3,AIR)
Block(0,39,4,AIR)
Block(1,0,-6,24)
Block(1,0,-5,24)
Block(1,0,-4,24)
Block(1,0,-3,24)
Block(1,0,-2,24)
Block(1,0,-1,24)
Block(1,0,0,24)
Block(1,0,1,24)
Block(1,0,2,24)
Block(1,0,3,24)
Block(1,0,4,24)
Block(1,0,5,24)
Block(1,0,6,24)
Block(1,0,7,24)
Block(1,0,8,24)
Block(1,1,-6,24)
Block(1,1,-5,24)
Block(1,1,-4,24)
Block(1,1,-3,24)
Block(1,1,-2,24)
Block(1,1,-1,24)
Block(1,1,0,24)
Block(1,1,1,24)
Block(1,1,2,24)
Block(1,1,3,24)
Block(1,1,4,24)
Block(1,1,5,24)
Block(1,1,6,24)
Block(1,1,7,24)
Block(1,1,8,24)
Block(1,2,-6,24)
Block(1,2,-5,24)
Block(1,2,-4,24)
Block(1,2,-3,24)
Block(1,2,-2,24)
Block(1,2,-1,24)
Block(1,2,0,24)
Block(1,2,1,24)
Block(1,2,2,24)
Block(1,2,3,24)
Block(1,2,4,24)
Block(1,2,5,24)
Block(1,2,6,24)
Block(1,2,7,24)
Block(1,2,8,24)
Block(1,3,-6,24)
Block(1,3,-5,24)
Block(1,3,-4,24)
Block(1,3,-3,24)
Block(1,3,-2,24)
Block(1,3,-1,24)
Block(1,3,0,24)
Block(1,3,1,24)
Block(1,3,2,24)
Block(1,3,3,24)
Block(1,3,4,24)
Block(1,3,5,24)
Block(1,3,6,24)
Block(1,3,7,24)
Block(1,3,8,24)
Block(1,4,-6,24)
Block(1,4,-5,24)
Block(1,4,-4,24)
Block(1,4,-3,24)
Block(1,4,-2,24)
Block(1,4,-1,24)
Block(1,4,0,24)
Block(1,4,1,24)
Block(1,4,2,24)
Block(1,4,3,24)
Block(1,4,4,24)
Block(1,4,5,24)
Block(1,4,6,24)
Block(1,4,7,24)
Block(1,4,8,24)
Block(1,5,-6,24)
Block(1,5,-5,24)
Block(1,5,-4,24)
Block(1,5,-3,24)
Block(1,5,-2,24)
Block(1,5,-1,24)
Block(1,5,0,24)
Block(1,5,1,24)
Block(1,5,2,24)
Block(1,5,3,24)
Block(1,5,4,24)
Block(1,5,5,24)
Block(1,5,6,24)
Block(1,5,7,24)
Block(1,5,8,24)
Block(1,6,-6,24)
Block(1,6,-5,24)
Block(1,6,-4,24)
Block(1,6,-3,24)
Block(1,6,-2,24)
Block(1,6,-1,24)
Block(1,6,0,24)
Block(1,6,1,24)
Block(1,6,2,24)
Block(1,6,3,24)
Block(1,6,4,24)
Block(1,6,5,24)
Block(1,6,6,24)
Block(1,6,7,24)
Block(1,6,8,24)
Block(1,7,-6,24)
Block(1,7,-5,24)
Block(1,7,-4,24)
Block(1,7,-3,24)
Block(1,7,-2,24)
Block(1,7,-1,24)
Block(1,7,0,24)
Block(1,7,1,24)
Block(1,7,2,24)
Block(1,7,3,24)
Block(1,7,4,24)
Block(1,7,5,24)
Block(1,7,6,24)
Block(1,7,7,24)
Block(1,7,8,24)
Block(1,8,-6,24)
Block(1,8,-5,24)
Block(1,8,-4,24)
Block(1,8,-3,24)
Block(1,8,-2,24)
Block(1,8,-1,24)
Block(1,8,0,24)
Block(1,8,1,24)
Block(1,8,2,24)
Block(1,8,3,24)
Block(1,8,4,24)
Block(1,8,5,24)
Block(1,8,6,24)
Block(1,8,7,24)
Block(1,8,8,24)
Block(1,9,-6,24)
Block(1,9,-5,24)
Block(1,9,-4,24)
Block(1,9,-3,24)
Block(1,9,-2,24)
Block(1,9,-1,24)
Block(1,9,0,24)
Block(1,9,1,24)
Block(1,9,2,24)
Block(1,9,3,24)
Block(1,9,4,24)
Block(1,9,5,24)
Block(1,9,6,24)
Block(1,9,7,24)
Block(1,9,8,24)
Block(1,10,-6,24)
Block(1,10,-5,24)
Block(1,10,-4,24)
Block(1,10,-3,24)
Block(1,10,-2,24)
Block(1,10,-1,24)
Block(1,10,0,24)
Block(1,10,1,24)
Block(1,10,2,24)
Block(1,10,3,24)
Block(1,10,4,24)
Block(1,10,5,24)
Block(1,10,6,24)
Block(1,10,7,24)
Block(1,10,8,24)
Block(1,11,-5,24)
Block(1,11,-4,24)
Block(1,11,-3,24)
Block(1,11,-2,24)
Block(1,11,-1,24)
Block(1,11,0,24)
Block(1,11,1,24)
Block(1,11,2,24)
Block(1,11,3,24)
Block(1,11,4,24)
Block(1,11,5,24)
Block(1,11,6,24)
Block(1,11,7,24)
Block(1,11,8,24)
Block(1,12,-4,24)
Block(1,12,-3,24)
Block(1,12,-2,24)
Block(1,12,-1,24)
Block(1,12,0,24)
Block(1,12,1,24)
Block(1,12,2,24)
Block(1,12,3,24)
Block(1,12,4,24)
Block(1,12,5,24)
Block(1,12,6,24)
Block(1,12,7,24)
Block(1,12,8,24)
Block(1,13,-4,24)
Block(1,13,-3,24)
Block(1,13,-2,24)
Block(1,13,-1,24)
Block(1,13,0,24)
Block(1,13,1,24)
Block(1,13,2,24)
Block(1,13,3,24)
Block(1,13,4,24)
Block(1,13,5,24)
Block(1,13,6,24)
Block(1,13,7,24)
Block(1,13,8,24)
Block(1,14,-4,24)
Block(1,14,-3,24)
Block(1,14,-2,24)
Block(1,14,-1,24)
Block(1,14,0,24)
Block(1,14,1,24)
Block(1,14,2,24)
Block(1,14,3,24)
Block(1,14,4,24)
Block(1,14,5,24)
Block(1,14,6,24)
Block(1,14,7,24)
Block(1,14,8,24)
Block(1,15,-4,24)
Block(1,15,-3,24)
Block(1,15,-2,24)
Block(1,15,-1,24)
Block(1,15,0,24)
Block(1,15,1,24)
Block(1,15,2,24)
Block(1,15,3,24)
Block(1,15,4,24)
Block(1,15,5,24)
Block(1,15,6,24)
Block(1,15,7,24)
Block(1,15,8,24)
Block(1,16,-4,24)
Block(1,16,-3,24)
Block(1,16,-2,24)
Block(1,16,-1,24)
Block(1,16,0,196:2)
Block(1,16,1,24)
Block(1,16,2,24)
Block(1,16,3,24)
Block(1,16,4,135:4)
Block(1,16,5,AIR)
Block(1,16,6,AIR)
Block(1,16,7,AIR)
Block(1,16,8,24)
Block(1,17,-4,24)
Block(1,17,-3,24)
Block(1,17,-2,24)
Block(1,17,-1,24)
Block(1,17,0,196:8)
Block(1,17,1,24)
Block(1,17,2,24)
Block(1,17,3,24)
Block(1,17,5,AIR)
Block(1,17,6,AIR)
Block(1,17,7,AIR)
Block(1,17,8,192)
Block(1,18,-4,24)
Block(1,18,-3,24)
Block(1,18,-2,24)
Block(1,18,-1,24)
Block(1,18,0,5:4)
Block(1,18,1,24)
Block(1,18,2,24)
Block(1,18,3,24)
Block(1,18,4,126:12)
Block(1,18,5,AIR)
Block(1,18,6,AIR)
Block(1,18,7,AIR)
Block(1,18,8,24)
Block(1,19,-4,24)
Block(1,19,-3,24)
Block(1,19,-2,24)
Block(1,19,-1,24)
Block(1,19,0,24)
Block(1,19,1,24)
Block(1,19,2,24)
Block(1,19,3,24)
Block(1,19,4,47)
Block(1,19,5,AIR)
Block(1,19,6,AIR)
Block(1,19,7,AIR)
Block(1,19,8,24)
Block(1,20,-4,126:4)
Block(1,20,-3,5:4)
Block(1,20,-2,126:4)
Block(1,20,-1,126:4)
Block(1,20,0,126:4)
Block(1,20,1,126:4)
Block(1,20,2,126:4)
Block(1,20,3,126:4)
Block(1,20,4,24)
Block(1,20,5,5:4)
Block(1,20,6,5:4)
Block(1,20,7,5:4)
Block(1,20,8,24)
Block(1,21,-4,AIR)
Block(1,21,-3,AIR)
Block(1,21,-2,AIR)
Block(1,21,-1,AIR)
Block(1,21,0,AIR)
Block(1,21,1,AIR)
Block(1,21,2,AIR)
Block(1,21,3,AIR)
Block(1,21,4,24)
Block(1,21,5,196)
Block(1,21,6,24)
Block(1,21,7,24)
Block(1,21,8,24)
Block(1,22,-4,AIR)
Block(1,22,-3,AIR)
Block(1,22,-2,AIR)
Block(1,22,-1,AIR)
Block(1,22,0,AIR)
Block(1,22,1,AIR)
Block(1,22,2,AIR)
Block(1,22,3,AIR)
Block(1,22,4,24)
Block(1,22,5,196:8)
Block(1,22,6,24)
Block(1,22,7,24)
Block(1,22,8,24)
Block(1,23,-4,AIR)
Block(1,23,-3,AIR)
Block(1,23,-2,AIR)
Block(1,23,-1,AIR)
Block(1,23,0,AIR)
Block(1,23,1,AIR)
Block(1,23,2,AIR)
Block(1,23,3,AIR)
Block(1,23,4,24)
Block(1,23,5,24)
Block(1,23,6,24)
Block(1,23,7,24)
Block(1,23,8,24)
Block(1,24,-4,AIR)
Block(1,24,-3,AIR)
Block(1,24,-2,AIR)
Block(1,24,-1,AIR)
Block(1,24,0,AIR)
Block(1,24,1,AIR)
Block(1,24,2,AIR)
Block(1,24,3,AIR)
Block(1,24,4,126:4)
Block(1,24,5,126:4)
Block(1,24,6,126:4)
Block(1,24,7,126:4)
Block(1,24,8,126:4)
Block(1,25,-4,AIR)
Block(1,25,-3,AIR)
Block(1,25,-2,AIR)
Block(1,25,-1,AIR)
Block(1,25,0,AIR)
Block(1,25,1,AIR)
Block(1,25,2,AIR)
Block(1,25,3,AIR)
Block(1,25,4,AIR)
Block(1,25,5,AIR)
Block(1,25,6,AIR)
Block(1,25,7,AIR)
Block(1,25,8,AIR)
Block(1,26,-4,AIR)
Block(1,26,-3,AIR)
Block(1,26,-2,AIR)
Block(1,26,-1,AIR)
Block(1,26,0,AIR)
Block(1,26,1,AIR)
Block(1,26,2,AIR)
Block(1,26,3,AIR)
Block(1,26,4,AIR)
Block(1,26,5,AIR)
Block(1,26,6,AIR)
Block(1,26,7,AIR)
Block(1,26,8,AIR)
Block(1,27,-4,AIR)
Block(1,27,-3,AIR)
Block(1,27,-2,AIR)
Block(1,27,-1,AIR)
Block(1,27,0,AIR)
Block(1,27,1,AIR)
Block(1,27,2,AIR)
Block(1,27,3,AIR)
Block(1,27,4,AIR)
Block(1,27,5,AIR)
Block(1,27,6,AIR)
Block(1,27,7,AIR)
Block(1,27,8,AIR)
Block(1,28,-3,AIR)
Block(1,28,-2,AIR)
Block(1,28,-1,AIR)
Block(1,28,0,AIR)
Block(1,28,1,AIR)
Block(1,28,2,AIR)
Block(1,28,3,AIR)
Block(1,28,4,AIR)
Block(1,28,5,AIR)
Block(1,28,6,AIR)
Block(1,28,7,AIR)
Block(1,28,8,AIR)
Block(1,29,-3,AIR)
Block(1,29,-2,AIR)
Block(1,29,-1,AIR)
Block(1,29,0,AIR)
Block(1,29,1,AIR)
Block(1,29,2,AIR)
Block(1,29,3,AIR)
Block(1,29,4,AIR)
Block(1,29,5,AIR)
Block(1,29,6,AIR)
Block(1,29,7,AIR)
Block(1,29,8,AIR)
Block(1,30,-3,AIR)
Block(1,30,-2,AIR)
Block(1,30,-1,AIR)
Block(1,30,0,AIR)
Block(1,30,1,AIR)
Block(1,30,2,AIR)
Block(1,30,3,AIR)
Block(1,30,4,AIR)
Block(1,30,5,AIR)
Block(1,30,6,AIR)
Block(1,30,7,AIR)
Block(1,30,8,AIR)
Block(1,31,-3,AIR)
Block(1,31,-2,AIR)
Block(1,31,-1,AIR)
Block(1,31,0,AIR)
Block(1,31,1,AIR)
Block(1,31,2,AIR)
Block(1,31,3,AIR)
Block(1,31,4,AIR)
Block(1,31,5,AIR)
Block(1,31,6,AIR)
Block(1,31,7,AIR)
Block(1,31,8,AIR)
Block(1,32,-2,AIR)
Block(1,32,-1,AIR)
Block(1,32,0,AIR)
Block(1,32,1,AIR)
Block(1,32,2,AIR)
Block(1,32,3,AIR)
Block(1,32,4,AIR)
Block(1,32,5,AIR)
Block(1,32,6,AIR)
Block(1,32,7,AIR)
Block(1,32,8,AIR)
Block(1,33,-2,AIR)
Block(1,33,-1,AIR)
Block(1,33,0,AIR)
Block(1,33,1,AIR)
Block(1,33,2,AIR)
Block(1,33,3,AIR)
Block(1,33,4,AIR)
Block(1,33,5,AIR)
Block(1,33,6,AIR)
Block(1,33,7,AIR)
Block(1,33,8,AIR)
Block(1,34,-2,AIR)
Block(1,34,-1,AIR)
Block(1,34,0,AIR)
Block(1,34,1,AIR)
Block(1,34,2,AIR)
Block(1,34,3,AIR)
Block(1,34,4,AIR)
Block(1,34,5,AIR)
Block(1,34,6,AIR)
Block(1,34,7,AIR)
Block(1,34,8,AIR)
Block(1,35,-2,AIR)
Block(1,35,-1,AIR)
Block(1,35,0,AIR)
Block(1,35,1,AIR)
Block(1,35,2,AIR)
Block(1,35,3,AIR)
Block(1,35,4,AIR)
Block(1,35,5,AIR)
Block(1,35,6,AIR)
Block(1,35,7,AIR)
Block(1,36,-1,AIR)
Block(1,36,0,AIR)
Block(1,36,1,AIR)
Block(1,36,2,AIR)
Block(1,36,3,AIR)
Block(1,36,4,AIR)
Block(1,36,5,AIR)
Block(1,36,6,AIR)
Block(1,36,7,AIR)
Block(1,37,-1,AIR)
Block(1,37,0,AIR)
Block(1,37,1,AIR)
Block(1,37,2,AIR)
Block(1,37,3,AIR)
Block(1,37,4,AIR)
Block(1,37,5,AIR)
Block(1,37,6,AIR)
Block(1,37,7,AIR)
Block(1,38,0,AIR)
Block(1,38,1,AIR)
Block(1,38,2,AIR)
Block(1,38,3,AIR)
Block(1,38,4,AIR)
Block(1,38,5,AIR)
Block(1,38,6,AIR)
Block(1,38,7,AIR)
Block(1,39,1,AIR)
Block(1,39,2,AIR)
Block(1,39,3,AIR)
Block(1,39,4,AIR)
Block(1,39,5,AIR)
Block(1,39,6,AIR)
Block(1,40,2,AIR)
Block(1,40,3,AIR)
Block(1,40,4,AIR)
Block(1,40,5,AIR)
Block(1,40,6,AIR)
Block(1,41,2,AIR)
Block(1,41,3,AIR)
Block(1,41,4,AIR)
Block(1,41,5,AIR)
Block(1,41,6,AIR)
Block(1,42,3,AIR)
Block(1,42,4,AIR)
Block(1,42,5,AIR)
Block(1,42,6,AIR)
Block(1,43,3,AIR)
Block(1,43,4,AIR)
Block(1,43,5,AIR)
Block(1,44,3,AIR)
Block(1,44,4,AIR)
Block(1,44,5,AIR)
Block(2,0,-6,24)
Block(2,0,-5,24)
Block(2,0,-4,24)
Block(2,0,-3,24)
Block(2,0,-2,24)
Block(2,0,-1,24)
Block(2,0,0,24)
Block(2,0,1,24)
Block(2,0,2,24)
Block(2,0,3,24)
Block(2,0,4,24)
Block(2,0,5,24)
Block(2,0,6,24)
Block(2,0,7,24)
Block(2,0,8,24)
Block(2,1,-6,24)
Block(2,1,-5,24)
Block(2,1,-4,24)
Block(2,1,-3,24)
Block(2,1,-2,24)
Block(2,1,-1,24)
Block(2,1,0,24)
Block(2,1,1,24)
Block(2,1,2,24)
Block(2,1,3,24)
Block(2,1,4,24)
Block(2,1,5,24)
Block(2,1,6,24)
Block(2,1,7,24)
Block(2,1,8,24)
Block(2,2,-6,24)
Block(2,2,-5,24)
Block(2,2,-4,24)
Block(2,2,-3,24)
Block(2,2,-2,24)
Block(2,2,-1,24)
Block(2,2,0,24)
Block(2,2,1,24)
Block(2,2,2,24)
Block(2,2,3,24)
Block(2,2,4,24)
Block(2,2,5,24)
Block(2,2,6,24)
Block(2,2,7,24)
Block(2,2,8,24)
Block(2,3,-6,24)
Block(2,3,-5,24)
Block(2,3,-4,24)
Block(2,3,-3,24)
Block(2,3,-2,24)
Block(2,3,-1,24)
Block(2,3,0,24)
Block(2,3,1,24)
Block(2,3,2,24)
Block(2,3,3,24)
Block(2,3,4,24)
Block(2,3,5,24)
Block(2,3,6,24)
Block(2,3,7,24)
Block(2,3,8,24)
Block(2,4,-6,24)
Block(2,4,-5,24)
Block(2,4,-4,24)
Block(2,4,-3,24)
Block(2,4,-2,24)
Block(2,4,-1,24)
Block(2,4,0,24)
Block(2,4,1,24)
Block(2,4,2,24)
Block(2,4,3,24)
Block(2,4,4,24)
Block(2,4,5,24)
Block(2,4,6,24)
Block(2,4,7,24)
Block(2,4,8,24)
Block(2,5,-6,24)
Block(2,5,-5,24)
Block(2,5,-4,24)
Block(2,5,-3,24)
Block(2,5,-2,24)
Block(2,5,-1,24)
Block(2,5,0,24)
Block(2,5,1,24)
Block(2,5,2,24)
Block(2,5,3,24)
Block(2,5,4,24)
Block(2,5,5,24)
Block(2,5,6,24)
Block(2,5,7,24)
Block(2,5,8,24)
Block(2,6,-6,24)
Block(2,6,-5,24)
Block(2,6,-4,24)
Block(2,6,-3,24)
Block(2,6,-2,24)
Block(2,6,-1,24)
Block(2,6,0,24)
Block(2,6,1,24)
Block(2,6,2,24)
Block(2,6,3,24)
Block(2,6,4,24)
Block(2,6,5,24)
Block(2,6,6,24)
Block(2,6,7,24)
Block(2,6,8,24)
Block(2,7,-6,24)
Block(2,7,-5,24)
Block(2,7,-4,24)
Block(2,7,-3,24)
Block(2,7,-2,24)
Block(2,7,-1,24)
Block(2,7,0,24)
Block(2,7,1,24)
Block(2,7,2,24)
Block(2,7,3,24)
Block(2,7,4,24)
Block(2,7,5,24)
Block(2,7,6,24)
Block(2,7,7,24)
Block(2,7,8,24)
Block(2,8,-6,24)
Block(2,8,-5,24)
Block(2,8,-4,24)
Block(2,8,-3,24)
Block(2,8,-2,24)
Block(2,8,-1,24)
Block(2,8,0,24)
Block(2,8,1,24)
Block(2,8,2,24)
Block(2,8,3,24)
Block(2,8,4,24)
Block(2,8,5,24)
Block(2,8,6,24)
Block(2,8,7,24)
Block(2,8,8,24)
Block(2,9,-6,24)
Block(2,9,-5,24)
Block(2,9,-4,24)
Block(2,9,-3,24)
Block(2,9,-2,24)
Block(2,9,-1,24)
Block(2,9,0,24)
Block(2,9,1,24)
Block(2,9,2,24)
Block(2,9,3,24)
Block(2,9,4,24)
Block(2,9,5,24)
Block(2,9,6,24)
Block(2,9,7,24)
Block(2,9,8,24)
Block(2,10,-6,24)
Block(2,10,-5,24)
Block(2,10,-4,24)
Block(2,10,-3,24)
Block(2,10,-2,24)
Block(2,10,-1,24)
Block(2,10,0,24)
Block(2,10,1,24)
Block(2,10,2,24)
Block(2,10,3,24)
Block(2,10,4,24)
Block(2,10,5,24)
Block(2,10,6,24)
Block(2,10,7,24)
Block(2,10,8,24)
Block(2,11,-5,24)
Block(2,11,-4,24)
Block(2,11,-3,24)
Block(2,11,-2,24)
Block(2,11,-1,24)
Block(2,11,0,24)
Block(2,11,1,24)
Block(2,11,2,24)
Block(2,11,3,24)
Block(2,11,4,24)
Block(2,11,5,24)
Block(2,11,6,24)
Block(2,11,7,24)
Block(2,11,8,24)
Block(2,12,-4,24)
Block(2,12,-3,24)
Block(2,12,-2,24)
Block(2,12,-1,24)
Block(2,12,0,24)
Block(2,12,1,24)
Block(2,12,2,24)
Block(2,12,3,24)
Block(2,12,4,24)
Block(2,12,5,24)
Block(2,12,6,24)
Block(2,12,7,24)
Block(2,12,8,24)
Block(2,13,-4,24)
Block(2,13,-3,24)
Block(2,13,-2,24)
Block(2,13,-1,24)
Block(2,13,0,24)
Block(2,13,1,24)
Block(2,13,2,24)
Block(2,13,3,24)
Block(2,13,4,24)
Block(2,13,5,24)
Block(2,13,6,24)
Block(2,13,7,24)
Block(2,13,8,24)
Block(2,14,-4,24)
Block(2,14,-3,24)
Block(2,14,-2,24)
Block(2,14,-1,24)
Block(2,14,0,24)
Block(2,14,1,24)
Block(2,14,2,24)
Block(2,14,3,24)
Block(2,14,4,24)
Block(2,14,5,24)
Block(2,14,6,24)
Block(2,14,7,24)
Block(2,14,8,24)
Block(2,15,-4,24)
Block(2,15,-3,24)
Block(2,15,-2,24)
Block(2,15,-1,179)
Block(2,15,0,179)
Block(2,15,1,179)
Block(2,15,2,179)
Block(2,15,3,179)
Block(2,15,4,24)
Block(2,15,5,24)
Block(2,15,6,24)
Block(2,15,7,24)
Block(2,15,8,24)
Block(2,16,-4,AIR)
Block(2,16,-3,65:5)
Block(2,16,-2,192)
Block(2,16,-1,AIR)
Block(2,16,0,AIR)
Block(2,16,1,AIR)
Block(2,16,2,AIR)
Block(2,16,3,192)
Block(2,16,4,24)
Block(2,16,5,AIR)
Block(2,16,6,AIR)
Entity(2,16,6,Villager,1,Librarian.txt)
Block(2,16,7,AIR)
Block(2,16,8,24)
Block(2,17,-4,AIR)
Block(2,17,-3,65:5)
Block(2,17,-2,192)
Block(2,17,-1,AIR)
Block(2,17,0,AIR)
Block(2,17,1,AIR)
Block(2,17,2,AIR)
Block(2,17,3,192)
Block(2,17,4,24)
Block(2,17,5,AIR)
Block(2,17,6,AIR)
Block(2,17,7,AIR)
Block(2,17,8,24)
Block(2,18,-4,AIR)
Block(2,18,-3,65:5)
Block(2,18,-2,192)
Block(2,18,-1,192)
Block(2,18,0,192)
Block(2,18,1,192)
Block(2,18,2,192)
Block(2,18,3,192)
Block(2,18,4,24)
Block(2,18,5,AIR)
Block(2,18,6,AIR)
Block(2,18,7,AIR)
Block(2,18,8,24)
Block(2,19,-4,AIR)
Block(2,19,-3,65:5)
Block(2,19,-2,126:4)
Block(2,19,-1,125:4)
Block(2,19,0,125:4)
Block(2,19,1,125:4)
Block(2,19,2,125:4)
Block(2,19,3,125:4)
Block(2,19,4,24)
Block(2,19,5,AIR)
Block(2,19,6,AIR)
Block(2,19,7,AIR)
Block(2,19,8,24)
Block(2,20,-4,AIR)
Block(2,20,-3,65:5)
Block(2,20,-2,AIR)
Block(2,20,-1,AIR)
Block(2,20,0,AIR)
Block(2,20,1,AIR)
Block(2,20,2,AIR)
Block(2,20,3,AIR)
Block(2,20,4,24)
Block(2,20,5,5:4)
Block(2,20,6,5:4)
Block(2,20,7,5:4)
Block(2,20,8,24)
Block(2,21,-4,AIR)
Block(2,21,-3,AIR)
Block(2,21,-2,AIR)
Block(2,21,-1,AIR)
Block(2,21,0,AIR)
Block(2,21,1,AIR)
Block(2,21,2,AIR)
Block(2,21,3,AIR)
Block(2,21,4,24)
Block(2,21,5,AIR)
Block(2,21,6,AIR)
RandomBlock(2,21,7,CHEST,../../nbt/VanillaLoot/simple_dungeon.nbt,50,CHEST,../../nbt/VanillaLoot/abandoned_mineshaft.nbt,30,CHEST,../../nbt/VanillaLoot/desert_pyramid.nbt,100)
Block(2,21,8,24)
Block(2,22,-4,AIR)
Block(2,22,-3,AIR)
Block(2,22,-2,AIR)
Block(2,22,-1,AIR)
Block(2,22,0,AIR)
Block(2,22,1,AIR)
Block(2,22,2,AIR)
Block(2,22,3,AIR)
Block(2,22,4,24)
Block(2,22,5,AIR)
Block(2,22,6,AIR)
Block(2,22,7,AIR)
Block(2,22,8,24)
Block(2,23,-4,AIR)
Block(2,23,-3,AIR)
Block(2,23,-2,AIR)
Block(2,23,-1,AIR)
Block(2,23,0,AIR)
Block(2,23,1,AIR)
Block(2,23,2,AIR)
Block(2,23,3,AIR)
Block(2,23,4,24)
Block(2,23,5,AIR)
Block(2,23,6,AIR)
Block(2,23,7,AIR)
Block(2,23,8,24)
Block(2,24,-4,AIR)
Block(2,24,-3,AIR)
Block(2,24,-2,AIR)
Block(2,24,-1,AIR)
Block(2,24,0,AIR)
Block(2,24,1,AIR)
Block(2,24,2,AIR)
Block(2,24,3,AIR)
Block(2,24,4,126:4)
Block(2,24,5,5:4)
Block(2,24,6,5:4)
Block(2,24,7,5:4)
Block(2,24,8,126:4)
Block(2,25,-4,AIR)
Block(2,25,-3,AIR)
Block(2,25,-2,AIR)
Block(2,25,-1,AIR)
Block(2,25,0,AIR)
Block(2,25,1,AIR)
Block(2,25,2,AIR)
Block(2,25,3,AIR)
Block(2,25,4,AIR)
Block(2,25,5,AIR)
Block(2,25,6,AIR)
Block(2,25,7,AIR)
Block(2,25,8,AIR)
Block(2,26,-3,AIR)
Block(2,26,-2,AIR)
Block(2,26,-1,AIR)
Block(2,26,0,AIR)
Block(2,26,1,AIR)
Block(2,26,2,AIR)
Block(2,26,3,AIR)
Block(2,26,4,AIR)
Block(2,26,5,AIR)
Block(2,26,6,AIR)
Block(2,26,7,AIR)
Block(2,26,8,AIR)
Block(2,27,-3,AIR)
Block(2,27,-2,AIR)
Block(2,27,-1,AIR)
Block(2,27,0,AIR)
Block(2,27,1,AIR)
Block(2,27,2,AIR)
Block(2,27,3,AIR)
Block(2,27,4,AIR)
Block(2,27,5,AIR)
Block(2,27,6,AIR)
Block(2,27,7,AIR)
Block(2,27,8,AIR)
Block(2,28,-3,AIR)
Block(2,28,-2,AIR)
Block(2,28,-1,AIR)
Block(2,28,0,AIR)
Block(2,28,1,AIR)
Block(2,28,2,AIR)
Block(2,28,3,AIR)
Block(2,28,4,AIR)
Block(2,28,5,AIR)
Block(2,28,6,AIR)
Block(2,28,7,AIR)
Block(2,28,8,AIR)
Block(2,29,-3,AIR)
Block(2,29,-2,AIR)
Block(2,29,-1,AIR)
Block(2,29,0,AIR)
Block(2,29,1,AIR)
Block(2,29,2,AIR)
Block(2,29,3,AIR)
Block(2,29,4,AIR)
Block(2,29,5,AIR)
Block(2,29,6,AIR)
Block(2,29,7,AIR)
Block(2,29,8,AIR)
Block(2,30,-2,AIR)
Block(2,30,-1,AIR)
Block(2,30,0,AIR)
Block(2,30,1,AIR)
Block(2,30,2,AIR)
Block(2,30,3,AIR)
Block(2,30,4,AIR)
Block(2,30,5,AIR)
Block(2,30,6,AIR)
Block(2,30,7,AIR)
Block(2,30,8,AIR)
Block(2,31,-2,AIR)
Block(2,31,-1,AIR)
Block(2,31,0,AIR)
Block(2,31,1,AIR)
Block(2,31,2,AIR)
Block(2,31,3,AIR)
Block(2,31,4,AIR)
Block(2,31,5,AIR)
Block(2,31,6,AIR)
Block(2,31,7,AIR)
Block(2,31,8,AIR)
Block(2,32,-2,AIR)
Block(2,32,-1,AIR)
Block(2,32,0,AIR)
Block(2,32,1,AIR)
Block(2,32,2,AIR)
Block(2,32,3,AIR)
Block(2,32,4,AIR)
Block(2,32,5,AIR)
Block(2,32,6,AIR)
Block(2,32,7,AIR)
Block(2,32,8,AIR)
Block(2,33,-2,AIR)
Block(2,33,-1,AIR)
Block(2,33,0,AIR)
Block(2,33,1,AIR)
Block(2,33,2,AIR)
Block(2,33,3,AIR)
Block(2,33,4,AIR)
Block(2,33,5,AIR)
Block(2,33,6,AIR)
Block(2,33,7,AIR)
Block(2,33,8,AIR)
Block(2,34,-2,AIR)
Block(2,34,-1,AIR)
Block(2,34,0,AIR)
Block(2,34,1,AIR)
Block(2,34,2,AIR)
Block(2,34,3,AIR)
Block(2,34,4,AIR)
Block(2,34,5,AIR)
Block(2,34,6,AIR)
Block(2,34,7,AIR)
Block(2,34,8,AIR)
Block(2,35,-1,AIR)
Block(2,35,0,AIR)
Block(2,35,1,AIR)
Block(2,35,2,AIR)
Block(2,35,3,AIR)
Block(2,35,4,AIR)
Block(2,35,5,AIR)
Block(2,35,6,AIR)
Block(2,35,7,AIR)
Block(2,35,8,AIR)
Block(2,36,-1,AIR)
Block(2,36,0,AIR)
Block(2,36,1,AIR)
Block(2,36,2,AIR)
Block(2,36,3,AIR)
Block(2,36,4,AIR)
Block(2,36,5,AIR)
Block(2,36,6,AIR)
Block(2,36,7,AIR)
Block(2,37,0,AIR)
Block(2,37,1,AIR)
Block(2,37,2,AIR)
Block(2,37,3,AIR)
Block(2,37,4,AIR)
Block(2,37,5,AIR)
Block(2,37,6,AIR)
Block(2,37,7,AIR)
Block(2,38,0,AIR)
Block(2,38,1,AIR)
Block(2,38,2,AIR)
Block(2,38,3,AIR)
Block(2,38,4,AIR)
Block(2,38,5,AIR)
Block(2,38,6,AIR)
Block(2,38,7,AIR)
Block(2,39,1,AIR)
Block(2,39,2,AIR)
Block(2,39,3,AIR)
Block(2,39,4,AIR)
Block(2,39,5,AIR)
Block(2,39,6,AIR)
Block(2,39,7,AIR)
Block(2,40,2,AIR)
Block(2,40,3,AIR)
Block(2,40,4,AIR)
Block(2,40,5,AIR)
Block(2,40,6,AIR)
Block(2,40,7,AIR)
Block(2,41,2,AIR)
Block(2,41,4,AIR)
Block(2,41,5,AIR)
Block(2,41,6,AIR)
Block(2,42,2,AIR)
Block(2,42,4,AIR)
Block(2,42,5,AIR)
Block(2,42,6,AIR)
Block(2,43,4,AIR)
Block(2,43,5,AIR)
Block(2,43,6,AIR)
Block(2,44,4,AIR)
Block(2,44,5,AIR)
Block(2,45,4,AIR)
Block(2,45,5,AIR)
Block(3,0,-6,24)
Block(3,0,-5,24)
Block(3,0,-4,24)
Block(3,0,-3,24)
Block(3,0,-2,24)
Block(3,0,-1,24)
Block(3,0,0,24)
Block(3,0,1,24)
Block(3,0,2,24)
Block(3,0,3,24)
Block(3,0,4,24)
Block(3,0,5,24)
Block(3,0,6,24)
Block(3,0,7,24)
Block(3,0,8,24)
Block(3,1,-6,24)
Block(3,1,-5,24)
Block(3,1,-4,24)
Block(3,1,-3,24)
Block(3,1,-2,24)
Block(3,1,-1,24)
Block(3,1,0,24)
Block(3,1,1,24)
Block(3,1,2,24)
Block(3,1,3,24)
Block(3,1,4,24)
Block(3,1,5,24)
Block(3,1,6,24)
Block(3,1,7,24)
Block(3,1,8,24)
Block(3,2,-6,24)
Block(3,2,-5,24)
Block(3,2,-4,24)
Block(3,2,-3,24)
Block(3,2,-2,24)
Block(3,2,-1,24)
Block(3,2,0,24)
Block(3,2,1,24)
Block(3,2,2,24)
Block(3,2,3,24)
Block(3,2,4,24)
Block(3,2,5,24)
Block(3,2,6,24)
Block(3,2,7,24)
Block(3,2,8,24)
Block(3,3,-6,24)
Block(3,3,-5,24)
Block(3,3,-4,24)
Block(3,3,-3,24)
Block(3,3,-2,24)
Block(3,3,-1,24)
Block(3,3,0,24)
Block(3,3,1,24)
Block(3,3,2,24)
Block(3,3,3,24)
Block(3,3,4,24)
Block(3,3,5,24)
Block(3,3,6,24)
Block(3,3,7,24)
Block(3,3,8,24)
Block(3,4,-6,24)
Block(3,4,-5,24)
Block(3,4,-4,24)
Block(3,4,-3,24)
Block(3,4,-2,24)
Block(3,4,-1,24)
Block(3,4,0,24)
Block(3,4,1,24)
Block(3,4,2,24)
Block(3,4,3,24)
Block(3,4,4,24)
Block(3,4,5,24)
Block(3,4,6,24)
Block(3,4,7,24)
Block(3,4,8,24)
Block(3,5,-6,24)
Block(3,5,-5,24)
Block(3,5,-4,24)
Block(3,5,-3,24)
Block(3,5,-2,24)
Block(3,5,-1,24)
Block(3,5,0,24)
Block(3,5,1,24)
Block(3,5,2,24)
Block(3,5,3,24)
Block(3,5,4,24)
Block(3,5,5,24)
Block(3,5,6,24)
Block(3,5,7,24)
Block(3,5,8,24)
Block(3,6,-6,24)
Block(3,6,-5,24)
Block(3,6,-4,24)
Block(3,6,-3,24)
Block(3,6,-2,24)
Block(3,6,-1,24)
Block(3,6,0,24)
Block(3,6,1,24)
Block(3,6,2,24)
Block(3,6,3,24)
Block(3,6,4,24)
Block(3,6,5,24)
Block(3,6,6,24)
Block(3,6,7,24)
Block(3,6,8,24)
Block(3,7,-6,24)
Block(3,7,-5,24)
Block(3,7,-4,24)
Block(3,7,-3,24)
Block(3,7,-2,24)
Block(3,7,-1,24)
Block(3,7,0,24)
Block(3,7,1,24)
Block(3,7,2,24)
Block(3,7,3,24)
Block(3,7,4,24)
Block(3,7,5,24)
Block(3,7,6,24)
Block(3,7,7,24)
Block(3,7,8,24)
Block(3,8,-6,24)
Block(3,8,-5,24)
Block(3,8,-4,24)
Block(3,8,-3,24)
Block(3,8,-2,24)
Block(3,8,-1,24)
Block(3,8,0,24)
Block(3,8,1,24)
Block(3,8,2,24)
Block(3,8,3,24)
Block(3,8,4,24)
Block(3,8,5,24)
Block(3,8,6,24)
Block(3,8,7,24)
Block(3,8,8,24)
Block(3,9,-6,24)
Block(3,9,-5,24)
Block(3,9,-4,24)
Block(3,9,-3,24)
Block(3,9,-2,24)
Block(3,9,-1,24)
Block(3,9,0,24)
Block(3,9,1,24)
Block(3,9,2,24)
Block(3,9,3,24)
Block(3,9,4,24)
Block(3,9,5,24)
Block(3,9,6,24)
Block(3,9,7,24)
Block(3,9,8,24)
Block(3,10,-6,24)
Block(3,10,-5,24)
Block(3,10,-4,24)
Block(3,10,-3,24)
Block(3,10,-2,24)
Block(3,10,-1,24)
Block(3,10,0,24)
Block(3,10,1,24)
Block(3,10,2,24)
Block(3,10,3,24)
Block(3,10,4,24)
Block(3,10,5,24)
Block(3,10,6,24)
Block(3,10,7,24)
Block(3,10,8,24)
Block(3,11,-5,24)
Block(3,11,-4,24)
Block(3,11,-3,24)
Block(3,11,-2,24)
Block(3,11,-1,24)
Block(3,11,0,24)
Block(3,11,1,24)
Block(3,11,2,24)
Block(3,11,3,24)
Block(3,11,4,24)
Block(3,11,5,24)
Block(3,11,6,24)
Block(3,11,7,24)
Block(3,11,8,24)
Block(3,12,-4,24)
Block(3,12,-3,24)
Block(3,12,-2,24)
Block(3,12,-1,24)
Block(3,12,0,24)
Block(3,12,1,24)
Block(3,12,2,24)
Block(3,12,3,24)
Block(3,12,4,24)
Block(3,12,5,24)
Block(3,12,6,24)
Block(3,12,7,24)
Block(3,12,8,24)
Block(3,13,-4,24)
Block(3,13,-3,24)
Block(3,13,-2,24)
Block(3,13,-1,24)
Block(3,13,0,24)
Block(3,13,1,24)
Block(3,13,2,24)
Block(3,13,3,24)
Block(3,13,4,24)
Block(3,13,5,24)
Block(3,13,6,24)
Block(3,13,7,24)
Block(3,13,8,24)
Block(3,14,-4,24)
Block(3,14,-3,24)
Block(3,14,-2,24)
Block(3,14,-1,24)
Block(3,14,0,24)
Block(3,14,1,24)
Block(3,14,2,24)
Block(3,14,3,24)
Block(3,14,4,24)
Block(3,14,5,24)
Block(3,14,6,24)
Block(3,14,7,24)
Block(3,14,8,24)
Block(3,15,-4,24)
Block(3,15,-3,24)
Block(3,15,-2,24)
Block(3,15,-1,179)
Block(3,15,0,24)
Block(3,15,1,24)
Block(3,15,2,24)
Block(3,15,3,179)
Block(3,15,4,24)
Block(3,15,5,24)
Block(3,15,6,24)
Block(3,15,7,24)
Block(3,15,8,24)
Block(3,16,-4,AIR)
Block(3,16,-3,AIR)
Block(3,16,-2,AIR)
Block(3,16,-1,AIR)
Block(3,16,0,AIR)
Block(3,16,1,AIR)
Block(3,16,2,AIR)
Block(3,16,3,AIR)
Block(3,16,4,24)
Block(3,16,5,AIR)
Block(3,16,6,AIR)
Block(3,16,7,AIR)
Block(3,16,8,24)
Block(3,17,-4,AIR)
Block(3,17,-3,AIR)
Block(3,17,-2,AIR)
Block(3,17,-1,AIR)
Block(3,17,0,AIR)
Block(3,17,1,AIR)
Block(3,17,2,AIR)
Block(3,17,3,AIR)
Block(3,17,4,24)
Block(3,17,5,AIR)
Block(3,17,6,AIR)
Block(3,17,7,AIR)
Block(3,17,8,24)
Block(3,18,-4,AIR)
Block(3,18,-3,AIR)
Block(3,18,-2,192)
Block(3,18,-1,AIR)
Block(3,18,0,AIR)
Block(3,18,1,AIR)
Block(3,18,2,AIR)
Block(3,18,3,AIR)
Block(3,18,4,24)
Block(3,18,5,AIR)
Block(3,18,6,AIR)
Block(3,18,7,AIR)
Block(3,18,8,192)
Block(3,19,-4,AIR)
Block(3,19,-3,AIR)
Block(3,19,-2,126:4)
Block(3,19,-1,125:4)
Block(3,19,0,125:4)
Block(3,19,1,125:4)
Block(3,19,2,125:4)
Block(3,19,3,125:4)
Block(3,19,4,24)
Block(3,19,5,AIR)
Block(3,19,6,AIR)
Block(3,19,7,AIR)
Block(3,19,8,24)
Block(3,20,-4,AIR)
Block(3,20,-3,AIR)
Block(3,20,-2,AIR)
Block(3,20,-1,AIR)
Block(3,20,0,AIR)
Block(3,20,1,AIR)
Block(3,20,2,AIR)
Block(3,20,3,AIR)
Block(3,20,4,24)
Block(3,20,5,5:4)
Block(3,20,6,5:4)
Block(3,20,7,5:4)
Block(3,20,8,24)
Block(3,21,-4,AIR)
Block(3,21,-3,AIR)
Block(3,21,-2,AIR)
Block(3,21,-1,AIR)
Block(3,21,0,AIR)
Block(3,21,1,AIR)
Block(3,21,2,AIR)
Block(3,21,3,AIR)
Block(3,21,4,24)
Block(3,21,5,AIR)
Block(3,21,6,AIR)
Block(3,21,7,AIR)
Block(3,21,8,24)
Block(3,22,-4,AIR)
Block(3,22,-3,AIR)
Block(3,22,-2,AIR)
Block(3,22,-1,AIR)
Block(3,22,0,AIR)
Block(3,22,1,AIR)
Block(3,22,2,AIR)
Block(3,22,3,AIR)
Block(3,22,4,192)
Block(3,22,5,AIR)
Block(3,22,6,AIR)
Block(3,22,7,AIR)
Block(3,22,8,192)
Block(3,23,-4,AIR)
Block(3,23,-3,AIR)
Block(3,23,-2,AIR)
Block(3,23,-1,AIR)
Block(3,23,0,AIR)
Block(3,23,1,AIR)
Block(3,23,2,AIR)
Block(3,23,3,AIR)
Block(3,23,4,24)
Block(3,23,5,AIR)
Block(3,23,6,AIR)
Block(3,23,7,AIR)
Block(3,23,8,24)
Block(3,24,-4,AIR)
Block(3,24,-3,AIR)
Block(3,24,-2,AIR)
Block(3,24,-1,AIR)
Block(3,24,0,AIR)
Block(3,24,1,AIR)
Block(3,24,2,AIR)
Block(3,24,3,AIR)
Block(3,24,4,126:4)
Block(3,24,5,5:4)
Block(3,24,6,5:4)
Block(3,24,7,5:4)
Block(3,24,8,126:4)
Block(3,25,-4,AIR)
Block(3,25,-3,AIR)
Block(3,25,-2,AIR)
Block(3,25,-1,AIR)
Block(3,25,0,AIR)
Block(3,25,1,AIR)
Block(3,25,2,AIR)
Block(3,25,3,AIR)
Block(3,25,4,AIR)
Block(3,25,5,AIR)
Block(3,25,6,AIR)
Block(3,25,7,AIR)
Block(3,25,8,AIR)
Block(3,26,-3,AIR)
Block(3,26,-2,AIR)
Block(3,26,-1,AIR)
Block(3,26,0,AIR)
Block(3,26,1,AIR)
Block(3,26,2,AIR)
Block(3,26,3,AIR)
Block(3,26,4,AIR)
Block(3,26,5,AIR)
Block(3,26,6,AIR)
Block(3,26,7,AIR)
Block(3,26,8,AIR)
Block(3,27,-2,AIR)
Block(3,27,-1,AIR)
Block(3,27,0,AIR)
Block(3,27,1,AIR)
Block(3,27,2,AIR)
Block(3,27,3,AIR)
Block(3,27,4,AIR)
Block(3,27,5,AIR)
Block(3,27,6,AIR)
Block(3,27,7,AIR)
Block(3,27,8,AIR)
Block(3,28,-2,AIR)
Block(3,28,-1,AIR)
Block(3,28,0,AIR)
Block(3,28,1,AIR)
Block(3,28,2,AIR)
Block(3,28,3,AIR)
Block(3,28,4,AIR)
Block(3,28,5,AIR)
Block(3,28,6,AIR)
Block(3,28,7,AIR)
Block(3,28,8,AIR)
Block(3,29,-2,AIR)
Block(3,29,-1,AIR)
Block(3,29,0,AIR)
Block(3,29,1,AIR)
Block(3,29,2,AIR)
Block(3,29,3,AIR)
Block(3,29,4,AIR)
Block(3,29,5,AIR)
Block(3,29,6,AIR)
Block(3,29,7,AIR)
Block(3,29,8,AIR)
Block(3,30,-2,AIR)
Block(3,30,-1,AIR)
Block(3,30,0,AIR)
Block(3,30,1,AIR)
Block(3,30,2,AIR)
Block(3,30,3,AIR)
Block(3,30,4,AIR)
Block(3,30,5,AIR)
Block(3,30,6,AIR)
Block(3,30,7,AIR)
Block(3,30,8,AIR)
Block(3,31,-2,AIR)
Block(3,31,-1,AIR)
Block(3,31,0,AIR)
Block(3,31,1,AIR)
Block(3,31,2,AIR)
Block(3,31,3,AIR)
Block(3,31,4,AIR)
Block(3,31,5,AIR)
Block(3,31,6,AIR)
Block(3,31,7,AIR)
Block(3,31,8,AIR)
Block(3,32,-2,AIR)
Block(3,32,-1,AIR)
Block(3,32,0,AIR)
Block(3,32,1,AIR)
Block(3,32,2,AIR)
Block(3,32,3,AIR)
Block(3,32,4,AIR)
Block(3,32,5,AIR)
Block(3,32,6,AIR)
Block(3,32,7,AIR)
Block(3,32,8,AIR)
Block(3,33,-2,AIR)
Block(3,33,-1,AIR)
Block(3,33,0,AIR)
Block(3,33,1,AIR)
Block(3,33,2,AIR)
Block(3,33,3,AIR)
Block(3,33,4,AIR)
Block(3,33,5,AIR)
Block(3,33,6,AIR)
Block(3,33,7,AIR)
Block(3,33,8,AIR)
Block(3,34,-2,AIR)
Block(3,34,-1,AIR)
Block(3,34,0,AIR)
Block(3,34,1,AIR)
Block(3,34,2,AIR)
Block(3,34,3,AIR)
Block(3,34,4,AIR)
Block(3,34,5,AIR)
Block(3,34,6,AIR)
Block(3,34,7,AIR)
Block(3,34,8,AIR)
Block(3,35,-1,AIR)
Block(3,35,0,AIR)
Block(3,35,1,AIR)
Block(3,35,2,AIR)
Block(3,35,3,AIR)
Block(3,35,4,AIR)
Block(3,35,5,AIR)
Block(3,35,6,AIR)
Block(3,35,7,AIR)
Block(3,35,8,AIR)
Block(3,36,-1,AIR)
Block(3,36,0,AIR)
Block(3,36,1,AIR)
Block(3,36,2,AIR)
Block(3,36,3,AIR)
Block(3,36,4,AIR)
Block(3,36,5,AIR)
Block(3,36,6,AIR)
Block(3,36,7,AIR)
Block(3,37,0,AIR)
Block(3,37,1,AIR)
Block(3,37,2,AIR)
Block(3,37,3,AIR)
Block(3,37,4,AIR)
Block(3,37,5,AIR)
Block(3,37,6,AIR)
Block(3,37,7,AIR)
Block(3,38,0,AIR)
Block(3,38,1,AIR)
Block(3,38,2,AIR)
Block(3,38,3,AIR)
Block(3,38,4,AIR)
Block(3,38,5,AIR)
Block(3,38,6,AIR)
Block(3,38,7,AIR)
Block(3,39,1,AIR)
Block(3,39,2,AIR)
Block(3,39,3,AIR)
Block(3,39,4,AIR)
Block(3,39,5,AIR)
Block(3,39,6,AIR)
Block(3,39,7,AIR)
Block(3,40,1,AIR)
Block(3,40,2,AIR)
Block(3,40,3,AIR)
Block(3,40,4,AIR)
Block(3,40,5,AIR)
Block(3,40,6,AIR)
Block(3,40,7,AIR)
Block(3,41,2,AIR)
Block(3,41,3,AIR)
Block(3,41,4,AIR)
Block(3,41,5,AIR)
Block(3,41,6,AIR)
Block(3,42,3,AIR)
Block(3,42,4,AIR)
Block(3,42,5,AIR)
Block(3,42,6,AIR)
Block(3,43,3,AIR)
Block(3,43,4,AIR)
Block(3,43,5,AIR)
Block(3,43,6,AIR)
Block(3,44,4,AIR)
Block(3,44,5,AIR)
Block(3,44,6,AIR)
Block(3,45,4,AIR)
Block(3,45,5,AIR)
Block(3,46,4,AIR)
Block(4,0,-6,24)
Block(4,0,-5,24)
Block(4,0,-4,24)
Block(4,0,-3,24)
Block(4,0,-2,24)
Block(4,0,-1,24)
Block(4,0,0,24)
Block(4,0,1,24)
Block(4,0,2,24)
Block(4,0,3,24)
Block(4,0,4,24)
Block(4,0,5,24)
Block(4,0,6,24)
Block(4,0,7,24)
Block(4,0,8,24)
Block(4,1,-6,24)
Block(4,1,-5,24)
Block(4,1,-4,24)
Block(4,1,-3,24)
Block(4,1,-2,24)
Block(4,1,-1,24)
Block(4,1,0,24)
Block(4,1,1,24)
Block(4,1,2,24)
Block(4,1,3,24)
Block(4,1,4,24)
Block(4,1,5,24)
Block(4,1,6,24)
Block(4,1,7,24)
Block(4,1,8,24)
Block(4,2,-6,24)
Block(4,2,-5,24)
Block(4,2,-4,24)
Block(4,2,-3,24)
Block(4,2,-2,24)
Block(4,2,-1,24)
Block(4,2,0,24)
Block(4,2,1,24)
Block(4,2,2,24)
Block(4,2,3,24)
Block(4,2,4,24)
Block(4,2,5,24)
Block(4,2,6,24)
Block(4,2,7,24)
Block(4,2,8,24)
Block(4,3,-6,24)
Block(4,3,-5,24)
Block(4,3,-4,24)
Block(4,3,-3,24)
Block(4,3,-2,24)
Block(4,3,-1,24)
Block(4,3,0,24)
Block(4,3,1,24)
Block(4,3,2,24)
Block(4,3,3,24)
Block(4,3,4,24)
Block(4,3,5,24)
Block(4,3,6,24)
Block(4,3,7,24)
Block(4,3,8,24)
Block(4,4,-6,24)
Block(4,4,-5,24)
Block(4,4,-4,24)
Block(4,4,-3,24)
Block(4,4,-2,24)
Block(4,4,-1,24)
Block(4,4,0,24)
Block(4,4,1,24)
Block(4,4,2,24)
Block(4,4,3,24)
Block(4,4,4,24)
Block(4,4,5,24)
Block(4,4,6,24)
Block(4,4,7,24)
Block(4,4,8,24)
Block(4,5,-6,24)
Block(4,5,-5,24)
Block(4,5,-4,24)
Block(4,5,-3,24)
Block(4,5,-2,24)
Block(4,5,-1,24)
Block(4,5,0,24)
Block(4,5,1,24)
Block(4,5,2,24)
Block(4,5,3,24)
Block(4,5,4,24)
Block(4,5,5,24)
Block(4,5,6,24)
Block(4,5,7,24)
Block(4,5,8,24)
Block(4,6,-6,24)
Block(4,6,-5,24)
Block(4,6,-4,24)
Block(4,6,-3,24)
Block(4,6,-2,24)
Block(4,6,-1,24)
Block(4,6,0,24)
Block(4,6,1,24)
Block(4,6,2,24)
Block(4,6,3,24)
Block(4,6,4,24)
Block(4,6,5,24)
Block(4,6,6,24)
Block(4,6,7,24)
Block(4,6,8,24)
Block(4,7,-6,24)
Block(4,7,-5,24)
Block(4,7,-4,24)
Block(4,7,-3,24)
Block(4,7,-2,24)
Block(4,7,-1,24)
Block(4,7,0,24)
Block(4,7,1,24)
Block(4,7,2,24)
Block(4,7,3,24)
Block(4,7,4,24)
Block(4,7,5,24)
Block(4,7,6,24)
Block(4,7,7,24)
Block(4,7,8,24)
Block(4,8,-6,24)
Block(4,8,-5,24)
Block(4,8,-4,24)
Block(4,8,-3,24)
Block(4,8,-2,24)
Block(4,8,-1,24)
Block(4,8,0,24)
Block(4,8,1,24)
Block(4,8,2,24)
Block(4,8,3,24)
Block(4,8,4,24)
Block(4,8,5,24)
Block(4,8,6,24)
Block(4,8,7,24)
Block(4,8,8,24)
Block(4,9,-6,24)
Block(4,9,-5,24)
Block(4,9,-4,24)
Block(4,9,-3,24)
Block(4,9,-2,24)
Block(4,9,-1,24)
Block(4,9,0,24)
Block(4,9,1,24)
Block(4,9,2,24)
Block(4,9,3,24)
Block(4,9,4,24)
Block(4,9,5,24)
Block(4,9,6,24)
Block(4,9,7,24)
Block(4,9,8,24)
Block(4,10,-6,24)
Block(4,10,-5,24)
Block(4,10,-4,24)
Block(4,10,-3,24)
Block(4,10,-2,24)
Block(4,10,-1,24)
Block(4,10,0,24)
Block(4,10,1,24)
Block(4,10,2,24)
Block(4,10,3,24)
Block(4,10,4,24)
Block(4,10,5,24)
Block(4,10,6,24)
Block(4,10,7,24)
Block(4,10,8,24)
Block(4,11,-5,24)
Block(4,11,-4,24)
Block(4,11,-3,24)
Block(4,11,-2,24)
Block(4,11,-1,24)
Block(4,11,0,24)
Block(4,11,1,24)
Block(4,11,2,24)
Block(4,11,3,24)
Block(4,11,4,24)
Block(4,11,5,24)
Block(4,11,6,24)
Block(4,11,7,24)
Block(4,11,8,24)
Block(4,12,-4,24)
Block(4,12,-3,24)
Block(4,12,-2,24)
Block(4,12,-1,24)
Block(4,12,0,24)
Block(4,12,1,24)
Block(4,12,2,24)
Block(4,12,3,24)
Block(4,12,4,24)
Block(4,12,5,24)
Block(4,12,6,24)
Block(4,12,7,24)
Block(4,12,8,24)
Block(4,13,-4,24)
Block(4,13,-3,24)
Block(4,13,-2,24)
Block(4,13,-1,24)
Block(4,13,0,24)
Block(4,13,1,24)
Block(4,13,2,24)
Block(4,13,3,24)
Block(4,13,4,24)
Block(4,13,5,24)
Block(4,13,6,24)
Block(4,13,7,24)
Block(4,13,8,24)
Block(4,14,-4,24)
Block(4,14,-3,24)
Block(4,14,-2,24)
Block(4,14,-1,24)
Block(4,14,0,24)
Block(4,14,1,24)
Block(4,14,2,24)
Block(4,14,3,24)
Block(4,14,4,24)
Block(4,14,5,24)
Block(4,14,6,24)
Block(4,14,7,24)
Block(4,14,8,24)
Block(4,15,-4,24)
Block(4,15,-3,24)
Block(4,15,-2,24)
Block(4,15,-1,179)
Block(4,15,0,24)
Block(4,15,1,24)
Block(4,15,2,24)
Block(4,15,3,179)
Block(4,15,4,24)
Block(4,15,5,24)
Block(4,15,6,24)
Block(4,15,7,24)
Block(4,15,8,24)
Block(4,16,-4,AIR)
Block(4,16,-3,AIR)
Block(4,16,-2,AIR)
Block(4,16,-1,AIR)
Block(4,16,0,AIR)
Block(4,16,1,AIR)
Block(4,16,2,AIR)
Block(4,16,3,AIR)
Block(4,16,4,196:1)
Block(4,16,5,AIR)
Block(4,16,6,AIR)
Block(4,16,7,AIR)
Block(4,16,8,24)
Block(4,17,-4,AIR)
Block(4,17,-3,AIR)
Block(4,17,-2,AIR)
Block(4,17,-1,AIR)
Block(4,17,0,AIR)
Block(4,17,1,AIR)
Block(4,17,2,AIR)
Block(4,17,3,AIR)
Block(4,17,4,196:9)
Block(4,17,5,AIR)
Block(4,17,6,AIR)
Block(4,17,7,AIR)
Block(4,17,8,24)
Block(4,18,-4,AIR)
Block(4,18,-3,AIR)
Block(4,18,-2,192)
Block(4,18,-1,AIR)
Block(4,18,0,AIR)
Block(4,18,1,AIR)
Block(4,18,2,AIR)
Block(4,18,3,AIR)
Block(4,18,4,5:4)
Block(4,18,5,AIR)
Block(4,18,6,AIR)
Block(4,18,7,AIR)
Block(4,18,8,24)
Block(4,19,-4,AIR)
Block(4,19,-3,AIR)
Block(4,19,-2,126:4)
Block(4,19,-1,125:4)
Block(4,19,0,125:4)
Block(4,19,1,125:4)
Block(4,19,2,125:4)
Block(4,19,3,125:4)
Block(4,19,4,24)
Block(4,19,5,AIR)
Block(4,19,6,AIR)
Block(4,19,7,AIR)
Block(4,19,8,24)
Block(4,20,-4,AIR)
Block(4,20,-3,AIR)
Block(4,20,-2,AIR)
Block(4,20,-1,AIR)
Block(4,20,0,AIR)
Block(4,20,1,AIR)
Block(4,20,2,AIR)
Block(4,20,3,AIR)
Block(4,20,4,24)
Block(4,20,5,5:4)
Block(4,20,6,5:4)
Block(4,20,7,5:4)
Block(4,20,8,24)
Block(4,21,-4,AIR)
Block(4,21,-3,AIR)
Block(4,21,-2,AIR)
Block(4,21,-1,AIR)
Block(4,21,0,AIR)
Block(4,21,1,AIR)
Block(4,21,2,AIR)
Block(4,21,3,AIR)
Block(4,21,4,24)
Block(4,21,5,AIR)
Block(4,21,6,AIR)
Entity(4,21,6,Villager,1,Nitwit.txt)
Block(4,21,7,AIR)
Block(4,21,8,24)
Block(4,22,-4,AIR)
Block(4,22,-3,AIR)
Block(4,22,-2,AIR)
Block(4,22,-1,AIR)
Block(4,22,0,AIR)
Block(4,22,1,AIR)
Block(4,22,2,AIR)
Block(4,22,3,AIR)
Block(4,22,4,192)
Block(4,22,5,AIR)
Block(4,22,6,AIR)
Block(4,22,7,AIR)
Block(4,22,8,24)
Block(4,23,-4,AIR)
Block(4,23,-3,AIR)
Block(4,23,-2,AIR)
Block(4,23,-1,AIR)
Block(4,23,0,AIR)
Block(4,23,1,AIR)
Block(4,23,2,AIR)
Block(4,23,3,AIR)
Block(4,23,4,24)
Block(4,23,5,AIR)
Block(4,23,6,AIR)
Block(4,23,7,AIR)
Block(4,23,8,24)
Block(4,24,-4,AIR)
Block(4,24,-3,AIR)
Block(4,24,-2,AIR)
Block(4,24,-1,AIR)
Block(4,24,0,AIR)
Block(4,24,1,AIR)
Block(4,24,2,AIR)
Block(4,24,3,AIR)
Block(4,24,4,126:4)
Block(4,24,5,5:4)
Block(4,24,6,5:4)
Block(4,24,7,5:4)
Block(4,24,8,126:4)
Block(4,25,-3,AIR)
Block(4,25,-2,AIR)
Block(4,25,-1,AIR)
Block(4,25,0,AIR)
Block(4,25,1,AIR)
Block(4,25,2,AIR)
Block(4,25,3,AIR)
Block(4,25,4,AIR)
Block(4,25,5,AIR)
Block(4,25,6,AIR)
Block(4,25,7,AIR)
Block(4,25,8,AIR)
Block(4,26,-2,AIR)
Block(4,26,-1,AIR)
Block(4,26,0,AIR)
Block(4,26,1,AIR)
Block(4,26,2,AIR)
Block(4,26,3,AIR)
Block(4,26,4,AIR)
Block(4,26,5,AIR)
Block(4,26,6,AIR)
Block(4,26,7,AIR)
Block(4,26,8,AIR)
Block(4,27,-2,AIR)
Block(4,27,-1,AIR)
Block(4,27,0,AIR)
Block(4,27,1,AIR)
Block(4,27,2,AIR)
Block(4,27,3,AIR)
Block(4,27,4,AIR)
Block(4,27,5,AIR)
Block(4,27,6,AIR)
Block(4,27,7,AIR)
Block(4,27,8,AIR)
Block(4,28,-2,AIR)
Block(4,28,-1,AIR)
Block(4,28,0,AIR)
Block(4,28,1,AIR)
Block(4,28,2,AIR)
Block(4,28,3,AIR)
Block(4,28,4,AIR)
Block(4,28,5,AIR)
Block(4,28,6,AIR)
Block(4,28,7,AIR)
Block(4,28,8,AIR)
Block(4,29,-2,AIR)
Block(4,29,-1,AIR)
Block(4,29,0,AIR)
Block(4,29,1,AIR)
Block(4,29,2,AIR)
Block(4,29,3,AIR)
Block(4,29,4,AIR)
Block(4,29,5,AIR)
Block(4,29,6,AIR)
Block(4,29,7,AIR)
Block(4,29,8,AIR)
Block(4,30,-2,AIR)
Block(4,30,-1,AIR)
Block(4,30,0,AIR)
Block(4,30,1,AIR)
Block(4,30,2,AIR)
Block(4,30,3,AIR)
Block(4,30,4,AIR)
Block(4,30,5,AIR)
Block(4,30,6,AIR)
Block(4,30,7,AIR)
Block(4,30,8,AIR)
Block(4,31,-2,AIR)
Block(4,31,-1,AIR)
Block(4,31,0,AIR)
Block(4,31,1,AIR)
Block(4,31,2,AIR)
Block(4,31,3,AIR)
Block(4,31,4,AIR)
Block(4,31,5,AIR)
Block(4,31,6,AIR)
Block(4,31,7,AIR)
Block(4,31,8,AIR)
Block(4,32,-2,AIR)
Block(4,32,-1,AIR)
Block(4,32,0,AIR)
Block(4,32,1,AIR)
Block(4,32,2,AIR)
Block(4,32,3,AIR)
Block(4,32,4,AIR)
Block(4,32,5,AIR)
Block(4,32,6,AIR)
Block(4,32,7,AIR)
Block(4,32,8,AIR)
Block(4,33,-2,AIR)
Block(4,33,-1,AIR)
Block(4,33,0,AIR)
Block(4,33,1,AIR)
Block(4,33,2,AIR)
Block(4,33,3,AIR)
Block(4,33,4,AIR)
Block(4,33,5,AIR)
Block(4,33,6,AIR)
Block(4,33,7,AIR)
Block(4,33,8,AIR)
Block(4,34,-1,AIR)
Block(4,34,0,AIR)
Block(4,34,1,AIR)
Block(4,34,2,AIR)
Block(4,34,3,AIR)
Block(4,34,4,AIR)
Block(4,34,5,AIR)
Block(4,34,6,AIR)
Block(4,34,7,AIR)
Block(4,34,8,AIR)
Block(4,35,-1,AIR)
Block(4,35,0,AIR)
Block(4,35,1,AIR)
Block(4,35,2,AIR)
Block(4,35,3,AIR)
Block(4,35,4,AIR)
Block(4,35,5,AIR)
Block(4,35,6,AIR)
Block(4,35,7,AIR)
Block(4,35,8,AIR)
Block(4,36,0,AIR)
Block(4,36,1,AIR)
Block(4,36,2,AIR)
Block(4,36,3,AIR)
Block(4,36,4,AIR)
Block(4,36,5,AIR)
Block(4,36,6,AIR)
Block(4,36,7,AIR)
Block(4,37,0,AIR)
Block(4,37,1,AIR)
Block(4,37,2,AIR)
Block(4,37,3,AIR)
Block(4,37,4,AIR)
Block(4,37,5,AIR)
Block(4,37,6,AIR)
Block(4,37,7,AIR)
Block(4,38,1,AIR)
Block(4,38,2,AIR)
Block(4,38,3,AIR)
Block(4,38,4,AIR)
Block(4,38,5,AIR)
Block(4,38,6,AIR)
Block(4,38,7,AIR)
Block(4,39,2,AIR)
Block(4,39,3,AIR)
Block(4,39,4,AIR)
Block(4,39,5,AIR)
Block(4,39,6,AIR)
Block(4,39,7,AIR)
Block(4,40,2,AIR)
Block(4,40,4,AIR)
Block(4,40,5,AIR)
Block(4,40,6,AIR)
Block(4,40,7,AIR)
Block(4,41,4,AIR)
Block(4,41,5,AIR)
Block(4,41,6,AIR)
Block(4,42,4,AIR)
Block(4,42,5,AIR)
Block(4,42,6,AIR)
Block(4,43,4,AIR)
Block(4,43,5,AIR)
Block(4,43,6,AIR)
Block(4,44,4,AIR)
Block(4,44,5,AIR)
Block(4,45,4,AIR)
Block(5,0,-6,24)
Block(5,0,-5,24)
Block(5,0,-4,24)
Block(5,0,-3,24)
Block(5,0,-2,24)
Block(5,0,-1,24)
Block(5,0,0,24)
Block(5,0,1,24)
Block(5,0,2,24)
Block(5,0,3,24)
Block(5,0,4,24)
Block(5,0,5,24)
Block(5,0,6,24)
Block(5,0,7,24)
Block(5,0,8,24)
Block(5,1,-6,24)
Block(5,1,-5,24)
Block(5,1,-4,24)
Block(5,1,-3,24)
Block(5,1,-2,24)
Block(5,1,-1,24)
Block(5,1,0,24)
Block(5,1,1,24)
Block(5,1,2,24)
Block(5,1,3,24)
Block(5,1,4,24)
Block(5,1,5,24)
Block(5,1,6,24)
Block(5,1,7,24)
Block(5,1,8,24)
Block(5,2,-6,24)
Block(5,2,-5,24)
Block(5,2,-4,24)
Block(5,2,-3,24)
Block(5,2,-2,24)
Block(5,2,-1,24)
Block(5,2,0,24)
Block(5,2,1,24)
Block(5,2,2,24)
Block(5,2,3,24)
Block(5,2,4,24)
Block(5,2,5,24)
Block(5,2,6,24)
Block(5,2,7,24)
Block(5,2,8,24)
Block(5,3,-6,24)
Block(5,3,-5,24)
Block(5,3,-4,24)
Block(5,3,-3,24)
Block(5,3,-2,24)
Block(5,3,-1,24)
Block(5,3,0,24)
Block(5,3,1,24)
Block(5,3,2,24)
Block(5,3,3,24)
Block(5,3,4,24)
Block(5,3,5,24)
Block(5,3,6,24)
Block(5,3,7,24)
Block(5,3,8,24)
Block(5,4,-6,24)
Block(5,4,-5,24)
Block(5,4,-4,24)
Block(5,4,-3,24)
Block(5,4,-2,24)
Block(5,4,-1,24)
Block(5,4,0,24)
Block(5,4,1,24)
Block(5,4,2,24)
Block(5,4,3,24)
Block(5,4,4,24)
Block(5,4,5,24)
Block(5,4,6,24)
Block(5,4,7,24)
Block(5,4,8,24)
Block(5,5,-6,24)
Block(5,5,-5,24)
Block(5,5,-4,24)
Block(5,5,-3,24)
Block(5,5,-2,24)
Block(5,5,-1,24)
Block(5,5,0,24)
Block(5,5,1,24)
Block(5,5,2,24)
Block(5,5,3,24)
Block(5,5,4,24)
Block(5,5,5,24)
Block(5,5,6,24)
Block(5,5,7,24)
Block(5,5,8,24)
Block(5,6,-6,24)
Block(5,6,-5,24)
Block(5,6,-4,24)
Block(5,6,-3,24)
Block(5,6,-2,24)
Block(5,6,-1,24)
Block(5,6,0,24)
Block(5,6,1,24)
Block(5,6,2,24)
Block(5,6,3,24)
Block(5,6,4,24)
Block(5,6,5,24)
Block(5,6,6,24)
Block(5,6,7,24)
Block(5,6,8,24)
Block(5,7,-6,24)
Block(5,7,-5,24)
Block(5,7,-4,24)
Block(5,7,-3,24)
Block(5,7,-2,24)
Block(5,7,-1,24)
Block(5,7,0,24)
Block(5,7,1,24)
Block(5,7,2,24)
Block(5,7,3,24)
Block(5,7,4,24)
Block(5,7,5,24)
Block(5,7,6,24)
Block(5,7,7,24)
Block(5,7,8,24)
Block(5,8,-6,24)
Block(5,8,-5,24)
Block(5,8,-4,24)
Block(5,8,-3,24)
Block(5,8,-2,24)
Block(5,8,-1,24)
Block(5,8,0,24)
Block(5,8,1,24)
Block(5,8,2,24)
Block(5,8,3,24)
Block(5,8,4,24)
Block(5,8,5,24)
Block(5,8,6,24)
Block(5,8,7,24)
Block(5,8,8,24)
Block(5,9,-6,24)
Block(5,9,-5,24)
Block(5,9,-4,24)
Block(5,9,-3,24)
Block(5,9,-2,24)
Block(5,9,-1,24)
Block(5,9,0,24)
Block(5,9,1,24)
Block(5,9,2,24)
Block(5,9,3,24)
Block(5,9,4,24)
Block(5,9,5,24)
Block(5,9,6,24)
Block(5,9,7,24)
Block(5,9,8,24)
Block(5,10,-6,24)
Block(5,10,-5,24)
Block(5,10,-4,24)
Block(5,10,-3,24)
Block(5,10,-2,24)
Block(5,10,-1,24)
Block(5,10,0,24)
Block(5,10,1,24)
Block(5,10,2,24)
Block(5,10,3,24)
Block(5,10,4,24)
Block(5,10,5,24)
Block(5,10,6,24)
Block(5,10,7,24)
Block(5,10,8,24)
Block(5,11,-5,24)
Block(5,11,-4,24)
Block(5,11,-3,24)
Block(5,11,-2,24)
Block(5,11,-1,24)
Block(5,11,0,24)
Block(5,11,1,24)
Block(5,11,2,24)
Block(5,11,3,24)
Block(5,11,4,24)
Block(5,11,5,24)
Block(5,11,6,24)
Block(5,11,7,24)
Block(5,11,8,24)
Block(5,12,-4,24)
Block(5,12,-3,24)
Block(5,12,-2,24)
Block(5,12,-1,24)
Block(5,12,0,24)
Block(5,12,1,24)
Block(5,12,2,24)
Block(5,12,3,24)
Block(5,12,4,24)
Block(5,12,5,24)
Block(5,12,6,24)
Block(5,12,7,24)
Block(5,12,8,24)
Block(5,13,-4,24)
Block(5,13,-3,24)
Block(5,13,-2,24)
Block(5,13,-1,24)
Block(5,13,0,24)
Block(5,13,1,24)
Block(5,13,2,24)
Block(5,13,3,24)
Block(5,13,4,24)
Block(5,13,5,24)
Block(5,13,6,24)
Block(5,13,7,24)
Block(5,13,8,24)
Block(5,14,-4,24)
Block(5,14,-3,24)
Block(5,14,-2,24)
Block(5,14,-1,24)
Block(5,14,0,24)
Block(5,14,1,24)
Block(5,14,2,24)
Block(5,14,3,24)
Block(5,14,4,24)
Block(5,14,5,24)
Block(5,14,6,24)
Block(5,14,7,24)
Block(5,14,8,24)
Block(5,15,-4,24)
Block(5,15,-3,24)
Block(5,15,-2,24)
Block(5,15,-1,179)
Block(5,15,0,24)
Block(5,15,1,24)
Block(5,15,2,24)
Block(5,15,3,179)
Block(5,15,4,24)
Block(5,15,5,24)
Block(5,15,6,24)
Block(5,15,7,24)
Block(5,15,8,24)
Block(5,16,-4,AIR)
Block(5,16,-3,AIR)
Block(5,16,-2,AIR)
Block(5,16,-1,AIR)
Block(5,16,0,AIR)
Block(5,16,1,AIR)
Block(5,16,2,AIR)
Block(5,16,3,AIR)
Block(5,16,4,24)
Block(5,16,5,AIR)
Block(5,16,6,AIR)
Block(5,16,7,AIR)
Block(5,16,8,24)
Block(5,17,-4,AIR)
Block(5,17,-3,AIR)
Block(5,17,-2,AIR)
Block(5,17,-1,AIR)
Block(5,17,0,AIR)
Block(5,17,1,AIR)
Block(5,17,2,AIR)
Block(5,17,3,AIR)
Block(5,17,4,24)
Block(5,17,5,AIR)
Block(5,17,6,AIR)
Block(5,17,7,AIR)
Block(5,17,8,24)
Block(5,18,-4,AIR)
Block(5,18,-3,AIR)
Block(5,18,-2,192)
Block(5,18,-1,AIR)
Block(5,18,0,AIR)
Block(5,18,1,AIR)
Block(5,18,2,AIR)
Block(5,18,3,AIR)
Block(5,18,4,24)
Block(5,18,5,AIR)
Block(5,18,6,AIR)
Block(5,18,7,AIR)
Block(5,18,8,24)
Block(5,19,-4,AIR)
Block(5,19,-3,AIR)
Block(5,19,-2,126:4)
Block(5,19,-1,125:4)
Block(5,19,0,125:4)
Block(5,19,1,125:4)
Block(5,19,2,125:4)
Block(5,19,3,125:4)
Block(5,19,4,24)
Block(5,19,5,AIR)
Block(5,19,6,AIR)
Block(5,19,7,AIR)
Block(5,19,8,24)
Block(5,20,-4,AIR)
Block(5,20,-3,AIR)
Block(5,20,-2,AIR)
Block(5,20,-1,AIR)
Block(5,20,0,AIR)
Block(5,20,1,AIR)
Block(5,20,2,AIR)
Block(5,20,3,AIR)
Block(5,20,4,24)
Block(5,20,5,5:4)
Block(5,20,6,5:4)
Block(5,20,7,5:4)
Block(5,20,8,24)
Block(5,21,-4,AIR)
Block(5,21,-3,AIR)
Block(5,21,-2,AIR)
Block(5,21,-1,AIR)
Block(5,21,0,AIR)
Block(5,21,1,AIR)
Block(5,21,2,AIR)
Block(5,21,3,AIR)
Block(5,21,4,24)
Block(5,21,5,AIR)
Block(5,21,6,AIR)
Block(5,21,7,AIR)
Block(5,21,8,24)
Block(5,22,-4,AIR)
Block(5,22,-3,AIR)
Block(5,22,-2,AIR)
Block(5,22,-1,AIR)
Block(5,22,0,AIR)
Block(5,22,1,AIR)
Block(5,22,2,AIR)
Block(5,22,3,AIR)
Block(5,22,4,24)
Block(5,22,5,AIR)
Block(5,22,6,AIR)
Block(5,22,7,AIR)
Block(5,22,8,24)
Block(5,23,-4,AIR)
Block(5,23,-3,AIR)
Block(5,23,-2,AIR)
Block(5,23,-1,AIR)
Block(5,23,0,AIR)
Block(5,23,1,AIR)
Block(5,23,2,AIR)
Block(5,23,3,AIR)
Block(5,23,4,24)
Block(5,23,5,AIR)
Block(5,23,6,AIR)
Block(5,23,7,30)
Block(5,23,8,24)
Block(5,24,-3,AIR)
Block(5,24,-2,AIR)
Block(5,24,-1,AIR)
Block(5,24,0,AIR)
Block(5,24,1,AIR)
Block(5,24,2,AIR)
Block(5,24,3,AIR)
Block(5,24,4,126:4)
Block(5,24,5,5:4)
Block(5,24,6,5:4)
Block(5,24,7,5:4)
Block(5,24,8,126:4)
Block(5,25,-3,AIR)
Block(5,25,-2,AIR)
Block(5,25,-1,AIR)
Block(5,25,0,AIR)
Block(5,25,1,AIR)
Block(5,25,2,AIR)
Block(5,25,3,AIR)
Block(5,25,4,AIR)
Block(5,25,5,AIR)
Block(5,25,6,AIR)
Block(5,25,7,AIR)
Block(5,25,8,AIR)
Block(5,26,-2,AIR)
Block(5,26,-1,AIR)
Block(5,26,0,AIR)
Block(5,26,1,AIR)
Block(5,26,2,AIR)
Block(5,26,3,AIR)
Block(5,26,4,AIR)
Block(5,26,5,AIR)
Block(5,26,6,AIR)
Block(5,26,7,AIR)
Block(5,26,8,AIR)
Block(5,27,-2,AIR)
Block(5,27,-1,AIR)
Block(5,27,0,AIR)
Block(5,27,1,AIR)
Block(5,27,2,AIR)
Block(5,27,3,AIR)
Block(5,27,4,AIR)
Block(5,27,5,AIR)
Block(5,27,6,AIR)
Block(5,27,7,AIR)
Block(5,27,8,AIR)
Block(5,28,-2,AIR)
Block(5,28,-1,AIR)
Block(5,28,0,AIR)
Block(5,28,1,AIR)
Block(5,28,2,AIR)
Block(5,28,3,AIR)
Block(5,28,4,AIR)
Block(5,28,5,AIR)
Block(5,28,6,AIR)
Block(5,28,7,AIR)
Block(5,28,8,AIR)
Block(5,29,-2,AIR)
Block(5,29,-1,AIR)
Block(5,29,0,AIR)
Block(5,29,1,AIR)
Block(5,29,2,AIR)
Block(5,29,3,AIR)
Block(5,29,4,AIR)
Block(5,29,5,AIR)
Block(5,29,6,AIR)
Block(5,29,7,AIR)
Block(5,29,8,AIR)
Block(5,30,-2,AIR)
Block(5,30,-1,AIR)
Block(5,30,0,AIR)
Block(5,30,1,AIR)
Block(5,30,2,AIR)
Block(5,30,3,AIR)
Block(5,30,4,AIR)
Block(5,30,5,AIR)
Block(5,30,6,AIR)
Block(5,30,7,AIR)
Block(5,30,8,AIR)
Block(5,31,-2,AIR)
Block(5,31,-1,AIR)
Block(5,31,0,AIR)
Block(5,31,1,AIR)
Block(5,31,2,AIR)
Block(5,31,3,AIR)
Block(5,31,4,AIR)
Block(5,31,5,AIR)
Block(5,31,6,AIR)
Block(5,31,7,AIR)
Block(5,31,8,AIR)
Block(5,32,-1,AIR)
Block(5,32,0,AIR)
Block(5,32,1,AIR)
Block(5,32,2,AIR)
Block(5,32,3,AIR)
Block(5,32,4,AIR)
Block(5,32,5,AIR)
Block(5,32,6,AIR)
Block(5,32,7,AIR)
Block(5,32,8,AIR)
Block(5,33,-1,AIR)
Block(5,33,0,AIR)
Block(5,33,1,AIR)
Block(5,33,2,AIR)
Block(5,33,3,AIR)
Block(5,33,4,AIR)
Block(5,33,5,AIR)
Block(5,33,6,AIR)
Block(5,33,7,AIR)
Block(5,33,8,AIR)
Block(5,34,0,AIR)
Block(5,34,1,AIR)
Block(5,34,2,AIR)
Block(5,34,3,AIR)
Block(5,34,4,AIR)
Block(5,34,5,AIR)
Block(5,34,6,AIR)
Block(5,34,7,AIR)
Block(5,35,0,AIR)
Block(5,35,1,AIR)
Block(5,35,2,AIR)
Block(5,35,3,AIR)
Block(5,35,4,AIR)
Block(5,35,5,AIR)
Block(5,35,6,AIR)
Block(5,35,7,AIR)
Block(5,36,1,AIR)
Block(5,36,2,AIR)
Block(5,36,3,AIR)
Block(5,36,4,AIR)
Block(5,36,5,AIR)
Block(5,36,6,AIR)
Block(5,36,7,AIR)
Block(5,37,3,AIR)
Block(5,37,4,AIR)
Block(5,37,5,AIR)
Block(5,37,6,AIR)
Block(5,37,7,AIR)
Block(5,38,4,AIR)
Block(5,38,5,AIR)
Block(5,38,6,AIR)
Block(5,39,4,AIR)
Block(5,39,5,AIR)
Block(5,39,6,AIR)
Block(5,40,4,AIR)
Block(5,40,5,AIR)
Block(5,40,6,AIR)
Block(5,41,4,AIR)
Block(5,41,5,AIR)
Block(5,42,4,AIR)
Block(5,42,5,AIR)
Block(6,0,-6,24)
Block(6,0,-5,24)
Block(6,0,-4,24)
Block(6,0,-3,24)
Block(6,0,-2,24)
Block(6,0,-1,24)
Block(6,0,0,24)
Block(6,0,1,24)
Block(6,0,2,24)
Block(6,0,3,24)
Block(6,0,4,24)
Block(6,0,5,24)
Block(6,0,6,24)
Block(6,0,7,24)
Block(6,0,8,24)
Block(6,1,-6,24)
Block(6,1,-5,24)
Block(6,1,-4,24)
Block(6,1,-3,24)
Block(6,1,-2,24)
Block(6,1,-1,24)
Block(6,1,0,24)
Block(6,1,1,24)
Block(6,1,2,24)
Block(6,1,3,24)
Block(6,1,4,24)
Block(6,1,5,24)
Block(6,1,6,24)
Block(6,1,7,24)
Block(6,1,8,24)
Block(6,2,-6,24)
Block(6,2,-5,24)
Block(6,2,-4,24)
Block(6,2,-3,24)
Block(6,2,-2,24)
Block(6,2,-1,24)
Block(6,2,0,24)
Block(6,2,1,24)
Block(6,2,2,24)
Block(6,2,3,24)
Block(6,2,4,24)
Block(6,2,5,24)
Block(6,2,6,24)
Block(6,2,7,24)
Block(6,2,8,24)
Block(6,3,-6,24)
Block(6,3,-5,24)
Block(6,3,-4,24)
Block(6,3,-3,24)
Block(6,3,-2,24)
Block(6,3,-1,24)
Block(6,3,0,24)
Block(6,3,1,24)
Block(6,3,2,24)
Block(6,3,3,24)
Block(6,3,4,24)
Block(6,3,5,24)
Block(6,3,6,24)
Block(6,3,7,24)
Block(6,3,8,24)
Block(6,4,-6,24)
Block(6,4,-5,24)
Block(6,4,-4,24)
Block(6,4,-3,24)
Block(6,4,-2,24)
Block(6,4,-1,24)
Block(6,4,0,24)
Block(6,4,1,24)
Block(6,4,2,24)
Block(6,4,3,24)
Block(6,4,4,24)
Block(6,4,5,24)
Block(6,4,6,24)
Block(6,4,7,24)
Block(6,4,8,24)
Block(6,5,-6,24)
Block(6,5,-5,24)
Block(6,5,-4,24)
Block(6,5,-3,24)
Block(6,5,-2,24)
Block(6,5,-1,24)
Block(6,5,0,24)
Block(6,5,1,24)
Block(6,5,2,24)
Block(6,5,3,24)
Block(6,5,4,24)
Block(6,5,5,24)
Block(6,5,6,24)
Block(6,5,7,24)
Block(6,5,8,24)
Block(6,6,-6,24)
Block(6,6,-5,24)
Block(6,6,-4,24)
Block(6,6,-3,24)
Block(6,6,-2,24)
Block(6,6,-1,24)
Block(6,6,0,24)
Block(6,6,1,24)
Block(6,6,2,24)
Block(6,6,3,24)
Block(6,6,4,24)
Block(6,6,5,24)
Block(6,6,6,24)
Block(6,6,7,24)
Block(6,6,8,24)
Block(6,7,-6,24)
Block(6,7,-5,24)
Block(6,7,-4,24)
Block(6,7,-3,24)
Block(6,7,-2,24)
Block(6,7,-1,24)
Block(6,7,0,24)
Block(6,7,1,24)
Block(6,7,2,24)
Block(6,7,3,24)
Block(6,7,4,24)
Block(6,7,5,24)
Block(6,7,6,24)
Block(6,7,7,24)
Block(6,7,8,24)
Block(6,8,-6,24)
Block(6,8,-5,24)
Block(6,8,-4,24)
Block(6,8,-3,24)
Block(6,8,-2,24)
Block(6,8,-1,24)
Block(6,8,0,24)
Block(6,8,1,24)
Block(6,8,2,24)
Block(6,8,3,24)
Block(6,8,4,24)
Block(6,8,5,24)
Block(6,8,6,24)
Block(6,8,7,24)
Block(6,8,8,24)
Block(6,9,-6,24)
Block(6,9,-5,24)
Block(6,9,-4,24)
Block(6,9,-3,24)
Block(6,9,-2,24)
Block(6,9,-1,24)
Block(6,9,0,24)
Block(6,9,1,24)
Block(6,9,2,24)
Block(6,9,3,24)
Block(6,9,4,24)
Block(6,9,5,24)
Block(6,9,6,24)
Block(6,9,7,24)
Block(6,9,8,24)
Block(6,10,-6,24)
Block(6,10,-5,24)
Block(6,10,-4,24)
Block(6,10,-3,24)
Block(6,10,-2,24)
Block(6,10,-1,24)
Block(6,10,0,24)
Block(6,10,1,24)
Block(6,10,2,24)
Block(6,10,3,24)
Block(6,10,4,24)
Block(6,10,5,24)
Block(6,10,6,24)
Block(6,10,7,24)
Block(6,10,8,24)
Block(6,11,-5,24)
Block(6,11,-4,24)
Block(6,11,-3,24)
Block(6,11,-2,24)
Block(6,11,-1,24)
Block(6,11,0,24)
Block(6,11,1,24)
Block(6,11,2,24)
Block(6,11,3,24)
Block(6,11,4,24)
Block(6,11,5,24)
Block(6,11,6,24)
Block(6,11,7,24)
Block(6,11,8,24)
Block(6,12,-4,24)
Block(6,12,-3,24)
Block(6,12,-2,24)
Block(6,12,-1,24)
Block(6,12,0,24)
Block(6,12,1,24)
Block(6,12,2,24)
Block(6,12,3,24)
Block(6,12,4,24)
Block(6,12,5,24)
Block(6,12,6,24)
Block(6,12,7,24)
Block(6,12,8,24)
Block(6,13,-4,24)
Block(6,13,-3,24)
Block(6,13,-2,24)
Block(6,13,-1,24)
Block(6,13,0,24)
Block(6,13,1,24)
Block(6,13,2,24)
Block(6,13,3,24)
Block(6,13,4,24)
Block(6,13,5,24)
Block(6,13,6,24)
Block(6,13,7,24)
Block(6,13,8,24)
Block(6,14,-4,24)
Block(6,14,-3,24)
Block(6,14,-2,24)
Block(6,14,-1,24)
Block(6,14,0,24)
Block(6,14,1,24)
Block(6,14,2,24)
Block(6,14,3,24)
Block(6,14,4,24)
Block(6,14,5,24)
Block(6,14,6,24)
Block(6,14,7,24)
Block(6,14,8,24)
Block(6,15,-4,24)
Block(6,15,-3,24)
Block(6,15,-2,24)
Block(6,15,-1,179)
Block(6,15,0,24)
Block(6,15,1,24)
Block(6,15,2,24)
Block(6,15,3,179)
Block(6,15,4,24)
Block(6,15,5,24)
Block(6,15,6,24)
Block(6,15,7,24)
Block(6,15,8,24)
Block(6,16,-4,AIR)
Block(6,16,-3,AIR)
Block(6,16,-2,192)
Block(6,16,-1,AIR)
Block(6,16,0,AIR)
Block(6,16,1,AIR)
Block(6,16,2,AIR)
Block(6,16,3,192)
Block(6,16,4,24)
Block(6,16,5,24)
Block(6,16,6,24)
Block(6,16,7,24)
Block(6,16,8,24)
Block(6,17,-4,AIR)
Block(6,17,-3,AIR)
Block(6,17,-2,192)
Block(6,17,-1,AIR)
Block(6,17,0,AIR)
Block(6,17,1,AIR)
Block(6,17,2,AIR)
Block(6,17,3,192)
Block(6,17,4,24)
Block(6,17,5,24)
Block(6,17,6,192)
Block(6,17,7,24)
Block(6,17,8,24)
Block(6,18,-4,AIR)
Block(6,18,-3,AIR)
Block(6,18,-2,192)
Block(6,18,-1,192)
Block(6,18,0,192)
Block(6,18,1,192)
Block(6,18,2,192)
Block(6,18,3,192)
Block(6,18,4,24)
Block(6,18,5,24)
Block(6,18,6,24)
Block(6,18,7,24)
Block(6,18,8,24)
Block(6,19,-4,AIR)
Block(6,19,-3,AIR)
Block(6,19,-2,126:4)
Block(6,19,-1,126:4)
Block(6,19,0,126:4)
Block(6,19,1,126:4)
Block(6,19,2,126:4)
Block(6,19,3,126:4)
Block(6,19,4,24)
Block(6,19,5,24)
Block(6,19,6,24)
Block(6,19,7,24)
Block(6,19,8,24)
Block(6,20,-4,AIR)
Block(6,20,-3,AIR)
Block(6,20,-2,AIR)
Block(6,20,-1,AIR)
Block(6,20,0,AIR)
Block(6,20,1,AIR)
Block(6,20,2,AIR)
Block(6,20,3,AIR)
Block(6,20,4,24)
Block(6,20,5,24)
Block(6,20,6,24)
Block(6,20,7,24)
Block(6,20,8,24)
Block(6,21,-4,AIR)
Block(6,21,-3,AIR)
Block(6,21,-2,AIR)
Block(6,21,-1,AIR)
Block(6,21,0,AIR)
Block(6,21,1,AIR)
Block(6,21,2,AIR)
Block(6,21,3,AIR)
Block(6,21,4,24)
Block(6,21,5,24)
Block(6,21,6,24)
Block(6,21,7,24)
Block(6,21,8,24)
Block(6,22,-3,AIR)
Block(6,22,-2,AIR)
Block(6,22,-1,AIR)
Block(6,22,0,AIR)
Block(6,22,1,AIR)
Block(6,22,2,AIR)
Block(6,22,3,AIR)
Block(6,22,4,24)
Block(6,22,5,192)
Block(6,22,6,192)
Block(6,22,7,24)
Block(6,22,8,24)
Block(6,23,-2,AIR)
Block(6,23,-1,AIR)
Block(6,23,0,AIR)
Block(6,23,1,AIR)
Block(6,23,2,AIR)
Block(6,23,3,AIR)
Block(6,23,4,24)
Block(6,23,5,24)
Block(6,23,6,24)
Block(6,23,7,24)
Block(6,23,8,24)
Block(6,24,-2,AIR)
Block(6,24,-1,AIR)
Block(6,24,0,AIR)
Block(6,24,1,AIR)
Block(6,24,2,AIR)
Block(6,24,3,AIR)
Block(6,24,4,126:4)
Block(6,24,5,126:4)
Block(6,24,6,126:4)
Block(6,24,7,126:4)
Block(6,24,8,126:4)
Block(6,25,-2,AIR)
Block(6,25,-1,AIR)
Block(6,25,0,AIR)
Block(6,25,1,AIR)
Block(6,25,2,AIR)
Block(6,25,3,AIR)
Block(6,25,4,AIR)
Block(6,25,5,AIR)
Block(6,25,6,AIR)
Block(6,25,7,AIR)
Block(6,25,8,AIR)
Block(6,26,-2,AIR)
Block(6,26,-1,AIR)
Block(6,26,0,AIR)
Block(6,26,1,AIR)
Block(6,26,2,AIR)
Block(6,26,3,AIR)
Block(6,26,4,AIR)
Block(6,26,5,AIR)
Block(6,26,6,AIR)
Block(6,26,7,AIR)
Block(6,26,8,AIR)
Block(6,27,-2,AIR)
Block(6,27,-1,AIR)
Block(6,27,0,AIR)
Block(6,27,1,AIR)
Block(6,27,2,AIR)
Block(6,27,3,AIR)
Block(6,27,4,AIR)
Block(6,27,5,AIR)
Block(6,27,6,AIR)
Block(6,27,7,AIR)
Block(6,27,8,AIR)
Block(6,28,-2,AIR)
Block(6,28,-1,AIR)
Block(6,28,0,AIR)
Block(6,28,1,AIR)
Block(6,28,2,AIR)
Block(6,28,3,AIR)
Block(6,28,4,AIR)
Block(6,28,5,AIR)
Block(6,28,6,AIR)
Block(6,28,7,AIR)
Block(6,28,8,AIR)
Block(6,29,-1,AIR)
Block(6,29,0,AIR)
Block(6,29,1,AIR)
Block(6,29,2,AIR)
Block(6,29,3,AIR)
Block(6,29,4,AIR)
Block(6,29,5,AIR)
Block(6,29,6,AIR)
Block(6,29,7,AIR)
Block(6,29,8,AIR)
Block(6,30,0,AIR)
Block(6,30,1,AIR)
Block(6,30,2,AIR)
Block(6,30,3,AIR)
Block(6,30,4,AIR)
Block(6,30,5,AIR)
Block(6,30,6,AIR)
Block(6,30,7,AIR)
Block(6,30,8,AIR)
Block(6,31,0,AIR)
Block(6,31,1,AIR)
Block(6,31,2,AIR)
Block(6,31,3,AIR)
Block(6,31,4,AIR)
Block(6,31,5,AIR)
Block(6,31,6,AIR)
Block(6,31,7,AIR)
Block(6,31,8,AIR)
Block(6,32,2,AIR)
Block(6,32,3,AIR)
Block(6,32,4,AIR)
Block(6,32,5,AIR)
Block(6,32,6,AIR)
Block(6,32,7,AIR)
Block(6,33,4,AIR)
Block(6,33,5,AIR)
Block(6,33,6,AIR)
Block(6,33,7,AIR)
Block(6,34,4,AIR)
Block(6,34,5,AIR)
Block(6,34,6,AIR)
Block(6,35,4,AIR)
Block(6,35,5,AIR)
Block(6,35,6,AIR)
Block(6,36,4,AIR)
Block(6,36,5,AIR)
Block(6,37,4,AIR)
Block(1,17,4,0)
Block(1,17,4,91:0)

#######################################################################
# +-----------------------------------------------------------------+ #
# |                            BO3 checks                           | #
# +-----------------------------------------------------------------+ #
#######################################################################

# Require a condition at a certain location in order for the BO3 to be spawned.
# BlockCheck(x,y,z,BlockName[,BlockName[,...]]) - one of the blocks must be at the location
# BlockCheckNot(x,y,z,BlockName[,BlockName[,...]]) - all the blocks must not be at the location
# LightCheck(x,y,z,minLightLevel,maxLightLevel) - light must be between min and max (inclusive)

# You can use "Solid" as a BlockName for matching all solid blocks or "All" to match all blocks that aren't air.

# Examples:
#   BlockCheck(0,-1,0,GRASS,DIRT)  Require grass or dirt just below the object
#   BlockCheck(0,-1,0,Solid)       Require any solid block just below the object
#   BlockCheck(0,-1,0,WOOL)        Require any type of wool just below the object
#   BlockCheck(0,-1,0,WOOL:0)      Require white wool just below the object
#   BlockCheckNot(0,-1,0,WOOL:0)   Require that there is no white wool below the object
#   LightCheck(0,0,0,0,1)          Require almost complete darkness just below the object

#######################################################################
# +-----------------------------------------------------------------+ #
# |                             Branches                            | #
# +-----------------------------------------------------------------+ #
#######################################################################

# Branches are objects that will spawn when this object spawns when it is used in
# the CustomStructure resource. Branches can also have branches, making complex
# structures possible. See the wiki for more details.

# Regular Branches spawn each branch with an independent chance of spawning.
# Branch(x,y,z,branchName,rotation,chance[,anotherBranchName,rotation,chance[,...]][IndividualChance])
# branchName - name of the object to spawn.
# rotation - NORTH, SOUTH, EAST or WEST.
