#######################################################################
# +-----------------------------------------------------------------+ #
# |                            BO3 object                           | #
# +-----------------------------------------------------------------+ #
#######################################################################

# The descriptions in this file are true only for TerrainControl. They are not true for the Minecraft Worlds mod!
# Minecraft Worlds completely reimplemented BO3s, check the MCW documentation on the mc/mctcp forums for how to use BO3s with MCW
# or watch the video's on my YT channel at https://www.youtube.com/user/PeeGee85. You can check out the "Editing and importing schematics & BO3s" 
# series of video's, in part 2 I explain BO3s. 

# This is the config file of a custom object.
# If you add this object correctly to your BiomeConfigs, it will spawn in the world.

# This is the creator of this BO3 object
Author: LordSmellyPants

# A short description of this BO3 object


# The BO3 version, don't change this! It can be used by external applications to do a version check.
Version: 3

# The settings mode, WriteAll, WriteWithoutComments or WriteDisable. See WorldConfig.
SettingsMode: WriteDisable

#######################################################################
# +-----------------------------------------------------------------+ #
# |                          Main settings                          | #
# +-----------------------------------------------------------------+ #
#######################################################################

# This needs to be set to true to spawn the object in the Tree and Sapling resources.
Tree: false

# The frequency of the BO3 from 1 to 200. Tries this many times to spawn this BO3 when using the CustomObject(...) resource.
# Ignored by Tree(..), Sapling(..) and CustomStructure(..)
Frequency: 40

# The rarity of the BO3 from 0 to 100. Each spawn attempt has rarity% chance to succeed when using the CustomObject(...) resource.
# Ignored by Tree(..), Sapling(..) and CustomStructure(..)
Rarity: 100.0

# If you set this to true, the BO3 will be placed with a random rotation.
RotateRandomly: true

# The spawn height of the BO3 - randomY, highestBlock or highestSolidBlock.
SpawnHeight: randomY

# The height limits for the BO3.
MinHeight: 35

MaxHeight: 45

# Objects can have other objects attached to it: branches. Branches can also
# have branches attached to it, which can also have branches, etc. This is the
# maximum branch depth for this objects.
MaxBranchDepth: 10

# When spawned with the UseWorld keyword, this BO3 should NOT spawn in the following biomes.
# If you writer.write the BO3 name directly in the BiomeConfigs, this will be ignored.
ExcludedBiomes: All

#######################################################################
# +-----------------------------------------------------------------+ #
# |                      Source block settings                      | #
# +-----------------------------------------------------------------+ #
#######################################################################

# The block(s) the BO3 should spawn in.
SourceBlocks: AIR

# The maximum percentage of the BO3 that can be outside the SourceBlock.
# The BO3 won't be placed on a location with more blocks outside the SourceBlock than this percentage.
MaxPercentageOutsideSourceBlock: 100

# What to do when a block is about to be placed outside the SourceBlock? (dontPlace, placeAnyway)
OutsideSourceBlock: placeAnyway

#######################################################################
# +-----------------------------------------------------------------+ #
# |                              Blocks                             | #
# +-----------------------------------------------------------------+ #
#######################################################################

# All the blocks used in the BO3 are listed here. Possible blocks:
# Block(x,y,z,id[.data][,nbtfile.nbt)
# RandomBlock(x,y,z,id[:data][,nbtfile.nbt],chance[,id[:data][,nbtfile.nbt],chance[,...]])
# So RandomBlock(0,0,0,CHEST,chest.nbt,50,CHEST,anotherchest.nbt,100) will spawn a chest at
# the BO3 origin, and give it a 50% chance to have the contents of chest.nbt, or, if that
# fails, a 100% percent chance to have the contents of anotherchest.nbt.

Block(1,13,5,1)
Block(1,13,6,1)
Block(1,14,5,1)
Block(1,14,6,1)
Block(1,14,7,1)
Block(1,15,5,1)
Block(1,15,6,1)
Block(1,16,4,1)
Block(2,8,7,1)
Block(2,9,7,1)
Block(2,10,6,1)
Block(2,11,2,1)
Block(2,11,3,1)
Block(2,11,4,1)
Block(2,11,5,1)
Block(2,11,6,1)
Block(2,12,2,1)
Block(2,12,3,1)
Block(2,12,4,1)
Block(2,12,5,1)
Block(2,12,6,1)
Block(2,13,3,1)
Block(2,13,4,1)
Block(2,13,5,1)
Block(2,13,6,1)
Block(2,13,7,1)
Block(2,13,8,1)
Block(2,14,3,1)
Block(2,14,4,1)
Block(2,14,5,1)
Block(2,14,6,1)
Block(2,14,7,1)
Block(2,14,8,1)
Block(2,15,3,1)
Block(2,15,4,1)
Block(2,15,5,1)
Block(2,15,6,1)
Block(2,15,7,1)
Block(2,15,8,1)
Block(2,16,3,1)
Block(2,16,4,1)
Block(2,16,5,1)
Block(2,16,6,1)
Block(2,16,7,1)
Block(2,17,4,1)
Block(2,17,5,1)
Block(2,17,6,1)
Block(2,17,7,1)
Block(2,18,4,1)
Block(2,18,5,1)
Block(2,18,6,1)
Block(2,18,7,1)
Block(2,19,4,1)
Block(2,19,5,1)
Block(2,19,6,1)
Block(2,19,7,1)
Block(2,20,4,1)
Block(2,20,5,1)
Block(2,20,6,1)
Block(2,20,7,1)
Block(2,21,5,1)
Block(2,21,6,1)
Block(3,8,6,1)
Block(3,8,7,1)
Block(3,8,8,1)
Block(3,9,6,1)
Block(3,9,7,1)
Block(3,9,8,1)
Block(3,10,3,1)
Block(3,10,4,1)
Block(3,10,5,1)
Block(3,10,6,1)
Block(3,10,7,1)
Block(3,10,8,1)
Block(3,11,2,1)
Block(3,11,3,1)
Block(3,11,4,1)
Block(3,11,5,1)
Block(3,11,6,1)
Block(3,11,7,1)
Block(3,11,8,1)
Block(3,12,2,1)
Block(3,12,3,1)
Block(3,12,4,1)
Block(3,12,5,1)
Block(3,12,6,1)
Block(3,12,7,1)
Block(3,12,8,1)
Block(3,13,3,1)
Block(3,13,4,1)
Block(3,13,5,1)
Block(3,13,6,1)
Block(3,13,7,1)
Block(3,13,8,1)
Block(3,14,3,1)
Block(3,14,4,1)
Block(3,14,5,1)
Block(3,14,6,1)
Block(3,14,7,1)
Block(3,14,8,1)
Block(3,15,3,1)
Block(3,15,4,1)
Block(3,15,5,1)
Block(3,15,6,1)
Block(3,15,7,1)
Block(3,15,8,1)
Block(3,16,3,1)
Block(3,16,4,1)
Block(3,16,5,1)
Block(3,16,6,1)
Block(3,16,7,1)
Block(3,16,8,1)
Block(3,17,3,1)
Block(3,17,4,1)
Block(3,17,5,1)
Block(3,17,6,1)
Block(3,17,7,1)
Block(3,17,8,1)
Block(3,18,3,1)
Block(3,18,4,1)
Block(3,18,5,1)
Block(3,18,6,1)
Block(3,18,7,1)
Block(3,18,8,1)
Block(3,19,3,1)
Block(3,19,4,1)
Block(3,19,5,1)
Block(3,19,6,1)
Block(3,19,7,1)
Block(3,19,8,1)
Block(3,20,3,1)
Block(3,20,4,1)
Block(3,20,5,1)
Block(3,20,6,1)
Block(3,20,7,1)
Block(3,20,8,1)
Block(3,21,4,1)
Block(3,21,5,1)
Block(3,21,6,1)
Block(3,21,7,1)
Block(3,21,8,1)
Block(3,22,4,1)
Block(3,22,5,1)
Block(3,22,6,1)
Block(3,22,7,1)
Block(3,22,8,1)
Block(3,23,4,1)
Block(3,23,5,1)
Block(3,23,6,1)
Block(3,23,7,1)
Block(3,23,8,1)
Block(3,24,4,1)
Block(3,24,5,1)
Block(3,24,6,1)
Block(3,24,7,1)
Block(3,24,8,3)
Block(3,25,5,1)
Block(3,25,6,3)
Block(3,25,7,3)
Block(3,25,8,3)
Block(3,26,6,3)
Block(3,26,7,3)
Block(3,26,8,2)
Block(3,27,6,3)
Block(3,27,7,3)
Block(3,28,6,2)
Block(3,28,7,2)
Block(4,7,3,1)
Block(4,7,4,1)
Block(4,7,5,1)
Block(4,7,6,1)
Block(4,7,7,1)
Block(4,8,3,1)
Block(4,8,4,1)
Block(4,8,5,1)
Block(4,8,6,1)
Block(4,8,7,1)
Block(4,8,8,1)
Block(4,9,3,1)
Block(4,9,4,1)
Block(4,9,5,1)
Block(4,9,6,1)
Block(4,9,7,1)
Block(4,9,8,1)
Block(4,10,0,1)
Block(4,10,1,1)
Block(4,10,2,1)
Block(4,10,3,1)
Block(4,10,4,1)
Block(4,10,5,1)
Block(4,10,6,1)
Block(4,10,7,1)
Block(4,10,8,1)
Block(4,11,-1,1)
Block(4,11,0,1)
Block(4,11,1,1)
Block(4,11,2,1)
Block(4,11,3,1)
Block(4,11,4,1)
Block(4,11,5,1)
Block(4,11,6,1)
Block(4,11,7,1)
Block(4,11,8,1)
Block(4,12,1,1)
Block(4,12,2,1)
Block(4,12,3,1)
Block(4,12,4,1)
Block(4,12,5,1)
Block(4,12,6,1)
Block(4,12,7,1)
Block(4,12,8,1)
Block(4,13,2,1)
Block(4,13,3,1)
Block(4,13,4,1)
Block(4,13,5,1)
Block(4,13,6,1)
Block(4,13,7,1)
Block(4,13,8,1)
Block(4,14,2,1)
Block(4,14,3,1)
Block(4,14,4,1)
Block(4,14,5,1)
Block(4,14,6,1)
Block(4,14,7,1)
Block(4,14,8,1)
Block(4,15,2,1)
Block(4,15,3,1)
Block(4,15,4,1)
Block(4,15,5,1)
Block(4,15,6,1)
Block(4,15,7,1)
Block(4,15,8,1)
Block(4,16,2,1)
Block(4,16,3,1)
Block(4,16,4,1)
Block(4,16,5,1)
Block(4,16,6,1)
Block(4,16,7,1)
Block(4,16,8,1)
Block(4,17,2,1)
Block(4,17,3,1)
Block(4,17,4,1)
Block(4,17,5,1)
Block(4,17,6,1)
Block(4,17,7,1)
Block(4,17,8,1)
Block(4,18,2,1)
Block(4,18,3,1)
Block(4,18,4,1)
Block(4,18,5,1)
Block(4,18,6,1)
Block(4,18,7,1)
Block(4,18,8,1)
Block(4,19,2,1)
Block(4,19,3,1)
Block(4,19,4,1)
Block(4,19,5,1)
Block(4,19,6,1)
Block(4,19,7,1)
Block(4,19,8,1)
Block(4,20,3,1)
Block(4,20,4,1)
Block(4,20,5,1)
Block(4,20,6,1)
Block(4,20,7,1)
Block(4,20,8,1)
Block(4,21,3,1)
Block(4,21,4,1)
Block(4,21,5,1)
Block(4,21,6,1)
Block(4,21,7,1)
Block(4,21,8,1)
Block(4,22,3,1)
Block(4,22,4,1)
Block(4,22,5,1)
Block(4,22,6,1)
Block(4,22,7,1)
Block(4,22,8,1)
Block(4,23,3,1)
Block(4,23,4,1)
Block(4,23,5,1)
Block(4,23,6,1)
Block(4,23,7,1)
Block(4,23,8,1)
Block(4,24,3,1)
Block(4,24,4,1)
Block(4,24,5,1)
Block(4,24,6,1)
Block(4,24,7,1)
Block(4,24,8,1)
Block(4,25,4,1)
Block(4,25,5,1)
Block(4,25,6,1)
Block(4,25,7,1)
Block(4,25,8,1)
Block(4,26,4,2)
Block(4,26,5,3)
Block(4,26,6,1)
Block(4,26,7,1)
Block(4,26,8,1)
Block(4,27,5,3)
Block(4,27,6,3)
Block(4,27,7,1)
Block(4,27,8,1)
Block(4,28,5,3)
Block(4,28,6,3)
Block(4,28,7,3)
Block(4,28,8,1)
Block(4,29,5,2)
Block(4,29,6,3)
Block(4,29,7,3)
Block(4,29,8,1)
Block(4,30,6,2)
Block(4,30,7,3)
Block(4,30,8,3)
Block(4,31,7,2)
Block(4,31,8,3)
Block(4,32,8,3)
Block(4,33,8,2)
Block(5,6,3,1)
Block(5,6,4,1)
Block(5,6,5,1)
Block(5,7,2,1)
Block(5,7,3,1)
Block(5,7,4,1)
Block(5,7,5,1)
Block(5,7,6,1)
Block(5,7,7,1)
Block(5,7,8,1)
Block(5,8,1,1)
Block(5,8,2,1)
Block(5,8,3,1)
Block(5,8,4,1)
Block(5,8,5,1)
Block(5,8,6,1)
Block(5,8,7,1)
Block(5,8,8,1)
Block(5,9,1,1)
Block(5,9,2,1)
Block(5,9,3,1)
Block(5,9,4,1)
Block(5,9,5,1)
Block(5,9,6,1)
Block(5,9,7,1)
Block(5,9,8,1)
Block(5,10,0,1)
Block(5,10,1,1)
Block(5,10,2,1)
Block(5,10,3,1)
Block(5,10,4,1)
Block(5,10,5,1)
Block(5,10,6,1)
Block(5,10,7,1)
Block(5,10,8,1)
Block(5,11,-2,1)
Block(5,11,-1,1)
Block(5,11,0,1)
Block(5,11,1,1)
Block(5,11,2,1)
Block(5,11,3,1)
Block(5,11,4,1)
Block(5,11,5,1)
Block(5,11,6,1)
Block(5,11,7,1)
Block(5,11,8,1)
Block(5,12,-1,1)
Block(5,12,0,1)
Block(5,12,1,1)
Block(5,12,2,1)
Block(5,12,3,1)
Block(5,12,4,1)
Block(5,12,5,1)
Block(5,12,6,1)
Block(5,12,7,1)
Block(5,12,8,1)
Block(5,13,0,1)
Block(5,13,1,1)
Block(5,13,2,1)
Block(5,13,3,1)
Block(5,13,4,1)
Block(5,13,5,1)
Block(5,13,6,1)
Block(5,13,7,1)
Block(5,13,8,1)
Block(5,14,0,1)
Block(5,14,1,1)
Block(5,14,2,1)
Block(5,14,3,1)
Block(5,14,4,1)
Block(5,14,5,1)
Block(5,14,6,1)
Block(5,14,7,1)
Block(5,14,8,1)
Block(5,15,0,1)
Block(5,15,1,1)
Block(5,15,2,1)
Block(5,15,3,1)
Block(5,15,4,1)
Block(5,15,5,1)
Block(5,15,6,1)
Block(5,15,7,1)
Block(5,15,8,1)
Block(5,16,1,1)
Block(5,16,2,1)
Block(5,16,3,1)
Block(5,16,4,1)
Block(5,16,5,1)
Block(5,16,6,1)
Block(5,16,7,1)
Block(5,16,8,1)
Block(5,17,1,1)
Block(5,17,2,1)
Block(5,17,3,1)
Block(5,17,4,1)
Block(5,17,5,1)
Block(5,17,6,1)
Block(5,17,7,1)
Block(5,17,8,1)
Block(5,18,2,1)
Block(5,18,3,1)
Block(5,18,4,1)
Block(5,18,5,1)
Block(5,18,6,1)
Block(5,18,7,1)
Block(5,18,8,1)
Block(5,19,2,1)
Block(5,19,3,1)
Block(5,19,4,1)
Block(5,19,5,1)
Block(5,19,6,1)
Block(5,19,7,1)
Block(5,19,8,1)
Block(5,20,2,1)
Block(5,20,3,1)
Block(5,20,4,1)
Block(5,20,5,1)
Block(5,20,6,1)
Block(5,20,7,1)
Block(5,20,8,1)
Block(5,21,2,1)
Block(5,21,3,1)
Block(5,21,4,1)
Block(5,21,5,1)
Block(5,21,6,1)
Block(5,21,7,1)
Block(5,21,8,1)
Block(5,22,2,1)
Block(5,22,3,1)
Block(5,22,4,1)
Block(5,22,5,1)
Block(5,22,6,1)
Block(5,22,7,1)
Block(5,22,8,1)
Block(5,23,2,1)
Block(5,23,3,1)
Block(5,23,4,1)
Block(5,23,5,1)
Block(5,23,6,1)
Block(5,23,7,1)
Block(5,23,8,1)
Block(5,24,2,1)
Block(5,24,3,1)
Block(5,24,4,1)
Block(5,24,5,1)
Block(5,24,6,1)
Block(5,24,7,1)
Block(5,24,8,1)
Block(5,25,3,3)
Block(5,25,4,1)
Block(5,25,5,1)
Block(5,25,6,1)
Block(5,25,7,1)
Block(5,25,8,1)
Block(5,26,3,2)
Block(5,26,4,3)
Block(5,26,5,1)
Block(5,26,6,1)
Block(5,26,7,1)
Block(5,26,8,1)
Block(5,27,4,3)
Block(5,27,5,3)
Block(5,27,6,1)
Block(5,27,7,1)
Block(5,27,8,1)
Block(5,28,4,3)
Block(5,28,5,3)
Block(5,28,6,3)
Block(5,28,7,1)
Block(5,28,8,1)
Block(5,29,4,2)
Block(5,29,5,3)
Block(5,29,6,3)
Block(5,29,7,1)
Block(5,29,8,1)
Block(5,30,5,2)
Block(5,30,6,3)
Block(5,30,7,3)
Block(5,30,8,1)
Block(5,31,6,2)
Block(5,31,7,3)
Block(5,31,8,3)
Block(5,32,7,3)
Block(5,32,8,3)
Block(5,33,7,2)
Block(5,33,8,3)
Block(5,34,8,2)
Block(6,6,3,1)
Block(6,6,4,1)
Block(6,6,5,1)
Block(6,7,0,1)
Block(6,7,1,1)
Block(6,7,2,1)
Block(6,7,3,1)
Block(6,7,4,1)
Block(6,7,5,1)
Block(6,7,6,1)
Block(6,7,7,1)
Block(6,7,8,1)
Block(6,8,0,1)
Block(6,8,1,1)
Block(6,8,2,1)
Block(6,8,3,1)
Block(6,8,4,1)
Block(6,8,5,1)
Block(6,8,6,1)
Block(6,8,7,1)
Block(6,8,8,1)
Block(6,9,0,1)
Block(6,9,1,1)
Block(6,9,2,1)
Block(6,9,3,1)
Block(6,9,4,1)
Block(6,9,5,1)
Block(6,9,6,1)
Block(6,9,7,1)
Block(6,9,8,1)
Block(6,10,0,1)
Block(6,10,1,1)
Block(6,10,2,1)
Block(6,10,3,1)
Block(6,10,4,1)
Block(6,10,5,1)
Block(6,10,6,1)
Block(6,10,7,1)
Block(6,10,8,1)
Block(6,11,-2,1)
Block(6,11,-1,1)
Block(6,11,0,1)
Block(6,11,1,1)
Block(6,11,2,1)
Block(6,11,3,1)
Block(6,11,4,1)
Block(6,11,5,1)
Block(6,11,6,1)
Block(6,11,7,1)
Block(6,11,8,1)
Block(6,12,-1,1)
Block(6,12,0,1)
Block(6,12,1,1)
Block(6,12,2,1)
Block(6,12,3,1)
Block(6,12,4,1)
Block(6,12,5,1)
Block(6,12,6,1)
Block(6,12,7,1)
Block(6,12,8,1)
Block(6,13,-1,1)
Block(6,13,0,1)
Block(6,13,1,1)
Block(6,13,2,1)
Block(6,13,3,1)
Block(6,13,4,1)
Block(6,13,5,1)
Block(6,13,6,1)
Block(6,13,7,1)
Block(6,13,8,1)
Block(6,14,-1,1)
Block(6,14,0,1)
Block(6,14,1,1)
Block(6,14,2,1)
Block(6,14,3,1)
Block(6,14,4,1)
Block(6,14,5,1)
Block(6,14,6,1)
Block(6,14,7,1)
Block(6,14,8,1)
Block(6,15,0,1)
Block(6,15,1,1)
Block(6,15,2,1)
Block(6,15,3,1)
Block(6,15,4,1)
Block(6,15,5,1)
Block(6,15,6,1)
Block(6,15,7,1)
Block(6,15,8,1)
Block(6,16,0,1)
Block(6,16,1,1)
Block(6,16,2,1)
Block(6,16,3,1)
Block(6,16,4,1)
Block(6,16,5,1)
Block(6,16,6,1)
Block(6,16,7,1)
Block(6,16,8,1)
Block(6,17,0,1)
Block(6,17,1,1)
Block(6,17,2,1)
Block(6,17,3,1)
Block(6,17,4,1)
Block(6,17,5,1)
Block(6,17,6,1)
Block(6,17,7,1)
Block(6,17,8,1)
Block(6,18,0,1)
Block(6,18,1,1)
Block(6,18,2,1)
Block(6,18,3,1)
Block(6,18,4,1)
Block(6,18,5,1)
Block(6,18,6,1)
Block(6,18,7,1)
Block(6,18,8,1)
Block(6,19,0,1)
Block(6,19,1,1)
Block(6,19,2,1)
Block(6,19,3,1)
Block(6,19,4,1)
Block(6,19,5,1)
Block(6,19,6,1)
Block(6,19,7,1)
Block(6,19,8,1)
Block(6,20,1,1)
Block(6,20,2,1)
Block(6,20,3,1)
Block(6,20,4,1)
Block(6,20,5,1)
Block(6,20,6,1)
Block(6,20,7,1)
Block(6,20,8,1)
Block(6,21,1,1)
Block(6,21,2,1)
Block(6,21,3,1)
Block(6,21,4,1)
Block(6,21,5,1)
Block(6,21,6,1)
Block(6,21,7,1)
Block(6,21,8,1)
Block(6,22,2,1)
Block(6,22,3,1)
Block(6,22,4,1)
Block(6,22,5,1)
Block(6,22,6,1)
Block(6,22,7,1)
Block(6,22,8,1)
Block(6,23,2,1)
Block(6,23,3,1)
Block(6,23,4,1)
Block(6,23,5,1)
Block(6,23,6,1)
Block(6,23,7,1)
Block(6,23,8,1)
Block(6,24,2,1)
Block(6,24,3,1)
Block(6,24,4,1)
Block(6,24,5,1)
Block(6,24,6,1)
Block(6,24,7,1)
Block(6,24,8,1)
Block(6,25,2,2)
Block(6,25,3,1)
Block(6,25,4,1)
Block(6,25,5,1)
Block(6,25,6,1)
Block(6,25,7,1)
Block(6,25,8,1)
Block(6,26,3,3)
Block(6,26,4,1)
Block(6,26,5,1)
Block(6,26,6,1)
Block(6,26,7,1)
Block(6,26,8,1)
Block(6,27,3,3)
Block(6,27,4,3)
Block(6,27,5,1)
Block(6,27,6,1)
Block(6,27,7,1)
Block(6,27,8,1)
Block(6,28,3,3)
Block(6,28,4,3)
Block(6,28,5,3)
Block(6,28,6,1)
Block(6,28,7,1)
Block(6,28,8,1)
Block(6,29,3,2)
Block(6,29,4,3)
Block(6,29,5,3)
Block(6,29,6,3)
Block(6,29,7,1)
Block(6,29,8,1)
Block(6,30,4,2)
Block(6,30,5,3)
Block(6,30,6,3)
Block(6,30,7,1)
Block(6,30,8,1)
Block(6,31,5,2)
Block(6,31,6,3)
Block(6,31,7,3)
Block(6,31,8,1)
Block(6,32,6,2)
Block(6,32,7,3)
Block(6,32,8,3)
Block(6,33,7,3)
Block(6,33,8,3)
Block(6,34,7,2)
Block(6,34,8,3)
Block(6,35,8,2)
Block(7,5,5,1)
Block(7,6,0,1)
Block(7,6,1,1)
Block(7,6,2,1)
Block(7,6,3,1)
Block(7,6,4,1)
Block(7,6,5,1)
Block(7,6,6,1)
Block(7,6,7,1)
Block(7,6,8,1)
Block(7,7,-1,1)
Block(7,7,0,1)
Block(7,7,1,1)
Block(7,7,2,1)
Block(7,7,3,1)
Block(7,7,4,1)
Block(7,7,5,1)
Block(7,7,6,1)
Block(7,7,7,1)
Block(7,7,8,1)
Block(7,8,-1,1)
Block(7,8,0,1)
Block(7,8,1,1)
Block(7,8,2,1)
Block(7,8,3,1)
Block(7,8,4,1)
Block(7,8,5,1)
Block(7,8,6,1)
Block(7,8,7,1)
Block(7,8,8,1)
Block(7,9,-1,1)
Block(7,9,0,1)
Block(7,9,1,1)
Block(7,9,2,1)
Block(7,9,3,1)
Block(7,9,4,1)
Block(7,9,5,1)
Block(7,9,6,1)
Block(7,9,7,1)
Block(7,9,8,1)
Block(7,10,-1,1)
Block(7,10,0,1)
Block(7,10,1,1)
Block(7,10,2,1)
Block(7,10,3,1)
Block(7,10,4,1)
Block(7,10,5,1)
Block(7,10,6,1)
Block(7,10,7,1)
Block(7,10,8,1)
Block(7,11,-2,1)
Block(7,11,-1,1)
Block(7,11,0,1)
Block(7,11,1,1)
Block(7,11,2,1)
Block(7,11,3,1)
Block(7,11,4,1)
Block(7,11,5,1)
Block(7,11,6,1)
Block(7,11,7,1)
Block(7,11,8,1)
Block(7,12,-2,1)
Block(7,12,-1,1)
Block(7,12,0,1)
Block(7,12,1,1)
Block(7,12,2,1)
Block(7,12,3,1)
Block(7,12,4,1)
Block(7,12,5,1)
Block(7,12,6,1)
Block(7,12,7,1)
Block(7,12,8,1)
Block(7,13,-2,1)
Block(7,13,-1,1)
Block(7,13,0,1)
Block(7,13,1,1)
Block(7,13,2,1)
Block(7,13,3,1)
Block(7,13,4,1)
Block(7,13,5,1)
Block(7,13,6,1)
Block(7,13,7,1)
Block(7,13,8,1)
Block(7,14,-2,1)
Block(7,14,-1,1)
Block(7,14,0,1)
Block(7,14,1,1)
Block(7,14,2,1)
Block(7,14,3,1)
Block(7,14,4,1)
Block(7,14,5,1)
Block(7,14,6,1)
Block(7,14,7,1)
Block(7,14,8,1)
Block(7,15,-2,1)
Block(7,15,-1,1)
Block(7,15,0,1)
Block(7,15,1,1)
Block(7,15,2,1)
Block(7,15,3,1)
Block(7,15,4,1)
Block(7,15,5,1)
Block(7,15,6,1)
Block(7,15,7,1)
Block(7,15,8,1)
Block(7,16,-1,1)
Block(7,16,0,1)
Block(7,16,1,1)
Block(7,16,2,1)
Block(7,16,3,1)
Block(7,16,4,1)
Block(7,16,5,1)
Block(7,16,6,1)
Block(7,16,7,1)
Block(7,16,8,1)
Block(7,17,-1,1)
Block(7,17,0,1)
Block(7,17,1,1)
Block(7,17,2,1)
Block(7,17,3,1)
Block(7,17,4,1)
Block(7,17,5,1)
Block(7,17,6,1)
Block(7,17,7,1)
Block(7,17,8,1)
Block(7,18,-1,1)
Block(7,18,0,1)
Block(7,18,1,1)
Block(7,18,2,1)
Block(7,18,3,1)
Block(7,18,4,1)
Block(7,18,5,1)
Block(7,18,6,1)
Block(7,18,7,1)
Block(7,18,8,1)
Block(7,19,-1,1)
Block(7,19,0,1)
Block(7,19,1,1)
Block(7,19,2,1)
Block(7,19,3,1)
Block(7,19,4,1)
Block(7,19,5,1)
Block(7,19,6,1)
Block(7,19,7,1)
Block(7,19,8,1)
Block(7,20,-1,1)
Block(7,20,0,1)
Block(7,20,1,1)
Block(7,20,2,1)
Block(7,20,3,1)
Block(7,20,4,1)
Block(7,20,5,1)
Block(7,20,6,1)
Block(7,20,7,1)
Block(7,20,8,1)
Block(7,21,0,1)
Block(7,21,1,1)
Block(7,21,2,1)
Block(7,21,3,1)
Block(7,21,4,1)
Block(7,21,5,1)
Block(7,21,6,1)
Block(7,21,7,1)
Block(7,21,8,1)
Block(7,22,0,1)
Block(7,22,1,1)
Block(7,22,2,1)
Block(7,22,3,1)
Block(7,22,4,1)
Block(7,22,5,1)
Block(7,22,6,1)
Block(7,22,7,1)
Block(7,22,8,1)
Block(7,23,1,1)
Block(7,23,2,1)
Block(7,23,3,1)
Block(7,23,4,1)
Block(7,23,5,1)
Block(7,23,6,1)
Block(7,23,7,1)
Block(7,23,8,1)
Block(7,24,1,1)
Block(7,24,2,1)
Block(7,24,3,1)
Block(7,24,4,1)
Block(7,24,5,1)
Block(7,24,6,1)
Block(7,24,7,1)
Block(7,24,8,1)
Block(7,25,2,3)
Block(7,25,3,3)
Block(7,25,4,1)
Block(7,25,5,1)
Block(7,25,6,1)
Block(7,25,7,1)
Block(7,25,8,1)
Block(7,26,2,2)
Block(7,26,3,3)
Block(7,26,4,1)
Block(7,26,5,1)
Block(7,26,6,1)
Block(7,26,7,1)
Block(7,26,8,1)
Block(7,27,3,3)
Block(7,27,4,1)
Block(7,27,5,1)
Block(7,27,6,1)
Block(7,27,7,1)
Block(7,27,8,1)
Block(7,28,3,2)
Block(7,28,4,3)
Block(7,28,5,1)
Block(7,28,6,1)
Block(7,28,7,1)
Block(7,28,8,1)
Block(7,29,4,3)
Block(7,29,5,3)
Block(7,29,6,1)
Block(7,29,7,1)
Block(7,29,8,1)
Block(7,30,4,3)
Block(7,30,5,3)
Block(7,30,6,3)
Block(7,30,7,1)
Block(7,30,8,1)
Block(7,31,4,2)
Block(7,31,5,3)
Block(7,31,6,3)
Block(7,31,7,1)
Block(7,31,8,1)
Block(7,32,5,2)
Block(7,32,6,3)
Block(7,32,7,3)
Block(7,32,8,1)
Block(7,33,6,2)
Block(7,33,7,3)
Block(7,33,8,1)
Block(7,34,7,3)
Block(7,34,8,1)
Block(7,35,7,2)
Block(7,35,8,3)
Block(7,36,8,3)
Block(7,37,8,3)
Block(7,38,8,2)

# 

#######################################################################
# +-----------------------------------------------------------------+ #
# |                            BO3 checks                           | #
# +-----------------------------------------------------------------+ #
#######################################################################

# Require a condition at a certain location in order for the BO3 to be spawned.
# BlockCheck(x,y,z,BlockName[,BlockName[,...]]) - one of the blocks must be at the location
# BlockCheckNot(x,y,z,BlockName[,BlockName[,...]]) - all the blocks must not be at the location
# LightCheck(x,y,z,minLightLevel,maxLightLevel) - light must be between min and max (inclusive)

# You can use "Solid" as a BlockName for matching all solid blocks or "All" to match all blocks that aren't air.

# Examples:
#   BlockCheck(0,-1,0,GRASS,DIRT)  Require grass or dirt just below the object
#   BlockCheck(0,-1,0,Solid)       Require any solid block just below the object
#   BlockCheck(0,-1,0,WOOL)        Require any type of wool just below the object
#   BlockCheck(0,-1,0,WOOL:0)      Require white wool just below the object
#   BlockCheckNot(0,0,0,WOOL:0)   Require that there is no white wool below the object
#   LightCheck(0,0,0,0,1)          Require almost complete darkness just below the object

#######################################################################
# +-----------------------------------------------------------------+ #
# |                             Branches                            | #
# +-----------------------------------------------------------------+ #
#######################################################################

# Branches are objects that will spawn when this object spawns when it is used in
# the CustomStructure resource. Branches can also have branches, making complex
# structures possible. See the wiki for more details.

# Regular Branches spawn each branch with an independent chance of spawning.
# Branch(x,y,z,branchName,rotation,chance[,anotherBranchName,rotation,chance[,...]][IndividualChance])
# branchName - name of the object to spawn.
# rotation - NORTH, SOUTH, EAST or WEST.
# IndividualChance - The chance each branch has to spawn, assumed to be 100 when left blank

Branch(16,0,0,hugearchC1R0,NORTH,100)
Branch(0,0,16,hugearchC0R1,NORTH,100)

# WeightedBranch(x,y,z,branchName,rotation,chance[,anotherBranchName,rotation,chance[,...]][MaxChanceOutOf])
# MaxChanceOutOf - The chance all branches have to spawn out of, assumed to be 100 when left blank
