
#######################################################################
# +-----------------------------------------------------------------+ #
# |                            BO3 object                           | #
# +-----------------------------------------------------------------+ #
#######################################################################

Author: Unknown

Description: Converted version of the BO2 AcaciaSavanna2

Version: 3

SettingsMode: WriteWithoutComments


#######################################################################
# +-----------------------------------------------------------------+ #
# |                          Main settings                          | #
# +-----------------------------------------------------------------+ #
#######################################################################

Tree: true

Frequency: 1

Rarity: 5.0

RotateRandomly: true

SpawnHeight: highestSolidBlock

SpawnHeightOffset: 0

SpawnHeightVariance: 0

##############################
# Height Limits for the BO3. #
##############################

MinHeight: 62

MaxHeight: 210

######################
# Extrusion settings #
######################

ExtrudeMode: None

ExtrudeThroughBlocks: AIR

MaxBranchDepth: 10

ExcludedBiomes: All


#######################################################################
# +-----------------------------------------------------------------+ #
# |                      Source block settings                      | #
# +-----------------------------------------------------------------+ #
#######################################################################

SourceBlocks: STONE:1,STONE:3,STONE:5,DIRT:1,DIRT,SAND,GRASS,DIRT:2,STATIONARY_WATER,HARD_CLAY,STAINED_CLAY,CLAY,SANDSTONE,SAND:1,AIR,STONE,GRAVEL,LONG_GRASS,LONG_GRASS:1,LONG_GRASS:2,DEAD_BUSH,YELLOW_FLOWER,RED_ROSE,BROWN_MUSHROOM,RED_MUSHROOM

MaxPercentageOutsideSourceBlock: 0

OutsideSourceBlock: placeAnyway

IsOTGPlus: false

InheritBO3: 

InheritBO3Rotation: NORTH

OverrideChildSettings: true

OverrideParentHeight: false

CanOverride: false

BranchFrequency: 0

BranchFrequencyGroup: 

MustBeBelowOther: false

MustBeInside: 

CannotBeInside: 

ReplacesBO3: 

CanSpawnOnWater: true

SpawnOnWaterOnly: false

SpawnUnderWater: false

SpawnAtWaterLevel: false

HeightOffset: 0

RemoveAir: true

ReplaceAbove: 

ReplaceBelow: 

ReplaceWithBiomeBlocks: true

ReplaceWithGroundBlock: DIRT

ReplaceWithSurfaceBlock: GRASS

SmoothRadius: 0

SmoothHeightOffset: 0

SmoothStartTop: false

SmoothStartWood: false

SmoothingSurfaceBlock: 

SmoothingGroundBlock: 

BO3Group: 

IsSpawnPoint: false


#######################################################################
# +-----------------------------------------------------------------+ #
# |                              Blocks                             | #
# +-----------------------------------------------------------------+ #
#######################################################################

Block(3,6,-3,LOG_2)
Block(-4,9,2,LEAVES_2)
Block(3,7,-3,LOG_2)
Block(-4,8,2,LEAVES_2)
Block(3,8,-3,LEAVES_2)
Block(3,9,-3,LEAVES_2)
Block(-6,9,-6,LEAVES_2)
Block(4,10,-3,LEAVES_2)
Block(6,6,1,LEAVES_2)
Block(3,10,-4,LEAVES_2)
Block(1,8,-4,LEAVES_2)
Block(1,9,-4,LEAVES_2)
Block(-3,9,4,LEAVES_2)
Block(2,6,2,LEAVES_2)
Block(-3,10,-2,LEAVES_2)
Block(-1,10,1,LEAVES_2)
Block(-7,9,3,LEAVES_2)
Block(-1,11,1,LEAVES_2)
Block(-5,9,-2,LEAVES_2)
Block(-3,10,2,LEAVES_2)
Block(3,6,0,LEAVES_2)
Block(2,9,-7,LEAVES_2)
Block(-1,9,0,LEAVES_2)
Block(-1,8,0,LEAVES_2)
Block(3,9,0,LEAVES_2)
Block(-4,9,-7,LEAVES_2)
Block(-1,9,-3,LEAVES_2)
Block(-2,11,-3,LEAVES_2)
Block(-2,10,-3,LEAVES_2)
Block(2,10,-5,LEAVES_2)
Block(5,7,4,LEAVES_2)
Block(-3,8,-2,LEAVES_2)
Block(5,6,4,LEAVES_2)
Block(5,9,-3,LEAVES_2)
Block(-3,9,-2,LEAVES_2)
Block(5,5,4,LEAVES_2)
Block(4,6,6,LEAVES_2)
Block(5,8,-3,LEAVES_2)
Block(-1,3,0,LOG_2)
Block(3,8,-2,LEAVES_2)
Block(-4,9,1,LEAVES_2)
Block(3,9,-2,LEAVES_2)
Block(0,9,-1,LEAVES_2)
Block(-3,10,-3,LEAVES_2)
Block(-6,9,-5,LEAVES_2)
Block(6,6,0,LEAVES_2)
Block(-2,10,-4,LEAVES_2)
Block(0,1,-1,LOG_2)
Block(-6,10,-4,LEAVES_2)
Block(0,0,-1,LOG_2)
Block(0,2,-1,LOG_2)
Block(1,9,-3,LEAVES_2)
Block(1,8,-3,LEAVES_2)
Block(4,9,-6,LEAVES_2)
Block(7,9,-3,LEAVES_2)
Block(-3,8,3,LEAVES_2)
Block(2,6,3,LEAVES_2)
Block(-3,9,3,LEAVES_2)
Block(1,10,-1,LEAVES_2)
Block(-5,8,-3,LEAVES_2)
Block(-5,9,-3,LEAVES_2)
Block(3,6,1,LEAVES_2)
Block(-4,10,5,LEAVES_2)
Block(-1,3,-2,LOG_2)
Block(3,4,1,LOG_2)
Block(-1,2,-2,LOG_2)
Block(-2,9,5,LEAVES_2)
Block(4,10,-2,LEAVES_2)
Block(-1,9,-2,LEAVES_2)
Block(-1,8,-2,LEAVES_2)
Block(-4,9,-6,LEAVES_2)
Block(-4,8,-6,LEAVES_2)
Block(3,10,-5,LEAVES_2)
Block(-1,10,-4,LEAVES_2)
Block(-2,10,4,LEAVES_2)
Block(-3,8,-1,LEAVES_2)
Block(5,6,5,LEAVES_2)
Block(-3,9,-1,LEAVES_2)
Block(-5,10,-5,LEAVES_2)
Block(-1,10,2,LEAVES_2)
Block(5,9,-4,LEAVES_2)
Block(-3,11,-3,LEAVES_2)
Block(0,10,-1,LEAVES_2)
Block(-3,11,3,LEAVES_2)
Block(-3,10,3,LEAVES_2)
Block(-4,8,4,LEAVES_2)
Block(3,8,-5,LEAVES_2)
Block(3,9,-5,LEAVES_2)
Block(-4,9,4,LEAVES_2)
Block(-6,9,-4,LEAVES_2)
Block(-2,10,0,LEAVES_2)
Block(-2,9,-5,LEAVES_2)
Block(4,9,-5,LEAVES_2)
Block(2,6,4,LEAVES_2)
Block(1,9,-2,LEAVES_2)
Block(1,6,-2,LOG_2)
Block(1,7,-2,LOG_2)
Block(-2,8,-5,LEAVES_2)
Block(3,6,2,LOG_2)
Block(8,6,3,LEAVES_2)
Block(-4,10,-3,LEAVES_2)
Block(3,5,2,LEAVES_2)
Block(-7,9,-3,LEAVES_2)
Block(-4,9,-1,LEAVES_2)
Block(-3,10,-4,LEAVES_2)
Block(-4,10,3,LEAVES_2)
Block(-1,9,2,LEAVES_2)
Block(-5,10,-4,LEAVES_2)
Block(3,7,2,LEAVES_2)
Block(-1,8,2,LEAVES_2)
Block(4,10,-4,LEAVES_2)
Block(3,11,-3,LEAVES_2)
Block(-2,9,0,LEAVES_2)
Block(3,10,-3,LEAVES_2)
Block(-2,8,0,LOG_2)
Block(-1,9,-5,LEAVES_2)
Block(1,10,-4,LEAVES_2)
Block(4,6,0,LEAVES_2)
Block(-5,9,1,LEAVES_2)
Block(4,9,0,LEAVES_2)
Block(5,6,6,LEAVES_2)
Block(0,8,1,LEAVES_2)
Block(2,9,-1,LEAVES_2)
Block(0,9,1,LEAVES_2)
Block(-1,10,0,LEAVES_2)
Block(-1,11,0,LEAVES_2)
Block(5,9,-5,LEAVES_2)
Block(-4,9,3,LOG_2)
Block(-4,8,3,LOG_2)
Block(-4,7,3,LOG_2)
Block(3,8,-4,LEAVES_2)
Block(-4,10,4,LEAVES_2)
Block(3,9,-4,LEAVES_2)
Block(-6,9,-3,LEAVES_2)
Block(-2,9,-6,LEAVES_2)
Block(4,9,-4,LEAVES_2)
Block(-3,9,5,LEAVES_2)
Block(-5,10,3,LEAVES_2)
Block(7,6,4,LEAVES_2)
Block(1,9,-1,LEAVES_2)
Block(2,10,-4,LEAVES_2)
Block(4,8,-4,LEAVES_2)
Block(1,3,-1,LOG_2)
Block(1,2,-1,LOG_2)
Block(-3,10,4,LEAVES_2)
Block(-5,9,-1,LEAVES_2)
Block(8,6,2,LEAVES_2)
Block(-7,9,-4,LEAVES_2)
Block(-1,8,1,LOG_2)
Block(3,7,3,LEAVES_2)
Block(3,6,3,LEAVES_2)
Block(-1,9,1,LOG_2)
Block(-4,9,-8,LEAVES_2)
Block(-2,10,-5,LEAVES_2)
Block(-1,9,-4,LEAVES_2)
Block(4,6,1,LEAVES_2)
Block(-5,9,2,LEAVES_2)
Block(4,5,1,LEAVES_2)
Block(2,4,-2,LOG_2)
Block(4,7,1,LEAVES_2)
Block(0,9,0,LEAVES_2)
Block(2,5,-2,LOG_2)
Block(-3,9,-7,LEAVES_2)
Block(2,9,-2,LEAVES_2)
Block(-4,10,-4,LEAVES_2)
Block(5,10,-3,LEAVES_2)
Block(-4,11,-4,LEAVES_2)
Block(6,6,5,LEAVES_2)
Block(1,9,0,LEAVES_2)
Block(-4,9,6,LEAVES_2)
Block(-3,10,-5,LEAVES_2)
Block(-5,10,-3,LEAVES_2)
Block(-4,10,2,LEAVES_2)
Block(-6,9,-2,LEAVES_2)
Block(6,9,-2,LEAVES_2)
Block(-5,9,-6,LEAVES_2)
Block(-2,9,-3,LEAVES_2)
Block(1,10,-3,LEAVES_2)
Block(2,10,-2,LEAVES_2)
Block(7,6,3,LEAVES_2)
Block(2,11,-2,LEAVES_2)
Block(4,9,-3,LOG_2)
Block(4,8,-3,LOG_2)
Block(0,9,-4,LEAVES_2)
Block(-3,9,0,LEAVES_2)
Block(0,10,-4,LEAVES_2)
Block(-3,8,0,LEAVES_2)
Block(-2,5,-3,LOG_2)
Block(0,10,1,LEAVES_2)
Block(-2,4,-3,LOG_2)
Block(-4,8,-3,LOG_2)
Block(-7,9,-5,LEAVES_2)
Block(3,7,4,LEAVES_2)
Block(3,6,4,LEAVES_2)
Block(-2,9,2,LEAVES_2)
Block(-2,8,2,LEAVES_2)
Block(-1,9,4,LEAVES_2)
Block(-4,9,-3,LOG_2)
Block(4,5,2,LOG_2)
Block(-5,8,3,LEAVES_2)
Block(-1,10,-2,LEAVES_2)
Block(4,7,2,LEAVES_2)
Block(4,6,2,LEAVES_2)
Block(-5,9,3,LEAVES_2)
Block(4,8,2,LEAVES_2)
Block(5,6,0,LEAVES_2)
Block(-3,9,-6,LEAVES_2)
Block(0,9,3,LEAVES_2)
Block(2,9,-3,LEAVES_2)
Block(2,8,-3,LEAVES_2)
Block(1,9,1,LEAVES_2)
Block(6,6,4,LEAVES_2)
Block(-4,9,5,LEAVES_2)
Block(3,9,-6,LEAVES_2)
Block(3,10,-2,LEAVES_2)
Block(-5,9,-7,LEAVES_2)
Block(-2,10,-1,LEAVES_2)
Block(-1,10,-1,LEAVES_2)
Block(4,8,-2,LEAVES_2)
Block(-2,8,-4,LEAVES_2)
Block(-2,9,-4,LEAVES_2)
Block(4,9,-2,LEAVES_2)
Block(0,9,-5,LEAVES_2)
Block(7,6,2,LEAVES_2)
Block(5,10,-4,LEAVES_2)
Block(-4,10,-5,LEAVES_2)
Block(-4,9,-2,LEAVES_2)
Block(-4,8,-2,LEAVES_2)
Block(-3,10,0,LEAVES_2)
Block(3,6,5,LEAVES_2)
Block(-2,9,1,LEAVES_2)
Block(-2,8,1,LEAVES_2)
Block(-1,9,-6,LEAVES_2)
Block(-1,9,3,LEAVES_2)
Block(-2,7,1,LOG_2)
Block(-6,9,2,LEAVES_2)
Block(-2,10,1,LEAVES_2)
Block(-2,4,1,LOG_2)
Block(-2,11,1,LEAVES_2)
Block(4,6,3,LEAVES_2)
Block(-5,9,4,LEAVES_2)
Block(4,5,3,LEAVES_2)
Block(2,10,-3,LEAVES_2)
Block(-5,10,4,LEAVES_2)
Block(4,7,3,LEAVES_2)
Block(5,7,1,LEAVES_2)
Block(-3,8,-5,LEAVES_2)
Block(0,9,2,LEAVES_2)
Block(5,6,1,LEAVES_2)
Block(-3,9,-5,LEAVES_2)
Block(5,5,1,LEAVES_2)
Block(0,10,0,LEAVES_2)
Block(2,9,-4,LOG_2)
Block(2,8,-4,LOG_2)
Block(3,9,-1,LEAVES_2)
Block(-4,9,0,LEAVES_2)
Block(1,9,2,LEAVES_2)
Block(0,8,-2,LOG_2)
Block(6,7,3,LEAVES_2)
Block(1,6,2,LEAVES_2)
Block(0,9,-2,LOG_2)
Block(6,6,3,LEAVES_2)
Block(6,5,3,LEAVES_2)
Block(6,9,-4,LEAVES_2)
Block(-2,10,-2,LEAVES_2)
Block(1,9,-6,LEAVES_2)
Block(-1,10,-3,LEAVES_2)
Block(-2,10,3,LEAVES_2)
Block(-5,9,-4,LEAVES_2)
Block(-2,9,-1,LOG_2)
Block(4,9,-1,LEAVES_2)
Block(-3,9,2,LEAVES_2)
Block(-3,8,2,LEAVES_2)
Block(2,9,0,LEAVES_2)
Block(-3,5,2,LOG_2)
Block(4,6,-1,LEAVES_2)
Block(-3,6,2,LOG_2)
Block(-2,8,-1,LEAVES_2)
Block(7,6,1,LEAVES_2)
Block(-5,8,-4,LEAVES_2)
Block(-2,9,4,LEAVES_2)
Block(1,10,0,LEAVES_2)
Block(-6,9,3,LEAVES_2)
Block(-4,8,-5,LOG_2)
Block(-1,9,-1,LEAVES_2)
Block(-1,8,-1,LEAVES_2)
Block(-4,9,-5,LOG_2)
Block(2,10,-1,LEAVES_2)
Block(4,7,4,LEAVES_2)
Block(-3,6,-4,LOG_2)
Block(5,6,-1,LEAVES_2)
Block(4,6,4,LEAVES_2)
Block(-5,9,5,LEAVES_2)
Block(-3,7,-4,LOG_2)
Block(5,7,2,LEAVES_2)
Block(-3,8,-4,LEAVES_2)
Block(-3,10,-1,LEAVES_2)
Block(0,10,2,LEAVES_2)
Block(5,6,2,LEAVES_2)
Block(-3,9,-4,LEAVES_2)
Block(5,9,-1,LEAVES_2)
Block(5,5,2,LEAVES_2)
Block(0,10,-3,LEAVES_2)
Block(2,9,-5,LEAVES_2)
Block(-4,10,-6,LEAVES_2)
Block(2,8,-5,LEAVES_2)
Block(-4,10,-2,LEAVES_2)
Block(-3,10,1,LEAVES_2)
Block(1,6,3,LEAVES_2)
Block(0,9,-3,LEAVES_2)
Block(0,8,-3,LEAVES_2)
Block(6,7,2,LEAVES_2)
Block(6,6,2,LEAVES_2)
Block(1,9,-5,LEAVES_2)
Block(-2,10,2,LEAVES_2)
Block(6,9,-3,LEAVES_2)
Block(-2,11,2,LEAVES_2)
Block(1,8,-5,LEAVES_2)
Block(2,9,1,LEAVES_2)
Block(-5,8,-5,LEAVES_2)
Block(-2,9,-2,LEAVES_2)
Block(-2,8,-2,LEAVES_2)
Block(-5,9,-5,LEAVES_2)
Block(2,6,1,LEAVES_2)
Block(-3,9,1,LEAVES_2)
Block(-1,10,3,LEAVES_2)
Block(-3,8,1,LEAVES_2)
Block(0,10,-2,LEAVES_2)
Block(2,9,-6,LEAVES_2)
Block(-2,9,3,LEAVES_2)
Block(-6,9,4,LEAVES_2)
Block(3,10,-1,LEAVES_2)
Block(2,4,0,LOG_2)
Block(-4,9,-4,LEAVES_2)
Block(-4,8,-4,LEAVES_2)
Block(1,10,-2,LEAVES_2)
Block(1,11,-2,LEAVES_2)
Block(4,6,5,LEAVES_2)
Block(5,8,3,LEAVES_2)
Block(5,7,3,LEAVES_2)
Block(-3,8,-3,LEAVES_2)
Block(5,6,3,LOG_2)
Block(-3,9,-3,LEAVES_2)
Block(5,5,3,LEAVES_2)
Block(5,9,-2,LEAVES_2)

#######################################################################
# +-----------------------------------------------------------------+ #
# |                            BO3 checks                           | #
# +-----------------------------------------------------------------+ #
#######################################################################

BlockCheck(0,-1,-1,GRASS,DIRT,DIRT:2)

#######################################################################
# +-----------------------------------------------------------------+ #
# |                             Branches                            | #
# +-----------------------------------------------------------------+ #
#######################################################################


#######################################################################
# +-----------------------------------------------------------------+ #
# |                             Entities                            | #
# +-----------------------------------------------------------------+ #
#######################################################################


#######################################################################
# +-----------------------------------------------------------------+ #
# |                            Particles                            | #
# +-----------------------------------------------------------------+ #
#######################################################################


#######################################################################
# +-----------------------------------------------------------------+ #
# |                             Spawners                            | #
# +-----------------------------------------------------------------+ #
#######################################################################


#######################################################################
# +-----------------------------------------------------------------+ #
# |                             ModData                             | #
# +-----------------------------------------------------------------+ #
#######################################################################

