
#######################################################################
# +-----------------------------------------------------------------+ #
# |                            BO3 object                           | #
# +-----------------------------------------------------------------+ #
#######################################################################

# This is the config file of a custom object.
# If you add this object correctly to your BiomeConfigs, it will spawn in the world.

# This is the creator of this BO3 object
Author: LordSmellyPants

# A short description of this BO3 object
Description: No description given

# The BO3 version, don't change this! It can be used by external applications to do a version check.
Version: 3

# The settings mode, WriteAll, WriteWithoutComments or WriteDisable. See WorldConfig.
SettingsMode: WriteDisable


#######################################################################
# +-----------------------------------------------------------------+ #
# |                          Main settings                          | #
# +-----------------------------------------------------------------+ #
#######################################################################

# This needs to be set to true to spawn the object in the Tree and Sapling resources.
Tree: false

# The frequency of the BO3 from 1 to 200. Tries this many times to spawn this BO3 when using the CustomObject(...) resource.
# Ignored by Tree(..), Sapling(..) and CustomStructure(..)
Frequency: 1

# The rarity of the BO3 from 0 to 100. Each spawn attempt has rarity% chance to succeed when using the CustomObject(...) resource.
# Ignored by Tree(..), Sapling(..) and CustomStructure(..)
Rarity: 5.0

# If you set this to true, the BO3 will be placed with a random rotation.
RotateRandomly: false

# The spawn height of the BO3 - randomY, highestBlock or highestSolidBlock.
SpawnHeight: highestSolidBlock

# The height limits for the BO3.
MinHeight: 0

MaxHeight: 80

# Objects can have other objects attacthed to it: branches. Branches can also
# have branches attached to it, which can also have branches, etc. This is the
# maximum branch depth for this objects.
MaxBranchDepth: 10

# When spawned with the UseWorld keyword, this BO3 should NOT spawn in the following biomes.
# If you writer.write the BO3 name directly in the BiomeConfigs, this will be ignored.
ExcludedBiomes: All


#######################################################################
# +-----------------------------------------------------------------+ #
# |                      Source block settings                      | #
# +-----------------------------------------------------------------+ #
#######################################################################

# The block(s) the BO3 should spawn in.
SourceBlocks: AIR

# The maximum percentage of the BO3 that can be outside the SourceBlock.
# The BO3 won't be placed on a location with more blocks outside the SourceBlock than this percentage.
MaxPercentageOutsideSourceBlock: 100

# What to do when a block is about to be placed outside the SourceBlock? (dontPlace, placeAnyway)
OutsideSourceBlock: placeAnyway


#######################################################################
# +-----------------------------------------------------------------+ #
# |                              Blocks                             | #
# +-----------------------------------------------------------------+ #
#######################################################################

# All the blocks used in the BO3 are listed here. Possible blocks:
# Block(x,y,z,id[.data][,nbtfile.nbt)
# RandomBlock(x,y,z,id[:data][,nbtfile.nbt],chance[,id[:data][,nbtfile.nbt],chance[,...]])
# So RandomBlock(0,0,0,CHEST,chest.nbt,50,CHEST,anotherchest.nbt,100) will spawn a chest at
# the BO3 origin, and give it a 50% chance to have the contents of chest.nbt, or, if that
# fails, a 100% percent chance to have the contents of anotherchest.nbt.
Block(-10,-13,-9,SANDSTONE)
Block(-10,-13,-8,SANDSTONE)
Block(-10,-13,-7,SANDSTONE)
Block(-10,-13,-6,SANDSTONE)
Block(-10,-13,-5,SANDSTONE)
Block(-10,-13,-4,SANDSTONE)
Block(-10,-13,-3,SANDSTONE)
Block(-10,-13,-2,SANDSTONE)
Block(-10,-13,-1,SANDSTONE)
Block(-10,-13,0,SANDSTONE)
Block(-10,-13,1,SANDSTONE)
Block(-10,-13,2,SANDSTONE)
Block(-10,-13,3,SANDSTONE)
Block(-10,-13,4,SANDSTONE)
Block(-10,-13,5,SANDSTONE)
Block(-10,-13,6,SANDSTONE)
Block(-10,-13,7,SANDSTONE)
Block(-10,-13,8,SANDSTONE)
Block(-10,-13,9,SANDSTONE)
Block(-10,-13,10,SANDSTONE)
Block(-10,-13,11,SANDSTONE)
Block(-10,-12,-9,SANDSTONE)
Block(-10,-12,-8,SANDSTONE)
Block(-10,-12,-7,SANDSTONE)
Block(-10,-12,-6,SANDSTONE)
Block(-10,-12,-5,SANDSTONE)
Block(-10,-12,-4,SANDSTONE)
Block(-10,-12,-3,SANDSTONE)
Block(-10,-12,-2,SANDSTONE)
Block(-10,-12,-1,SANDSTONE)
Block(-10,-12,0,SANDSTONE)
Block(-10,-12,1,SANDSTONE)
Block(-10,-12,2,SANDSTONE)
Block(-10,-12,3,SANDSTONE)
Block(-10,-12,4,SANDSTONE)
Block(-10,-12,5,SANDSTONE)
Block(-10,-12,6,SANDSTONE)
Block(-10,-12,7,SANDSTONE)
Block(-10,-12,8,SANDSTONE)
Block(-10,-12,9,SANDSTONE)
Block(-10,-12,10,SANDSTONE)
Block(-10,-12,11,SANDSTONE)
Block(-10,-11,-9,SANDSTONE)
Block(-10,-11,-8,SANDSTONE)
Block(-10,-11,-7,SANDSTONE)
Block(-10,-11,-6,SANDSTONE)
Block(-10,-11,-5,SANDSTONE)
Block(-10,-11,-4,SANDSTONE)
Block(-10,-11,-3,SANDSTONE)
Block(-10,-11,-2,SANDSTONE)
Block(-10,-11,-1,SANDSTONE)
Block(-10,-11,0,SANDSTONE)
Block(-10,-11,1,SANDSTONE)
Block(-10,-11,2,SANDSTONE)
Block(-10,-11,3,SANDSTONE)
Block(-10,-11,4,SANDSTONE)
Block(-10,-11,5,SANDSTONE)
Block(-10,-11,6,SANDSTONE)
Block(-10,-11,7,SANDSTONE)
Block(-10,-11,8,SANDSTONE)
Block(-10,-11,9,SANDSTONE)
Block(-10,-11,10,SANDSTONE)
Block(-10,-11,11,SANDSTONE)
Block(-10,-10,-9,SANDSTONE)
Block(-10,-10,-8,SANDSTONE)
Block(-10,-10,-7,SANDSTONE)
Block(-10,-10,-6,SANDSTONE)
Block(-10,-10,-5,SANDSTONE)
Block(-10,-10,-4,SANDSTONE)
Block(-10,-10,-3,SANDSTONE)
Block(-10,-10,-2,SANDSTONE)
Block(-10,-10,-1,SANDSTONE)
Block(-10,-10,0,SANDSTONE)
Block(-10,-10,1,SANDSTONE)
Block(-10,-10,2,SANDSTONE)
Block(-10,-10,3,SANDSTONE)
Block(-10,-10,4,SANDSTONE)
Block(-10,-10,5,SANDSTONE)
Block(-10,-10,6,SANDSTONE)
Block(-10,-10,7,SANDSTONE)
Block(-10,-10,8,SANDSTONE)
Block(-10,-10,9,SANDSTONE)
Block(-10,-10,10,SANDSTONE)
Block(-10,-10,11,SANDSTONE)
Block(-10,-9,-9,SANDSTONE)
Block(-10,-9,-8,SANDSTONE)
Block(-10,-9,-7,SANDSTONE)
Block(-10,-9,-6,SANDSTONE)
Block(-10,-9,-5,SANDSTONE)
Block(-10,-9,-4,SANDSTONE)
Block(-10,-9,-3,SANDSTONE)
Block(-10,-9,-2,SANDSTONE)
Block(-10,-9,-1,SANDSTONE)
Block(-10,-9,0,SANDSTONE)
Block(-10,-9,1,SANDSTONE)
Block(-10,-9,2,SANDSTONE)
Block(-10,-9,3,SANDSTONE)
Block(-10,-9,4,SANDSTONE)
Block(-10,-9,5,SANDSTONE)
Block(-10,-9,6,SANDSTONE)
Block(-10,-9,7,SANDSTONE)
Block(-10,-9,8,SANDSTONE)
Block(-10,-9,9,SANDSTONE)
Block(-10,-9,10,SANDSTONE)
Block(-10,-9,11,SANDSTONE)
Block(-10,-8,-9,SANDSTONE)
Block(-10,-8,-8,SANDSTONE)
Block(-10,-8,-7,SANDSTONE)
Block(-10,-8,-6,SANDSTONE)
Block(-10,-8,-5,SANDSTONE)
Block(-10,-8,-4,SANDSTONE)
Block(-10,-8,-3,SANDSTONE)
Block(-10,-8,-2,SANDSTONE)
Block(-10,-8,-1,SANDSTONE)
Block(-10,-8,0,SANDSTONE)
Block(-10,-8,1,SANDSTONE)
Block(-10,-8,2,SANDSTONE)
Block(-10,-8,3,SANDSTONE)
Block(-10,-8,4,SANDSTONE)
Block(-10,-8,5,SANDSTONE)
Block(-10,-8,6,SANDSTONE)
Block(-10,-8,7,SANDSTONE)
Block(-10,-8,8,SANDSTONE)
Block(-10,-8,9,SANDSTONE)
Block(-10,-8,10,SANDSTONE)
Block(-10,-8,11,SANDSTONE)
Block(-10,-7,-9,SANDSTONE)
Block(-10,-7,-8,SANDSTONE)
Block(-10,-7,-7,SANDSTONE)
Block(-10,-7,-6,SANDSTONE)
Block(-10,-7,-5,SANDSTONE)
Block(-10,-7,-4,SANDSTONE)
Block(-10,-7,-3,SANDSTONE)
Block(-10,-7,-2,SANDSTONE)
Block(-10,-7,-1,SANDSTONE)
Block(-10,-7,0,SANDSTONE)
Block(-10,-7,1,SANDSTONE)
Block(-10,-7,2,SANDSTONE)
Block(-10,-7,3,SANDSTONE)
Block(-10,-7,4,SANDSTONE)
Block(-10,-7,5,SANDSTONE)
Block(-10,-7,6,SANDSTONE)
Block(-10,-7,7,SANDSTONE)
Block(-10,-7,8,SANDSTONE)
Block(-10,-7,9,SANDSTONE)
Block(-10,-7,10,SANDSTONE)
Block(-10,-7,11,SANDSTONE)
Block(-10,-6,-9,SANDSTONE)
Block(-10,-6,-8,SANDSTONE)
Block(-10,-6,-7,SANDSTONE)
Block(-10,-6,-6,SANDSTONE)
Block(-10,-6,-5,SANDSTONE)
Block(-10,-6,-4,SANDSTONE)
Block(-10,-6,-3,SANDSTONE)
Block(-10,-6,-2,SANDSTONE)
Block(-10,-6,-1,SANDSTONE)
Block(-10,-6,0,SANDSTONE)
Block(-10,-6,1,SANDSTONE)
Block(-10,-6,2,SANDSTONE)
Block(-10,-6,3,SANDSTONE)
Block(-10,-6,4,SANDSTONE)
Block(-10,-6,5,SANDSTONE)
Block(-10,-6,6,SANDSTONE)
Block(-10,-6,7,SANDSTONE)
Block(-10,-6,8,SANDSTONE)
Block(-10,-6,9,SANDSTONE)
Block(-10,-6,10,SANDSTONE)
Block(-10,-6,11,SANDSTONE)
Block(-10,-5,-9,SANDSTONE)
Block(-10,-5,-8,SANDSTONE)
Block(-10,-5,-7,SANDSTONE)
Block(-10,-5,-6,SANDSTONE)
Block(-10,-5,-5,SANDSTONE)
Block(-10,-5,-4,SANDSTONE)
Block(-10,-5,-3,SANDSTONE)
Block(-10,-5,-2,SANDSTONE)
Block(-10,-5,-1,SANDSTONE)
Block(-10,-5,0,SANDSTONE)
Block(-10,-5,1,SANDSTONE)
Block(-10,-5,2,SANDSTONE)
Block(-10,-5,3,SANDSTONE)
Block(-10,-5,4,SANDSTONE)
Block(-10,-5,5,SANDSTONE)
Block(-10,-5,6,SANDSTONE)
Block(-10,-5,7,SANDSTONE)
Block(-10,-5,8,SANDSTONE)
Block(-10,-5,9,SANDSTONE)
Block(-10,-5,10,SANDSTONE)
Block(-10,-5,11,SANDSTONE)
Block(-10,-4,-9,SANDSTONE)
Block(-10,-4,-8,SANDSTONE)
Block(-10,-4,-7,SANDSTONE)
Block(-10,-4,-6,SANDSTONE)
Block(-10,-4,-5,SANDSTONE)
Block(-10,-4,-4,SANDSTONE)
Block(-10,-4,-3,SANDSTONE)
Block(-10,-4,-2,SANDSTONE)
Block(-10,-4,-1,SANDSTONE)
Block(-10,-4,0,SANDSTONE)
Block(-10,-4,1,SANDSTONE)
Block(-10,-4,2,SANDSTONE)
Block(-10,-4,3,SANDSTONE)
Block(-10,-4,4,SANDSTONE)
Block(-10,-4,5,SANDSTONE)
Block(-10,-4,6,SANDSTONE)
Block(-10,-4,7,SANDSTONE)
Block(-10,-4,8,SANDSTONE)
Block(-10,-4,9,SANDSTONE)
Block(-10,-4,10,SANDSTONE)
Block(-10,-4,11,SANDSTONE)
Block(-10,-3,-9,SANDSTONE)
Block(-10,-3,-8,SANDSTONE)
Block(-10,-3,-7,SANDSTONE)
Block(-10,-3,-6,SANDSTONE)
Block(-10,-3,-5,SANDSTONE)
Block(-10,-3,-4,SANDSTONE)
Block(-10,-3,-3,SANDSTONE)
Block(-10,-3,-2,SANDSTONE)
Block(-10,-3,-1,SANDSTONE)
Block(-10,-3,0,SANDSTONE)
Block(-10,-3,1,SANDSTONE)
Block(-10,-3,2,SANDSTONE)
Block(-10,-3,3,SANDSTONE)
Block(-10,-3,4,SANDSTONE)
Block(-10,-3,5,SANDSTONE)
Block(-10,-3,6,SANDSTONE)
Block(-10,-3,7,SANDSTONE)
Block(-10,-3,8,SANDSTONE)
Block(-10,-3,9,SANDSTONE)
Block(-10,-3,10,SANDSTONE)
Block(-10,-3,11,SANDSTONE)
Block(-10,-2,-9,SANDSTONE)
Block(-10,-2,-8,SANDSTONE)
Block(-10,-2,-7,SANDSTONE)
Block(-10,-2,-6,SANDSTONE)
Block(-10,-2,-5,SANDSTONE)
Block(-10,-2,-4,SANDSTONE)
Block(-10,-2,-3,SANDSTONE)
Block(-10,-2,-2,SANDSTONE)
Block(-10,-2,-1,SANDSTONE)
Block(-10,-2,0,SANDSTONE)
Block(-10,-2,1,SANDSTONE)
Block(-10,-2,2,SANDSTONE)
Block(-10,-2,3,SANDSTONE)
Block(-10,-2,4,SANDSTONE)
Block(-10,-2,5,SANDSTONE)
Block(-10,-2,6,SANDSTONE)
Block(-10,-2,7,SANDSTONE)
Block(-10,-2,8,SANDSTONE)
Block(-10,-2,9,SANDSTONE)
Block(-10,-2,10,SANDSTONE)
Block(-10,-2,11,SANDSTONE)
Block(-10,-1,-9,SANDSTONE)
Block(-10,-1,-8,SANDSTONE)
Block(-10,-1,-7,SANDSTONE)
Block(-10,-1,-6,SANDSTONE)
Block(-10,-1,-5,SANDSTONE)
Block(-10,-1,-4,SANDSTONE)
Block(-10,-1,-3,SANDSTONE)
Block(-10,-1,-2,SANDSTONE)
Block(-10,-1,-1,SANDSTONE)
Block(-10,-1,0,SANDSTONE)
Block(-10,-1,1,SANDSTONE)
Block(-10,-1,2,SANDSTONE)
Block(-10,-1,3,SANDSTONE)
Block(-10,-1,4,SANDSTONE)
Block(-10,-1,5,SANDSTONE)
Block(-10,-1,6,SANDSTONE)
Block(-10,-1,7,SANDSTONE)
Block(-10,-1,8,SANDSTONE)
Block(-10,-1,9,SANDSTONE)
Block(-10,-1,10,SANDSTONE)
Block(-10,-1,11,SANDSTONE)
Block(-10,0,-9,SANDSTONE)
Block(-10,0,-8,SANDSTONE)
Block(-10,0,-7,SANDSTONE)
Block(-10,0,-6,SANDSTONE)
Block(-10,0,-5,SANDSTONE)
Block(-10,0,-4,SANDSTONE)
Block(-10,0,-3,SANDSTONE)
Block(-10,0,-2,SANDSTONE)
Block(-10,0,-1,SANDSTONE)
Block(-10,0,0,SANDSTONE)
Block(-10,0,1,SANDSTONE)
Block(-10,0,2,SANDSTONE)
Block(-10,0,3,SANDSTONE)
Block(-10,0,4,SANDSTONE)
Block(-10,0,5,SANDSTONE)
Block(-10,0,6,SANDSTONE)
Block(-10,0,7,SANDSTONE)
Block(-10,0,8,SANDSTONE)
Block(-10,0,9,SANDSTONE)
Block(-10,0,10,SANDSTONE)
Block(-10,0,11,SANDSTONE)
Block(-10,1,-9,SANDSTONE)
Block(-10,1,-8,SANDSTONE:2)
Block(-10,1,-7,WOOL:7)
Block(-10,1,-6,SANDSTONE:2)
Block(-10,1,-5,SANDSTONE)
Block(-10,1,-4,AIR)
RandomBlock(-10,1,-3,SAND,44,AIR,100)
Block(-10,1,-2,AIR)
RandomBlock(-10,1,-1,SAND,44,AIR,100)
Block(-10,1,0,AIR)
Block(-10,1,1,AIR)
Block(-10,1,2,AIR)
RandomBlock(-10,1,3,SAND,44,AIR,100)
Block(-10,1,4,AIR)
Block(-10,1,5,AIR)
Block(-10,1,6,AIR)
Block(-10,1,7,AIR)
RandomBlock(-10,1,8,SAND,44,AIR,100)
Block(-10,1,9,AIR)
Block(-10,1,10,AIR)
Block(-10,1,11,AIR)
Block(-10,2,-9,SANDSTONE)
Block(-10,2,-8,SANDSTONE:2)
Block(-10,2,-7,WOOL:7)
Block(-10,2,-6,SANDSTONE:2)
Block(-10,2,-5,SANDSTONE)
Block(-10,2,-4,AIR)
Block(-10,2,-3,AIR)
Block(-10,2,-2,AIR)
Block(-10,2,-1,AIR)
Block(-10,2,0,AIR)
Block(-10,2,1,AIR)
Block(-10,2,2,AIR)
Block(-10,2,3,AIR)
Block(-10,2,4,AIR)
Block(-10,2,5,AIR)
Block(-10,2,6,AIR)
Block(-10,2,7,AIR)
Block(-10,2,8,AIR)
Block(-10,2,9,AIR)
Block(-10,2,10,AIR)
Block(-10,2,11,AIR)
Block(-10,3,-9,SANDSTONE)
Block(-10,3,-8,SANDSTONE:2)
Block(-10,3,-7,WOOL:7)
Block(-10,3,-6,SANDSTONE:2)
Block(-10,3,-5,SANDSTONE)
Block(-10,3,-4,AIR)
Block(-10,3,-3,AIR)
Block(-10,3,-2,AIR)
Block(-10,3,-1,AIR)
Block(-10,3,0,AIR)
Block(-10,3,1,AIR)
Block(-10,3,2,AIR)
Block(-10,3,3,AIR)
Block(-10,3,4,AIR)
Block(-10,3,5,AIR)
Block(-10,3,6,AIR)
Block(-10,3,7,AIR)
Block(-10,3,8,AIR)
Block(-10,3,9,AIR)
Block(-10,3,10,AIR)
Block(-10,3,11,AIR)
Block(-10,4,-9,SANDSTONE)
Block(-10,4,-8,WOOL:7)
Block(-10,4,-7,SANDSTONE:1)
Block(-10,4,-6,WOOL:7)
Block(-10,4,-5,SANDSTONE)
Block(-10,4,-4,AIR)
Block(-10,4,-3,AIR)
Block(-10,4,-2,AIR)
Block(-10,4,-1,AIR)
Block(-10,4,0,AIR)
Block(-10,4,1,AIR)
Block(-10,4,2,AIR)
Block(-10,4,3,AIR)
Block(-10,4,4,AIR)
Block(-10,4,5,AIR)
Block(-10,4,6,AIR)
Block(-10,4,7,AIR)
Block(-10,4,8,AIR)
Block(-10,4,9,AIR)
Block(-10,4,10,AIR)
Block(-10,4,11,AIR)
Block(-10,5,-9,SANDSTONE)
Block(-10,5,-8,SANDSTONE:2)
Block(-10,5,-7,WOOL:7)
Block(-10,5,-6,SANDSTONE:2)
Block(-10,5,-5,SANDSTONE)
Block(-10,5,-4,AIR)
Block(-10,5,-3,AIR)
Block(-10,5,-2,AIR)
Block(-10,5,-1,AIR)
Block(-10,5,0,AIR)
Block(-10,5,1,AIR)
Block(-10,5,2,AIR)
Block(-10,5,3,AIR)
Block(-10,5,4,AIR)
Block(-10,5,5,AIR)
Block(-10,5,6,AIR)
Block(-10,5,7,AIR)
Block(-10,5,8,AIR)
Block(-10,5,9,AIR)
Block(-10,5,10,AIR)
Block(-10,5,11,AIR)
Block(-10,6,-9,SANDSTONE)
Block(-10,6,-8,WOOL:7)
Block(-10,6,-7,SANDSTONE:1)
Block(-10,6,-6,WOOL:7)
Block(-10,6,-5,SANDSTONE)
Block(-10,6,-4,AIR)
Block(-10,6,-3,AIR)
Block(-10,6,-2,AIR)
Block(-10,6,-1,AIR)
Block(-10,6,0,AIR)
Block(-10,6,1,AIR)
Block(-10,6,2,AIR)
Block(-10,6,3,AIR)
Block(-10,6,4,AIR)
Block(-10,6,5,AIR)
Block(-10,6,6,AIR)
Block(-10,6,7,AIR)
Block(-10,6,8,AIR)
Block(-10,6,9,AIR)
Block(-10,6,10,AIR)
Block(-10,6,11,AIR)
Block(-10,7,-9,SANDSTONE)
Block(-10,7,-8,WOOL:7)
Block(-10,7,-7,WOOL:7)
Block(-10,7,-6,WOOL:7)
Block(-10,7,-5,SANDSTONE)
Block(-10,7,-4,AIR)
Block(-10,7,-3,AIR)
Block(-10,7,-2,AIR)
Block(-10,7,-1,AIR)
Block(-10,7,0,AIR)
Block(-10,7,1,AIR)
Block(-10,7,2,AIR)
Block(-10,7,3,AIR)
Block(-10,7,4,AIR)
Block(-10,7,5,AIR)
Block(-10,7,6,AIR)
Block(-10,7,7,AIR)
Block(-10,7,8,AIR)
Block(-10,7,9,AIR)
Block(-10,7,10,AIR)
Block(-10,7,11,AIR)
Block(-10,8,-9,SANDSTONE)
Block(-10,8,-8,SANDSTONE)
Block(-10,8,-7,SANDSTONE)
Block(-10,8,-6,SANDSTONE)
Block(-10,8,-5,SANDSTONE)
Block(-10,8,-4,AIR)
Block(-10,8,-3,AIR)
Block(-10,8,-2,AIR)
Block(-10,8,-1,AIR)
Block(-10,8,0,AIR)
Block(-10,8,1,AIR)
Block(-10,8,2,AIR)
Block(-10,8,3,AIR)
Block(-10,8,4,AIR)
Block(-10,8,5,AIR)
Block(-10,8,6,AIR)
Block(-10,8,7,AIR)
Block(-10,8,8,AIR)
Block(-10,8,9,AIR)
Block(-10,8,10,AIR)
Block(-10,8,11,AIR)
Block(-10,9,-9,AIR)
Block(-10,9,-8,AIR)
Block(-10,9,-7,SANDSTONE_STAIRS:0)
RandomBlock(-10,9,-6,SAND,44,AIR,100)
Block(-10,9,-5,AIR)
Block(-10,9,-4,AIR)
Block(-10,9,-3,AIR)
Block(-10,9,-2,AIR)
Block(-10,9,-1,AIR)
Block(-10,9,0,AIR)
Block(-10,9,1,AIR)
Block(-10,9,2,AIR)
Block(-10,9,3,AIR)
Block(-10,9,4,AIR)
Block(-10,9,5,AIR)
Block(-10,9,6,AIR)
Block(-10,9,7,AIR)
Block(-10,9,8,AIR)
Block(-10,9,9,AIR)
Block(-10,9,10,AIR)
Block(-10,9,11,AIR)
Block(-10,10,-9,AIR)
Block(-10,10,-8,AIR)
Block(-10,10,-7,AIR)
Block(-10,10,-6,AIR)
Block(-10,10,-5,AIR)
Block(-10,10,-4,AIR)
Block(-10,10,-3,AIR)
Block(-10,10,-2,AIR)
Block(-10,10,-1,AIR)
Block(-10,10,0,AIR)
Block(-10,10,1,AIR)
Block(-10,10,2,AIR)
Block(-10,10,3,AIR)
Block(-10,10,4,AIR)
Block(-10,10,5,AIR)
Block(-10,10,6,AIR)
Block(-10,10,7,AIR)
Block(-10,10,8,AIR)
Block(-10,10,9,AIR)
Block(-10,10,10,AIR)
Block(-10,10,11,AIR)
Block(-9,-13,-9,SANDSTONE)
Block(-9,-13,-8,SANDSTONE)
Block(-9,-13,-7,SANDSTONE)
Block(-9,-13,-6,SANDSTONE)
Block(-9,-13,-5,SANDSTONE)
Block(-9,-13,-4,SANDSTONE)
Block(-9,-13,-3,SANDSTONE)
Block(-9,-13,-2,SANDSTONE)
Block(-9,-13,-1,SANDSTONE)
Block(-9,-13,0,SANDSTONE)
Block(-9,-13,1,SANDSTONE)
Block(-9,-13,2,SANDSTONE)
Block(-9,-13,3,SANDSTONE)
Block(-9,-13,4,SANDSTONE)
Block(-9,-13,5,SANDSTONE)
Block(-9,-13,6,SANDSTONE)
Block(-9,-13,7,SANDSTONE)
Block(-9,-13,8,SANDSTONE)
Block(-9,-13,9,SANDSTONE)
Block(-9,-13,10,SANDSTONE)
Block(-9,-13,11,SANDSTONE)
Block(-9,-12,-9,SANDSTONE)
Block(-9,-12,-8,SANDSTONE)
Block(-9,-12,-7,SANDSTONE)
Block(-9,-12,-6,SANDSTONE)
Block(-9,-12,-5,SANDSTONE)
Block(-9,-12,-4,SANDSTONE)
Block(-9,-12,-3,SANDSTONE)
Block(-9,-12,-2,SANDSTONE)
Block(-9,-12,-1,SANDSTONE)
Block(-9,-12,0,SANDSTONE)
Block(-9,-12,1,SANDSTONE)
Block(-9,-12,2,SANDSTONE)
Block(-9,-12,3,SANDSTONE)
Block(-9,-12,4,SANDSTONE)
Block(-9,-12,5,SANDSTONE)
Block(-9,-12,6,SANDSTONE)
Block(-9,-12,7,SANDSTONE)
Block(-9,-12,8,SANDSTONE)
Block(-9,-12,9,SANDSTONE)
Block(-9,-12,10,SANDSTONE)
Block(-9,-12,11,SANDSTONE)
Block(-9,-11,-9,SANDSTONE)
Block(-9,-11,-8,SANDSTONE)
Block(-9,-11,-7,SANDSTONE)
Block(-9,-11,-6,SANDSTONE)
Block(-9,-11,-5,SANDSTONE)
Block(-9,-11,-4,SANDSTONE)
Block(-9,-11,-3,SANDSTONE)
Block(-9,-11,-2,SANDSTONE)
Block(-9,-11,-1,SANDSTONE)
Block(-9,-11,0,SANDSTONE)
Block(-9,-11,1,SANDSTONE)
Block(-9,-11,2,SANDSTONE)
Block(-9,-11,3,SANDSTONE)
Block(-9,-11,4,SANDSTONE)
Block(-9,-11,5,SANDSTONE)
Block(-9,-11,6,SANDSTONE)
Block(-9,-11,7,SANDSTONE)
Block(-9,-11,8,SANDSTONE)
Block(-9,-11,9,SANDSTONE)
Block(-9,-11,10,SANDSTONE)
Block(-9,-11,11,SANDSTONE)
Block(-9,-10,-9,SANDSTONE)
Block(-9,-10,-8,SANDSTONE)
Block(-9,-10,-7,SANDSTONE)
Block(-9,-10,-6,SANDSTONE)
Block(-9,-10,-5,SANDSTONE)
Block(-9,-10,-4,SANDSTONE)
Block(-9,-10,-3,SANDSTONE)
Block(-9,-10,-2,SANDSTONE)
Block(-9,-10,-1,SANDSTONE)
Block(-9,-10,0,SANDSTONE)
Block(-9,-10,1,SANDSTONE)
Block(-9,-10,2,SANDSTONE)
Block(-9,-10,3,SANDSTONE)
Block(-9,-10,4,SANDSTONE)
Block(-9,-10,5,SANDSTONE)
Block(-9,-10,6,SANDSTONE)
Block(-9,-10,7,SANDSTONE)
Block(-9,-10,8,SANDSTONE)
Block(-9,-10,9,SANDSTONE)
Block(-9,-10,10,SANDSTONE)
Block(-9,-10,11,SANDSTONE)
Block(-9,-9,-9,SANDSTONE)
Block(-9,-9,-8,SANDSTONE)
Block(-9,-9,-7,SANDSTONE)
Block(-9,-9,-6,SANDSTONE)
Block(-9,-9,-5,SANDSTONE)
Block(-9,-9,-4,SANDSTONE)
Block(-9,-9,-3,SANDSTONE)
Block(-9,-9,-2,SANDSTONE)
Block(-9,-9,-1,SANDSTONE)
Block(-9,-9,0,SANDSTONE)
Block(-9,-9,1,SANDSTONE)
Block(-9,-9,2,SANDSTONE)
Block(-9,-9,3,SANDSTONE)
Block(-9,-9,4,SANDSTONE)
Block(-9,-9,5,SANDSTONE)
Block(-9,-9,6,SANDSTONE)
Block(-9,-9,7,SANDSTONE)
Block(-9,-9,8,SANDSTONE)
Block(-9,-9,9,SANDSTONE)
Block(-9,-9,10,SANDSTONE)
Block(-9,-9,11,SANDSTONE)
Block(-9,-8,-9,SANDSTONE)
Block(-9,-8,-8,SANDSTONE)
Block(-9,-8,-7,SANDSTONE)
Block(-9,-8,-6,SANDSTONE)
Block(-9,-8,-5,SANDSTONE)
Block(-9,-8,-4,SANDSTONE)
Block(-9,-8,-3,SANDSTONE)
Block(-9,-8,-2,SANDSTONE)
Block(-9,-8,-1,SANDSTONE)
Block(-9,-8,0,SANDSTONE)
Block(-9,-8,1,SANDSTONE)
Block(-9,-8,2,SANDSTONE)
Block(-9,-8,3,SANDSTONE)
Block(-9,-8,4,SANDSTONE)
Block(-9,-8,5,SANDSTONE)
Block(-9,-8,6,SANDSTONE)
Block(-9,-8,7,SANDSTONE)
Block(-9,-8,8,SANDSTONE)
Block(-9,-8,9,SANDSTONE)
Block(-9,-8,10,SANDSTONE)
Block(-9,-8,11,SANDSTONE)
Block(-9,-7,-9,SANDSTONE)
Block(-9,-7,-8,SANDSTONE)
Block(-9,-7,-7,SANDSTONE)
Block(-9,-7,-6,SANDSTONE)
Block(-9,-7,-5,SANDSTONE)
Block(-9,-7,-4,SANDSTONE)
Block(-9,-7,-3,SANDSTONE)
Block(-9,-7,-2,SANDSTONE)
Block(-9,-7,-1,SANDSTONE)
Block(-9,-7,0,SANDSTONE)
Block(-9,-7,1,SANDSTONE)
Block(-9,-7,2,SANDSTONE)
Block(-9,-7,3,SANDSTONE)
Block(-9,-7,4,SANDSTONE)
Block(-9,-7,5,SANDSTONE)
Block(-9,-7,6,SANDSTONE)
Block(-9,-7,7,SANDSTONE)
Block(-9,-7,8,SANDSTONE)
Block(-9,-7,9,SANDSTONE)
Block(-9,-7,10,SANDSTONE)
Block(-9,-7,11,SANDSTONE)
Block(-9,-6,-9,SANDSTONE)
Block(-9,-6,-8,SANDSTONE)
Block(-9,-6,-7,SANDSTONE)
Block(-9,-6,-6,SANDSTONE)
Block(-9,-6,-5,SANDSTONE)
Block(-9,-6,-4,SANDSTONE)
Block(-9,-6,-3,SANDSTONE)
Block(-9,-6,-2,SANDSTONE)
Block(-9,-6,-1,SANDSTONE)
Block(-9,-6,0,SANDSTONE)
Block(-9,-6,1,SANDSTONE)
Block(-9,-6,2,SANDSTONE)
Block(-9,-6,3,SANDSTONE)
Block(-9,-6,4,SANDSTONE)
Block(-9,-6,5,SANDSTONE)
Block(-9,-6,6,SANDSTONE)
Block(-9,-6,7,SANDSTONE)
Block(-9,-6,8,SANDSTONE)
Block(-9,-6,9,SANDSTONE)
Block(-9,-6,10,SANDSTONE)
Block(-9,-6,11,SANDSTONE)
Block(-9,-5,-9,SANDSTONE)
Block(-9,-5,-8,SANDSTONE)
Block(-9,-5,-7,SANDSTONE)
Block(-9,-5,-6,SANDSTONE)
Block(-9,-5,-5,SANDSTONE)
Block(-9,-5,-4,SANDSTONE)
Block(-9,-5,-3,SANDSTONE)
Block(-9,-5,-2,SANDSTONE)
Block(-9,-5,-1,SANDSTONE)
Block(-9,-5,0,SANDSTONE)
Block(-9,-5,1,SANDSTONE)
Block(-9,-5,2,SANDSTONE)
Block(-9,-5,3,SANDSTONE)
Block(-9,-5,4,SANDSTONE)
Block(-9,-5,5,SANDSTONE)
Block(-9,-5,6,SANDSTONE)
Block(-9,-5,7,SANDSTONE)
Block(-9,-5,8,SANDSTONE)
Block(-9,-5,9,SANDSTONE)
Block(-9,-5,10,SANDSTONE)
Block(-9,-5,11,SANDSTONE)
Block(-9,-4,-9,SANDSTONE)
Block(-9,-4,-8,SANDSTONE)
Block(-9,-4,-7,SANDSTONE)
Block(-9,-4,-6,SANDSTONE)
Block(-9,-4,-5,SANDSTONE)
Block(-9,-4,-4,SANDSTONE)
Block(-9,-4,-3,SANDSTONE)
Block(-9,-4,-2,SANDSTONE)
Block(-9,-4,-1,SANDSTONE)
Block(-9,-4,0,SANDSTONE)
Block(-9,-4,1,SANDSTONE)
Block(-9,-4,2,SANDSTONE)
Block(-9,-4,3,SANDSTONE)
Block(-9,-4,4,SANDSTONE)
Block(-9,-4,5,SANDSTONE)
Block(-9,-4,6,SANDSTONE)
Block(-9,-4,7,SANDSTONE)
Block(-9,-4,8,SANDSTONE)
Block(-9,-4,9,SANDSTONE)
Block(-9,-4,10,SANDSTONE)
Block(-9,-4,11,SANDSTONE)
Block(-9,-3,-9,SANDSTONE)
Block(-9,-3,-8,SANDSTONE)
Block(-9,-3,-7,SANDSTONE)
Block(-9,-3,-6,SANDSTONE)
Block(-9,-3,-5,SANDSTONE)
Block(-9,-3,-4,SANDSTONE)
Block(-9,-3,-3,SANDSTONE)
Block(-9,-3,-2,SANDSTONE)
Block(-9,-3,-1,SANDSTONE)
Block(-9,-3,0,SANDSTONE)
Block(-9,-3,1,SANDSTONE)
Block(-9,-3,2,SANDSTONE)
Block(-9,-3,3,SANDSTONE)
Block(-9,-3,4,SANDSTONE)
Block(-9,-3,5,SANDSTONE)
Block(-9,-3,6,SANDSTONE)
Block(-9,-3,7,SANDSTONE)
Block(-9,-3,8,SANDSTONE)
Block(-9,-3,9,SANDSTONE)
Block(-9,-3,10,SANDSTONE)
Block(-9,-3,11,SANDSTONE)
Block(-9,-2,-9,SANDSTONE)
Block(-9,-2,-8,SANDSTONE)
Block(-9,-2,-7,SANDSTONE)
Block(-9,-2,-6,SANDSTONE)
Block(-9,-2,-5,SANDSTONE)
Block(-9,-2,-4,SANDSTONE)
Block(-9,-2,-3,SANDSTONE)
Block(-9,-2,-2,SANDSTONE)
Block(-9,-2,-1,SANDSTONE)
Block(-9,-2,0,SANDSTONE)
Block(-9,-2,1,SANDSTONE)
Block(-9,-2,2,SANDSTONE)
Block(-9,-2,3,SANDSTONE)
Block(-9,-2,4,SANDSTONE)
Block(-9,-2,5,SANDSTONE)
Block(-9,-2,6,SANDSTONE)
Block(-9,-2,7,SANDSTONE)
Block(-9,-2,8,SANDSTONE)
Block(-9,-2,9,SANDSTONE)
Block(-9,-2,10,SANDSTONE)
Block(-9,-2,11,SANDSTONE)
Block(-9,-1,-9,SANDSTONE)
Block(-9,-1,-8,SANDSTONE)
Block(-9,-1,-7,SANDSTONE)
Block(-9,-1,-6,SANDSTONE)
Block(-9,-1,-5,SANDSTONE)
Block(-9,-1,-4,SANDSTONE)
Block(-9,-1,-3,SANDSTONE)
Block(-9,-1,-2,SANDSTONE)
Block(-9,-1,-1,SANDSTONE)
Block(-9,-1,0,SANDSTONE)
Block(-9,-1,1,SANDSTONE)
Block(-9,-1,2,SANDSTONE)
Block(-9,-1,3,SANDSTONE)
Block(-9,-1,4,SANDSTONE)
Block(-9,-1,5,SANDSTONE)
Block(-9,-1,6,SANDSTONE)
Block(-9,-1,7,SANDSTONE)
Block(-9,-1,8,SANDSTONE)
Block(-9,-1,9,SANDSTONE)
Block(-9,-1,10,SANDSTONE)
Block(-9,-1,11,SANDSTONE)
Block(-9,0,-9,SANDSTONE)
Block(-9,0,-8,SANDSTONE)
Block(-9,0,-7,SANDSTONE)
Block(-9,0,-6,SANDSTONE)
Block(-9,0,-5,SANDSTONE)
Block(-9,0,-4,SANDSTONE)
Block(-9,0,-3,SANDSTONE)
Block(-9,0,-2,SANDSTONE)
Block(-9,0,-1,SANDSTONE)
Block(-9,0,0,SANDSTONE)
Block(-9,0,1,SANDSTONE)
Block(-9,0,2,SANDSTONE)
Block(-9,0,3,SANDSTONE)
Block(-9,0,4,SANDSTONE)
Block(-9,0,5,SANDSTONE)
Block(-9,0,6,SANDSTONE)
Block(-9,0,7,SANDSTONE)
Block(-9,0,8,SANDSTONE)
Block(-9,0,9,SANDSTONE)
Block(-9,0,10,SANDSTONE)
Block(-9,0,11,SANDSTONE)
Block(-9,1,-9,SANDSTONE:2)
Block(-9,1,-8,AIR)
Block(-9,1,-7,SANDSTONE)
Block(-9,1,-6,SANDSTONE)
Block(-9,1,-5,SANDSTONE)
Block(-9,1,-4,SANDSTONE)
Block(-9,1,-3,SANDSTONE)
Block(-9,1,-2,SANDSTONE)
Block(-9,1,-1,SANDSTONE)
Block(-9,1,0,SANDSTONE)
Block(-9,1,1,SANDSTONE)
Block(-9,1,2,SANDSTONE)
Block(-9,1,3,SANDSTONE)
Block(-9,1,4,SANDSTONE)
Block(-9,1,5,SANDSTONE)
Block(-9,1,6,SANDSTONE)
Block(-9,1,7,SANDSTONE)
Block(-9,1,8,SANDSTONE)
RandomBlock(-9,1,9,SANDSTONE,44,AIR,100)
Block(-9,1,10,SANDSTONE)
Block(-9,1,11,AIR)
Block(-9,2,-9,SANDSTONE:2)
Block(-9,2,-8,AIR)
Block(-9,2,-7,SANDSTONE_STAIRS:1)
Block(-9,2,-6,SANDSTONE)
Block(-9,2,-5,SANDSTONE)
Block(-9,2,-4,SANDSTONE)
Block(-9,2,-3,SANDSTONE)
Block(-9,2,-2,SANDSTONE)
Block(-9,2,-1,SANDSTONE)
Block(-9,2,0,SANDSTONE)
Block(-9,2,1,SANDSTONE)
Block(-9,2,2,SANDSTONE)
Block(-9,2,3,AIR)
Block(-9,2,4,AIR)
Block(-9,2,5,AIR)
Block(-9,2,6,AIR)
Block(-9,2,7,AIR)
RandomBlock(-9,2,8,SAND,44,AIR,100)
Block(-9,2,9,AIR)
Block(-9,2,10,AIR)
Block(-9,2,11,AIR)
Block(-9,3,-9,SANDSTONE:2)
Block(-9,3,-8,AIR)
Block(-9,3,-7,AIR)
Block(-9,3,-6,AIR)
Block(-9,3,-5,SANDSTONE)
Block(-9,3,-4,SANDSTONE)
Block(-9,3,-3,SANDSTONE)
Block(-9,3,-2,SANDSTONE)
RandomBlock(-9,3,-1,SANDSTONE,44,AIR,100)
Block(-9,3,0,SANDSTONE)
Block(-9,3,1,SANDSTONE)
Block(-9,3,2,SANDSTONE)
Block(-9,3,3,AIR)
Block(-9,3,4,AIR)
Block(-9,3,5,AIR)
Block(-9,3,6,AIR)
Block(-9,3,7,AIR)
Block(-9,3,8,AIR)
Block(-9,3,9,AIR)
Block(-9,3,10,AIR)
Block(-9,3,11,AIR)
Block(-9,4,-9,WOOL:7)
Block(-9,4,-8,AIR)
Block(-9,4,-7,AIR)
Block(-9,4,-6,AIR)
Block(-9,4,-5,SANDSTONE)
Block(-9,4,-4,SANDSTONE)
Block(-9,4,-3,SANDSTONE)
Block(-9,4,-2,SANDSTONE)
Block(-9,4,-1,SANDSTONE)
Block(-9,4,0,SANDSTONE)
RandomBlock(-9,4,1,SANDSTONE,44,AIR,100)
Block(-9,4,2,SANDSTONE)
Block(-9,4,3,AIR)
Block(-9,4,4,AIR)
Block(-9,4,5,AIR)
Block(-9,4,6,AIR)
Block(-9,4,7,AIR)
Block(-9,4,8,AIR)
Block(-9,4,9,AIR)
Block(-9,4,10,AIR)
Block(-9,4,11,AIR)
Block(-9,5,-9,SANDSTONE:2)
Block(-9,5,-8,AIR)
Block(-9,5,-7,AIR)
Block(-9,5,-6,AIR)
Block(-9,5,-5,SANDSTONE)
Block(-9,5,-4,AIR)
RandomBlock(-9,5,-3,SAND,44,AIR,100)
Block(-9,5,-2,AIR)
RandomBlock(-9,5,-1,SAND,44,AIR,100)
Block(-9,5,0,AIR)
Block(-9,5,1,AIR)
Block(-9,5,2,AIR)
Block(-9,5,3,AIR)
Block(-9,5,4,AIR)
Block(-9,5,5,AIR)
Block(-9,5,6,AIR)
Block(-9,5,7,AIR)
Block(-9,5,8,AIR)
Block(-9,5,9,AIR)
Block(-9,5,10,AIR)
Block(-9,5,11,AIR)
Block(-9,6,-9,WOOL:7)
Block(-9,6,-8,AIR)
Block(-9,6,-7,AIR)
Block(-9,6,-6,AIR)
Block(-9,6,-5,SANDSTONE)
Block(-9,6,-4,AIR)
Block(-9,6,-3,AIR)
Block(-9,6,-2,AIR)
Block(-9,6,-1,AIR)
Block(-9,6,0,AIR)
Block(-9,6,1,AIR)
Block(-9,6,2,AIR)
Block(-9,6,3,AIR)
Block(-9,6,4,AIR)
Block(-9,6,5,AIR)
Block(-9,6,6,AIR)
Block(-9,6,7,AIR)
Block(-9,6,8,AIR)
Block(-9,6,9,AIR)
Block(-9,6,10,AIR)
Block(-9,6,11,AIR)
Block(-9,7,-9,WOOL:7)
Block(-9,7,-8,AIR)
Block(-9,7,-7,AIR)
Block(-9,7,-6,AIR)
Block(-9,7,-5,SANDSTONE)
Block(-9,7,-4,AIR)
Block(-9,7,-3,AIR)
Block(-9,7,-2,AIR)
Block(-9,7,-1,AIR)
Block(-9,7,0,AIR)
Block(-9,7,1,AIR)
Block(-9,7,2,AIR)
Block(-9,7,3,AIR)
Block(-9,7,4,AIR)
Block(-9,7,5,AIR)
Block(-9,7,6,AIR)
Block(-9,7,7,AIR)
Block(-9,7,8,AIR)
Block(-9,7,9,AIR)
Block(-9,7,10,AIR)
Block(-9,7,11,AIR)
Block(-9,8,-9,SANDSTONE)
Block(-9,8,-8,AIR)
Block(-9,8,-7,AIR)
Block(-9,8,-6,AIR)
Block(-9,8,-5,SANDSTONE)
Block(-9,8,-4,AIR)
Block(-9,8,-3,AIR)
Block(-9,8,-2,AIR)
Block(-9,8,-1,AIR)
Block(-9,8,0,AIR)
Block(-9,8,1,AIR)
Block(-9,8,2,AIR)
Block(-9,8,3,AIR)
Block(-9,8,4,AIR)
Block(-9,8,5,AIR)
Block(-9,8,6,AIR)
Block(-9,8,7,AIR)
Block(-9,8,8,AIR)
Block(-9,8,9,AIR)
Block(-9,8,10,AIR)
Block(-9,8,11,AIR)
Block(-9,9,-9,AIR)
Block(-9,9,-8,SANDSTONE)
Block(-9,9,-7,SANDSTONE)
Block(-9,9,-6,SANDSTONE)
Block(-9,9,-5,AIR)
Block(-9,9,-4,AIR)
Block(-9,9,-3,AIR)
Block(-9,9,-2,AIR)
Block(-9,9,-1,AIR)
Block(-9,9,0,AIR)
Block(-9,9,1,AIR)
Block(-9,9,2,AIR)
Block(-9,9,3,AIR)
Block(-9,9,4,AIR)
Block(-9,9,5,AIR)
Block(-9,9,6,AIR)
Block(-9,9,7,AIR)
Block(-9,9,8,AIR)
Block(-9,9,9,AIR)
Block(-9,9,10,AIR)
Block(-9,9,11,AIR)
Block(-9,10,-9,AIR)
Block(-9,10,-8,AIR)
Block(-9,10,-7,AIR)
Block(-9,10,-6,AIR)
Block(-9,10,-5,AIR)
Block(-9,10,-4,AIR)
Block(-9,10,-3,AIR)
Block(-9,10,-2,AIR)
Block(-9,10,-1,AIR)
Block(-9,10,0,AIR)
Block(-9,10,1,AIR)
Block(-9,10,2,AIR)
Block(-9,10,3,AIR)
Block(-9,10,4,AIR)
Block(-9,10,5,AIR)
Block(-9,10,6,AIR)
Block(-9,10,7,AIR)
Block(-9,10,8,AIR)
Block(-9,10,9,AIR)
Block(-9,10,10,AIR)
Block(-9,10,11,AIR)
Block(-8,-13,-9,SANDSTONE)
Block(-8,-13,-8,SANDSTONE)
Block(-8,-13,-7,SANDSTONE)
Block(-8,-13,-6,SANDSTONE)
Block(-8,-13,-5,SANDSTONE)
Block(-8,-13,-4,SANDSTONE)
Block(-8,-13,-3,SANDSTONE)
Block(-8,-13,-2,SANDSTONE)
Block(-8,-13,-1,SANDSTONE)
Block(-8,-13,0,SANDSTONE)
Block(-8,-13,1,SANDSTONE)
Block(-8,-13,2,SANDSTONE)
Block(-8,-13,3,SANDSTONE)
Block(-8,-13,4,SANDSTONE)
Block(-8,-13,5,SANDSTONE)
Block(-8,-13,6,SANDSTONE)
Block(-8,-13,7,SANDSTONE)
Block(-8,-13,8,SANDSTONE)
Block(-8,-13,9,SANDSTONE)
Block(-8,-13,10,SANDSTONE)
Block(-8,-13,11,SANDSTONE)
Block(-8,-12,-9,SANDSTONE)
Block(-8,-12,-8,SANDSTONE)
Block(-8,-12,-7,SANDSTONE)
Block(-8,-12,-6,SANDSTONE)
Block(-8,-12,-5,SANDSTONE)
Block(-8,-12,-4,SANDSTONE)
Block(-8,-12,-3,SANDSTONE)
Block(-8,-12,-2,SANDSTONE)
Block(-8,-12,-1,SANDSTONE)
Block(-8,-12,0,SANDSTONE)
Block(-8,-12,1,SANDSTONE)
Block(-8,-12,2,SANDSTONE)
Block(-8,-12,3,SANDSTONE)
Block(-8,-12,4,SANDSTONE)
Block(-8,-12,5,SANDSTONE)
Block(-8,-12,6,SANDSTONE)
Block(-8,-12,7,SANDSTONE)
Block(-8,-12,8,SANDSTONE)
Block(-8,-12,9,SANDSTONE)
Block(-8,-12,10,SANDSTONE)
Block(-8,-12,11,SANDSTONE)
Block(-8,-11,-9,SANDSTONE)
Block(-8,-11,-8,SANDSTONE)
Block(-8,-11,-7,SANDSTONE)
Block(-8,-11,-6,SANDSTONE)
Block(-8,-11,-5,SANDSTONE)
Block(-8,-11,-4,SANDSTONE)
Block(-8,-11,-3,SANDSTONE)
Block(-8,-11,-2,SANDSTONE)
Block(-8,-11,-1,SANDSTONE)
Block(-8,-11,0,SANDSTONE)
Block(-8,-11,1,SANDSTONE)
Block(-8,-11,2,SANDSTONE)
Block(-8,-11,3,SANDSTONE)
Block(-8,-11,4,SANDSTONE)
Block(-8,-11,5,SANDSTONE)
Block(-8,-11,6,SANDSTONE)
Block(-8,-11,7,SANDSTONE)
Block(-8,-11,8,SANDSTONE)
Block(-8,-11,9,SANDSTONE)
Block(-8,-11,10,SANDSTONE)
Block(-8,-11,11,SANDSTONE)
Block(-8,-10,-9,SANDSTONE)
Block(-8,-10,-8,SANDSTONE)
Block(-8,-10,-7,SANDSTONE)
Block(-8,-10,-6,SANDSTONE)
Block(-8,-10,-5,SANDSTONE)
Block(-8,-10,-4,SANDSTONE)
Block(-8,-10,-3,SANDSTONE)
Block(-8,-10,-2,SANDSTONE)
Block(-8,-10,-1,SANDSTONE)
Block(-8,-10,0,SANDSTONE)
Block(-8,-10,1,SANDSTONE)
Block(-8,-10,2,SANDSTONE)
Block(-8,-10,3,SANDSTONE)
Block(-8,-10,4,SANDSTONE)
Block(-8,-10,5,SANDSTONE)
Block(-8,-10,6,SANDSTONE)
Block(-8,-10,7,SANDSTONE)
Block(-8,-10,8,SANDSTONE)
Block(-8,-10,9,SANDSTONE)
Block(-8,-10,10,SANDSTONE)
Block(-8,-10,11,SANDSTONE)
Block(-8,-9,-9,SANDSTONE)
Block(-8,-9,-8,SANDSTONE)
Block(-8,-9,-7,SANDSTONE)
Block(-8,-9,-6,SANDSTONE)
Block(-8,-9,-5,SANDSTONE)
Block(-8,-9,-4,SANDSTONE)
Block(-8,-9,-3,SANDSTONE)
Block(-8,-9,-2,SANDSTONE)
Block(-8,-9,-1,SANDSTONE)
Block(-8,-9,0,SANDSTONE)
Block(-8,-9,1,SANDSTONE)
Block(-8,-9,2,SANDSTONE)
Block(-8,-9,3,SANDSTONE)
Block(-8,-9,4,SANDSTONE)
Block(-8,-9,5,SANDSTONE)
Block(-8,-9,6,SANDSTONE)
Block(-8,-9,7,SANDSTONE)
Block(-8,-9,8,SANDSTONE)
Block(-8,-9,9,SANDSTONE)
Block(-8,-9,10,SANDSTONE)
Block(-8,-9,11,SANDSTONE)
Block(-8,-8,-9,SANDSTONE)
Block(-8,-8,-8,SANDSTONE)
Block(-8,-8,-7,SANDSTONE)
Block(-8,-8,-6,SANDSTONE)
Block(-8,-8,-5,SANDSTONE)
Block(-8,-8,-4,SANDSTONE)
Block(-8,-8,-3,SANDSTONE)
Block(-8,-8,-2,SANDSTONE)
Block(-8,-8,-1,SANDSTONE)
Block(-8,-8,0,SANDSTONE)
Block(-8,-8,1,SANDSTONE)
Block(-8,-8,2,SANDSTONE)
Block(-8,-8,3,SANDSTONE)
Block(-8,-8,4,SANDSTONE)
Block(-8,-8,5,SANDSTONE)
Block(-8,-8,6,SANDSTONE)
Block(-8,-8,7,SANDSTONE)
Block(-8,-8,8,SANDSTONE)
Block(-8,-8,9,SANDSTONE)
Block(-8,-8,10,SANDSTONE)
Block(-8,-8,11,SANDSTONE)
Block(-8,-7,-9,SANDSTONE)
Block(-8,-7,-8,SANDSTONE)
Block(-8,-7,-7,SANDSTONE)
Block(-8,-7,-6,SANDSTONE)
Block(-8,-7,-5,SANDSTONE)
Block(-8,-7,-4,SANDSTONE)
Block(-8,-7,-3,SANDSTONE)
Block(-8,-7,-2,SANDSTONE)
Block(-8,-7,-1,SANDSTONE)
Block(-8,-7,0,SANDSTONE)
Block(-8,-7,1,SANDSTONE)
Block(-8,-7,2,SANDSTONE)
Block(-8,-7,3,SANDSTONE)
Block(-8,-7,4,SANDSTONE)
Block(-8,-7,5,SANDSTONE)
Block(-8,-7,6,SANDSTONE)
Block(-8,-7,7,SANDSTONE)
Block(-8,-7,8,SANDSTONE)
Block(-8,-7,9,SANDSTONE)
Block(-8,-7,10,SANDSTONE)
Block(-8,-7,11,SANDSTONE)
Block(-8,-6,-9,SANDSTONE)
Block(-8,-6,-8,SANDSTONE)
Block(-8,-6,-7,SANDSTONE)
Block(-8,-6,-6,SANDSTONE)
Block(-8,-6,-5,SANDSTONE)
Block(-8,-6,-4,SANDSTONE)
Block(-8,-6,-3,SANDSTONE)
Block(-8,-6,-2,SANDSTONE)
Block(-8,-6,-1,SANDSTONE)
Block(-8,-6,0,SANDSTONE)
Block(-8,-6,1,SANDSTONE)
Block(-8,-6,2,SANDSTONE)
Block(-8,-6,3,SANDSTONE)
Block(-8,-6,4,SANDSTONE)
Block(-8,-6,5,SANDSTONE)
Block(-8,-6,6,SANDSTONE)
Block(-8,-6,7,SANDSTONE)
Block(-8,-6,8,SANDSTONE)
Block(-8,-6,9,SANDSTONE)
Block(-8,-6,10,SANDSTONE)
Block(-8,-6,11,SANDSTONE)
Block(-8,-5,-9,SANDSTONE)
Block(-8,-5,-8,SANDSTONE)
Block(-8,-5,-7,SANDSTONE)
Block(-8,-5,-6,SANDSTONE)
Block(-8,-5,-5,SANDSTONE)
Block(-8,-5,-4,SANDSTONE)
Block(-8,-5,-3,SANDSTONE)
Block(-8,-5,-2,SANDSTONE)
Block(-8,-5,-1,SANDSTONE)
Block(-8,-5,0,SANDSTONE)
Block(-8,-5,1,SANDSTONE)
Block(-8,-5,2,SANDSTONE)
Block(-8,-5,3,SANDSTONE)
Block(-8,-5,4,SANDSTONE)
Block(-8,-5,5,SANDSTONE)
Block(-8,-5,6,SANDSTONE)
Block(-8,-5,7,SANDSTONE)
Block(-8,-5,8,SANDSTONE)
Block(-8,-5,9,SANDSTONE)
Block(-8,-5,10,SANDSTONE)
Block(-8,-5,11,SANDSTONE)
Block(-8,-4,-9,SANDSTONE)
Block(-8,-4,-8,SANDSTONE)
Block(-8,-4,-7,SANDSTONE)
Block(-8,-4,-6,SANDSTONE)
Block(-8,-4,-5,SANDSTONE)
Block(-8,-4,-4,SANDSTONE)
Block(-8,-4,-3,SANDSTONE)
Block(-8,-4,-2,SANDSTONE)
Block(-8,-4,-1,SANDSTONE)
Block(-8,-4,0,SANDSTONE)
Block(-8,-4,1,SANDSTONE)
Block(-8,-4,2,SANDSTONE)
Block(-8,-4,3,SANDSTONE)
Block(-8,-4,4,SANDSTONE)
Block(-8,-4,5,SANDSTONE)
Block(-8,-4,6,SANDSTONE)
Block(-8,-4,7,SANDSTONE)
Block(-8,-4,8,SANDSTONE)
Block(-8,-4,9,SANDSTONE)
Block(-8,-4,10,SANDSTONE)
Block(-8,-4,11,SANDSTONE)
Block(-8,-3,-9,SANDSTONE)
Block(-8,-3,-8,SANDSTONE)
Block(-8,-3,-7,SANDSTONE)
Block(-8,-3,-6,SANDSTONE)
Block(-8,-3,-5,SANDSTONE)
Block(-8,-3,-4,SANDSTONE)
Block(-8,-3,-3,SANDSTONE)
Block(-8,-3,-2,SANDSTONE)
Block(-8,-3,-1,SANDSTONE)
Block(-8,-3,0,SANDSTONE)
Block(-8,-3,1,SANDSTONE)
Block(-8,-3,2,SANDSTONE)
Block(-8,-3,3,SANDSTONE)
Block(-8,-3,4,SANDSTONE)
Block(-8,-3,5,SANDSTONE)
Block(-8,-3,6,SANDSTONE)
Block(-8,-3,7,SANDSTONE)
Block(-8,-3,8,SANDSTONE)
Block(-8,-3,9,SANDSTONE)
Block(-8,-3,10,SANDSTONE)
Block(-8,-3,11,SANDSTONE)
Block(-8,-2,-9,SANDSTONE)
Block(-8,-2,-8,SANDSTONE)
Block(-8,-2,-7,SANDSTONE)
Block(-8,-2,-6,SANDSTONE)
Block(-8,-2,-5,SANDSTONE)
Block(-8,-2,-4,SANDSTONE)
Block(-8,-2,-3,SANDSTONE)
Block(-8,-2,-2,SANDSTONE)
Block(-8,-2,-1,SANDSTONE)
Block(-8,-2,0,SANDSTONE)
Block(-8,-2,1,SANDSTONE)
Block(-8,-2,2,SANDSTONE)
Block(-8,-2,3,SANDSTONE)
Block(-8,-2,4,SANDSTONE)
Block(-8,-2,5,SANDSTONE)
Block(-8,-2,6,SANDSTONE)
Block(-8,-2,7,SANDSTONE)
Block(-8,-2,8,SANDSTONE)
Block(-8,-2,9,SANDSTONE)
Block(-8,-2,10,SANDSTONE)
Block(-8,-2,11,SANDSTONE)
Block(-8,-1,-9,SANDSTONE)
Block(-8,-1,-8,SANDSTONE)
Block(-8,-1,-7,SANDSTONE)
Block(-8,-1,-6,SANDSTONE)
Block(-8,-1,-5,SANDSTONE)
Block(-8,-1,-4,SANDSTONE)
Block(-8,-1,-3,SANDSTONE)
Block(-8,-1,-2,SANDSTONE)
Block(-8,-1,-1,SANDSTONE)
Block(-8,-1,0,SANDSTONE)
Block(-8,-1,1,SANDSTONE)
Block(-8,-1,2,SANDSTONE)
Block(-8,-1,3,SANDSTONE)
Block(-8,-1,4,SANDSTONE)
Block(-8,-1,5,SANDSTONE)
Block(-8,-1,6,SANDSTONE)
Block(-8,-1,7,SANDSTONE)
Block(-8,-1,8,SANDSTONE)
Block(-8,-1,9,SANDSTONE)
Block(-8,-1,10,SANDSTONE)
Block(-8,-1,11,SANDSTONE)
Block(-8,0,-9,SANDSTONE)
Block(-8,0,-8,SANDSTONE)
Block(-8,0,-7,SANDSTONE)
Block(-8,0,-6,SANDSTONE)
Block(-8,0,-5,SANDSTONE)
Block(-8,0,-4,SANDSTONE)
Block(-8,0,-3,SANDSTONE)
Block(-8,0,-2,SANDSTONE)
Block(-8,0,-1,SANDSTONE)
Block(-8,0,0,SANDSTONE)
Block(-8,0,1,SANDSTONE)
Block(-8,0,2,SANDSTONE)
Block(-8,0,3,SANDSTONE)
Block(-8,0,4,SANDSTONE)
Block(-8,0,5,SANDSTONE)
Block(-8,0,6,SANDSTONE)
Block(-8,0,7,SANDSTONE)
Block(-8,0,8,SANDSTONE)
Block(-8,0,9,SANDSTONE)
Block(-8,0,10,SANDSTONE)
Block(-8,0,11,SANDSTONE)
Block(-8,1,-9,WOOL:7)
Block(-8,1,-8,AIR)
Block(-8,1,-7,SANDSTONE_STAIRS:1)
Block(-8,1,-6,SANDSTONE)
Block(-8,1,-5,SANDSTONE)
Block(-8,1,-4,AIR)
Block(-8,1,-3,AIR)
Block(-8,1,-2,AIR)
Block(-8,1,-1,AIR)
Block(-8,1,0,AIR)
Block(-8,1,1,AIR)
Block(-8,1,2,AIR)
Block(-8,1,3,AIR)
Block(-8,1,4,AIR)
Block(-8,1,5,AIR)
Block(-8,1,6,AIR)
Block(-8,1,7,AIR)
Block(-8,1,8,AIR)
Block(-8,1,9,AIR)
Block(-8,1,10,SANDSTONE)
RandomBlock(-8,1,11,SAND,44,AIR,100)
Block(-8,2,-9,WOOL:7)
Block(-8,2,-8,AIR)
Block(-8,2,-7,AIR)
Block(-8,2,-6,SANDSTONE)
Block(-8,2,-5,SANDSTONE)
Block(-8,2,-4,SANDSTONE)
Block(-8,2,-3,SANDSTONE)
Block(-8,2,-2,SANDSTONE)
Block(-8,2,-1,SANDSTONE)
Block(-8,2,0,SANDSTONE)
Block(-8,2,1,SANDSTONE)
Block(-8,2,2,SANDSTONE)
Block(-8,2,3,SANDSTONE)
Block(-8,2,4,SANDSTONE)
Block(-8,2,5,SANDSTONE)
Block(-8,2,6,SANDSTONE)
Block(-8,2,7,SANDSTONE)
Block(-8,2,8,SANDSTONE)
Block(-8,2,9,SANDSTONE)
Block(-8,2,10,AIR)
Block(-8,2,11,AIR)
Block(-8,3,-9,WOOL:7)
Block(-8,3,-8,AIR)
Block(-8,3,-7,AIR)
Block(-8,3,-6,AIR)
Block(-8,3,-5,SANDSTONE_STAIRS:2)
Block(-8,3,-4,SANDSTONE)
Block(-8,3,-3,SANDSTONE)
Block(-8,3,-2,SANDSTONE)
Block(-8,3,-1,SANDSTONE)
Block(-8,3,0,SANDSTONE)
Block(-8,3,1,SANDSTONE)
Block(-8,3,2,SANDSTONE)
Block(-8,3,3,AIR)
RandomBlock(-8,3,4,SAND,44,AIR,100)
Block(-8,3,5,AIR)
Block(-8,3,6,AIR)
Block(-8,3,7,AIR)
Block(-8,3,8,AIR)
Block(-8,3,9,AIR)
Block(-8,3,10,AIR)
Block(-8,3,11,AIR)
Block(-8,4,-9,SANDSTONE:1)
Block(-8,4,-8,AIR)
Block(-8,4,-7,AIR)
Block(-8,4,-6,AIR)
Block(-8,4,-5,AIR)
Block(-8,4,-4,SANDSTONE_STAIRS:2)
Block(-8,4,-3,SANDSTONE)
Block(-8,4,-2,SANDSTONE)
Block(-8,4,-1,SANDSTONE)
Block(-8,4,0,SANDSTONE)
Block(-8,4,1,SANDSTONE)
Block(-8,4,2,SANDSTONE)
Block(-8,4,3,AIR)
Block(-8,4,4,AIR)
Block(-8,4,5,AIR)
Block(-8,4,6,AIR)
Block(-8,4,7,AIR)
Block(-8,4,8,AIR)
Block(-8,4,9,AIR)
Block(-8,4,10,AIR)
Block(-8,4,11,AIR)
Block(-8,5,-9,WOOL:7)
Block(-8,5,-8,AIR)
Block(-8,5,-7,AIR)
Block(-8,5,-6,AIR)
Block(-8,5,-5,AIR)
Block(-8,5,-4,AIR)
Block(-8,5,-3,AIR)
Block(-8,5,-2,AIR)
Block(-8,5,-1,AIR)
Block(-8,5,0,AIR)
Block(-8,5,1,AIR)
Block(-8,5,2,AIR)
Block(-8,5,3,AIR)
Block(-8,5,4,AIR)
Block(-8,5,5,AIR)
Block(-8,5,6,AIR)
Block(-8,5,7,AIR)
Block(-8,5,8,AIR)
Block(-8,5,9,AIR)
Block(-8,5,10,AIR)
Block(-8,5,11,AIR)
Block(-8,6,-9,SANDSTONE:1)
Block(-8,6,-8,AIR)
Block(-8,6,-7,AIR)
Block(-8,6,-6,AIR)
Block(-8,6,-5,AIR)
Block(-8,6,-4,AIR)
Block(-8,6,-3,AIR)
Block(-8,6,-2,AIR)
Block(-8,6,-1,AIR)
Block(-8,6,0,AIR)
Block(-8,6,1,AIR)
Block(-8,6,2,AIR)
Block(-8,6,3,AIR)
Block(-8,6,4,AIR)
Block(-8,6,5,AIR)
Block(-8,6,6,AIR)
Block(-8,6,7,AIR)
Block(-8,6,8,AIR)
Block(-8,6,9,AIR)
Block(-8,6,10,AIR)
Block(-8,6,11,AIR)
Block(-8,7,-9,WOOL:7)
Block(-8,7,-8,AIR)
Block(-8,7,-7,AIR)
Block(-8,7,-6,AIR)
Block(-8,7,-5,SANDSTONE)
Block(-8,7,-4,AIR)
Block(-8,7,-3,AIR)
Block(-8,7,-2,AIR)
Block(-8,7,-1,AIR)
Block(-8,7,0,AIR)
Block(-8,7,1,AIR)
Block(-8,7,2,AIR)
Block(-8,7,3,AIR)
Block(-8,7,4,AIR)
Block(-8,7,5,AIR)
Block(-8,7,6,AIR)
Block(-8,7,7,AIR)
Block(-8,7,8,AIR)
Block(-8,7,9,AIR)
Block(-8,7,10,AIR)
Block(-8,7,11,AIR)
Block(-8,8,-9,SANDSTONE)
Block(-8,8,-8,AIR)
Block(-8,8,-7,AIR)
Block(-8,8,-6,AIR)
Block(-8,8,-5,SANDSTONE)
Block(-8,8,-4,AIR)
Block(-8,8,-3,AIR)
Block(-8,8,-2,AIR)
Block(-8,8,-1,AIR)
Block(-8,8,0,AIR)
Block(-8,8,1,AIR)
Block(-8,8,2,AIR)
Block(-8,8,3,AIR)
Block(-8,8,4,AIR)
Block(-8,8,5,AIR)
Block(-8,8,6,AIR)
Block(-8,8,7,AIR)
Block(-8,8,8,AIR)
Block(-8,8,9,AIR)
Block(-8,8,10,AIR)
Block(-8,8,11,AIR)
Block(-8,9,-9,SANDSTONE_STAIRS:2)
Block(-8,9,-8,SANDSTONE)
Block(-8,9,-7,SANDSTONE)
Block(-8,9,-6,SANDSTONE)
Block(-8,9,-5,SANDSTONE_STAIRS:3)
Block(-8,9,-4,AIR)
Block(-8,9,-3,AIR)
Block(-8,9,-2,AIR)
Block(-8,9,-1,AIR)
Block(-8,9,0,AIR)
Block(-8,9,1,AIR)
Block(-8,9,2,AIR)
Block(-8,9,3,AIR)
Block(-8,9,4,AIR)
Block(-8,9,5,AIR)
Block(-8,9,6,AIR)
Block(-8,9,7,AIR)
Block(-8,9,8,AIR)
Block(-8,9,9,AIR)
Block(-8,9,10,AIR)
Block(-8,9,11,AIR)
Block(-8,10,-9,AIR)
Block(-8,10,-8,AIR)
Block(-8,10,-7,AIR)
Block(-8,10,-6,AIR)
Block(-8,10,-5,AIR)
Block(-8,10,-4,AIR)
Block(-8,10,-3,AIR)
Block(-8,10,-2,AIR)
Block(-8,10,-1,AIR)
Block(-8,10,0,AIR)
Block(-8,10,1,AIR)
Block(-8,10,2,AIR)
Block(-8,10,3,AIR)
Block(-8,10,4,AIR)
Block(-8,10,5,AIR)
Block(-8,10,6,AIR)
Block(-8,10,7,AIR)
Block(-8,10,8,AIR)
Block(-8,10,9,AIR)
Block(-8,10,10,AIR)
Block(-8,10,11,AIR)
Block(-7,-13,-9,SANDSTONE)
Block(-7,-13,-8,SANDSTONE)
Block(-7,-13,-7,SANDSTONE)
Block(-7,-13,-6,SANDSTONE)
Block(-7,-13,-5,SANDSTONE)
Block(-7,-13,-4,SANDSTONE)
Block(-7,-13,-3,SANDSTONE)
Block(-7,-13,-2,SANDSTONE)
Block(-7,-13,-1,SANDSTONE)
Block(-7,-13,0,SANDSTONE)
Block(-7,-13,1,SANDSTONE)
Block(-7,-13,2,SANDSTONE)
Block(-7,-13,3,SANDSTONE)
Block(-7,-13,4,SANDSTONE)
Block(-7,-13,5,SANDSTONE)
Block(-7,-13,6,SANDSTONE)
Block(-7,-13,7,SANDSTONE)
Block(-7,-13,8,SANDSTONE)
Block(-7,-13,9,SANDSTONE)
Block(-7,-13,10,SANDSTONE)
Block(-7,-13,11,SANDSTONE)
Block(-7,-12,-9,SANDSTONE)
Block(-7,-12,-8,SANDSTONE)
Block(-7,-12,-7,SANDSTONE)
Block(-7,-12,-6,SANDSTONE)
Block(-7,-12,-5,SANDSTONE)
Block(-7,-12,-4,SANDSTONE)
Block(-7,-12,-3,SANDSTONE)
Block(-7,-12,-2,SANDSTONE)
Block(-7,-12,-1,SANDSTONE)
Block(-7,-12,0,SANDSTONE)
Block(-7,-12,1,SANDSTONE)
Block(-7,-12,2,SANDSTONE)
Block(-7,-12,3,SANDSTONE)
Block(-7,-12,4,SANDSTONE)
Block(-7,-12,5,SANDSTONE)
Block(-7,-12,6,SANDSTONE)
Block(-7,-12,7,SANDSTONE)
Block(-7,-12,8,SANDSTONE)
Block(-7,-12,9,SANDSTONE)
Block(-7,-12,10,SANDSTONE)
Block(-7,-12,11,SANDSTONE)
Block(-7,-11,-9,SANDSTONE)
Block(-7,-11,-8,SANDSTONE)
Block(-7,-11,-7,SANDSTONE)
Block(-7,-11,-6,SANDSTONE)
Block(-7,-11,-5,SANDSTONE)
Block(-7,-11,-4,SANDSTONE)
Block(-7,-11,-3,SANDSTONE)
Block(-7,-11,-2,SANDSTONE)
Block(-7,-11,-1,SANDSTONE)
Block(-7,-11,0,SANDSTONE)
Block(-7,-11,1,SANDSTONE)
Block(-7,-11,2,SANDSTONE)
Block(-7,-11,3,SANDSTONE)
Block(-7,-11,4,SANDSTONE)
Block(-7,-11,5,SANDSTONE)
Block(-7,-11,6,SANDSTONE)
Block(-7,-11,7,SANDSTONE)
Block(-7,-11,8,SANDSTONE)
Block(-7,-11,9,SANDSTONE)
Block(-7,-11,10,SANDSTONE)
Block(-7,-11,11,SANDSTONE)
Block(-7,-10,-9,SANDSTONE)
Block(-7,-10,-8,SANDSTONE)
Block(-7,-10,-7,SANDSTONE)
Block(-7,-10,-6,SANDSTONE)
Block(-7,-10,-5,SANDSTONE)
Block(-7,-10,-4,SANDSTONE)
Block(-7,-10,-3,SANDSTONE)
Block(-7,-10,-2,SANDSTONE)
Block(-7,-10,-1,SANDSTONE)
Block(-7,-10,0,SANDSTONE)
Block(-7,-10,1,SANDSTONE)
Block(-7,-10,2,SANDSTONE)
Block(-7,-10,3,SANDSTONE)
Block(-7,-10,4,SANDSTONE)
Block(-7,-10,5,SANDSTONE)
Block(-7,-10,6,SANDSTONE)
Block(-7,-10,7,SANDSTONE)
Block(-7,-10,8,SANDSTONE)
Block(-7,-10,9,SANDSTONE)
Block(-7,-10,10,SANDSTONE)
Block(-7,-10,11,SANDSTONE)
Block(-7,-9,-9,SANDSTONE)
Block(-7,-9,-8,SANDSTONE)
Block(-7,-9,-7,SANDSTONE)
Block(-7,-9,-6,SANDSTONE)
Block(-7,-9,-5,SANDSTONE)
Block(-7,-9,-4,SANDSTONE)
Block(-7,-9,-3,SANDSTONE)
Block(-7,-9,-2,SANDSTONE)
Block(-7,-9,-1,SANDSTONE)
Block(-7,-9,0,SANDSTONE)
Block(-7,-9,1,SANDSTONE)
Block(-7,-9,2,SANDSTONE)
Block(-7,-9,3,SANDSTONE)
Block(-7,-9,4,SANDSTONE)
Block(-7,-9,5,SANDSTONE)
Block(-7,-9,6,SANDSTONE)
Block(-7,-9,7,SANDSTONE)
Block(-7,-9,8,SANDSTONE)
Block(-7,-9,9,SANDSTONE)
Block(-7,-9,10,SANDSTONE)
Block(-7,-9,11,SANDSTONE)
Block(-7,-8,-9,SANDSTONE)
Block(-7,-8,-8,SANDSTONE)
Block(-7,-8,-7,SANDSTONE)
Block(-7,-8,-6,SANDSTONE)
Block(-7,-8,-5,SANDSTONE)
Block(-7,-8,-4,SANDSTONE)
Block(-7,-8,-3,SANDSTONE)
Block(-7,-8,-2,SANDSTONE)
Block(-7,-8,-1,SANDSTONE)
Block(-7,-8,0,SANDSTONE)
Block(-7,-8,1,SANDSTONE)
Block(-7,-8,2,SANDSTONE)
Block(-7,-8,3,SANDSTONE)
Block(-7,-8,4,SANDSTONE)
Block(-7,-8,5,SANDSTONE)
Block(-7,-8,6,SANDSTONE)
Block(-7,-8,7,SANDSTONE)
Block(-7,-8,8,SANDSTONE)
Block(-7,-8,9,SANDSTONE)
Block(-7,-8,10,SANDSTONE)
Block(-7,-8,11,SANDSTONE)
Block(-7,-7,-9,SANDSTONE)
Block(-7,-7,-8,SANDSTONE)
Block(-7,-7,-7,SANDSTONE)
Block(-7,-7,-6,SANDSTONE)
Block(-7,-7,-5,SANDSTONE)
Block(-7,-7,-4,SANDSTONE)
Block(-7,-7,-3,SANDSTONE)
Block(-7,-7,-2,SANDSTONE)
Block(-7,-7,-1,SANDSTONE)
Block(-7,-7,0,SANDSTONE)
Block(-7,-7,1,SANDSTONE)
Block(-7,-7,2,SANDSTONE)
Block(-7,-7,3,SANDSTONE)
Block(-7,-7,4,SANDSTONE)
Block(-7,-7,5,SANDSTONE)
Block(-7,-7,6,SANDSTONE)
Block(-7,-7,7,SANDSTONE)
Block(-7,-7,8,SANDSTONE)
Block(-7,-7,9,SANDSTONE)
Block(-7,-7,10,SANDSTONE)
Block(-7,-7,11,SANDSTONE)
Block(-7,-6,-9,SANDSTONE)
Block(-7,-6,-8,SANDSTONE)
Block(-7,-6,-7,SANDSTONE)
Block(-7,-6,-6,SANDSTONE)
Block(-7,-6,-5,SANDSTONE)
Block(-7,-6,-4,SANDSTONE)
Block(-7,-6,-3,SANDSTONE)
Block(-7,-6,-2,SANDSTONE)
Block(-7,-6,-1,SANDSTONE)
Block(-7,-6,0,SANDSTONE)
Block(-7,-6,1,SANDSTONE)
Block(-7,-6,2,SANDSTONE)
Block(-7,-6,3,SANDSTONE)
Block(-7,-6,4,SANDSTONE)
Block(-7,-6,5,SANDSTONE)
Block(-7,-6,6,SANDSTONE)
Block(-7,-6,7,SANDSTONE)
Block(-7,-6,8,SANDSTONE)
Block(-7,-6,9,SANDSTONE)
Block(-7,-6,10,SANDSTONE)
Block(-7,-6,11,SANDSTONE)
Block(-7,-5,-9,SANDSTONE)
Block(-7,-5,-8,SANDSTONE)
Block(-7,-5,-7,SANDSTONE)
Block(-7,-5,-6,SANDSTONE)
Block(-7,-5,-5,SANDSTONE)
Block(-7,-5,-4,SANDSTONE)
Block(-7,-5,-3,SANDSTONE)
Block(-7,-5,-2,SANDSTONE)
Block(-7,-5,-1,SANDSTONE)
Block(-7,-5,0,SANDSTONE)
Block(-7,-5,1,SANDSTONE)
Block(-7,-5,2,SANDSTONE)
Block(-7,-5,3,SANDSTONE)
Block(-7,-5,4,SANDSTONE)
Block(-7,-5,5,SANDSTONE)
Block(-7,-5,6,SANDSTONE)
Block(-7,-5,7,SANDSTONE)
Block(-7,-5,8,SANDSTONE)
Block(-7,-5,9,SANDSTONE)
Block(-7,-5,10,SANDSTONE)
Block(-7,-5,11,SANDSTONE)
Block(-7,-4,-9,SANDSTONE)
Block(-7,-4,-8,SANDSTONE)
Block(-7,-4,-7,SANDSTONE)
Block(-7,-4,-6,SANDSTONE)
Block(-7,-4,-5,SANDSTONE)
Block(-7,-4,-4,SANDSTONE)
Block(-7,-4,-3,SANDSTONE)
Block(-7,-4,-2,SANDSTONE)
Block(-7,-4,-1,SANDSTONE)
Block(-7,-4,0,SANDSTONE)
Block(-7,-4,1,SANDSTONE)
Block(-7,-4,2,SANDSTONE)
Block(-7,-4,3,SANDSTONE)
Block(-7,-4,4,SANDSTONE)
Block(-7,-4,5,SANDSTONE)
Block(-7,-4,6,SANDSTONE)
Block(-7,-4,7,SANDSTONE)
Block(-7,-4,8,SANDSTONE)
Block(-7,-4,9,SANDSTONE)
Block(-7,-4,10,SANDSTONE)
Block(-7,-4,11,SANDSTONE)
Block(-7,-3,-9,SANDSTONE)
Block(-7,-3,-8,SANDSTONE)
Block(-7,-3,-7,SANDSTONE)
Block(-7,-3,-6,SANDSTONE)
Block(-7,-3,-5,SANDSTONE)
Block(-7,-3,-4,SANDSTONE)
Block(-7,-3,-3,SANDSTONE)
Block(-7,-3,-2,SANDSTONE)
Block(-7,-3,-1,SANDSTONE)
Block(-7,-3,0,SANDSTONE)
Block(-7,-3,1,SANDSTONE)
Block(-7,-3,2,SANDSTONE)
Block(-7,-3,3,SANDSTONE)
Block(-7,-3,4,SANDSTONE)
Block(-7,-3,5,SANDSTONE)
Block(-7,-3,6,SANDSTONE)
Block(-7,-3,7,SANDSTONE)
Block(-7,-3,8,SANDSTONE)
Block(-7,-3,9,SANDSTONE)
Block(-7,-3,10,SANDSTONE)
Block(-7,-3,11,SANDSTONE)
Block(-7,-2,-9,SANDSTONE)
Block(-7,-2,-8,SANDSTONE)
Block(-7,-2,-7,SANDSTONE)
Block(-7,-2,-6,SANDSTONE)
Block(-7,-2,-5,SANDSTONE)
Block(-7,-2,-4,SANDSTONE)
Block(-7,-2,-3,SANDSTONE)
Block(-7,-2,-2,SANDSTONE)
Block(-7,-2,-1,SANDSTONE)
Block(-7,-2,0,SANDSTONE)
Block(-7,-2,1,SANDSTONE)
Block(-7,-2,2,SANDSTONE)
Block(-7,-2,3,SANDSTONE)
Block(-7,-2,4,SANDSTONE)
Block(-7,-2,5,SANDSTONE)
Block(-7,-2,6,SANDSTONE)
Block(-7,-2,7,SANDSTONE)
Block(-7,-2,8,SANDSTONE)
Block(-7,-2,9,SANDSTONE)
Block(-7,-2,10,SANDSTONE)
Block(-7,-2,11,SANDSTONE)
Block(-7,-1,-9,SANDSTONE)
Block(-7,-1,-8,SANDSTONE)
Block(-7,-1,-7,SANDSTONE)
Block(-7,-1,-6,SANDSTONE)
Block(-7,-1,-5,SANDSTONE)
Block(-7,-1,-4,SANDSTONE)
Block(-7,-1,-3,SANDSTONE)
Block(-7,-1,-2,SANDSTONE)
Block(-7,-1,-1,SANDSTONE)
Block(-7,-1,0,SANDSTONE)
Block(-7,-1,1,SANDSTONE)
Block(-7,-1,2,SANDSTONE)
Block(-7,-1,3,SANDSTONE)
Block(-7,-1,4,SANDSTONE)
Block(-7,-1,5,SANDSTONE)
Block(-7,-1,6,SANDSTONE)
Block(-7,-1,7,SANDSTONE)
Block(-7,-1,8,SANDSTONE)
Block(-7,-1,9,SANDSTONE)
Block(-7,-1,10,SANDSTONE)
Block(-7,-1,11,SANDSTONE)
Block(-7,0,-9,SANDSTONE)
Block(-7,0,-8,SANDSTONE)
Block(-7,0,-7,SANDSTONE)
Block(-7,0,-6,SANDSTONE)
Block(-7,0,-5,SANDSTONE)
Block(-7,0,-4,SANDSTONE)
Block(-7,0,-3,SANDSTONE)
Block(-7,0,-2,SANDSTONE)
Block(-7,0,-1,SANDSTONE)
Block(-7,0,0,SANDSTONE)
Block(-7,0,1,SANDSTONE)
Block(-7,0,2,SANDSTONE)
Block(-7,0,3,SANDSTONE)
Block(-7,0,4,SANDSTONE)
Block(-7,0,5,SANDSTONE)
Block(-7,0,6,SANDSTONE)
Block(-7,0,7,SANDSTONE)
Block(-7,0,8,SANDSTONE)
Block(-7,0,9,SANDSTONE)
Block(-7,0,10,SANDSTONE)
Block(-7,0,11,SANDSTONE)
Block(-7,1,-9,SANDSTONE:2)
Block(-7,1,-8,AIR)
Block(-7,1,-7,AIR)
Block(-7,1,-6,SANDSTONE)
Block(-7,1,-5,SANDSTONE)
Block(-7,1,-4,AIR)
RandomBlock(-7,1,-3,CHEST,../../nbt/VanillaLoot/simple_dungeon.nbt,50,CHEST,../../nbt/VanillaLoot/abandoned_mineshaft.nbt,30,CHEST,../../nbt/VanillaLoot/desert_pyramid.nbt,100)
Block(-7,1,-2,AIR)
Block(-7,1,-1,AIR)
Block(-7,1,0,AIR)
Block(-7,1,1,AIR)
Block(-7,1,2,AIR)
Block(-7,1,3,AIR)
Block(-7,1,4,AIR)
Block(-7,1,5,AIR)
Block(-7,1,6,AIR)
Block(-7,1,7,AIR)
Block(-7,1,8,AIR)
Block(-7,1,9,AIR)
Block(-7,1,10,SANDSTONE)
Block(-7,1,11,AIR)
Block(-7,2,-9,SANDSTONE:2)
Block(-7,2,-8,AIR)
Block(-7,2,-7,AIR)
Block(-7,2,-6,SANDSTONE)
Block(-7,2,-5,SANDSTONE)
Block(-7,2,-4,AIR)
Block(-7,2,-3,AIR)
Block(-7,2,-2,AIR)
Block(-7,2,-1,AIR)
Block(-7,2,0,AIR)
Block(-7,2,1,AIR)
Block(-7,2,2,AIR)
Block(-7,2,3,AIR)
Block(-7,2,4,AIR)
Block(-7,2,5,AIR)
Block(-7,2,6,AIR)
Block(-7,2,7,AIR)
Block(-7,2,8,AIR)
Block(-7,2,9,SANDSTONE)
Block(-7,2,10,AIR)
Block(-7,2,11,AIR)
Block(-7,3,-9,SANDSTONE:2)
Block(-7,3,-8,AIR)
Block(-7,3,-7,AIR)
Block(-7,3,-6,AIR)
Block(-7,3,-5,SANDSTONE)
Block(-7,3,-4,SANDSTONE)
Block(-7,3,-3,SANDSTONE)
Block(-7,3,-2,SANDSTONE)
Block(-7,3,-1,SANDSTONE)
Block(-7,3,0,SANDSTONE)
Block(-7,3,1,SANDSTONE)
Block(-7,3,2,SANDSTONE)
Block(-7,3,3,SANDSTONE)
Block(-7,3,4,SANDSTONE)
Block(-7,3,5,SANDSTONE)
RandomBlock(-7,3,6,SANDSTONE,44,AIR,100)
Block(-7,3,7,SANDSTONE)
Block(-7,3,8,SANDSTONE)
RandomBlock(-7,3,9,SAND,44,AIR,100)
Block(-7,3,10,AIR)
Block(-7,3,11,AIR)
Block(-7,4,-9,WOOL:7)
Block(-7,4,-8,AIR)
Block(-7,4,-7,AIR)
Block(-7,4,-6,AIR)
Block(-7,4,-5,SANDSTONE)
Block(-7,4,-4,SANDSTONE)
Block(-7,4,-3,SANDSTONE)
Block(-7,4,-2,SANDSTONE)
Block(-7,4,-1,SANDSTONE)
Block(-7,4,0,SANDSTONE)
Block(-7,4,1,SANDSTONE)
Block(-7,4,2,SANDSTONE)
Block(-7,4,3,AIR)
Block(-7,4,4,AIR)
Block(-7,4,5,AIR)
Block(-7,4,6,AIR)
RandomBlock(-7,4,7,SAND,44,AIR,100)
RandomBlock(-7,4,8,SAND,44,AIR,100)
Block(-7,4,9,AIR)
Block(-7,4,10,AIR)
Block(-7,4,11,AIR)
Block(-7,5,-9,SANDSTONE:2)
Block(-7,5,-8,AIR)
Block(-7,5,-7,AIR)
Block(-7,5,-6,AIR)
Block(-7,5,-5,SANDSTONE)
Block(-7,5,-4,AIR)
Block(-7,5,-3,AIR)
Block(-7,5,-2,AIR)
Block(-7,5,-1,AIR)
Block(-7,5,0,AIR)
Block(-7,5,1,AIR)
RandomBlock(-7,5,2,SAND,44,AIR,100)
Block(-7,5,3,AIR)
Block(-7,5,4,AIR)
Block(-7,5,5,AIR)
Block(-7,5,6,AIR)
Block(-7,5,7,AIR)
Block(-7,5,8,AIR)
Block(-7,5,9,AIR)
Block(-7,5,10,AIR)
Block(-7,5,11,AIR)
Block(-7,6,-9,WOOL:7)
Block(-7,6,-8,AIR)
Block(-7,6,-7,AIR)
Block(-7,6,-6,AIR)
Block(-7,6,-5,SANDSTONE)
Block(-7,6,-4,AIR)
Block(-7,6,-3,AIR)
Block(-7,6,-2,AIR)
Block(-7,6,-1,AIR)
Block(-7,6,0,AIR)
Block(-7,6,1,AIR)
Block(-7,6,2,AIR)
Block(-7,6,3,AIR)
Block(-7,6,4,AIR)
Block(-7,6,5,AIR)
Block(-7,6,6,AIR)
Block(-7,6,7,AIR)
Block(-7,6,8,AIR)
Block(-7,6,9,AIR)
Block(-7,6,10,AIR)
Block(-7,6,11,AIR)
Block(-7,7,-9,WOOL:7)
Block(-7,7,-8,AIR)
Block(-7,7,-7,AIR)
Block(-7,7,-6,AIR)
Block(-7,7,-5,SANDSTONE)
Block(-7,7,-4,AIR)
Block(-7,7,-3,AIR)
Block(-7,7,-2,AIR)
Block(-7,7,-1,AIR)
Block(-7,7,0,AIR)
Block(-7,7,1,AIR)
Block(-7,7,2,AIR)
Block(-7,7,3,AIR)
Block(-7,7,4,AIR)
Block(-7,7,5,AIR)
Block(-7,7,6,AIR)
Block(-7,7,7,AIR)
Block(-7,7,8,AIR)
Block(-7,7,9,AIR)
Block(-7,7,10,AIR)
Block(-7,7,11,AIR)
Block(-7,8,-9,SANDSTONE)
Block(-7,8,-8,AIR)
Block(-7,8,-7,AIR)
Block(-7,8,-6,AIR)
RandomBlock(-7,8,-5,SANDSTONE,44,AIR,100)
Block(-7,8,-4,AIR)
Block(-7,8,-3,AIR)
Block(-7,8,-2,AIR)
Block(-7,8,-1,AIR)
Block(-7,8,0,AIR)
Block(-7,8,1,AIR)
Block(-7,8,2,AIR)
Block(-7,8,3,AIR)
Block(-7,8,4,AIR)
Block(-7,8,5,AIR)
Block(-7,8,6,AIR)
Block(-7,8,7,AIR)
Block(-7,8,8,AIR)
Block(-7,8,9,AIR)
Block(-7,8,10,AIR)
Block(-7,8,11,AIR)
RandomBlock(-7,9,-9,SAND,44,AIR,100)
Block(-7,9,-8,SANDSTONE)
Block(-7,9,-7,SANDSTONE)
Block(-7,9,-6,SANDSTONE)
Block(-7,9,-5,AIR)
Block(-7,9,-4,AIR)
Block(-7,9,-3,AIR)
Block(-7,9,-2,AIR)
Block(-7,9,-1,AIR)
Block(-7,9,0,AIR)
Block(-7,9,1,AIR)
Block(-7,9,2,AIR)
Block(-7,9,3,AIR)
Block(-7,9,4,AIR)
Block(-7,9,5,AIR)
Block(-7,9,6,AIR)
Block(-7,9,7,AIR)
Block(-7,9,8,AIR)
Block(-7,9,9,AIR)
Block(-7,9,10,AIR)
Block(-7,9,11,AIR)
Block(-7,10,-9,AIR)
Block(-7,10,-8,AIR)
Block(-7,10,-7,AIR)
Block(-7,10,-6,AIR)
Block(-7,10,-5,AIR)
Block(-7,10,-4,AIR)
Block(-7,10,-3,AIR)
Block(-7,10,-2,AIR)
Block(-7,10,-1,AIR)
Block(-7,10,0,AIR)
Block(-7,10,1,AIR)
Block(-7,10,2,AIR)
Block(-7,10,3,AIR)
Block(-7,10,4,AIR)
Block(-7,10,5,AIR)
Block(-7,10,6,AIR)
Block(-7,10,7,AIR)
Block(-7,10,8,AIR)
Block(-7,10,9,AIR)
Block(-7,10,10,AIR)
Block(-7,10,11,AIR)
Block(-6,-13,-9,SANDSTONE)
Block(-6,-13,-8,SANDSTONE)
Block(-6,-13,-7,SANDSTONE)
Block(-6,-13,-6,SANDSTONE)
Block(-6,-13,-5,SANDSTONE)
Block(-6,-13,-4,SANDSTONE)
Block(-6,-13,-3,SANDSTONE)
Block(-6,-13,-2,SANDSTONE)
Block(-6,-13,-1,SANDSTONE)
Block(-6,-13,0,SANDSTONE)
Block(-6,-13,1,SANDSTONE)
Block(-6,-13,2,SANDSTONE)
Block(-6,-13,3,SANDSTONE)
Block(-6,-13,4,SANDSTONE)
Block(-6,-13,5,SANDSTONE)
Block(-6,-13,6,SANDSTONE)
Block(-6,-13,7,SANDSTONE)
Block(-6,-13,8,SANDSTONE)
Block(-6,-13,9,SANDSTONE)
Block(-6,-13,10,SANDSTONE)
Block(-6,-13,11,SANDSTONE)
Block(-6,-12,-9,SANDSTONE)
Block(-6,-12,-8,SANDSTONE)
Block(-6,-12,-7,SANDSTONE)
Block(-6,-12,-6,SANDSTONE)
Block(-6,-12,-5,SANDSTONE)
Block(-6,-12,-4,SANDSTONE)
Block(-6,-12,-3,SANDSTONE)
Block(-6,-12,-2,SANDSTONE)
Block(-6,-12,-1,SANDSTONE)
Block(-6,-12,0,SANDSTONE)
Block(-6,-12,1,SANDSTONE)
Block(-6,-12,2,SANDSTONE)
Block(-6,-12,3,SANDSTONE)
Block(-6,-12,4,SANDSTONE)
Block(-6,-12,5,SANDSTONE)
Block(-6,-12,6,SANDSTONE)
Block(-6,-12,7,SANDSTONE)
Block(-6,-12,8,SANDSTONE)
Block(-6,-12,9,SANDSTONE)
Block(-6,-12,10,SANDSTONE)
Block(-6,-12,11,SANDSTONE)
Block(-6,-11,-9,SANDSTONE)
Block(-6,-11,-8,SANDSTONE)
Block(-6,-11,-7,SANDSTONE)
Block(-6,-11,-6,SANDSTONE)
Block(-6,-11,-5,SANDSTONE)
Block(-6,-11,-4,SANDSTONE)
Block(-6,-11,-3,SANDSTONE)
Block(-6,-11,-2,SANDSTONE)
Block(-6,-11,-1,SANDSTONE)
Block(-6,-11,0,SANDSTONE)
Block(-6,-11,1,SANDSTONE)
Block(-6,-11,2,SANDSTONE)
Block(-6,-11,3,SANDSTONE)
Block(-6,-11,4,SANDSTONE)
Block(-6,-11,5,SANDSTONE)
Block(-6,-11,6,SANDSTONE)
Block(-6,-11,7,SANDSTONE)
Block(-6,-11,8,SANDSTONE)
Block(-6,-11,9,SANDSTONE)
Block(-6,-11,10,SANDSTONE)
Block(-6,-11,11,SANDSTONE)
Block(-6,-10,-9,SANDSTONE)
Block(-6,-10,-8,SANDSTONE)
Block(-6,-10,-7,SANDSTONE)
Block(-6,-10,-6,SANDSTONE)
Block(-6,-10,-5,SANDSTONE)
Block(-6,-10,-4,SANDSTONE)
Block(-6,-10,-3,SANDSTONE)
Block(-6,-10,-2,SANDSTONE)
Block(-6,-10,-1,SANDSTONE)
Block(-6,-10,0,SANDSTONE)
Block(-6,-10,1,SANDSTONE)
Block(-6,-10,2,SANDSTONE)
Block(-6,-10,3,SANDSTONE)
Block(-6,-10,4,SANDSTONE)
Block(-6,-10,5,SANDSTONE)
Block(-6,-10,6,SANDSTONE)
Block(-6,-10,7,SANDSTONE)
Block(-6,-10,8,SANDSTONE)
Block(-6,-10,9,SANDSTONE)
Block(-6,-10,10,SANDSTONE)
Block(-6,-10,11,SANDSTONE)
Block(-6,-9,-9,SANDSTONE)
Block(-6,-9,-8,SANDSTONE)
Block(-6,-9,-7,SANDSTONE)
Block(-6,-9,-6,SANDSTONE)
Block(-6,-9,-5,SANDSTONE)
Block(-6,-9,-4,SANDSTONE)
Block(-6,-9,-3,SANDSTONE)
Block(-6,-9,-2,SANDSTONE)
Block(-6,-9,-1,SANDSTONE)
Block(-6,-9,0,SANDSTONE)
Block(-6,-9,1,SANDSTONE)
Block(-6,-9,2,SANDSTONE)
Block(-6,-9,3,SANDSTONE)
Block(-6,-9,4,SANDSTONE)
Block(-6,-9,5,SANDSTONE)
Block(-6,-9,6,SANDSTONE)
Block(-6,-9,7,SANDSTONE)
Block(-6,-9,8,SANDSTONE)
Block(-6,-9,9,SANDSTONE)
Block(-6,-9,10,SANDSTONE)
Block(-6,-9,11,SANDSTONE)
Block(-6,-8,-9,SANDSTONE)
Block(-6,-8,-8,SANDSTONE)
Block(-6,-8,-7,SANDSTONE)
Block(-6,-8,-6,SANDSTONE)
Block(-6,-8,-5,SANDSTONE)
Block(-6,-8,-4,SANDSTONE)
Block(-6,-8,-3,SANDSTONE)
Block(-6,-8,-2,SANDSTONE)
Block(-6,-8,-1,SANDSTONE)
Block(-6,-8,0,SANDSTONE)
Block(-6,-8,1,SANDSTONE)
Block(-6,-8,2,SANDSTONE)
Block(-6,-8,3,SANDSTONE)
Block(-6,-8,4,SANDSTONE)
Block(-6,-8,5,SANDSTONE)
Block(-6,-8,6,SANDSTONE)
Block(-6,-8,7,SANDSTONE)
Block(-6,-8,8,SANDSTONE)
Block(-6,-8,9,SANDSTONE)
Block(-6,-8,10,SANDSTONE)
Block(-6,-8,11,SANDSTONE)
Block(-6,-7,-9,SANDSTONE)
Block(-6,-7,-8,SANDSTONE)
Block(-6,-7,-7,SANDSTONE)
Block(-6,-7,-6,SANDSTONE)
Block(-6,-7,-5,SANDSTONE)
Block(-6,-7,-4,SANDSTONE)
Block(-6,-7,-3,SANDSTONE)
Block(-6,-7,-2,SANDSTONE)
Block(-6,-7,-1,SANDSTONE)
Block(-6,-7,0,SANDSTONE)
Block(-6,-7,1,SANDSTONE)
Block(-6,-7,2,SANDSTONE)
Block(-6,-7,3,SANDSTONE)
Block(-6,-7,4,SANDSTONE)
Block(-6,-7,5,SANDSTONE)
Block(-6,-7,6,SANDSTONE)
Block(-6,-7,7,SANDSTONE)
Block(-6,-7,8,SANDSTONE)
Block(-6,-7,9,SANDSTONE)
Block(-6,-7,10,SANDSTONE)
Block(-6,-7,11,SANDSTONE)
Block(-6,-6,-9,SANDSTONE)
Block(-6,-6,-8,SANDSTONE)
Block(-6,-6,-7,SANDSTONE)
Block(-6,-6,-6,SANDSTONE)
Block(-6,-6,-5,SANDSTONE)
Block(-6,-6,-4,SANDSTONE)
Block(-6,-6,-3,SANDSTONE)
Block(-6,-6,-2,SANDSTONE)
Block(-6,-6,-1,SANDSTONE)
Block(-6,-6,0,SANDSTONE)
Block(-6,-6,1,SANDSTONE)
Block(-6,-6,2,SANDSTONE)
Block(-6,-6,3,SANDSTONE)
Block(-6,-6,4,SANDSTONE)
Block(-6,-6,5,SANDSTONE)
Block(-6,-6,6,SANDSTONE)
Block(-6,-6,7,SANDSTONE)
Block(-6,-6,8,SANDSTONE)
Block(-6,-6,9,SANDSTONE)
Block(-6,-6,10,SANDSTONE)
Block(-6,-6,11,SANDSTONE)
Block(-6,-5,-9,SANDSTONE)
Block(-6,-5,-8,SANDSTONE)
Block(-6,-5,-7,SANDSTONE)
Block(-6,-5,-6,SANDSTONE)
Block(-6,-5,-5,SANDSTONE)
Block(-6,-5,-4,SANDSTONE)
Block(-6,-5,-3,SANDSTONE)
Block(-6,-5,-2,SANDSTONE)
Block(-6,-5,-1,SANDSTONE)
Block(-6,-5,0,SANDSTONE)
Block(-6,-5,1,SANDSTONE)
Block(-6,-5,2,SANDSTONE)
Block(-6,-5,3,SANDSTONE)
Block(-6,-5,4,SANDSTONE)
Block(-6,-5,5,SANDSTONE)
Block(-6,-5,6,SANDSTONE)
Block(-6,-5,7,SANDSTONE)
Block(-6,-5,8,SANDSTONE)
Block(-6,-5,9,SANDSTONE)
Block(-6,-5,10,SANDSTONE)
Block(-6,-5,11,SANDSTONE)
Block(-6,-4,-9,SANDSTONE)
Block(-6,-4,-8,SANDSTONE)
Block(-6,-4,-7,SANDSTONE)
Block(-6,-4,-6,SANDSTONE)
Block(-6,-4,-5,SANDSTONE)
Block(-6,-4,-4,SANDSTONE)
Block(-6,-4,-3,SANDSTONE)
Block(-6,-4,-2,SANDSTONE)
Block(-6,-4,-1,SANDSTONE)
Block(-6,-4,0,SANDSTONE)
Block(-6,-4,1,SANDSTONE)
Block(-6,-4,2,SANDSTONE)
Block(-6,-4,3,SANDSTONE)
Block(-6,-4,4,SANDSTONE)
Block(-6,-4,5,SANDSTONE)
Block(-6,-4,6,SANDSTONE)
Block(-6,-4,7,SANDSTONE)
Block(-6,-4,8,SANDSTONE)
Block(-6,-4,9,SANDSTONE)
Block(-6,-4,10,SANDSTONE)
Block(-6,-4,11,SANDSTONE)
Block(-6,-3,-9,SANDSTONE)
Block(-6,-3,-8,SANDSTONE)
Block(-6,-3,-7,SANDSTONE)
Block(-6,-3,-6,SANDSTONE)
Block(-6,-3,-5,SANDSTONE)
Block(-6,-3,-4,SANDSTONE)
Block(-6,-3,-3,SANDSTONE)
Block(-6,-3,-2,SANDSTONE)
Block(-6,-3,-1,SANDSTONE)
Block(-6,-3,0,SANDSTONE)
Block(-6,-3,1,SANDSTONE)
Block(-6,-3,2,SANDSTONE)
Block(-6,-3,3,SANDSTONE)
Block(-6,-3,4,SANDSTONE)
Block(-6,-3,5,SANDSTONE)
Block(-6,-3,6,SANDSTONE)
Block(-6,-3,7,SANDSTONE)
Block(-6,-3,8,SANDSTONE)
Block(-6,-3,9,SANDSTONE)
Block(-6,-3,10,SANDSTONE)
Block(-6,-3,11,SANDSTONE)
Block(-6,-2,-9,SANDSTONE)
Block(-6,-2,-8,SANDSTONE)
Block(-6,-2,-7,SANDSTONE)
Block(-6,-2,-6,SANDSTONE)
Block(-6,-2,-5,SANDSTONE)
Block(-6,-2,-4,SANDSTONE)
Block(-6,-2,-3,SANDSTONE)
Block(-6,-2,-2,SANDSTONE)
Block(-6,-2,-1,SANDSTONE)
Block(-6,-2,0,SANDSTONE)
Block(-6,-2,1,SANDSTONE)
Block(-6,-2,2,SANDSTONE)
Block(-6,-2,3,SANDSTONE)
Block(-6,-2,4,SANDSTONE)
Block(-6,-2,5,SANDSTONE)
Block(-6,-2,6,SANDSTONE)
Block(-6,-2,7,SANDSTONE)
Block(-6,-2,8,SANDSTONE)
Block(-6,-2,9,SANDSTONE)
Block(-6,-2,10,SANDSTONE)
Block(-6,-2,11,SANDSTONE)
Block(-6,-1,-9,SANDSTONE)
Block(-6,-1,-8,SANDSTONE)
Block(-6,-1,-7,SANDSTONE)
Block(-6,-1,-6,SANDSTONE)
Block(-6,-1,-5,SANDSTONE)
Block(-6,-1,-4,SANDSTONE)
Block(-6,-1,-3,SANDSTONE)
Block(-6,-1,-2,SANDSTONE)
Block(-6,-1,-1,SANDSTONE)
Block(-6,-1,0,SANDSTONE)
Block(-6,-1,1,SANDSTONE)
Block(-6,-1,2,SANDSTONE)
Block(-6,-1,3,SANDSTONE)
Block(-6,-1,4,SANDSTONE)
Block(-6,-1,5,SANDSTONE)
Block(-6,-1,6,SANDSTONE)
Block(-6,-1,7,SANDSTONE)
Block(-6,-1,8,SANDSTONE)
Block(-6,-1,9,SANDSTONE)
Block(-6,-1,10,SANDSTONE)
Block(-6,-1,11,SANDSTONE)
Block(-6,0,-9,SANDSTONE)
Block(-6,0,-8,SANDSTONE)
Block(-6,0,-7,SANDSTONE)
Block(-6,0,-6,SANDSTONE)
Block(-6,0,-5,SANDSTONE)
Block(-6,0,-4,SANDSTONE)
Block(-6,0,-3,SANDSTONE)
Block(-6,0,-2,SANDSTONE)
Block(-6,0,-1,SANDSTONE)
Block(-6,0,0,SANDSTONE)
Block(-6,0,1,SANDSTONE)
Block(-6,0,2,SANDSTONE)
Block(-6,0,3,SANDSTONE)
Block(-6,0,4,SANDSTONE)
Block(-6,0,5,SANDSTONE)
Block(-6,0,6,SANDSTONE)
Block(-6,0,7,SANDSTONE)
Block(-6,0,8,SANDSTONE)
Block(-6,0,9,SANDSTONE)
Block(-6,0,10,SANDSTONE)
Block(-6,0,11,SANDSTONE)
Block(-6,1,-9,SANDSTONE)
Block(-6,1,-8,SANDSTONE)
Block(-6,1,-7,AIR)
Block(-6,1,-6,SANDSTONE)
Block(-6,1,-5,SANDSTONE)
Block(-6,1,-4,AIR)
Block(-6,1,-3,SANDSTONE:2)
Block(-6,1,-2,AIR)
Block(-6,1,-1,SANDSTONE:2)
Block(-6,1,0,AIR)
Block(-6,1,1,SANDSTONE:2)
Block(-6,1,2,AIR)
Block(-6,1,3,SANDSTONE:2)
Block(-6,1,4,AIR)
Block(-6,1,5,SANDSTONE:2)
Block(-6,1,6,AIR)
Block(-6,1,7,SANDSTONE:2)
Block(-6,1,8,AIR)
Block(-6,1,9,AIR)
Block(-6,1,10,SANDSTONE)
Block(-6,1,11,AIR)
Block(-6,2,-9,SANDSTONE)
Block(-6,2,-8,SANDSTONE)
Block(-6,2,-7,AIR)
Block(-6,2,-6,SANDSTONE)
Block(-6,2,-5,SANDSTONE)
Block(-6,2,-4,AIR)
Block(-6,2,-3,SANDSTONE:1)
Block(-6,2,-2,AIR)
Block(-6,2,-1,SANDSTONE:1)
Block(-6,2,0,AIR)
Block(-6,2,1,SANDSTONE:1)
Block(-6,2,2,AIR)
Block(-6,2,3,SANDSTONE:1)
Block(-6,2,4,AIR)
Block(-6,2,5,SANDSTONE:1)
Block(-6,2,6,AIR)
Block(-6,2,7,SANDSTONE:1)
Block(-6,2,8,AIR)
Block(-6,2,9,SANDSTONE)
Block(-6,2,10,AIR)
Block(-6,2,11,AIR)
Block(-6,3,-9,SANDSTONE)
Block(-6,3,-8,SANDSTONE)
Block(-6,3,-7,SANDSTONE)
Block(-6,3,-6,SANDSTONE)
Block(-6,3,-5,SANDSTONE)
Block(-6,3,-4,SANDSTONE:2)
Block(-6,3,-3,SANDSTONE:2)
Block(-6,3,-2,SANDSTONE:2)
Block(-6,3,-1,SANDSTONE:2)
Block(-6,3,0,SANDSTONE:2)
Block(-6,3,1,SANDSTONE:2)
Block(-6,3,2,SANDSTONE:2)
Block(-6,3,3,SANDSTONE:2)
Block(-6,3,4,SANDSTONE:2)
Block(-6,3,5,SANDSTONE:2)
Block(-6,3,6,SANDSTONE:2)
Block(-6,3,7,SANDSTONE:2)
Block(-6,3,8,SANDSTONE)
Block(-6,3,9,AIR)
Block(-6,3,10,AIR)
Block(-6,3,11,AIR)
Block(-6,4,-9,SANDSTONE)
Block(-6,4,-8,SANDSTONE)
Block(-6,4,-7,SANDSTONE)
Block(-6,4,-6,SANDSTONE)
Block(-6,4,-5,SANDSTONE)
Block(-6,4,-4,SANDSTONE)
Block(-6,4,-3,SANDSTONE)
Block(-6,4,-2,SANDSTONE)
Block(-6,4,-1,SANDSTONE)
Block(-6,4,0,SANDSTONE)
Block(-6,4,1,SANDSTONE)
Block(-6,4,2,SANDSTONE)
Block(-6,4,3,SANDSTONE)
Block(-6,4,4,SANDSTONE)
Block(-6,4,5,SANDSTONE)
Block(-6,4,6,SANDSTONE)
Block(-6,4,7,SANDSTONE)
Block(-6,4,8,AIR)
Block(-6,4,9,AIR)
Block(-6,4,10,AIR)
Block(-6,4,11,AIR)
Block(-6,5,-9,SANDSTONE)
Block(-6,5,-8,SANDSTONE)
Block(-6,5,-7,SANDSTONE)
Block(-6,5,-6,SANDSTONE)
Block(-6,5,-5,SANDSTONE)
RandomBlock(-6,5,-4,SAND,44,AIR,100)
Block(-6,5,-3,AIR)
RandomBlock(-6,5,-2,SAND,44,AIR,100)
RandomBlock(-6,5,-1,SAND,44,AIR,100)
Block(-6,5,0,AIR)
RandomBlock(-6,5,1,SAND,44,AIR,100)
Block(-6,5,2,AIR)
Block(-6,5,3,AIR)
Block(-6,5,4,AIR)
RandomBlock(-6,5,5,SAND,44,AIR,100)
Block(-6,5,6,AIR)
Block(-6,5,7,AIR)
Block(-6,5,8,AIR)
Block(-6,5,9,AIR)
Block(-6,5,10,AIR)
Block(-6,5,11,AIR)
Block(-6,6,-9,SANDSTONE)
Block(-6,6,-8,SANDSTONE)
Block(-6,6,-7,SANDSTONE)
Block(-6,6,-6,SANDSTONE)
Block(-6,6,-5,SANDSTONE)
Block(-6,6,-4,AIR)
Block(-6,6,-3,AIR)
Block(-6,6,-2,AIR)
Block(-6,6,-1,AIR)
Block(-6,6,0,AIR)
Block(-6,6,1,AIR)
Block(-6,6,2,AIR)
Block(-6,6,3,AIR)
Block(-6,6,4,AIR)
Block(-6,6,5,AIR)
Block(-6,6,6,AIR)
Block(-6,6,7,AIR)
Block(-6,6,8,AIR)
Block(-6,6,9,AIR)
Block(-6,6,10,AIR)
Block(-6,6,11,AIR)
Block(-6,7,-9,SANDSTONE)
Block(-6,7,-8,SANDSTONE)
Block(-6,7,-7,SANDSTONE)
Block(-6,7,-6,SANDSTONE)
Block(-6,7,-5,SANDSTONE)
Block(-6,7,-4,AIR)
Block(-6,7,-3,AIR)
Block(-6,7,-2,AIR)
Block(-6,7,-1,AIR)
Block(-6,7,0,AIR)
Block(-6,7,1,AIR)
Block(-6,7,2,AIR)
Block(-6,7,3,AIR)
Block(-6,7,4,AIR)
Block(-6,7,5,AIR)
Block(-6,7,6,AIR)
Block(-6,7,7,AIR)
Block(-6,7,8,AIR)
Block(-6,7,9,AIR)
Block(-6,7,10,AIR)
Block(-6,7,11,AIR)
Block(-6,8,-9,SANDSTONE)
Block(-6,8,-8,SANDSTONE)
Block(-6,8,-7,SANDSTONE)
Block(-6,8,-6,SANDSTONE)
Block(-6,8,-5,SANDSTONE)
Block(-6,8,-4,AIR)
Block(-6,8,-3,AIR)
Block(-6,8,-2,AIR)
Block(-6,8,-1,AIR)
Block(-6,8,0,AIR)
Block(-6,8,1,AIR)
Block(-6,8,2,AIR)
Block(-6,8,3,AIR)
Block(-6,8,4,AIR)
Block(-6,8,5,AIR)
Block(-6,8,6,AIR)
Block(-6,8,7,AIR)
Block(-6,8,8,AIR)
Block(-6,8,9,AIR)
Block(-6,8,10,AIR)
Block(-6,8,11,AIR)
Block(-6,9,-9,AIR)
Block(-6,9,-8,AIR)
Block(-6,9,-7,SANDSTONE_STAIRS:1)
Block(-6,9,-6,AIR)
Block(-6,9,-5,AIR)
Block(-6,9,-4,AIR)
Block(-6,9,-3,AIR)
Block(-6,9,-2,AIR)
Block(-6,9,-1,AIR)
Block(-6,9,0,AIR)
Block(-6,9,1,AIR)
Block(-6,9,2,AIR)
Block(-6,9,3,AIR)
Block(-6,9,4,AIR)
Block(-6,9,5,AIR)
Block(-6,9,6,AIR)
Block(-6,9,7,AIR)
Block(-6,9,8,AIR)
Block(-6,9,9,AIR)
Block(-6,9,10,AIR)
Block(-6,9,11,AIR)
Block(-6,10,-9,AIR)
Block(-6,10,-8,AIR)
Block(-6,10,-7,AIR)
Block(-6,10,-6,AIR)
Block(-6,10,-5,AIR)
Block(-6,10,-4,AIR)
Block(-6,10,-3,AIR)
Block(-6,10,-2,AIR)
Block(-6,10,-1,AIR)
Block(-6,10,0,AIR)
Block(-6,10,1,AIR)
Block(-6,10,2,AIR)
Block(-6,10,3,AIR)
Block(-6,10,4,AIR)
Block(-6,10,5,AIR)
Block(-6,10,6,AIR)
Block(-6,10,7,AIR)
Block(-6,10,8,AIR)
Block(-6,10,9,AIR)
Block(-6,10,10,AIR)
Block(-6,10,11,AIR)
Block(-5,-13,-9,SANDSTONE)
Block(-5,-13,-8,SANDSTONE)
Block(-5,-13,-7,SANDSTONE)
Block(-5,-13,-6,SANDSTONE)
Block(-5,-13,-5,SANDSTONE)
Block(-5,-13,-4,SANDSTONE)
Block(-5,-13,-3,SANDSTONE)
Block(-5,-13,-2,SANDSTONE)
Block(-5,-13,-1,SANDSTONE)
Block(-5,-13,0,SANDSTONE)
Block(-5,-13,1,SANDSTONE)
Block(-5,-13,2,SANDSTONE)
Block(-5,-13,3,SANDSTONE)
Block(-5,-13,4,SANDSTONE)
Block(-5,-13,5,SANDSTONE)
Block(-5,-13,6,SANDSTONE)
Block(-5,-13,7,SANDSTONE)
Block(-5,-13,8,SANDSTONE)
Block(-5,-13,9,SANDSTONE)
Block(-5,-13,10,SANDSTONE)
Block(-5,-13,11,SANDSTONE)
Block(-5,-12,-9,SANDSTONE)
Block(-5,-12,-8,SANDSTONE)
Block(-5,-12,-7,SANDSTONE)
Block(-5,-12,-6,SANDSTONE)
Block(-5,-12,-5,SANDSTONE)
Block(-5,-12,-4,SANDSTONE)
Block(-5,-12,-3,SANDSTONE)
Block(-5,-12,-2,SANDSTONE)
Block(-5,-12,-1,SANDSTONE)
Block(-5,-12,0,SANDSTONE)
Block(-5,-12,1,SANDSTONE)
Block(-5,-12,2,SANDSTONE)
Block(-5,-12,3,SANDSTONE)
Block(-5,-12,4,SANDSTONE)
Block(-5,-12,5,SANDSTONE)
Block(-5,-12,6,SANDSTONE)
Block(-5,-12,7,SANDSTONE)
Block(-5,-12,8,SANDSTONE)
Block(-5,-12,9,SANDSTONE)
Block(-5,-12,10,SANDSTONE)
Block(-5,-12,11,SANDSTONE)
Block(-5,-11,-9,SANDSTONE)
Block(-5,-11,-8,SANDSTONE)
Block(-5,-11,-7,SANDSTONE)
Block(-5,-11,-6,SANDSTONE)
Block(-5,-11,-5,SANDSTONE)
Block(-5,-11,-4,SANDSTONE)
Block(-5,-11,-3,SANDSTONE)
Block(-5,-11,-2,SANDSTONE)
Block(-5,-11,-1,SANDSTONE)
Block(-5,-11,0,SANDSTONE)
Block(-5,-11,1,SANDSTONE)
Block(-5,-11,2,SANDSTONE)
Block(-5,-11,3,SANDSTONE)
Block(-5,-11,4,SANDSTONE)
Block(-5,-11,5,SANDSTONE)
Block(-5,-11,6,SANDSTONE)
Block(-5,-11,7,SANDSTONE)
Block(-5,-11,8,SANDSTONE)
Block(-5,-11,9,SANDSTONE)
Block(-5,-11,10,SANDSTONE)
Block(-5,-11,11,SANDSTONE)
Block(-5,-10,-9,SANDSTONE)
Block(-5,-10,-8,SANDSTONE)
Block(-5,-10,-7,SANDSTONE)
Block(-5,-10,-6,SANDSTONE)
Block(-5,-10,-5,SANDSTONE)
Block(-5,-10,-4,SANDSTONE)
Block(-5,-10,-3,SANDSTONE)
Block(-5,-10,-2,SANDSTONE)
Block(-5,-10,-1,SANDSTONE)
Block(-5,-10,0,SANDSTONE)
Block(-5,-10,1,SANDSTONE)
Block(-5,-10,2,SANDSTONE)
Block(-5,-10,3,SANDSTONE)
Block(-5,-10,4,SANDSTONE)
Block(-5,-10,5,SANDSTONE)
Block(-5,-10,6,SANDSTONE)
Block(-5,-10,7,SANDSTONE)
Block(-5,-10,8,SANDSTONE)
Block(-5,-10,9,SANDSTONE)
Block(-5,-10,10,SANDSTONE)
Block(-5,-10,11,SANDSTONE)
Block(-5,-9,-9,SANDSTONE)
Block(-5,-9,-8,SANDSTONE)
Block(-5,-9,-7,SANDSTONE)
Block(-5,-9,-6,SANDSTONE)
Block(-5,-9,-5,SANDSTONE)
Block(-5,-9,-4,SANDSTONE)
Block(-5,-9,-3,SANDSTONE)
Block(-5,-9,-2,SANDSTONE)
Block(-5,-9,-1,SANDSTONE)
Block(-5,-9,0,SANDSTONE)
Block(-5,-9,1,SANDSTONE)
Block(-5,-9,2,SANDSTONE)
Block(-5,-9,3,SANDSTONE)
Block(-5,-9,4,SANDSTONE)
Block(-5,-9,5,SANDSTONE)
Block(-5,-9,6,SANDSTONE)
Block(-5,-9,7,SANDSTONE)
Block(-5,-9,8,SANDSTONE)
Block(-5,-9,9,SANDSTONE)
Block(-5,-9,10,SANDSTONE)
Block(-5,-9,11,SANDSTONE)
Block(-5,-8,-9,SANDSTONE)
Block(-5,-8,-8,SANDSTONE)
Block(-5,-8,-7,SANDSTONE)
Block(-5,-8,-6,SANDSTONE)
Block(-5,-8,-5,SANDSTONE)
Block(-5,-8,-4,SANDSTONE)
Block(-5,-8,-3,SANDSTONE)
Block(-5,-8,-2,SANDSTONE)
Block(-5,-8,-1,SANDSTONE)
Block(-5,-8,0,SANDSTONE)
Block(-5,-8,1,SANDSTONE)
Block(-5,-8,2,SANDSTONE)
Block(-5,-8,3,SANDSTONE)
Block(-5,-8,4,SANDSTONE)
Block(-5,-8,5,SANDSTONE)
Block(-5,-8,6,SANDSTONE)
Block(-5,-8,7,SANDSTONE)
Block(-5,-8,8,SANDSTONE)
Block(-5,-8,9,SANDSTONE)
Block(-5,-8,10,SANDSTONE)
Block(-5,-8,11,SANDSTONE)
Block(-5,-7,-9,SANDSTONE)
Block(-5,-7,-8,SANDSTONE)
Block(-5,-7,-7,SANDSTONE)
Block(-5,-7,-6,SANDSTONE)
Block(-5,-7,-5,SANDSTONE)
Block(-5,-7,-4,SANDSTONE)
Block(-5,-7,-3,SANDSTONE)
Block(-5,-7,-2,SANDSTONE)
Block(-5,-7,-1,SANDSTONE)
Block(-5,-7,0,SANDSTONE)
Block(-5,-7,1,SANDSTONE)
Block(-5,-7,2,SANDSTONE)
Block(-5,-7,3,SANDSTONE)
Block(-5,-7,4,SANDSTONE)
Block(-5,-7,5,SANDSTONE)
Block(-5,-7,6,SANDSTONE)
Block(-5,-7,7,SANDSTONE)
Block(-5,-7,8,SANDSTONE)
Block(-5,-7,9,SANDSTONE)
Block(-5,-7,10,SANDSTONE)
Block(-5,-7,11,SANDSTONE)
Block(-5,-6,-9,SANDSTONE)
Block(-5,-6,-8,SANDSTONE)
Block(-5,-6,-7,SANDSTONE)
Block(-5,-6,-6,SANDSTONE)
Block(-5,-6,-5,SANDSTONE)
Block(-5,-6,-4,SANDSTONE)
Block(-5,-6,-3,SANDSTONE)
Block(-5,-6,-2,SANDSTONE)
Block(-5,-6,-1,SANDSTONE)
Block(-5,-6,0,SANDSTONE)
Block(-5,-6,1,SANDSTONE)
Block(-5,-6,2,SANDSTONE)
Block(-5,-6,3,SANDSTONE)
Block(-5,-6,4,SANDSTONE)
Block(-5,-6,5,SANDSTONE)
Block(-5,-6,6,SANDSTONE)
Block(-5,-6,7,SANDSTONE)
Block(-5,-6,8,SANDSTONE)
Block(-5,-6,9,SANDSTONE)
Block(-5,-6,10,SANDSTONE)
Block(-5,-6,11,SANDSTONE)
Block(-5,-5,-9,SANDSTONE)
Block(-5,-5,-8,SANDSTONE)
Block(-5,-5,-7,SANDSTONE)
Block(-5,-5,-6,SANDSTONE)
Block(-5,-5,-5,SANDSTONE)
Block(-5,-5,-4,SANDSTONE)
Block(-5,-5,-3,SANDSTONE)
Block(-5,-5,-2,SANDSTONE)
Block(-5,-5,-1,SANDSTONE)
Block(-5,-5,0,SANDSTONE)
Block(-5,-5,1,SANDSTONE)
Block(-5,-5,2,SANDSTONE)
Block(-5,-5,3,SANDSTONE)
Block(-5,-5,4,SANDSTONE)
Block(-5,-5,5,SANDSTONE)
Block(-5,-5,6,SANDSTONE)
Block(-5,-5,7,SANDSTONE)
Block(-5,-5,8,SANDSTONE)
Block(-5,-5,9,SANDSTONE)
Block(-5,-5,10,SANDSTONE)
Block(-5,-5,11,SANDSTONE)
Block(-5,-4,-9,SANDSTONE)
Block(-5,-4,-8,SANDSTONE)
Block(-5,-4,-7,SANDSTONE)
Block(-5,-4,-6,SANDSTONE)
Block(-5,-4,-5,SANDSTONE)
Block(-5,-4,-4,SANDSTONE)
Block(-5,-4,-3,SANDSTONE)
Block(-5,-4,-2,SANDSTONE)
Block(-5,-4,-1,SANDSTONE)
Block(-5,-4,0,SANDSTONE)
Block(-5,-4,1,SANDSTONE)
Block(-5,-4,2,SANDSTONE)
Block(-5,-4,3,SANDSTONE)
Block(-5,-4,4,SANDSTONE)
Block(-5,-4,5,SANDSTONE)
Block(-5,-4,6,SANDSTONE)
Block(-5,-4,7,SANDSTONE)
Block(-5,-4,8,SANDSTONE)
Block(-5,-4,9,SANDSTONE)
Block(-5,-4,10,SANDSTONE)
Block(-5,-4,11,SANDSTONE)
Block(-5,-3,-9,SANDSTONE)
Block(-5,-3,-8,SANDSTONE)
Block(-5,-3,-7,SANDSTONE)
Block(-5,-3,-6,SANDSTONE)
Block(-5,-3,-5,SANDSTONE)
Block(-5,-3,-4,SANDSTONE)
Block(-5,-3,-3,SANDSTONE)
Block(-5,-3,-2,SANDSTONE)
Block(-5,-3,-1,SANDSTONE)
Block(-5,-3,0,SANDSTONE)
Block(-5,-3,1,SANDSTONE)
Block(-5,-3,2,SANDSTONE)
Block(-5,-3,3,SANDSTONE)
Block(-5,-3,4,SANDSTONE)
Block(-5,-3,5,SANDSTONE)
Block(-5,-3,6,SANDSTONE)
Block(-5,-3,7,SANDSTONE)
Block(-5,-3,8,SANDSTONE)
Block(-5,-3,9,SANDSTONE)
Block(-5,-3,10,SANDSTONE)
Block(-5,-3,11,SANDSTONE)
Block(-5,-2,-9,SANDSTONE)
Block(-5,-2,-8,SANDSTONE)
Block(-5,-2,-7,SANDSTONE)
Block(-5,-2,-6,SANDSTONE)
Block(-5,-2,-5,SANDSTONE)
Block(-5,-2,-4,SANDSTONE)
Block(-5,-2,-3,SANDSTONE)
Block(-5,-2,-2,SANDSTONE)
Block(-5,-2,-1,SANDSTONE)
Block(-5,-2,0,SANDSTONE)
Block(-5,-2,1,SANDSTONE)
Block(-5,-2,2,SANDSTONE)
Block(-5,-2,3,SANDSTONE)
Block(-5,-2,4,SANDSTONE)
Block(-5,-2,5,SANDSTONE)
Block(-5,-2,6,SANDSTONE)
Block(-5,-2,7,SANDSTONE)
Block(-5,-2,8,SANDSTONE)
Block(-5,-2,9,SANDSTONE)
Block(-5,-2,10,SANDSTONE)
Block(-5,-2,11,SANDSTONE)
Block(-5,-1,-9,SANDSTONE)
Block(-5,-1,-8,SANDSTONE)
Block(-5,-1,-7,SANDSTONE)
Block(-5,-1,-6,SANDSTONE)
Block(-5,-1,-5,SANDSTONE)
Block(-5,-1,-4,SANDSTONE)
Block(-5,-1,-3,SANDSTONE)
Block(-5,-1,-2,SANDSTONE)
Block(-5,-1,-1,SANDSTONE)
Block(-5,-1,0,SANDSTONE)
Block(-5,-1,1,SANDSTONE)
Block(-5,-1,2,SANDSTONE)
Block(-5,-1,3,SANDSTONE)
Block(-5,-1,4,SANDSTONE)
Block(-5,-1,5,SANDSTONE)
Block(-5,-1,6,SANDSTONE)
Block(-5,-1,7,SANDSTONE)
Block(-5,-1,8,SANDSTONE)
Block(-5,-1,9,SANDSTONE)
Block(-5,-1,10,SANDSTONE)
Block(-5,-1,11,SANDSTONE)
Block(-5,0,-9,SANDSTONE)
Block(-5,0,-8,SANDSTONE)
Block(-5,0,-7,SANDSTONE)
Block(-5,0,-6,SANDSTONE)
Block(-5,0,-5,SANDSTONE)
Block(-5,0,-4,SANDSTONE)
Block(-5,0,-3,SANDSTONE)
Block(-5,0,-2,SANDSTONE)
Block(-5,0,-1,SANDSTONE)
Block(-5,0,0,SANDSTONE)
Block(-5,0,1,SANDSTONE)
Block(-5,0,2,SANDSTONE)
Block(-5,0,3,SANDSTONE)
Block(-5,0,4,SANDSTONE)
Block(-5,0,5,SANDSTONE)
Block(-5,0,6,SANDSTONE)
Block(-5,0,7,SANDSTONE)
Block(-5,0,8,SANDSTONE)
Block(-5,0,9,SANDSTONE)
Block(-5,0,10,SANDSTONE)
Block(-5,0,11,SANDSTONE)
Block(-5,1,-9,AIR)
Block(-5,1,-8,SANDSTONE)
Block(-5,1,-7,AIR)
Block(-5,1,-6,SANDSTONE)
Block(-5,1,-5,AIR)
Block(-5,1,-4,AIR)
Block(-5,1,-3,AIR)
Block(-5,1,-2,AIR)
RandomBlock(-5,1,-1,SAND,44,AIR,100)
Block(-5,1,0,AIR)
Block(-5,1,1,AIR)
Block(-5,1,2,AIR)
Block(-5,1,3,AIR)
Block(-5,1,4,AIR)
Block(-5,1,5,AIR)
Block(-5,1,6,AIR)
Block(-5,1,7,AIR)
Block(-5,1,8,AIR)
Block(-5,1,9,AIR)
Block(-5,1,10,SANDSTONE)
RandomBlock(-5,1,11,SAND,44,AIR,100)
Block(-5,2,-9,AIR)
Block(-5,2,-8,SANDSTONE)
Block(-5,2,-7,AIR)
Block(-5,2,-6,SANDSTONE)
Block(-5,2,-5,AIR)
Block(-5,2,-4,AIR)
Block(-5,2,-3,AIR)
Block(-5,2,-2,AIR)
Block(-5,2,-1,AIR)
Block(-5,2,0,AIR)
Block(-5,2,1,AIR)
Block(-5,2,2,AIR)
Block(-5,2,3,AIR)
Block(-5,2,4,AIR)
Block(-5,2,5,AIR)
Block(-5,2,6,AIR)
Block(-5,2,7,AIR)
Block(-5,2,8,AIR)
Block(-5,2,9,SANDSTONE)
Block(-5,2,10,AIR)
Block(-5,2,11,AIR)
Block(-5,3,-9,AIR)
RandomBlock(-5,3,-8,SANDSTONE,44,AIR,100)
Block(-5,3,-7,SANDSTONE)
Block(-5,3,-6,SANDSTONE)
Block(-5,3,-5,SANDSTONE:2)
Block(-5,3,-4,AIR)
Block(-5,3,-3,AIR)
Block(-5,3,-2,AIR)
Block(-5,3,-1,AIR)
Block(-5,3,0,AIR)
Block(-5,3,1,AIR)
Block(-5,3,2,AIR)
Block(-5,3,3,AIR)
Block(-5,3,4,AIR)
Block(-5,3,5,AIR)
Block(-5,3,6,AIR)
Block(-5,3,7,SANDSTONE:2)
Block(-5,3,8,SANDSTONE)
Block(-5,3,9,AIR)
Block(-5,3,10,AIR)
Block(-5,3,11,AIR)
Block(-5,4,-9,AIR)
Block(-5,4,-8,AIR)
Block(-5,4,-7,AIR)
Block(-5,4,-6,AIR)
Block(-5,4,-5,SANDSTONE)
Block(-5,4,-4,SANDSTONE)
Block(-5,4,-3,SANDSTONE)
Block(-5,4,-2,SANDSTONE)
Block(-5,4,-1,SANDSTONE)
Block(-5,4,0,SANDSTONE)
Block(-5,4,1,SANDSTONE)
Block(-5,4,2,SANDSTONE)
Block(-5,4,3,SANDSTONE)
Block(-5,4,4,SANDSTONE)
Block(-5,4,5,SANDSTONE)
Block(-5,4,6,SANDSTONE)
Block(-5,4,7,SANDSTONE)
Block(-5,4,8,AIR)
Block(-5,4,9,AIR)
Block(-5,4,10,AIR)
Block(-5,4,11,AIR)
Block(-5,5,-9,AIR)
Block(-5,5,-8,AIR)
Block(-5,5,-7,AIR)
Block(-5,5,-6,AIR)
RandomBlock(-5,5,-5,SAND,44,AIR,100)
Block(-5,5,-4,SANDSTONE)
Block(-5,5,-3,SANDSTONE)
Block(-5,5,-2,SANDSTONE)
Block(-5,5,-1,SANDSTONE)
Block(-5,5,0,SANDSTONE:2)
Block(-5,5,1,AIR)
Block(-5,5,2,SANDSTONE:2)
Block(-5,5,3,SANDSTONE)
Block(-5,5,4,SANDSTONE)
Block(-5,5,5,SANDSTONE)
Block(-5,5,6,SANDSTONE)
Block(-5,5,7,AIR)
Block(-5,5,8,AIR)
Block(-5,5,9,AIR)
Block(-5,5,10,AIR)
Block(-5,5,11,AIR)
Block(-5,6,-9,AIR)
Block(-5,6,-8,AIR)
Block(-5,6,-7,AIR)
Block(-5,6,-6,AIR)
Block(-5,6,-5,AIR)
Block(-5,6,-4,AIR)
Block(-5,6,-3,AIR)
Block(-5,6,-2,AIR)
Block(-5,6,-1,AIR)
Block(-5,6,0,SANDSTONE:2)
Block(-5,6,1,AIR)
Block(-5,6,2,SANDSTONE:2)
Block(-5,6,3,AIR)
Block(-5,6,4,AIR)
Block(-5,6,5,AIR)
Block(-5,6,6,AIR)
Block(-5,6,7,AIR)
Block(-5,6,8,AIR)
Block(-5,6,9,AIR)
Block(-5,6,10,AIR)
Block(-5,6,11,AIR)
Block(-5,7,-9,AIR)
Block(-5,7,-8,AIR)
Block(-5,7,-7,AIR)
Block(-5,7,-6,AIR)
Block(-5,7,-5,AIR)
Block(-5,7,-4,AIR)
Block(-5,7,-3,AIR)
Block(-5,7,-2,AIR)
Block(-5,7,-1,AIR)
Block(-5,7,0,SANDSTONE:2)
Block(-5,7,1,SANDSTONE:2)
Block(-5,7,2,SANDSTONE:2)
Block(-5,7,3,AIR)
Block(-5,7,4,AIR)
Block(-5,7,5,AIR)
Block(-5,7,6,AIR)
Block(-5,7,7,AIR)
Block(-5,7,8,AIR)
Block(-5,7,9,AIR)
Block(-5,7,10,AIR)
Block(-5,7,11,AIR)
Block(-5,8,-9,AIR)
Block(-5,8,-8,AIR)
Block(-5,8,-7,AIR)
Block(-5,8,-6,AIR)
Block(-5,8,-5,AIR)
Block(-5,8,-4,AIR)
Block(-5,8,-3,AIR)
Block(-5,8,-2,AIR)
Block(-5,8,-1,AIR)
Block(-5,8,0,AIR)
Block(-5,8,1,AIR)
Block(-5,8,2,AIR)
Block(-5,8,3,AIR)
Block(-5,8,4,AIR)
Block(-5,8,5,AIR)
Block(-5,8,6,AIR)
Block(-5,8,7,AIR)
Block(-5,8,8,AIR)
Block(-5,8,9,AIR)
Block(-5,8,10,AIR)
Block(-5,8,11,AIR)
Block(-5,9,-9,AIR)
Block(-5,9,-8,AIR)
Block(-5,9,-7,AIR)
Block(-5,9,-6,AIR)
Block(-5,9,-5,AIR)
Block(-5,9,-4,AIR)
Block(-5,9,-3,AIR)
Block(-5,9,-2,AIR)
Block(-5,9,-1,AIR)
Block(-5,9,0,AIR)
Block(-5,9,1,AIR)
Block(-5,9,2,AIR)
Block(-5,9,3,AIR)
Block(-5,9,4,AIR)
Block(-5,9,5,AIR)
Block(-5,9,6,AIR)
Block(-5,9,7,AIR)
Block(-5,9,8,AIR)
Block(-5,9,9,AIR)
Block(-5,9,10,AIR)
Block(-5,9,11,AIR)
Block(-5,10,-9,AIR)
Block(-5,10,-8,AIR)
Block(-5,10,-7,AIR)
Block(-5,10,-6,AIR)
Block(-5,10,-5,AIR)
Block(-5,10,-4,AIR)
Block(-5,10,-3,AIR)
Block(-5,10,-2,AIR)
Block(-5,10,-1,AIR)
Block(-5,10,0,AIR)
Block(-5,10,1,AIR)
Block(-5,10,2,AIR)
Block(-5,10,3,AIR)
Block(-5,10,4,AIR)
Block(-5,10,5,AIR)
Block(-5,10,6,AIR)
Block(-5,10,7,AIR)
Block(-5,10,8,AIR)
Block(-5,10,9,AIR)
Block(-5,10,10,AIR)
Block(-5,10,11,AIR)
Block(-4,-13,-9,SANDSTONE)
Block(-4,-13,-8,SANDSTONE)
Block(-4,-13,-7,SANDSTONE)
Block(-4,-13,-6,SANDSTONE)
Block(-4,-13,-5,SANDSTONE)
Block(-4,-13,-4,SANDSTONE)
Block(-4,-13,-3,SANDSTONE)
Block(-4,-13,-2,SANDSTONE)
Block(-4,-13,-1,SANDSTONE)
Block(-4,-13,0,SANDSTONE)
Block(-4,-13,1,SANDSTONE)
Block(-4,-13,2,SANDSTONE)
Block(-4,-13,3,SANDSTONE)
Block(-4,-13,4,SANDSTONE)
Block(-4,-13,5,SANDSTONE)
Block(-4,-13,6,SANDSTONE)
Block(-4,-13,7,SANDSTONE)
Block(-4,-13,8,SANDSTONE)
Block(-4,-13,9,SANDSTONE)
Block(-4,-13,10,SANDSTONE)
Block(-4,-13,11,SANDSTONE)
Block(-4,-12,-9,SANDSTONE)
Block(-4,-12,-8,SANDSTONE)
Block(-4,-12,-7,SANDSTONE)
Block(-4,-12,-6,SANDSTONE)
Block(-4,-12,-5,SANDSTONE)
Block(-4,-12,-4,SANDSTONE)
Block(-4,-12,-3,SANDSTONE)
Block(-4,-12,-2,SANDSTONE)
Block(-4,-12,-1,SANDSTONE)
Block(-4,-12,0,SANDSTONE)
Block(-4,-12,1,SANDSTONE)
Block(-4,-12,2,SANDSTONE)
Block(-4,-12,3,SANDSTONE)
Block(-4,-12,4,SANDSTONE)
Block(-4,-12,5,SANDSTONE)
Block(-4,-12,6,SANDSTONE)
Block(-4,-12,7,SANDSTONE)
Block(-4,-12,8,SANDSTONE)
Block(-4,-12,9,SANDSTONE)
Block(-4,-12,10,SANDSTONE)
Block(-4,-12,11,SANDSTONE)
Block(-4,-11,-9,SANDSTONE)
Block(-4,-11,-8,SANDSTONE)
Block(-4,-11,-7,SANDSTONE)
Block(-4,-11,-6,SANDSTONE)
Block(-4,-11,-5,SANDSTONE)
Block(-4,-11,-4,SANDSTONE)
Block(-4,-11,-3,SANDSTONE)
Block(-4,-11,-2,SANDSTONE)
Block(-4,-11,-1,SANDSTONE)
Block(-4,-11,0,SANDSTONE)
Block(-4,-11,1,SANDSTONE)
Block(-4,-11,2,SANDSTONE)
Block(-4,-11,3,SANDSTONE)
Block(-4,-11,4,SANDSTONE)
Block(-4,-11,5,SANDSTONE)
Block(-4,-11,6,SANDSTONE)
Block(-4,-11,7,SANDSTONE)
Block(-4,-11,8,SANDSTONE)
Block(-4,-11,9,SANDSTONE)
Block(-4,-11,10,SANDSTONE)
Block(-4,-11,11,SANDSTONE)
Block(-4,-10,-9,SANDSTONE)
Block(-4,-10,-8,SANDSTONE)
Block(-4,-10,-7,SANDSTONE)
Block(-4,-10,-6,SANDSTONE)
Block(-4,-10,-5,SANDSTONE)
Block(-4,-10,-4,SANDSTONE)
Block(-4,-10,-3,SANDSTONE)
Block(-4,-10,-2,SANDSTONE)
Block(-4,-10,-1,SANDSTONE)
Block(-4,-10,0,SANDSTONE)
Block(-4,-10,1,SANDSTONE)
Block(-4,-10,2,SANDSTONE)
Block(-4,-10,3,SANDSTONE)
Block(-4,-10,4,SANDSTONE)
Block(-4,-10,5,SANDSTONE)
Block(-4,-10,6,SANDSTONE)
Block(-4,-10,7,SANDSTONE)
Block(-4,-10,8,SANDSTONE)
Block(-4,-10,9,SANDSTONE)
Block(-4,-10,10,SANDSTONE)
Block(-4,-10,11,SANDSTONE)
Block(-4,-9,-9,SANDSTONE)
Block(-4,-9,-8,SANDSTONE)
Block(-4,-9,-7,SANDSTONE)
Block(-4,-9,-6,SANDSTONE)
Block(-4,-9,-5,SANDSTONE)
Block(-4,-9,-4,SANDSTONE)
Block(-4,-9,-3,SANDSTONE)
Block(-4,-9,-2,SANDSTONE)
Block(-4,-9,-1,SANDSTONE)
Block(-4,-9,0,SANDSTONE)
Block(-4,-9,1,SANDSTONE)
Block(-4,-9,2,SANDSTONE)
Block(-4,-9,3,SANDSTONE)
Block(-4,-9,4,SANDSTONE)
Block(-4,-9,5,SANDSTONE)
Block(-4,-9,6,SANDSTONE)
Block(-4,-9,7,SANDSTONE)
Block(-4,-9,8,SANDSTONE)
Block(-4,-9,9,SANDSTONE)
Block(-4,-9,10,SANDSTONE)
Block(-4,-9,11,SANDSTONE)
Block(-4,-8,-9,SANDSTONE)
Block(-4,-8,-8,SANDSTONE)
Block(-4,-8,-7,SANDSTONE)
Block(-4,-8,-6,SANDSTONE)
Block(-4,-8,-5,SANDSTONE)
Block(-4,-8,-4,SANDSTONE)
Block(-4,-8,-3,SANDSTONE)
Block(-4,-8,-2,SANDSTONE)
Block(-4,-8,-1,SANDSTONE)
Block(-4,-8,0,SANDSTONE)
Block(-4,-8,1,SANDSTONE)
Block(-4,-8,2,SANDSTONE)
Block(-4,-8,3,SANDSTONE)
Block(-4,-8,4,SANDSTONE)
Block(-4,-8,5,SANDSTONE)
Block(-4,-8,6,SANDSTONE)
Block(-4,-8,7,SANDSTONE)
Block(-4,-8,8,SANDSTONE)
Block(-4,-8,9,SANDSTONE)
Block(-4,-8,10,SANDSTONE)
Block(-4,-8,11,SANDSTONE)
Block(-4,-7,-9,SANDSTONE)
Block(-4,-7,-8,SANDSTONE)
Block(-4,-7,-7,SANDSTONE)
Block(-4,-7,-6,SANDSTONE)
Block(-4,-7,-5,SANDSTONE)
Block(-4,-7,-4,SANDSTONE)
Block(-4,-7,-3,SANDSTONE)
Block(-4,-7,-2,SANDSTONE)
Block(-4,-7,-1,SANDSTONE)
Block(-4,-7,0,SANDSTONE)
Block(-4,-7,1,SANDSTONE)
Block(-4,-7,2,SANDSTONE)
Block(-4,-7,3,SANDSTONE)
Block(-4,-7,4,SANDSTONE)
Block(-4,-7,5,SANDSTONE)
Block(-4,-7,6,SANDSTONE)
Block(-4,-7,7,SANDSTONE)
Block(-4,-7,8,SANDSTONE)
Block(-4,-7,9,SANDSTONE)
Block(-4,-7,10,SANDSTONE)
Block(-4,-7,11,SANDSTONE)
Block(-4,-6,-9,SANDSTONE)
Block(-4,-6,-8,SANDSTONE)
Block(-4,-6,-7,SANDSTONE)
Block(-4,-6,-6,SANDSTONE)
Block(-4,-6,-5,SANDSTONE)
Block(-4,-6,-4,SANDSTONE)
Block(-4,-6,-3,SANDSTONE)
Block(-4,-6,-2,SANDSTONE)
Block(-4,-6,-1,SANDSTONE)
Block(-4,-6,0,SANDSTONE)
Block(-4,-6,1,SANDSTONE)
Block(-4,-6,2,SANDSTONE)
Block(-4,-6,3,SANDSTONE)
Block(-4,-6,4,SANDSTONE)
Block(-4,-6,5,SANDSTONE)
Block(-4,-6,6,SANDSTONE)
Block(-4,-6,7,SANDSTONE)
Block(-4,-6,8,SANDSTONE)
Block(-4,-6,9,SANDSTONE)
Block(-4,-6,10,SANDSTONE)
Block(-4,-6,11,SANDSTONE)
Block(-4,-5,-9,SANDSTONE)
Block(-4,-5,-8,SANDSTONE)
Block(-4,-5,-7,SANDSTONE)
Block(-4,-5,-6,SANDSTONE)
Block(-4,-5,-5,SANDSTONE)
Block(-4,-5,-4,SANDSTONE)
Block(-4,-5,-3,SANDSTONE)
Block(-4,-5,-2,SANDSTONE)
Block(-4,-5,-1,SANDSTONE)
Block(-4,-5,0,SANDSTONE)
Block(-4,-5,1,SANDSTONE)
Block(-4,-5,2,SANDSTONE)
Block(-4,-5,3,SANDSTONE)
Block(-4,-5,4,SANDSTONE)
Block(-4,-5,5,SANDSTONE)
Block(-4,-5,6,SANDSTONE)
Block(-4,-5,7,SANDSTONE)
Block(-4,-5,8,SANDSTONE)
Block(-4,-5,9,SANDSTONE)
Block(-4,-5,10,SANDSTONE)
Block(-4,-5,11,SANDSTONE)
Block(-4,-4,-9,SANDSTONE)
Block(-4,-4,-8,SANDSTONE)
Block(-4,-4,-7,SANDSTONE)
Block(-4,-4,-6,SANDSTONE)
Block(-4,-4,-5,SANDSTONE)
Block(-4,-4,-4,SANDSTONE)
Block(-4,-4,-3,SANDSTONE)
Block(-4,-4,-2,SANDSTONE)
Block(-4,-4,-1,SANDSTONE)
Block(-4,-4,0,SANDSTONE)
Block(-4,-4,1,SANDSTONE)
Block(-4,-4,2,SANDSTONE)
Block(-4,-4,3,SANDSTONE)
Block(-4,-4,4,SANDSTONE)
Block(-4,-4,5,SANDSTONE)
Block(-4,-4,6,SANDSTONE)
Block(-4,-4,7,SANDSTONE)
Block(-4,-4,8,SANDSTONE)
Block(-4,-4,9,SANDSTONE)
Block(-4,-4,10,SANDSTONE)
Block(-4,-4,11,SANDSTONE)
Block(-4,-3,-9,SANDSTONE)
Block(-4,-3,-8,SANDSTONE)
Block(-4,-3,-7,SANDSTONE)
Block(-4,-3,-6,SANDSTONE)
Block(-4,-3,-5,SANDSTONE)
Block(-4,-3,-4,SANDSTONE)
Block(-4,-3,-3,SANDSTONE)
Block(-4,-3,-2,SANDSTONE)
Block(-4,-3,-1,SANDSTONE)
Block(-4,-3,0,SANDSTONE)
Block(-4,-3,1,SANDSTONE)
Block(-4,-3,2,SANDSTONE)
Block(-4,-3,3,SANDSTONE)
Block(-4,-3,4,SANDSTONE)
Block(-4,-3,5,SANDSTONE)
Block(-4,-3,6,SANDSTONE)
Block(-4,-3,7,SANDSTONE)
Block(-4,-3,8,SANDSTONE)
Block(-4,-3,9,SANDSTONE)
Block(-4,-3,10,SANDSTONE)
Block(-4,-3,11,SANDSTONE)
Block(-4,-2,-9,SANDSTONE)
Block(-4,-2,-8,SANDSTONE)
Block(-4,-2,-7,SANDSTONE)
Block(-4,-2,-6,SANDSTONE)
Block(-4,-2,-5,SANDSTONE)
Block(-4,-2,-4,SANDSTONE)
Block(-4,-2,-3,SANDSTONE)
Block(-4,-2,-2,SANDSTONE)
Block(-4,-2,-1,SANDSTONE)
Block(-4,-2,0,SANDSTONE)
Block(-4,-2,1,SANDSTONE)
Block(-4,-2,2,SANDSTONE)
Block(-4,-2,3,SANDSTONE)
Block(-4,-2,4,SANDSTONE)
Block(-4,-2,5,SANDSTONE)
Block(-4,-2,6,SANDSTONE)
Block(-4,-2,7,SANDSTONE)
Block(-4,-2,8,SANDSTONE)
Block(-4,-2,9,SANDSTONE)
Block(-4,-2,10,SANDSTONE)
Block(-4,-2,11,SANDSTONE)
Block(-4,-1,-9,SANDSTONE)
Block(-4,-1,-8,SANDSTONE)
Block(-4,-1,-7,SANDSTONE)
Block(-4,-1,-6,SANDSTONE)
Block(-4,-1,-5,SANDSTONE)
Block(-4,-1,-4,SANDSTONE)
Block(-4,-1,-3,SANDSTONE)
Block(-4,-1,-2,SANDSTONE)
Block(-4,-1,-1,SANDSTONE)
Block(-4,-1,0,SANDSTONE)
Block(-4,-1,1,SANDSTONE)
Block(-4,-1,2,SANDSTONE)
Block(-4,-1,3,SANDSTONE)
Block(-4,-1,4,SANDSTONE)
Block(-4,-1,5,SANDSTONE)
Block(-4,-1,6,SANDSTONE)
Block(-4,-1,7,SANDSTONE)
Block(-4,-1,8,SANDSTONE)
Block(-4,-1,9,SANDSTONE)
Block(-4,-1,10,SANDSTONE)
Block(-4,-1,11,SANDSTONE)
Block(-4,0,-9,SANDSTONE)
Block(-4,0,-8,SANDSTONE)
Block(-4,0,-7,SANDSTONE)
Block(-4,0,-6,SANDSTONE)
Block(-4,0,-5,SANDSTONE)
Block(-4,0,-4,SANDSTONE)
Block(-4,0,-3,SANDSTONE)
Block(-4,0,-2,SANDSTONE)
Block(-4,0,-1,SANDSTONE)
Block(-4,0,0,SANDSTONE)
Block(-4,0,1,SANDSTONE)
Block(-4,0,2,SANDSTONE)
Block(-4,0,3,SANDSTONE)
Block(-4,0,4,SANDSTONE)
Block(-4,0,5,SANDSTONE)
Block(-4,0,6,SANDSTONE)
Block(-4,0,7,SANDSTONE)
Block(-4,0,8,SANDSTONE)
Block(-4,0,9,SANDSTONE)
Block(-4,0,10,SANDSTONE)
Block(-4,0,11,SANDSTONE)
Block(-4,1,-9,AIR)
Block(-4,1,-8,SANDSTONE)
Block(-4,1,-7,AIR)
Block(-4,1,-6,SANDSTONE)
Block(-4,1,-5,SANDSTONE:2)
Block(-4,1,-4,AIR)
Block(-4,1,-3,AIR)
Block(-4,1,-2,AIR)
Block(-4,1,-1,AIR)
Block(-4,1,0,AIR)
Block(-4,1,1,AIR)
Block(-4,1,2,AIR)
Block(-4,1,3,AIR)
Block(-4,1,4,AIR)
Block(-4,1,5,AIR)
Block(-4,1,6,AIR)
Block(-4,1,7,SANDSTONE:2)
Block(-4,1,8,AIR)
Block(-4,1,9,AIR)
Block(-4,1,10,SANDSTONE)
Block(-4,1,11,AIR)
Block(-4,2,-9,AIR)
Block(-4,2,-8,SANDSTONE)
Block(-4,2,-7,AIR)
Block(-4,2,-6,SANDSTONE)
Block(-4,2,-5,SANDSTONE:1)
Block(-4,2,-4,AIR)
Block(-4,2,-3,AIR)
Block(-4,2,-2,AIR)
Block(-4,2,-1,AIR)
Block(-4,2,0,AIR)
Block(-4,2,1,AIR)
Block(-4,2,2,AIR)
Block(-4,2,3,AIR)
Block(-4,2,4,AIR)
Block(-4,2,5,AIR)
Block(-4,2,6,AIR)
Block(-4,2,7,SANDSTONE:1)
Block(-4,2,8,AIR)
Block(-4,2,9,SANDSTONE)
Block(-4,2,10,AIR)
Block(-4,2,11,AIR)
Block(-4,3,-9,AIR)
Block(-4,3,-8,SANDSTONE)
RandomBlock(-4,3,-7,SANDSTONE,44,AIR,100)
Block(-4,3,-6,SANDSTONE)
Block(-4,3,-5,SANDSTONE:2)
Block(-4,3,-4,AIR)
Block(-4,3,-3,AIR)
Block(-4,3,-2,AIR)
Block(-4,3,-1,AIR)
Block(-4,3,0,AIR)
Block(-4,3,1,AIR)
Block(-4,3,2,AIR)
Block(-4,3,3,AIR)
Block(-4,3,4,AIR)
Block(-4,3,5,AIR)
Block(-4,3,6,AIR)
Block(-4,3,7,SANDSTONE:2)
Block(-4,3,8,SANDSTONE)
Block(-4,3,9,AIR)
Block(-4,3,10,AIR)
Block(-4,3,11,AIR)
Block(-4,4,-9,AIR)
Block(-4,4,-8,AIR)
Block(-4,4,-7,AIR)
RandomBlock(-4,4,-6,SAND,44,AIR,100)
Block(-4,4,-5,SANDSTONE)
Block(-4,4,-4,SANDSTONE)
Block(-4,4,-3,SANDSTONE)
Block(-4,4,-2,SANDSTONE)
Block(-4,4,-1,SANDSTONE)
Block(-4,4,0,SANDSTONE)
Block(-4,4,1,SANDSTONE)
Block(-4,4,2,SANDSTONE)
Block(-4,4,3,SANDSTONE)
Block(-4,4,4,SANDSTONE)
Block(-4,4,5,SANDSTONE)
Block(-4,4,6,SANDSTONE)
Block(-4,4,7,SANDSTONE)
Block(-4,4,8,AIR)
Block(-4,4,9,AIR)
Block(-4,4,10,AIR)
Block(-4,4,11,AIR)
Block(-4,5,-9,AIR)
Block(-4,5,-8,AIR)
Block(-4,5,-7,AIR)
Block(-4,5,-6,AIR)
Block(-4,5,-5,AIR)
Block(-4,5,-4,SANDSTONE)
Block(-4,5,-3,AIR)
Block(-4,5,-2,AIR)
Block(-4,5,-1,AIR)
Block(-4,5,0,SANDSTONE:2)
Block(-4,5,1,AIR)
Block(-4,5,2,SANDSTONE:2)
RandomBlock(-4,5,3,SAND,44,AIR,100)
Block(-4,5,4,AIR)
Block(-4,5,5,AIR)
Block(-4,5,6,SANDSTONE)
Block(-4,5,7,AIR)
Block(-4,5,8,AIR)
Block(-4,5,9,AIR)
Block(-4,5,10,AIR)
Block(-4,5,11,AIR)
Block(-4,6,-9,AIR)
Block(-4,6,-8,AIR)
Block(-4,6,-7,AIR)
Block(-4,6,-6,AIR)
Block(-4,6,-5,AIR)
Block(-4,6,-4,AIR)
Block(-4,6,-3,SANDSTONE)
Block(-4,6,-2,SANDSTONE)
Block(-4,6,-1,SANDSTONE)
Block(-4,6,0,SANDSTONE:1)
Block(-4,6,1,AIR)
Block(-4,6,2,SANDSTONE:1)
Block(-4,6,3,SANDSTONE)
Block(-4,6,4,SANDSTONE)
Block(-4,6,5,SANDSTONE)
Block(-4,6,6,AIR)
Block(-4,6,7,AIR)
Block(-4,6,8,AIR)
Block(-4,6,9,AIR)
Block(-4,6,10,AIR)
Block(-4,6,11,AIR)
Block(-4,7,-9,AIR)
Block(-4,7,-8,AIR)
Block(-4,7,-7,AIR)
Block(-4,7,-6,AIR)
Block(-4,7,-5,AIR)
Block(-4,7,-4,AIR)
Block(-4,7,-3,AIR)
Block(-4,7,-2,AIR)
Block(-4,7,-1,AIR)
Block(-4,7,0,SANDSTONE)
Block(-4,7,1,SANDSTONE)
Block(-4,7,2,SANDSTONE)
Block(-4,7,3,AIR)
Block(-4,7,4,AIR)
Block(-4,7,5,AIR)
Block(-4,7,6,AIR)
Block(-4,7,7,AIR)
Block(-4,7,8,AIR)
Block(-4,7,9,AIR)
Block(-4,7,10,AIR)
Block(-4,7,11,AIR)
Block(-4,8,-9,AIR)
Block(-4,8,-8,AIR)
Block(-4,8,-7,AIR)
Block(-4,8,-6,AIR)
Block(-4,8,-5,AIR)
Block(-4,8,-4,AIR)
Block(-4,8,-3,AIR)
Block(-4,8,-2,AIR)
Block(-4,8,-1,AIR)
Block(-4,8,0,AIR)
Block(-4,8,1,AIR)
RandomBlock(-4,8,2,SAND,44,AIR,100)
Block(-4,8,3,AIR)
Block(-4,8,4,AIR)
Block(-4,8,5,AIR)
Block(-4,8,6,AIR)
Block(-4,8,7,AIR)
Block(-4,8,8,AIR)
Block(-4,8,9,AIR)
Block(-4,8,10,AIR)
Block(-4,8,11,AIR)
Block(-4,9,-9,AIR)
Block(-4,9,-8,AIR)
Block(-4,9,-7,AIR)
Block(-4,9,-6,AIR)
Block(-4,9,-5,AIR)
Block(-4,9,-4,AIR)
Block(-4,9,-3,AIR)
Block(-4,9,-2,AIR)
Block(-4,9,-1,AIR)
Block(-4,9,0,AIR)
Block(-4,9,1,AIR)
Block(-4,9,2,AIR)
Block(-4,9,3,AIR)
Block(-4,9,4,AIR)
Block(-4,9,5,AIR)
Block(-4,9,6,AIR)
Block(-4,9,7,AIR)
Block(-4,9,8,AIR)
Block(-4,9,9,AIR)
Block(-4,9,10,AIR)
Block(-4,9,11,AIR)
Block(-4,10,-9,AIR)
Block(-4,10,-8,AIR)
Block(-4,10,-7,AIR)
Block(-4,10,-6,AIR)
Block(-4,10,-5,AIR)
Block(-4,10,-4,AIR)
Block(-4,10,-3,AIR)
Block(-4,10,-2,AIR)
Block(-4,10,-1,AIR)
Block(-4,10,0,AIR)
Block(-4,10,1,AIR)
Block(-4,10,2,AIR)
Block(-4,10,3,AIR)
Block(-4,10,4,AIR)
Block(-4,10,5,AIR)
Block(-4,10,6,AIR)
Block(-4,10,7,AIR)
Block(-4,10,8,AIR)
Block(-4,10,9,AIR)
Block(-4,10,10,AIR)
Block(-4,10,11,AIR)
Block(-3,-13,-9,SANDSTONE)
Block(-3,-13,-8,SANDSTONE)
Block(-3,-13,-7,SANDSTONE)
Block(-3,-13,-6,SANDSTONE)
Block(-3,-13,-5,SANDSTONE)
Block(-3,-13,-4,SANDSTONE)
Block(-3,-13,-3,SANDSTONE)
Block(-3,-13,-2,SANDSTONE)
Block(-3,-13,-1,SANDSTONE)
Block(-3,-13,0,SANDSTONE)
Block(-3,-13,1,SANDSTONE)
Block(-3,-13,2,SANDSTONE)
Block(-3,-13,3,SANDSTONE)
Block(-3,-13,4,SANDSTONE)
Block(-3,-13,5,SANDSTONE)
Block(-3,-13,6,SANDSTONE)
Block(-3,-13,7,SANDSTONE)
Block(-3,-13,8,SANDSTONE)
Block(-3,-13,9,SANDSTONE)
Block(-3,-13,10,SANDSTONE)
Block(-3,-13,11,SANDSTONE)
Block(-3,-12,-9,SANDSTONE)
Block(-3,-12,-8,SANDSTONE)
Block(-3,-12,-7,SANDSTONE)
Block(-3,-12,-6,SANDSTONE)
Block(-3,-12,-5,SANDSTONE)
Block(-3,-12,-4,SANDSTONE)
Block(-3,-12,-3,SANDSTONE)
Block(-3,-12,-2,SANDSTONE)
Block(-3,-12,-1,SANDSTONE)
Block(-3,-12,0,SANDSTONE)
Block(-3,-12,1,SANDSTONE)
Block(-3,-12,2,SANDSTONE)
Block(-3,-12,3,SANDSTONE)
Block(-3,-12,4,SANDSTONE)
Block(-3,-12,5,SANDSTONE)
Block(-3,-12,6,SANDSTONE)
Block(-3,-12,7,SANDSTONE)
Block(-3,-12,8,SANDSTONE)
Block(-3,-12,9,SANDSTONE)
Block(-3,-12,10,SANDSTONE)
Block(-3,-12,11,SANDSTONE)
Block(-3,-11,-9,SANDSTONE)
Block(-3,-11,-8,SANDSTONE)
Block(-3,-11,-7,SANDSTONE)
Block(-3,-11,-6,SANDSTONE)
Block(-3,-11,-5,SANDSTONE)
Block(-3,-11,-4,SANDSTONE)
Block(-3,-11,-3,SANDSTONE)
Block(-3,-11,-2,DOUBLE_STEP:1)
Block(-3,-11,-1,STEP:1)
Block(-3,-11,0,SANDSTONE)
Block(-3,-11,1,SANDSTONE:2)
Block(-3,-11,2,SANDSTONE)
Block(-3,-11,3,STEP:1)
Block(-3,-11,4,DOUBLE_STEP:1)
Block(-3,-11,5,SANDSTONE)
Block(-3,-11,6,SANDSTONE)
Block(-3,-11,7,SANDSTONE)
Block(-3,-11,8,SANDSTONE)
Block(-3,-11,9,SANDSTONE)
Block(-3,-11,10,SANDSTONE)
Block(-3,-11,11,SANDSTONE)
Block(-3,-10,-9,SANDSTONE)
Block(-3,-10,-8,SANDSTONE)
Block(-3,-10,-7,SANDSTONE)
Block(-3,-10,-6,SANDSTONE)
Block(-3,-10,-5,SANDSTONE)
Block(-3,-10,-4,SANDSTONE)
Block(-3,-10,-3,SANDSTONE)
RandomBlock(-3,-10,-2,CHEST,../../nbt/VanillaLoot/simple_dungeon.nbt,50,CHEST,../../nbt/VanillaLoot/abandoned_mineshaft.nbt,30,CHEST,../../nbt/VanillaLoot/desert_pyramid.nbt,100)
Block(-3,-10,-1,AIR)
Block(-3,-10,0,SANDSTONE)
Block(-3,-10,1,DISPENSER:5,../../nbt/Misc/LavaBucket.nbt)
Block(-3,-10,2,SANDSTONE)
Block(-3,-10,3,AIR)
Block(-3,-10,4,SKULL:1,../../nbt/Misc/Skull.nbt,50,AIR,100)
Block(-3,-10,5,SANDSTONE)
Block(-3,-10,6,SANDSTONE)
Block(-3,-10,7,SANDSTONE)
Block(-3,-10,8,SANDSTONE)
Block(-3,-10,9,SANDSTONE)
Block(-3,-10,10,SANDSTONE)
Block(-3,-10,11,SANDSTONE)
Block(-3,-9,-9,SANDSTONE)
Block(-3,-9,-8,SANDSTONE)
Block(-3,-9,-7,SANDSTONE)
Block(-3,-9,-6,SANDSTONE)
Block(-3,-9,-5,SANDSTONE)
Block(-3,-9,-4,SANDSTONE)
Block(-3,-9,-3,SANDSTONE)
Block(-3,-9,-2,AIR)
Block(-3,-9,-1,AIR)
Block(-3,-9,0,SANDSTONE)
Block(-3,-9,1,SANDSTONE:1)
Block(-3,-9,2,SANDSTONE)
Block(-3,-9,3,AIR)
Block(-3,-9,4,AIR)
Block(-3,-9,5,SANDSTONE)
Block(-3,-9,6,SANDSTONE)
Block(-3,-9,7,SANDSTONE)
Block(-3,-9,8,SANDSTONE)
Block(-3,-9,9,SANDSTONE)
Block(-3,-9,10,SANDSTONE)
Block(-3,-9,11,SANDSTONE)
Block(-3,-8,-9,SANDSTONE)
Block(-3,-8,-8,SANDSTONE)
Block(-3,-8,-7,SANDSTONE)
Block(-3,-8,-6,SANDSTONE)
Block(-3,-8,-5,SANDSTONE)
Block(-3,-8,-4,SANDSTONE)
Block(-3,-8,-3,SANDSTONE)
Block(-3,-8,-2,SANDSTONE)
Block(-3,-8,-1,SANDSTONE)
Block(-3,-8,0,SANDSTONE)
Block(-3,-8,1,SANDSTONE)
Block(-3,-8,2,SANDSTONE)
Block(-3,-8,3,SANDSTONE)
Block(-3,-8,4,SANDSTONE)
Block(-3,-8,5,SANDSTONE)
Block(-3,-8,6,SANDSTONE)
Block(-3,-8,7,SANDSTONE)
Block(-3,-8,8,SANDSTONE)
Block(-3,-8,9,SANDSTONE)
Block(-3,-8,10,SANDSTONE)
Block(-3,-8,11,SANDSTONE)
Block(-3,-7,-9,SANDSTONE)
Block(-3,-7,-8,SANDSTONE)
Block(-3,-7,-7,SANDSTONE)
Block(-3,-7,-6,SANDSTONE)
Block(-3,-7,-5,SANDSTONE)
Block(-3,-7,-4,SANDSTONE)
Block(-3,-7,-3,SANDSTONE)
Block(-3,-7,-2,SANDSTONE)
Block(-3,-7,-1,SANDSTONE)
Block(-3,-7,0,SANDSTONE)
Block(-3,-7,1,SANDSTONE)
Block(-3,-7,2,SANDSTONE)
Block(-3,-7,3,SANDSTONE)
Block(-3,-7,4,SANDSTONE)
Block(-3,-7,5,SANDSTONE)
Block(-3,-7,6,SANDSTONE)
Block(-3,-7,7,SANDSTONE)
Block(-3,-7,8,SANDSTONE)
Block(-3,-7,9,SANDSTONE)
Block(-3,-7,10,SANDSTONE)
Block(-3,-7,11,SANDSTONE)
Block(-3,-6,-9,SANDSTONE)
Block(-3,-6,-8,SANDSTONE)
Block(-3,-6,-7,SANDSTONE)
Block(-3,-6,-6,SANDSTONE)
Block(-3,-6,-5,SANDSTONE)
Block(-3,-6,-4,SANDSTONE)
Block(-3,-6,-3,SANDSTONE)
Block(-3,-6,-2,SANDSTONE)
Block(-3,-6,-1,SANDSTONE)
Block(-3,-6,0,SANDSTONE)
Block(-3,-6,1,SANDSTONE)
Block(-3,-6,2,SANDSTONE)
Block(-3,-6,3,SANDSTONE)
Block(-3,-6,4,SANDSTONE)
Block(-3,-6,5,SANDSTONE)
Block(-3,-6,6,SANDSTONE)
Block(-3,-6,7,SANDSTONE)
Block(-3,-6,8,SANDSTONE)
Block(-3,-6,9,SANDSTONE)
Block(-3,-6,10,SANDSTONE)
Block(-3,-6,11,SANDSTONE)
Block(-3,-5,-9,SANDSTONE)
Block(-3,-5,-8,SANDSTONE)
Block(-3,-5,-7,SANDSTONE)
Block(-3,-5,-6,SANDSTONE)
Block(-3,-5,-5,SANDSTONE)
Block(-3,-5,-4,SANDSTONE)
Block(-3,-5,-3,SANDSTONE)
Block(-3,-5,-2,SANDSTONE)
Block(-3,-5,-1,SANDSTONE)
Block(-3,-5,0,SANDSTONE)
Block(-3,-5,1,SANDSTONE)
Block(-3,-5,2,SANDSTONE)
Block(-3,-5,3,SANDSTONE)
Block(-3,-5,4,SANDSTONE)
Block(-3,-5,5,SANDSTONE)
Block(-3,-5,6,SANDSTONE)
Block(-3,-5,7,SANDSTONE)
Block(-3,-5,8,SANDSTONE)
Block(-3,-5,9,SANDSTONE)
Block(-3,-5,10,SANDSTONE)
Block(-3,-5,11,SANDSTONE)
Block(-3,-4,-9,SANDSTONE)
Block(-3,-4,-8,SANDSTONE)
Block(-3,-4,-7,SANDSTONE)
Block(-3,-4,-6,SANDSTONE)
Block(-3,-4,-5,SANDSTONE)
Block(-3,-4,-4,SANDSTONE)
Block(-3,-4,-3,SANDSTONE)
Block(-3,-4,-2,SANDSTONE)
Block(-3,-4,-1,SANDSTONE)
Block(-3,-4,0,SANDSTONE)
Block(-3,-4,1,SANDSTONE)
Block(-3,-4,2,SANDSTONE)
Block(-3,-4,3,SANDSTONE)
Block(-3,-4,4,SANDSTONE)
Block(-3,-4,5,SANDSTONE)
Block(-3,-4,6,SANDSTONE)
Block(-3,-4,7,SANDSTONE)
Block(-3,-4,8,SANDSTONE)
Block(-3,-4,9,SANDSTONE)
Block(-3,-4,10,SANDSTONE)
Block(-3,-4,11,SANDSTONE)
Block(-3,-3,-9,SANDSTONE)
Block(-3,-3,-8,SANDSTONE)
Block(-3,-3,-7,SANDSTONE)
Block(-3,-3,-6,SANDSTONE)
Block(-3,-3,-5,SANDSTONE)
Block(-3,-3,-4,SANDSTONE)
Block(-3,-3,-3,SANDSTONE)
Block(-3,-3,-2,SANDSTONE)
Block(-3,-3,-1,SANDSTONE)
Block(-3,-3,0,SANDSTONE)
Block(-3,-3,1,SANDSTONE)
Block(-3,-3,2,SANDSTONE)
Block(-3,-3,3,SANDSTONE)
Block(-3,-3,4,SANDSTONE)
Block(-3,-3,5,SANDSTONE)
Block(-3,-3,6,SANDSTONE)
Block(-3,-3,7,SANDSTONE)
Block(-3,-3,8,SANDSTONE)
Block(-3,-3,9,SANDSTONE)
Block(-3,-3,10,SANDSTONE)
Block(-3,-3,11,SANDSTONE)
Block(-3,-2,-9,SANDSTONE)
Block(-3,-2,-8,SANDSTONE)
Block(-3,-2,-7,SANDSTONE)
Block(-3,-2,-6,SANDSTONE)
Block(-3,-2,-5,SANDSTONE)
Block(-3,-2,-4,SANDSTONE)
Block(-3,-2,-3,SANDSTONE)
Block(-3,-2,-2,SANDSTONE)
Block(-3,-2,-1,SANDSTONE)
Block(-3,-2,0,SANDSTONE)
Block(-3,-2,1,SANDSTONE)
Block(-3,-2,2,SANDSTONE)
Block(-3,-2,3,SANDSTONE)
Block(-3,-2,4,SANDSTONE)
Block(-3,-2,5,SANDSTONE)
Block(-3,-2,6,SANDSTONE)
Block(-3,-2,7,SANDSTONE)
Block(-3,-2,8,SANDSTONE)
Block(-3,-2,9,SANDSTONE)
Block(-3,-2,10,SANDSTONE)
Block(-3,-2,11,SANDSTONE)
Block(-3,-1,-9,SANDSTONE)
Block(-3,-1,-8,SANDSTONE)
Block(-3,-1,-7,SANDSTONE)
Block(-3,-1,-6,SANDSTONE)
Block(-3,-1,-5,SANDSTONE)
Block(-3,-1,-4,SANDSTONE)
Block(-3,-1,-3,SANDSTONE)
Block(-3,-1,-2,SANDSTONE)
Block(-3,-1,-1,SANDSTONE)
Block(-3,-1,0,SANDSTONE)
Block(-3,-1,1,SANDSTONE)
Block(-3,-1,2,SANDSTONE)
Block(-3,-1,3,SANDSTONE)
Block(-3,-1,4,SANDSTONE)
Block(-3,-1,5,SANDSTONE)
Block(-3,-1,6,SANDSTONE)
Block(-3,-1,7,SANDSTONE)
Block(-3,-1,8,SANDSTONE)
Block(-3,-1,9,SANDSTONE)
Block(-3,-1,10,SANDSTONE)
Block(-3,-1,11,SANDSTONE)
Block(-3,0,-9,SANDSTONE)
Block(-3,0,-8,SANDSTONE)
Block(-3,0,-7,SANDSTONE)
Block(-3,0,-6,SANDSTONE)
Block(-3,0,-5,SANDSTONE)
Block(-3,0,-4,SANDSTONE)
Block(-3,0,-3,SANDSTONE)
Block(-3,0,-2,SANDSTONE)
Block(-3,0,-1,SANDSTONE)
Block(-3,0,0,SANDSTONE)
Block(-3,0,1,WOOL:7)
Block(-3,0,2,SANDSTONE)
Block(-3,0,3,SANDSTONE)
Block(-3,0,4,SANDSTONE)
Block(-3,0,5,SANDSTONE)
Block(-3,0,6,SANDSTONE)
Block(-3,0,7,SANDSTONE)
Block(-3,0,8,SANDSTONE)
Block(-3,0,9,SANDSTONE)
Block(-3,0,10,SANDSTONE)
Block(-3,0,11,SANDSTONE)
Block(-3,1,-9,AIR)
Block(-3,1,-8,SANDSTONE)
Block(-3,1,-7,AIR)
Block(-3,1,-6,SANDSTONE)
Block(-3,1,-5,AIR)
Block(-3,1,-4,AIR)
Block(-3,1,-3,AIR)
Block(-3,1,-2,AIR)
Block(-3,1,-1,AIR)
Block(-3,1,0,AIR)
Block(-3,1,1,AIR)
Block(-3,1,2,AIR)
Block(-3,1,3,AIR)
Block(-3,1,4,AIR)
Block(-3,1,5,AIR)
Block(-3,1,6,AIR)
Block(-3,1,7,AIR)
Block(-3,1,8,AIR)
Block(-3,1,9,AIR)
Block(-3,1,10,SANDSTONE)
Block(-3,1,11,AIR)
Block(-3,2,-9,AIR)
Block(-3,2,-8,SANDSTONE)
Block(-3,2,-7,AIR)
Block(-3,2,-6,SANDSTONE)
Block(-3,2,-5,AIR)
Block(-3,2,-4,AIR)
Block(-3,2,-3,AIR)
Block(-3,2,-2,AIR)
Block(-3,2,-1,AIR)
Block(-3,2,0,AIR)
Block(-3,2,1,AIR)
Block(-3,2,2,AIR)
Block(-3,2,3,AIR)
Block(-3,2,4,AIR)
Block(-3,2,5,AIR)
Block(-3,2,6,AIR)
Block(-3,2,7,AIR)
Block(-3,2,8,AIR)
Block(-3,2,9,SANDSTONE)
Block(-3,2,10,AIR)
Block(-3,2,11,AIR)
Block(-3,3,-9,AIR)
Block(-3,3,-8,SANDSTONE)
Block(-3,3,-7,SANDSTONE)
Block(-3,3,-6,SANDSTONE)
Block(-3,3,-5,SANDSTONE:2)
Block(-3,3,-4,AIR)
Block(-3,3,-3,AIR)
Block(-3,3,-2,AIR)
Block(-3,3,-1,AIR)
Block(-3,3,0,AIR)
Block(-3,3,1,AIR)
Block(-3,3,2,AIR)
Block(-3,3,3,AIR)
Block(-3,3,4,AIR)
Block(-3,3,5,AIR)
Block(-3,3,6,AIR)
Block(-3,3,7,SANDSTONE:2)
Block(-3,3,8,SANDSTONE)
Block(-3,3,9,AIR)
Block(-3,3,10,AIR)
Block(-3,3,11,AIR)
Block(-3,4,-9,AIR)
Block(-3,4,-8,AIR)
Block(-3,4,-7,AIR)
Block(-3,4,-6,AIR)
RandomBlock(-3,4,-5,SANDSTONE,44,AIR,100)
Block(-3,4,-4,SANDSTONE)
Block(-3,4,-3,SANDSTONE)
Block(-3,4,-2,SANDSTONE)
Block(-3,4,-1,SANDSTONE)
Block(-3,4,0,SANDSTONE)
Block(-3,4,1,SANDSTONE)
Block(-3,4,2,SANDSTONE)
Block(-3,4,3,SANDSTONE)
Block(-3,4,4,SANDSTONE)
Block(-3,4,5,SANDSTONE)
Block(-3,4,6,SANDSTONE)
Block(-3,4,7,SANDSTONE)
Block(-3,4,8,AIR)
Block(-3,4,9,AIR)
Block(-3,4,10,AIR)
Block(-3,4,11,AIR)
Block(-3,5,-9,AIR)
Block(-3,5,-8,AIR)
Block(-3,5,-7,AIR)
Block(-3,5,-6,AIR)
Block(-3,5,-5,AIR)
Block(-3,5,-4,SANDSTONE)
Block(-3,5,-3,AIR)
Block(-3,5,-2,AIR)
Block(-3,5,-1,AIR)
Block(-3,5,0,AIR)
Block(-3,5,1,AIR)
Block(-3,5,2,AIR)
Block(-3,5,3,AIR)
Block(-3,5,4,AIR)
Block(-3,5,5,AIR)
Block(-3,5,6,SANDSTONE)
Block(-3,5,7,AIR)
Block(-3,5,8,AIR)
Block(-3,5,9,AIR)
Block(-3,5,10,AIR)
Block(-3,5,11,AIR)
Block(-3,6,-9,AIR)
Block(-3,6,-8,AIR)
Block(-3,6,-7,AIR)
Block(-3,6,-6,AIR)
Block(-3,6,-5,AIR)
Block(-3,6,-4,AIR)
Block(-3,6,-3,SANDSTONE)
Block(-3,6,-2,AIR)
Block(-3,6,-1,AIR)
Block(-3,6,0,AIR)
Block(-3,6,1,AIR)
Block(-3,6,2,AIR)
Block(-3,6,3,AIR)
Block(-3,6,4,AIR)
Block(-3,6,5,SANDSTONE)
Block(-3,6,6,AIR)
Block(-3,6,7,AIR)
Block(-3,6,8,AIR)
Block(-3,6,9,AIR)
Block(-3,6,10,AIR)
Block(-3,6,11,AIR)
Block(-3,7,-9,AIR)
Block(-3,7,-8,AIR)
Block(-3,7,-7,AIR)
Block(-3,7,-6,AIR)
Block(-3,7,-5,AIR)
Block(-3,7,-4,AIR)
Block(-3,7,-3,AIR)
Block(-3,7,-2,SANDSTONE)
RandomBlock(-3,7,-1,SANDSTONE,44,AIR,100)
Block(-3,7,0,SANDSTONE)
Block(-3,7,1,SANDSTONE)
Block(-3,7,2,SANDSTONE)
Block(-3,7,3,SANDSTONE)
Block(-3,7,4,SANDSTONE)
Block(-3,7,5,AIR)
Block(-3,7,6,AIR)
Block(-3,7,7,AIR)
Block(-3,7,8,AIR)
Block(-3,7,9,AIR)
Block(-3,7,10,AIR)
Block(-3,7,11,AIR)
Block(-3,8,-9,AIR)
Block(-3,8,-8,AIR)
Block(-3,8,-7,AIR)
Block(-3,8,-6,AIR)
Block(-3,8,-5,AIR)
Block(-3,8,-4,AIR)
Block(-3,8,-3,AIR)
Block(-3,8,-2,AIR)
Block(-3,8,-1,AIR)
Block(-3,8,0,AIR)
Block(-3,8,1,AIR)
RandomBlock(-3,8,2,SAND,44,AIR,100)
Block(-3,8,3,AIR)
Block(-3,8,4,AIR)
Block(-3,8,5,AIR)
Block(-3,8,6,AIR)
Block(-3,8,7,AIR)
Block(-3,8,8,AIR)
Block(-3,8,9,AIR)
Block(-3,8,10,AIR)
Block(-3,8,11,AIR)
Block(-3,9,-9,AIR)
Block(-3,9,-8,AIR)
Block(-3,9,-7,AIR)
Block(-3,9,-6,AIR)
Block(-3,9,-5,AIR)
Block(-3,9,-4,AIR)
Block(-3,9,-3,AIR)
Block(-3,9,-2,AIR)
Block(-3,9,-1,AIR)
Block(-3,9,0,AIR)
Block(-3,9,1,AIR)
Block(-3,9,2,AIR)
Block(-3,9,3,AIR)
Block(-3,9,4,AIR)
Block(-3,9,5,AIR)
Block(-3,9,6,AIR)
Block(-3,9,7,AIR)
Block(-3,9,8,AIR)
Block(-3,9,9,AIR)
Block(-3,9,10,AIR)
Block(-3,9,11,AIR)
Block(-3,10,-9,AIR)
Block(-3,10,-8,AIR)
Block(-3,10,-7,AIR)
Block(-3,10,-6,AIR)
Block(-3,10,-5,AIR)
Block(-3,10,-4,AIR)
Block(-3,10,-3,AIR)
Block(-3,10,-2,AIR)
Block(-3,10,-1,AIR)
Block(-3,10,0,AIR)
Block(-3,10,1,AIR)
Block(-3,10,2,AIR)
Block(-3,10,3,AIR)
Block(-3,10,4,AIR)
Block(-3,10,5,AIR)
Block(-3,10,6,AIR)
Block(-3,10,7,AIR)
Block(-3,10,8,AIR)
Block(-3,10,9,AIR)
Block(-3,10,10,AIR)
Block(-3,10,11,AIR)
Block(-2,-13,-9,SANDSTONE)
Block(-2,-13,-8,SANDSTONE)
Block(-2,-13,-7,SANDSTONE)
Block(-2,-13,-6,SANDSTONE)
Block(-2,-13,-5,SANDSTONE)
Block(-2,-13,-4,SANDSTONE)
Block(-2,-13,-3,SANDSTONE)
Block(-2,-13,-2,SANDSTONE)
