#######################################################################
# +-----------------------------------------------------------------+ #
# |                            BO3 object                           | #
# +-----------------------------------------------------------------+ #
#######################################################################

# The descriptions in this file are true only for TerrainControl. They are not true for the Minecraft Worlds mod!
# Minecraft Worlds completely reimplemented BO3s, check the MCW documentation on the mc/mctcp forums for how to use BO3s with MCW
# or watch the video's on my YT channel at https://www.youtube.com/user/PeeGee85. You can check out the "Editing and importing schematics & BO3s" 
# series of video's, in part 2 I explain BO3s. 

# This is the config file of a custom object.
# If you add this object correctly to your BiomeConfigs, it will spawn in the world.

# This is the creator of this BO3 object
Author: Unknown

# A short description of this BO3 object
Description: This BO3 was converted from a schematic using the MineCraft Worlds Editor. Unfortunately the author and description information for the schematic could not be found. If you know who the author of the schematic is then please tell the author of this BO3!

# The BO3 version, don't change this! It can be used by external applications to do a version check.
Version: 3

# The settings mode, WriteAll, WriteWithoutComments or WriteDisable. See WorldConfig.
SettingsMode: WriteDisable

#######################################################################
# +-----------------------------------------------------------------+ #
# |                          Main settings                          | #
# +-----------------------------------------------------------------+ #
#######################################################################

# This needs to be set to true to spawn the object in the Tree and Sapling resources.
Tree: false

# The frequency of the BO3 from 1 to 200. Tries this many times to spawn this BO3 when using the CustomObject(...) resource.
# Ignored by Tree(..), Sapling(..) and CustomStructure(..)
Frequency: 40

# The rarity of the BO3 from 0 to 100. Each spawn attempt has rarity% chance to succeed when using the CustomObject(...) resource.
# Ignored by Tree(..), Sapling(..) and CustomStructure(..)
Rarity: 100.0

# If you set this to true, the BO3 will be placed with a random rotation.
RotateRandomly: false

# The spawn height of the BO3 - randomY, highestBlock or highestSolidBlock.
SpawnHeight: randomY

# The height limits for the BO3.
MinHeight: 0

MaxHeight: 45

# Objects can have other objects attached to it: branches. Branches can also
# have branches attached to it, which can also have branches, etc. This is the
# maximum branch depth for this objects.
MaxBranchDepth: 10

# When spawned with the UseWorld keyword, this BO3 should NOT spawn in the following biomes.
# If you writer.write the BO3 name directly in the BiomeConfigs, this will be ignored.
ExcludedBiomes: All

#######################################################################
# +-----------------------------------------------------------------+ #
# |                      Source block settings                      | #
# +-----------------------------------------------------------------+ #
#######################################################################

# The block(s) the BO3 should spawn in.
SourceBlocks: AIR

# The maximum percentage of the BO3 that can be outside the SourceBlock.
# The BO3 won't be placed on a location with more blocks outside the SourceBlock than this percentage.
MaxPercentageOutsideSourceBlock: 100

# What to do when a block is about to be placed outside the SourceBlock? (dontPlace, placeAnyway)
OutsideSourceBlock: placeAnyway

#######################################################################
# +-----------------------------------------------------------------+ #
# |                              Blocks                             | #
# +-----------------------------------------------------------------+ #
#######################################################################

# All the blocks used in the BO3 are listed here. Possible blocks:
# Block(x,y,z,id[.data][,nbtfile.nbt)
# RandomBlock(x,y,z,id[:data][,nbtfile.nbt],chance[,id[:data][,nbtfile.nbt],chance[,...]])
# So RandomBlock(0,0,0,CHEST,chest.nbt,50,CHEST,anotherchest.nbt,100) will spawn a chest at
# the BO3 origin, and give it a 50% chance to have the contents of chest.nbt, or, if that
# fails, a 100% percent chance to have the contents of anotherchest.nbt.

Block(-7,0,4,COBBLESTONE)
Block(-7,0,5,COBBLESTONE)
Block(-7,0,6,COBBLESTONE)
Block(-7,0,7,COBBLESTONE)
Block(-7,0,8,COBBLESTONE)
Block(-7,1,4,COBBLESTONE)
Block(-7,1,5,COBBLESTONE)
Block(-7,1,6,COBBLESTONE)
Block(-7,1,7,COBBLESTONE)
Block(-7,1,8,COBBLESTONE)
Block(-7,2,4,COBBLESTONE)
Block(-7,2,5,COBBLESTONE)
Block(-7,2,6,COBBLESTONE)
Block(-7,2,7,COBBLESTONE)
Block(-7,2,8,COBBLESTONE)
Block(-7,3,4,COBBLESTONE)
Block(-7,3,5,COBBLESTONE)
Block(-7,3,6,COBBLESTONE)
Block(-7,3,7,COBBLESTONE)
Block(-7,3,8,COBBLESTONE)
Block(-7,4,4,COBBLESTONE)
Block(-7,4,5,COBBLESTONE)
Block(-7,4,6,COBBLESTONE)
Block(-7,4,7,COBBLESTONE)
Block(-7,4,8,COBBLESTONE)
Block(-7,5,4,COBBLESTONE)
Block(-7,5,5,COBBLESTONE)
Block(-7,5,6,COBBLESTONE)
Block(-7,5,7,COBBLESTONE)
Block(-7,5,8,COBBLESTONE)
Block(-7,6,4,COBBLESTONE)
Block(-7,6,5,COBBLESTONE)
Block(-7,6,6,COBBLESTONE)
Block(-7,6,7,COBBLESTONE)
Block(-7,6,8,COBBLESTONE)
Block(-7,7,4,COBBLESTONE)
Block(-7,7,5,COBBLESTONE)
Block(-7,7,6,COBBLESTONE)
Block(-7,7,7,COBBLESTONE)
Block(-7,7,8,COBBLESTONE)
Block(-7,8,4,COBBLESTONE)
Block(-7,8,5,COBBLESTONE)
Block(-7,8,6,COBBLESTONE)
Block(-7,8,7,COBBLESTONE)
Block(-7,8,8,COBBLESTONE)
Block(-7,9,4,COBBLESTONE)
Block(-7,9,5,COBBLESTONE)
Block(-7,9,6,COBBLESTONE)
Block(-7,9,7,COBBLESTONE)
Block(-7,9,8,COBBLESTONE)
Block(-7,10,4,COBBLESTONE)
Block(-7,10,5,COBBLESTONE)
Block(-7,10,6,COBBLESTONE)
Block(-7,10,7,COBBLESTONE)
Block(-7,10,8,COBBLESTONE)
Block(-7,11,5,COBBLESTONE)
Block(-7,11,6,COBBLESTONE)
Block(-7,11,7,COBBLESTONE)
Block(-7,11,8,COBBLESTONE)
Block(-7,12,6,COBBLESTONE)
Block(-7,12,7,COBBLESTONE)
Block(-7,12,8,COBBLESTONE)
Block(-7,13,7,COBBLESTONE)
Block(-7,13,8,COBBLESTONE)
Block(-7,14,8,COBBLESTONE)
Block(-6,0,4,COBBLESTONE)
Block(-6,0,5,COBBLESTONE)
Block(-6,0,6,COBBLESTONE)
Block(-6,0,7,COBBLESTONE)
Block(-6,0,8,COBBLESTONE)
Block(-6,1,4,COBBLESTONE)
Block(-6,1,5,COBBLESTONE)
Block(-6,1,6,COBBLESTONE)
Block(-6,1,7,COBBLESTONE)
Block(-6,1,8,COBBLESTONE)
Block(-6,2,4,COBBLESTONE)
Block(-6,2,5,COBBLESTONE)
Block(-6,2,6,COBBLESTONE)
Block(-6,2,7,COBBLESTONE)
Block(-6,2,8,COBBLESTONE)
Block(-6,3,4,COBBLESTONE)
Block(-6,3,5,COBBLESTONE)
Block(-6,3,6,COBBLESTONE)
Block(-6,3,7,COBBLESTONE)
Block(-6,3,8,COBBLESTONE)
Block(-6,4,4,COBBLESTONE)
Block(-6,4,5,COBBLESTONE)
Block(-6,4,6,COBBLESTONE)
Block(-6,4,7,COBBLESTONE)
Block(-6,4,8,COBBLESTONE)
Block(-6,5,4,COBBLESTONE)
Block(-6,5,5,COBBLESTONE)
Block(-6,5,6,COBBLESTONE)
Block(-6,5,7,COBBLESTONE)
Block(-6,5,8,COBBLESTONE)
Block(-6,6,4,COBBLESTONE)
Block(-6,6,5,COBBLESTONE)
Block(-6,6,6,COBBLESTONE)
Block(-6,6,7,COBBLESTONE)
Block(-6,6,8,COBBLESTONE)
Block(-6,7,4,COBBLESTONE)
Block(-6,7,5,COBBLESTONE)
Block(-6,7,6,COBBLESTONE)
Block(-6,7,7,COBBLESTONE)
Block(-6,7,8,COBBLESTONE)
Block(-6,8,4,COBBLESTONE)
Block(-6,8,5,COBBLESTONE)
Block(-6,8,6,COBBLESTONE)
Block(-6,8,7,COBBLESTONE)
Block(-6,8,8,COBBLESTONE)
Block(-6,9,4,COBBLESTONE)
Block(-6,9,5,COBBLESTONE)
Block(-6,9,6,COBBLESTONE)
Block(-6,9,7,COBBLESTONE)
Block(-6,9,8,COBBLESTONE)
Block(-6,10,4,COBBLESTONE)
Block(-6,10,5,COBBLESTONE)
Block(-6,10,6,COBBLESTONE)
Block(-6,10,7,COBBLESTONE)
Block(-6,10,8,COBBLESTONE)
Block(-6,11,5,COBBLESTONE)
Block(-6,11,6,COBBLESTONE)
Block(-6,11,7,COBBLESTONE)
Block(-6,11,8,COBBLESTONE)
Block(-6,12,6,COBBLESTONE)
Block(-6,12,7,COBBLESTONE)
Block(-6,12,8,COBBLESTONE)
Block(-6,13,7,COBBLESTONE)
Block(-6,13,8,COBBLESTONE)
Block(-6,14,8,COBBLESTONE)
Block(-5,0,4,COBBLESTONE)
Block(-5,0,5,COBBLESTONE)
Block(-5,0,6,COBBLESTONE)
Block(-5,0,7,COBBLESTONE)
Block(-5,0,8,COBBLESTONE)
Block(-5,1,4,COBBLESTONE)
Block(-5,1,5,COBBLESTONE)
Block(-5,1,6,COBBLESTONE)
Block(-5,1,7,COBBLESTONE)
Block(-5,1,8,COBBLESTONE)
Block(-5,2,4,COBBLESTONE)
Block(-5,2,5,COBBLESTONE)
Block(-5,2,6,COBBLESTONE)
Block(-5,2,7,COBBLESTONE)
Block(-5,2,8,COBBLESTONE)
Block(-5,3,4,COBBLESTONE)
Block(-5,3,5,COBBLESTONE)
Block(-5,3,6,COBBLESTONE)
Block(-5,3,7,COBBLESTONE)
Block(-5,3,8,COBBLESTONE)
Block(-5,4,4,COBBLESTONE)
Block(-5,4,5,COBBLESTONE)
Block(-5,4,6,COBBLESTONE)
Block(-5,4,7,COBBLESTONE)
Block(-5,4,8,COBBLESTONE)
Block(-5,5,4,COBBLESTONE)
Block(-5,5,5,COBBLESTONE)
Block(-5,5,6,COBBLESTONE)
Block(-5,5,7,COBBLESTONE)
Block(-5,5,8,COBBLESTONE)
Block(-5,6,4,COBBLESTONE)
Block(-5,6,5,COBBLESTONE)
Block(-5,6,6,COBBLESTONE)
Block(-5,6,7,COBBLESTONE)
Block(-5,6,8,COBBLESTONE)
Block(-5,7,4,COBBLESTONE)
Block(-5,7,5,COBBLESTONE)
Block(-5,7,6,COBBLESTONE)
Block(-5,7,7,COBBLESTONE)
Block(-5,7,8,COBBLESTONE)
Block(-5,8,4,COBBLESTONE)
Block(-5,8,5,COBBLESTONE)
Block(-5,8,6,COBBLESTONE)
Block(-5,8,7,COBBLESTONE)
Block(-5,8,8,COBBLESTONE)
Block(-5,9,4,COBBLESTONE)
Block(-5,9,5,COBBLESTONE)
Block(-5,9,6,COBBLESTONE)
Block(-5,9,7,COBBLESTONE)
Block(-5,9,8,COBBLESTONE)
Block(-5,10,4,COBBLESTONE)
Block(-5,10,5,COBBLESTONE)
Block(-5,10,6,COBBLESTONE)
Block(-5,10,7,COBBLESTONE)
Block(-5,10,8,COBBLESTONE)
Block(-5,11,5,COBBLESTONE)
Block(-5,11,6,COBBLESTONE)
Block(-5,11,7,COBBLESTONE)
Block(-5,11,8,COBBLESTONE)
Block(-5,12,6,COBBLESTONE)
Block(-5,12,7,COBBLESTONE)
Block(-5,12,8,COBBLESTONE)
Block(-5,13,7,COBBLESTONE)
Block(-5,13,8,COBBLESTONE)
Block(-5,14,8,COBBLESTONE)
Block(-4,0,4,COBBLESTONE)
Block(-4,0,5,COBBLESTONE)
Block(-4,0,6,COBBLESTONE)
Block(-4,0,7,COBBLESTONE)
Block(-4,0,8,COBBLESTONE)
Block(-4,1,4,COBBLESTONE)
Block(-4,1,5,COBBLESTONE)
Block(-4,1,6,COBBLESTONE)
Block(-4,1,7,COBBLESTONE)
Block(-4,1,8,COBBLESTONE)
Block(-4,2,4,COBBLESTONE)
Block(-4,2,5,COBBLESTONE)
Block(-4,2,6,COBBLESTONE)
Block(-4,2,7,COBBLESTONE)
Block(-4,2,8,COBBLESTONE)
Block(-4,3,4,COBBLESTONE)
Block(-4,3,5,COBBLESTONE)
Block(-4,3,6,COBBLESTONE)
Block(-4,3,7,COBBLESTONE)
Block(-4,3,8,COBBLESTONE)
Block(-4,4,4,COBBLESTONE)
Block(-4,4,5,COBBLESTONE)
Block(-4,4,6,COBBLESTONE)
Block(-4,4,7,COBBLESTONE)
Block(-4,4,8,COBBLESTONE)
Block(-4,5,4,COBBLESTONE)
Block(-4,5,5,COBBLESTONE)
Block(-4,5,6,COBBLESTONE)
Block(-4,5,7,COBBLESTONE)
Block(-4,5,8,COBBLESTONE)
Block(-4,6,4,COBBLESTONE)
Block(-4,6,5,COBBLESTONE)
Block(-4,6,6,COBBLESTONE)
Block(-4,6,7,COBBLESTONE)
Block(-4,6,8,COBBLESTONE)
Block(-4,7,4,COBBLESTONE)
Block(-4,7,5,COBBLESTONE)
Block(-4,7,6,COBBLESTONE)
Block(-4,7,7,COBBLESTONE)
Block(-4,7,8,COBBLESTONE)
Block(-4,8,4,COBBLESTONE)
Block(-4,8,5,COBBLESTONE)
Block(-4,8,6,COBBLESTONE)
Block(-4,8,7,COBBLESTONE)
Block(-4,8,8,COBBLESTONE)
Block(-4,9,4,COBBLESTONE)
Block(-4,9,5,COBBLESTONE)
Block(-4,9,6,COBBLESTONE)
Block(-4,9,7,COBBLESTONE)
Block(-4,9,8,COBBLESTONE)
Block(-4,10,4,COBBLESTONE)
Block(-4,10,5,COBBLESTONE)
Block(-4,10,6,COBBLESTONE)
Block(-4,10,7,COBBLESTONE)
Block(-4,10,8,COBBLESTONE)
Block(-4,11,5,COBBLESTONE)
Block(-4,11,6,COBBLESTONE)
Block(-4,11,7,COBBLESTONE)
Block(-4,11,8,COBBLESTONE)
Block(-4,12,6,COBBLESTONE)
Block(-4,12,7,COBBLESTONE)
Block(-4,12,8,COBBLESTONE)
Block(-4,13,7,COBBLESTONE)
Block(-4,13,8,COBBLESTONE)
Block(-4,14,8,COBBLESTONE)
Block(-3,0,4,COBBLESTONE)
Block(-3,0,5,COBBLESTONE)
Block(-3,0,6,COBBLESTONE)
Block(-3,0,7,COBBLESTONE)
Block(-3,0,8,COBBLESTONE)
Block(-3,1,4,COBBLESTONE)
Block(-3,1,5,COBBLESTONE)
Block(-3,1,6,COBBLESTONE)
Block(-3,1,7,COBBLESTONE)
Block(-3,1,8,COBBLESTONE)
Block(-3,2,4,COBBLESTONE)
Block(-3,2,5,COBBLESTONE)
Block(-3,2,6,COBBLESTONE)
Block(-3,2,7,COBBLESTONE)
Block(-3,2,8,COBBLESTONE)
Block(-3,3,4,COBBLESTONE)
Block(-3,3,5,COBBLESTONE)
Block(-3,3,6,COBBLESTONE)
Block(-3,3,7,COBBLESTONE)
Block(-3,3,8,COBBLESTONE)
Block(-3,4,4,COBBLESTONE)
Block(-3,4,5,COBBLESTONE)
Block(-3,4,6,COBBLESTONE)
Block(-3,4,7,COBBLESTONE)
Block(-3,4,8,COBBLESTONE)
Block(-3,5,4,COBBLESTONE)
Block(-3,5,5,COBBLESTONE)
Block(-3,5,6,COBBLESTONE)
Block(-3,5,7,COBBLESTONE)
Block(-3,5,8,COBBLESTONE)
Block(-3,6,4,COBBLESTONE)
Block(-3,6,5,COBBLESTONE)
Block(-3,6,6,COBBLESTONE)
Block(-3,6,7,COBBLESTONE)
Block(-3,6,8,COBBLESTONE)
Block(-3,7,4,COBBLESTONE)
Block(-3,7,5,COBBLESTONE)
Block(-3,7,6,COBBLESTONE)
Block(-3,7,7,COBBLESTONE)
Block(-3,7,8,COBBLESTONE)
Block(-3,8,4,COBBLESTONE)
Block(-3,8,5,COBBLESTONE)
Block(-3,8,6,COBBLESTONE)
Block(-3,8,7,COBBLESTONE)
Block(-3,8,8,COBBLESTONE)
Block(-3,9,4,COBBLESTONE)
Block(-3,9,5,COBBLESTONE)
Block(-3,9,6,COBBLESTONE)
Block(-3,9,7,COBBLESTONE)
Block(-3,9,8,COBBLESTONE)
Block(-3,10,4,COBBLESTONE)
Block(-3,10,5,COBBLESTONE)
Block(-3,10,6,COBBLESTONE)
Block(-3,10,7,COBBLESTONE)
Block(-3,10,8,COBBLESTONE)
Block(-3,11,5,COBBLESTONE)
Block(-3,11,6,COBBLESTONE)
Block(-3,11,7,COBBLESTONE)
Block(-3,11,8,COBBLESTONE)
Block(-3,12,6,COBBLESTONE)
Block(-3,12,7,COBBLESTONE)
Block(-3,12,8,COBBLESTONE)
Block(-3,13,7,COBBLESTONE)
Block(-3,13,8,COBBLESTONE)
Block(-3,14,8,COBBLESTONE)
Block(-2,0,4,COBBLESTONE)
Block(-2,0,5,COBBLESTONE)
Block(-2,0,6,COBBLESTONE)
Block(-2,0,7,COBBLESTONE)
Block(-2,0,8,COBBLESTONE)
Block(-2,1,4,COBBLESTONE)
Block(-2,1,5,COBBLESTONE)
Block(-2,1,6,COBBLESTONE)
Block(-2,1,7,COBBLESTONE)
Block(-2,1,8,COBBLESTONE)
Block(-2,2,4,COBBLESTONE)
Block(-2,2,5,COBBLESTONE)
Block(-2,2,6,COBBLESTONE)
Block(-2,2,7,COBBLESTONE)
Block(-2,2,8,COBBLESTONE)
Block(-2,3,4,COBBLESTONE)
Block(-2,3,5,COBBLESTONE)
Block(-2,3,6,COBBLESTONE)
Block(-2,3,7,COBBLESTONE)
Block(-2,3,8,COBBLESTONE)
Block(-2,4,4,COBBLESTONE)
Block(-2,4,5,COBBLESTONE)
Block(-2,4,6,COBBLESTONE)
Block(-2,4,7,COBBLESTONE)
Block(-2,4,8,COBBLESTONE)
Block(-2,5,4,COBBLESTONE)
Block(-2,5,5,COBBLESTONE)
Block(-2,5,6,COBBLESTONE)
Block(-2,5,7,COBBLESTONE)
Block(-2,5,8,COBBLESTONE)
Block(-2,6,4,COBBLESTONE)
Block(-2,6,5,COBBLESTONE)
Block(-2,6,6,COBBLESTONE)
Block(-2,6,7,COBBLESTONE)
Block(-2,6,8,COBBLESTONE)
Block(-2,7,4,COBBLESTONE)
Block(-2,7,5,COBBLESTONE)
Block(-2,7,6,COBBLESTONE)
Block(-2,7,7,COBBLESTONE)
Block(-2,7,8,COBBLESTONE)
Block(-2,8,4,COBBLESTONE)
Block(-2,8,5,COBBLESTONE)
Block(-2,8,6,COBBLESTONE)
Block(-2,8,7,COBBLESTONE)
Block(-2,8,8,COBBLESTONE)
Block(-2,9,4,COBBLESTONE)
Block(-2,9,5,COBBLESTONE)
Block(-2,9,6,COBBLESTONE)
Block(-2,9,7,COBBLESTONE)
Block(-2,9,8,COBBLESTONE)
Block(-2,10,4,COBBLESTONE)
Block(-2,10,5,COBBLESTONE)
Block(-2,10,6,COBBLESTONE)
Block(-2,10,7,COBBLESTONE)
Block(-2,10,8,COBBLESTONE)
Block(-2,11,5,COBBLESTONE)
Block(-2,11,6,COBBLESTONE)
Block(-2,11,7,COBBLESTONE)
Block(-2,11,8,COBBLESTONE)
Block(-2,12,6,COBBLESTONE)
Block(-2,12,7,COBBLESTONE)
Block(-2,12,8,COBBLESTONE)
Block(-2,13,7,COBBLESTONE)
Block(-2,13,8,COBBLESTONE)
Block(-2,14,8,COBBLESTONE)
Block(-1,0,4,COBBLESTONE)
Block(-1,0,5,COBBLESTONE)
Block(-1,0,6,COBBLESTONE)
Block(-1,0,7,COBBLESTONE)
Block(-1,0,8,COBBLESTONE)
Block(-1,1,4,COBBLESTONE)
Block(-1,1,5,COBBLESTONE)
Block(-1,1,6,COBBLESTONE)
Block(-1,1,7,COBBLESTONE)
Block(-1,1,8,COBBLESTONE)
Block(-1,2,4,COBBLESTONE)
Block(-1,2,5,COBBLESTONE)
Block(-1,2,6,COBBLESTONE)
Block(-1,2,7,COBBLESTONE)
Block(-1,2,8,COBBLESTONE)
Block(-1,3,4,COBBLESTONE)
Block(-1,3,5,COBBLESTONE)
Block(-1,3,6,COBBLESTONE)
Block(-1,3,7,COBBLESTONE)
Block(-1,3,8,COBBLESTONE)
Block(-1,4,4,COBBLESTONE)
Block(-1,4,5,COBBLESTONE)
Block(-1,4,6,COBBLESTONE)
Block(-1,4,7,COBBLESTONE)
Block(-1,4,8,COBBLESTONE)
Block(-1,5,4,COBBLESTONE)
Block(-1,5,5,COBBLESTONE)
Block(-1,5,6,COBBLESTONE)
Block(-1,5,7,COBBLESTONE)
Block(-1,5,8,COBBLESTONE)
Block(-1,6,4,COBBLESTONE)
Block(-1,6,5,COBBLESTONE)
Block(-1,6,6,COBBLESTONE)
Block(-1,6,7,COBBLESTONE)
Block(-1,6,8,COBBLESTONE)
Block(-1,7,4,COBBLESTONE)
Block(-1,7,5,COBBLESTONE)
Block(-1,7,6,COBBLESTONE)
Block(-1,7,7,COBBLESTONE)
Block(-1,7,8,COBBLESTONE)
Block(-1,8,4,COBBLESTONE)
Block(-1,8,5,COBBLESTONE)
Block(-1,8,6,COBBLESTONE)
Block(-1,8,7,COBBLESTONE)
Block(-1,8,8,COBBLESTONE)
Block(-1,9,4,COBBLESTONE)
Block(-1,9,5,COBBLESTONE)
Block(-1,9,6,COBBLESTONE)
Block(-1,9,7,COBBLESTONE)
Block(-1,9,8,COBBLESTONE)
Block(-1,10,4,COBBLESTONE)
Block(-1,10,5,COBBLESTONE)
Block(-1,10,6,COBBLESTONE)
Block(-1,10,7,COBBLESTONE)
Block(-1,10,8,COBBLESTONE)
Block(-1,11,5,COBBLESTONE)
Block(-1,11,6,COBBLESTONE)
Block(-1,11,7,COBBLESTONE)
Block(-1,11,8,COBBLESTONE)
Block(-1,12,6,COBBLESTONE)
Block(-1,12,7,COBBLESTONE)
Block(-1,12,8,COBBLESTONE)
Block(-1,13,7,COBBLESTONE)
Block(-1,13,8,COBBLESTONE)
Block(-1,14,8,COBBLESTONE)
Block(0,0,4,COBBLESTONE)
Block(0,0,5,COBBLESTONE)
Block(0,0,6,COBBLESTONE)
Block(0,0,7,COBBLESTONE)
Block(0,0,8,COBBLESTONE)
Block(0,1,4,COBBLESTONE)
Block(0,1,5,COBBLESTONE)
Block(0,1,6,COBBLESTONE)
Block(0,1,7,COBBLESTONE)
Block(0,1,8,COBBLESTONE)
Block(0,2,4,COBBLESTONE)
Block(0,2,5,COBBLESTONE)
Block(0,2,6,COBBLESTONE)
Block(0,2,7,COBBLESTONE)
Block(0,2,8,COBBLESTONE)
Block(0,3,4,COBBLESTONE)
Block(0,3,5,COBBLESTONE)
Block(0,3,6,COBBLESTONE)
Block(0,3,7,COBBLESTONE)
Block(0,3,8,COBBLESTONE)
Block(0,4,4,COBBLESTONE)
Block(0,4,5,COBBLESTONE)
Block(0,4,6,COBBLESTONE)
Block(0,4,7,COBBLESTONE)
Block(0,4,8,COBBLESTONE)
Block(0,5,4,COBBLESTONE)
Block(0,5,5,COBBLESTONE)
Block(0,5,6,COBBLESTONE)
Block(0,5,7,COBBLESTONE)
Block(0,5,8,COBBLESTONE)
Block(0,6,4,COBBLESTONE)
Block(0,6,5,COBBLESTONE)
Block(0,6,6,COBBLESTONE)
Block(0,6,7,COBBLESTONE)
Block(0,6,8,COBBLESTONE)
Block(0,7,4,COBBLESTONE)
Block(0,7,5,COBBLESTONE)
Block(0,7,6,COBBLESTONE)
Block(0,7,7,COBBLESTONE)
Block(0,7,8,COBBLESTONE)
Block(0,8,4,COBBLESTONE)
Block(0,8,5,COBBLESTONE)
Block(0,8,6,COBBLESTONE)
Block(0,8,7,COBBLESTONE)
Block(0,8,8,COBBLESTONE)
Block(0,9,4,COBBLESTONE)
Block(0,9,5,COBBLESTONE)
Block(0,9,6,COBBLESTONE)
Block(0,9,7,COBBLESTONE)
Block(0,9,8,COBBLESTONE)
Block(0,10,4,COBBLESTONE)
Block(0,10,5,COBBLESTONE)
Block(0,10,6,COBBLESTONE)
Block(0,10,7,COBBLESTONE)
Block(0,10,8,COBBLESTONE)
Block(0,11,5,COBBLESTONE)
Block(0,11,6,COBBLESTONE)
Block(0,11,7,COBBLESTONE)
Block(0,11,8,COBBLESTONE)
Block(0,12,6,COBBLESTONE)
Block(0,12,7,COBBLESTONE)
Block(0,12,8,COBBLESTONE)
Block(0,13,7,COBBLESTONE)
Block(0,13,8,COBBLESTONE)
Block(0,14,8,COBBLESTONE)
Block(1,0,4,COBBLESTONE)
Block(1,0,5,COBBLESTONE)
Block(1,0,6,COBBLESTONE)
Block(1,0,7,COBBLESTONE)
Block(1,0,8,COBBLESTONE)
Block(1,1,4,COBBLESTONE)
Block(1,1,5,COBBLESTONE)
Block(1,1,6,COBBLESTONE)
Block(1,1,7,COBBLESTONE)
Block(1,1,8,COBBLESTONE)
Block(1,2,4,COBBLESTONE)
Block(1,2,5,COBBLESTONE)
Block(1,2,6,COBBLESTONE)
Block(1,2,7,COBBLESTONE)
Block(1,2,8,COBBLESTONE)
Block(1,3,4,COBBLESTONE)
Block(1,3,5,COBBLESTONE)
Block(1,3,6,COBBLESTONE)
Block(1,3,7,COBBLESTONE)
Block(1,3,8,COBBLESTONE)
Block(1,4,4,COBBLESTONE)
Block(1,4,5,COBBLESTONE)
Block(1,4,6,COBBLESTONE)
Block(1,4,7,COBBLESTONE)
Block(1,4,8,COBBLESTONE)
Block(1,5,4,COBBLESTONE)
Block(1,5,5,COBBLESTONE)
Block(1,5,6,COBBLESTONE)
Block(1,5,7,COBBLESTONE)
Block(1,5,8,COBBLESTONE)
Block(1,6,4,COBBLESTONE)
Block(1,6,5,COBBLESTONE)
Block(1,6,6,COBBLESTONE)
Block(1,6,7,COBBLESTONE)
Block(1,6,8,COBBLESTONE)
Block(1,7,4,COBBLESTONE)
Block(1,7,5,COBBLESTONE)
Block(1,7,6,COBBLESTONE)
Block(1,7,7,COBBLESTONE)
Block(1,7,8,COBBLESTONE)
Block(1,8,4,COBBLESTONE)
Block(1,8,5,COBBLESTONE)
Block(1,8,6,COBBLESTONE)
Block(1,8,7,COBBLESTONE)
Block(1,8,8,COBBLESTONE)
Block(1,9,4,COBBLESTONE)
Block(1,9,5,COBBLESTONE)
Block(1,9,6,COBBLESTONE)
Block(1,9,7,COBBLESTONE)
Block(1,9,8,COBBLESTONE)
Block(1,10,4,COBBLESTONE)
Block(1,10,5,COBBLESTONE)
Block(1,10,6,COBBLESTONE)
Block(1,10,7,COBBLESTONE)
Block(1,10,8,COBBLESTONE)
Block(1,11,5,COBBLESTONE)
Block(1,11,6,COBBLESTONE)
Block(1,11,7,COBBLESTONE)
Block(1,11,8,COBBLESTONE)
Block(1,12,6,COBBLESTONE)
Block(1,12,7,COBBLESTONE)
Block(1,12,8,COBBLESTONE)
Block(1,13,7,COBBLESTONE)
Block(1,13,8,COBBLESTONE)
Block(1,14,8,COBBLESTONE)
Block(2,0,4,COBBLESTONE)
Block(2,0,5,COBBLESTONE)
Block(2,0,6,COBBLESTONE)
Block(2,0,7,COBBLESTONE)
Block(2,0,8,COBBLESTONE)
Block(2,1,4,COBBLESTONE)
Block(2,1,5,COBBLESTONE)
Block(2,1,6,COBBLESTONE)
Block(2,1,7,COBBLESTONE)
Block(2,1,8,COBBLESTONE)
Block(2,2,4,COBBLESTONE)
Block(2,2,5,COBBLESTONE)
Block(2,2,6,COBBLESTONE)
Block(2,2,7,COBBLESTONE)
Block(2,2,8,COBBLESTONE)
Block(2,3,4,COBBLESTONE)
Block(2,3,5,COBBLESTONE)
Block(2,3,6,COBBLESTONE)
Block(2,3,7,COBBLESTONE)
Block(2,3,8,COBBLESTONE)
Block(2,4,4,COBBLESTONE)
Block(2,4,5,COBBLESTONE)
Block(2,4,6,COBBLESTONE)
Block(2,4,7,COBBLESTONE)
Block(2,4,8,COBBLESTONE)
Block(2,5,4,COBBLESTONE)
Block(2,5,5,COBBLESTONE)
Block(2,5,6,COBBLESTONE)
Block(2,5,7,COBBLESTONE)
Block(2,5,8,COBBLESTONE)
Block(2,6,4,COBBLESTONE)
Block(2,6,5,COBBLESTONE)
Block(2,6,6,COBBLESTONE)
Block(2,6,7,COBBLESTONE)
Block(2,6,8,COBBLESTONE)
Block(2,7,4,COBBLESTONE)
Block(2,7,5,COBBLESTONE)
Block(2,7,6,COBBLESTONE)
Block(2,7,7,COBBLESTONE)
Block(2,7,8,COBBLESTONE)
Block(2,8,4,COBBLESTONE)
Block(2,8,5,COBBLESTONE)
Block(2,8,6,COBBLESTONE)
Block(2,8,7,COBBLESTONE)
Block(2,8,8,COBBLESTONE)
Block(2,9,4,COBBLESTONE)
Block(2,9,5,COBBLESTONE)
Block(2,9,6,COBBLESTONE)
Block(2,9,7,COBBLESTONE)
Block(2,9,8,COBBLESTONE)
Block(2,10,4,COBBLESTONE)
Block(2,10,5,COBBLESTONE)
Block(2,10,6,COBBLESTONE)
Block(2,10,7,COBBLESTONE)
Block(2,10,8,COBBLESTONE)
Block(2,11,5,COBBLESTONE)
Block(2,11,6,COBBLESTONE)
Block(2,11,7,COBBLESTONE)
Block(2,11,8,COBBLESTONE)
Block(2,12,6,COBBLESTONE)
Block(2,12,7,COBBLESTONE)
Block(2,12,8,COBBLESTONE)
Block(2,13,7,COBBLESTONE)
Block(2,13,8,COBBLESTONE)
Block(2,14,8,COBBLESTONE)
Block(3,0,4,COBBLESTONE)
Block(3,0,5,COBBLESTONE)
Block(3,0,6,COBBLESTONE)
Block(3,0,7,COBBLESTONE)
Block(3,0,8,COBBLESTONE)
Block(3,1,4,COBBLESTONE)
Block(3,1,5,COBBLESTONE)
Block(3,1,6,COBBLESTONE)
Block(3,1,7,COBBLESTONE)
Block(3,1,8,COBBLESTONE)
Block(3,2,4,COBBLESTONE)
Block(3,2,5,COBBLESTONE)
Block(3,2,6,COBBLESTONE)
Block(3,2,7,COBBLESTONE)
Block(3,2,8,COBBLESTONE)
Block(3,3,4,COBBLESTONE)
Block(3,3,5,COBBLESTONE)
Block(3,3,6,COBBLESTONE)
Block(3,3,7,COBBLESTONE)
Block(3,3,8,COBBLESTONE)
Block(3,4,4,COBBLESTONE)
Block(3,4,5,COBBLESTONE)
Block(3,4,6,COBBLESTONE)
Block(3,4,7,COBBLESTONE)
Block(3,4,8,COBBLESTONE)
Block(3,5,4,COBBLESTONE)
Block(3,5,5,COBBLESTONE)
Block(3,5,6,COBBLESTONE)
Block(3,5,7,COBBLESTONE)
Block(3,5,8,COBBLESTONE)
Block(3,6,4,COBBLESTONE)
Block(3,6,5,COBBLESTONE)
Block(3,6,6,COBBLESTONE)
Block(3,6,7,COBBLESTONE)
Block(3,6,8,COBBLESTONE)
Block(3,7,4,COBBLESTONE)
Block(3,7,5,COBBLESTONE)
Block(3,7,6,COBBLESTONE)
Block(3,7,7,COBBLESTONE)
Block(3,7,8,COBBLESTONE)
Block(3,8,4,COBBLESTONE)
Block(3,8,5,COBBLESTONE)
Block(3,8,6,COBBLESTONE)
Block(3,8,7,COBBLESTONE)
Block(3,8,8,COBBLESTONE)
Block(3,9,4,COBBLESTONE)
Block(3,9,5,COBBLESTONE)
Block(3,9,6,COBBLESTONE)
Block(3,9,7,COBBLESTONE)
Block(3,9,8,COBBLESTONE)
Block(3,10,4,COBBLESTONE)
Block(3,10,5,COBBLESTONE)
Block(3,10,6,COBBLESTONE)
Block(3,10,7,COBBLESTONE)
Block(3,10,8,COBBLESTONE)
Block(3,11,5,COBBLESTONE)
Block(3,11,6,COBBLESTONE)
Block(3,11,7,COBBLESTONE)
Block(3,11,8,COBBLESTONE)
Block(3,12,6,COBBLESTONE)
Block(3,12,7,COBBLESTONE)
Block(3,12,8,COBBLESTONE)
Block(3,13,7,COBBLESTONE)
Block(3,13,8,COBBLESTONE)
Block(3,14,8,COBBLESTONE)
Block(4,0,4,COBBLESTONE)
Block(4,0,5,COBBLESTONE)
Block(4,0,6,COBBLESTONE)
Block(4,0,7,COBBLESTONE)
Block(4,0,8,COBBLESTONE)
Block(4,1,4,COBBLESTONE)
Block(4,1,5,COBBLESTONE)
Block(4,1,6,COBBLESTONE)
Block(4,1,7,COBBLESTONE)
Block(4,1,8,COBBLESTONE)
Block(4,2,4,COBBLESTONE)
Block(4,2,5,COBBLESTONE)
Block(4,2,6,COBBLESTONE)
Block(4,2,7,COBBLESTONE)
Block(4,2,8,COBBLESTONE)
Block(4,3,4,COBBLESTONE)
Block(4,3,5,COBBLESTONE)
Block(4,3,6,COBBLESTONE)
Block(4,3,7,COBBLESTONE)
Block(4,3,8,COBBLESTONE)
Block(4,4,4,COBBLESTONE)
Block(4,4,5,COBBLESTONE)
Block(4,4,6,COBBLESTONE)
Block(4,4,7,COBBLESTONE)
Block(4,4,8,COBBLESTONE)
Block(4,5,4,COBBLESTONE)
Block(4,5,5,COBBLESTONE)
Block(4,5,6,COBBLESTONE)
Block(4,5,7,COBBLESTONE)
Block(4,5,8,COBBLESTONE)
Block(4,6,4,COBBLESTONE)
Block(4,6,5,COBBLESTONE)
Block(4,6,6,COBBLESTONE)
Block(4,6,7,COBBLESTONE)
Block(4,6,8,COBBLESTONE)
Block(4,7,4,COBBLESTONE)
Block(4,7,5,COBBLESTONE)
Block(4,7,6,COBBLESTONE)
Block(4,7,7,COBBLESTONE)
Block(4,7,8,COBBLESTONE)
Block(4,8,4,COBBLESTONE)
Block(4,8,5,COBBLESTONE)
Block(4,8,6,COBBLESTONE)
Block(4,8,7,COBBLESTONE)
Block(4,8,8,COBBLESTONE)
Block(4,9,4,COBBLESTONE)
Block(4,9,5,COBBLESTONE)
Block(4,9,6,COBBLESTONE)
Block(4,9,7,COBBLESTONE)
Block(4,9,8,COBBLESTONE)
Block(4,10,4,COBBLESTONE)
Block(4,10,5,COBBLESTONE)
Block(4,10,6,COBBLESTONE)
Block(4,10,7,COBBLESTONE)
Block(4,10,8,COBBLESTONE)
Block(4,11,5,COBBLESTONE)
Block(4,11,6,COBBLESTONE)
Block(4,11,7,COBBLESTONE)
Block(4,11,8,COBBLESTONE)
Block(4,12,6,COBBLESTONE)
Block(4,12,7,COBBLESTONE)
Block(4,12,8,COBBLESTONE)
Block(4,13,7,COBBLESTONE)
Block(4,13,8,COBBLESTONE)
Block(5,0,4,COBBLESTONE)
Block(5,0,5,COBBLESTONE)
Block(5,0,6,COBBLESTONE)
Block(5,0,7,COBBLESTONE)
Block(5,0,8,COBBLESTONE)
Block(5,1,4,COBBLESTONE)
Block(5,1,5,COBBLESTONE)
Block(5,1,6,COBBLESTONE)
Block(5,1,7,COBBLESTONE)
Block(5,1,8,COBBLESTONE)
Block(5,2,4,COBBLESTONE)
Block(5,2,5,COBBLESTONE)
Block(5,2,6,COBBLESTONE)
Block(5,2,7,COBBLESTONE)
Block(5,2,8,COBBLESTONE)
Block(5,3,4,COBBLESTONE)
Block(5,3,5,COBBLESTONE)
Block(5,3,6,COBBLESTONE)
Block(5,3,7,COBBLESTONE)
Block(5,3,8,COBBLESTONE)
Block(5,4,4,COBBLESTONE)
Block(5,4,5,COBBLESTONE)
Block(5,4,6,COBBLESTONE)
Block(5,4,7,COBBLESTONE)
Block(5,4,8,COBBLESTONE)
Block(5,5,4,COBBLESTONE)
Block(5,5,5,COBBLESTONE)
Block(5,5,6,COBBLESTONE)
Block(5,5,7,COBBLESTONE)
Block(5,5,8,COBBLESTONE)
Block(5,6,4,COBBLESTONE)
Block(5,6,5,COBBLESTONE)
Block(5,6,6,COBBLESTONE)
Block(5,6,7,COBBLESTONE)
Block(5,6,8,COBBLESTONE)
Block(5,7,4,COBBLESTONE)
Block(5,7,5,COBBLESTONE)
Block(5,7,6,COBBLESTONE)
Block(5,7,7,COBBLESTONE)
Block(5,7,8,COBBLESTONE)
Block(5,8,4,COBBLESTONE)
Block(5,8,5,COBBLESTONE)
Block(5,8,6,COBBLESTONE)
Block(5,8,7,COBBLESTONE)
Block(5,8,8,COBBLESTONE)
Block(5,9,4,COBBLESTONE)
Block(5,9,5,COBBLESTONE)
Block(5,9,6,COBBLESTONE)
Block(5,9,7,COBBLESTONE)
Block(5,9,8,COBBLESTONE)
Block(5,10,4,COBBLESTONE)
Block(5,10,5,COBBLESTONE)
Block(5,10,6,COBBLESTONE)
Block(5,10,7,COBBLESTONE)
Block(5,10,8,COBBLESTONE)
Block(5,11,5,COBBLESTONE)
Block(5,11,6,COBBLESTONE)
Block(5,11,7,COBBLESTONE)
Block(5,11,8,COBBLESTONE)
Block(5,12,6,COBBLESTONE)
Block(5,12,7,COBBLESTONE)
Block(5,12,8,COBBLESTONE)
Block(6,0,4,COBBLESTONE)
Block(6,0,5,COBBLESTONE)
Block(6,0,6,COBBLESTONE)
Block(6,0,7,COBBLESTONE)
Block(6,0,8,COBBLESTONE)
Block(6,1,4,COBBLESTONE)
Block(6,1,5,COBBLESTONE)
Block(6,1,6,COBBLESTONE)
Block(6,1,7,COBBLESTONE)
Block(6,1,8,COBBLESTONE)
Block(6,2,4,COBBLESTONE)
Block(6,2,5,COBBLESTONE)
Block(6,2,6,COBBLESTONE)
Block(6,2,7,COBBLESTONE)
Block(6,2,8,COBBLESTONE)
Block(6,3,4,COBBLESTONE)
Block(6,3,5,COBBLESTONE)
Block(6,3,6,COBBLESTONE)
Block(6,3,7,COBBLESTONE)
Block(6,3,8,COBBLESTONE)
Block(6,4,4,COBBLESTONE)
Block(6,4,5,COBBLESTONE)
Block(6,4,6,COBBLESTONE)
Block(6,4,7,COBBLESTONE)
Block(6,4,8,COBBLESTONE)
Block(6,5,4,COBBLESTONE)
Block(6,5,5,COBBLESTONE)
Block(6,5,6,COBBLESTONE)
Block(6,5,7,COBBLESTONE)
Block(6,5,8,COBBLESTONE)
Block(6,6,4,COBBLESTONE)
Block(6,6,5,COBBLESTONE)
Block(6,6,6,COBBLESTONE)
Block(6,6,7,COBBLESTONE)
Block(6,6,8,COBBLESTONE)
Block(6,7,4,COBBLESTONE)
Block(6,7,5,COBBLESTONE)
Block(6,7,6,COBBLESTONE)
Block(6,7,7,COBBLESTONE)
Block(6,7,8,COBBLESTONE)
Block(6,8,4,COBBLESTONE)
Block(6,8,5,COBBLESTONE)
Block(6,8,6,COBBLESTONE)
Block(6,8,7,COBBLESTONE)
Block(6,8,8,COBBLESTONE)
Block(6,9,4,COBBLESTONE)
Block(6,9,5,COBBLESTONE)
Block(6,9,6,COBBLESTONE)
Block(6,9,7,COBBLESTONE)
Block(6,9,8,COBBLESTONE)
Block(6,10,4,COBBLESTONE)
Block(6,10,5,COBBLESTONE)
Block(6,10,6,COBBLESTONE)
Block(6,10,7,COBBLESTONE)
Block(6,10,8,COBBLESTONE)
Block(6,11,5,COBBLESTONE)
Block(6,11,6,COBBLESTONE)
Block(6,11,7,COBBLESTONE)
Block(6,11,8,COBBLESTONE)
Block(7,0,4,COBBLESTONE)
Block(7,0,5,COBBLESTONE)
Block(7,0,6,COBBLESTONE)
Block(7,0,7,COBBLESTONE)
Block(7,0,8,COBBLESTONE)
Block(7,1,4,COBBLESTONE)
Block(7,1,5,COBBLESTONE)
Block(7,1,6,COBBLESTONE)
Block(7,1,7,COBBLESTONE)
Block(7,1,8,COBBLESTONE)
Block(7,2,4,COBBLESTONE)
Block(7,2,5,COBBLESTONE)
Block(7,2,6,COBBLESTONE)
Block(7,2,7,COBBLESTONE)
Block(7,2,8,COBBLESTONE)
Block(7,3,4,COBBLESTONE)
Block(7,3,5,COBBLESTONE)
Block(7,3,6,COBBLESTONE)
Block(7,3,7,COBBLESTONE)
Block(7,3,8,COBBLESTONE)
Block(7,4,4,COBBLESTONE)
Block(7,4,5,COBBLESTONE)
Block(7,4,6,COBBLESTONE)
Block(7,4,7,COBBLESTONE)
Block(7,4,8,COBBLESTONE)
Block(7,5,4,COBBLESTONE)
Block(7,5,5,COBBLESTONE)
Block(7,5,6,COBBLESTONE)
Block(7,5,7,COBBLESTONE)
Block(7,5,8,COBBLESTONE)
Block(7,6,4,COBBLESTONE)
Block(7,6,5,COBBLESTONE)
Block(7,6,6,COBBLESTONE)
Block(7,6,7,COBBLESTONE)
Block(7,6,8,COBBLESTONE)
Block(7,7,4,COBBLESTONE)
Block(7,7,5,COBBLESTONE)
Block(7,7,6,COBBLESTONE)
Block(7,7,7,COBBLESTONE)
Block(7,7,8,COBBLESTONE)
Block(7,8,4,COBBLESTONE)
Block(7,8,5,COBBLESTONE)
Block(7,8,6,COBBLESTONE)
Block(7,8,7,COBBLESTONE)
Block(7,8,8,COBBLESTONE)
Block(7,9,4,COBBLESTONE)
Block(7,9,5,COBBLESTONE)
Block(7,9,6,COBBLESTONE)
Block(7,9,7,COBBLESTONE)
Block(7,9,8,COBBLESTONE)
Block(7,10,4,COBBLESTONE)
Block(7,10,5,COBBLESTONE)
Block(7,10,6,COBBLESTONE)
Block(7,10,7,COBBLESTONE)
Block(7,10,8,COBBLESTONE)


#######################################################################
# +-----------------------------------------------------------------+ #
# |                            BO3 checks                           | #
# +-----------------------------------------------------------------+ #
#######################################################################

# Require a condition at a certain location in order for the BO3 to be spawned.
# BlockCheck(x,y,z,BlockName[,BlockName[,...]]) - one of the blocks must be at the location
# BlockCheckNot(x,y,z,BlockName[,BlockName[,...]]) - all the blocks must not be at the location
# LightCheck(x,y,z,minLightLevel,maxLightLevel) - light must be between min and max (inclusive)

# You can use "Solid" as a BlockName for matching all solid blocks or "All" to match all blocks that aren't air.

# Examples:
#   BlockCheck(0,-1,0,GRASS,DIRT)  Require grass or dirt just below the object
#   BlockCheck(0,-1,0,Solid)       Require any solid block just below the object
#   BlockCheck(0,-1,0,WOOL)        Require any type of wool just below the object
#   BlockCheck(0,-1,0,WOOL:0)      Require white wool just below the object
#   BlockCheckNot(0,-1,0,WOOL:0)   Require that there is no white wool below the object
#   LightCheck(0,0,0,0,1)          Require almost complete darkness just below the object

#######################################################################
# +-----------------------------------------------------------------+ #
# |                             Branches                            | #
# +-----------------------------------------------------------------+ #
#######################################################################

# Branches are objects that will spawn when this object spawns when it is used in
# the CustomStructure resource. Branches can also have branches, making complex
# structures possible. See the wiki for more details.

# Regular Branches spawn each branch with an independent chance of spawning.
# Branch(x,y,z,branchName,rotation,chance[,anotherBranchName,rotation,chance[,...]][IndividualChance])
# branchName - name of the object to spawn.
# rotation - NORTH, SOUTH, EAST or WEST.
# IndividualChance - The chance each branch has to spawn, assumed to be 100 when left blank

# WeightedBranch(x,y,z,branchName,rotation,chance[,anotherBranchName,rotation,chance[,...]][MaxChanceOutOf])
# MaxChanceOutOf - The chance all branches have to spawn out of, assumed to be 100 when left blank
