
#######################################################################
# +-----------------------------------------------------------------+ #
# |                            BO3 object                           | #
# +-----------------------------------------------------------------+ #
#######################################################################

# This is the config file of a custom object.
# If you add this object correctly to your BiomeConfigs, it will spawn in the world.

# This is the creator of this BO3 object
Author: LordSmellyPants

# A short description of this BO3 object
Description: No description given

# The BO3 version, don't change this! It can be used by external applications to do a version check.
Version: 3

# The settings mode, WriteAll, WriteWithoutComments or WriteDisable. See WorldConfig.
SettingsMode: WriteDisable


#######################################################################
# +-----------------------------------------------------------------+ #
# |                          Main settings                          | #
# +-----------------------------------------------------------------+ #
#######################################################################

# This needs to be set to true to spawn the object in the Tree and Sapling resources.
Tree: false

# The frequency of the BO3 from 1 to 200. Tries this many times to spawn this BO3 when using the CustomObject(...) resource.
# Ignored by Tree(..), Sapling(..) and CustomStructure(..)
Frequency: 1

# The rarity of the BO3 from 0 to 100. Each spawn attempt has rarity% chance to succeed when using the CustomObject(...) resource.
# Ignored by Tree(..), Sapling(..) and CustomStructure(..)
Rarity: 5.0

# If you set this to true, the BO3 will be placed with a random rotation.
RotateRandomly: false

# The spawn height of the BO3 - randomY, highestBlock or highestSolidBlock.
SpawnHeight: highestSolidBlock

# The height limits for the BO3.
MinHeight: 50

MaxHeight: 100

# Objects can have other objects attacthed to it: branches. Branches can also
# have branches attached to it, which can also have branches, etc. This is the
# maximum branch depth for this objects.
MaxBranchDepth: 10

# When spawned with the UseWorld keyword, this BO3 should NOT spawn in the following biomes.
# If you writer.write the BO3 name directly in the BiomeConfigs, this will be ignored.
ExcludedBiomes: All


#######################################################################
# +-----------------------------------------------------------------+ #
# |                      Source block settings                      | #
# +-----------------------------------------------------------------+ #
#######################################################################

# The block(s) the BO3 should spawn in.
SourceBlocks: GRASS,DIRT,GRAVEL,SAND,SAND:1,SANDSTONE,STONE,STONE:1,STONE:3,STONE:5,DIRT:1,CLAY,HARD_CLAY,38,38:1,38:2,38:3,38:4,38:5,38:6,38:7,38:8,39,40,175,175:1,175:2,175:3,175:4,175:5,31,31:1,31:2,32,COAL_ORE,IRON_ORE,GOLD_ORE,REDSTONE_ORE,DIAMOND_ORE,LAPIS_ORE,EMERALD_ORE,106,AIR

# The maximum percentage of the BO3 that can be outside the SourceBlock.
# The BO3 won't be placed on a location with more blocks outside the SourceBlock than this percentage.
MaxPercentageOutsideSourceBlock: 10

# What to do when a block is about to be placed outside the SourceBlock? (dontPlace, placeAnyway)
OutsideSourceBlock: placeAnyway


#######################################################################
# +-----------------------------------------------------------------+ #
# |                              Blocks                             | #
# +-----------------------------------------------------------------+ #
#######################################################################

# All the blocks used in the BO3 are listed here. Possible blocks:
# Block(x,y,z,id[.data][,nbtfile.nbt)
# RandomBlock(x,y,z,id[:data][,nbtfile.nbt],chance[,id[:data][,nbtfile.nbt],chance[,...]])
# So RandomBlock(0,0,0,CHEST,chest.nbt,50,CHEST,anotherchest.nbt,100) will spawn a chest at
# the BO3 origin, and give it a 50% chance to have the contents of chest.nbt, or, if that
# fails, a 100% percent chance to have the contents of anotherchest.nbt.
Block(-11,1,-10,VINE:8)
Block(-11,1,-8,VINE:8)
Block(-11,2,-10,VINE:8)
Block(-11,2,-9,VINE:8)
Block(-11,2,-8,VINE:8)
Block(-11,3,-10,VINE:8)
Block(-11,3,-9,VINE:8)
Block(-11,3,-8,VINE:8)
Block(-11,4,-10,VINE:8)
Block(-11,4,-9,VINE:8)
Block(-11,4,-8,VINE:8)
Block(-11,4,-7,VINE:8)
Block(-11,4,-6,VINE:8)
Block(-11,5,-9,VINE:8)
Block(-11,5,-8,VINE:8)
Block(-11,5,-7,VINE:8)
Block(-11,5,-6,VINE:8)
Block(-11,6,-10,VINE:8)
Block(-11,6,-9,VINE:8)
Block(-11,6,-8,VINE:8)
Block(-11,6,-7,VINE:8)
Block(-11,6,-6,VINE:8)
Block(-11,7,-8,VINE:8)
Block(-11,7,-7,VINE:8)
Block(-11,7,-6,VINE:8)
Block(-11,8,-7,VINE:8)
Block(-11,8,-6,VINE:8)
RandomBlock(-10,-13,-10,COBBLESTONE,50,48,100)
RandomBlock(-10,-13,-9,COBBLESTONE,50,48,100)
RandomBlock(-10,-13,-8,COBBLESTONE,50,48,100)
RandomBlock(-10,-13,-7,COBBLESTONE,50,48,100)
RandomBlock(-10,-13,-6,COBBLESTONE,50,48,100)
RandomBlock(-10,-13,-5,COBBLESTONE,50,48,100)
RandomBlock(-10,-13,-4,COBBLESTONE,50,48,100)
RandomBlock(-10,-13,-3,COBBLESTONE,50,48,100)
RandomBlock(-10,-13,-2,COBBLESTONE,50,48,100)
RandomBlock(-10,-13,-1,COBBLESTONE,50,48,100)
RandomBlock(-10,-13,0,COBBLESTONE,50,48,100)
RandomBlock(-10,-13,1,COBBLESTONE,50,48,100)
RandomBlock(-10,-13,2,COBBLESTONE,50,48,100)
RandomBlock(-10,-13,3,COBBLESTONE,50,48,100)
RandomBlock(-10,-13,4,COBBLESTONE,50,48,100)
RandomBlock(-10,-13,5,COBBLESTONE,50,48,100)
RandomBlock(-10,-13,6,COBBLESTONE,50,48,100)
RandomBlock(-10,-13,7,COBBLESTONE,50,48,100)
RandomBlock(-10,-13,8,COBBLESTONE,50,48,100)
RandomBlock(-10,-13,9,COBBLESTONE,50,48,100)
RandomBlock(-10,-13,10,COBBLESTONE,50,48,100)
RandomBlock(-10,-12,-10,COBBLESTONE,50,48,100)
RandomBlock(-10,-12,-9,COBBLESTONE,50,48,100)
RandomBlock(-10,-12,-8,COBBLESTONE,50,48,100)
RandomBlock(-10,-12,-7,COBBLESTONE,50,48,100)
RandomBlock(-10,-12,-6,COBBLESTONE,50,48,100)
RandomBlock(-10,-12,-5,COBBLESTONE,50,48,100)
RandomBlock(-10,-12,-4,COBBLESTONE,50,48,100)
RandomBlock(-10,-12,-3,COBBLESTONE,50,48,100)
RandomBlock(-10,-12,-2,COBBLESTONE,50,48,100)
RandomBlock(-10,-12,-1,COBBLESTONE,50,48,100)
RandomBlock(-10,-12,0,COBBLESTONE,50,48,100)
RandomBlock(-10,-12,1,COBBLESTONE,50,48,100)
RandomBlock(-10,-12,2,COBBLESTONE,50,48,100)
RandomBlock(-10,-12,3,COBBLESTONE,50,48,100)
RandomBlock(-10,-12,4,COBBLESTONE,50,48,100)
RandomBlock(-10,-12,5,COBBLESTONE,50,48,100)
RandomBlock(-10,-12,6,COBBLESTONE,50,48,100)
RandomBlock(-10,-12,7,COBBLESTONE,50,48,100)
RandomBlock(-10,-12,8,COBBLESTONE,50,48,100)
RandomBlock(-10,-12,9,COBBLESTONE,50,48,100)
RandomBlock(-10,-12,10,COBBLESTONE,50,48,100)
RandomBlock(-10,-11,-10,COBBLESTONE,50,48,100)
RandomBlock(-10,-11,-9,COBBLESTONE,50,48,100)
RandomBlock(-10,-11,-8,COBBLESTONE,50,48,100)
RandomBlock(-10,-11,-7,COBBLESTONE,50,48,100)
RandomBlock(-10,-11,-6,COBBLESTONE,50,48,100)
RandomBlock(-10,-11,-5,COBBLESTONE,50,48,100)
RandomBlock(-10,-11,-4,COBBLESTONE,50,48,100)
RandomBlock(-10,-11,-3,COBBLESTONE,50,48,100)
RandomBlock(-10,-11,-2,COBBLESTONE,50,48,100)
RandomBlock(-10,-11,-1,COBBLESTONE,50,48,100)
RandomBlock(-10,-11,0,COBBLESTONE,50,48,100)
RandomBlock(-10,-11,1,COBBLESTONE,50,48,100)
RandomBlock(-10,-11,2,COBBLESTONE,50,48,100)
RandomBlock(-10,-11,3,COBBLESTONE,50,48,100)
RandomBlock(-10,-11,4,COBBLESTONE,50,48,100)
RandomBlock(-10,-11,5,COBBLESTONE,50,48,100)
RandomBlock(-10,-11,6,COBBLESTONE,50,48,100)
RandomBlock(-10,-11,7,COBBLESTONE,50,48,100)
RandomBlock(-10,-11,8,COBBLESTONE,50,48,100)
RandomBlock(-10,-11,9,COBBLESTONE,50,48,100)
RandomBlock(-10,-11,10,COBBLESTONE,50,48,100)
RandomBlock(-10,-10,-10,COBBLESTONE,50,48,100)
RandomBlock(-10,-10,-9,COBBLESTONE,50,48,100)
RandomBlock(-10,-10,-8,COBBLESTONE,50,48,100)
RandomBlock(-10,-10,-7,COBBLESTONE,50,48,100)
RandomBlock(-10,-10,-6,COBBLESTONE,50,48,100)
RandomBlock(-10,-10,-5,COBBLESTONE,50,48,100)
RandomBlock(-10,-10,-4,COBBLESTONE,50,48,100)
RandomBlock(-10,-10,-3,COBBLESTONE,50,48,100)
RandomBlock(-10,-10,-2,COBBLESTONE,50,48,100)
RandomBlock(-10,-10,-1,COBBLESTONE,50,48,100)
RandomBlock(-10,-10,0,COBBLESTONE,50,48,100)
RandomBlock(-10,-10,1,COBBLESTONE,50,48,100)
RandomBlock(-10,-10,2,COBBLESTONE,50,48,100)
RandomBlock(-10,-10,3,COBBLESTONE,50,48,100)
RandomBlock(-10,-10,4,COBBLESTONE,50,48,100)
RandomBlock(-10,-10,5,COBBLESTONE,50,48,100)
RandomBlock(-10,-10,6,COBBLESTONE,50,48,100)
RandomBlock(-10,-10,7,COBBLESTONE,50,48,100)
Block(-10,-10,8,AIR)
RandomBlock(-10,-10,9,COBBLESTONE,50,48,100)
RandomBlock(-10,-10,10,COBBLESTONE,50,48,100)
RandomBlock(-10,-9,-10,COBBLESTONE,50,48,100)
RandomBlock(-10,-9,-9,COBBLESTONE,50,48,100)
RandomBlock(-10,-9,-8,COBBLESTONE,50,48,100)
RandomBlock(-10,-9,-7,COBBLESTONE,50,48,100)
RandomBlock(-10,-9,-6,COBBLESTONE,50,48,100)
RandomBlock(-10,-9,-5,COBBLESTONE,50,48,100)
RandomBlock(-10,-9,-4,COBBLESTONE,50,48,100)
RandomBlock(-10,-9,-3,COBBLESTONE,50,48,100)
RandomBlock(-10,-9,-2,COBBLESTONE,50,48,100)
RandomBlock(-10,-9,-1,COBBLESTONE,50,48,100)
RandomBlock(-10,-9,0,COBBLESTONE,50,48,100)
RandomBlock(-10,-9,1,COBBLESTONE,50,48,100)
RandomBlock(-10,-9,2,COBBLESTONE,50,48,100)
RandomBlock(-10,-9,3,COBBLESTONE,50,48,100)
RandomBlock(-10,-9,4,COBBLESTONE,50,48,100)
RandomBlock(-10,-9,5,COBBLESTONE,50,48,100)
RandomBlock(-10,-9,6,COBBLESTONE,50,48,100)
RandomBlock(-10,-9,7,COBBLESTONE,50,48,100)
RandomBlock(-10,-9,8,COBBLESTONE,50,48,100)
RandomBlock(-10,-9,9,COBBLESTONE,50,48,100)
RandomBlock(-10,-9,10,COBBLESTONE,50,48,100)
RandomBlock(-10,-8,-10,COBBLESTONE,50,48,100)
RandomBlock(-10,-8,-9,COBBLESTONE,50,48,100)
RandomBlock(-10,-8,-8,COBBLESTONE,50,48,100)
RandomBlock(-10,-8,-7,COBBLESTONE,50,48,100)
RandomBlock(-10,-8,-6,COBBLESTONE,50,48,100)
RandomBlock(-10,-8,-5,COBBLESTONE,50,48,100)
RandomBlock(-10,-8,-4,COBBLESTONE,50,48,100)
RandomBlock(-10,-8,-3,COBBLESTONE,50,48,100)
RandomBlock(-10,-8,-2,COBBLESTONE,50,48,100)
RandomBlock(-10,-8,-1,COBBLESTONE,50,48,100)
RandomBlock(-10,-8,0,COBBLESTONE,50,48,100)
RandomBlock(-10,-8,1,COBBLESTONE,50,48,100)
RandomBlock(-10,-8,2,COBBLESTONE,50,48,100)
RandomBlock(-10,-8,3,COBBLESTONE,50,48,100)
RandomBlock(-10,-8,4,COBBLESTONE,50,48,100)
RandomBlock(-10,-8,5,COBBLESTONE,50,48,100)
RandomBlock(-10,-8,6,COBBLESTONE,50,48,100)
RandomBlock(-10,-8,7,COBBLESTONE,50,48,100)
RandomBlock(-10,-8,8,COBBLESTONE,50,48,100)
RandomBlock(-10,-8,9,COBBLESTONE,50,48,100)
RandomBlock(-10,-8,10,COBBLESTONE,50,48,100)
RandomBlock(-10,-7,-10,COBBLESTONE,50,48,100)
RandomBlock(-10,-7,-9,COBBLESTONE,50,48,100)
RandomBlock(-10,-7,-8,COBBLESTONE,50,48,100)
RandomBlock(-10,-7,-7,COBBLESTONE,50,48,100)
RandomBlock(-10,-7,-6,COBBLESTONE,50,48,100)
RandomBlock(-10,-7,-5,COBBLESTONE,50,48,100)
RandomBlock(-10,-7,-4,COBBLESTONE,50,48,100)
RandomBlock(-10,-7,-3,COBBLESTONE,50,48,100)
RandomBlock(-10,-7,-2,COBBLESTONE,50,48,100)
RandomBlock(-10,-7,-1,COBBLESTONE,50,48,100)
RandomBlock(-10,-7,0,COBBLESTONE,50,48,100)
RandomBlock(-10,-7,1,COBBLESTONE,50,48,100)
RandomBlock(-10,-7,2,COBBLESTONE,50,48,100)
RandomBlock(-10,-7,3,COBBLESTONE,50,48,100)
RandomBlock(-10,-7,4,COBBLESTONE,50,48,100)
RandomBlock(-10,-7,5,COBBLESTONE,50,48,100)
RandomBlock(-10,-7,6,COBBLESTONE,50,48,100)
RandomBlock(-10,-7,7,COBBLESTONE,50,48,100)
RandomBlock(-10,-7,8,COBBLESTONE,50,48,100)
RandomBlock(-10,-7,9,COBBLESTONE,50,48,100)
RandomBlock(-10,-7,10,COBBLESTONE,50,48,100)
RandomBlock(-10,-6,-10,COBBLESTONE,50,48,100)
RandomBlock(-10,-6,-9,COBBLESTONE,50,48,100)
RandomBlock(-10,-6,-8,COBBLESTONE,50,48,100)
RandomBlock(-10,-6,-7,COBBLESTONE,50,48,100)
RandomBlock(-10,-6,-6,COBBLESTONE,50,48,100)
RandomBlock(-10,-6,-5,COBBLESTONE,50,48,100)
RandomBlock(-10,-6,-4,COBBLESTONE,50,48,100)
RandomBlock(-10,-6,-3,COBBLESTONE,50,48,100)
RandomBlock(-10,-6,-2,COBBLESTONE,50,48,100)
RandomBlock(-10,-6,-1,COBBLESTONE,50,48,100)
RandomBlock(-10,-6,0,COBBLESTONE,50,48,100)
RandomBlock(-10,-6,1,COBBLESTONE,50,48,100)
RandomBlock(-10,-6,2,COBBLESTONE,50,48,100)
RandomBlock(-10,-6,3,COBBLESTONE,50,48,100)
RandomBlock(-10,-6,4,COBBLESTONE,50,48,100)
RandomBlock(-10,-6,5,COBBLESTONE,50,48,100)
RandomBlock(-10,-6,6,COBBLESTONE,50,48,100)
RandomBlock(-10,-6,7,COBBLESTONE,50,48,100)
RandomBlock(-10,-6,8,COBBLESTONE,50,48,100)
RandomBlock(-10,-6,9,COBBLESTONE,50,48,100)
RandomBlock(-10,-6,10,COBBLESTONE,50,48,100)
RandomBlock(-10,-5,-10,COBBLESTONE,50,48,100)
RandomBlock(-10,-5,-9,COBBLESTONE,50,48,100)
RandomBlock(-10,-5,-8,COBBLESTONE,50,48,100)
RandomBlock(-10,-5,-7,COBBLESTONE,50,48,100)
RandomBlock(-10,-5,-6,COBBLESTONE,50,48,100)
RandomBlock(-10,-5,-5,COBBLESTONE,50,48,100)
RandomBlock(-10,-5,-4,COBBLESTONE,50,48,100)
RandomBlock(-10,-5,-3,COBBLESTONE,50,48,100)
RandomBlock(-10,-5,-2,COBBLESTONE,50,48,100)
RandomBlock(-10,-5,-1,COBBLESTONE,50,48,100)
RandomBlock(-10,-5,0,COBBLESTONE,50,48,100)
RandomBlock(-10,-5,1,COBBLESTONE,50,48,100)
RandomBlock(-10,-5,2,COBBLESTONE,50,48,100)
RandomBlock(-10,-5,3,COBBLESTONE,50,48,100)
RandomBlock(-10,-5,4,COBBLESTONE,50,48,100)
RandomBlock(-10,-5,5,COBBLESTONE,50,48,100)
RandomBlock(-10,-5,6,COBBLESTONE,50,48,100)
RandomBlock(-10,-5,7,COBBLESTONE,50,48,100)
RandomBlock(-10,-5,8,COBBLESTONE,50,48,100)
RandomBlock(-10,-5,9,COBBLESTONE,50,48,100)
RandomBlock(-10,-5,10,COBBLESTONE,50,48,100)
RandomBlock(-10,-4,-10,COBBLESTONE,50,48,100)
RandomBlock(-10,-4,-9,COBBLESTONE,50,48,100)
RandomBlock(-10,-4,-8,COBBLESTONE,50,48,100)
RandomBlock(-10,-4,-7,COBBLESTONE,50,48,100)
RandomBlock(-10,-4,-6,COBBLESTONE,50,48,100)
RandomBlock(-10,-4,-5,COBBLESTONE,50,48,100)
RandomBlock(-10,-4,-4,COBBLESTONE,50,48,100)
RandomBlock(-10,-4,-3,COBBLESTONE,50,48,100)
RandomBlock(-10,-4,-2,COBBLESTONE,50,48,100)
RandomBlock(-10,-4,-1,COBBLESTONE,50,48,100)
RandomBlock(-10,-4,0,COBBLESTONE,50,48,100)
RandomBlock(-10,-4,1,COBBLESTONE,50,48,100)
RandomBlock(-10,-4,2,COBBLESTONE,50,48,100)
RandomBlock(-10,-4,3,COBBLESTONE,50,48,100)
RandomBlock(-10,-4,4,COBBLESTONE,50,48,100)
RandomBlock(-10,-4,5,COBBLESTONE,50,48,100)
RandomBlock(-10,-4,6,COBBLESTONE,50,48,100)
RandomBlock(-10,-4,7,COBBLESTONE,50,48,100)
RandomBlock(-10,-4,8,COBBLESTONE,50,48,100)
RandomBlock(-10,-4,9,COBBLESTONE,50,48,100)
RandomBlock(-10,-4,10,COBBLESTONE,50,48,100)
RandomBlock(-10,-3,-10,COBBLESTONE,50,48,100)
RandomBlock(-10,-3,-9,COBBLESTONE,50,48,100)
RandomBlock(-10,-3,-8,COBBLESTONE,50,48,100)
RandomBlock(-10,-3,-7,COBBLESTONE,50,48,100)
RandomBlock(-10,-3,-6,COBBLESTONE,50,48,100)
RandomBlock(-10,-3,-5,COBBLESTONE,50,48,100)
RandomBlock(-10,-3,-4,COBBLESTONE,50,48,100)
RandomBlock(-10,-3,-3,COBBLESTONE,50,48,100)
RandomBlock(-10,-3,-2,COBBLESTONE,50,48,100)
RandomBlock(-10,-3,-1,COBBLESTONE,50,48,100)
RandomBlock(-10,-3,0,COBBLESTONE,50,48,100)
RandomBlock(-10,-3,1,COBBLESTONE,50,48,100)
RandomBlock(-10,-3,2,COBBLESTONE,50,48,100)
RandomBlock(-10,-3,3,COBBLESTONE,50,48,100)
RandomBlock(-10,-3,4,COBBLESTONE,50,48,100)
RandomBlock(-10,-3,5,COBBLESTONE,50,48,100)
RandomBlock(-10,-3,6,COBBLESTONE,50,48,100)
RandomBlock(-10,-3,7,COBBLESTONE,50,48,100)
RandomBlock(-10,-3,8,COBBLESTONE,50,48,100)
RandomBlock(-10,-3,9,COBBLESTONE,50,48,100)
RandomBlock(-10,-3,10,COBBLESTONE,50,48,100)
RandomBlock(-10,-2,-10,COBBLESTONE,50,48,100)
RandomBlock(-10,-2,-9,COBBLESTONE,50,48,100)
RandomBlock(-10,-2,-8,COBBLESTONE,50,48,100)
RandomBlock(-10,-2,-7,COBBLESTONE,50,48,100)
RandomBlock(-10,-2,-6,COBBLESTONE,50,48,100)
RandomBlock(-10,-2,-5,COBBLESTONE,50,48,100)
RandomBlock(-10,-2,-4,COBBLESTONE,50,48,100)
RandomBlock(-10,-2,-3,COBBLESTONE,50,48,100)
RandomBlock(-10,-2,-2,COBBLESTONE,50,48,100)
RandomBlock(-10,-2,-1,COBBLESTONE,50,48,100)
RandomBlock(-10,-2,0,COBBLESTONE,50,48,100)
RandomBlock(-10,-2,1,COBBLESTONE,50,48,100)
RandomBlock(-10,-2,2,COBBLESTONE,50,48,100)
RandomBlock(-10,-2,3,COBBLESTONE,50,48,100)
RandomBlock(-10,-2,4,COBBLESTONE,50,48,100)
RandomBlock(-10,-2,5,COBBLESTONE,50,48,100)
RandomBlock(-10,-2,6,COBBLESTONE,50,48,100)
RandomBlock(-10,-2,7,COBBLESTONE,50,48,100)
RandomBlock(-10,-2,8,COBBLESTONE,50,48,100)
RandomBlock(-10,-2,9,COBBLESTONE,50,48,100)
RandomBlock(-10,-2,10,COBBLESTONE,50,48,100)
RandomBlock(-10,-1,-10,COBBLESTONE,50,48,100)
RandomBlock(-10,-1,-9,COBBLESTONE,50,48,100)
RandomBlock(-10,-1,-8,COBBLESTONE,50,48,100)
RandomBlock(-10,-1,-7,COBBLESTONE,50,48,100)
RandomBlock(-10,-1,-6,COBBLESTONE,50,48,100)
RandomBlock(-10,-1,-5,COBBLESTONE,50,48,100)
RandomBlock(-10,-1,-4,COBBLESTONE,50,48,100)
RandomBlock(-10,-1,-3,COBBLESTONE,50,48,100)
RandomBlock(-10,-1,-2,COBBLESTONE,50,48,100)
RandomBlock(-10,-1,-1,COBBLESTONE,50,48,100)
RandomBlock(-10,-1,0,COBBLESTONE,50,48,100)
RandomBlock(-10,-1,1,COBBLESTONE,50,48,100)
RandomBlock(-10,-1,2,COBBLESTONE,50,48,100)
RandomBlock(-10,-1,3,COBBLESTONE,50,48,100)
RandomBlock(-10,-1,4,COBBLESTONE,50,48,100)
RandomBlock(-10,-1,5,COBBLESTONE,50,48,100)
RandomBlock(-10,-1,6,COBBLESTONE,50,48,100)
RandomBlock(-10,-1,7,COBBLESTONE,50,48,100)
RandomBlock(-10,-1,8,COBBLESTONE,50,48,100)
RandomBlock(-10,-1,9,COBBLESTONE,50,48,100)
RandomBlock(-10,-1,10,COBBLESTONE,50,48,100)
RandomBlock(-10,0,-10,COBBLESTONE,50,48,100)
RandomBlock(-10,0,-9,COBBLESTONE,50,48,100)
RandomBlock(-10,0,-8,COBBLESTONE,50,48,100)
RandomBlock(-10,0,-7,COBBLESTONE,50,48,100)
RandomBlock(-10,0,-6,COBBLESTONE,50,48,100)
RandomBlock(-10,0,-5,COBBLESTONE,50,48,100)
RandomBlock(-10,0,-4,COBBLESTONE,50,48,100)
RandomBlock(-10,0,-3,COBBLESTONE,50,48,100)
RandomBlock(-10,0,-2,COBBLESTONE,50,48,100)
RandomBlock(-10,0,-1,COBBLESTONE,50,48,100)
RandomBlock(-10,0,0,COBBLESTONE,50,48,100)
RandomBlock(-10,0,1,COBBLESTONE,50,48,100)
RandomBlock(-10,0,2,COBBLESTONE,50,48,100)
RandomBlock(-10,0,3,COBBLESTONE,50,48,100)
RandomBlock(-10,0,4,COBBLESTONE,50,48,100)
RandomBlock(-10,0,5,COBBLESTONE,50,48,100)
RandomBlock(-10,0,6,COBBLESTONE,50,48,100)
RandomBlock(-10,0,7,COBBLESTONE,50,48,100)
RandomBlock(-10,0,8,COBBLESTONE,50,48,100)
RandomBlock(-10,0,9,COBBLESTONE,50,48,100)
RandomBlock(-10,0,10,COBBLESTONE,50,48,100)
Block(-10,1,-11,VINE:1)
RandomBlock(-10,1,-10,COBBLESTONE,50,48,100)
Block(-10,1,-9,98)
Block(-10,1,-8,98:3)
Block(-10,1,-7,98)
RandomBlock(-10,1,-6,COBBLESTONE,50,48,100)
Block(-10,1,-5,VINE:5)
RandomBlock(-10,1,-4,GRAVEL,44,AIR,100)
RandomBlock(-10,1,-2,GRAVEL,44,AIR,100)
RandomBlock(-10,1,2,GRAVEL,44,AIR,100)
RandomBlock(-10,1,7,GRAVEL,44,AIR,100)
Block(-10,2,-11,VINE:1)
RandomBlock(-10,2,-10,COBBLESTONE,50,48,100)
Block(-10,2,-9,98)
Block(-10,2,-8,98:3)
Block(-10,2,-7,98)
RandomBlock(-10,2,-6,COBBLESTONE,50,48,100)
Block(-10,2,-5,VINE:4)
Block(-10,3,-11,VINE:1)
RandomBlock(-10,3,-10,COBBLESTONE,50,48,100)
Block(-10,3,-9,98)
Block(-10,3,-8,98:3)
Block(-10,3,-7,98)
RandomBlock(-10,3,-6,COBBLESTONE,50,48,100)
Block(-10,3,-5,VINE:4)
Block(-10,4,-11,VINE:1)
RandomBlock(-10,4,-10,COBBLESTONE,50,48,100)
Block(-10,4,-9,98:3)
Block(-10,4,-8,98:1)
Block(-10,4,-7,98:3)
RandomBlock(-10,4,-6,COBBLESTONE,50,48,100)
Block(-10,4,-5,VINE:4)
Block(-10,5,-11,VINE:1)
RandomBlock(-10,5,-10,COBBLESTONE,50,48,100)
Block(-10,5,-9,98)
Block(-10,5,-8,98:3)
Block(-10,5,-7,98)
RandomBlock(-10,5,-6,COBBLESTONE,50,48,100)
Block(-10,5,-5,VINE:4)
Block(-10,6,-11,VINE:1)
RandomBlock(-10,6,-10,COBBLESTONE,50,48,100)
Block(-10,6,-9,98:3)
Block(-10,6,-8,98:1)
Block(-10,6,-7,98:3)
RandomBlock(-10,6,-6,COBBLESTONE,50,48,100)
Block(-10,6,-5,VINE:4)
Block(-10,7,-11,VINE:1)
RandomBlock(-10,7,-10,COBBLESTONE,50,48,100)
Block(-10,7,-9,98:3)
Block(-10,7,-8,98:3)
Block(-10,7,-7,98:3)
RandomBlock(-10,7,-6,COBBLESTONE,50,48,100)
Block(-10,7,-5,VINE:4)
RandomBlock(-10,8,-10,COBBLESTONE,50,48,100)
RandomBlock(-10,8,-9,COBBLESTONE,50,48,100)
RandomBlock(-10,8,-8,COBBLESTONE,50,48,100)
RandomBlock(-10,8,-7,COBBLESTONE,50,48,100)
RandomBlock(-10,8,-6,COBBLESTONE,50,48,100)
Block(-10,8,-5,VINE:4)
Block(-10,9,-8,67:0)
RandomBlock(-10,9,-7,GRAVEL,44,AIR,100)
RandomBlock(-9,-13,-10,COBBLESTONE,50,48,100)
RandomBlock(-9,-13,-9,COBBLESTONE,50,48,100)
RandomBlock(-9,-13,-8,COBBLESTONE,50,48,100)
RandomBlock(-9,-13,-7,COBBLESTONE,50,48,100)
RandomBlock(-9,-13,-6,COBBLESTONE,50,48,100)
RandomBlock(-9,-13,-5,COBBLESTONE,50,48,100)
RandomBlock(-9,-13,-4,COBBLESTONE,50,48,100)
RandomBlock(-9,-13,-3,COBBLESTONE,50,48,100)
RandomBlock(-9,-13,-2,COBBLESTONE,50,48,100)
RandomBlock(-9,-13,-1,COBBLESTONE,50,48,100)
RandomBlock(-9,-13,0,COBBLESTONE,50,48,100)
RandomBlock(-9,-13,1,COBBLESTONE,50,48,100)
RandomBlock(-9,-13,2,COBBLESTONE,50,48,100)
RandomBlock(-9,-13,3,COBBLESTONE,50,48,100)
RandomBlock(-9,-13,4,COBBLESTONE,50,48,100)
RandomBlock(-9,-13,5,COBBLESTONE,50,48,100)
RandomBlock(-9,-13,6,COBBLESTONE,50,48,100)
RandomBlock(-9,-13,7,COBBLESTONE,50,48,100)
RandomBlock(-9,-13,8,COBBLESTONE,50,48,100)
RandomBlock(-9,-13,9,COBBLESTONE,50,48,100)
RandomBlock(-9,-13,10,COBBLESTONE,50,48,100)
RandomBlock(-9,-12,-10,COBBLESTONE,50,48,100)
RandomBlock(-9,-12,-9,COBBLESTONE,50,48,100)
RandomBlock(-9,-12,-8,COBBLESTONE,50,48,100)
RandomBlock(-9,-12,-7,COBBLESTONE,50,48,100)
RandomBlock(-9,-12,-6,COBBLESTONE,50,48,100)
RandomBlock(-9,-12,-5,COBBLESTONE,50,48,100)
RandomBlock(-9,-12,-4,COBBLESTONE,50,48,100)
RandomBlock(-9,-12,-3,COBBLESTONE,50,48,100)
RandomBlock(-9,-12,-2,COBBLESTONE,50,48,100)
RandomBlock(-9,-12,-1,COBBLESTONE,50,48,100)
RandomBlock(-9,-12,0,COBBLESTONE,50,48,100)
RandomBlock(-9,-12,1,COBBLESTONE,50,48,100)
RandomBlock(-9,-12,2,COBBLESTONE,50,48,100)
RandomBlock(-9,-12,3,COBBLESTONE,50,48,100)
RandomBlock(-9,-12,4,COBBLESTONE,50,48,100)
RandomBlock(-9,-12,5,COBBLESTONE,50,48,100)
RandomBlock(-9,-12,6,COBBLESTONE,50,48,100)
RandomBlock(-9,-12,7,COBBLESTONE,50,48,100)
RandomBlock(-9,-12,8,COBBLESTONE,50,48,100)
RandomBlock(-9,-12,9,COBBLESTONE,50,48,100)
RandomBlock(-9,-12,10,COBBLESTONE,50,48,100)
RandomBlock(-9,-11,-10,COBBLESTONE,50,48,100)
RandomBlock(-9,-11,-9,COBBLESTONE,50,48,100)
RandomBlock(-9,-11,-8,COBBLESTONE,50,48,100)
RandomBlock(-9,-11,-7,COBBLESTONE,50,48,100)
RandomBlock(-9,-11,-6,COBBLESTONE,50,48,100)
RandomBlock(-9,-11,-5,COBBLESTONE,50,48,100)
RandomBlock(-9,-11,-4,COBBLESTONE,50,48,100)
RandomBlock(-9,-11,-3,COBBLESTONE,50,48,100)
RandomBlock(-9,-11,-2,COBBLESTONE,50,48,100)
RandomBlock(-9,-11,-1,COBBLESTONE,50,48,100)
RandomBlock(-9,-11,0,COBBLESTONE,50,48,100)
RandomBlock(-9,-11,1,COBBLESTONE,50,48,100)
RandomBlock(-9,-11,2,COBBLESTONE,50,48,100)
RandomBlock(-9,-11,3,COBBLESTONE,50,48,100)
RandomBlock(-9,-11,4,COBBLESTONE,50,48,100)
RandomBlock(-9,-11,5,COBBLESTONE,50,48,100)
RandomBlock(-9,-11,6,COBBLESTONE,50,48,100)
RandomBlock(-9,-11,7,COBBLESTONE,50,48,100)
RandomBlock(-9,-11,8,COBBLESTONE,50,48,100)
RandomBlock(-9,-11,9,COBBLESTONE,50,48,100)
RandomBlock(-9,-11,10,COBBLESTONE,50,48,100)
RandomBlock(-9,-10,-10,COBBLESTONE,50,48,100)
RandomBlock(-9,-10,-9,COBBLESTONE,50,48,100)
RandomBlock(-9,-10,-8,COBBLESTONE,50,48,100)
RandomBlock(-9,-10,-7,COBBLESTONE,50,48,100)
RandomBlock(-9,-10,-6,COBBLESTONE,50,48,100)
RandomBlock(-9,-10,-5,COBBLESTONE,50,48,100)
RandomBlock(-9,-10,-4,COBBLESTONE,50,48,100)
RandomBlock(-9,-10,-3,COBBLESTONE,50,48,100)
RandomBlock(-9,-10,-2,COBBLESTONE,50,48,100)
RandomBlock(-9,-10,-1,COBBLESTONE,50,48,100)
Block(-9,-10,0,47)
Block(-9,-10,1,47)
RandomBlock(-9,-10,2,COBBLESTONE,50,48,100)
RandomBlock(-9,-10,3,COBBLESTONE,50,48,100)
RandomBlock(-9,-10,4,COBBLESTONE,50,48,100)
RandomBlock(-9,-10,5,COBBLESTONE,50,48,100)
RandomBlock(-9,-10,6,COBBLESTONE,50,48,100)
RandomBlock(-9,-10,7,COBBLESTONE,50,48,100)
RandomBlock(-9,-10,8,COBBLESTONE,50,48,100)
RandomBlock(-9,-10,9,COBBLESTONE,50,48,100)
RandomBlock(-9,-10,10,COBBLESTONE,50,48,100)
RandomBlock(-9,-9,-10,COBBLESTONE,50,48,100)
RandomBlock(-9,-9,-9,COBBLESTONE,50,48,100)
RandomBlock(-9,-9,-8,COBBLESTONE,50,48,100)
RandomBlock(-9,-9,-7,COBBLESTONE,50,48,100)
RandomBlock(-9,-9,-6,COBBLESTONE,50,48,100)
RandomBlock(-9,-9,-5,COBBLESTONE,50,48,100)
RandomBlock(-9,-9,-4,COBBLESTONE,50,48,100)
RandomBlock(-9,-9,-3,COBBLESTONE,50,48,100)
RandomBlock(-9,-9,-2,COBBLESTONE,50,48,100)
RandomBlock(-9,-9,-1,COBBLESTONE,50,48,100)
Block(-9,-9,0,AIR)
Block(-9,-9,1,AIR)
RandomBlock(-9,-9,2,COBBLESTONE,50,48,100)
RandomBlock(-9,-9,3,COBBLESTONE,50,48,100)
RandomBlock(-9,-9,4,COBBLESTONE,50,48,100)
RandomBlock(-9,-9,5,COBBLESTONE,50,48,100)
RandomBlock(-9,-9,6,COBBLESTONE,50,48,100)
RandomBlock(-9,-9,7,COBBLESTONE,50,48,100)
RandomBlock(-9,-9,8,COBBLESTONE,50,48,100)
RandomBlock(-9,-9,9,COBBLESTONE,50,48,100)
RandomBlock(-9,-9,10,COBBLESTONE,50,48,100)
RandomBlock(-9,-8,-10,COBBLESTONE,50,48,100)
RandomBlock(-9,-8,-9,COBBLESTONE,50,48,100)
RandomBlock(-9,-8,-8,COBBLESTONE,50,48,100)
RandomBlock(-9,-8,-7,COBBLESTONE,50,48,100)
RandomBlock(-9,-8,-6,COBBLESTONE,50,48,100)
RandomBlock(-9,-8,-5,COBBLESTONE,50,48,100)
RandomBlock(-9,-8,-4,COBBLESTONE,50,48,100)
RandomBlock(-9,-8,-3,COBBLESTONE,50,48,100)
RandomBlock(-9,-8,-2,COBBLESTONE,50,48,100)
RandomBlock(-9,-8,-1,COBBLESTONE,50,48,100)
RandomBlock(-9,-8,0,COBBLESTONE,50,48,100)
RandomBlock(-9,-8,1,COBBLESTONE,50,48,100)
RandomBlock(-9,-8,2,COBBLESTONE,50,48,100)
RandomBlock(-9,-8,3,COBBLESTONE,50,48,100)
RandomBlock(-9,-8,4,COBBLESTONE,50,48,100)
RandomBlock(-9,-8,5,COBBLESTONE,50,48,100)
RandomBlock(-9,-8,6,COBBLESTONE,50,48,100)
RandomBlock(-9,-8,7,COBBLESTONE,50,48,100)
RandomBlock(-9,-8,8,COBBLESTONE,50,48,100)
RandomBlock(-9,-8,9,COBBLESTONE,50,48,100)
RandomBlock(-9,-8,10,COBBLESTONE,50,48,100)
RandomBlock(-9,-7,-10,COBBLESTONE,50,48,100)
RandomBlock(-9,-7,-9,COBBLESTONE,50,48,100)
RandomBlock(-9,-7,-8,COBBLESTONE,50,48,100)
RandomBlock(-9,-7,-7,COBBLESTONE,50,48,100)
RandomBlock(-9,-7,-6,COBBLESTONE,50,48,100)
RandomBlock(-9,-7,-5,COBBLESTONE,50,48,100)
RandomBlock(-9,-7,-4,COBBLESTONE,50,48,100)
RandomBlock(-9,-7,-3,COBBLESTONE,50,48,100)
RandomBlock(-9,-7,-2,COBBLESTONE,50,48,100)
RandomBlock(-9,-7,-1,COBBLESTONE,50,48,100)
RandomBlock(-9,-7,0,COBBLESTONE,50,48,100)
RandomBlock(-9,-7,1,COBBLESTONE,50,48,100)
RandomBlock(-9,-7,2,COBBLESTONE,50,48,100)
RandomBlock(-9,-7,3,COBBLESTONE,50,48,100)
RandomBlock(-9,-7,4,COBBLESTONE,50,48,100)
RandomBlock(-9,-7,5,COBBLESTONE,50,48,100)
RandomBlock(-9,-7,6,COBBLESTONE,50,48,100)
RandomBlock(-9,-7,7,COBBLESTONE,50,48,100)
RandomBlock(-9,-7,8,COBBLESTONE,50,48,100)
RandomBlock(-9,-7,9,COBBLESTONE,50,48,100)
RandomBlock(-9,-7,10,COBBLESTONE,50,48,100)
RandomBlock(-9,-6,-10,COBBLESTONE,50,48,100)
RandomBlock(-9,-6,-9,COBBLESTONE,50,48,100)
RandomBlock(-9,-6,-8,COBBLESTONE,50,48,100)
RandomBlock(-9,-6,-7,COBBLESTONE,50,48,100)
RandomBlock(-9,-6,-6,COBBLESTONE,50,48,100)
RandomBlock(-9,-6,-5,COBBLESTONE,50,48,100)
RandomBlock(-9,-6,-4,COBBLESTONE,50,48,100)
RandomBlock(-9,-6,-3,COBBLESTONE,50,48,100)
RandomBlock(-9,-6,-2,COBBLESTONE,50,48,100)
RandomBlock(-9,-6,-1,COBBLESTONE,50,48,100)
RandomBlock(-9,-6,0,COBBLESTONE,50,48,100)
RandomBlock(-9,-6,1,COBBLESTONE,50,48,100)
RandomBlock(-9,-6,2,COBBLESTONE,50,48,100)
RandomBlock(-9,-6,3,COBBLESTONE,50,48,100)
RandomBlock(-9,-6,4,COBBLESTONE,50,48,100)
RandomBlock(-9,-6,5,COBBLESTONE,50,48,100)
RandomBlock(-9,-6,6,COBBLESTONE,50,48,100)
RandomBlock(-9,-6,7,COBBLESTONE,50,48,100)
RandomBlock(-9,-6,8,COBBLESTONE,50,48,100)
RandomBlock(-9,-6,9,COBBLESTONE,50,48,100)
RandomBlock(-9,-6,10,COBBLESTONE,50,48,100)
RandomBlock(-9,-5,-10,COBBLESTONE,50,48,100)
RandomBlock(-9,-5,-9,COBBLESTONE,50,48,100)
RandomBlock(-9,-5,-8,COBBLESTONE,50,48,100)
RandomBlock(-9,-5,-7,COBBLESTONE,50,48,100)
RandomBlock(-9,-5,-6,COBBLESTONE,50,48,100)
RandomBlock(-9,-5,-5,COBBLESTONE,50,48,100)
RandomBlock(-9,-5,-4,COBBLESTONE,50,48,100)
RandomBlock(-9,-5,-3,COBBLESTONE,50,48,100)
RandomBlock(-9,-5,-2,COBBLESTONE,50,48,100)
RandomBlock(-9,-5,-1,COBBLESTONE,50,48,100)
RandomBlock(-9,-5,0,COBBLESTONE,50,48,100)
RandomBlock(-9,-5,1,COBBLESTONE,50,48,100)
RandomBlock(-9,-5,2,COBBLESTONE,50,48,100)
RandomBlock(-9,-5,3,COBBLESTONE,50,48,100)
RandomBlock(-9,-5,4,COBBLESTONE,50,48,100)
RandomBlock(-9,-5,5,COBBLESTONE,50,48,100)
RandomBlock(-9,-5,6,COBBLESTONE,50,48,100)
RandomBlock(-9,-5,7,COBBLESTONE,50,48,100)
RandomBlock(-9,-5,8,COBBLESTONE,50,48,100)
RandomBlock(-9,-5,9,COBBLESTONE,50,48,100)
RandomBlock(-9,-5,10,COBBLESTONE,50,48,100)
RandomBlock(-9,-4,-10,COBBLESTONE,50,48,100)
RandomBlock(-9,-4,-9,COBBLESTONE,50,48,100)
RandomBlock(-9,-4,-8,COBBLESTONE,50,48,100)
RandomBlock(-9,-4,-7,COBBLESTONE,50,48,100)
RandomBlock(-9,-4,-6,COBBLESTONE,50,48,100)
RandomBlock(-9,-4,-5,COBBLESTONE,50,48,100)
RandomBlock(-9,-4,-4,COBBLESTONE,50,48,100)
RandomBlock(-9,-4,-3,COBBLESTONE,50,48,100)
RandomBlock(-9,-4,-2,COBBLESTONE,50,48,100)
RandomBlock(-9,-4,-1,COBBLESTONE,50,48,100)
RandomBlock(-9,-4,0,COBBLESTONE,50,48,100)
RandomBlock(-9,-4,1,COBBLESTONE,50,48,100)
RandomBlock(-9,-4,2,COBBLESTONE,50,48,100)
RandomBlock(-9,-4,3,COBBLESTONE,50,48,100)
RandomBlock(-9,-4,4,COBBLESTONE,50,48,100)
RandomBlock(-9,-4,5,COBBLESTONE,50,48,100)
RandomBlock(-9,-4,6,COBBLESTONE,50,48,100)
RandomBlock(-9,-4,7,COBBLESTONE,50,48,100)
RandomBlock(-9,-4,8,COBBLESTONE,50,48,100)
RandomBlock(-9,-4,9,COBBLESTONE,50,48,100)
RandomBlock(-9,-4,10,COBBLESTONE,50,48,100)
RandomBlock(-9,-3,-10,COBBLESTONE,50,48,100)
RandomBlock(-9,-3,-9,COBBLESTONE,50,48,100)
RandomBlock(-9,-3,-8,COBBLESTONE,50,48,100)
RandomBlock(-9,-3,-7,COBBLESTONE,50,48,100)
RandomBlock(-9,-3,-6,COBBLESTONE,50,48,100)
RandomBlock(-9,-3,-5,COBBLESTONE,50,48,100)
RandomBlock(-9,-3,-4,COBBLESTONE,50,48,100)
RandomBlock(-9,-3,-3,COBBLESTONE,50,48,100)
RandomBlock(-9,-3,-2,COBBLESTONE,50,48,100)
RandomBlock(-9,-3,-1,COBBLESTONE,50,48,100)
RandomBlock(-9,-3,0,COBBLESTONE,50,48,100)
RandomBlock(-9,-3,1,COBBLESTONE,50,48,100)
RandomBlock(-9,-3,2,COBBLESTONE,50,48,100)
RandomBlock(-9,-3,3,COBBLESTONE,50,48,100)
RandomBlock(-9,-3,4,COBBLESTONE,50,48,100)
RandomBlock(-9,-3,5,COBBLESTONE,50,48,100)
RandomBlock(-9,-3,6,COBBLESTONE,50,48,100)
RandomBlock(-9,-3,7,COBBLESTONE,50,48,100)
RandomBlock(-9,-3,8,COBBLESTONE,50,48,100)
RandomBlock(-9,-3,9,COBBLESTONE,50,48,100)
RandomBlock(-9,-3,10,COBBLESTONE,50,48,100)
RandomBlock(-9,-2,-10,COBBLESTONE,50,48,100)
RandomBlock(-9,-2,-9,COBBLESTONE,50,48,100)
RandomBlock(-9,-2,-8,COBBLESTONE,50,48,100)
RandomBlock(-9,-2,-7,COBBLESTONE,50,48,100)
RandomBlock(-9,-2,-6,COBBLESTONE,50,48,100)
RandomBlock(-9,-2,-5,COBBLESTONE,50,48,100)
RandomBlock(-9,-2,-4,COBBLESTONE,50,48,100)
RandomBlock(-9,-2,-3,COBBLESTONE,50,48,100)
RandomBlock(-9,-2,-2,COBBLESTONE,50,48,100)
RandomBlock(-9,-2,-1,COBBLESTONE,50,48,100)
RandomBlock(-9,-2,0,COBBLESTONE,50,48,100)
RandomBlock(-9,-2,1,COBBLESTONE,50,48,100)
RandomBlock(-9,-2,2,COBBLESTONE,50,48,100)
RandomBlock(-9,-2,3,COBBLESTONE,50,48,100)
RandomBlock(-9,-2,4,COBBLESTONE,50,48,100)
RandomBlock(-9,-2,5,COBBLESTONE,50,48,100)
RandomBlock(-9,-2,6,COBBLESTONE,50,48,100)
RandomBlock(-9,-2,7,COBBLESTONE,50,48,100)
RandomBlock(-9,-2,8,COBBLESTONE,50,48,100)
RandomBlock(-9,-2,9,COBBLESTONE,50,48,100)
RandomBlock(-9,-2,10,COBBLESTONE,50,48,100)
RandomBlock(-9,-1,-10,COBBLESTONE,50,48,100)
RandomBlock(-9,-1,-9,COBBLESTONE,50,48,100)
RandomBlock(-9,-1,-8,COBBLESTONE,50,48,100)
RandomBlock(-9,-1,-7,COBBLESTONE,50,48,100)
RandomBlock(-9,-1,-6,COBBLESTONE,50,48,100)
RandomBlock(-9,-1,-5,COBBLESTONE,50,48,100)
RandomBlock(-9,-1,-4,COBBLESTONE,50,48,100)
RandomBlock(-9,-1,-3,COBBLESTONE,50,48,100)
RandomBlock(-9,-1,-2,COBBLESTONE,50,48,100)
RandomBlock(-9,-1,-1,COBBLESTONE,50,48,100)
RandomBlock(-9,-1,0,COBBLESTONE,50,48,100)
RandomBlock(-9,-1,1,COBBLESTONE,50,48,100)
RandomBlock(-9,-1,2,COBBLESTONE,50,48,100)
RandomBlock(-9,-1,3,COBBLESTONE,50,48,100)
RandomBlock(-9,-1,4,COBBLESTONE,50,48,100)
RandomBlock(-9,-1,5,COBBLESTONE,50,48,100)
RandomBlock(-9,-1,6,COBBLESTONE,50,48,100)
RandomBlock(-9,-1,7,COBBLESTONE,50,48,100)
RandomBlock(-9,-1,8,COBBLESTONE,50,48,100)
RandomBlock(-9,-1,9,COBBLESTONE,50,48,100)
RandomBlock(-9,-1,10,COBBLESTONE,50,48,100)
RandomBlock(-9,0,-10,COBBLESTONE,50,48,100)
RandomBlock(-9,0,-9,COBBLESTONE,50,48,100)
RandomBlock(-9,0,-8,COBBLESTONE,50,48,100)
RandomBlock(-9,0,-7,COBBLESTONE,50,48,100)
RandomBlock(-9,0,-6,COBBLESTONE,50,48,100)
RandomBlock(-9,0,-5,COBBLESTONE,50,48,100)
RandomBlock(-9,0,-4,COBBLESTONE,50,48,100)
RandomBlock(-9,0,-3,COBBLESTONE,50,48,100)
RandomBlock(-9,0,-2,COBBLESTONE,50,48,100)
RandomBlock(-9,0,-1,COBBLESTONE,50,48,100)
RandomBlock(-9,0,0,COBBLESTONE,50,48,100)
RandomBlock(-9,0,1,COBBLESTONE,50,48,100)
RandomBlock(-9,0,2,COBBLESTONE,50,48,100)
RandomBlock(-9,0,3,COBBLESTONE,50,48,100)
RandomBlock(-9,0,4,COBBLESTONE,50,48,100)
RandomBlock(-9,0,5,COBBLESTONE,50,48,100)
RandomBlock(-9,0,6,COBBLESTONE,50,48,100)
RandomBlock(-9,0,7,COBBLESTONE,50,48,100)
RandomBlock(-9,0,8,COBBLESTONE,50,48,100)
RandomBlock(-9,0,9,COBBLESTONE,50,48,100)
RandomBlock(-9,0,10,COBBLESTONE,50,48,100)
Block(-9,1,-10,98)
RandomBlock(-9,1,-8,COBBLESTONE,50,48,100)
RandomBlock(-9,1,-7,COBBLESTONE,50,48,100)
RandomBlock(-9,1,-6,COBBLESTONE,50,48,100)
RandomBlock(-9,1,-5,COBBLESTONE,50,48,100)
RandomBlock(-9,1,-4,COBBLESTONE,50,48,100)
RandomBlock(-9,1,-3,COBBLESTONE,50,48,100)
RandomBlock(-9,1,-2,COBBLESTONE,50,48,100)
RandomBlock(-9,1,-1,COBBLESTONE,50,48,100)
RandomBlock(-9,1,0,COBBLESTONE,50,48,100)
RandomBlock(-9,1,1,COBBLESTONE,50,48,100)
RandomBlock(-9,1,2,COBBLESTONE,50,48,100)
RandomBlock(-9,1,3,COBBLESTONE,50,48,100)
RandomBlock(-9,1,4,COBBLESTONE,50,48,100)
RandomBlock(-9,1,5,COBBLESTONE,50,48,100)
RandomBlock(-9,1,6,COBBLESTONE,50,48,100)
RandomBlock(-9,1,7,COBBLESTONE,50,48,100)
RandomBlock(-9,1,8,98:2,44,AIR,100)
RandomBlock(-9,1,9,COBBLESTONE,50,48,100)
Block(-9,2,-10,98)
Block(-9,2,-8,67:1)
RandomBlock(-9,2,-7,COBBLESTONE,50,48,100)
RandomBlock(-9,2,-6,COBBLESTONE,50,48,100)
RandomBlock(-9,2,-5,COBBLESTONE,50,48,100)
RandomBlock(-9,2,-4,COBBLESTONE,50,48,100)
RandomBlock(-9,2,-3,COBBLESTONE,50,48,100)
RandomBlock(-9,2,-2,COBBLESTONE,50,48,100)
RandomBlock(-9,2,-1,COBBLESTONE,50,48,100)
RandomBlock(-9,2,0,COBBLESTONE,50,48,100)
RandomBlock(-9,2,1,COBBLESTONE,50,48,100)
Block(-9,2,5,VINE:8)
RandomBlock(-9,2,7,GRAVEL,44,AIR,100)
Block(-9,3,-10,98)
RandomBlock(-9,3,-6,COBBLESTONE,50,48,100)
RandomBlock(-9,3,-5,COBBLESTONE,50,48,100)
RandomBlock(-9,3,-4,COBBLESTONE,50,48,100)
RandomBlock(-9,3,-3,COBBLESTONE,50,48,100)
RandomBlock(-9,3,-2,98:2,44,AIR,100)
RandomBlock(-9,3,-1,COBBLESTONE,50,48,100)
RandomBlock(-9,3,0,COBBLESTONE,50,48,100)
RandomBlock(-9,3,1,COBBLESTONE,50,48,100)
Block(-9,4,-10,98:3)
Block(-9,4,-8,VINE:2)
RandomBlock(-9,4,-6,COBBLESTONE,50,48,100)
RandomBlock(-9,4,-5,COBBLESTONE,50,48,100)
RandomBlock(-9,4,-4,COBBLESTONE,50,48,100)
RandomBlock(-9,4,-3,COBBLESTONE,50,48,100)
RandomBlock(-9,4,-2,COBBLESTONE,50,48,100)
RandomBlock(-9,4,-1,COBBLESTONE,50,48,100)
RandomBlock(-9,4,0,98:2,44,AIR,100)
RandomBlock(-9,4,1,COBBLESTONE,50,48,100)
Block(-9,5,-10,98)
RandomBlock(-9,5,-6,COBBLESTONE,50,48,100)
Block(-9,5,-5,VINE:4)
RandomBlock(-9,5,-4,GRAVEL,44,AIR,100)
RandomBlock(-9,5,-2,GRAVEL,44,AIR,100)
Block(-9,6,-10,98:3)
RandomBlock(-9,6,-6,COBBLESTONE,50,48,100)
Block(-9,6,-5,VINE:4)
Block(-9,7,-11,VINE:1)
Block(-9,7,-10,98:3)
RandomBlock(-9,7,-6,COBBLESTONE,50,48,100)
Block(-9,7,-5,VINE:4)
Block(-9,8,-11,VINE:1)
RandomBlock(-9,8,-10,COBBLESTONE,50,48,100)
RandomBlock(-9,8,-6,COBBLESTONE,50,48,100)
Block(-9,8,-5,VINE:4)
RandomBlock(-9,9,-9,COBBLESTONE,50,48,100)
RandomBlock(-9,9,-8,COBBLESTONE,50,48,100)
RandomBlock(-9,9,-7,COBBLESTONE,50,48,100)
RandomBlock(-8,-13,-10,COBBLESTONE,50,48,100)
RandomBlock(-8,-13,-9,COBBLESTONE,50,48,100)
RandomBlock(-8,-13,-8,COBBLESTONE,50,48,100)
RandomBlock(-8,-13,-7,COBBLESTONE,50,48,100)
RandomBlock(-8,-13,-6,COBBLESTONE,50,48,100)
RandomBlock(-8,-13,-5,COBBLESTONE,50,48,100)
RandomBlock(-8,-13,-4,COBBLESTONE,50,48,100)
RandomBlock(-8,-13,-3,COBBLESTONE,50,48,100)
RandomBlock(-8,-13,-2,COBBLESTONE,50,48,100)
RandomBlock(-8,-13,-1,COBBLESTONE,50,48,100)
RandomBlock(-8,-13,0,COBBLESTONE,50,48,100)
RandomBlock(-8,-13,1,COBBLESTONE,50,48,100)
RandomBlock(-8,-13,2,COBBLESTONE,50,48,100)
RandomBlock(-8,-13,3,COBBLESTONE,50,48,100)
RandomBlock(-8,-13,4,COBBLESTONE,50,48,100)
RandomBlock(-8,-13,5,COBBLESTONE,50,48,100)
RandomBlock(-8,-13,6,COBBLESTONE,50,48,100)
RandomBlock(-8,-13,7,COBBLESTONE,50,48,100)
RandomBlock(-8,-13,8,COBBLESTONE,50,48,100)
RandomBlock(-8,-13,9,COBBLESTONE,50,48,100)
RandomBlock(-8,-13,10,COBBLESTONE,50,48,100)
RandomBlock(-8,-12,-10,COBBLESTONE,50,48,100)
Block(-8,-12,-9,STATIONARY_WATER)
Block(-8,-12,-8,STATIONARY_WATER)
Block(-8,-12,-7,STATIONARY_WATER)
Block(-8,-12,-6,STATIONARY_WATER)
Block(-8,-12,-5,STATIONARY_WATER)
Block(-8,-12,-4,STATIONARY_WATER)
Block(-8,-12,-3,STATIONARY_WATER)
Block(-8,-12,-2,STATIONARY_WATER)
Block(-8,-12,-1,STATIONARY_WATER)
Block(-8,-12,0,STATIONARY_WATER)
Block(-8,-12,1,STATIONARY_WATER)
Block(-8,-12,2,STATIONARY_WATER)
Block(-8,-12,3,STATIONARY_WATER)
Block(-8,-12,4,STATIONARY_WATER)
Block(-8,-12,5,STATIONARY_WATER)
Block(-8,-12,6,STATIONARY_WATER)
Block(-8,-12,7,STATIONARY_WATER)
Block(-8,-12,8,STATIONARY_WATER)
Block(-8,-12,9,STATIONARY_WATER)
RandomBlock(-8,-12,10,COBBLESTONE,50,48,100)
RandomBlock(-8,-11,-10,COBBLESTONE,50,48,100)
Block(-8,-11,-9,AIR)
Block(-8,-11,-8,AIR)
Block(-8,-11,-7,AIR)
Block(-8,-11,-6,AIR)
Block(-8,-11,-5,AIR)
Block(-8,-11,-4,AIR)
Block(-8,-11,-3,AIR)
Block(-8,-11,-2,AIR)
Block(-8,-11,-1,AIR)
Block(-8,-11,0,AIR)
Block(-8,-11,1,AIR)
Block(-8,-11,2,AIR)
Block(-8,-11,3,AIR)
Block(-8,-11,4,AIR)
Block(-8,-11,5,AIR)
Block(-8,-11,6,AIR)
Block(-8,-11,7,AIR)
Block(-8,-11,8,AIR)
Block(-8,-11,9,AIR)
RandomBlock(-8,-11,10,COBBLESTONE,50,48,100)
RandomBlock(-8,-10,-10,COBBLESTONE,50,48,100)
Block(-8,-10,-9,AIR)
Block(-8,-10,-8,AIR)
Block(-8,-10,-7,AIR)
Block(-8,-10,-6,AIR)
Block(-8,-10,-5,AIR)
Block(-8,-10,-4,AIR)
Block(-8,-10,-3,AIR)
Block(-8,-10,-2,AIR)
Block(-8,-10,-1,AIR)
Block(-8,-10,0,AIR)
Block(-8,-10,1,AIR)
Block(-8,-10,2,AIR)
Block(-8,-10,3,AIR)
Block(-8,-10,4,AIR)
Block(-8,-10,5,AIR)
Block(-8,-10,6,AIR)
Block(-8,-10,7,AIR)
Block(-8,-10,8,AIR)
Block(-8,-10,9,AIR)
RandomBlock(-8,-10,10,COBBLESTONE,50,48,100)
RandomBlock(-8,-9,-10,COBBLESTONE,50,48,100)
RandomBlock(-8,-9,-9,COBBLESTONE,50,48,100)
RandomBlock(-8,-9,-8,COBBLESTONE,50,48,100)
RandomBlock(-8,-9,-7,COBBLESTONE,50,48,100)
RandomBlock(-8,-9,-6,COBBLESTONE,50,48,100)
RandomBlock(-8,-9,-5,COBBLESTONE,50,48,100)
RandomBlock(-8,-9,-4,COBBLESTONE,50,48,100)
RandomBlock(-8,-9,-3,COBBLESTONE,50,48,100)
RandomBlock(-8,-9,-2,COBBLESTONE,50,48,100)
RandomBlock(-8,-9,-1,COBBLESTONE,50,48,100)
Block(-8,-9,0,AIR)
Block(-8,-9,1,AIR)
RandomBlock(-8,-9,2,COBBLESTONE,50,48,100)
RandomBlock(-8,-9,3,COBBLESTONE,50,48,100)
RandomBlock(-8,-9,4,COBBLESTONE,50,48,100)
RandomBlock(-8,-9,5,COBBLESTONE,50,48,100)
RandomBlock(-8,-9,6,COBBLESTONE,50,48,100)
RandomBlock(-8,-9,7,COBBLESTONE,50,48,100)
RandomBlock(-8,-9,8,COBBLESTONE,50,48,100)
RandomBlock(-8,-9,9,COBBLESTONE,50,48,100)
RandomBlock(-8,-9,10,COBBLESTONE,50,48,100)
RandomBlock(-8,-8,-10,COBBLESTONE,50,48,100)
RandomBlock(-8,-8,-9,COBBLESTONE,50,48,100)
RandomBlock(-8,-8,-8,COBBLESTONE,50,48,100)
RandomBlock(-8,-8,-7,COBBLESTONE,50,48,100)
RandomBlock(-8,-8,-6,COBBLESTONE,50,48,100)
RandomBlock(-8,-8,-5,COBBLESTONE,50,48,100)
RandomBlock(-8,-8,-4,COBBLESTONE,50,48,100)
RandomBlock(-8,-8,-3,COBBLESTONE,50,48,100)
RandomBlock(-8,-8,-2,COBBLESTONE,50,48,100)
RandomBlock(-8,-8,-1,COBBLESTONE,50,48,100)
RandomBlock(-8,-8,0,COBBLESTONE,50,48,100)
RandomBlock(-8,-8,1,COBBLESTONE,50,48,100)
RandomBlock(-8,-8,2,COBBLESTONE,50,48,100)
RandomBlock(-8,-8,3,COBBLESTONE,50,48,100)
RandomBlock(-8,-8,4,COBBLESTONE,50,48,100)
RandomBlock(-8,-8,5,COBBLESTONE,50,48,100)
RandomBlock(-8,-8,6,COBBLESTONE,50,48,100)
RandomBlock(-8,-8,7,COBBLESTONE,50,48,100)
RandomBlock(-8,-8,8,COBBLESTONE,50,48,100)
RandomBlock(-8,-8,9,COBBLESTONE,50,48,100)
RandomBlock(-8,-8,10,COBBLESTONE,50,48,100)
RandomBlock(-8,-7,-10,COBBLESTONE,50,48,100)
RandomBlock(-8,-7,-9,COBBLESTONE,50,48,100)
RandomBlock(-8,-7,-8,COBBLESTONE,50,48,100)
RandomBlock(-8,-7,-7,COBBLESTONE,50,48,100)
RandomBlock(-8,-7,-6,COBBLESTONE,50,48,100)
RandomBlock(-8,-7,-5,COBBLESTONE,50,48,100)
RandomBlock(-8,-7,-4,COBBLESTONE,50,48,100)
RandomBlock(-8,-7,-3,COBBLESTONE,50,48,100)
RandomBlock(-8,-7,-2,COBBLESTONE,50,48,100)
RandomBlock(-8,-7,-1,COBBLESTONE,50,48,100)
RandomBlock(-8,-7,0,COBBLESTONE,50,48,100)
RandomBlock(-8,-7,1,COBBLESTONE,50,48,100)
RandomBlock(-8,-7,2,COBBLESTONE,50,48,100)
RandomBlock(-8,-7,3,COBBLESTONE,50,48,100)
RandomBlock(-8,-7,4,COBBLESTONE,50,48,100)
RandomBlock(-8,-7,5,COBBLESTONE,50,48,100)
RandomBlock(-8,-7,6,COBBLESTONE,50,48,100)
RandomBlock(-8,-7,7,COBBLESTONE,50,48,100)
RandomBlock(-8,-7,8,COBBLESTONE,50,48,100)
RandomBlock(-8,-7,9,COBBLESTONE,50,48,100)
RandomBlock(-8,-7,10,COBBLESTONE,50,48,100)
RandomBlock(-8,-6,-10,COBBLESTONE,50,48,100)
RandomBlock(-8,-6,-9,COBBLESTONE,50,48,100)
RandomBlock(-8,-6,-8,COBBLESTONE,50,48,100)
RandomBlock(-8,-6,-7,COBBLESTONE,50,48,100)
RandomBlock(-8,-6,-6,COBBLESTONE,50,48,100)
RandomBlock(-8,-6,-5,COBBLESTONE,50,48,100)
RandomBlock(-8,-6,-4,COBBLESTONE,50,48,100)
RandomBlock(-8,-6,-3,COBBLESTONE,50,48,100)
RandomBlock(-8,-6,-2,COBBLESTONE,50,48,100)
RandomBlock(-8,-6,-1,COBBLESTONE,50,48,100)
RandomBlock(-8,-6,0,COBBLESTONE,50,48,100)
RandomBlock(-8,-6,1,COBBLESTONE,50,48,100)
RandomBlock(-8,-6,2,COBBLESTONE,50,48,100)
RandomBlock(-8,-6,3,COBBLESTONE,50,48,100)
RandomBlock(-8,-6,4,COBBLESTONE,50,48,100)
RandomBlock(-8,-6,5,COBBLESTONE,50,48,100)
RandomBlock(-8,-6,6,COBBLESTONE,50,48,100)
RandomBlock(-8,-6,7,COBBLESTONE,50,48,100)
RandomBlock(-8,-6,8,COBBLESTONE,50,48,100)
RandomBlock(-8,-6,9,COBBLESTONE,50,48,100)
RandomBlock(-8,-6,10,COBBLESTONE,50,48,100)
RandomBlock(-8,-5,-10,COBBLESTONE,50,48,100)
RandomBlock(-8,-5,-9,COBBLESTONE,50,48,100)
RandomBlock(-8,-5,-8,COBBLESTONE,50,48,100)
RandomBlock(-8,-5,-7,COBBLESTONE,50,48,100)
RandomBlock(-8,-5,-6,COBBLESTONE,50,48,100)
RandomBlock(-8,-5,-5,COBBLESTONE,50,48,100)
RandomBlock(-8,-5,-4,COBBLESTONE,50,48,100)
RandomBlock(-8,-5,-3,COBBLESTONE,50,48,100)
RandomBlock(-8,-5,-2,COBBLESTONE,50,48,100)
RandomBlock(-8,-5,-1,COBBLESTONE,50,48,100)
RandomBlock(-8,-5,0,COBBLESTONE,50,48,100)
RandomBlock(-8,-5,1,COBBLESTONE,50,48,100)
RandomBlock(-8,-5,2,COBBLESTONE,50,48,100)
RandomBlock(-8,-5,3,COBBLESTONE,50,48,100)
RandomBlock(-8,-5,4,COBBLESTONE,50,48,100)
RandomBlock(-8,-5,5,COBBLESTONE,50,48,100)
RandomBlock(-8,-5,6,COBBLESTONE,50,48,100)
RandomBlock(-8,-5,7,COBBLESTONE,50,48,100)
RandomBlock(-8,-5,8,COBBLESTONE,50,48,100)
RandomBlock(-8,-5,9,COBBLESTONE,50,48,100)
RandomBlock(-8,-5,10,COBBLESTONE,50,48,100)
RandomBlock(-8,-4,-10,COBBLESTONE,50,48,100)
RandomBlock(-8,-4,-9,COBBLESTONE,50,48,100)
RandomBlock(-8,-4,-8,COBBLESTONE,50,48,100)
RandomBlock(-8,-4,-7,COBBLESTONE,50,48,100)
RandomBlock(-8,-4,-6,COBBLESTONE,50,48,100)
RandomBlock(-8,-4,-5,COBBLESTONE,50,48,100)
RandomBlock(-8,-4,-4,COBBLESTONE,50,48,100)
RandomBlock(-8,-4,-3,COBBLESTONE,50,48,100)
RandomBlock(-8,-4,-2,COBBLESTONE,50,48,100)
RandomBlock(-8,-4,-1,COBBLESTONE,50,48,100)
RandomBlock(-8,-4,0,COBBLESTONE,50,48,100)
RandomBlock(-8,-4,1,COBBLESTONE,50,48,100)
RandomBlock(-8,-4,2,COBBLESTONE,50,48,100)
RandomBlock(-8,-4,3,COBBLESTONE,50,48,100)
RandomBlock(-8,-4,4,COBBLESTONE,50,48,100)
RandomBlock(-8,-4,5,COBBLESTONE,50,48,100)
RandomBlock(-8,-4,6,COBBLESTONE,50,48,100)
RandomBlock(-8,-4,7,COBBLESTONE,50,48,100)
RandomBlock(-8,-4,8,COBBLESTONE,50,48,100)
RandomBlock(-8,-4,9,COBBLESTONE,50,48,100)
RandomBlock(-8,-4,10,COBBLESTONE,50,48,100)
RandomBlock(-8,-3,-10,COBBLESTONE,50,48,100)
RandomBlock(-8,-3,-9,COBBLESTONE,50,48,100)
RandomBlock(-8,-3,-8,COBBLESTONE,50,48,100)
RandomBlock(-8,-3,-7,COBBLESTONE,50,48,100)
RandomBlock(-8,-3,-6,COBBLESTONE,50,48,100)
RandomBlock(-8,-3,-5,COBBLESTONE,50,48,100)
RandomBlock(-8,-3,-4,COBBLESTONE,50,48,100)
RandomBlock(-8,-3,-3,COBBLESTONE,50,48,100)
RandomBlock(-8,-3,-2,COBBLESTONE,50,48,100)
RandomBlock(-8,-3,-1,COBBLESTONE,50,48,100)
RandomBlock(-8,-3,0,COBBLESTONE,50,48,100)
RandomBlock(-8,-3,1,COBBLESTONE,50,48,100)
RandomBlock(-8,-3,2,COBBLESTONE,50,48,100)
RandomBlock(-8,-3,3,COBBLESTONE,50,48,100)
RandomBlock(-8,-3,4,COBBLESTONE,50,48,100)
RandomBlock(-8,-3,5,COBBLESTONE,50,48,100)
RandomBlock(-8,-3,6,COBBLESTONE,50,48,100)
RandomBlock(-8,-3,7,COBBLESTONE,50,48,100)
RandomBlock(-8,-3,8,COBBLESTONE,50,48,100)
RandomBlock(-8,-3,9,COBBLESTONE,50,48,100)
RandomBlock(-8,-3,10,COBBLESTONE,50,48,100)
RandomBlock(-8,-2,-10,COBBLESTONE,50,48,100)
RandomBlock(-8,-2,-9,COBBLESTONE,50,48,100)
RandomBlock(-8,-2,-8,COBBLESTONE,50,48,100)
RandomBlock(-8,-2,-7,COBBLESTONE,50,48,100)
RandomBlock(-8,-2,-6,COBBLESTONE,50,48,100)
RandomBlock(-8,-2,-5,COBBLESTONE,50,48,100)
RandomBlock(-8,-2,-4,COBBLESTONE,50,48,100)
RandomBlock(-8,-2,-3,COBBLESTONE,50,48,100)
RandomBlock(-8,-2,-2,COBBLESTONE,50,48,100)
RandomBlock(-8,-2,-1,COBBLESTONE,50,48,100)
RandomBlock(-8,-2,0,COBBLESTONE,50,48,100)
RandomBlock(-8,-2,1,COBBLESTONE,50,48,100)
RandomBlock(-8,-2,2,COBBLESTONE,50,48,100)
RandomBlock(-8,-2,3,COBBLESTONE,50,48,100)
RandomBlock(-8,-2,4,COBBLESTONE,50,48,100)
RandomBlock(-8,-2,5,COBBLESTONE,50,48,100)
RandomBlock(-8,-2,6,COBBLESTONE,50,48,100)
RandomBlock(-8,-2,7,COBBLESTONE,50,48,100)
RandomBlock(-8,-2,8,COBBLESTONE,50,48,100)
RandomBlock(-8,-2,9,COBBLESTONE,50,48,100)
RandomBlock(-8,-2,10,COBBLESTONE,50,48,100)
RandomBlock(-8,-1,-10,COBBLESTONE,50,48,100)
RandomBlock(-8,-1,-9,COBBLESTONE,50,48,100)
RandomBlock(-8,-1,-8,COBBLESTONE,50,48,100)
RandomBlock(-8,-1,-7,COBBLESTONE,50,48,100)
RandomBlock(-8,-1,-6,COBBLESTONE,50,48,100)
RandomBlock(-8,-1,-5,COBBLESTONE,50,48,100)
RandomBlock(-8,-1,-4,COBBLESTONE,50,48,100)
RandomBlock(-8,-1,-3,COBBLESTONE,50,48,100)
RandomBlock(-8,-1,-2,COBBLESTONE,50,48,100)
RandomBlock(-8,-1,-1,COBBLESTONE,50,48,100)
RandomBlock(-8,-1,0,COBBLESTONE,50,48,100)
RandomBlock(-8,-1,1,COBBLESTONE,50,48,100)
RandomBlock(-8,-1,2,COBBLESTONE,50,48,100)
RandomBlock(-8,-1,3,COBBLESTONE,50,48,100)
RandomBlock(-8,-1,4,COBBLESTONE,50,48,100)
RandomBlock(-8,-1,5,COBBLESTONE,50,48,100)
RandomBlock(-8,-1,6,COBBLESTONE,50,48,100)
RandomBlock(-8,-1,7,COBBLESTONE,50,48,100)
RandomBlock(-8,-1,8,COBBLESTONE,50,48,100)
RandomBlock(-8,-1,9,COBBLESTONE,50,48,100)
RandomBlock(-8,-1,10,COBBLESTONE,50,48,100)
RandomBlock(-8,0,-10,COBBLESTONE,50,48,100)
RandomBlock(-8,0,-9,COBBLESTONE,50,48,100)
RandomBlock(-8,0,-8,COBBLESTONE,50,48,100)
RandomBlock(-8,0,-7,COBBLESTONE,50,48,100)
RandomBlock(-8,0,-6,COBBLESTONE,50,48,100)
RandomBlock(-8,0,-5,COBBLESTONE,50,48,100)
RandomBlock(-8,0,-4,COBBLESTONE,50,48,100)
RandomBlock(-8,0,-3,COBBLESTONE,50,48,100)
RandomBlock(-8,0,-2,COBBLESTONE,50,48,100)
RandomBlock(-8,0,-1,COBBLESTONE,50,48,100)
RandomBlock(-8,0,0,COBBLESTONE,50,48,100)
RandomBlock(-8,0,1,COBBLESTONE,50,48,100)
RandomBlock(-8,0,2,COBBLESTONE,50,48,100)
RandomBlock(-8,0,3,COBBLESTONE,50,48,100)
RandomBlock(-8,0,4,COBBLESTONE,50,48,100)
RandomBlock(-8,0,5,COBBLESTONE,50,48,100)
RandomBlock(-8,0,6,COBBLESTONE,50,48,100)
RandomBlock(-8,0,7,COBBLESTONE,50,48,100)
RandomBlock(-8,0,8,COBBLESTONE,50,48,100)
RandomBlock(-8,0,9,COBBLESTONE,50,48,100)
RandomBlock(-8,0,10,COBBLESTONE,50,48,100)
Block(-8,1,-10,98:3)
Block(-8,1,-8,67:1)
RandomBlock(-8,1,-7,COBBLESTONE,50,48,100)
RandomBlock(-8,1,-6,COBBLESTONE,50,48,100)
RandomBlock(-8,1,9,COBBLESTONE,50,48,100)
RandomBlock(-8,1,10,GRAVEL,44,AIR,100)
Block(-8,2,-10,98:3)
Block(-8,2,-9,VINE:4)
RandomBlock(-8,2,-7,COBBLESTONE,50,48,100)
RandomBlock(-8,2,-6,COBBLESTONE,50,48,100)
RandomBlock(-8,2,-5,COBBLESTONE,50,48,100)
RandomBlock(-8,2,-4,COBBLESTONE,50,48,100)
RandomBlock(-8,2,-3,COBBLESTONE,50,48,100)
RandomBlock(-8,2,-2,COBBLESTONE,50,48,100)
RandomBlock(-8,2,-1,COBBLESTONE,50,48,100)
RandomBlock(-8,2,0,COBBLESTONE,50,48,100)
RandomBlock(-8,2,1,COBBLESTONE,50,48,100)
RandomBlock(-8,2,2,COBBLESTONE,50,48,100)
RandomBlock(-8,2,3,COBBLESTONE,50,48,100)
RandomBlock(-8,2,4,COBBLESTONE,50,48,100)
RandomBlock(-8,2,5,COBBLESTONE,50,48,100)
RandomBlock(-8,2,6,COBBLESTONE,50,48,100)
RandomBlock(-8,2,7,COBBLESTONE,50,48,100)
RandomBlock(-8,2,8,COBBLESTONE,50,48,100)
Block(-8,3,-11,VINE:1)
Block(-8,3,-10,98:3)
Block(-8,3,-6,67:2)
RandomBlock(-8,3,-5,COBBLESTONE,50,48,100)
RandomBlock(-8,3,-4,COBBLESTONE,50,48,100)
RandomBlock(-8,3,-3,COBBLESTONE,50,48,100)
RandomBlock(-8,3,-2,COBBLESTONE,50,48,100)
RandomBlock(-8,3,-1,COBBLESTONE,50,48,100)
RandomBlock(-8,3,0,COBBLESTONE,50,48,100)
RandomBlock(-8,3,1,COBBLESTONE,50,48,100)
RandomBlock(-8,3,3,GRAVEL,44,AIR,100)
Block(-8,4,-11,VINE:1)
Block(-8,4,-10,98:1)
Block(-8,4,-5,67:2)
RandomBlock(-8,4,-4,COBBLESTONE,50,48,100)
RandomBlock(-8,4,-3,COBBLESTONE,50,48,100)
RandomBlock(-8,4,-2,COBBLESTONE,50,48,100)
RandomBlock(-8,4,-1,COBBLESTONE,50,48,100)
RandomBlock(-8,4,0,COBBLESTONE,50,48,100)
RandomBlock(-8,4,1,COBBLESTONE,50,48,100)
Block(-8,5,-11,VINE:1)
Block(-8,5,-10,98:3)
Block(-8,6,-11,VINE:1)
Block(-8,6,-10,98:1)
Block(-8,6,-7,VINE:1)
Block(-8,7,-11,VINE:1)
Block(-8,7,-10,98:3)
Block(-8,7,-7,VINE:1)
RandomBlock(-8,7,-6,COBBLESTONE,50,48,100)
Block(-8,8,-11,VINE:1)
RandomBlock(-8,8,-10,COBBLESTONE,50,48,100)
RandomBlock(-8,8,-6,COBBLESTONE,50,48,100)
Block(-8,9,-10,67:2)
RandomBlock(-8,9,-9,COBBLESTONE,50,48,100)
RandomBlock(-8,9,-8,COBBLESTONE,50,48,100)
RandomBlock(-8,9,-7,COBBLESTONE,50,48,100)
Block(-8,9,-6,67:3)
RandomBlock(-7,-13,-10,COBBLESTONE,50,48,100)
RandomBlock(-7,-13,-9,COBBLESTONE,50,48,100)
RandomBlock(-7,-13,-8,COBBLESTONE,50,48,100)
RandomBlock(-7,-13,-7,COBBLESTONE,50,48,100)
RandomBlock(-7,-13,-6,COBBLESTONE,50,48,100)
RandomBlock(-7,-13,-5,COBBLESTONE,50,48,100)
RandomBlock(-7,-13,-4,COBBLESTONE,50,48,100)
RandomBlock(-7,-13,-3,COBBLESTONE,50,48,100)
RandomBlock(-7,-13,-2,COBBLESTONE,50,48,100)
RandomBlock(-7,-13,-1,COBBLESTONE,50,48,100)
RandomBlock(-7,-13,0,COBBLESTONE,50,48,100)
RandomBlock(-7,-13,1,COBBLESTONE,50,48,100)
RandomBlock(-7,-13,2,COBBLESTONE,50,48,100)
RandomBlock(-7,-13,3,COBBLESTONE,50,48,100)
RandomBlock(-7,-13,4,COBBLESTONE,50,48,100)
RandomBlock(-7,-13,5,COBBLESTONE,50,48,100)
RandomBlock(-7,-13,6,COBBLESTONE,50,48,100)
RandomBlock(-7,-13,7,COBBLESTONE,50,48,100)
RandomBlock(-7,-13,8,COBBLESTONE,50,48,100)
RandomBlock(-7,-13,9,COBBLESTONE,50,48,100)
RandomBlock(-7,-13,10,COBBLESTONE,50,48,100)
RandomBlock(-7,-12,-10,COBBLESTONE,50,48,100)
Block(-7,-12,-9,STATIONARY_WATER)
Block(-7,-12,-8,STATIONARY_WATER)
Block(-7,-12,-7,STATIONARY_WATER)
Block(-7,-12,-6,STATIONARY_WATER)
Block(-7,-12,-5,STATIONARY_WATER)
Block(-7,-12,-4,STATIONARY_WATER)
Block(-7,-12,-3,STATIONARY_WATER)
Block(-7,-12,-2,STATIONARY_WATER)
Block(-7,-12,-1,STATIONARY_WATER)
Block(-7,-12,0,STATIONARY_WATER)
Block(-7,-12,1,STATIONARY_WATER)
Block(-7,-12,2,STATIONARY_WATER)
Block(-7,-12,3,STATIONARY_WATER)
Block(-7,-12,4,STATIONARY_WATER)
Block(-7,-12,5,STATIONARY_WATER)
Block(-7,-12,6,STATIONARY_WATER)
Block(-7,-12,7,STATIONARY_WATER)
Block(-7,-12,8,STATIONARY_WATER)
Block(-7,-12,9,STATIONARY_WATER)
RandomBlock(-7,-12,10,COBBLESTONE,50,48,100)
RandomBlock(-7,-11,-10,COBBLESTONE,50,48,100)
Block(-7,-11,-9,AIR)
Block(-7,-11,-8,AIR)
Block(-7,-11,-7,AIR)
Block(-7,-11,-6,AIR)
Block(-7,-11,-5,AIR)
Block(-7,-11,-4,AIR)
Block(-7,-11,-3,AIR)
Block(-7,-11,-2,AIR)
Block(-7,-11,-1,AIR)
Block(-7,-11,0,AIR)
Block(-7,-11,1,AIR)
Block(-7,-11,2,AIR)
Block(-7,-11,3,AIR)
Block(-7,-11,4,AIR)
Block(-7,-11,5,AIR)
Block(-7,-11,6,AIR)
Block(-7,-11,7,AIR)
Block(-7,-11,8,AIR)
Block(-7,-11,9,AIR)
RandomBlock(-7,-11,10,COBBLESTONE,50,48,100)
RandomBlock(-7,-10,-10,COBBLESTONE,50,48,100)
Block(-7,-10,-9,AIR)
Block(-7,-10,-8,AIR)
Block(-7,-10,-7,AIR)
Block(-7,-10,-6,AIR)
Block(-7,-10,-5,AIR)
Block(-7,-10,-4,AIR)
Block(-7,-10,-3,AIR)
Block(-7,-10,-2,AIR)
Block(-7,-10,-1,AIR)
Block(-7,-10,0,AIR)
Block(-7,-10,1,AIR)
Block(-7,-10,2,AIR)
Block(-7,-10,3,AIR)
Block(-7,-10,4,AIR)
Block(-7,-10,5,AIR)
Block(-7,-10,6,AIR)
Block(-7,-10,7,AIR)
Block(-7,-10,8,AIR)
Block(-7,-10,9,AIR)
RandomBlock(-7,-10,10,COBBLESTONE,50,48,100)
RandomBlock(-7,-9,-10,COBBLESTONE,50,48,100)
RandomBlock(-7,-9,-9,COBBLESTONE,50,48,100)
RandomBlock(-7,-9,-8,COBBLESTONE,50,48,100)
RandomBlock(-7,-9,-7,COBBLESTONE,50,48,100)
RandomBlock(-7,-9,-6,COBBLESTONE,50,48,100)
RandomBlock(-7,-9,-5,COBBLESTONE,50,48,100)
RandomBlock(-7,-9,-4,COBBLESTONE,50,48,100)
RandomBlock(-7,-9,-3,COBBLESTONE,50,48,100)
RandomBlock(-7,-9,-2,COBBLESTONE,50,48,100)
RandomBlock(-7,-9,-1,COBBLESTONE,50,48,100)
Block(-7,-9,0,AIR)
Block(-7,-9,1,AIR)
RandomBlock(-7,-9,2,COBBLESTONE,50,48,100)
RandomBlock(-7,-9,3,COBBLESTONE,50,48,100)
RandomBlock(-7,-9,4,COBBLESTONE,50,48,100)
RandomBlock(-7,-9,5,COBBLESTONE,50,48,100)
RandomBlock(-7,-9,6,COBBLESTONE,50,48,100)
RandomBlock(-7,-9,7,COBBLESTONE,50,48,100)
RandomBlock(-7,-9,8,COBBLESTONE,50,48,100)
RandomBlock(-7,-9,9,COBBLESTONE,50,48,100)
RandomBlock(-7,-9,10,COBBLESTONE,50,48,100)
RandomBlock(-7,-8,-10,COBBLESTONE,50,48,100)
RandomBlock(-7,-8,-9,COBBLESTONE,50,48,100)
RandomBlock(-7,-8,-8,COBBLESTONE,50,48,100)
RandomBlock(-7,-8,-7,COBBLESTONE,50,48,100)
RandomBlock(-7,-8,-6,COBBLESTONE,50,48,100)
RandomBlock(-7,-8,-5,COBBLESTONE,50,48,100)
RandomBlock(-7,-8,-4,COBBLESTONE,50,48,100)
RandomBlock(-7,-8,-3,COBBLESTONE,50,48,100)
RandomBlock(-7,-8,-2,COBBLESTONE,50,48,100)
RandomBlock(-7,-8,-1,COBBLESTONE,50,48,100)
RandomBlock(-7,-8,0,COBBLESTONE,50,48,100)
RandomBlock(-7,-8,1,COBBLESTONE,50,48,100)
RandomBlock(-7,-8,2,COBBLESTONE,50,48,100)
RandomBlock(-7,-8,3,COBBLESTONE,50,48,100)
RandomBlock(-7,-8,4,COBBLESTONE,50,48,100)
RandomBlock(-7,-8,5,COBBLESTONE,50,48,100)
RandomBlock(-7,-8,6,COBBLESTONE,50,48,100)
RandomBlock(-7,-8,7,COBBLESTONE,50,48,100)
RandomBlock(-7,-8,8,COBBLESTONE,50,48,100)
RandomBlock(-7,-8,9,COBBLESTONE,50,48,100)
RandomBlock(-7,-8,10,COBBLESTONE,50,48,100)
RandomBlock(-7,-7,-10,COBBLESTONE,50,48,100)
RandomBlock(-7,-7,-9,COBBLESTONE,50,48,100)
RandomBlock(-7,-7,-8,COBBLESTONE,50,48,100)
RandomBlock(-7,-7,-7,COBBLESTONE,50,48,100)
RandomBlock(-7,-7,-6,COBBLESTONE,50,48,100)
RandomBlock(-7,-7,-5,COBBLESTONE,50,48,100)
RandomBlock(-7,-7,-4,COBBLESTONE,50,48,100)
RandomBlock(-7,-7,-3,COBBLESTONE,50,48,100)
RandomBlock(-7,-7,-2,COBBLESTONE,50,48,100)
RandomBlock(-7,-7,-1,COBBLESTONE,50,48,100)
RandomBlock(-7,-7,0,COBBLESTONE,50,48,100)
RandomBlock(-7,-7,1,COBBLESTONE,50,48,100)
RandomBlock(-7,-7,2,COBBLESTONE,50,48,100)
RandomBlock(-7,-7,3,COBBLESTONE,50,48,100)
RandomBlock(-7,-7,4,COBBLESTONE,50,48,100)
RandomBlock(-7,-7,5,COBBLESTONE,50,48,100)
RandomBlock(-7,-7,6,COBBLESTONE,50,48,100)
RandomBlock(-7,-7,7,COBBLESTONE,50,48,100)
RandomBlock(-7,-7,8,COBBLESTONE,50,48,100)
RandomBlock(-7,-7,9,COBBLESTONE,50,48,100)
RandomBlock(-7,-7,10,COBBLESTONE,50,48,100)
RandomBlock(-7,-6,-10,COBBLESTONE,50,48,100)
RandomBlock(-7,-6,-9,COBBLESTONE,50,48,100)
RandomBlock(-7,-6,-8,COBBLESTONE,50,48,100)
RandomBlock(-7,-6,-7,COBBLESTONE,50,48,100)
RandomBlock(-7,-6,-6,COBBLESTONE,50,48,100)
RandomBlock(-7,-6,-5,COBBLESTONE,50,48,100)
RandomBlock(-7,-6,-4,COBBLESTONE,50,48,100)
RandomBlock(-7,-6,-3,COBBLESTONE,50,48,100)
RandomBlock(-7,-6,-2,COBBLESTONE,50,48,100)
RandomBlock(-7,-6,-1,COBBLESTONE,50,48,100)
RandomBlock(-7,-6,0,COBBLESTONE,50,48,100)
RandomBlock(-7,-6,1,COBBLESTONE,50,48,100)
RandomBlock(-7,-6,2,COBBLESTONE,50,48,100)
RandomBlock(-7,-6,3,COBBLESTONE,50,48,100)
RandomBlock(-7,-6,4,COBBLESTONE,50,48,100)
RandomBlock(-7,-6,5,COBBLESTONE,50,48,100)
RandomBlock(-7,-6,6,COBBLESTONE,50,48,100)
RandomBlock(-7,-6,7,COBBLESTONE,50,48,100)
RandomBlock(-7,-6,8,COBBLESTONE,50,48,100)
RandomBlock(-7,-6,9,COBBLESTONE,50,48,100)
RandomBlock(-7,-6,10,COBBLESTONE,50,48,100)
RandomBlock(-7,-5,-10,COBBLESTONE,50,48,100)
RandomBlock(-7,-5,-9,COBBLESTONE,50,48,100)
RandomBlock(-7,-5,-8,COBBLESTONE,50,48,100)
RandomBlock(-7,-5,-7,COBBLESTONE,50,48,100)
RandomBlock(-7,-5,-6,COBBLESTONE,50,48,100)
RandomBlock(-7,-5,-5,COBBLESTONE,50,48,100)
RandomBlock(-7,-5,-4,COBBLESTONE,50,48,100)
RandomBlock(-7,-5,-3,COBBLESTONE,50,48,100)
RandomBlock(-7,-5,-2,COBBLESTONE,50,48,100)
RandomBlock(-7,-5,-1,COBBLESTONE,50,48,100)
RandomBlock(-7,-5,0,COBBLESTONE,50,48,100)
RandomBlock(-7,-5,1,COBBLESTONE,50,48,100)
RandomBlock(-7,-5,2,COBBLESTONE,50,48,100)
RandomBlock(-7,-5,3,COBBLESTONE,50,48,100)
RandomBlock(-7,-5,4,COBBLESTONE,50,48,100)
RandomBlock(-7,-5,5,COBBLESTONE,50,48,100)
RandomBlock(-7,-5,6,COBBLESTONE,50,48,100)
RandomBlock(-7,-5,7,COBBLESTONE,50,48,100)
RandomBlock(-7,-5,8,COBBLESTONE,50,48,100)
RandomBlock(-7,-5,9,COBBLESTONE,50,48,100)
RandomBlock(-7,-5,10,COBBLESTONE,50,48,100)
RandomBlock(-7,-4,-10,COBBLESTONE,50,48,100)
RandomBlock(-7,-4,-9,COBBLESTONE,50,48,100)
RandomBlock(-7,-4,-8,COBBLESTONE,50,48,100)
RandomBlock(-7,-4,-7,COBBLESTONE,50,48,100)
RandomBlock(-7,-4,-6,COBBLESTONE,50,48,100)
RandomBlock(-7,-4,-5,COBBLESTONE,50,48,100)
RandomBlock(-7,-4,-4,COBBLESTONE,50,48,100)
RandomBlock(-7,-4,-3,COBBLESTONE,50,48,100)
RandomBlock(-7,-4,-2,COBBLESTONE,50,48,100)
RandomBlock(-7,-4,-1,COBBLESTONE,50,48,100)
RandomBlock(-7,-4,0,COBBLESTONE,50,48,100)
RandomBlock(-7,-4,1,COBBLESTONE,50,48,100)
RandomBlock(-7,-4,2,COBBLESTONE,50,48,100)
RandomBlock(-7,-4,3,COBBLESTONE,50,48,100)
RandomBlock(-7,-4,4,COBBLESTONE,50,48,100)
RandomBlock(-7,-4,5,COBBLESTONE,50,48,100)
RandomBlock(-7,-4,6,COBBLESTONE,50,48,100)
RandomBlock(-7,-4,7,COBBLESTONE,50,48,100)
RandomBlock(-7,-4,8,COBBLESTONE,50,48,100)
RandomBlock(-7,-4,9,COBBLESTONE,50,48,100)
RandomBlock(-7,-4,10,COBBLESTONE,50,48,100)
RandomBlock(-7,-3,-10,COBBLESTONE,50,48,100)
RandomBlock(-7,-3,-9,COBBLESTONE,50,48,100)
RandomBlock(-7,-3,-8,COBBLESTONE,50,48,100)
RandomBlock(-7,-3,-7,COBBLESTONE,50,48,100)
RandomBlock(-7,-3,-6,COBBLESTONE,50,48,100)
RandomBlock(-7,-3,-5,COBBLESTONE,50,48,100)
RandomBlock(-7,-3,-4,COBBLESTONE,50,48,100)
RandomBlock(-7,-3,-3,COBBLESTONE,50,48,100)
RandomBlock(-7,-3,-2,COBBLESTONE,50,48,100)
RandomBlock(-7,-3,-1,COBBLESTONE,50,48,100)
RandomBlock(-7,-3,0,COBBLESTONE,50,48,100)
RandomBlock(-7,-3,1,COBBLESTONE,50,48,100)
RandomBlock(-7,-3,2,COBBLESTONE,50,48,100)
RandomBlock(-7,-3,3,COBBLESTONE,50,48,100)
RandomBlock(-7,-3,4,COBBLESTONE,50,48,100)
RandomBlock(-7,-3,5,COBBLESTONE,50,48,100)
RandomBlock(-7,-3,6,COBBLESTONE,50,48,100)
RandomBlock(-7,-3,7,COBBLESTONE,50,48,100)
RandomBlock(-7,-3,8,COBBLESTONE,50,48,100)
RandomBlock(-7,-3,9,COBBLESTONE,50,48,100)
RandomBlock(-7,-3,10,COBBLESTONE,50,48,100)
RandomBlock(-7,-2,-10,COBBLESTONE,50,48,100)
RandomBlock(-7,-2,-9,COBBLESTONE,50,48,100)
RandomBlock(-7,-2,-8,COBBLESTONE,50,48,100)
RandomBlock(-7,-2,-7,COBBLESTONE,50,48,100)
RandomBlock(-7,-2,-6,COBBLESTONE,50,48,100)
RandomBlock(-7,-2,-5,COBBLESTONE,50,48,100)
RandomBlock(-7,-2,-4,COBBLESTONE,50,48,100)
RandomBlock(-7,-2,-3,COBBLESTONE,50,48,100)
RandomBlock(-7,-2,-2,COBBLESTONE,50,48,100)
RandomBlock(-7,-2,-1,COBBLESTONE,50,48,100)
RandomBlock(-7,-2,0,COBBLESTONE,50,48,100)
RandomBlock(-7,-2,1,COBBLESTONE,50,48,100)
RandomBlock(-7,-2,2,COBBLESTONE,50,48,100)
RandomBlock(-7,-2,3,COBBLESTONE,50,48,100)
RandomBlock(-7,-2,4,COBBLESTONE,50,48,100)
RandomBlock(-7,-2,5,COBBLESTONE,50,48,100)
RandomBlock(-7,-2,6,COBBLESTONE,50,48,100)
RandomBlock(-7,-2,7,COBBLESTONE,50,48,100)
RandomBlock(-7,-2,8,COBBLESTONE,50,48,100)
RandomBlock(-7,-2,9,COBBLESTONE,50,48,100)
RandomBlock(-7,-2,10,COBBLESTONE,50,48,100)
RandomBlock(-7,-1,-10,COBBLESTONE,50,48,100)
RandomBlock(-7,-1,-9,COBBLESTONE,50,48,100)
RandomBlock(-7,-1,-8,COBBLESTONE,50,48,100)
RandomBlock(-7,-1,-7,COBBLESTONE,50,48,100)
RandomBlock(-7,-1,-6,COBBLESTONE,50,48,100)
RandomBlock(-7,-1,-5,COBBLESTONE,50,48,100)
RandomBlock(-7,-1,-4,COBBLESTONE,50,48,100)
RandomBlock(-7,-1,-3,COBBLESTONE,50,48,100)
RandomBlock(-7,-1,-2,COBBLESTONE,50,48,100)
RandomBlock(-7,-1,-1,COBBLESTONE,50,48,100)
RandomBlock(-7,-1,0,COBBLESTONE,50,48,100)
RandomBlock(-7,-1,1,COBBLESTONE,50,48,100)
RandomBlock(-7,-1,2,COBBLESTONE,50,48,100)
RandomBlock(-7,-1,3,COBBLESTONE,50,48,100)
RandomBlock(-7,-1,4,COBBLESTONE,50,48,100)
RandomBlock(-7,-1,5,COBBLESTONE,50,48,100)
RandomBlock(-7,-1,6,COBBLESTONE,50,48,100)
RandomBlock(-7,-1,7,COBBLESTONE,50,48,100)
RandomBlock(-7,-1,8,COBBLESTONE,50,48,100)
RandomBlock(-7,-1,9,COBBLESTONE,50,48,100)
RandomBlock(-7,-1,10,COBBLESTONE,50,48,100)
RandomBlock(-7,0,-10,COBBLESTONE,50,48,100)
RandomBlock(-7,0,-9,COBBLESTONE,50,48,100)
RandomBlock(-7,0,-8,COBBLESTONE,50,48,100)
RandomBlock(-7,0,-7,COBBLESTONE,50,48,100)
RandomBlock(-7,0,-6,COBBLESTONE,50,48,100)
RandomBlock(-7,0,-5,COBBLESTONE,50,48,100)
RandomBlock(-7,0,-4,COBBLESTONE,50,48,100)
RandomBlock(-7,0,-3,COBBLESTONE,50,48,100)
RandomBlock(-7,0,-2,COBBLESTONE,50,48,100)
RandomBlock(-7,0,-1,COBBLESTONE,50,48,100)
RandomBlock(-7,0,0,COBBLESTONE,50,48,100)
RandomBlock(-7,0,1,COBBLESTONE,50,48,100)
RandomBlock(-7,0,2,COBBLESTONE,50,48,100)
RandomBlock(-7,0,3,COBBLESTONE,50,48,100)
RandomBlock(-7,0,4,COBBLESTONE,50,48,100)
RandomBlock(-7,0,5,COBBLESTONE,50,48,100)
RandomBlock(-7,0,6,COBBLESTONE,50,48,100)
RandomBlock(-7,0,7,COBBLESTONE,50,48,100)
RandomBlock(-7,0,8,COBBLESTONE,50,48,100)
RandomBlock(-7,0,9,COBBLESTONE,50,48,100)
RandomBlock(-7,0,10,COBBLESTONE,50,48,100)
Block(-7,1,-10,98)
RandomBlock(-7,1,-7,COBBLESTONE,50,48,100)
RandomBlock(-7,1,-6,COBBLESTONE,50,48,100)
RandomBlock(-7,1,-2,MOB_SPAWNER,../../nbt/Spawner/Skeleton.nbt,50,MOB_SPAWNER,../../nbt/Spawner/Zombie.nbt,50)
Block(-7,1,1,VINE:2)
RandomBlock(-7,1,9,COBBLESTONE,50,48,100)
Block(-7,2,-11,VINE:1)
Block(-7,2,-10,98)
RandomBlock(-7,2,-7,COBBLESTONE,50,48,100)
RandomBlock(-7,2,-6,COBBLESTONE,50,48,100)
Block(-7,2,1,VINE:2)
RandomBlock(-7,2,8,COBBLESTONE,50,48,100)
Block(-7,2,9,VINE:4)
Block(-7,3,-11,VINE:1)
Block(-7,3,-10,98)
RandomBlock(-7,3,-6,COBBLESTONE,50,48,100)
RandomBlock(-7,3,-5,COBBLESTONE,50,48,100)
RandomBlock(-7,3,-4,COBBLESTONE,50,48,100)
RandomBlock(-7,3,-3,COBBLESTONE,50,48,100)
RandomBlock(-7,3,-2,COBBLESTONE,50,48,100)
RandomBlock(-7,3,-1,COBBLESTONE,50,48,100)
RandomBlock(-7,3,0,COBBLESTONE,50,48,100)
RandomBlock(-7,3,1,COBBLESTONE,50,48,100)
RandomBlock(-7,3,2,COBBLESTONE,50,48,100)
RandomBlock(-7,3,3,COBBLESTONE,50,48,100)
RandomBlock(-7,3,4,COBBLESTONE,50,48,100)
RandomBlock(-7,3,5,98:2,44,AIR,100)
RandomBlock(-7,3,6,COBBLESTONE,50,48,100)
RandomBlock(-7,3,7,COBBLESTONE,50,48,100)
RandomBlock(-7,3,8,GRAVEL,44,AIR,100)
Block(-7,4,-11,VINE:1)
Block(-7,4,-10,98:3)
RandomBlock(-7,4,-6,COBBLESTONE,50,48,100)
RandomBlock(-7,4,-5,COBBLESTONE,50,48,100)
RandomBlock(-7,4,-4,COBBLESTONE,50,48,100)
RandomBlock(-7,4,-3,COBBLESTONE,50,48,100)
RandomBlock(-7,4,-2,COBBLESTONE,50,48,100)
RandomBlock(-7,4,-1,COBBLESTONE,50,48,100)
RandomBlock(-7,4,0,COBBLESTONE,50,48,100)
RandomBlock(-7,4,1,COBBLESTONE,50,48,100)
Block(-7,4,3,VINE:8)
Block(-7,4,4,VINE:8)
RandomBlock(-7,4,6,GRAVEL,44,AIR,100)
RandomBlock(-7,4,7,GRAVEL,44,AIR,100)
Block(-7,5,-11,VINE:1)
Block(-7,5,-10,98)
Block(-7,5,-8,VINE:8)
RandomBlock(-7,5,-6,COBBLESTONE,50,48,100)
RandomBlock(-7,5,1,GRAVEL,44,AIR,100)
Block(-7,5,4,VINE:8)
Block(-7,6,-11,VINE:1)
Block(-7,6,-10,98:3)
RandomBlock(-7,6,-6,COBBLESTONE,50,48,100)
Block(-7,7,-11,VINE:1)
Block(-7,7,-10,98:3)
RandomBlock(-7,7,-6,COBBLESTONE,50,48,100)
RandomBlock(-7,8,-10,COBBLESTONE,50,48,100)
RandomBlock(-7,8,-6,98:2,44,AIR,100)
RandomBlock(-7,9,-10,GRAVEL,44,AIR,100)
RandomBlock(-7,9,-9,COBBLESTONE,50,48,100)
RandomBlock(-7,9,-8,COBBLESTONE,50,48,100)
RandomBlock(-7,9,-7,COBBLESTONE,50,48,100)
RandomBlock(-6,-13,-10,COBBLESTONE,50,48,100)
RandomBlock(-6,-13,-9,COBBLESTONE,50,48,100)
RandomBlock(-6,-13,-8,COBBLESTONE,50,48,100)
RandomBlock(-6,-13,-7,COBBLESTONE,50,48,100)
RandomBlock(-6,-13,-6,COBBLESTONE,50,48,100)
RandomBlock(-6,-13,-5,COBBLESTONE,50,48,100)
RandomBlock(-6,-13,-4,COBBLESTONE,50,48,100)
RandomBlock(-6,-13,-3,COBBLESTONE,50,48,100)
RandomBlock(-6,-13,-2,COBBLESTONE,50,48,100)
RandomBlock(-6,-13,-1,COBBLESTONE,50,48,100)
RandomBlock(-6,-13,0,COBBLESTONE,50,48,100)
RandomBlock(-6,-13,1,COBBLESTONE,50,48,100)
RandomBlock(-6,-13,2,COBBLESTONE,50,48,100)
RandomBlock(-6,-13,3,COBBLESTONE,50,48,100)
RandomBlock(-6,-13,4,COBBLESTONE,50,48,100)
RandomBlock(-6,-13,5,COBBLESTONE,50,48,100)
RandomBlock(-6,-13,6,COBBLESTONE,50,48,100)
RandomBlock(-6,-13,7,COBBLESTONE,50,48,100)
RandomBlock(-6,-13,8,COBBLESTONE,50,48,100)
RandomBlock(-6,-13,9,COBBLESTONE,50,48,100)
RandomBlock(-6,-13,10,COBBLESTONE,50,48,100)
RandomBlock(-6,-12,-10,COBBLESTONE,50,48,100)
Block(-6,-12,-9,STATIONARY_WATER)
Block(-6,-12,-8,STATIONARY_WATER)
Block(-6,-12,-7,STATIONARY_WATER)
Block(-6,-12,-6,GRAVEL)
Block(-6,-12,-5,GRAVEL)
Block(-6,-12,-4,GRAVEL)
Block(-6,-12,-3,GRAVEL)
Block(-6,-12,-2,GRAVEL)
Block(-6,-12,-1,GRAVEL)
Block(-6,-12,0,GRAVEL)
Block(-6,-12,1,GRAVEL)
Block(-6,-12,2,GRAVEL)
Block(-6,-12,3,GRAVEL)
Block(-6,-12,4,GRAVEL)
Block(-6,-12,5,GRAVEL)
Block(-6,-12,6,GRAVEL)
Block(-6,-12,7,GRAVEL)
Block(-6,-12,8,STATIONARY_WATER)
Block(-6,-12,9,STATIONARY_WATER)
RandomBlock(-6,-12,10,COBBLESTONE,50,48,100)
RandomBlock(-6,-11,-10,COBBLESTONE,50,48,100)
Block(-6,-11,-9,AIR)
Block(-6,-11,-8,AIR)
Block(-6,-11,-7,AIR)
Block(-6,-11,-6,AIR)
Block(-6,-11,-5,AIR)
Block(-6,-11,-4,AIR)
Block(-6,-11,-3,AIR)
Block(-6,-11,-2,AIR)
Block(-6,-11,-1,AIR)
Block(-6,-11,0,AIR)
Block(-6,-11,1,AIR)
Block(-6,-11,2,AIR)
Block(-6,-11,3,AIR)
Block(-6,-11,4,AIR)
Block(-6,-11,5,AIR)
Block(-6,-11,6,AIR)
Block(-6,-11,7,AIR)
Block(-6,-11,8,AIR)
Block(-6,-11,9,AIR)
RandomBlock(-6,-11,10,COBBLESTONE,50,48,100)
RandomBlock(-6,-10,-10,COBBLESTONE,50,48,100)
Block(-6,-10,-9,AIR)
Block(-6,-10,-8,AIR)
Block(-6,-10,-7,AIR)
Block(-6,-10,-6,AIR)
Block(-6,-10,-5,AIR)
Block(-6,-10,-4,AIR)
Block(-6,-10,-3,AIR)
Block(-6,-10,-2,AIR)
Block(-6,-10,-1,AIR)
Block(-6,-10,0,AIR)
Block(-6,-10,1,AIR)
Block(-6,-10,2,AIR)
Block(-6,-10,3,AIR)
Block(-6,-10,4,AIR)
Block(-6,-10,5,AIR)
Block(-6,-10,6,AIR)
Block(-6,-10,7,AIR)
Block(-6,-10,8,AIR)
Block(-6,-10,9,AIR)
RandomBlock(-6,-10,10,COBBLESTONE,50,48,100)
RandomBlock(-6,-9,-10,COBBLESTONE,50,48,100)
RandomBlock(-6,-9,-9,COBBLESTONE,50,48,100)
RandomBlock(-6,-9,-8,COBBLESTONE,50,48,100)
RandomBlock(-6,-9,-7,COBBLESTONE,50,48,100)
RandomBlock(-6,-9,-6,COBBLESTONE,50,48,100)
RandomBlock(-6,-9,-5,COBBLESTONE,50,48,100)
RandomBlock(-6,-9,-4,COBBLESTONE,50,48,100)
RandomBlock(-6,-9,-3,COBBLESTONE,50,48,100)
RandomBlock(-6,-9,-2,COBBLESTONE,50,48,100)
RandomBlock(-6,-9,-1,COBBLESTONE,50,48,100)
Block(-6,-9,0,AIR)
Block(-6,-9,1,AIR)
RandomBlock(-6,-9,2,COBBLESTONE,50,48,100)
RandomBlock(-6,-9,3,COBBLESTONE,50,48,100)
RandomBlock(-6,-9,4,COBBLESTONE,50,48,100)
RandomBlock(-6,-9,5,COBBLESTONE,50,48,100)
RandomBlock(-6,-9,6,COBBLESTONE,50,48,100)
RandomBlock(-6,-9,7,COBBLESTONE,50,48,100)
RandomBlock(-6,-9,8,COBBLESTONE,50,48,100)
RandomBlock(-6,-9,9,COBBLESTONE,50,48,100)
RandomBlock(-6,-9,10,COBBLESTONE,50,48,100)
RandomBlock(-6,-8,-10,COBBLESTONE,50,48,100)
RandomBlock(-6,-8,-9,COBBLESTONE,50,48,100)
RandomBlock(-6,-8,-8,COBBLESTONE,50,48,100)
RandomBlock(-6,-8,-7,COBBLESTONE,50,48,100)
RandomBlock(-6,-8,-6,COBBLESTONE,50,48,100)
RandomBlock(-6,-8,-5,COBBLESTONE,50,48,100)
RandomBlock(-6,-8,-4,COBBLESTONE,50,48,100)
RandomBlock(-6,-8,-3,COBBLESTONE,50,48,100)
RandomBlock(-6,-8,-2,COBBLESTONE,50,48,100)
RandomBlock(-6,-8,-1,COBBLESTONE,50,48,100)
RandomBlock(-6,-8,0,COBBLESTONE,50,48,100)
RandomBlock(-6,-8,1,COBBLESTONE,50,48,100)
RandomBlock(-6,-8,2,COBBLESTONE,50,48,100)
RandomBlock(-6,-8,3,COBBLESTONE,50,48,100)
RandomBlock(-6,-8,4,COBBLESTONE,50,48,100)
RandomBlock(-6,-8,5,COBBLESTONE,50,48,100)
RandomBlock(-6,-8,6,COBBLESTONE,50,48,100)
RandomBlock(-6,-8,7,COBBLESTONE,50,48,100)
RandomBlock(-6,-8,8,COBBLESTONE,50,48,100)
RandomBlock(-6,-8,9,COBBLESTONE,50,48,100)
RandomBlock(-6,-8,10,COBBLESTONE,50,48,100)
RandomBlock(-6,-7,-10,COBBLESTONE,50,48,100)
RandomBlock(-6,-7,-9,COBBLESTONE,50,48,100)
RandomBlock(-6,-7,-8,COBBLESTONE,50,48,100)
RandomBlock(-6,-7,-7,COBBLESTONE,50,48,100)
RandomBlock(-6,-7,-6,COBBLESTONE,50,48,100)
RandomBlock(-6,-7,-5,COBBLESTONE,50,48,100)
RandomBlock(-6,-7,-4,COBBLESTONE,50,48,100)
RandomBlock(-6,-7,-3,COBBLESTONE,50,48,100)
RandomBlock(-6,-7,-2,COBBLESTONE,50,48,100)
RandomBlock(-6,-7,-1,COBBLESTONE,50,48,100)
RandomBlock(-6,-7,0,COBBLESTONE,50,48,100)
RandomBlock(-6,-7,1,COBBLESTONE,50,48,100)
RandomBlock(-6,-7,2,COBBLESTONE,50,48,100)
RandomBlock(-6,-7,3,COBBLESTONE,50,48,100)
RandomBlock(-6,-7,4,COBBLESTONE,50,48,100)
RandomBlock(-6,-7,5,COBBLESTONE,50,48,100)
RandomBlock(-6,-7,6,COBBLESTONE,50,48,100)
RandomBlock(-6,-7,7,COBBLESTONE,50,48,100)
RandomBlock(-6,-7,8,COBBLESTONE,50,48,100)
RandomBlock(-6,-7,9,COBBLESTONE,50,48,100)
RandomBlock(-6,-7,10,COBBLESTONE,50,48,100)
RandomBlock(-6,-6,-10,COBBLESTONE,50,48,100)
RandomBlock(-6,-6,-9,COBBLESTONE,50,48,100)
RandomBlock(-6,-6,-8,COBBLESTONE,50,48,100)
RandomBlock(-6,-6,-7,COBBLESTONE,50,48,100)
RandomBlock(-6,-6,-6,COBBLESTONE,50,48,100)
RandomBlock(-6,-6,-5,COBBLESTONE,50,48,100)
RandomBlock(-6,-6,-4,COBBLESTONE,50,48,100)
RandomBlock(-6,-6,-3,COBBLESTONE,50,48,100)
RandomBlock(-6,-6,-2,COBBLESTONE,50,48,100)
RandomBlock(-6,-6,-1,COBBLESTONE,50,48,100)
RandomBlock(-6,-6,0,COBBLESTONE,50,48,100)
RandomBlock(-6,-6,1,COBBLESTONE,50,48,100)
RandomBlock(-6,-6,2,COBBLESTONE,50,48,100)
RandomBlock(-6,-6,3,COBBLESTONE,50,48,100)
RandomBlock(-6,-6,4,COBBLESTONE,50,48,100)
RandomBlock(-6,-6,5,COBBLESTONE,50,48,100)
RandomBlock(-6,-6,6,COBBLESTONE,50,48,100)
RandomBlock(-6,-6,7,COBBLESTONE,50,48,100)
RandomBlock(-6,-6,8,COBBLESTONE,50,48,100)
RandomBlock(-6,-6,9,COBBLESTONE,50,48,100)
RandomBlock(-6,-6,10,COBBLESTONE,50,48,100)
RandomBlock(-6,-5,-10,COBBLESTONE,50,48,100)
RandomBlock(-6,-5,-9,COBBLESTONE,50,48,100)
RandomBlock(-6,-5,-8,COBBLESTONE,50,48,100)
RandomBlock(-6,-5,-7,COBBLESTONE,50,48,100)
RandomBlock(-6,-5,-6,COBBLESTONE,50,48,100)
RandomBlock(-6,-5,-5,COBBLESTONE,50,48,100)
RandomBlock(-6,-5,-4,COBBLESTONE,50,48,100)
RandomBlock(-6,-5,-3,COBBLESTONE,50,48,100)
RandomBlock(-6,-5,-2,COBBLESTONE,50,48,100)
RandomBlock(-6,-5,-1,COBBLESTONE,50,48,100)
RandomBlock(-6,-5,0,COBBLESTONE,50,48,100)
RandomBlock(-6,-5,1,COBBLESTONE,50,48,100)
RandomBlock(-6,-5,2,COBBLESTONE,50,48,100)
RandomBlock(-6,-5,3,COBBLESTONE,50,48,100)
RandomBlock(-6,-5,4,COBBLESTONE,50,48,100)
RandomBlock(-6,-5,5,COBBLESTONE,50,48,100)
RandomBlock(-6,-5,6,COBBLESTONE,50,48,100)
RandomBlock(-6,-5,7,COBBLESTONE,50,48,100)
RandomBlock(-6,-5,8,COBBLESTONE,50,48,100)
RandomBlock(-6,-5,9,COBBLESTONE,50,48,100)
RandomBlock(-6,-5,10,COBBLESTONE,50,48,100)
RandomBlock(-6,-4,-10,COBBLESTONE,50,48,100)
RandomBlock(-6,-4,-9,COBBLESTONE,50,48,100)
RandomBlock(-6,-4,-8,COBBLESTONE,50,48,100)
RandomBlock(-6,-4,-7,COBBLESTONE,50,48,100)
RandomBlock(-6,-4,-6,COBBLESTONE,50,48,100)
RandomBlock(-6,-4,-5,COBBLESTONE,50,48,100)
RandomBlock(-6,-4,-4,COBBLESTONE,50,48,100)
RandomBlock(-6,-4,-3,COBBLESTONE,50,48,100)
RandomBlock(-6,-4,-2,COBBLESTONE,50,48,100)
RandomBlock(-6,-4,-1,COBBLESTONE,50,48,100)
RandomBlock(-6,-4,0,COBBLESTONE,50,48,100)
RandomBlock(-6,-4,1,COBBLESTONE,50,48,100)
RandomBlock(-6,-4,2,COBBLESTONE,50,48,100)
RandomBlock(-6,-4,3,COBBLESTONE,50,48,100)
RandomBlock(-6,-4,4,COBBLESTONE,50,48,100)
RandomBlock(-6,-4,5,COBBLESTONE,50,48,100)
RandomBlock(-6,-4,6,COBBLESTONE,50,48,100)
RandomBlock(-6,-4,7,COBBLESTONE,50,48,100)
RandomBlock(-6,-4,8,COBBLESTONE,50,48,100)
RandomBlock(-6,-4,9,COBBLESTONE,50,48,100)
RandomBlock(-6,-4,10,COBBLESTONE,50,48,100)
RandomBlock(-6,-3,-10,COBBLESTONE,50,48,100)
RandomBlock(-6,-3,-9,COBBLESTONE,50,48,100)
RandomBlock(-6,-3,-8,COBBLESTONE,50,48,100)
RandomBlock(-6,-3,-7,COBBLESTONE,50,48,100)
RandomBlock(-6,-3,-6,COBBLESTONE,50,48,100)
RandomBlock(-6,-3,-5,COBBLESTONE,50,48,100)
RandomBlock(-6,-3,-4,COBBLESTONE,50,48,100)
RandomBlock(-6,-3,-3,COBBLESTONE,50,48,100)
RandomBlock(-6,-3,-2,COBBLESTONE,50,48,100)
RandomBlock(-6,-3,-1,COBBLESTONE,50,48,100)
RandomBlock(-6,-3,0,COBBLESTONE,50,48,100)
RandomBlock(-6,-3,1,COBBLESTONE,50,48,100)
RandomBlock(-6,-3,2,COBBLESTONE,50,48,100)
RandomBlock(-6,-3,3,COBBLESTONE,50,48,100)
RandomBlock(-6,-3,4,COBBLESTONE,50,48,100)
RandomBlock(-6,-3,5,COBBLESTONE,50,48,100)
RandomBlock(-6,-3,6,COBBLESTONE,50,48,100)
RandomBlock(-6,-3,7,COBBLESTONE,50,48,100)
RandomBlock(-6,-3,8,COBBLESTONE,50,48,100)
RandomBlock(-6,-3,9,COBBLESTONE,50,48,100)
RandomBlock(-6,-3,10,COBBLESTONE,50,48,100)
RandomBlock(-6,-2,-10,COBBLESTONE,50,48,100)
RandomBlock(-6,-2,-9,COBBLESTONE,50,48,100)
RandomBlock(-6,-2,-8,COBBLESTONE,50,48,100)
RandomBlock(-6,-2,-7,COBBLESTONE,50,48,100)
RandomBlock(-6,-2,-6,COBBLESTONE,50,48,100)
RandomBlock(-6,-2,-5,COBBLESTONE,50,48,100)
RandomBlock(-6,-2,-4,COBBLESTONE,50,48,100)
RandomBlock(-6,-2,-3,COBBLESTONE,50,48,100)
RandomBlock(-6,-2,-2,COBBLESTONE,50,48,100)
RandomBlock(-6,-2,-1,COBBLESTONE,50,48,100)
RandomBlock(-6,-2,0,COBBLESTONE,50,48,100)
RandomBlock(-6,-2,1,COBBLESTONE,50,48,100)
RandomBlock(-6,-2,2,COBBLESTONE,50,48,100)
RandomBlock(-6,-2,3,COBBLESTONE,50,48,100)
RandomBlock(-6,-2,4,COBBLESTONE,50,48,100)
RandomBlock(-6,-2,5,COBBLESTONE,50,48,100)
RandomBlock(-6,-2,6,COBBLESTONE,50,48,100)
RandomBlock(-6,-2,7,COBBLESTONE,50,48,100)
RandomBlock(-6,-2,8,COBBLESTONE,50,48,100)
RandomBlock(-6,-2,9,COBBLESTONE,50,48,100)
RandomBlock(-6,-2,10,COBBLESTONE,50,48,100)
RandomBlock(-6,-1,-10,COBBLESTONE,50,48,100)
RandomBlock(-6,-1,-9,COBBLESTONE,50,48,100)
RandomBlock(-6,-1,-8,COBBLESTONE,50,48,100)
RandomBlock(-6,-1,-7,COBBLESTONE,50,48,100)
RandomBlock(-6,-1,-6,COBBLESTONE,50,48,100)
RandomBlock(-6,-1,-5,COBBLESTONE,50,48,100)
RandomBlock(-6,-1,-4,COBBLESTONE,50,48,100)
RandomBlock(-6,-1,-3,COBBLESTONE,50,48,100)
RandomBlock(-6,-1,-2,COBBLESTONE,50,48,100)
RandomBlock(-6,-1,-1,COBBLESTONE,50,48,100)
RandomBlock(-6,-1,0,COBBLESTONE,50,48,100)
RandomBlock(-6,-1,1,COBBLESTONE,50,48,100)
RandomBlock(-6,-1,2,COBBLESTONE,50,48,100)
RandomBlock(-6,-1,3,COBBLESTONE,50,48,100)
RandomBlock(-6,-1,4,COBBLESTONE,50,48,100)
RandomBlock(-6,-1,5,COBBLESTONE,50,48,100)
RandomBlock(-6,-1,6,COBBLESTONE,50,48,100)
RandomBlock(-6,-1,7,COBBLESTONE,50,48,100)
RandomBlock(-6,-1,8,COBBLESTONE,50,48,100)
RandomBlock(-6,-1,9,COBBLESTONE,50,48,100)
RandomBlock(-6,-1,10,COBBLESTONE,50,48,100)
RandomBlock(-6,0,-10,COBBLESTONE,50,48,100)
RandomBlock(-6,0,-9,COBBLESTONE,50,48,100)
RandomBlock(-6,0,-8,COBBLESTONE,50,48,100)
RandomBlock(-6,0,-7,COBBLESTONE,50,48,100)
RandomBlock(-6,0,-6,COBBLESTONE,50,48,100)
RandomBlock(-6,0,-5,COBBLESTONE,50,48,100)
RandomBlock(-6,0,-4,COBBLESTONE,50,48,100)
RandomBlock(-6,0,-3,COBBLESTONE,50,48,100)
RandomBlock(-6,0,-2,COBBLESTONE,50,48,100)
RandomBlock(-6,0,-1,COBBLESTONE,50,48,100)
RandomBlock(-6,0,0,COBBLESTONE,50,48,100)
RandomBlock(-6,0,1,COBBLESTONE,50,48,100)
RandomBlock(-6,0,2,COBBLESTONE,50,48,100)
RandomBlock(-6,0,3,COBBLESTONE,50,48,100)
RandomBlock(-6,0,4,COBBLESTONE,50,48,100)
RandomBlock(-6,0,5,COBBLESTONE,50,48,100)
RandomBlock(-6,0,6,COBBLESTONE,50,48,100)
RandomBlock(-6,0,7,COBBLESTONE,50,48,100)
RandomBlock(-6,0,8,COBBLESTONE,50,48,100)
RandomBlock(-6,0,9,COBBLESTONE,50,48,100)
RandomBlock(-6,0,10,COBBLESTONE,50,48,100)
RandomBlock(-6,1,-10,COBBLESTONE,50,48,100)
RandomBlock(-6,1,-9,COBBLESTONE,50,48,100)
RandomBlock(-6,1,-7,COBBLESTONE,50,48,100)
RandomBlock(-6,1,-6,COBBLESTONE,50,48,100)
Block(-6,1,-4,98)
Block(-6,1,-2,98)
Block(-6,1,0,98)
Block(-6,1,2,98)
Block(-6,1,4,98)
Block(-6,1,6,98)
RandomBlock(-6,1,9,COBBLESTONE,50,48,100)
RandomBlock(-6,2,-10,COBBLESTONE,50,48,100)
RandomBlock(-6,2,-9,COBBLESTONE,50,48,100)
RandomBlock(-6,2,-7,COBBLESTONE,50,48,100)
RandomBlock(-6,2,-6,COBBLESTONE,50,48,100)
Block(-6,2,-4,98:1)
Block(-6,2,-2,98:1)
Block(-6,2,0,98:1)
Block(-6,2,2,98:1)
Block(-6,2,4,98:1)
Block(-6,2,6,98:1)
RandomBlock(-6,2,8,COBBLESTONE,50,48,100)
Block(-6,2,9,VINE:4)
RandomBlock(-6,3,-10,COBBLESTONE,50,48,100)
RandomBlock(-6,3,-9,COBBLESTONE,50,48,100)
RandomBlock(-6,3,-8,COBBLESTONE,50,48,100)
RandomBlock(-6,3,-7,COBBLESTONE,50,48,100)
RandomBlock(-6,3,-6,COBBLESTONE,50,48,100)
Block(-6,3,-5,98)
Block(-6,3,-4,98)
Block(-6,3,-3,98)
Block(-6,3,-2,98)
Block(-6,3,-1,98)
Block(-6,3,0,98)
Block(-6,3,1,98)
Block(-6,3,2,98)
Block(-6,3,3,98)
Block(-6,3,4,98)
Block(-6,3,5,98)
Block(-6,3,6,98)
RandomBlock(-6,3,7,COBBLESTONE,50,48,100)
RandomBlock(-6,4,-10,COBBLESTONE,50,48,100)
RandomBlock(-6,4,-9,COBBLESTONE,50,48,100)
RandomBlock(-6,4,-8,COBBLESTONE,50,48,100)
RandomBlock(-6,4,-7,COBBLESTONE,50,48,100)
RandomBlock(-6,4,-6,COBBLESTONE,50,48,100)
RandomBlock(-6,4,-5,COBBLESTONE,50,48,100)
RandomBlock(-6,4,-4,COBBLESTONE,50,48,100)
RandomBlock(-6,4,-3,COBBLESTONE,50,48,100)
RandomBlock(-6,4,-2,COBBLESTONE,50,48,100)
RandomBlock(-6,4,-1,COBBLESTONE,50,48,100)
RandomBlock(-6,4,0,COBBLESTONE,50,48,100)
RandomBlock(-6,4,1,COBBLESTONE,50,48,100)
RandomBlock(-6,4,2,COBBLESTONE,50,48,100)
RandomBlock(-6,4,3,COBBLESTONE,50,48,100)
RandomBlock(-6,4,4,COBBLESTONE,50,48,100)
RandomBlock(-6,4,5,COBBLESTONE,50,48,100)
RandomBlock(-6,4,6,COBBLESTONE,50,48,100)
RandomBlock(-6,5,-10,COBBLESTONE,50,48,100)
RandomBlock(-6,5,-9,COBBLESTONE,50,48,100)
RandomBlock(-6,5,-8,COBBLESTONE,50,48,100)
RandomBlock(-6,5,-7,COBBLESTONE,50,48,100)
RandomBlock(-6,5,-6,COBBLESTONE,50,48,100)
RandomBlock(-6,5,-5,GRAVEL,44,AIR,100)
RandomBlock(-6,5,-3,GRAVEL,44,AIR,100)
RandomBlock(-6,5,-2,GRAVEL,44,AIR,100)
RandomBlock(-6,5,0,GRAVEL,44,AIR,100)
Block(-6,5,1,VINE:8)
RandomBlock(-6,5,4,GRAVEL,44,AIR,100)
Block(-6,6,-11,VINE:1)
RandomBlock(-6,6,-10,COBBLESTONE,50,48,100)
RandomBlock(-6,6,-9,COBBLESTONE,50,48,100)
RandomBlock(-6,6,-8,COBBLESTONE,50,48,100)
RandomBlock(-6,6,-7,COBBLESTONE,50,48,100)
RandomBlock(-6,6,-6,COBBLESTONE,50,48,100)
Block(-6,6,1,VINE:8)
Block(-6,7,-11,VINE:1)
RandomBlock(-6,7,-10,COBBLESTONE,50,48,100)
RandomBlock(-6,7,-9,COBBLESTONE,50,48,100)
RandomBlock(-6,7,-8,COBBLESTONE,50,48,100)
RandomBlock(-6,7,-7,COBBLESTONE,50,48,100)
RandomBlock(-6,7,-6,COBBLESTONE,50,48,100)
Block(-6,8,-11,VINE:1)
RandomBlock(-6,8,-10,COBBLESTONE,50,48,100)
RandomBlock(-6,8,-9,COBBLESTONE,50,48,100)
RandomBlock(-6,8,-8,COBBLESTONE,50,48,100)
RandomBlock(-6,8,-7,COBBLESTONE,50,48,100)
RandomBlock(-6,8,-6,COBBLESTONE,50,48,100)
Block(-6,9,-8,67:1)
RandomBlock(-5,-13,-10,COBBLESTONE,50,48,100)
RandomBlock(-5,-13,-9,COBBLESTONE,50,48,100)
RandomBlock(-5,-13,-8,COBBLESTONE,50,48,100)
RandomBlock(-5,-13,-7,COBBLESTONE,50,48,100)
RandomBlock(-5,-13,-6,COBBLESTONE,50,48,100)
RandomBlock(-5,-13,-5,COBBLESTONE,50,48,100)
RandomBlock(-5,-13,-4,COBBLESTONE,50,48,100)
RandomBlock(-5,-13,-3,COBBLESTONE,50,48,100)
RandomBlock(-5,-13,-2,COBBLESTONE,50,48,100)
RandomBlock(-5,-13,-1,COBBLESTONE,50,48,100)
RandomBlock(-5,-13,0,COBBLESTONE,50,48,100)
RandomBlock(-5,-13,1,COBBLESTONE,50,48,100)
RandomBlock(-5,-13,2,COBBLESTONE,50,48,100)
RandomBlock(-5,-13,3,COBBLESTONE,50,48,100)
RandomBlock(-5,-13,4,COBBLESTONE,50,48,100)
RandomBlock(-5,-13,5,COBBLESTONE,50,48,100)
RandomBlock(-5,-13,6,COBBLESTONE,50,48,100)
RandomBlock(-5,-13,7,COBBLESTONE,50,48,100)
RandomBlock(-5,-13,8,COBBLESTONE,50,48,100)
RandomBlock(-5,-13,9,COBBLESTONE,50,48,100)
RandomBlock(-5,-13,10,COBBLESTONE,50,48,100)
RandomBlock(-5,-12,-10,COBBLESTONE,50,48,100)
Block(-5,-12,-9,STATIONARY_WATER)
Block(-5,-12,-8,STATIONARY_WATER)
Block(-5,-12,-7,STATIONARY_WATER)
Block(-5,-12,-6,GRAVEL)
Block(-5,-12,-5,GRAVEL)
Block(-5,-12,-4,GRAVEL)
Block(-5,-12,-3,GRAVEL)
RandomBlock(-5,-12,-2,COBBLESTONE,50,48,100)
Block(-5,-12,-1,GRAVEL)
Block(-5,-12,0,GRAVEL)
Block(-5,-12,1,GRAVEL)
RandomBlock(-5,-12,2,COBBLESTONE,50,48,100)
Block(-5,-12,3,GRAVEL)
Block(-5,-12,4,GRAVEL)
Block(-5,-12,5,GRAVEL)
Block(-5,-12,6,GRAVEL)
Block(-5,-12,7,GRAVEL)
Block(-5,-12,8,STATIONARY_WATER)
Block(-5,-12,9,STATIONARY_WATER)
RandomBlock(-5,-12,10,COBBLESTONE,50,48,100)
RandomBlock(-5,-11,-10,COBBLESTONE,50,48,100)
Block(-5,-11,-9,AIR)
Block(-5,-11,-8,AIR)
Block(-5,-11,-7,AIR)
Block(-5,-11,-6,AIR)
Block(-5,-11,-5,AIR)
Block(-5,-11,-4,AIR)
Block(-5,-11,-3,AIR)
Block(-5,-11,-2,AIR)
Block(-5,-11,-1,AIR)
Block(-5,-11,0,AIR)
Block(-5,-11,1,AIR)
Block(-5,-11,2,AIR)
RandomBlock(-5,-11,3,CHEST,../../nbt/VanillaLoot/jungle_temple.nbt,50,CHEST,../../nbt/VanillaLoot/jungle_temple.nbt,100)
Block(-5,-11,4,AIR)
Block(-5,-11,5,AIR)
Block(-5,-11,6,AIR)
Block(-5,-11,7,AIR)
Block(-5,-11,8,AIR)
Block(-5,-11,9,AIR)
RandomBlock(-5,-11,10,COBBLESTONE,50,48,100)
RandomBlock(-5,-10,-10,COBBLESTONE,50,48,100)
Block(-5,-10,-9,AIR)
Block(-5,-10,-8,AIR)
Block(-5,-10,-7,AIR)
Block(-5,-10,-6,AIR)
Block(-5,-10,-5,AIR)
Block(-5,-10,-4,AIR)
Block(-5,-10,-3,AIR)
Block(-5,-10,-2,AIR)
Block(-5,-10,-1,AIR)
Block(-5,-10,0,AIR)
Block(-5,-10,1,AIR)
Block(-5,-10,2,AIR)
Block(-5,-10,3,AIR)
Block(-5,-10,4,AIR)
Block(-5,-10,5,AIR)
Block(-5,-10,6,AIR)
Block(-5,-10,7,AIR)
Block(-5,-10,8,AIR)
Block(-5,-10,9,AIR)
RandomBlock(-5,-10,10,COBBLESTONE,50,48,100)
RandomBlock(-5,-9,-10,COBBLESTONE,50,48,100)
RandomBlock(-5,-9,-9,COBBLESTONE,50,48,100)
RandomBlock(-5,-9,-8,COBBLESTONE,50,48,100)
RandomBlock(-5,-9,-7,COBBLESTONE,50,48,100)
RandomBlock(-5,-9,-6,COBBLESTONE,50,48,100)
RandomBlock(-5,-9,-5,COBBLESTONE,50,48,100)
RandomBlock(-5,-9,-4,COBBLESTONE,50,48,100)
RandomBlock(-5,-9,-3,COBBLESTONE,50,48,100)
RandomBlock(-5,-9,-2,COBBLESTONE,50,48,100)
RandomBlock(-5,-9,-1,COBBLESTONE,50,48,100)
RandomBlock(-5,-9,0,COBBLESTONE,50,48,100)
RandomBlock(-5,-9,1,COBBLESTONE,50,48,100)
RandomBlock(-5,-9,2,COBBLESTONE,50,48,100)
RandomBlock(-5,-9,3,COBBLESTONE,50,48,100)
RandomBlock(-5,-9,4,COBBLESTONE,50,48,100)
RandomBlock(-5,-9,5,COBBLESTONE,50,48,100)
RandomBlock(-5,-9,6,COBBLESTONE,50,48,100)
RandomBlock(-5,-9,7,COBBLESTONE,50,48,100)
RandomBlock(-5,-9,8,COBBLESTONE,50,48,100)
RandomBlock(-5,-9,9,COBBLESTONE,50,48,100)
RandomBlock(-5,-9,10,COBBLESTONE,50,48,100)
RandomBlock(-5,-8,-10,COBBLESTONE,50,48,100)
RandomBlock(-5,-8,-9,COBBLESTONE,50,48,100)
RandomBlock(-5,-8,-8,COBBLESTONE,50,48,100)
RandomBlock(-5,-8,-7,COBBLESTONE,50,48,100)
RandomBlock(-5,-8,-6,COBBLESTONE,50,48,100)
RandomBlock(-5,-8,-5,COBBLESTONE,50,48,100)
RandomBlock(-5,-8,-4,COBBLESTONE,50,48,100)
RandomBlock(-5,-8,-3,COBBLESTONE,50,48,100)
RandomBlock(-5,-8,-2,COBBLESTONE,50,48,100)
RandomBlock(-5,-8,-1,COBBLESTONE,50,48,100)
RandomBlock(-5,-8,0,COBBLESTONE,50,48,100)
RandomBlock(-5,-8,1,COBBLESTONE,50,48,100)
RandomBlock(-5,-8,2,COBBLESTONE,50,48,100)
RandomBlock(-5,-8,3,COBBLESTONE,50,48,100)
RandomBlock(-5,-8,4,COBBLESTONE,50,48,100)
RandomBlock(-5,-8,5,COBBLESTONE,50,48,100)
RandomBlock(-5,-8,6,COBBLESTONE,50,48,100)
RandomBlock(-5,-8,7,COBBLESTONE,50,48,100)
RandomBlock(-5,-8,8,COBBLESTONE,50,48,100)
RandomBlock(-5,-8,9,COBBLESTONE,50,48,100)
RandomBlock(-5,-8,10,COBBLESTONE,50,48,100)
RandomBlock(-5,-7,-10,COBBLESTONE,50,48,100)
RandomBlock(-5,-7,-9,COBBLESTONE,50,48,100)
RandomBlock(-5,-7,-8,COBBLESTONE,50,48,100)
RandomBlock(-5,-7,-7,COBBLESTONE,50,48,100)
RandomBlock(-5,-7,-6,COBBLESTONE,50,48,100)
RandomBlock(-5,-7,-5,COBBLESTONE,50,48,100)
RandomBlock(-5,-7,-4,COBBLESTONE,50,48,100)
RandomBlock(-5,-7,-3,COBBLESTONE,50,48,100)
RandomBlock(-5,-7,-2,COBBLESTONE,50,48,100)
RandomBlock(-5,-7,-1,COBBLESTONE,50,48,100)
RandomBlock(-5,-7,0,COBBLESTONE,50,48,100)
RandomBlock(-5,-7,1,COBBLESTONE,50,48,100)
RandomBlock(-5,-7,2,COBBLESTONE,50,48,100)
RandomBlock(-5,-7,3,COBBLESTONE,50,48,100)
RandomBlock(-5,-7,4,COBBLESTONE,50,48,100)
RandomBlock(-5,-7,5,COBBLESTONE,50,48,100)
RandomBlock(-5,-7,6,COBBLESTONE,50,48,100)
RandomBlock(-5,-7,7,COBBLESTONE,50,48,100)
RandomBlock(-5,-7,8,COBBLESTONE,50,48,100)
RandomBlock(-5,-7,9,COBBLESTONE,50,48,100)
RandomBlock(-5,-7,10,COBBLESTONE,50,48,100)
RandomBlock(-5,-6,-10,COBBLESTONE,50,48,100)
RandomBlock(-5,-6,-9,COBBLESTONE,50,48,100)
RandomBlock(-5,-6,-8,COBBLESTONE,50,48,100)
RandomBlock(-5,-6,-7,COBBLESTONE,50,48,100)
RandomBlock(-5,-6,-6,COBBLESTONE,50,48,100)
RandomBlock(-5,-6,-5,COBBLESTONE,50,48,100)
RandomBlock(-5,-6,-4,COBBLESTONE,50,48,100)
RandomBlock(-5,-6,-3,COBBLESTONE,50,48,100)
RandomBlock(-5,-6,-2,COBBLESTONE,50,48,100)
RandomBlock(-5,-6,-1,COBBLESTONE,50,48,100)
RandomBlock(-5,-6,0,COBBLESTONE,50,48,100)
RandomBlock(-5,-6,1,COBBLESTONE,50,48,100)
RandomBlock(-5,-6,2,COBBLESTONE,50,48,100)
RandomBlock(-5,-6,3,COBBLESTONE,50,48,100)
RandomBlock(-5,-6,4,COBBLESTONE,50,48,100)
RandomBlock(-5,-6,5,COBBLESTONE,50,48,100)
RandomBlock(-5,-6,6,COBBLESTONE,50,48,100)
RandomBlock(-5,-6,7,COBBLESTONE,50,48,100)
RandomBlock(-5,-6,8,COBBLESTONE,50,48,100)
RandomBlock(-5,-6,9,COBBLESTONE,50,48,100)
RandomBlock(-5,-6,10,COBBLESTONE,50,48,100)
RandomBlock(-5,-5,-10,COBBLESTONE,50,48,100)
RandomBlock(-5,-5,-9,COBBLESTONE,50,48,100)
RandomBlock(-5,-5,-8,COBBLESTONE,50,48,100)
RandomBlock(-5,-5,-7,COBBLESTONE,50,48,100)
RandomBlock(-5,-5,-6,COBBLESTONE,50,48,100)
RandomBlock(-5,-5,-5,COBBLESTONE,50,48,100)
RandomBlock(-5,-5,-4,COBBLESTONE,50,48,100)
RandomBlock(-5,-5,-3,COBBLESTONE,50,48,100)
RandomBlock(-5,-5,-2,COBBLESTONE,50,48,100)
RandomBlock(-5,-5,-1,COBBLESTONE,50,48,100)
RandomBlock(-5,-5,0,COBBLESTONE,50,48,100)
RandomBlock(-5,-5,1,COBBLESTONE,50,48,100)
RandomBlock(-5,-5,2,COBBLESTONE,50,48,100)
RandomBlock(-5,-5,3,COBBLESTONE,50,48,100)
RandomBlock(-5,-5,4,COBBLESTONE,50,48,100)
RandomBlock(-5,-5,5,COBBLESTONE,50,48,100)
RandomBlock(-5,-5,6,COBBLESTONE,50,48,100)
RandomBlock(-5,-5,7,COBBLESTONE,50,48,100)
RandomBlock(-5,-5,8,COBBLESTONE,50,48,100)
RandomBlock(-5,-5,9,COBBLESTONE,50,48,100)
RandomBlock(-5,-5,10,COBBLESTONE,50,48,100)
RandomBlock(-5,-4,-10,COBBLESTONE,50,48,100)
RandomBlock(-5,-4,-9,COBBLESTONE,50,48,100)
RandomBlock(-5,-4,-8,COBBLESTONE,50,48,100)
RandomBlock(-5,-4,-7,COBBLESTONE,50,48,100)
RandomBlock(-5,-4,-6,COBBLESTONE,50,48,100)
RandomBlock(-5,-4,-5,COBBLESTONE,50,48,100)
RandomBlock(-5,-4,-4,COBBLESTONE,50,48,100)
RandomBlock(-5,-4,-3,COBBLESTONE,50,48,100)
RandomBlock(-5,-4,-2,COBBLESTONE,50,48,100)
RandomBlock(-5,-4,-1,COBBLESTONE,50,48,100)
RandomBlock(-5,-4,0,COBBLESTONE,50,48,100)
RandomBlock(-5,-4,1,COBBLESTONE,50,48,100)
RandomBlock(-5,-4,2,COBBLESTONE,50,48,100)
RandomBlock(-5,-4,3,COBBLESTONE,50,48,100)
RandomBlock(-5,-4,4,COBBLESTONE,50,48,100)
RandomBlock(-5,-4,5,COBBLESTONE,50,48,100)
RandomBlock(-5,-4,6,COBBLESTONE,50,48,100)
RandomBlock(-5,-4,7,COBBLESTONE,50,48,100)
RandomBlock(-5,-4,8,COBBLESTONE,50,48,100)
RandomBlock(-5,-4,9,COBBLESTONE,50,48,100)
RandomBlock(-5,-4,10,COBBLESTONE,50,48,100)
RandomBlock(-5,-3,-10,COBBLESTONE,50,48,100)
RandomBlock(-5,-3,-9,COBBLESTONE,50,48,100)
RandomBlock(-5,-3,-8,COBBLESTONE,50,48,100)
RandomBlock(-5,-3,-7,COBBLESTONE,50,48,100)
RandomBlock(-5,-3,-6,COBBLESTONE,50,48,100)
RandomBlock(-5,-3,-5,COBBLESTONE,50,48,100)
RandomBlock(-5,-3,-4,COBBLESTONE,50,48,100)
RandomBlock(-5,-3,-3,COBBLESTONE,50,48,100)
RandomBlock(-5,-3,-2,COBBLESTONE,50,48,100)
RandomBlock(-5,-3,-1,COBBLESTONE,50,48,100)
RandomBlock(-5,-3,0,COBBLESTONE,50,48,100)
RandomBlock(-5,-3,1,COBBLESTONE,50,48,100)
RandomBlock(-5,-3,2,COBBLESTONE,50,48,100)
RandomBlock(-5,-3,3,COBBLESTONE,50,48,100)
RandomBlock(-5,-3,4,COBBLESTONE,50,48,100)
RandomBlock(-5,-3,5,COBBLESTONE,50,48,100)
RandomBlock(-5,-3,6,COBBLESTONE,50,48,100)
RandomBlock(-5,-3,7,COBBLESTONE,50,48,100)
RandomBlock(-5,-3,8,COBBLESTONE,50,48,100)
RandomBlock(-5,-3,9,COBBLESTONE,50,48,100)
RandomBlock(-5,-3,10,COBBLESTONE,50,48,100)
RandomBlock(-5,-2,-10,COBBLESTONE,50,48,100)
RandomBlock(-5,-2,-9,COBBLESTONE,50,48,100)
RandomBlock(-5,-2,-8,COBBLESTONE,50,48,100)
RandomBlock(-5,-2,-7,COBBLESTONE,50,48,100)
RandomBlock(-5,-2,-6,COBBLESTONE,50,48,100)
RandomBlock(-5,-2,-5,COBBLESTONE,50,48,100)
RandomBlock(-5,-2,-4,COBBLESTONE,50,48,100)
RandomBlock(-5,-2,-3,COBBLESTONE,50,48,100)
RandomBlock(-5,-2,-2,COBBLESTONE,50,48,100)
RandomBlock(-5,-2,-1,COBBLESTONE,50,48,100)
RandomBlock(-5,-2,0,COBBLESTONE,50,48,100)
RandomBlock(-5,-2,1,COBBLESTONE,50,48,100)
RandomBlock(-5,-2,2,COBBLESTONE,50,48,100)
RandomBlock(-5,-2,3,COBBLESTONE,50,48,100)
RandomBlock(-5,-2,4,COBBLESTONE,50,48,100)
RandomBlock(-5,-2,5,COBBLESTONE,50,48,100)
RandomBlock(-5,-2,6,COBBLESTONE,50,48,100)
RandomBlock(-5,-2,7,COBBLESTONE,50,48,100)
RandomBlock(-5,-2,8,COBBLESTONE,50,48,100)
RandomBlock(-5,-2,9,COBBLESTONE,50,48,100)
RandomBlock(-5,-2,10,COBBLESTONE,50,48,100)
RandomBlock(-5,-1,-10,COBBLESTONE,50,48,100)
RandomBlock(-5,-1,-9,COBBLESTONE,50,48,100)
RandomBlock(-5,-1,-8,COBBLESTONE,50,48,100)
RandomBlock(-5,-1,-7,COBBLESTONE,50,48,100)
RandomBlock(-5,-1,-6,COBBLESTONE,50,48,100)
RandomBlock(-5,-1,-5,COBBLESTONE,50,48,100)
RandomBlock(-5,-1,-4,COBBLESTONE,50,48,100)
RandomBlock(-5,-1,-3,COBBLESTONE,50,48,100)
RandomBlock(-5,-1,-2,COBBLESTONE,50,48,100)
RandomBlock(-5,-1,-1,COBBLESTONE,50,48,100)
RandomBlock(-5,-1,0,COBBLESTONE,50,48,100)
RandomBlock(-5,-1,1,COBBLESTONE,50,48,100)
RandomBlock(-5,-1,2,COBBLESTONE,50,48,100)
RandomBlock(-5,-1,3,COBBLESTONE,50,48,100)
RandomBlock(-5,-1,4,COBBLESTONE,50,48,100)
RandomBlock(-5,-1,5,COBBLESTONE,50,48,100)
RandomBlock(-5,-1,6,COBBLESTONE,50,48,100)
RandomBlock(-5,-1,7,COBBLESTONE,50,48,100)
RandomBlock(-5,-1,8,COBBLESTONE,50,48,100)
RandomBlock(-5,-1,9,COBBLESTONE,50,48,100)
RandomBlock(-5,-1,10,COBBLESTONE,50,48,100)
RandomBlock(-5,0,-10,COBBLESTONE,50,48,100)
RandomBlock(-5,0,-9,COBBLESTONE,50,48,100)
RandomBlock(-5,0,-8,COBBLESTONE,50,48,100)
RandomBlock(-5,0,-7,COBBLESTONE,50,48,100)
RandomBlock(-5,0,-6,COBBLESTONE,50,48,100)
RandomBlock(-5,0,-5,COBBLESTONE,50,48,100)
RandomBlock(-5,0,-4,COBBLESTONE,50,48,100)
RandomBlock(-5,0,-3,COBBLESTONE,50,48,100)
RandomBlock(-5,0,-2,COBBLESTONE,50,48,100)
RandomBlock(-5,0,-1,COBBLESTONE,50,48,100)
RandomBlock(-5,0,0,COBBLESTONE,50,48,100)
RandomBlock(-5,0,1,COBBLESTONE,50,48,100)
RandomBlock(-5,0,2,COBBLESTONE,50,48,100)
RandomBlock(-5,0,3,COBBLESTONE,50,48,100)
RandomBlock(-5,0,4,COBBLESTONE,50,48,100)
RandomBlock(-5,0,5,COBBLESTONE,50,48,100)
RandomBlock(-5,0,6,COBBLESTONE,50,48,100)
RandomBlock(-5,0,7,COBBLESTONE,50,48,100)
RandomBlock(-5,0,8,COBBLESTONE,50,48,100)
RandomBlock(-5,0,9,COBBLESTONE,50,48,100)
RandomBlock(-5,0,10,COBBLESTONE,50,48,100)
RandomBlock(-5,1,-9,COBBLESTONE,50,48,100)
RandomBlock(-5,1,-7,COBBLESTONE,50,48,100)
RandomBlock(-5,1,9,COBBLESTONE,50,48,100)
RandomBlock(-5,1,10,GRAVEL,44,AIR,100)
RandomBlock(-5,2,-9,COBBLESTONE,50,48,100)
RandomBlock(-5,2,-7,COBBLESTONE,50,48,100)
Block(-5,2,3,VINE:2)
RandomBlock(-5,2,8,COBBLESTONE,50,48,100)
Block(-5,2,9,VINE:4)
RandomBlock(-5,3,-9,98:2,44,AIR,100)
RandomBlock(-5,3,-8,COBBLESTONE,50,48,100)
RandomBlock(-5,3,-7,COBBLESTONE,50,48,100)
Block(-5,3,-6,98)
Block(-5,3,0,VINE:2)
Block(-5,3,3,VINE:2)
Block(-5,3,6,98)
RandomBlock(-5,3,7,COBBLESTONE,50,48,100)
RandomBlock(-5,4,-9,COBBLESTONE,50,48,100)
RandomBlock(-5,4,-8,COBBLESTONE,50,48,100)
RandomBlock(-5,4,-7,COBBLESTONE,50,48,100)
RandomBlock(-5,4,-6,COBBLESTONE,50,48,100)
RandomBlock(-5,4,-5,COBBLESTONE,50,48,100)
RandomBlock(-5,4,-4,COBBLESTONE,50,48,100)
RandomBlock(-5,4,-3,COBBLESTONE,50,48,100)
RandomBlock(-5,4,-2,COBBLESTONE,50,48,100)
RandomBlock(-5,4,-1,COBBLESTONE,50,48,100)
RandomBlock(-5,4,0,COBBLESTONE,50,48,100)
RandomBlock(-5,4,1,COBBLESTONE,50,48,100)
RandomBlock(-5,4,2,COBBLESTONE,50,48,100)
RandomBlock(-5,4,3,COBBLESTONE,50,48,100)
RandomBlock(-5,4,4,COBBLESTONE,50,48,100)
RandomBlock(-5,4,5,COBBLESTONE,50,48,100)
RandomBlock(-5,4,6,COBBLESTONE,50,48,100)
RandomBlock(-5,5,-6,GRAVEL,44,AIR,100)
RandomBlock(-5,5,-5,COBBLESTONE,50,48,100)
RandomBlock(-5,5,-4,COBBLESTONE,50,48,100)
RandomBlock(-5,5,-3,COBBLESTONE,50,48,100)
RandomBlock(-5,5,-2,COBBLESTONE,50,48,100)
Block(-5,5,-1,98)
Block(-5,5,1,98)
RandomBlock(-5,5,2,COBBLESTONE,50,48,100)
RandomBlock(-5,5,3,COBBLESTONE,50,48,100)
RandomBlock(-5,5,4,COBBLESTONE,50,48,100)
RandomBlock(-5,5,5,COBBLESTONE,50,48,100)
Block(-5,6,-1,98)
Block(-5,6,1,98)
Block(-5,6,2,VINE:8)
Block(-5,6,3,VINE:8)
Block(-5,7,-1,98)
Block(-5,7,0,98)
Block(-5,7,1,98)
RandomBlock(-4,-13,-10,COBBLESTONE,50,48,100)
RandomBlock(-4,-13,-9,COBBLESTONE,50,48,100)
RandomBlock(-4,-13,-8,COBBLESTONE,50,48,100)
RandomBlock(-4,-13,-7,COBBLESTONE,50,48,100)
RandomBlock(-4,-13,-6,COBBLESTONE,50,48,100)
RandomBlock(-4,-13,-5,COBBLESTONE,50,48,100)
RandomBlock(-4,-13,-4,COBBLESTONE,50,48,100)
RandomBlock(-4,-13,-3,COBBLESTONE,50,48,100)
RandomBlock(-4,-13,-2,COBBLESTONE,50,48,100)
RandomBlock(-4,-13,-1,COBBLESTONE,50,48,100)
RandomBlock(-4,-13,0,COBBLESTONE,50,48,100)
RandomBlock(-4,-13,1,COBBLESTONE,50,48,100)
RandomBlock(-4,-13,2,COBBLESTONE,50,48,100)
RandomBlock(-4,-13,3,COBBLESTONE,50,48,100)
RandomBlock(-4,-13,4,COBBLESTONE,50,48,100)
RandomBlock(-4,-13,5,COBBLESTONE,50,48,100)
RandomBlock(-4,-13,6,COBBLESTONE,50,48,100)
RandomBlock(-4,-13,7,COBBLESTONE,50,48,100)
RandomBlock(-4,-13,8,COBBLESTONE,50,48,100)
RandomBlock(-4,-13,9,COBBLESTONE,50,48,100)
RandomBlock(-4,-13,10,COBBLESTONE,50,48,100)
RandomBlock(-4,-12,-10,COBBLESTONE,50,48,100)
Block(-4,-12,-9,STATIONARY_WATER)
Block(-4,-12,-8,STATIONARY_WATER)
Block(-4,-12,-7,STATIONARY_WATER)
RandomBlock(-4,-12,-6,COBBLESTONE,50,48,100)
RandomBlock(-4,-12,-5,COBBLESTONE,50,48,100)
RandomBlock(-4,-12,-4,COBBLESTONE,50,48,100)
RandomBlock(-4,-12,-3,COBBLESTONE,50,48,100)
RandomBlock(-4,-12,-2,COBBLESTONE,50,48,100)
Block(-4,-12,-1,GRAVEL)
Block(-4,-12,0,GRAVEL)
Block(-4,-12,1,GRAVEL)
RandomBlock(-4,-12,2,COBBLESTONE,50,48,100)
RandomBlock(-4,-12,3,COBBLESTONE,50,48,100)
RandomBlock(-4,-12,4,COBBLESTONE,50,48,100)
RandomBlock(-4,-12,5,COBBLESTONE,50,48,100)
RandomBlock(-4,-12,6,COBBLESTONE,50,48,100)
RandomBlock(-4,-12,7,COBBLESTONE,50,48,100)
Block(-4,-12,8,STATIONARY_WATER)
Block(-4,-12,9,STATIONARY_WATER)
RandomBlock(-4,-12,10,COBBLESTONE,50,48,100)
RandomBlock(-4,-11,-10,COBBLESTONE,50,48,100)
Block(-4,-11,-9,AIR)
Block(-4,-11,-8,AIR)
Block(-4,-11,-7,AIR)
RandomBlock(-4,-11,-6,COBBLESTONE,50,48,100)
RandomBlock(-4,-11,-5,COBBLESTONE,50,48,100)
RandomBlock(-4,-11,-4,COBBLESTONE,50,48,100)
RandomBlock(-4,-11,-3,COBBLESTONE,50,48,100)
RandomBlock(-4,-11,-2,COBBLESTONE,50,48,100)
Block(-4,-11,-1,AIR)
Block(-4,-11,0,AIR)
Block(-4,-11,1,AIR)
RandomBlock(-4,-11,2,COBBLESTONE,50,48,100)
RandomBlock(-4,-11,3,COBBLESTONE,50,48,100)
RandomBlock(-4,-11,4,COBBLESTONE,50,48,100)
RandomBlock(-4,-11,5,COBBLESTONE,50,48,100)
RandomBlock(-4,-11,6,COBBLESTONE,50,48,100)
RandomBlock(-4,-11,7,COBBLESTONE,50,48,100)
Block(-4,-11,8,AIR)
Block(-4,-11,9,AIR)
RandomBlock(-4,-11,10,COBBLESTONE,50,48,100)
RandomBlock(-4,-10,-10,COBBLESTONE,50,48,100)
Block(-4,-10,-9,AIR)
Block(-4,-10,-8,AIR)
Block(-4,-10,-7,AIR)
RandomBlock(-4,-10,-6,COBBLESTONE,50,48,100)
RandomBlock(-4,-10,-5,COBBLESTONE,50,48,100)
RandomBlock(-4,-10,-4,COBBLESTONE,50,48,100)
RandomBlock(-4,-10,-3,COBBLESTONE,50,48,100)
RandomBlock(-4,-10,-2,COBBLESTONE,50,48,100)
Block(-4,-10,-1,AIR)
Block(-4,-10,0,AIR)
Block(-4,-10,1,AIR)
RandomBlock(-4,-10,2,COBBLESTONE,50,48,100)
RandomBlock(-4,-10,3,COBBLESTONE,50,48,100)
RandomBlock(-4,-10,4,COBBLESTONE,50,48,100)
RandomBlock(-4,-10,5,COBBLESTONE,50,48,100)
RandomBlock(-4,-10,6,COBBLESTONE,50,48,100)
RandomBlock(-4,-10,7,COBBLESTONE,50,48,100)
Block(-4,-10,8,AIR)
Block(-4,-10,9,AIR)
RandomBlock(-4,-10,10,COBBLESTONE,50,48,100)
RandomBlock(-4,-9,-10,COBBLESTONE,50,48,100)
RandomBlock(-4,-9,-9,COBBLESTONE,50,48,100)
RandomBlock(-4,-9,-8,COBBLESTONE,50,48,100)
RandomBlock(-4,-9,-7,COBBLESTONE,50,48,100)
RandomBlock(-4,-9,-6,COBBLESTONE,50,48,100)
RandomBlock(-4,-9,-5,COBBLESTONE,50,48,100)
RandomBlock(-4,-9,-4,COBBLESTONE,50,48,100)
RandomBlock(-4,-9,-3,COBBLESTONE,50,48,100)
RandomBlock(-4,-9,-2,COBBLESTONE,50,48,100)
RandomBlock(-4,-9,-1,COBBLESTONE,50,48,100)
RandomBlock(-4,-9,0,COBBLESTONE,50,48,100)
RandomBlock(-4,-9,1,COBBLESTONE,50,48,100)
RandomBlock(-4,-9,2,COBBLESTONE,50,48,100)
RandomBlock(-4,-9,3,COBBLESTONE,50,48,100)
RandomBlock(-4,-9,4,COBBLESTONE,50,48,100)
RandomBlock(-4,-9,5,COBBLESTONE,50,48,100)
RandomBlock(-4,-9,6,COBBLESTONE,50,48,100)
RandomBlock(-4,-9,7,COBBLESTONE,50,48,100)
RandomBlock(-4,-9,8,COBBLESTONE,50,48,100)
RandomBlock(-4,-9,9,COBBLESTONE,50,48,100)
RandomBlock(-4,-9,10,COBBLESTONE,50,48,100)
RandomBlock(-4,-8,-10,COBBLESTONE,50,48,100)
RandomBlock(-4,-8,-9,COBBLESTONE,50,48,100)
RandomBlock(-4,-8,-8,COBBLESTONE,50,48,100)
RandomBlock(-4,-8,-7,COBBLESTONE,50,48,100)
RandomBlock(-4,-8,-6,COBBLESTONE,50,48,100)
RandomBlock(-4,-8,-5,COBBLESTONE,50,48,100)
RandomBlock(-4,-8,-4,COBBLESTONE,50,48,100)
RandomBlock(-4,-8,-3,COBBLESTONE,50,48,100)
RandomBlock(-4,-8,-2,COBBLESTONE,50,48,100)
RandomBlock(-4,-8,-1,COBBLESTONE,50,48,100)
RandomBlock(-4,-8,0,COBBLESTONE,50,48,100)
RandomBlock(-4,-8,1,COBBLESTONE,50,48,100)
RandomBlock(-4,-8,2,COBBLESTONE,50,48,100)
RandomBlock(-4,-8,3,COBBLESTONE,50,48,100)
RandomBlock(-4,-8,4,COBBLESTONE,50,48,100)
RandomBlock(-4,-8,5,COBBLESTONE,50,48,100)
RandomBlock(-4,-8,6,COBBLESTONE,50,48,100)
RandomBlock(-4,-8,7,COBBLESTONE,50,48,100)
RandomBlock(-4,-8,8,COBBLESTONE,50,48,100)
RandomBlock(-4,-8,9,COBBLESTONE,50,48,100)
RandomBlock(-4,-8,10,COBBLESTONE,50,48,100)
RandomBlock(-4,-7,-10,COBBLESTONE,50,48,100)
RandomBlock(-4,-7,-9,COBBLESTONE,50,48,100)
RandomBlock(-4,-7,-8,COBBLESTONE,50,48,100)
RandomBlock(-4,-7,-7,COBBLESTONE,50,48,100)
RandomBlock(-4,-7,-6,COBBLESTONE,50,48,100)
RandomBlock(-4,-7,-5,COBBLESTONE,50,48,100)
RandomBlock(-4,-7,-4,COBBLESTONE,50,48,100)
RandomBlock(-4,-7,-3,COBBLESTONE,50,48,100)
RandomBlock(-4,-7,-2,COBBLESTONE,50,48,100)
RandomBlock(-4,-7,-1,COBBLESTONE,50,48,100)
RandomBlock(-4,-7,0,COBBLESTONE,50,48,100)
RandomBlock(-4,-7,1,COBBLESTONE,50,48,100)
RandomBlock(-4,-7,2,COBBLESTONE,50,48,100)
RandomBlock(-4,-7,3,COBBLESTONE,50,48,100)
RandomBlock(-4,-7,4,COBBLESTONE,50,48,100)
RandomBlock(-4,-7,5,COBBLESTONE,50,48,100)
RandomBlock(-4,-7,6,COBBLESTONE,50,48,100)
RandomBlock(-4,-7,7,COBBLESTONE,50,48,100)
RandomBlock(-4,-7,8,COBBLESTONE,50,48,100)
RandomBlock(-4,-7,9,COBBLESTONE,50,48,100)
RandomBlock(-4,-7,10,COBBLESTONE,50,48,100)
RandomBlock(-4,-6,-10,COBBLESTONE,50,48,100)
RandomBlock(-4,-6,-9,COBBLESTONE,50,48,100)
RandomBlock(-4,-6,-8,COBBLESTONE,50,48,100)
RandomBlock(-4,-6,-7,COBBLESTONE,50,48,100)
RandomBlock(-4,-6,-6,COBBLESTONE,50,48,100)
RandomBlock(-4,-6,-5,COBBLESTONE,50,48,100)
RandomBlock(-4,-6,-4,COBBLESTONE,50,48,100)
RandomBlock(-4,-6,-3,COBBLESTONE,50,48,100)
RandomBlock(-4,-6,-2,COBBLESTONE,50,48,100)
RandomBlock(-4,-6,-1,COBBLESTONE,50,48,100)
RandomBlock(-4,-6,0,COBBLESTONE,50,48,100)
RandomBlock(-4,-6,1,COBBLESTONE,50,48,100)
RandomBlock(-4,-6,2,COBBLESTONE,50,48,100)
RandomBlock(-4,-6,3,COBBLESTONE,50,48,100)
RandomBlock(-4,-6,4,COBBLESTONE,50,48,100)
RandomBlock(-4,-6,5,COBBLESTONE,50,48,100)
RandomBlock(-4,-6,6,COBBLESTONE,50,48,100)
RandomBlock(-4,-6,7,COBBLESTONE,50,48,100)
RandomBlock(-4,-6,8,COBBLESTONE,50,48,100)
RandomBlock(-4,-6,9,COBBLESTONE,50,48,100)
RandomBlock(-4,-6,10,COBBLESTONE,50,48,100)
RandomBlock(-4,-5,-10,COBBLESTONE,50,48,100)
RandomBlock(-4,-5,-9,COBBLESTONE,50,48,100)
RandomBlock(-4,-5,-8,COBBLESTONE,50,48,100)
RandomBlock(-4,-5,-7,COBBLESTONE,50,48,100)
RandomBlock(-4,-5,-6,COBBLESTONE,50,48,100)
RandomBlock(-4,-5,-5,COBBLESTONE,50,48,100)
RandomBlock(-4,-5,-4,COBBLESTONE,50,48,100)
RandomBlock(-4,-5,-3,COBBLESTONE,50,48,100)
RandomBlock(-4,-5,-2,COBBLESTONE,50,48,100)
RandomBlock(-4,-5,-1,COBBLESTONE,50,48,100)
RandomBlock(-4,-5,0,COBBLESTONE,50,48,100)
RandomBlock(-4,-5,1,COBBLESTONE,50,48,100)
RandomBlock(-4,-5,2,COBBLESTONE,50,48,100)
RandomBlock(-4,-5,3,COBBLESTONE,50,48,100)
RandomBlock(-4,-5,4,COBBLESTONE,50,48,100)
RandomBlock(-4,-5,5,COBBLESTONE,50,48,100)
RandomBlock(-4,-5,6,COBBLESTONE,50,48,100)
RandomBlock(-4,-5,7,COBBLESTONE,50,48,100)
RandomBlock(-4,-5,8,COBBLESTONE,50,48,100)
RandomBlock(-4,-5,9,COBBLESTONE,50,48,100)
RandomBlock(-4,-5,10,COBBLESTONE,50,48,100)
RandomBlock(-4,-4,-10,COBBLESTONE,50,48,100)
RandomBlock(-4,-4,-9,COBBLESTONE,50,48,100)
RandomBlock(-4,-4,-8,COBBLESTONE,50,48,100)
RandomBlock(-4,-4,-7,COBBLESTONE,50,48,100)
RandomBlock(-4,-4,-6,COBBLESTONE,50,48,100)
RandomBlock(-4,-4,-5,COBBLESTONE,50,48,100)
RandomBlock(-4,-4,-4,COBBLESTONE,50,48,100)
RandomBlock(-4,-4,-3,COBBLESTONE,50,48,100)
RandomBlock(-4,-4,-2,COBBLESTONE,50,48,100)
RandomBlock(-4,-4,-1,COBBLESTONE,50,48,100)
RandomBlock(-4,-4,0,COBBLESTONE,50,48,100)
RandomBlock(-4,-4,1,COBBLESTONE,50,48,100)
RandomBlock(-4,-4,2,COBBLESTONE,50,48,100)
RandomBlock(-4,-4,3,COBBLESTONE,50,48,100)
RandomBlock(-4,-4,4,COBBLESTONE,50,48,100)
RandomBlock(-4,-4,5,COBBLESTONE,50,48,100)
RandomBlock(-4,-4,6,COBBLESTONE,50,48,100)
RandomBlock(-4,-4,7,COBBLESTONE,50,48,100)
RandomBlock(-4,-4,8,COBBLESTONE,50,48,100)
RandomBlock(-4,-4,9,COBBLESTONE,50,48,100)
RandomBlock(-4,-4,10,COBBLESTONE,50,48,100)
