#######################################################################
# +-----------------------------------------------------------------+ #
# |                            BO3 object                           | #
# +-----------------------------------------------------------------+ #
#######################################################################

# The descriptions in this file are true only for TerrainControl. They are not true for the Minecraft Worlds mod!
# Minecraft Worlds completely reimplemented BO3s, check the MCW documentation on the mc/mctcp forums for how to use BO3s with MCW
# or watch the video's on my YT channel at https://www.youtube.com/user/PeeGee85. You can check out the "Editing and importing schematics & BO3s" 
# series of video's, in part 2 I explain BO3s. 

# This is the config file of a custom object.
# If you add this object correctly to your BiomeConfigs, it will spawn in the world.

# This is the creator of this BO3 object
Author: Unknown

# A short description of this BO3 object
Description: This BO3 was converted from a schematic using the MineCraft Worlds Editor. Unfortunately the author and description information for the schematic could not be found. If you know who the author of the schematic is then please tell the author of this BO3!

# The BO3 version, don't change this! It can be used by external applications to do a version check.
Version: 3

# The settings mode, WriteAll, WriteWithoutComments or WriteDisable. See WorldConfig.
SettingsMode: WriteDisable

#######################################################################
# +-----------------------------------------------------------------+ #
# |                          Main settings                          | #
# +-----------------------------------------------------------------+ #
#######################################################################

# This needs to be set to true to spawn the object in the Tree and Sapling resources.
Tree: false

# The frequency of the BO3 from 1 to 200. Tries this many times to spawn this BO3 when using the CustomObject(...) resource.
# Ignored by Tree(..), Sapling(..) and CustomStructure(..)
Frequency: 1

# The rarity of the BO3 from 0 to 100. Each spawn attempt has rarity% chance to succeed when using the CustomObject(...) resource.
# Ignored by Tree(..), Sapling(..) and CustomStructure(..)
Rarity: 5.0

# If you set this to true, the BO3 will be placed with a random rotation.
RotateRandomly: true

# The spawn height of the BO3 - randomY, highestBlock or highestSolidBlock.
SpawnHeight: highestSolidBlock

# The height limits for the BO3.
MinHeight: 0

MaxHeight: 256

# Objects can have other objects attached to it: branches. Branches can also
# have branches attached to it, which can also have branches, etc. This is the
# maximum branch depth for this objects.
MaxBranchDepth: 10

# When spawned with the UseWorld keyword, this BO3 should NOT spawn in the following biomes.
# If you writer.write the BO3 name directly in the BiomeConfigs, this will be ignored.
ExcludedBiomes: All

#######################################################################
# +-----------------------------------------------------------------+ #
# |                      Source block settings                      | #
# +-----------------------------------------------------------------+ #
#######################################################################

# The B(s) the BO3 should spawn in.
SourceBlocks: AIR

# The maximum percentage of the BO3 that can be outside the SourceBlock.
# The BO3 won't be placed on a location with more blocks outside the SourceBlock than this percentage.
MaxPercentageOutsideSourceBlock: 100

# What to do when a block is about to be placed outside the SourceBlock? (dontPlace, placeAnyway)
OutsideSourceBlock: placeAnyway

#######################################################################
# +-----------------------------------------------------------------+ #
# |                              Blocks                             | #
# +-----------------------------------------------------------------+ #
#######################################################################

# All the blocks used in the BO3 are listed here. Possible blocks:
# B(x,y,z,id[.data][,nbtfile.nbt)
# RB(x,y,z,id[:data][,nbtfile.nbt],chance[,id[:data][,nbtfile.nbt],chance[,...]])
# So RB(0,0,0,CHEST,chest.nbt,50,CHEST,anotherchest.nbt,100) will spawn a chest at
# the BO3 origin, and give it a 50% chance to have the contents of chest.nbt, or, if that
# fails, a 100% percent chance to have the contents of anotherchest.nbt.

B(-8,-5,-7,4)
B(-8,-5,-6,48)
B(-8,-5,-5,48)
B(-8,-5,-4,48)
B(-8,-5,-3,48)
B(-8,-5,-2,4)
B(-8,-5,-1,48)
B(-8,-5,0,48)
B(-8,-5,1,48)
B(-8,-5,2,48)
B(-8,-5,3,48)
B(-8,-5,4,48)
B(-8,-5,5,48)
B(-8,-5,6,48)
B(-8,-5,7,48)
B(-8,-4,-7,4)
B(-8,-4,-6,4)
B(-8,-4,-5,48)
B(-8,-4,-4,48)
B(-8,-4,-3,48)
B(-8,-4,-2,48)
B(-8,-4,-1,48)
B(-8,-4,0,48)
B(-8,-4,1,4)
B(-8,-4,2,48)
B(-8,-4,3,4)
B(-8,-4,4,48)
B(-8,-4,5,4)
B(-8,-4,6,48)
B(-8,-4,7,48)
B(-8,-3,-7,4)
B(-8,-3,-6,48)
B(-8,-3,-5,4)
B(-8,-3,-4,48)
B(-8,-3,-3,4)
B(-8,-3,-2,4)
B(-8,-3,-1,48)
B(-8,-3,0,4)
B(-8,-3,1,4)
B(-8,-3,2,48)
B(-8,-3,3,48)
B(-8,-3,4,48)
B(-8,-3,5,48)
B(-8,-3,6,48)
B(-8,-3,7,4)
B(-8,-2,-7,4)
B(-8,-2,-6,4)
B(-8,-2,-5,48)
B(-8,-2,-4,48)
B(-8,-2,-3,4)
B(-8,-2,-2,4)
B(-8,-2,-1,48)
B(-8,-2,0,48)
B(-8,-2,1,4)
B(-8,-2,2,4)
B(-8,-2,3,48)
B(-8,-2,4,4)
B(-8,-2,5,4)
B(-8,-2,6,4)
B(-8,-2,7,4)
B(-8,-1,-7,48)
B(-8,-1,-6,4)
B(-8,-1,-5,4)
B(-8,-1,-4,48)
B(-8,-1,-3,4)
B(-8,-1,-2,4)
B(-8,-1,-1,4)
B(-8,-1,0,48)
B(-8,-1,1,48)
B(-8,-1,2,48)
B(-8,-1,3,48)
B(-8,-1,4,48)
B(-8,-1,5,48)
B(-8,-1,6,48)
B(-8,-1,7,4)
B(-8,3,-5,4)
B(-8,3,-3,48)
B(-8,3,-1,48)
B(-8,3,1,48)
B(-8,3,3,48)
B(-8,3,5,48)
B(-8,4,-5,4)
B(-8,4,-4,106:8)
B(-8,4,-3,4)
B(-8,4,-1,48)
B(-8,4,1,48)
B(-8,4,3,48)
B(-8,4,5,97:1)
B(-8,5,-5,106:8)
B(-8,5,-4,106:8)
B(-8,5,-2,48)
B(-8,5,2,48)
B(-7,-5,-7,4)
B(-7,-5,-6,4)
B(-7,-5,-5,4)
B(-7,-5,-4,48)
B(-7,-5,-3,48)
B(-7,-5,-2,48)
B(-7,-5,-1,4)
B(-7,-5,0,4)
B(-7,-5,1,48)
B(-7,-5,2,48)
B(-7,-5,3,4)
B(-7,-5,4,48)
B(-7,-5,5,48)
B(-7,-5,6,4)
B(-7,-5,7,4)
B(-7,-4,-7,48)
B(-7,-4,-6,48)
B(-7,-4,-5,AIR)
B(-7,-4,-4,48)
B(-7,-4,-3,106:1)
B(-7,-4,-2,4)
B(-7,-4,-1,131:7)
B(-7,-4,0,4)
B(-7,-4,1,AIR)
B(-7,-4,2,4)
B(-7,-4,3,AIR)
B(-7,-4,4,48)
B(-7,-4,5,AIR)
B(-7,-4,6,48)
B(-7,-4,7,48)
B(-7,-3,-7,48)
B(-7,-3,-6,4)
B(-7,-3,-5,AIR)
B(-7,-3,-4,4)
B(-7,-3,-3,106:1)
B(-7,-3,-2,48)
B(-7,-3,-1,AIR)
B(-7,-3,0,48)
B(-7,-3,1,AIR)
B(-7,-3,2,4)
B(-7,-3,3,AIR)
B(-7,-3,4,48)
B(-7,-3,5,AIR)
B(-7,-3,6,4)
B(-7,-3,7,48)
B(-7,-2,-7,4)
B(-7,-2,-6,AIR)
B(-7,-2,-5,4)
B(-7,-2,-4,AIR)
B(-7,-2,-3,48)
B(-7,-2,-2,AIR)
B(-7,-2,-1,4)
B(-7,-2,0,AIR)
B(-7,-2,1,48)
B(-7,-2,2,AIR)
B(-7,-2,3,48)
B(-7,-2,4,AIR)
B(-7,-2,5,48)
B(-7,-2,6,AIR)
B(-7,-2,7,48)
B(-7,-1,-7,48)
B(-7,-1,-6,48)
B(-7,-1,-5,4)
B(-7,-1,-4,48)
B(-7,-1,-3,48)
B(-7,-1,-2,4)
B(-7,-1,-1,48)
B(-7,-1,0,4)
B(-7,-1,1,48)
B(-7,-1,2,48)
B(-7,-1,3,48)
B(-7,-1,4,4)
B(-7,-1,5,4)
B(-7,-1,6,4)
B(-7,-1,7,4)
B(-7,0,-5,106:8)
B(-7,1,-5,106:8)
B(-7,2,-6,48)
B(-7,2,-5,4)
B(-7,2,-4,48)
B(-7,2,-3,48)
B(-7,2,-2,48)
B(-7,2,-1,48)
B(-7,2,0,48)
B(-7,2,1,48)
B(-7,2,2,48)
B(-7,2,3,48)
B(-7,2,4,4)
B(-7,2,5,4)
B(-7,2,6,48)
B(-7,3,-6,48)
B(-7,3,-5,4)
B(-7,3,-4,48)
B(-7,3,-3,48)
B(-7,3,-2,48)
B(-7,3,-1,4)
B(-7,3,0,48)
B(-7,3,1,4)
B(-7,3,2,4)
B(-7,3,3,48)
B(-7,3,4,48)
B(-7,3,5,4)
B(-7,3,6,48)
B(-7,4,-6,48)
B(-7,4,-5,4)
B(-7,4,-4,48)
B(-7,4,-3,48)
B(-7,4,-2,AIR)
B(-7,4,-1,48)
B(-7,4,0,4)
B(-7,4,1,4)
B(-7,4,2,AIR)
B(-7,4,3,48)
B(-7,4,4,4)
B(-7,4,5,48)
B(-7,4,6,4)
B(-7,5,-7,48)
B(-7,5,-6,4)
B(-7,5,-5,48)
B(-7,5,-4,4)
B(-7,5,-3,48)
B(-7,5,-2,4)
B(-7,5,-1,48)
B(-7,5,0,48)
B(-7,5,1,48)
B(-7,5,2,4)
B(-7,5,3,48)
B(-7,5,4,4)
B(-7,5,5,48)
B(-7,5,6,4)
B(-6,-5,-7,4)
B(-6,-5,-6,48)
B(-6,-5,-5,4)
B(-6,-5,-4,4)
B(-6,-5,-3,48)
B(-6,-5,-2,48)
B(-6,-5,-1,4)
B(-6,-5,0,48)
B(-6,-5,1,48)
B(-6,-5,2,4)
B(-6,-5,3,48)
B(-6,-5,4,4)
B(-6,-5,5,4)
B(-6,-5,6,48)
B(-6,-5,7,4)
B(-6,-4,-7,4)
B(-6,-4,-6,AIR)
B(-6,-4,-5,AIR)
B(-6,-4,-4,AIR)
B(-6,-4,-3,AIR)
B(-6,-4,-2,106:3)
B(-6,-4,-1,132:4)
B(-6,-4,0,AIR)
B(-6,-4,1,AIR)
B(-6,-4,2,AIR)
B(-6,-4,3,AIR)
B(-6,-4,4,AIR)
B(-6,-4,5,AIR)
B(-6,-4,6,AIR)
B(-6,-4,7,4)
B(-6,-3,-7,48)
B(-6,-3,-5,AIR)
B(-6,-3,-4,AIR)
B(-6,-3,-3,AIR)
B(-6,-3,-2,106:3)
B(-6,-3,-1,AIR)
B(-6,-3,0,106:1)
B(-6,-3,1,AIR)
B(-6,-3,2,AIR)
B(-6,-3,3,AIR)
B(-6,-3,4,AIR)
B(-6,-3,5,AIR)
B(-6,-3,6,4)
B(-6,-3,7,48)
B(-6,-2,-7,48)
B(-6,-2,-6,AIR)
B(-6,-2,-5,48)
B(-6,-2,-4,AIR)
B(-6,-2,-3,48)
B(-6,-2,-2,106:1)
B(-6,-2,-1,4)
B(-6,-2,0,106:1)
B(-6,-2,1,4)
B(-6,-2,2,AIR)
B(-6,-2,3,48)
B(-6,-2,4,AIR)
B(-6,-2,5,48)
B(-6,-2,6,AIR)
B(-6,-2,7,4)
B(-6,-1,-7,4)
B(-6,-1,-6,48)
B(-6,-1,-5,48)
B(-6,-1,-4,48)
B(-6,-1,-3,48)
B(-6,-1,-2,48)
B(-6,-1,-1,48)
B(-6,-1,0,48)
B(-6,-1,1,48)
B(-6,-1,2,48)
B(-6,-1,3,4)
B(-6,-1,4,48)
B(-6,-1,5,48)
B(-6,-1,6,48)
B(-6,-1,7,48)
B(-6,0,-5,48)
B(-6,0,-4,48)
B(-6,0,-3,48)
B(-6,0,-2,48)
B(-6,0,-1,48)
B(-6,0,0,4)
B(-6,0,1,4)
B(-6,0,2,4)
B(-6,0,3,4)
B(-6,0,4,48)
B(-6,0,5,48)
B(-6,1,-5,48)
B(-6,1,-4,48)
B(-6,1,-3,48)
B(-6,1,-2,48)
B(-6,1,-1,48)
B(-6,1,0,4)
B(-6,1,1,4)
B(-6,1,2,48)
B(-6,1,3,48)
B(-6,1,4,48)
B(-6,1,5,4)
B(-6,2,-6,4)
B(-6,2,-5,4)
B(-6,2,-4,48)
B(-6,2,-3,48)
B(-6,2,-2,48)
B(-6,2,-1,48)
B(-6,2,0,48)
B(-6,2,1,4)
B(-6,2,2,48)
B(-6,2,3,48)
B(-6,2,4,48)
B(-6,2,5,4)
B(-6,2,6,4)
B(-6,3,-7,48)
B(-6,3,-6,48)
B(-6,3,-5,AIR)
B(-6,3,-4,AIR)
B(-6,3,-3,AIR)
B(-6,3,-2,AIR)
B(-6,3,-1,AIR)
B(-6,3,0,106:2)
B(-6,3,1,AIR)
B(-6,3,2,106:2)
B(-6,3,3,AIR)
B(-6,3,4,106:2)
B(-6,3,5,AIR)
B(-6,3,6,48)
B(-6,3,7,97:1)
B(-6,4,-7,48)
B(-6,4,-6,4)
B(-6,4,-5,AIR)
B(-6,4,-4,AIR)
B(-6,4,-3,AIR)
B(-6,4,-2,AIR)
B(-6,4,-1,106:2)
B(-6,4,0,106:2)
B(-6,4,1,AIR)
B(-6,4,2,AIR)
B(-6,4,3,AIR)
B(-6,4,4,106:2)
B(-6,4,5,AIR)
B(-6,4,6,48)
B(-6,4,7,4)
B(-6,5,-6,48)
B(-6,5,-5,4)
B(-6,5,-4,48)
B(-6,5,-3,4)
B(-6,5,-2,48)
B(-6,5,-1,4)
B(-6,5,0,4)
B(-6,5,1,4)
B(-6,5,2,4)
B(-6,5,3,48)
B(-6,5,4,48)
B(-6,5,5,48)
B(-6,5,6,4)
B(-6,6,-5,48)
B(-6,6,-2,106:8)
B(-6,6,5,48)
B(-6,7,-5,4)
B(-6,7,5,4)
B(-6,8,-5,48)
B(-6,8,5,4)
B(-5,-5,-7,4)
B(-5,-5,-6,48)
B(-5,-5,-5,48)
B(-5,-5,-4,48)
B(-5,-5,-3,48)
B(-5,-5,-2,48)
B(-5,-5,-1,48)
B(-5,-5,0,4)
B(-5,-5,1,48)
B(-5,-5,2,4)
B(-5,-5,3,4)
B(-5,-5,4,48)
B(-5,-5,5,4)
B(-5,-5,6,48)
B(-5,-5,7,48)
B(-5,-4,-7,4)
B(-5,-4,-6,AIR)
B(-5,-4,-5,AIR)
B(-5,-4,-4,AIR)
B(-5,-4,-3,AIR)
B(-5,-4,-2,AIR)
B(-5,-4,-1,132:4)
B(-5,-4,0,AIR)
B(-5,-4,1,106:8)
B(-5,-4,2,106:8)
B(-5,-4,3,AIR)
B(-5,-4,4,AIR)
B(-5,-4,5,106:7)
B(-5,-4,6,48)
B(-5,-4,7,4)
B(-5,-3,-7,48)
B(-5,-3,-6,AIR)
B(-5,-3,-5,AIR)
B(-5,-3,-4,AIR)
B(-5,-3,-3,AIR)
B(-5,-3,-2,AIR)
B(-5,-3,-1,AIR)
B(-5,-3,0,106:1)
B(-5,-3,1,106:8)
B(-5,-3,2,AIR)
B(-5,-3,3,AIR)
B(-5,-3,4,AIR)
B(-5,-3,5,106:5)
B(-5,-3,6,23:2,../../nbt/Misc/ArrowTrap.nbt)
B(-5,-3,7,48)
B(-5,-2,-7,4)
B(-5,-2,-6,AIR)
B(-5,-2,-5,4)
B(-5,-2,-4,AIR)
B(-5,-2,-3,4)
B(-5,-2,-2,AIR)
B(-5,-2,-1,48)
B(-5,-2,0,106:1)
B(-5,-2,1,48)
B(-5,-2,2,106:1)
B(-5,-2,3,48)
B(-5,-2,4,AIR)
B(-5,-2,5,48)
B(-5,-2,6,AIR)
B(-5,-2,7,48)
B(-5,-1,-7,4)
B(-5,-1,-6,48)
B(-5,-1,-5,4)
B(-5,-1,-4,48)
B(-5,-1,-3,4)
B(-5,-1,-2,48)
B(-5,-1,-1,48)
B(-5,-1,0,48)
B(-5,-1,1,48)
B(-5,-1,2,48)
B(-5,-1,3,48)
B(-5,-1,4,4)
B(-5,-1,5,4)
B(-5,-1,6,48)
B(-5,-1,7,4)
B(-5,0,-5,48)
B(-5,0,-4,AIR)
B(-5,0,-3,AIR)
B(-5,0,-2,AIR)
B(-5,0,-1,106:2)
B(-5,0,0,AIR)
B(-5,0,1,AIR)
B(-5,0,2,AIR)
B(-5,0,3,106:2)
B(-5,0,4,AIR)
B(-5,0,5,4)
B(-5,1,-5,48)
B(-5,1,-4,AIR)
B(-5,1,-3,106:8)
B(-5,1,-2,AIR)
B(-5,1,-1,106:2)
B(-5,1,0,AIR)
B(-5,1,1,AIR)
B(-5,1,2,AIR)
B(-5,1,3,106:2)
B(-5,1,4,AIR)
B(-5,1,5,4)
B(-5,2,-6,48)
B(-5,2,-5,48)
B(-5,2,-4,48)
B(-5,2,-3,48)
B(-5,2,-2,4)
B(-5,2,-1,48)
B(-5,2,0,48)
B(-5,2,1,4)
B(-5,2,2,4)
B(-5,2,3,4)
B(-5,2,4,4)
B(-5,2,5,48)
B(-5,2,6,4)
B(-5,3,-6,48)
B(-5,3,-5,AIR)
B(-5,3,-4,AIR)
B(-5,3,-3,AIR)
B(-5,3,-2,AIR)
B(-5,3,-1,AIR)
B(-5,3,0,AIR)
B(-5,3,1,AIR)
B(-5,3,2,AIR)
B(-5,3,3,AIR)
B(-5,3,4,AIR)
B(-5,3,5,AIR)
B(-5,3,6,4)
B(-5,4,-6,4)
B(-5,4,-5,AIR)
B(-5,4,-4,AIR)
B(-5,4,-3,AIR)
B(-5,4,-2,AIR)
B(-5,4,-1,AIR)
B(-5,4,0,AIR)
B(-5,4,1,AIR)
B(-5,4,2,AIR)
B(-5,4,3,AIR)
B(-5,4,4,AIR)
B(-5,4,5,AIR)
B(-5,4,6,48)
B(-5,5,-6,4)
B(-5,5,-5,48)
B(-5,5,-4,48)
B(-5,5,-3,48)
B(-5,5,-2,4)
B(-5,5,-1,48)
B(-5,5,0,4)
B(-5,5,1,48)
B(-5,5,2,48)
B(-5,5,3,4)
B(-5,5,4,48)
B(-5,5,5,48)
B(-5,5,6,48)
B(-5,6,-4,48)
B(-5,6,-3,48)
B(-5,6,-2,48)
B(-5,6,-1,48)
B(-5,6,0,48)
B(-5,6,1,48)
B(-5,6,2,4)
B(-5,6,3,4)
B(-5,6,4,4)
B(-4,-5,-7,48)
B(-4,-5,-6,48)
B(-4,-5,-5,48)
B(-4,-5,-4,4)
B(-4,-5,-3,48)
B(-4,-5,-2,48)
B(-4,-5,-1,4)
B(-4,-5,0,48)
B(-4,-5,1,48)
B(-4,-5,2,4)
B(-4,-5,3,48)
B(-4,-5,4,48)
B(-4,-5,5,4)
B(-4,-5,6,48)
B(-4,-5,7,48)
B(-4,-4,-7,48)
B(-4,-4,-6,AIR)
B(-4,-4,-5,AIR)
B(-4,-4,-4,4)
B(-4,-4,-3,48)
B(-4,-4,-2,48)
B(-4,-4,-1,131:5)
B(-4,-4,0,48)
B(-4,-4,1,48)
B(-4,-4,2,48)
B(-4,-4,3,AIR)
B(-4,-4,4,AIR)
B(-4,-4,5,AIR)
B(-4,-4,6,55)
B(-4,-4,7,48)
B(-4,-3,-7,48)
B(-4,-3,-6,AIR)
B(-4,-3,-5,AIR)
B(-4,-3,-4,48)
B(-4,-3,-3,4)
B(-4,-3,-2,48)
B(-4,-3,-1,4)
B(-4,-3,0,48)
B(-4,-3,1,4)
B(-4,-3,2,AIR)
B(-4,-3,3,AIR)
B(-4,-3,4,AIR)
B(-4,-3,5,AIR)
B(-4,-3,6,48)
B(-4,-3,7,4)
B(-4,-2,-7,48)
B(-4,-2,-6,AIR)
B(-4,-2,-5,AIR)
B(-4,-2,-4,48)
B(-4,-2,-3,4)
B(-4,-2,-2,48)
B(-4,-2,-1,4)
B(-4,-2,0,4)
B(-4,-2,1,4)
B(-4,-2,2,AIR)
B(-4,-2,3,AIR)
B(-4,-2,4,AIR)
B(-4,-2,5,AIR)
B(-4,-2,6,106:1)
B(-4,-2,7,48)
B(-4,-1,-7,4)
B(-4,-1,-6,48)
B(-4,-1,-5,48)
B(-4,-1,-4,48)
B(-4,-1,-3,4)
B(-4,-1,-2,48)
B(-4,-1,-1,48)
B(-4,-1,0,4)
B(-4,-1,1,48)
B(-4,-1,2,48)
B(-4,-1,3,48)
B(-4,-1,4,48)
B(-4,-1,5,4)
B(-4,-1,6,48)
B(-4,-1,7,67:3)
B(-4,0,-5,48)
B(-4,0,-4,AIR)
B(-4,0,-3,4)
B(-4,0,-2,48)
B(-4,0,-1,67:3)
B(-4,0,0,AIR)
B(-4,0,1,AIR)
B(-4,0,2,AIR)
B(-4,0,3,AIR)
B(-4,0,4,AIR)
B(-4,0,5,48)
B(-4,1,-5,48)
B(-4,1,-4,AIR)
B(-4,1,-3,48)
B(-4,1,-2,67:3)
B(-4,1,-1,AIR)
B(-4,1,0,AIR)
B(-4,1,1,AIR)
B(-4,1,2,AIR)
B(-4,1,3,AIR)
B(-4,1,4,AIR)
B(-4,1,5,48)
B(-4,2,-6,4)
B(-4,2,-5,4)
B(-4,2,-4,4)
B(-4,2,-3,67:3)
B(-4,2,-2,106:2)
B(-4,2,-1,AIR)
B(-4,2,0,106:2)
B(-4,2,1,AIR)
B(-4,2,2,48)
B(-4,2,3,4)
B(-4,2,4,4)
B(-4,2,5,48)
B(-4,2,6,4)
B(-4,3,-7,48)
B(-4,3,-6,48)
B(-4,3,-5,AIR)
B(-4,3,-4,AIR)
B(-4,3,-3,AIR)
B(-4,3,-2,AIR)
B(-4,3,-1,AIR)
B(-4,3,0,AIR)
B(-4,3,1,AIR)
B(-4,3,2,67)
B(-4,3,3,AIR)
B(-4,3,4,AIR)
B(-4,3,5,AIR)
B(-4,3,6,48)
B(-4,3,7,48)
B(-4,4,-7,48)
B(-4,4,-6,4)
B(-4,4,-5,AIR)
B(-4,4,-4,AIR)
B(-4,4,-3,AIR)
B(-4,4,-2,106:4)
B(-4,4,-1,AIR)
B(-4,4,0,AIR)
B(-4,4,1,AIR)
B(-4,4,2,AIR)
B(-4,4,3,AIR)
B(-4,4,4,AIR)
B(-4,4,5,AIR)
B(-4,4,6,4)
B(-4,4,7,48)
B(-4,5,-6,48)
B(-4,5,-5,48)
B(-4,5,-4,4)
B(-4,5,-3,48)
B(-4,5,-2,106:4)
B(-4,5,-1,AIR)
B(-4,5,0,106:2)
B(-4,5,1,AIR)
B(-4,5,2,AIR)
B(-4,5,3,48)
B(-4,5,4,4)
B(-4,5,5,48)
B(-4,5,6,48)
B(-4,6,-4,48)
B(-4,6,-3,48)
B(-4,6,-2,4)
B(-4,6,-1,4)
B(-4,6,0,4)
B(-4,6,1,48)
B(-4,6,2,4)
B(-4,6,3,48)
B(-4,6,4,48)
B(-4,7,-3,48)
B(-4,7,-2,4)
B(-4,7,-1,4)
B(-4,7,0,48)
B(-4,7,1,48)
B(-4,7,2,48)
B(-4,7,3,4)
B(-4,8,-3,48)
B(-4,8,3,48)
B(-3,-5,-7,48)
B(-3,-5,-6,48)
B(-3,-5,-5,48)
B(-3,-5,-4,48)
B(-3,-5,-3,4)
B(-3,-5,-2,4)
B(-3,-5,-1,4)
B(-3,-5,0,4)
B(-3,-5,1,48)
B(-3,-5,2,48)
B(-3,-5,3,48)
B(-3,-5,4,48)
B(-3,-5,5,48)
B(-3,-5,6,48)
B(-3,-5,7,48)
B(-3,-4,-7,4)
B(-3,-4,-6,AIR)
B(-3,-4,-5,AIR)
B(-3,-4,-4,106:2)
B(-3,-4,-3,AIR)
B(-3,-4,-2,67:2)
B(-3,-4,-1,48)
B(-3,-4,0,55)
B(-3,-4,1,55)
B(-3,-4,2,55)
B(-3,-4,3,55)
B(-3,-4,4,55)
B(-3,-4,5,55)
B(-3,-4,6,55)
B(-3,-4,7,4)
B(-3,-3,-7,4)
B(-3,-3,-6,AIR)
B(-3,-3,-5,AIR)
B(-3,-3,-4,106:2)
B(-3,-3,-3,AIR)
B(-3,-3,-2,AIR)
B(-3,-3,-1,67:2)
B(-3,-3,0,4)
B(-3,-3,1,4)
B(-3,-3,2,48)
B(-3,-3,3,AIR)
B(-3,-3,4,AIR)
B(-3,-3,5,106:1)
B(-3,-3,6,48)
B(-3,-3,7,48)
B(-3,-2,-7,48)
B(-3,-2,-6,AIR)
B(-3,-2,-5,AIR)
B(-3,-2,-4,48)
B(-3,-2,-3,AIR)
B(-3,-2,-2,AIR)
B(-3,-2,-1,AIR)
B(-3,-2,0,67:2)
B(-3,-2,1,4)
B(-3,-2,2,48)
B(-3,-2,3,AIR)
B(-3,-2,4,AIR)
B(-3,-2,5,AIR)
B(-3,-2,6,AIR)
B(-3,-2,7,4)
B(-3,-1,-7,4)
B(-3,-1,-6,48)
B(-3,-1,-5,48)
B(-3,-1,-4,4)
B(-3,-1,-3,4)
B(-3,-1,-2,AIR)
B(-3,-1,-1,AIR)
B(-3,-1,0,AIR)
B(-3,-1,1,67:2)
B(-3,-1,2,48)
B(-3,-1,3,48)
B(-3,-1,4,48)
B(-3,-1,5,48)
B(-3,-1,6,48)
B(-3,-1,7,67:3)
B(-3,0,-5,48)
B(-3,0,-4,AIR)
B(-3,0,-3,48)
B(-3,0,-2,106:4)
B(-3,0,-1,AIR)
B(-3,0,0,AIR)
B(-3,0,1,AIR)
B(-3,0,2,AIR)
B(-3,0,3,AIR)
B(-3,0,4,AIR)
B(-3,0,5,AIR)
B(-3,1,-5,AIR)
B(-3,1,-4,AIR)
B(-3,1,-3,48)
B(-3,1,-2,106:4)
B(-3,1,-1,AIR)
B(-3,1,0,AIR)
B(-3,1,1,AIR)
B(-3,1,2,AIR)
B(-3,1,3,AIR)
B(-3,1,4,AIR)
B(-3,1,5,AIR)
B(-3,2,-6,4)
B(-3,2,-5,48)
B(-3,2,-4,4)
B(-3,2,-3,48)
B(-3,2,-2,106:4)
B(-3,2,-1,AIR)
B(-3,2,0,AIR)
B(-3,2,1,AIR)
B(-3,2,2,48)
B(-3,2,3,48)
B(-3,2,4,48)
B(-3,2,5,48)
B(-3,2,6,4)
B(-3,3,-6,4)
B(-3,3,-5,AIR)
B(-3,3,-4,AIR)
B(-3,3,-3,AIR)
B(-3,3,-2,AIR)
B(-3,3,-1,AIR)
B(-3,3,0,AIR)
B(-3,3,1,106:1)
B(-3,3,2,48)
B(-3,3,3,AIR)
B(-3,3,4,AIR)
B(-3,3,5,AIR)
B(-3,3,6,4)
B(-3,4,-6,AIR)
B(-3,4,-5,AIR)
B(-3,4,-4,AIR)
B(-3,4,-3,AIR)
B(-3,4,-2,106:4)
B(-3,4,-1,AIR)
B(-3,4,0,AIR)
B(-3,4,1,AIR)
B(-3,4,2,AIR)
B(-3,4,3,AIR)
B(-3,4,4,AIR)
B(-3,4,5,AIR)
B(-3,4,6,AIR)
B(-3,5,-6,4)
B(-3,5,-5,48)
B(-3,5,-4,48)
B(-3,5,-3,48)
B(-3,5,-2,106:4)
B(-3,5,-1,AIR)
B(-3,5,0,AIR)
B(-3,5,1,AIR)
B(-3,5,2,AIR)
B(-3,5,3,48)
B(-3,5,4,4)
B(-3,5,5,48)
B(-3,5,6,48)
B(-3,5,7,48)
B(-3,6,-4,48)
B(-3,6,-3,4)
B(-3,6,-2,48)
B(-3,6,-1,AIR)
B(-3,6,0,AIR)
B(-3,6,1,106:1)
B(-3,6,2,4)
B(-3,6,3,4)
B(-3,6,4,4)
B(-3,7,-3,48)
B(-3,7,-2,4)
B(-3,7,-1,4)
B(-3,7,0,48)
B(-3,7,1,48)
B(-3,7,2,48)
B(-3,7,3,48)
B(-3,8,-1,67:2)
B(-3,8,0,48)
B(-3,8,1,67:3)
B(-2,-5,-7,48)
B(-2,-5,-6,48)
B(-2,-5,-5,48)
B(-2,-5,-4,48)
B(-2,-5,-3,4)
B(-2,-5,-2,48)
B(-2,-5,-1,48)
B(-2,-5,0,48)
B(-2,-5,1,48)
B(-2,-5,2,48)
B(-2,-5,3,4)
B(-2,-5,4,48)
B(-2,-5,5,48)
B(-2,-5,6,48)
B(-2,-5,7,48)
B(-2,-4,-7,48)
B(-2,-4,-6,AIR)
B(-2,-4,-5,AIR)
B(-2,-4,-4,AIR)
B(-2,-4,-3,AIR)
B(-2,-4,-2,67:2)
B(-2,-4,-1,4)
B(-2,-4,0,48)
B(-2,-4,1,4)
B(-2,-4,2,48)
B(-2,-4,3,AIR)
B(-2,-4,4,AIR)
B(-2,-4,5,AIR)
B(-2,-4,6,4)
B(-2,-4,7,48)
B(-2,-3,-7,48)
B(-2,-3,-6,AIR)
B(-2,-3,-5,AIR)
B(-2,-3,-4,AIR)
B(-2,-3,-3,AIR)
B(-2,-3,-2,AIR)
B(-2,-3,-1,67:2)
B(-2,-3,0,4)
B(-2,-3,1,4)
B(-2,-3,2,106:4)
B(-2,-3,3,AIR)
B(-2,-3,4,AIR)
B(-2,-3,5,AIR)
B(-2,-3,6,AIR)
B(-2,-3,7,48)
B(-2,-2,-7,4)
B(-2,-2,-6,AIR)
B(-2,-2,-5,AIR)
B(-2,-2,-4,4)
B(-2,-2,-3,AIR)
B(-2,-2,-2,AIR)
B(-2,-2,-1,AIR)
B(-2,-2,0,67:2)
B(-2,-2,1,4)
B(-2,-2,2,106:4)
B(-2,-2,3,AIR)
B(-2,-2,4,AIR)
B(-2,-2,5,AIR)
B(-2,-2,6,48)
B(-2,-2,7,48)
B(-2,-1,-7,48)
B(-2,-1,-6,48)
B(-2,-1,-5,48)
B(-2,-1,-4,48)
B(-2,-1,-3,48)
B(-2,-1,-2,AIR)
B(-2,-1,-1,AIR)
B(-2,-1,0,106:8)
B(-2,-1,1,67:2)
B(-2,-1,2,48)
B(-2,-1,3,48)
B(-2,-1,4,48)
B(-2,-1,5,48)
B(-2,-1,6,4)
B(-2,-1,7,67:3)
B(-2,0,-6,106:1)
B(-2,0,-5,4)
B(-2,0,-4,AIR)
B(-2,0,-3,48)
B(-2,0,-2,AIR)
B(-2,0,-1,AIR)
B(-2,0,0,AIR)
B(-2,0,1,AIR)
B(-2,0,2,AIR)
B(-2,0,3,AIR)
B(-2,0,4,AIR)
B(-2,0,5,AIR)
B(-2,1,-5,AIR)
B(-2,1,-4,AIR)
B(-2,1,-3,48)
B(-2,1,-2,AIR)
B(-2,1,-1,AIR)
B(-2,1,0,AIR)
B(-2,1,1,AIR)
B(-2,1,2,AIR)
B(-2,1,3,AIR)
B(-2,1,4,AIR)
B(-2,1,5,AIR)
B(-2,2,-6,4)
B(-2,2,-5,4)
B(-2,2,-4,4)
B(-2,2,-3,48)
B(-2,2,-2,AIR)
B(-2,2,-1,AIR)
B(-2,2,0,AIR)
B(-2,2,1,AIR)
B(-2,2,2,4)
B(-2,2,3,48)
B(-2,2,4,48)
B(-2,2,5,4)
B(-2,2,6,48)
B(-2,3,-6,48)
B(-2,3,-5,AIR)
B(-2,3,-4,AIR)
B(-2,3,-3,AIR)
B(-2,3,-2,AIR)
B(-2,3,-1,AIR)
B(-2,3,0,AIR)
B(-2,3,1,AIR)
B(-2,3,2,48)
B(-2,3,3,AIR)
B(-2,3,4,AIR)
B(-2,3,5,106:1)
B(-2,3,6,4)
B(-2,4,-6,AIR)
B(-2,4,-5,AIR)
B(-2,4,-4,AIR)
B(-2,4,-3,AIR)
B(-2,4,-2,AIR)
B(-2,4,-1,AIR)
B(-2,4,0,AIR)
B(-2,4,1,AIR)
B(-2,4,2,AIR)
B(-2,4,3,AIR)
B(-2,4,4,AIR)
B(-2,4,5,AIR)
B(-2,4,6,AIR)
B(-2,5,-6,4)
B(-2,5,-5,48)
B(-2,5,-4,48)
B(-2,5,-3,4)
B(-2,5,-2,AIR)
B(-2,5,-1,AIR)
B(-2,5,0,106:8)
B(-2,5,1,AIR)
B(-2,5,2,AIR)
B(-2,5,3,48)
B(-2,5,4,48)
B(-2,5,5,48)
B(-2,5,6,48)
B(-2,5,7,4)
B(-2,6,-4,48)
B(-2,6,-3,48)
B(-2,6,-2,48)
B(-2,6,-1,106:4)
B(-2,6,0,106:8)
B(-2,6,1,106:1)
B(-2,6,2,48)
B(-2,6,3,48)
B(-2,6,4,48)
B(-2,6,5,106:4)
B(-2,7,-3,48)
B(-2,7,-2,48)
B(-2,7,-1,4)
B(-2,7,0,4)
B(-2,7,1,4)
B(-2,7,2,48)
B(-2,7,3,48)
B(-2,8,-1,67:2)
B(-2,8,0,4)
B(-2,8,1,67:3)
B(-1,-5,-7,48)
B(-1,-5,-6,48)
B(-1,-5,-5,4)
B(-1,-5,-4,48)
B(-1,-5,-3,4)
B(-1,-5,-2,4)
B(-1,-5,-1,4)
B(-1,-5,0,48)
B(-1,-5,1,4)
B(-1,-5,2,4)
B(-1,-5,3,48)
B(-1,-5,4,48)
B(-1,-5,5,48)
B(-1,-5,6,48)
B(-1,-5,7,48)
B(-1,-4,-7,48)
B(-1,-4,-6,AIR)
B(-1,-4,-5,AIR)
B(-1,-4,-4,48)
B(-1,-4,-3,4)
B(-1,-4,-2,48)
B(-1,-4,-1,4)
B(-1,-4,0,48)
B(-1,-4,1,48)
B(-1,-4,2,131:4)
B(-1,-4,3,132:4)
B(-1,-4,4,132:4)
B(-1,-4,5,132:4)
B(-1,-4,6,131:6)
B(-1,-4,7,48)
B(-1,-3,-7,48)
B(-1,-3,-6,AIR)
B(-1,-3,-5,AIR)
B(-1,-3,-4,48)
B(-1,-3,-3,4)
B(-1,-3,-2,4)
B(-1,-3,-1,4)
B(-1,-3,0,48)
B(-1,-3,1,48)
B(-1,-3,2,48)
B(-1,-3,3,AIR)
B(-1,-3,4,AIR)
B(-1,-3,5,AIR)
B(-1,-3,6,48)
B(-1,-3,7,4)
B(-1,-2,-7,48)
B(-1,-2,-6,AIR)
B(-1,-2,-5,AIR)
B(-1,-2,-4,4)
B(-1,-2,-3,4)
B(-1,-2,-2,48)
B(-1,-2,-1,48)
B(-1,-2,0,4)
B(-1,-2,1,4)
B(-1,-2,2,48)
B(-1,-2,3,AIR)
B(-1,-2,4,AIR)
B(-1,-2,5,AIR)
B(-1,-2,6,AIR)
B(-1,-2,7,48)
B(-1,-1,-7,48)
B(-1,-1,-6,48)
B(-1,-1,-5,4)
B(-1,-1,-4,4)
B(-1,-1,-3,4)
B(-1,-1,-2,4)
B(-1,-1,-1,48)
B(-1,-1,0,48)
B(-1,-1,1,4)
B(-1,-1,2,4)
B(-1,-1,3,4)
B(-1,-1,4,48)
B(-1,-1,5,4)
B(-1,-1,6,4)
B(-1,-1,7,67:3)
B(-1,0,-5,48)
B(-1,0,-4,AIR)
B(-1,0,-3,48)
B(-1,0,-2,48)
B(-1,0,-1,67:3)
B(-1,0,0,AIR)
B(-1,0,1,AIR)
B(-1,0,2,AIR)
B(-1,0,3,AIR)
B(-1,0,4,AIR)
B(-1,0,5,4)
B(-1,1,-5,48)
B(-1,1,-4,AIR)
B(-1,1,-3,4)
B(-1,1,-2,67:3)
B(-1,1,-1,AIR)
B(-1,1,0,AIR)
B(-1,1,1,AIR)
B(-1,1,2,AIR)
B(-1,1,3,AIR)
B(-1,1,4,AIR)
B(-1,1,5,4)
B(-1,2,-6,48)
B(-1,2,-5,48)
B(-1,2,-4,48)
B(-1,2,-3,67:3)
B(-1,2,-2,AIR)
B(-1,2,-1,AIR)
B(-1,2,0,AIR)
B(-1,2,1,AIR)
B(-1,2,2,48)
B(-1,2,3,48)
B(-1,2,4,4)
B(-1,2,5,4)
B(-1,2,6,48)
B(-1,3,-7,48)
B(-1,3,-6,4)
B(-1,3,-5,AIR)
B(-1,3,-4,AIR)
B(-1,3,-3,AIR)
B(-1,3,-2,AIR)
B(-1,3,-1,AIR)
B(-1,3,0,AIR)
B(-1,3,1,AIR)
B(-1,3,2,67:1)
B(-1,3,3,AIR)
B(-1,3,4,AIR)
B(-1,3,5,106:1)
B(-1,3,6,4)
B(-1,3,7,4)
B(-1,4,-7,4)
B(-1,4,-6,48)
B(-1,4,-5,AIR)
B(-1,4,-4,AIR)
B(-1,4,-3,AIR)
B(-1,4,-2,AIR)
B(-1,4,-1,AIR)
B(-1,4,0,AIR)
B(-1,4,1,AIR)
B(-1,4,2,AIR)
B(-1,4,3,AIR)
B(-1,4,4,AIR)
B(-1,4,5,106:1)
B(-1,4,6,4)
B(-1,4,7,48)
B(-1,5,-6,48)
B(-1,5,-5,48)
B(-1,5,-4,4)
B(-1,5,-3,4)
B(-1,5,-2,AIR)
B(-1,5,-1,AIR)
B(-1,5,0,AIR)
B(-1,5,1,AIR)
B(-1,5,2,AIR)
B(-1,5,3,4)
B(-1,5,4,4)
B(-1,5,5,4)
B(-1,5,6,48)
B(-1,6,-5,106:1)
B(-1,6,-4,4)
B(-1,6,-3,48)
B(-1,6,-2,4)
B(-1,6,-1,48)
B(-1,6,0,48)
B(-1,6,1,4)
B(-1,6,2,48)
B(-1,6,3,48)
B(-1,6,4,48)
B(-1,7,-3,4)
B(-1,7,-2,4)
B(-1,7,-1,48)
B(-1,7,0,48)
B(-1,7,1,48)
B(-1,7,2,4)
B(-1,7,3,4)
B(-1,8,-3,48)
B(-1,8,3,48)
B(0,-5,-7,48)
B(0,-5,-6,48)
B(0,-5,-5,4)
B(0,-5,-4,48)
B(0,-5,-3,4)
B(0,-5,-2,48)
B(0,-5,-1,48)
B(0,-5,0,48)
B(0,-5,1,48)
B(0,-5,2,48)
B(0,-5,3,48)
B(0,-5,4,48)
B(0,-5,5,48)
B(0,-5,6,48)
B(0,-5,7,4)
B(0,-4,-7,48)
B(0,-4,-6,AIR)
B(0,-4,-5,AIR)
B(0,-4,-4,48)
B(0,-4,-3,48)
B(0,-4,-2,48)
B(0,-4,-1,4)
B(0,-4,0,48)
B(0,-4,1,55)
B(0,-4,2,48)
B(0,-4,3,AIR)
RB(0,-4,4,CHEST,../../nbt/VanillaLoot/jungle_temple.nbt,50,CHEST,../../nbt/VanillaLoot/desert_pyramid.nbt,100)
B(0,-4,5,AIR)
B(0,-4,6,48)
B(0,-4,7,4)
B(0,-3,-7,48)
B(0,-3,-6,AIR)
B(0,-3,-5,69:4)
B(0,-3,-4,98:3)
B(0,-3,-3,55)
B(0,-3,-2,55)
B(0,-3,-1,AIR)
B(0,-3,0,48)
B(0,-3,1,4)
B(0,-3,2,AIR)
B(0,-3,3,AIR)
B(0,-3,4,106:14)
B(0,-3,5,AIR)
B(0,-3,6,48)
B(0,-3,7,48)
B(0,-2,-7,48)
B(0,-2,-6,AIR)
B(0,-2,-5,AIR)
B(0,-2,-4,4)
B(0,-2,-3,AIR)
B(0,-2,-2,AIR)
B(0,-2,-1,AIR)
B(0,-2,0,48)
B(0,-2,1,48)
B(0,-2,2,AIR)
B(0,-2,3,AIR)
B(0,-2,4,106:12)
B(0,-2,5,AIR)
B(0,-2,6,AIR)
B(0,-2,7,4)
B(0,-1,-7,48)
B(0,-1,-6,48)
B(0,-1,-5,4)
B(0,-1,-4,4)
B(0,-1,-3,48)
B(0,-1,-2,4)
B(0,-1,-1,48)
B(0,-1,0,48)
B(0,-1,1,48)
B(0,-1,2,4)
B(0,-1,3,48)
B(0,-1,4,4)
B(0,-1,5,4)
B(0,-1,6,4)
B(0,-1,7,48)
B(0,0,-5,48)
B(0,0,-4,AIR)
B(0,0,-3,AIR)
B(0,0,-2,AIR)
B(0,0,-1,106:8)
B(0,0,0,AIR)
B(0,0,1,AIR)
B(0,0,2,AIR)
B(0,0,3,AIR)
B(0,0,4,AIR)
B(0,0,5,4)
B(0,1,-5,48)
B(0,1,-4,AIR)
B(0,1,-3,AIR)
B(0,1,-2,AIR)
B(0,1,-1,106:8)
B(0,1,0,AIR)
B(0,1,1,AIR)
B(0,1,2,AIR)
B(0,1,3,AIR)
B(0,1,4,AIR)
B(0,1,5,48)
B(0,2,-6,4)
B(0,2,-5,48)
B(0,2,-4,48)
B(0,2,-3,48)
B(0,2,-2,48)
B(0,2,-1,48)
B(0,2,0,48)
B(0,2,1,4)
B(0,2,2,4)
B(0,2,3,4)
B(0,2,4,4)
B(0,2,5,48)
B(0,2,6,48)
B(0,3,-6,4)
B(0,3,-5,AIR)
B(0,3,-4,AIR)
B(0,3,-3,AIR)
B(0,3,-2,AIR)
B(0,3,-1,AIR)
B(0,3,0,AIR)
B(0,3,1,AIR)
B(0,3,2,AIR)
B(0,3,3,AIR)
B(0,3,4,AIR)
B(0,3,5,AIR)
B(0,3,6,48)
B(0,4,-7,106:1)
B(0,4,-6,48)
B(0,4,-5,AIR)
B(0,4,-4,AIR)
B(0,4,-3,AIR)
B(0,4,-2,AIR)
B(0,4,-1,AIR)
B(0,4,0,AIR)
B(0,4,1,AIR)
B(0,4,2,AIR)
B(0,4,3,AIR)
B(0,4,4,AIR)
B(0,4,5,AIR)
B(0,4,6,48)
B(0,5,-7,106:1)
B(0,5,-6,48)
B(0,5,-5,48)
B(0,5,-4,48)
B(0,5,-3,48)
B(0,5,-2,4)
B(0,5,-1,48)
B(0,5,0,48)
B(0,5,1,4)
B(0,5,2,4)
B(0,5,3,4)
B(0,5,4,48)
B(0,5,5,48)
B(0,5,6,48)
B(0,6,-4,48)
B(0,6,-3,4)
B(0,6,-2,4)
B(0,6,-1,48)
B(0,6,0,48)
B(0,6,1,48)
B(0,6,2,48)
B(0,6,3,48)
B(0,6,4,48)
B(0,7,3,106:2)
B(0,8,3,106:2)
B(1,-5,-7,48)
B(1,-5,-6,48)
B(1,-5,-5,48)
B(1,-5,-4,48)
B(1,-5,-3,48)
B(1,-5,-2,4)
B(1,-5,-1,48)
B(1,-5,0,48)
B(1,-5,1,48)
B(1,-5,2,48)
B(1,-5,3,48)
B(1,-5,4,4)
B(1,-5,5,48)
B(1,-5,6,48)
B(1,-5,7,48)
B(1,-4,-7,48)
B(1,-4,-6,AIR)
B(1,-4,-5,AIR)
B(1,-4,-4,48)
RB(1,-4,-3,CHEST,../../nbt/VanillaLoot/desert_pyramid.nbt,50,CHEST,../../nbt/VanillaLoot/jungle_temple.nbt,100)
B(1,-4,-2,AIR)
B(1,-4,-1,AIR)
B(1,-4,0,48)
B(1,-4,1,55)
B(1,-4,2,55)
B(1,-4,3,48)
B(1,-4,4,AIR)
B(1,-4,5,48)
B(1,-4,6,AIR)
B(1,-4,7,4)
B(1,-3,-7,48)
B(1,-3,-6,AIR)
B(1,-3,-5,69:4)
B(1,-3,-4,98:3)
B(1,-3,-3,106:4)
B(1,-3,-2,AIR)
B(1,-3,-1,29:1)
B(1,-3,0,4)
B(1,-3,1,48)
B(1,-3,2,AIR)
B(1,-3,3,55)
B(1,-3,4,23:4,../../nbt/Misc/ArrowTrap.nbt)
B(1,-3,5,AIR)
B(1,-3,6,48)
B(1,-3,7,48)
B(1,-2,-7,48)
B(1,-2,-6,50:3)
B(1,-2,-5,AIR)
B(1,-2,-4,4)
B(1,-2,-3,106:4)
B(1,-2,-2,AIR)
B(1,-2,-1,106:1)
B(1,-2,0,48)
B(1,-2,1,48)
B(1,-2,2,48)
B(1,-2,3,4)
B(1,-2,4,4)
B(1,-2,5,4)
B(1,-2,6,4)
B(1,-2,7,4)
B(1,-1,-7,48)
B(1,-1,-6,48)
B(1,-1,-5,48)
B(1,-1,-4,48)
B(1,-1,-3,4)
B(1,-1,-2,4)
B(1,-1,-1,48)
B(1,-1,0,4)
B(1,-1,1,4)
B(1,-1,2,4)
B(1,-1,3,4)
B(1,-1,4,48)
B(1,-1,5,4)
B(1,-1,6,48)
B(1,-1,7,4)
B(1,0,-5,48)
B(1,0,-4,4)
B(1,0,-3,48)
B(1,0,-2,48)
B(1,0,-1,48)
B(1,0,0,4)
B(1,0,1,4)
B(1,0,2,48)
B(1,0,3,48)
B(1,0,4,4)
B(1,0,5,4)
B(1,1,-5,48)
B(1,1,-4,4)
B(1,1,-3,48)
B(1,1,-2,4)
B(1,1,-1,4)
B(1,1,0,48)
B(1,1,1,48)
B(1,1,2,4)
B(1,1,3,4)
B(1,1,4,4)
B(1,1,5,48)
B(1,2,-6,48)
B(1,2,-5,48)
B(1,2,-4,4)
B(1,2,-3,48)
B(1,2,-2,48)
B(1,2,-1,48)
B(1,2,0,48)
B(1,2,1,48)
B(1,2,2,48)
B(1,2,3,4)
B(1,2,4,48)
B(1,2,5,48)
B(1,2,6,48)
B(1,3,-7,4)
B(1,3,-6,48)
B(1,3,-5,106:4)
B(1,3,-4,AIR)
B(1,3,-3,106:8)
B(1,3,-2,AIR)
B(1,3,-1,AIR)
B(1,3,0,AIR)
B(1,3,1,AIR)
B(1,3,2,AIR)
B(1,3,3,AIR)
B(1,3,4,AIR)
B(1,3,5,AIR)
B(1,3,6,4)
B(1,3,7,48)
B(1,4,-7,4)
B(1,4,-6,48)
B(1,4,-5,106:4)
B(1,4,-4,106:8)
B(1,4,-3,106:8)
B(1,4,-2,AIR)
B(1,4,-1,AIR)
B(1,4,0,AIR)
B(1,4,1,AIR)
B(1,4,2,AIR)
B(1,4,3,AIR)
B(1,4,4,AIR)
B(1,4,5,AIR)
B(1,4,6,48)
B(1,4,7,48)
B(1,5,-6,48)
B(1,5,-5,4)
B(1,5,-4,4)
B(1,5,-3,48)
B(1,5,-2,48)
B(1,5,-1,4)
B(1,5,0,48)
B(1,5,1,4)
B(1,5,2,48)
B(1,5,3,4)
B(1,5,4,4)
B(1,5,5,48)
B(1,5,6,48)
B(1,6,-5,48)
B(1,6,5,4)
B(1,7,-5,48)
B(1,7,5,48)
B(1,8,-5,48)
B(1,8,5,48)
B(2,-5,-7,48)
B(2,-5,-6,48)
B(2,-5,-5,4)
B(2,-5,-4,48)
B(2,-5,-3,48)
B(2,-5,-2,48)
B(2,-5,-1,48)
B(2,-5,0,4)
B(2,-5,1,48)
B(2,-5,2,4)
B(2,-5,3,48)
B(2,-5,4,4)
B(2,-5,5,48)
B(2,-5,6,4)
B(2,-5,7,48)
B(2,-4,-7,4)
B(2,-4,-6,AIR)
B(2,-4,-5,AIR)
B(2,-4,-4,48)
B(2,-4,-3,4)
B(2,-4,-2,48)
B(2,-4,-1,48)
B(2,-4,0,48)
B(2,-4,1,4)
B(2,-4,2,48)
B(2,-4,3,48)
B(2,-4,4,4)
B(2,-4,5,4)
B(2,-4,6,48)
B(2,-4,7,48)
B(2,-3,-7,48)
B(2,-3,-6,106:12)
B(2,-3,-5,69:4)
B(2,-3,-4,98:3)
B(2,-3,-3,93:2)
B(2,-3,-2,48)
B(2,-3,-1,29:4)
B(2,-3,0,48)
B(2,-3,1,4)
B(2,-3,2,48)
B(2,-3,3,4)
B(2,-3,4,4)
B(2,-3,5,4)
B(2,-3,6,48)
B(2,-3,7,48)
B(2,-2,-7,48)
B(2,-2,-6,106:4)
B(2,-2,-5,AIR)
B(2,-2,-4,48)
B(2,-2,-3,AIR)
B(2,-2,-2,55)
B(2,-2,-1,29:4)
B(2,-2,0,4)
B(2,-2,1,48)
B(2,-2,2,4)
B(2,-2,3,48)
B(2,-2,4,4)
B(2,-2,5,4)
B(2,-2,6,4)
B(2,-2,7,4)
B(2,-1,-7,48)
B(2,-1,-6,48)
B(2,-1,-5,48)
B(2,-1,-4,4)
B(2,-1,-3,4)
B(2,-1,-2,4)
B(2,-1,-1,48)
B(2,-1,0,48)
B(2,-1,1,48)
B(2,-1,2,4)
B(2,-1,3,4)
B(2,-1,4,4)
B(2,-1,5,48)
B(2,-1,6,48)
B(2,-1,7,48)
B(2,0,-5,106:2)
B(2,1,-5,106:2)
B(2,2,-6,4)
B(2,2,-5,4)
B(2,2,-4,4)
B(2,2,-3,48)
B(2,2,-2,4)
B(2,2,-1,48)
B(2,2,0,48)
B(2,2,1,4)
B(2,2,2,4)
B(2,2,3,4)
B(2,2,4,48)
B(2,2,5,48)
B(2,2,6,48)
B(2,3,-6,48)
B(2,3,-5,48)
B(2,3,-4,48)
B(2,3,-3,4)
B(2,3,-2,48)
B(2,3,-1,4)
B(2,3,0,48)
B(2,3,1,4)
B(2,3,2,48)
B(2,3,3,4)
B(2,3,4,48)
B(2,3,5,4)
B(2,3,6,48)
B(2,4,-6,4)
B(2,4,-5,48)
B(2,4,-4,48)
B(2,4,-3,48)
B(2,4,-2,106:1)
B(2,4,-1,4)
B(2,4,0,48)
B(2,4,1,48)
B(2,4,2,AIR)
B(2,4,3,48)
B(2,4,4,48)
B(2,4,5,48)
B(2,4,6,48)
B(2,5,-6,4)
B(2,5,-5,48)
B(2,5,-4,48)
B(2,5,-3,48)
B(2,5,-2,48)
B(2,5,-1,48)
B(2,5,0,4)
B(2,5,1,48)
B(2,5,2,4)
B(2,5,3,4)
B(2,5,4,4)
B(2,5,5,48)
B(2,5,6,4)
B(3,-5,-7,48)
B(3,-5,-6,4)
B(3,-5,-5,48)
B(3,-5,-4,48)
B(3,-5,-3,48)
B(3,-5,-2,4)
B(3,-5,-1,48)
B(3,-5,0,48)
B(3,-5,1,48)
B(3,-5,2,48)
B(3,-5,3,4)
B(3,-5,4,4)
B(3,-5,5,48)
B(3,-5,6,4)
B(3,-5,7,48)
B(3,-4,-7,4)
B(3,-4,-6,48)
B(3,-4,-5,48)
B(3,-4,-4,48)
B(3,-4,-3,48)
B(3,-4,-2,4)
B(3,-4,-1,48)
B(3,-4,0,4)
B(3,-4,1,48)
B(3,-4,2,48)
B(3,-4,3,4)
B(3,-4,4,48)
B(3,-4,5,48)
B(3,-4,6,48)
B(3,-4,7,4)
B(3,-3,-7,4)
B(3,-3,-6,4)
B(3,-3,-5,48)
B(3,-3,-4,48)
B(3,-3,-3,48)
B(3,-3,-2,48)
B(3,-3,-1,48)
B(3,-3,0,4)
B(3,-3,1,4)
B(3,-3,2,4)
B(3,-3,3,48)
B(3,-3,4,48)
B(3,-3,5,48)
B(3,-3,6,4)
B(3,-3,7,48)
B(3,-2,-7,48)
B(3,-2,-6,4)
B(3,-2,-5,4)
B(3,-2,-4,4)
B(3,-2,-3,4)
B(3,-2,-2,48)
B(3,-2,-1,48)
B(3,-2,0,48)
B(3,-2,1,4)
B(3,-2,2,48)
B(3,-2,3,48)
B(3,-2,4,48)
B(3,-2,5,48)
B(3,-2,6,48)
B(3,-2,7,48)
B(3,-1,-7,48)
B(3,-1,-6,4)
B(3,-1,-5,48)
B(3,-1,-4,48)
B(3,-1,-3,48)
B(3,-1,-2,4)
B(3,-1,-1,48)
B(3,-1,0,48)
B(3,-1,1,48)
B(3,-1,2,48)
B(3,-1,3,4)
B(3,-1,4,48)
B(3,-1,5,4)
B(3,-1,6,48)
B(3,-1,7,4)
B(3,1,-6,106:1)
B(3,2,-6,106:1)
B(3,2,-2,106:1)
B(3,3,-6,106:1)
B(3,3,-5,48)
B(3,3,-3,48)
B(3,3,-2,106:1)
B(3,3,-1,48)
B(3,3,1,48)
B(3,3,3,4)
B(3,3,5,4)
B(3,4,-6,106:1)
B(3,4,-5,48)
B(3,4,-3,48)
B(3,4,-2,106:1)
B(3,4,-1,48)
B(3,4,1,48)
B(3,4,3,4)
B(3,4,5,48)
B(3,5,-6,106:2)
B(3,5,-2,48)
B(3,5,2,48)


#######################################################################
# +-----------------------------------------------------------------+ #
# |                            BO3 checks                           | #
# +-----------------------------------------------------------------+ #
#######################################################################

# Require a condition at a certain location in order for the BO3 to be spawned.
# BlockCheck(x,y,z,BlockName[,BlockName[,...]]) - one of the blocks must be at the location
# BlockCheckNot(x,y,z,BlockName[,BlockName[,...]]) - all the blocks must not be at the location
# LightCheck(x,y,z,minLightLevel,maxLightLevel) - light must be between min and max (inclusive)

# You can use "Solid" as a BlockName for matching all solid blocks or "All" to match all blocks that aren't air.

# Examples:
#   BlockCheck(0,-1,0,GRASS,DIRT)  Require grass or dirt just below the object
#   BlockCheck(0,-1,0,Solid)       Require any solid block just below the object
#   BlockCheck(0,-1,0,WOOL)        Require any type of wool just below the object
#   BlockCheck(0,-1,0,WOOL:0)      Require white wool just below the object
#   BlockCheckNot(0,-1,0,WOOL:0)   Require that there is no white wool below the object
#   LightCheck(0,0,0,0,1)          Require almost complete darkness just below the object

#######################################################################
# +-----------------------------------------------------------------+ #
# |                             Branches                            | #
# +-----------------------------------------------------------------+ #
#######################################################################

# Branches are objects that will spawn when this object spawns when it is used in
# the CustomStructure resource. Branches can also have branches, making complex
# structures possible. See the wiki for more details.

# Regular Branches spawn each branch with an independent chance of spawning.
# Branch(x,y,z,branchName,rotation,chance[,anotherBranchName,rotation,chance[,...]][IndividualChance])
# branchName - name of the object to spawn.
# rotation - NORTH, SOUTH, EAST or WEST.
# IndividualChance - The chance each branch has to spawn, assumed to be 100 when left blank

# WBR(x,y,z,branchName,rotation,chance[,anotherBranchName,rotation,chance[,...]][MaxChanceOutOf])
# MaxChanceOutOf - The chance all branches have to spawn out of, assumed to be 100 when left blank
