
#######################################################################
# +-----------------------------------------------------------------+ #
# |                            BO3 object                           | #
# +-----------------------------------------------------------------+ #
#######################################################################

# This is the config file of a custom object.
# If you add this object correctly to your BiomeConfigs, it will spawn in the world.

# This is the creator of this BO3 object
Author: LordSmellyPants

# A short description of this BO3 object
Description: No description given

# The BO3 version, don't change this! It can be used by external applications to do a version check.
Version: 3

# The settings mode, WriteAll, WriteWithoutComments or WriteDisable. See WorldConfig.
SettingsMode: WriteDisable


#######################################################################
# +-----------------------------------------------------------------+ #
# |                          Main settings                          | #
# +-----------------------------------------------------------------+ #
#######################################################################

# This needs to be set to true to spawn the object in the Tree and Sapling resources.
Tree: false

# The frequency of the BO3 from 1 to 200. Tries this many times to spawn this BO3 when using the CustomObject(...) resource.
# Ignored by Tree(..), Sapling(..) and CustomStructure(..)
Frequency: 1

# The rarity of the BO3 from 0 to 100. Each spawn attempt has rarity% chance to succeed when using the CustomObject(...) resource.
# Ignored by Tree(..), Sapling(..) and CustomStructure(..)
Rarity: 0.06

# If you set this to true, the BO3 will be placed with a random rotation.
RotateRandomly: true

# The spawn height of the BO3 - randomY, highestBlock or highestSolidBlock.
SpawnHeight: highestSolidBlock

# The height limits for the BO3.
MinHeight: 0

MaxHeight: 256

# Objects can have other objects attacthed to it: branches. Branches can also
# have branches attached to it, which can also have branches, etc. This is the
# maximum branch depth for this objects.
MaxBranchDepth: 10

# When spawned with the UseWorld keyword, this BO3 should NOT spawn in the following biomes.
# If you writer.write the BO3 name directly in the BiomeConfigs, this will be ignored.
ExcludedBiomes: All


#######################################################################
# +-----------------------------------------------------------------+ #
# |                      Source block settings                      | #
# +-----------------------------------------------------------------+ #
#######################################################################

# The block(s) the BO3 should spawn in.
SourceBlocks: STONE:1,STONE:3,STONE:5,DIRT:1,DIRT,SAND,GRASS,DIRT:2,HARD_CLAY,STAINED_CLAY,CLAY,SANDSTONE,RED_SANDSTONE,SAND:1,AIR,STONE,GRAVEL,LONG_GRASS,LONG_GRASS:1,LONG_GRASS:2,DEAD_BUSH,YELLOW_FLOWER,RED_ROSE,BROWN_MUSHROOM,RED_MUSHROOM,RED_ROSE:1,RED_ROSE:2,RED_ROSE:3,RED_ROSE:4,RED_ROSE:5,RED_ROSE:6,RED_ROSE:7,RED_ROSE:8,DOUBLE_PLANT,DOUBLE_PLANT:1,DOUBLE_PLANT:2,DOUBLE_PLANT:3,DOUBLE_PLANT:4,DOUBLE_PLANT:5,IRON_ORE,GOLD_ORE,LAPIS_ORE,COAL_ORE,DIAMOND_ORE,REDSTONE_ORE,EMERALD_ORE,STATIONARY_WATER

# The maximum percentage of the BO3 that can be outside the SourceBlock.
# The BO3 won't be placed on a location with more blocks outside the SourceBlock than this percentage.
MaxPercentageOutsideSourceBlock: 15

# What to do when a block is about to be placed outside the SourceBlock? (dontPlace, placeAnyway)
OutsideSourceBlock: placeAnyway


#######################################################################
# +-----------------------------------------------------------------+ #
# |                              Blocks                             | #
# +-----------------------------------------------------------------+ #
#######################################################################

# All the blocks used in the BO3 are listed here. Possible blocks:
# Block(x,y,z,id[.data][,nbtfile.nbt)
# RandomBlock(x,y,z,id[:data][,nbtfile.nbt],chance[,id[:data][,nbtfile.nbt],chance[,...]])
# So RandomBlock(0,0,0,CHEST,chest.nbt,50,CHEST,anotherchest.nbt,100) will spawn a chest at
# the BO3 origin, and give it a 50% chance to have the contents of chest.nbt, or, if that
# fails, a 100% percent chance to have the contents of anotherchest.nbt.
Block(-6,-10,-3,HARD_CLAY)
Block(-6,-10,-2,HARD_CLAY)
Block(-6,-10,-1,HARD_CLAY)
Block(-6,-10,0,HARD_CLAY)
Block(-6,-10,1,HARD_CLAY)
Block(-6,-10,2,HARD_CLAY)
Block(-6,-10,3,HARD_CLAY)
Block(-6,-10,4,HARD_CLAY)
Block(-6,-10,5,HARD_CLAY)
Block(-6,-10,6,HARD_CLAY)
Block(-6,-10,7,HARD_CLAY)
Block(-6,-10,8,HARD_CLAY)
Block(-6,-9,-3,HARD_CLAY)
Block(-6,-9,-2,HARD_CLAY)
Block(-6,-9,-1,HARD_CLAY)
Block(-6,-9,0,HARD_CLAY)
Block(-6,-9,1,HARD_CLAY)
Block(-6,-9,2,HARD_CLAY)
Block(-6,-9,3,HARD_CLAY)
Block(-6,-9,4,HARD_CLAY)
Block(-6,-9,5,HARD_CLAY)
Block(-6,-9,6,HARD_CLAY)
Block(-6,-9,7,HARD_CLAY)
Block(-6,-9,8,HARD_CLAY)
Block(-6,-8,-3,HARD_CLAY)
Block(-6,-8,-2,HARD_CLAY)
Block(-6,-8,-1,HARD_CLAY)
Block(-6,-8,0,HARD_CLAY)
Block(-6,-8,1,HARD_CLAY)
Block(-6,-8,2,HARD_CLAY)
Block(-6,-8,3,HARD_CLAY)
Block(-6,-8,4,HARD_CLAY)
Block(-6,-8,5,HARD_CLAY)
Block(-6,-8,6,HARD_CLAY)
Block(-6,-8,7,HARD_CLAY)
Block(-6,-8,8,HARD_CLAY)
Block(-6,-7,-3,HARD_CLAY)
Block(-6,-7,-2,HARD_CLAY)
Block(-6,-7,-1,HARD_CLAY)
Block(-6,-7,0,HARD_CLAY)
Block(-6,-7,1,HARD_CLAY)
Block(-6,-7,2,HARD_CLAY)
Block(-6,-7,3,HARD_CLAY)
Block(-6,-7,4,HARD_CLAY)
Block(-6,-7,5,HARD_CLAY)
Block(-6,-7,6,HARD_CLAY)
Block(-6,-7,7,HARD_CLAY)
Block(-6,-7,8,HARD_CLAY)
Block(-6,-6,-3,HARD_CLAY)
Block(-6,-6,-2,HARD_CLAY)
Block(-6,-6,-1,HARD_CLAY)
Block(-6,-6,0,HARD_CLAY)
Block(-6,-6,1,HARD_CLAY)
Block(-6,-6,2,HARD_CLAY)
Block(-6,-6,3,HARD_CLAY)
Block(-6,-6,4,HARD_CLAY)
Block(-6,-6,5,HARD_CLAY)
Block(-6,-6,6,HARD_CLAY)
Block(-6,-6,7,HARD_CLAY)
Block(-6,-6,8,HARD_CLAY)
Block(-6,-5,-3,HARD_CLAY)
Block(-6,-5,-2,HARD_CLAY)
Block(-6,-5,-1,HARD_CLAY)
Block(-6,-5,0,HARD_CLAY)
Block(-6,-5,1,HARD_CLAY)
Block(-6,-5,2,HARD_CLAY)
Block(-6,-5,3,HARD_CLAY)
Block(-6,-5,4,HARD_CLAY)
Block(-6,-5,5,HARD_CLAY)
Block(-6,-5,6,HARD_CLAY)
Block(-6,-5,7,HARD_CLAY)
Block(-6,-5,8,HARD_CLAY)
Block(-6,-4,-3,HARD_CLAY)
Block(-6,-4,-2,HARD_CLAY)
Block(-6,-4,-1,HARD_CLAY)
Block(-6,-4,0,HARD_CLAY)
Block(-6,-4,1,HARD_CLAY)
Block(-6,-4,2,HARD_CLAY)
Block(-6,-4,3,HARD_CLAY)
Block(-6,-4,4,HARD_CLAY)
Block(-6,-4,5,HARD_CLAY)
Block(-6,-4,6,HARD_CLAY)
Block(-6,-4,7,HARD_CLAY)
Block(-6,-4,8,HARD_CLAY)
Block(-6,-3,-3,HARD_CLAY)
Block(-6,-3,-2,HARD_CLAY)
Block(-6,-3,-1,HARD_CLAY)
Block(-6,-3,0,HARD_CLAY)
Block(-6,-3,1,HARD_CLAY)
Block(-6,-3,2,HARD_CLAY)
Block(-6,-3,3,HARD_CLAY)
Block(-6,-3,4,HARD_CLAY)
Block(-6,-3,5,HARD_CLAY)
Block(-6,-3,6,HARD_CLAY)
Block(-6,-3,7,HARD_CLAY)
Block(-6,-3,8,HARD_CLAY)
Block(-6,-2,-3,HARD_CLAY)
Block(-6,-2,-2,HARD_CLAY)
Block(-6,-2,-1,HARD_CLAY)
Block(-6,-2,0,HARD_CLAY)
Block(-6,-2,1,HARD_CLAY)
Block(-6,-2,2,HARD_CLAY)
Block(-6,-2,3,HARD_CLAY)
Block(-6,-2,4,HARD_CLAY)
Block(-6,-2,5,HARD_CLAY)
Block(-6,-2,6,HARD_CLAY)
Block(-6,-2,7,HARD_CLAY)
Block(-6,-2,8,HARD_CLAY)
Block(-6,-1,-3,HARD_CLAY)
Block(-6,-1,-2,HARD_CLAY)
Block(-6,-1,-1,HARD_CLAY)
Block(-6,-1,0,HARD_CLAY)
Block(-6,-1,1,HARD_CLAY)
Block(-6,-1,2,HARD_CLAY)
Block(-6,-1,3,HARD_CLAY)
Block(-6,-1,4,HARD_CLAY)
Block(-6,-1,5,HARD_CLAY)
Block(-6,-1,6,HARD_CLAY)
Block(-6,-1,7,HARD_CLAY)
Block(-6,-1,8,HARD_CLAY)
Block(-6,0,-1,STAINED_CLAY:1)
Block(-6,0,2,STAINED_CLAY:1)
Block(-6,0,3,STAINED_CLAY:1)
Block(-6,0,6,STAINED_CLAY:1)
Block(-6,1,-1,STAINED_CLAY:1)
Block(-6,1,2,STAINED_CLAY:6)
Block(-6,1,3,STAINED_CLAY:6)
Block(-6,1,6,STAINED_CLAY:1)
Block(-6,2,-1,STAINED_CLAY:1)
Block(-6,2,2,STAINED_CLAY:1)
Block(-6,2,3,STAINED_CLAY:1)
Block(-6,2,6,STAINED_CLAY:1)
Block(-5,-10,-4,HARD_CLAY)
Block(-5,-10,-3,HARD_CLAY)
Block(-5,-10,-2,STAINED_CLAY:1)
Block(-5,-10,-1,STAINED_CLAY:1)
Block(-5,-10,0,STAINED_CLAY:1)
Block(-5,-10,1,STAINED_CLAY:1)
Block(-5,-10,2,STAINED_CLAY:1)
Block(-5,-10,3,STAINED_CLAY:1)
Block(-5,-10,4,STAINED_CLAY:1)
Block(-5,-10,5,STAINED_CLAY:1)
Block(-5,-10,6,STAINED_CLAY:1)
Block(-5,-10,7,STAINED_CLAY:1)
Block(-5,-10,8,HARD_CLAY)
Block(-5,-10,9,HARD_CLAY)
Block(-5,-9,-4,HARD_CLAY)
Block(-5,-9,-3,HARD_CLAY)
Block(-5,-9,-2,STAINED_CLAY:1)
Block(-5,-9,-1,STAINED_CLAY:1)
Block(-5,-9,0,STAINED_CLAY:1)
Block(-5,-9,1,STAINED_CLAY:1)
Block(-5,-9,2,STAINED_CLAY:6)
Block(-5,-9,3,STAINED_CLAY:6)
Block(-5,-9,4,STAINED_CLAY:1)
Block(-5,-9,5,STAINED_CLAY:1)
Block(-5,-9,6,STAINED_CLAY:1)
Block(-5,-9,7,STAINED_CLAY:1)
Block(-5,-9,8,HARD_CLAY)
Block(-5,-9,9,HARD_CLAY)
Block(-5,-8,-4,HARD_CLAY)
Block(-5,-8,-3,HARD_CLAY)
Block(-5,-8,-2,STAINED_CLAY:1)
Block(-5,-8,-1,STAINED_CLAY:1)
Block(-5,-8,0,STAINED_CLAY:1)
Block(-5,-8,1,STAINED_CLAY:1)
Block(-5,-8,2,STAINED_CLAY:6)
Block(-5,-8,3,STAINED_CLAY:6)
Block(-5,-8,4,STAINED_CLAY:1)
Block(-5,-8,5,STAINED_CLAY:1)
Block(-5,-8,6,STAINED_CLAY:1)
Block(-5,-8,7,STAINED_CLAY:1)
Block(-5,-8,8,HARD_CLAY)
Block(-5,-8,9,HARD_CLAY)
Block(-5,-7,-4,HARD_CLAY)
Block(-5,-7,-3,HARD_CLAY)
Block(-5,-7,-2,STAINED_CLAY:1)
Block(-5,-7,-1,STAINED_CLAY:1)
Block(-5,-7,0,STAINED_CLAY:1)
Block(-5,-7,1,STAINED_CLAY:1)
Block(-5,-7,2,STAINED_CLAY:1)
Block(-5,-7,3,STAINED_CLAY:1)
Block(-5,-7,4,STAINED_CLAY:1)
Block(-5,-7,5,STAINED_CLAY:1)
Block(-5,-7,6,STAINED_CLAY:1)
Block(-5,-7,7,STAINED_CLAY:1)
Block(-5,-7,8,HARD_CLAY)
Block(-5,-7,9,HARD_CLAY)
Block(-5,-6,-4,HARD_CLAY)
Block(-5,-6,-3,HARD_CLAY)
Block(-5,-6,-2,STAINED_CLAY:1)
Block(-5,-6,-1,STAINED_CLAY:1)
Block(-5,-6,0,STAINED_CLAY:1)
Block(-5,-6,1,STAINED_CLAY:1)
Block(-5,-6,2,STAINED_CLAY:1)
Block(-5,-6,3,STAINED_CLAY:1)
Block(-5,-6,4,STAINED_CLAY:1)
Block(-5,-6,5,STAINED_CLAY:1)
Block(-5,-6,6,STAINED_CLAY:1)
Block(-5,-6,7,STAINED_CLAY:1)
Block(-5,-6,8,HARD_CLAY)
Block(-5,-6,9,HARD_CLAY)
Block(-5,-5,-4,HARD_CLAY)
Block(-5,-5,-3,HARD_CLAY)
Block(-5,-5,-2,STAINED_CLAY:1)
Block(-5,-5,-1,STAINED_CLAY:1)
Block(-5,-5,0,STAINED_CLAY:1)
Block(-5,-5,1,STAINED_CLAY:1)
Block(-5,-5,2,STAINED_CLAY:1)
Block(-5,-5,3,STAINED_CLAY:1)
Block(-5,-5,4,STAINED_CLAY:1)
Block(-5,-5,5,STAINED_CLAY:1)
Block(-5,-5,6,STAINED_CLAY:1)
Block(-5,-5,7,STAINED_CLAY:1)
Block(-5,-5,8,HARD_CLAY)
Block(-5,-5,9,HARD_CLAY)
Block(-5,-4,-4,HARD_CLAY)
Block(-5,-4,-3,HARD_CLAY)
Block(-5,-4,-2,HARD_CLAY)
Block(-5,-4,-1,STAINED_CLAY:1)
Block(-5,-4,0,STAINED_CLAY:1)
Block(-5,-4,1,STAINED_CLAY:1)
Block(-5,-4,2,STAINED_CLAY:1)
Block(-5,-4,3,STAINED_CLAY:1)
Block(-5,-4,4,STAINED_CLAY:1)
Block(-5,-4,5,STAINED_CLAY:1)
Block(-5,-4,6,STAINED_CLAY:1)
Block(-5,-4,7,STAINED_CLAY:1)
Block(-5,-4,8,HARD_CLAY)
Block(-5,-4,9,HARD_CLAY)
Block(-5,-3,-4,HARD_CLAY)
Block(-5,-3,-3,HARD_CLAY)
Block(-5,-3,-2,STAINED_CLAY:1)
Block(-5,-3,-1,STAINED_CLAY:1)
Block(-5,-3,0,STAINED_CLAY:1)
Block(-5,-3,1,STAINED_CLAY:1)
Block(-5,-3,2,STAINED_CLAY:1)
Block(-5,-3,3,STAINED_CLAY:1)
Block(-5,-3,4,STAINED_CLAY:1)
Block(-5,-3,5,STAINED_CLAY:1)
Block(-5,-3,6,STAINED_CLAY:1)
Block(-5,-3,7,STAINED_CLAY:1)
Block(-5,-3,8,HARD_CLAY)
Block(-5,-3,9,HARD_CLAY)
Block(-5,-2,-4,HARD_CLAY)
Block(-5,-2,-3,HARD_CLAY)
Block(-5,-2,-2,STAINED_CLAY:1)
Block(-5,-2,-1,STAINED_CLAY:1)
Block(-5,-2,0,STAINED_CLAY:1)
Block(-5,-2,1,STAINED_CLAY:1)
Block(-5,-2,2,STAINED_CLAY:1)
Block(-5,-2,3,STAINED_CLAY:1)
Block(-5,-2,4,STAINED_CLAY:1)
Block(-5,-2,5,STAINED_CLAY:1)
Block(-5,-2,6,STAINED_CLAY:1)
Block(-5,-2,7,HARD_CLAY)
Block(-5,-2,8,HARD_CLAY)
Block(-5,-2,9,HARD_CLAY)
Block(-5,-1,-4,HARD_CLAY)
Block(-5,-1,-3,HARD_CLAY)
Block(-5,-1,-2,STAINED_CLAY:1)
Block(-5,-1,-1,STAINED_CLAY:1)
Block(-5,-1,0,STAINED_CLAY:1)
Block(-5,-1,1,STAINED_CLAY:1)
Block(-5,-1,2,STAINED_CLAY:1)
Block(-5,-1,3,STAINED_CLAY:1)
Block(-5,-1,4,STAINED_CLAY:1)
Block(-5,-1,5,STAINED_CLAY:1)
Block(-5,-1,6,STAINED_CLAY:1)
Block(-5,-1,7,STAINED_CLAY:1)
Block(-5,-1,8,HARD_CLAY)
Block(-5,-1,9,HARD_CLAY)
Block(-5,0,-2,STAINED_CLAY:1)
Block(-5,0,-1,STAINED_CLAY:1)
Block(-5,0,0,STAINED_CLAY:1)
Block(-5,0,1,STAINED_CLAY:1)
Block(-5,0,2,STAINED_CLAY:1)
Block(-5,0,3,STAINED_CLAY:1)
Block(-5,0,4,STAINED_CLAY:1)
Block(-5,0,5,STAINED_CLAY:1)
Block(-5,0,6,STAINED_CLAY:1)
Block(-5,0,7,STAINED_CLAY:1)
Block(-5,1,-2,STAINED_CLAY:1)
Block(-5,1,-1,STAINED_CLAY:1)
Block(-5,1,0,STAINED_CLAY:1)
Block(-5,1,1,STAINED_CLAY:1)
Block(-5,1,2,AIR)
Block(-5,1,3,AIR)
Block(-5,1,4,STAINED_CLAY:1)
Block(-5,1,5,STAINED_CLAY:1)
Block(-5,1,6,STAINED_CLAY:1)
Block(-5,1,7,STAINED_CLAY:1)
Block(-5,2,-2,STAINED_CLAY:1)
Block(-5,2,-1,STAINED_CLAY:1)
Block(-5,2,0,STAINED_CLAY:1)
Block(-5,2,1,STAINED_CLAY:1)
Block(-5,2,2,STAINED_CLAY:1)
Block(-5,2,3,STAINED_CLAY:1)
Block(-5,2,4,STAINED_CLAY:1)
Block(-5,2,5,STAINED_CLAY:1)
Block(-5,2,6,STAINED_CLAY:1)
Block(-5,2,7,STAINED_CLAY:1)
Block(-4,-10,-4,HARD_CLAY)
Block(-4,-10,-3,STAINED_CLAY:1)
Block(-4,-10,-2,STAINED_CLAY:1)
Block(-4,-10,-1,STAINED_CLAY:1)
Block(-4,-10,0,STAINED_CLAY:1)
Block(-4,-10,1,STAINED_CLAY:1)
Block(-4,-10,2,STAINED_CLAY:6)
Block(-4,-10,3,STAINED_CLAY:6)
Block(-4,-10,4,STAINED_CLAY:1)
Block(-4,-10,5,STAINED_CLAY:1)
Block(-4,-10,6,STAINED_CLAY:1)
Block(-4,-10,7,STAINED_CLAY:1)
Block(-4,-10,8,STAINED_CLAY:1)
Block(-4,-10,9,HARD_CLAY)
Block(-4,-9,-4,HARD_CLAY)
Block(-4,-9,-3,STAINED_CLAY:1)
Block(-4,-9,-2,STAINED_CLAY:1)
Block(-4,-9,-1,STAINED_CLAY:1)
Block(-4,-9,0,STAINED_CLAY:1)
Block(-4,-9,1,AIR)
Block(-4,-9,2,AIR)
Block(-4,-9,3,AIR)
Block(-4,-9,4,AIR)
Block(-4,-9,5,STAINED_CLAY:1)
Block(-4,-9,6,STAINED_CLAY:1)
Block(-4,-9,7,STAINED_CLAY:1)
Block(-4,-9,8,STAINED_CLAY:1)
Block(-4,-9,9,HARD_CLAY)
Block(-4,-8,-4,HARD_CLAY)
Block(-4,-8,-3,STAINED_CLAY:1)
Block(-4,-8,-2,STAINED_CLAY:1)
Block(-4,-8,-1,STAINED_CLAY:1)
Block(-4,-8,0,STAINED_CLAY:1)
Block(-4,-8,1,AIR)
Block(-4,-8,2,AIR)
Block(-4,-8,3,AIR)
Block(-4,-8,4,AIR)
Block(-4,-8,5,STAINED_CLAY:1)
Block(-4,-8,6,STAINED_CLAY:1)
Block(-4,-8,7,STAINED_CLAY:1)
Block(-4,-8,8,STAINED_CLAY:1)
Block(-4,-8,9,HARD_CLAY)
Block(-4,-7,-4,HARD_CLAY)
Block(-4,-7,-3,STAINED_CLAY:1)
Block(-4,-7,-2,STAINED_CLAY:1)
Block(-4,-7,-1,STAINED_CLAY:1)
Block(-4,-7,0,STAINED_CLAY:1)
Block(-4,-7,1,STAINED_CLAY:1)
Block(-4,-7,2,STAINED_CLAY:1)
Block(-4,-7,3,STAINED_CLAY:1)
Block(-4,-7,4,STAINED_CLAY:1)
Block(-4,-7,5,STAINED_CLAY:1)
Block(-4,-7,6,STAINED_CLAY:1)
Block(-4,-7,7,STAINED_CLAY:1)
Block(-4,-7,8,STAINED_CLAY:1)
Block(-4,-7,9,HARD_CLAY)
Block(-4,-6,-4,HARD_CLAY)
Block(-4,-6,-3,STAINED_CLAY:1)
Block(-4,-6,-2,STAINED_CLAY:1)
Block(-4,-6,-1,STAINED_CLAY:1)
Block(-4,-6,0,STAINED_CLAY:1)
Block(-4,-6,1,STAINED_CLAY:1)
Block(-4,-6,2,STAINED_CLAY:1)
Block(-4,-6,3,STAINED_CLAY:1)
Block(-4,-6,4,STAINED_CLAY:1)
Block(-4,-6,5,STAINED_CLAY:1)
Block(-4,-6,6,STAINED_CLAY:1)
Block(-4,-6,7,STAINED_CLAY:1)
Block(-4,-6,8,STAINED_CLAY:1)
Block(-4,-6,9,HARD_CLAY)
Block(-4,-5,-4,HARD_CLAY)
Block(-4,-5,-3,STAINED_CLAY:1)
Block(-4,-5,-2,STAINED_CLAY:1)
Block(-4,-5,-1,STAINED_CLAY:1)
Block(-4,-5,0,STAINED_CLAY:1)
Block(-4,-5,1,STAINED_CLAY:1)
Block(-4,-5,2,STAINED_CLAY:1)
Block(-4,-5,3,STAINED_CLAY:1)
Block(-4,-5,4,STAINED_CLAY:1)
Block(-4,-5,5,STAINED_CLAY:1)
Block(-4,-5,6,STAINED_CLAY:1)
Block(-4,-5,7,STAINED_CLAY:1)
Block(-4,-5,8,STAINED_CLAY:1)
Block(-4,-5,9,HARD_CLAY)
Block(-4,-4,-4,HARD_CLAY)
Block(-4,-4,-3,HARD_CLAY)
Block(-4,-4,-2,HARD_CLAY)
Block(-4,-4,-1,AIR)
Block(-4,-4,0,AIR)
Block(-4,-4,1,AIR)
Block(-4,-4,2,AIR)
Block(-4,-4,3,AIR)
Block(-4,-4,4,AIR)
Block(-4,-4,5,AIR)
Block(-4,-4,6,AIR)
Block(-4,-4,7,HARD_CLAY)
Block(-4,-4,8,STAINED_CLAY:1)
Block(-4,-4,9,HARD_CLAY)
Block(-4,-3,-4,HARD_CLAY)
Block(-4,-3,-3,HARD_CLAY)
Block(-4,-3,-2,HARD_CLAY)
Block(-4,-3,-1,AIR)
Block(-4,-3,0,AIR)
Block(-4,-3,1,AIR)
Block(-4,-3,2,AIR)
Block(-4,-3,3,AIR)
Block(-4,-3,4,AIR)
Block(-4,-3,5,AIR)
Block(-4,-3,6,AIR)
Block(-4,-3,7,HARD_CLAY)
Block(-4,-3,8,STAINED_CLAY:1)
Block(-4,-3,9,HARD_CLAY)
Block(-4,-2,-4,HARD_CLAY)
Block(-4,-2,-3,HARD_CLAY)
Block(-4,-2,-2,HARD_CLAY)
Block(-4,-2,-1,AIR)
Block(-4,-2,0,AIR)
Block(-4,-2,1,AIR)
Block(-4,-2,2,AIR)
Block(-4,-2,3,AIR)
Block(-4,-2,4,AIR)
Block(-4,-2,5,AIR)
Block(-4,-2,6,AIR)
Block(-4,-2,7,HARD_CLAY)
Block(-4,-2,8,HARD_CLAY)
Block(-4,-2,9,HARD_CLAY)
Block(-4,-1,-4,HARD_CLAY)
Block(-4,-1,-3,HARD_CLAY)
Block(-4,-1,-2,HARD_CLAY)
Block(-4,-1,-1,HARD_CLAY)
Block(-4,-1,0,HARD_CLAY)
Block(-4,-1,1,HARD_CLAY)
Block(-4,-1,2,HARD_CLAY)
Block(-4,-1,3,HARD_CLAY)
Block(-4,-1,4,HARD_CLAY)
Block(-4,-1,5,HARD_CLAY)
Block(-4,-1,6,HARD_CLAY)
Block(-4,-1,7,HARD_CLAY)
Block(-4,-1,8,STAINED_CLAY:1)
Block(-4,-1,9,HARD_CLAY)
Block(-4,0,-3,STAINED_CLAY:1)
Block(-4,0,-2,HARD_CLAY)
Block(-4,0,-1,AIR)
Block(-4,0,0,AIR)
Block(-4,0,1,AIR)
Block(-4,0,2,AIR)
Block(-4,0,3,AIR)
Block(-4,0,4,AIR)
Block(-4,0,5,AIR)
Block(-4,0,6,AIR)
Block(-4,0,7,HARD_CLAY)
Block(-4,0,8,STAINED_CLAY:1)
Block(-4,1,-3,STAINED_CLAY:1)
Block(-4,1,-2,HARD_CLAY)
Block(-4,1,-1,AIR)
Block(-4,1,0,AIR)
Block(-4,1,1,AIR)
Block(-4,1,2,AIR)
Block(-4,1,3,AIR)
Block(-4,1,4,AIR)
Block(-4,1,5,AIR)
Block(-4,1,6,AIR)
Block(-4,1,7,HARD_CLAY)
Block(-4,1,8,STAINED_CLAY:1)
Block(-4,2,-3,STAINED_CLAY:1)
Block(-4,2,-2,HARD_CLAY)
Block(-4,2,-1,HARD_CLAY)
Block(-4,2,0,AIR)
Block(-4,2,1,AIR)
Block(-4,2,2,AIR)
Block(-4,2,3,AIR)
Block(-4,2,4,AIR)
Block(-4,2,5,AIR)
Block(-4,2,6,HARD_CLAY)
Block(-4,2,7,HARD_CLAY)
Block(-4,2,8,STAINED_CLAY:1)
Block(-4,3,-2,STAINED_CLAY:1)
Block(-4,3,-1,HARD_CLAY)
Block(-4,3,0,HARD_CLAY)
Block(-4,3,1,HARD_CLAY)
Block(-4,3,2,HARD_CLAY)
Block(-4,3,3,HARD_CLAY)
Block(-4,3,4,HARD_CLAY)
Block(-4,3,5,HARD_CLAY)
Block(-4,3,6,HARD_CLAY)
Block(-4,3,7,STAINED_CLAY:1)
Block(-4,6,-1,STAINED_CLAY:1)
Block(-4,6,0,STAINED_CLAY:1)
Block(-4,6,1,STAINED_CLAY:1)
Block(-4,6,2,STAINED_CLAY:1)
Block(-4,6,3,STAINED_CLAY:1)
Block(-4,6,4,STAINED_CLAY:1)
Block(-4,6,5,STAINED_CLAY:1)
Block(-4,6,6,STAINED_CLAY:1)
Block(-3,-10,-4,HARD_CLAY)
Block(-3,-10,-3,STAINED_CLAY:1)
Block(-3,-10,-2,STAINED_CLAY:1)
Block(-3,-10,-1,STAINED_CLAY:1)
Block(-3,-10,0,STAINED_CLAY:1)
Block(-3,-10,1,STAINED_CLAY:1)
Block(-3,-10,2,STAINED_CLAY:6)
Block(-3,-10,3,STAINED_CLAY:6)
Block(-3,-10,4,STAINED_CLAY:1)
Block(-3,-10,5,STAINED_CLAY:1)
Block(-3,-10,6,STAINED_CLAY:1)
Block(-3,-10,7,STAINED_CLAY:1)
Block(-3,-10,8,STAINED_CLAY:1)
Block(-3,-10,9,HARD_CLAY)
Block(-3,-9,-4,HARD_CLAY)
Block(-3,-9,-3,STAINED_CLAY:1)
Block(-3,-9,-2,STAINED_CLAY:1)
Block(-3,-9,-1,STAINED_CLAY:1)
Block(-3,-9,0,STAINED_CLAY:1)
Block(-3,-9,1,STAINED_CLAY:1)
Block(-3,-9,2,AIR)
Block(-3,-9,3,AIR)
Block(-3,-9,4,STAINED_CLAY:1)
Block(-3,-9,5,STAINED_CLAY:1)
Block(-3,-9,6,STAINED_CLAY:1)
Block(-3,-9,7,STAINED_CLAY:1)
Block(-3,-9,8,STAINED_CLAY:1)
Block(-3,-9,9,HARD_CLAY)
Block(-3,-8,-4,HARD_CLAY)
Block(-3,-8,-3,STAINED_CLAY:1)
Block(-3,-8,-2,STAINED_CLAY:1)
Block(-3,-8,-1,STAINED_CLAY:1)
Block(-3,-8,0,STAINED_CLAY:1)
Block(-3,-8,1,STAINED_CLAY:1)
Block(-3,-8,2,AIR)
Block(-3,-8,3,AIR)
Block(-3,-8,4,STAINED_CLAY:1)
Block(-3,-8,5,STAINED_CLAY:1)
Block(-3,-8,6,STAINED_CLAY:1)
Block(-3,-8,7,STAINED_CLAY:1)
Block(-3,-8,8,STAINED_CLAY:1)
Block(-3,-8,9,HARD_CLAY)
Block(-3,-7,-4,HARD_CLAY)
Block(-3,-7,-3,STAINED_CLAY:1)
Block(-3,-7,-2,STAINED_CLAY:1)
Block(-3,-7,-1,STAINED_CLAY:1)
Block(-3,-7,0,STAINED_CLAY:1)
Block(-3,-7,1,STAINED_CLAY:1)
Block(-3,-7,2,STAINED_CLAY:1)
Block(-3,-7,3,STAINED_CLAY:1)
Block(-3,-7,4,STAINED_CLAY:1)
Block(-3,-7,5,STAINED_CLAY:1)
Block(-3,-7,6,STAINED_CLAY:1)
Block(-3,-7,7,STAINED_CLAY:1)
Block(-3,-7,8,STAINED_CLAY:1)
Block(-3,-7,9,HARD_CLAY)
Block(-3,-6,-4,HARD_CLAY)
Block(-3,-6,-3,STAINED_CLAY:1)
Block(-3,-6,-2,STAINED_CLAY:1)
Block(-3,-6,-1,STAINED_CLAY:1)
Block(-3,-6,0,STAINED_CLAY:1)
Block(-3,-6,1,STAINED_CLAY:1)
Block(-3,-6,2,STAINED_CLAY:1)
Block(-3,-6,3,STAINED_CLAY:1)
Block(-3,-6,4,STAINED_CLAY:1)
Block(-3,-6,5,STAINED_CLAY:1)
Block(-3,-6,6,STAINED_CLAY:1)
Block(-3,-6,7,STAINED_CLAY:1)
Block(-3,-6,8,STAINED_CLAY:1)
Block(-3,-6,9,HARD_CLAY)
Block(-3,-5,-4,HARD_CLAY)
Block(-3,-5,-3,STAINED_CLAY:1)
Block(-3,-5,-2,STAINED_CLAY:1)
Block(-3,-5,-1,STAINED_CLAY:1)
Block(-3,-5,0,STAINED_CLAY:1)
Block(-3,-5,1,STAINED_CLAY:1)
Block(-3,-5,2,STAINED_CLAY:1)
Block(-3,-5,3,STAINED_CLAY:1)
Block(-3,-5,4,STAINED_CLAY:1)
Block(-3,-5,5,STAINED_CLAY:1)
Block(-3,-5,6,STAINED_CLAY:1)
Block(-3,-5,7,STAINED_CLAY:1)
Block(-3,-5,8,STAINED_CLAY:1)
Block(-3,-5,9,HARD_CLAY)
Block(-3,-4,-4,HARD_CLAY)
Block(-3,-4,-3,STAINED_CLAY:1)
Block(-3,-4,-2,AIR)
Block(-3,-4,-1,AIR)
Block(-3,-4,0,AIR)
Block(-3,-4,1,AIR)
Block(-3,-4,2,AIR)
Block(-3,-4,3,AIR)
Block(-3,-4,4,AIR)
Block(-3,-4,5,AIR)
Block(-3,-4,6,AIR)
Block(-3,-4,7,AIR)
Block(-3,-4,8,STAINED_CLAY:1)
Block(-3,-4,9,HARD_CLAY)
Block(-3,-3,-4,HARD_CLAY)
Block(-3,-3,-3,STAINED_CLAY:1)
Block(-3,-3,-2,AIR)
Block(-3,-3,-1,AIR)
Block(-3,-3,0,AIR)
Block(-3,-3,1,AIR)
Block(-3,-3,2,AIR)
Block(-3,-3,3,AIR)
Block(-3,-3,4,AIR)
Block(-3,-3,5,AIR)
Block(-3,-3,6,AIR)
Block(-3,-3,7,AIR)
Block(-3,-3,8,STAINED_CLAY:1)
Block(-3,-3,9,HARD_CLAY)
Block(-3,-2,-4,HARD_CLAY)
Block(-3,-2,-3,STAINED_CLAY:1)
Block(-3,-2,-2,AIR)
Block(-3,-2,-1,AIR)
Block(-3,-2,0,AIR)
Block(-3,-2,1,AIR)
Block(-3,-2,2,AIR)
Block(-3,-2,3,AIR)
Block(-3,-2,4,AIR)
Block(-3,-2,5,AIR)
Block(-3,-2,6,AIR)
Block(-3,-2,7,AIR)
Block(-3,-2,8,STAINED_CLAY:1)
Block(-3,-2,9,HARD_CLAY)
Block(-3,-1,-4,HARD_CLAY)
Block(-3,-1,-3,STAINED_CLAY:1)
Block(-3,-1,-2,STAINED_CLAY:1)
Block(-3,-1,-1,STAINED_CLAY:1)
Block(-3,-1,0,STAINED_CLAY:1)
Block(-3,-1,1,STAINED_CLAY:1)
Block(-3,-1,2,STAINED_CLAY:1)
Block(-3,-1,3,STAINED_CLAY:1)
Block(-3,-1,4,STAINED_CLAY:1)
Block(-3,-1,5,STAINED_CLAY:1)
Block(-3,-1,6,STAINED_CLAY:1)
Block(-3,-1,7,HARD_CLAY)
Block(-3,-1,8,STAINED_CLAY:1)
Block(-3,-1,9,HARD_CLAY)
Block(-3,0,-3,AIR)
Block(-3,0,-2,AIR)
Block(-3,0,-1,AIR)
Block(-3,0,0,AIR)
Block(-3,0,1,AIR)
Block(-3,0,2,AIR)
Block(-3,0,3,AIR)
Block(-3,0,4,AIR)
Block(-3,0,5,AIR)
Block(-3,0,6,AIR)
Block(-3,0,7,AIR)
Block(-3,0,8,STAINED_CLAY:1)
Block(-3,0,9,STAINED_CLAY:1)
Block(-3,1,-3,AIR)
Block(-3,1,-2,AIR)
Block(-3,1,-1,AIR)
Block(-3,1,0,AIR)
Block(-3,1,1,AIR)
Block(-3,1,2,AIR)
Block(-3,1,3,AIR)
Block(-3,1,4,AIR)
Block(-3,1,5,AIR)
Block(-3,1,6,AIR)
Block(-3,1,7,AIR)
Block(-3,1,8,STAINED_CLAY:1)
Block(-3,1,9,STAINED_CLAY:1)
Block(-3,2,-4,STAINED_CLAY:1)
Block(-3,2,-3,STAINED_CLAY:1)
Block(-3,2,-2,HARD_CLAY)
Block(-3,2,-1,AIR)
Block(-3,2,0,AIR)
Block(-3,2,1,AIR)
Block(-3,2,2,AIR)
Block(-3,2,3,AIR)
Block(-3,2,4,AIR)
Block(-3,2,5,AIR)
Block(-3,2,6,AIR)
Block(-3,2,7,HARD_CLAY)
Block(-3,2,8,STAINED_CLAY:1)
Block(-3,2,9,STAINED_CLAY:1)
Block(-3,3,-2,HARD_CLAY)
Block(-3,3,-1,AIR)
Block(-3,3,0,AIR)
Block(-3,3,1,AIR)
Block(-3,3,2,AIR)
Block(-3,3,3,AIR)
Block(-3,3,4,AIR)
Block(-3,3,5,AIR)
Block(-3,3,6,AIR)
Block(-3,3,7,HARD_CLAY)
Block(-3,4,-1,STAINED_CLAY:1)
Block(-3,4,0,HARD_CLAY)
Block(-3,4,1,HARD_CLAY)
Block(-3,4,2,HARD_CLAY)
Block(-3,4,3,HARD_CLAY)
Block(-3,4,4,HARD_CLAY)
Block(-3,4,5,HARD_CLAY)
Block(-3,4,6,STAINED_CLAY:1)
Block(-3,5,-1,STAINED_CLAY:1)
Block(-3,5,0,HARD_CLAY)
Block(-3,5,1,HARD_CLAY)
Block(-3,5,2,STAINED_CLAY:6)
Block(-3,5,3,STAINED_CLAY:6)
Block(-3,5,4,HARD_CLAY)
Block(-3,5,5,HARD_CLAY)
Block(-3,5,6,STAINED_CLAY:1)
Block(-3,6,-2,STAINED_CLAY:1)
Block(-3,6,-1,STAINED_CLAY:1)
Block(-3,6,0,HARD_CLAY)
Block(-3,6,1,HARD_CLAY)
Block(-3,6,2,HARD_CLAY)
Block(-3,6,3,HARD_CLAY)
Block(-3,6,4,HARD_CLAY)
Block(-3,6,5,HARD_CLAY)
Block(-3,6,6,STAINED_CLAY:1)
Block(-3,6,7,STAINED_CLAY:1)
Block(-2,-10,-4,HARD_CLAY)
Block(-2,-10,-3,STAINED_CLAY:1)
Block(-2,-10,-2,STAINED_CLAY:1)
Block(-2,-10,-1,STAINED_CLAY:1)
Block(-2,-10,0,STAINED_CLAY:1)
Block(-2,-10,1,STAINED_CLAY:1)
Block(-2,-10,2,STAINED_CLAY:6)
Block(-2,-10,3,STAINED_CLAY:6)
Block(-2,-10,4,STAINED_CLAY:1)
Block(-2,-10,5,STAINED_CLAY:1)
Block(-2,-10,6,STAINED_CLAY:1)
Block(-2,-10,7,STAINED_CLAY:1)
Block(-2,-10,8,STAINED_CLAY:1)
Block(-2,-10,9,HARD_CLAY)
Block(-2,-9,-4,HARD_CLAY)
Block(-2,-9,-3,STAINED_CLAY:1)
RandomBlock(-2,-9,-2,CHEST,../../nbt/VanillaLoot/desert_pyramid.nbt,50,CHEST,../../nbt/VanillaLoot/desert_pyramid.nbt,100)
Block(-2,-9,-1,AIR)
Block(-2,-9,0,STAINED_CLAY:1)
Block(-2,-9,1,STAINED_CLAY:1)
Block(-2,-9,2,AIR)
Block(-2,-9,3,AIR)
Block(-2,-9,4,STAINED_CLAY:1)
Block(-2,-9,5,STAINED_CLAY:1)
Block(-2,-9,6,STAINED_CLAY:1)
Block(-2,-9,7,LADDER:2)
Block(-1,-4,7,AIR)
Block(-1,-3,7,AIR)
Block(-1,-2,7,AIR)

Block(0,-4,7,AIR)
Block(0,-3,7,AIR)
Block(0,-2,7,AIR)

Block(1,-4,7,AIR)
Block(1,-3,7,AIR)
Block(1,-2,7,AIR)

Block(2,-4,7,AIR)
Block(2,-3,7,AIR)
Block(2,-2,7,AIR)

Block(3,-4,7,AIR)
Block(3,-3,7,AIR)
Block(3,-2,7,AIR)

Block(4,-4,7,AIR)
Block(4,-3,7,AIR)
Block(4,-2,7,AIR)


Block(-2,-9,8,STAINED_CLAY:1)
Block(-2,-9,9,HARD_CLAY)
Block(-2,-8,-4,HARD_CLAY)
Block(-2,-8,-3,STAINED_CLAY:1)
Block(-2,-8,-2,AIR)
Block(-2,-8,-1,AIR)
Block(-2,-8,0,STAINED_CLAY:1)
Block(-2,-8,1,STAINED_CLAY:1)
Block(-2,-8,2,AIR)
Block(-2,-8,3,AIR)
Block(-2,-8,4,STAINED_CLAY:1)
Block(-2,-8,5,STAINED_CLAY:1)
Block(-2,-8,6,STAINED_CLAY:1)
Block(-2,-8,7,LADDER:2)
Block(-2,-8,8,STAINED_CLAY:1)
Block(-2,-8,9,HARD_CLAY)
Block(-2,-7,-4,HARD_CLAY)
Block(-2,-7,-3,STAINED_CLAY:1)
Block(-2,-7,-2,STAINED_CLAY:1)
Block(-2,-7,-1,STAINED_CLAY:1)
Block(-2,-7,0,STAINED_CLAY:1)
Block(-2,-7,1,STAINED_CLAY:1)
Block(-2,-7,2,STAINED_CLAY:1)
Block(-2,-7,3,STAINED_CLAY:1)
Block(-2,-7,4,STAINED_CLAY:1)
Block(-2,-7,5,STAINED_CLAY:1)
Block(-2,-7,6,STAINED_CLAY:1)
Block(-2,-7,7,LADDER:2)
Block(3,0,5,AIR)
Block(-2,-7,8,STAINED_CLAY:1)
Block(-2,-7,9,HARD_CLAY)
Block(-2,-6,-4,HARD_CLAY)
Block(-2,-6,-3,STAINED_CLAY:1)
Block(-2,-6,-2,STAINED_CLAY:1)
Block(-2,-6,-1,STAINED_CLAY:1)
Block(-2,-6,0,STAINED_CLAY:1)
Block(-2,-6,1,STAINED_CLAY:1)
Block(-2,-6,2,STAINED_CLAY:1)
Block(-2,-6,3,STAINED_CLAY:1)
Block(-2,-6,4,STAINED_CLAY:1)
Block(-2,-6,5,STAINED_CLAY:1)
Block(-2,-6,6,STAINED_CLAY:1)
Block(-2,-6,7,LADDER:2)
Block(-2,-6,8,STAINED_CLAY:1)
Block(-2,-6,9,HARD_CLAY)
Block(-2,-5,-4,HARD_CLAY)
Block(-2,-5,-3,STAINED_CLAY:1)
Block(-2,-5,-2,STAINED_CLAY:1)
Block(-2,-5,-1,STAINED_CLAY:1)
Block(-2,-5,0,STAINED_CLAY:1)
Block(-2,-5,1,STAINED_CLAY:1)
Block(-2,-5,2,STAINED_CLAY:1)
Block(-2,-5,3,STAINED_CLAY:1)
Block(-2,-5,4,STAINED_CLAY:1)
Block(-2,-5,5,STAINED_CLAY:1)
Block(-2,-5,6,STAINED_CLAY:1)
Block(-2,-5,7,LADDER:2)
Block(-2,-5,8,STAINED_CLAY:1)
Block(-2,-5,9,HARD_CLAY)
Block(-2,-4,-4,HARD_CLAY)
Block(-2,-4,-3,STAINED_CLAY:1)
Block(-2,-4,-2,AIR)
Block(-2,-4,-1,AIR)
RandomBlock(-2,-4,0,MOB_SPAWNER,../../nbt/Spawner/Zombie.nbt,50,MOB_SPAWNER,../../nbt/Spawner/Skeleton.nbt,100)
Block(-2,-4,1,AIR)
Block(-2,-4,2,AIR)
Block(-2,-4,3,AIR)
Block(-2,-4,4,AIR)
Block(-2,-4,5,AIR)
Block(-2,-4,6,AIR)
Block(-2,-4,7,LADDER:2)
Block(-2,-4,8,STAINED_CLAY:1)
Block(-2,-4,9,HARD_CLAY)
Block(-2,-3,-4,HARD_CLAY)
Block(-2,-3,-3,STAINED_CLAY:1)
Block(-2,-3,-2,AIR)
Block(-2,-3,-1,AIR)
Block(-2,-3,0,AIR)
Block(-2,-3,1,AIR)
Block(-2,-3,2,AIR)
Block(-2,-3,3,AIR)
Block(-2,-3,4,AIR)
Block(-2,-3,5,AIR)
Block(-2,-3,6,AIR)
Block(-2,-3,7,LADDER:2)
Block(-2,-3,8,STAINED_CLAY:1)
Block(-2,-3,9,HARD_CLAY)
Block(-2,-2,-4,HARD_CLAY)
Block(-2,-2,-3,STAINED_CLAY:1)
Block(-2,-2,-2,AIR)
Block(-2,-2,-1,AIR)
Block(-2,-2,0,AIR)
Block(-2,-2,1,AIR)
Block(-2,-2,2,AIR)
Block(-2,-2,3,AIR)
Block(-2,-2,4,AIR)
Block(-2,-2,5,AIR)
Block(-2,-2,6,AIR)
Block(-2,-2,7,LADDER:2)
Block(-2,-2,8,STAINED_CLAY:1)
Block(-2,-2,9,HARD_CLAY)
Block(-2,-1,-4,HARD_CLAY)
Block(-2,-1,-3,STAINED_CLAY:1)
Block(-2,-1,-2,STAINED_CLAY:1)
Block(-2,-1,-1,STAINED_CLAY:1)
Block(-2,-1,0,STAINED_CLAY:1)
Block(-2,-1,1,STAINED_CLAY:1)
Block(-2,-1,2,STAINED_CLAY:1)
Block(-2,-1,3,STAINED_CLAY:1)
Block(-2,-1,4,STAINED_CLAY:1)
Block(-2,-1,5,STAINED_CLAY:1)
Block(-2,-1,6,STAINED_CLAY:1)
Block(-2,-1,7,LADDER:2)
Block(-2,-1,8,STAINED_CLAY:1)
Block(-2,-1,9,HARD_CLAY)
Block(-2,0,-3,STAINED_CLAY:1)
Block(-2,0,-2,AIR)
Block(-2,0,-1,AIR)
Block(-2,0,0,AIR)
Block(-2,0,1,AIR)
Block(-2,0,2,AIR)
Block(-2,0,3,AIR)
Block(-2,0,4,AIR)
Block(-2,0,5,AIR)
Block(-2,0,6,AIR)
Block(-2,0,7,AIR)
Block(-2,0,8,STAINED_CLAY:1)
Block(-2,1,-3,STAINED_CLAY:1)
Block(-2,1,-2,AIR)
Block(-2,1,-1,AIR)
Block(-2,1,0,AIR)
Block(-2,1,1,AIR)
Block(-2,1,2,AIR)
Block(-2,1,3,AIR)
Block(-2,1,4,AIR)
Block(-2,1,5,AIR)
Block(-2,1,6,AIR)
Block(-2,1,7,AIR)
Block(-2,1,8,STAINED_CLAY:1)
Block(-2,2,-3,STAINED_CLAY:1)
Block(-2,2,-2,AIR)
Block(-2,2,-1,AIR)
Block(-2,2,0,AIR)
Block(-2,2,1,AIR)
Block(-2,2,2,AIR)
Block(-2,2,3,AIR)
Block(-2,2,4,AIR)
Block(-2,2,5,AIR)
Block(-2,2,6,AIR)
Block(-2,2,7,AIR)
Block(-2,2,8,STAINED_CLAY:1)
Block(-2,3,-2,HARD_CLAY)
Block(-2,3,-1,AIR)
Block(-2,3,0,AIR)
Block(-2,3,1,AIR)
Block(-2,3,2,AIR)
Block(-2,3,3,AIR)
Block(-2,3,4,AIR)
Block(-2,3,5,AIR)
Block(-2,3,6,AIR)
Block(-2,3,7,HARD_CLAY)
Block(-2,4,-1,HARD_CLAY)
Block(-2,4,0,AIR)
Block(-2,4,1,AIR)
Block(-2,4,2,AIR)
Block(-2,4,3,AIR)
Block(-2,4,4,AIR)
Block(-2,4,5,AIR)
Block(-2,4,6,HARD_CLAY)
Block(-2,5,-1,HARD_CLAY)
Block(-2,5,0,STAINED_CLAY:6)
Block(-2,5,1,STAINED_CLAY:6)
Block(-2,5,2,STAINED_CLAY:6)
Block(-2,5,3,STAINED_CLAY:6)
Block(-2,5,4,STAINED_CLAY:6)
Block(-2,5,5,STAINED_CLAY:6)
Block(-2,5,6,HARD_CLAY)
Block(-2,6,-2,STAINED_CLAY:1)
Block(-2,6,-1,HARD_CLAY)
Block(-2,6,0,AIR)
Block(-2,6,1,AIR)
Block(-2,6,2,AIR)
Block(-2,6,3,AIR)
Block(-2,6,4,AIR)
Block(-2,6,5,AIR)
Block(-2,6,6,HARD_CLAY)
Block(-2,6,7,STAINED_CLAY:1)
Block(-2,7,0,STAINED_CLAY:1)
Block(-2,7,1,HARD_CLAY)
Block(-2,7,2,HARD_CLAY)
Block(-2,7,3,HARD_CLAY)
Block(-2,7,4,HARD_CLAY)
Block(-2,7,5,STAINED_CLAY:1)
Block(-2,8,0,STAINED_CLAY:1)
Block(-2,8,1,HARD_CLAY)
Block(-2,8,2,STAINED_CLAY:6)
Block(-2,8,3,STAINED_CLAY:6)
Block(-2,8,4,HARD_CLAY)
Block(-2,8,5,STAINED_CLAY:1)
Block(-2,9,1,HARD_CLAY)
Block(-2,9,2,HARD_CLAY)
Block(-2,9,3,HARD_CLAY)
Block(-2,9,4,HARD_CLAY)
Block(-2,12,1,STAINED_CLAY:1)
Block(-2,12,4,STAINED_CLAY:1)
Block(-1,-10,-4,HARD_CLAY)
Block(-1,-10,-3,STAINED_CLAY:1)
Block(-1,-10,-2,STAINED_CLAY:1)
Block(-1,-10,-1,STAINED_CLAY:1)
Block(-1,-10,0,STAINED_CLAY:1)
Block(-1,-10,1,STAINED_CLAY:1)
Block(-1,-10,2,STAINED_CLAY:6)
Block(-1,-10,3,STAINED_CLAY:6)
Block(-1,-10,4,STAINED_CLAY:1)
Block(-1,-10,5,STAINED_CLAY:1)
Block(-1,-10,6,STAINED_CLAY:1)
Block(-1,-10,7,STAINED_CLAY:1)
Block(-1,-10,8,STAINED_CLAY:1)
Block(-1,-10,9,HARD_CLAY)
Block(-1,-9,-4,HARD_CLAY)
Block(-1,-9,-3,STAINED_CLAY:1)
Block(-1,-9,-2,AIR)
Block(-1,-9,-1,AIR)
Block(-1,-9,0,STAINED_CLAY:1)
Block(-1,-9,1,AIR)
Block(-1,-9,2,AIR)
Block(-1,-9,3,AIR)
Block(-1,-9,4,AIR)
Block(-1,-9,5,STAINED_CLAY:1)
Block(-1,-9,6,AIR)
Block(-1,-9,7,AIR)
Block(-1,-9,8,STAINED_CLAY:1)
Block(-1,-9,9,HARD_CLAY)
Block(-1,-8,-4,HARD_CLAY)
Block(-1,-8,-3,STAINED_CLAY:1)
Block(-1,-8,-2,AIR)
Block(-1,-8,-1,AIR)
Block(-1,-8,0,STAINED_CLAY:1)
Block(-1,-8,1,AIR)
Block(-1,-8,2,AIR)
Block(-1,-8,3,AIR)
Block(-1,-8,4,AIR)
Block(-1,-8,5,STAINED_CLAY:1)
Block(-1,-8,6,AIR)
Block(-1,-8,7,AIR)
Block(-1,-8,8,STAINED_CLAY:1)
Block(-1,-8,9,HARD_CLAY)
Block(-1,-7,-4,HARD_CLAY)
Block(-1,-7,-3,STAINED_CLAY:1)
Block(-1,-7,-2,STAINED_CLAY:1)
Block(-1,-7,-1,STAINED_CLAY:1)
Block(-1,-7,0,STAINED_CLAY:1)
Block(-1,-7,1,AIR)
Block(-1,-7,2,AIR)
Block(-1,-7,3,AIR)
Block(-1,-7,4,AIR)
Block(-1,-7,5,STAINED_CLAY:1)
Block(-1,-7,6,STAINED_CLAY:1)
Block(-1,-7,7,STAINED_CLAY:1)
Block(-1,-7,8,STAINED_CLAY:1)
Block(-1,-7,9,HARD_CLAY)
Block(-1,-6,-4,HARD_CLAY)
Block(-1,-6,-3,STAINED_CLAY:1)
Block(-1,-6,-2,STAINED_CLAY:1)
Block(-1,-6,-1,STAINED_CLAY:1)
Block(-1,-6,0,STAINED_CLAY:1)
Block(-1,-6,1,STAINED_CLAY:1)
Block(-1,-6,2,AIR)
Block(-1,-6,3,AIR)
Block(-1,-6,4,STAINED_CLAY:1)
Block(-1,-6,5,STAINED_CLAY:1)
Block(-1,-6,6,STAINED_CLAY:1)
Block(-1,-6,7,STAINED_CLAY:1)
Block(-1,-6,8,STAINED_CLAY:1)
Block(-1,-6,9,HARD_CLAY)
Block(-1,-5,-4,HARD_CLAY)
Block(-1,-5,-3,STAINED_CLAY:1)
Block(-1,-5,-2,STAINED_CLAY:1)
Block(-1,-5,-1,STAINED_CLAY:1)
Block(-1,-5,0,STAINED_CLAY:1)
Block(-1,-5,1,STAINED_CLAY:6)
Block(-1,-5,2,STAINED_CLAY:6)
Block(-1,-5,3,STAINED_CLAY:6)
Block(-1,-5,4,STAINED_CLAY:6)
Block(-1,-5,5,STAINED_CLAY:1)
Block(-1,-5,6,STAINED_CLAY:1)
Block(-1,-5,7,STAINED_CLAY:1)
Block(-1,-5,8,STAINED_CLAY:1)
Block(-1,-5,9,HARD_CLAY)
Block(-1,-4,-4,HARD_CLAY)
Block(-1,-4,-3,STAINED_CLAY:1)
Block(-1,-4,-2,AIR)
Block(-1,-4,-1,AIR)
Block(-1,-4,0,AIR)
Block(-1,-4,1,AIR)
Block(-1,-4,2,AIR)
Block(-1,-4,3,AIR)
Block(-1,-4,4,AIR)
Block(-1,-4,5,AIR)
Block(-1,-4,6,AIR)
Block(-1,-4,8,STAINED_CLAY:1)
Block(-1,-4,9,HARD_CLAY)
Block(-1,-3,-4,HARD_CLAY)
Block(-1,-3,-3,STAINED_CLAY:1)
Block(-1,-3,-2,AIR)
Block(-1,-3,-1,AIR)
Block(-1,-3,0,AIR)
Block(-1,-3,1,AIR)
Block(-1,-3,2,AIR)
Block(-1,-3,3,AIR)
Block(-1,-3,4,AIR)
Block(-1,-3,5,AIR)
Block(-1,-3,6,AIR)
Block(-1,-3,8,STAINED_CLAY:1)
Block(-1,-3,9,HARD_CLAY)
Block(-1,-2,-4,HARD_CLAY)
Block(-1,-2,-3,STAINED_CLAY:1)
Block(-1,-2,-2,AIR)
Block(-1,-2,-1,AIR)
Block(-1,-2,0,AIR)
Block(-1,-2,1,AIR)
Block(-1,-2,2,AIR)
Block(-1,-2,3,AIR)
Block(-1,-2,4,AIR)
Block(-1,-2,5,AIR)
Block(-1,-2,6,AIR)
Block(-1,-2,8,STAINED_CLAY:1)
Block(-1,-2,9,HARD_CLAY)
Block(-1,-1,-4,HARD_CLAY)
Block(-1,-1,-3,STAINED_CLAY:1)
Block(-1,-1,-2,STAINED_CLAY:1)
Block(-1,-1,-1,STAINED_CLAY:1)
Block(-1,-1,0,STAINED_CLAY:1)
Block(-1,-1,1,STAINED_CLAY:6)
Block(-1,-1,2,STAINED_CLAY:6)
Block(-1,-1,3,STAINED_CLAY:6)
Block(-1,-1,4,STAINED_CLAY:6)
Block(-1,-1,5,STAINED_CLAY:1)
Block(-1,-1,6,STAINED_CLAY:1)
Block(-1,-1,7,HARD_CLAY)
Block(-1,-1,8,STAINED_CLAY:1)
Block(-1,-1,9,HARD_CLAY)
Block(-1,0,-3,AIR)
Block(-1,0,-2,AIR)
Block(-1,0,-1,AIR)
Block(-1,0,0,AIR)
Block(-1,0,1,AIR)
Block(-1,0,2,AIR)
Block(-1,0,3,AIR)
Block(-1,0,4,AIR)
Block(-1,0,5,AIR)
Block(-1,0,6,AIR)
Block(-1,0,7,AIR)
Block(-1,0,8,STAINED_CLAY:1)
Block(-1,1,-3,AIR)
Block(-1,1,-2,AIR)
Block(-1,1,-1,AIR)
Block(-1,1,0,AIR)
Block(-1,1,1,AIR)
Block(-1,1,2,AIR)
Block(-1,1,3,AIR)
Block(-1,1,4,AIR)
Block(-1,1,5,AIR)
Block(-1,1,6,AIR)
Block(-1,1,7,AIR)
Block(-1,1,8,STAINED_CLAY:1)
Block(-1,2,-4,STAINED_CLAY:1)
Block(-1,2,-3,STAINED_CLAY:1)
Block(-1,2,-2,AIR)
Block(-1,2,-1,AIR)
Block(-1,2,0,AIR)
Block(-1,2,1,AIR)
Block(-1,2,2,AIR)
Block(-1,2,3,AIR)
Block(-1,2,4,AIR)
Block(-1,2,5,AIR)
Block(-1,2,6,AIR)
Block(-1,2,7,AIR)
Block(-1,2,8,STAINED_CLAY:1)
Block(-1,3,-2,HARD_CLAY)
Block(-1,3,-1,AIR)
Block(-1,3,0,AIR)
Block(-1,3,1,AIR)
Block(-1,3,2,AIR)
Block(-1,3,3,AIR)
Block(-1,3,4,AIR)
Block(-1,3,5,AIR)
Block(-1,3,6,AIR)
Block(-1,3,7,HARD_CLAY)
Block(-1,4,-1,HARD_CLAY)
Block(-1,4,0,AIR)
Block(-1,4,1,AIR)
Block(-1,4,2,AIR)
Block(-1,4,3,AIR)
Block(-1,4,4,AIR)
Block(-1,4,5,AIR)
Block(-1,4,6,HARD_CLAY)
Block(-1,5,-1,HARD_CLAY)
Block(-1,5,0,STAINED_CLAY:6)
Block(-1,5,1,AIR)
Block(-1,5,2,AIR)
Block(-1,5,3,AIR)
Block(-1,5,4,AIR)
Block(-1,5,5,STAINED_CLAY:6)
Block(-1,5,6,HARD_CLAY)
Block(-1,6,-2,STAINED_CLAY:1)
Block(-1,6,-1,HARD_CLAY)
Block(-1,6,0,AIR)
Block(-1,6,1,AIR)
Block(-1,6,2,AIR)
Block(-1,6,3,AIR)
Block(-1,6,4,AIR)
Block(-1,6,5,AIR)
Block(-1,6,6,HARD_CLAY)
Block(-1,6,7,STAINED_CLAY:1)
Block(-1,7,0,HARD_CLAY)
Block(-1,7,1,AIR)
Block(-1,7,2,AIR)
Block(-1,7,3,AIR)
Block(-1,7,4,AIR)
Block(-1,7,5,HARD_CLAY)
Block(-1,8,0,HARD_CLAY)
Block(-1,8,1,AIR)
Block(-1,8,2,AIR)
Block(-1,8,3,AIR)
Block(-1,8,4,AIR)
Block(-1,8,5,HARD_CLAY)
Block(-1,9,0,HARD_CLAY)
Block(-1,9,1,AIR)
Block(-1,9,2,AIR)
Block(-1,9,3,AIR)
Block(-1,9,4,AIR)
Block(-1,9,5,HARD_CLAY)
Block(-1,10,1,STAINED_CLAY:1)
Block(-1,10,2,HARD_CLAY)
Block(-1,10,3,HARD_CLAY)
Block(-1,10,4,STAINED_CLAY:1)
Block(-1,11,1,STAINED_CLAY:1)
Block(-1,11,2,HARD_CLAY)
Block(-1,11,3,HARD_CLAY)
Block(-1,11,4,STAINED_CLAY:1)
Block(-1,12,0,STAINED_CLAY:1)
Block(-1,12,1,STAINED_CLAY:1)
Block(-1,12,2,HARD_CLAY)
Block(-1,12,3,HARD_CLAY)
Block(-1,12,4,STAINED_CLAY:1)
Block(-1,12,5,STAINED_CLAY:1)
Block(0,-10,-4,HARD_CLAY)
Block(0,-10,-3,STAINED_CLAY:1)
Block(0,-10,-2,STAINED_CLAY:6)
Block(0,-10,-1,STAINED_CLAY:6)
Block(0,-10,0,STAINED_CLAY:6)
Block(0,-10,1,STAINED_CLAY:6)
Block(0,-10,2,STAINED_CLAY:6)
Block(0,-10,3,STAINED_CLAY:6)
Block(0,-10,4,STAINED_CLAY:6)
Block(0,-10,5,STAINED_CLAY:6)
Block(0,-10,6,STAINED_CLAY:6)
Block(0,-10,7,STAINED_CLAY:6)
Block(0,-10,8,STAINED_CLAY:1)
Block(0,-10,9,HARD_CLAY)
Block(0,-9,-4,HARD_CLAY)
Block(0,-9,-3,STAINED_CLAY:6)
Block(0,-9,-2,AIR)
Block(0,-9,-1,AIR)
Block(0,-9,0,AIR)
Block(0,-9,1,AIR)
Block(0,-9,2,AIR)
Block(0,-9,3,AIR)
Block(0,-9,4,AIR)
Block(0,-9,5,AIR)
Block(0,-9,6,AIR)
Block(0,-9,7,AIR)
Block(0,-9,8,STAINED_CLAY:1)
Block(0,-9,9,HARD_CLAY)
Block(0,-8,-4,HARD_CLAY)
Block(0,-8,-3,STAINED_CLAY:6)
Block(0,-8,-2,AIR)
Block(0,-8,-1,AIR)
Block(0,-8,0,AIR)
Block(0,-8,1,AIR)
Block(0,-8,2,AIR)
Block(0,-8,3,AIR)
Block(0,-8,4,AIR)
Block(0,-8,5,AIR)
Block(0,-8,6,AIR)
Block(0,-8,7,AIR)
Block(0,-8,8,STAINED_CLAY:1)
Block(0,-8,9,HARD_CLAY)
Block(0,-7,-4,HARD_CLAY)
Block(0,-7,-3,STAINED_CLAY:1)
Block(0,-7,-2,STAINED_CLAY:1)
Block(0,-7,-1,STAINED_CLAY:1)
Block(0,-7,0,STAINED_CLAY:1)
Block(0,-7,1,AIR)
Block(0,-7,2,AIR)
Block(0,-7,3,AIR)
Block(0,-7,4,AIR)
Block(0,-7,5,STAINED_CLAY:1)
Block(0,-7,6,STAINED_CLAY:1)
Block(0,-7,7,STAINED_CLAY:1)
Block(0,-7,8,STAINED_CLAY:1)
Block(0,-7,9,HARD_CLAY)
Block(0,-6,-4,HARD_CLAY)
Block(0,-6,-3,STAINED_CLAY:1)
Block(0,-6,-2,STAINED_CLAY:1)
Block(0,-6,-1,STAINED_CLAY:1)
Block(0,-6,0,STAINED_CLAY:1)
Block(0,-6,1,AIR)
Block(0,-6,2,AIR)
Block(0,-6,3,AIR)
Block(0,-6,4,AIR)
Block(0,-6,5,STAINED_CLAY:1)
Block(0,-6,6,STAINED_CLAY:1)
Block(0,-6,7,STAINED_CLAY:1)
Block(0,-6,8,STAINED_CLAY:1)
Block(0,-6,9,HARD_CLAY)
Block(0,-5,-4,HARD_CLAY)
Block(0,-5,-3,STAINED_CLAY:1)
Block(0,-5,-2,STAINED_CLAY:1)
Block(0,-5,-1,STAINED_CLAY:1)
Block(0,-5,0,STAINED_CLAY:1)
Block(0,-5,1,STAINED_CLAY:6)
Block(0,-5,2,AIR)
Block(0,-5,3,AIR)
Block(0,-5,4,STAINED_CLAY:6)
Block(0,-5,5,STAINED_CLAY:1)
Block(0,-5,6,STAINED_CLAY:1)
Block(0,-5,7,STAINED_CLAY:1)
Block(0,-5,8,STAINED_CLAY:1)
Block(0,-5,9,HARD_CLAY)
Block(0,-4,-4,HARD_CLAY)
Block(0,-4,-3,STAINED_CLAY:1)
Block(0,-4,-2,AIR)
Block(0,-4,-1,AIR)
Block(0,-4,0,AIR)
Block(0,-4,1,AIR)
Block(0,-4,2,AIR)
Block(0,-4,3,AIR)
Block(0,-4,4,AIR)
Block(0,-4,5,AIR)
Block(0,-4,6,AIR)
Block(0,-4,8,STAINED_CLAY:1)
Block(0,-4,9,HARD_CLAY)
Block(0,-3,-4,HARD_CLAY)
Block(0,-3,-3,STAINED_CLAY:1)
Block(0,-3,-2,AIR)
Block(0,-3,-1,AIR)
Block(0,-3,0,AIR)
Block(0,-3,1,AIR)
Block(0,-3,2,AIR)
Block(0,-3,3,AIR)
Block(0,-3,4,AIR)
Block(0,-3,5,AIR)
Block(0,-3,6,AIR)
Block(0,-3,8,STAINED_CLAY:1)
Block(0,-3,9,HARD_CLAY)
Block(0,-2,-4,HARD_CLAY)
Block(0,-2,-3,STAINED_CLAY:1)
Block(0,-2,-2,AIR)
Block(0,-2,-1,AIR)
Block(0,-2,0,AIR)
Block(0,-2,1,AIR)
Block(0,-2,2,AIR)
Block(0,-2,3,AIR)
Block(0,-2,4,AIR)
Block(0,-2,5,AIR)
Block(0,-2,6,AIR)
Block(0,-2,8,STAINED_CLAY:1)
Block(0,-2,9,HARD_CLAY)
Block(0,-1,-4,HARD_CLAY)
Block(0,-1,-3,STAINED_CLAY:1)
Block(0,-1,-2,STAINED_CLAY:1)
Block(0,-1,-1,STAINED_CLAY:1)
Block(0,-1,0,STAINED_CLAY:1)
Block(0,-1,1,STAINED_CLAY:6)
Block(0,-1,2,AIR)
Block(0,-1,3,AIR)
Block(0,-1,4,STAINED_CLAY:6)
Block(0,-1,5,STAINED_CLAY:1)
Block(0,-1,6,STAINED_CLAY:1)
Block(0,-1,7,HARD_CLAY)
Block(0,-1,8,STAINED_CLAY:1)
Block(0,-1,9,HARD_CLAY)
Block(0,0,-3,STAINED_CLAY:1)
Block(0,0,-2,AIR)
Block(0,0,-1,AIR)
Block(0,0,0,AIR)
Block(0,0,1,AIR)
Block(0,0,2,AIR)
Block(0,0,3,AIR)
Block(0,0,4,AIR)
Block(0,0,5,AIR)
Block(0,0,6,AIR)
Block(0,0,7,AIR)
Block(0,0,8,STAINED_CLAY:1)
Block(0,0,9,STAINED_CLAY:1)
Block(0,1,-3,STAINED_CLAY:1)
Block(0,1,-2,AIR)
Block(0,1,-1,AIR)
Block(0,1,0,AIR)
Block(0,1,1,AIR)
Block(0,1,2,AIR)
Block(0,1,3,AIR)
Block(0,1,4,AIR)
Block(0,1,5,AIR)
Block(0,1,6,AIR)
Block(0,1,7,AIR)
Block(0,1,8,AIR)
Block(0,1,9,STAINED_CLAY:6)
Block(0,2,-3,STAINED_CLAY:1)
Block(0,2,-2,AIR)
Block(0,2,-1,AIR)
Block(0,2,0,AIR)
Block(0,2,1,AIR)
Block(0,2,2,AIR)
Block(0,2,3,AIR)
Block(0,2,4,AIR)
Block(0,2,5,AIR)
Block(0,2,6,AIR)
Block(0,2,7,AIR)
Block(0,2,8,STAINED_CLAY:1)
Block(0,2,9,STAINED_CLAY:1)
Block(0,3,-2,HARD_CLAY)
Block(0,3,-1,AIR)
Block(0,3,0,AIR)
Block(0,3,1,AIR)
Block(0,3,2,AIR)
Block(0,3,3,AIR)
Block(0,3,4,AIR)
Block(0,3,5,AIR)
Block(0,3,6,AIR)
Block(0,3,7,HARD_CLAY)
Block(0,4,-1,HARD_CLAY)
Block(0,4,0,AIR)
Block(0,4,1,AIR)
Block(0,4,2,AIR)
Block(0,4,3,AIR)
Block(0,4,4,AIR)
Block(0,4,5,AIR)
Block(0,4,6,HARD_CLAY)
Block(0,5,-1,STAINED_CLAY:6)
Block(0,5,0,STAINED_CLAY:6)
Block(0,5,1,AIR)
Block(0,5,2,AIR)
Block(0,5,3,AIR)
Block(0,5,4,AIR)
Block(0,5,5,STAINED_CLAY:6)
Block(0,5,6,STAINED_CLAY:6)
Block(0,6,-2,STAINED_CLAY:1)
Block(0,6,-1,HARD_CLAY)
Block(0,6,0,AIR)
Block(0,6,1,AIR)
Block(0,6,2,AIR)
Block(0,6,3,AIR)
Block(0,6,4,AIR)
Block(0,6,5,AIR)
Block(0,6,6,HARD_CLAY)
Block(0,6,7,STAINED_CLAY:1)
Block(0,7,0,HARD_CLAY)
Block(0,7,1,AIR)
Block(0,7,2,AIR)
Block(0,7,3,AIR)
Block(0,7,4,AIR)
Block(0,7,5,HARD_CLAY)
Block(0,8,0,STAINED_CLAY:6)
Block(0,8,1,AIR)
Block(0,8,2,AIR)
Block(0,8,3,AIR)
Block(0,8,4,AIR)
Block(0,8,5,STAINED_CLAY:6)
Block(0,9,0,HARD_CLAY)
Block(0,9,1,AIR)
Block(0,9,2,AIR)
Block(0,9,3,AIR)
Block(0,9,4,AIR)
Block(0,9,5,HARD_CLAY)
Block(0,10,1,HARD_CLAY)
Block(0,10,2,AIR)
Block(0,10,3,AIR)
Block(0,10,4,HARD_CLAY)
Block(0,11,1,HARD_CLAY)
Block(0,11,2,REDSTONE_LAMP_ON)
Block(0,11,3,REDSTONE_LAMP_ON)
Block(0,11,4,HARD_CLAY)
Block(0,12,1,HARD_CLAY)
Block(0,12,2,REDSTONE_TORCH_ON:1)
Block(0,12,3,REDSTONE_TORCH_ON:1)
Block(0,12,4,HARD_CLAY)
Block(0,13,2,STAINED_CLAY:1)
Block(0,13,3,STAINED_CLAY:1)
Block(0,14,2,STAINED_CLAY:1)
Block(0,14,3,STAINED_CLAY:1)
Block(0,15,2,STAINED_CLAY:1)
Block(0,15,3,STAINED_CLAY:1)
Block(1,-10,-4,HARD_CLAY)
Block(1,-10,-3,STAINED_CLAY:1)
Block(1,-10,-2,STAINED_CLAY:6)
Block(1,-10,-1,STAINED_CLAY:6)
Block(1,-10,0,STAINED_CLAY:6)
Block(1,-10,1,STAINED_CLAY:6)
Block(1,-10,2,STAINED_CLAY:6)
Block(1,-10,3,STAINED_CLAY:6)
Block(1,-10,4,STAINED_CLAY:6)
Block(1,-10,5,STAINED_CLAY:6)
Block(1,-10,6,STAINED_CLAY:6)
Block(1,-10,7,STAINED_CLAY:6)
Block(1,-10,8,STAINED_CLAY:1)
Block(1,-10,9,HARD_CLAY)
Block(1,-9,-4,HARD_CLAY)
Block(1,-9,-3,STAINED_CLAY:6)
Block(1,-9,-2,AIR)
Block(1,-9,-1,AIR)
Block(1,-9,0,AIR)
Block(1,-9,1,AIR)
Block(1,-9,2,AIR)
Block(1,-9,3,AIR)
Block(1,-9,4,AIR)
Block(1,-9,5,AIR)
Block(1,-9,6,AIR)
Block(1,-9,7,AIR)
Block(1,-9,8,STAINED_CLAY:1)
Block(1,-9,9,HARD_CLAY)
Block(1,-8,-4,HARD_CLAY)
Block(1,-8,-3,STAINED_CLAY:6)
Block(1,-8,-2,AIR)
Block(1,-8,-1,AIR)
Block(1,-8,0,AIR)
Block(1,-8,1,AIR)
Block(1,-8,2,AIR)
Block(1,-8,3,AIR)
Block(1,-8,4,AIR)
Block(1,-8,5,AIR)
Block(1,-8,6,AIR)
Block(1,-8,7,AIR)
Block(1,-8,8,STAINED_CLAY:1)
Block(1,-8,9,HARD_CLAY)
Block(1,-7,-4,HARD_CLAY)
Block(1,-7,-3,STAINED_CLAY:1)
Block(1,-7,-2,STAINED_CLAY:1)
Block(1,-7,-1,STAINED_CLAY:1)
Block(1,-7,0,STAINED_CLAY:1)
Block(1,-7,1,AIR)
Block(1,-7,2,AIR)
Block(1,-7,3,AIR)
Block(1,-7,4,AIR)
Block(1,-7,5,STAINED_CLAY:1)
Block(1,-7,6,STAINED_CLAY:1)
Block(1,-7,7,STAINED_CLAY:1)
Block(1,-7,8,STAINED_CLAY:1)
Block(1,-7,9,HARD_CLAY)
Block(1,-6,-4,HARD_CLAY)
Block(1,-6,-3,STAINED_CLAY:1)
Block(1,-6,-2,STAINED_CLAY:1)
Block(1,-6,-1,STAINED_CLAY:1)
Block(1,-6,0,STAINED_CLAY:1)
Block(1,-6,1,AIR)
Block(1,-6,2,AIR)
Block(1,-6,3,AIR)
Block(1,-6,4,AIR)
Block(1,-6,5,STAINED_CLAY:1)
Block(1,-6,6,STAINED_CLAY:1)
Block(1,-6,7,STAINED_CLAY:1)
Block(1,-6,8,STAINED_CLAY:1)
Block(1,-6,9,HARD_CLAY)
Block(1,-5,-4,HARD_CLAY)
Block(1,-5,-3,STAINED_CLAY:1)
Block(1,-5,-2,STAINED_CLAY:1)
Block(1,-5,-1,STAINED_CLAY:1)
Block(1,-5,0,STAINED_CLAY:1)
Block(1,-5,1,STAINED_CLAY:6)
Block(1,-5,2,AIR)
Block(1,-5,3,AIR)
Block(1,-5,4,STAINED_CLAY:6)
Block(1,-5,5,STAINED_CLAY:1)
Block(1,-5,6,STAINED_CLAY:1)
Block(1,-5,7,STAINED_CLAY:1)
Block(1,-5,8,STAINED_CLAY:1)
Block(1,-5,9,HARD_CLAY)
Block(1,-4,-4,HARD_CLAY)
Block(1,-4,-3,STAINED_CLAY:1)
Block(1,-4,-2,AIR)
Block(1,-4,-1,AIR)
Block(1,-4,0,AIR)
Block(1,-4,1,AIR)
Block(1,-4,2,AIR)
Block(1,-4,3,AIR)
Block(1,-4,4,AIR)
Block(1,-4,5,AIR)
Block(1,-4,6,AIR)
Block(1,-4,8,STAINED_CLAY:1)
Block(1,-4,9,HARD_CLAY)
Block(1,-3,-4,HARD_CLAY)
Block(1,-3,-3,STAINED_CLAY:1)
Block(1,-3,-2,AIR)
Block(1,-3,-1,AIR)
Block(1,-3,0,AIR)
Block(1,-3,1,AIR)
Block(1,-3,2,AIR)
Block(1,-3,3,AIR)
Block(1,-3,4,AIR)
Block(1,-3,5,AIR)
Block(1,-3,6,AIR)
Block(1,-3,8,STAINED_CLAY:1)
Block(1,-3,9,HARD_CLAY)
Block(1,-2,-4,HARD_CLAY)
Block(1,-2,-3,STAINED_CLAY:1)
Block(1,-2,-2,AIR)
Block(1,-2,-1,AIR)
Block(1,-2,0,AIR)
Block(1,-2,1,AIR)
Block(1,-2,2,AIR)
Block(1,-2,3,AIR)
Block(1,-2,4,AIR)
Block(1,-2,5,AIR)
Block(1,-2,6,AIR)
Block(1,-2,8,STAINED_CLAY:1)
Block(1,-2,9,HARD_CLAY)
Block(1,-1,-4,HARD_CLAY)
Block(1,-1,-3,STAINED_CLAY:1)
Block(1,-1,-2,STAINED_CLAY:1)
Block(1,-1,-1,STAINED_CLAY:1)
Block(1,-1,0,STAINED_CLAY:1)
Block(1,-1,1,STAINED_CLAY:6)
Block(1,-1,2,AIR)
Block(1,-1,3,AIR)
Block(1,-1,4,STAINED_CLAY:6)
Block(1,-1,5,STAINED_CLAY:1)
Block(1,-1,6,STAINED_CLAY:1)
Block(1,-1,7,HARD_CLAY)
Block(1,-1,8,STAINED_CLAY:1)
Block(1,-1,9,HARD_CLAY)
Block(1,0,-3,AIR)
Block(1,0,-2,AIR)
Block(1,0,-1,AIR)
Block(1,0,0,AIR)
Block(1,0,1,AIR)
Block(1,0,2,AIR)
Block(1,0,3,AIR)
Block(1,0,4,AIR)
Block(1,0,5,AIR)
Block(1,0,6,AIR)
Block(1,0,7,AIR)
Block(1,0,8,STAINED_CLAY:1)
Block(1,0,9,STAINED_CLAY:1)
Block(1,1,-3,AIR)
Block(1,1,-2,AIR)
Block(1,1,-1,AIR)
Block(1,1,0,AIR)
Block(1,1,1,AIR)
Block(1,1,2,AIR)
Block(1,1,3,AIR)
Block(1,1,4,AIR)
Block(1,1,5,AIR)
Block(1,1,6,AIR)
Block(1,1,7,AIR)
Block(1,1,8,AIR)
Block(1,1,9,STAINED_CLAY:6)
Block(1,2,-4,STAINED_CLAY:1)
Block(1,2,-3,STAINED_CLAY:1)
Block(1,2,-2,AIR)
Block(1,2,-1,AIR)
Block(1,2,0,AIR)
Block(1,2,1,AIR)
Block(1,2,2,AIR)
Block(1,2,3,AIR)
Block(1,2,4,AIR)
Block(1,2,5,AIR)
Block(1,2,6,AIR)
Block(1,2,7,AIR)
Block(1,2,8,STAINED_CLAY:1)
Block(1,2,9,STAINED_CLAY:1)
Block(1,3,-2,HARD_CLAY)
Block(1,3,-1,AIR)
Block(1,3,0,AIR)
Block(1,3,1,AIR)
Block(1,3,2,AIR)
Block(1,3,3,AIR)
Block(1,3,4,AIR)
Block(1,3,5,AIR)
Block(1,3,6,AIR)
Block(1,3,7,HARD_CLAY)
Block(1,4,-1,HARD_CLAY)
Block(1,4,0,AIR)
Block(1,4,1,AIR)
Block(1,4,2,AIR)
Block(1,4,3,AIR)
Block(1,4,4,AIR)
Block(1,4,5,AIR)
Block(1,4,6,HARD_CLAY)
Block(1,5,-1,STAINED_CLAY:6)
Block(1,5,0,STAINED_CLAY:6)
Block(1,5,1,AIR)
Block(1,5,2,AIR)
Block(1,5,3,AIR)
Block(1,5,4,AIR)
Block(1,5,5,STAINED_CLAY:6)
Block(1,5,6,STAINED_CLAY:6)
Block(1,6,-2,STAINED_CLAY:1)
Block(1,6,-1,HARD_CLAY)
Block(1,6,0,AIR)
Block(1,6,1,AIR)
Block(1,6,2,AIR)
Block(1,6,3,AIR)
Block(1,6,4,AIR)
Block(1,6,5,AIR)
Block(1,6,6,HARD_CLAY)
Block(1,6,7,STAINED_CLAY:1)
Block(1,7,0,HARD_CLAY)
Block(1,7,1,AIR)
Block(1,7,2,AIR)
Block(1,7,3,AIR)
Block(1,7,4,AIR)
Block(1,7,5,HARD_CLAY)
Block(1,8,0,STAINED_CLAY:6)
Block(1,8,1,AIR)
Block(1,8,2,AIR)
Block(1,8,3,AIR)
Block(1,8,4,AIR)
Block(1,8,5,STAINED_CLAY:6)
Block(1,9,0,HARD_CLAY)
Block(1,9,1,AIR)
Block(1,9,2,AIR)
Block(1,9,3,AIR)
Block(1,9,4,AIR)
Block(1,9,5,HARD_CLAY)
Block(1,10,1,HARD_CLAY)
Block(1,10,2,AIR)
Block(1,10,3,AIR)
Block(1,10,4,HARD_CLAY)
Block(1,11,1,HARD_CLAY)
Block(1,11,2,REDSTONE_LAMP_ON)
Block(1,11,3,REDSTONE_LAMP_ON)
Block(1,11,4,HARD_CLAY)
Block(1,12,1,HARD_CLAY)
Block(1,12,2,REDSTONE_TORCH_ON:2)
Block(1,12,3,REDSTONE_TORCH_ON:2)
Block(1,12,4,HARD_CLAY)
Block(1,13,2,STAINED_CLAY:1)
Block(1,13,3,STAINED_CLAY:1)
Block(1,14,2,STAINED_CLAY:1)
Block(1,14,3,STAINED_CLAY:1)
Block(1,15,2,STAINED_CLAY:1)
Block(1,15,3,STAINED_CLAY:1)
Block(2,-10,-4,HARD_CLAY)
Block(2,-10,-3,STAINED_CLAY:1)
Block(2,-10,-2,STAINED_CLAY:1)
Block(2,-10,-1,STAINED_CLAY:1)
Block(2,-10,0,STAINED_CLAY:1)
Block(2,-10,1,STAINED_CLAY:1)
Block(2,-10,2,STAINED_CLAY:6)
Block(2,-10,3,STAINED_CLAY:6)
Block(2,-10,4,STAINED_CLAY:1)
Block(2,-10,5,STAINED_CLAY:1)
Block(2,-10,6,STAINED_CLAY:1)
Block(2,-10,7,STAINED_CLAY:1)
Block(2,-10,8,STAINED_CLAY:1)
Block(2,-10,9,HARD_CLAY)
Block(2,-9,-4,HARD_CLAY)
Block(2,-9,-3,STAINED_CLAY:1)
Block(2,-9,-2,AIR)
Block(2,-9,-1,AIR)
Block(2,-9,0,STAINED_CLAY:1)
Block(2,-9,1,AIR)
Block(2,-9,2,AIR)
Block(2,-9,3,AIR)
Block(2,-9,4,AIR)
Block(2,-9,5,STAINED_CLAY:1)
Block(2,-9,6,STAINED_CLAY:1)
Block(2,-9,7,STAINED_CLAY:1)
Block(2,-9,8,STAINED_CLAY:1)
Block(2,-9,9,HARD_CLAY)
Block(2,-8,-4,HARD_CLAY)
Block(2,-8,-3,STAINED_CLAY:1)
Block(2,-8,-2,AIR)
Block(2,-8,-1,AIR)
Block(2,-8,0,STAINED_CLAY:1)
Block(2,-8,1,AIR)
Block(2,-8,2,AIR)
Block(2,-8,3,AIR)
Block(2,-8,4,AIR)
Block(2,-8,5,STAINED_CLAY:1)
Block(2,-8,6,STAINED_CLAY:1)
Block(2,-8,7,STAINED_CLAY:1)
Block(2,-8,8,STAINED_CLAY:1)
Block(2,-8,9,HARD_CLAY)
Block(2,-7,-4,HARD_CLAY)
Block(2,-7,-3,STAINED_CLAY:1)
Block(2,-7,-2,STAINED_CLAY:1)
Block(2,-7,-1,STAINED_CLAY:1)
Block(2,-7,0,STAINED_CLAY:1)
Block(2,-7,1,AIR)
Block(2,-7,2,AIR)
Block(2,-7,3,AIR)
Block(2,-7,4,AIR)
Block(2,-7,5,STAINED_CLAY:1)
Block(2,-7,6,STAINED_CLAY:1)
Block(2,-7,7,STAINED_CLAY:1)
Block(2,-7,8,STAINED_CLAY:1)
Block(2,-7,9,HARD_CLAY)
Block(2,-6,-4,HARD_CLAY)
Block(2,-6,-3,STAINED_CLAY:1)
Block(2,-6,-2,STAINED_CLAY:1)
Block(2,-6,-1,STAINED_CLAY:1)
Block(2,-6,0,STAINED_CLAY:1)
Block(2,-6,1,STAINED_CLAY:1)
Block(2,-6,2,AIR)
Block(2,-6,3,AIR)
Block(2,-6,4,STAINED_CLAY:1)
Block(2,-6,5,STAINED_CLAY:1)
Block(2,-6,6,STAINED_CLAY:1)
Block(2,-6,7,STAINED_CLAY:1)
Block(2,-6,8,STAINED_CLAY:1)
Block(2,-6,9,HARD_CLAY)
Block(2,-5,-4,HARD_CLAY)
Block(2,-5,-3,STAINED_CLAY:1)
Block(2,-5,-2,STAINED_CLAY:1)
Block(2,-5,-1,STAINED_CLAY:1)
Block(2,-5,0,STAINED_CLAY:1)
Block(2,-5,1,STAINED_CLAY:6)
Block(2,-5,2,STAINED_CLAY:6)
Block(2,-5,3,STAINED_CLAY:6)
Block(2,-5,4,STAINED_CLAY:6)
Block(2,-5,5,STAINED_CLAY:1)
Block(2,-5,6,STAINED_CLAY:1)
Block(2,-5,7,STAINED_CLAY:1)
Block(2,-5,8,STAINED_CLAY:1)
Block(2,-5,9,HARD_CLAY)
Block(2,-4,-4,HARD_CLAY)
Block(2,-4,-3,STAINED_CLAY:1)
Block(2,-4,-2,AIR)
Block(2,-4,-1,AIR)
Block(2,-4,0,AIR)
Block(2,-4,1,AIR)
Block(2,-4,2,AIR)
Block(2,-4,3,AIR)
Block(2,-4,4,AIR)
Block(2,-4,5,AIR)
Block(2,-4,6,AIR)
Block(2,-4,8,STAINED_CLAY:1)
Block(2,-4,9,HARD_CLAY)
Block(2,-3,-4,HARD_CLAY)
Block(2,-3,-3,STAINED_CLAY:1)
Block(2,-3,-2,AIR)
Block(2,-3,-1,AIR)
Block(2,-3,0,AIR)
Block(2,-3,1,AIR)
Block(2,-3,2,AIR)
Block(2,-3,3,AIR)
Block(2,-3,4,AIR)
Block(2,-3,5,AIR)
Block(2,-3,6,AIR)
Block(2,-3,8,STAINED_CLAY:1)
Block(2,-3,9,HARD_CLAY)
Block(2,-2,-4,HARD_CLAY)
Block(2,-2,-3,STAINED_CLAY:1)
Block(2,-2,-2,AIR)
Block(2,-2,-1,AIR)
Block(2,-2,0,AIR)
Block(2,-2,1,AIR)
Block(2,-2,2,AIR)
Block(2,-2,3,AIR)
Block(2,-2,4,AIR)
Block(2,-2,5,AIR)
Block(2,-2,6,AIR)
Block(2,-2,8,STAINED_CLAY:1)
Block(2,-2,9,HARD_CLAY)
Block(2,-1,-4,HARD_CLAY)
Block(2,-1,-3,STAINED_CLAY:1)
Block(2,-1,-2,STAINED_CLAY:1)
Block(2,-1,-1,STAINED_CLAY:1)
Block(2,-1,0,STAINED_CLAY:1)
Block(2,-1,1,STAINED_CLAY:6)
Block(2,-1,2,STAINED_CLAY:6)
Block(2,-1,3,STAINED_CLAY:6)
Block(2,-1,4,STAINED_CLAY:6)
Block(2,-1,5,STAINED_CLAY:1)
Block(2,-1,6,STAINED_CLAY:1)
Block(2,-1,7,HARD_CLAY)
Block(2,-1,8,STAINED_CLAY:1)
Block(2,-1,9,HARD_CLAY)
Block(2,0,-3,STAINED_CLAY:1)
Block(2,0,-2,AIR)
Block(2,0,-1,AIR)
Block(2,0,0,AIR)
Block(2,0,1,AIR)
Block(2,0,2,AIR)
Block(2,0,3,AIR)
Block(2,0,4,AIR)
Block(2,0,5,AIR)
Block(2,0,6,AIR)
Block(2,0,7,AIR)
Block(2,0,8,STAINED_CLAY:1)
Block(2,1,-3,STAINED_CLAY:1)
Block(2,1,-2,AIR)
Block(2,1,-1,AIR)
Block(2,1,0,AIR)
Block(2,1,1,AIR)
Block(2,1,2,AIR)
Block(2,1,3,AIR)
Block(2,1,4,AIR)
Block(2,1,5,AIR)
Block(2,1,6,AIR)
Block(2,1,7,AIR)
Block(2,1,8,STAINED_CLAY:1)
Block(2,2,-3,STAINED_CLAY:1)
Block(2,2,-2,AIR)
Block(2,2,-1,AIR)
Block(2,2,0,AIR)
Block(2,2,1,AIR)
Block(2,2,2,AIR)
Block(2,2,3,AIR)
Block(2,2,4,AIR)
Block(2,2,5,AIR)
Block(2,2,6,AIR)
Block(2,2,7,AIR)
Block(2,2,8,STAINED_CLAY:1)
Block(2,3,-2,HARD_CLAY)
Block(2,3,-1,AIR)
Block(2,3,0,AIR)
Block(2,3,1,AIR)
Block(2,3,2,AIR)
Block(2,3,3,AIR)
Block(2,3,4,AIR)
Block(2,3,5,AIR)
Block(2,3,6,AIR)
Block(2,3,7,HARD_CLAY)
Block(2,4,-1,HARD_CLAY)
Block(2,4,0,AIR)
Block(2,4,1,AIR)
Block(2,4,2,AIR)
Block(2,4,3,AIR)
Block(2,4,4,AIR)
Block(2,4,5,AIR)
Block(2,4,6,HARD_CLAY)
Block(2,5,-1,HARD_CLAY)
Block(2,5,0,STAINED_CLAY:6)
Block(2,5,1,AIR)
Block(2,5,2,AIR)
Block(2,5,3,AIR)
Block(2,5,4,AIR)
Block(2,5,5,STAINED_CLAY:6)
Block(2,5,6,HARD_CLAY)
Block(2,6,-2,STAINED_CLAY:1)
Block(2,6,-1,HARD_CLAY)
Block(2,6,0,AIR)
Block(2,6,1,AIR)
Block(2,6,2,AIR)
Block(2,6,3,AIR)
Block(2,6,4,AIR)
Block(2,6,5,AIR)
Block(2,6,6,HARD_CLAY)
Block(2,6,7,STAINED_CLAY:1)
Block(2,7,0,HARD_CLAY)
Block(2,7,1,AIR)
Block(2,7,2,AIR)
Block(2,7,3,AIR)
Block(2,7,4,AIR)
Block(2,7,5,HARD_CLAY)
Block(2,8,0,HARD_CLAY)
Block(2,8,1,AIR)
Block(2,8,2,AIR)
Block(2,8,3,AIR)
Block(2,8,4,AIR)
Block(2,8,5,HARD_CLAY)
Block(2,9,0,HARD_CLAY)
Block(2,9,1,AIR)
Block(2,9,2,AIR)
Block(2,9,3,AIR)
Block(2,9,4,AIR)
Block(2,9,5,HARD_CLAY)
Block(2,10,1,STAINED_CLAY:1)
Block(2,10,2,HARD_CLAY)
Block(2,10,3,HARD_CLAY)
Block(2,10,4,STAINED_CLAY:1)
Block(2,11,1,STAINED_CLAY:1)
Block(2,11,2,HARD_CLAY)
Block(2,11,3,HARD_CLAY)
Block(2,11,4,STAINED_CLAY:1)
Block(2,12,0,STAINED_CLAY:1)
Block(2,12,1,STAINED_CLAY:1)
Block(2,12,2,HARD_CLAY)
Block(2,12,3,HARD_CLAY)
Block(2,12,4,STAINED_CLAY:1)
Block(2,12,5,STAINED_CLAY:1)
Block(3,-10,-4,HARD_CLAY)
Block(3,-10,-3,STAINED_CLAY:1)
Block(3,-10,-2,STAINED_CLAY:1)
Block(3,-10,-1,STAINED_CLAY:1)
Block(3,-10,0,STAINED_CLAY:1)
Block(3,-10,1,STAINED_CLAY:1)
Block(3,-10,2,STAINED_CLAY:6)
Block(3,-10,3,STAINED_CLAY:6)
Block(3,-10,4,STAINED_CLAY:1)
Block(3,-10,5,STAINED_CLAY:1)
Block(3,-10,6,STAINED_CLAY:1)
Block(3,-10,7,STAINED_CLAY:1)
Block(3,-10,8,STAINED_CLAY:1)
Block(3,-10,9,HARD_CLAY)
Block(3,-9,-4,HARD_CLAY)
Block(3,-9,-3,STAINED_CLAY:1)
Block(3,-9,-2,AIR)
RandomBlock(3,-9,-1,CHEST,../../nbt/VanillaLoot/desert_pyramid.nbt,50,CHEST,../../nbt/VanillaLoot/desert_pyramid.nbt,100)
Block(3,-9,0,STAINED_CLAY:1)
Block(3,-9,1,STAINED_CLAY:1)
Block(3,-9,2,AIR)
Block(3,-9,3,AIR)
Block(3,-9,4,STAINED_CLAY:1)
Block(3,-9,5,STAINED_CLAY:1)
Block(3,-9,6,STAINED_CLAY:1)
Block(3,-9,7,STAINED_CLAY:1)
Block(3,-9,8,STAINED_CLAY:1)
Block(3,-9,9,HARD_CLAY)
Block(3,-8,-4,HARD_CLAY)
Block(3,-8,-3,STAINED_CLAY:1)
Block(3,-8,-2,AIR)
Block(3,-8,-1,AIR)
Block(3,-8,0,STAINED_CLAY:1)
Block(3,-8,1,STAINED_CLAY:1)
Block(3,-8,2,AIR)
Block(3,-8,3,AIR)
Block(3,-8,4,STAINED_CLAY:1)
Block(3,-8,5,STAINED_CLAY:1)
Block(3,-8,6,STAINED_CLAY:1)
Block(3,-8,7,STAINED_CLAY:1)
Block(3,-8,8,STAINED_CLAY:1)
Block(3,-8,9,HARD_CLAY)
Block(3,-7,-4,HARD_CLAY)
Block(3,-7,-3,STAINED_CLAY:1)
Block(3,-7,-2,STAINED_CLAY:1)
Block(3,-7,-1,STAINED_CLAY:1)
Block(3,-7,0,STAINED_CLAY:1)
Block(3,-7,1,STAINED_CLAY:1)
Block(3,-7,2,STAINED_CLAY:1)
Block(3,-7,3,STAINED_CLAY:1)
Block(3,-7,4,STAINED_CLAY:1)
Block(3,-7,5,STAINED_CLAY:1)
Block(3,-7,6,STAINED_CLAY:1)
Block(3,-7,7,STAINED_CLAY:1)
Block(3,-7,8,STAINED_CLAY:1)
Block(3,-7,9,HARD_CLAY)
Block(3,-6,-4,HARD_CLAY)
Block(3,-6,-3,STAINED_CLAY:1)
Block(3,-6,-2,STAINED_CLAY:1)
Block(3,-6,-1,STAINED_CLAY:1)
Block(3,-6,0,STAINED_CLAY:1)
Block(3,-6,1,STAINED_CLAY:1)
Block(3,-6,2,STAINED_CLAY:1)
Block(3,-6,3,STAINED_CLAY:1)
Block(3,-6,4,STAINED_CLAY:1)
Block(3,-6,5,STAINED_CLAY:1)
Block(3,-6,6,STAINED_CLAY:1)
Block(3,-6,7,STAINED_CLAY:1)
Block(3,-6,8,STAINED_CLAY:1)
Block(3,-6,9,HARD_CLAY)
Block(3,-5,-4,HARD_CLAY)
Block(3,-5,-3,STAINED_CLAY:1)
Block(3,-5,-2,STAINED_CLAY:1)
Block(3,-5,-1,STAINED_CLAY:1)
Block(3,-5,0,STAINED_CLAY:1)
Block(3,-5,1,STAINED_CLAY:1)
Block(3,-5,2,STAINED_CLAY:1)
Block(3,-5,3,STAINED_CLAY:1)
Block(3,-5,4,STAINED_CLAY:1)
Block(3,-5,5,STAINED_CLAY:1)
Block(3,-5,6,STAINED_CLAY:1)
Block(3,-5,7,STAINED_CLAY:1)
Block(3,-5,8,STAINED_CLAY:1)
Block(3,-5,9,HARD_CLAY)
Block(3,-4,-4,HARD_CLAY)
Block(3,-4,-3,STAINED_CLAY:1)
Block(3,-4,-2,AIR)
Block(3,-4,-1,AIR)
Block(3,-4,0,AIR)
Block(3,-4,1,AIR)
Block(3,-4,2,AIR)
Block(3,-4,3,AIR)
Block(3,-4,4,AIR)
Block(3,-4,5,AIR)
Block(3,-4,6,AIR)
Block(3,-4,8,STAINED_CLAY:1)
Block(3,-4,9,HARD_CLAY)
Block(3,-3,-4,HARD_CLAY)
Block(3,-3,-3,STAINED_CLAY:1)
Block(3,-3,-2,AIR)
Block(3,-3,-1,AIR)
Block(3,-3,0,AIR)
Block(3,-3,1,AIR)
Block(3,-3,2,AIR)
Block(3,-3,3,AIR)
Block(3,-3,4,AIR)
Block(3,-3,5,AIR)
Block(3,-3,6,AIR)
Block(3,-3,8,STAINED_CLAY:1)
Block(3,-3,9,HARD_CLAY)
Block(3,-2,-4,HARD_CLAY)
Block(3,-2,-3,STAINED_CLAY:1)
Block(3,-2,-2,AIR)
Block(3,-2,-1,AIR)
Block(3,-2,0,AIR)
Block(3,-2,1,AIR)
Block(3,-2,2,AIR)
Block(3,-2,3,AIR)
Block(3,-2,4,AIR)
Block(3,-2,5,AIR)
Block(3,-2,6,AIR)
Block(3,-2,8,STAINED_CLAY:1)
Block(3,-2,9,HARD_CLAY)
Block(3,-1,-4,HARD_CLAY)
Block(3,-1,-3,STAINED_CLAY:1)
Block(3,-1,-2,STAINED_CLAY:1)
Block(3,-1,-1,STAINED_CLAY:1)
Block(3,-1,0,STAINED_CLAY:1)
Block(3,-1,1,STAINED_CLAY:1)
Block(3,-1,2,STAINED_CLAY:1)
Block(3,-1,3,STAINED_CLAY:1)
Block(3,-1,4,STAINED_CLAY:1)
Block(3,-1,5,STAINED_CLAY:1)
Block(3,-1,6,STAINED_CLAY:1)
Block(3,-1,7,HARD_CLAY)
Block(3,-1,8,STAINED_CLAY:1)
Block(3,-1,9,HARD_CLAY)
Block(3,0,-3,AIR)
Block(3,0,-2,AIR)
Block(3,0,-1,AIR)
Block(3,0,0,AIR)
Block(3,0,1,AIR)
Block(3,0,2,AIR)
Block(3,0,3,AIR)
Block(3,0,4,AIR)
Block(3,0,6,AIR)
Block(3,0,7,AIR)
Block(3,0,8,STAINED_CLAY:1)
Block(3,1,-3,AIR)
Block(3,1,-2,AIR)
Block(3,1,-1,AIR)
Block(3,1,0,AIR)
Block(3,1,1,AIR)
Block(3,1,2,AIR)
Block(3,1,3,AIR)
Block(3,1,4,AIR)
Block(3,1,5,AIR)
Block(3,1,6,AIR)
Block(3,1,7,AIR)
Block(3,1,8,STAINED_CLAY:1)
Block(3,2,-4,STAINED_CLAY:1)
Block(3,2,-3,STAINED_CLAY:1)
Block(3,2,-2,AIR)
Block(3,2,-1,AIR)
Block(3,2,0,AIR)
Block(3,2,1,AIR)
Block(3,2,2,AIR)
Block(3,2,3,AIR)
Block(3,2,4,AIR)
Block(3,2,5,AIR)
Block(3,2,6,AIR)
Block(3,2,7,AIR)
Block(3,2,8,STAINED_CLAY:1)
Block(3,3,-2,HARD_CLAY)
Block(3,3,-1,AIR)
Block(3,3,0,AIR)
Block(3,3,1,AIR)
Block(3,3,2,AIR)
Block(3,3,3,AIR)
Block(3,3,4,AIR)
Block(3,3,5,AIR)
Block(3,3,6,AIR)
Block(3,3,7,HARD_CLAY)
Block(3,4,-1,HARD_CLAY)
Block(3,4,0,AIR)
Block(3,4,1,AIR)
Block(3,4,2,AIR)
Block(3,4,3,AIR)
Block(3,4,4,AIR)
Block(3,4,5,AIR)
Block(3,4,6,HARD_CLAY)
Block(3,5,-1,HARD_CLAY)
Block(3,5,0,STAINED_CLAY:6)
Block(3,5,1,STAINED_CLAY:6)
Block(3,5,2,STAINED_CLAY:6)
Block(3,5,3,STAINED_CLAY:6)
Block(3,5,4,STAINED_CLAY:6)
Block(3,5,5,STAINED_CLAY:6)
Block(3,5,6,HARD_CLAY)
Block(3,6,-2,STAINED_CLAY:1)
Block(3,6,-1,HARD_CLAY)
Block(3,6,0,AIR)
Block(3,6,1,AIR)
Block(3,6,2,AIR)
Block(3,6,3,AIR)
Block(3,6,4,AIR)
Block(3,6,6,HARD_CLAY)
Block(3,6,7,STAINED_CLAY:1)
Block(3,7,0,STAINED_CLAY:1)
Block(3,7,1,HARD_CLAY)
Block(3,7,2,HARD_CLAY)
Block(3,7,3,HARD_CLAY)
Block(3,7,4,HARD_CLAY)
Block(3,7,5,STAINED_CLAY:1)
Block(3,8,0,STAINED_CLAY:1)
Block(3,8,1,HARD_CLAY)
Block(3,8,2,STAINED_CLAY:6)
Block(3,8,3,STAINED_CLAY:6)
Block(3,8,4,HARD_CLAY)
Block(3,8,5,STAINED_CLAY:1)
Block(3,9,1,HARD_CLAY)
Block(3,9,2,HARD_CLAY)
Block(3,9,3,HARD_CLAY)
Block(3,9,4,HARD_CLAY)
Block(3,12,1,STAINED_CLAY:1)
Block(3,12,4,STAINED_CLAY:1)
Block(4,-10,-4,HARD_CLAY)
Block(4,-10,-3,STAINED_CLAY:1)
Block(4,-10,-2,STAINED_CLAY:1)
Block(4,-10,-1,STAINED_CLAY:1)
Block(4,-10,0,STAINED_CLAY:1)
Block(4,-10,1,STAINED_CLAY:1)
Block(4,-10,2,STAINED_CLAY:6)
Block(4,-10,3,STAINED_CLAY:6)
Block(4,-10,4,STAINED_CLAY:1)
Block(4,-10,5,STAINED_CLAY:1)
Block(4,-10,6,STAINED_CLAY:1)
Block(4,-10,7,STAINED_CLAY:1)
Block(4,-10,8,STAINED_CLAY:1)
Block(4,-10,9,HARD_CLAY)
Block(4,-9,-4,HARD_CLAY)
Block(4,-9,-3,STAINED_CLAY:1)
Block(4,-9,-2,STAINED_CLAY:1)
Block(4,-9,-1,STAINED_CLAY:1)
Block(4,-9,0,STAINED_CLAY:1)
Block(4,-9,1,STAINED_CLAY:1)
Block(4,-9,2,AIR)
Block(4,-9,3,AIR)
Block(4,-9,4,STAINED_CLAY:1)
Block(4,-9,5,STAINED_CLAY:1)
Block(4,-9,6,STAINED_CLAY:1)
Block(4,-9,7,STAINED_CLAY:1)
Block(4,-9,8,STAINED_CLAY:1)
Block(4,-9,9,HARD_CLAY)
Block(4,-8,-4,HARD_CLAY)
Block(4,-8,-3,STAINED_CLAY:1)
Block(4,-8,-2,STAINED_CLAY:1)
Block(4,-8,-1,STAINED_CLAY:1)
Block(4,-8,0,STAINED_CLAY:1)
Block(4,-8,1,STAINED_CLAY:1)
Block(4,-8,2,AIR)
Block(4,-8,3,AIR)
Block(4,-8,4,STAINED_CLAY:1)
Block(4,-8,5,STAINED_CLAY:1)
Block(4,-8,6,STAINED_CLAY:1)
Block(4,-8,7,STAINED_CLAY:1)
Block(4,-8,8,STAINED_CLAY:1)
Block(4,-8,9,HARD_CLAY)
Block(4,-7,-4,HARD_CLAY)
Block(4,-7,-3,STAINED_CLAY:1)
Block(4,-7,-2,STAINED_CLAY:1)
Block(4,-7,-1,STAINED_CLAY:1)
Block(4,-7,0,STAINED_CLAY:1)
Block(4,-7,1,STAINED_CLAY:1)
Block(4,-7,2,STAINED_CLAY:1)
Block(4,-7,3,STAINED_CLAY:1)
Block(4,-7,4,STAINED_CLAY:1)
Block(4,-7,5,STAINED_CLAY:1)
Block(4,-7,6,STAINED_CLAY:1)
Block(4,-7,7,STAINED_CLAY:1)
Block(4,-7,8,STAINED_CLAY:1)
Block(4,-7,9,HARD_CLAY)
Block(4,-6,-4,HARD_CLAY)
Block(4,-6,-3,STAINED_CLAY:1)
Block(4,-6,-2,STAINED_CLAY:1)
Block(4,-6,-1,STAINED_CLAY:1)
Block(4,-6,0,STAINED_CLAY:1)
Block(4,-6,1,STAINED_CLAY:1)
Block(4,-6,2,STAINED_CLAY:1)
Block(4,-6,3,STAINED_CLAY:1)
Block(4,-6,4,STAINED_CLAY:1)
Block(4,-6,5,STAINED_CLAY:1)
Block(4,-6,6,STAINED_CLAY:1)
Block(4,-6,7,STAINED_CLAY:1)
Block(4,-6,8,STAINED_CLAY:1)
Block(4,-6,9,HARD_CLAY)
Block(4,-5,-4,HARD_CLAY)
Block(4,-5,-3,STAINED_CLAY:1)
Block(4,-5,-2,STAINED_CLAY:1)
Block(4,-5,-1,STAINED_CLAY:1)
Block(4,-5,0,STAINED_CLAY:1)
Block(4,-5,1,STAINED_CLAY:1)
Block(4,-5,2,STAINED_CLAY:1)
Block(4,-5,3,STAINED_CLAY:1)
Block(4,-5,4,STAINED_CLAY:1)
Block(4,-5,5,STAINED_CLAY:1)
Block(4,-5,6,STAINED_CLAY:1)
Block(4,-5,7,STAINED_CLAY:1)
Block(4,-5,8,STAINED_CLAY:1)
Block(4,-5,9,HARD_CLAY)
Block(4,-4,-4,HARD_CLAY)
Block(4,-4,-3,STAINED_CLAY:1)
Block(4,-4,-2,AIR)
Block(4,-4,-1,AIR)
Block(4,-4,0,AIR)
Block(4,-4,1,AIR)
Block(4,-4,2,AIR)
Block(4,-4,3,AIR)
Block(4,-4,4,AIR)
Block(4,-4,5,AIR)
Block(4,-4,6,AIR)
Block(4,-4,8,STAINED_CLAY:1)
Block(4,-4,9,HARD_CLAY)
Block(4,-3,-4,HARD_CLAY)
Block(4,-3,-3,STAINED_CLAY:1)
Block(4,-3,-2,AIR)
Block(4,-3,-1,AIR)
Block(4,-3,0,AIR)
Block(4,-3,1,AIR)
Block(4,-3,2,AIR)
Block(4,-3,3,AIR)
Block(4,-3,4,AIR)
Block(4,-3,5,AIR)
Block(4,-3,6,AIR)
Block(4,-3,8,STAINED_CLAY:1)
Block(4,-3,9,HARD_CLAY)
Block(4,-2,-4,HARD_CLAY)
Block(4,-2,-3,STAINED_CLAY:1)
Block(4,-2,-2,AIR)
Block(4,-2,-1,AIR)
Block(4,-2,0,AIR)
Block(4,-2,1,AIR)
Block(4,-2,2,AIR)
Block(4,-2,3,AIR)
Block(4,-2,4,AIR)
Block(4,-2,5,AIR)
Block(4,-2,6,AIR)
Block(4,-2,8,STAINED_CLAY:1)
Block(4,-2,9,HARD_CLAY)
Block(4,-1,-4,HARD_CLAY)
Block(4,-1,-3,STAINED_CLAY:1)
Block(4,-1,-2,STAINED_CLAY:1)
Block(4,-1,-1,STAINED_CLAY:1)
Block(4,-1,0,STAINED_CLAY:1)
Block(4,-1,1,STAINED_CLAY:1)
Block(4,-1,2,STAINED_CLAY:1)
Block(4,-1,3,STAINED_CLAY:1)
Block(4,-1,4,STAINED_CLAY:1)
Block(4,-1,5,STAINED_CLAY:1)
Block(4,-1,6,STAINED_CLAY:1)
Block(4,-1,7,HARD_CLAY)
Block(4,-1,8,STAINED_CLAY:1)
Block(4,-1,9,HARD_CLAY)
Block(4,0,-3,STAINED_CLAY:1)
Block(4,0,-2,AIR)
Block(4,0,-1,AIR)
Block(4,0,0,AIR)
Block(4,0,1,AIR)
Block(4,0,2,AIR)
Block(4,0,3,AIR)
Block(4,0,4,AIR)
Block(4,0,5,AIR)
Block(4,0,6,AIR)
Block(4,0,7,AIR)
Block(4,0,8,STAINED_CLAY:1)
Block(4,0,9,STAINED_CLAY:1)
Block(4,1,-3,STAINED_CLAY:1)
Block(4,1,-2,AIR)
Block(4,1,-1,AIR)
Block(4,1,0,AIR)
Block(4,1,1,AIR)
Block(4,1,2,AIR)
Block(4,1,3,AIR)
Block(4,1,4,AIR)
Block(4,1,5,AIR)
Block(4,1,6,AIR)
Block(4,1,7,AIR)
Block(4,1,8,STAINED_CLAY:1)
Block(4,1,9,STAINED_CLAY:1)
Block(4,2,-3,STAINED_CLAY:1)
Block(4,2,-2,HARD_CLAY)
Block(4,2,-1,AIR)
Block(4,2,0,AIR)
Block(4,2,1,AIR)
Block(4,2,2,AIR)
Block(4,2,3,AIR)
Block(4,2,4,AIR)
Block(4,2,5,AIR)
Block(4,2,6,AIR)
Block(4,2,7,HARD_CLAY)
Block(4,2,8,STAINED_CLAY:1)
Block(4,2,9,STAINED_CLAY:1)
Block(4,3,-2,HARD_CLAY)
Block(4,3,-1,AIR)
Block(4,3,0,AIR)
Block(4,3,1,AIR)
Block(4,3,2,AIR)
Block(4,3,3,AIR)
Block(4,3,4,AIR)
Block(4,3,5,AIR)
Block(4,3,6,AIR)
Block(4,3,7,HARD_CLAY)
Block(4,4,-1,STAINED_CLAY:1)
Block(4,4,0,HARD_CLAY)
Block(4,4,1,HARD_CLAY)
Block(4,4,2,HARD_CLAY)
Block(4,4,3,HARD_CLAY)
Block(4,4,4,HARD_CLAY)
Block(4,4,5,HARD_CLAY)
Block(4,4,6,STAINED_CLAY:1)
Block(4,5,-1,STAINED_CLAY:1)
Block(4,5,0,HARD_CLAY)
Block(4,5,1,HARD_CLAY)
Block(4,5,2,STAINED_CLAY:6)
Block(4,5,3,STAINED_CLAY:6)
Block(4,5,4,HARD_CLAY)
Block(4,5,5,HARD_CLAY)
Block(4,5,6,STAINED_CLAY:1)
Block(4,6,-2,STAINED_CLAY:1)
Block(4,6,-1,STAINED_CLAY:1)
Block(4,6,0,HARD_CLAY)
Block(4,6,1,HARD_CLAY)
Block(4,6,2,HARD_CLAY)
Block(4,6,3,HARD_CLAY)
Block(4,6,4,HARD_CLAY)
Block(4,6,5,HARD_CLAY)
Block(4,6,6,STAINED_CLAY:1)
Block(4,6,7,STAINED_CLAY:1)
Block(5,-10,-4,HARD_CLAY)
Block(5,-10,-3,STAINED_CLAY:1)
Block(5,-10,-2,STAINED_CLAY:1)
Block(5,-10,-1,STAINED_CLAY:1)
Block(5,-10,0,STAINED_CLAY:1)
Block(5,-10,1,STAINED_CLAY:1)
Block(5,-10,2,STAINED_CLAY:6)
Block(5,-10,3,STAINED_CLAY:6)
Block(5,-10,4,STAINED_CLAY:1)
Block(5,-10,5,STAINED_CLAY:1)
Block(5,-10,6,STAINED_CLAY:1)
Block(5,-10,7,STAINED_CLAY:1)
Block(5,-10,8,STAINED_CLAY:1)
Block(5,-10,9,HARD_CLAY)
Block(5,-9,-4,HARD_CLAY)
Block(5,-9,-3,STAINED_CLAY:1)
Block(5,-9,-2,STAINED_CLAY:1)
Block(5,-9,-1,STAINED_CLAY:1)
Block(5,-9,0,STAINED_CLAY:1)
Block(5,-9,1,AIR)
Block(5,-9,2,AIR)
Block(5,-9,3,AIR)
Block(5,-9,4,AIR)
Block(5,-9,5,STAINED_CLAY:1)
Block(5,-9,6,STAINED_CLAY:1)
Block(5,-9,7,STAINED_CLAY:1)
Block(5,-9,8,STAINED_CLAY:1)
Block(5,-9,9,HARD_CLAY)
Block(5,-8,-4,HARD_CLAY)
Block(5,-8,-3,STAINED_CLAY:1)
Block(5,-8,-2,STAINED_CLAY:1)
Block(5,-8,-1,STAINED_CLAY:1)
Block(5,-8,0,STAINED_CLAY:1)
Block(5,-8,1,AIR)
Block(5,-8,2,AIR)
Block(5,-8,3,AIR)
Block(5,-8,4,AIR)
Block(5,-8,5,STAINED_CLAY:1)
Block(5,-8,6,STAINED_CLAY:1)
Block(5,-8,7,STAINED_CLAY:1)
Block(5,-8,8,STAINED_CLAY:1)
Block(5,-8,9,HARD_CLAY)
Block(5,-7,-4,HARD_CLAY)
Block(5,-7,-3,STAINED_CLAY:1)
Block(5,-7,-2,STAINED_CLAY:1)
Block(5,-7,-1,STAINED_CLAY:1)
Block(5,-7,0,STAINED_CLAY:1)
Block(5,-7,1,STAINED_CLAY:1)
Block(5,-7,2,STAINED_CLAY:1)
Block(5,-7,3,STAINED_CLAY:1)
Block(5,-7,4,STAINED_CLAY:1)
Block(5,-7,5,STAINED_CLAY:1)
Block(5,-7,6,STAINED_CLAY:1)
Block(5,-7,7,STAINED_CLAY:1)
Block(5,-7,8,STAINED_CLAY:1)
Block(5,-7,9,HARD_CLAY)
Block(5,-6,-4,HARD_CLAY)
Block(5,-6,-3,STAINED_CLAY:1)
Block(5,-6,-2,STAINED_CLAY:1)
Block(5,-6,-1,STAINED_CLAY:1)
Block(5,-6,0,STAINED_CLAY:1)
Block(5,-6,1,STAINED_CLAY:1)
Block(5,-6,2,STAINED_CLAY:1)
Block(5,-6,3,STAINED_CLAY:1)
Block(5,-6,4,STAINED_CLAY:1)
Block(5,-6,5,STAINED_CLAY:1)
Block(5,-6,6,STAINED_CLAY:1)
Block(5,-6,7,STAINED_CLAY:1)
Block(5,-6,8,STAINED_CLAY:1)
Block(5,-6,9,HARD_CLAY)
Block(5,-5,-4,HARD_CLAY)
Block(5,-5,-3,STAINED_CLAY:1)
Block(5,-5,-2,STAINED_CLAY:1)
Block(5,-5,-1,STAINED_CLAY:1)
Block(5,-5,0,STAINED_CLAY:1)
Block(5,-5,1,STAINED_CLAY:1)
Block(5,-5,2,STAINED_CLAY:1)
Block(5,-5,3,STAINED_CLAY:1)
Block(5,-5,4,STAINED_CLAY:1)
Block(5,-5,5,STAINED_CLAY:1)
Block(5,-5,6,STAINED_CLAY:1)
Block(5,-5,7,STAINED_CLAY:1)
Block(5,-5,8,STAINED_CLAY:1)
Block(5,-5,9,HARD_CLAY)
Block(5,-4,-4,HARD_CLAY)
Block(5,-4,-3,HARD_CLAY)
Block(5,-4,-2,HARD_CLAY)
Block(5,-4,-1,AIR)
Block(5,-4,0,AIR)
Block(5,-4,1,AIR)
Block(5,-4,2,AIR)
Block(5,-4,3,AIR)
Block(5,-4,4,AIR)
Block(5,-4,5,AIR)
Block(5,-4,6,AIR)
Block(5,-4,7,HARD_CLAY)
Block(5,-4,8,HARD_CLAY)
Block(5,-4,9,HARD_CLAY)
Block(5,-3,-4,HARD_CLAY)
Block(5,-3,-3,HARD_CLAY)
Block(5,-3,-2,HARD_CLAY)
Block(5,-3,-1,AIR)
Block(5,-3,0,AIR)
Block(5,-3,1,AIR)
Block(5,-3,2,AIR)
Block(5,-3,3,AIR)
Block(5,-3,4,AIR)
Block(5,-3,5,AIR)
Block(5,-3,6,AIR)
Block(5,-3,7,HARD_CLAY)
Block(5,-3,8,STAINED_CLAY:1)
Block(5,-3,9,HARD_CLAY)
Block(5,-2,-4,HARD_CLAY)
Block(5,-2,-3,HARD_CLAY)
Block(5,-2,-2,HARD_CLAY)
Block(5,-2,-1,AIR)
Block(5,-2,0,AIR)
Block(5,-2,1,AIR)
Block(5,-2,2,AIR)
Block(5,-2,3,AIR)
Block(5,-2,4,AIR)
Block(5,-2,5,AIR)
Block(5,-2,6,AIR)
Block(5,-2,7,HARD_CLAY)
Block(5,-2,8,STAINED_CLAY:1)
Block(5,-2,9,HARD_CLAY)
Block(5,-1,-4,HARD_CLAY)
Block(5,-1,-3,STAINED_CLAY:1)
Block(5,-1,-2,HARD_CLAY)
Block(5,-1,-1,HARD_CLAY)
Block(5,-1,0,HARD_CLAY)
Block(5,-1,1,HARD_CLAY)
Block(5,-1,2,HARD_CLAY)
Block(5,-1,3,HARD_CLAY)
Block(5,-1,4,HARD_CLAY)
Block(5,-1,5,HARD_CLAY)
Block(5,-1,6,HARD_CLAY)
Block(5,-1,7,HARD_CLAY)
Block(5,-1,8,STAINED_CLAY:1)
Block(5,-1,9,HARD_CLAY)
Block(5,0,-3,STAINED_CLAY:1)
Block(5,0,-2,HARD_CLAY)
Block(5,0,-1,AIR)
Block(5,0,0,AIR)
Block(5,0,1,AIR)
Block(5,0,2,AIR)
Block(5,0,3,AIR)
Block(5,0,4,AIR)
Block(5,0,5,AIR)
Block(5,0,6,AIR)
Block(5,0,7,HARD_CLAY)
Block(5,0,8,STAINED_CLAY:1)
Block(5,1,-3,STAINED_CLAY:1)
Block(5,1,-2,HARD_CLAY)
Block(5,1,-1,AIR)
Block(5,1,0,AIR)
Block(5,1,1,AIR)
Block(5,1,2,AIR)
Block(5,1,3,AIR)
Block(5,1,4,AIR)
Block(5,1,5,AIR)
Block(5,1,6,AIR)
Block(5,1,7,HARD_CLAY)
Block(5,1,8,STAINED_CLAY:1)
Block(5,2,-3,STAINED_CLAY:1)
Block(5,2,-2,HARD_CLAY)
Block(5,2,-1,HARD_CLAY)
Block(5,2,0,AIR)
Block(5,2,1,AIR)
Block(5,2,2,AIR)
Block(5,2,3,AIR)
Block(5,2,4,AIR)
Block(5,2,5,AIR)
Block(5,2,6,HARD_CLAY)
Block(5,2,7,HARD_CLAY)
Block(5,2,8,STAINED_CLAY:1)
Block(5,3,-2,STAINED_CLAY:1)
Block(5,3,-1,HARD_CLAY)
Block(5,3,0,HARD_CLAY)
Block(5,3,1,HARD_CLAY)
Block(5,3,2,HARD_CLAY)
Block(5,3,3,HARD_CLAY)
Block(5,3,4,HARD_CLAY)
Block(5,3,5,HARD_CLAY)
Block(5,3,6,HARD_CLAY)
Block(5,3,7,STAINED_CLAY:1)
Block(5,6,-1,STAINED_CLAY:1)
Block(5,6,0,STAINED_CLAY:1)
Block(5,6,1,STAINED_CLAY:1)
Block(5,6,2,STAINED_CLAY:1)
Block(5,6,3,STAINED_CLAY:1)
Block(5,6,4,STAINED_CLAY:1)
Block(5,6,5,STAINED_CLAY:1)
Block(5,6,6,STAINED_CLAY:1)
Block(6,-10,-4,HARD_CLAY)
Block(6,-10,-3,HARD_CLAY)
Block(6,-10,-2,STAINED_CLAY:1)
Block(6,-10,-1,STAINED_CLAY:1)
Block(6,-10,0,STAINED_CLAY:1)
Block(6,-10,1,STAINED_CLAY:1)
Block(6,-10,2,STAINED_CLAY:1)
Block(6,-10,3,STAINED_CLAY:1)
Block(6,-10,4,STAINED_CLAY:1)
Block(6,-10,5,STAINED_CLAY:1)
Block(6,-10,6,STAINED_CLAY:1)
Block(6,-10,7,STAINED_CLAY:1)
Block(6,-10,8,HARD_CLAY)
Block(6,-10,9,HARD_CLAY)
Block(6,-9,-4,HARD_CLAY)
Block(6,-9,-3,HARD_CLAY)
Block(6,-9,-2,STAINED_CLAY:1)
Block(6,-9,-1,STAINED_CLAY:1)
Block(6,-9,0,STAINED_CLAY:1)
Block(6,-9,1,STAINED_CLAY:1)
Block(6,-9,2,STAINED_CLAY:6)
Block(6,-9,3,STAINED_CLAY:6)
Block(6,-9,4,STAINED_CLAY:1)
Block(6,-9,5,STAINED_CLAY:1)
Block(6,-9,6,STAINED_CLAY:1)
Block(6,-9,7,STAINED_CLAY:1)
Block(6,-9,8,HARD_CLAY)
Block(6,-9,9,HARD_CLAY)
Block(6,-8,-4,HARD_CLAY)
Block(6,-8,-3,HARD_CLAY)
Block(6,-8,-2,STAINED_CLAY:1)
Block(6,-8,-1,STAINED_CLAY:1)
Block(6,-8,0,STAINED_CLAY:1)
Block(6,-8,1,STAINED_CLAY:1)
Block(6,-8,2,STAINED_CLAY:6)
Block(6,-8,3,STAINED_CLAY:6)
Block(6,-8,4,STAINED_CLAY:1)
Block(6,-8,5,STAINED_CLAY:1)
Block(6,-8,6,STAINED_CLAY:1)
Block(6,-8,7,STAINED_CLAY:1)
Block(6,-8,8,HARD_CLAY)
Block(6,-8,9,HARD_CLAY)
Block(6,-7,-4,HARD_CLAY)
Block(6,-7,-3,HARD_CLAY)
Block(6,-7,-2,STAINED_CLAY:1)
Block(6,-7,-1,STAINED_CLAY:1)
Block(6,-7,0,STAINED_CLAY:1)
Block(6,-7,1,STAINED_CLAY:1)
Block(6,-7,2,STAINED_CLAY:1)
Block(6,-7,3,STAINED_CLAY:1)
Block(6,-7,4,STAINED_CLAY:1)
Block(6,-7,5,STAINED_CLAY:1)
Block(6,-7,6,STAINED_CLAY:1)
Block(6,-7,7,STAINED_CLAY:1)
Block(6,-7,8,HARD_CLAY)
Block(6,-7,9,HARD_CLAY)
Block(6,-6,-4,HARD_CLAY)
Block(6,-6,-3,HARD_CLAY)
Block(6,-6,-2,STAINED_CLAY:1)
Block(6,-6,-1,STAINED_CLAY:1)
Block(6,-6,0,STAINED_CLAY:1)
Block(6,-6,1,STAINED_CLAY:1)
Block(6,-6,2,STAINED_CLAY:1)
Block(6,-6,3,STAINED_CLAY:1)
Block(6,-6,4,STAINED_CLAY:1)
Block(6,-6,5,STAINED_CLAY:1)
Block(6,-6,6,STAINED_CLAY:1)
Block(6,-6,7,STAINED_CLAY:1)
Block(6,-6,8,HARD_CLAY)
Block(6,-6,9,HARD_CLAY)
Block(6,-5,-4,HARD_CLAY)
Block(6,-5,-3,HARD_CLAY)
Block(6,-5,-2,STAINED_CLAY:1)
Block(6,-5,-1,STAINED_CLAY:1)
Block(6,-5,0,STAINED_CLAY:1)
Block(6,-5,1,STAINED_CLAY:1)
Block(6,-5,2,STAINED_CLAY:1)
Block(6,-5,3,STAINED_CLAY:1)
Block(6,-5,4,STAINED_CLAY:1)
Block(6,-5,5,STAINED_CLAY:1)
Block(6,-5,6,STAINED_CLAY:1)
Block(6,-5,7,STAINED_CLAY:1)
Block(6,-5,8,HARD_CLAY)
Block(6,-5,9,HARD_CLAY)
Block(6,-4,-4,HARD_CLAY)
Block(6,-4,-3,HARD_CLAY)
Block(6,-4,-2,HARD_CLAY)
Block(6,-4,-1,STAINED_CLAY:1)
Block(6,-4,0,STAINED_CLAY:1)
Block(6,-4,1,STAINED_CLAY:1)
Block(6,-4,2,STAINED_CLAY:1)
Block(6,-4,3,STAINED_CLAY:1)
Block(6,-4,4,STAINED_CLAY:1)
Block(6,-4,5,STAINED_CLAY:1)
Block(6,-4,6,STAINED_CLAY:1)
Block(6,-4,7,HARD_CLAY)
Block(6,-4,8,HARD_CLAY)
Block(6,-4,9,HARD_CLAY)
Block(6,-3,-4,HARD_CLAY)
Block(6,-3,-3,HARD_CLAY)
Block(6,-3,-2,HARD_CLAY)
Block(6,-3,-1,STAINED_CLAY:1)
Block(6,-3,0,STAINED_CLAY:1)
Block(6,-3,1,STAINED_CLAY:1)
Block(6,-3,2,STAINED_CLAY:1)
Block(6,-3,3,STAINED_CLAY:1)
Block(6,-3,4,STAINED_CLAY:1)
Block(6,-3,5,STAINED_CLAY:1)
Block(6,-3,6,STAINED_CLAY:1)
Block(6,-3,7,HARD_CLAY)
Block(6,-3,8,HARD_CLAY)
Block(6,-3,9,HARD_CLAY)
Block(6,-2,-4,HARD_CLAY)
Block(6,-2,-3,HARD_CLAY)
Block(6,-2,-2,HARD_CLAY)
Block(6,-2,-1,STAINED_CLAY:1)
Block(6,-2,0,STAINED_CLAY:1)
Block(6,-2,1,STAINED_CLAY:1)
Block(6,-2,2,STAINED_CLAY:1)
Block(6,-2,3,STAINED_CLAY:1)
Block(6,-2,4,STAINED_CLAY:1)
Block(6,-2,5,STAINED_CLAY:1)
Block(6,-2,6,STAINED_CLAY:1)
Block(6,-2,7,HARD_CLAY)
Block(6,-2,8,HARD_CLAY)
Block(6,-2,9,HARD_CLAY)
Block(6,-1,-4,HARD_CLAY)
Block(6,-1,-3,HARD_CLAY)
Block(6,-1,-2,STAINED_CLAY:1)
Block(6,-1,-1,STAINED_CLAY:1)
Block(6,-1,0,STAINED_CLAY:1)
Block(6,-1,1,STAINED_CLAY:1)
Block(6,-1,2,STAINED_CLAY:1)
Block(6,-1,3,STAINED_CLAY:1)
Block(6,-1,4,STAINED_CLAY:1)
Block(6,-1,5,STAINED_CLAY:1)
Block(6,-1,6,STAINED_CLAY:1)
Block(6,-1,7,STAINED_CLAY:1)
Block(6,-1,8,HARD_CLAY)
Block(6,-1,9,HARD_CLAY)
Block(6,0,-2,STAINED_CLAY:1)
Block(6,0,-1,STAINED_CLAY:1)
Block(6,0,0,STAINED_CLAY:1)
Block(6,0,1,STAINED_CLAY:1)
Block(6,0,2,STAINED_CLAY:1)
Block(6,0,3,STAINED_CLAY:1)
Block(6,0,4,STAINED_CLAY:1)
Block(6,0,5,STAINED_CLAY:1)
Block(6,0,6,STAINED_CLAY:1)
Block(6,0,7,STAINED_CLAY:1)
Block(6,1,-2,STAINED_CLAY:1)
Block(6,1,-1,STAINED_CLAY:1)
Block(6,1,0,STAINED_CLAY:1)
Block(6,1,1,STAINED_CLAY:1)
Block(6,1,2,AIR)
Block(6,1,3,AIR)
Block(6,1,4,STAINED_CLAY:1)
Block(6,1,5,STAINED_CLAY:1)
Block(6,1,6,STAINED_CLAY:1)
Block(6,1,7,STAINED_CLAY:1)
Block(6,2,-2,STAINED_CLAY:1)
Block(6,2,-1,STAINED_CLAY:1)
Block(6,2,0,STAINED_CLAY:1)
Block(6,2,1,STAINED_CLAY:1)
Block(6,2,2,STAINED_CLAY:1)
Block(6,2,3,STAINED_CLAY:1)
Block(6,2,4,STAINED_CLAY:1)
Block(6,2,5,STAINED_CLAY:1)
Block(6,2,6,STAINED_CLAY:1)
Block(6,2,7,STAINED_CLAY:1)
Block(7,-10,-3,HARD_CLAY)
Block(7,-10,-2,HARD_CLAY)
Block(7,-10,-1,HARD_CLAY)
Block(7,-10,0,HARD_CLAY)
Block(7,-10,1,HARD_CLAY)
Block(7,-10,2,HARD_CLAY)
Block(7,-10,3,HARD_CLAY)
Block(7,-10,4,HARD_CLAY)
Block(7,-10,5,HARD_CLAY)
Block(7,-10,6,HARD_CLAY)
Block(7,-10,7,HARD_CLAY)
Block(7,-10,8,HARD_CLAY)
Block(7,-9,-3,HARD_CLAY)
Block(7,-9,-2,HARD_CLAY)
Block(7,-9,-1,HARD_CLAY)
Block(7,-9,0,HARD_CLAY)
Block(7,-9,1,HARD_CLAY)
Block(7,-9,2,HARD_CLAY)
Block(7,-9,3,HARD_CLAY)
Block(7,-9,4,HARD_CLAY)
Block(7,-9,5,HARD_CLAY)
Block(7,-9,6,HARD_CLAY)
Block(7,-9,7,HARD_CLAY)
Block(7,-9,8,HARD_CLAY)
Block(7,-8,-3,HARD_CLAY)
Block(7,-8,-2,HARD_CLAY)
Block(7,-8,-1,HARD_CLAY)
Block(7,-8,0,HARD_CLAY)
Block(7,-8,1,HARD_CLAY)
Block(7,-8,2,HARD_CLAY)
Block(7,-8,3,HARD_CLAY)
Block(7,-8,4,HARD_CLAY)
Block(7,-8,5,HARD_CLAY)
Block(7,-8,6,HARD_CLAY)
Block(7,-8,7,HARD_CLAY)
Block(7,-8,8,HARD_CLAY)
Block(7,-7,-3,HARD_CLAY)
Block(7,-7,-2,HARD_CLAY)
Block(7,-7,-1,HARD_CLAY)
Block(7,-7,0,HARD_CLAY)
Block(7,-7,1,HARD_CLAY)
Block(7,-7,2,HARD_CLAY)
Block(7,-7,3,HARD_CLAY)
Block(7,-7,4,HARD_CLAY)
Block(7,-7,5,HARD_CLAY)
Block(7,-7,6,HARD_CLAY)
Block(7,-7,7,HARD_CLAY)
Block(7,-7,8,HARD_CLAY)
Block(7,-6,-3,HARD_CLAY)
Block(7,-6,-2,HARD_CLAY)
Block(7,-6,-1,HARD_CLAY)
Block(7,-6,0,HARD_CLAY)
Block(7,-6,1,HARD_CLAY)
Block(7,-6,2,HARD_CLAY)
Block(7,-6,3,HARD_CLAY)
Block(7,-6,4,HARD_CLAY)
Block(7,-6,5,HARD_CLAY)
Block(7,-6,6,HARD_CLAY)
Block(7,-6,7,HARD_CLAY)
Block(7,-6,8,HARD_CLAY)
Block(7,-5,-3,HARD_CLAY)
Block(7,-5,-2,HARD_CLAY)
Block(7,-5,-1,HARD_CLAY)
Block(7,-5,0,HARD_CLAY)
Block(7,-5,1,HARD_CLAY)
Block(7,-5,2,HARD_CLAY)
Block(7,-5,3,HARD_CLAY)
Block(7,-5,4,HARD_CLAY)
Block(7,-5,5,HARD_CLAY)
Block(7,-5,6,HARD_CLAY)
Block(7,-5,7,HARD_CLAY)
Block(7,-5,8,HARD_CLAY)
Block(7,-4,-3,HARD_CLAY)
Block(7,-4,-2,HARD_CLAY)
Block(7,-4,-1,HARD_CLAY)
Block(7,-4,0,HARD_CLAY)
Block(7,-4,1,HARD_CLAY)
Block(7,-4,2,HARD_CLAY)
Block(7,-4,3,HARD_CLAY)
Block(7,-4,4,HARD_CLAY)
Block(7,-4,5,HARD_CLAY)
Block(7,-4,6,HARD_CLAY)
Block(7,-4,7,HARD_CLAY)
Block(7,-4,8,HARD_CLAY)
Block(7,-3,-3,HARD_CLAY)
Block(7,-3,-2,HARD_CLAY)
Block(7,-3,-1,HARD_CLAY)
Block(7,-3,0,HARD_CLAY)
Block(7,-3,1,HARD_CLAY)
Block(7,-3,2,HARD_CLAY)
Block(7,-3,3,HARD_CLAY)
Block(7,-3,4,HARD_CLAY)
Block(7,-3,5,HARD_CLAY)
Block(7,-3,6,HARD_CLAY)
Block(7,-3,7,HARD_CLAY)
Block(7,-3,8,HARD_CLAY)
Block(7,-2,-3,HARD_CLAY)
Block(7,-2,-2,HARD_CLAY)
Block(7,-2,-1,HARD_CLAY)
Block(7,-2,0,HARD_CLAY)
Block(7,-2,1,HARD_CLAY)
Block(7,-2,2,HARD_CLAY)
Block(7,-2,3,HARD_CLAY)
Block(7,-2,4,HARD_CLAY)
Block(7,-2,5,HARD_CLAY)
Block(7,-2,6,HARD_CLAY)
Block(7,-2,7,HARD_CLAY)
Block(7,-2,8,HARD_CLAY)
Block(7,-1,-3,HARD_CLAY)
Block(7,-1,-2,HARD_CLAY)
Block(7,-1,-1,HARD_CLAY)
Block(7,-1,0,HARD_CLAY)
Block(7,-1,1,HARD_CLAY)
Block(7,-1,2,HARD_CLAY)
Block(7,-1,3,HARD_CLAY)
Block(7,-1,4,HARD_CLAY)
Block(7,-1,5,HARD_CLAY)
Block(7,-1,6,HARD_CLAY)
Block(7,-1,7,HARD_CLAY)
Block(7,-1,8,HARD_CLAY)
Block(7,0,-1,STAINED_CLAY:1)
Block(7,0,2,STAINED_CLAY:1)
Block(7,0,3,STAINED_CLAY:1)
Block(7,0,6,STAINED_CLAY:1)
Block(7,1,-1,STAINED_CLAY:1)
Block(7,1,2,STAINED_CLAY:6)
Block(7,1,3,STAINED_CLAY:6)
Block(7,1,6,STAINED_CLAY:1)
Block(7,2,-1,STAINED_CLAY:1)
Block(7,2,2,STAINED_CLAY:1)
Block(7,2,3,STAINED_CLAY:1)
Block(7,2,6,STAINED_CLAY:1)

#######################################################################
# +-----------------------------------------------------------------+ #
# |                            BO3 checks                           | #
# +-----------------------------------------------------------------+ #
#######################################################################

# Require a condition at a certain location in order for the BO3 to be spawned.
# BlockCheck(x,y,z,BlockName[,BlockName[,...]]) - one of the blocks must be at the location
# BlockCheckNot(x,y,z,BlockName[,BlockName[,...]]) - all the blocks must not be at the location
# LightCheck(x,y,z,minLightLevel,maxLightLevel) - light must be between min and max (inclusive)

# You can use "Solid" as a BlockName for matching all solid blocks or "All" to match all blocks that aren't air.

# Examples:
#   BlockCheck(0,-1,0,GRASS,DIRT)  Require grass or dirt just below the object
#   BlockCheck(0,-1,0,solid)       Require any solid block just below the object
#   BlockCheck(0,-1,0,AIR)        Require any type of wool just below the object
#   BlockCheck(0,-1,0,WOOL:0)      Require white wool just below the object
#   BlockCheckNot(0,0,0,WOOL:0)   Require that there is no white wool below the object
#   LightCheck(0,0,0,0,1)          Require almost complete darkness just below the object
BlockCheck(7,-1,6,HARD_CLAY,STAINED_CLAY:0,STAINED_CLAY:1,STAINED_CLAY:2,STAINED_CLAY:3,STAINED_CLAY:4,STAINED_CLAY:5,STAINED_CLAY:6,STAINED_CLAY:7,STAINED_CLAY:8,STAINED_CLAY:9,STAINED_CLAY:10,STAINED_CLAY:11,STAINED_CLAY:12,STAINED_CLAY:13,STAINED_CLAY:14,STAINED_CLAY:15,SAND,SAND:1,DIRT,DIRT:2,CLAY)
BlockCheck(7,-1,-7,HARD_CLAY,STAINED_CLAY:0,STAINED_CLAY:1,STAINED_CLAY:2,STAINED_CLAY:3,STAINED_CLAY:4,STAINED_CLAY:5,STAINED_CLAY:6,STAINED_CLAY:7,STAINED_CLAY:8,STAINED_CLAY:9,STAINED_CLAY:10,STAINED_CLAY:11,STAINED_CLAY:12,STAINED_CLAY:13,STAINED_CLAY:14,STAINED_CLAY:15,SAND,SAND:1,DIRT,DIRT:2,CLAY)
Blockcheck(6,-1,6,HARD_CLAY,STAINED_CLAY:0,STAINED_CLAY:1,STAINED_CLAY:2,STAINED_CLAY:3,STAINED_CLAY:4,STAINED_CLAY:5,STAINED_CLAY:6,STAINED_CLAY:7,STAINED_CLAY:8,STAINED_CLAY:9,STAINED_CLAY:10,STAINED_CLAY:11,STAINED_CLAY:12,STAINED_CLAY:13,STAINED_CLAY:14,STAINED_CLAY:15,SAND,SAND:1,DIRT,DIRT:2,CLAY)
BlockCheck(6,-1,-7,HARD_CLAY,STAINED_CLAY:0,STAINED_CLAY:1,STAINED_CLAY:2,STAINED_CLAY:3,STAINED_CLAY:4,STAINED_CLAY:5,STAINED_CLAY:6,STAINED_CLAY:7,STAINED_CLAY:8,STAINED_CLAY:9,STAINED_CLAY:10,STAINED_CLAY:11,STAINED_CLAY:12,STAINED_CLAY:13,STAINED_CLAY:14,STAINED_CLAY:15,SAND,SAND:1,DIRT,DIRT:2,CLAY)
#######################################################################
# +-----------------------------------------------------------------+ #
# |                             Branches                            | #
# +-----------------------------------------------------------------+ #
#######################################################################

# Branches are objects that will spawn when this object spawns when it is used in
# the CustomStructure resource. Branches can also have branches, making complex
# structures possible. See the wiki for more details.

# Regular Branches spawn each branch with an independent chance of spawning.
# Branch(x,y,z,branchName,rotation,chance[,anotherBranchName,rotation,chance[,...]][IndividualChance])
# branchName - name of the object to spawn.
# rotation - NORTH, SOUTH, EAST or WEST.
# IndividualChance - The chance each branch has to spawn, assumed to be 100 when left blank

# Weighted Branches spawn branches with a dependent chance of spawning.
# WeightedBranch(x,y,z,branchName,rotation,chance[,anotherBranchName,rotation,chance[,...]][MaxChanceOutOf])
# MaxChanceOutOf - The chance all branches have to spawn out of, assumed to be 100 when left blank
