
#######################################################################
# +-----------------------------------------------------------------+ #
# |                            BO3 object                           | #
# +-----------------------------------------------------------------+ #
#######################################################################

# This is the config file of a custom object.
# If you add this object correctly to your BiomeConfigs, it will spawn in the world.

# This is the creator of this BO3 object
Author: LordSmellyPants

# A short description of this BO3 object
Description: No description given

# The BO3 version, don't change this! It can be used by external applications to do a version check.
Version: 3

# The settings mode, WriteAll, WriteWithoutComments or WriteDisable. See WorldConfig.
SettingsMode: WriteDisable


#######################################################################
# +-----------------------------------------------------------------+ #
# |                          Main settings                          | #
# +-----------------------------------------------------------------+ #
#######################################################################

# This needs to be set to true to spawn the object in the Tree and Sapling resources.
Tree: false

# The frequency of the BO3 from 1 to 200. Tries this many times to spawn this BO3 when using the CustomObject(...) resource.
# Ignored by Tree(..), Sapling(..) and CustomStructure(..)
Frequency: 1

# The rarity of the BO3 from 0 to 100. Each spawn attempt has rarity% chance to succeed when using the CustomObject(...) resource.
# Ignored by Tree(..), Sapling(..) and CustomStructure(..)
Rarity: 100.0

# If you set this to true, the BO3 will be placed with a random rotation.
RotateRandomly: false

# The spawn height of the BO3 - atMinY, randomY, highestBlock or highestSolidBlock.
SpawnHeight: randomY

# The offset from the spawn height to spawn this BO3
# Ex. SpawnHeight = highestSolidBlock, SpawnHeightOffset = 3; This object will spawn 3 blocks above the highest solid block
SpawnHeightOffset: 0

# A random amount to offset the spawn location from the spawn offset height
# Ex. SpawnHeightOffset = 3, SpawnHeightVariance = 3; This object will spawn 3 to 6 blocks above the original spot it would have spawned
SpawnHeightVariance: 0

##############################
# Height Limits for the BO3. #
##############################

# When in randomY mode used as the minimum Y or in atMinY mode as the actual Y to spawn this BO3 at.
MinHeight: 0

# When in randomY mode used as the maximum Y to spawn this BO3 at.
MaxHeight: 256

######################
# Extrusion settings #
######################

# The style of extrusion you wish to use - BottomDown, TopUp, None (Default)
ExtrudeMode: None

# The blocks to extrude your BO3 through
ExtrudeThroughBlocks: AIR

# Objects can have other objects attacthed to it: branches. Branches can also
# have branches attached to it, which can also have branches, etc. This is the
# maximum branch depth for this objects.
MaxBranchDepth: 10

# When spawned with the UseWorld keyword, this BO3 should NOT spawn in the following biomes.
# If you write the BO3 name directly in the BiomeConfigs, this will be ignored.
ExcludedBiomes: All


#######################################################################
# +-----------------------------------------------------------------+ #
# |                      Source block settings                      | #
# +-----------------------------------------------------------------+ #
#######################################################################

# The block(s) the BO3 should spawn in.
SourceBlocks: AIR

# The maximum percentage of the BO3 that can be outside the SourceBlock.
# The BO3 won't be placed on a location with more blocks outside the SourceBlock than this percentage.
MaxPercentageOutsideSourceBlock: 100

# What to do when a block is about to be placed outside the SourceBlock? (dontPlace, placeAnyway)
OutsideSourceBlock: placeAnyway


#######################################################################
# +-----------------------------------------------------------------+ #
# |                              Blocks                             | #
# +-----------------------------------------------------------------+ #
#######################################################################

# All the blocks used in the BO3 are listed here. Possible blocks:
# Block(x,y,z,id[.data][,nbtfile.nbt)
# RandomBlock(x,y,z,id[:data][,nbtfile.nbt],chance[,id[:data][,nbtfile.nbt],chance[,...]])
#  So RandomBlock(0,0,0,CHEST,chest.nbt,50,CHEST,anotherchest.nbt,100) will spawn a chest at
#  the BO3 origin, and give it a 50% chance to have the contents of chest.nbt, or, if that
#  fails, a 100% percent chance to have the contents of anotherchest.nbt.
# MinecraftObject(x,y,z,name)
#  Spawns an object in the Mojang NBT structure format. For example, 
#  MinecraftObject(0,0,0,minecraft:igloo/igloo_bottom)
#  spawns the bottom part of an igloo.
Block(-15,0,-15,PRISMARINE:1)
Block(-15,0,-14,PRISMARINE:1)
Block(-15,0,-13,PRISMARINE:1)
Block(-15,0,-12,PRISMARINE:1)
Block(-15,0,-11,PRISMARINE:1)
Block(-15,0,-10,PRISMARINE:1)
Block(-15,0,-9,PRISMARINE:1)
Block(-15,0,-8,PRISMARINE:1)
Block(-15,0,-7,PRISMARINE:1)
Block(-15,0,-6,PRISMARINE:1)
Block(-15,0,-5,PRISMARINE:1)
Block(-15,0,-4,PRISMARINE:1)
Block(-15,0,-3,PRISMARINE:1)
Block(-15,0,-2,PRISMARINE:1)
Block(-15,0,-1,PRISMARINE:1)
Block(-15,0,0,PRISMARINE:1)
Block(-15,0,1,PRISMARINE:1)
Block(-15,0,2,PRISMARINE:1)
Block(-15,0,3,PRISMARINE:1)
Block(-15,0,4,PRISMARINE:1)
Block(-15,0,5,PRISMARINE:1)
Block(-15,0,6,PRISMARINE:1)
Block(-15,0,7,PRISMARINE:1)
Block(-15,0,8,PRISMARINE:1)
Block(-15,0,9,PRISMARINE:1)
Block(-15,0,10,PRISMARINE:1)
Block(-15,0,11,PRISMARINE:1)
Block(-15,0,12,PRISMARINE:1)
Block(-15,0,13,PRISMARINE:1)
Block(-15,0,14,PRISMARINE:1)
Block(-15,0,15,PRISMARINE:1)
Block(-15,1,-15,PRISMARINE:1)
Block(-15,1,-14,PRISMARINE:1)
Block(-15,1,-13,PRISMARINE:1)
Block(-15,1,-12,PRISMARINE:1)
Block(-15,1,-11,PRISMARINE:1)
Block(-15,1,-10,PRISMARINE:1)
Block(-15,1,-9,PRISMARINE:1)
Block(-15,1,-8,PRISMARINE:1)
Block(-15,1,-7,PRISMARINE:1)
Block(-15,1,-6,PRISMARINE:1)
Block(-15,1,-5,PRISMARINE:1)
Block(-15,1,-4,PRISMARINE:1)
Block(-15,1,-3,PRISMARINE:1)
Block(-15,1,-2,PRISMARINE:1)
Block(-15,1,-1,PRISMARINE:1)
Block(-15,1,0,PRISMARINE:1)
Block(-15,1,1,PRISMARINE:1)
Block(-15,1,2,PRISMARINE:1)
Block(-15,1,3,PRISMARINE:1)
Block(-15,1,4,PRISMARINE:1)
Block(-15,1,5,PRISMARINE:1)
Block(-15,1,6,PRISMARINE:1)
Block(-15,1,7,PRISMARINE:1)
Block(-15,1,8,PRISMARINE:1)
Block(-15,1,9,PRISMARINE:1)
Block(-15,1,10,PRISMARINE:1)
Block(-15,1,11,PRISMARINE:1)
Block(-15,1,12,PRISMARINE:1)
Block(-15,1,13,PRISMARINE:1)
Block(-15,1,14,PRISMARINE:1)
Block(-15,1,15,PRISMARINE:1)
Block(-15,2,-15,PRISMARINE:1)
Block(-15,2,-14,PRISMARINE:1)
Block(-15,2,-13,PRISMARINE:1)
Block(-15,2,-12,PRISMARINE:1)
Block(-15,2,-11,PRISMARINE:1)
Block(-15,2,-10,PRISMARINE:1)
Block(-15,2,-9,PRISMARINE:1)
Block(-15,2,-8,PRISMARINE:1)
Block(-15,2,-7,PRISMARINE:1)
Block(-15,2,-6,PRISMARINE:1)
Block(-15,2,-5,PRISMARINE:1)
Block(-15,2,-4,PRISMARINE:1)
Block(-15,2,-3,PRISMARINE:1)
Block(-15,2,-2,PRISMARINE:1)
Block(-15,2,-1,PRISMARINE:1)
Block(-15,2,0,PRISMARINE:1)
Block(-15,2,1,PRISMARINE:1)
Block(-15,2,2,PRISMARINE:1)
Block(-15,2,3,PRISMARINE:1)
Block(-15,2,4,PRISMARINE:1)
Block(-15,2,5,PRISMARINE:1)
Block(-15,2,6,PRISMARINE:1)
Block(-15,2,7,PRISMARINE:1)
Block(-15,2,8,PRISMARINE:1)
Block(-15,2,9,PRISMARINE:1)
Block(-15,2,10,PRISMARINE:1)
Block(-15,2,11,PRISMARINE:1)
Block(-15,2,12,PRISMARINE:1)
Block(-15,2,13,PRISMARINE:1)
Block(-15,2,14,PRISMARINE:1)
Block(-15,2,15,PRISMARINE:1)
Block(-15,3,-15,PRISMARINE:1)
Block(-15,3,-14,PRISMARINE:1)
Block(-15,3,-13,PRISMARINE:1)
Block(-15,3,-12,PRISMARINE:1)
Block(-15,3,-11,PRISMARINE:1)
Block(-15,3,-10,PRISMARINE:1)
Block(-15,3,-9,PRISMARINE:1)
Block(-15,3,-8,PRISMARINE:1)
Block(-15,3,-7,PRISMARINE:1)
Block(-15,3,-6,PRISMARINE:1)
Block(-15,3,-5,PRISMARINE:1)
Block(-15,3,-4,PRISMARINE:1)
Block(-15,3,-3,PRISMARINE:1)
Block(-15,3,-2,PRISMARINE:1)
Block(-15,3,-1,PRISMARINE:1)
Block(-15,3,0,PRISMARINE:1)
Block(-15,3,1,PRISMARINE:1)
Block(-15,3,2,PRISMARINE:1)
Block(-15,3,3,PRISMARINE:1)
Block(-15,3,4,PRISMARINE:1)
Block(-15,3,5,PRISMARINE:1)
Block(-15,3,6,PRISMARINE:1)
Block(-15,3,7,PRISMARINE:1)
Block(-15,3,8,PRISMARINE:1)
Block(-15,3,9,PRISMARINE:1)
Block(-15,3,10,PRISMARINE:1)
Block(-15,3,11,PRISMARINE:1)
Block(-15,3,12,PRISMARINE:1)
Block(-15,3,13,PRISMARINE:1)
Block(-15,3,14,PRISMARINE:1)
Block(-15,3,15,PRISMARINE:1)
Block(-14,0,-15,PRISMARINE:1)
Block(-14,0,-14,PRISMARINE)
Block(-14,0,-13,PRISMARINE)
Block(-14,0,-12,PRISMARINE)
Block(-14,0,-11,PRISMARINE)
Block(-14,0,-10,PRISMARINE)
Block(-14,0,-9,PRISMARINE)
Block(-14,0,-8,PRISMARINE)
Block(-14,0,-7,PRISMARINE)
Block(-14,0,-6,PRISMARINE)
Block(-14,0,-5,PRISMARINE)
Block(-14,0,-4,PRISMARINE)
Block(-14,0,-3,PRISMARINE)
Block(-14,0,-2,PRISMARINE)
Block(-14,0,-1,PRISMARINE)
Block(-14,0,0,PRISMARINE)
Block(-14,0,1,PRISMARINE)
Block(-14,0,2,PRISMARINE)
Block(-14,0,3,PRISMARINE)
Block(-14,0,4,PRISMARINE)
Block(-14,0,5,PRISMARINE)
Block(-14,0,6,PRISMARINE)
Block(-14,0,7,PRISMARINE)
Block(-14,0,8,PRISMARINE)
Block(-14,0,9,PRISMARINE)
Block(-14,0,10,PRISMARINE)
Block(-14,0,11,PRISMARINE)
Block(-14,0,12,PRISMARINE)
Block(-14,0,13,PRISMARINE)
Block(-14,0,14,PRISMARINE)
Block(-14,0,15,PRISMARINE:1)
Block(-14,1,-15,PRISMARINE:1)
Block(-14,1,-14,PRISMARINE)
Block(-14,1,-13,PRISMARINE)
Block(-14,1,-12,PRISMARINE)
Block(-14,1,-11,PRISMARINE)
Block(-14,1,-10,PRISMARINE)
Block(-14,1,-9,PRISMARINE)
Block(-14,1,-8,PRISMARINE)
Block(-14,1,-7,PRISMARINE)
Block(-14,1,-6,PRISMARINE)
Block(-14,1,-5,PRISMARINE)
Block(-14,1,-4,PRISMARINE)
Block(-14,1,-3,PRISMARINE)
Block(-14,1,-2,PRISMARINE)
Block(-14,1,-1,PRISMARINE)
Block(-14,1,0,PRISMARINE)
Block(-14,1,1,PRISMARINE)
Block(-14,1,2,PRISMARINE)
Block(-14,1,3,PRISMARINE)
Block(-14,1,4,PRISMARINE)
Block(-14,1,5,PRISMARINE)
Block(-14,1,6,PRISMARINE)
Block(-14,1,7,PRISMARINE)
Block(-14,1,8,PRISMARINE)
Block(-14,1,9,PRISMARINE)
Block(-14,1,10,PRISMARINE)
Block(-14,1,11,PRISMARINE)
Block(-14,1,12,PRISMARINE)
Block(-14,1,13,PRISMARINE)
Block(-14,1,14,PRISMARINE)
Block(-14,1,15,PRISMARINE:1)
Block(-14,2,-15,PRISMARINE:1)
Block(-14,2,-14,PRISMARINE)
Block(-14,2,-13,PRISMARINE)
Block(-14,2,-12,PRISMARINE)
Block(-14,2,-11,PRISMARINE)
Block(-14,2,-10,PRISMARINE)
Block(-14,2,-9,PRISMARINE)
Block(-14,2,-8,PRISMARINE)
Block(-14,2,-7,PRISMARINE)
Block(-14,2,-6,PRISMARINE)
Block(-14,2,-5,PRISMARINE)
Block(-14,2,-4,PRISMARINE)
Block(-14,2,-3,PRISMARINE)
Block(-14,2,-2,PRISMARINE)
Block(-14,2,-1,PRISMARINE)
Block(-14,2,0,PRISMARINE)
Block(-14,2,1,PRISMARINE)
Block(-14,2,2,PRISMARINE)
Block(-14,2,3,PRISMARINE)
Block(-14,2,4,PRISMARINE)
Block(-14,2,5,PRISMARINE)
Block(-14,2,6,PRISMARINE)
Block(-14,2,7,PRISMARINE)
Block(-14,2,8,PRISMARINE)
Block(-14,2,9,PRISMARINE)
Block(-14,2,10,PRISMARINE)
Block(-14,2,11,PRISMARINE)
Block(-14,2,12,PRISMARINE)
Block(-14,2,13,PRISMARINE)
Block(-14,2,14,PRISMARINE)
Block(-14,2,15,PRISMARINE:1)
Block(-14,3,-15,PRISMARINE:1)
Block(-14,3,-14,PRISMARINE)
Block(-14,3,-13,PRISMARINE)
Block(-14,3,-12,PRISMARINE)
Block(-14,3,-11,PRISMARINE)
Block(-14,3,-10,PRISMARINE)
Block(-14,3,-9,PRISMARINE)
Block(-14,3,-8,PRISMARINE)
Block(-14,3,-7,PRISMARINE)
Block(-14,3,-6,PRISMARINE)
Block(-14,3,-5,PRISMARINE)
Block(-14,3,-4,PRISMARINE)
Block(-14,3,-3,PRISMARINE)
Block(-14,3,-2,PRISMARINE)
Block(-14,3,-1,PRISMARINE)
Block(-14,3,0,PRISMARINE)
Block(-14,3,1,PRISMARINE)
Block(-14,3,2,PRISMARINE)
Block(-14,3,3,PRISMARINE)
Block(-14,3,4,PRISMARINE)
Block(-14,3,5,PRISMARINE)
Block(-14,3,6,PRISMARINE)
Block(-14,3,7,PRISMARINE)
Block(-14,3,8,PRISMARINE)
Block(-14,3,9,PRISMARINE)
Block(-14,3,10,PRISMARINE)
Block(-14,3,11,PRISMARINE)
Block(-14,3,12,PRISMARINE)
Block(-14,3,13,PRISMARINE)
Block(-14,3,14,PRISMARINE)
Block(-14,3,15,PRISMARINE:1)
Block(-14,4,-14,PRISMARINE)
Block(-14,4,-13,PRISMARINE)
Block(-14,4,-12,PRISMARINE)
Block(-14,4,-11,PRISMARINE)
Block(-14,4,-10,PRISMARINE)
Block(-14,4,-9,PRISMARINE)
Block(-14,4,-8,PRISMARINE)
Block(-14,4,-7,PRISMARINE)
Block(-14,4,-6,PRISMARINE)
Block(-14,4,-5,PRISMARINE)
Block(-14,4,-4,PRISMARINE)
Block(-14,4,-3,PRISMARINE)
Block(-14,4,-2,PRISMARINE)
Block(-14,4,-1,PRISMARINE)
Block(-14,4,0,PRISMARINE)
Block(-14,4,1,PRISMARINE)
Block(-14,4,2,PRISMARINE)
Block(-14,4,3,PRISMARINE)
Block(-14,4,4,PRISMARINE)
Block(-14,4,5,PRISMARINE)
Block(-14,4,6,PRISMARINE)
Block(-14,4,7,PRISMARINE)
Block(-14,4,8,PRISMARINE)
Block(-14,4,9,PRISMARINE)
Block(-14,4,10,PRISMARINE)
Block(-14,4,11,PRISMARINE)
Block(-14,4,12,PRISMARINE)
Block(-14,4,13,PRISMARINE)
Block(-14,4,14,PRISMARINE)
Block(-13,0,-15,PRISMARINE:1)
Block(-13,0,-14,PRISMARINE)
Block(-13,0,-13,PRISMARINE)
Block(-13,0,-12,PRISMARINE)
Block(-13,0,-11,PRISMARINE)
Block(-13,0,-10,PRISMARINE)
Block(-13,0,-9,PRISMARINE)
Block(-13,0,-8,PRISMARINE)
Block(-13,0,-7,PRISMARINE)
Block(-13,0,-6,PRISMARINE)
Block(-13,0,-5,PRISMARINE)
Block(-13,0,-4,PRISMARINE)
Block(-13,0,-3,PRISMARINE)
Block(-13,0,-2,PRISMARINE)
Block(-13,0,-1,PRISMARINE)
Block(-13,0,0,PRISMARINE)
Block(-13,0,1,PRISMARINE)
Block(-13,0,2,PRISMARINE)
Block(-13,0,3,PRISMARINE)
Block(-13,0,4,PRISMARINE)
Block(-13,0,5,PRISMARINE)
Block(-13,0,6,PRISMARINE)
Block(-13,0,7,PRISMARINE)
Block(-13,0,8,PRISMARINE)
Block(-13,0,9,PRISMARINE)
Block(-13,0,10,PRISMARINE)
Block(-13,0,11,PRISMARINE)
Block(-13,0,12,PRISMARINE)
Block(-13,0,13,PRISMARINE)
Block(-13,0,14,PRISMARINE)
Block(-13,0,15,PRISMARINE:1)
Block(-13,1,-15,PRISMARINE:1)
Block(-13,1,-14,PRISMARINE)
Block(-13,1,-13,PRISMARINE)
Block(-13,1,-12,PRISMARINE)
Block(-13,1,-11,PRISMARINE)
Block(-13,1,-10,PRISMARINE)
Block(-13,1,-9,PRISMARINE)
Block(-13,1,-8,PRISMARINE)
Block(-13,1,-7,PRISMARINE)
Block(-13,1,-6,PRISMARINE)
Block(-13,1,-5,PRISMARINE)
Block(-13,1,-4,PRISMARINE)
Block(-13,1,-3,PRISMARINE)
Block(-13,1,-2,PRISMARINE)
Block(-13,1,-1,PRISMARINE)
Block(-13,1,0,PRISMARINE)
Block(-13,1,1,PRISMARINE)
Block(-13,1,2,PRISMARINE)
Block(-13,1,3,PRISMARINE)
Block(-13,1,4,PRISMARINE)
Block(-13,1,5,PRISMARINE)
Block(-13,1,6,PRISMARINE)
Block(-13,1,7,PRISMARINE)
Block(-13,1,8,PRISMARINE)
Block(-13,1,9,PRISMARINE)
Block(-13,1,10,PRISMARINE)
Block(-13,1,11,PRISMARINE)
Block(-13,1,12,PRISMARINE)
Block(-13,1,13,PRISMARINE)
Block(-13,1,14,PRISMARINE)
Block(-13,1,15,PRISMARINE:1)
Block(-13,2,-15,PRISMARINE:1)
Block(-13,2,-14,PRISMARINE)
Block(-13,2,-13,PRISMARINE)
Block(-13,2,-12,PRISMARINE)
Block(-13,2,-11,PRISMARINE)
Block(-13,2,-10,PRISMARINE)
Block(-13,2,-9,PRISMARINE)
Block(-13,2,-8,PRISMARINE)
Block(-13,2,-7,PRISMARINE)
Block(-13,2,-6,PRISMARINE)
Block(-13,2,-5,PRISMARINE)
Block(-13,2,-4,PRISMARINE)
Block(-13,2,-3,PRISMARINE)
Block(-13,2,-2,PRISMARINE)
Block(-13,2,-1,PRISMARINE)
Block(-13,2,0,PRISMARINE)
Block(-13,2,1,PRISMARINE)
Block(-13,2,2,PRISMARINE)
Block(-13,2,3,PRISMARINE)
Block(-13,2,4,PRISMARINE)
Block(-13,2,5,PRISMARINE)
Block(-13,2,6,PRISMARINE)
Block(-13,2,7,PRISMARINE)
Block(-13,2,8,PRISMARINE)
Block(-13,2,9,PRISMARINE)
Block(-13,2,10,PRISMARINE)
Block(-13,2,11,PRISMARINE)
Block(-13,2,12,PRISMARINE)
Block(-13,2,13,PRISMARINE)
Block(-13,2,14,PRISMARINE)
Block(-13,2,15,PRISMARINE:1)
Block(-13,3,-15,PRISMARINE:1)
Block(-13,3,-14,PRISMARINE)
Block(-13,3,-13,PRISMARINE)
Block(-13,3,-12,PRISMARINE)
Block(-13,3,-11,PRISMARINE)
Block(-13,3,-10,PRISMARINE)
Block(-13,3,-9,PRISMARINE)
Block(-13,3,-8,PRISMARINE)
Block(-13,3,-7,PRISMARINE)
Block(-13,3,-6,PRISMARINE)
Block(-13,3,-5,PRISMARINE)
Block(-13,3,-4,PRISMARINE)
Block(-13,3,-3,PRISMARINE)
Block(-13,3,-2,PRISMARINE)
Block(-13,3,-1,PRISMARINE)
Block(-13,3,0,PRISMARINE)
Block(-13,3,1,PRISMARINE)
Block(-13,3,2,PRISMARINE)
Block(-13,3,3,PRISMARINE)
Block(-13,3,4,PRISMARINE)
Block(-13,3,5,PRISMARINE)
Block(-13,3,6,PRISMARINE)
Block(-13,3,7,PRISMARINE)
Block(-13,3,8,PRISMARINE)
Block(-13,3,9,PRISMARINE)
Block(-13,3,10,PRISMARINE)
Block(-13,3,11,PRISMARINE)
Block(-13,3,12,PRISMARINE)
Block(-13,3,13,PRISMARINE)
Block(-13,3,14,PRISMARINE)
Block(-13,3,15,PRISMARINE:1)
Block(-13,4,-14,PRISMARINE)
Block(-13,4,-13,PRISMARINE)
Block(-13,4,-12,PRISMARINE)
Block(-13,4,-11,PRISMARINE)
Block(-13,4,-10,PRISMARINE)
Block(-13,4,-9,PRISMARINE)
Block(-13,4,-8,PRISMARINE)
Block(-13,4,-7,PRISMARINE)
Block(-13,4,-6,PRISMARINE)
Block(-13,4,-5,PRISMARINE)
Block(-13,4,-4,PRISMARINE)
Block(-13,4,-3,PRISMARINE)
Block(-13,4,-2,PRISMARINE)
Block(-13,4,-1,PRISMARINE)
Block(-13,4,0,PRISMARINE)
Block(-13,4,1,PRISMARINE)
Block(-13,4,2,PRISMARINE)
Block(-13,4,3,PRISMARINE)
Block(-13,4,4,PRISMARINE)
Block(-13,4,5,PRISMARINE)
Block(-13,4,6,PRISMARINE)
Block(-13,4,7,PRISMARINE)
Block(-13,4,8,PRISMARINE)
Block(-13,4,9,PRISMARINE)
Block(-13,4,10,PRISMARINE)
Block(-13,4,11,PRISMARINE)
Block(-13,4,12,PRISMARINE)
Block(-13,4,13,PRISMARINE)
Block(-13,4,14,PRISMARINE)
Block(-13,5,-13,PRISMARINE)
Block(-13,5,-12,PRISMARINE)
Block(-13,5,-11,PRISMARINE)
Block(-13,5,-10,PRISMARINE)
Block(-13,5,-9,PRISMARINE)
Block(-13,5,-8,PRISMARINE)
Block(-13,5,-7,PRISMARINE)
Block(-13,5,-6,PRISMARINE)
Block(-13,5,-5,PRISMARINE)
Block(-13,5,-4,PRISMARINE)
Block(-13,5,-3,PRISMARINE)
Block(-13,5,-2,PRISMARINE)
Block(-13,5,-1,PRISMARINE)
Block(-13,5,0,PRISMARINE)
Block(-13,5,1,PRISMARINE)
Block(-13,5,2,PRISMARINE)
Block(-13,5,3,PRISMARINE)
Block(-13,5,4,PRISMARINE)
Block(-13,5,5,PRISMARINE)
Block(-13,5,6,PRISMARINE)
Block(-13,5,7,PRISMARINE)
Block(-13,5,8,PRISMARINE)
Block(-13,5,9,PRISMARINE)
Block(-13,5,10,PRISMARINE)
Block(-13,5,11,PRISMARINE)
Block(-13,5,12,PRISMARINE)
Block(-13,5,13,PRISMARINE)
Block(-12,0,-15,PRISMARINE:1)
Block(-12,0,-14,PRISMARINE)
Block(-12,0,-13,PRISMARINE)
Block(-12,0,-12,PRISMARINE)
Block(-12,0,-11,PRISMARINE)
Block(-12,0,-10,PRISMARINE)
Block(-12,0,-9,PRISMARINE)
Block(-12,0,-8,PRISMARINE)
Block(-12,0,-7,PRISMARINE)
Block(-12,0,-6,PRISMARINE)
Block(-12,0,-5,PRISMARINE)
Block(-12,0,-4,PRISMARINE)
Block(-12,0,-3,PRISMARINE)
Block(-12,0,-2,PRISMARINE)
Block(-12,0,-1,PRISMARINE)
Block(-12,0,0,PRISMARINE)
Block(-12,0,1,PRISMARINE)
Block(-12,0,2,PRISMARINE)
Block(-12,0,3,PRISMARINE)
Block(-12,0,4,PRISMARINE)
Block(-12,0,5,PRISMARINE)
Block(-12,0,6,PRISMARINE)
Block(-12,0,7,PRISMARINE)
Block(-12,0,8,PRISMARINE)
Block(-12,0,9,PRISMARINE)
Block(-12,0,10,PRISMARINE)
Block(-12,0,11,PRISMARINE)
Block(-12,0,12,PRISMARINE)
Block(-12,0,13,PRISMARINE)
Block(-12,0,14,PRISMARINE)
Block(-12,0,15,PRISMARINE:1)
Block(-12,1,-15,PRISMARINE:1)
Block(-12,1,-14,PRISMARINE)
Block(-12,1,-13,PRISMARINE)
Block(-12,1,-12,PRISMARINE)
Block(-12,1,-11,PRISMARINE)
Block(-12,1,-10,PRISMARINE)
Block(-12,1,-9,PRISMARINE)
Block(-12,1,-8,PRISMARINE)
Block(-12,1,-7,PRISMARINE)
Block(-12,1,-6,PRISMARINE)
Block(-12,1,-5,PRISMARINE)
Block(-12,1,-4,PRISMARINE)
Block(-12,1,-3,PRISMARINE)
Block(-12,1,-2,PRISMARINE)
Block(-12,1,-1,PRISMARINE)
Block(-12,1,0,PRISMARINE)
Block(-12,1,1,PRISMARINE)
Block(-12,1,2,PRISMARINE)
Block(-12,1,3,PRISMARINE)
Block(-12,1,4,PRISMARINE)
Block(-12,1,5,PRISMARINE)
Block(-12,1,6,PRISMARINE)
Block(-12,1,7,PRISMARINE)
Block(-12,1,8,PRISMARINE)
Block(-12,1,9,PRISMARINE)
Block(-12,1,10,PRISMARINE)
Block(-12,1,11,PRISMARINE)
Block(-12,1,12,PRISMARINE)
Block(-12,1,13,PRISMARINE)
Block(-12,1,14,PRISMARINE)
Block(-12,1,15,PRISMARINE:1)
Block(-12,2,-15,PRISMARINE:1)
Block(-12,2,-14,PRISMARINE)
Block(-12,2,-13,PRISMARINE)
Block(-12,2,-12,PRISMARINE)
Block(-12,2,-11,PRISMARINE)
Block(-12,2,-10,PRISMARINE)
Block(-12,2,-9,PRISMARINE)
Block(-12,2,-8,PRISMARINE)
Block(-12,2,-7,PRISMARINE)
Block(-12,2,-6,PRISMARINE)
Block(-12,2,-5,PRISMARINE)
Block(-12,2,-4,PRISMARINE)
Block(-12,2,-3,PRISMARINE)
Block(-12,2,-2,PRISMARINE)
Block(-12,2,-1,PRISMARINE)
Block(-12,2,0,PRISMARINE)
Block(-12,2,1,PRISMARINE)
Block(-12,2,2,PRISMARINE)
Block(-12,2,3,PRISMARINE)
Block(-12,2,4,PRISMARINE)
Block(-12,2,5,PRISMARINE)
Block(-12,2,6,PRISMARINE)
Block(-12,2,7,PRISMARINE)
Block(-12,2,8,PRISMARINE)
Block(-12,2,9,PRISMARINE)
Block(-12,2,10,PRISMARINE)
Block(-12,2,11,PRISMARINE)
Block(-12,2,12,PRISMARINE)
Block(-12,2,13,PRISMARINE)
Block(-12,2,14,PRISMARINE)
Block(-12,2,15,PRISMARINE:1)
Block(-12,3,-15,PRISMARINE:1)
Block(-12,3,-14,PRISMARINE)
Block(-12,3,-13,PRISMARINE)
Block(-12,3,-12,PRISMARINE)
Block(-12,3,-11,PRISMARINE)
Block(-12,3,-10,PRISMARINE)
Block(-12,3,-9,PRISMARINE)
Block(-12,3,-8,PRISMARINE)
Block(-12,3,-7,PRISMARINE)
Block(-12,3,-6,PRISMARINE)
Block(-12,3,-5,PRISMARINE)
Block(-12,3,-4,PRISMARINE)
Block(-12,3,-3,PRISMARINE)
Block(-12,3,-2,PRISMARINE)
Block(-12,3,-1,PRISMARINE)
Block(-12,3,0,PRISMARINE)
Block(-12,3,1,PRISMARINE)
Block(-12,3,2,PRISMARINE)
Block(-12,3,3,PRISMARINE)
Block(-12,3,4,PRISMARINE)
Block(-12,3,5,PRISMARINE)
Block(-12,3,6,PRISMARINE)
Block(-12,3,7,PRISMARINE)
Block(-12,3,8,PRISMARINE)
Block(-12,3,9,PRISMARINE)
Block(-12,3,10,PRISMARINE)
Block(-12,3,11,PRISMARINE)
Block(-12,3,12,PRISMARINE)
Block(-12,3,13,PRISMARINE)
Block(-12,3,14,PRISMARINE)
Block(-12,3,15,PRISMARINE:1)
Block(-12,4,-14,PRISMARINE)
Block(-12,4,-13,PRISMARINE)
Block(-12,4,-12,PRISMARINE)
Block(-12,4,-11,PRISMARINE)
Block(-12,4,-10,PRISMARINE)
Block(-12,4,-9,PRISMARINE)
Block(-12,4,-8,PRISMARINE)
Block(-12,4,-7,PRISMARINE)
Block(-12,4,-6,PRISMARINE)
Block(-12,4,-5,PRISMARINE)
Block(-12,4,-4,PRISMARINE)
Block(-12,4,-3,PRISMARINE)
Block(-12,4,-2,PRISMARINE)
Block(-12,4,-1,PRISMARINE)
Block(-12,4,0,PRISMARINE)
Block(-12,4,1,PRISMARINE)
Block(-12,4,2,PRISMARINE)
Block(-12,4,3,PRISMARINE)
Block(-12,4,4,PRISMARINE)
Block(-12,4,5,PRISMARINE)
Block(-12,4,6,PRISMARINE)
Block(-12,4,7,PRISMARINE)
Block(-12,4,8,PRISMARINE)
Block(-12,4,9,PRISMARINE)
Block(-12,4,10,PRISMARINE)
Block(-12,4,11,PRISMARINE)
Block(-12,4,12,PRISMARINE)
Block(-12,4,13,PRISMARINE)
Block(-12,4,14,PRISMARINE)
Block(-12,5,-13,PRISMARINE)
Block(-12,5,-12,PRISMARINE)
Block(-12,5,-11,PRISMARINE)
Block(-12,5,-10,PRISMARINE)
Block(-12,5,-9,PRISMARINE)
Block(-12,5,-8,PRISMARINE)
Block(-12,5,-7,PRISMARINE)
Block(-12,5,-6,PRISMARINE)
Block(-12,5,-5,PRISMARINE)
Block(-12,5,-4,PRISMARINE)
Block(-12,5,-3,PRISMARINE)
Block(-12,5,-2,PRISMARINE)
Block(-12,5,-1,PRISMARINE)
Block(-12,5,0,PRISMARINE)
Block(-12,5,1,PRISMARINE)
Block(-12,5,2,PRISMARINE)
Block(-12,5,3,PRISMARINE)
Block(-12,5,4,PRISMARINE)
Block(-12,5,5,PRISMARINE)
Block(-12,5,6,PRISMARINE)
Block(-12,5,7,PRISMARINE)
Block(-12,5,8,PRISMARINE)
Block(-12,5,9,PRISMARINE)
Block(-12,5,10,PRISMARINE)
Block(-12,5,11,PRISMARINE)
Block(-12,5,12,PRISMARINE)
Block(-12,5,13,PRISMARINE)
Block(-12,6,-12,PRISMARINE:1)
Block(-12,6,-11,PRISMARINE:1)
Block(-12,6,-10,PRISMARINE:1)
Block(-12,6,-9,PRISMARINE:1)
Block(-12,6,-8,PRISMARINE:1)
Block(-12,6,-7,PRISMARINE:1)
Block(-12,6,-6,PRISMARINE:1)
Block(-12,6,-5,PRISMARINE:1)
Block(-12,6,-4,PRISMARINE:1)
Block(-12,6,-3,PRISMARINE:1)
Block(-12,6,-2,PRISMARINE:1)
Block(-12,6,-1,PRISMARINE:1)
Block(-12,6,0,PRISMARINE:1)
Block(-12,6,1,PRISMARINE:1)
Block(-12,6,2,PRISMARINE:1)
Block(-12,6,3,PRISMARINE:1)
Block(-12,6,4,PRISMARINE:1)
Block(-12,6,5,PRISMARINE:1)
Block(-12,6,6,PRISMARINE:1)
Block(-12,6,7,PRISMARINE:1)
Block(-12,6,8,PRISMARINE:1)
Block(-12,6,9,PRISMARINE:1)
Block(-12,6,10,PRISMARINE:1)
Block(-12,6,11,PRISMARINE:1)
Block(-12,6,12,PRISMARINE:1)
Block(-11,0,-15,PRISMARINE:1)
Block(-11,0,-14,PRISMARINE)
Block(-11,0,-13,PRISMARINE)
Block(-11,0,-12,PRISMARINE)
Block(-11,0,-11,PRISMARINE)
Block(-11,0,-10,PRISMARINE)
Block(-11,0,-9,PRISMARINE)
Block(-11,0,-8,PRISMARINE)
Block(-11,0,-7,PRISMARINE)
Block(-11,0,-6,PRISMARINE)
Block(-11,0,-5,PRISMARINE)
Block(-11,0,-4,PRISMARINE)
Block(-11,0,-3,PRISMARINE)
Block(-11,0,-2,PRISMARINE)
Block(-11,0,-1,PRISMARINE)
Block(-11,0,0,PRISMARINE)
Block(-11,0,1,PRISMARINE)
Block(-11,0,2,PRISMARINE)
Block(-11,0,3,PRISMARINE)
Block(-11,0,4,PRISMARINE)
Block(-11,0,5,PRISMARINE)
Block(-11,0,6,PRISMARINE)
Block(-11,0,7,PRISMARINE)
Block(-11,0,8,PRISMARINE)
Block(-11,0,9,PRISMARINE)
Block(-11,0,10,PRISMARINE)
Block(-11,0,11,PRISMARINE)
Block(-11,0,12,PRISMARINE)
Block(-11,0,13,PRISMARINE)
Block(-11,0,14,PRISMARINE)
Block(-11,0,15,PRISMARINE:1)
Block(-11,1,-15,PRISMARINE:1)
Block(-11,1,-14,PRISMARINE)
Block(-11,1,-13,PRISMARINE)
Block(-11,1,-12,PRISMARINE)
Block(-11,1,-11,PRISMARINE)
Block(-11,1,-10,PRISMARINE)
Block(-11,1,-9,PRISMARINE)
Block(-11,1,-8,PRISMARINE)
Block(-11,1,-7,PRISMARINE)
Block(-11,1,-6,PRISMARINE)
Block(-11,1,-5,PRISMARINE)
Block(-11,1,-4,PRISMARINE)
Block(-11,1,-3,PRISMARINE)
Block(-11,1,-2,PRISMARINE)
Block(-11,1,-1,PRISMARINE)
Block(-11,1,0,PRISMARINE)
Block(-11,1,1,PRISMARINE)
Block(-11,1,2,PRISMARINE)
Block(-11,1,3,PRISMARINE)
Block(-11,1,4,PRISMARINE)
Block(-11,1,5,PRISMARINE)
Block(-11,1,6,PRISMARINE)
Block(-11,1,7,PRISMARINE)
Block(-11,1,8,PRISMARINE)
Block(-11,1,9,PRISMARINE)
Block(-11,1,10,PRISMARINE)
Block(-11,1,11,PRISMARINE)
Block(-11,1,12,PRISMARINE)
Block(-11,1,13,PRISMARINE)
Block(-11,1,14,PRISMARINE)
Block(-11,1,15,PRISMARINE:1)
Block(-11,2,-15,PRISMARINE:1)
Block(-11,2,-14,PRISMARINE)
Block(-11,2,-13,PRISMARINE)
Block(-11,2,-12,PRISMARINE)
Block(-11,2,-11,PRISMARINE)
Block(-11,2,-10,PRISMARINE)
Block(-11,2,-9,PRISMARINE)
Block(-11,2,-8,PRISMARINE)
Block(-11,2,-7,PRISMARINE)
Block(-11,2,-6,PRISMARINE)
Block(-11,2,-5,PRISMARINE)
Block(-11,2,-4,PRISMARINE)
Block(-11,2,-3,PRISMARINE)
Block(-11,2,-2,PRISMARINE)
Block(-11,2,-1,PRISMARINE)
Block(-11,2,0,PRISMARINE)
Block(-11,2,1,PRISMARINE)
Block(-11,2,2,PRISMARINE)
Block(-11,2,3,PRISMARINE)
Block(-11,2,4,PRISMARINE)
Block(-11,2,5,PRISMARINE)
Block(-11,2,6,PRISMARINE)
Block(-11,2,7,PRISMARINE)
Block(-11,2,8,PRISMARINE)
Block(-11,2,9,PRISMARINE)
Block(-11,2,10,PRISMARINE)
Block(-11,2,11,PRISMARINE)
Block(-11,2,12,PRISMARINE)
Block(-11,2,13,PRISMARINE)
Block(-11,2,14,PRISMARINE)
Block(-11,2,15,PRISMARINE:1)
Block(-11,3,-15,PRISMARINE:1)
Block(-11,3,-14,PRISMARINE)
Block(-11,3,-13,PRISMARINE)
Block(-11,3,-12,PRISMARINE)
Block(-11,3,-11,PRISMARINE)
Block(-11,3,-10,PRISMARINE)
Block(-11,3,-9,PRISMARINE)
Block(-11,3,-8,PRISMARINE)
Block(-11,3,-7,PRISMARINE)
Block(-11,3,-6,PRISMARINE)
Block(-11,3,-5,PRISMARINE)
Block(-11,3,-4,PRISMARINE)
Block(-11,3,-3,PRISMARINE)
Block(-11,3,-2,PRISMARINE)
Block(-11,3,-1,PRISMARINE)
Block(-11,3,0,PRISMARINE)
Block(-11,3,1,PRISMARINE)
Block(-11,3,2,PRISMARINE)
Block(-11,3,3,PRISMARINE)
Block(-11,3,4,PRISMARINE)
Block(-11,3,5,PRISMARINE)
Block(-11,3,6,PRISMARINE)
Block(-11,3,7,PRISMARINE)
Block(-11,3,8,PRISMARINE)
Block(-11,3,9,PRISMARINE)
Block(-11,3,10,PRISMARINE)
Block(-11,3,11,PRISMARINE)
Block(-11,3,12,PRISMARINE)
Block(-11,3,13,PRISMARINE)
Block(-11,3,14,PRISMARINE)
Block(-11,3,15,PRISMARINE:1)
Block(-11,4,-14,PRISMARINE)
Block(-11,4,-13,PRISMARINE)
Block(-11,4,-12,PRISMARINE)
Block(-11,4,-11,PRISMARINE)
Block(-11,4,-10,PRISMARINE)
Block(-11,4,-9,PRISMARINE)
Block(-11,4,-8,PRISMARINE)
Block(-11,4,-7,PRISMARINE)
Block(-11,4,-6,PRISMARINE)
Block(-11,4,-5,PRISMARINE)
Block(-11,4,-4,PRISMARINE)
Block(-11,4,-3,PRISMARINE)
Block(-11,4,-2,PRISMARINE)
Block(-11,4,-1,PRISMARINE)
Block(-11,4,0,PRISMARINE)
Block(-11,4,1,PRISMARINE)
Block(-11,4,2,PRISMARINE)
Block(-11,4,3,PRISMARINE)
Block(-11,4,4,PRISMARINE)
Block(-11,4,5,PRISMARINE)
Block(-11,4,6,PRISMARINE)
Block(-11,4,7,PRISMARINE)
Block(-11,4,8,PRISMARINE)
Block(-11,4,9,PRISMARINE)
Block(-11,4,10,PRISMARINE)
Block(-11,4,11,PRISMARINE)
Block(-11,4,12,PRISMARINE)
Block(-11,4,13,PRISMARINE)
Block(-11,4,14,PRISMARINE)
Block(-11,5,-13,PRISMARINE)
Block(-11,5,-12,PRISMARINE)
Block(-11,5,-11,PRISMARINE)
Block(-11,5,-10,PRISMARINE)
Block(-11,5,-9,PRISMARINE)
Block(-11,5,-8,PRISMARINE)
Block(-11,5,-7,PRISMARINE)
Block(-11,5,-6,PRISMARINE)
Block(-11,5,-5,PRISMARINE)
Block(-11,5,-4,PRISMARINE)
Block(-11,5,-3,PRISMARINE)
Block(-11,5,-2,PRISMARINE)
Block(-11,5,-1,PRISMARINE)
Block(-11,5,0,PRISMARINE)
Block(-11,5,1,PRISMARINE)
Block(-11,5,2,PRISMARINE)
Block(-11,5,3,PRISMARINE)
Block(-11,5,4,PRISMARINE)
Block(-11,5,5,PRISMARINE)
Block(-11,5,6,PRISMARINE)
Block(-11,5,7,PRISMARINE)
Block(-11,5,8,PRISMARINE)
Block(-11,5,9,PRISMARINE)
Block(-11,5,10,PRISMARINE)
Block(-11,5,11,PRISMARINE)
Block(-11,5,12,PRISMARINE)
Block(-11,5,13,PRISMARINE)
Block(-11,6,-12,PRISMARINE:1)
Block(-11,6,-11,PRISMARINE)
Block(-11,6,-10,PRISMARINE)
Block(-11,6,-9,PRISMARINE)
Block(-11,6,-8,PRISMARINE)
Block(-11,6,-7,PRISMARINE)
Block(-11,6,-6,PRISMARINE)
Block(-11,6,-5,PRISMARINE)
Block(-11,6,-4,PRISMARINE)
Block(-11,6,-3,PRISMARINE)
Block(-11,6,-2,PRISMARINE)
Block(-11,6,-1,PRISMARINE)
Block(-11,6,0,PRISMARINE)
Block(-11,6,1,PRISMARINE)
Block(-11,6,2,PRISMARINE)
Block(-11,6,3,PRISMARINE)
Block(-11,6,4,PRISMARINE)
Block(-11,6,5,PRISMARINE)
Block(-11,6,6,PRISMARINE)
Block(-11,6,7,PRISMARINE)
Block(-11,6,8,PRISMARINE)
Block(-11,6,9,PRISMARINE)
Block(-11,6,10,PRISMARINE)
Block(-11,6,11,PRISMARINE)
Block(-11,6,12,PRISMARINE:1)
Block(-10,0,-15,PRISMARINE:1)
Block(-10,0,-14,PRISMARINE)
Block(-10,0,-13,PRISMARINE)
Block(-10,0,-12,PRISMARINE)
Block(-10,0,-11,PRISMARINE)
Block(-10,0,-10,PRISMARINE)
Block(-10,0,-9,PRISMARINE)
Block(-10,0,-8,PRISMARINE)
Block(-10,0,-7,PRISMARINE)
Block(-10,0,-6,PRISMARINE)
Block(-10,0,-5,PRISMARINE)
Block(-10,0,-4,PRISMARINE)
Block(-10,0,-3,PRISMARINE)
Block(-10,0,-2,PRISMARINE)
Block(-10,0,-1,PRISMARINE)
Block(-10,0,0,PRISMARINE)
Block(-10,0,1,PRISMARINE)
Block(-10,0,2,PRISMARINE)
Block(-10,0,3,PRISMARINE)
Block(-10,0,4,PRISMARINE)
Block(-10,0,5,PRISMARINE)
Block(-10,0,6,PRISMARINE)
Block(-10,0,7,PRISMARINE)
Block(-10,0,8,PRISMARINE)
Block(-10,0,9,PRISMARINE)
Block(-10,0,10,PRISMARINE)
Block(-10,0,11,PRISMARINE)
Block(-10,0,12,PRISMARINE)
Block(-10,0,13,PRISMARINE)
Block(-10,0,14,PRISMARINE)
Block(-10,0,15,PRISMARINE:1)
Block(-10,1,-15,PRISMARINE:1)
Block(-10,1,-14,PRISMARINE)
Block(-10,1,-13,PRISMARINE)
Block(-10,1,-12,PRISMARINE)
Block(-10,1,-11,PRISMARINE)
Block(-10,1,-10,PRISMARINE)
Block(-10,1,-9,PRISMARINE)
Block(-10,1,-8,PRISMARINE)
Block(-10,1,-7,PRISMARINE)
Block(-10,1,-6,PRISMARINE)
Block(-10,1,-5,PRISMARINE)
Block(-10,1,-4,PRISMARINE)
Block(-10,1,-3,PRISMARINE)
Block(-10,1,-2,PRISMARINE)
Block(-10,1,-1,PRISMARINE)
Block(-10,1,0,PRISMARINE)
Block(-10,1,1,PRISMARINE)
Block(-10,1,2,PRISMARINE)
Block(-10,1,3,PRISMARINE)
Block(-10,1,4,PRISMARINE)
Block(-10,1,5,PRISMARINE)
Block(-10,1,6,PRISMARINE)
Block(-10,1,7,PRISMARINE)
Block(-10,1,8,PRISMARINE)
Block(-10,1,9,PRISMARINE)
Block(-10,1,10,PRISMARINE)
Block(-10,1,11,PRISMARINE)
Block(-10,1,12,PRISMARINE)
Block(-10,1,13,PRISMARINE)
Block(-10,1,14,PRISMARINE)
Block(-10,1,15,PRISMARINE:1)
Block(-10,2,-15,PRISMARINE:1)
Block(-10,2,-14,PRISMARINE)
Block(-10,2,-13,PRISMARINE)
Block(-10,2,-12,PRISMARINE)
Block(-10,2,-11,PRISMARINE)
Block(-10,2,-10,PRISMARINE)
Block(-10,2,-9,PRISMARINE)
Block(-10,2,-8,PRISMARINE)
Block(-10,2,-7,PRISMARINE)
Block(-10,2,-6,PRISMARINE)
Block(-10,2,-5,PRISMARINE)
Block(-10,2,-4,PRISMARINE)
Block(-10,2,-3,PRISMARINE)
Block(-10,2,-2,PRISMARINE)
Block(-10,2,-1,PRISMARINE)
Block(-10,2,0,PRISMARINE)
Block(-10,2,1,PRISMARINE)
Block(-10,2,2,PRISMARINE)
Block(-10,2,3,PRISMARINE)
Block(-10,2,4,PRISMARINE)
Block(-10,2,5,PRISMARINE)
Block(-10,2,6,PRISMARINE)
Block(-10,2,7,PRISMARINE)
Block(-10,2,8,PRISMARINE)
Block(-10,2,9,PRISMARINE)
Block(-10,2,10,PRISMARINE)
Block(-10,2,11,PRISMARINE)
Block(-10,2,12,PRISMARINE)
Block(-10,2,13,PRISMARINE)
Block(-10,2,14,PRISMARINE)
Block(-10,2,15,PRISMARINE:1)
Block(-10,3,-15,PRISMARINE:1)
Block(-10,3,-14,PRISMARINE)
Block(-10,3,-13,PRISMARINE)
Block(-10,3,-12,PRISMARINE)
Block(-10,3,-11,PRISMARINE)
Block(-10,3,-10,PRISMARINE)
Block(-10,3,-9,PRISMARINE)
Block(-10,3,-8,PRISMARINE)
Block(-10,3,-7,PRISMARINE)
Block(-10,3,-6,PRISMARINE)
Block(-10,3,-5,PRISMARINE)
Block(-10,3,-4,PRISMARINE)
Block(-10,3,-3,PRISMARINE)
Block(-10,3,-2,PRISMARINE)
Block(-10,3,-1,PRISMARINE)
Block(-10,3,0,PRISMARINE)
Block(-10,3,1,PRISMARINE)
Block(-10,3,2,PRISMARINE)
Block(-10,3,3,PRISMARINE)
Block(-10,3,4,PRISMARINE)
Block(-10,3,5,PRISMARINE)
Block(-10,3,6,PRISMARINE)
Block(-10,3,7,PRISMARINE)
Block(-10,3,8,PRISMARINE)
Block(-10,3,9,PRISMARINE)
Block(-10,3,10,PRISMARINE)
Block(-10,3,11,PRISMARINE)
Block(-10,3,12,PRISMARINE)
Block(-10,3,13,PRISMARINE)
Block(-10,3,14,PRISMARINE)
Block(-10,3,15,PRISMARINE:1)
Block(-10,4,-14,PRISMARINE)
Block(-10,4,-13,PRISMARINE)
Block(-10,4,-12,PRISMARINE)
Block(-10,4,-11,PRISMARINE)
Block(-10,4,-10,PRISMARINE)
Block(-10,4,-9,PRISMARINE)
Block(-10,4,-8,PRISMARINE)
Block(-10,4,-7,PRISMARINE)
Block(-10,4,-6,PRISMARINE)
Block(-10,4,-5,PRISMARINE)
Block(-10,4,-4,PRISMARINE)
Block(-10,4,-3,PRISMARINE)
Block(-10,4,-2,PRISMARINE)
Block(-10,4,-1,PRISMARINE)
Block(-10,4,0,PRISMARINE)
Block(-10,4,1,PRISMARINE)
Block(-10,4,2,PRISMARINE)
Block(-10,4,3,PRISMARINE)
Block(-10,4,4,PRISMARINE)
Block(-10,4,5,PRISMARINE)
Block(-10,4,6,PRISMARINE)
Block(-10,4,7,PRISMARINE)
Block(-10,4,8,PRISMARINE)
Block(-10,4,9,PRISMARINE)
Block(-10,4,10,PRISMARINE)
Block(-10,4,11,PRISMARINE)
Block(-10,4,12,PRISMARINE)
Block(-10,4,13,PRISMARINE)
Block(-10,4,14,PRISMARINE)
Block(-10,5,-13,PRISMARINE)
Block(-10,5,-12,PRISMARINE)
Block(-10,5,-11,PRISMARINE)
Block(-10,5,-10,PRISMARINE)
Block(-10,5,-9,PRISMARINE)
Block(-10,5,-8,PRISMARINE)
Block(-10,5,-7,PRISMARINE)
Block(-10,5,-6,PRISMARINE)
Block(-10,5,-5,PRISMARINE)
Block(-10,5,-4,PRISMARINE)
Block(-10,5,-3,PRISMARINE)
Block(-10,5,-2,PRISMARINE)
Block(-10,5,-1,PRISMARINE)
Block(-10,5,0,PRISMARINE)
Block(-10,5,1,PRISMARINE)
Block(-10,5,2,PRISMARINE)
Block(-10,5,3,PRISMARINE)
Block(-10,5,4,PRISMARINE)
Block(-10,5,5,PRISMARINE)
Block(-10,5,6,PRISMARINE)
Block(-10,5,7,PRISMARINE)
Block(-10,5,8,PRISMARINE)
Block(-10,5,9,PRISMARINE)
Block(-10,5,10,PRISMARINE)
Block(-10,5,11,PRISMARINE)
Block(-10,5,12,PRISMARINE)
Block(-10,5,13,PRISMARINE)
Block(-10,6,-12,PRISMARINE:1)
Block(-10,6,-11,PRISMARINE)
Block(-10,6,-10,PRISMARINE)
Block(-10,6,-9,PRISMARINE)
Block(-10,6,-8,PRISMARINE)
Block(-10,6,-7,PRISMARINE)
Block(-10,6,-6,PRISMARINE)
Block(-10,6,-5,PRISMARINE)
Block(-10,6,-4,PRISMARINE)
Block(-10,6,-3,PRISMARINE)
Block(-10,6,-2,PRISMARINE)
Block(-10,6,-1,PRISMARINE)
Block(-10,6,0,PRISMARINE)
Block(-10,6,1,PRISMARINE)
Block(-10,6,2,PRISMARINE)
Block(-10,6,3,PRISMARINE)
Block(-10,6,4,PRISMARINE)
Block(-10,6,5,PRISMARINE)
Block(-10,6,6,PRISMARINE)
Block(-10,6,7,PRISMARINE)
Block(-10,6,8,PRISMARINE)
Block(-10,6,9,PRISMARINE)
Block(-10,6,10,PRISMARINE)
Block(-10,6,11,PRISMARINE)
Block(-10,6,12,PRISMARINE:1)
Block(-10,7,-10,PRISMARINE:1)
Block(-10,7,-9,PRISMARINE:1)
Block(-10,7,-8,PRISMARINE:1)
Block(-10,7,-3,PRISMARINE:1)
Block(-10,7,-2,PRISMARINE:1)
Block(-10,7,-1,PRISMARINE:1)
Block(-10,7,1,PRISMARINE:1)
Block(-10,7,2,PRISMARINE:1)
Block(-10,7,3,PRISMARINE:1)
Block(-10,7,8,PRISMARINE:1)
Block(-10,7,9,PRISMARINE:1)
Block(-10,7,10,PRISMARINE:1)
Block(-10,8,-10,PRISMARINE:1)
Block(-10,8,-8,PRISMARINE:1)
Block(-10,8,-3,PRISMARINE:1)
Block(-10,8,-1,PRISMARINE:1)
Block(-10,8,1,PRISMARINE:1)
Block(-10,8,3,PRISMARINE:1)
Block(-10,8,8,PRISMARINE:1)
Block(-10,8,10,PRISMARINE:1)
Block(-10,9,-10,PRISMARINE:1)
Block(-10,9,-9,PRISMARINE:2)
Block(-10,9,-8,PRISMARINE:1)
Block(-10,9,-3,PRISMARINE:1)
Block(-10,9,-2,PRISMARINE:2)
Block(-10,9,-1,PRISMARINE:1)
Block(-10,9,1,PRISMARINE:1)
Block(-10,9,2,PRISMARINE:2)
Block(-10,9,3,PRISMARINE:1)
Block(-10,9,8,PRISMARINE:1)
Block(-10,9,9,PRISMARINE:2)
Block(-10,9,10,PRISMARINE:1)
Block(-10,10,-10,PRISMARINE:1)
Block(-10,10,-8,PRISMARINE:1)
Block(-10,10,-3,PRISMARINE:1)
Block(-10,10,-1,PRISMARINE:1)
Block(-10,10,1,PRISMARINE:1)
Block(-10,10,3,PRISMARINE:1)
Block(-10,10,8,PRISMARINE:1)
Block(-10,10,10,PRISMARINE:1)
Block(-10,11,-10,PRISMARINE:1)
Block(-10,11,-9,PRISMARINE:2)
Block(-10,11,-8,PRISMARINE:1)
Block(-10,11,-3,PRISMARINE:1)
Block(-10,11,-2,PRISMARINE:2)
Block(-10,11,-1,PRISMARINE:1)
Block(-10,11,1,PRISMARINE:1)
Block(-10,11,2,PRISMARINE:2)
Block(-10,11,3,PRISMARINE:1)
Block(-10,11,8,PRISMARINE:1)
Block(-10,11,9,PRISMARINE:2)
Block(-10,11,10,PRISMARINE:1)
Block(-10,12,-10,PRISMARINE:1)
Block(-10,12,-8,PRISMARINE:1)
Block(-10,12,-3,PRISMARINE:1)
Block(-10,12,-1,PRISMARINE:1)
Block(-10,12,1,PRISMARINE:1)
Block(-10,12,3,PRISMARINE:1)
Block(-10,12,8,PRISMARINE:1)
Block(-10,12,10,PRISMARINE:1)
Block(-10,13,-10,PRISMARINE:1)
Block(-10,13,-9,PRISMARINE:2)
Block(-10,13,-8,PRISMARINE:1)
Block(-10,13,-3,PRISMARINE:1)
Block(-10,13,-2,PRISMARINE:2)
Block(-10,13,-1,PRISMARINE:1)
Block(-10,13,1,PRISMARINE:1)
Block(-10,13,2,PRISMARINE:2)
Block(-10,13,3,PRISMARINE:1)
Block(-10,13,8,PRISMARINE:1)
Block(-10,13,9,PRISMARINE:2)
Block(-10,13,10,PRISMARINE:1)
Block(-10,14,-10,PRISMARINE:1)
Block(-10,14,-8,PRISMARINE:1)
Block(-10,14,-3,PRISMARINE:1)
Block(-10,14,-1,PRISMARINE:1)
Block(-10,14,1,PRISMARINE:1)
Block(-10,14,3,PRISMARINE:1)
Block(-10,14,8,PRISMARINE:1)
Block(-10,14,10,PRISMARINE:1)
Block(-10,15,-10,PRISMARINE:1)
Block(-10,15,-9,PRISMARINE:2)
Block(-10,15,-8,PRISMARINE:1)
Block(-10,15,-3,PRISMARINE:1)
Block(-10,15,-2,PRISMARINE:2)
Block(-10,15,-1,PRISMARINE:1)
Block(-10,15,1,PRISMARINE:1)
Block(-10,15,2,PRISMARINE:2)
Block(-10,15,3,PRISMARINE:1)
Block(-10,15,8,PRISMARINE:1)
Block(-10,15,9,PRISMARINE:2)
Block(-10,15,10,PRISMARINE:1)
Block(-10,16,-10,PRISMARINE:1)
Block(-10,16,-9,PRISMARINE:1)
Block(-10,16,-8,PRISMARINE:1)
Block(-10,16,-3,PRISMARINE:1)
Block(-10,16,-2,PRISMARINE:1)
Block(-10,16,-1,PRISMARINE:1)
Block(-10,16,1,PRISMARINE:1)
Block(-10,16,2,PRISMARINE:1)
Block(-10,16,3,PRISMARINE:1)
Block(-10,16,8,PRISMARINE:1)
Block(-10,16,9,PRISMARINE:1)
Block(-10,16,10,PRISMARINE:1)
Block(-10,17,-10,PRISMARINE:2)
Block(-10,17,-9,PRISMARINE:2)
Block(-10,17,-8,PRISMARINE:2)
Block(-10,17,-7,PRISMARINE:2)
Block(-10,17,-6,PRISMARINE:2)
Block(-10,17,-5,PRISMARINE:2)
Block(-10,17,-4,PRISMARINE:2)
Block(-10,17,-3,PRISMARINE:2)
Block(-10,17,-2,PRISMARINE:2)
Block(-10,17,-1,PRISMARINE:2)
Block(-10,17,0,PRISMARINE:2)
Block(-10,17,1,PRISMARINE:2)
Block(-10,17,2,PRISMARINE:2)
Block(-10,17,3,PRISMARINE:2)
Block(-10,17,4,PRISMARINE:2)
Block(-10,17,5,PRISMARINE:2)
Block(-10,17,6,PRISMARINE:2)
Block(-10,17,7,PRISMARINE:2)
Block(-10,17,8,PRISMARINE:2)
Block(-10,17,9,PRISMARINE:2)
Block(-10,17,10,PRISMARINE:2)
Block(-10,18,-10,PRISMARINE:2)
Block(-10,18,-7,PRISMARINE:2)
Block(-10,18,-4,PRISMARINE:2)
Block(-10,18,0,PRISMARINE:2)
Block(-10,18,4,PRISMARINE:2)
Block(-10,18,7,PRISMARINE:2)
Block(-10,18,10,PRISMARINE:2)
Block(-10,19,-10,PRISMARINE:2)
Block(-10,19,-9,PRISMARINE:2)
Block(-10,19,-8,PRISMARINE:2)
Block(-10,19,-7,PRISMARINE:2)
Block(-10,19,-6,PRISMARINE:2)
Block(-10,19,-5,PRISMARINE:2)
Block(-10,19,-4,PRISMARINE:2)
Block(-10,19,-3,PRISMARINE:2)
Block(-10,19,-2,PRISMARINE:2)
Block(-10,19,-1,PRISMARINE:2)
Block(-10,19,0,PRISMARINE:2)
Block(-10,19,1,PRISMARINE:2)
Block(-10,19,2,PRISMARINE:2)
Block(-10,19,3,PRISMARINE:2)
Block(-10,19,4,PRISMARINE:2)
Block(-10,19,5,PRISMARINE:2)
Block(-10,19,6,PRISMARINE:2)
Block(-10,19,7,PRISMARINE:2)
Block(-10,19,8,PRISMARINE:2)
Block(-10,19,9,PRISMARINE:2)
Block(-10,19,10,PRISMARINE:2)
Block(-10,20,-12,PRISMARINE:1)
Block(-10,20,-11,PRISMARINE:1)
Block(-10,20,11,PRISMARINE:1)
Block(-10,20,12,PRISMARINE:1)
Block(-10,21,-10,PRISMARINE:1)
Block(-10,21,-9,PRISMARINE:1)
Block(-10,21,9,PRISMARINE:1)
Block(-10,21,10,PRISMARINE:1)
Block(-10,22,-8,PRISMARINE:1)
Block(-10,22,-7,PRISMARINE:1)
Block(-10,22,7,PRISMARINE:1)
Block(-10,22,8,PRISMARINE:1)
Block(-10,23,-6,PRISMARINE:1)
Block(-10,23,-5,PRISMARINE:1)
Block(-10,23,5,PRISMARINE:1)
Block(-10,23,6,PRISMARINE:1)
Block(-10,24,-4,PRISMARINE:1)
Block(-10,24,-3,PRISMARINE:1)
Block(-10,24,3,PRISMARINE:1)
Block(-10,24,4,PRISMARINE:1)
Block(-10,25,-2,PRISMARINE:1)
Block(-10,25,-1,PRISMARINE:1)
Block(-10,25,1,PRISMARINE:1)
Block(-10,25,2,PRISMARINE:1)
Block(-10,26,0,PRISMARINE:1)
Block(-9,0,-15,PRISMARINE:1)
Block(-9,0,-14,PRISMARINE)
Block(-9,0,-13,PRISMARINE)
Block(-9,0,-12,PRISMARINE)
Block(-9,0,-11,PRISMARINE)
Block(-9,0,-10,PRISMARINE)
Block(-9,0,-9,PRISMARINE)
Block(-9,0,-8,PRISMARINE)
Block(-9,0,-7,PRISMARINE)
Block(-9,0,-6,PRISMARINE)
Block(-9,0,-5,PRISMARINE)
Block(-9,0,-4,PRISMARINE)
Block(-9,0,-3,PRISMARINE)
Block(-9,0,-2,PRISMARINE)
Block(-9,0,-1,PRISMARINE)
Block(-9,0,0,PRISMARINE)
Block(-9,0,1,PRISMARINE)
Block(-9,0,2,PRISMARINE)
Block(-9,0,3,PRISMARINE)
Block(-9,0,4,PRISMARINE)
Block(-9,0,5,PRISMARINE)
Block(-9,0,6,PRISMARINE)
Block(-9,0,7,PRISMARINE)
Block(-9,0,8,PRISMARINE)
Block(-9,0,9,PRISMARINE)
Block(-9,0,10,PRISMARINE)
Block(-9,0,11,PRISMARINE)
Block(-9,0,12,PRISMARINE)
Block(-9,0,13,PRISMARINE)
Block(-9,0,14,PRISMARINE)
Block(-9,0,15,PRISMARINE:1)
Block(-9,1,-15,PRISMARINE:1)
Block(-9,1,-14,PRISMARINE)
Block(-9,1,-13,PRISMARINE)
Block(-9,1,-12,PRISMARINE)
Block(-9,1,-11,PRISMARINE)
Block(-9,1,-10,PRISMARINE)
Block(-9,1,-9,PRISMARINE)
Block(-9,1,-8,PRISMARINE)
Block(-9,1,-7,PRISMARINE)
Block(-9,1,-6,PRISMARINE)
Block(-9,1,-5,PRISMARINE)
Block(-9,1,-4,PRISMARINE)
Block(-9,1,-3,PRISMARINE)
Block(-9,1,-2,PRISMARINE)
Block(-9,1,-1,PRISMARINE)
Block(-9,1,0,PRISMARINE)
Block(-9,1,1,PRISMARINE)
Block(-9,1,2,PRISMARINE)
Block(-9,1,3,PRISMARINE)
Block(-9,1,4,PRISMARINE)
Block(-9,1,5,PRISMARINE)
Block(-9,1,6,PRISMARINE)
Block(-9,1,7,PRISMARINE)
Block(-9,1,8,PRISMARINE)
Block(-9,1,9,PRISMARINE)
Block(-9,1,10,PRISMARINE)
Block(-9,1,11,PRISMARINE)
Block(-9,1,12,PRISMARINE)
Block(-9,1,13,PRISMARINE)
Block(-9,1,14,PRISMARINE)
Block(-9,1,15,PRISMARINE:1)
Block(-9,2,-15,PRISMARINE:1)
Block(-9,2,-14,PRISMARINE)
Block(-9,2,-13,PRISMARINE)
Block(-9,2,-12,PRISMARINE)
Block(-9,2,-11,PRISMARINE)
Block(-9,2,-10,PRISMARINE)
Block(-9,2,-9,PRISMARINE)
Block(-9,2,-8,PRISMARINE)
Block(-9,2,-7,PRISMARINE)
Block(-9,2,-6,PRISMARINE)
Block(-9,2,-5,PRISMARINE)
Block(-9,2,-4,PRISMARINE)
Block(-9,2,-3,PRISMARINE)
Block(-9,2,-2,PRISMARINE)
Block(-9,2,-1,PRISMARINE)
Block(-9,2,0,PRISMARINE)
Block(-9,2,1,PRISMARINE)
Block(-9,2,2,PRISMARINE)
Block(-9,2,3,PRISMARINE)
Block(-9,2,4,PRISMARINE)
Block(-9,2,5,PRISMARINE)
Block(-9,2,6,PRISMARINE)
Block(-9,2,7,PRISMARINE)
Block(-9,2,8,PRISMARINE)
Block(-9,2,9,PRISMARINE)
Block(-9,2,10,PRISMARINE)
Block(-9,2,11,PRISMARINE)
Block(-9,2,12,PRISMARINE)
Block(-9,2,13,PRISMARINE)
Block(-9,2,14,PRISMARINE)
Block(-9,2,15,PRISMARINE:1)
Block(-9,3,-15,PRISMARINE:1)
Block(-9,3,-14,PRISMARINE)
Block(-9,3,-13,PRISMARINE)
Block(-9,3,-12,PRISMARINE)
Block(-9,3,-11,PRISMARINE)
Block(-9,3,-10,PRISMARINE)
Block(-9,3,-9,PRISMARINE)
Block(-9,3,-8,PRISMARINE)
Block(-9,3,-7,PRISMARINE)
Block(-9,3,-6,PRISMARINE)
Block(-9,3,-5,PRISMARINE)
Block(-9,3,-4,PRISMARINE)
Block(-9,3,-3,PRISMARINE)
Block(-9,3,-2,PRISMARINE)
Block(-9,3,-1,PRISMARINE)
Block(-9,3,0,PRISMARINE)
Block(-9,3,1,PRISMARINE)
Block(-9,3,2,PRISMARINE)
Block(-9,3,3,PRISMARINE)
Block(-9,3,4,PRISMARINE)
Block(-9,3,5,PRISMARINE)
Block(-9,3,6,PRISMARINE)
Block(-9,3,7,PRISMARINE)
Block(-9,3,8,PRISMARINE)
Block(-9,3,9,PRISMARINE)
Block(-9,3,10,PRISMARINE)
Block(-9,3,11,PRISMARINE)
Block(-9,3,12,PRISMARINE)
Block(-9,3,13,PRISMARINE)
Block(-9,3,14,PRISMARINE)
Block(-9,3,15,PRISMARINE:1)
Block(-9,4,-14,PRISMARINE)
Block(-9,4,-13,PRISMARINE)
Block(-9,4,-12,PRISMARINE)
Block(-9,4,-11,PRISMARINE)
Block(-9,4,-10,PRISMARINE)
Block(-9,4,-9,PRISMARINE)
Block(-9,4,-8,PRISMARINE)
Block(-9,4,-7,PRISMARINE)
Block(-9,4,-6,PRISMARINE)
Block(-9,4,-5,PRISMARINE)
Block(-9,4,-4,PRISMARINE)
Block(-9,4,-3,PRISMARINE)
Block(-9,4,-2,PRISMARINE)
Block(-9,4,-1,PRISMARINE)
Block(-9,4,0,PRISMARINE)
Block(-9,4,1,PRISMARINE)
Block(-9,4,2,PRISMARINE)
Block(-9,4,3,PRISMARINE)
Block(-9,4,4,PRISMARINE)
Block(-9,4,5,PRISMARINE)
Block(-9,4,6,PRISMARINE)
Block(-9,4,7,PRISMARINE)
Block(-9,4,8,PRISMARINE)
Block(-9,4,9,PRISMARINE)
Block(-9,4,10,PRISMARINE)
Block(-9,4,11,PRISMARINE)
Block(-9,4,12,PRISMARINE)
Block(-9,4,13,PRISMARINE)
Block(-9,4,14,PRISMARINE)
Block(-9,5,-13,PRISMARINE)
Block(-9,5,-12,PRISMARINE)
Block(-9,5,-11,PRISMARINE)
Block(-9,5,-10,PRISMARINE)
Block(-9,5,-9,PRISMARINE)
Block(-9,5,-8,PRISMARINE)
Block(-9,5,-7,PRISMARINE)
Block(-9,5,-6,PRISMARINE)
Block(-9,5,-5,PRISMARINE)
Block(-9,5,-4,PRISMARINE)
Block(-9,5,-3,PRISMARINE)
Block(-9,5,-2,PRISMARINE)
Block(-9,5,-1,PRISMARINE)
Block(-9,5,0,PRISMARINE)
Block(-9,5,1,PRISMARINE)
Block(-9,5,2,PRISMARINE)
Block(-9,5,3,PRISMARINE)
Block(-9,5,4,PRISMARINE)
Block(-9,5,5,PRISMARINE)
Block(-9,5,6,PRISMARINE)
Block(-9,5,7,PRISMARINE)
Block(-9,5,8,PRISMARINE)
Block(-9,5,9,PRISMARINE)
Block(-9,5,10,PRISMARINE)
Block(-9,5,11,PRISMARINE)
Block(-9,5,12,PRISMARINE)
Block(-9,5,13,PRISMARINE)
Block(-9,6,-12,PRISMARINE:1)
Block(-9,6,-11,PRISMARINE)
Block(-9,6,-10,PRISMARINE)
Block(-9,6,-9,PRISMARINE)
Block(-9,6,-8,PRISMARINE)
Block(-9,6,-7,PRISMARINE)
Block(-9,6,-6,PRISMARINE)
Block(-9,6,-5,PRISMARINE)
Block(-9,6,-4,PRISMARINE)
Block(-9,6,-3,PRISMARINE)
Block(-9,6,-2,PRISMARINE)
Block(-9,6,-1,PRISMARINE)
Block(-9,6,0,PRISMARINE)
Block(-9,6,1,PRISMARINE)
Block(-9,6,2,PRISMARINE)
Block(-9,6,3,PRISMARINE)
Block(-9,6,4,PRISMARINE)
Block(-9,6,5,PRISMARINE)
Block(-9,6,6,PRISMARINE)
Block(-9,6,7,PRISMARINE)
Block(-9,6,8,PRISMARINE)
Block(-9,6,9,PRISMARINE)
Block(-9,6,10,PRISMARINE)
Block(-9,6,11,PRISMARINE)
Block(-9,6,12,PRISMARINE:1)
Block(-9,7,-10,PRISMARINE:1)
Block(-9,7,-9,PRISMARINE:1)
Block(-9,7,-8,PRISMARINE:1)
Block(-9,7,-6,PRISMARINE:1)
Block(-9,7,-5,PRISMARINE:1)
Block(-9,7,-3,PRISMARINE:1)
Block(-9,7,-2,PRISMARINE:1)
Block(-9,7,-1,PRISMARINE:1)
Block(-9,7,1,PRISMARINE:1)
Block(-9,7,2,PRISMARINE:1)
Block(-9,7,3,PRISMARINE:1)
Block(-9,7,5,PRISMARINE:1)
Block(-9,7,6,PRISMARINE:1)
Block(-9,7,8,PRISMARINE:1)
Block(-9,7,9,PRISMARINE:1)
Block(-9,7,10,PRISMARINE:1)
Block(-9,8,-9,PRISMARINE)
Block(-9,8,-6,PRISMARINE)
Block(-9,8,-5,PRISMARINE)
Block(-9,8,-2,PRISMARINE)
Block(-9,8,2,PRISMARINE)
Block(-9,8,5,PRISMARINE)
Block(-9,8,6,PRISMARINE)
Block(-9,8,9,PRISMARINE)
Block(-9,9,-10,PRISMARINE:2)
Block(-9,9,-9,PRISMARINE)
Block(-9,9,-8,PRISMARINE:2)
Block(-9,9,-6,PRISMARINE)
Block(-9,9,-5,PRISMARINE)
Block(-9,9,-3,PRISMARINE:2)
Block(-9,9,-2,PRISMARINE)
Block(-9,9,-1,PRISMARINE:2)
Block(-9,9,1,PRISMARINE:2)
Block(-9,9,2,PRISMARINE)
Block(-9,9,3,PRISMARINE:2)
Block(-9,9,5,PRISMARINE)
Block(-9,9,6,PRISMARINE)
Block(-9,9,8,PRISMARINE:2)
Block(-9,9,9,PRISMARINE)
Block(-9,9,10,PRISMARINE:2)
Block(-9,10,-9,PRISMARINE)
Block(-9,10,-6,PRISMARINE)
Block(-9,10,-5,PRISMARINE)
Block(-9,10,-2,PRISMARINE)
Block(-9,10,2,PRISMARINE)
Block(-9,10,5,PRISMARINE)
Block(-9,10,6,PRISMARINE)
Block(-9,10,9,PRISMARINE)
Block(-9,11,-10,PRISMARINE:2)
Block(-9,11,-9,PRISMARINE)
Block(-9,11,-8,PRISMARINE:2)
Block(-9,11,-6,PRISMARINE)
Block(-9,11,-5,PRISMARINE)
Block(-9,11,-3,PRISMARINE:2)
Block(-9,11,-2,PRISMARINE)
Block(-9,11,-1,PRISMARINE:2)
Block(-9,11,1,PRISMARINE:2)
Block(-9,11,2,PRISMARINE)
Block(-9,11,3,PRISMARINE:2)
Block(-9,11,5,PRISMARINE)
Block(-9,11,6,PRISMARINE)
Block(-9,11,8,PRISMARINE:2)
Block(-9,11,9,PRISMARINE)
Block(-9,11,10,PRISMARINE:2)
Block(-9,12,-9,PRISMARINE)
Block(-9,12,-6,PRISMARINE)
Block(-9,12,-5,PRISMARINE)
Block(-9,12,-2,PRISMARINE)
Block(-9,12,2,PRISMARINE)
Block(-9,12,5,PRISMARINE)
Block(-9,12,6,PRISMARINE)
Block(-9,12,9,PRISMARINE)
Block(-9,13,-10,PRISMARINE:2)
Block(-9,13,-9,PRISMARINE)
Block(-9,13,-8,PRISMARINE:2)
Block(-9,13,-6,PRISMARINE)
Block(-9,13,-5,PRISMARINE)
Block(-9,13,-3,PRISMARINE:2)
Block(-9,13,-2,PRISMARINE)
Block(-9,13,-1,PRISMARINE:2)
Block(-9,13,1,PRISMARINE:2)
Block(-9,13,2,PRISMARINE)
Block(-9,13,3,PRISMARINE:2)
Block(-9,13,5,PRISMARINE)
Block(-9,13,6,PRISMARINE)
Block(-9,13,8,PRISMARINE:2)
Block(-9,13,9,PRISMARINE)
Block(-9,13,10,PRISMARINE:2)
Block(-9,14,-9,PRISMARINE)
Block(-9,14,-6,PRISMARINE)
Block(-9,14,-5,PRISMARINE)
Block(-9,14,-2,PRISMARINE)
Block(-9,14,2,PRISMARINE)
Block(-9,14,5,PRISMARINE)
Block(-9,14,6,PRISMARINE)
Block(-9,14,9,PRISMARINE)
Block(-9,15,-10,PRISMARINE:2)
Block(-9,15,-9,PRISMARINE)
Block(-9,15,-8,PRISMARINE:2)
Block(-9,15,-6,PRISMARINE)
Block(-9,15,-5,PRISMARINE)
Block(-9,15,-3,PRISMARINE:2)
Block(-9,15,-2,PRISMARINE)
Block(-9,15,-1,PRISMARINE:2)
Block(-9,15,1,PRISMARINE:2)
Block(-9,15,2,PRISMARINE)
Block(-9,15,3,PRISMARINE:2)
Block(-9,15,5,PRISMARINE)
Block(-9,15,6,PRISMARINE)
Block(-9,15,8,PRISMARINE:2)
Block(-9,15,9,PRISMARINE)
Block(-9,15,10,PRISMARINE:2)
Block(-9,16,-10,PRISMARINE:1)
Block(-9,16,-9,PRISMARINE)
Block(-9,16,-8,PRISMARINE:1)
Block(-9,16,-7,PRISMARINE:1)
Block(-9,16,-6,PRISMARINE:1)
Block(-9,16,-5,PRISMARINE:1)
Block(-9,16,-4,PRISMARINE:1)
Block(-9,16,-3,PRISMARINE:1)
Block(-9,16,-2,PRISMARINE)
Block(-9,16,-1,PRISMARINE:1)
Block(-9,16,0,PRISMARINE:1)
Block(-9,16,1,PRISMARINE:1)
Block(-9,16,2,PRISMARINE)
Block(-9,16,3,PRISMARINE:1)
Block(-9,16,4,PRISMARINE:1)
Block(-9,16,5,PRISMARINE:1)
Block(-9,16,6,PRISMARINE:1)
Block(-9,16,7,PRISMARINE:1)
Block(-9,16,8,PRISMARINE:1)
Block(-9,16,9,PRISMARINE)
Block(-9,16,10,PRISMARINE:1)
Block(-9,17,-10,PRISMARINE:2)
Block(-9,17,-9,PRISMARINE)
Block(-9,17,-8,PRISMARINE)
Block(-9,17,-7,PRISMARINE)
Block(-9,17,-6,PRISMARINE)
Block(-9,17,-5,PRISMARINE)
Block(-9,17,-4,PRISMARINE)
Block(-9,17,-3,PRISMARINE)
Block(-9,17,-2,PRISMARINE)
Block(-9,17,-1,PRISMARINE)
Block(-9,17,0,PRISMARINE)
Block(-9,17,1,PRISMARINE)
Block(-9,17,2,PRISMARINE)
Block(-9,17,3,PRISMARINE)
Block(-9,17,4,PRISMARINE)
Block(-9,17,5,PRISMARINE)
Block(-9,17,6,PRISMARINE)
Block(-9,17,7,PRISMARINE)
Block(-9,17,8,PRISMARINE)
Block(-9,17,9,PRISMARINE)
Block(-9,17,10,PRISMARINE:2)
Block(-9,18,-9,PRISMARINE)
Block(-9,18,-8,PRISMARINE)
Block(-9,18,-7,PRISMARINE)
Block(-9,18,-6,PRISMARINE)
Block(-9,18,-5,PRISMARINE)
Block(-9,18,-4,PRISMARINE)
Block(-9,18,-3,PRISMARINE)
Block(-9,18,-2,SEA_LANTERN)
Block(-9,18,-1,PRISMARINE)
Block(-9,18,0,PRISMARINE)
Block(-9,18,1,PRISMARINE)
Block(-9,18,2,SEA_LANTERN)
Block(-9,18,3,PRISMARINE)
Block(-9,18,4,PRISMARINE)
Block(-9,18,5,PRISMARINE)
Block(-9,18,6,PRISMARINE)
Block(-9,18,7,PRISMARINE)
Block(-9,18,8,PRISMARINE)
Block(-9,18,9,PRISMARINE)
Block(-9,19,-10,PRISMARINE:2)
Block(-9,19,-9,PRISMARINE)
Block(-9,19,-8,PRISMARINE)
Block(-9,19,-7,PRISMARINE)
Block(-9,19,-6,PRISMARINE)
Block(-9,19,-5,PRISMARINE)
Block(-9,19,-4,PRISMARINE)
Block(-9,19,-3,PRISMARINE)
Block(-9,19,-2,PRISMARINE)
Block(-9,19,-1,PRISMARINE)
Block(-9,19,0,PRISMARINE)
Block(-9,19,1,PRISMARINE)
Block(-9,19,2,PRISMARINE)
Block(-9,19,3,PRISMARINE)
Block(-9,19,4,PRISMARINE)
Block(-9,19,5,PRISMARINE)
Block(-9,19,6,PRISMARINE)
Block(-9,19,7,PRISMARINE)
Block(-9,19,8,PRISMARINE)
Block(-9,19,9,PRISMARINE)
Block(-9,19,10,PRISMARINE:2)
Block(-9,20,-12,PRISMARINE:1)
Block(-9,20,-11,PRISMARINE:1)
Block(-9,20,-10,PRISMARINE:2)
Block(-9,20,-9,PRISMARINE:2)
Block(-9,20,-8,PRISMARINE:2)
Block(-9,20,-7,PRISMARINE:2)
Block(-9,20,-6,PRISMARINE:2)
Block(-9,20,-5,PRISMARINE:2)
Block(-9,20,-4,PRISMARINE:2)
Block(-9,20,-3,PRISMARINE:2)
Block(-9,20,-2,PRISMARINE:2)
Block(-9,20,-1,PRISMARINE:2)
Block(-9,20,0,PRISMARINE:2)
Block(-9,20,1,PRISMARINE:2)
Block(-9,20,2,PRISMARINE:2)
Block(-9,20,3,PRISMARINE:2)
Block(-9,20,4,PRISMARINE:2)
Block(-9,20,5,PRISMARINE:2)
Block(-9,20,6,PRISMARINE:2)
Block(-9,20,7,PRISMARINE:2)
Block(-9,20,8,PRISMARINE:2)
Block(-9,20,9,PRISMARINE:2)
Block(-9,20,10,PRISMARINE:2)
Block(-9,20,11,PRISMARINE:1)
Block(-9,20,12,PRISMARINE:1)
Block(-9,21,-11,PRISMARINE:1)
Block(-9,21,-10,PRISMARINE:1)
Block(-9,21,-9,PRISMARINE:1)
Block(-9,21,-6,PRISMARINE:2)
Block(-9,21,-3,PRISMARINE:2)
Block(-9,21,0,PRISMARINE:2)
Block(-9,21,3,PRISMARINE:2)
Block(-9,21,6,PRISMARINE:2)
Block(-9,21,9,PRISMARINE:1)
Block(-9,21,10,PRISMARINE:1)
Block(-9,21,11,PRISMARINE:1)
Block(-9,22,-9,PRISMARINE:1)
Block(-9,22,-8,PRISMARINE:1)
Block(-9,22,-7,PRISMARINE:1)
Block(-9,22,-6,PRISMARINE:2)
Block(-9,22,-3,PRISMARINE:2)
Block(-9,22,0,PRISMARINE:2)
Block(-9,22,3,PRISMARINE:2)
Block(-9,22,6,PRISMARINE:2)
Block(-9,22,7,PRISMARINE:1)
Block(-9,22,8,PRISMARINE:1)
Block(-9,22,9,PRISMARINE:1)
Block(-9,23,-7,PRISMARINE:1)
Block(-9,23,-6,PRISMARINE:1)
Block(-9,23,-5,PRISMARINE:1)
Block(-9,23,-3,PRISMARINE:2)
Block(-9,23,0,PRISMARINE:2)
Block(-9,23,3,PRISMARINE:2)
Block(-9,23,5,PRISMARINE:1)
Block(-9,23,6,PRISMARINE:1)
Block(-9,23,7,PRISMARINE:1)
Block(-9,24,-5,PRISMARINE:1)
Block(-9,24,-4,PRISMARINE:1)
Block(-9,24,-3,PRISMARINE:1)
Block(-9,24,0,PRISMARINE:2)
Block(-9,24,3,PRISMARINE:1)
Block(-9,24,4,PRISMARINE:1)
Block(-9,24,5,PRISMARINE:1)
Block(-9,25,-3,PRISMARINE:1)
Block(-9,25,-2,PRISMARINE:1)
Block(-9,25,-1,PRISMARINE:1)
Block(-9,25,0,PRISMARINE:2)
Block(-9,25,1,PRISMARINE:1)
Block(-9,25,2,PRISMARINE:1)
Block(-9,25,3,PRISMARINE:1)
Block(-9,26,-1,PRISMARINE:1)
Block(-9,26,0,PRISMARINE:1)
Block(-9,26,1,PRISMARINE:1)
Block(-9,27,0,PRISMARINE:1)
Block(-8,0,-15,PRISMARINE:1)
Block(-8,0,-14,PRISMARINE)
Block(-8,0,-13,PRISMARINE)
Block(-8,0,-12,PRISMARINE)
Block(-8,0,-11,PRISMARINE)
Block(-8,0,-10,PRISMARINE)
Block(-8,0,-9,PRISMARINE)
Block(-8,0,-8,PRISMARINE)
Block(-8,0,-7,PRISMARINE)
Block(-8,0,-6,PRISMARINE)
Block(-8,0,-5,PRISMARINE)
Block(-8,0,-4,PRISMARINE)
Block(-8,0,-3,PRISMARINE)
Block(-8,0,-2,PRISMARINE)
Block(-8,0,-1,PRISMARINE)
Block(-8,0,0,PRISMARINE)
Block(-8,0,1,PRISMARINE)
Block(-8,0,2,PRISMARINE)
Block(-8,0,3,PRISMARINE)
Block(-8,0,4,PRISMARINE)
Block(-8,0,5,PRISMARINE)
Block(-8,0,6,PRISMARINE)
Block(-8,0,7,PRISMARINE)
Block(-8,0,8,PRISMARINE)
Block(-8,0,9,PRISMARINE)
Block(-8,0,10,PRISMARINE)
Block(-8,0,11,PRISMARINE)
Block(-8,0,12,PRISMARINE)
Block(-8,0,13,PRISMARINE)
Block(-8,0,14,PRISMARINE)
Block(-8,0,15,PRISMARINE:1)
Block(-8,1,-15,PRISMARINE:1)
Block(-8,1,-14,PRISMARINE)
Block(-8,1,-13,PRISMARINE)
Block(-8,1,-12,PRISMARINE)
Block(-8,1,-11,PRISMARINE)
Block(-8,1,-10,PRISMARINE)
Block(-8,1,-9,PRISMARINE)
Block(-8,1,-8,PRISMARINE)
Block(-8,1,-7,PRISMARINE)
Block(-8,1,-6,PRISMARINE)
Block(-8,1,-5,PRISMARINE)
Block(-8,1,-4,PRISMARINE)
Block(-8,1,-3,PRISMARINE)
Block(-8,1,-2,PRISMARINE)
Block(-8,1,-1,PRISMARINE)
Block(-8,1,0,PRISMARINE)
Block(-8,1,1,PRISMARINE)
Block(-8,1,2,PRISMARINE)
Block(-8,1,3,PRISMARINE)
Block(-8,1,4,PRISMARINE)
Block(-8,1,5,PRISMARINE)
Block(-8,1,6,PRISMARINE)
Block(-8,1,7,PRISMARINE)
Block(-8,1,8,PRISMARINE)
Block(-8,1,9,PRISMARINE)
Block(-8,1,10,PRISMARINE)
Block(-8,1,11,PRISMARINE)
Block(-8,1,12,PRISMARINE)
Block(-8,1,13,PRISMARINE)
Block(-8,1,14,PRISMARINE)
Block(-8,1,15,PRISMARINE:1)
Block(-8,2,-15,PRISMARINE:1)
Block(-8,2,-14,PRISMARINE)
Block(-8,2,-13,PRISMARINE)
Block(-8,2,-12,PRISMARINE)
Block(-8,2,-11,PRISMARINE)
Block(-8,2,-10,PRISMARINE)
Block(-8,2,-9,PRISMARINE)
Block(-8,2,-8,PRISMARINE)
Block(-8,2,-7,PRISMARINE)
Block(-8,2,-6,PRISMARINE)
Block(-8,2,-5,PRISMARINE)
Block(-8,2,-4,PRISMARINE)
Block(-8,2,-3,PRISMARINE)
Block(-8,2,-2,PRISMARINE)
Block(-8,2,-1,PRISMARINE)
Block(-8,2,0,PRISMARINE)
Block(-8,2,1,PRISMARINE)
Block(-8,2,2,PRISMARINE)
Block(-8,2,3,PRISMARINE)
Block(-8,2,4,PRISMARINE)
Block(-8,2,5,PRISMARINE)
Block(-8,2,6,PRISMARINE)
Block(-8,2,7,PRISMARINE)
Block(-8,2,8,PRISMARINE)
Block(-8,2,9,PRISMARINE)
Block(-8,2,10,PRISMARINE)
Block(-8,2,11,PRISMARINE)
Block(-8,2,12,PRISMARINE)
Block(-8,2,13,PRISMARINE)
Block(-8,2,14,PRISMARINE)
Block(-8,2,15,PRISMARINE:1)
Block(-8,3,-15,PRISMARINE:1)
Block(-8,3,-14,PRISMARINE)
Block(-8,3,-13,PRISMARINE)
Block(-8,3,-12,PRISMARINE)
Block(-8,3,-11,PRISMARINE)
Block(-8,3,-10,PRISMARINE)
Block(-8,3,-9,PRISMARINE)
Block(-8,3,-8,PRISMARINE)
Block(-8,3,-7,PRISMARINE)
Block(-8,3,-6,PRISMARINE)
Block(-8,3,-5,PRISMARINE)
Block(-8,3,-4,PRISMARINE)
Block(-8,3,-3,PRISMARINE)
Block(-8,3,-2,PRISMARINE)
Block(-8,3,-1,PRISMARINE)
Block(-8,3,0,PRISMARINE)
Block(-8,3,1,PRISMARINE)
Block(-8,3,2,PRISMARINE)
Block(-8,3,3,PRISMARINE)
Block(-8,3,4,PRISMARINE)
Block(-8,3,5,PRISMARINE)
Block(-8,3,6,PRISMARINE)
Block(-8,3,7,PRISMARINE)
Block(-8,3,8,PRISMARINE)
Block(-8,3,9,PRISMARINE)
Block(-8,3,10,PRISMARINE)
Block(-8,3,11,PRISMARINE)
Block(-8,3,12,PRISMARINE)
Block(-8,3,13,PRISMARINE)
Block(-8,3,14,PRISMARINE)
Block(-8,3,15,PRISMARINE:1)
Block(-8,4,-14,PRISMARINE)
Block(-8,4,-13,PRISMARINE)
Block(-8,4,-12,PRISMARINE)
Block(-8,4,-11,PRISMARINE)
Block(-8,4,-10,PRISMARINE)
Block(-8,4,-9,PRISMARINE)
Block(-8,4,-8,PRISMARINE)
Block(-8,4,-7,PRISMARINE)
Block(-8,4,-6,PRISMARINE)
Block(-8,4,-5,PRISMARINE)
Block(-8,4,-4,PRISMARINE)
Block(-8,4,-3,PRISMARINE)
Block(-8,4,-2,PRISMARINE)
Block(-8,4,-1,PRISMARINE)
Block(-8,4,0,PRISMARINE)
Block(-8,4,1,PRISMARINE)
Block(-8,4,2,PRISMARINE)
Block(-8,4,3,PRISMARINE)
Block(-8,4,4,PRISMARINE)
Block(-8,4,5,PRISMARINE)
Block(-8,4,6,PRISMARINE)
Block(-8,4,7,PRISMARINE)
Block(-8,4,8,PRISMARINE)
Block(-8,4,9,PRISMARINE)
Block(-8,4,10,PRISMARINE)
Block(-8,4,11,PRISMARINE)
Block(-8,4,12,PRISMARINE)
Block(-8,4,13,PRISMARINE)
Block(-8,4,14,PRISMARINE)
Block(-8,5,-13,PRISMARINE)
Block(-8,5,-12,PRISMARINE)
Block(-8,5,-11,PRISMARINE)
Block(-8,5,-10,PRISMARINE)
Block(-8,5,-9,PRISMARINE)
Block(-8,5,-8,PRISMARINE)
Block(-8,5,-7,PRISMARINE)
Block(-8,5,-6,PRISMARINE)
Block(-8,5,-5,PRISMARINE)
Block(-8,5,-4,PRISMARINE)
Block(-8,5,-3,PRISMARINE)
Block(-8,5,-2,PRISMARINE)
Block(-8,5,-1,PRISMARINE)
Block(-8,5,0,PRISMARINE)
Block(-8,5,1,PRISMARINE)
Block(-8,5,2,PRISMARINE)
Block(-8,5,3,PRISMARINE)
Block(-8,5,4,PRISMARINE)
Block(-8,5,5,PRISMARINE)
Block(-8,5,6,PRISMARINE)
Block(-8,5,7,PRISMARINE)
Block(-8,5,8,PRISMARINE)
Block(-8,5,9,PRISMARINE)
Block(-8,5,10,PRISMARINE)
Block(-8,5,11,PRISMARINE)
Block(-8,5,12,PRISMARINE)
Block(-8,5,13,PRISMARINE)
Block(-8,6,-12,PRISMARINE:1)
Block(-8,6,-11,PRISMARINE)
Block(-8,6,-10,PRISMARINE)
Block(-8,6,-9,PRISMARINE)
Block(-8,6,-8,PRISMARINE)
Block(-8,6,-7,PRISMARINE)
Block(-8,6,-6,PRISMARINE)
Block(-8,6,-5,PRISMARINE)
Block(-8,6,-4,PRISMARINE)
Block(-8,6,-3,PRISMARINE)
Block(-8,6,-2,PRISMARINE)
Block(-8,6,-1,PRISMARINE)
Block(-8,6,0,PRISMARINE)
Block(-8,6,1,PRISMARINE)
Block(-8,6,2,PRISMARINE)
Block(-8,6,3,PRISMARINE)
Block(-8,6,4,PRISMARINE)
Block(-8,6,5,PRISMARINE)
Block(-8,6,6,PRISMARINE)
Block(-8,6,7,PRISMARINE)
Block(-8,6,8,PRISMARINE)
Block(-8,6,9,PRISMARINE)
Block(-8,6,10,PRISMARINE)
Block(-8,6,11,PRISMARINE)
Block(-8,6,12,PRISMARINE:1)
Block(-8,7,-10,PRISMARINE:1)
Block(-8,7,-9,PRISMARINE:1)
Block(-8,7,-8,PRISMARINE:1)
Block(-8,7,-6,PRISMARINE:1)
Block(-8,7,-5,PRISMARINE:1)
Block(-8,7,-3,PRISMARINE:1)
Block(-8,7,-2,PRISMARINE:1)
Block(-8,7,-1,PRISMARINE:1)
Block(-8,7,1,PRISMARINE:1)
Block(-8,7,2,PRISMARINE:1)
Block(-8,7,3,PRISMARINE:1)
Block(-8,7,5,PRISMARINE:1)
Block(-8,7,6,PRISMARINE:1)
Block(-8,7,8,PRISMARINE:1)
Block(-8,7,9,PRISMARINE:1)
Block(-8,7,10,PRISMARINE:1)
Block(-8,8,-10,PRISMARINE:1)
Block(-8,8,-8,PRISMARINE:1)
Block(-8,8,-6,PRISMARINE)
Block(-8,8,-5,PRISMARINE)
Block(-8,8,-3,PRISMARINE:1)
Block(-8,8,-1,PRISMARINE:1)
Block(-8,8,1,PRISMARINE:1)
Block(-8,8,3,PRISMARINE:1)
Block(-8,8,5,PRISMARINE)
Block(-8,8,6,PRISMARINE)
Block(-8,8,8,PRISMARINE:1)
Block(-8,8,10,PRISMARINE:1)
Block(-8,9,-10,PRISMARINE:1)
Block(-8,9,-9,PRISMARINE:2)
Block(-8,9,-8,PRISMARINE:1)
Block(-8,9,-6,PRISMARINE)
Block(-8,9,-5,PRISMARINE)
Block(-8,9,-3,PRISMARINE:1)
Block(-8,9,-2,PRISMARINE:2)
Block(-8,9,-1,PRISMARINE:1)
Block(-8,9,1,PRISMARINE:1)
Block(-8,9,2,PRISMARINE:2)
Block(-8,9,3,PRISMARINE:1)
Block(-8,9,5,PRISMARINE)
Block(-8,9,6,PRISMARINE)
Block(-8,9,8,PRISMARINE:1)
Block(-8,9,9,PRISMARINE:2)
Block(-8,9,10,PRISMARINE:1)
Block(-8,10,-10,PRISMARINE:1)
Block(-8,10,-8,PRISMARINE:1)
Block(-8,10,-6,PRISMARINE)
Block(-8,10,-5,PRISMARINE)
Block(-8,10,-3,PRISMARINE:1)
Block(-8,10,-1,PRISMARINE:1)
Block(-8,10,1,PRISMARINE:1)
Block(-8,10,3,PRISMARINE:1)
Block(-8,10,5,PRISMARINE)
Block(-8,10,6,PRISMARINE)
Block(-8,10,8,PRISMARINE:1)
Block(-8,10,10,PRISMARINE:1)
Block(-8,11,-10,PRISMARINE:1)
Block(-8,11,-9,PRISMARINE:2)
Block(-8,11,-8,PRISMARINE:1)
Block(-8,11,-6,PRISMARINE)
Block(-8,11,-5,PRISMARINE)
Block(-8,11,-3,PRISMARINE:1)
Block(-8,11,-2,PRISMARINE:2)
Block(-8,11,-1,PRISMARINE:1)
Block(-8,11,1,PRISMARINE:1)
Block(-8,11,2,PRISMARINE:2)
Block(-8,11,3,PRISMARINE:1)
Block(-8,11,5,PRISMARINE)
Block(-8,11,6,PRISMARINE)
Block(-8,11,8,PRISMARINE:1)
Block(-8,11,9,PRISMARINE:2)
Block(-8,11,10,PRISMARINE:1)
Block(-8,12,-10,PRISMARINE:1)
Block(-8,12,-8,PRISMARINE:1)
Block(-8,12,-6,PRISMARINE)
Block(-8,12,-5,PRISMARINE)
Block(-8,12,-3,PRISMARINE:1)
Block(-8,12,-1,PRISMARINE:1)
Block(-8,12,1,PRISMARINE:1)
Block(-8,12,3,PRISMARINE:1)
Block(-8,12,5,PRISMARINE)
Block(-8,12,6,PRISMARINE)
Block(-8,12,8,PRISMARINE:1)
Block(-8,12,10,PRISMARINE:1)
Block(-8,13,-10,PRISMARINE:1)
Block(-8,13,-9,PRISMARINE:2)
Block(-8,13,-8,PRISMARINE:1)
Block(-8,13,-6,PRISMARINE)
Block(-8,13,-5,PRISMARINE)
Block(-8,13,-3,PRISMARINE:1)
Block(-8,13,-2,PRISMARINE:2)
Block(-8,13,-1,PRISMARINE:1)
Block(-8,13,1,PRISMARINE:1)
Block(-8,13,2,PRISMARINE:2)
Block(-8,13,3,PRISMARINE:1)
Block(-8,13,5,PRISMARINE)
Block(-8,13,6,PRISMARINE)
Block(-8,13,8,PRISMARINE:1)
Block(-8,13,9,PRISMARINE:2)
Block(-8,13,10,PRISMARINE:1)
Block(-8,14,-10,PRISMARINE:1)
Block(-8,14,-8,PRISMARINE:1)
Block(-8,14,-6,PRISMARINE)
Block(-8,14,-5,PRISMARINE)
Block(-8,14,-3,PRISMARINE:1)
Block(-8,14,-1,PRISMARINE:1)
Block(-8,14,1,PRISMARINE:1)
Block(-8,14,3,PRISMARINE:1)
Block(-8,14,5,PRISMARINE)
Block(-8,14,6,PRISMARINE)
Block(-8,14,8,PRISMARINE:1)
Block(-8,14,10,PRISMARINE:1)
Block(-8,15,-10,PRISMARINE:1)
Block(-8,15,-9,PRISMARINE:2)
Block(-8,15,-8,PRISMARINE:1)
Block(-8,15,-6,PRISMARINE)
Block(-8,15,-5,PRISMARINE)
Block(-8,15,-3,PRISMARINE:1)
Block(-8,15,-2,PRISMARINE:2)
Block(-8,15,-1,PRISMARINE:1)
Block(-8,15,1,PRISMARINE:1)
Block(-8,15,2,PRISMARINE:2)
Block(-8,15,3,PRISMARINE:1)
Block(-8,15,5,PRISMARINE)
Block(-8,15,6,PRISMARINE)
Block(-8,15,8,PRISMARINE:1)
Block(-8,15,9,PRISMARINE:2)
Block(-8,15,10,PRISMARINE:1)
Block(-8,16,-10,PRISMARINE:1)
Block(-8,16,-9,PRISMARINE:1)
Block(-8,16,-8,PRISMARINE:1)
Block(-8,16,-6,PRISMARINE:1)
Block(-8,16,-5,PRISMARINE:1)
Block(-8,16,-3,PRISMARINE:1)
Block(-8,16,-2,PRISMARINE:1)
Block(-8,16,-1,PRISMARINE:1)
Block(-8,16,1,PRISMARINE:1)
Block(-8,16,2,PRISMARINE:1)
Block(-8,16,3,PRISMARINE:1)
Block(-8,16,5,PRISMARINE:1)
Block(-8,16,6,PRISMARINE:1)
Block(-8,16,8,PRISMARINE:1)
Block(-8,16,9,PRISMARINE:1)
Block(-8,16,10,PRISMARINE:1)
Block(-8,17,-10,PRISMARINE:2)
Block(-8,17,-9,PRISMARINE)
Block(-8,17,-8,PRISMARINE:1)
Block(-8,17,-7,PRISMARINE:1)
Block(-8,17,-6,PRISMARINE:1)
Block(-8,17,-5,PRISMARINE:1)
Block(-8,17,-4,PRISMARINE:1)
Block(-8,17,-3,PRISMARINE:1)
Block(-8,17,-2,PRISMARINE:1)
Block(-8,17,-1,PRISMARINE:1)
Block(-8,17,0,PRISMARINE:1)
Block(-8,17,1,PRISMARINE:1)
Block(-8,17,2,PRISMARINE:1)
Block(-8,17,3,PRISMARINE:1)
Block(-8,17,4,PRISMARINE:1)
Block(-8,17,5,PRISMARINE:1)
Block(-8,17,6,PRISMARINE:1)
Block(-8,17,7,PRISMARINE:1)
Block(-8,17,8,PRISMARINE:1)
Block(-8,17,9,PRISMARINE)
Block(-8,17,10,PRISMARINE:2)
Block(-8,18,-9,PRISMARINE)
Block(-8,18,-8,PRISMARINE)
Block(-8,18,-7,PRISMARINE)
Block(-8,18,-6,PRISMARINE)
Block(-8,18,-5,PRISMARINE)
Block(-8,18,-4,PRISMARINE)
Block(-8,18,-3,PRISMARINE)
Block(-8,18,-2,PRISMARINE)
Block(-8,18,-1,PRISMARINE)
Block(-8,18,0,PRISMARINE)
Block(-8,18,1,PRISMARINE)
Block(-8,18,2,PRISMARINE)
Block(-8,18,3,PRISMARINE)
Block(-8,18,4,PRISMARINE)
Block(-8,18,5,PRISMARINE)
Block(-8,18,6,PRISMARINE)
Block(-8,18,7,PRISMARINE)
Block(-8,18,8,PRISMARINE)
Block(-8,18,9,PRISMARINE)
Block(-8,19,-10,PRISMARINE:2)
Block(-8,19,-9,PRISMARINE:1)
Block(-8,19,-8,PRISMARINE:1)
Block(-8,19,-7,PRISMARINE:1)
Block(-8,19,-6,PRISMARINE:1)
Block(-8,19,-5,PRISMARINE:1)
Block(-8,19,-4,PRISMARINE:1)
Block(-8,19,-3,PRISMARINE:1)
Block(-8,19,-2,PRISMARINE:1)
Block(-8,19,-1,PRISMARINE:1)
Block(-8,19,0,PRISMARINE:1)
Block(-8,19,1,PRISMARINE:1)
Block(-8,19,2,PRISMARINE:1)
Block(-8,19,3,PRISMARINE:1)
Block(-8,19,4,PRISMARINE:1)
Block(-8,19,5,PRISMARINE:1)
Block(-8,19,6,PRISMARINE:1)
Block(-8,19,7,PRISMARINE:1)
Block(-8,19,8,PRISMARINE:1)
Block(-8,19,9,PRISMARINE)
Block(-8,19,10,PRISMARINE:2)
Block(-8,20,-12,PRISMARINE:1)
Block(-8,20,-11,PRISMARINE:1)
Block(-8,20,-10,PRISMARINE)
Block(-8,20,-9,PRISMARINE)
Block(-8,20,-8,PRISMARINE)
Block(-8,20,-7,PRISMARINE)
Block(-8,20,-6,PRISMARINE)
Block(-8,20,-5,PRISMARINE)
Block(-8,20,-4,PRISMARINE)
Block(-8,20,-3,PRISMARINE)
Block(-8,20,-2,PRISMARINE)
Block(-8,20,-1,PRISMARINE)
Block(-8,20,0,PRISMARINE)
Block(-8,20,1,PRISMARINE)
Block(-8,20,2,PRISMARINE)
Block(-8,20,3,PRISMARINE)
Block(-8,20,4,PRISMARINE)
Block(-8,20,5,PRISMARINE)
Block(-8,20,6,PRISMARINE)
Block(-8,20,7,PRISMARINE)
Block(-8,20,8,PRISMARINE)
Block(-8,20,9,PRISMARINE)
Block(-8,20,11,PRISMARINE:1)
Block(-8,20,12,PRISMARINE:1)
Block(-8,21,-11,PRISMARINE:1)
Block(-8,21,-10,PRISMARINE:1)
Block(-8,21,-9,PRISMARINE:1)
Block(-8,21,-8,PRISMARINE)
Block(-8,21,-7,PRISMARINE)
Block(-8,21,-6,PRISMARINE)
Block(-8,21,-5,PRISMARINE)
Block(-8,21,-4,PRISMARINE)
Block(-8,21,-3,PRISMARINE)
Block(-8,21,-2,PRISMARINE)
Block(-8,21,-1,PRISMARINE)
Block(-8,21,0,PRISMARINE)
Block(-8,21,1,PRISMARINE)
Block(-8,21,2,PRISMARINE)
Block(-8,21,3,PRISMARINE)
Block(-8,21,4,PRISMARINE)
Block(-8,21,5,PRISMARINE)
Block(-8,21,6,PRISMARINE)
Block(-8,21,7,PRISMARINE)
Block(-8,21,8,PRISMARINE)
Block(-8,21,9,PRISMARINE:1)
Block(-8,21,10,PRISMARINE:1)
Block(-8,21,11,PRISMARINE:1)
Block(-8,22,-9,PRISMARINE:1)
Block(-8,22,-8,PRISMARINE:1)
Block(-8,22,-7,PRISMARINE:1)
Block(-8,22,-6,PRISMARINE)
Block(-8,22,-5,PRISMARINE)
Block(-8,22,-4,PRISMARINE)
Block(-8,22,-3,PRISMARINE)
Block(-8,22,-2,PRISMARINE)
Block(-8,22,-1,PRISMARINE)
Block(-8,22,0,PRISMARINE)
Block(-8,22,1,PRISMARINE)
Block(-8,22,2,PRISMARINE)
Block(-8,22,3,PRISMARINE)
Block(-8,22,4,PRISMARINE)
Block(-8,22,5,PRISMARINE)
Block(-8,22,6,PRISMARINE)
Block(-8,22,7,PRISMARINE:1)
Block(-8,22,8,PRISMARINE:1)
Block(-8,22,9,PRISMARINE:1)
Block(-8,23,-7,PRISMARINE:1)
Block(-8,23,-6,PRISMARINE:1)
Block(-8,23,-5,PRISMARINE:1)
Block(-8,23,-4,PRISMARINE)
Block(-8,23,-3,PRISMARINE)
Block(-8,23,-2,PRISMARINE)
Block(-8,23,-1,PRISMARINE)
Block(-8,23,0,PRISMARINE)
Block(-8,23,1,PRISMARINE)
Block(-8,23,2,PRISMARINE)
Block(-8,23,3,PRISMARINE)
Block(-8,23,4,PRISMARINE)
Block(-8,23,5,PRISMARINE:1)
Block(-8,23,6,PRISMARINE:1)
Block(-8,23,7,PRISMARINE:1)
Block(-8,24,-5,PRISMARINE:1)
Block(-8,24,-4,PRISMARINE:1)
Block(-8,24,-3,PRISMARINE:1)
Block(-8,24,-2,PRISMARINE)
Block(-8,24,-1,PRISMARINE)
Block(-8,24,0,PRISMARINE)
Block(-8,24,1,PRISMARINE)
Block(-8,24,2,PRISMARINE)
Block(-8,24,3,PRISMARINE:1)
Block(-8,24,4,PRISMARINE:1)
Block(-8,24,5,PRISMARINE:1)
Block(-8,25,-3,PRISMARINE:1)
Block(-8,25,-2,PRISMARINE:1)
Block(-8,25,-1,PRISMARINE:1)
Block(-8,25,0,PRISMARINE)
Block(-8,25,1,PRISMARINE:1)
Block(-8,25,2,PRISMARINE:1)
Block(-8,25,3,PRISMARINE:1)
Block(-8,26,-1,PRISMARINE:1)
Block(-8,26,0,PRISMARINE:1)
Block(-8,26,1,PRISMARINE:1)
Block(-8,27,0,PRISMARINE:1)
Block(-7,0,-15,PRISMARINE:1)
Block(-7,0,-14,PRISMARINE)
Block(-7,0,-13,PRISMARINE)
Block(-7,0,-12,PRISMARINE)
Block(-7,0,-11,PRISMARINE)
Block(-7,0,-10,PRISMARINE)
Block(-7,0,-9,PRISMARINE)
Block(-7,0,-8,PRISMARINE)
Block(-7,0,-7,PRISMARINE)
Block(-7,0,-6,PRISMARINE)
Block(-7,0,-5,PRISMARINE)
Block(-7,0,-4,PRISMARINE)
Block(-7,0,-3,PRISMARINE)
Block(-7,0,-2,PRISMARINE)
Block(-7,0,-1,PRISMARINE)
Block(-7,0,0,PRISMARINE)
Block(-7,0,1,PRISMARINE)
Block(-7,0,2,PRISMARINE)
Block(-7,0,3,PRISMARINE)
Block(-7,0,4,PRISMARINE)
Block(-7,0,5,PRISMARINE)
Block(-7,0,6,PRISMARINE)
Block(-7,0,7,PRISMARINE)
Block(-7,0,8,PRISMARINE)
Block(-7,0,9,PRISMARINE)
Block(-7,0,10,PRISMARINE)
Block(-7,0,11,PRISMARINE)
Block(-7,0,12,PRISMARINE)
Block(-7,0,13,PRISMARINE)
Block(-7,0,14,PRISMARINE)
Block(-7,0,15,PRISMARINE:1)
Block(-7,1,-15,PRISMARINE:1)
Block(-7,1,-14,PRISMARINE)
Block(-7,1,-13,PRISMARINE)
Block(-7,1,-12,PRISMARINE)
Block(-7,1,-11,PRISMARINE)
Block(-7,1,-10,PRISMARINE)
Block(-7,1,-9,PRISMARINE)
Block(-7,1,-8,PRISMARINE)
Block(-7,1,-7,PRISMARINE)
Block(-7,1,-6,PRISMARINE)
Block(-7,1,-5,PRISMARINE)
Block(-7,1,-4,PRISMARINE)
Block(-7,1,-3,PRISMARINE)
Block(-7,1,-2,PRISMARINE)
Block(-7,1,-1,PRISMARINE)
Block(-7,1,0,PRISMARINE)
Block(-7,1,1,PRISMARINE)
Block(-7,1,2,PRISMARINE)
Block(-7,1,3,PRISMARINE)
Block(-7,1,4,PRISMARINE)
Block(-7,1,5,PRISMARINE)
Block(-7,1,6,PRISMARINE)
Block(-7,1,7,PRISMARINE)
Block(-7,1,8,PRISMARINE)
Block(-7,1,9,PRISMARINE)
Block(-7,1,10,PRISMARINE)
Block(-7,1,11,PRISMARINE)
Block(-7,1,12,PRISMARINE)
Block(-7,1,13,PRISMARINE)
Block(-7,1,14,PRISMARINE)
Block(-7,1,15,PRISMARINE:1)
Block(-7,2,-15,PRISMARINE:1)
Block(-7,2,-14,PRISMARINE)
Block(-7,2,-13,PRISMARINE)
Block(-7,2,-12,PRISMARINE)
Block(-7,2,-11,PRISMARINE)
Block(-7,2,-10,PRISMARINE)
Block(-7,2,-9,PRISMARINE)
Block(-7,2,-8,PRISMARINE)
Block(-7,2,-7,PRISMARINE)
Block(-7,2,-6,PRISMARINE)
Block(-7,2,-5,PRISMARINE)
Block(-7,2,-4,PRISMARINE)
Block(-7,2,-3,PRISMARINE)
Block(-7,2,-2,PRISMARINE)
Block(-7,2,-1,PRISMARINE)
Block(-7,2,0,PRISMARINE)
Block(-7,2,1,PRISMARINE)
Block(-7,2,2,PRISMARINE)
Block(-7,2,3,PRISMARINE)
Block(-7,2,4,PRISMARINE)
Block(-7,2,5,PRISMARINE)
Block(-7,2,6,PRISMARINE)
Block(-7,2,7,PRISMARINE)
Block(-7,2,8,PRISMARINE)
Block(-7,2,9,PRISMARINE)
Block(-7,2,10,PRISMARINE)
Block(-7,2,11,PRISMARINE)
Block(-7,2,12,PRISMARINE)
Block(-7,2,13,PRISMARINE)
Block(-7,2,14,PRISMARINE)
Block(-7,2,15,PRISMARINE:1)
Block(-7,3,-15,PRISMARINE:1)
Block(-7,3,-14,PRISMARINE)
Block(-7,3,-13,PRISMARINE)
Block(-7,3,-12,PRISMARINE)
Block(-7,3,-11,PRISMARINE)
Block(-7,3,-10,PRISMARINE)
Block(-7,3,-9,PRISMARINE)
Block(-7,3,-8,PRISMARINE)
Block(-7,3,-7,PRISMARINE)
Block(-7,3,-6,PRISMARINE)
Block(-7,3,-5,PRISMARINE)
Block(-7,3,-4,PRISMARINE)
Block(-7,3,-3,PRISMARINE)
Block(-7,3,-2,PRISMARINE)
Block(-7,3,-1,PRISMARINE)
Block(-7,3,0,PRISMARINE)
Block(-7,3,1,PRISMARINE)
Block(-7,3,2,PRISMARINE)
Block(-7,3,3,PRISMARINE)
Block(-7,3,4,PRISMARINE)
Block(-7,3,5,PRISMARINE)
Block(-7,3,6,PRISMARINE)
Block(-7,3,7,PRISMARINE)
Block(-7,3,8,PRISMARINE)
Block(-7,3,9,PRISMARINE)
Block(-7,3,10,PRISMARINE)
Block(-7,3,11,PRISMARINE)
Block(-7,3,12,PRISMARINE)
Block(-7,3,13,PRISMARINE)
Block(-7,3,14,PRISMARINE)
Block(-7,3,15,PRISMARINE:1)
Block(-7,4,-14,PRISMARINE)
Block(-7,4,-13,PRISMARINE)
Block(-7,4,-12,PRISMARINE)
Block(-7,4,-11,PRISMARINE)
Block(-7,4,-10,PRISMARINE)
Block(-7,4,-9,PRISMARINE)
Block(-7,4,-8,PRISMARINE)
Block(-7,4,-7,PRISMARINE)
Block(-7,4,-6,PRISMARINE)
Block(-7,4,-5,PRISMARINE)
Block(-7,4,-4,PRISMARINE)
Block(-7,4,-3,PRISMARINE)
Block(-7,4,-2,PRISMARINE)
Block(-7,4,-1,PRISMARINE)
Block(-7,4,0,PRISMARINE)
Block(-7,4,1,PRISMARINE)
Block(-7,4,2,PRISMARINE)
Block(-7,4,3,PRISMARINE)
Block(-7,4,4,PRISMARINE)
Block(-7,4,5,PRISMARINE)
Block(-7,4,6,PRISMARINE)
Block(-7,4,7,PRISMARINE)
Block(-7,4,8,PRISMARINE)
Block(-7,4,9,PRISMARINE)
Block(-7,4,10,PRISMARINE)
Block(-7,4,11,PRISMARINE)
Block(-7,4,12,PRISMARINE)
Block(-7,4,13,PRISMARINE)
Block(-7,4,14,PRISMARINE)
Block(-7,5,-13,PRISMARINE)
Block(-7,5,-12,PRISMARINE)
Block(-7,5,-11,PRISMARINE)
Block(-7,5,-10,PRISMARINE)
Block(-7,5,-9,PRISMARINE)
Block(-7,5,-8,PRISMARINE)
Block(-7,5,-7,PRISMARINE)
Block(-7,5,-6,PRISMARINE)
Block(-7,5,-5,PRISMARINE)
Block(-7,5,-4,PRISMARINE)
Block(-7,5,-3,PRISMARINE)
Block(-7,5,-2,PRISMARINE)
Block(-7,5,-1,PRISMARINE)
Block(-7,5,0,PRISMARINE)
Block(-7,5,1,PRISMARINE)
Block(-7,5,2,PRISMARINE)
Block(-7,5,3,PRISMARINE)
Block(-7,5,4,PRISMARINE)
Block(-7,5,5,PRISMARINE)
Block(-7,5,6,PRISMARINE)
Block(-7,5,7,PRISMARINE)
Block(-7,5,8,PRISMARINE)
Block(-7,5,9,PRISMARINE)
Block(-7,5,10,PRISMARINE)
Block(-7,5,11,PRISMARINE)
Block(-7,5,12,PRISMARINE)
Block(-7,5,13,PRISMARINE)
Block(-7,6,-12,PRISMARINE:1)
Block(-7,6,-11,PRISMARINE)
Block(-7,6,-10,PRISMARINE)
Block(-7,6,-9,PRISMARINE)
Block(-7,6,-8,PRISMARINE)
Block(-7,6,-7,PRISMARINE)
Block(-7,6,-6,PRISMARINE)
Block(-7,6,-5,PRISMARINE)
Block(-7,6,-4,PRISMARINE)
Block(-7,6,-3,PRISMARINE)
Block(-7,6,-2,PRISMARINE)
Block(-7,6,-1,PRISMARINE)
Block(-7,6,0,PRISMARINE)
Block(-7,6,1,PRISMARINE)
Block(-7,6,2,PRISMARINE)
Block(-7,6,3,PRISMARINE)
Block(-7,6,4,PRISMARINE)
Block(-7,6,5,PRISMARINE)
Block(-7,6,6,PRISMARINE)
Block(-7,6,7,PRISMARINE)
Block(-7,6,8,PRISMARINE)
Block(-7,6,9,PRISMARINE)
Block(-7,6,10,PRISMARINE)
Block(-7,6,11,PRISMARINE)
Block(-7,6,12,PRISMARINE:1)
Block(-7,7,-8,STATIONARY_WATER)
Block(-7,7,-7,STATIONARY_WATER)
Block(-7,7,-6,STATIONARY_WATER)
Block(-7,7,-5,STATIONARY_WATER)
Block(-7,7,-4,STATIONARY_WATER)
Block(-7,7,-3,STATIONARY_WATER)
Block(-7,7,-2,STATIONARY_WATER)
Block(-7,7,-1,STATIONARY_WATER)
Block(-7,7,0,STATIONARY_WATER)
Block(-7,7,1,STATIONARY_WATER)
Block(-7,7,2,STATIONARY_WATER)
Block(-7,7,3,STATIONARY_WATER)
Block(-7,7,4,STATIONARY_WATER)
Block(-7,7,5,STATIONARY_WATER)
Block(-7,7,6,STATIONARY_WATER)
Block(-7,7,7,STATIONARY_WATER)
Block(-7,7,8,STATIONARY_WATER)
Block(-7,8,-8,STATIONARY_WATER)
Block(-7,8,-7,STATIONARY_WATER)
Block(-7,8,-6,STATIONARY_WATER)
Block(-7,8,-5,STATIONARY_WATER)
Block(-7,8,-4,STATIONARY_WATER)
Block(-7,8,-3,STATIONARY_WATER)
Block(-7,8,-2,STATIONARY_WATER)
Block(-7,8,-1,STATIONARY_WATER)
Block(-7,8,0,STATIONARY_WATER)
Block(-7,8,1,STATIONARY_WATER)
Block(-7,8,2,STATIONARY_WATER)
Block(-7,8,3,STATIONARY_WATER)
Block(-7,8,4,STATIONARY_WATER)
Block(-7,8,5,STATIONARY_WATER)
Block(-7,8,6,STATIONARY_WATER)
Block(-7,8,7,STATIONARY_WATER)
Block(-7,8,8,STATIONARY_WATER)
Block(-7,9,-8,STATIONARY_WATER)
Block(-7,9,-7,STATIONARY_WATER)
Block(-7,9,-6,STATIONARY_WATER)
Block(-7,9,-5,STATIONARY_WATER)
Block(-7,9,-4,STATIONARY_WATER)
Block(-7,9,-3,STATIONARY_WATER)
Block(-7,9,-2,STATIONARY_WATER)
Block(-7,9,-1,STATIONARY_WATER)
Block(-7,9,0,STATIONARY_WATER)
Block(-7,9,1,STATIONARY_WATER)
Block(-7,9,2,STATIONARY_WATER)
Block(-7,9,3,STATIONARY_WATER)
Block(-7,9,4,STATIONARY_WATER)
Block(-7,9,5,STATIONARY_WATER)
Block(-7,9,6,STATIONARY_WATER)
Block(-7,9,7,STATIONARY_WATER)
Block(-7,9,8,STATIONARY_WATER)
Block(-7,10,-8,STATIONARY_WATER)
Block(-7,10,-7,STATIONARY_WATER)
Block(-7,10,-6,STATIONARY_WATER)
Block(-7,10,-5,STATIONARY_WATER)
Block(-7,10,-4,STATIONARY_WATER)
Block(-7,10,-3,STATIONARY_WATER)
Block(-7,10,-2,STATIONARY_WATER)
Block(-7,10,-1,STATIONARY_WATER)
Block(-7,10,0,STATIONARY_WATER)
Block(-7,10,1,STATIONARY_WATER)
Block(-7,10,2,STATIONARY_WATER)
Block(-7,10,3,STATIONARY_WATER)
Block(-7,10,4,STATIONARY_WATER)
Block(-7,10,5,STATIONARY_WATER)
Block(-7,10,6,STATIONARY_WATER)
Block(-7,10,7,STATIONARY_WATER)
Block(-7,10,8,STATIONARY_WATER)
Block(-7,11,-8,STATIONARY_WATER)
Block(-7,11,-7,STATIONARY_WATER)
Block(-7,11,-6,STATIONARY_WATER)
Block(-7,11,-5,STATIONARY_WATER)
Block(-7,11,-4,STATIONARY_WATER)
Block(-7,11,-3,STATIONARY_WATER)
Block(-7,11,-2,STATIONARY_WATER)
Block(-7,11,-1,STATIONARY_WATER)
Block(-7,11,0,STATIONARY_WATER)
Block(-7,11,1,STATIONARY_WATER)
Block(-7,11,2,STATIONARY_WATER)
Block(-7,11,3,STATIONARY_WATER)
Block(-7,11,4,STATIONARY_WATER)
Block(-7,11,5,STATIONARY_WATER)
Block(-7,11,6,STATIONARY_WATER)
Block(-7,11,7,STATIONARY_WATER)
Block(-7,11,8,STATIONARY_WATER)
Block(-7,12,-8,STATIONARY_WATER)
Block(-7,12,-7,STATIONARY_WATER)
Block(-7,12,-6,STATIONARY_WATER)
Block(-7,12,-5,STATIONARY_WATER)
Block(-7,12,-4,STATIONARY_WATER)
Block(-7,12,-3,STATIONARY_WATER)
Block(-7,12,-2,STATIONARY_WATER)
Block(-7,12,-1,STATIONARY_WATER)
Block(-7,12,0,STATIONARY_WATER)
Block(-7,12,1,STATIONARY_WATER)
Block(-7,12,2,STATIONARY_WATER)
Block(-7,12,3,STATIONARY_WATER)
Block(-7,12,4,STATIONARY_WATER)
Block(-7,12,5,STATIONARY_WATER)
Block(-7,12,6,STATIONARY_WATER)
Block(-7,12,7,STATIONARY_WATER)
Block(-7,12,8,STATIONARY_WATER)
Block(-7,13,-8,STATIONARY_WATER)
Block(-7,13,-7,STATIONARY_WATER)
Block(-7,13,-6,STATIONARY_WATER)
Block(-7,13,-5,STATIONARY_WATER)
Block(-7,13,-4,STATIONARY_WATER)
Block(-7,13,-3,STATIONARY_WATER)
Block(-7,13,-2,STATIONARY_WATER)
Block(-7,13,-1,STATIONARY_WATER)
Block(-7,13,0,STATIONARY_WATER)
Block(-7,13,1,STATIONARY_WATER)
Block(-7,13,2,STATIONARY_WATER)
Block(-7,13,3,STATIONARY_WATER)
Block(-7,13,4,STATIONARY_WATER)
Block(-7,13,5,STATIONARY_WATER)
Block(-7,13,6,STATIONARY_WATER)
Block(-7,13,7,STATIONARY_WATER)
Block(-7,13,8,STATIONARY_WATER)
Block(-7,14,-8,STATIONARY_WATER)
Block(-7,14,-7,STATIONARY_WATER)
Block(-7,14,-6,STATIONARY_WATER)
Block(-7,14,-5,STATIONARY_WATER)
Block(-7,14,-4,STATIONARY_WATER)
Block(-7,14,-3,STATIONARY_WATER)
Block(-7,14,-2,STATIONARY_WATER)
Block(-7,14,-1,STATIONARY_WATER)
Block(-7,14,0,STATIONARY_WATER)
Block(-7,14,1,STATIONARY_WATER)
Block(-7,14,2,STATIONARY_WATER)
Block(-7,14,3,STATIONARY_WATER)
Block(-7,14,4,STATIONARY_WATER)
Block(-7,14,5,STATIONARY_WATER)
Block(-7,14,6,STATIONARY_WATER)
Block(-7,14,7,STATIONARY_WATER)
Block(-7,14,8,STATIONARY_WATER)
Block(-7,15,-8,STATIONARY_WATER)
Block(-7,15,-7,STATIONARY_WATER)
Block(-7,15,-6,STATIONARY_WATER)
Block(-7,15,-5,STATIONARY_WATER)
Block(-7,15,-4,STATIONARY_WATER)
Block(-7,15,-3,STATIONARY_WATER)
Block(-7,15,-2,STATIONARY_WATER)
Block(-7,15,-1,STATIONARY_WATER)
Block(-7,15,0,STATIONARY_WATER)
Block(-7,15,1,STATIONARY_WATER)
Block(-7,15,2,STATIONARY_WATER)
Block(-7,15,3,STATIONARY_WATER)
Block(-7,15,4,STATIONARY_WATER)
Block(-7,15,5,STATIONARY_WATER)
Block(-7,15,6,STATIONARY_WATER)
Block(-7,15,7,STATIONARY_WATER)
Block(-7,15,8,STATIONARY_WATER)
Block(-7,16,-8,STATIONARY_WATER)
Block(-7,16,-7,STATIONARY_WATER)
Block(-7,16,-6,STATIONARY_WATER)
Block(-7,16,-5,STATIONARY_WATER)
Block(-7,16,-4,STATIONARY_WATER)
Block(-7,16,-3,STATIONARY_WATER)
Block(-7,16,-2,STATIONARY_WATER)
Block(-7,16,-1,STATIONARY_WATER)
Block(-7,16,0,STATIONARY_WATER)
Block(-7,16,1,STATIONARY_WATER)
Block(-7,16,2,STATIONARY_WATER)
Block(-7,16,3,STATIONARY_WATER)
Block(-7,16,4,STATIONARY_WATER)
Block(-7,16,5,STATIONARY_WATER)
Block(-7,16,6,STATIONARY_WATER)
Block(-7,16,7,STATIONARY_WATER)
Block(-7,16,8,STATIONARY_WATER)
Block(-7,17,-10,PRISMARINE:2)
Block(-7,17,-9,PRISMARINE:1)
Block(-7,17,-8,PRISMARINE:1)
Block(-7,17,-7,PRISMARINE:1)
Block(-7,17,-6,PRISMARINE:1)
Block(-7,17,-5,PRISMARINE:1)
Block(-7,17,-4,PRISMARINE:1)
Block(-7,17,-3,PRISMARINE:1)
Block(-7,17,-2,PRISMARINE:1)
Block(-7,17,-1,PRISMARINE:1)
Block(-7,17,0,PRISMARINE:1)
Block(-7,17,1,PRISMARINE:1)
Block(-7,17,2,PRISMARINE:1)
Block(-7,17,3,PRISMARINE:1)
Block(-7,17,4,PRISMARINE:1)
Block(-7,17,5,PRISMARINE:1)
Block(-7,17,6,PRISMARINE:1)
Block(-7,17,7,PRISMARINE:1)
Block(-7,17,8,PRISMARINE:1)
Block(-7,17,9,PRISMARINE:1)
Block(-7,17,10,PRISMARINE:2)
Block(-7,18,-10,PRISMARINE:2)
Block(-7,18,-9,PRISMARINE)
Block(-7,18,-8,PRISMARINE:2)
Block(-7,18,-7,STATIONARY_WATER)
Block(-7,18,-6,PRISMARINE:2)
Block(-7,18,-5,STATIONARY_WATER)
Block(-7,18,-4,PRISMARINE:2)
Block(-7,18,-3,PRISMARINE:2)
Block(-7,18,-2,STATIONARY_WATER)
Block(-7,18,-1,PRISMARINE:2)
Block(-7,18,0,STATIONARY_WATER)
Block(-7,18,1,PRISMARINE:2)
Block(-7,18,2,STATIONARY_WATER)
Block(-7,18,3,PRISMARINE:2)
Block(-7,18,4,PRISMARINE:2)
Block(-7,18,5,STATIONARY_WATER)
Block(-7,18,6,PRISMARINE:2)
Block(-7,18,7,STATIONARY_WATER)
Block(-7,18,8,PRISMARINE:2)
Block(-7,18,9,PRISMARINE)
Block(-7,18,10,PRISMARINE:2)
Block(-7,19,-10,PRISMARINE:2)
Block(-7,19,-9,PRISMARINE:1)
Block(-7,19,-8,PRISMARINE:1)
Block(-7,19,-7,PRISMARINE:1)
Block(-7,19,-6,PRISMARINE:1)
Block(-7,19,-5,PRISMARINE:1)
Block(-7,19,-4,PRISMARINE:1)
Block(-7,19,-3,PRISMARINE:1)
Block(-7,19,-2,PRISMARINE:1)
Block(-7,19,-1,PRISMARINE:1)
Block(-7,19,0,PRISMARINE:1)
Block(-7,19,1,PRISMARINE:1)
Block(-7,19,2,PRISMARINE:1)
Block(-7,19,3,PRISMARINE:1)
Block(-7,19,4,PRISMARINE:1)
Block(-7,19,5,PRISMARINE:1)
Block(-7,19,6,PRISMARINE:1)
Block(-7,19,7,PRISMARINE:1)
Block(-7,19,8,PRISMARINE:1)
Block(-7,19,9,PRISMARINE:1)
Block(-7,19,10,PRISMARINE:2)
Block(-7,20,-12,PRISMARINE:1)
Block(-7,20,-11,PRISMARINE:1)
Block(-7,20,-10,PRISMARINE)
Block(-7,20,-9,PRISMARINE)
Block(-7,20,-8,STATIONARY_WATER)
Block(-7,20,-7,STATIONARY_WATER)
Block(-7,20,-6,PRISMARINE:1)
Block(-7,20,-5,PRISMARINE:1)
Block(-7,20,-4,PRISMARINE:1)
Block(-7,20,-3,STATIONARY_WATER)
Block(-7,20,-2,STATIONARY_WATER)
Block(-7,20,-1,PRISMARINE:1)
Block(-7,20,0,PRISMARINE:1)
Block(-7,20,1,PRISMARINE:1)
Block(-7,20,2,STATIONARY_WATER)
Block(-7,20,3,STATIONARY_WATER)
Block(-7,20,4,PRISMARINE:1)
Block(-7,20,5,PRISMARINE:1)
Block(-7,20,6,PRISMARINE:1)
Block(-7,20,7,STATIONARY_WATER)
Block(-7,20,8,STATIONARY_WATER)
Block(-7,20,9,PRISMARINE)
Block(-7,20,10,PRISMARINE)
Block(-7,20,11,PRISMARINE:1)
Block(-7,20,12,PRISMARINE:1)
Block(-7,21,-11,PRISMARINE:1)
Block(-7,21,-10,PRISMARINE:1)
Block(-7,21,-9,PRISMARINE:1)
Block(-7,21,-8,STATIONARY_WATER)
Block(-7,21,-7,STATIONARY_WATER)
Block(-7,21,-6,PRISMARINE:2)
Block(-7,21,-5,PRISMARINE:2)
Block(-7,21,-4,PRISMARINE:2)
Block(-7,21,-3,STATIONARY_WATER)
Block(-7,21,-2,STATIONARY_WATER)
Block(-7,21,-1,PRISMARINE:2)
Block(-7,21,0,PRISMARINE:2)
Block(-7,21,1,PRISMARINE:2)
Block(-7,21,2,STATIONARY_WATER)
Block(-7,21,3,STATIONARY_WATER)
Block(-7,21,4,PRISMARINE:2)
Block(-7,21,5,PRISMARINE:2)
Block(-7,21,6,PRISMARINE:2)
Block(-7,21,7,STATIONARY_WATER)
Block(-7,21,8,STATIONARY_WATER)
Block(-7,21,9,PRISMARINE:1)
Block(-7,21,10,PRISMARINE:1)
Block(-7,21,11,PRISMARINE:1)
Block(-7,22,-9,PRISMARINE:1)
Block(-7,22,-8,PRISMARINE:1)
Block(-7,22,-7,PRISMARINE:1)
Block(-7,22,-6,PRISMARINE:2)
Block(-7,22,-5,SEA_LANTERN)
Block(-7,22,-4,PRISMARINE:2)
Block(-7,22,-3,STATIONARY_WATER)
Block(-7,22,-2,STATIONARY_WATER)
Block(-7,22,-1,PRISMARINE:2)
Block(-7,22,0,SEA_LANTERN)
Block(-7,22,1,PRISMARINE:2)
Block(-7,22,2,STATIONARY_WATER)
Block(-7,22,3,STATIONARY_WATER)
Block(-7,22,4,PRISMARINE:2)
Block(-7,22,5,SEA_LANTERN)
Block(-7,22,6,PRISMARINE:2)
Block(-7,22,7,PRISMARINE:1)
Block(-7,22,8,PRISMARINE:1)
Block(-7,22,9,PRISMARINE:1)
Block(-7,23,-7,PRISMARINE:1)
Block(-7,23,-6,PRISMARINE:1)
Block(-7,23,-5,PRISMARINE:1)
Block(-7,23,-4,PRISMARINE:2)
Block(-7,23,-3,STATIONARY_WATER)
Block(-7,23,-2,STATIONARY_WATER)
Block(-7,23,-1,PRISMARINE:2)
Block(-7,23,0,PRISMARINE:2)
Block(-7,23,1,PRISMARINE:2)
Block(-7,23,2,STATIONARY_WATER)
Block(-7,23,3,STATIONARY_WATER)
Block(-7,23,4,PRISMARINE:2)
Block(-7,23,5,PRISMARINE:1)
Block(-7,23,6,PRISMARINE:1)
Block(-7,23,7,PRISMARINE:1)
Block(-7,24,-5,PRISMARINE:1)
Block(-7,24,-4,PRISMARINE:1)
Block(-7,24,-3,PRISMARINE:1)
Block(-7,24,-2,PRISMARINE:1)
Block(-7,24,-1,PRISMARINE:1)
Block(-7,24,0,PRISMARINE:1)
Block(-7,24,1,PRISMARINE:1)
Block(-7,24,2,PRISMARINE:1)
Block(-7,24,3,PRISMARINE:1)
Block(-7,24,4,PRISMARINE:1)
Block(-7,24,5,PRISMARINE:1)
Block(-7,25,-3,PRISMARINE:1)
Block(-7,25,-2,PRISMARINE:1)
Block(-7,25,-1,PRISMARINE:1)
Block(-7,25,0,PRISMARINE:1)
Block(-7,25,1,PRISMARINE:1)
Block(-7,25,2,PRISMARINE:1)
Block(-7,25,3,PRISMARINE:1)
Block(-7,26,-1,PRISMARINE:1)
Block(-7,26,0,PRISMARINE:1)
Block(-7,26,1,PRISMARINE:1)
Block(-7,27,0,PRISMARINE:1)
Block(-6,0,-15,PRISMARINE:1)
Block(-6,0,-14,PRISMARINE)
Block(-6,0,-13,PRISMARINE)
Block(-6,0,-12,PRISMARINE)
Block(-6,0,-11,PRISMARINE)
Block(-6,0,-10,PRISMARINE)
Block(-6,0,-9,PRISMARINE)
Block(-6,0,-8,PRISMARINE)
Block(-6,0,-7,PRISMARINE)
Block(-6,0,-6,PRISMARINE)
Block(-6,0,-5,PRISMARINE)
Block(-6,0,-4,PRISMARINE)
Block(-6,0,-3,PRISMARINE)
Block(-6,0,-2,PRISMARINE)
Block(-6,0,-1,PRISMARINE)
Block(-6,0,0,PRISMARINE)
Block(-6,0,1,PRISMARINE)
Block(-6,0,2,PRISMARINE)
Block(-6,0,3,PRISMARINE)
Block(-6,0,4,PRISMARINE)
Block(-6,0,5,PRISMARINE)
Block(-6,0,6,PRISMARINE)
Block(-6,0,7,PRISMARINE)
Block(-6,0,8,PRISMARINE)
Block(-6,0,9,PRISMARINE)
Block(-6,0,10,PRISMARINE)
Block(-6,0,11,PRISMARINE)
Block(-6,0,12,PRISMARINE)
Block(-6,0,13,PRISMARINE)
Block(-6,0,14,PRISMARINE)
Block(-6,0,15,PRISMARINE:1)
Block(-6,1,-15,PRISMARINE:1)
Block(-6,1,-14,PRISMARINE)
Block(-6,1,-13,PRISMARINE)
Block(-6,1,-12,PRISMARINE)
Block(-6,1,-11,PRISMARINE)
Block(-6,1,-10,PRISMARINE)
Block(-6,1,-9,PRISMARINE)
Block(-6,1,-8,PRISMARINE)
Block(-6,1,-7,PRISMARINE)
Block(-6,1,-6,PRISMARINE)
Block(-6,1,-5,PRISMARINE)
Block(-6,1,-4,PRISMARINE)
Block(-6,1,-3,PRISMARINE)
Block(-6,1,-2,PRISMARINE)
Block(-6,1,-1,PRISMARINE)
Block(-6,1,0,PRISMARINE)
Block(-6,1,1,PRISMARINE)
Block(-6,1,2,PRISMARINE)
Block(-6,1,3,PRISMARINE)
Block(-6,1,4,PRISMARINE)
Block(-6,1,5,PRISMARINE)
Block(-6,1,6,PRISMARINE)
Block(-6,1,7,PRISMARINE)
Block(-6,1,8,PRISMARINE)
Block(-6,1,9,PRISMARINE)
Block(-6,1,10,PRISMARINE)
Block(-6,1,11,PRISMARINE)
Block(-6,1,12,PRISMARINE)
Block(-6,1,13,PRISMARINE)
Block(-6,1,14,PRISMARINE)
Block(-6,1,15,PRISMARINE:1)
Block(-6,2,-15,PRISMARINE:1)
Block(-6,2,-14,PRISMARINE)
Block(-6,2,-13,PRISMARINE)
Block(-6,2,-12,PRISMARINE)
Block(-6,2,-11,PRISMARINE)
Block(-6,2,-10,PRISMARINE)
Block(-6,2,-9,PRISMARINE)
Block(-6,2,-8,PRISMARINE)
Block(-6,2,-7,PRISMARINE)
Block(-6,2,-6,PRISMARINE)
Block(-6,2,-5,PRISMARINE)
Block(-6,2,-4,PRISMARINE)
Block(-6,2,-3,PRISMARINE)
Block(-6,2,-2,PRISMARINE)
Block(-6,2,-1,PRISMARINE)
Block(-6,2,0,PRISMARINE)
Block(-6,2,1,PRISMARINE)
Block(-6,2,2,PRISMARINE)
Block(-6,2,3,PRISMARINE)
Block(-6,2,4,PRISMARINE)
Block(-6,2,5,PRISMARINE)
Block(-6,2,6,PRISMARINE)
Block(-6,2,7,PRISMARINE)
Block(-6,2,8,PRISMARINE)
Block(-6,2,9,PRISMARINE)
Block(-6,2,10,PRISMARINE)
Block(-6,2,11,PRISMARINE)
Block(-6,2,12,PRISMARINE)
Block(-6,2,13,PRISMARINE)
Block(-6,2,14,PRISMARINE)
Block(-6,2,15,PRISMARINE:1)
Block(-6,3,-15,PRISMARINE:1)
Block(-6,3,-14,PRISMARINE)
Block(-6,3,-13,PRISMARINE)
Block(-6,3,-12,PRISMARINE)
Block(-6,3,-11,PRISMARINE)
Block(-6,3,-10,PRISMARINE)
Block(-6,3,-9,PRISMARINE)
Block(-6,3,-8,PRISMARINE)
Block(-6,3,-7,PRISMARINE)
Block(-6,3,-6,PRISMARINE)
Block(-6,3,-5,PRISMARINE)
Block(-6,3,-4,PRISMARINE)
Block(-6,3,-3,PRISMARINE)
Block(-6,3,-2,PRISMARINE)
Block(-6,3,-1,PRISMARINE)
Block(-6,3,0,PRISMARINE)
Block(-6,3,1,PRISMARINE)
Block(-6,3,2,PRISMARINE)
Block(-6,3,3,PRISMARINE)
Block(-6,3,4,PRISMARINE)
Block(-6,3,5,PRISMARINE)
Block(-6,3,6,PRISMARINE)
Block(-6,3,7,PRISMARINE)
Block(-6,3,8,PRISMARINE)
Block(-6,3,9,PRISMARINE)
Block(-6,3,10,PRISMARINE)
Block(-6,3,11,PRISMARINE)
Block(-6,3,12,PRISMARINE)
Block(-6,3,13,PRISMARINE)
Block(-6,3,14,PRISMARINE)
Block(-6,3,15,PRISMARINE:1)
Block(-6,4,-14,PRISMARINE)
Block(-6,4,-13,PRISMARINE)
Block(-6,4,-12,PRISMARINE)
Block(-6,4,-11,PRISMARINE)
Block(-6,4,-10,PRISMARINE)
Block(-6,4,-9,PRISMARINE)
Block(-6,4,-8,PRISMARINE)
Block(-6,4,-7,PRISMARINE)
Block(-6,4,-6,PRISMARINE)
Block(-6,4,-5,PRISMARINE)
Block(-6,4,-4,PRISMARINE)
Block(-6,4,-3,PRISMARINE)
Block(-6,4,-2,PRISMARINE)
Block(-6,4,-1,PRISMARINE)
Block(-6,4,0,PRISMARINE)
Block(-6,4,1,PRISMARINE)
Block(-6,4,2,PRISMARINE)
Block(-6,4,3,PRISMARINE)
Block(-6,4,4,PRISMARINE)
Block(-6,4,5,PRISMARINE)
Block(-6,4,6,PRISMARINE)
Block(-6,4,7,PRISMARINE)
Block(-6,4,8,PRISMARINE)
Block(-6,4,9,PRISMARINE)
Block(-6,4,10,PRISMARINE)
Block(-6,4,11,PRISMARINE)
Block(-6,4,12,PRISMARINE)
Block(-6,4,13,PRISMARINE)
Block(-6,4,14,PRISMARINE)
Block(-6,5,-13,PRISMARINE)
Block(-6,5,-12,PRISMARINE)
Block(-6,5,-11,PRISMARINE)
Block(-6,5,-10,PRISMARINE)
Block(-6,5,-9,PRISMARINE)
Block(-6,5,-8,PRISMARINE)
Block(-6,5,-7,PRISMARINE)
Block(-6,5,-6,PRISMARINE)
Block(-6,5,-5,PRISMARINE)
Block(-6,5,-4,PRISMARINE)
Block(-6,5,-3,PRISMARINE)
Block(-6,5,-2,PRISMARINE)
Block(-6,5,-1,PRISMARINE)
Block(-6,5,0,PRISMARINE)
Block(-6,5,1,PRISMARINE)
Block(-6,5,2,PRISMARINE)
Block(-6,5,3,PRISMARINE)
Block(-6,5,4,PRISMARINE)
Block(-6,5,5,PRISMARINE)
Block(-6,5,6,PRISMARINE)
Block(-6,5,7,PRISMARINE)
Block(-6,5,8,PRISMARINE)
Block(-6,5,9,PRISMARINE)
Block(-6,5,10,PRISMARINE)
Block(-6,5,11,PRISMARINE)
Block(-6,5,12,PRISMARINE)
Block(-6,5,13,PRISMARINE)
Block(-6,6,-12,PRISMARINE:1)
Block(-6,6,-11,PRISMARINE)
Block(-6,6,-10,PRISMARINE)
Block(-6,6,-9,PRISMARINE)
Block(-6,6,-8,PRISMARINE)
Block(-6,6,-7,PRISMARINE)
Block(-6,6,-6,PRISMARINE)
Block(-6,6,-5,PRISMARINE)
Block(-6,6,-4,PRISMARINE)
Block(-6,6,-3,PRISMARINE)
Block(-6,6,-2,PRISMARINE)
Block(-6,6,-1,PRISMARINE)
Block(-6,6,0,PRISMARINE)
Block(-6,6,1,PRISMARINE)
Block(-6,6,2,PRISMARINE)
Block(-6,6,3,PRISMARINE)
Block(-6,6,4,PRISMARINE)
Block(-6,6,5,PRISMARINE)
Block(-6,6,6,PRISMARINE)
Block(-6,6,7,PRISMARINE)
Block(-6,6,8,PRISMARINE)
Block(-6,6,9,PRISMARINE)
Block(-6,6,10,PRISMARINE)
Block(-6,6,11,PRISMARINE)
Block(-6,6,12,PRISMARINE:1)
Block(-6,7,-9,PRISMARINE:1)
Block(-6,7,-8,STATIONARY_WATER)
Block(-6,7,-7,STATIONARY_WATER)
Block(-6,7,-6,STATIONARY_WATER)
Block(-6,7,-5,STATIONARY_WATER)
Block(-6,7,-4,STATIONARY_WATER)
Block(-6,7,-3,STATIONARY_WATER)
Block(-6,7,-2,STATIONARY_WATER)
Block(-6,7,-1,STATIONARY_WATER)
Block(-6,7,0,STATIONARY_WATER)
Block(-6,7,1,STATIONARY_WATER)
Block(-6,7,2,STATIONARY_WATER)
Block(-6,7,3,STATIONARY_WATER)
Block(-6,7,4,STATIONARY_WATER)
Block(-6,7,5,STATIONARY_WATER)
Block(-6,7,6,STATIONARY_WATER)
Block(-6,7,7,STATIONARY_WATER)
Block(-6,7,8,STATIONARY_WATER)
Block(-6,7,9,PRISMARINE:1)
Block(-6,8,-9,PRISMARINE)
Block(-6,8,-8,STATIONARY_WATER)
Block(-6,8,-7,STATIONARY_WATER)
Block(-6,8,-6,STATIONARY_WATER)
Block(-6,8,-5,STATIONARY_WATER)
Block(-6,8,-4,STATIONARY_WATER)
Block(-6,8,-3,STATIONARY_WATER)
Block(-6,8,-2,STATIONARY_WATER)
Block(-6,8,-1,STATIONARY_WATER)
Block(-6,8,0,STATIONARY_WATER)
Block(-6,8,1,STATIONARY_WATER)
Block(-6,8,2,STATIONARY_WATER)
Block(-6,8,3,STATIONARY_WATER)
Block(-6,8,4,STATIONARY_WATER)
Block(-6,8,5,STATIONARY_WATER)
Block(-6,8,6,STATIONARY_WATER)
Block(-6,8,7,STATIONARY_WATER)
Block(-6,8,8,STATIONARY_WATER)
Block(-6,8,9,PRISMARINE)
Block(-6,9,-9,PRISMARINE)
Block(-6,9,-8,STATIONARY_WATER)
Block(-6,9,-7,STATIONARY_WATER)
Block(-6,9,-6,STATIONARY_WATER)
Block(-6,9,-5,STATIONARY_WATER)
Block(-6,9,-4,STATIONARY_WATER)
Block(-6,9,-3,STATIONARY_WATER)
Block(-6,9,-2,STATIONARY_WATER)
Block(-6,9,-1,STATIONARY_WATER)
Block(-6,9,0,STATIONARY_WATER)
Block(-6,9,1,STATIONARY_WATER)
Block(-6,9,2,STATIONARY_WATER)
Block(-6,9,3,STATIONARY_WATER)
Block(-6,9,4,STATIONARY_WATER)
Block(-6,9,5,STATIONARY_WATER)
Block(-6,9,6,STATIONARY_WATER)
Block(-6,9,7,STATIONARY_WATER)
Block(-6,9,8,STATIONARY_WATER)
Block(-6,9,9,PRISMARINE)
Block(-6,10,-9,PRISMARINE)
Block(-6,10,-8,STATIONARY_WATER)
Block(-6,10,-7,STATIONARY_WATER)
Block(-6,10,-6,STATIONARY_WATER)
Block(-6,10,-5,STATIONARY_WATER)
Block(-6,10,-4,STATIONARY_WATER)
Block(-6,10,-3,STATIONARY_WATER)
Block(-6,10,-2,STATIONARY_WATER)
Block(-6,10,-1,STATIONARY_WATER)
Block(-6,10,0,STATIONARY_WATER)
Block(-6,10,1,STATIONARY_WATER)
Block(-6,10,2,STATIONARY_WATER)
Block(-6,10,3,STATIONARY_WATER)
Block(-6,10,4,STATIONARY_WATER)
Block(-6,10,5,STATIONARY_WATER)
Block(-6,10,6,STATIONARY_WATER)
Block(-6,10,7,STATIONARY_WATER)
Block(-6,10,8,STATIONARY_WATER)
Block(-6,10,9,PRISMARINE)
Block(-6,11,-9,PRISMARINE)
Block(-6,11,-8,STATIONARY_WATER)
Block(-6,11,-7,STATIONARY_WATER)
Block(-6,11,-6,STATIONARY_WATER)
Block(-6,11,-5,STATIONARY_WATER)
Block(-6,11,-4,STATIONARY_WATER)
Block(-6,11,-3,STATIONARY_WATER)
Block(-6,11,-2,STATIONARY_WATER)
Block(-6,11,-1,STATIONARY_WATER)
Block(-6,11,0,STATIONARY_WATER)
Block(-6,11,1,STATIONARY_WATER)
Block(-6,11,2,STATIONARY_WATER)
Block(-6,11,3,STATIONARY_WATER)
Block(-6,11,4,STATIONARY_WATER)
Block(-6,11,5,STATIONARY_WATER)
Block(-6,11,6,STATIONARY_WATER)
Block(-6,11,7,STATIONARY_WATER)
Block(-6,11,8,STATIONARY_WATER)
Block(-6,11,9,PRISMARINE)
Block(-6,12,-9,PRISMARINE)
Block(-6,12,-8,STATIONARY_WATER)
Block(-6,12,-7,STATIONARY_WATER)
Block(-6,12,-6,STATIONARY_WATER)
Block(-6,12,-5,STATIONARY_WATER)
Block(-6,12,-4,STATIONARY_WATER)
Block(-6,12,-3,STATIONARY_WATER)
Block(-6,12,-2,STATIONARY_WATER)
Block(-6,12,-1,STATIONARY_WATER)
Block(-6,12,0,STATIONARY_WATER)
Block(-6,12,1,STATIONARY_WATER)
Block(-6,12,2,STATIONARY_WATER)
Block(-6,12,3,STATIONARY_WATER)
Block(-6,12,4,STATIONARY_WATER)
Block(-6,12,5,STATIONARY_WATER)
Block(-6,12,6,STATIONARY_WATER)
Block(-6,12,7,STATIONARY_WATER)
Block(-6,12,8,STATIONARY_WATER)
Block(-6,12,9,PRISMARINE)
Block(-6,13,-9,PRISMARINE)
Block(-6,13,-8,STATIONARY_WATER)
Block(-6,13,-7,STATIONARY_WATER)
Block(-6,13,-6,STATIONARY_WATER)
Block(-6,13,-5,STATIONARY_WATER)
Block(-6,13,-4,STATIONARY_WATER)
Block(-6,13,-3,STATIONARY_WATER)
Block(-6,13,-2,STATIONARY_WATER)
Block(-6,13,-1,STATIONARY_WATER)
Block(-6,13,0,STATIONARY_WATER)
Block(-6,13,1,STATIONARY_WATER)
Block(-6,13,2,STATIONARY_WATER)
Block(-6,13,3,STATIONARY_WATER)
Block(-6,13,4,STATIONARY_WATER)
Block(-6,13,5,STATIONARY_WATER)
Block(-6,13,6,STATIONARY_WATER)
Block(-6,13,7,STATIONARY_WATER)
Block(-6,13,8,STATIONARY_WATER)
Block(-6,13,9,PRISMARINE)
Block(-6,14,-9,PRISMARINE)
Block(-6,14,-8,STATIONARY_WATER)
Block(-6,14,-7,STATIONARY_WATER)
Block(-6,14,-6,STATIONARY_WATER)
Block(-6,14,-5,STATIONARY_WATER)
Block(-6,14,-4,STATIONARY_WATER)
Block(-6,14,-3,STATIONARY_WATER)
Block(-6,14,-2,STATIONARY_WATER)
Block(-6,14,-1,STATIONARY_WATER)
Block(-6,14,0,STATIONARY_WATER)
Block(-6,14,1,STATIONARY_WATER)
Block(-6,14,2,STATIONARY_WATER)
Block(-6,14,3,STATIONARY_WATER)
Block(-6,14,4,STATIONARY_WATER)
Block(-6,14,5,STATIONARY_WATER)
Block(-6,14,6,STATIONARY_WATER)
Block(-6,14,7,STATIONARY_WATER)
Block(-6,14,8,STATIONARY_WATER)
Block(-6,14,9,PRISMARINE)
Block(-6,15,-9,PRISMARINE)
Block(-6,15,-8,STATIONARY_WATER)
Block(-6,15,-7,STATIONARY_WATER)
Block(-6,15,-6,STATIONARY_WATER)
Block(-6,15,-5,STATIONARY_WATER)
Block(-6,15,-4,STATIONARY_WATER)
Block(-6,15,-3,STATIONARY_WATER)
Block(-6,15,-2,STATIONARY_WATER)
Block(-6,15,-1,STATIONARY_WATER)
Block(-6,15,0,STATIONARY_WATER)
Block(-6,15,1,STATIONARY_WATER)
Block(-6,15,2,STATIONARY_WATER)
Block(-6,15,3,STATIONARY_WATER)
Block(-6,15,4,STATIONARY_WATER)
Block(-6,15,5,STATIONARY_WATER)
Block(-6,15,6,STATIONARY_WATER)
Block(-6,15,7,STATIONARY_WATER)
Block(-6,15,8,STATIONARY_WATER)
Block(-6,15,9,PRISMARINE)
Block(-6,16,-9,PRISMARINE:1)
Block(-6,16,-8,STATIONARY_WATER)
Block(-6,16,-7,STATIONARY_WATER)
Block(-6,16,-6,STATIONARY_WATER)
Block(-6,16,-5,STATIONARY_WATER)
Block(-6,16,-4,STATIONARY_WATER)
Block(-6,16,-3,STATIONARY_WATER)
Block(-6,16,-2,STATIONARY_WATER)
Block(-6,16,-1,STATIONARY_WATER)
Block(-6,16,0,STATIONARY_WATER)
Block(-6,16,1,STATIONARY_WATER)
Block(-6,16,2,STATIONARY_WATER)
Block(-6,16,3,STATIONARY_WATER)
Block(-6,16,4,STATIONARY_WATER)
Block(-6,16,5,STATIONARY_WATER)
Block(-6,16,6,STATIONARY_WATER)
Block(-6,16,7,STATIONARY_WATER)
Block(-6,16,8,STATIONARY_WATER)
Block(-6,16,9,PRISMARINE:1)
Block(-6,17,-10,PRISMARINE:2)
Block(-6,17,-9,PRISMARINE:1)
Block(-6,17,-8,PRISMARINE:1)
Block(-6,17,-7,STATIONARY_WATER)
Block(-6,17,-6,STATIONARY_WATER)
Block(-6,17,-5,STATIONARY_WATER)
Block(-6,17,-4,STATIONARY_WATER)
Block(-6,17,-3,STATIONARY_WATER)
Block(-6,17,-2,STATIONARY_WATER)
Block(-6,17,-1,STATIONARY_WATER)
Block(-6,17,0,STATIONARY_WATER)
Block(-6,17,1,STATIONARY_WATER)
Block(-6,17,2,STATIONARY_WATER)
Block(-6,17,3,STATIONARY_WATER)
Block(-6,17,4,STATIONARY_WATER)
Block(-6,17,5,STATIONARY_WATER)
Block(-6,17,6,STATIONARY_WATER)
Block(-6,17,7,STATIONARY_WATER)
Block(-6,17,8,PRISMARINE:1)
Block(-6,17,9,PRISMARINE:1)
Block(-6,17,10,PRISMARINE:2)
Block(-6,18,-9,PRISMARINE)
Block(-6,18,-8,STATIONARY_WATER)
Block(-6,18,-7,STATIONARY_WATER)
Block(-6,18,-6,STATIONARY_WATER)
Block(-6,18,-5,STATIONARY_WATER)
Block(-6,18,-4,STATIONARY_WATER)
Block(-6,18,-3,STATIONARY_WATER)
Block(-6,18,-2,STATIONARY_WATER)
Block(-6,18,-1,STATIONARY_WATER)
Block(-6,18,0,STATIONARY_WATER)
Block(-6,18,1,STATIONARY_WATER)
Block(-6,18,2,STATIONARY_WATER)
Block(-6,18,3,STATIONARY_WATER)
Block(-6,18,4,STATIONARY_WATER)
Block(-6,18,5,STATIONARY_WATER)
Block(-6,18,6,STATIONARY_WATER)
Block(-6,18,7,STATIONARY_WATER)
Block(-6,18,8,STATIONARY_WATER)
Block(-6,18,9,PRISMARINE)
Block(-6,19,-10,PRISMARINE:2)
Block(-6,19,-9,PRISMARINE:1)
Block(-6,19,-8,PRISMARINE:1)
Block(-6,19,-7,STATIONARY_WATER)
Block(-6,19,-6,STATIONARY_WATER)
Block(-6,19,-5,STATIONARY_WATER)
Block(-6,19,-4,STATIONARY_WATER)
Block(-6,19,-3,STATIONARY_WATER)
Block(-6,19,-2,STATIONARY_WATER)
Block(-6,19,-1,STATIONARY_WATER)
Block(-6,19,0,STATIONARY_WATER)
Block(-6,19,1,STATIONARY_WATER)
Block(-6,19,2,STATIONARY_WATER)
Block(-6,19,3,STATIONARY_WATER)
Block(-6,19,4,STATIONARY_WATER)
Block(-6,19,5,STATIONARY_WATER)
Block(-6,19,6,STATIONARY_WATER)
Block(-6,19,7,STATIONARY_WATER)
Block(-6,19,8,PRISMARINE:1)
Block(-6,19,9,PRISMARINE:1)
Block(-6,19,10,PRISMARINE:2)
Block(-6,20,-12,PRISMARINE:1)
Block(-6,20,-11,PRISMARINE:1)
Block(-6,20,-10,PRISMARINE)
Block(-6,20,-9,PRISMARINE)
Block(-6,20,-8,STATIONARY_WATER)
Block(-6,20,-7,STATIONARY_WATER)
Block(-6,20,-6,STATIONARY_WATER)
Block(-6,20,-5,STATIONARY_WATER)
Block(-6,20,-4,STATIONARY_WATER)
Block(-6,20,-3,STATIONARY_WATER)
Block(-6,20,-2,STATIONARY_WATER)
Block(-6,20,-1,STATIONARY_WATER)
Block(-6,20,0,STATIONARY_WATER)
Block(-6,20,1,STATIONARY_WATER)
Block(-6,20,2,STATIONARY_WATER)
Block(-6,20,3,STATIONARY_WATER)
Block(-6,20,4,STATIONARY_WATER)
Block(-6,20,5,STATIONARY_WATER)
Block(-6,20,6,STATIONARY_WATER)
Block(-6,20,7,STATIONARY_WATER)
Block(-6,20,8,STATIONARY_WATER)
Block(-6,20,9,PRISMARINE)
Block(-6,20,10,PRISMARINE)
Block(-6,20,11,PRISMARINE:1)
Block(-6,20,12,PRISMARINE:1)
Block(-6,21,-11,PRISMARINE:1)
Block(-6,21,-10,PRISMARINE:1)
Block(-6,21,-9,PRISMARINE:1)
Block(-6,21,-8,STATIONARY_WATER)
Block(-6,21,-7,STATIONARY_WATER)
Block(-6,21,-6,STATIONARY_WATER)
Block(-6,21,-5,STATIONARY_WATER)
Block(-6,21,-4,STATIONARY_WATER)
Block(-6,21,-3,STATIONARY_WATER)
Block(-6,21,-2,STATIONARY_WATER)
Block(-6,21,-1,STATIONARY_WATER)
Block(-6,21,0,STATIONARY_WATER)
Block(-6,21,1,STATIONARY_WATER)
Block(-6,21,2,STATIONARY_WATER)
Block(-6,21,3,STATIONARY_WATER)
Block(-6,21,4,STATIONARY_WATER)
Block(-6,21,5,STATIONARY_WATER)
Block(-6,21,6,STATIONARY_WATER)
Block(-6,21,7,STATIONARY_WATER)
Block(-6,21,8,STATIONARY_WATER)
Block(-6,21,9,PRISMARINE:1)
Block(-6,21,10,PRISMARINE:1)
Block(-6,21,11,PRISMARINE:1)
Block(-6,22,-9,PRISMARINE:1)
Block(-6,22,-8,PRISMARINE:1)
Block(-6,22,-7,PRISMARINE:1)
Block(-6,22,-6,STATIONARY_WATER)
Block(-6,22,-5,STATIONARY_WATER)
Block(-6,22,-4,STATIONARY_WATER)
Block(-6,22,-3,STATIONARY_WATER)
Block(-6,22,-2,STATIONARY_WATER)
Block(-6,22,-1,STATIONARY_WATER)
Block(-6,22,0,STATIONARY_WATER)
Block(-6,22,1,STATIONARY_WATER)
Block(-6,22,2,STATIONARY_WATER)
Block(-6,22,3,STATIONARY_WATER)
Block(-6,22,4,STATIONARY_WATER)
Block(-6,22,5,STATIONARY_WATER)
Block(-6,22,6,STATIONARY_WATER)
Block(-6,22,7,PRISMARINE:1)
Block(-6,22,8,PRISMARINE:1)
Block(-6,22,9,PRISMARINE:1)
Block(-6,23,-7,PRISMARINE:1)
Block(-6,23,-6,PRISMARINE:1)
Block(-6,23,-5,PRISMARINE:1)
Block(-6,23,-4,STATIONARY_WATER)
Block(-6,23,-3,STATIONARY_WATER)
Block(-6,23,-2,STATIONARY_WATER)
Block(-6,23,-1,STATIONARY_WATER)
Block(-6,23,0,STATIONARY_WATER)
Block(-6,23,1,STATIONARY_WATER)
Block(-6,23,2,STATIONARY_WATER)
Block(-6,23,3,STATIONARY_WATER)
Block(-6,23,4,STATIONARY_WATER)
Block(-6,23,5,PRISMARINE:1)
Block(-6,23,6,PRISMARINE:1)
Block(-6,23,7,PRISMARINE:1)
Block(-6,24,-5,PRISMARINE:1)
Block(-6,24,-4,PRISMARINE:1)
Block(-6,24,-3,PRISMARINE:1)
Block(-6,24,-2,STATIONARY_WATER)
Block(-6,24,-1,STATIONARY_WATER)
Block(-6,24,0,STATIONARY_WATER)
Block(-6,24,1,STATIONARY_WATER)
Block(-6,24,2,STATIONARY_WATER)
Block(-6,24,3,PRISMARINE:1)
Block(-6,24,4,PRISMARINE:1)
Block(-6,24,5,PRISMARINE:1)
Block(-6,25,-3,PRISMARINE:1)
Block(-6,25,-2,PRISMARINE:1)
Block(-6,25,-1,PRISMARINE:1)
Block(-6,25,0,STATIONARY_WATER)
Block(-6,25,1,PRISMARINE:1)
Block(-6,25,2,PRISMARINE:1)
Block(-6,25,3,PRISMARINE:1)
Block(-6,26,-1,PRISMARINE:1)
Block(-6,26,0,PRISMARINE:1)
Block(-6,26,1,PRISMARINE:1)
Block(-6,27,0,PRISMARINE:1)
Block(-5,0,-15,PRISMARINE:1)
Block(-5,0,-14,PRISMARINE)
Block(-5,0,-13,PRISMARINE)
Block(-5,0,-12,PRISMARINE)
Block(-5,0,-11,PRISMARINE)
Block(-5,0,-10,PRISMARINE)
Block(-5,0,-9,PRISMARINE)
Block(-5,0,-8,PRISMARINE)
Block(-5,0,-7,PRISMARINE)
Block(-5,0,-6,PRISMARINE)
Block(-5,0,-5,PRISMARINE)
Block(-5,0,-4,PRISMARINE)
Block(-5,0,-3,PRISMARINE)
Block(-5,0,-2,PRISMARINE)
Block(-5,0,-1,PRISMARINE)
Block(-5,0,0,PRISMARINE)
Block(-5,0,1,PRISMARINE)
Block(-5,0,2,PRISMARINE)
Block(-5,0,3,PRISMARINE)
Block(-5,0,4,PRISMARINE)
Block(-5,0,5,PRISMARINE)
Block(-5,0,6,PRISMARINE)
Block(-5,0,7,PRISMARINE)
Block(-5,0,8,PRISMARINE)
Block(-5,0,9,PRISMARINE)
Block(-5,0,10,PRISMARINE)
Block(-5,0,11,PRISMARINE)
Block(-5,0,12,PRISMARINE)
Block(-5,0,13,PRISMARINE)
Block(-5,0,14,PRISMARINE)
Block(-5,0,15,PRISMARINE:1)
Block(-5,1,-15,PRISMARINE:1)
Block(-5,1,-14,PRISMARINE)
Block(-5,1,-13,PRISMARINE)
Block(-5,1,-12,PRISMARINE)
Block(-5,1,-11,PRISMARINE)
Block(-5,1,-10,PRISMARINE)
Block(-5,1,-9,PRISMARINE)
Block(-5,1,-8,PRISMARINE)
Block(-5,1,-7,PRISMARINE)
Block(-5,1,-6,PRISMARINE)
Block(-5,1,-5,PRISMARINE)
Block(-5,1,-4,PRISMARINE)
Block(-5,1,-3,PRISMARINE)
Block(-5,1,-2,PRISMARINE)
Block(-5,1,-1,PRISMARINE)
Block(-5,1,0,PRISMARINE)
Block(-5,1,1,PRISMARINE)
Block(-5,1,2,PRISMARINE)
Block(-5,1,3,PRISMARINE)
Block(-5,1,4,PRISMARINE)
Block(-5,1,5,PRISMARINE)
Block(-5,1,6,PRISMARINE)
Block(-5,1,7,PRISMARINE)
Block(-5,1,8,PRISMARINE)
Block(-5,1,9,PRISMARINE)
Block(-5,1,10,PRISMARINE)
Block(-5,1,11,PRISMARINE)
Block(-5,1,12,PRISMARINE)
Block(-5,1,13,PRISMARINE)
Block(-5,1,14,PRISMARINE)
Block(-5,1,15,PRISMARINE:1)
Block(-5,2,-15,PRISMARINE:1)
Block(-5,2,-14,PRISMARINE)
Block(-5,2,-13,PRISMARINE)
Block(-5,2,-12,PRISMARINE)
Block(-5,2,-11,PRISMARINE)
Block(-5,2,-10,PRISMARINE)
Block(-5,2,-9,PRISMARINE)
Block(-5,2,-8,PRISMARINE)
Block(-5,2,-7,PRISMARINE)
