
#######################################################################
# +-----------------------------------------------------------------+ #
# |                            BO3 object                           | #
# +-----------------------------------------------------------------+ #
#######################################################################

# This is the config file of a custom object.
# If you add this object correctly to your BiomeConfigs, it will spawn in the world.

# This is the creator of this BO3 object
Author: LordSmellyPants

# A short description of this BO3 object
Description: No description given

# The BO3 version, don't change this! It can be used by external applications to do a version check.
Version: 3

# The settings mode, WriteAll, WriteWithoutComments or WriteDisable. See WorldConfig.
SettingsMode: WriteDisable


#######################################################################
# +-----------------------------------------------------------------+ #
# |                          Main settings                          | #
# +-----------------------------------------------------------------+ #
#######################################################################

# This needs to be set to true to spawn the object in the Tree and Sapling resources.
Tree: false

# The frequency of the BO3 from 1 to 200. Tries this many times to spawn this BO3 when using the CustomObject(...) resource.
# Ignored by Tree(..), Sapling(..) and CustomStructure(..)
Frequency: 1

# The rarity of the BO3 from 0 to 100. Each spawn attempt has rarity% chance to succeed when using the CustomObject(...) resource.
# Ignored by Tree(..), Sapling(..) and CustomStructure(..)
Rarity: 100.0

# If you set this to true, the BO3 will be placed with a random rotation.
RotateRandomly: false

# The spawn height of the BO3 - atMinY, randomY, highestBlock or highestSolidBlock.
SpawnHeight: highestBlock

# The offset from the spawn height to spawn this BO3
# Ex. SpawnHeight = highestSolidBlock, SpawnHeightOffset = 3; This object will spawn 3 blocks above the highest solid block
SpawnHeightOffset: 0

# A random amount to offset the spawn location from the spawn offset height
# Ex. SpawnHeightOffset = 3, SpawnHeightVariance = 3; This object will spawn 3 to 6 blocks above the original spot it would have spawned
SpawnHeightVariance: 0

##############################
# Height Limits for the BO3. #
##############################

# When in randomY mode used as the minimum Y or in atMinY mode as the actual Y to spawn this BO3 at.
MinHeight: 0

# When in randomY mode used as the maximum Y to spawn this BO3 at.
MaxHeight: 256

######################
# Extrusion settings #
######################

# The style of extrusion you wish to use - BottomDown, TopUp, None (Default)
ExtrudeMode: None

# The blocks to extrude your BO3 through
ExtrudeThroughBlocks: AIR

# Objects can have other objects attacthed to it: branches. Branches can also
# have branches attached to it, which can also have branches, etc. This is the
# maximum branch depth for this objects.
MaxBranchDepth: 10

# When spawned with the UseWorld keyword, this BO3 should NOT spawn in the following biomes.
# If you write the BO3 name directly in the BiomeConfigs, this will be ignored.
ExcludedBiomes: All


#######################################################################
# +-----------------------------------------------------------------+ #
# |                      Source block settings                      | #
# +-----------------------------------------------------------------+ #
#######################################################################

# The block(s) the BO3 should spawn in.
SourceBlocks: AIR

# The maximum percentage of the BO3 that can be outside the SourceBlock.
# The BO3 won't be placed on a location with more blocks outside the SourceBlock than this percentage.
MaxPercentageOutsideSourceBlock: 100

# What to do when a block is about to be placed outside the SourceBlock? (dontPlace, placeAnyway)
OutsideSourceBlock: placeAnyway


#######################################################################
# +-----------------------------------------------------------------+ #
# |                              Blocks                             | #
# +-----------------------------------------------------------------+ #
#######################################################################

# All the blocks used in the BO3 are listed here. Possible blocks:
# Block(x,y,z,id[.data][,nbtfile.nbt)
# RandomBlock(x,y,z,id[:data][,nbtfile.nbt],chance[,id[:data][,nbtfile.nbt],chance[,...]])
#  So RandomBlock(0,0,0,CHEST,chest.nbt,50,CHEST,anotherchest.nbt,100) will spawn a chest at
#  the BO3 origin, and give it a 50% chance to have the contents of chest.nbt, or, if that
#  fails, a 100% percent chance to have the contents of anotherchest.nbt.
# MinecraftObject(x,y,z,name)
#  Spawns an object in the Mojang NBT structure format. For example, 
#  MinecraftObject(0,0,0,minecraft:igloo/igloo_bottom)
#  spawns the bottom part of an igloo.
Block(-8,-3,-8,PRISMARINE)
Block(-8,-3,-6,PRISMARINE)
Block(-8,-3,-4,PRISMARINE)
Block(-8,-3,-3,PRISMARINE)
Block(-8,-3,-1,PRISMARINE)
Block(-8,-3,1,PRISMARINE)
Block(-8,-3,3,PRISMARINE)
Block(-8,-3,4,PRISMARINE)
Block(-8,-3,6,PRISMARINE)
Block(-8,-3,8,PRISMARINE)
Block(-8,-2,-8,PRISMARINE)
Block(-8,-2,-6,PRISMARINE)
Block(-8,-2,-4,PRISMARINE)
Block(-8,-2,-3,PRISMARINE)
Block(-8,-2,-1,PRISMARINE)
Block(-8,-2,1,PRISMARINE)
Block(-8,-2,3,PRISMARINE)
Block(-8,-2,4,PRISMARINE)
Block(-8,-2,6,PRISMARINE)
Block(-8,-2,8,PRISMARINE)
Block(-8,-1,-8,PRISMARINE)
Block(-8,-1,-6,PRISMARINE)
Block(-8,-1,-4,PRISMARINE)
Block(-8,-1,-3,PRISMARINE)
Block(-8,-1,-1,PRISMARINE)
Block(-8,-1,1,PRISMARINE)
Block(-8,-1,3,PRISMARINE)
Block(-8,-1,4,PRISMARINE)
Block(-8,-1,6,PRISMARINE)
Block(-8,-1,8,PRISMARINE)
Block(-8,0,-8,PRISMARINE)
Block(-8,0,-6,PRISMARINE)
Block(-8,0,-4,PRISMARINE)
Block(-8,0,-3,PRISMARINE)
Block(-8,0,-1,PRISMARINE)
Block(-8,0,1,PRISMARINE)
Block(-8,0,3,PRISMARINE)
Block(-8,0,4,PRISMARINE)
Block(-8,0,6,PRISMARINE)
Block(-8,0,8,PRISMARINE)
Block(-8,1,-8,PRISMARINE)
Block(-8,1,-6,PRISMARINE)
Block(-8,1,-4,PRISMARINE)
Block(-8,1,-3,PRISMARINE)
Block(-8,1,-1,PRISMARINE)
Block(-8,1,1,PRISMARINE)
Block(-8,1,3,PRISMARINE)
Block(-8,1,4,PRISMARINE)
Block(-8,1,6,PRISMARINE)
Block(-8,1,8,PRISMARINE)
Block(-8,2,-8,PRISMARINE)
Block(-8,2,-6,PRISMARINE)
Block(-8,2,-4,PRISMARINE)
Block(-8,2,-3,PRISMARINE)
Block(-8,2,-1,PRISMARINE)
Block(-8,2,1,PRISMARINE)
Block(-8,2,3,PRISMARINE)
Block(-8,2,4,PRISMARINE)
Block(-8,2,6,PRISMARINE)
Block(-8,2,8,PRISMARINE)
Block(-8,3,-8,PRISMARINE)
Block(-8,3,-6,PRISMARINE)
Block(-8,3,-4,PRISMARINE)
Block(-8,3,-3,PRISMARINE)
Block(-8,3,-1,PRISMARINE)
Block(-8,3,1,PRISMARINE)
Block(-8,3,3,PRISMARINE)
Block(-8,3,4,PRISMARINE)
Block(-8,3,6,PRISMARINE)
Block(-8,3,8,PRISMARINE)
Block(-8,4,-8,PRISMARINE)
Block(-8,4,-6,PRISMARINE)
Block(-8,4,-4,PRISMARINE)
Block(-8,4,-3,PRISMARINE)
Block(-8,4,-1,PRISMARINE)
Block(-8,4,1,PRISMARINE)
Block(-8,4,3,PRISMARINE)
Block(-8,4,4,PRISMARINE)
Block(-8,4,6,PRISMARINE)
Block(-8,4,8,PRISMARINE)
Block(-8,5,-8,PRISMARINE)
Block(-8,5,-6,PRISMARINE)
Block(-8,5,-4,PRISMARINE)
Block(-8,5,-3,PRISMARINE)
Block(-8,5,-1,PRISMARINE)
Block(-8,5,1,PRISMARINE)
Block(-8,5,3,PRISMARINE)
Block(-8,5,4,PRISMARINE)
Block(-8,5,6,PRISMARINE)
Block(-8,5,8,PRISMARINE)
Block(-8,6,-8,PRISMARINE)
Block(-8,6,-6,PRISMARINE)
Block(-8,6,-4,PRISMARINE)
Block(-8,6,-3,PRISMARINE)
Block(-8,6,-1,PRISMARINE)
Block(-8,6,1,PRISMARINE)
Block(-8,6,3,PRISMARINE)
Block(-8,6,4,PRISMARINE)
Block(-8,6,6,PRISMARINE)
Block(-8,6,8,PRISMARINE)
Block(-8,7,-8,PRISMARINE)
Block(-8,7,-6,PRISMARINE)
Block(-8,7,-4,PRISMARINE)
Block(-8,7,-3,PRISMARINE)
Block(-8,7,-1,PRISMARINE)
Block(-8,7,1,PRISMARINE)
Block(-8,7,3,PRISMARINE)
Block(-8,7,4,PRISMARINE)
Block(-8,7,6,PRISMARINE)
Block(-8,7,8,PRISMARINE)
Block(-8,8,-8,PRISMARINE)
Block(-8,8,-6,PRISMARINE)
Block(-8,8,-4,PRISMARINE)
Block(-8,8,-3,PRISMARINE)
Block(-8,8,-1,PRISMARINE)
Block(-8,8,1,PRISMARINE)
Block(-8,8,3,PRISMARINE)
Block(-8,8,4,PRISMARINE)
Block(-8,8,6,PRISMARINE)
Block(-8,8,8,PRISMARINE)
Block(-8,9,-8,PRISMARINE:1)
Block(-8,9,-7,PRISMARINE:1)
Block(-8,9,-6,PRISMARINE:1)
Block(-8,9,-5,PRISMARINE:1)
Block(-8,9,-4,PRISMARINE:1)
Block(-8,9,-3,PRISMARINE:1)
Block(-8,9,-2,PRISMARINE:1)
Block(-8,9,-1,PRISMARINE:1)
Block(-8,9,0,PRISMARINE:1)
Block(-8,9,1,PRISMARINE:1)
Block(-8,9,2,PRISMARINE:1)
Block(-8,9,3,PRISMARINE:1)
Block(-8,9,4,PRISMARINE:1)
Block(-8,9,5,PRISMARINE:1)
Block(-8,9,6,PRISMARINE:1)
Block(-8,9,7,PRISMARINE:1)
Block(-8,9,8,PRISMARINE:1)
Block(-7,-3,-7,PRISMARINE)
Block(-7,-3,-6,PRISMARINE)
Block(-7,-3,-5,PRISMARINE)
Block(-7,-3,-4,PRISMARINE)
Block(-7,-3,-3,PRISMARINE:1)
Block(-7,-3,-2,PRISMARINE)
Block(-7,-3,-1,PRISMARINE:1)
Block(-7,-3,0,PRISMARINE)
Block(-7,-3,1,PRISMARINE:1)
Block(-7,-3,2,PRISMARINE)
Block(-7,-3,3,PRISMARINE:1)
Block(-7,-3,4,PRISMARINE)
Block(-7,-3,5,PRISMARINE)
Block(-7,-3,6,PRISMARINE)
Block(-7,-3,7,PRISMARINE)
Block(-7,-2,-7,PRISMARINE)
Block(-7,-2,-6,PRISMARINE)
Block(-7,-2,-5,PRISMARINE)
Block(-7,-2,-4,PRISMARINE)
Block(-7,-2,-3,PRISMARINE:1)
Block(-7,-2,-2,PRISMARINE)
Block(-7,-2,-1,PRISMARINE:1)
Block(-7,-2,0,PRISMARINE)
Block(-7,-2,1,PRISMARINE:1)
Block(-7,-2,2,PRISMARINE)
Block(-7,-2,3,PRISMARINE:1)
Block(-7,-2,4,PRISMARINE)
Block(-7,-2,5,PRISMARINE)
Block(-7,-2,6,PRISMARINE)
Block(-7,-2,7,PRISMARINE)
Block(-7,-1,-7,PRISMARINE)
Block(-7,-1,-6,PRISMARINE)
Block(-7,-1,-5,PRISMARINE)
Block(-7,-1,-4,PRISMARINE)
Block(-7,-1,-3,STATIONARY_WATER)
Block(-7,-1,-2,PRISMARINE)
Block(-7,-1,-1,STATIONARY_WATER)
Block(-7,-1,0,PRISMARINE)
Block(-7,-1,1,STATIONARY_WATER)
Block(-7,-1,2,PRISMARINE)
Block(-7,-1,3,STATIONARY_WATER)
Block(-7,-1,4,PRISMARINE)
Block(-7,-1,5,PRISMARINE)
Block(-7,-1,6,PRISMARINE)
Block(-7,-1,7,PRISMARINE)
Block(-7,0,-7,PRISMARINE)
Block(-7,0,-6,PRISMARINE)
Block(-7,0,-5,PRISMARINE)
Block(-7,0,-4,PRISMARINE)
Block(-7,0,-3,STATIONARY_WATER)
Block(-7,0,-2,PRISMARINE)
Block(-7,0,-1,STATIONARY_WATER)
Block(-7,0,0,PRISMARINE)
Block(-7,0,1,STATIONARY_WATER)
Block(-7,0,2,PRISMARINE)
Block(-7,0,3,STATIONARY_WATER)
Block(-7,0,4,PRISMARINE)
Block(-7,0,5,PRISMARINE)
Block(-7,0,6,PRISMARINE)
Block(-7,0,7,PRISMARINE)
Block(-7,1,-7,PRISMARINE)
Block(-7,1,-6,PRISMARINE)
Block(-7,1,-5,PRISMARINE)
Block(-7,1,-4,PRISMARINE)
Block(-7,1,-3,PRISMARINE)
Block(-7,1,-2,PRISMARINE)
Block(-7,1,-1,STATIONARY_WATER)
Block(-7,1,0,PRISMARINE)
Block(-7,1,1,STATIONARY_WATER)
Block(-7,1,2,PRISMARINE)
Block(-7,1,3,PRISMARINE)
Block(-7,1,4,PRISMARINE)
Block(-7,1,5,PRISMARINE)
Block(-7,1,6,PRISMARINE)
Block(-7,1,7,PRISMARINE)
Block(-7,2,-7,PRISMARINE)
Block(-7,2,-6,PRISMARINE)
Block(-7,2,-5,PRISMARINE)
Block(-7,2,-4,PRISMARINE)
Block(-7,2,-3,PRISMARINE)
Block(-7,2,-2,PRISMARINE)
Block(-7,2,-1,STATIONARY_WATER)
Block(-7,2,0,PRISMARINE)
Block(-7,2,1,STATIONARY_WATER)
Block(-7,2,2,PRISMARINE)
Block(-7,2,3,PRISMARINE)
Block(-7,2,4,PRISMARINE)
Block(-7,2,5,PRISMARINE)
Block(-7,2,6,PRISMARINE)
Block(-7,2,7,PRISMARINE)
Block(-7,3,-7,PRISMARINE)
Block(-7,3,-6,PRISMARINE)
Block(-7,3,-5,PRISMARINE)
Block(-7,3,-4,PRISMARINE)
Block(-7,3,-3,PRISMARINE)
Block(-7,3,-2,PRISMARINE)
Block(-7,3,-1,PRISMARINE)
Block(-7,3,0,PRISMARINE)
Block(-7,3,1,PRISMARINE)
Block(-7,3,2,PRISMARINE)
Block(-7,3,3,PRISMARINE)
Block(-7,3,4,PRISMARINE)
Block(-7,3,5,PRISMARINE)
Block(-7,3,6,PRISMARINE)
Block(-7,3,7,PRISMARINE)
Block(-7,4,-7,PRISMARINE)
Block(-7,4,-6,PRISMARINE)
Block(-7,4,-5,PRISMARINE)
Block(-7,4,-4,PRISMARINE)
Block(-7,4,-3,PRISMARINE)
Block(-7,4,-2,PRISMARINE)
Block(-7,4,-1,PRISMARINE)
Block(-7,4,0,PRISMARINE)
Block(-7,4,1,PRISMARINE)
Block(-7,4,2,PRISMARINE)
Block(-7,4,3,PRISMARINE)
Block(-7,4,4,PRISMARINE)
Block(-7,4,5,PRISMARINE)
Block(-7,4,6,PRISMARINE)
Block(-7,4,7,PRISMARINE)
Block(-7,5,-7,PRISMARINE)
Block(-7,5,-6,PRISMARINE)
Block(-7,5,-5,PRISMARINE)
Block(-7,5,-4,PRISMARINE)
Block(-7,5,-3,PRISMARINE)
Block(-7,5,-2,PRISMARINE)
Block(-7,5,-1,PRISMARINE)
Block(-7,5,0,PRISMARINE)
Block(-7,5,1,PRISMARINE)
Block(-7,5,2,PRISMARINE)
Block(-7,5,3,PRISMARINE)
Block(-7,5,4,PRISMARINE)
Block(-7,5,5,PRISMARINE)
Block(-7,5,6,PRISMARINE)
Block(-7,5,7,PRISMARINE)
Block(-7,6,-7,PRISMARINE)
Block(-7,6,-6,PRISMARINE)
Block(-7,6,-5,PRISMARINE)
Block(-7,6,-4,PRISMARINE)
Block(-7,6,-3,PRISMARINE)
Block(-7,6,-2,PRISMARINE)
Block(-7,6,-1,PRISMARINE)
Block(-7,6,0,PRISMARINE)
Block(-7,6,1,PRISMARINE)
Block(-7,6,2,PRISMARINE)
Block(-7,6,3,PRISMARINE)
Block(-7,6,4,PRISMARINE)
Block(-7,6,5,PRISMARINE)
Block(-7,6,6,PRISMARINE)
Block(-7,6,7,PRISMARINE)
Block(-7,7,-7,PRISMARINE)
Block(-7,7,-6,PRISMARINE)
Block(-7,7,-5,PRISMARINE)
Block(-7,7,-4,PRISMARINE)
Block(-7,7,-3,PRISMARINE)
Block(-7,7,-2,PRISMARINE)
Block(-7,7,-1,PRISMARINE)
Block(-7,7,0,PRISMARINE)
Block(-7,7,1,PRISMARINE)
Block(-7,7,2,PRISMARINE)
Block(-7,7,3,PRISMARINE)
Block(-7,7,4,PRISMARINE)
Block(-7,7,5,PRISMARINE)
Block(-7,7,6,PRISMARINE)
Block(-7,7,7,PRISMARINE)
Block(-7,8,-7,PRISMARINE)
Block(-7,8,-6,PRISMARINE)
Block(-7,8,-5,PRISMARINE)
Block(-7,8,-4,PRISMARINE)
Block(-7,8,-3,PRISMARINE)
Block(-7,8,-2,PRISMARINE)
Block(-7,8,-1,PRISMARINE)
Block(-7,8,0,PRISMARINE)
Block(-7,8,1,PRISMARINE)
Block(-7,8,2,PRISMARINE)
Block(-7,8,3,PRISMARINE)
Block(-7,8,4,PRISMARINE)
Block(-7,8,5,PRISMARINE)
Block(-7,8,6,PRISMARINE)
Block(-7,8,7,PRISMARINE)
Block(-7,9,-8,PRISMARINE:1)
Block(-7,9,-7,PRISMARINE:1)
Block(-7,9,-6,PRISMARINE:1)
Block(-7,9,-5,PRISMARINE:1)
Block(-7,9,-4,PRISMARINE:1)
Block(-7,9,-3,PRISMARINE:1)
Block(-7,9,-2,PRISMARINE:1)
Block(-7,9,-1,PRISMARINE:1)
Block(-7,9,0,PRISMARINE:1)
Block(-7,9,1,PRISMARINE:1)
Block(-7,9,2,PRISMARINE:1)
Block(-7,9,3,PRISMARINE:1)
Block(-7,9,4,PRISMARINE:1)
Block(-7,9,5,PRISMARINE:1)
Block(-7,9,6,PRISMARINE:1)
Block(-7,9,7,PRISMARINE:1)
Block(-7,9,8,PRISMARINE:1)
Block(-7,10,-7,PRISMARINE)
Block(-7,10,-6,PRISMARINE)
Block(-7,10,-5,PRISMARINE)
Block(-7,10,-4,PRISMARINE)
Block(-7,10,-3,PRISMARINE)
Block(-7,10,-2,PRISMARINE)
Block(-7,10,-1,PRISMARINE)
Block(-7,10,0,PRISMARINE)
Block(-7,10,1,PRISMARINE)
Block(-7,10,2,PRISMARINE)
Block(-7,10,3,PRISMARINE)
Block(-7,10,4,PRISMARINE)
Block(-7,10,5,PRISMARINE)
Block(-7,10,6,PRISMARINE)
Block(-7,10,7,PRISMARINE)
Block(-7,11,-7,PRISMARINE:2)
Block(-7,11,-6,PRISMARINE:2)
Block(-7,11,-5,PRISMARINE:2)
Block(-7,11,-4,PRISMARINE:2)
Block(-7,11,-3,PRISMARINE:2)
Block(-7,11,-2,PRISMARINE:2)
Block(-7,11,-1,PRISMARINE:2)
Block(-7,11,0,PRISMARINE:2)
Block(-7,11,1,PRISMARINE:2)
Block(-7,11,2,PRISMARINE:2)
Block(-7,11,3,PRISMARINE:2)
Block(-7,11,4,PRISMARINE:2)
Block(-7,11,5,PRISMARINE:2)
Block(-7,11,6,PRISMARINE:2)
Block(-7,11,7,PRISMARINE:2)
Block(-6,-3,-8,PRISMARINE)
Block(-6,-3,-7,PRISMARINE)
Block(-6,-3,-6,PRISMARINE)
Block(-6,-3,-5,PRISMARINE:1)
Block(-6,-3,-4,PRISMARINE)
Block(-6,-3,-3,PRISMARINE)
Block(-6,-3,-2,PRISMARINE)
Block(-6,-3,-1,PRISMARINE)
Block(-6,-3,0,PRISMARINE)
Block(-6,-3,1,PRISMARINE)
Block(-6,-3,2,PRISMARINE)
Block(-6,-3,3,PRISMARINE)
Block(-6,-3,4,PRISMARINE)
Block(-6,-3,5,PRISMARINE)
Block(-6,-3,6,PRISMARINE)
Block(-6,-3,7,PRISMARINE)
Block(-6,-3,8,PRISMARINE)
Block(-6,-2,-8,PRISMARINE)
Block(-6,-2,-7,PRISMARINE)
Block(-6,-2,-6,PRISMARINE)
Block(-6,-2,-5,PRISMARINE:1)
Block(-6,-2,-4,PRISMARINE)
Block(-6,-2,-3,PRISMARINE)
Block(-6,-2,-2,PRISMARINE)
Block(-6,-2,-1,PRISMARINE)
Block(-6,-2,0,PRISMARINE)
Block(-6,-2,1,PRISMARINE)
Block(-6,-2,2,PRISMARINE)
Block(-6,-2,3,PRISMARINE)
Block(-6,-2,4,PRISMARINE)
Block(-6,-2,5,PRISMARINE)
Block(-6,-2,6,PRISMARINE)
Block(-6,-2,7,PRISMARINE)
Block(-6,-2,8,PRISMARINE)
Block(-6,-1,-8,PRISMARINE)
Block(-6,-1,-7,PRISMARINE)
Block(-6,-1,-6,PRISMARINE:1)
Block(-6,-1,-5,PRISMARINE:1)
Block(-6,-1,-4,STATIONARY_WATER)
Block(-6,-1,-3,STATIONARY_WATER)
Block(-6,-1,-2,STATIONARY_WATER)
Block(-6,-1,-1,STATIONARY_WATER)
Block(-6,-1,0,PRISMARINE:1)
Block(-6,-1,1,STATIONARY_WATER)
Block(-6,-1,2,STATIONARY_WATER)
Block(-6,-1,3,STATIONARY_WATER)
Block(-6,-1,4,STATIONARY_WATER)
Block(-6,-1,5,PRISMARINE:1)
Block(-6,-1,6,PRISMARINE:1)
Block(-6,-1,7,PRISMARINE)
Block(-6,-1,8,PRISMARINE)
Block(-6,0,-8,PRISMARINE)
Block(-6,0,-7,PRISMARINE)
Block(-6,0,-6,PRISMARINE:1)
Block(-6,0,-5,PRISMARINE:1)
Block(-6,0,-4,PRISMARINE:1)
Block(-6,0,-3,STATIONARY_WATER)
Block(-6,0,-2,STATIONARY_WATER)
Block(-6,0,-1,STATIONARY_WATER)
Block(-6,0,0,GOLD_BLOCK)
Block(-6,0,1,STATIONARY_WATER)
Block(-6,0,2,STATIONARY_WATER)
Block(-6,0,3,STATIONARY_WATER)
Block(-6,0,4,PRISMARINE:1)
Block(-6,0,5,PRISMARINE:1)
Block(-6,0,6,PRISMARINE:1)
Block(-6,0,7,PRISMARINE)
Block(-6,0,8,PRISMARINE)
Block(-6,1,-8,PRISMARINE)
Block(-6,1,-7,PRISMARINE)
Block(-6,1,-6,PRISMARINE:1)
Block(-6,1,-5,PRISMARINE)
Block(-6,1,-4,PRISMARINE:1)
Block(-6,1,-3,PRISMARINE:1)
Block(-6,1,-2,STATIONARY_WATER)
Block(-6,1,-1,STATIONARY_WATER)
Block(-6,1,0,STATIONARY_WATER)
Block(-6,1,1,STATIONARY_WATER)
Block(-6,1,2,STATIONARY_WATER)
Block(-6,1,3,PRISMARINE:1)
Block(-6,1,4,PRISMARINE:1)
Block(-6,1,5,PRISMARINE)
Block(-6,1,6,PRISMARINE:1)
Block(-6,1,7,PRISMARINE)
Block(-6,1,8,PRISMARINE)
Block(-6,2,-8,PRISMARINE)
Block(-6,2,-7,PRISMARINE)
Block(-6,2,-6,PRISMARINE:1)
Block(-6,2,-5,PRISMARINE)
Block(-6,2,-4,PRISMARINE)
Block(-6,2,-3,PRISMARINE:1)
Block(-6,2,-2,PRISMARINE:1)
Block(-6,2,-1,STATIONARY_WATER)
Block(-6,2,0,STATIONARY_WATER)
Block(-6,2,1,STATIONARY_WATER)
Block(-6,2,2,PRISMARINE:1)
Block(-6,2,3,PRISMARINE:1)
Block(-6,2,4,PRISMARINE)
Block(-6,2,5,PRISMARINE)
Block(-6,2,6,PRISMARINE:1)
Block(-6,2,7,PRISMARINE)
Block(-6,2,8,PRISMARINE)
Block(-6,3,-8,PRISMARINE)
Block(-6,3,-7,PRISMARINE)
Block(-6,3,-6,PRISMARINE:1)
Block(-6,3,-5,PRISMARINE)
Block(-6,3,-4,PRISMARINE)
Block(-6,3,-3,PRISMARINE)
Block(-6,3,-2,PRISMARINE:1)
Block(-6,3,-1,PRISMARINE:1)
Block(-6,3,0,PRISMARINE:1)
Block(-6,3,1,PRISMARINE:1)
Block(-6,3,2,PRISMARINE:1)
Block(-6,3,3,PRISMARINE)
Block(-6,3,4,PRISMARINE)
Block(-6,3,5,PRISMARINE)
Block(-6,3,6,PRISMARINE:1)
Block(-6,3,7,PRISMARINE)
Block(-6,3,8,PRISMARINE)
Block(-6,4,-8,PRISMARINE)
Block(-6,4,-7,PRISMARINE)
Block(-6,4,-6,PRISMARINE:1)
Block(-6,4,-5,PRISMARINE)
Block(-6,4,-4,PRISMARINE)
Block(-6,4,-3,PRISMARINE)
Block(-6,4,-2,PRISMARINE)
Block(-6,4,-1,PRISMARINE:1)
Block(-6,4,0,SEA_LANTERN)
Block(-6,4,1,PRISMARINE:1)
Block(-6,4,2,PRISMARINE)
Block(-6,4,3,PRISMARINE)
Block(-6,4,4,PRISMARINE)
Block(-6,4,5,PRISMARINE)
Block(-6,4,6,PRISMARINE:1)
Block(-6,4,7,PRISMARINE)
Block(-6,4,8,PRISMARINE)
Block(-6,5,-8,PRISMARINE)
Block(-6,5,-7,PRISMARINE)
Block(-6,5,-6,PRISMARINE:1)
Block(-6,5,-5,PRISMARINE:1)
Block(-6,5,-4,PRISMARINE:1)
Block(-6,5,-3,PRISMARINE:1)
Block(-6,5,-2,PRISMARINE:1)
Block(-6,5,-1,PRISMARINE:1)
Block(-6,5,0,PRISMARINE:1)
Block(-6,5,1,PRISMARINE:1)
Block(-6,5,2,PRISMARINE:1)
Block(-6,5,3,PRISMARINE:1)
Block(-6,5,4,PRISMARINE:1)
Block(-6,5,5,PRISMARINE:1)
Block(-6,5,6,PRISMARINE:1)
Block(-6,5,7,PRISMARINE)
Block(-6,5,8,PRISMARINE)
Block(-6,6,-8,PRISMARINE)
Block(-6,6,-7,PRISMARINE)
Block(-6,6,-6,PRISMARINE:1)
Block(-6,6,-5,STATIONARY_WATER)
Block(-6,6,-4,PRISMARINE)
Block(-6,6,-3,STATIONARY_WATER)
Block(-6,6,-2,PRISMARINE)
Block(-6,6,-1,STATIONARY_WATER)
Block(-6,6,0,PRISMARINE)
Block(-6,6,1,STATIONARY_WATER)
Block(-6,6,2,PRISMARINE)
Block(-6,6,3,STATIONARY_WATER)
Block(-6,6,4,PRISMARINE)
Block(-6,6,5,STATIONARY_WATER)
Block(-6,6,6,PRISMARINE:1)
Block(-6,6,7,PRISMARINE)
Block(-6,6,8,PRISMARINE)
Block(-6,7,-8,PRISMARINE)
Block(-6,7,-7,PRISMARINE)
Block(-6,7,-6,PRISMARINE:1)
Block(-6,7,-5,STATIONARY_WATER)
Block(-6,7,-4,PRISMARINE)
Block(-6,7,-3,STATIONARY_WATER)
Block(-6,7,-2,PRISMARINE)
Block(-6,7,-1,STATIONARY_WATER)
Block(-6,7,0,PRISMARINE)
Block(-6,7,1,STATIONARY_WATER)
Block(-6,7,2,PRISMARINE)
Block(-6,7,3,STATIONARY_WATER)
Block(-6,7,4,PRISMARINE)
Block(-6,7,5,STATIONARY_WATER)
Block(-6,7,6,PRISMARINE:1)
Block(-6,7,7,PRISMARINE)
Block(-6,7,8,PRISMARINE)
Block(-6,8,-8,PRISMARINE)
Block(-6,8,-7,PRISMARINE)
Block(-6,8,-6,PRISMARINE:1)
Block(-6,8,-5,STATIONARY_WATER)
Block(-6,8,-4,PRISMARINE)
Block(-6,8,-3,STATIONARY_WATER)
Block(-6,8,-2,PRISMARINE)
Block(-6,8,-1,STATIONARY_WATER)
Block(-6,8,0,PRISMARINE)
Block(-6,8,1,STATIONARY_WATER)
Block(-6,8,2,PRISMARINE)
Block(-6,8,3,STATIONARY_WATER)
Block(-6,8,4,PRISMARINE)
Block(-6,8,5,STATIONARY_WATER)
Block(-6,8,6,PRISMARINE:1)
Block(-6,8,7,PRISMARINE)
Block(-6,8,8,PRISMARINE)
Block(-6,9,-8,PRISMARINE:1)
Block(-6,9,-7,PRISMARINE:1)
Block(-6,9,-6,PRISMARINE:1)
Block(-6,9,-5,PRISMARINE:1)
Block(-6,9,-4,PRISMARINE:1)
Block(-6,9,-3,PRISMARINE:1)
Block(-6,9,-2,PRISMARINE:1)
Block(-6,9,-1,PRISMARINE:1)
Block(-6,9,0,PRISMARINE:1)
Block(-6,9,1,PRISMARINE:1)
Block(-6,9,2,PRISMARINE:1)
Block(-6,9,3,PRISMARINE:1)
Block(-6,9,4,PRISMARINE:1)
Block(-6,9,5,PRISMARINE:1)
Block(-6,9,6,PRISMARINE:1)
Block(-6,9,7,PRISMARINE:1)
Block(-6,9,8,PRISMARINE:1)
Block(-6,10,-7,PRISMARINE)
Block(-6,10,-6,PRISMARINE:2)
Block(-6,10,-5,PRISMARINE:2)
Block(-6,10,-4,PRISMARINE:2)
Block(-6,10,-3,PRISMARINE:2)
Block(-6,10,-2,PRISMARINE:2)
Block(-6,10,-1,PRISMARINE:2)
Block(-6,10,0,PRISMARINE:2)
Block(-6,10,1,PRISMARINE:2)
Block(-6,10,2,PRISMARINE:2)
Block(-6,10,3,PRISMARINE:2)
Block(-6,10,4,PRISMARINE:2)
Block(-6,10,5,PRISMARINE:2)
Block(-6,10,6,PRISMARINE:2)
Block(-6,10,7,PRISMARINE)
Block(-6,11,-7,PRISMARINE:2)
Block(-6,11,-6,PRISMARINE:1)
Block(-6,11,-5,PRISMARINE:1)
Block(-6,11,-4,PRISMARINE:1)
Block(-6,11,-3,PRISMARINE:1)
Block(-6,11,-2,PRISMARINE:1)
Block(-6,11,-1,PRISMARINE:1)
Block(-6,11,0,PRISMARINE:1)
Block(-6,11,1,PRISMARINE:1)
Block(-6,11,2,PRISMARINE:1)
Block(-6,11,3,PRISMARINE:1)
Block(-6,11,4,PRISMARINE:1)
Block(-6,11,5,PRISMARINE:1)
Block(-6,11,6,PRISMARINE:1)
Block(-6,11,7,PRISMARINE:2)
Block(-6,12,-5,PRISMARINE)
Block(-6,12,-3,PRISMARINE)
Block(-6,12,-1,PRISMARINE)
Block(-6,12,1,PRISMARINE)
Block(-6,12,3,PRISMARINE)
Block(-6,12,5,PRISMARINE)
Block(-6,13,-5,PRISMARINE)
Block(-6,13,-3,PRISMARINE)
Block(-6,13,-1,PRISMARINE)
Block(-6,13,1,PRISMARINE)
Block(-6,13,3,PRISMARINE)
Block(-6,13,5,PRISMARINE)
Block(-6,14,-5,PRISMARINE)
Block(-6,14,-3,PRISMARINE)
Block(-6,14,-1,PRISMARINE)
Block(-6,14,1,PRISMARINE)
Block(-6,14,3,PRISMARINE)
Block(-6,14,5,PRISMARINE)
Block(-6,15,-5,PRISMARINE)
Block(-6,15,-3,PRISMARINE)
Block(-6,15,-1,PRISMARINE)
Block(-6,15,1,PRISMARINE)
Block(-6,15,3,PRISMARINE)
Block(-6,15,5,PRISMARINE)
Block(-6,16,-5,PRISMARINE)
Block(-6,16,-3,PRISMARINE)
Block(-6,16,-1,PRISMARINE)
Block(-6,16,1,PRISMARINE)
Block(-6,16,3,PRISMARINE)
Block(-6,16,5,PRISMARINE)
Block(-6,17,-5,PRISMARINE:1)
Block(-6,17,-4,PRISMARINE:1)
Block(-6,17,-3,PRISMARINE:1)
Block(-6,17,-2,PRISMARINE:1)
Block(-6,17,-1,PRISMARINE:1)
Block(-6,17,1,PRISMARINE:1)
Block(-6,17,2,PRISMARINE:1)
Block(-6,17,3,PRISMARINE:1)
Block(-6,17,4,PRISMARINE:1)
Block(-6,17,5,PRISMARINE:1)
Block(-6,18,-1,PRISMARINE:1)
Block(-6,18,0,PRISMARINE:1)
Block(-6,18,1,PRISMARINE:1)
Block(-5,-3,-7,PRISMARINE)
Block(-5,-3,-6,PRISMARINE:1)
Block(-5,-3,-5,PRISMARINE:1)
Block(-5,-3,-4,PRISMARINE:1)
Block(-5,-3,-3,PRISMARINE)
Block(-5,-3,-2,PRISMARINE)
Block(-5,-3,-1,PRISMARINE)
Block(-5,-3,0,PRISMARINE)
Block(-5,-3,1,PRISMARINE)
Block(-5,-3,2,PRISMARINE)
Block(-5,-3,3,PRISMARINE)
Block(-5,-3,4,PRISMARINE:1)
Block(-5,-3,5,PRISMARINE:1)
Block(-5,-3,6,PRISMARINE)
Block(-5,-3,7,PRISMARINE)
Block(-5,-2,-7,PRISMARINE)
Block(-5,-2,-6,PRISMARINE:1)
Block(-5,-2,-5,PRISMARINE:1)
Block(-5,-2,-4,PRISMARINE:1)
Block(-5,-2,-3,PRISMARINE)
Block(-5,-2,-2,PRISMARINE)
Block(-5,-2,-1,PRISMARINE)
Block(-5,-2,0,PRISMARINE)
Block(-5,-2,1,PRISMARINE)
Block(-5,-2,2,PRISMARINE)
Block(-5,-2,3,PRISMARINE)
Block(-5,-2,4,PRISMARINE:1)
Block(-5,-2,5,PRISMARINE:1)
Block(-5,-2,6,PRISMARINE)
Block(-5,-2,7,PRISMARINE)
Block(-5,-1,-7,PRISMARINE)
Block(-5,-1,-6,PRISMARINE:1)
Block(-5,-1,-5,STATIONARY_WATER)
Block(-5,-1,-4,STATIONARY_WATER)
Block(-5,-1,-3,STATIONARY_WATER)
Block(-5,-1,-2,STATIONARY_WATER)
Block(-5,-1,-1,STATIONARY_WATER)
Block(-5,-1,0,STATIONARY_WATER)
Block(-5,-1,1,STATIONARY_WATER)
Block(-5,-1,2,STATIONARY_WATER)
Block(-5,-1,3,STATIONARY_WATER)
Block(-5,-1,4,STATIONARY_WATER)
Block(-5,-1,5,STATIONARY_WATER)
Block(-5,-1,6,PRISMARINE:1)
Block(-5,-1,7,PRISMARINE)
Block(-5,0,-7,PRISMARINE)
Block(-5,0,-6,PRISMARINE:1)
Block(-5,0,-5,STATIONARY_WATER)
Block(-5,0,-4,STATIONARY_WATER)
Block(-5,0,-3,STATIONARY_WATER)
Block(-5,0,-2,STATIONARY_WATER)
Block(-5,0,-1,STATIONARY_WATER)
Block(-5,0,0,STATIONARY_WATER)
Block(-5,0,1,STATIONARY_WATER)
Block(-5,0,2,STATIONARY_WATER)
Block(-5,0,3,STATIONARY_WATER)
Block(-5,0,4,STATIONARY_WATER)
Block(-5,0,5,STATIONARY_WATER)
Block(-5,0,6,PRISMARINE:1)
Block(-5,0,7,PRISMARINE)
Block(-5,1,-7,PRISMARINE)
Block(-5,1,-6,PRISMARINE)
Block(-5,1,-5,STATIONARY_WATER)
Block(-5,1,-4,STATIONARY_WATER)
Block(-5,1,-3,STATIONARY_WATER)
Block(-5,1,-2,STATIONARY_WATER)
Block(-5,1,-1,STATIONARY_WATER)
Block(-5,1,0,STATIONARY_WATER)
Block(-5,1,1,STATIONARY_WATER)
Block(-5,1,2,STATIONARY_WATER)
Block(-5,1,3,STATIONARY_WATER)
Block(-5,1,4,STATIONARY_WATER)
Block(-5,1,5,STATIONARY_WATER)
Block(-5,1,6,PRISMARINE)
Block(-5,1,7,PRISMARINE)
Block(-5,2,-7,PRISMARINE)
Block(-5,2,-6,PRISMARINE)
Block(-5,2,-5,STATIONARY_WATER)
Block(-5,2,-4,STATIONARY_WATER)
Block(-5,2,-3,STATIONARY_WATER)
Block(-5,2,-2,STATIONARY_WATER)
Block(-5,2,-1,STATIONARY_WATER)
Block(-5,2,0,STATIONARY_WATER)
Block(-5,2,1,STATIONARY_WATER)
Block(-5,2,2,STATIONARY_WATER)
Block(-5,2,3,STATIONARY_WATER)
Block(-5,2,4,STATIONARY_WATER)
Block(-5,2,5,STATIONARY_WATER)
Block(-5,2,6,PRISMARINE)
Block(-5,2,7,PRISMARINE)
Block(-5,3,-7,PRISMARINE)
Block(-5,3,-6,PRISMARINE)
Block(-5,3,-5,STATIONARY_WATER)
Block(-5,3,-4,STATIONARY_WATER)
Block(-5,3,-3,STATIONARY_WATER)
Block(-5,3,-2,STATIONARY_WATER)
Block(-5,3,-1,STATIONARY_WATER)
Block(-5,3,0,STATIONARY_WATER)
Block(-5,3,1,STATIONARY_WATER)
Block(-5,3,2,STATIONARY_WATER)
Block(-5,3,3,STATIONARY_WATER)
Block(-5,3,4,STATIONARY_WATER)
Block(-5,3,5,STATIONARY_WATER)
Block(-5,3,6,PRISMARINE)
Block(-5,3,7,PRISMARINE)
Block(-5,4,-7,PRISMARINE)
Block(-5,4,-6,PRISMARINE)
Block(-5,4,-5,STATIONARY_WATER)
Block(-5,4,-4,STATIONARY_WATER)
Block(-5,4,-3,STATIONARY_WATER)
Block(-5,4,-2,STATIONARY_WATER)
Block(-5,4,-1,STATIONARY_WATER)
Block(-5,4,0,STATIONARY_WATER)
Block(-5,4,1,STATIONARY_WATER)
Block(-5,4,2,STATIONARY_WATER)
Block(-5,4,3,STATIONARY_WATER)
Block(-5,4,4,STATIONARY_WATER)
Block(-5,4,5,STATIONARY_WATER)
Block(-5,4,6,PRISMARINE)
Block(-5,4,7,PRISMARINE)
Block(-5,5,-7,PRISMARINE)
Block(-5,5,-6,PRISMARINE:1)
Block(-5,5,-5,STATIONARY_WATER)
Block(-5,5,-4,STATIONARY_WATER)
Block(-5,5,-3,STATIONARY_WATER)
Block(-5,5,-2,STATIONARY_WATER)
Block(-5,5,-1,STATIONARY_WATER)
Block(-5,5,0,STATIONARY_WATER)
Block(-5,5,1,STATIONARY_WATER)
Block(-5,5,2,STATIONARY_WATER)
Block(-5,5,3,STATIONARY_WATER)
Block(-5,5,4,STATIONARY_WATER)
Block(-5,5,5,STATIONARY_WATER)
Block(-5,5,6,PRISMARINE:1)
Block(-5,5,7,PRISMARINE)
Block(-5,6,-7,PRISMARINE)
Block(-5,6,-6,STATIONARY_WATER)
Block(-5,6,-5,STATIONARY_WATER)
Block(-5,6,-4,STATIONARY_WATER)
Block(-5,6,-3,STATIONARY_WATER)
Block(-5,6,-2,STATIONARY_WATER)
Block(-5,6,-1,STATIONARY_WATER)
Block(-5,6,0,STATIONARY_WATER)
Block(-5,6,1,STATIONARY_WATER)
Block(-5,6,2,STATIONARY_WATER)
Block(-5,6,3,STATIONARY_WATER)
Block(-5,6,4,STATIONARY_WATER)
Block(-5,6,5,STATIONARY_WATER)
Block(-5,6,6,STATIONARY_WATER)
Block(-5,6,7,PRISMARINE)
Block(-5,7,-7,PRISMARINE)
Block(-5,7,-6,STATIONARY_WATER)
Block(-5,7,-5,STATIONARY_WATER)
Block(-5,7,-4,STATIONARY_WATER)
Block(-5,7,-3,STATIONARY_WATER)
Block(-5,7,-2,STATIONARY_WATER)
Block(-5,7,-1,STATIONARY_WATER)
Block(-5,7,0,STATIONARY_WATER)
Block(-5,7,1,STATIONARY_WATER)
Block(-5,7,2,STATIONARY_WATER)
Block(-5,7,3,STATIONARY_WATER)
Block(-5,7,4,STATIONARY_WATER)
Block(-5,7,5,STATIONARY_WATER)
Block(-5,7,6,STATIONARY_WATER)
Block(-5,7,7,PRISMARINE)
Block(-5,8,-7,PRISMARINE)
Block(-5,8,-6,STATIONARY_WATER)
Block(-5,8,-5,STATIONARY_WATER)
Block(-5,8,-4,STATIONARY_WATER)
Block(-5,8,-3,STATIONARY_WATER)
Block(-5,8,-2,STATIONARY_WATER)
Block(-5,8,-1,STATIONARY_WATER)
Block(-5,8,0,STATIONARY_WATER)
Block(-5,8,1,STATIONARY_WATER)
Block(-5,8,2,STATIONARY_WATER)
Block(-5,8,3,STATIONARY_WATER)
Block(-5,8,4,STATIONARY_WATER)
Block(-5,8,5,STATIONARY_WATER)
Block(-5,8,6,STATIONARY_WATER)
Block(-5,8,7,PRISMARINE)
Block(-5,9,-8,PRISMARINE:1)
Block(-5,9,-7,PRISMARINE:1)
Block(-5,9,-6,PRISMARINE:1)
Block(-5,9,-5,STATIONARY_WATER)
Block(-5,9,-4,PRISMARINE:1)
Block(-5,9,-3,STATIONARY_WATER)
Block(-5,9,-2,PRISMARINE:1)
Block(-5,9,-1,STATIONARY_WATER)
Block(-5,9,0,PRISMARINE:1)
Block(-5,9,1,STATIONARY_WATER)
Block(-5,9,2,PRISMARINE:1)
Block(-5,9,3,STATIONARY_WATER)
Block(-5,9,4,PRISMARINE:1)
Block(-5,9,5,STATIONARY_WATER)
Block(-5,9,6,PRISMARINE:1)
Block(-5,9,7,PRISMARINE:1)
Block(-5,9,8,PRISMARINE:1)
Block(-5,10,-7,PRISMARINE)
Block(-5,10,-6,PRISMARINE:2)
Block(-5,10,-5,STATIONARY_WATER)
Block(-5,10,-4,STATIONARY_WATER)
Block(-5,10,-3,STATIONARY_WATER)
Block(-5,10,-2,STATIONARY_WATER)
Block(-5,10,-1,STATIONARY_WATER)
Block(-5,10,0,STATIONARY_WATER)
Block(-5,10,1,STATIONARY_WATER)
Block(-5,10,2,STATIONARY_WATER)
Block(-5,10,3,STATIONARY_WATER)
Block(-5,10,4,STATIONARY_WATER)
Block(-5,10,5,STATIONARY_WATER)
Block(-5,10,6,PRISMARINE:2)
Block(-5,10,7,PRISMARINE)
Block(-5,11,-7,PRISMARINE:2)
Block(-5,11,-6,PRISMARINE:1)
Block(-5,11,-5,STATIONARY_WATER)
Block(-5,11,-4,STATIONARY_WATER)
Block(-5,11,-3,STATIONARY_WATER)
Block(-5,11,-2,STATIONARY_WATER)
Block(-5,11,-1,STATIONARY_WATER)
Block(-5,11,0,STATIONARY_WATER)
Block(-5,11,1,STATIONARY_WATER)
Block(-5,11,2,STATIONARY_WATER)
Block(-5,11,3,STATIONARY_WATER)
Block(-5,11,4,STATIONARY_WATER)
Block(-5,11,5,STATIONARY_WATER)
Block(-5,11,6,PRISMARINE:1)
Block(-5,11,7,PRISMARINE:2)
Block(-5,12,-6,PRISMARINE)
Block(-5,12,-5,STATIONARY_WATER)
Block(-5,12,-4,STATIONARY_WATER)
Block(-5,12,-3,STATIONARY_WATER)
Block(-5,12,-2,STATIONARY_WATER)
Block(-5,12,-1,STATIONARY_WATER)
Block(-5,12,0,STATIONARY_WATER)
Block(-5,12,1,STATIONARY_WATER)
Block(-5,12,2,STATIONARY_WATER)
Block(-5,12,3,STATIONARY_WATER)
Block(-5,12,4,STATIONARY_WATER)
Block(-5,12,5,STATIONARY_WATER)
Block(-5,12,6,PRISMARINE)
Block(-5,13,-6,PRISMARINE)
Block(-5,13,-5,STATIONARY_WATER)
Block(-5,13,-4,STATIONARY_WATER)
Block(-5,13,-3,STATIONARY_WATER)
Block(-5,13,-2,STATIONARY_WATER)
Block(-5,13,-1,STATIONARY_WATER)
Block(-5,13,0,STATIONARY_WATER)
Block(-5,13,1,STATIONARY_WATER)
Block(-5,13,2,STATIONARY_WATER)
Block(-5,13,3,STATIONARY_WATER)
Block(-5,13,4,STATIONARY_WATER)
Block(-5,13,5,STATIONARY_WATER)
Block(-5,13,6,PRISMARINE)
Block(-5,14,-6,PRISMARINE)
Block(-5,14,-5,STATIONARY_WATER)
Block(-5,14,-4,STATIONARY_WATER)
Block(-5,14,-3,STATIONARY_WATER)
Block(-5,14,-2,STATIONARY_WATER)
Block(-5,14,-1,STATIONARY_WATER)
Block(-5,14,0,STATIONARY_WATER)
Block(-5,14,1,STATIONARY_WATER)
Block(-5,14,2,STATIONARY_WATER)
Block(-5,14,3,STATIONARY_WATER)
Block(-5,14,4,STATIONARY_WATER)
Block(-5,14,5,STATIONARY_WATER)
Block(-5,14,6,PRISMARINE)
Block(-5,15,-6,PRISMARINE)
Block(-5,15,-5,STATIONARY_WATER)
Block(-5,15,-4,STATIONARY_WATER)
Block(-5,15,-3,STATIONARY_WATER)
Block(-5,15,-2,STATIONARY_WATER)
Block(-5,15,-1,STATIONARY_WATER)
Block(-5,15,0,STATIONARY_WATER)
Block(-5,15,1,STATIONARY_WATER)
Block(-5,15,2,STATIONARY_WATER)
Block(-5,15,3,STATIONARY_WATER)
Block(-5,15,4,STATIONARY_WATER)
Block(-5,15,5,STATIONARY_WATER)
Block(-5,15,6,PRISMARINE)
Block(-5,16,-6,PRISMARINE)
Block(-5,16,-5,STATIONARY_WATER)
Block(-5,16,-4,STATIONARY_WATER)
Block(-5,16,-3,STATIONARY_WATER)
Block(-5,16,-2,STATIONARY_WATER)
Block(-5,16,-1,STATIONARY_WATER)
Block(-5,16,0,STATIONARY_WATER)
Block(-5,16,1,STATIONARY_WATER)
Block(-5,16,2,STATIONARY_WATER)
Block(-5,16,3,STATIONARY_WATER)
Block(-5,16,4,STATIONARY_WATER)
Block(-5,16,5,STATIONARY_WATER)
Block(-5,16,6,PRISMARINE)
Block(-5,17,-6,PRISMARINE:1)
Block(-5,17,-5,STATIONARY_WATER)
Block(-5,17,-4,STATIONARY_WATER)
Block(-5,17,-3,STATIONARY_WATER)
Block(-5,17,-2,STATIONARY_WATER)
Block(-5,17,-1,STATIONARY_WATER)
Block(-5,17,0,STATIONARY_WATER)
Block(-5,17,1,STATIONARY_WATER)
Block(-5,17,2,STATIONARY_WATER)
Block(-5,17,3,STATIONARY_WATER)
Block(-5,17,4,STATIONARY_WATER)
Block(-5,17,5,STATIONARY_WATER)
Block(-5,17,6,PRISMARINE:1)
Block(-5,18,-5,PRISMARINE)
Block(-5,18,-4,PRISMARINE)
Block(-5,18,-3,PRISMARINE)
Block(-5,18,-2,PRISMARINE)
Block(-5,18,-1,PRISMARINE)
Block(-5,18,0,PRISMARINE)
Block(-5,18,1,PRISMARINE)
Block(-5,18,2,PRISMARINE)
Block(-5,18,3,PRISMARINE)
Block(-5,18,4,PRISMARINE)
Block(-5,18,5,PRISMARINE)
Block(-5,19,-5,PRISMARINE:2)
Block(-5,19,-4,PRISMARINE:2)
Block(-5,19,-3,PRISMARINE:2)
Block(-5,19,-2,PRISMARINE:2)
Block(-5,19,-1,PRISMARINE:2)
Block(-5,19,0,PRISMARINE:2)
Block(-5,19,1,PRISMARINE:2)
Block(-5,19,2,PRISMARINE:2)
Block(-5,19,3,PRISMARINE:2)
Block(-5,19,4,PRISMARINE:2)
Block(-5,19,5,PRISMARINE:2)
Block(-4,-3,-8,PRISMARINE)
Block(-4,-3,-7,PRISMARINE)
Block(-4,-3,-6,PRISMARINE)
Block(-4,-3,-5,PRISMARINE:1)
Block(-4,-3,-4,PRISMARINE:1)
Block(-4,-3,-3,PRISMARINE:1)
Block(-4,-3,-2,PRISMARINE)
Block(-4,-3,-1,PRISMARINE)
Block(-4,-3,0,PRISMARINE)
Block(-4,-3,1,PRISMARINE)
Block(-4,-3,2,PRISMARINE)
Block(-4,-3,3,PRISMARINE:1)
Block(-4,-3,4,PRISMARINE:1)
Block(-4,-3,5,PRISMARINE:1)
Block(-4,-3,6,PRISMARINE)
Block(-4,-3,7,PRISMARINE)
Block(-4,-3,8,PRISMARINE)
Block(-4,-2,-8,PRISMARINE)
Block(-4,-2,-7,PRISMARINE)
Block(-4,-2,-6,PRISMARINE)
Block(-4,-2,-5,PRISMARINE:1)
Block(-4,-2,-4,PRISMARINE:1)
Block(-4,-2,-3,PRISMARINE:1)
Block(-4,-2,-2,PRISMARINE)
Block(-4,-2,-1,PRISMARINE)
Block(-4,-2,0,PRISMARINE)
Block(-4,-2,1,PRISMARINE)
Block(-4,-2,2,PRISMARINE)
Block(-4,-2,3,PRISMARINE:1)
Block(-4,-2,4,PRISMARINE:1)
Block(-4,-2,5,PRISMARINE:1)
Block(-4,-2,6,PRISMARINE)
Block(-4,-2,7,PRISMARINE)
Block(-4,-2,8,PRISMARINE)
Block(-4,-1,-8,PRISMARINE)
Block(-4,-1,-7,PRISMARINE)
Block(-4,-1,-6,STATIONARY_WATER)
Block(-4,-1,-5,STATIONARY_WATER)
Block(-4,-1,-4,STATIONARY_WATER)
Block(-4,-1,-3,STATIONARY_WATER)
Block(-4,-1,-2,STATIONARY_WATER)
Block(-4,-1,-1,STATIONARY_WATER)
Block(-4,-1,0,STATIONARY_WATER)
Block(-4,-1,1,STATIONARY_WATER)
Block(-4,-1,2,STATIONARY_WATER)
Block(-4,-1,3,STATIONARY_WATER)
Block(-4,-1,4,STATIONARY_WATER)
Block(-4,-1,5,STATIONARY_WATER)
Block(-4,-1,6,STATIONARY_WATER)
Block(-4,-1,7,PRISMARINE)
Block(-4,-1,8,PRISMARINE)
Block(-4,0,-8,PRISMARINE)
Block(-4,0,-7,PRISMARINE)
Block(-4,0,-6,PRISMARINE:1)
Block(-4,0,-5,STATIONARY_WATER)
Block(-4,0,-4,STATIONARY_WATER)
Block(-4,0,-3,STATIONARY_WATER)
Block(-4,0,-2,STATIONARY_WATER)
Block(-4,0,-1,STATIONARY_WATER)
Block(-4,0,0,STATIONARY_WATER)
Block(-4,0,1,STATIONARY_WATER)
Block(-4,0,2,STATIONARY_WATER)
Block(-4,0,3,STATIONARY_WATER)
Block(-4,0,4,STATIONARY_WATER)
Block(-4,0,5,STATIONARY_WATER)
Block(-4,0,6,PRISMARINE:1)
Block(-4,0,7,PRISMARINE)
Block(-4,0,8,PRISMARINE)
Block(-4,1,-8,PRISMARINE)
Block(-4,1,-7,PRISMARINE)
Block(-4,1,-6,PRISMARINE:1)
Block(-4,1,-5,STATIONARY_WATER)
Block(-4,1,-4,STATIONARY_WATER)
Block(-4,1,-3,STATIONARY_WATER)
Block(-4,1,-2,STATIONARY_WATER)
Block(-4,1,-1,STATIONARY_WATER)
Block(-4,1,0,STATIONARY_WATER)
Block(-4,1,1,STATIONARY_WATER)
Block(-4,1,2,STATIONARY_WATER)
Block(-4,1,3,STATIONARY_WATER)
Block(-4,1,4,STATIONARY_WATER)
Block(-4,1,5,STATIONARY_WATER)
Block(-4,1,6,PRISMARINE:1)
Block(-4,1,7,PRISMARINE)
Block(-4,1,8,PRISMARINE)
Block(-4,2,-8,PRISMARINE)
Block(-4,2,-7,PRISMARINE)
Block(-4,2,-6,PRISMARINE)
Block(-4,2,-5,STATIONARY_WATER)
Block(-4,2,-4,STATIONARY_WATER)
Block(-4,2,-3,STATIONARY_WATER)
Block(-4,2,-2,STATIONARY_WATER)
Block(-4,2,-1,STATIONARY_WATER)
Block(-4,2,0,STATIONARY_WATER)
Block(-4,2,1,STATIONARY_WATER)
Block(-4,2,2,STATIONARY_WATER)
Block(-4,2,3,STATIONARY_WATER)
Block(-4,2,4,STATIONARY_WATER)
Block(-4,2,5,STATIONARY_WATER)
Block(-4,2,6,PRISMARINE)
Block(-4,2,7,PRISMARINE)
Block(-4,2,8,PRISMARINE)
Block(-4,3,-8,PRISMARINE)
Block(-4,3,-7,PRISMARINE)
Block(-4,3,-6,PRISMARINE)
Block(-4,3,-5,STATIONARY_WATER)
Block(-4,3,-4,STATIONARY_WATER)
Block(-4,3,-3,STATIONARY_WATER)
Block(-4,3,-2,STATIONARY_WATER)
Block(-4,3,-1,STATIONARY_WATER)
Block(-4,3,0,STATIONARY_WATER)
Block(-4,3,1,STATIONARY_WATER)
Block(-4,3,2,STATIONARY_WATER)
Block(-4,3,3,STATIONARY_WATER)
Block(-4,3,4,STATIONARY_WATER)
Block(-4,3,5,STATIONARY_WATER)
Block(-4,3,6,PRISMARINE)
Block(-4,3,7,PRISMARINE)
Block(-4,3,8,PRISMARINE)
Block(-4,4,-8,PRISMARINE)
Block(-4,4,-7,PRISMARINE)
Block(-4,4,-6,PRISMARINE)
Block(-4,4,-5,STATIONARY_WATER)
Block(-4,4,-4,STATIONARY_WATER)
Block(-4,4,-3,STATIONARY_WATER)
Block(-4,4,-2,STATIONARY_WATER)
Block(-4,4,-1,STATIONARY_WATER)
Block(-4,4,0,STATIONARY_WATER)
Block(-4,4,1,STATIONARY_WATER)
Block(-4,4,2,STATIONARY_WATER)
Block(-4,4,3,STATIONARY_WATER)
Block(-4,4,4,STATIONARY_WATER)
Block(-4,4,5,STATIONARY_WATER)
Block(-4,4,6,PRISMARINE)
Block(-4,4,7,PRISMARINE)
Block(-4,4,8,PRISMARINE)
Block(-4,5,-8,PRISMARINE)
Block(-4,5,-7,PRISMARINE)
Block(-4,5,-6,PRISMARINE:1)
Block(-4,5,-5,STATIONARY_WATER)
Block(-4,5,-4,STATIONARY_WATER)
Block(-4,5,-3,STATIONARY_WATER)
Block(-4,5,-2,STATIONARY_WATER)
Block(-4,5,-1,STATIONARY_WATER)
Block(-4,5,0,STATIONARY_WATER)
Block(-4,5,1,STATIONARY_WATER)
Block(-4,5,2,STATIONARY_WATER)
Block(-4,5,3,STATIONARY_WATER)
Block(-4,5,4,STATIONARY_WATER)
Block(-4,5,5,STATIONARY_WATER)
Block(-4,5,6,PRISMARINE:1)
Block(-4,5,7,PRISMARINE)
Block(-4,5,8,PRISMARINE)
Block(-4,6,-8,PRISMARINE)
Block(-4,6,-7,PRISMARINE)
Block(-4,6,-6,PRISMARINE)
Block(-4,6,-5,STATIONARY_WATER)
Block(-4,6,-4,STATIONARY_WATER)
Block(-4,6,-3,STATIONARY_WATER)
Block(-4,6,-2,STATIONARY_WATER)
Block(-4,6,-1,STATIONARY_WATER)
Block(-4,6,0,STATIONARY_WATER)
Block(-4,6,1,STATIONARY_WATER)
Block(-4,6,2,STATIONARY_WATER)
Block(-4,6,3,STATIONARY_WATER)
Block(-4,6,4,STATIONARY_WATER)
Block(-4,6,5,STATIONARY_WATER)
Block(-4,6,6,PRISMARINE)
Block(-4,6,7,PRISMARINE)
Block(-4,6,8,PRISMARINE)
Block(-4,7,-8,PRISMARINE)
Block(-4,7,-7,PRISMARINE)
Block(-4,7,-6,PRISMARINE)
Block(-4,7,-5,STATIONARY_WATER)
Block(-4,7,-4,STATIONARY_WATER)
Block(-4,7,-3,STATIONARY_WATER)
Block(-4,7,-2,STATIONARY_WATER)
Block(-4,7,-1,STATIONARY_WATER)
Block(-4,7,0,STATIONARY_WATER)
Block(-4,7,1,STATIONARY_WATER)
Block(-4,7,2,STATIONARY_WATER)
Block(-4,7,3,STATIONARY_WATER)
Block(-4,7,4,STATIONARY_WATER)
Block(-4,7,5,STATIONARY_WATER)
Block(-4,7,6,PRISMARINE)
Block(-4,7,7,PRISMARINE)
Block(-4,7,8,PRISMARINE)
Block(-4,8,-8,PRISMARINE)
Block(-4,8,-7,PRISMARINE)
Block(-4,8,-6,PRISMARINE)
Block(-4,8,-5,STATIONARY_WATER)
Block(-4,8,-4,STATIONARY_WATER)
Block(-4,8,-3,STATIONARY_WATER)
Block(-4,8,-2,STATIONARY_WATER)
Block(-4,8,-1,STATIONARY_WATER)
Block(-4,8,0,STATIONARY_WATER)
Block(-4,8,1,STATIONARY_WATER)
Block(-4,8,2,STATIONARY_WATER)
Block(-4,8,3,STATIONARY_WATER)
Block(-4,8,4,STATIONARY_WATER)
Block(-4,8,5,STATIONARY_WATER)
Block(-4,8,6,PRISMARINE)
Block(-4,8,7,PRISMARINE)
Block(-4,8,8,PRISMARINE)
Block(-4,9,-8,PRISMARINE:1)
Block(-4,9,-7,PRISMARINE:1)
Block(-4,9,-6,PRISMARINE:1)
Block(-4,9,-5,STATIONARY_WATER)
Block(-4,9,-4,PRISMARINE)
Block(-4,9,-3,STATIONARY_WATER)
Block(-4,9,-2,PRISMARINE)
Block(-4,9,-1,STATIONARY_WATER)
Block(-4,9,0,PRISMARINE)
Block(-4,9,1,STATIONARY_WATER)
Block(-4,9,2,PRISMARINE)
Block(-4,9,3,STATIONARY_WATER)
Block(-4,9,4,PRISMARINE)
Block(-4,9,5,STATIONARY_WATER)
Block(-4,9,6,PRISMARINE:1)
Block(-4,9,7,PRISMARINE:1)
Block(-4,9,8,PRISMARINE:1)
Block(-4,10,-7,PRISMARINE)
Block(-4,10,-6,PRISMARINE:2)
Block(-4,10,-5,STATIONARY_WATER)
Block(-4,10,-4,STATIONARY_WATER)
Block(-4,10,-3,STATIONARY_WATER)
Block(-4,10,-2,STATIONARY_WATER)
Block(-4,10,-1,STATIONARY_WATER)
Block(-4,10,0,STATIONARY_WATER)
Block(-4,10,1,STATIONARY_WATER)
Block(-4,10,2,STATIONARY_WATER)
Block(-4,10,3,STATIONARY_WATER)
Block(-4,10,4,STATIONARY_WATER)
Block(-4,10,5,STATIONARY_WATER)
Block(-4,10,6,PRISMARINE:2)
Block(-4,10,7,PRISMARINE)
Block(-4,11,-7,PRISMARINE:2)
Block(-4,11,-6,PRISMARINE:1)
Block(-4,11,-5,STATIONARY_WATER)
Block(-4,11,-4,STATIONARY_WATER)
Block(-4,11,-3,STATIONARY_WATER)
Block(-4,11,-2,STATIONARY_WATER)
Block(-4,11,-1,STATIONARY_WATER)
Block(-4,11,0,STATIONARY_WATER)
Block(-4,11,1,STATIONARY_WATER)
Block(-4,11,2,STATIONARY_WATER)
Block(-4,11,3,STATIONARY_WATER)
Block(-4,11,4,STATIONARY_WATER)
Block(-4,11,5,STATIONARY_WATER)
Block(-4,11,6,PRISMARINE:1)
Block(-4,11,7,PRISMARINE:2)
Block(-4,12,-5,STATIONARY_WATER)
Block(-4,12,-4,STATIONARY_WATER)
Block(-4,12,-3,STATIONARY_WATER)
Block(-4,12,-2,STATIONARY_WATER)
Block(-4,12,-1,STATIONARY_WATER)
Block(-4,12,0,STATIONARY_WATER)
Block(-4,12,1,STATIONARY_WATER)
Block(-4,12,2,STATIONARY_WATER)
Block(-4,12,3,STATIONARY_WATER)
Block(-4,12,4,STATIONARY_WATER)
Block(-4,12,5,STATIONARY_WATER)
Block(-4,13,-5,STATIONARY_WATER)
Block(-4,13,-4,STATIONARY_WATER)
Block(-4,13,-3,STATIONARY_WATER)
Block(-4,13,-2,STATIONARY_WATER)
Block(-4,13,-1,STATIONARY_WATER)
Block(-4,13,0,STATIONARY_WATER)
Block(-4,13,1,STATIONARY_WATER)
Block(-4,13,2,STATIONARY_WATER)
Block(-4,13,3,STATIONARY_WATER)
Block(-4,13,4,STATIONARY_WATER)
Block(-4,13,5,STATIONARY_WATER)
Block(-4,14,-5,STATIONARY_WATER)
Block(-4,14,-4,STATIONARY_WATER)
Block(-4,14,-3,STATIONARY_WATER)
Block(-4,14,-2,STATIONARY_WATER)
Block(-4,14,-1,STATIONARY_WATER)
Block(-4,14,0,STATIONARY_WATER)
Block(-4,14,1,STATIONARY_WATER)
Block(-4,14,2,STATIONARY_WATER)
Block(-4,14,3,STATIONARY_WATER)
Block(-4,14,4,STATIONARY_WATER)
Block(-4,14,5,STATIONARY_WATER)
Block(-4,15,-5,STATIONARY_WATER)
Block(-4,15,-4,STATIONARY_WATER)
Block(-4,15,-3,STATIONARY_WATER)
Block(-4,15,-2,STATIONARY_WATER)
Block(-4,15,-1,STATIONARY_WATER)
Block(-4,15,0,STATIONARY_WATER)
Block(-4,15,1,STATIONARY_WATER)
Block(-4,15,2,STATIONARY_WATER)
Block(-4,15,3,STATIONARY_WATER)
Block(-4,15,4,STATIONARY_WATER)
Block(-4,15,5,STATIONARY_WATER)
Block(-4,16,-5,STATIONARY_WATER)
Block(-4,16,-4,STATIONARY_WATER)
Block(-4,16,-3,STATIONARY_WATER)
Block(-4,16,-2,STATIONARY_WATER)
Block(-4,16,-1,STATIONARY_WATER)
Block(-4,16,0,STATIONARY_WATER)
Block(-4,16,1,STATIONARY_WATER)
Block(-4,16,2,STATIONARY_WATER)
Block(-4,16,3,STATIONARY_WATER)
Block(-4,16,4,STATIONARY_WATER)
Block(-4,16,5,STATIONARY_WATER)
Block(-4,17,-6,PRISMARINE:1)
Block(-4,17,-5,STATIONARY_WATER)
Block(-4,17,-4,STATIONARY_WATER)
Block(-4,17,-3,STATIONARY_WATER)
Block(-4,17,-2,STATIONARY_WATER)
Block(-4,17,-1,STATIONARY_WATER)
Block(-4,17,0,STATIONARY_WATER)
Block(-4,17,1,STATIONARY_WATER)
Block(-4,17,2,STATIONARY_WATER)
Block(-4,17,3,STATIONARY_WATER)
Block(-4,17,4,STATIONARY_WATER)
Block(-4,17,5,STATIONARY_WATER)
Block(-4,17,6,PRISMARINE:1)
Block(-4,18,-5,PRISMARINE)
Block(-4,18,-4,STATIONARY_WATER)
Block(-4,18,-3,STATIONARY_WATER)
Block(-4,18,-2,STATIONARY_WATER)
Block(-4,18,-1,STATIONARY_WATER)
Block(-4,18,0,STATIONARY_WATER)
Block(-4,18,1,STATIONARY_WATER)
Block(-4,18,2,STATIONARY_WATER)
Block(-4,18,3,STATIONARY_WATER)
Block(-4,18,4,STATIONARY_WATER)
Block(-4,18,5,PRISMARINE)
Block(-4,19,-5,PRISMARINE:2)
Block(-4,19,-4,PRISMARINE)
Block(-4,19,-3,PRISMARINE)
Block(-4,19,-2,PRISMARINE)
Block(-4,19,-1,PRISMARINE)
Block(-4,19,0,PRISMARINE:2)
Block(-4,19,1,PRISMARINE)
Block(-4,19,2,PRISMARINE)
Block(-4,19,3,PRISMARINE)
Block(-4,19,4,PRISMARINE)
Block(-4,19,5,PRISMARINE:2)
Block(-3,-3,-8,PRISMARINE)
Block(-3,-3,-7,PRISMARINE:1)
Block(-3,-3,-6,PRISMARINE)
Block(-3,-3,-5,PRISMARINE)
Block(-3,-3,-4,PRISMARINE:1)
Block(-3,-3,-3,PRISMARINE:1)
Block(-3,-3,-2,PRISMARINE:1)
Block(-3,-3,-1,PRISMARINE)
Block(-3,-3,0,PRISMARINE)
Block(-3,-3,1,PRISMARINE)
Block(-3,-3,2,PRISMARINE:1)
Block(-3,-3,3,PRISMARINE:1)
Block(-3,-3,4,PRISMARINE:1)
Block(-3,-3,5,PRISMARINE)
Block(-3,-3,6,PRISMARINE)
Block(-3,-3,7,PRISMARINE:1)
Block(-3,-3,8,PRISMARINE)
Block(-3,-2,-8,PRISMARINE)
Block(-3,-2,-7,PRISMARINE:1)
Block(-3,-2,-6,PRISMARINE)
Block(-3,-2,-5,PRISMARINE)
Block(-3,-2,-4,PRISMARINE:1)
Block(-3,-2,-3,PRISMARINE:1)
Block(-3,-2,-2,PRISMARINE:1)
Block(-3,-2,-1,PRISMARINE)
Block(-3,-2,0,PRISMARINE)
Block(-3,-2,1,PRISMARINE)
Block(-3,-2,2,PRISMARINE:1)
Block(-3,-2,3,PRISMARINE:1)
Block(-3,-2,4,PRISMARINE:1)
Block(-3,-2,5,PRISMARINE)
Block(-3,-2,6,PRISMARINE)
Block(-3,-2,7,PRISMARINE:1)
Block(-3,-2,8,PRISMARINE)
Block(-3,-1,-8,PRISMARINE)
Block(-3,-1,-7,STATIONARY_WATER)
Block(-3,-1,-6,STATIONARY_WATER)
Block(-3,-1,-5,STATIONARY_WATER)
Block(-3,-1,-4,STATIONARY_WATER)
Block(-3,-1,-3,STATIONARY_WATER)
Block(-3,-1,-2,STATIONARY_WATER)
Block(-3,-1,-1,STATIONARY_WATER)
Block(-3,-1,0,STATIONARY_WATER)
Block(-3,-1,1,STATIONARY_WATER)
Block(-3,-1,2,STATIONARY_WATER)
Block(-3,-1,3,STATIONARY_WATER)
Block(-3,-1,4,STATIONARY_WATER)
Block(-3,-1,5,STATIONARY_WATER)
Block(-3,-1,6,STATIONARY_WATER)
Block(-3,-1,7,STATIONARY_WATER)
Block(-3,-1,8,PRISMARINE)
Block(-3,0,-8,PRISMARINE)
Block(-3,0,-7,STATIONARY_WATER)
Block(-3,0,-6,STATIONARY_WATER)
Block(-3,0,-5,STATIONARY_WATER)
Block(-3,0,-4,STATIONARY_WATER)
Block(-3,0,-3,STATIONARY_WATER)
Block(-3,0,-2,STATIONARY_WATER)
Block(-3,0,-1,STATIONARY_WATER)
Block(-3,0,0,STATIONARY_WATER)
Block(-3,0,1,STATIONARY_WATER)
Block(-3,0,2,STATIONARY_WATER)
Block(-3,0,3,STATIONARY_WATER)
Block(-3,0,4,STATIONARY_WATER)
Block(-3,0,5,STATIONARY_WATER)
Block(-3,0,6,STATIONARY_WATER)
Block(-3,0,7,STATIONARY_WATER)
Block(-3,0,8,PRISMARINE)
Block(-3,1,-8,PRISMARINE)
Block(-3,1,-7,PRISMARINE)
Block(-3,1,-6,PRISMARINE:1)
Block(-3,1,-5,STATIONARY_WATER)
Block(-3,1,-4,STATIONARY_WATER)
Block(-3,1,-3,STATIONARY_WATER)
Block(-3,1,-2,STATIONARY_WATER)
Block(-3,1,-1,STATIONARY_WATER)
Block(-3,1,0,STATIONARY_WATER)
Block(-3,1,1,STATIONARY_WATER)
Block(-3,1,2,STATIONARY_WATER)
Block(-3,1,3,STATIONARY_WATER)
Block(-3,1,4,STATIONARY_WATER)
Block(-3,1,5,STATIONARY_WATER)
Block(-3,1,6,PRISMARINE:1)
Block(-3,1,7,PRISMARINE)
Block(-3,1,8,PRISMARINE)
Block(-3,2,-8,PRISMARINE)
Block(-3,2,-7,PRISMARINE)
Block(-3,2,-6,PRISMARINE:1)
Block(-3,2,-5,STATIONARY_WATER)
Block(-3,2,-4,STATIONARY_WATER)
Block(-3,2,-3,STATIONARY_WATER)
Block(-3,2,-2,STATIONARY_WATER)
Block(-3,2,-1,STATIONARY_WATER)
Block(-3,2,0,STATIONARY_WATER)
Block(-3,2,1,STATIONARY_WATER)
Block(-3,2,2,STATIONARY_WATER)
Block(-3,2,3,STATIONARY_WATER)
Block(-3,2,4,STATIONARY_WATER)
Block(-3,2,5,STATIONARY_WATER)
Block(-3,2,6,PRISMARINE:1)
Block(-3,2,7,PRISMARINE)
Block(-3,2,8,PRISMARINE)
Block(-3,3,-8,PRISMARINE)
Block(-3,3,-7,PRISMARINE)
Block(-3,3,-6,PRISMARINE)
Block(-3,3,-5,STATIONARY_WATER)
Block(-3,3,-4,STATIONARY_WATER)
Block(-3,3,-3,STATIONARY_WATER)
Block(-3,3,-2,STATIONARY_WATER)
Block(-3,3,-1,STATIONARY_WATER)
Block(-3,3,0,STATIONARY_WATER)
Block(-3,3,1,STATIONARY_WATER)
Block(-3,3,2,STATIONARY_WATER)
Block(-3,3,3,STATIONARY_WATER)
Block(-3,3,4,STATIONARY_WATER)
Block(-3,3,5,STATIONARY_WATER)
Block(-3,3,6,PRISMARINE)
Block(-3,3,7,PRISMARINE)
Block(-3,3,8,PRISMARINE)
Block(-3,4,-8,PRISMARINE)
Block(-3,4,-7,PRISMARINE)
Block(-3,4,-6,PRISMARINE)
Block(-3,4,-5,STATIONARY_WATER)
Block(-3,4,-4,STATIONARY_WATER)
Block(-3,4,-3,STATIONARY_WATER)
Block(-3,4,-2,STATIONARY_WATER)
Block(-3,4,-1,STATIONARY_WATER)
Block(-3,4,0,STATIONARY_WATER)
Block(-3,4,1,STATIONARY_WATER)
Block(-3,4,2,STATIONARY_WATER)
Block(-3,4,3,STATIONARY_WATER)
Block(-3,4,4,STATIONARY_WATER)
Block(-3,4,5,STATIONARY_WATER)
Block(-3,4,6,PRISMARINE)
Block(-3,4,7,PRISMARINE)
Block(-3,4,8,PRISMARINE)
Block(-3,5,-8,PRISMARINE)
Block(-3,5,-7,PRISMARINE)
Block(-3,5,-6,PRISMARINE:1)
Block(-3,5,-5,STATIONARY_WATER)
Block(-3,5,-4,STATIONARY_WATER)
Block(-3,5,-3,STATIONARY_WATER)
Block(-3,5,-2,STATIONARY_WATER)
Block(-3,5,-1,STATIONARY_WATER)
Block(-3,5,0,STATIONARY_WATER)
Block(-3,5,1,STATIONARY_WATER)
Block(-3,5,2,STATIONARY_WATER)
Block(-3,5,3,STATIONARY_WATER)
Block(-3,5,4,STATIONARY_WATER)
Block(-3,5,5,STATIONARY_WATER)
Block(-3,5,6,PRISMARINE:1)
Block(-3,5,7,PRISMARINE)
Block(-3,5,8,PRISMARINE)
Block(-3,6,-8,PRISMARINE)
Block(-3,6,-7,PRISMARINE)
Block(-3,6,-6,STATIONARY_WATER)
Block(-3,6,-5,STATIONARY_WATER)
Block(-3,6,-4,STATIONARY_WATER)
Block(-3,6,-3,STATIONARY_WATER)
Block(-3,6,-2,STATIONARY_WATER)
Block(-3,6,-1,STATIONARY_WATER)
Block(-3,6,0,STATIONARY_WATER)
Block(-3,6,1,STATIONARY_WATER)
Block(-3,6,2,STATIONARY_WATER)
Block(-3,6,3,STATIONARY_WATER)
Block(-3,6,4,STATIONARY_WATER)
Block(-3,6,5,STATIONARY_WATER)
Block(-3,6,6,STATIONARY_WATER)
Block(-3,6,7,PRISMARINE)
Block(-3,6,8,PRISMARINE)
Block(-3,7,-8,PRISMARINE)
Block(-3,7,-7,PRISMARINE)
Block(-3,7,-6,STATIONARY_WATER)
Block(-3,7,-5,STATIONARY_WATER)
Block(-3,7,-4,STATIONARY_WATER)
Block(-3,7,-3,STATIONARY_WATER)
Block(-3,7,-2,STATIONARY_WATER)
Block(-3,7,-1,STATIONARY_WATER)
Block(-3,7,0,STATIONARY_WATER)
Block(-3,7,1,STATIONARY_WATER)
Block(-3,7,2,STATIONARY_WATER)
Block(-3,7,3,STATIONARY_WATER)
Block(-3,7,4,STATIONARY_WATER)
Block(-3,7,5,STATIONARY_WATER)
Block(-3,7,6,STATIONARY_WATER)
Block(-3,7,7,PRISMARINE)
Block(-3,7,8,PRISMARINE)
Block(-3,8,-8,PRISMARINE)
Block(-3,8,-7,PRISMARINE)
Block(-3,8,-6,STATIONARY_WATER)
Block(-3,8,-5,STATIONARY_WATER)
Block(-3,8,-4,STATIONARY_WATER)
Block(-3,8,-3,STATIONARY_WATER)
Block(-3,8,-2,STATIONARY_WATER)
Block(-3,8,-1,STATIONARY_WATER)
Block(-3,8,0,STATIONARY_WATER)
Block(-3,8,1,STATIONARY_WATER)
Block(-3,8,2,STATIONARY_WATER)
Block(-3,8,3,STATIONARY_WATER)
Block(-3,8,4,STATIONARY_WATER)
Block(-3,8,5,STATIONARY_WATER)
Block(-3,8,6,STATIONARY_WATER)
Block(-3,8,7,PRISMARINE)
Block(-3,8,8,PRISMARINE)
Block(-3,9,-8,PRISMARINE:1)
Block(-3,9,-7,PRISMARINE:1)
Block(-3,9,-6,PRISMARINE:1)
Block(-3,9,-5,STATIONARY_WATER)
Block(-3,9,-4,PRISMARINE)
Block(-3,9,-3,STATIONARY_WATER)
Block(-3,9,-2,PRISMARINE)
Block(-3,9,-1,STATIONARY_WATER)
Block(-3,9,0,PRISMARINE)
Block(-3,9,1,STATIONARY_WATER)
Block(-3,9,2,PRISMARINE)
Block(-3,9,3,STATIONARY_WATER)
Block(-3,9,4,PRISMARINE)
Block(-3,9,5,STATIONARY_WATER)
Block(-3,9,6,PRISMARINE:1)
Block(-3,9,7,PRISMARINE:1)
Block(-3,9,8,PRISMARINE:1)
Block(-3,10,-7,PRISMARINE)
Block(-3,10,-6,PRISMARINE:2)
Block(-3,10,-5,STATIONARY_WATER)
Block(-3,10,-4,STATIONARY_WATER)
Block(-3,10,-3,STATIONARY_WATER)
Block(-3,10,-2,STATIONARY_WATER)
Block(-3,10,-1,STATIONARY_WATER)
Block(-3,10,0,STATIONARY_WATER)
Block(-3,10,1,STATIONARY_WATER)
Block(-3,10,2,STATIONARY_WATER)
Block(-3,10,3,STATIONARY_WATER)
Block(-3,10,4,STATIONARY_WATER)
Block(-3,10,5,STATIONARY_WATER)
Block(-3,10,6,PRISMARINE:2)
Block(-3,10,7,PRISMARINE)
Block(-3,11,-7,PRISMARINE:2)
Block(-3,11,-6,PRISMARINE:1)
Block(-3,11,-5,STATIONARY_WATER)
Block(-3,11,-4,STATIONARY_WATER)
Block(-3,11,-3,STATIONARY_WATER)
Block(-3,11,-2,STATIONARY_WATER)
Block(-3,11,-1,STATIONARY_WATER)
Block(-3,11,0,STATIONARY_WATER)
Block(-3,11,1,STATIONARY_WATER)
Block(-3,11,2,STATIONARY_WATER)
Block(-3,11,3,STATIONARY_WATER)
Block(-3,11,4,STATIONARY_WATER)
Block(-3,11,5,STATIONARY_WATER)
Block(-3,11,6,PRISMARINE:1)
Block(-3,11,7,PRISMARINE:2)
Block(-3,12,-6,PRISMARINE)
Block(-3,12,-5,STATIONARY_WATER)
Block(-3,12,-4,STATIONARY_WATER)
Block(-3,12,-3,STATIONARY_WATER)
Block(-3,12,-2,STATIONARY_WATER)
Block(-3,12,-1,STATIONARY_WATER)
Block(-3,12,0,STATIONARY_WATER)
Block(-3,12,1,STATIONARY_WATER)
Block(-3,12,2,STATIONARY_WATER)
Block(-3,12,3,STATIONARY_WATER)
Block(-3,12,4,STATIONARY_WATER)
Block(-3,12,5,STATIONARY_WATER)
Block(-3,12,6,PRISMARINE)
Block(-3,13,-6,PRISMARINE)
Block(-3,13,-5,STATIONARY_WATER)
Block(-3,13,-4,STATIONARY_WATER)
Block(-3,13,-3,STATIONARY_WATER)
Block(-3,13,-2,STATIONARY_WATER)
Block(-3,13,-1,STATIONARY_WATER)
Block(-3,13,0,STATIONARY_WATER)
Block(-3,13,1,STATIONARY_WATER)
Block(-3,13,2,STATIONARY_WATER)
Block(-3,13,3,STATIONARY_WATER)
Block(-3,13,4,STATIONARY_WATER)
Block(-3,13,5,STATIONARY_WATER)
Block(-3,13,6,PRISMARINE)
Block(-3,14,-6,PRISMARINE)
Block(-3,14,-5,STATIONARY_WATER)
Block(-3,14,-4,STATIONARY_WATER)
Block(-3,14,-3,STATIONARY_WATER)
Block(-3,14,-2,STATIONARY_WATER)
Block(-3,14,-1,STATIONARY_WATER)
Block(-3,14,0,STATIONARY_WATER)
Block(-3,14,1,STATIONARY_WATER)
Block(-3,14,2,STATIONARY_WATER)
Block(-3,14,3,STATIONARY_WATER)
Block(-3,14,4,STATIONARY_WATER)
Block(-3,14,5,STATIONARY_WATER)
Block(-3,14,6,PRISMARINE)
Block(-3,15,-6,PRISMARINE)
Block(-3,15,-5,STATIONARY_WATER)
Block(-3,15,-4,STATIONARY_WATER)
Block(-3,15,-3,STATIONARY_WATER)
Block(-3,15,-2,STATIONARY_WATER)
Block(-3,15,-1,STATIONARY_WATER)
Block(-3,15,0,STATIONARY_WATER)
Block(-3,15,1,STATIONARY_WATER)
Block(-3,15,2,STATIONARY_WATER)
Block(-3,15,3,STATIONARY_WATER)
Block(-3,15,4,STATIONARY_WATER)
Block(-3,15,5,STATIONARY_WATER)
Block(-3,15,6,PRISMARINE)
Block(-3,16,-6,PRISMARINE)
Block(-3,16,-5,STATIONARY_WATER)
Block(-3,16,-4,STATIONARY_WATER)
Block(-3,16,-3,STATIONARY_WATER)
Block(-3,16,-2,STATIONARY_WATER)
Block(-3,16,-1,STATIONARY_WATER)
Block(-3,16,0,STATIONARY_WATER)
Block(-3,16,1,STATIONARY_WATER)
Block(-3,16,2,STATIONARY_WATER)
Block(-3,16,3,STATIONARY_WATER)
Block(-3,16,4,STATIONARY_WATER)
Block(-3,16,5,STATIONARY_WATER)
Block(-3,16,6,PRISMARINE)
Block(-3,17,-6,PRISMARINE:1)
Block(-3,17,-5,STATIONARY_WATER)
Block(-3,17,-4,STATIONARY_WATER)
Block(-3,17,-3,STATIONARY_WATER)
Block(-3,17,-2,STATIONARY_WATER)
Block(-3,17,-1,STATIONARY_WATER)
Block(-3,17,0,STATIONARY_WATER)
Block(-3,17,1,STATIONARY_WATER)
Block(-3,17,2,STATIONARY_WATER)
Block(-3,17,3,STATIONARY_WATER)
Block(-3,17,4,STATIONARY_WATER)
Block(-3,17,5,STATIONARY_WATER)
Block(-3,17,6,PRISMARINE:1)
Block(-3,18,-5,PRISMARINE)
Block(-3,18,-4,STATIONARY_WATER)
Block(-3,18,-3,STATIONARY_WATER)
Block(-3,18,-2,STATIONARY_WATER)
Block(-3,18,-1,STATIONARY_WATER)
Block(-3,18,0,STATIONARY_WATER)
Block(-3,18,1,STATIONARY_WATER)
Block(-3,18,2,STATIONARY_WATER)
Block(-3,18,3,STATIONARY_WATER)
Block(-3,18,4,STATIONARY_WATER)
Block(-3,18,5,PRISMARINE)
Block(-3,19,-5,PRISMARINE:2)
Block(-3,19,-4,PRISMARINE)
Block(-3,19,-3,PRISMARINE:1)
Block(-3,19,-2,PRISMARINE:1)
Block(-3,19,-1,PRISMARINE:1)
Block(-3,19,0,PRISMARINE:2)
Block(-3,19,1,PRISMARINE:1)
Block(-3,19,2,PRISMARINE:1)
Block(-3,19,3,PRISMARINE:1)
Block(-3,19,4,PRISMARINE)
Block(-3,19,5,PRISMARINE:2)
Block(-3,20,-3,PRISMARINE:1)
Block(-3,20,-2,STATIONARY_WATER)
Block(-3,20,-1,PRISMARINE)
Block(-3,20,0,STATIONARY_WATER)
Block(-3,20,1,PRISMARINE)
Block(-3,20,2,STATIONARY_WATER)
Block(-3,20,3,PRISMARINE:1)
Block(-3,21,-3,PRISMARINE:1)
Block(-3,21,-2,STATIONARY_WATER)
Block(-3,21,-1,PRISMARINE)
Block(-3,21,0,STATIONARY_WATER)
Block(-3,21,1,PRISMARINE)
Block(-3,21,2,STATIONARY_WATER)
Block(-3,21,3,PRISMARINE:1)
Block(-3,22,-3,PRISMARINE:1)
Block(-3,22,-2,STATIONARY_WATER)
Block(-3,22,-1,PRISMARINE)
Block(-3,22,0,STATIONARY_WATER)
Block(-3,22,1,PRISMARINE)
Block(-3,22,2,STATIONARY_WATER)
Block(-3,22,3,PRISMARINE:1)
Block(-3,23,-3,PRISMARINE:1)
Block(-3,23,-2,PRISMARINE:1)
Block(-3,23,-1,PRISMARINE:1)
Block(-3,23,0,STATIONARY_WATER)
Block(-3,23,1,PRISMARINE:1)
Block(-3,23,2,PRISMARINE:1)
Block(-3,23,3,PRISMARINE:1)
Block(-3,24,-1,PRISMARINE:1)
Block(-3,24,0,PRISMARINE:1)
Block(-3,24,1,PRISMARINE:1)
Block(-2,-3,-7,PRISMARINE)
Block(-2,-3,-6,PRISMARINE)
Block(-2,-3,-5,PRISMARINE)
Block(-2,-3,-4,PRISMARINE)
Block(-2,-3,-3,PRISMARINE:1)
Block(-2,-3,-2,PRISMARINE:1)
Block(-2,-3,-1,PRISMARINE:1)
Block(-2,-3,0,PRISMARINE)
Block(-2,-3,1,PRISMARINE:1)
Block(-2,-3,2,PRISMARINE:1)
Block(-2,-3,3,PRISMARINE:1)
Block(-2,-3,4,PRISMARINE)
Block(-2,-3,5,PRISMARINE)
Block(-2,-3,6,PRISMARINE)
Block(-2,-3,7,PRISMARINE)
Block(-2,-2,-7,PRISMARINE)
Block(-2,-2,-6,PRISMARINE)
Block(-2,-2,-5,PRISMARINE)
Block(-2,-2,-4,PRISMARINE)
Block(-2,-2,-3,PRISMARINE:1)
Block(-2,-2,-2,PRISMARINE:1)
Block(-2,-2,-1,PRISMARINE:1)
Block(-2,-2,0,PRISMARINE)
Block(-2,-2,1,PRISMARINE:1)
Block(-2,-2,2,PRISMARINE:1)
Block(-2,-2,3,PRISMARINE:1)
Block(-2,-2,4,PRISMARINE)
Block(-2,-2,5,PRISMARINE)
Block(-2,-2,6,PRISMARINE)
Block(-2,-2,7,PRISMARINE)
Block(-2,-1,-7,PRISMARINE)
Block(-2,-1,-6,STATIONARY_WATER)
Block(-2,-1,-5,STATIONARY_WATER)
Block(-2,-1,-4,STATIONARY_WATER)
Block(-2,-1,-3,STATIONARY_WATER)
Block(-2,-1,-2,STATIONARY_WATER)
Block(-2,-1,-1,STATIONARY_WATER)
Block(-2,-1,0,STATIONARY_WATER)
Block(-2,-1,1,STATIONARY_WATER)
Block(-2,-1,2,STATIONARY_WATER)
Block(-2,-1,3,STATIONARY_WATER)
Block(-2,-1,4,STATIONARY_WATER)
Block(-2,-1,5,STATIONARY_WATER)
Block(-2,-1,6,STATIONARY_WATER)
Block(-2,-1,7,PRISMARINE)
Block(-2,0,-7,PRISMARINE)
Block(-2,0,-6,STATIONARY_WATER)
Block(-2,0,-5,STATIONARY_WATER)
Block(-2,0,-4,STATIONARY_WATER)
Block(-2,0,-3,STATIONARY_WATER)
Block(-2,0,-2,STATIONARY_WATER)
Block(-2,0,-1,STATIONARY_WATER)
Block(-2,0,0,STATIONARY_WATER)
Block(-2,0,1,STATIONARY_WATER)
Block(-2,0,2,STATIONARY_WATER)
Block(-2,0,3,STATIONARY_WATER)
Block(-2,0,4,STATIONARY_WATER)
Block(-2,0,5,STATIONARY_WATER)
Block(-2,0,6,STATIONARY_WATER)
Block(-2,0,7,PRISMARINE)
Block(-2,1,-7,PRISMARINE)
Block(-2,1,-6,STATIONARY_WATER)
Block(-2,1,-5,STATIONARY_WATER)
Block(-2,1,-4,STATIONARY_WATER)
Block(-2,1,-3,STATIONARY_WATER)
Block(-2,1,-2,STATIONARY_WATER)
Block(-2,1,-1,STATIONARY_WATER)
Block(-2,1,0,STATIONARY_WATER)
Block(-2,1,1,STATIONARY_WATER)
Block(-2,1,2,STATIONARY_WATER)
Block(-2,1,3,STATIONARY_WATER)
Block(-2,1,4,STATIONARY_WATER)
Block(-2,1,5,STATIONARY_WATER)
Block(-2,1,6,STATIONARY_WATER)
Block(-2,1,7,PRISMARINE)
Block(-2,2,-7,PRISMARINE)
Block(-2,2,-6,PRISMARINE:1)
Block(-2,2,-5,STATIONARY_WATER)
Block(-2,2,-4,STATIONARY_WATER)
Block(-2,2,-3,STATIONARY_WATER)
Block(-2,2,-2,STATIONARY_WATER)
Block(-2,2,-1,STATIONARY_WATER)
Block(-2,2,0,STATIONARY_WATER)
Block(-2,2,1,STATIONARY_WATER)
Block(-2,2,2,STATIONARY_WATER)
Block(-2,2,3,STATIONARY_WATER)
Block(-2,2,4,STATIONARY_WATER)
Block(-2,2,5,STATIONARY_WATER)
Block(-2,2,6,PRISMARINE:1)
Block(-2,2,7,PRISMARINE)
Block(-2,3,-7,PRISMARINE)
Block(-2,3,-6,PRISMARINE:1)
Block(-2,3,-5,STATIONARY_WATER)
Block(-2,3,-4,STATIONARY_WATER)
Block(-2,3,-3,STATIONARY_WATER)
Block(-2,3,-2,STATIONARY_WATER)
Block(-2,3,-1,STATIONARY_WATER)
Block(-2,3,0,STATIONARY_WATER)
Block(-2,3,1,STATIONARY_WATER)
Block(-2,3,2,STATIONARY_WATER)
Block(-2,3,3,STATIONARY_WATER)
Block(-2,3,4,STATIONARY_WATER)
Block(-2,3,5,STATIONARY_WATER)
Block(-2,3,6,PRISMARINE:1)
Block(-2,3,7,PRISMARINE)
Block(-2,4,-7,PRISMARINE)
Block(-2,4,-6,PRISMARINE)
Block(-2,4,-5,STATIONARY_WATER)
Block(-2,4,-4,STATIONARY_WATER)
Block(-2,4,-3,STATIONARY_WATER)
Block(-2,4,-2,STATIONARY_WATER)
Block(-2,4,-1,STATIONARY_WATER)
Block(-2,4,0,STATIONARY_WATER)
Block(-2,4,1,STATIONARY_WATER)
Block(-2,4,2,STATIONARY_WATER)
Block(-2,4,3,STATIONARY_WATER)
Block(-2,4,4,STATIONARY_WATER)
Block(-2,4,5,STATIONARY_WATER)
Block(-2,4,6,PRISMARINE)
Block(-2,4,7,PRISMARINE)
Block(-2,5,-7,PRISMARINE)
Block(-2,5,-6,PRISMARINE:1)
Block(-2,5,-5,STATIONARY_WATER)
Block(-2,5,-4,STATIONARY_WATER)
Block(-2,5,-3,STATIONARY_WATER)
Block(-2,5,-2,STATIONARY_WATER)
Block(-2,5,-1,STATIONARY_WATER)
Block(-2,5,0,STATIONARY_WATER)
Block(-2,5,1,STATIONARY_WATER)
Block(-2,5,2,STATIONARY_WATER)
Block(-2,5,3,STATIONARY_WATER)
Block(-2,5,4,STATIONARY_WATER)
Block(-2,5,5,STATIONARY_WATER)
Block(-2,5,6,PRISMARINE:1)
Block(-2,5,7,PRISMARINE)
Block(-2,6,-7,PRISMARINE)
Block(-2,6,-6,PRISMARINE)
Block(-2,6,-5,STATIONARY_WATER)
Block(-2,6,-4,STATIONARY_WATER)
Block(-2,6,-3,STATIONARY_WATER)
Block(-2,6,-2,STATIONARY_WATER)
Block(-2,6,-1,STATIONARY_WATER)
Block(-2,6,0,STATIONARY_WATER)
Block(-2,6,1,STATIONARY_WATER)
Block(-2,6,2,STATIONARY_WATER)
Block(-2,6,3,STATIONARY_WATER)
Block(-2,6,4,STATIONARY_WATER)
Block(-2,6,5,STATIONARY_WATER)
Block(-2,6,6,PRISMARINE)
Block(-2,6,7,PRISMARINE)
Block(-2,7,-7,PRISMARINE)
Block(-2,7,-6,PRISMARINE)
Block(-2,7,-5,STATIONARY_WATER)
Block(-2,7,-4,STATIONARY_WATER)
Block(-2,7,-3,STATIONARY_WATER)
Block(-2,7,-2,STATIONARY_WATER)
Block(-2,7,-1,STATIONARY_WATER)
Block(-2,7,0,STATIONARY_WATER)
Block(-2,7,1,STATIONARY_WATER)
Block(-2,7,2,STATIONARY_WATER)
Block(-2,7,3,STATIONARY_WATER)
Block(-2,7,4,STATIONARY_WATER)
Block(-2,7,5,STATIONARY_WATER)
Block(-2,7,6,PRISMARINE)
Block(-2,7,7,PRISMARINE)
Block(-2,8,-7,PRISMARINE)
Block(-2,8,-6,PRISMARINE)
Block(-2,8,-5,STATIONARY_WATER)
Block(-2,8,-4,STATIONARY_WATER)
Block(-2,8,-3,STATIONARY_WATER)
Block(-2,8,-2,STATIONARY_WATER)
Block(-2,8,-1,STATIONARY_WATER)
Block(-2,8,0,STATIONARY_WATER)
Block(-2,8,1,STATIONARY_WATER)
Block(-2,8,2,STATIONARY_WATER)
Block(-2,8,3,STATIONARY_WATER)
Block(-2,8,4,STATIONARY_WATER)
Block(-2,8,5,STATIONARY_WATER)
Block(-2,8,6,PRISMARINE)
Block(-2,8,7,PRISMARINE)
Block(-2,9,-8,PRISMARINE:1)
Block(-2,9,-7,PRISMARINE:1)
Block(-2,9,-6,PRISMARINE:1)
Block(-2,9,-5,STATIONARY_WATER)
Block(-2,9,-4,PRISMARINE:1)
Block(-2,9,-3,STATIONARY_WATER)
Block(-2,9,-2,PRISMARINE:1)
Block(-2,9,-1,STATIONARY_WATER)
Block(-2,9,0,PRISMARINE:1)
Block(-2,9,1,STATIONARY_WATER)
Block(-2,9,2,PRISMARINE:1)
Block(-2,9,3,STATIONARY_WATER)
Block(-2,9,4,PRISMARINE:1)
Block(-2,9,5,STATIONARY_WATER)
Block(-2,9,6,PRISMARINE:1)
Block(-2,9,7,PRISMARINE:1)
Block(-2,9,8,PRISMARINE:1)
Block(-2,10,-7,PRISMARINE)
Block(-2,10,-6,PRISMARINE:2)
Block(-2,10,-5,STATIONARY_WATER)
Block(-2,10,-4,STATIONARY_WATER)
Block(-2,10,-3,STATIONARY_WATER)
Block(-2,10,-2,STATIONARY_WATER)
Block(-2,10,-1,STATIONARY_WATER)
Block(-2,10,0,STATIONARY_WATER)
Block(-2,10,1,STATIONARY_WATER)
Block(-2,10,2,STATIONARY_WATER)
Block(-2,10,3,STATIONARY_WATER)
Block(-2,10,4,STATIONARY_WATER)
Block(-2,10,5,STATIONARY_WATER)
Block(-2,10,6,PRISMARINE:2)
Block(-2,10,7,PRISMARINE)
Block(-2,11,-7,PRISMARINE:2)
Block(-2,11,-6,PRISMARINE:1)
Block(-2,11,-5,STATIONARY_WATER)
Block(-2,11,-4,STATIONARY_WATER)
Block(-2,11,-3,STATIONARY_WATER)
Block(-2,11,-2,STATIONARY_WATER)
Block(-2,11,-1,STATIONARY_WATER)
Block(-2,11,0,STATIONARY_WATER)
Block(-2,11,1,STATIONARY_WATER)
Block(-2,11,2,STATIONARY_WATER)
Block(-2,11,3,STATIONARY_WATER)
Block(-2,11,4,STATIONARY_WATER)
Block(-2,11,5,STATIONARY_WATER)
Block(-2,11,6,PRISMARINE:1)
Block(-2,11,7,PRISMARINE:2)
Block(-2,12,-5,STATIONARY_WATER)
Block(-2,12,-4,STATIONARY_WATER)
Block(-2,12,-3,STATIONARY_WATER)
Block(-2,12,-2,STATIONARY_WATER)
Block(-2,12,-1,STATIONARY_WATER)
Block(-2,12,0,STATIONARY_WATER)
Block(-2,12,1,STATIONARY_WATER)
Block(-2,12,2,STATIONARY_WATER)
Block(-2,12,3,STATIONARY_WATER)
Block(-2,12,4,STATIONARY_WATER)
Block(-2,12,5,STATIONARY_WATER)
Block(-2,13,-5,STATIONARY_WATER)
Block(-2,13,-4,STATIONARY_WATER)
Block(-2,13,-3,STATIONARY_WATER)
Block(-2,13,-2,STATIONARY_WATER)
Block(-2,13,-1,STATIONARY_WATER)
Block(-2,13,0,STATIONARY_WATER)
Block(-2,13,1,STATIONARY_WATER)
Block(-2,13,2,STATIONARY_WATER)
Block(-2,13,3,STATIONARY_WATER)
Block(-2,13,4,STATIONARY_WATER)
Block(-2,13,5,STATIONARY_WATER)
Block(-2,14,-5,STATIONARY_WATER)
Block(-2,14,-4,STATIONARY_WATER)
Block(-2,14,-3,STATIONARY_WATER)
Block(-2,14,-2,STATIONARY_WATER)
Block(-2,14,-1,STATIONARY_WATER)
Block(-2,14,0,STATIONARY_WATER)
Block(-2,14,1,STATIONARY_WATER)
Block(-2,14,2,STATIONARY_WATER)
Block(-2,14,3,STATIONARY_WATER)
Block(-2,14,4,STATIONARY_WATER)
Block(-2,14,5,STATIONARY_WATER)
Block(-2,15,-5,STATIONARY_WATER)
Block(-2,15,-4,STATIONARY_WATER)
Block(-2,15,-3,STATIONARY_WATER)
Block(-2,15,-2,STATIONARY_WATER)
Block(-2,15,-1,STATIONARY_WATER)
Block(-2,15,0,STATIONARY_WATER)
Block(-2,15,1,STATIONARY_WATER)
Block(-2,15,2,STATIONARY_WATER)
Block(-2,15,3,STATIONARY_WATER)
Block(-2,15,4,STATIONARY_WATER)
Block(-2,15,5,STATIONARY_WATER)
Block(-2,16,-5,STATIONARY_WATER)
Block(-2,16,-4,STATIONARY_WATER)
Block(-2,16,-3,STATIONARY_WATER)
Block(-2,16,-2,STATIONARY_WATER)
Block(-2,16,-1,STATIONARY_WATER)
Block(-2,16,0,STATIONARY_WATER)
Block(-2,16,1,STATIONARY_WATER)
Block(-2,16,2,STATIONARY_WATER)
Block(-2,16,3,STATIONARY_WATER)
Block(-2,16,4,STATIONARY_WATER)
Block(-2,16,5,STATIONARY_WATER)
Block(-2,17,-6,PRISMARINE:1)
Block(-2,17,-5,STATIONARY_WATER)
Block(-2,17,-4,STATIONARY_WATER)
Block(-2,17,-3,STATIONARY_WATER)
Block(-2,17,-2,STATIONARY_WATER)
Block(-2,17,-1,STATIONARY_WATER)
Block(-2,17,0,STATIONARY_WATER)
Block(-2,17,1,STATIONARY_WATER)
Block(-2,17,2,STATIONARY_WATER)
Block(-2,17,3,STATIONARY_WATER)
Block(-2,17,4,STATIONARY_WATER)
Block(-2,17,5,STATIONARY_WATER)
Block(-2,17,6,PRISMARINE:1)
Block(-2,18,-5,PRISMARINE)
Block(-2,18,-4,STATIONARY_WATER)
Block(-2,18,-3,STATIONARY_WATER)
Block(-2,18,-2,STATIONARY_WATER)
Block(-2,18,-1,STATIONARY_WATER)
Block(-2,18,0,STATIONARY_WATER)
Block(-2,18,1,STATIONARY_WATER)
Block(-2,18,2,STATIONARY_WATER)
Block(-2,18,3,STATIONARY_WATER)
Block(-2,18,4,STATIONARY_WATER)
Block(-2,18,5,PRISMARINE)
Block(-2,19,-5,PRISMARINE:2)
Block(-2,19,-4,PRISMARINE)
Block(-2,19,-3,PRISMARINE:1)
Block(-2,19,-2,PRISMARINE:1)
Block(-2,19,-1,PRISMARINE:1)
Block(-2,19,0,PRISMARINE:1)
Block(-2,19,1,PRISMARINE:1)
Block(-2,19,2,PRISMARINE:1)
Block(-2,19,3,PRISMARINE:1)
Block(-2,19,4,PRISMARINE)
Block(-2,19,5,PRISMARINE:2)
Block(-2,20,-3,STATIONARY_WATER)
Block(-2,20,-2,STATIONARY_WATER)
Block(-2,20,-1,STATIONARY_WATER)
Block(-2,20,0,STATIONARY_WATER)
Block(-2,20,1,STATIONARY_WATER)
Block(-2,20,2,STATIONARY_WATER)
Block(-2,21,-3,STATIONARY_WATER)
Block(-2,21,-2,STATIONARY_WATER)
Block(-2,21,-1,STATIONARY_WATER)
Block(-2,21,0,STATIONARY_WATER)
Block(-2,21,1,STATIONARY_WATER)
Block(-2,21,2,STATIONARY_WATER)
Block(-2,22,-3,STATIONARY_WATER)
Block(-2,22,-2,STATIONARY_WATER)
Block(-2,22,-1,STATIONARY_WATER)
Block(-2,22,0,STATIONARY_WATER)
Block(-2,22,1,STATIONARY_WATER)
Block(-2,22,2,STATIONARY_WATER)
Block(-2,23,-3,PRISMARINE:1)
Block(-2,23,-2,STATIONARY_WATER)
Block(-2,23,-1,STATIONARY_WATER)
Block(-2,23,0,STATIONARY_WATER)
Block(-2,23,1,STATIONARY_WATER)
Block(-2,23,2,STATIONARY_WATER)
Block(-2,23,3,PRISMARINE:1)
Block(-2,24,-2,PRISMARINE:2)
Block(-2,24,-1,PRISMARINE:2)
Block(-2,24,0,PRISMARINE:2)
Block(-2,24,1,PRISMARINE:2)
Block(-2,24,2,PRISMARINE:2)
Block(-1,-3,-8,PRISMARINE)
Block(-1,-3,-7,PRISMARINE:1)
Block(-1,-3,-6,PRISMARINE)
Block(-1,-3,-5,PRISMARINE)
Block(-1,-3,-4,PRISMARINE)
Block(-1,-3,-3,PRISMARINE)
Block(-1,-3,-2,PRISMARINE:1)
Block(-1,-3,-1,PRISMARINE)
Block(-1,-3,0,PRISMARINE)
Block(-1,-3,1,PRISMARINE)
Block(-1,-3,2,PRISMARINE:1)
Block(-1,-3,3,PRISMARINE)
Block(-1,-3,4,PRISMARINE)
Block(-1,-3,5,PRISMARINE)
Block(-1,-3,6,PRISMARINE)
Block(-1,-3,7,PRISMARINE:1)
Block(-1,-3,8,PRISMARINE)
Block(-1,-2,-8,PRISMARINE)
Block(-1,-2,-7,PRISMARINE:1)
Block(-1,-2,-6,PRISMARINE)
Block(-1,-2,-5,PRISMARINE)
Block(-1,-2,-4,PRISMARINE)
Block(-1,-2,-3,PRISMARINE)
Block(-1,-2,-2,PRISMARINE:1)
Block(-1,-2,-1,PRISMARINE)
Block(-1,-2,0,PRISMARINE)
Block(-1,-2,1,PRISMARINE)
Block(-1,-2,2,PRISMARINE:1)
Block(-1,-2,3,PRISMARINE)
Block(-1,-2,4,PRISMARINE)
Block(-1,-2,5,PRISMARINE)
Block(-1,-2,6,PRISMARINE)
Block(-1,-2,7,PRISMARINE:1)
Block(-1,-2,8,PRISMARINE)
Block(-1,-1,-8,PRISMARINE)
Block(-1,-1,-7,PRISMARINE:1)
Block(-1,-1,-6,STATIONARY_WATER)
Block(-1,-1,-5,STATIONARY_WATER)
Block(-1,-1,-4,STATIONARY_WATER)
Block(-1,-1,-3,STATIONARY_WATER)
Block(-1,-1,-2,STATIONARY_WATER)
Block(-1,-1,-1,PRISMARINE:1)
Block(-1,-1,0,PRISMARINE:1)
Block(-1,-1,1,PRISMARINE:1)
Block(-1,-1,2,STATIONARY_WATER)
Block(-1,-1,3,STATIONARY_WATER)
Block(-1,-1,4,STATIONARY_WATER)
Block(-1,-1,5,STATIONARY_WATER)
Block(-1,-1,6,STATIONARY_WATER)
Block(-1,-1,7,STATIONARY_WATER)
Block(-1,-1,8,PRISMARINE)
Block(-1,0,-8,PRISMARINE)
Block(-1,0,-7,STATIONARY_WATER)
Block(-1,0,-6,STATIONARY_WATER)
Block(-1,0,-5,STATIONARY_WATER)
Block(-1,0,-4,STATIONARY_WATER)
Block(-1,0,-3,STATIONARY_WATER)
Block(-1,0,-2,STATIONARY_WATER)
Block(-1,0,-1,PRISMARINE:1)
Block(-1,0,0,STATIONARY_WATER)
Block(-1,0,1,PRISMARINE:1)
Block(-1,0,2,STATIONARY_WATER)
Block(-1,0,3,STATIONARY_WATER)
Block(-1,0,4,STATIONARY_WATER)
Block(-1,0,5,STATIONARY_WATER)
Block(-1,0,6,STATIONARY_WATER)
Block(-1,0,7,STATIONARY_WATER)
Block(-1,0,8,PRISMARINE)
Block(-1,1,-8,PRISMARINE)
Block(-1,1,-7,STATIONARY_WATER)
Block(-1,1,-6,STATIONARY_WATER)
Block(-1,1,-5,STATIONARY_WATER)
Block(-1,1,-4,STATIONARY_WATER)
Block(-1,1,-3,STATIONARY_WATER)
Block(-1,1,-2,STATIONARY_WATER)
Entity(-1,1,-2,Guardian,1,Guardian.txt)
Block(-1,1,-1,PRISMARINE:1)
Block(-1,1,0,PRISMARINE:1)
Block(-1,1,1,PRISMARINE:1)
Block(-1,1,2,STATIONARY_WATER)
Block(-1,1,3,STATIONARY_WATER)
Block(-1,1,4,STATIONARY_WATER)
Block(-1,1,5,STATIONARY_WATER)
Block(-1,1,6,STATIONARY_WATER)
Block(-1,1,7,STATIONARY_WATER)
Block(-1,1,8,PRISMARINE)
Block(-1,2,-8,PRISMARINE)
Block(-1,2,-7,STATIONARY_WATER)
Block(-1,2,-6,STATIONARY_WATER)
Block(-1,2,-5,STATIONARY_WATER)
Block(-1,2,-4,STATIONARY_WATER)
Block(-1,2,-3,STATIONARY_WATER)
Block(-1,2,-2,STATIONARY_WATER)
Block(-1,2,-1,PRISMARINE:2)
Block(-1,2,0,STATIONARY_WATER)
Block(-1,2,1,PRISMARINE:2)
Block(-1,2,2,STATIONARY_WATER)
Block(-1,2,3,STATIONARY_WATER)
Block(-1,2,4,STATIONARY_WATER)
Block(-1,2,5,STATIONARY_WATER)
Block(-1,2,6,STATIONARY_WATER)
Block(-1,2,7,STATIONARY_WATER)
Block(-1,2,8,PRISMARINE)
Block(-1,3,-8,PRISMARINE)
Block(-1,3,-7,PRISMARINE)
Block(-1,3,-6,PRISMARINE:1)
Block(-1,3,-5,STATIONARY_WATER)
Block(-1,3,-4,STATIONARY_WATER)
Block(-1,3,-3,STATIONARY_WATER)
Block(-1,3,-2,STATIONARY_WATER)
Block(-1,3,-1,PRISMARINE:2)
Block(-1,3,0,STATIONARY_WATER)
Block(-1,3,1,PRISMARINE:2)
Block(-1,3,2,STATIONARY_WATER)
Block(-1,3,3,STATIONARY_WATER)
Block(-1,3,4,STATIONARY_WATER)
Block(-1,3,5,STATIONARY_WATER)
Block(-1,3,6,PRISMARINE:1)
Block(-1,3,7,PRISMARINE)
Block(-1,3,8,PRISMARINE)
Block(-1,4,-8,PRISMARINE)
Block(-1,4,-7,PRISMARINE)
Block(-1,4,-6,PRISMARINE:1)
Block(-1,4,-5,STATIONARY_WATER)
Block(-1,4,-4,STATIONARY_WATER)
Block(-1,4,-3,STATIONARY_WATER)
Block(-1,4,-2,STATIONARY_WATER)
Block(-1,4,-1,PRISMARINE:2)
Block(-1,4,0,STATIONARY_WATER)
Block(-1,4,1,PRISMARINE:2)
Block(-1,4,2,STATIONARY_WATER)
Block(-1,4,3,STATIONARY_WATER)
Block(-1,4,4,STATIONARY_WATER)
Block(-1,4,5,STATIONARY_WATER)
Block(-1,4,6,PRISMARINE:1)
Block(-1,4,7,PRISMARINE)
Block(-1,4,8,PRISMARINE)
Block(-1,5,-8,PRISMARINE)
Block(-1,5,-7,PRISMARINE)
Block(-1,5,-6,PRISMARINE:1)
Block(-1,5,-5,STATIONARY_WATER)
Block(-1,5,-4,STATIONARY_WATER)
Block(-1,5,-3,STATIONARY_WATER)
Block(-1,5,-2,STATIONARY_WATER)
Block(-1,5,-1,PRISMARINE:2)
Block(-1,5,0,STATIONARY_WATER)
Block(-1,5,1,PRISMARINE:2)
Block(-1,5,2,STATIONARY_WATER)
Block(-1,5,3,STATIONARY_WATER)
Block(-1,5,4,STATIONARY_WATER)
Block(-1,5,5,STATIONARY_WATER)
Block(-1,5,6,PRISMARINE:1)
Block(-1,5,7,PRISMARINE)
Block(-1,5,8,PRISMARINE)
Block(-1,6,-8,PRISMARINE)
Block(-1,6,-7,PRISMARINE)
Block(-1,6,-6,STATIONARY_WATER)
Block(-1,6,-5,STATIONARY_WATER)
Block(-1,6,-4,STATIONARY_WATER)
Block(-1,6,-3,STATIONARY_WATER)
Block(-1,6,-2,STATIONARY_WATER)
Block(-1,6,-1,PRISMARINE:1)
Block(-1,6,0,PRISMARINE:1)
Block(-1,6,1,PRISMARINE:1)
Block(-1,6,2,STATIONARY_WATER)
Block(-1,6,3,STATIONARY_WATER)
Block(-1,6,4,STATIONARY_WATER)
Block(-1,6,5,STATIONARY_WATER)
Block(-1,6,6,STATIONARY_WATER)
Block(-1,6,7,PRISMARINE)
Block(-1,6,8,PRISMARINE)
Block(-1,7,-8,PRISMARINE)
Block(-1,7,-7,PRISMARINE)
Block(-1,7,-6,STATIONARY_WATER)
Block(-1,7,-5,STATIONARY_WATER)
Block(-1,7,-4,STATIONARY_WATER)
Block(-1,7,-3,STATIONARY_WATER)
Block(-1,7,-2,STATIONARY_WATER)
Block(-1,7,-1,PRISMARINE:1)
Block(-1,7,0,STATIONARY_WATER)
Block(-1,7,1,PRISMARINE:1)
Block(-1,7,2,STATIONARY_WATER)
Block(-1,7,3,STATIONARY_WATER)
Block(-1,7,4,STATIONARY_WATER)
Block(-1,7,5,STATIONARY_WATER)
Block(-1,7,6,STATIONARY_WATER)
Block(-1,7,7,PRISMARINE)
Block(-1,7,8,PRISMARINE)
Block(-1,8,-8,PRISMARINE)
Block(-1,8,-7,PRISMARINE)
Block(-1,8,-6,STATIONARY_WATER)
Block(-1,8,-5,STATIONARY_WATER)
Block(-1,8,-4,STATIONARY_WATER)
Block(-1,8,-3,STATIONARY_WATER)
Block(-1,8,-2,STATIONARY_WATER)
Block(-1,8,-1,PRISMARINE:1)
Block(-1,8,0,PRISMARINE:1)
Block(-1,8,1,PRISMARINE:1)
Block(-1,8,2,STATIONARY_WATER)
Block(-1,8,3,STATIONARY_WATER)
Block(-1,8,4,STATIONARY_WATER)
Block(-1,8,5,STATIONARY_WATER)
Block(-1,8,6,STATIONARY_WATER)
Block(-1,8,7,PRISMARINE)
Block(-1,8,8,PRISMARINE)
Block(-1,9,-8,PRISMARINE:1)
Block(-1,9,-7,PRISMARINE:1)
Block(-1,9,-6,PRISMARINE:1)
Block(-1,9,-5,PRISMARINE:1)
Block(-1,9,-4,PRISMARINE:1)
Block(-1,9,-3,PRISMARINE:1)
Block(-1,9,-2,PRISMARINE:1)
Block(-1,9,-1,PRISMARINE:1)
Block(-1,9,0,PRISMARINE:1)
Block(-1,9,1,PRISMARINE:1)
Block(-1,9,2,PRISMARINE:1)
Block(-1,9,3,PRISMARINE:1)
Block(-1,9,4,PRISMARINE:1)
Block(-1,9,5,PRISMARINE:1)
Block(-1,9,6,PRISMARINE:1)
Block(-1,9,7,PRISMARINE:1)
Block(-1,9,8,PRISMARINE:1)
Block(-1,10,-7,PRISMARINE)
Block(-1,10,-6,PRISMARINE:2)
Block(-1,10,-5,STATIONARY_WATER)
Block(-1,10,-4,STATIONARY_WATER)
Block(-1,10,-3,STATIONARY_WATER)
Block(-1,10,-2,STATIONARY_WATER)
Block(-1,10,-1,STATIONARY_WATER)
Block(-1,10,0,STATIONARY_WATER)
Block(-1,10,1,STATIONARY_WATER)
Entity(-1,10,1,Guardian,1,ElderGuardian.txt)
Block(-1,10,2,STATIONARY_WATER)
Block(-1,10,3,STATIONARY_WATER)
Block(-1,10,4,STATIONARY_WATER)
Block(-1,10,5,STATIONARY_WATER)
Block(-1,10,6,PRISMARINE:2)
Block(-1,10,7,PRISMARINE)
Block(-1,11,-7,PRISMARINE:2)
Block(-1,11,-6,PRISMARINE:1)
Block(-1,11,-5,STATIONARY_WATER)
Block(-1,11,-4,STATIONARY_WATER)
Block(-1,11,-3,STATIONARY_WATER)
Block(-1,11,-2,STATIONARY_WATER)
Block(-1,11,-1,STATIONARY_WATER)
Block(-1,11,0,STATIONARY_WATER)
Block(-1,11,1,STATIONARY_WATER)
Block(-1,11,2,STATIONARY_WATER)
Block(-1,11,3,STATIONARY_WATER)
Block(-1,11,4,STATIONARY_WATER)
Block(-1,11,5,STATIONARY_WATER)
Block(-1,11,6,PRISMARINE:1)
Block(-1,11,7,PRISMARINE:2)
Block(-1,12,-6,PRISMARINE)
Block(-1,12,-5,STATIONARY_WATER)
Block(-1,12,-4,STATIONARY_WATER)
Block(-1,12,-3,STATIONARY_WATER)
Block(-1,12,-2,STATIONARY_WATER)
Block(-1,12,-1,STATIONARY_WATER)
Block(-1,12,0,STATIONARY_WATER)
Block(-1,12,1,STATIONARY_WATER)
Block(-1,12,2,STATIONARY_WATER)
Block(-1,12,3,STATIONARY_WATER)
Block(-1,12,4,STATIONARY_WATER)
Block(-1,12,5,STATIONARY_WATER)
Block(-1,12,6,PRISMARINE)
Block(-1,13,-6,PRISMARINE)
Block(-1,13,-5,STATIONARY_WATER)
Block(-1,13,-4,STATIONARY_WATER)
Block(-1,13,-3,STATIONARY_WATER)
Block(-1,13,-2,STATIONARY_WATER)
Block(-1,13,-1,STATIONARY_WATER)
Block(-1,13,0,STATIONARY_WATER)
Block(-1,13,1,STATIONARY_WATER)
Block(-1,13,2,STATIONARY_WATER)
Block(-1,13,3,STATIONARY_WATER)
Block(-1,13,4,STATIONARY_WATER)
Block(-1,13,5,STATIONARY_WATER)
Block(-1,13,6,PRISMARINE)
Block(-1,14,-6,PRISMARINE)
Block(-1,14,-5,STATIONARY_WATER)
Block(-1,14,-4,STATIONARY_WATER)
Block(-1,14,-3,STATIONARY_WATER)
Block(-1,14,-2,STATIONARY_WATER)
Block(-1,14,-1,STATIONARY_WATER)
Block(-1,14,0,STATIONARY_WATER)
Block(-1,14,1,STATIONARY_WATER)
Block(-1,14,2,STATIONARY_WATER)
Block(-1,14,3,STATIONARY_WATER)
Block(-1,14,4,STATIONARY_WATER)
Block(-1,14,5,STATIONARY_WATER)
Block(-1,14,6,PRISMARINE)
Block(-1,15,-6,PRISMARINE)
Block(-1,15,-5,STATIONARY_WATER)
Block(-1,15,-4,STATIONARY_WATER)
Block(-1,15,-3,STATIONARY_WATER)
Block(-1,15,-2,STATIONARY_WATER)
Block(-1,15,-1,STATIONARY_WATER)
Block(-1,15,0,STATIONARY_WATER)
Block(-1,15,1,STATIONARY_WATER)
Block(-1,15,2,STATIONARY_WATER)
Block(-1,15,3,STATIONARY_WATER)
Block(-1,15,4,STATIONARY_WATER)
Block(-1,15,5,STATIONARY_WATER)
Block(-1,15,6,PRISMARINE)
Block(-1,16,-6,PRISMARINE)
Block(-1,16,-5,STATIONARY_WATER)
Block(-1,16,-4,STATIONARY_WATER)
Block(-1,16,-3,STATIONARY_WATER)
Block(-1,16,-2,STATIONARY_WATER)
Block(-1,16,-1,STATIONARY_WATER)
Block(-1,16,0,STATIONARY_WATER)
Block(-1,16,1,STATIONARY_WATER)
Block(-1,16,2,STATIONARY_WATER)
Block(-1,16,3,STATIONARY_WATER)
Block(-1,16,4,STATIONARY_WATER)
Block(-1,16,5,STATIONARY_WATER)
Block(-1,16,6,PRISMARINE)
Block(-1,17,-6,PRISMARINE:1)
Block(-1,17,-5,STATIONARY_WATER)
Block(-1,17,-4,STATIONARY_WATER)
Block(-1,17,-3,STATIONARY_WATER)
Block(-1,17,-2,STATIONARY_WATER)
Block(-1,17,-1,STATIONARY_WATER)
Block(-1,17,0,STATIONARY_WATER)
Block(-1,17,1,STATIONARY_WATER)
Block(-1,17,2,STATIONARY_WATER)
Block(-1,17,3,STATIONARY_WATER)
Block(-1,17,4,STATIONARY_WATER)
Block(-1,17,5,STATIONARY_WATER)
Block(-1,17,6,PRISMARINE:1)
Block(-1,18,-6,PRISMARINE:1)
Block(-1,18,-5,PRISMARINE)
Block(-1,18,-4,STATIONARY_WATER)
Block(-1,18,-3,STATIONARY_WATER)
Block(-1,18,-2,STATIONARY_WATER)
Block(-1,18,-1,STATIONARY_WATER)
Block(-1,18,0,STATIONARY_WATER)
Block(-1,18,1,STATIONARY_WATER)
Block(-1,18,2,STATIONARY_WATER)
Block(-1,18,3,STATIONARY_WATER)
Block(-1,18,4,STATIONARY_WATER)
Block(-1,18,5,PRISMARINE)
Block(-1,18,6,PRISMARINE:1)
Block(-1,19,-5,PRISMARINE:2)
Block(-1,19,-4,PRISMARINE)
Block(-1,19,-3,PRISMARINE:1)
Block(-1,19,-2,PRISMARINE:1)
Block(-1,19,-1,STATIONARY_WATER)
Block(-1,19,0,STATIONARY_WATER)
Block(-1,19,1,STATIONARY_WATER)
Block(-1,19,2,PRISMARINE:1)
Block(-1,19,3,PRISMARINE:1)
Block(-1,19,4,PRISMARINE)
Block(-1,19,5,PRISMARINE:2)
Block(-1,20,-3,PRISMARINE)
Block(-1,20,-2,STATIONARY_WATER)
Block(-1,20,-1,STATIONARY_WATER)
Block(-1,20,0,STATIONARY_WATER)
Block(-1,20,1,STATIONARY_WATER)
Block(-1,20,2,STATIONARY_WATER)
Block(-1,20,3,PRISMARINE)
Block(-1,21,-3,PRISMARINE)
Block(-1,21,-2,STATIONARY_WATER)
Block(-1,21,-1,STATIONARY_WATER)
Block(-1,21,0,STATIONARY_WATER)
Block(-1,21,1,STATIONARY_WATER)
Block(-1,21,2,STATIONARY_WATER)
Entity(-1,21,2,Guardian,1,Guardian.txt)
Block(-1,21,3,PRISMARINE)
Block(-1,22,-3,PRISMARINE)
Block(-1,22,-2,STATIONARY_WATER)
Block(-1,22,-1,STATIONARY_WATER)
Block(-1,22,0,STATIONARY_WATER)
Block(-1,22,1,STATIONARY_WATER)
Block(-1,22,2,STATIONARY_WATER)
Block(-1,22,3,PRISMARINE)
Block(-1,23,-3,PRISMARINE:1)
Block(-1,23,-2,STATIONARY_WATER)
Block(-1,23,-1,STATIONARY_WATER)
Block(-1,23,0,STATIONARY_WATER)
Block(-1,23,1,STATIONARY_WATER)
Block(-1,23,2,STATIONARY_WATER)
Block(-1,23,3,PRISMARINE:1)
Block(-1,24,-3,PRISMARINE:1)
Block(-1,24,-2,PRISMARINE:2)
Block(-1,24,-1,STATIONARY_WATER)
Block(-1,24,0,STATIONARY_WATER)
Block(-1,24,1,STATIONARY_WATER)
Block(-1,24,2,PRISMARINE:2)
Block(-1,24,3,PRISMARINE:1)
Block(-1,25,-1,PRISMARINE)
Block(-1,25,0,PRISMARINE)
Block(-1,25,1,PRISMARINE)
Block(-1,26,-1,PRISMARINE:1)
Block(-1,26,1,PRISMARINE:1)
Block(-1,27,-1,PRISMARINE)
Block(-1,27,0,PRISMARINE)
Block(-1,27,1,PRISMARINE)
Block(0,-3,-7,PRISMARINE)
Block(0,-3,-6,PRISMARINE)
Block(0,-3,-5,PRISMARINE)
Block(0,-3,-4,PRISMARINE)
Block(0,-3,-3,PRISMARINE)
Block(0,-3,-2,PRISMARINE)
Block(0,-3,-1,PRISMARINE)
Block(0,-3,0,PRISMARINE)
Block(0,-3,1,PRISMARINE)
Block(0,-3,2,PRISMARINE)
Block(0,-3,3,PRISMARINE)
Block(0,-3,4,PRISMARINE)
Block(0,-3,5,PRISMARINE)
Block(0,-3,6,PRISMARINE)
Block(0,-3,7,PRISMARINE)
Block(0,-2,-7,PRISMARINE)
Block(0,-2,-6,PRISMARINE)
Block(0,-2,-5,PRISMARINE)
Block(0,-2,-4,PRISMARINE)
Block(0,-2,-3,PRISMARINE)
Block(0,-2,-2,PRISMARINE)
Block(0,-2,-1,PRISMARINE)
Block(0,-2,0,PRISMARINE)
Block(0,-2,1,PRISMARINE)
Block(0,-2,2,PRISMARINE)
Block(0,-2,3,PRISMARINE)
Block(0,-2,4,PRISMARINE)
Block(0,-2,5,PRISMARINE)
Block(0,-2,6,PRISMARINE)
Block(0,-2,7,PRISMARINE)
Block(0,-1,-7,PRISMARINE)
Block(0,-1,-6,PRISMARINE:1)
Block(0,-1,-5,STATIONARY_WATER)
Block(0,-1,-4,STATIONARY_WATER)
Block(0,-1,-3,STATIONARY_WATER)
Block(0,-1,-2,STATIONARY_WATER)
Block(0,-1,-1,PRISMARINE:1)
Block(0,-1,0,PRISMARINE)
Block(0,-1,1,PRISMARINE:1)
Block(0,-1,2,STATIONARY_WATER)
Block(0,-1,3,STATIONARY_WATER)
Block(0,-1,4,STATIONARY_WATER)
Block(0,-1,5,STATIONARY_WATER)
Block(0,-1,6,PRISMARINE:1)
Block(0,-1,7,PRISMARINE)
Block(0,0,-7,PRISMARINE)
Block(0,0,-6,GOLD_BLOCK)
Block(0,0,-5,STATIONARY_WATER)
Block(0,0,-4,STATIONARY_WATER)
Block(0,0,-3,STATIONARY_WATER)
Block(0,0,-2,STATIONARY_WATER)
Block(0,0,-1,STATIONARY_WATER)
Block(0,0,0,SEA_LANTERN)
Block(0,0,1,STATIONARY_WATER)
Block(0,0,2,STATIONARY_WATER)
Block(0,0,3,STATIONARY_WATER)
Block(0,0,4,STATIONARY_WATER)
Block(0,0,5,STATIONARY_WATER)
Block(0,0,6,GOLD_BLOCK)
Block(0,0,7,PRISMARINE)
Block(0,1,-7,PRISMARINE)
Block(0,1,-6,STATIONARY_WATER)
Block(0,1,-5,STATIONARY_WATER)
Block(0,1,-4,STATIONARY_WATER)
Block(0,1,-3,STATIONARY_WATER)
Block(0,1,-2,STATIONARY_WATER)
Block(0,1,-1,PRISMARINE:1)
Block(0,1,0,PRISMARINE:2)
Block(0,1,1,PRISMARINE:1)
Block(0,1,2,STATIONARY_WATER)
Block(0,1,3,STATIONARY_WATER)
Block(0,1,4,STATIONARY_WATER)
Block(0,1,5,STATIONARY_WATER)
Block(0,1,6,STATIONARY_WATER)
Block(0,1,7,PRISMARINE)
Block(0,2,-7,PRISMARINE)
Block(0,2,-6,STATIONARY_WATER)
Block(0,2,-5,STATIONARY_WATER)
Block(0,2,-4,STATIONARY_WATER)
Block(0,2,-3,STATIONARY_WATER)
Block(0,2,-2,STATIONARY_WATER)
Block(0,2,-1,STATIONARY_WATER)
Block(0,2,0,PRISMARINE:2)
Block(0,2,1,STATIONARY_WATER)
Block(0,2,2,STATIONARY_WATER)
Block(0,2,3,STATIONARY_WATER)
Block(0,2,4,STATIONARY_WATER)
Block(0,2,5,STATIONARY_WATER)
Block(0,2,6,STATIONARY_WATER)
Block(0,2,7,PRISMARINE)
Block(0,3,-7,PRISMARINE)
Block(0,3,-6,PRISMARINE:1)
Block(0,3,-5,STATIONARY_WATER)
Block(0,3,-4,STATIONARY_WATER)
Block(0,3,-3,STATIONARY_WATER)
Block(0,3,-2,STATIONARY_WATER)
Block(0,3,-1,STATIONARY_WATER)
Block(0,3,0,PRISMARINE:2)
Block(0,3,1,STATIONARY_WATER)
Block(0,3,2,STATIONARY_WATER)
Block(0,3,3,STATIONARY_WATER)
Block(0,3,4,STATIONARY_WATER)
Block(0,3,5,STATIONARY_WATER)
Block(0,3,6,PRISMARINE:1)
Block(0,3,7,PRISMARINE)
Block(0,4,-7,PRISMARINE)
Block(0,4,-6,SEA_LANTERN)
Block(0,4,-5,STATIONARY_WATER)
Block(0,4,-4,STATIONARY_WATER)
Block(0,4,-3,STATIONARY_WATER)
Block(0,4,-2,STATIONARY_WATER)
Block(0,4,-1,STATIONARY_WATER)
Block(0,4,0,PRISMARINE:2)
Block(0,4,1,STATIONARY_WATER)
Block(0,4,2,STATIONARY_WATER)
Block(0,4,3,STATIONARY_WATER)
Block(0,4,4,STATIONARY_WATER)
Block(0,4,5,STATIONARY_WATER)
Block(0,4,6,SEA_LANTERN)
Block(0,4,7,PRISMARINE)
Block(0,5,-7,PRISMARINE)
Block(0,5,-6,PRISMARINE:1)
Block(0,5,-5,STATIONARY_WATER)
Block(0,5,-4,STATIONARY_WATER)
Block(0,5,-3,STATIONARY_WATER)
Block(0,5,-2,STATIONARY_WATER)
Block(0,5,-1,STATIONARY_WATER)
Block(0,5,0,PRISMARINE:2)
Block(0,5,1,STATIONARY_WATER)
Block(0,5,2,STATIONARY_WATER)
Block(0,5,3,STATIONARY_WATER)
Block(0,5,4,STATIONARY_WATER)
Block(0,5,5,STATIONARY_WATER)
Block(0,5,6,PRISMARINE:1)
Block(0,5,7,PRISMARINE)
Block(0,6,-7,PRISMARINE)
Block(0,6,-6,PRISMARINE)
Block(0,6,-5,STATIONARY_WATER)
Block(0,6,-4,STATIONARY_WATER)
Block(0,6,-3,STATIONARY_WATER)
Block(0,6,-2,STATIONARY_WATER)
Block(0,6,-1,PRISMARINE:1)
Block(0,6,0,PRISMARINE:2)
Block(0,6,1,PRISMARINE:1)
Block(0,6,2,STATIONARY_WATER)
Block(0,6,3,STATIONARY_WATER)
Block(0,6,4,STATIONARY_WATER)
Block(0,6,5,STATIONARY_WATER)
Block(0,6,6,PRISMARINE)
Block(0,6,7,PRISMARINE)
Block(0,7,-7,PRISMARINE)
Block(0,7,-6,PRISMARINE)
Block(0,7,-5,STATIONARY_WATER)
Block(0,7,-4,STATIONARY_WATER)
Block(0,7,-3,STATIONARY_WATER)
Block(0,7,-2,STATIONARY_WATER)
Block(0,7,-1,STATIONARY_WATER)
Block(0,7,0,SEA_LANTERN)
Block(0,7,1,STATIONARY_WATER)
Block(0,7,2,STATIONARY_WATER)
Block(0,7,3,STATIONARY_WATER)
Block(0,7,4,STATIONARY_WATER)
Block(0,7,5,STATIONARY_WATER)
Block(0,7,6,PRISMARINE)
Block(0,7,7,PRISMARINE)
Block(0,8,-7,PRISMARINE)
Block(0,8,-6,PRISMARINE)
Block(0,8,-5,STATIONARY_WATER)
Block(0,8,-4,STATIONARY_WATER)
Block(0,8,-3,STATIONARY_WATER)
Block(0,8,-2,STATIONARY_WATER)
Block(0,8,-1,PRISMARINE:1)
Block(0,8,0,PRISMARINE:1)
Block(0,8,1,PRISMARINE:1)
Block(0,8,2,STATIONARY_WATER)
Block(0,8,3,STATIONARY_WATER)
Block(0,8,4,STATIONARY_WATER)
Block(0,8,5,STATIONARY_WATER)
Block(0,8,6,PRISMARINE)
Block(0,8,7,PRISMARINE)
Block(0,9,-8,PRISMARINE:1)
Block(0,9,-7,PRISMARINE:1)
Block(0,9,-6,PRISMARINE:1)
Block(0,9,-5,PRISMARINE:1)
Block(0,9,-4,PRISMARINE)
Block(0,9,-3,PRISMARINE)
Block(0,9,-2,PRISMARINE)
Block(0,9,-1,PRISMARINE)
Block(0,9,0,PRISMARINE)
Block(0,9,1,PRISMARINE)
Block(0,9,2,PRISMARINE)
Block(0,9,3,PRISMARINE)
Block(0,9,4,PRISMARINE)
Block(0,9,5,PRISMARINE:1)
Block(0,9,6,PRISMARINE:1)
Block(0,9,7,PRISMARINE:1)
Block(0,9,8,PRISMARINE:1)
Block(0,10,-7,PRISMARINE)
Block(0,10,-6,PRISMARINE:2)
Block(0,10,-5,STATIONARY_WATER)
Block(0,10,-4,STATIONARY_WATER)
Block(0,10,-3,STATIONARY_WATER)
Block(0,10,-2,STATIONARY_WATER)
Block(0,10,-1,STATIONARY_WATER)
Block(0,10,0,STATIONARY_WATER)
Block(0,10,1,STATIONARY_WATER)
Block(0,10,2,STATIONARY_WATER)
Block(0,10,3,STATIONARY_WATER)
Block(0,10,4,STATIONARY_WATER)
Block(0,10,5,STATIONARY_WATER)
Block(0,10,6,PRISMARINE:2)
Block(0,10,7,PRISMARINE)
Block(0,11,-7,PRISMARINE:2)
Block(0,11,-6,PRISMARINE:1)
Block(0,11,-5,STATIONARY_WATER)
Block(0,11,-4,STATIONARY_WATER)
Block(0,11,-3,STATIONARY_WATER)
Block(0,11,-2,STATIONARY_WATER)
Block(0,11,-1,STATIONARY_WATER)
Block(0,11,0,STATIONARY_WATER)
Block(0,11,1,STATIONARY_WATER)
Block(0,11,2,STATIONARY_WATER)
Block(0,11,3,STATIONARY_WATER)
Block(0,11,4,STATIONARY_WATER)
Block(0,11,5,STATIONARY_WATER)
Block(0,11,6,PRISMARINE:1)
Block(0,11,7,PRISMARINE:2)
Block(0,12,-5,STATIONARY_WATER)
Block(0,12,-4,STATIONARY_WATER)
Block(0,12,-3,STATIONARY_WATER)
Block(0,12,-2,STATIONARY_WATER)
Block(0,12,-1,STATIONARY_WATER)
Block(0,12,0,STATIONARY_WATER)
Block(0,12,1,STATIONARY_WATER)
Block(0,12,2,STATIONARY_WATER)
Block(0,12,3,STATIONARY_WATER)
Block(0,12,4,STATIONARY_WATER)
Block(0,12,5,STATIONARY_WATER)
Block(0,13,-5,STATIONARY_WATER)
Block(0,13,-4,STATIONARY_WATER)
Block(0,13,-3,STATIONARY_WATER)
Block(0,13,-2,STATIONARY_WATER)
Block(0,13,-1,STATIONARY_WATER)
Block(0,13,0,STATIONARY_WATER)
Block(0,13,1,STATIONARY_WATER)
Block(0,13,2,STATIONARY_WATER)
Block(0,13,3,STATIONARY_WATER)
Block(0,13,4,STATIONARY_WATER)
Block(0,13,5,STATIONARY_WATER)
Block(0,14,-5,STATIONARY_WATER)
Block(0,14,-4,STATIONARY_WATER)
Block(0,14,-3,STATIONARY_WATER)
Block(0,14,-2,STATIONARY_WATER)
Block(0,14,-1,STATIONARY_WATER)
Block(0,14,0,STATIONARY_WATER)
Block(0,14,1,STATIONARY_WATER)
Block(0,14,2,STATIONARY_WATER)
Block(0,14,3,STATIONARY_WATER)
Block(0,14,4,STATIONARY_WATER)
Block(0,14,5,STATIONARY_WATER)
Block(0,15,-5,STATIONARY_WATER)
Block(0,15,-4,STATIONARY_WATER)
Block(0,15,-3,STATIONARY_WATER)
Block(0,15,-2,STATIONARY_WATER)
Block(0,15,-1,STATIONARY_WATER)
Block(0,15,0,STATIONARY_WATER)
Block(0,15,1,STATIONARY_WATER)
Block(0,15,2,STATIONARY_WATER)
Block(0,15,3,STATIONARY_WATER)
Block(0,15,4,STATIONARY_WATER)
Block(0,15,5,STATIONARY_WATER)
Block(0,16,-5,STATIONARY_WATER)
Block(0,16,-4,STATIONARY_WATER)
Block(0,16,-3,STATIONARY_WATER)
Block(0,16,-2,STATIONARY_WATER)
Block(0,16,-1,STATIONARY_WATER)
Block(0,16,0,STATIONARY_WATER)
Block(0,16,1,STATIONARY_WATER)
Block(0,16,2,STATIONARY_WATER)
Block(0,16,3,STATIONARY_WATER)
Block(0,16,4,STATIONARY_WATER)
Block(0,16,5,STATIONARY_WATER)
Block(0,17,-5,STATIONARY_WATER)
Block(0,17,-4,STATIONARY_WATER)
Block(0,17,-3,STATIONARY_WATER)
Block(0,17,-2,STATIONARY_WATER)
Block(0,17,-1,STATIONARY_WATER)
Block(0,17,0,STATIONARY_WATER)
Block(0,17,1,STATIONARY_WATER)
Block(0,17,2,STATIONARY_WATER)
Block(0,17,3,STATIONARY_WATER)
Block(0,17,4,STATIONARY_WATER)
Block(0,17,5,STATIONARY_WATER)
Block(0,18,-6,PRISMARINE:1)
Block(0,18,-5,PRISMARINE)
Block(0,18,-4,STATIONARY_WATER)
Block(0,18,-3,STATIONARY_WATER)
Block(0,18,-2,STATIONARY_WATER)
Block(0,18,-1,STATIONARY_WATER)
Block(0,18,0,STATIONARY_WATER)
Block(0,18,1,STATIONARY_WATER)
Block(0,18,2,STATIONARY_WATER)
Block(0,18,3,STATIONARY_WATER)
Block(0,18,4,STATIONARY_WATER)
Block(0,18,5,PRISMARINE)
Block(0,18,6,PRISMARINE:1)
Block(0,19,-5,PRISMARINE:2)
Block(0,19,-4,PRISMARINE:2)
Block(0,19,-3,PRISMARINE:2)
Block(0,19,-2,PRISMARINE:1)
Block(0,19,-1,STATIONARY_WATER)
Block(0,19,0,STATIONARY_WATER)
Block(0,19,1,STATIONARY_WATER)
Block(0,19,2,PRISMARINE:1)
Block(0,19,3,PRISMARINE:2)
Block(0,19,4,PRISMARINE:2)
Block(0,19,5,PRISMARINE:2)
Block(0,20,-3,STATIONARY_WATER)
Block(0,20,-2,STATIONARY_WATER)
Block(0,20,-1,STATIONARY_WATER)
Block(0,20,0,STATIONARY_WATER)
Block(0,20,1,STATIONARY_WATER)
Block(0,20,2,STATIONARY_WATER)
Block(0,21,-3,STATIONARY_WATER)
Block(0,21,-2,STATIONARY_WATER)
Block(0,21,-1,STATIONARY_WATER)
Block(0,21,0,STATIONARY_WATER)
Block(0,21,1,STATIONARY_WATER)
Block(0,21,2,STATIONARY_WATER)
Block(0,22,-3,STATIONARY_WATER)
Block(0,22,-2,STATIONARY_WATER)
Block(0,22,-1,STATIONARY_WATER)
Block(0,22,0,STATIONARY_WATER)
Block(0,22,1,STATIONARY_WATER)
Block(0,22,2,STATIONARY_WATER)
Block(0,23,-3,STATIONARY_WATER)
Block(0,23,-2,STATIONARY_WATER)
Block(0,23,-1,STATIONARY_WATER)
Block(0,23,0,STATIONARY_WATER)
Block(0,23,1,STATIONARY_WATER)
Block(0,23,2,STATIONARY_WATER)
Block(0,24,-3,PRISMARINE:1)
Block(0,24,-2,PRISMARINE:2)
Block(0,24,-1,STATIONARY_WATER)
Block(0,24,0,STATIONARY_WATER)
Block(0,24,1,STATIONARY_WATER)
Block(0,24,2,PRISMARINE:2)
Block(0,24,3,PRISMARINE:1)
Block(0,25,-1,PRISMARINE)
Block(0,25,0,STATIONARY_WATER)
Block(0,25,1,PRISMARINE)
Block(0,26,0,SEA_LANTERN)
Block(0,27,-1,PRISMARINE)
Block(0,27,0,PRISMARINE)
Block(0,27,1,PRISMARINE)
Block(0,28,0,PRISMARINE:1)
Block(0,29,0,PRISMARINE:1)
Block(1,-3,-8,PRISMARINE)
Block(1,-3,-7,PRISMARINE:1)
Block(1,-3,-6,PRISMARINE)
Block(1,-3,-5,PRISMARINE)
Block(1,-3,-4,PRISMARINE)
Block(1,-3,-3,PRISMARINE)
Block(1,-3,-2,PRISMARINE:1)
Block(1,-3,-1,PRISMARINE)
Block(1,-3,0,PRISMARINE)
Block(1,-3,1,PRISMARINE)
Block(1,-3,2,PRISMARINE:1)
Block(1,-3,3,PRISMARINE)
Block(1,-3,4,PRISMARINE)
Block(1,-3,5,PRISMARINE)
Block(1,-3,6,PRISMARINE)
Block(1,-3,7,PRISMARINE:1)
Block(1,-3,8,PRISMARINE)
Block(1,-2,-8,PRISMARINE)
Block(1,-2,-7,PRISMARINE:1)
Block(1,-2,-6,PRISMARINE)
Block(1,-2,-5,PRISMARINE)
Block(1,-2,-4,PRISMARINE)
Block(1,-2,-3,PRISMARINE)
Block(1,-2,-2,PRISMARINE:1)
Block(1,-2,-1,PRISMARINE)
Block(1,-2,0,PRISMARINE)
Block(1,-2,1,PRISMARINE)
Block(1,-2,2,PRISMARINE:1)
Block(1,-2,3,PRISMARINE)
Block(1,-2,4,PRISMARINE)
Block(1,-2,5,PRISMARINE)
Block(1,-2,6,PRISMARINE)
Block(1,-2,7,PRISMARINE:1)
Block(1,-2,8,PRISMARINE)
Block(1,-1,-8,PRISMARINE)
Block(1,-1,-7,STATIONARY_WATER)
Block(1,-1,-6,STATIONARY_WATER)
Block(1,-1,-5,STATIONARY_WATER)
Block(1,-1,-4,STATIONARY_WATER)
Block(1,-1,-3,STATIONARY_WATER)
Block(1,-1,-2,STATIONARY_WATER)
Block(1,-1,-1,PRISMARINE:1)
Block(1,-1,0,PRISMARINE:1)
Block(1,-1,1,PRISMARINE:1)
Block(1,-1,2,STATIONARY_WATER)
Block(1,-1,3,STATIONARY_WATER)
Block(1,-1,4,STATIONARY_WATER)
Block(1,-1,5,STATIONARY_WATER)
Block(1,-1,6,STATIONARY_WATER)
Block(1,-1,7,STATIONARY_WATER)
Block(1,-1,8,PRISMARINE)
Block(1,0,-8,PRISMARINE)
Block(1,0,-7,STATIONARY_WATER)
Block(1,0,-6,STATIONARY_WATER)
Block(1,0,-5,STATIONARY_WATER)
Block(1,0,-4,STATIONARY_WATER)
Block(1,0,-3,STATIONARY_WATER)
Block(1,0,-2,STATIONARY_WATER)
Block(1,0,-1,PRISMARINE:1)
Block(1,0,0,STATIONARY_WATER)
Block(1,0,1,PRISMARINE:1)
Block(1,0,2,STATIONARY_WATER)
Block(1,0,3,STATIONARY_WATER)
Block(1,0,4,STATIONARY_WATER)
Block(1,0,5,STATIONARY_WATER)
Block(1,0,6,STATIONARY_WATER)
Block(1,0,7,STATIONARY_WATER)
Block(1,0,8,PRISMARINE)
Block(1,1,-8,PRISMARINE)
Block(1,1,-7,STATIONARY_WATER)
Block(1,1,-6,STATIONARY_WATER)
Block(1,1,-5,STATIONARY_WATER)
Block(1,1,-4,STATIONARY_WATER)
Block(1,1,-3,STATIONARY_WATER)
Block(1,1,-2,STATIONARY_WATER)
Block(1,1,-1,PRISMARINE:1)
Block(1,1,0,PRISMARINE:1)
Block(1,1,1,PRISMARINE:1)
Block(1,1,2,STATIONARY_WATER)
Block(1,1,3,STATIONARY_WATER)
Block(1,1,4,STATIONARY_WATER)
Block(1,1,5,STATIONARY_WATER)
Block(1,1,6,STATIONARY_WATER)
Block(1,1,7,STATIONARY_WATER)
Block(1,1,8,PRISMARINE)
Block(1,2,-8,PRISMARINE)
Block(1,2,-7,STATIONARY_WATER)
Block(1,2,-6,STATIONARY_WATER)
Block(1,2,-5,STATIONARY_WATER)
Block(1,2,-4,STATIONARY_WATER)
Block(1,2,-3,STATIONARY_WATER)
Block(1,2,-2,STATIONARY_WATER)
Block(1,2,-1,PRISMARINE:2)
Block(1,2,0,STATIONARY_WATER)
Block(1,2,1,PRISMARINE:2)
Block(1,2,2,STATIONARY_WATER)
Block(1,2,3,STATIONARY_WATER)
Block(1,2,4,STATIONARY_WATER)
Block(1,2,5,STATIONARY_WATER)
Block(1,2,6,STATIONARY_WATER)
Block(1,2,7,STATIONARY_WATER)
Block(1,2,8,PRISMARINE)
Block(1,3,-8,PRISMARINE)
Block(1,3,-7,PRISMARINE)
Block(1,3,-6,PRISMARINE:1)
Block(1,3,-5,STATIONARY_WATER)
Block(1,3,-4,STATIONARY_WATER)
Block(1,3,-3,STATIONARY_WATER)
Block(1,3,-2,STATIONARY_WATER)
Block(1,3,-1,PRISMARINE:2)
Block(1,3,0,STATIONARY_WATER)
Block(1,3,1,PRISMARINE:2)
Block(1,3,2,STATIONARY_WATER)
Block(1,3,3,STATIONARY_WATER)
Block(1,3,4,STATIONARY_WATER)
Block(1,3,5,STATIONARY_WATER)
Block(1,3,6,PRISMARINE:1)
Block(1,3,7,PRISMARINE)
Block(1,3,8,PRISMARINE)
Block(1,4,-8,PRISMARINE)
Block(1,4,-7,PRISMARINE)
Block(1,4,-6,PRISMARINE:1)
Block(1,4,-5,STATIONARY_WATER)
Block(1,4,-4,STATIONARY_WATER)
Block(1,4,-3,STATIONARY_WATER)
Block(1,4,-2,STATIONARY_WATER)
Block(1,4,-1,PRISMARINE:2)
Block(1,4,0,STATIONARY_WATER)
Block(1,4,1,PRISMARINE:2)
Block(1,4,2,STATIONARY_WATER)
Block(1,4,3,STATIONARY_WATER)
Block(1,4,4,STATIONARY_WATER)
Block(1,4,5,STATIONARY_WATER)
Block(1,4,6,PRISMARINE:1)
Block(1,4,7,PRISMARINE)
Block(1,4,8,PRISMARINE)
Block(1,5,-8,PRISMARINE)
Block(1,5,-7,PRISMARINE)
Block(1,5,-6,PRISMARINE:1)
Block(1,5,-5,STATIONARY_WATER)
Block(1,5,-4,STATIONARY_WATER)
Block(1,5,-3,STATIONARY_WATER)
Block(1,5,-2,STATIONARY_WATER)
Block(1,5,-1,PRISMARINE:2)
Block(1,5,0,STATIONARY_WATER)
Block(1,5,1,PRISMARINE:2)
Block(1,5,2,STATIONARY_WATER)
Block(1,5,3,STATIONARY_WATER)
Block(1,5,4,STATIONARY_WATER)
Block(1,5,5,STATIONARY_WATER)
Block(1,5,6,PRISMARINE:1)
Block(1,5,7,PRISMARINE)
Block(1,5,8,PRISMARINE)
Block(1,6,-8,PRISMARINE)
Block(1,6,-7,PRISMARINE)
Block(1,6,-6,STATIONARY_WATER)
Block(1,6,-5,STATIONARY_WATER)
Block(1,6,-4,STATIONARY_WATER)
Block(1,6,-3,STATIONARY_WATER)
Block(1,6,-2,STATIONARY_WATER)
Block(1,6,-1,PRISMARINE:1)
Block(1,6,0,PRISMARINE:1)
Block(1,6,1,PRISMARINE:1)
Block(1,6,2,STATIONARY_WATER)
Block(1,6,3,STATIONARY_WATER)
Block(1,6,4,STATIONARY_WATER)
Block(1,6,5,STATIONARY_WATER)
Block(1,6,6,STATIONARY_WATER)
Block(1,6,7,PRISMARINE)
Block(1,6,8,PRISMARINE)
Block(1,7,-8,PRISMARINE)
Block(1,7,-7,PRISMARINE)
Block(1,7,-6,STATIONARY_WATER)
Block(1,7,-5,STATIONARY_WATER)
Block(1,7,-4,STATIONARY_WATER)
Block(1,7,-3,STATIONARY_WATER)
Block(1,7,-2,STATIONARY_WATER)
Block(1,7,-1,PRISMARINE:1)
Block(1,7,0,STATIONARY_WATER)
Block(1,7,1,PRISMARINE:1)
Block(1,7,2,STATIONARY_WATER)
Block(1,7,3,STATIONARY_WATER)
Block(1,7,4,STATIONARY_WATER)
Block(1,7,5,STATIONARY_WATER)
Block(1,7,6,STATIONARY_WATER)
Block(1,7,7,PRISMARINE)
Block(1,7,8,PRISMARINE)
Block(1,8,-8,PRISMARINE)
Block(1,8,-7,PRISMARINE)
Block(1,8,-6,STATIONARY_WATER)
Block(1,8,-5,STATIONARY_WATER)
Block(1,8,-4,STATIONARY_WATER)
Block(1,8,-3,STATIONARY_WATER)
Block(1,8,-2,STATIONARY_WATER)
Block(1,8,-1,PRISMARINE:1)
Block(1,8,0,PRISMARINE:1)
Block(1,8,1,PRISMARINE:1)
Block(1,8,2,STATIONARY_WATER)
Block(1,8,3,STATIONARY_WATER)
Block(1,8,4,STATIONARY_WATER)
Block(1,8,5,STATIONARY_WATER)
Block(1,8,6,STATIONARY_WATER)
Block(1,8,7,PRISMARINE)
Block(1,8,8,PRISMARINE)
Block(1,9,-8,PRISMARINE:1)
Block(1,9,-7,PRISMARINE:1)
Block(1,9,-6,PRISMARINE:1)
Block(1,9,-5,PRISMARINE:1)
Block(1,9,-4,PRISMARINE:1)
Block(1,9,-3,PRISMARINE:1)
Block(1,9,-2,PRISMARINE:1)
Block(1,9,-1,PRISMARINE:1)
Block(1,9,0,PRISMARINE:1)
Block(1,9,1,PRISMARINE:1)
Block(1,9,2,PRISMARINE:1)
Block(1,9,3,PRISMARINE:1)
Block(1,9,4,PRISMARINE:1)
Block(1,9,5,PRISMARINE:1)
Block(1,9,6,PRISMARINE:1)
Block(1,9,7,PRISMARINE:1)
Block(1,9,8,PRISMARINE:1)
Block(1,10,-7,PRISMARINE)
Block(1,10,-6,PRISMARINE:2)
Block(1,10,-5,STATIONARY_WATER)
Block(1,10,-4,STATIONARY_WATER)
Block(1,10,-3,STATIONARY_WATER)
Block(1,10,-2,STATIONARY_WATER)
Block(1,10,-1,STATIONARY_WATER)
Block(1,10,0,STATIONARY_WATER)
Block(1,10,1,STATIONARY_WATER)
Block(1,10,2,STATIONARY_WATER)
Block(1,10,3,STATIONARY_WATER)
Block(1,10,4,STATIONARY_WATER)
Block(1,10,5,STATIONARY_WATER)
Block(1,10,6,PRISMARINE:2)
Block(1,10,7,PRISMARINE)
Block(1,11,-7,PRISMARINE:2)
Block(1,11,-6,PRISMARINE:1)
Block(1,11,-5,STATIONARY_WATER)
Block(1,11,-4,STATIONARY_WATER)
Block(1,11,-3,STATIONARY_WATER)
Block(1,11,-2,STATIONARY_WATER)
Block(1,11,-1,STATIONARY_WATER)
Block(1,11,0,STATIONARY_WATER)
Block(1,11,1,STATIONARY_WATER)
Block(1,11,2,STATIONARY_WATER)
Block(1,11,3,STATIONARY_WATER)
Block(1,11,4,STATIONARY_WATER)
Block(1,11,5,STATIONARY_WATER)
Block(1,11,6,PRISMARINE:1)
Block(1,11,7,PRISMARINE:2)
Block(1,12,-6,PRISMARINE)
Block(1,12,-5,STATIONARY_WATER)
Block(1,12,-4,STATIONARY_WATER)
Block(1,12,-3,STATIONARY_WATER)
Block(1,12,-2,STATIONARY_WATER)
Block(1,12,-1,STATIONARY_WATER)
Block(1,12,0,STATIONARY_WATER)
Block(1,12,1,STATIONARY_WATER)
Block(1,12,2,STATIONARY_WATER)
Block(1,12,3,STATIONARY_WATER)
Block(1,12,4,STATIONARY_WATER)
Block(1,12,5,STATIONARY_WATER)
Block(1,12,6,PRISMARINE)
Block(1,13,-6,PRISMARINE)
Block(1,13,-5,STATIONARY_WATER)
Block(1,13,-4,STATIONARY_WATER)
Block(1,13,-3,STATIONARY_WATER)
Block(1,13,-2,STATIONARY_WATER)
Block(1,13,-1,STATIONARY_WATER)
Block(1,13,0,STATIONARY_WATER)
Block(1,13,1,STATIONARY_WATER)
Block(1,13,2,STATIONARY_WATER)
Block(1,13,3,STATIONARY_WATER)
Block(1,13,4,STATIONARY_WATER)
Block(1,13,5,STATIONARY_WATER)
Block(1,13,6,PRISMARINE)
Block(1,14,-6,PRISMARINE)
Block(1,14,-5,STATIONARY_WATER)
Block(1,14,-4,STATIONARY_WATER)
Block(1,14,-3,STATIONARY_WATER)
Block(1,14,-2,STATIONARY_WATER)
Block(1,14,-1,STATIONARY_WATER)
Block(1,14,0,STATIONARY_WATER)
Block(1,14,1,STATIONARY_WATER)
Block(1,14,2,STATIONARY_WATER)
Block(1,14,3,STATIONARY_WATER)
Block(1,14,4,STATIONARY_WATER)
Block(1,14,5,STATIONARY_WATER)
Block(1,14,6,PRISMARINE)
Block(1,15,-6,PRISMARINE)
Block(1,15,-5,STATIONARY_WATER)
Block(1,15,-4,STATIONARY_WATER)
Block(1,15,-3,STATIONARY_WATER)
Block(1,15,-2,STATIONARY_WATER)
Block(1,15,-1,STATIONARY_WATER)
Block(1,15,0,STATIONARY_WATER)
Block(1,15,1,STATIONARY_WATER)
Block(1,15,2,STATIONARY_WATER)
Block(1,15,3,STATIONARY_WATER)
Block(1,15,4,STATIONARY_WATER)
Block(1,15,5,STATIONARY_WATER)
Block(1,15,6,PRISMARINE)
Block(1,16,-6,PRISMARINE)
Block(1,16,-5,STATIONARY_WATER)
Block(1,16,-4,STATIONARY_WATER)
Block(1,16,-3,STATIONARY_WATER)
Block(1,16,-2,STATIONARY_WATER)
Block(1,16,-1,STATIONARY_WATER)
Block(1,16,0,STATIONARY_WATER)
Block(1,16,1,STATIONARY_WATER)
Block(1,16,2,STATIONARY_WATER)
Block(1,16,3,STATIONARY_WATER)
Block(1,16,4,STATIONARY_WATER)
Block(1,16,5,STATIONARY_WATER)
Block(1,16,6,PRISMARINE)
Block(1,17,-6,PRISMARINE:1)
Block(1,17,-5,STATIONARY_WATER)
Block(1,17,-4,STATIONARY_WATER)
Block(1,17,-3,STATIONARY_WATER)
Block(1,17,-2,STATIONARY_WATER)
Block(1,17,-1,STATIONARY_WATER)
Block(1,17,0,STATIONARY_WATER)
Block(1,17,1,STATIONARY_WATER)
Block(1,17,2,STATIONARY_WATER)
Block(1,17,3,STATIONARY_WATER)
Block(1,17,4,STATIONARY_WATER)
Block(1,17,5,STATIONARY_WATER)
Block(1,17,6,PRISMARINE:1)
Block(1,18,-6,PRISMARINE:1)
Block(1,18,-5,PRISMARINE)
Block(1,18,-4,STATIONARY_WATER)
Block(1,18,-3,STATIONARY_WATER)
Block(1,18,-2,STATIONARY_WATER)
Block(1,18,-1,STATIONARY_WATER)
Block(1,18,0,STATIONARY_WATER)
Block(1,18,1,STATIONARY_WATER)
Block(1,18,2,STATIONARY_WATER)
Block(1,18,3,STATIONARY_WATER)
Block(1,18,4,STATIONARY_WATER)
Block(1,18,5,PRISMARINE)
Block(1,18,6,PRISMARINE:1)
Block(1,19,-5,PRISMARINE:2)
Block(1,19,-4,PRISMARINE)
Block(1,19,-3,PRISMARINE:1)
Block(1,19,-2,PRISMARINE:1)
Block(1,19,-1,STATIONARY_WATER)
Block(1,19,0,STATIONARY_WATER)
Block(1,19,1,STATIONARY_WATER)
Block(1,19,2,PRISMARINE:1)
Block(1,19,3,PRISMARINE:1)
Block(1,19,4,PRISMARINE)
Block(1,19,5,PRISMARINE:2)
Block(1,20,-3,PRISMARINE)
Block(1,20,-2,STATIONARY_WATER)
Block(1,20,-1,STATIONARY_WATER)
Block(1,20,0,STATIONARY_WATER)
Block(1,20,1,STATIONARY_WATER)
Block(1,20,2,STATIONARY_WATER)
Block(1,20,3,PRISMARINE)
Block(1,21,-3,PRISMARINE)
Block(1,21,-2,STATIONARY_WATER)
Block(1,21,-1,STATIONARY_WATER)
Block(1,21,0,STATIONARY_WATER)
Block(1,21,1,STATIONARY_WATER)
Block(1,21,2,STATIONARY_WATER)
Block(1,21,3,PRISMARINE)
Block(1,22,-3,PRISMARINE)
Block(1,22,-2,STATIONARY_WATER)
Block(1,22,-1,STATIONARY_WATER)
Block(1,22,0,STATIONARY_WATER)
Block(1,22,1,STATIONARY_WATER)
Block(1,22,2,STATIONARY_WATER)
Block(1,22,3,PRISMARINE)
Block(1,23,-3,PRISMARINE:1)
Block(1,23,-2,STATIONARY_WATER)
Block(1,23,-1,STATIONARY_WATER)
Block(1,23,0,STATIONARY_WATER)
Block(1,23,1,STATIONARY_WATER)
Block(1,23,2,STATIONARY_WATER)
Block(1,23,3,PRISMARINE:1)
Block(1,24,-3,PRISMARINE:1)
Block(1,24,-2,PRISMARINE:2)
Block(1,24,-1,STATIONARY_WATER)
Block(1,24,0,STATIONARY_WATER)
Block(1,24,1,STATIONARY_WATER)
Block(1,24,2,PRISMARINE:2)
Block(1,24,3,PRISMARINE:1)
Block(1,25,-1,PRISMARINE)
Block(1,25,0,PRISMARINE)
Block(1,25,1,PRISMARINE)
Block(1,26,-1,PRISMARINE:1)
Block(1,26,1,PRISMARINE:1)
Block(1,27,-1,PRISMARINE)
Block(1,27,0,PRISMARINE)
Block(1,27,1,PRISMARINE)
Block(2,-3,-7,PRISMARINE)
Block(2,-3,-6,PRISMARINE)
Block(2,-3,-5,PRISMARINE)
Block(2,-3,-4,PRISMARINE)
Block(2,-3,-3,PRISMARINE:1)
Block(2,-3,-2,PRISMARINE:1)
Block(2,-3,-1,PRISMARINE:1)
Block(2,-3,0,PRISMARINE)
Block(2,-3,1,PRISMARINE:1)
Block(2,-3,2,PRISMARINE:1)
Block(2,-3,3,PRISMARINE:1)
Block(2,-3,4,PRISMARINE)
Block(2,-3,5,PRISMARINE)
Block(2,-3,6,PRISMARINE)
Block(2,-3,7,PRISMARINE)
Block(2,-2,-7,PRISMARINE)
Block(2,-2,-6,PRISMARINE)
Block(2,-2,-5,PRISMARINE)
Block(2,-2,-4,PRISMARINE)
Block(2,-2,-3,PRISMARINE:1)
Block(2,-2,-2,PRISMARINE:1)
Block(2,-2,-1,PRISMARINE:1)
Block(2,-2,0,PRISMARINE)
Block(2,-2,1,PRISMARINE:1)
Block(2,-2,2,PRISMARINE:1)
Block(2,-2,3,PRISMARINE:1)
Block(2,-2,4,PRISMARINE)
Block(2,-2,5,PRISMARINE)
Block(2,-2,6,PRISMARINE)
Block(2,-2,7,PRISMARINE)
Block(2,-1,-7,PRISMARINE)
Block(2,-1,-6,STATIONARY_WATER)
Block(2,-1,-5,STATIONARY_WATER)
Block(2,-1,-4,STATIONARY_WATER)
Block(2,-1,-3,STATIONARY_WATER)
Block(2,-1,-2,STATIONARY_WATER)
Block(2,-1,-1,STATIONARY_WATER)
Block(2,-1,0,STATIONARY_WATER)
Block(2,-1,1,STATIONARY_WATER)
Block(2,-1,2,STATIONARY_WATER)
Block(2,-1,3,STATIONARY_WATER)
Block(2,-1,4,STATIONARY_WATER)
Block(2,-1,5,STATIONARY_WATER)
Block(2,-1,6,STATIONARY_WATER)
Block(2,-1,7,PRISMARINE)
Block(2,0,-7,PRISMARINE)
Block(2,0,-6,STATIONARY_WATER)
