
#######################################################################
# +-----------------------------------------------------------------+ #
# |                            BO3 object                           | #
# +-----------------------------------------------------------------+ #
#######################################################################

Author: Unknown

Description: This BO3 was converted from a schematic using the MineCraft Worlds Editor. Unfortunately the author and description information for the schematic could not be found. If you know who the author of the schematic is then please tell the author of this BO3!

Version: 3

SettingsMode: WriteWithoutComments


#######################################################################
# +-----------------------------------------------------------------+ #
# |                          Main settings                          | #
# +-----------------------------------------------------------------+ #
#######################################################################

Tree: false

Frequency: 40

Rarity: 100.0

RotateRandomly: false

SpawnHeight: highestBlock

SpawnHeightOffset: 0

SpawnHeightVariance: 0

##############################
# Height Limits for the BO3. #
##############################

MinHeight: 0

MaxHeight: 256

######################
# Extrusion settings #
######################

ExtrudeMode: None

ExtrudeThroughBlocks: AIR

MaxBranchDepth: 10

ExcludedBiomes: All


#######################################################################
# +-----------------------------------------------------------------+ #
# |                      Source block settings                      | #
# +-----------------------------------------------------------------+ #
#######################################################################

SourceBlocks: AIR

MaxPercentageOutsideSourceBlock: 100

OutsideSourceBlock: placeAnyway


#######################################################################
# +-----------------------------------------------------------------+ #
# |                              Blocks                             | #
# +-----------------------------------------------------------------+ #
#######################################################################

Block(-7,19,8,WOOL)
Block(-6,9,8,WOOL)
Block(-6,10,8,WOOL)
Block(-6,11,8,WOOL)
Block(-6,12,8,WOOL)
Block(-6,13,8,WOOL)
Block(-6,14,8,WOOL)
Block(-6,15,8,WOOL)
Block(-6,17,8,WOOL)
Block(-6,18,8,WOOL)
Block(-6,19,7,WOOL)
Block(-6,19,8,WOOL)
Block(-6,20,8,WOOL)
Block(-6,21,8,WOOL)
Block(-5,3,8,WOOL)
Block(-5,4,8,WOOL)
Block(-5,5,8,WOOL)
Block(-5,6,8,WOOL)
Block(-5,7,8,WOOL)
Block(-5,8,7,WOOL)
Block(-5,8,8,WOOL)
Block(-5,9,7,WOOL)
Block(-5,9,8,WOOL)
Block(-5,10,7,WOOL)
Block(-5,10,8,WOOL)
Block(-5,11,6,WOOL)
Block(-5,11,7,WOOL)
Block(-5,11,8,WOOL)
Block(-5,12,6,WOOL)
Block(-5,12,7,WOOL)
Block(-5,12,8,WOOL)
Block(-5,13,6,WOOL)
Block(-5,13,7,WOOL)
Block(-5,13,8,WOOL)
Block(-5,14,6,WOOL)
Block(-5,14,7,WOOL)
Block(-5,14,8,WOOL)
Block(-5,15,6,WOOL)
Block(-5,15,7,WOOL)
Block(-5,15,8,WOOL)
Block(-5,16,8,WOOL)
Block(-5,17,7,WOOL)
Block(-5,17,8,WOOL)
Block(-5,18,7,WOOL)
Block(-5,18,8,WOOL)
Block(-5,19,6,WOOL)
Block(-5,19,7,WOOL)
Block(-5,19,8,WOOL)
Block(-5,20,7,WOOL)
Block(-5,20,8,WOOL)
Block(-5,21,7,WOOL)
Block(-5,21,8,WOOL)
Block(-5,22,8,WOOL)
Block(-5,23,4,WOOL)
Block(-5,23,5,WOOL)
Block(-5,23,6,WOOL)
Block(-5,23,7,WOOL)
Block(-5,23,8,WOOL)
Block(-5,24,4,WOOL)
Block(-5,24,5,WOOL)
Block(-5,24,6,WOOL)
Block(-5,24,7,WOOL)
Block(-5,24,8,WOOL)
Block(-4,2,8,WOOL)
Block(-4,3,7,WOOL)
Block(-4,3,8,WOOL)
Block(-4,4,7,WOOL)
Block(-4,4,8,WOOL)
Block(-4,5,7,WOOL)
Block(-4,5,8,WOOL)
Block(-4,6,7,WOOL)
Block(-4,6,8,WOOL)
Block(-4,7,6,WOOL)
Block(-4,7,7,WOOL)
Block(-4,7,8,WOOL)
Block(-4,8,6,WOOL)
Block(-4,8,7,WOOL)
Block(-4,8,8,WOOL)
Block(-4,9,6,WOOL)
Block(-4,9,7,WOOL)
Block(-4,9,8,WOOL)
Block(-4,10,6,WOOL)
Block(-4,10,7,WOOL)
Block(-4,10,8,WOOL)
Block(-4,11,5,WOOL)
Block(-4,11,6,WOOL)
Block(-4,11,7,WOOL)
Block(-4,11,8,WOOL)
Block(-4,12,5,WOOL)
Block(-4,12,6,WOOL)
Block(-4,12,7,WOOL)
Block(-4,12,8,WOOL)
Block(-4,13,5,WOOL)
Block(-4,13,6,WOOL)
Block(-4,13,7,WOOL)
Block(-4,13,8,WOOL)
Block(-4,14,5,WOOL)
Block(-4,14,6,WOOL)
Block(-4,14,7,WOOL)
Block(-4,14,8,WOOL)
Block(-4,15,5,WOOL)
Block(-4,15,6,WOOL)
Block(-4,15,7,WOOL)
Block(-4,15,8,WOOL)
Block(-4,16,6,WOOL)
Block(-4,16,7,WOOL)
Block(-4,16,8,WOOL)
Block(-4,17,6,WOOL)
Block(-4,17,7,WOOL)
Block(-4,17,8,WOOL)
Block(-4,18,6,WOOL)
Block(-4,18,7,WOOL)
Block(-4,18,8,WOOL)
Block(-4,19,4,WOOL)
Block(-4,19,5,WOOL)
Block(-4,19,6,WOOL)
Block(-4,19,7,WOOL)
Block(-4,19,8,WOOL)
Block(-4,20,6,WOOL)
Block(-4,20,7,WOOL)
Block(-4,20,8,WOOL)
Block(-4,21,6,WOOL)
Block(-4,21,7,WOOL)
Block(-4,21,8,WOOL)
Block(-4,22,1,WOOL)
Block(-4,22,2,WOOL)
Block(-4,22,3,WOOL)
Block(-4,22,4,WOOL)
Block(-4,22,6,WOOL)
Block(-4,22,7,WOOL)
Block(-4,22,8,WOOL)
Block(-4,23,0,WOOL)
Block(-4,23,1,WOOL)
Block(-4,23,2,WOOL)
Block(-4,23,3,WOOL)
Block(-4,23,4,WOOL)
Block(-4,23,5,WOOL)
Block(-4,23,6,WOOL)
Block(-4,23,7,WOOL)
Block(-4,23,8,WOOL)
Block(-4,24,0,WOOL)
Block(-4,24,1,WOOL)
Block(-4,24,2,WOOL)
Block(-4,24,3,WOOL)
Block(-4,24,4,WOOL)
Block(-4,24,5,WOOL)
Block(-4,24,6,WOOL)
Block(-4,24,7,WOOL)
Block(-4,24,8,WOOL)
Block(-3,3,6,WOOL)
Block(-3,3,7,WOOL)
Block(-3,3,8,WOOL)
Block(-3,4,6,WOOL)
Block(-3,4,7,WOOL)
Block(-3,4,8,WOOL)
Block(-3,5,5,WOOL)
Block(-3,5,6,WOOL)
Block(-3,5,7,WOOL)
Block(-3,5,8,WOOL)
Block(-3,6,5,WOOL)
Block(-3,6,6,WOOL)
Block(-3,6,7,WOOL)
Block(-3,6,8,WOOL)
Block(-3,7,4,WOOL)
Block(-3,7,5,WOOL)
Block(-3,7,6,WOOL)
Block(-3,7,7,WOOL)
Block(-3,7,8,WOOL)
Block(-3,8,4,WOOL)
Block(-3,8,5,WOOL)
Block(-3,8,6,WOOL)
Block(-3,8,7,WOOL)
Block(-3,8,8,WOOL)
Block(-3,9,4,WOOL)
Block(-3,9,5,WOOL)
Block(-3,9,6,WOOL)
Block(-3,9,7,WOOL)
Block(-3,9,8,WOOL)
Block(-3,10,4,WOOL)
Block(-3,10,5,WOOL)
Block(-3,10,6,WOOL)
Block(-3,10,7,WOOL)
Block(-3,10,8,WOOL)
Block(-3,11,4,WOOL)
Block(-3,11,5,WOOL)
Block(-3,11,6,WOOL)
Block(-3,11,7,WOOL)
Block(-3,11,8,WOOL)
Block(-3,12,4,WOOL)
Block(-3,12,5,WOOL)
Block(-3,12,6,WOOL)
Block(-3,12,7,WOOL)
Block(-3,12,8,WOOL)
Block(-3,13,3,WOOL)
Block(-3,13,4,WOOL)
Block(-3,13,5,WOOL)
Block(-3,13,6,WOOL)
Block(-3,13,7,WOOL)
Block(-3,13,8,WOOL)
Block(-3,14,3,WOOL)
Block(-3,14,4,WOOL)
Block(-3,14,5,WOOL)
Block(-3,14,6,WOOL)
Block(-3,14,7,WOOL)
Block(-3,14,8,WOOL)
Block(-3,15,3,WOOL)
Block(-3,15,4,WOOL)
Block(-3,15,5,WOOL)
Block(-3,15,6,WOOL)
Block(-3,15,7,WOOL)
Block(-3,15,8,WOOL)
Block(-3,16,5,WOOL)
Block(-3,16,6,WOOL)
Block(-3,16,7,WOOL)
Block(-3,16,8,WOOL)
Block(-3,17,4,WOOL)
Block(-3,17,5,WOOL)
Block(-3,17,6,WOOL)
Block(-3,17,7,WOOL)
Block(-3,17,8,WOOL)
Block(-3,18,4,WOOL)
Block(-3,18,5,WOOL)
Block(-3,18,6,WOOL)
Block(-3,18,7,WOOL)
Block(-3,18,8,WOOL)
Block(-3,19,3,WOOL)
Block(-3,19,4,WOOL)
Block(-3,19,5,WOOL)
Block(-3,19,6,WOOL)
Block(-3,19,7,WOOL)
Block(-3,19,8,WOOL)
Block(-3,20,4,WOOL)
Block(-3,20,5,WOOL)
Block(-3,20,6,WOOL)
Block(-3,20,7,WOOL)
Block(-3,20,8,WOOL)
Block(-3,21,2,WOOL)
Block(-3,21,4,WOOL)
Block(-3,21,5,WOOL)
Block(-3,21,6,WOOL)
Block(-3,21,7,WOOL)
Block(-3,21,8,WOOL)
Block(-3,22,0,WOOL)
Block(-3,22,1,WOOL)
Block(-3,22,2,WOOL)
Block(-3,22,3,WOOL)
Block(-3,22,4,WOOL)
Block(-3,22,5,WOOL)
Block(-3,22,6,WOOL)
Block(-3,22,7,WOOL)
Block(-3,22,8,WOOL)
Block(-3,23,-2,WOOL)
Block(-3,23,-1,WOOL)
Block(-3,23,0,WOOL)
Block(-3,23,1,WOOL)
Block(-3,23,2,WOOL)
Block(-3,23,3,WOOL)
Block(-3,23,4,WOOL)
Block(-3,23,5,WOOL)
Block(-3,23,6,WOOL)
Block(-3,23,7,WOOL)
Block(-3,23,8,WOOL)
Block(-3,24,-2,WOOL)
Block(-3,24,-1,WOOL)
Block(-3,24,0,WOOL)
Block(-3,24,1,WOOL)
Block(-3,24,2,WOOL)
Block(-3,24,3,WOOL)
Block(-3,24,4,WOOL)
Block(-3,24,5,WOOL)
Block(-3,24,6,WOOL)
Block(-3,24,7,WOOL)
Block(-3,24,8,WOOL)
Block(-2,3,6,WOOL)
Block(-2,3,7,WOOL)
Block(-2,3,8,WOOL)
Block(-2,4,6,WOOL)
Block(-2,4,7,WOOL)
Block(-2,4,8,WOOL)
Block(-2,5,4,WOOL)
Block(-2,5,5,WOOL)
Block(-2,5,6,WOOL)
Block(-2,5,7,WOOL)
Block(-2,5,8,WOOL)
Block(-2,6,3,WOOL)
Block(-2,6,4,WOOL)
Block(-2,6,5,WOOL)
Block(-2,6,6,WOOL)
Block(-2,6,7,WOOL)
Block(-2,6,8,WOOL)
Block(-2,7,3,WOOL)
Block(-2,7,4,WOOL)
Block(-2,7,5,WOOL)
Block(-2,7,6,WOOL)
Block(-2,7,7,WOOL)
Block(-2,7,8,WOOL)
Block(-2,8,2,WOOL)
Block(-2,8,3,WOOL)
Block(-2,8,4,WOOL)
Block(-2,8,5,WOOL)
Block(-2,8,6,WOOL)
Block(-2,8,7,WOOL)
Block(-2,8,8,WOOL)
Block(-2,9,2,WOOL)
Block(-2,9,3,WOOL)
Block(-2,9,4,WOOL)
Block(-2,9,5,WOOL)
Block(-2,9,6,WOOL)
Block(-2,9,7,WOOL)
Block(-2,9,8,WOOL)
Block(-2,10,2,WOOL)
Block(-2,10,3,WOOL)
Block(-2,10,4,WOOL)
Block(-2,10,5,WOOL)
Block(-2,10,6,WOOL)
Block(-2,10,7,WOOL)
Block(-2,10,8,WOOL)
Block(-2,11,1,WOOL)
Block(-2,11,2,WOOL)
Block(-2,11,3,WOOL)
Block(-2,11,4,WOOL)
Block(-2,11,5,WOOL)
Block(-2,11,6,WOOL)
Block(-2,11,7,WOOL)
Block(-2,11,8,WOOL)
Block(-2,12,1,WOOL)
Block(-2,12,2,WOOL)
Block(-2,12,3,WOOL)
Block(-2,12,4,WOOL)
Block(-2,12,5,WOOL)
Block(-2,12,6,WOOL)
Block(-2,12,7,WOOL)
Block(-2,12,8,WOOL)
Block(-2,13,1,WOOL)
Block(-2,13,2,WOOL)
Block(-2,13,3,WOOL)
Block(-2,13,4,WOOL)
Block(-2,13,5,WOOL)
Block(-2,13,6,WOOL)
Block(-2,13,7,WOOL)
Block(-2,13,8,WOOL)
Block(-2,14,1,WOOL)
Block(-2,14,2,WOOL)
Block(-2,14,3,WOOL)
Block(-2,14,4,WOOL)
Block(-2,14,5,WOOL)
Block(-2,14,6,WOOL)
Block(-2,14,7,WOOL)
Block(-2,14,8,WOOL)
Block(-2,15,1,WOOL)
Block(-2,15,2,WOOL)
Block(-2,15,3,WOOL)
Block(-2,15,4,WOOL)
Block(-2,15,5,WOOL)
Block(-2,15,6,WOOL)
Block(-2,15,7,WOOL)
Block(-2,15,8,WOOL)
Block(-2,16,3,WOOL)
Block(-2,16,4,WOOL)
Block(-2,16,5,WOOL)
Block(-2,16,6,WOOL)
Block(-2,16,7,WOOL)
Block(-2,16,8,WOOL)
Block(-2,17,2,WOOL)
Block(-2,17,3,WOOL)
Block(-2,17,4,WOOL)
Block(-2,17,5,WOOL)
Block(-2,17,6,WOOL)
Block(-2,17,7,WOOL)
Block(-2,17,8,WOOL)
Block(-2,18,2,WOOL)
Block(-2,18,3,WOOL)
Block(-2,18,4,WOOL)
Block(-2,18,5,WOOL)
Block(-2,18,6,WOOL)
Block(-2,18,7,WOOL)
Block(-2,18,8,WOOL)
Block(-2,19,1,WOOL)
Block(-2,19,2,WOOL)
Block(-2,19,3,WOOL)
Block(-2,19,4,WOOL)
Block(-2,19,5,WOOL)
Block(-2,19,6,WOOL)
Block(-2,19,7,WOOL)
Block(-2,19,8,WOOL)
Block(-2,20,2,WOOL)
Block(-2,20,3,WOOL)
Block(-2,20,4,WOOL)
Block(-2,20,5,WOOL)
Block(-2,20,6,WOOL)
Block(-2,20,7,WOOL)
Block(-2,20,8,WOOL)
Block(-2,21,2,WOOL)
Block(-2,21,3,WOOL)
Block(-2,21,4,WOOL)
Block(-2,21,5,WOOL)
Block(-2,21,6,WOOL)
Block(-2,21,7,WOOL)
Block(-2,21,8,WOOL)
Block(-2,22,0,WOOL)
Block(-2,22,1,WOOL)
Block(-2,22,2,WOOL)
Block(-2,22,3,WOOL)
Block(-2,22,4,WOOL)
Block(-2,22,5,WOOL)
Block(-2,22,6,WOOL)
Block(-2,22,7,WOOL)
Block(-2,22,8,WOOL)
Block(-2,23,-4,WOOL)
Block(-2,23,-3,WOOL)
Block(-2,23,-2,WOOL)
Block(-2,23,-1,WOOL)
Block(-2,23,0,WOOL)
Block(-2,23,1,WOOL)
Block(-2,23,2,WOOL)
Block(-2,23,3,WOOL)
Block(-2,23,4,WOOL)
Block(-2,23,5,WOOL)
Block(-2,23,6,WOOL)
Block(-2,23,7,WOOL)
Block(-2,23,8,WOOL)
Block(-2,24,-4,WOOL)
Block(-2,24,-3,WOOL)
Block(-2,24,-2,WOOL)
Block(-2,24,-1,WOOL)
Block(-2,24,0,WOOL)
Block(-2,24,1,WOOL)
Block(-2,24,2,WOOL)
Block(-2,24,3,WOOL)
Block(-2,24,4,WOOL)
Block(-2,24,5,WOOL)
Block(-2,24,6,WOOL)
Block(-2,24,7,WOOL)
Block(-2,24,8,WOOL)
Block(-1,3,6,WOOL)
Block(-1,3,7,WOOL)
Block(-1,3,8,WOOL)
Block(-1,4,6,WOOL)
Block(-1,4,7,WOOL)
Block(-1,4,8,WOOL)
Block(-1,5,4,WOOL)
Block(-1,5,5,WOOL)
Block(-1,5,6,WOOL)
Block(-1,5,7,WOOL)
Block(-1,5,8,WOOL)
Block(-1,6,2,WOOL)
Block(-1,6,3,WOOL)
Block(-1,6,4,WOOL)
Block(-1,6,5,WOOL)
Block(-1,6,6,WOOL)
Block(-1,6,7,WOOL)
Block(-1,6,8,WOOL)
Block(-1,7,2,WOOL)
Block(-1,7,3,WOOL)
Block(-1,7,4,WOOL)
Block(-1,7,5,WOOL)
Block(-1,7,6,WOOL)
Block(-1,7,7,WOOL)
Block(-1,7,8,WOOL)
Block(-1,8,1,WOOL)
Block(-1,8,2,WOOL)
Block(-1,8,3,WOOL)
Block(-1,8,4,WOOL)
Block(-1,8,5,WOOL)
Block(-1,8,6,WOOL)
Block(-1,8,7,WOOL)
Block(-1,8,8,WOOL)
Block(-1,9,1,WOOL)
Block(-1,9,2,WOOL)
Block(-1,9,3,WOOL)
Block(-1,9,4,WOOL)
Block(-1,9,5,WOOL)
Block(-1,9,6,WOOL)
Block(-1,9,7,WOOL)
Block(-1,9,8,WOOL)
Block(-1,10,1,WOOL)
Block(-1,10,2,WOOL)
Block(-1,10,3,WOOL)
Block(-1,10,4,WOOL)
Block(-1,10,5,WOOL)
Block(-1,10,6,WOOL)
Block(-1,10,7,WOOL)
Block(-1,10,8,WOOL)
Block(-1,11,-2,WOOL)
Block(-1,11,-1,WOOL)
Block(-1,11,0,WOOL)
Block(-1,11,1,WOOL)
Block(-1,11,2,WOOL)
Block(-1,11,3,WOOL)
Block(-1,11,4,WOOL)
Block(-1,11,5,WOOL)
Block(-1,11,6,WOOL)
Block(-1,11,7,WOOL)
Block(-1,11,8,WOOL)
Block(-1,12,-2,WOOL)
Block(-1,12,-1,WOOL)
Block(-1,12,0,WOOL)
Block(-1,12,1,WOOL)
Block(-1,12,2,WOOL)
Block(-1,12,3,WOOL)
Block(-1,12,4,WOOL)
Block(-1,12,5,WOOL)
Block(-1,12,6,WOOL)
Block(-1,12,7,WOOL)
Block(-1,12,8,WOOL)
Block(-1,13,-2,WOOL)
Block(-1,13,-1,WOOL)
Block(-1,13,0,WOOL)
Block(-1,13,1,WOOL)
Block(-1,13,2,WOOL)
Block(-1,13,3,WOOL)
Block(-1,13,4,WOOL)
Block(-1,13,5,WOOL)
Block(-1,13,6,WOOL)
Block(-1,13,7,WOOL)
Block(-1,13,8,WOOL)
Block(-1,14,-2,WOOL)
Block(-1,14,-1,WOOL)
Block(-1,14,0,WOOL)
Block(-1,14,1,WOOL)
Block(-1,14,2,WOOL)
Block(-1,14,3,WOOL)
Block(-1,14,4,WOOL)
Block(-1,14,5,WOOL)
Block(-1,14,6,WOOL)
Block(-1,14,7,WOOL)
Block(-1,14,8,WOOL)
Block(-1,15,-2,WOOL)
Block(-1,15,-1,WOOL)
Block(-1,15,0,WOOL)
Block(-1,15,1,WOOL)
Block(-1,15,2,WOOL)
Block(-1,15,3,WOOL)
Block(-1,15,4,WOOL)
Block(-1,15,5,WOOL)
Block(-1,15,6,WOOL)
Block(-1,15,7,WOOL)
Block(-1,15,8,WOOL)
Block(-1,16,1,WOOL)
Block(-1,16,2,WOOL)
Block(-1,16,3,WOOL)
Block(-1,16,4,WOOL)
Block(-1,16,5,WOOL)
Block(-1,16,6,WOOL)
Block(-1,16,7,WOOL)
Block(-1,16,8,WOOL)
Block(-1,17,-1,WOOL)
Block(-1,17,0,WOOL)
Block(-1,17,1,WOOL)
Block(-1,17,2,WOOL)
Block(-1,17,3,WOOL)
Block(-1,17,4,WOOL)
Block(-1,17,5,WOOL)
Block(-1,17,6,WOOL)
Block(-1,17,7,WOOL)
Block(-1,17,8,WOOL)
Block(-1,18,-1,WOOL)
Block(-1,18,0,WOOL)
Block(-1,18,1,WOOL)
Block(-1,18,2,WOOL)
Block(-1,18,3,WOOL)
Block(-1,18,4,WOOL)
Block(-1,18,5,WOOL)
Block(-1,18,6,WOOL)
Block(-1,18,7,WOOL)
Block(-1,18,8,WOOL)
Block(-1,19,-2,WOOL)
Block(-1,19,-1,WOOL)
Block(-1,19,0,WOOL)
Block(-1,19,1,WOOL)
Block(-1,19,2,WOOL)
Block(-1,19,3,WOOL)
Block(-1,19,4,WOOL)
Block(-1,19,5,WOOL)
Block(-1,19,6,WOOL)
Block(-1,19,7,WOOL)
Block(-1,19,8,WOOL)
Block(-1,20,-1,WOOL)
Block(-1,20,0,WOOL)
Block(-1,20,1,WOOL)
Block(-1,20,2,WOOL)
Block(-1,20,3,WOOL)
Block(-1,20,4,WOOL)
Block(-1,20,5,WOOL)
Block(-1,20,6,WOOL)
Block(-1,20,7,WOOL)
Block(-1,20,8,WOOL)
Block(-1,21,-1,WOOL)
Block(-1,21,0,WOOL)
Block(-1,21,1,WOOL)
Block(-1,21,2,WOOL)
Block(-1,21,3,WOOL)
Block(-1,21,4,WOOL)
Block(-1,21,5,WOOL)
Block(-1,21,6,WOOL)
Block(-1,21,7,WOOL)
Block(-1,21,8,WOOL)
Block(-1,22,-1,WOOL)
Block(-1,22,0,WOOL)
Block(-1,22,1,WOOL)
Block(-1,22,2,WOOL)
Block(-1,22,3,WOOL)
Block(-1,22,4,WOOL)
Block(-1,22,5,WOOL)
Block(-1,22,6,WOOL)
Block(-1,22,7,WOOL)
Block(-1,22,8,WOOL)
Block(-1,23,-5,WOOL)
Block(-1,23,-4,WOOL)
Block(-1,23,-3,WOOL)
Block(-1,23,-2,WOOL)
Block(-1,23,-1,WOOL)
Block(-1,23,0,WOOL)
Block(-1,23,1,WOOL)
Block(-1,23,2,WOOL)
Block(-1,23,3,WOOL)
Block(-1,23,4,WOOL)
Block(-1,23,5,WOOL)
Block(-1,23,6,WOOL)
Block(-1,23,7,WOOL)
Block(-1,23,8,WOOL)
Block(-1,24,-5,WOOL)
Block(-1,24,-4,WOOL)
Block(-1,24,-3,WOOL)
Block(-1,24,-2,WOOL)
Block(-1,24,-1,WOOL)
Block(-1,24,0,WOOL)
Block(-1,24,1,WOOL)
Block(-1,24,2,WOOL)
Block(-1,24,3,WOOL)
Block(-1,24,4,WOOL)
Block(-1,24,5,WOOL)
Block(-1,24,6,WOOL)
Block(-1,24,7,WOOL)
Block(-1,24,8,WOOL)
Block(0,4,8,WOOL)
Block(0,5,4,WOOL)
Block(0,5,5,WOOL)
Block(0,5,6,WOOL)
Block(0,5,8,WOOL)
Block(0,6,2,WOOL)
Block(0,6,3,WOOL)
Block(0,6,4,WOOL)
Block(0,6,5,WOOL)
Block(0,6,6,WOOL)
Block(0,6,7,WOOL)
Block(0,6,8,WOOL)
Block(0,7,2,WOOL)
Block(0,7,3,WOOL)
Block(0,7,4,WOOL)
Block(0,7,5,WOOL)
Block(0,7,6,WOOL)
Block(0,7,7,WOOL)
Block(0,7,8,WOOL)
Block(0,8,0,WOOL)
Block(0,8,1,WOOL)
Block(0,8,2,WOOL)
Block(0,8,3,WOOL)
Block(0,8,4,WOOL)
Block(0,8,5,WOOL)
Block(0,8,6,WOOL)
Block(0,8,7,WOOL)
Block(0,8,8,WOOL)
Block(0,9,-2,WOOL)
Block(0,9,-1,WOOL)
Block(0,9,0,WOOL)
Block(0,9,1,WOOL)
Block(0,9,2,WOOL)
Block(0,9,3,WOOL)
Block(0,9,4,WOOL)
Block(0,9,5,WOOL)
Block(0,9,6,WOOL)
Block(0,9,7,WOOL)
Block(0,9,8,WOOL)
Block(0,10,-4,WOOL)
Block(0,10,-3,WOOL)
Block(0,10,-2,WOOL)
Block(0,10,-1,WOOL)
Block(0,10,0,WOOL)
Block(0,10,1,WOOL)
Block(0,10,2,WOOL)
Block(0,10,3,WOOL)
Block(0,10,4,WOOL)
Block(0,10,5,WOOL)
Block(0,10,6,WOOL)
Block(0,10,7,WOOL)
Block(0,10,8,WOOL)
Block(0,11,-6,WOOL)
Block(0,11,-5,WOOL)
Block(0,11,-4,WOOL)
Block(0,11,-3,WOOL)
Block(0,11,-2,WOOL)
Block(0,11,-1,WOOL)
Block(0,11,0,WOOL)
Block(0,11,1,WOOL)
Block(0,11,2,WOOL)
Block(0,11,3,WOOL)
Block(0,11,4,WOOL)
Block(0,11,5,WOOL)
Block(0,11,6,WOOL)
Block(0,11,7,WOOL)
Block(0,11,8,WOOL)
Block(0,12,-7,WOOL)
Block(0,12,-6,WOOL)
Block(0,12,-5,WOOL)
Block(0,12,-4,WOOL)
Block(0,12,-3,WOOL)
Block(0,12,-2,WOOL)
Block(0,12,-1,WOOL)
Block(0,12,0,WOOL)
Block(0,12,1,WOOL)
Block(0,12,2,WOOL)
Block(0,12,3,WOOL)
Block(0,12,4,WOOL)
Block(0,12,5,WOOL)
Block(0,12,6,WOOL)
Block(0,12,7,WOOL)
Block(0,12,8,WOOL)
Block(0,13,-7,WOOL)
Block(0,13,-6,WOOL)
Block(0,13,-5,WOOL)
Block(0,13,-4,WOOL)
Block(0,13,-3,WOOL)
Block(0,13,-2,WOOL)
Block(0,13,-1,WOOL)
Block(0,13,0,WOOL)
Block(0,13,1,WOOL)
Block(0,13,2,WOOL)
Block(0,13,3,WOOL)
Block(0,13,4,WOOL)
Block(0,13,5,WOOL)
Block(0,13,6,WOOL)
Block(0,13,7,WOOL)
Block(0,13,8,WOOL)
Block(0,14,-7,WOOL)
Block(0,14,-6,WOOL)
Block(0,14,-5,WOOL)
Block(0,14,-4,WOOL)
Block(0,14,-3,WOOL)
Block(0,14,-2,WOOL)
Block(0,14,-1,WOOL)
Block(0,14,0,WOOL)
Block(0,14,1,WOOL)
Block(0,14,2,WOOL)
Block(0,14,3,WOOL)
Block(0,14,4,WOOL)
Block(0,14,5,WOOL)
Block(0,14,6,WOOL)
Block(0,14,7,WOOL)
Block(0,14,8,WOOL)
Block(0,15,-7,WOOL)
Block(0,15,-6,WOOL)
Block(0,15,-5,WOOL)
Block(0,15,-4,WOOL)
Block(0,15,-3,WOOL)
Block(0,15,-2,WOOL)
Block(0,15,-1,WOOL)
Block(0,15,0,WOOL)
Block(0,15,1,WOOL)
Block(0,15,2,WOOL)
Block(0,15,3,WOOL)
Block(0,15,4,WOOL)
Block(0,15,5,WOOL)
Block(0,15,6,WOOL)
Block(0,15,7,WOOL)
Block(0,15,8,WOOL)
Block(0,16,-7,WOOL)
Block(0,16,-6,WOOL)
Block(0,16,-5,WOOL)
Block(0,16,-4,WOOL)
Block(0,16,-3,WOOL)
Block(0,16,-2,WOOL)
Block(0,16,-1,WOOL)
Block(0,16,0,WOOL)
Block(0,16,1,WOOL)
Block(0,16,2,WOOL)
Block(0,16,3,WOOL)
Block(0,16,4,WOOL)
Block(0,16,5,WOOL)
Block(0,16,6,WOOL)
Block(0,16,7,WOOL)
Block(0,16,8,WOOL)
Block(0,17,-7,WOOL)
Block(0,17,-6,WOOL)
Block(0,17,-5,WOOL)
Block(0,17,-4,WOOL)
Block(0,17,-3,WOOL)
Block(0,17,-2,WOOL)
Block(0,17,-1,WOOL)
Block(0,17,0,WOOL)
Block(0,17,1,WOOL)
Block(0,17,2,WOOL)
Block(0,17,3,WOOL)
Block(0,17,4,WOOL)
Block(0,17,5,WOOL)
Block(0,17,6,WOOL)
Block(0,17,7,WOOL)
Block(0,17,8,WOOL)
Block(0,18,-7,WOOL)
Block(0,18,-6,WOOL)
Block(0,18,-5,WOOL)
Block(0,18,-4,WOOL)
Block(0,18,-3,WOOL)
Block(0,18,-2,WOOL)
Block(0,18,-1,WOOL)
Block(0,18,0,WOOL)
Block(0,18,1,WOOL)
Block(0,18,2,WOOL)
Block(0,18,3,WOOL)
Block(0,18,4,WOOL)
Block(0,18,5,WOOL)
Block(0,18,6,WOOL)
Block(0,18,7,WOOL)
Block(0,18,8,WOOL)
Block(0,19,-7,WOOL)
Block(0,19,-6,WOOL)
Block(0,19,-5,WOOL)
Block(0,19,-4,WOOL)
Block(0,19,-3,WOOL)
Block(0,19,-2,WOOL)
Block(0,19,-1,WOOL)
Block(0,19,0,WOOL)
Block(0,19,1,WOOL)
Block(0,19,2,WOOL)
Block(0,19,3,WOOL)
Block(0,19,4,WOOL)
Block(0,19,5,WOOL)
Block(0,19,6,WOOL)
Block(0,19,7,WOOL)
Block(0,19,8,WOOL)
Block(0,20,-7,WOOL)
Block(0,20,-6,WOOL)
Block(0,20,-5,WOOL)
Block(0,20,-4,WOOL)
Block(0,20,-3,WOOL)
Block(0,20,-2,WOOL)
Block(0,20,-1,WOOL)
Block(0,20,0,WOOL)
Block(0,20,1,WOOL)
Block(0,20,2,WOOL)
Block(0,20,3,WOOL)
Block(0,20,4,WOOL)
Block(0,20,5,WOOL)
Block(0,20,6,WOOL)
Block(0,20,7,WOOL)
Block(0,20,8,WOOL)
Block(0,21,-7,WOOL)
Block(0,21,-6,WOOL)
Block(0,21,-5,WOOL)
Block(0,21,-4,WOOL)
Block(0,21,-3,WOOL)
Block(0,21,-2,WOOL)
Block(0,21,-1,WOOL)
Block(0,21,0,WOOL)
Block(0,21,1,WOOL)
Block(0,21,2,WOOL)
Block(0,21,3,WOOL)
Block(0,21,4,WOOL)
Block(0,21,5,WOOL)
Block(0,21,6,WOOL)
Block(0,21,7,WOOL)
Block(0,21,8,WOOL)
Block(0,22,-7,WOOL)
Block(0,22,-6,WOOL)
Block(0,22,-5,WOOL)
Block(0,22,-4,WOOL)
Block(0,22,-3,WOOL)
Block(0,22,-2,WOOL)
Block(0,22,-1,WOOL)
Block(0,22,0,WOOL)
Block(0,22,1,WOOL)
Block(0,22,2,WOOL)
Block(0,22,3,WOOL)
Block(0,22,4,WOOL)
Block(0,22,5,WOOL)
Block(0,22,6,WOOL)
Block(0,22,7,WOOL)
Block(0,22,8,WOOL)
Block(0,23,-7,WOOL)
Block(0,23,-6,WOOL)
Block(0,23,-5,WOOL)
Block(0,23,-4,WOOL)
Block(0,23,-3,WOOL)
Block(0,23,-2,WOOL)
Block(0,23,-1,WOOL)
Block(0,23,0,WOOL)
Block(0,23,1,WOOL)
Block(0,23,2,WOOL)
Block(0,23,3,WOOL)
Block(0,23,4,WOOL)
Block(0,23,5,WOOL)
Block(0,23,6,WOOL)
Block(0,23,7,WOOL)
Block(0,23,8,WOOL)
Block(0,24,-7,WOOL)
Block(0,24,-6,WOOL)
Block(0,24,-5,WOOL)
Block(0,24,-4,WOOL)
Block(0,24,-3,WOOL)
Block(0,24,-2,WOOL)
Block(0,24,-1,WOOL)
Block(0,24,0,WOOL)
Block(0,24,1,WOOL)
Block(0,24,2,WOOL)
Block(0,24,3,WOOL)
Block(0,24,4,WOOL)
Block(0,24,5,WOOL)
Block(0,24,6,WOOL)
Block(0,24,7,WOOL)
Block(0,24,8,WOOL)
Block(1,5,5,WOOL)
Block(1,6,3,WOOL)
Block(1,6,4,WOOL)
Block(1,6,5,WOOL)
Block(1,7,2,WOOL)
Block(1,7,3,WOOL)
Block(1,7,4,WOOL)
Block(1,7,5,WOOL)
Block(1,7,6,WOOL)
Block(1,8,0,WOOL)
Block(1,8,1,WOOL)
Block(1,8,2,WOOL)
Block(1,8,3,WOOL)
Block(1,8,4,WOOL)
Block(1,8,5,WOOL)
Block(1,8,6,WOOL)
Block(1,9,-3,WOOL)
Block(1,9,-2,WOOL)
Block(1,9,-1,WOOL)
Block(1,9,0,WOOL)
Block(1,9,1,WOOL)
Block(1,9,2,WOOL)
Block(1,9,3,WOOL)
Block(1,9,4,WOOL)
Block(1,9,5,WOOL)
Block(1,9,6,WOOL)
Block(1,10,-4,WOOL)
Block(1,10,-3,WOOL)
Block(1,10,-2,WOOL)
Block(1,10,-1,WOOL)
Block(1,10,0,WOOL)
Block(1,10,1,WOOL)
Block(1,10,2,WOOL)
Block(1,10,3,WOOL)
Block(1,10,4,WOOL)
Block(1,10,5,WOOL)
Block(1,10,6,WOOL)
Block(1,11,-7,WOOL)
Block(1,11,-6,WOOL)
Block(1,11,-5,WOOL)
Block(1,11,-4,WOOL)
Block(1,11,-3,WOOL)
Block(1,11,-2,WOOL)
Block(1,11,-1,WOOL)
Block(1,11,0,WOOL)
Block(1,11,1,WOOL)
Block(1,11,2,WOOL)
Block(1,11,3,WOOL)
Block(1,11,4,WOOL)
Block(1,11,5,WOOL)
Block(1,11,6,WOOL)
Block(1,11,7,WOOL)
Block(1,12,-7,WOOL)
Block(1,12,-6,WOOL)
Block(1,12,-5,WOOL)
Block(1,12,-4,WOOL)
Block(1,12,-3,WOOL)
Block(1,12,-2,WOOL)
Block(1,12,-1,WOOL)
Block(1,12,0,WOOL)
Block(1,12,1,WOOL)
Block(1,12,2,WOOL)
Block(1,12,3,WOOL)
Block(1,12,4,WOOL)
Block(1,12,5,WOOL)
Block(1,12,6,WOOL)
Block(1,12,7,WOOL)
Block(1,13,-7,WOOL)
Block(1,13,-6,WOOL)
Block(1,13,-5,WOOL)
Block(1,13,-4,WOOL)
Block(1,13,-3,WOOL)
Block(1,13,-2,WOOL)
Block(1,13,-1,WOOL)
Block(1,13,0,WOOL)
Block(1,13,1,WOOL)
Block(1,13,2,WOOL)
Block(1,13,3,WOOL)
Block(1,13,4,WOOL)
Block(1,13,5,WOOL)
Block(1,13,6,WOOL)
Block(1,13,7,WOOL)
Block(1,14,-7,WOOL)
Block(1,14,-6,WOOL)
Block(1,14,-5,WOOL)
Block(1,14,-4,WOOL)
Block(1,14,-3,WOOL)
Block(1,14,-2,WOOL)
Block(1,14,-1,WOOL)
Block(1,14,0,WOOL)
Block(1,14,1,WOOL)
Block(1,14,2,WOOL)
Block(1,14,3,WOOL)
Block(1,14,4,WOOL)
Block(1,14,5,WOOL)
Block(1,14,6,WOOL)
Block(1,14,7,WOOL)
Block(1,14,8,WOOL)
Block(1,15,-7,WOOL)
Block(1,15,-6,WOOL)
Block(1,15,-5,WOOL)
Block(1,15,-4,WOOL)
Block(1,15,-3,WOOL)
Block(1,15,-2,WOOL)
Block(1,15,-1,WOOL)
Block(1,15,0,WOOL)
Block(1,15,1,WOOL)
Block(1,15,2,WOOL)
Block(1,15,3,WOOL)
Block(1,15,4,WOOL)
Block(1,15,5,WOOL)
Block(1,15,6,WOOL)
Block(1,15,7,WOOL)
Block(1,15,8,WOOL)
Block(1,16,-7,WOOL)
Block(1,16,-6,WOOL)
Block(1,16,-5,WOOL)
Block(1,16,-4,WOOL)
Block(1,16,-3,WOOL)
Block(1,16,-2,WOOL)
Block(1,16,-1,WOOL)
Block(1,16,0,WOOL)
Block(1,16,1,WOOL)
Block(1,16,2,WOOL)
Block(1,16,3,WOOL)
Block(1,16,4,WOOL)
Block(1,16,5,WOOL)
Block(1,16,6,WOOL)
Block(1,17,-7,WOOL)
Block(1,17,-6,WOOL)
Block(1,17,-5,WOOL)
Block(1,17,-4,WOOL)
Block(1,17,-3,WOOL)
Block(1,17,-2,WOOL)
Block(1,17,-1,WOOL)
Block(1,17,0,WOOL)
Block(1,17,1,WOOL)
Block(1,17,2,WOOL)
Block(1,17,3,WOOL)
Block(1,17,4,WOOL)
Block(1,17,5,WOOL)
Block(1,17,6,WOOL)
Block(1,18,-7,WOOL)
Block(1,18,-6,WOOL)
Block(1,18,-5,WOOL)
Block(1,18,-4,WOOL)
Block(1,18,-3,WOOL)
Block(1,18,-2,WOOL)
Block(1,18,-1,WOOL)
Block(1,18,0,WOOL)
Block(1,18,1,WOOL)
Block(1,18,2,WOOL)
Block(1,18,3,WOOL)
Block(1,18,4,WOOL)
Block(1,18,5,WOOL)
Block(1,18,6,WOOL)
Block(1,19,-7,WOOL)
Block(1,19,-6,WOOL)
Block(1,19,-5,WOOL)
Block(1,19,-4,WOOL)
Block(1,19,-3,WOOL)
Block(1,19,-2,WOOL)
Block(1,19,-1,WOOL)
Block(1,19,0,WOOL)
Block(1,19,1,WOOL)
Block(1,19,2,WOOL)
Block(1,19,3,WOOL)
Block(1,19,4,WOOL)
Block(1,19,5,WOOL)
Block(1,19,6,WOOL)
Block(1,19,7,WOOL)
Block(1,19,8,WOOL)
Block(1,20,-7,WOOL)
Block(1,20,-6,WOOL)
Block(1,20,-5,WOOL)
Block(1,20,-4,WOOL)
Block(1,20,-3,WOOL)
Block(1,20,-2,WOOL)
Block(1,20,-1,WOOL)
Block(1,20,0,WOOL)
Block(1,20,1,WOOL)
Block(1,20,2,WOOL)
Block(1,20,3,WOOL)
Block(1,20,4,WOOL)
Block(1,20,5,WOOL)
Block(1,20,6,WOOL)
Block(1,21,-7,WOOL)
Block(1,21,-6,WOOL)
Block(1,21,-5,WOOL)
Block(1,21,-4,WOOL)
Block(1,21,-3,WOOL)
Block(1,21,-2,WOOL)
Block(1,21,-1,WOOL)
Block(1,21,0,WOOL)
Block(1,21,1,WOOL)
Block(1,21,2,WOOL)
Block(1,21,3,WOOL)
Block(1,21,4,WOOL)
Block(1,21,5,WOOL)
Block(1,21,6,WOOL)
Block(1,22,-7,WOOL)
Block(1,22,-6,WOOL)
Block(1,22,-5,WOOL)
Block(1,22,-4,WOOL)
Block(1,22,-3,WOOL)
Block(1,22,-2,WOOL)
Block(1,22,-1,WOOL)
Block(1,22,0,WOOL)
Block(1,22,1,WOOL)
Block(1,22,2,WOOL)
Block(1,22,3,WOOL)
Block(1,22,4,WOOL)
Block(1,22,5,WOOL)
Block(1,22,6,WOOL)
Block(1,23,-7,WOOL)
Block(1,23,-6,WOOL)
Block(1,23,-5,WOOL)
Block(1,23,-4,WOOL)
Block(1,23,-3,WOOL)
Block(1,23,-2,WOOL)
Block(1,23,-1,WOOL)
Block(1,23,0,WOOL)
Block(1,23,1,WOOL)
Block(1,23,2,WOOL)
Block(1,23,3,WOOL)
Block(1,23,4,WOOL)
Block(1,23,5,WOOL)
Block(1,23,6,WOOL)
Block(1,23,7,WOOL)
Block(1,23,8,WOOL)
Block(1,24,-7,WOOL)
Block(1,24,-6,WOOL)
Block(1,24,-5,WOOL)
Block(1,24,-4,WOOL)
Block(1,24,-3,WOOL)
Block(1,24,-2,WOOL)
Block(1,24,-1,WOOL)
Block(1,24,0,WOOL)
Block(1,24,1,WOOL)
Block(1,24,2,WOOL)
Block(1,24,3,WOOL)
Block(1,24,4,WOOL)
Block(1,24,5,WOOL)
Block(1,24,6,WOOL)
Block(1,24,7,WOOL)
Block(1,24,8,WOOL)
Block(2,8,1,WOOL)
Block(2,9,-2,WOOL)
Block(2,9,-1,WOOL)
Block(2,9,0,WOOL)
Block(2,9,1,WOOL)
Block(2,9,2,WOOL)
Block(2,9,3,WOOL)
Block(2,10,-4,WOOL)
Block(2,10,-3,WOOL)
Block(2,10,-2,WOOL)
Block(2,10,-1,WOOL)
Block(2,10,0,WOOL)
Block(2,10,1,WOOL)
Block(2,10,2,WOOL)
Block(2,10,3,WOOL)
Block(2,11,-6,WOOL)
Block(2,11,-5,WOOL)
Block(2,11,-4,WOOL)
Block(2,11,-3,WOOL)
Block(2,11,-2,WOOL)
Block(2,11,-1,WOOL)
Block(2,11,0,WOOL)
Block(2,11,1,WOOL)
Block(2,11,2,WOOL)
Block(2,11,3,WOOL)
Block(2,11,4,WOOL)
Block(2,12,-6,WOOL)
Block(2,12,-5,WOOL)
Block(2,12,-4,WOOL)
Block(2,12,-3,WOOL)
Block(2,12,-2,WOOL)
Block(2,12,-1,WOOL)
Block(2,12,0,WOOL)
Block(2,12,1,WOOL)
Block(2,12,2,WOOL)
Block(2,12,3,WOOL)
Block(2,12,4,WOOL)
Block(2,13,-6,WOOL)
Block(2,13,-5,WOOL)
Block(2,13,-4,WOOL)
Block(2,13,-3,WOOL)
Block(2,13,-2,WOOL)
Block(2,13,-1,WOOL)
Block(2,13,0,WOOL)
Block(2,13,1,WOOL)
Block(2,13,2,WOOL)
Block(2,13,3,WOOL)
Block(2,13,4,WOOL)
Block(2,14,-6,WOOL)
Block(2,14,-5,WOOL)
Block(2,14,-4,WOOL)
Block(2,14,-3,WOOL)
Block(2,14,-2,WOOL)
Block(2,14,-1,WOOL)
Block(2,14,0,WOOL)
Block(2,14,1,WOOL)
Block(2,14,2,WOOL)
Block(2,14,3,WOOL)
Block(2,14,4,WOOL)
Block(2,15,-7,WOOL)
Block(2,15,-6,WOOL)
Block(2,15,-5,WOOL)
Block(2,15,-4,WOOL)
Block(2,15,-3,WOOL)
Block(2,15,-2,WOOL)
Block(2,15,-1,WOOL)
Block(2,15,0,WOOL)
Block(2,15,1,WOOL)
Block(2,15,2,WOOL)
Block(2,15,3,WOOL)
Block(2,15,4,WOOL)
Block(2,16,-6,WOOL)
Block(2,16,-5,WOOL)
Block(2,16,-4,WOOL)
Block(2,16,-3,WOOL)
Block(2,16,-2,WOOL)
Block(2,16,-1,WOOL)
Block(2,16,0,WOOL)
Block(2,16,2,WOOL)
Block(2,17,-6,WOOL)
Block(2,17,-5,WOOL)
Block(2,17,-4,WOOL)
Block(2,17,-3,WOOL)
Block(2,17,-2,WOOL)
Block(2,17,-1,WOOL)
Block(2,17,0,WOOL)
Block(2,17,1,WOOL)
Block(2,17,2,WOOL)
Block(2,17,3,WOOL)
Block(2,18,-6,WOOL)
Block(2,18,-5,WOOL)
Block(2,18,-4,WOOL)
Block(2,18,-3,WOOL)
Block(2,18,-2,WOOL)
Block(2,18,-1,WOOL)
Block(2,18,0,WOOL)
Block(2,18,1,WOOL)
Block(2,18,2,WOOL)
Block(2,18,3,WOOL)
Block(2,19,-7,WOOL)
Block(2,19,-6,WOOL)
Block(2,19,-5,WOOL)
Block(2,19,-4,WOOL)
Block(2,19,-3,WOOL)
Block(2,19,-2,WOOL)
Block(2,19,-1,WOOL)
Block(2,19,0,WOOL)
Block(2,19,1,WOOL)
Block(2,19,2,WOOL)
Block(2,19,3,WOOL)
Block(2,19,4,WOOL)
Block(2,19,5,WOOL)
Block(2,19,6,WOOL)
Block(2,20,-6,WOOL)
Block(2,20,-5,WOOL)
Block(2,20,-4,WOOL)
Block(2,20,-3,WOOL)
Block(2,20,-2,WOOL)
Block(2,20,-1,WOOL)
Block(2,20,0,WOOL)
Block(2,20,1,WOOL)
Block(2,20,2,WOOL)
Block(2,20,3,WOOL)
Block(2,21,-6,WOOL)
Block(2,21,-5,WOOL)
Block(2,21,-4,WOOL)
Block(2,21,-3,WOOL)
Block(2,21,-2,WOOL)
Block(2,21,-1,WOOL)
Block(2,21,0,WOOL)
Block(2,21,1,WOOL)
Block(2,21,2,WOOL)
Block(2,21,3,WOOL)
Block(2,22,-6,WOOL)
Block(2,22,-5,WOOL)
Block(2,22,-4,WOOL)
Block(2,22,-3,WOOL)
Block(2,22,-2,WOOL)
Block(2,22,-1,WOOL)
Block(2,22,0,WOOL)
Block(2,22,1,WOOL)
Block(2,22,2,WOOL)
Block(2,22,3,WOOL)
Block(2,23,-6,WOOL)
Block(2,23,-5,WOOL)
Block(2,23,-4,WOOL)
Block(2,23,-3,WOOL)
Block(2,23,-2,WOOL)
Block(2,23,-1,WOOL)
Block(2,23,0,WOOL)
Block(2,23,1,WOOL)
Block(2,23,2,WOOL)
Block(2,23,3,WOOL)
Block(2,24,-7,WOOL)
Block(2,24,-6,WOOL)
Block(2,24,-5,WOOL)
Block(2,24,-4,WOOL)
Block(2,24,-3,WOOL)
Block(2,24,-2,WOOL)
Block(2,24,-1,WOOL)
Block(2,24,0,WOOL)
Block(2,24,1,WOOL)
Block(2,24,2,WOOL)
Block(2,24,3,WOOL)
Block(3,11,-1,WOOL)
Block(3,11,0,WOOL)
Block(3,12,-1,WOOL)
Block(3,12,0,WOOL)
Block(3,13,-1,WOOL)
Block(3,13,0,WOOL)
Block(3,14,-1,WOOL)
Block(3,14,0,WOOL)
Block(3,15,-1,WOOL)
Block(3,15,0,WOOL)
Block(3,19,-2,WOOL)
Block(3,19,-1,WOOL)
Block(3,19,0,WOOL)
Block(3,23,-3,WOOL)
Block(3,24,-3,WOOL)

#######################################################################
# +-----------------------------------------------------------------+ #
# |                            BO3 checks                           | #
# +-----------------------------------------------------------------+ #
#######################################################################


#######################################################################
# +-----------------------------------------------------------------+ #
# |                             Branches                            | #
# +-----------------------------------------------------------------+ #
#######################################################################


#######################################################################
# +-----------------------------------------------------------------+ #
# |                         EntityFunctions                         | #
# +-----------------------------------------------------------------+ #
#######################################################################

