
#######################################################################
# +-----------------------------------------------------------------+ #
# |                            BO3 object                           | #
# +-----------------------------------------------------------------+ #
#######################################################################

Author: Unknown

Description: This BO3 was converted from a schematic using the MineCraft Worlds Editor. Unfortunately the author and description information for the schematic could not be found. If you know who the author of the schematic is then please tell the author of this BO3!

Version: 3

SettingsMode: WriteWithoutComments


#######################################################################
# +-----------------------------------------------------------------+ #
# |                          Main settings                          | #
# +-----------------------------------------------------------------+ #
#######################################################################

Tree: false

Frequency: 40

Rarity: 100.0

RotateRandomly: false

SpawnHeight: highestBlock

SpawnHeightOffset: 0

SpawnHeightVariance: 0

##############################
# Height Limits for the BO3. #
##############################

MinHeight: 0

MaxHeight: 256

######################
# Extrusion settings #
######################

ExtrudeMode: None

ExtrudeThroughBlocks: AIR

MaxBranchDepth: 10

ExcludedBiomes: All


#######################################################################
# +-----------------------------------------------------------------+ #
# |                      Source block settings                      | #
# +-----------------------------------------------------------------+ #
#######################################################################

SourceBlocks: AIR

MaxPercentageOutsideSourceBlock: 100

OutsideSourceBlock: placeAnyway


#######################################################################
# +-----------------------------------------------------------------+ #
# |                              Blocks                             | #
# +-----------------------------------------------------------------+ #
#######################################################################

Block(-8,0,-2,WOOL)
Block(-8,0,-1,WOOL)
Block(-8,0,0,WOOL)
Block(-8,0,1,WOOL)
Block(-8,0,2,WOOL)
Block(-8,0,4,WOOL)
Block(-8,0,5,WOOL)
Block(-8,1,-2,WOOL)
Block(-8,1,-1,WOOL)
Block(-8,1,0,WOOL)
Block(-8,1,1,WOOL)
Block(-8,1,2,WOOL)
Block(-8,1,4,WOOL)
Block(-8,1,5,WOOL)
Block(-8,2,-3,WOOL)
Block(-8,2,-2,WOOL)
Block(-8,2,-1,WOOL)
Block(-8,2,0,WOOL)
Block(-8,2,1,WOOL)
Block(-8,2,2,WOOL)
Block(-8,2,3,WOOL)
Block(-8,2,4,WOOL)
Block(-8,2,5,WOOL)
Block(-8,3,-3,WOOL)
Block(-8,3,-2,WOOL)
Block(-8,3,-1,WOOL)
Block(-8,3,0,WOOL)
Block(-8,3,1,WOOL)
Block(-8,3,2,WOOL)
Block(-8,3,3,WOOL)
Block(-8,3,4,WOOL)
Block(-8,3,5,WOOL)
Block(-8,3,6,WOOL)
Block(-8,4,-3,WOOL)
Block(-8,4,-2,WOOL)
Block(-8,4,-1,WOOL)
Block(-8,4,0,WOOL)
Block(-8,4,1,WOOL)
Block(-8,4,2,WOOL)
Block(-8,4,3,WOOL)
Block(-8,4,4,WOOL)
Block(-8,4,5,WOOL)
Block(-8,4,6,WOOL)
Block(-8,5,-3,WOOL)
Block(-8,5,-2,WOOL)
Block(-8,5,-1,WOOL)
Block(-8,5,0,WOOL)
Block(-8,5,1,WOOL)
Block(-8,5,2,WOOL)
Block(-8,5,3,WOOL)
Block(-8,5,4,WOOL)
Block(-8,5,5,WOOL)
Block(-8,5,6,WOOL)
Block(-8,6,-3,WOOL)
Block(-8,6,-2,WOOL)
Block(-8,6,-1,WOOL)
Block(-8,6,0,WOOL)
Block(-8,6,1,WOOL)
Block(-8,6,2,WOOL)
Block(-8,6,3,WOOL)
Block(-8,6,4,WOOL)
Block(-8,6,5,WOOL)
Block(-8,6,6,WOOL)
Block(-8,7,-4,WOOL)
Block(-8,7,-3,WOOL)
Block(-8,7,-2,WOOL)
Block(-8,7,-1,WOOL)
Block(-8,7,0,WOOL)
Block(-8,7,1,WOOL)
Block(-8,7,2,WOOL)
Block(-8,7,3,WOOL)
Block(-8,7,4,WOOL)
Block(-8,7,5,WOOL)
Block(-8,7,6,WOOL)
Block(-8,8,-4,WOOL)
Block(-8,8,-3,WOOL)
Block(-8,8,-2,WOOL)
Block(-8,8,-1,WOOL)
Block(-8,8,0,WOOL)
Block(-8,8,1,WOOL)
Block(-8,8,2,WOOL)
Block(-8,8,3,WOOL)
Block(-8,8,4,WOOL)
Block(-8,8,5,WOOL)
Block(-8,8,6,WOOL)
Block(-8,8,7,WOOL)
Block(-8,9,-4,WOOL)
Block(-8,9,-3,WOOL)
Block(-8,9,-2,WOOL)
Block(-8,9,-1,WOOL)
Block(-8,9,0,WOOL)
Block(-8,9,1,WOOL)
Block(-8,9,2,WOOL)
Block(-8,9,3,WOOL)
Block(-8,9,4,WOOL)
Block(-8,9,5,WOOL)
Block(-8,9,6,WOOL)
Block(-8,9,7,WOOL)
Block(-8,10,-4,WOOL)
Block(-8,10,-3,WOOL)
Block(-8,10,-2,WOOL)
Block(-8,10,-1,WOOL)
Block(-8,10,0,WOOL)
Block(-8,10,1,WOOL)
Block(-8,10,2,WOOL)
Block(-8,10,3,WOOL)
Block(-8,10,4,WOOL)
Block(-8,10,5,WOOL)
Block(-8,10,6,WOOL)
Block(-8,10,7,WOOL)
Block(-8,11,-5,WOOL)
Block(-8,11,-4,WOOL)
Block(-8,11,-3,WOOL)
Block(-8,11,-2,WOOL)
Block(-8,11,-1,WOOL)
Block(-8,11,0,WOOL)
Block(-8,11,1,WOOL)
Block(-8,11,2,WOOL)
Block(-8,11,3,WOOL)
Block(-8,11,4,WOOL)
Block(-8,11,5,WOOL)
Block(-8,11,6,WOOL)
Block(-8,11,7,WOOL)
Block(-8,12,-5,WOOL)
Block(-8,12,-4,WOOL)
Block(-8,12,-3,WOOL)
Block(-8,12,-2,WOOL)
Block(-8,12,-1,WOOL)
Block(-8,12,0,WOOL)
Block(-8,12,1,WOOL)
Block(-8,12,2,WOOL)
Block(-8,12,3,WOOL)
Block(-8,12,4,WOOL)
Block(-8,12,5,WOOL)
Block(-8,12,6,WOOL)
Block(-8,12,7,WOOL)
Block(-8,13,-5,WOOL)
Block(-8,13,-4,WOOL)
Block(-8,13,-3,WOOL)
Block(-8,13,-2,WOOL)
Block(-8,13,-1,WOOL)
Block(-8,13,0,WOOL)
Block(-8,13,1,WOOL)
Block(-8,13,2,WOOL)
Block(-8,13,3,WOOL)
Block(-8,13,4,WOOL)
Block(-8,13,5,WOOL)
Block(-8,13,6,WOOL)
Block(-8,13,7,WOOL)
Block(-8,14,-5,WOOL)
Block(-8,14,-4,WOOL)
Block(-8,14,-3,WOOL)
Block(-8,14,-2,WOOL)
Block(-8,14,-1,WOOL)
Block(-8,14,0,WOOL)
Block(-8,14,1,WOOL)
Block(-8,14,2,WOOL)
Block(-8,14,3,WOOL)
Block(-8,14,4,WOOL)
Block(-8,14,5,WOOL)
Block(-8,14,6,WOOL)
Block(-8,14,7,WOOL)
Block(-8,15,-5,WOOL)
Block(-8,15,-4,WOOL)
Block(-8,15,-3,WOOL)
Block(-8,15,-2,WOOL)
Block(-8,15,-1,WOOL)
Block(-8,15,0,WOOL)
Block(-8,15,1,WOOL)
Block(-8,15,2,WOOL)
Block(-8,15,3,WOOL)
Block(-8,15,4,WOOL)
Block(-8,15,5,WOOL)
Block(-8,15,6,WOOL)
Block(-8,15,7,WOOL)
Block(-8,16,-4,WOOL)
Block(-8,16,-3,WOOL)
Block(-8,16,-2,WOOL)
Block(-8,16,-1,WOOL)
Block(-8,16,0,WOOL)
Block(-8,16,1,WOOL)
Block(-8,16,2,WOOL)
Block(-8,16,3,WOOL)
Block(-8,16,4,WOOL)
Block(-8,16,5,WOOL)
Block(-8,16,6,WOOL)
Block(-8,17,-4,WOOL)
Block(-8,17,-3,WOOL)
Block(-8,17,-2,WOOL)
Block(-8,17,-1,WOOL)
Block(-8,17,0,WOOL)
Block(-8,17,1,WOOL)
Block(-8,17,2,WOOL)
Block(-8,17,3,WOOL)
Block(-8,17,4,WOOL)
Block(-8,17,5,WOOL)
Block(-8,17,6,WOOL)
Block(-8,17,7,WOOL)
Block(-8,18,-4,WOOL)
Block(-8,18,-3,WOOL)
Block(-8,18,-2,WOOL)
Block(-8,18,-1,WOOL)
Block(-8,18,0,WOOL)
Block(-8,18,1,WOOL)
Block(-8,18,2,WOOL)
Block(-8,18,3,WOOL)
Block(-8,18,4,WOOL)
Block(-8,18,5,WOOL)
Block(-8,18,6,WOOL)
Block(-8,18,7,WOOL)
Block(-8,19,-5,WOOL)
Block(-8,19,-4,WOOL)
Block(-8,19,-3,WOOL)
Block(-8,19,-2,WOOL)
Block(-8,19,-1,WOOL)
Block(-8,19,0,WOOL)
Block(-8,19,1,WOOL)
Block(-8,19,2,WOOL)
Block(-8,19,3,WOOL)
Block(-8,19,4,WOOL)
Block(-8,19,5,WOOL)
Block(-8,19,6,WOOL)
Block(-8,19,7,WOOL)
Block(-8,19,8,WOOL)
Block(-8,20,-4,WOOL)
Block(-8,20,-3,WOOL)
Block(-8,20,-2,WOOL)
Block(-8,20,-1,WOOL)
Block(-8,20,0,WOOL)
Block(-8,20,1,WOOL)
Block(-8,20,2,WOOL)
Block(-8,20,3,WOOL)
Block(-8,20,4,WOOL)
Block(-8,20,5,WOOL)
Block(-8,20,6,WOOL)
Block(-8,20,7,WOOL)
Block(-8,21,-4,WOOL)
Block(-8,21,-3,WOOL)
Block(-8,21,-2,WOOL)
Block(-8,21,-1,WOOL)
Block(-8,21,0,WOOL)
Block(-8,21,1,WOOL)
Block(-8,21,2,WOOL)
Block(-8,21,3,WOOL)
Block(-8,21,4,WOOL)
Block(-8,21,5,WOOL)
Block(-8,21,6,WOOL)
Block(-8,21,7,WOOL)
Block(-8,22,-4,WOOL)
Block(-8,22,-3,WOOL)
Block(-8,22,-2,WOOL)
Block(-8,22,-1,WOOL)
Block(-8,22,0,WOOL)
Block(-8,22,1,WOOL)
Block(-8,22,2,WOOL)
Block(-8,22,3,WOOL)
Block(-8,22,4,WOOL)
Block(-8,22,5,WOOL)
Block(-8,22,6,WOOL)
Block(-8,23,-5,WOOL)
Block(-8,23,-4,WOOL)
Block(-8,23,-3,WOOL)
Block(-8,23,-2,WOOL)
Block(-8,23,-1,WOOL)
Block(-8,23,0,WOOL)
Block(-8,23,1,WOOL)
Block(-8,23,2,WOOL)
Block(-8,23,3,WOOL)
Block(-8,23,4,WOOL)
Block(-8,23,5,WOOL)
Block(-8,23,6,WOOL)
Block(-8,24,-6,WOOL)
Block(-8,24,-5,WOOL)
Block(-8,24,-4,WOOL)
Block(-8,24,-3,WOOL)
Block(-8,24,-2,WOOL)
Block(-8,24,-1,WOOL)
Block(-8,24,0,WOOL)
Block(-8,24,1,WOOL)
Block(-8,24,2,WOOL)
Block(-8,24,3,WOOL)
Block(-8,24,4,WOOL)
Block(-8,24,5,WOOL)
Block(-8,24,6,WOOL)
Block(-8,24,7,WOOL)
Block(-8,24,8,WOOL)
Block(-7,0,-2,WOOL)
Block(-7,0,-1,WOOL)
Block(-7,0,0,WOOL)
Block(-7,0,1,WOOL)
Block(-7,0,2,WOOL)
Block(-7,1,-2,WOOL)
Block(-7,1,-1,WOOL)
Block(-7,1,0,WOOL)
Block(-7,1,1,WOOL)
Block(-7,1,2,WOOL)
Block(-7,2,-4,WOOL)
Block(-7,2,-3,WOOL)
Block(-7,2,-2,WOOL)
Block(-7,2,-1,WOOL)
Block(-7,2,0,WOOL)
Block(-7,2,1,WOOL)
Block(-7,2,2,WOOL)
Block(-7,3,-4,WOOL)
Block(-7,3,-3,WOOL)
Block(-7,3,-2,WOOL)
Block(-7,3,-1,WOOL)
Block(-7,3,0,WOOL)
Block(-7,3,1,WOOL)
Block(-7,3,2,WOOL)
Block(-7,3,3,WOOL)
Block(-7,3,4,WOOL)
Block(-7,3,5,WOOL)
Block(-7,4,-4,WOOL)
Block(-7,4,-3,WOOL)
Block(-7,4,-2,WOOL)
Block(-7,4,-1,WOOL)
Block(-7,4,0,WOOL)
Block(-7,4,1,WOOL)
Block(-7,4,2,WOOL)
Block(-7,4,3,WOOL)
Block(-7,4,4,WOOL)
Block(-7,4,5,WOOL)
Block(-7,5,-4,WOOL)
Block(-7,5,-3,WOOL)
Block(-7,5,-2,WOOL)
Block(-7,5,-1,WOOL)
Block(-7,5,0,WOOL)
Block(-7,5,1,WOOL)
Block(-7,5,2,WOOL)
Block(-7,5,3,WOOL)
Block(-7,5,4,WOOL)
Block(-7,5,5,WOOL)
Block(-7,6,-4,WOOL)
Block(-7,6,-3,WOOL)
Block(-7,6,-2,WOOL)
Block(-7,6,-1,WOOL)
Block(-7,6,0,WOOL)
Block(-7,6,1,WOOL)
Block(-7,6,2,WOOL)
Block(-7,6,3,WOOL)
Block(-7,6,4,WOOL)
Block(-7,6,5,WOOL)
Block(-7,7,-6,WOOL)
Block(-7,7,-5,WOOL)
Block(-7,7,-4,WOOL)
Block(-7,7,-3,WOOL)
Block(-7,7,-2,WOOL)
Block(-7,7,-1,WOOL)
Block(-7,7,0,WOOL)
Block(-7,7,1,WOOL)
Block(-7,7,2,WOOL)
Block(-7,7,3,WOOL)
Block(-7,7,4,WOOL)
Block(-7,7,5,WOOL)
Block(-7,7,6,WOOL)
Block(-7,8,-6,WOOL)
Block(-7,8,-5,WOOL)
Block(-7,8,-4,WOOL)
Block(-7,8,-3,WOOL)
Block(-7,8,-2,WOOL)
Block(-7,8,-1,WOOL)
Block(-7,8,0,WOOL)
Block(-7,8,1,WOOL)
Block(-7,8,2,WOOL)
Block(-7,8,3,WOOL)
Block(-7,8,4,WOOL)
Block(-7,8,5,WOOL)
Block(-7,8,6,WOOL)
Block(-7,9,-6,WOOL)
Block(-7,9,-5,WOOL)
Block(-7,9,-4,WOOL)
Block(-7,9,-3,WOOL)
Block(-7,9,-2,WOOL)
Block(-7,9,-1,WOOL)
Block(-7,9,0,WOOL)
Block(-7,9,1,WOOL)
Block(-7,9,2,WOOL)
Block(-7,9,3,WOOL)
Block(-7,9,4,WOOL)
Block(-7,9,5,WOOL)
Block(-7,9,6,WOOL)
Block(-7,10,-6,WOOL)
Block(-7,10,-5,WOOL)
Block(-7,10,-4,WOOL)
Block(-7,10,-3,WOOL)
Block(-7,10,-2,WOOL)
Block(-7,10,-1,WOOL)
Block(-7,10,0,WOOL)
Block(-7,10,1,WOOL)
Block(-7,10,2,WOOL)
Block(-7,10,3,WOOL)
Block(-7,10,4,WOOL)
Block(-7,10,5,WOOL)
Block(-7,10,6,WOOL)
Block(-7,11,-7,WOOL)
Block(-7,11,-6,WOOL)
Block(-7,11,-5,WOOL)
Block(-7,11,-4,WOOL)
Block(-7,11,-3,WOOL)
Block(-7,11,-2,WOOL)
Block(-7,11,-1,WOOL)
Block(-7,11,0,WOOL)
Block(-7,11,1,WOOL)
Block(-7,11,2,WOOL)
Block(-7,11,3,WOOL)
Block(-7,11,4,WOOL)
Block(-7,11,5,WOOL)
Block(-7,11,6,WOOL)
Block(-7,11,7,WOOL)
Block(-7,12,-7,WOOL)
Block(-7,12,-6,WOOL)
Block(-7,12,-5,WOOL)
Block(-7,12,-4,WOOL)
Block(-7,12,-3,WOOL)
Block(-7,12,-2,WOOL)
Block(-7,12,-1,WOOL)
Block(-7,12,0,WOOL)
Block(-7,12,1,WOOL)
Block(-7,12,2,WOOL)
Block(-7,12,3,WOOL)
Block(-7,12,4,WOOL)
Block(-7,12,5,WOOL)
Block(-7,12,6,WOOL)
Block(-7,12,7,WOOL)
Block(-7,13,-7,WOOL)
Block(-7,13,-6,WOOL)
Block(-7,13,-5,WOOL)
Block(-7,13,-4,WOOL)
Block(-7,13,-3,WOOL)
Block(-7,13,-2,WOOL)
Block(-7,13,-1,WOOL)
Block(-7,13,0,WOOL)
Block(-7,13,1,WOOL)
Block(-7,13,2,WOOL)
Block(-7,13,3,WOOL)
Block(-7,13,4,WOOL)
Block(-7,13,5,WOOL)
Block(-7,13,6,WOOL)
Block(-7,13,7,WOOL)
Block(-7,14,-7,WOOL)
Block(-7,14,-6,WOOL)
Block(-7,14,-5,WOOL)
Block(-7,14,-4,WOOL)
Block(-7,14,-3,WOOL)
Block(-7,14,-2,WOOL)
Block(-7,14,-1,WOOL)
Block(-7,14,0,WOOL)
Block(-7,14,1,WOOL)
Block(-7,14,2,WOOL)
Block(-7,14,3,WOOL)
Block(-7,14,4,WOOL)
Block(-7,14,5,WOOL)
Block(-7,14,6,WOOL)
Block(-7,14,7,WOOL)
Block(-7,15,-7,WOOL)
Block(-7,15,-6,WOOL)
Block(-7,15,-5,WOOL)
Block(-7,15,-4,WOOL)
Block(-7,15,-3,WOOL)
Block(-7,15,-2,WOOL)
Block(-7,15,-1,WOOL)
Block(-7,15,0,WOOL)
Block(-7,15,1,WOOL)
Block(-7,15,2,WOOL)
Block(-7,15,3,WOOL)
Block(-7,15,4,WOOL)
Block(-7,15,5,WOOL)
Block(-7,15,6,WOOL)
Block(-7,15,7,WOOL)
Block(-7,16,-5,WOOL)
Block(-7,16,-4,WOOL)
Block(-7,16,-3,WOOL)
Block(-7,16,-2,WOOL)
Block(-7,16,-1,WOOL)
Block(-7,16,0,WOOL)
Block(-7,16,1,WOOL)
Block(-7,16,2,WOOL)
Block(-7,16,3,WOOL)
Block(-7,16,4,WOOL)
Block(-7,16,5,WOOL)
Block(-7,17,-6,WOOL)
Block(-7,17,-5,WOOL)
Block(-7,17,-4,WOOL)
Block(-7,17,-3,WOOL)
Block(-7,17,-2,WOOL)
Block(-7,17,-1,WOOL)
Block(-7,17,0,WOOL)
Block(-7,17,1,WOOL)
Block(-7,17,2,WOOL)
Block(-7,17,3,WOOL)
Block(-7,17,4,WOOL)
Block(-7,17,5,WOOL)
Block(-7,17,6,WOOL)
Block(-7,18,-6,WOOL)
Block(-7,18,-5,WOOL)
Block(-7,18,-4,WOOL)
Block(-7,18,-3,WOOL)
Block(-7,18,-2,WOOL)
Block(-7,18,-1,WOOL)
Block(-7,18,0,WOOL)
Block(-7,18,1,WOOL)
Block(-7,18,2,WOOL)
Block(-7,18,3,WOOL)
Block(-7,18,4,WOOL)
Block(-7,18,5,WOOL)
Block(-7,18,6,WOOL)
Block(-7,19,-7,WOOL)
Block(-7,19,-6,WOOL)
Block(-7,19,-5,WOOL)
Block(-7,19,-4,WOOL)
Block(-7,19,-3,WOOL)
Block(-7,19,-2,WOOL)
Block(-7,19,-1,WOOL)
Block(-7,19,0,WOOL)
Block(-7,19,1,WOOL)
Block(-7,19,2,WOOL)
Block(-7,19,3,WOOL)
Block(-7,19,4,WOOL)
Block(-7,19,5,WOOL)
Block(-7,19,6,WOOL)
Block(-7,19,7,WOOL)
Block(-7,20,-6,WOOL)
Block(-7,20,-5,WOOL)
Block(-7,20,-4,WOOL)
Block(-7,20,-3,WOOL)
Block(-7,20,-2,WOOL)
Block(-7,20,-1,WOOL)
Block(-7,20,0,WOOL)
Block(-7,20,1,WOOL)
Block(-7,20,2,WOOL)
Block(-7,20,3,WOOL)
Block(-7,20,4,WOOL)
Block(-7,20,5,WOOL)
Block(-7,20,6,WOOL)
Block(-7,21,-6,WOOL)
Block(-7,21,-5,WOOL)
Block(-7,21,-4,WOOL)
Block(-7,21,-3,WOOL)
Block(-7,21,-2,WOOL)
Block(-7,21,-1,WOOL)
Block(-7,21,0,WOOL)
Block(-7,21,1,WOOL)
Block(-7,21,2,WOOL)
Block(-7,21,3,WOOL)
Block(-7,21,4,WOOL)
Block(-7,21,5,WOOL)
Block(-7,21,6,WOOL)
Block(-7,22,-5,WOOL)
Block(-7,22,-4,WOOL)
Block(-7,22,-3,WOOL)
Block(-7,22,-2,WOOL)
Block(-7,22,-1,WOOL)
Block(-7,22,0,WOOL)
Block(-7,22,1,WOOL)
Block(-7,22,2,WOOL)
Block(-7,22,3,WOOL)
Block(-7,22,4,WOOL)
Block(-7,22,5,WOOL)
Block(-7,22,6,WOOL)
Block(-7,23,-5,WOOL)
Block(-7,23,-4,WOOL)
Block(-7,23,-3,WOOL)
Block(-7,23,-2,WOOL)
Block(-7,23,-1,WOOL)
Block(-7,23,0,WOOL)
Block(-7,23,1,WOOL)
Block(-7,23,2,WOOL)
Block(-7,23,3,WOOL)
Block(-7,23,4,WOOL)
Block(-7,23,5,WOOL)
Block(-7,23,6,WOOL)
Block(-7,24,-6,WOOL)
Block(-7,24,-5,WOOL)
Block(-7,24,-4,WOOL)
Block(-7,24,-3,WOOL)
Block(-7,24,-2,WOOL)
Block(-7,24,-1,WOOL)
Block(-7,24,0,WOOL)
Block(-7,24,1,WOOL)
Block(-7,24,2,WOOL)
Block(-7,24,3,WOOL)
Block(-7,24,4,WOOL)
Block(-7,24,5,WOOL)
Block(-7,24,6,WOOL)
Block(-7,24,7,WOOL)
Block(-6,0,-1,WOOL)
Block(-6,0,0,WOOL)
Block(-6,0,1,WOOL)
Block(-6,0,2,WOOL)
Block(-6,1,-1,WOOL)
Block(-6,1,0,WOOL)
Block(-6,1,1,WOOL)
Block(-6,1,2,WOOL)
Block(-6,2,-7,WOOL)
Block(-6,2,-6,WOOL)
Block(-6,2,-5,WOOL)
Block(-6,2,-4,WOOL)
Block(-6,2,-3,WOOL)
Block(-6,2,-2,WOOL)
Block(-6,2,-1,WOOL)
Block(-6,2,0,WOOL)
Block(-6,2,1,WOOL)
Block(-6,2,2,WOOL)
Block(-6,3,-7,WOOL)
Block(-6,3,-6,WOOL)
Block(-6,3,-5,WOOL)
Block(-6,3,-4,WOOL)
Block(-6,3,-3,WOOL)
Block(-6,3,-2,WOOL)
Block(-6,3,-1,WOOL)
Block(-6,3,0,WOOL)
Block(-6,3,1,WOOL)
Block(-6,3,2,WOOL)
Block(-6,3,3,WOOL)
Block(-6,4,-7,WOOL)
Block(-6,4,-6,WOOL)
Block(-6,4,-5,WOOL)
Block(-6,4,-4,WOOL)
Block(-6,4,-3,WOOL)
Block(-6,4,-2,WOOL)
Block(-6,4,-1,WOOL)
Block(-6,4,0,WOOL)
Block(-6,4,1,WOOL)
Block(-6,4,2,WOOL)
Block(-6,4,3,WOOL)
Block(-6,5,-7,WOOL)
Block(-6,5,-6,WOOL)
Block(-6,5,-5,WOOL)
Block(-6,5,-4,WOOL)
Block(-6,5,-3,WOOL)
Block(-6,5,-2,WOOL)
Block(-6,5,-1,WOOL)
Block(-6,5,0,WOOL)
Block(-6,5,1,WOOL)
Block(-6,5,2,WOOL)
Block(-6,5,3,WOOL)
Block(-6,6,-7,WOOL)
Block(-6,6,-6,WOOL)
Block(-6,6,-5,WOOL)
Block(-6,6,-4,WOOL)
Block(-6,6,-3,WOOL)
Block(-6,6,-2,WOOL)
Block(-6,6,-1,WOOL)
Block(-6,6,0,WOOL)
Block(-6,6,1,WOOL)
Block(-6,6,2,WOOL)
Block(-6,6,3,WOOL)
Block(-6,7,-7,WOOL)
Block(-6,7,-6,WOOL)
Block(-6,7,-5,WOOL)
Block(-6,7,-4,WOOL)
Block(-6,7,-3,WOOL)
Block(-6,7,-2,WOOL)
Block(-6,7,-1,WOOL)
Block(-6,7,0,WOOL)
Block(-6,7,1,WOOL)
Block(-6,7,2,WOOL)
Block(-6,7,3,WOOL)
Block(-6,7,4,WOOL)
Block(-6,8,-7,WOOL)
Block(-6,8,-6,WOOL)
Block(-6,8,-5,WOOL)
Block(-6,8,-4,WOOL)
Block(-6,8,-3,WOOL)
Block(-6,8,-2,WOOL)
Block(-6,8,-1,WOOL)
Block(-6,8,0,WOOL)
Block(-6,8,1,WOOL)
Block(-6,8,2,WOOL)
Block(-6,8,3,WOOL)
Block(-6,8,4,WOOL)
Block(-6,9,-7,WOOL)
Block(-6,9,-6,WOOL)
Block(-6,9,-5,WOOL)
Block(-6,9,-4,WOOL)
Block(-6,9,-3,WOOL)
Block(-6,9,-2,WOOL)
Block(-6,9,-1,WOOL)
Block(-6,9,0,WOOL)
Block(-6,9,1,WOOL)
Block(-6,9,2,WOOL)
Block(-6,9,3,WOOL)
Block(-6,9,4,WOOL)
Block(-6,10,-7,WOOL)
Block(-6,10,-6,WOOL)
Block(-6,10,-5,WOOL)
Block(-6,10,-4,WOOL)
Block(-6,10,-3,WOOL)
Block(-6,10,-2,WOOL)
Block(-6,10,-1,WOOL)
Block(-6,10,0,WOOL)
Block(-6,10,1,WOOL)
Block(-6,10,2,WOOL)
Block(-6,10,3,WOOL)
Block(-6,10,4,WOOL)
Block(-6,11,-7,WOOL)
Block(-6,11,-6,WOOL)
Block(-6,11,-5,WOOL)
Block(-6,11,-4,WOOL)
Block(-6,11,-3,WOOL)
Block(-6,11,-2,WOOL)
Block(-6,11,-1,WOOL)
Block(-6,11,0,WOOL)
Block(-6,11,1,WOOL)
Block(-6,11,2,WOOL)
Block(-6,11,3,WOOL)
Block(-6,11,4,WOOL)
Block(-6,11,5,WOOL)
Block(-6,11,6,WOOL)
Block(-6,12,-7,WOOL)
Block(-6,12,-6,WOOL)
Block(-6,12,-5,WOOL)
Block(-6,12,-4,WOOL)
Block(-6,12,-3,WOOL)
Block(-6,12,-2,WOOL)
Block(-6,12,-1,WOOL)
Block(-6,12,0,WOOL)
Block(-6,12,1,WOOL)
Block(-6,12,2,WOOL)
Block(-6,12,3,WOOL)
Block(-6,12,4,WOOL)
Block(-6,12,5,WOOL)
Block(-6,12,6,WOOL)
Block(-6,13,-7,WOOL)
Block(-6,13,-6,WOOL)
Block(-6,13,-5,WOOL)
Block(-6,13,-4,WOOL)
Block(-6,13,-3,WOOL)
Block(-6,13,-2,WOOL)
Block(-6,13,-1,WOOL)
Block(-6,13,0,WOOL)
Block(-6,13,1,WOOL)
Block(-6,13,2,WOOL)
Block(-6,13,3,WOOL)
Block(-6,13,4,WOOL)
Block(-6,13,5,WOOL)
Block(-6,13,6,WOOL)
Block(-6,14,-7,WOOL)
Block(-6,14,-6,WOOL)
Block(-6,14,-5,WOOL)
Block(-6,14,-4,WOOL)
Block(-6,14,-3,WOOL)
Block(-6,14,-2,WOOL)
Block(-6,14,-1,WOOL)
Block(-6,14,0,WOOL)
Block(-6,14,1,WOOL)
Block(-6,14,2,WOOL)
Block(-6,14,3,WOOL)
Block(-6,14,4,WOOL)
Block(-6,14,5,WOOL)
Block(-6,14,6,WOOL)
Block(-6,15,-7,WOOL)
Block(-6,15,-6,WOOL)
Block(-6,15,-5,WOOL)
Block(-6,15,-4,WOOL)
Block(-6,15,-3,WOOL)
Block(-6,15,-2,WOOL)
Block(-6,15,-1,WOOL)
Block(-6,15,0,WOOL)
Block(-6,15,1,WOOL)
Block(-6,15,2,WOOL)
Block(-6,15,3,WOOL)
Block(-6,15,4,WOOL)
Block(-6,15,5,WOOL)
Block(-6,15,6,WOOL)
Block(-6,16,-7,WOOL)
Block(-6,16,-6,WOOL)
Block(-6,16,-5,WOOL)
Block(-6,16,-4,WOOL)
Block(-6,16,-3,WOOL)
Block(-6,16,-2,WOOL)
Block(-6,16,-1,WOOL)
Block(-6,16,0,WOOL)
Block(-6,16,1,WOOL)
Block(-6,16,2,WOOL)
Block(-6,16,3,WOOL)
Block(-6,16,4,WOOL)
Block(-6,17,-7,WOOL)
Block(-6,17,-6,WOOL)
Block(-6,17,-5,WOOL)
Block(-6,17,-4,WOOL)
Block(-6,17,-3,WOOL)
Block(-6,17,-2,WOOL)
Block(-6,17,-1,WOOL)
Block(-6,17,0,WOOL)
Block(-6,17,1,WOOL)
Block(-6,17,2,WOOL)
Block(-6,17,3,WOOL)
Block(-6,17,4,WOOL)
Block(-6,17,5,WOOL)
Block(-6,18,-7,WOOL)
Block(-6,18,-6,WOOL)
Block(-6,18,-5,WOOL)
Block(-6,18,-4,WOOL)
Block(-6,18,-3,WOOL)
Block(-6,18,-2,WOOL)
Block(-6,18,-1,WOOL)
Block(-6,18,0,WOOL)
Block(-6,18,1,WOOL)
Block(-6,18,2,WOOL)
Block(-6,18,3,WOOL)
Block(-6,18,4,WOOL)
Block(-6,18,5,WOOL)
Block(-6,19,-7,WOOL)
Block(-6,19,-6,WOOL)
Block(-6,19,-5,WOOL)
Block(-6,19,-4,WOOL)
Block(-6,19,-3,WOOL)
Block(-6,19,-2,WOOL)
Block(-6,19,-1,WOOL)
Block(-6,19,0,WOOL)
Block(-6,19,1,WOOL)
Block(-6,19,2,WOOL)
Block(-6,19,3,WOOL)
Block(-6,19,4,WOOL)
Block(-6,19,5,WOOL)
Block(-6,19,6,WOOL)
Block(-6,20,-7,WOOL)
Block(-6,20,-6,WOOL)
Block(-6,20,-5,WOOL)
Block(-6,20,-4,WOOL)
Block(-6,20,-3,WOOL)
Block(-6,20,-2,WOOL)
Block(-6,20,-1,WOOL)
Block(-6,20,0,WOOL)
Block(-6,20,1,WOOL)
Block(-6,20,2,WOOL)
Block(-6,20,3,WOOL)
Block(-6,20,4,WOOL)
Block(-6,20,5,WOOL)
Block(-6,21,-7,WOOL)
Block(-6,21,-6,WOOL)
Block(-6,21,-5,WOOL)
Block(-6,21,-4,WOOL)
Block(-6,21,-3,WOOL)
Block(-6,21,-2,WOOL)
Block(-6,21,-1,WOOL)
Block(-6,21,0,WOOL)
Block(-6,21,1,WOOL)
Block(-6,21,2,WOOL)
Block(-6,21,3,WOOL)
Block(-6,21,4,WOOL)
Block(-6,21,5,WOOL)
Block(-6,22,-7,WOOL)
Block(-6,22,-6,WOOL)
Block(-6,22,-5,WOOL)
Block(-6,22,-4,WOOL)
Block(-6,22,-3,WOOL)
Block(-6,22,-2,WOOL)
Block(-6,22,-1,WOOL)
Block(-6,22,0,WOOL)
Block(-6,22,1,WOOL)
Block(-6,22,2,WOOL)
Block(-6,22,3,WOOL)
Block(-6,22,4,WOOL)
Block(-6,23,-7,WOOL)
Block(-6,23,-6,WOOL)
Block(-6,23,-5,WOOL)
Block(-6,23,-4,WOOL)
Block(-6,23,-3,WOOL)
Block(-6,23,-2,WOOL)
Block(-6,23,-1,WOOL)
Block(-6,23,0,WOOL)
Block(-6,23,1,WOOL)
Block(-6,23,2,WOOL)
Block(-6,23,3,WOOL)
Block(-6,23,4,WOOL)
Block(-6,24,-7,WOOL)
Block(-6,24,-6,WOOL)
Block(-6,24,-5,WOOL)
Block(-6,24,-4,WOOL)
Block(-6,24,-3,WOOL)
Block(-6,24,-2,WOOL)
Block(-6,24,-1,WOOL)
Block(-6,24,0,WOOL)
Block(-6,24,1,WOOL)
Block(-6,24,2,WOOL)
Block(-6,24,3,WOOL)
Block(-6,24,4,WOOL)
Block(-6,24,5,WOOL)
Block(-6,24,6,WOOL)
Block(-5,0,0,WOOL)
Block(-5,0,1,WOOL)
Block(-5,1,0,WOOL)
Block(-5,1,1,WOOL)
Block(-5,2,-7,WOOL)
Block(-5,2,-6,WOOL)
Block(-5,2,-5,WOOL)
Block(-5,2,-4,WOOL)
Block(-5,2,-3,WOOL)
Block(-5,2,-2,WOOL)
Block(-5,2,-1,WOOL)
Block(-5,2,0,WOOL)
Block(-5,2,1,WOOL)
Block(-5,3,-7,WOOL)
Block(-5,3,-6,WOOL)
Block(-5,3,-5,WOOL)
Block(-5,3,-4,WOOL)
Block(-5,3,-3,WOOL)
Block(-5,3,-2,WOOL)
Block(-5,3,-1,WOOL)
Block(-5,3,0,WOOL)
Block(-5,3,1,WOOL)
Block(-5,4,-7,WOOL)
Block(-5,4,-6,WOOL)
Block(-5,4,-5,WOOL)
Block(-5,4,-4,WOOL)
Block(-5,4,-3,WOOL)
Block(-5,4,-2,WOOL)
Block(-5,4,-1,WOOL)
Block(-5,4,0,WOOL)
Block(-5,4,1,WOOL)
Block(-5,5,-7,WOOL)
Block(-5,5,-6,WOOL)
Block(-5,5,-5,WOOL)
Block(-5,5,-4,WOOL)
Block(-5,5,-3,WOOL)
Block(-5,5,-2,WOOL)
Block(-5,5,-1,WOOL)
Block(-5,5,0,WOOL)
Block(-5,5,1,WOOL)
Block(-5,6,-7,WOOL)
Block(-5,6,-6,WOOL)
Block(-5,6,-5,WOOL)
Block(-5,6,-4,WOOL)
Block(-5,6,-3,WOOL)
Block(-5,6,-2,WOOL)
Block(-5,6,-1,WOOL)
Block(-5,6,0,WOOL)
Block(-5,6,1,WOOL)
Block(-5,7,-7,WOOL)
Block(-5,7,-6,WOOL)
Block(-5,7,-5,WOOL)
Block(-5,7,-4,WOOL)
Block(-5,7,-3,WOOL)
Block(-5,7,-2,WOOL)
Block(-5,7,-1,WOOL)
Block(-5,7,0,WOOL)
Block(-5,7,1,WOOL)
Block(-5,7,2,WOOL)
Block(-5,8,-7,WOOL)
Block(-5,8,-6,WOOL)
Block(-5,8,-5,WOOL)
Block(-5,8,-4,WOOL)
Block(-5,8,-3,WOOL)
Block(-5,8,-2,WOOL)
Block(-5,8,-1,WOOL)
Block(-5,8,0,WOOL)
Block(-5,8,1,WOOL)
Block(-5,8,2,WOOL)
Block(-5,9,-7,WOOL)
Block(-5,9,-6,WOOL)
Block(-5,9,-5,WOOL)
Block(-5,9,-4,WOOL)
Block(-5,9,-3,WOOL)
Block(-5,9,-2,WOOL)
Block(-5,9,-1,WOOL)
Block(-5,9,0,WOOL)
Block(-5,9,1,WOOL)
Block(-5,9,2,WOOL)
Block(-5,9,3,WOOL)
Block(-5,10,-7,WOOL)
Block(-5,10,-6,WOOL)
Block(-5,10,-5,WOOL)
Block(-5,10,-4,WOOL)
Block(-5,10,-3,WOOL)
Block(-5,10,-2,WOOL)
Block(-5,10,-1,WOOL)
Block(-5,10,0,WOOL)
Block(-5,10,1,WOOL)
Block(-5,10,2,WOOL)
Block(-5,10,3,WOOL)
Block(-5,11,-7,WOOL)
Block(-5,11,-6,WOOL)
Block(-5,11,-5,WOOL)
Block(-5,11,-4,WOOL)
Block(-5,11,-3,WOOL)
Block(-5,11,-2,WOOL)
Block(-5,11,-1,WOOL)
Block(-5,11,0,WOOL)
Block(-5,11,1,WOOL)
Block(-5,11,2,WOOL)
Block(-5,11,3,WOOL)
Block(-5,11,4,WOOL)
Block(-5,12,-7,WOOL)
Block(-5,12,-6,WOOL)
Block(-5,12,-5,WOOL)
Block(-5,12,-4,WOOL)
Block(-5,12,-3,WOOL)
Block(-5,12,-2,WOOL)
Block(-5,12,-1,WOOL)
Block(-5,12,0,WOOL)
Block(-5,12,1,WOOL)
Block(-5,12,2,WOOL)
Block(-5,12,3,WOOL)
Block(-5,12,4,WOOL)
Block(-5,13,-7,WOOL)
Block(-5,13,-6,WOOL)
Block(-5,13,-5,WOOL)
Block(-5,13,-4,WOOL)
Block(-5,13,-3,WOOL)
Block(-5,13,-2,WOOL)
Block(-5,13,-1,WOOL)
Block(-5,13,0,WOOL)
Block(-5,13,1,WOOL)
Block(-5,13,2,WOOL)
Block(-5,13,3,WOOL)
Block(-5,13,4,WOOL)
Block(-5,14,-7,WOOL)
Block(-5,14,-6,WOOL)
Block(-5,14,-5,WOOL)
Block(-5,14,-4,WOOL)
Block(-5,14,-3,WOOL)
Block(-5,14,-2,WOOL)
Block(-5,14,-1,WOOL)
Block(-5,14,0,WOOL)
Block(-5,14,1,WOOL)
Block(-5,14,2,WOOL)
Block(-5,14,3,WOOL)
Block(-5,14,4,WOOL)
Block(-5,15,-7,WOOL)
Block(-5,15,-6,WOOL)
Block(-5,15,-5,WOOL)
Block(-5,15,-4,WOOL)
Block(-5,15,-3,WOOL)
Block(-5,15,-2,WOOL)
Block(-5,15,-1,WOOL)
Block(-5,15,0,WOOL)
Block(-5,15,1,WOOL)
Block(-5,15,2,WOOL)
Block(-5,15,3,WOOL)
Block(-5,15,4,WOOL)
Block(-5,16,-7,WOOL)
Block(-5,16,-6,WOOL)
Block(-5,16,-5,WOOL)
Block(-5,16,-4,WOOL)
Block(-5,16,-3,WOOL)
Block(-5,16,-2,WOOL)
Block(-5,16,-1,WOOL)
Block(-5,16,0,WOOL)
Block(-5,16,1,WOOL)
Block(-5,16,2,WOOL)
Block(-5,17,-7,WOOL)
Block(-5,17,-6,WOOL)
Block(-5,17,-5,WOOL)
Block(-5,17,-4,WOOL)
Block(-5,17,-3,WOOL)
Block(-5,17,-2,WOOL)
Block(-5,17,-1,WOOL)
Block(-5,17,0,WOOL)
Block(-5,17,1,WOOL)
Block(-5,17,2,WOOL)
Block(-5,17,3,WOOL)
Block(-5,18,-7,WOOL)
Block(-5,18,-6,WOOL)
Block(-5,18,-5,WOOL)
Block(-5,18,-4,WOOL)
Block(-5,18,-3,WOOL)
Block(-5,18,-2,WOOL)
Block(-5,18,-1,WOOL)
Block(-5,18,0,WOOL)
Block(-5,18,1,WOOL)
Block(-5,18,2,WOOL)
Block(-5,18,3,WOOL)
Block(-5,19,-7,WOOL)
Block(-5,19,-6,WOOL)
Block(-5,19,-5,WOOL)
Block(-5,19,-4,WOOL)
Block(-5,19,-3,WOOL)
Block(-5,19,-2,WOOL)
Block(-5,19,-1,WOOL)
Block(-5,19,0,WOOL)
Block(-5,19,1,WOOL)
Block(-5,19,2,WOOL)
Block(-5,19,3,WOOL)
Block(-5,19,4,WOOL)
Block(-5,19,5,WOOL)
Block(-5,20,-7,WOOL)
Block(-5,20,-6,WOOL)
Block(-5,20,-5,WOOL)
Block(-5,20,-4,WOOL)
Block(-5,20,-3,WOOL)
Block(-5,20,-2,WOOL)
Block(-5,20,-1,WOOL)
Block(-5,20,0,WOOL)
Block(-5,20,1,WOOL)
Block(-5,20,2,WOOL)
Block(-5,20,3,WOOL)
Block(-5,21,-7,WOOL)
Block(-5,21,-6,WOOL)
Block(-5,21,-5,WOOL)
Block(-5,21,-4,WOOL)
Block(-5,21,-3,WOOL)
Block(-5,21,-2,WOOL)
Block(-5,21,-1,WOOL)
Block(-5,21,0,WOOL)
Block(-5,21,1,WOOL)
Block(-5,21,2,WOOL)
Block(-5,21,3,WOOL)
Block(-5,22,-7,WOOL)
Block(-5,22,-6,WOOL)
Block(-5,22,-5,WOOL)
Block(-5,22,-4,WOOL)
Block(-5,22,-3,WOOL)
Block(-5,22,-2,WOOL)
Block(-5,22,-1,WOOL)
Block(-5,22,0,WOOL)
Block(-5,22,1,WOOL)
Block(-5,22,2,WOOL)
Block(-5,23,-7,WOOL)
Block(-5,23,-6,WOOL)
Block(-5,23,-5,WOOL)
Block(-5,23,-4,WOOL)
Block(-5,23,-3,WOOL)
Block(-5,23,-2,WOOL)
Block(-5,23,-1,WOOL)
Block(-5,23,0,WOOL)
Block(-5,23,1,WOOL)
Block(-5,23,2,WOOL)
Block(-5,24,-7,WOOL)
Block(-5,24,-6,WOOL)
Block(-5,24,-5,WOOL)
Block(-5,24,-4,WOOL)
Block(-5,24,-3,WOOL)
Block(-5,24,-2,WOOL)
Block(-5,24,-1,WOOL)
Block(-5,24,0,WOOL)
Block(-5,24,1,WOOL)
Block(-5,24,2,WOOL)
Block(-5,24,3,WOOL)
Block(-5,24,4,WOOL)
Block(-5,24,5,WOOL)
Block(-4,2,-7,WOOL)
Block(-4,2,-6,WOOL)
Block(-4,2,-5,WOOL)
Block(-4,2,-4,WOOL)
Block(-4,2,-3,WOOL)
Block(-4,2,-2,WOOL)
Block(-4,2,-1,WOOL)
Block(-4,3,-7,WOOL)
Block(-4,3,-6,WOOL)
Block(-4,3,-5,WOOL)
Block(-4,3,-4,WOOL)
Block(-4,3,-3,WOOL)
Block(-4,3,-2,WOOL)
Block(-4,3,-1,WOOL)
Block(-4,4,-7,WOOL)
Block(-4,4,-6,WOOL)
Block(-4,4,-5,WOOL)
Block(-4,4,-4,WOOL)
Block(-4,4,-3,WOOL)
Block(-4,4,-2,WOOL)
Block(-4,4,-1,WOOL)
Block(-4,5,-7,WOOL)
Block(-4,5,-6,WOOL)
Block(-4,5,-5,WOOL)
Block(-4,5,-4,WOOL)
Block(-4,5,-3,WOOL)
Block(-4,5,-2,WOOL)
Block(-4,5,-1,WOOL)
Block(-4,6,-7,WOOL)
Block(-4,6,-6,WOOL)
Block(-4,6,-5,WOOL)
Block(-4,6,-4,WOOL)
Block(-4,6,-3,WOOL)
Block(-4,6,-2,WOOL)
Block(-4,6,-1,WOOL)
Block(-4,7,-7,WOOL)
Block(-4,7,-6,WOOL)
Block(-4,7,-5,WOOL)
Block(-4,7,-4,WOOL)
Block(-4,7,-3,WOOL)
Block(-4,7,-2,WOOL)
Block(-4,7,-1,WOOL)
Block(-4,7,0,WOOL)
Block(-4,8,-7,WOOL)
Block(-4,8,-6,WOOL)
Block(-4,8,-5,WOOL)
Block(-4,8,-4,WOOL)
Block(-4,8,-3,WOOL)
Block(-4,8,-2,WOOL)
Block(-4,8,-1,WOOL)
Block(-4,8,0,WOOL)
Block(-4,9,-7,WOOL)
Block(-4,9,-6,WOOL)
Block(-4,9,-5,WOOL)
Block(-4,9,-4,WOOL)
Block(-4,9,-3,WOOL)
Block(-4,9,-2,WOOL)
Block(-4,9,-1,WOOL)
Block(-4,9,0,WOOL)
Block(-4,10,-7,WOOL)
Block(-4,10,-6,WOOL)
Block(-4,10,-5,WOOL)
Block(-4,10,-4,WOOL)
Block(-4,10,-3,WOOL)
Block(-4,10,-2,WOOL)
Block(-4,10,-1,WOOL)
Block(-4,10,0,WOOL)
Block(-4,11,-7,WOOL)
Block(-4,11,-6,WOOL)
Block(-4,11,-5,WOOL)
Block(-4,11,-4,WOOL)
Block(-4,11,-3,WOOL)
Block(-4,11,-2,WOOL)
Block(-4,11,-1,WOOL)
Block(-4,11,0,WOOL)
Block(-4,11,1,WOOL)
Block(-4,11,2,WOOL)
Block(-4,12,-7,WOOL)
Block(-4,12,-6,WOOL)
Block(-4,12,-5,WOOL)
Block(-4,12,-4,WOOL)
Block(-4,12,-3,WOOL)
Block(-4,12,-2,WOOL)
Block(-4,12,-1,WOOL)
Block(-4,12,0,WOOL)
Block(-4,12,1,WOOL)
Block(-4,12,2,WOOL)
Block(-4,13,-7,WOOL)
Block(-4,13,-6,WOOL)
Block(-4,13,-5,WOOL)
Block(-4,13,-4,WOOL)
Block(-4,13,-3,WOOL)
Block(-4,13,-2,WOOL)
Block(-4,13,-1,WOOL)
Block(-4,13,0,WOOL)
Block(-4,13,1,WOOL)
Block(-4,13,2,WOOL)
Block(-4,14,-7,WOOL)
Block(-4,14,-6,WOOL)
Block(-4,14,-5,WOOL)
Block(-4,14,-4,WOOL)
Block(-4,14,-3,WOOL)
Block(-4,14,-2,WOOL)
Block(-4,14,-1,WOOL)
Block(-4,14,0,WOOL)
Block(-4,14,1,WOOL)
Block(-4,14,2,WOOL)
Block(-4,15,-7,WOOL)
Block(-4,15,-6,WOOL)
Block(-4,15,-5,WOOL)
Block(-4,15,-4,WOOL)
Block(-4,15,-3,WOOL)
Block(-4,15,-2,WOOL)
Block(-4,15,-1,WOOL)
Block(-4,15,0,WOOL)
Block(-4,15,1,WOOL)
Block(-4,15,2,WOOL)
Block(-4,16,-7,WOOL)
Block(-4,16,-6,WOOL)
Block(-4,16,-5,WOOL)
Block(-4,16,-4,WOOL)
Block(-4,16,-3,WOOL)
Block(-4,16,-2,WOOL)
Block(-4,16,-1,WOOL)
Block(-4,17,-7,WOOL)
Block(-4,17,-6,WOOL)
Block(-4,17,-5,WOOL)
Block(-4,17,-4,WOOL)
Block(-4,17,-3,WOOL)
Block(-4,17,-2,WOOL)
Block(-4,17,-1,WOOL)
Block(-4,17,0,WOOL)
Block(-4,18,-7,WOOL)
Block(-4,18,-6,WOOL)
Block(-4,18,-5,WOOL)
Block(-4,18,-4,WOOL)
Block(-4,18,-3,WOOL)
Block(-4,18,-2,WOOL)
Block(-4,18,-1,WOOL)
Block(-4,18,0,WOOL)
Block(-4,19,-7,WOOL)
Block(-4,19,-6,WOOL)
Block(-4,19,-5,WOOL)
Block(-4,19,-4,WOOL)
Block(-4,19,-3,WOOL)
Block(-4,19,-2,WOOL)
Block(-4,19,-1,WOOL)
Block(-4,19,0,WOOL)
Block(-4,19,1,WOOL)
Block(-4,19,2,WOOL)
Block(-4,19,3,WOOL)
Block(-4,20,-7,WOOL)
Block(-4,20,-6,WOOL)
Block(-4,20,-5,WOOL)
Block(-4,20,-4,WOOL)
Block(-4,20,-3,WOOL)
Block(-4,20,-2,WOOL)
Block(-4,20,-1,WOOL)
Block(-4,20,0,WOOL)
Block(-4,21,-7,WOOL)
Block(-4,21,-6,WOOL)
Block(-4,21,-5,WOOL)
Block(-4,21,-4,WOOL)
Block(-4,21,-3,WOOL)
Block(-4,21,-2,WOOL)
Block(-4,21,-1,WOOL)
Block(-4,21,0,WOOL)
Block(-4,22,-7,WOOL)
Block(-4,22,-6,WOOL)
Block(-4,22,-5,WOOL)
Block(-4,22,-4,WOOL)
Block(-4,22,-3,WOOL)
Block(-4,22,-2,WOOL)
Block(-4,22,-1,WOOL)
Block(-4,23,-7,WOOL)
Block(-4,23,-6,WOOL)
Block(-4,23,-5,WOOL)
Block(-4,23,-4,WOOL)
Block(-4,23,-3,WOOL)
Block(-4,23,-2,WOOL)
Block(-4,23,-1,WOOL)
Block(-4,23,0,WOOL)
Block(-4,23,1,WOOL)
Block(-4,24,-7,WOOL)
Block(-4,24,-6,WOOL)
Block(-4,24,-5,WOOL)
Block(-4,24,-4,WOOL)
Block(-4,24,-3,WOOL)
Block(-4,24,-2,WOOL)
Block(-4,24,-1,WOOL)
Block(-4,24,0,WOOL)
Block(-4,24,1,WOOL)
Block(-4,24,2,WOOL)
Block(-4,24,3,WOOL)
Block(-4,24,4,WOOL)
Block(-3,2,-7,WOOL)
Block(-3,2,-6,WOOL)
Block(-3,2,-5,WOOL)
Block(-3,2,-4,WOOL)
Block(-3,3,-7,WOOL)
Block(-3,3,-6,WOOL)
Block(-3,3,-5,WOOL)
Block(-3,3,-4,WOOL)
Block(-3,3,-3,WOOL)
Block(-3,4,-7,WOOL)
Block(-3,4,-6,WOOL)
Block(-3,4,-5,WOOL)
Block(-3,4,-4,WOOL)
Block(-3,4,-3,WOOL)
Block(-3,5,-7,WOOL)
Block(-3,5,-6,WOOL)
Block(-3,5,-5,WOOL)
Block(-3,5,-4,WOOL)
Block(-3,5,-3,WOOL)
Block(-3,6,-7,WOOL)
Block(-3,6,-6,WOOL)
Block(-3,6,-5,WOOL)
Block(-3,6,-4,WOOL)
Block(-3,6,-3,WOOL)
Block(-3,7,-7,WOOL)
Block(-3,7,-6,WOOL)
Block(-3,7,-5,WOOL)
Block(-3,7,-4,WOOL)
Block(-3,7,-3,WOOL)
Block(-3,7,-2,WOOL)
Block(-3,8,-7,WOOL)
Block(-3,8,-6,WOOL)
Block(-3,8,-5,WOOL)
Block(-3,8,-4,WOOL)
Block(-3,8,-3,WOOL)
Block(-3,8,-2,WOOL)
Block(-3,9,-7,WOOL)
Block(-3,9,-6,WOOL)
Block(-3,9,-5,WOOL)
Block(-3,9,-4,WOOL)
Block(-3,9,-3,WOOL)
Block(-3,9,-2,WOOL)
Block(-3,10,-7,WOOL)
Block(-3,10,-6,WOOL)
Block(-3,10,-5,WOOL)
Block(-3,10,-4,WOOL)
Block(-3,10,-3,WOOL)
Block(-3,10,-2,WOOL)
Block(-3,11,-7,WOOL)
Block(-3,11,-6,WOOL)
Block(-3,11,-5,WOOL)
Block(-3,11,-4,WOOL)
Block(-3,11,-3,WOOL)
Block(-3,11,-2,WOOL)
Block(-3,11,-1,WOOL)
Block(-3,12,-7,WOOL)
Block(-3,12,-6,WOOL)
Block(-3,12,-5,WOOL)
Block(-3,12,-4,WOOL)
Block(-3,12,-3,WOOL)
Block(-3,12,-2,WOOL)
Block(-3,12,-1,WOOL)
Block(-3,13,-7,WOOL)
Block(-3,13,-6,WOOL)
Block(-3,13,-5,WOOL)
Block(-3,13,-4,WOOL)
Block(-3,13,-3,WOOL)
Block(-3,13,-2,WOOL)
Block(-3,13,-1,WOOL)
Block(-3,14,-7,WOOL)
Block(-3,14,-6,WOOL)
Block(-3,14,-5,WOOL)
Block(-3,14,-4,WOOL)
Block(-3,14,-3,WOOL)
Block(-3,14,-2,WOOL)
Block(-3,14,-1,WOOL)
Block(-3,15,-7,WOOL)
Block(-3,15,-6,WOOL)
Block(-3,15,-5,WOOL)
Block(-3,15,-4,WOOL)
Block(-3,15,-3,WOOL)
Block(-3,15,-2,WOOL)
Block(-3,15,-1,WOOL)
Block(-3,16,-7,WOOL)
Block(-3,16,-6,WOOL)
Block(-3,16,-5,WOOL)
Block(-3,16,-4,WOOL)
Block(-3,16,-3,WOOL)
Block(-3,17,-7,WOOL)
Block(-3,17,-6,WOOL)
Block(-3,17,-5,WOOL)
Block(-3,17,-4,WOOL)
Block(-3,17,-3,WOOL)
Block(-3,17,-2,WOOL)
Block(-3,18,-7,WOOL)
Block(-3,18,-6,WOOL)
Block(-3,18,-5,WOOL)
Block(-3,18,-4,WOOL)
Block(-3,18,-3,WOOL)
Block(-3,18,-2,WOOL)
Block(-3,19,-7,WOOL)
Block(-3,19,-6,WOOL)
Block(-3,19,-5,WOOL)
Block(-3,19,-4,WOOL)
Block(-3,19,-3,WOOL)
Block(-3,19,-2,WOOL)
Block(-3,19,-1,WOOL)
Block(-3,19,0,WOOL)
Block(-3,20,-7,WOOL)
Block(-3,20,-6,WOOL)
Block(-3,20,-5,WOOL)
Block(-3,20,-4,WOOL)
Block(-3,20,-3,WOOL)
Block(-3,20,-2,WOOL)
Block(-3,21,-7,WOOL)
Block(-3,21,-6,WOOL)
Block(-3,21,-5,WOOL)
Block(-3,21,-4,WOOL)
Block(-3,21,-3,WOOL)
Block(-3,21,-2,WOOL)
Block(-3,22,-7,WOOL)
Block(-3,22,-6,WOOL)
Block(-3,22,-5,WOOL)
Block(-3,22,-4,WOOL)
Block(-3,22,-3,WOOL)
Block(-3,22,-2,WOOL)
Block(-3,22,-1,WOOL)
Block(-3,23,-7,WOOL)
Block(-3,23,-6,WOOL)
Block(-3,23,-5,WOOL)
Block(-3,23,-4,WOOL)
Block(-3,23,-3,WOOL)
Block(-3,23,-2,WOOL)
Block(-3,23,-1,WOOL)
Block(-3,24,-7,WOOL)
Block(-3,24,-6,WOOL)
Block(-3,24,-5,WOOL)
Block(-3,24,-4,WOOL)
Block(-3,24,-3,WOOL)
Block(-3,24,-2,WOOL)
Block(-3,24,-1,WOOL)
Block(-3,24,0,WOOL)
Block(-2,2,-7,WOOL)
Block(-2,2,-6,WOOL)
Block(-2,2,-5,WOOL)
Block(-2,3,-7,WOOL)
Block(-2,3,-6,WOOL)
Block(-2,3,-5,WOOL)
Block(-2,4,-7,WOOL)
Block(-2,4,-6,WOOL)
Block(-2,4,-5,WOOL)
Block(-2,5,-7,WOOL)
Block(-2,5,-6,WOOL)
Block(-2,5,-5,WOOL)
Block(-2,5,-4,WOOL)
Block(-2,6,-7,WOOL)
Block(-2,6,-6,WOOL)
Block(-2,6,-5,WOOL)
Block(-2,6,-4,WOOL)
Block(-2,7,-7,WOOL)
Block(-2,7,-6,WOOL)
Block(-2,7,-5,WOOL)
Block(-2,7,-4,WOOL)
Block(-2,8,-7,WOOL)
Block(-2,8,-6,WOOL)
Block(-2,8,-5,WOOL)
Block(-2,8,-4,WOOL)
Block(-2,9,-7,WOOL)
Block(-2,9,-6,WOOL)
Block(-2,9,-5,WOOL)
Block(-2,9,-4,WOOL)
Block(-2,10,-7,WOOL)
Block(-2,10,-6,WOOL)
Block(-2,10,-5,WOOL)
Block(-2,10,-4,WOOL)
Block(-2,11,-7,WOOL)
Block(-2,11,-6,WOOL)
Block(-2,11,-5,WOOL)
Block(-2,11,-4,WOOL)
Block(-2,11,-3,WOOL)
Block(-2,12,-7,WOOL)
Block(-2,12,-6,WOOL)
Block(-2,12,-5,WOOL)
Block(-2,12,-4,WOOL)
Block(-2,12,-3,WOOL)
Block(-2,13,-7,WOOL)
Block(-2,13,-6,WOOL)
Block(-2,13,-5,WOOL)
Block(-2,13,-4,WOOL)
Block(-2,13,-3,WOOL)
Block(-2,14,-7,WOOL)
Block(-2,14,-6,WOOL)
Block(-2,14,-5,WOOL)
Block(-2,14,-4,WOOL)
Block(-2,14,-3,WOOL)
Block(-2,15,-7,WOOL)
Block(-2,15,-6,WOOL)
Block(-2,15,-5,WOOL)
Block(-2,15,-4,WOOL)
Block(-2,15,-3,WOOL)
Block(-2,16,-7,WOOL)
Block(-2,16,-6,WOOL)
Block(-2,16,-5,WOOL)
Block(-2,16,-4,WOOL)
Block(-2,17,-7,WOOL)
Block(-2,17,-6,WOOL)
Block(-2,17,-5,WOOL)
Block(-2,17,-4,WOOL)
Block(-2,18,-7,WOOL)
Block(-2,18,-6,WOOL)
Block(-2,18,-5,WOOL)
Block(-2,18,-4,WOOL)
Block(-2,19,-7,WOOL)
Block(-2,19,-6,WOOL)
Block(-2,19,-5,WOOL)
Block(-2,19,-4,WOOL)
Block(-2,19,-3,WOOL)
Block(-2,19,-2,WOOL)
Block(-2,20,-7,WOOL)
Block(-2,20,-6,WOOL)
Block(-2,20,-5,WOOL)
Block(-2,20,-4,WOOL)
Block(-2,21,-7,WOOL)
Block(-2,21,-6,WOOL)
Block(-2,21,-5,WOOL)
Block(-2,21,-4,WOOL)
Block(-2,21,-2,WOOL)
Block(-2,22,-7,WOOL)
Block(-2,22,-6,WOOL)
Block(-2,22,-5,WOOL)
Block(-2,22,-4,WOOL)
Block(-2,22,-3,WOOL)
Block(-2,22,-2,WOOL)
Block(-2,23,-7,WOOL)
Block(-2,23,-6,WOOL)
Block(-2,23,-5,WOOL)
Block(-2,23,-4,WOOL)
Block(-2,23,-3,WOOL)
Block(-2,24,-7,WOOL)
Block(-2,24,-6,WOOL)
Block(-2,24,-5,WOOL)
Block(-2,24,-4,WOOL)
Block(-2,24,-3,WOOL)
Block(-1,3,-7,WOOL)
Block(-1,4,-7,WOOL)
Block(-1,5,-7,WOOL)
Block(-1,6,-7,WOOL)
Block(-1,7,-7,WOOL)
Block(-1,7,-6,WOOL)
Block(-1,8,-7,WOOL)
Block(-1,8,-6,WOOL)
Block(-1,8,-5,WOOL)
Block(-1,9,-7,WOOL)
Block(-1,9,-6,WOOL)
Block(-1,9,-5,WOOL)
Block(-1,10,-7,WOOL)
Block(-1,10,-6,WOOL)
Block(-1,10,-5,WOOL)
Block(-1,11,-7,WOOL)
Block(-1,11,-6,WOOL)
Block(-1,11,-5,WOOL)
Block(-1,11,-4,WOOL)
Block(-1,12,-7,WOOL)
Block(-1,12,-6,WOOL)
Block(-1,12,-5,WOOL)
Block(-1,12,-4,WOOL)
Block(-1,13,-7,WOOL)
Block(-1,13,-6,WOOL)
Block(-1,13,-5,WOOL)
Block(-1,13,-4,WOOL)
Block(-1,14,-7,WOOL)
Block(-1,14,-6,WOOL)
Block(-1,14,-5,WOOL)
Block(-1,14,-4,WOOL)
Block(-1,15,-7,WOOL)
Block(-1,15,-6,WOOL)
Block(-1,15,-5,WOOL)
Block(-1,15,-4,WOOL)
Block(-1,16,-7,WOOL)
Block(-1,16,-6,WOOL)
Block(-1,17,-7,WOOL)
Block(-1,17,-6,WOOL)
Block(-1,17,-5,WOOL)
Block(-1,18,-7,WOOL)
Block(-1,18,-6,WOOL)
Block(-1,18,-5,WOOL)
Block(-1,19,-7,WOOL)
Block(-1,19,-6,WOOL)
Block(-1,19,-5,WOOL)
Block(-1,19,-4,WOOL)
Block(-1,20,-7,WOOL)
Block(-1,20,-6,WOOL)
Block(-1,20,-5,WOOL)
Block(-1,21,-7,WOOL)
Block(-1,21,-6,WOOL)
Block(-1,21,-5,WOOL)
Block(-1,22,-7,WOOL)
Block(-1,22,-6,WOOL)
Block(-1,22,-5,WOOL)
Block(-1,23,-7,WOOL)
Block(-1,23,-6,WOOL)
Block(-1,23,-5,WOOL)
Block(-1,23,-4,WOOL)
Block(-1,24,-7,WOOL)
Block(-1,24,-6,WOOL)
Block(-1,24,-5,WOOL)
Block(-1,24,-4,WOOL)
Block(0,7,-7,WOOL)
Block(0,8,-7,WOOL)
Block(0,9,-7,WOOL)
Block(0,10,-7,WOOL)
Block(0,11,-7,WOOL)
Block(0,11,-6,WOOL)
Block(0,12,-7,WOOL)
Block(0,12,-6,WOOL)
Block(0,13,-7,WOOL)
Block(0,13,-6,WOOL)
Block(0,14,-7,WOOL)
Block(0,14,-6,WOOL)
Block(0,15,-7,WOOL)
Block(0,15,-6,WOOL)
Block(0,17,-7,WOOL)
Block(0,18,-7,WOOL)
Block(0,19,-7,WOOL)
Block(0,19,-6,WOOL)
Block(0,20,-7,WOOL)
Block(0,21,-7,WOOL)
Block(0,22,-7,WOOL)
Block(0,23,-7,WOOL)
Block(0,24,-7,WOOL)
Block(1,19,-7,WOOL)

#######################################################################
# +-----------------------------------------------------------------+ #
# |                            BO3 checks                           | #
# +-----------------------------------------------------------------+ #
#######################################################################


#######################################################################
# +-----------------------------------------------------------------+ #
# |                             Branches                            | #
# +-----------------------------------------------------------------+ #
#######################################################################


#######################################################################
# +-----------------------------------------------------------------+ #
# |                         EntityFunctions                         | #
# +-----------------------------------------------------------------+ #
#######################################################################

