
#######################################################################
# +-----------------------------------------------------------------+ #
# |                            BO3 object                           | #
# +-----------------------------------------------------------------+ #
#######################################################################

# This is the config file of a custom object.
# If you add this object correctly to your BiomeConfigs, it will spawn in the world.

# This is the creator of this BO3 object
Author: LordSmellyPants

# A short description of this BO3 object
Description: Converted version of the BO2 mountain4R5

# The BO3 version, don't change this! It can be used by external applications to do a version check.
Version: 3

# The settings mode, WriteAll, WriteWithoutComments or WriteDisable. See WorldConfig.
SettingsMode: WriteDisable


#######################################################################
# +-----------------------------------------------------------------+ #
# |                          Main settings                          | #
# +-----------------------------------------------------------------+ #
#######################################################################

# This needs to be set to true to spawn the object in the Tree and Sapling resources.
Tree: false

# The frequency of the BO3 from 1 to 200. Tries this many times to spawn this BO3 when using the CustomObject(...) resource.
# Ignored by Tree(..), Sapling(..) and CustomStructure(..)
Frequency: 1

# The rarity of the BO3 from 0 to 100. Each spawn attempt has rarity% chance to succeed when using the CustomObject(...) resource.
# Ignored by Tree(..), Sapling(..) and CustomStructure(..)
Rarity: 100.0

# If you set this to true, the BO3 will be placed with a random rotation.
RotateRandomly: true

# The spawn height of the BO3 - randomY, highestBlock or highestSolidBlock.
SpawnHeight: highestSolidBlock

# The height limits for the BO3.
MinHeight: 117

MaxHeight: 124

# Objects can have other objects attacthed to it: branches. Branches can also
# have branches attached to it, which can also have branches, etc. This is the
# maximum branch depth for this objects.
MaxBranchDepth: 10

# When spawned with the UseWorld keyword, this BO3 should NOT spawn in the following biomes.
# If you writer.write the BO3 name directly in the BiomeConfigs, this will be ignored.
ExcludedBiomes: All


#######################################################################
# +-----------------------------------------------------------------+ #
# |                      Source block settings                      | #
# +-----------------------------------------------------------------+ #
#######################################################################

# The block(s) the BO3 should spawn in.
SourceBlocks: STONE:1,STONE:3,STONE:5,DIRT:1,GRASS,DIRT,STONE

# The maximum percentage of the BO3 that can be outside the SourceBlock.
# The BO3 won't be placed on a location with more blocks outside the SourceBlock than this percentage.
MaxPercentageOutsideSourceBlock: 50

# What to do when a block is about to be placed outside the SourceBlock? (dontPlace, placeAnyway)
OutsideSourceBlock: placeAnyway


#######################################################################
# +-----------------------------------------------------------------+ #
# |                              Blocks                             | #
# +-----------------------------------------------------------------+ #
#######################################################################

# All the blocks used in the BO3 are listed here. Possible blocks:
# Block(x,y,z,id[.data][,nbtfile.nbt)
# RandomBlock(x,y,z,id[:data][,nbtfile.nbt],chance[,id[:data][,nbtfile.nbt],chance[,...]])
# So RandomBlock(0,0,0,CHEST,chest.nbt,50,CHEST,anotherchest.nbt,100) will spawn a chest at
# the BO3 origin, and give it a 50% chance to have the contents of chest.nbt, or, if that
# fails, a 100% percent chance to have the contents of anotherchest.nbt.
Block(-7,-2,4,STONE)
Block(-7,-1,4,STONE)
Block(-6,1,-6,SNOW_BLOCK)
Block(-6,0,-6,STONE)
Block(-3,-1,14,STONE)
Block(-3,-4,14,STONE)
Block(-3,-5,14,STONE)
Block(-3,-2,14,STONE)
Block(-3,-3,14,STONE)
Block(-4,7,15,SNOW_BLOCK)
Block(-4,6,15,STONE)
Block(-4,5,15,STONE)
Block(-4,4,15,STONE)
Block(-4,3,15,STONE)
Block(-4,-5,-2,STONE)
Block(-7,-5,4,STONE)
Block(-8,12,6,SNOW_BLOCK)
Block(-4,-4,-2,STONE)
Block(-7,-4,4,STONE)
Block(-4,-3,-2,STONE)
Block(-7,-3,4,STONE)
Block(-4,-2,-2,STONE)
Block(-4,2,15,STONE)
Block(-4,-1,-2,STONE)
Block(-4,1,15,STONE)
Block(-4,0,15,STONE)
Block(-8,11,6,STONE)
Block(-8,10,6,STONE)
Block(-8,-5,14,STONE)
Block(-11,-4,19,STONE)
Block(-11,-5,19,STONE)
Block(-8,-2,14,STONE)
Block(-8,-1,14,STONE)
Block(-8,-4,14,STONE)
Block(-11,-2,19,SNOW)
Block(-8,-3,14,STONE)
Block(-11,-3,19,SNOW_BLOCK)
Block(-11,-4,20,SNOW_BLOCK)
Block(-11,2,-4,SNOW_BLOCK)
Block(-11,-5,20,SNOW_BLOCK)
Block(-11,0,-4,STONE)
Block(-11,1,-4,STONE)
Block(-9,-4,-2,STONE)
Block(-9,-5,-2,STONE)
Block(-9,-2,-2,STONE)
Block(-9,-3,-2,STONE)
Block(-9,-1,-2,STONE)
Block(0,0,0,SNOW_BLOCK)
Block(-11,-4,-1,STONE)
Block(-11,-5,-1,STONE)
Block(-3,10,14,STONE)
Block(-3,11,14,STONE)
Block(-11,-1,-1,STONE)
Block(-11,-2,-1,STONE)
Block(-3,12,14,SNOW_BLOCK)
Block(-11,-3,-1,STONE)
Block(-2,0,-5,STONE)
Block(-6,-1,2,STONE)
Block(-4,8,-1,STONE)
Block(-4,7,-1,STONE)
Block(-6,-3,2,STONE)
Block(-6,-2,2,STONE)
Block(-4,9,-1,STONE)
Block(-6,-5,2,STONE)
Block(-4,4,-1,STONE)
Block(-6,-4,2,STONE)
Block(-4,3,-1,STONE)
Block(-4,6,-1,STONE)
Block(-4,5,-1,STONE)
Block(-8,-3,6,STONE)
Block(-5,8,1,STONE)
Block(-8,-2,6,STONE)
Block(-5,7,1,STONE)
Block(-8,-5,6,STONE)
Block(-8,-4,6,STONE)
Block(-5,9,1,STONE)
Block(-8,-1,6,STONE)
Block(0,-4,15,STONE)
Block(-4,0,-1,STONE)
Block(-5,0,1,STONE)
Block(0,-3,15,STONE)
Block(0,-2,15,STONE)
Block(-4,2,-1,STONE)
Block(-5,2,1,STONE)
Block(0,-1,15,STONE)
Block(-4,1,-1,STONE)
Block(-5,1,1,STONE)
Block(-5,4,1,STONE)
Block(-5,3,1,STONE)
Block(-5,6,1,STONE)
Block(0,-5,15,STONE)
Block(-5,5,1,STONE)
Block(-1,12,6,STONE)
Block(-1,11,6,STONE)
Block(-11,1,2,SNOW)
Block(-1,10,6,STONE)
Block(-11,0,2,SNOW_BLOCK)
Block(-3,9,5,STONE)
Block(-3,6,5,STONE)
Block(-3,5,5,STONE)
Block(-3,8,5,STONE)
Block(-3,7,5,STONE)
Block(-3,2,5,STONE)
Block(-3,1,5,STONE)
Block(-3,4,5,STONE)
Block(-3,3,5,STONE)
Block(-6,11,2,STONE)
Block(-6,10,2,STONE)
Block(-3,0,5,STONE)
Block(-6,13,2,STONE)
Block(-6,12,2,STONE)
Block(-1,0,9,STONE)
Block(-1,2,9,STONE)
Block(-1,1,9,STONE)
Block(-1,20,6,SNOW_BLOCK)
Block(-1,4,9,STONE)
Block(-1,3,9,STONE)
Block(-1,6,9,STONE)
Block(-1,5,9,STONE)
Block(-1,8,9,STONE)
Block(-1,7,9,STONE)
Block(-1,9,9,STONE)
Block(-1,16,6,STONE)
Block(-1,15,6,STONE)
Block(-1,14,6,STONE)
Block(-1,13,6,STONE)
Block(-1,19,6,SNOW_BLOCK)
Block(-1,18,6,STONE)
Block(-1,17,6,STONE)
Block(-9,1,-5,STONE)
Block(-9,0,-5,STONE)
Block(-9,3,-5,SNOW_BLOCK)
Block(-9,2,-5,STONE)
Block(-7,10,-1,SNOW_BLOCK)
Block(-7,11,-1,SNOW)
Block(-6,10,13,STONE)
Block(-6,11,13,STONE)
Block(-1,-4,-3,STONE)
Block(-1,-3,-3,STONE)
Block(-1,-5,-3,STONE)
Block(-6,12,13,SNOW_BLOCK)
Block(-1,-2,-3,STONE)
Block(-1,-1,-3,STONE)
Block(-5,-5,15,STONE)
Block(-5,-4,15,STONE)
Block(-9,0,2,STONE)
Block(-5,-3,15,STONE)
Block(-9,1,2,STONE)
Block(-5,-2,15,STONE)
Block(-5,-1,15,STONE)
Block(-9,4,2,STONE)
Block(-9,5,2,SNOW_BLOCK)
Block(-9,2,2,STONE)
Block(-9,3,2,STONE)
Block(-12,-3,14,SNOW_BLOCK)
Block(-12,-4,14,STONE)
Block(-12,-5,14,STONE)
Block(-13,-1,1,SNOW)
Block(-13,-2,1,SNOW_BLOCK)
Block(-13,-3,1,STONE)
Block(-13,-4,1,STONE)
Block(1,-2,6,STONE)
Block(1,-3,6,STONE)
Block(1,-1,6,STONE)
Block(1,-4,6,STONE)
Block(1,-5,6,STONE)
Block(-6,-2,-3,STONE)
Block(-6,-3,-3,STONE)
Block(-6,-4,-3,STONE)
Block(-7,7,14,SNOW_BLOCK)
Block(-6,-5,-3,STONE)
Block(-6,-1,-3,STONE)
Block(-3,2,13,STONE)
Block(-3,3,13,STONE)
Block(-3,0,13,STONE)
Block(-3,1,13,STONE)
Block(-3,6,13,STONE)
Block(-3,7,13,STONE)
Block(-3,4,13,STONE)
Block(-3,5,13,STONE)
Block(-3,8,13,STONE)
Block(-3,9,13,STONE)
Block(-7,5,14,STONE)
Block(-7,6,14,STONE)
Block(-3,-1,7,STONE)
Block(-7,3,14,STONE)
Block(-7,4,14,STONE)
Block(-7,1,14,STONE)
Block(-7,2,14,STONE)
Block(-7,0,14,STONE)
Block(-10,-1,9,STONE)
Block(-3,-3,7,STONE)
Block(-3,-2,7,STONE)
Block(-3,-5,7,STONE)
Block(-3,-4,7,STONE)
Block(-7,16,4,SNOW_BLOCK)
Block(-7,15,4,STONE)
Block(-7,14,4,STONE)
Block(-7,13,4,STONE)
Block(-10,-3,9,STONE)
Block(-7,12,4,STONE)
Block(-10,-2,9,STONE)
Block(-7,11,4,STONE)
Block(-10,-5,9,STONE)
Block(-7,10,4,STONE)
Block(-10,-4,9,STONE)
Block(-7,-2,-1,STONE)
Block(-7,-1,-1,STONE)
Block(-7,-4,-1,STONE)
Block(-7,-3,-1,STONE)
Block(-7,-5,-1,STONE)
Block(-6,3,3,STONE)
Block(-6,2,3,STONE)
Block(-6,1,3,STONE)
Block(-6,0,3,STONE)
Block(-6,9,3,STONE)
Block(-6,8,3,STONE)
Block(-6,7,3,STONE)
Block(-6,6,3,STONE)
Block(-6,5,3,STONE)
Block(-6,4,3,STONE)
Block(-13,-5,1,STONE)
Block(-4,11,-2,SNOW)
Block(-4,10,-2,SNOW_BLOCK)
Block(-4,5,7,STONE)
Block(-4,4,7,STONE)
Block(-4,3,7,STONE)
Block(1,-1,13,STONE)
Block(-4,2,7,STONE)
Block(1,-2,13,STONE)
Block(-4,9,7,STONE)
Block(1,-3,13,STONE)
Block(-4,8,7,STONE)
Block(1,-4,13,STONE)
Block(-4,7,7,STONE)
Block(1,-5,13,STONE)
Block(-4,6,7,STONE)
Block(-4,1,7,STONE)
Block(-4,0,7,STONE)
Block(-4,17,1,SNOW)
Block(-4,16,1,SNOW_BLOCK)
Block(-4,15,1,STONE)
Block(-4,14,1,STONE)
Block(-4,13,1,STONE)
Block(-4,12,1,STONE)
Block(-4,11,1,STONE)
Block(-10,4,0,SNOW)
Block(-10,3,0,SNOW_BLOCK)
Block(-10,2,0,STONE)
Block(-10,1,0,STONE)
Block(-10,0,0,STONE)
Block(-10,-2,13,STONE)
Block(-10,-1,13,STONE)
Block(-4,10,1,STONE)
Block(-3,13,7,STONE)
Block(-10,-5,13,STONE)
Block(-3,12,7,STONE)
Block(-10,-4,13,STONE)
Block(-3,15,7,STONE)
Block(-10,-3,13,STONE)
Block(-3,14,7,STONE)
Block(-3,11,7,STONE)
Block(-3,10,7,STONE)
Block(-6,19,5,SNOW_BLOCK)
Block(-6,17,5,STONE)
Block(-6,18,5,STONE)
Block(-6,12,10,STONE)
Block(-6,11,10,STONE)
Block(-6,10,10,STONE)
Block(-6,16,10,STONE)
Block(-6,15,10,STONE)
Block(-6,14,10,STONE)
Block(-6,13,10,STONE)
Block(-11,-3,8,SNOW_BLOCK)
Block(-6,19,10,SNOW_BLOCK)
Block(-11,-5,8,STONE)
Block(-6,18,10,SNOW_BLOCK)
Block(-11,-4,8,STONE)
Block(-6,17,10,STONE)
Block(-6,20,5,SNOW_BLOCK)
Block(-6,21,5,SNOW_BLOCK)
Block(-1,5,0,SNOW_BLOCK)
Block(-1,4,0,STONE)
Block(-6,11,5,STONE)
Block(-6,12,5,STONE)
Block(-9,-1,5,STONE)
Block(-6,10,5,STONE)
Block(-9,-3,5,STONE)
Block(-1,1,0,STONE)
Block(-6,15,5,STONE)
Block(-9,-2,5,STONE)
Block(-1,0,0,STONE)
Block(-6,16,5,STONE)
Block(-9,-5,5,STONE)
Block(-1,3,0,STONE)
Block(-6,13,5,STONE)
Block(-9,-4,5,STONE)
Block(-1,2,0,STONE)
Block(-6,14,5,STONE)
Block(-1,10,10,STONE)
Block(-1,11,10,STONE)
Block(-1,12,10,STONE)
Block(-1,13,10,STONE)
Block(-5,8,9,STONE)
Block(-1,18,10,STONE)
Block(-5,7,9,STONE)
Block(-1,19,10,STONE)
Block(-5,9,9,STONE)
Block(-1,14,10,STONE)
Block(-1,15,10,STONE)
Block(-1,16,10,STONE)
Block(-1,17,10,STONE)
Block(-4,-4,1,STONE)
Block(-4,-3,1,STONE)
Block(-4,-2,1,STONE)
Block(-4,-1,1,STONE)
Block(-10,1,15,SNOW_BLOCK)
Block(-10,0,15,STONE)
Block(-10,2,15,SNOW)
Block(-4,20,12,SNOW_BLOCK)
Block(-4,-5,1,STONE)
Block(-1,3,-2,SNOW)
Block(-1,2,-2,SNOW_BLOCK)
Block(-1,1,-2,STONE)
Block(-7,9,5,STONE)
Block(-1,0,-2,STONE)
Block(-1,20,10,SNOW_BLOCK)
Block(-2,-5,5,STONE)
Block(-2,-4,5,STONE)
Block(-2,-3,5,STONE)
Block(-2,-2,5,STONE)
Block(-2,-1,5,STONE)
Block(0,-5,4,STONE)
Block(-4,13,12,STONE)
Block(-4,14,12,STONE)
Block(-4,15,12,STONE)
Block(-4,16,12,STONE)
Block(0,-1,4,STONE)
Block(-4,17,12,STONE)
Block(0,-2,4,STONE)
Block(-4,18,12,STONE)
Block(0,-3,4,STONE)
Block(-4,19,12,SNOW_BLOCK)
Block(0,-4,4,STONE)
Block(-4,10,12,STONE)
Block(-4,11,12,STONE)
Block(-4,12,12,STONE)
Block(0,6,14,SNOW_BLOCK)
Block(0,5,14,STONE)
Block(0,0,14,STONE)
Block(0,4,14,STONE)
Block(0,3,14,STONE)
Block(0,2,14,STONE)
Block(0,1,14,STONE)
Block(-7,0,5,STONE)
Block(-7,6,5,STONE)
Block(-7,5,5,STONE)
Block(-7,8,5,STONE)
Block(-7,7,5,STONE)
Block(-7,2,5,STONE)
Block(-7,1,5,STONE)
Block(-7,4,5,STONE)
Block(-7,3,5,STONE)
Block(-9,-5,12,STONE)
Block(-2,-5,16,STONE)
Block(-9,-4,12,STONE)
Block(-9,-3,12,STONE)
Block(-9,-2,12,STONE)
Block(-2,-2,16,STONE)
Block(-2,-1,16,STONE)
Block(-2,-4,16,STONE)
Block(-2,-3,16,STONE)
Block(1,-3,9,STONE)
Block(-5,0,9,STONE)
Block(1,-4,9,STONE)
Block(1,-5,9,STONE)
Block(-5,2,9,STONE)
Block(-5,1,9,STONE)
Block(-5,4,9,STONE)
Block(-5,3,9,STONE)
Block(1,-1,9,STONE)
Block(-5,6,9,STONE)
Block(1,-2,9,STONE)
Block(-5,5,9,STONE)
Block(-9,-1,12,STONE)
Block(-1,-4,10,STONE)
Block(-1,-5,10,STONE)
Block(-1,-1,10,STONE)
Block(-1,-2,10,STONE)
Block(-1,-3,10,STONE)
Block(-2,12,5,STONE)
Block(-2,11,5,STONE)
Block(-2,10,5,STONE)
Block(-6,0,11,STONE)
Block(-6,2,11,STONE)
Block(-6,1,11,STONE)
Block(-2,19,5,SNOW_BLOCK)
Block(-6,4,11,STONE)
Block(-2,18,5,STONE)
Block(-6,3,11,STONE)
Block(-2,17,5,STONE)
Block(-6,6,11,STONE)
Block(-2,16,5,STONE)
Block(-6,5,11,STONE)
Block(-2,15,5,STONE)
Block(-6,8,11,STONE)
Block(-2,14,5,STONE)
Block(-6,10,-3,SNOW)
Block(-6,7,11,STONE)
Block(-2,13,5,STONE)
Block(0,9,8,STONE)
Block(0,8,8,STONE)
Block(-6,9,11,STONE)
Block(-2,21,5,SNOW_BLOCK)
Block(-2,20,5,SNOW_BLOCK)
Block(1,-5,10,STONE)
Block(1,-4,10,STONE)
Block(1,-3,10,STONE)
Block(1,-2,10,STONE)
Block(0,1,8,STONE)
Block(1,-1,10,STONE)
Block(0,0,8,STONE)
Block(0,3,8,STONE)
Block(0,2,8,STONE)
Block(0,5,8,STONE)
Block(0,4,8,STONE)
Block(0,7,8,STONE)
Block(0,6,8,STONE)
Block(-2,2,11,STONE)
Block(-2,1,11,STONE)
Block(-2,4,11,STONE)
Block(-2,3,11,STONE)
Block(-2,0,11,STONE)
Block(-7,-5,1,STONE)
Block(-7,-4,1,STONE)
Block(-10,-1,-6,STONE)
Block(-7,-1,1,STONE)
Block(-7,-3,1,STONE)
Block(-7,-2,1,STONE)
Block(-2,9,11,STONE)
Block(-10,-2,-6,STONE)
Block(-2,6,11,STONE)
Block(-10,-3,-6,STONE)
Block(-2,5,11,STONE)
Block(-10,-4,-6,STONE)
Block(-2,8,11,STONE)
Block(-10,-5,-6,STONE)
Block(-2,7,11,STONE)
Block(-11,-5,16,STONE)
Block(-2,9,2,STONE)
Block(-2,8,2,STONE)
Block(-2,7,2,STONE)
Block(-2,6,2,STONE)
Block(-2,5,2,STONE)
Block(-2,4,2,STONE)
Block(-2,3,2,STONE)
Block(-2,2,2,STONE)
Block(-2,1,2,STONE)
Block(-2,0,2,STONE)
Block(-12,-5,2,STONE)
Block(-11,-4,16,STONE)
Block(-11,-3,16,STONE)
Block(-11,-2,16,STONE)
Block(-11,-1,16,SNOW_BLOCK)
Block(-8,0,16,STONE)
Block(-8,1,16,STONE)
Block(-5,-5,0,STONE)
Block(-12,-4,2,STONE)
Block(-12,-3,2,STONE)
Block(-12,-2,2,SNOW_BLOCK)
Block(-8,2,16,SNOW_BLOCK)
Block(-5,-4,0,STONE)
Block(-5,-3,0,STONE)
Block(-5,-2,0,STONE)
Block(-5,-1,0,STONE)
Block(-14,-2,18,SNOW)
Block(-14,-3,18,STONE)
Block(-12,-1,-4,SNOW_BLOCK)
Block(-12,-2,-4,STONE)
Block(-12,-3,-4,STONE)
Block(-12,-4,-4,STONE)
Block(-12,-5,-4,STONE)
Block(-8,6,7,STONE)
Block(-8,7,7,STONE)
Block(-14,-4,18,STONE)
Block(-8,8,7,STONE)
Block(-14,-5,18,STONE)
Block(-8,9,7,STONE)
Block(-3,-4,-7,STONE)
Block(-1,-2,6,STONE)
Block(-3,-3,-7,STONE)
Block(-1,-1,6,STONE)
Block(-3,-2,-7,STONE)
Block(-1,-5,6,STONE)
Block(-1,-4,6,STONE)
Block(-3,-5,-7,STONE)
Block(-1,-3,6,STONE)
Block(-6,-5,5,STONE)
Block(-6,-3,5,STONE)
Block(-6,-4,5,STONE)
Block(-5,0,-4,STONE)
Block(-8,2,7,STONE)
Block(-8,3,7,STONE)
Block(-13,-2,-2,STONE)
Block(-8,4,7,STONE)
Block(-13,-1,-2,SNOW_BLOCK)
Block(-8,5,7,STONE)
Block(-6,-2,10,STONE)
Block(-6,-1,10,STONE)
Block(-8,0,7,STONE)
Block(-8,1,7,STONE)
Block(-6,-5,10,STONE)
Block(-6,-4,10,STONE)
Block(-6,-3,10,STONE)
Block(-13,-4,-2,STONE)
Block(-13,-3,-2,STONE)
Block(-13,-5,-2,STONE)
Block(-9,4,11,SNOW_BLOCK)
Block(-5,3,-4,STONE)
Block(-9,3,11,STONE)
Block(-9,2,11,STONE)
Block(-5,4,-4,STONE)
Block(-5,1,-4,STONE)
Block(-9,1,11,STONE)
Block(-9,0,11,STONE)
Block(-5,2,-4,STONE)
Block(-5,7,-4,SNOW_BLOCK)
Block(-5,5,-4,STONE)
Block(-5,6,-4,STONE)
Block(-9,-1,-5,STONE)
Block(-9,-2,-5,STONE)
Block(-9,-3,-5,STONE)
Block(-9,-4,-5,STONE)
Block(-9,-5,-5,STONE)
Block(-11,-1,-4,STONE)
Block(-11,-2,-4,STONE)
Block(-11,-5,-4,STONE)
Block(-11,-3,-4,STONE)
Block(-11,-4,-4,STONE)
Block(-6,-1,5,STONE)
Block(-6,-2,5,STONE)
Block(-8,1,-2,STONE)
Block(-8,0,-2,STONE)
Block(-8,3,-2,STONE)
Block(-8,2,-2,STONE)
Block(-8,5,-2,STONE)
Block(-8,4,-2,STONE)
Block(-5,14,0,SNOW_BLOCK)
Block(-5,13,0,STONE)
Block(-5,12,0,STONE)
Block(-5,11,0,STONE)
Block(-10,2,8,SNOW)
Block(-10,1,8,SNOW_BLOCK)
Block(-10,0,8,STONE)
Block(-10,0,-1,STONE)
Block(-8,7,-2,SNOW_BLOCK)
Block(-10,1,-1,STONE)
Block(-8,6,-2,STONE)
Block(-10,2,-1,STONE)
Block(-10,3,-1,STONE)
Block(-10,4,-1,SNOW_BLOCK)
Block(-10,5,-1,SNOW)
Block(-4,-1,12,STONE)
Block(-4,-2,12,STONE)
Block(-4,-3,12,STONE)
Block(-5,10,0,STONE)
Block(-4,-4,12,STONE)
Block(-4,-5,12,STONE)
Block(-5,5,10,STONE)
Block(-5,6,10,STONE)
Block(-5,7,10,STONE)
Block(-5,8,10,STONE)
Block(-2,-3,0,STONE)
Block(-5,1,10,STONE)
Block(0,10,12,STONE)
Block(-2,-2,0,STONE)
Block(-5,2,10,STONE)
Block(0,11,12,STONE)
Block(-2,-5,0,STONE)
Block(-5,3,10,STONE)
Block(-2,-4,0,STONE)
Block(-5,4,10,STONE)
Block(-2,-1,0,STONE)
Block(-5,0,10,STONE)
Block(-3,7,4,STONE)
Block(-3,6,4,STONE)
Block(-3,9,4,STONE)
Block(-10,3,1,SNOW_BLOCK)
Block(-3,8,4,STONE)
Block(-10,2,1,STONE)
Block(-3,3,4,STONE)
Block(-10,1,1,STONE)
Block(-3,2,4,STONE)
Block(-10,0,1,STONE)
Block(-3,5,4,STONE)
Block(0,12,12,STONE)
Block(-3,4,4,STONE)
Block(0,13,12,SNOW_BLOCK)
Block(-5,9,10,STONE)
Block(-3,10,2,STONE)
Block(-3,1,4,STONE)
Block(-3,0,4,STONE)
Block(-3,14,2,STONE)
Block(-3,13,2,STONE)
Block(-3,12,2,STONE)
Block(-3,11,2,STONE)
Block(-4,20,4,SNOW_BLOCK)
Block(-1,1,8,STONE)
Block(-4,21,4,SNOW_BLOCK)
Block(-1,0,8,STONE)
Block(-3,17,2,SNOW_BLOCK)
Block(-1,3,8,STONE)
Block(-3,16,2,STONE)
Block(-1,2,8,STONE)
Block(-3,15,2,STONE)
Block(-1,5,8,STONE)
Block(-1,4,8,STONE)
Block(-1,7,8,STONE)
Block(-1,6,8,STONE)
Block(-1,9,8,STONE)
Block(-1,8,8,STONE)
Block(-2,-3,-4,STONE)
Block(-2,-4,-4,STONE)
Block(-2,-5,-4,STONE)
Block(-2,-1,-4,STONE)
Block(-2,-2,-4,STONE)
Block(-4,14,4,STONE)
Block(-4,15,4,STONE)
Block(-4,16,4,STONE)
Block(-4,17,4,STONE)
Block(-4,18,4,SNOW_BLOCK)
Block(-4,19,4,SNOW_BLOCK)
Block(-5,-5,8,STONE)
Block(-4,9,14,STONE)
Block(-4,8,14,STONE)
Block(-4,7,14,STONE)
Block(-4,6,14,STONE)
Block(-4,5,14,STONE)
Block(-4,4,14,STONE)
Block(-5,-4,8,STONE)
Block(-5,9,0,STONE)
Block(-5,-3,8,STONE)
Block(-5,8,0,STONE)
Block(-5,-2,8,STONE)
Block(-5,-1,8,STONE)
Block(-5,1,0,STONE)
Block(-4,3,14,STONE)
Block(-5,0,0,STONE)
Block(-4,2,14,STONE)
Block(-4,1,14,STONE)
Block(-5,3,0,STONE)
Block(-4,0,14,STONE)
Block(-5,2,0,STONE)
Block(-5,5,0,STONE)
Block(-5,4,0,STONE)
Block(-5,7,0,STONE)
Block(-5,6,0,STONE)
Block(-2,-3,11,STONE)
Block(-8,1,15,STONE)
Block(-2,-2,11,STONE)
Block(-8,2,15,STONE)
Block(-2,-1,11,STONE)
Block(-8,0,15,STONE)
Block(-8,5,15,SNOW)
Block(-2,-5,11,STONE)
Block(-8,3,15,STONE)
Block(-2,-4,11,STONE)
Block(-8,4,15,SNOW_BLOCK)
Block(-10,-1,1,STONE)
Block(1,-3,16,SNOW_BLOCK)
Block(1,-4,16,STONE)
Block(1,-5,16,STONE)
Block(-11,0,-5,SNOW_BLOCK)
Block(-10,-3,1,STONE)
Block(-10,-2,1,STONE)
Block(-10,-5,1,STONE)
Block(-10,-4,1,STONE)
Block(-4,-1,4,STONE)
Block(-4,-2,4,STONE)
Block(-4,-3,4,STONE)
Block(-4,-4,4,STONE)
Block(-4,-5,4,STONE)
Block(-5,-4,-5,STONE)
Block(-5,-3,-5,STONE)
Block(-5,-2,-5,STONE)
Block(-5,-1,-5,STONE)
Block(-4,10,4,STONE)
Block(-4,11,4,STONE)
Block(-4,12,4,STONE)
Block(-4,13,4,STONE)
Block(-5,-5,-5,STONE)
Block(-5,19,8,STONE)
Block(-9,0,-6,SNOW_BLOCK)
Block(-5,25,8,SNOW_BLOCK)
Block(-5,24,8,SNOW_BLOCK)
Block(-5,23,8,SNOW_BLOCK)
Block(-5,22,8,SNOW_BLOCK)
Block(-5,21,8,SNOW_BLOCK)
Block(-5,20,8,STONE)
Block(-4,-1,-5,STONE)
Block(-4,-3,-5,STONE)
Block(-4,-2,-5,STONE)
Block(-4,-5,-5,STONE)
Block(-4,-4,-5,STONE)
Block(-5,18,8,STONE)
Block(-5,17,8,STONE)
Block(-5,16,8,STONE)
Block(-5,15,8,STONE)
Block(-7,-1,-4,STONE)
Block(-5,14,8,STONE)
Block(-9,0,3,STONE)
Block(-5,13,8,STONE)
Block(-5,12,8,STONE)
Block(-5,11,8,STONE)
Block(-7,-5,-4,STONE)
Block(-9,3,3,STONE)
Block(-5,10,8,STONE)
Block(-7,-4,-4,STONE)
Block(-9,4,3,STONE)
Block(-7,-3,-4,STONE)
Block(-9,1,3,STONE)
Block(-7,-2,-4,STONE)
Block(-9,2,3,STONE)
Block(-9,5,3,SNOW_BLOCK)
Block(-4,6,6,STONE)
Block(-4,5,6,STONE)
Block(-4,4,6,STONE)
Block(-4,3,6,STONE)
Block(-4,9,6,STONE)
Block(-4,8,6,STONE)
Block(-4,7,6,STONE)
Block(-4,2,6,STONE)
Block(-4,1,6,STONE)
Block(-4,0,6,STONE)
Block(-9,-1,2,STONE)
Block(-9,-2,2,STONE)
Block(-9,-3,2,STONE)
Block(-9,-4,2,STONE)
Block(-9,-5,2,STONE)
Block(-7,-1,7,STONE)
Block(-7,-2,7,STONE)
Block(-7,-3,7,STONE)
Block(-7,-4,7,STONE)
Block(-7,8,13,STONE)
Block(-7,-5,7,STONE)
Block(-7,9,13,SNOW_BLOCK)
Block(-3,-3,-1,STONE)
Block(-1,-1,0,STONE)
Block(-3,-4,-1,STONE)
Block(-1,-2,0,STONE)
Block(-3,-5,-1,STONE)
Block(-1,-3,0,STONE)
Block(-1,-4,0,STONE)
Block(-1,-5,0,STONE)
Block(-7,6,13,STONE)
Block(-7,7,13,STONE)
Block(-7,4,13,STONE)
Block(-7,5,13,STONE)
Block(-7,2,13,STONE)
Block(-7,3,13,STONE)
Block(-3,-1,-1,STONE)
Block(-7,0,13,STONE)
Block(-3,-2,-1,STONE)
Block(-7,1,13,STONE)
Block(-2,2,-4,SNOW_BLOCK)
Block(-8,10,9,SNOW_BLOCK)
Block(-2,0,-4,STONE)
Block(-2,1,-4,STONE)
Block(-6,4,2,STONE)
Block(-6,3,2,STONE)
Block(-6,2,2,STONE)
Block(-6,1,2,STONE)
Block(-6,0,2,STONE)
Block(-6,9,2,STONE)
Block(-6,8,2,STONE)
Block(-6,7,2,STONE)
Block(-6,6,2,STONE)
Block(-6,5,2,STONE)
Block(-11,-1,5,SNOW_BLOCK)
Block(-11,-2,5,STONE)
Block(-11,-3,5,STONE)
Block(-11,-4,5,STONE)
Block(-11,-5,5,STONE)
Block(-9,-5,15,STONE)
Block(-9,-1,15,STONE)
Block(-9,-2,15,STONE)
Block(-9,-3,15,STONE)
Block(-9,-4,15,STONE)
Block(0,-1,12,STONE)
Block(0,-4,12,STONE)
Block(0,-5,12,STONE)
Block(0,-2,12,STONE)
Block(0,-3,12,STONE)
Block(2,-4,13,STONE)
Block(2,-3,13,STONE)
Block(2,-2,13,STONE)
Block(2,-1,13,STONE)
Block(-3,0,12,STONE)
Block(-3,3,12,STONE)
Block(-3,4,12,STONE)
Block(-3,1,12,STONE)
Block(2,-5,13,STONE)
Block(-3,2,12,STONE)
Block(-3,7,12,STONE)
Block(-3,8,12,STONE)
Block(-3,5,12,STONE)
Block(-3,6,12,STONE)
Block(-3,9,12,STONE)
Block(-3,10,-1,SNOW_BLOCK)
Block(-3,11,-1,SNOW)
Block(-8,-5,9,STONE)
Block(-8,-3,9,STONE)
Block(-8,-4,9,STONE)
Block(-8,-1,9,STONE)
Block(-8,-2,9,STONE)
Block(-8,-1,-1,STONE)
Block(-8,-2,-1,STONE)
Block(-8,-3,-1,STONE)
Block(-8,-4,-1,STONE)
Block(-8,-5,-1,STONE)
Block(-11,-4,13,STONE)
Block(-4,-3,-8,STONE)
Block(-11,-5,13,STONE)
Block(-4,-4,-8,STONE)
Block(-11,-2,13,STONE)
Block(-11,-3,13,STONE)
Block(-4,-5,-8,STONE)
Block(-5,9,8,STONE)
Block(-5,8,8,STONE)
Block(-8,-2,-4,STONE)
Block(-8,-1,-4,STONE)
Block(-10,1,9,SNOW)
Block(-8,-4,-4,STONE)
Block(-10,0,9,SNOW_BLOCK)
Block(-8,-3,-4,STONE)
Block(-8,-5,-4,STONE)
Block(-11,-1,13,SNOW_BLOCK)
Block(-1,0,-3,SNOW_BLOCK)
Block(-12,-5,17,STONE)
Block(-12,-3,17,STONE)
Block(-12,-4,17,STONE)
Block(-12,-1,17,SNOW)
Block(-12,-2,17,SNOW_BLOCK)
Block(-10,-2,-3,STONE)
Block(-10,-1,-3,STONE)
Block(-10,-5,-3,STONE)
Block(-10,-4,-3,STONE)
Block(-10,-3,-3,STONE)
Block(2,-4,16,SNOW_BLOCK)
Block(2,-5,16,SNOW_BLOCK)
Block(-1,-5,3,STONE)
Block(-1,-4,3,STONE)
Block(-7,1,4,STONE)
Block(-7,0,4,STONE)
Block(-7,7,4,STONE)
Block(-3,-1,-4,STONE)
Block(-7,6,4,STONE)
Block(-7,9,4,STONE)
Block(-7,8,4,STONE)
Block(-3,-4,-4,STONE)
Block(-1,-1,3,STONE)
Block(-7,3,4,STONE)
Block(-3,-5,-4,STONE)
Block(-7,2,4,STONE)
Block(-1,-3,3,STONE)
Block(-3,-2,-4,STONE)
Block(-7,5,4,STONE)
Block(-3,-3,-4,STONE)
Block(-1,-2,3,STONE)
Block(-7,4,4,STONE)
Block(-5,1,8,STONE)
Block(-5,0,8,STONE)
Block(-5,3,8,STONE)
Block(-5,2,8,STONE)
Block(-5,5,8,STONE)
Block(-5,4,8,STONE)
Block(-5,7,8,STONE)
Block(-5,6,8,STONE)
Block(-5,-1,5,STONE)
Block(-10,0,14,STONE)
Block(-10,-2,10,STONE)
Block(-10,2,14,SNOW)
Block(-10,-3,10,STONE)
Block(-10,1,14,SNOW_BLOCK)
Block(-10,-1,10,SNOW_BLOCK)
Block(-10,-4,10,STONE)
Block(-10,-5,10,STONE)
Block(-7,12,7,STONE)
Block(-7,13,7,STONE)
Block(-7,14,7,STONE)
Block(-7,15,7,STONE)
Block(-7,16,7,SNOW_BLOCK)
Block(-7,17,7,SNOW_BLOCK)
Block(-7,18,7,SNOW_BLOCK)
Block(-6,1,12,STONE)
Block(-6,0,12,STONE)
Block(-6,3,12,STONE)
Block(-6,2,12,STONE)
Block(-6,5,12,STONE)
Block(-6,4,12,STONE)
Block(-6,7,12,STONE)
Block(-7,10,7,STONE)
Block(-6,6,12,STONE)
Block(-7,11,7,STONE)
Block(0,8,9,STONE)
Block(-6,9,12,STONE)
Block(0,7,9,STONE)
Block(-6,8,12,STONE)
Block(0,9,9,STONE)
Block(0,0,9,STONE)
Block(0,2,9,STONE)
Block(0,1,9,STONE)
Block(0,4,9,STONE)
Block(0,3,9,STONE)
Block(0,6,9,STONE)
Block(0,5,9,STONE)
Block(-4,-3,15,STONE)
Block(-4,-2,15,STONE)
Block(-4,-5,15,STONE)
Block(-4,-4,15,STONE)
Block(-2,-2,-1,STONE)
Block(-2,-3,-1,STONE)
Block(-2,-1,-1,STONE)
Block(-2,-4,-1,STONE)
Block(-2,-5,-1,STONE)
Block(-4,-1,15,STONE)
Block(-8,-3,1,STONE)
Block(-8,-4,1,STONE)
Block(-8,-1,1,STONE)
Block(-8,-2,1,STONE)
Block(-8,-5,1,STONE)
Block(-8,0,-1,STONE)
Block(-2,17,11,STONE)
Block(-4,22,7,SNOW_BLOCK)
Block(-2,16,11,STONE)
Block(-4,23,7,SNOW_BLOCK)
Block(-8,2,-1,STONE)
Block(-2,15,11,STONE)
Block(-4,20,7,SNOW_BLOCK)
Block(-8,1,-1,STONE)
Block(-2,14,11,STONE)
Block(-4,21,7,SNOW_BLOCK)
Block(-8,4,-1,STONE)
Block(-4,26,7,SNOW_BLOCK)
Block(-8,3,-1,STONE)
Block(-11,0,3,SNOW)
Block(-8,6,-1,STONE)
Block(-2,19,11,STONE)
Block(-4,24,7,SNOW_BLOCK)
Block(-8,5,-1,STONE)
Block(-2,18,11,STONE)
Block(-4,25,7,SNOW_BLOCK)
Block(-2,13,11,STONE)
Block(-2,12,11,STONE)
Block(-2,11,11,STONE)
Block(-2,10,11,STONE)
Block(-2,-2,8,STONE)
Block(-2,-3,8,STONE)
Block(-2,-4,8,STONE)
Block(-2,-5,8,STONE)
Block(-8,8,-1,SNOW_BLOCK)
Block(-4,19,7,STONE)
Block(-8,7,-1,STONE)
Block(-4,17,7,STONE)
Block(-4,18,7,STONE)
Block(-8,9,-1,SNOW)
Block(-4,11,7,STONE)
Block(-6,15,2,STONE)
Block(-4,12,7,STONE)
Block(-6,14,2,STONE)
Block(-6,17,2,SNOW_BLOCK)
Block(-4,10,7,STONE)
Block(-6,16,2,STONE)
Block(-4,15,7,STONE)
Block(-4,16,7,STONE)
Block(-4,13,7,STONE)
Block(-4,14,7,STONE)
Block(-8,7,6,STONE)
Block(-8,8,6,STONE)
Block(-8,9,6,STONE)
Block(0,9,13,STONE)
Block(-7,11,11,STONE)
Block(0,8,13,STONE)
Block(-7,12,11,SNOW_BLOCK)
Block(0,7,13,STONE)
Block(0,6,13,STONE)
Block(-7,10,11,STONE)
Block(-6,-5,-8,STONE)
Block(0,1,13,STONE)
Block(-8,3,6,STONE)
Block(0,0,13,STONE)
Block(-8,4,6,STONE)
Block(-8,5,6,STONE)
Block(-6,-4,-8,STONE)
Block(-8,6,6,STONE)
Block(0,5,13,STONE)
Block(-8,0,6,STONE)
Block(0,4,13,STONE)
Block(-8,1,6,STONE)
Block(0,3,13,STONE)
Block(-8,2,6,STONE)
Block(0,2,13,STONE)
Block(0,-4,7,STONE)
Block(-9,4,12,SNOW_BLOCK)
Block(0,-5,7,STONE)
Block(-9,3,12,STONE)
Block(0,-2,7,STONE)
Block(-9,2,12,STONE)
Block(0,-3,7,STONE)
Block(-9,1,12,STONE)
Block(-9,0,12,STONE)
Block(0,-1,7,STONE)
Block(-2,9,1,STONE)
Block(-2,8,1,STONE)
Block(-2,7,1,STONE)
Block(-2,6,1,STONE)
Block(-2,5,1,STONE)
Block(-2,4,1,STONE)
Block(-2,3,1,STONE)
Block(-2,-1,8,STONE)
Block(-2,2,1,STONE)
Block(-2,1,1,STONE)
Block(-2,0,1,STONE)
Block(-3,-2,11,STONE)
Block(-3,-1,11,STONE)
Block(-3,-4,11,STONE)
Block(-3,-3,11,STONE)
Block(-3,-5,11,STONE)
Block(-2,20,8,STONE)
Block(-2,21,8,SNOW_BLOCK)
Block(-2,22,8,SNOW_BLOCK)
Block(-2,23,8,SNOW_BLOCK)
Block(-2,24,8,SNOW_BLOCK)
Block(-2,16,8,STONE)
Block(-2,17,8,STONE)
Block(-2,18,8,STONE)
Block(-2,19,8,STONE)
Block(-3,21,11,SNOW_BLOCK)
Block(-3,20,11,SNOW_BLOCK)
Block(-3,22,11,SNOW_BLOCK)
Block(-4,-5,7,STONE)
Block(-4,-3,7,STONE)
Block(-4,-4,7,STONE)
Block(-8,-2,11,STONE)
Block(-8,-3,11,STONE)
Block(-8,-4,11,STONE)
Block(-8,-5,11,STONE)
Block(-4,9,13,STONE)
Block(-3,-4,2,STONE)
Block(-4,-1,7,STONE)
Block(-4,8,13,STONE)
Block(-3,-3,2,STONE)
Block(-4,-2,7,STONE)
Block(-4,7,13,STONE)
Block(-3,-2,2,STONE)
Block(-4,6,13,STONE)
Block(-3,-1,2,STONE)
Block(-4,5,13,STONE)
Block(-3,-5,2,STONE)
Block(-5,-3,-8,STONE)
Block(-5,-4,-8,STONE)
Block(-10,-4,4,STONE)
Block(-5,-5,-8,STONE)
Block(-10,-3,4,STONE)
Block(-10,-2,4,STONE)
Block(-10,-1,4,STONE)
Block(-4,4,13,STONE)
Block(-4,3,13,STONE)
Block(-4,2,13,STONE)
Block(-4,1,13,STONE)
Block(-4,0,13,STONE)
Block(-8,-1,11,STONE)
Block(-2,3,10,STONE)
Block(-2,2,10,STONE)
Block(-2,5,10,STONE)
Block(-2,4,10,STONE)
Block(-7,-1,11,STONE)
Block(-7,-2,11,STONE)
Block(-2,1,10,STONE)
Block(-2,0,10,STONE)
Block(-10,-5,4,STONE)
Block(-7,-5,11,STONE)
Block(-5,2,-5,STONE)
Block(-5,3,-5,STONE)
Block(-1,10,3,SNOW_BLOCK)
Block(-7,-3,11,STONE)
Block(-5,0,-5,STONE)
Block(0,14,7,SNOW_BLOCK)
Block(-7,-4,11,STONE)
Block(-5,1,-5,STONE)
Block(0,15,7,SNOW_BLOCK)
Block(-2,7,10,STONE)
Block(0,12,7,STONE)
Block(-2,6,10,STONE)
Block(0,13,7,STONE)
Block(-5,4,-5,SNOW_BLOCK)
Block(-2,9,10,STONE)
Block(0,10,7,STONE)
Block(-2,8,10,STONE)
Block(0,11,7,STONE)
Block(-2,20,11,SNOW_BLOCK)
Block(-2,10,8,STONE)
Block(-2,11,8,STONE)
Block(-2,12,8,STONE)
Block(-2,13,8,STONE)
Block(-2,14,8,STONE)
Block(-13,-2,17,SNOW)
Block(-13,-3,17,SNOW_BLOCK)
Block(-2,15,8,STONE)
Block(-2,21,11,SNOW_BLOCK)
Block(-13,-4,17,STONE)
Block(-13,-5,17,STONE)
Block(-3,10,11,STONE)
Block(-3,12,11,STONE)
Block(-3,11,11,STONE)
Block(-3,14,11,STONE)
Block(-3,13,11,STONE)
Block(-3,16,11,STONE)
Block(-3,15,11,STONE)
Block(-3,18,11,STONE)
Block(-3,17,11,STONE)
Block(-3,19,11,STONE)
Block(0,11,9,STONE)
Block(0,10,9,STONE)
Block(-5,-5,9,STONE)
Block(-5,-4,9,STONE)
Block(-5,-3,9,STONE)
Block(-5,-2,9,STONE)
Block(-5,-1,9,STONE)
Block(0,16,9,SNOW_BLOCK)
Block(0,15,9,STONE)
Block(0,14,9,STONE)
Block(-6,10,0,STONE)
Block(0,13,9,STONE)
Block(-6,11,0,STONE)
Block(0,12,9,STONE)
Block(-6,-3,-1,STONE)
Block(-6,-2,-1,STONE)
Block(-6,-1,-1,STONE)
Block(-6,-5,-1,STONE)
Block(-6,-4,-1,STONE)
Block(-1,-5,8,STONE)
Block(-1,-1,8,STONE)
Block(-1,-2,8,STONE)
Block(-1,-3,8,STONE)
Block(-1,-4,8,STONE)
Block(-7,13,2,STONE)
Block(-7,14,2,SNOW_BLOCK)
Block(-7,11,2,STONE)
Block(-7,12,2,STONE)
Block(-7,10,2,STONE)
Block(-10,-2,0,STONE)
Block(-10,-1,0,STONE)
Block(-10,-4,0,STONE)
Block(-10,-3,0,STONE)
Block(-3,8,3,STONE)
Block(-3,11,12,STONE)
Block(-10,-5,0,STONE)
Block(-3,7,3,STONE)
Block(-3,10,12,STONE)
Block(-3,13,12,STONE)
Block(-10,2,2,SNOW_BLOCK)
Block(-3,9,3,STONE)
Block(-3,12,12,STONE)
Block(-10,1,2,STONE)
Block(-3,4,3,STONE)
Block(-3,15,12,STONE)
Block(-10,0,2,STONE)
Block(-3,3,3,STONE)
Block(-3,14,12,STONE)
Block(-3,6,3,STONE)
Block(-3,17,12,STONE)
Block(-3,5,3,STONE)
Block(-3,16,12,STONE)
Block(-3,0,3,STONE)
Block(-3,19,12,SNOW_BLOCK)
Block(-3,18,12,STONE)
Block(-3,2,3,STONE)
Block(-3,1,3,STONE)
Block(-6,12,0,STONE)
Block(-6,13,0,SNOW_BLOCK)
Block(-1,0,7,STONE)
Block(-6,14,0,SNOW)
Block(-1,2,7,STONE)
Block(-1,1,7,STONE)
Block(-1,4,7,STONE)
Block(-1,3,7,STONE)
Block(0,10,13,SNOW_BLOCK)
Block(-1,5,10,STONE)
Block(-1,6,7,STONE)
Block(-1,5,7,STONE)
Block(-1,6,10,STONE)
Block(-1,7,10,STONE)
Block(-1,8,7,STONE)
Block(-1,7,7,STONE)
Block(-1,8,10,STONE)
Block(-1,9,10,STONE)
Block(-1,9,7,STONE)
Block(-3,0,-1,STONE)
Block(-3,1,-1,STONE)
Block(-3,2,-1,STONE)
Block(-3,3,-1,STONE)
Block(-3,4,-1,STONE)
Block(-3,20,12,SNOW_BLOCK)
Block(-1,0,10,STONE)
Block(-3,5,-1,STONE)
Block(-1,1,10,STONE)
Block(-3,6,-1,STONE)
Block(-1,2,10,STONE)
Block(-3,7,-1,STONE)
Block(-1,3,10,STONE)
Block(-3,8,-1,STONE)
Block(-1,4,10,STONE)
Block(-3,9,-1,STONE)
Block(2,-1,10,STONE)
Block(-4,20,3,SNOW_BLOCK)
Block(-4,21,3,SNOW)
Block(-6,7,-4,SNOW_BLOCK)
Block(-6,6,-4,STONE)
Block(2,-3,10,STONE)
Block(-6,5,-4,STONE)
Block(2,-2,10,STONE)
Block(-6,4,-4,STONE)
Block(2,-5,10,STONE)
Block(-6,3,-4,STONE)
Block(2,-4,10,STONE)
Block(-6,2,-4,STONE)
Block(-6,1,-4,STONE)
Block(-5,19,9,STONE)
Block(-6,0,-4,STONE)
Block(-5,18,9,STONE)
Block(-5,17,9,STONE)
Block(-5,16,9,STONE)
Block(-5,15,9,STONE)
Block(-5,14,9,STONE)
Block(-5,13,9,STONE)
Block(-5,12,9,STONE)
Block(-5,11,9,STONE)
Block(-4,13,3,STONE)
Block(-5,10,9,STONE)
Block(-4,14,3,STONE)
Block(-4,15,3,STONE)
Block(-4,16,3,STONE)
Block(-4,17,3,STONE)
Block(-4,18,3,STONE)
Block(-4,19,3,SNOW_BLOCK)
Block(-1,-3,15,STONE)
Block(-1,-4,15,STONE)
Block(-1,-1,15,STONE)
Block(-1,-2,15,STONE)
Block(-4,10,3,STONE)
Block(-4,11,3,STONE)
Block(-4,12,3,STONE)
Block(-1,-5,15,STONE)
Block(-9,-5,-4,STONE)
Block(-9,-4,-4,STONE)
Block(-9,-3,-4,STONE)
Block(-9,-2,-4,STONE)
Block(-9,-1,-4,STONE)
Block(-9,2,4,STONE)
Block(-9,3,4,STONE)
Block(-9,0,4,STONE)
Block(-9,1,4,STONE)
Block(-9,4,4,STONE)
Block(-9,5,4,SNOW_BLOCK)
Block(-8,2,14,STONE)
Block(-8,3,14,STONE)
Block(-8,0,14,STONE)
Block(-8,1,14,STONE)
Block(-8,6,14,SNOW_BLOCK)
Block(-8,7,14,SNOW)
Block(-8,4,14,STONE)
Block(-8,5,14,STONE)
Block(-2,-1,10,STONE)
Block(-2,-2,10,STONE)
Block(-2,-5,10,STONE)
Block(-2,-3,10,STONE)
Block(-2,-4,10,STONE)
Block(-3,0,15,STONE)
Block(-3,1,15,STONE)
Block(-3,4,15,STONE)
Block(-3,5,15,STONE)
Block(-7,-5,2,STONE)
Block(-3,2,15,STONE)
Block(-3,3,15,STONE)
Block(-7,-3,2,STONE)
Block(-7,-4,2,STONE)
Block(-7,-1,2,STONE)
Block(-3,6,15,STONE)
Block(-7,-2,2,STONE)
Block(-3,7,15,SNOW_BLOCK)
Block(-4,-1,3,STONE)
Block(-4,-2,3,STONE)
Block(-4,-3,3,STONE)
Block(-4,-4,3,STONE)
Block(-4,-5,3,STONE)
Block(-6,5,1,STONE)
Block(-4,6,-3,STONE)
Block(-6,4,1,STONE)
Block(-4,5,-3,STONE)
Block(-6,3,1,STONE)
Block(-4,8,-3,SNOW_BLOCK)
Block(-6,2,1,STONE)
Block(-4,7,-3,STONE)
Block(-6,1,1,STONE)
Block(-4,2,-3,STONE)
Block(-6,0,1,STONE)
Block(-4,1,-3,STONE)
Block(-4,4,-3,STONE)
Block(-4,3,-3,STONE)
Block(-6,9,1,STONE)
Block(-6,8,1,STONE)
Block(-6,7,1,STONE)
Block(-6,6,1,STONE)
Block(-10,-3,11,STONE)
Block(-10,-4,11,STONE)
Block(-10,-1,11,STONE)
Block(-4,0,-3,STONE)
Block(-10,-2,11,STONE)
Block(-10,-5,11,STONE)
Block(-5,0,15,STONE)
Block(-4,7,5,STONE)
Block(-5,1,15,STONE)
Block(-4,6,5,STONE)
Block(-5,2,15,STONE)
Block(-4,5,5,STONE)
Block(-5,3,15,STONE)
Block(-4,4,5,STONE)
Block(-4,9,5,STONE)
Block(-4,8,5,STONE)
Block(-4,3,5,STONE)
Block(-4,2,5,STONE)
Block(-4,1,5,STONE)
Block(-4,0,5,STONE)
Block(-5,4,15,STONE)
Block(-5,5,15,STONE)
Block(-5,6,15,STONE)
Block(-5,7,15,SNOW_BLOCK)
Block(-2,9,9,STONE)
Block(-2,8,9,STONE)
Block(-2,7,9,STONE)
Block(-2,6,9,STONE)
Block(-2,5,9,STONE)
Block(-2,4,9,STONE)
Block(-2,3,9,STONE)
Block(-2,2,9,STONE)
Block(-5,10,-2,SNOW_BLOCK)
Block(-2,1,9,STONE)
Block(-2,0,9,STONE)
Block(-1,11,8,STONE)
Block(-7,-5,17,STONE)
Block(-1,12,8,STONE)
Block(-1,13,8,STONE)
Block(-1,14,8,STONE)
Block(-7,-2,17,STONE)
Block(-7,-1,17,STONE)
Block(-7,-4,17,STONE)
Block(-7,-3,17,STONE)
Block(-1,10,8,STONE)
Block(-3,-5,-2,STONE)
Block(-2,-1,-3,STONE)
Block(-3,-4,-2,STONE)
Block(-2,-5,-3,STONE)
Block(-2,-4,-3,STONE)
Block(-2,-3,-3,STONE)
Block(-2,-2,-3,STONE)
Block(-8,-1,16,STONE)
Block(-8,-2,16,STONE)
Block(-8,-5,16,STONE)
Block(-3,-1,-2,STONE)
Block(-3,-3,-2,STONE)
Block(-8,-3,16,STONE)
Block(-8,-4,16,STONE)
Block(-3,-2,-2,STONE)
Block(-1,22,8,SNOW_BLOCK)
Block(-1,20,8,SNOW_BLOCK)
Block(-1,21,8,SNOW_BLOCK)
Block(-6,12,-1,SNOW)
Block(-6,11,-1,SNOW_BLOCK)
Block(-6,10,-1,STONE)
Block(-1,19,8,SNOW_BLOCK)
Block(-1,15,8,STONE)
Block(-1,16,8,STONE)
Block(-1,17,8,STONE)
Block(-1,18,8,STONE)
Block(-5,-2,17,SNOW_BLOCK)
Block(-5,-3,17,STONE)
Block(-5,-4,17,STONE)
Block(-5,9,7,STONE)
Block(-5,-5,17,STONE)
Block(-5,-1,-2,STONE)
Block(-6,-1,0,STONE)
Block(-6,-2,0,STONE)
Block(-6,-3,0,STONE)
Block(-6,-4,0,STONE)
Block(-6,-5,0,STONE)
Block(-11,4,-2,SNOW)
Block(-5,-3,-2,STONE)
Block(-11,0,-2,STONE)
Block(-5,-2,-2,STONE)
Block(-11,1,-2,STONE)
Block(-5,-5,-2,STONE)
Block(-11,2,-2,STONE)
Block(-5,-4,-2,STONE)
Block(-11,3,-2,SNOW_BLOCK)
Block(0,-1,13,STONE)
Block(0,-2,13,STONE)
Block(0,-5,13,STONE)
Block(0,-3,13,STONE)
Block(0,-4,13,STONE)
Block(-12,-2,0,STONE)
Block(-5,1,-2,STONE)
Block(-12,-1,0,STONE)
Block(-5,2,-2,STONE)
Block(-5,0,-2,STONE)
Block(-7,0,3,STONE)
Block(-7,2,3,STONE)
Block(-7,1,3,STONE)
Block(-5,5,-2,STONE)
Block(-7,8,3,STONE)
Block(-5,6,-2,STONE)
Block(-7,7,3,STONE)
Block(-5,3,-2,STONE)
Block(-5,4,-2,STONE)
Block(-7,9,3,STONE)
Block(-7,4,3,STONE)
Block(-5,9,-2,STONE)
Block(-7,3,3,STONE)
Block(-7,6,3,STONE)
Block(-5,7,-2,STONE)
Block(-7,5,3,STONE)
Block(-5,8,-2,STONE)
Block(-5,2,7,STONE)
Block(-5,1,7,STONE)
Block(-5,4,7,STONE)
Block(-5,3,7,STONE)
Block(-14,-4,16,STONE)
Block(-5,6,7,STONE)
Block(-14,-5,16,STONE)
Block(-5,5,7,STONE)
Block(-5,8,7,STONE)
Block(-14,-2,16,SNOW)
Block(-14,-3,16,SNOW_BLOCK)
Block(-5,7,7,STONE)
Block(-5,0,7,STONE)
Block(-9,-4,14,STONE)
Block(-9,-5,14,STONE)
Block(-9,-1,14,STONE)
Block(-9,-2,14,STONE)
Block(-9,-3,14,STONE)
Block(-2,0,13,STONE)
Block(-5,0,16,STONE)
Block(-5,1,16,STONE)
Block(-2,2,13,STONE)
Block(-2,1,13,STONE)
Block(-5,2,16,SNOW_BLOCK)
Block(-12,-5,16,STONE)
Block(-12,-4,16,STONE)
Block(-12,-1,16,SNOW)
Block(-12,-3,16,STONE)
Block(-12,-2,16,SNOW_BLOCK)
Block(-2,8,13,STONE)
Block(-2,7,13,STONE)
Block(-2,9,13,STONE)
Block(-2,4,13,STONE)
Block(-2,3,13,STONE)
Block(-2,6,13,STONE)
Block(-2,5,13,STONE)
Block(-7,-1,14,STONE)
Block(-7,-5,14,STONE)
Block(-7,-4,14,STONE)
Block(-7,-3,14,STONE)
Block(-7,-2,14,STONE)
Block(-2,9,0,SNOW_BLOCK)
Block(-2,8,0,STONE)
Block(-2,7,0,STONE)
Block(-2,6,0,STONE)
Block(-2,5,0,STONE)
Block(-2,4,0,STONE)
Block(-2,3,0,STONE)
Block(-2,-1,7,STONE)
Block(-2,2,0,STONE)
Block(-2,-2,7,STONE)
Block(-2,1,0,STONE)
Block(-2,-3,7,STONE)
Block(-2,0,0,STONE)
Block(-2,-4,7,STONE)
Block(-2,-5,7,STONE)
Block(0,-4,6,STONE)
Block(0,-3,6,STONE)
Block(0,-5,6,STONE)
Block(-3,-1,-5,STONE)
Block(-3,-2,-5,STONE)
Block(0,-2,6,STONE)
Block(0,-1,6,STONE)
Block(-3,-5,-5,STONE)
Block(-3,-3,-5,STONE)
Block(-3,-4,-5,STONE)
Block(0,-5,10,STONE)
Block(0,-4,10,STONE)
Block(-11,-1,6,SNOW)
Block(-11,-2,6,SNOW_BLOCK)
Block(-11,-3,6,STONE)
Block(-11,-4,6,STONE)
Block(-6,9,9,STONE)
Block(-11,-5,6,STONE)
Block(-6,8,9,STONE)
Block(-6,7,9,STONE)
Block(-6,6,9,STONE)
Block(0,-1,10,STONE)
Block(0,-3,10,STONE)
Block(0,-2,10,STONE)
Block(-7,9,12,STONE)
Block(-7,0,12,STONE)
Block(-8,8,5,STONE)
Block(-8,9,5,STONE)
Block(-7,7,12,STONE)
Block(-12,-5,0,STONE)
Block(-7,8,12,STONE)
Block(-12,-4,0,STONE)
Block(-7,5,12,STONE)
Block(-12,-3,0,STONE)
Block(-7,6,12,STONE)
Block(-7,3,12,STONE)
Block(-7,4,12,STONE)
Block(-7,1,12,STONE)
Block(-7,2,12,STONE)
Block(-1,13,12,STONE)
Block(-1,12,12,STONE)
Block(-1,15,12,STONE)
Block(0,0,2,SNOW_BLOCK)
Block(-1,14,12,STONE)
Block(-1,11,12,STONE)
Block(-1,10,12,STONE)
Block(-8,4,5,STONE)
Block(-8,5,5,STONE)
Block(2,1,11,SNOW_BLOCK)
Block(-8,6,5,STONE)
Block(2,0,11,STONE)
Block(-8,7,5,STONE)
Block(-2,10,7,STONE)
Block(-8,-4,4,STONE)
Block(-8,0,5,STONE)
Block(-2,11,7,STONE)
Block(-1,17,12,SNOW_BLOCK)
Block(-8,-5,4,STONE)
Block(-8,1,5,STONE)
Block(-2,12,7,STONE)
Block(-1,16,12,STONE)
Block(-8,2,5,STONE)
Block(-2,13,7,STONE)
Block(-8,3,5,STONE)
Block(-2,14,7,STONE)
Block(-1,18,12,SNOW)
Block(-9,4,13,SNOW_BLOCK)
Block(-9,3,13,STONE)
Block(-9,2,13,STONE)
Block(-9,1,13,STONE)
Block(-9,0,13,STONE)
Block(-4,-5,10,STONE)
Block(-6,5,9,STONE)
Block(-6,4,9,STONE)
Block(-6,3,9,STONE)
Block(-2,20,7,SNOW_BLOCK)
Block(-6,2,9,STONE)
Block(-2,21,7,SNOW_BLOCK)
Block(-6,1,9,STONE)
Block(-2,22,7,SNOW_BLOCK)
Block(-6,0,9,STONE)
Block(-2,23,7,SNOW_BLOCK)
Block(-2,24,7,SNOW_BLOCK)
Block(-2,25,7,SNOW)
Block(-2,15,7,STONE)
Block(-2,16,7,STONE)
Block(-2,17,7,STONE)
Block(-2,18,7,STONE)
Block(-2,19,7,STONE)
Block(-4,-4,10,STONE)
Block(-4,-3,10,STONE)
Block(0,13,6,SNOW_BLOCK)
Block(-4,-2,10,STONE)
Block(-4,-1,10,STONE)
Block(0,10,6,STONE)
Block(0,12,6,STONE)
Block(0,11,6,STONE)
Block(-6,17,3,STONE)
Block(-6,18,3,SNOW_BLOCK)
Block(-6,15,3,STONE)
Block(-2,24,10,SNOW)
Block(-6,16,3,STONE)
Block(-3,-2,1,STONE)
Block(-11,0,4,SNOW)
Block(-3,-3,1,STONE)
Block(-6,19,3,SNOW)
Block(-3,-1,1,STONE)
Block(-3,-4,1,STONE)
Block(-3,-5,1,STONE)
Block(-10,-2,3,STONE)
Block(-2,22,10,SNOW_BLOCK)
Block(-10,-3,3,STONE)
Block(-2,23,10,SNOW_BLOCK)
Block(-2,20,10,SNOW_BLOCK)
Block(-10,-1,3,STONE)
Block(-2,21,10,SNOW_BLOCK)
Block(-10,0,-3,STONE)
Block(-10,1,-3,STONE)
Block(-10,2,-3,STONE)
Block(-10,3,-3,STONE)
Block(-10,4,-3,SNOW_BLOCK)
Block(-10,5,-3,SNOW)
Block(-2,15,10,STONE)
Block(-2,16,10,STONE)
Block(-2,13,10,STONE)
Block(-2,14,10,STONE)
Block(-2,19,10,STONE)
Block(-2,17,10,STONE)
Block(-2,18,10,STONE)
Block(-2,11,10,STONE)
Block(-2,12,10,STONE)
Block(-2,10,10,STONE)
Block(-10,-4,3,STONE)
Block(-10,-5,3,STONE)
Block(-8,10,4,SNOW_BLOCK)
Block(-5,24,9,SNOW_BLOCK)
Block(-5,23,9,SNOW_BLOCK)
Block(-9,-2,7,STONE)
Block(-5,22,9,SNOW_BLOCK)
Block(-9,-3,7,STONE)
Block(-6,10,3,STONE)
Block(-5,21,9,SNOW_BLOCK)
Block(-5,20,9,STONE)
Block(-9,-1,7,STONE)
Block(-6,13,3,STONE)
Block(-6,14,3,STONE)
Block(-9,-4,7,STONE)
Block(-6,11,3,STONE)
Block(-9,-5,7,STONE)
Block(-6,12,3,STONE)
Block(-1,-1,12,STONE)
Block(-4,11,6,STONE)
Block(-4,10,6,STONE)
Block(-4,13,6,STONE)
Block(-4,12,6,STONE)
Block(-4,15,6,STONE)
Block(-4,14,6,STONE)
Block(-1,-3,12,STONE)
Block(-1,-2,12,STONE)
Block(-13,-2,18,SNOW)
Block(-1,-5,12,STONE)
Block(-13,-3,18,SNOW_BLOCK)
Block(-1,-4,12,STONE)
Block(-13,-4,18,STONE)
Block(-13,-5,18,STONE)
Block(-4,21,10,SNOW_BLOCK)
Block(-4,20,10,STONE)
Block(-3,9,2,STONE)
Block(-3,8,2,STONE)
Block(-3,5,2,STONE)
Block(-3,4,2,STONE)
Block(-3,7,2,STONE)
Block(-3,6,2,STONE)
Block(-3,1,2,STONE)
Block(-4,25,10,SNOW)
Block(-3,0,2,STONE)
Block(-4,24,10,SNOW_BLOCK)
Block(-3,3,2,STONE)
Block(-4,23,10,SNOW_BLOCK)
Block(-3,2,2,STONE)
Block(-4,22,10,SNOW_BLOCK)
Block(-1,1,6,STONE)
Block(-1,0,6,STONE)
Block(-1,3,6,STONE)
Block(-1,2,6,STONE)
Block(-1,5,6,STONE)
Block(-1,4,6,STONE)
Block(-4,19,10,STONE)
Block(-1,7,6,STONE)
Block(-1,6,6,STONE)
Block(-1,9,6,STONE)
Block(-1,8,6,STONE)
Block(-4,10,10,STONE)
Block(-4,18,10,STONE)
Block(-4,17,10,STONE)
Block(-4,16,10,STONE)
Block(-4,15,10,STONE)
Block(-4,14,10,STONE)
Block(-4,13,10,STONE)
Block(-4,12,10,STONE)
Block(-4,11,10,STONE)
Block(-3,12,1,STONE)
Block(-3,13,1,STONE)
Block(-3,10,1,STONE)
Block(-3,11,1,STONE)
Block(-3,14,1,SNOW_BLOCK)
Block(-10,-3,-4,STONE)
Block(-3,-1,12,STONE)
Block(-10,-2,-4,STONE)
Block(-3,-3,12,STONE)
Block(-10,-1,-4,STONE)
Block(-3,-2,12,STONE)
Block(-3,-5,12,STONE)
Block(-7,-5,-7,SNOW)
Block(-3,-4,12,STONE)
Block(-10,-5,-4,STONE)
Block(-10,-4,-4,STONE)
Block(-4,20,6,STONE)
Block(-4,22,6,SNOW_BLOCK)
Block(-4,21,6,SNOW_BLOCK)
Block(-4,24,6,SNOW_BLOCK)
Block(-4,23,6,SNOW_BLOCK)
Block(-4,25,6,SNOW_BLOCK)
Block(-8,-1,4,STONE)
Block(-8,-2,4,STONE)
Block(-8,-3,4,STONE)
Block(-11,-3,18,STONE)
Block(-4,17,6,STONE)
Block(-11,-4,18,STONE)
Block(-4,16,6,STONE)
Block(-14,-5,1,SNOW_BLOCK)
Block(-11,-5,18,STONE)
Block(-4,19,6,STONE)
Block(-14,-4,1,SNOW_BLOCK)
Block(-4,18,6,STONE)
Block(-11,-1,18,SNOW)
Block(-11,-2,18,SNOW_BLOCK)
Block(-8,3,13,STONE)
Block(-8,4,13,STONE)
Block(-8,1,13,STONE)
Block(-8,2,13,STONE)
Block(-8,7,13,SNOW_BLOCK)
Block(-8,8,13,SNOW)
Block(-4,-1,6,STONE)
Block(-8,5,13,STONE)
Block(-8,6,13,STONE)
Block(-5,-2,-7,STONE)
Block(-5,-3,-7,STONE)
Block(-5,-4,-7,STONE)
Block(-8,0,13,STONE)
Block(-5,-5,-7,STONE)
Block(-8,-4,7,STONE)
Block(-5,-4,12,STONE)
Block(-5,-5,12,STONE)
Block(-8,-3,7,STONE)
Block(-5,-2,12,STONE)
Block(-8,-5,7,STONE)
Block(-5,-3,12,STONE)
Block(-5,-1,12,STONE)
Block(-8,-2,7,STONE)
Block(-8,-1,7,STONE)
Block(-12,-5,5,STONE)
Block(-12,-4,5,STONE)
Block(-4,-1,-3,STONE)
Block(-12,-3,5,SNOW_BLOCK)
Block(-4,-2,-3,STONE)
Block(-4,-3,-3,STONE)
Block(-4,-4,-3,STONE)
Block(-11,3,-3,SNOW_BLOCK)
Block(-1,4,11,STONE)
Block(-4,-5,-3,STONE)
Block(-1,5,11,STONE)
Block(-11,4,-3,SNOW)
Block(-1,6,11,STONE)
Block(-1,7,11,STONE)
Block(-1,8,11,STONE)
Block(-11,0,-3,STONE)
Block(-1,9,11,STONE)
Block(-11,1,-3,STONE)
Block(-11,2,-3,STONE)
Block(-1,0,11,STONE)
Block(-1,1,11,STONE)
Block(-1,2,11,STONE)
Block(-1,3,11,STONE)
Block(-11,-4,3,STONE)
Block(-11,-3,3,STONE)
Block(-11,-2,3,STONE)
Block(-11,-1,3,SNOW_BLOCK)
Block(-6,4,-5,SNOW_BLOCK)
Block(-6,3,-5,STONE)
Block(-6,2,-5,STONE)
Block(-6,1,-5,STONE)
Block(-6,0,-5,STONE)
Block(-3,-2,4,STONE)
Block(-3,-1,4,STONE)
Block(-3,-5,4,STONE)
Block(-3,-4,4,STONE)
Block(-3,-3,4,STONE)
Block(-11,-5,-2,STONE)
Block(-11,-2,-2,STONE)
Block(-11,-1,-2,STONE)
Block(-11,-4,-2,STONE)
Block(-11,-3,-2,STONE)
Block(-4,-3,6,STONE)
Block(-9,1,5,STONE)
Block(-4,-2,6,STONE)
Block(-9,2,5,STONE)
Block(-4,-5,6,STONE)
Block(-4,-4,6,STONE)
Block(-9,0,5,STONE)
Block(-9,5,5,STONE)
Block(-9,6,5,SNOW_BLOCK)
Block(-9,3,5,STONE)
Block(-9,4,5,STONE)
Block(-4,8,4,STONE)
Block(-4,7,4,STONE)
Block(-4,6,4,STONE)
Block(-4,5,4,STONE)
Block(-4,9,4,STONE)
Block(-4,0,4,STONE)
Block(-13,-5,15,STONE)
Block(-4,4,4,STONE)
Block(-13,-4,15,STONE)
Block(-4,3,4,STONE)
Block(-13,-3,15,SNOW_BLOCK)
Block(-4,2,4,STONE)
Block(-4,1,4,STONE)
Block(-13,-2,15,SNOW)
Block(0,-1,1,SNOW_BLOCK)
Block(-5,18,12,SNOW_BLOCK)
Block(-5,16,12,STONE)
Block(-5,17,12,STONE)
Block(0,-5,1,STONE)
Block(-5,14,12,STONE)
Block(0,-4,1,STONE)
Block(-5,15,12,STONE)
Block(0,-3,1,STONE)
Block(-10,2,3,SNOW_BLOCK)
Block(-5,12,12,STONE)
Block(0,-2,1,STONE)
Block(-10,1,3,STONE)
Block(-5,13,12,STONE)
Block(-10,0,3,STONE)
Block(-5,10,12,STONE)
Block(-1,14,5,STONE)
Block(-5,11,12,STONE)
Block(-1,15,5,STONE)
Block(-1,12,5,STONE)
Block(-1,13,5,STONE)
Block(-1,16,5,STONE)
Block(-1,17,5,SNOW_BLOCK)
Block(-2,9,8,STONE)
Block(-2,8,8,STONE)
Block(-2,7,8,STONE)
Block(-2,6,8,STONE)
Block(-2,5,8,STONE)
Block(-2,4,8,STONE)
Block(-2,3,8,STONE)
Block(-2,2,8,STONE)
Block(-2,1,8,STONE)
Block(-2,0,8,STONE)
Block(-7,10,-2,SNOW)
Block(-10,-3,16,STONE)
Block(-10,-2,16,STONE)
Block(-10,-5,16,STONE)
Block(-10,-4,16,STONE)
Block(-10,-1,16,STONE)
Block(-14,-4,19,STONE)
Block(-14,-3,19,SNOW)
Block(-14,-5,19,STONE)
Block(-3,12,4,STONE)
Block(-3,11,4,STONE)
Block(-3,10,4,STONE)
Block(-8,-5,13,STONE)
Block(-6,6,0,STONE)
Block(-3,16,4,STONE)
Block(-8,-4,13,STONE)
Block(-6,5,0,STONE)
Block(-3,15,4,STONE)
Block(-6,4,0,STONE)
Block(-3,14,4,STONE)
Block(-6,3,0,STONE)
Block(-3,13,4,STONE)
Block(-6,2,0,STONE)
Block(-6,1,0,STONE)
Block(-3,19,4,SNOW_BLOCK)
Block(-6,0,0,STONE)
Block(-3,18,4,STONE)
Block(-3,17,4,STONE)
Block(-14,-4,20,SNOW)
Block(-14,-5,20,STONE)
Block(-6,9,0,STONE)
Block(-6,8,0,STONE)
Block(-6,7,0,STONE)
Block(-2,-5,-6,STONE)
Block(-2,-2,-6,STONE)
Block(-2,-4,-6,STONE)
Block(-2,-3,-6,STONE)
Block(-4,1,16,SNOW_BLOCK)
Block(-4,0,16,STONE)
Block(-8,-1,13,STONE)
Block(-3,22,4,SNOW)
Block(-8,-3,13,STONE)
Block(-3,21,4,SNOW_BLOCK)
Block(-8,-2,13,STONE)
Block(-3,20,4,SNOW_BLOCK)
Block(-5,-5,6,STONE)
Block(-5,-3,6,STONE)
Block(-5,-4,6,STONE)
Block(-6,10,8,STONE)
Block(-6,11,8,STONE)
Block(-6,16,8,STONE)
Block(-6,17,8,STONE)
Block(-6,18,8,STONE)
Block(-6,19,8,STONE)
Block(-6,12,8,STONE)
Block(-6,13,8,STONE)
Block(-6,14,8,STONE)
Block(-6,15,8,STONE)
Block(-6,1,10,STONE)
Block(-6,0,10,STONE)
Block(-6,3,10,STONE)
Block(-6,2,10,STONE)
Block(-6,5,10,STONE)
Block(-6,4,10,STONE)
Block(-3,1,14,STONE)
Block(-6,7,10,STONE)
Block(-3,2,14,STONE)
Block(-6,6,10,STONE)
Block(-6,9,10,STONE)
Block(-3,0,14,STONE)
Block(-6,8,10,STONE)
Block(-5,-1,6,STONE)
Block(-3,5,14,STONE)
Block(-5,-2,6,STONE)
Block(-3,6,14,STONE)
Block(-3,3,14,STONE)
Block(-3,4,14,STONE)
Block(-3,9,14,STONE)
Block(-3,7,14,STONE)
Block(-3,8,14,STONE)
Block(-7,-2,-2,STONE)
Block(-7,-3,-2,STONE)
Block(-7,-1,-2,STONE)
Block(-7,-4,-2,STONE)
Block(-7,-5,-2,STONE)
Block(-2,-4,2,STONE)
Block(-2,-5,2,STONE)
Block(-1,-2,-2,STONE)
Block(-2,-2,2,STONE)
Block(-1,-3,-2,STONE)
Block(-2,-3,2,STONE)
Block(-1,-4,-2,STONE)
Block(-1,-5,-2,STONE)
Block(-2,-1,2,STONE)
Block(-1,-1,-2,STONE)
Block(-9,-2,17,STONE)
Block(-9,-1,17,STONE)
Block(-9,-4,17,STONE)
Block(-9,-3,17,STONE)
Block(-9,-5,17,STONE)
Block(0,11,10,STONE)
Block(0,10,10,STONE)
Block(0,13,10,STONE)
Block(0,12,10,STONE)
Block(0,15,10,STONE)
Block(0,14,10,STONE)
Block(0,16,10,SNOW_BLOCK)
Block(-4,7,-2,STONE)
Block(-4,6,-2,STONE)
Block(1,-2,14,STONE)
Block(-4,9,-2,STONE)
Block(1,-1,14,STONE)
Block(-4,8,-2,STONE)
Block(1,-4,14,STONE)
Block(-4,3,-2,STONE)
Block(1,-3,14,STONE)
Block(-4,2,-2,STONE)
Block(-4,5,-2,STONE)
Block(1,-5,14,STONE)
Block(-4,4,-2,STONE)
Block(-7,17,5,SNOW_BLOCK)
Block(-7,16,5,STONE)
Block(-7,15,5,STONE)
Block(-7,14,5,STONE)
Block(-7,13,5,STONE)
Block(-7,12,5,STONE)
Block(-7,11,5,STONE)
Block(-7,10,5,STONE)
Block(-6,20,8,SNOW_BLOCK)
Block(-6,21,8,SNOW_BLOCK)
Block(-6,22,8,SNOW_BLOCK)
Block(-4,1,-2,STONE)
Block(-4,0,-2,STONE)
Block(-5,19,6,STONE)
Block(-5,17,6,STONE)
Block(-5,18,6,STONE)
Block(-5,24,6,SNOW_BLOCK)
Block(-5,25,6,SNOW)
Block(-5,22,6,SNOW_BLOCK)
Block(-5,23,6,SNOW_BLOCK)
Block(-7,-5,5,STONE)
Block(-5,20,6,SNOW_BLOCK)
Block(-7,-4,5,STONE)
Block(-5,21,6,SNOW_BLOCK)
Block(-8,10,7,STONE)
Block(-8,11,7,SNOW_BLOCK)
Block(-11,0,17,SNOW)
Block(-5,15,6,STONE)
Block(-5,16,6,STONE)
Block(-5,13,6,STONE)
Block(-5,14,6,STONE)
Block(-5,11,6,STONE)
Block(-5,12,6,STONE)
Block(-5,10,6,STONE)
Block(-11,-5,3,STONE)
Block(-6,-5,16,STONE)
Block(-6,-3,16,STONE)
Block(-2,12,2,STONE)
Block(-6,-4,16,STONE)
Block(-2,13,2,SNOW_BLOCK)
Block(-6,-1,16,STONE)
Block(-2,10,2,STONE)
Block(-6,-2,16,STONE)
Block(-2,11,2,STONE)
Block(-7,1,2,STONE)
Block(-7,0,2,STONE)
Block(-7,3,2,STONE)
Block(-7,2,2,STONE)
Block(-7,9,2,STONE)
Block(-7,8,2,STONE)
Block(-7,5,2,STONE)
Block(-7,4,2,STONE)
Block(-7,7,2,STONE)
Block(-7,6,2,STONE)
Block(-7,-3,5,STONE)
Block(-7,-2,5,STONE)
Block(-7,-1,5,STONE)
Block(-13,-4,2,SNOW_BLOCK)
Block(-13,-5,2,SNOW_BLOCK)
Block(-5,3,6,STONE)
Block(-5,2,6,STONE)
Block(-5,5,6,STONE)
Block(-5,4,6,STONE)
Block(-5,7,6,STONE)
Block(-5,6,6,STONE)
Block(-5,9,6,STONE)
Block(-5,8,6,STONE)
Block(-5,1,6,STONE)
Block(-5,0,6,STONE)
Block(-3,17,7,STONE)
Block(-6,-5,-6,STONE)
Block(-3,16,7,STONE)
Block(-3,19,7,STONE)
Block(-3,18,7,STONE)
Block(-6,-2,-6,STONE)
Block(-6,-1,-6,STONE)
Block(-6,-4,-6,STONE)
Block(-6,-3,-6,STONE)
Block(-10,-4,20,SNOW_BLOCK)
Block(-10,-5,20,SNOW_BLOCK)
Block(-4,-1,13,STONE)
Block(-4,-2,13,STONE)
Block(-4,-3,13,STONE)
Block(-4,-4,13,STONE)
Block(-4,-5,13,STONE)
Block(-10,0,16,SNOW_BLOCK)
Block(-3,24,7,SNOW_BLOCK)
Block(-3,23,7,SNOW_BLOCK)
Block(-3,10,-2,SNOW)
Block(-3,25,7,SNOW_BLOCK)
Block(-10,1,16,SNOW)
Block(-3,20,7,STONE)
Block(-3,22,7,SNOW_BLOCK)
Block(-3,21,7,SNOW_BLOCK)
Block(-10,-5,19,STONE)
Block(-10,-3,19,SNOW_BLOCK)
Block(-10,-4,19,STONE)
Block(-10,-2,19,SNOW)
Block(-5,-5,3,STONE)
Block(-5,-4,3,STONE)
Block(-12,-5,-1,STONE)
Block(-5,-1,3,STONE)
Block(-12,-3,-1,STONE)
Block(-5,-3,3,STONE)
Block(-12,-4,-1,STONE)
Block(-5,-2,3,STONE)
Block(-12,-1,-1,STONE)
Block(-12,-2,-1,STONE)
Block(-5,0,-3,STONE)
Block(-2,16,13,SNOW_BLOCK)
Block(-5,1,-3,STONE)
Block(-2,17,13,SNOW)
Block(1,2,5,SNOW_BLOCK)
Block(-2,12,13,STONE)
Block(-2,13,13,STONE)
Block(-2,14,13,STONE)
Block(-2,15,13,STONE)
Block(-2,10,13,STONE)
Block(-2,11,13,STONE)
Block(-5,4,-3,STONE)
Block(-5,5,-3,STONE)
Block(-5,2,-3,STONE)
Block(-5,3,-3,STONE)
Block(-9,-1,4,STONE)
Block(-5,8,-3,STONE)
Block(-9,-2,4,STONE)
Block(-5,9,-3,SNOW_BLOCK)
Block(-9,-3,4,STONE)
Block(-5,6,-3,STONE)
Block(-9,-4,4,STONE)
Block(-5,7,-3,STONE)
Block(-9,-5,4,STONE)
Block(-10,-3,6,STONE)
Block(-10,-4,6,STONE)
Block(-10,-5,6,STONE)
Block(-10,-1,6,STONE)
Block(-10,-2,6,STONE)
Block(1,-1,11,STONE)
Block(1,-2,11,STONE)
Block(1,-3,11,STONE)
Block(1,-4,11,STONE)
Block(1,-5,11,STONE)
Block(-4,14,13,STONE)
Block(-4,15,13,STONE)
Block(-4,16,13,SNOW_BLOCK)
Block(-4,17,13,SNOW)
Block(-6,9,8,STONE)
Block(-6,8,8,STONE)
Block(-6,7,8,STONE)
Block(-6,-2,8,STONE)
Block(-6,-3,8,STONE)
Block(-6,-4,8,STONE)
Block(-6,-5,8,STONE)
Block(-4,10,13,STONE)
Block(-4,11,13,STONE)
Block(-4,12,13,STONE)
Block(-6,-1,8,STONE)
Block(-4,13,13,STONE)
Block(-6,-2,13,STONE)
Block(-5,19,3,SNOW_BLOCK)
Block(-6,-3,13,STONE)
Block(-5,18,3,STONE)
Block(-6,-4,13,STONE)
Block(-6,-5,13,STONE)
Block(-5,15,3,STONE)
Block(-5,14,3,STONE)
Block(-5,17,3,STONE)
Block(-6,-1,13,STONE)
Block(-5,16,3,STONE)
Block(-7,0,11,STONE)
Block(-7,1,11,STONE)
Block(-12,-4,20,STONE)
Block(-8,9,4,STONE)
Block(-5,20,3,SNOW)
Block(1,1,5,STONE)
Block(-7,8,11,STONE)
Block(1,0,5,STONE)
Block(-7,9,11,STONE)
Block(-7,6,11,STONE)
Block(-7,7,11,STONE)
Block(-12,-5,20,STONE)
Block(-7,4,11,STONE)
Block(-7,5,11,STONE)
Block(-7,2,11,STONE)
Block(-7,3,11,STONE)
Block(-4,25,9,SNOW_BLOCK)
Block(-4,24,9,SNOW_BLOCK)
Block(-11,-4,15,STONE)
Block(-4,23,9,SNOW_BLOCK)
Block(-11,-5,15,STONE)
Block(-8,0,4,STONE)
Block(-4,22,9,SNOW_BLOCK)
Block(2,0,10,STONE)
Block(-8,5,4,STONE)
Block(-8,6,4,STONE)
Block(-8,7,4,STONE)
Block(2,1,10,SNOW_BLOCK)
Block(-8,8,4,STONE)
Block(-8,1,4,STONE)
Block(-4,21,9,SNOW_BLOCK)
Block(-8,2,4,STONE)
Block(-4,20,9,SNOW_BLOCK)
Block(0,1,15,SNOW_BLOCK)
Block(-8,3,4,STONE)
Block(0,0,15,STONE)
Block(-8,4,4,STONE)
Block(-5,11,3,STONE)
Block(-5,10,3,STONE)
Block(-5,13,3,STONE)
Block(-5,12,3,STONE)
Block(-9,5,14,SNOW)
Block(-9,4,14,SNOW_BLOCK)
Block(-9,3,14,STONE)
Block(-9,2,14,STONE)
Block(-9,1,14,STONE)
Block(-9,0,14,STONE)
Block(-4,19,9,STONE)
Block(-11,-2,15,STONE)
Block(-11,-3,15,STONE)
Block(-11,-1,15,STONE)
Block(-4,14,9,STONE)
Block(-4,13,9,STONE)
Block(-10,-5,-1,STONE)
Block(-4,12,9,STONE)
Block(-4,11,9,STONE)
Block(-4,18,9,STONE)
Block(-4,17,9,STONE)
Block(-4,16,9,STONE)
Block(-4,15,9,STONE)
Block(-6,6,8,STONE)
Block(-6,5,8,STONE)
Block(-6,4,8,STONE)
Block(-6,3,8,STONE)
Block(-6,2,8,STONE)
Block(-4,10,9,STONE)
Block(-6,1,8,STONE)
Block(-6,0,8,STONE)
Block(-10,-3,-1,STONE)
Block(-10,-4,-1,STONE)
Block(-10,-1,-1,STONE)
Block(-10,-2,-1,STONE)
Block(-11,-2,-5,STONE)
Block(-11,-3,-5,STONE)
Block(-11,-1,-5,STONE)
Block(-11,-4,-5,STONE)
Block(-11,-5,-5,STONE)
Block(-11,-1,0,STONE)
Block(-1,-1,5,STONE)
Block(-1,-4,5,STONE)
Block(-1,-5,5,STONE)
Block(-1,-2,5,STONE)
Block(-1,-3,5,STONE)
Block(-11,-4,0,STONE)
Block(-11,-5,0,STONE)
Block(-11,-2,0,STONE)
Block(-11,-3,0,STONE)
Block(-2,1,12,STONE)
Block(-2,0,12,STONE)
Block(-4,-2,-6,STONE)
Block(-2,3,12,STONE)
Block(-4,-1,-6,STONE)
Block(-2,2,12,STONE)
Block(-4,-4,-6,STONE)
Block(-4,-3,-6,STONE)
Block(-4,-5,-6,STONE)
Block(-2,9,12,STONE)
Block(-2,8,12,STONE)
Block(-4,-5,9,STONE)
Block(-2,5,12,STONE)
Block(-2,4,12,STONE)
Block(-2,7,12,STONE)
Block(-2,6,12,STONE)
Block(-4,-4,9,STONE)
Block(-1,10,5,STONE)
Block(-7,1,-6,SNOW)
Block(-4,-3,9,STONE)
Block(-1,11,5,STONE)
Block(-4,-2,9,STONE)
Block(-4,-1,9,STONE)
Block(-12,-2,19,SNOW)
Block(-12,-5,19,STONE)
Block(-12,-3,19,SNOW_BLOCK)
Block(-12,-4,19,STONE)
Block(-7,0,-6,SNOW_BLOCK)
Block(-11,0,5,SNOW)
Block(0,-5,9,STONE)
Block(-14,-4,-1,STONE)
Block(0,-4,9,STONE)
Block(-14,-3,-1,SNOW_BLOCK)
Block(-10,0,-2,STONE)
Block(0,-3,9,STONE)
Block(-10,1,-2,STONE)
Block(0,-2,9,STONE)
Block(-10,2,-2,STONE)
Block(0,-1,9,STONE)
Block(-10,3,-2,STONE)
Block(-10,4,-2,SNOW_BLOCK)
Block(-10,5,-2,SNOW)
Block(-14,-5,-1,STONE)
Block(-3,0,1,STONE)
Block(0,0,3,SNOW_BLOCK)
Block(-2,-2,13,STONE)
Block(0,2,3,SNOW_BLOCK)
Block(-2,-3,13,STONE)
Block(0,1,3,SNOW_BLOCK)
Block(-2,-4,13,STONE)
Block(-2,-5,13,STONE)
Block(-2,-1,13,STONE)
Block(-8,-5,-6,STONE)
Block(-8,-3,-6,STONE)
Block(-8,-4,-6,STONE)
Block(-3,9,1,STONE)
Block(-3,6,1,STONE)
Block(-3,5,1,STONE)
Block(-3,8,1,STONE)
Block(-3,7,1,STONE)
Block(-8,-1,-6,STONE)
Block(-3,2,1,STONE)
Block(-8,-2,-6,STONE)
Block(-3,1,1,STONE)
Block(-3,4,1,STONE)
Block(-3,3,1,STONE)
Block(-1,0,5,STONE)
Block(-1,2,5,STONE)
Block(-1,1,5,STONE)
Block(-1,4,5,STONE)
Block(-1,3,5,STONE)
Block(-1,6,5,STONE)
Block(-1,5,5,STONE)
Block(-1,8,5,STONE)
Block(-1,7,5,STONE)
Block(-1,9,5,STONE)
Block(-3,-1,3,STONE)
Block(-3,-5,3,STONE)
Block(-3,-4,3,STONE)
Block(-3,-3,3,STONE)
Block(-3,-2,3,STONE)
Block(-7,-2,-5,STONE)
Block(-7,-1,-5,STONE)
Block(-7,-5,-5,STONE)
Block(-7,-4,-5,STONE)
Block(-7,-3,-5,STONE)
Block(-6,-1,17,SNOW_BLOCK)
Block(-6,-4,17,STONE)
Block(-6,-5,17,STONE)
Block(-5,19,11,SNOW_BLOCK)
Block(-6,-2,17,STONE)
Block(-5,18,7,STONE)
Block(-6,-3,17,STONE)
Block(-5,19,7,STONE)
Block(-5,16,11,STONE)
Block(-5,15,11,STONE)
Block(-5,18,11,STONE)
Block(-5,25,7,SNOW_BLOCK)
Block(-5,17,11,STONE)
Block(-5,12,11,STONE)
Block(-5,23,7,SNOW_BLOCK)
Block(-5,11,11,STONE)
Block(-5,24,7,SNOW_BLOCK)
Block(-5,14,11,STONE)
Block(-5,21,7,SNOW_BLOCK)
Block(-5,13,11,STONE)
Block(-5,22,7,SNOW_BLOCK)
Block(-9,0,6,STONE)
Block(-9,1,6,STONE)
Block(-5,20,7,STONE)
Block(-5,10,11,STONE)
Block(-9,4,6,STONE)
Block(-9,5,6,STONE)
Block(-9,2,6,STONE)
Block(-9,3,6,STONE)
Block(-8,4,12,STONE)
Block(-8,5,12,STONE)
Block(-8,2,12,STONE)
Block(-9,6,6,SNOW_BLOCK)
Block(-4,21,5,SNOW_BLOCK)
Block(-8,3,12,STONE)
Block(-4,20,5,SNOW_BLOCK)
Block(-9,7,6,SNOW)
Block(-8,8,12,SNOW_BLOCK)
Block(-4,23,5,SNOW_BLOCK)
Block(-4,22,5,SNOW_BLOCK)
Block(-8,6,12,STONE)
Block(-8,7,12,STONE)
Block(-8,0,12,STONE)
Block(-8,1,12,STONE)
Block(-2,-4,-5,STONE)
Block(-5,16,7,STONE)
Block(-2,-5,-5,STONE)
Block(-5,17,7,STONE)
Block(-5,14,7,STONE)
Block(-5,15,7,STONE)
Block(-5,12,7,STONE)
Block(-2,-1,-5,STONE)
Block(-5,13,7,STONE)
Block(-2,-2,-5,STONE)
Block(-5,10,7,STONE)
Block(-2,-3,-5,STONE)
Block(-5,11,7,STONE)
Block(-4,16,5,STONE)
Block(-4,15,5,STONE)
Block(-4,18,5,STONE)
Block(-5,21,11,SNOW_BLOCK)
Block(-4,17,5,STONE)
Block(-5,20,11,SNOW_BLOCK)
Block(-4,19,5,STONE)
Block(-4,10,5,STONE)
Block(-4,12,5,STONE)
Block(-4,11,5,STONE)
Block(-4,14,5,STONE)
Block(-4,13,5,STONE)
Block(-13,-5,16,STONE)
Block(-13,-4,16,STONE)
Block(-13,-3,16,SNOW_BLOCK)
Block(-13,-2,16,SNOW)
Block(-3,11,3,STONE)
Block(-3,10,3,STONE)
Block(-3,15,3,STONE)
Block(-3,14,3,STONE)
Block(-3,13,3,STONE)
Block(-3,12,3,STONE)
Block(-3,19,3,SNOW_BLOCK)
Block(-3,18,3,STONE)
Block(-3,17,3,STONE)
Block(-3,16,3,STONE)
Block(-9,-1,1,STONE)
Block(-4,9,3,STONE)
Block(-12,-5,6,SNOW_BLOCK)
Block(-4,8,3,STONE)
Block(-4,7,3,STONE)
Block(-4,6,3,STONE)
Block(-12,-4,6,SNOW_BLOCK)
Block(-4,1,3,STONE)
Block(-4,0,3,STONE)
Block(0,-5,0,STONE)
Block(-4,5,3,STONE)
Block(-4,4,3,STONE)
Block(-4,3,3,STONE)
Block(-4,2,3,STONE)
Block(-10,3,4,SNOW)
Block(-10,2,4,SNOW_BLOCK)
Block(-10,1,4,STONE)
Block(-10,0,4,STONE)
Block(-4,-2,5,STONE)
Block(-4,-1,5,STONE)
Block(-4,-4,5,STONE)
Block(-4,-3,5,STONE)
Block(-4,-5,5,STONE)
Block(-7,7,-4,SNOW_BLOCK)
Block(-7,8,-4,SNOW)
Block(-2,9,7,STONE)
Block(-2,8,7,STONE)
Block(-2,-4,1,STONE)
Block(-7,3,-4,STONE)
Block(-2,7,7,STONE)
Block(-2,-3,1,STONE)
Block(-7,4,-4,STONE)
Block(-2,6,7,STONE)
Block(-7,5,-4,STONE)
Block(-2,5,7,STONE)
Block(-2,-5,1,STONE)
Block(-2,4,7,STONE)
Block(-7,6,-4,STONE)
Block(-2,3,7,STONE)
Block(-1,3,12,STONE)
Block(-2,2,7,STONE)
Block(-1,4,12,STONE)
Block(-2,-2,1,STONE)
Block(-2,1,7,STONE)
Block(-1,5,12,STONE)
Block(-2,-1,1,STONE)
Block(-2,0,7,STONE)
Block(-1,6,12,STONE)
Block(-10,-1,2,STONE)
Block(-1,7,12,STONE)
Block(-10,-2,2,STONE)
Block(-1,8,12,STONE)
Block(-1,9,12,STONE)
Block(0,-4,0,STONE)
Block(0,-3,0,STONE)
Block(-1,0,12,STONE)
Block(0,-2,0,STONE)
Block(-1,1,12,STONE)
Block(0,-1,0,STONE)
Block(-1,2,12,STONE)
Block(-7,0,-4,STONE)
Block(-7,1,-4,STONE)
Block(-7,2,-4,STONE)
Block(-12,0,0,SNOW_BLOCK)
Block(-5,-2,-4,STONE)
Block(-5,-3,-4,STONE)
Block(-5,-1,-4,STONE)
Block(-3,9,9,STONE)
Block(-5,-4,-4,STONE)
Block(-5,-5,-4,STONE)
Block(0,-5,11,STONE)
Block(-9,-1,16,STONE)
Block(-9,-3,16,STONE)
Block(-9,-2,16,STONE)
Block(-9,-5,16,STONE)
Block(-9,-4,16,STONE)
Block(-6,-3,9,STONE)
Block(-6,-4,9,STONE)
Block(-6,-5,9,STONE)
Block(-9,-5,1,STONE)
Block(0,-2,11,STONE)
Block(-9,-4,1,STONE)
Block(0,-1,11,STONE)
Block(0,-4,11,STONE)
Block(-9,-3,1,STONE)
Block(-6,-1,9,STONE)
Block(0,-3,11,STONE)
Block(-9,-2,1,STONE)
Block(-6,-2,9,STONE)
Block(-10,0,11,SNOW_BLOCK)
Block(-2,10,1,STONE)
Block(-2,11,1,SNOW_BLOCK)
Block(-4,-4,16,STONE)
Block(-4,-3,16,STONE)
Block(-4,-5,16,STONE)
Block(-4,-2,16,STONE)
Block(-4,-1,16,STONE)
Block(-2,0,-1,STONE)
Block(-7,2,1,STONE)
Block(-6,20,9,SNOW_BLOCK)
Block(-7,1,1,STONE)
Block(-6,21,9,SNOW_BLOCK)
Block(-7,4,1,STONE)
Block(-11,-1,4,SNOW_BLOCK)
Block(-7,3,1,STONE)
Block(-11,-2,4,STONE)
Block(-11,-3,4,STONE)
Block(-11,-4,4,STONE)
Block(-7,0,1,STONE)
Block(-11,-5,4,STONE)
Block(-2,4,-1,STONE)
Block(-2,3,-1,STONE)
Block(-7,9,1,STONE)
Block(-2,2,-1,STONE)
Block(-2,1,-1,STONE)
Block(-7,6,1,STONE)
Block(-2,8,-1,SNOW_BLOCK)
Block(-7,5,1,STONE)
Block(-2,7,-1,STONE)
Block(-2,6,-1,STONE)
Block(-7,8,1,STONE)
Block(-2,5,-1,STONE)
Block(-7,7,1,STONE)
Block(-4,3,-5,SNOW_BLOCK)
Block(-11,-4,12,STONE)
Block(-11,-3,12,SNOW_BLOCK)
Block(-4,0,-5,STONE)
Block(-11,-5,12,STONE)
Block(-4,2,-5,STONE)
Block(0,10,11,STONE)
Block(-4,1,-5,STONE)
Block(-5,-4,7,STONE)
Block(-5,-5,7,STONE)
Block(-5,4,5,STONE)
Block(-5,3,5,STONE)
Block(-6,10,9,STONE)
Block(-5,6,5,STONE)
Block(-6,11,9,STONE)
Block(-5,5,5,STONE)
Block(-6,12,9,STONE)
Block(-5,8,5,STONE)
Block(-5,7,5,STONE)
Block(-5,9,5,STONE)
Block(0,12,11,STONE)
Block(-6,17,9,STONE)
Block(0,11,11,STONE)
Block(-6,18,9,STONE)
Block(0,14,11,STONE)
Block(-6,19,9,SNOW_BLOCK)
Block(0,13,11,STONE)
Block(-5,0,5,STONE)
Block(-6,13,9,STONE)
Block(-6,14,9,STONE)
Block(0,15,11,SNOW_BLOCK)
Block(-5,2,5,STONE)
Block(-6,15,9,STONE)
Block(-5,1,5,STONE)
Block(-6,16,9,STONE)
Block(2,-2,12,STONE)
Block(-5,2,13,STONE)
Block(2,-3,12,STONE)
Block(-5,3,13,STONE)
Block(-5,4,13,STONE)
Block(2,-1,12,STONE)
Block(-5,5,13,STONE)
Block(-5,0,13,STONE)
Block(-5,1,13,STONE)
Block(2,-4,12,STONE)
Block(2,-5,12,STONE)
Block(-5,-2,7,STONE)
Block(-3,6,9,STONE)
Block(-5,-3,7,STONE)
Block(-3,5,9,STONE)
Block(-3,8,9,STONE)
Block(-5,-1,7,STONE)
Block(-3,7,9,STONE)
Block(-3,2,9,STONE)
Block(-3,1,9,STONE)
Block(2,0,9,SNOW_BLOCK)
Block(-3,4,9,STONE)
Block(-3,3,9,STONE)
Block(-3,0,9,STONE)
Block(-5,6,13,STONE)
Block(-5,7,13,STONE)
Block(-5,8,13,STONE)
Block(-5,9,13,STONE)
Block(-7,14,8,STONE)
Block(-7,13,8,STONE)
Block(-2,0,15,STONE)
Block(-7,16,8,STONE)
Block(-7,15,8,STONE)
Block(-7,18,8,SNOW)
Block(-7,17,8,SNOW_BLOCK)
Block(-10,-1,5,STONE)
Block(-10,-5,5,STONE)
Block(-7,10,8,STONE)
Block(-10,-4,5,STONE)
Block(-10,-3,5,STONE)
Block(-7,12,8,STONE)
Block(-10,-2,5,STONE)
Block(-7,11,8,STONE)
Block(-9,5,-1,SNOW_BLOCK)
Block(-9,4,-1,STONE)
Block(-9,6,-1,SNOW)
Block(-9,1,-1,STONE)
Block(-9,0,-1,STONE)
Block(-9,3,-1,STONE)
Block(-9,2,-1,STONE)
Block(-2,6,15,SNOW_BLOCK)
Block(-2,5,15,STONE)
Block(-2,2,15,STONE)
Block(-2,1,15,STONE)
Block(-2,4,15,STONE)
Block(1,0,11,STONE)
Block(-2,3,15,STONE)
Block(-8,-1,2,STONE)
Block(-8,-5,2,STONE)
Block(-8,-4,2,STONE)
Block(-8,-3,2,STONE)
Block(-8,-2,2,STONE)
Block(-6,9,7,STONE)
Block(-6,8,7,STONE)
Block(1,1,11,STONE)
Block(1,2,11,STONE)
Block(1,3,11,STONE)
Block(1,4,11,STONE)
Block(1,5,11,STONE)
Block(1,6,11,STONE)
Block(1,7,11,STONE)
Block(1,8,11,SNOW_BLOCK)
Block(-7,0,10,STONE)
Block(-7,2,10,STONE)
Block(-7,1,10,STONE)
Block(-7,8,10,STONE)
Block(-7,7,10,STONE)
Block(-7,9,10,STONE)
Block(-7,4,10,STONE)
Block(-7,3,10,STONE)
Block(-7,6,10,STONE)
Block(-7,5,10,STONE)
Block(-7,-2,8,STONE)
Block(-7,-1,8,STONE)
Block(-7,-4,8,STONE)
Block(-8,1,3,STONE)
Block(1,4,6,SNOW_BLOCK)
Block(-7,-3,8,STONE)
Block(-8,0,3,STONE)
Block(1,3,6,STONE)
Block(1,2,6,STONE)
Block(-7,-5,8,STONE)
Block(1,1,6,STONE)
Block(-8,5,3,STONE)
Block(-8,4,3,STONE)
Block(-8,3,3,STONE)
Block(-8,2,3,STONE)
Block(-8,9,3,SNOW_BLOCK)
Block(-8,8,3,STONE)
Block(-8,7,3,STONE)
Block(-8,6,3,STONE)
Block(-9,4,15,SNOW)
Block(-9,3,15,SNOW_BLOCK)
Block(-9,2,15,STONE)
Block(-9,1,15,STONE)
Block(-9,0,15,STONE)
Block(-10,-1,-2,STONE)
Block(-3,-1,10,STONE)
Block(-10,-4,-2,STONE)
Block(-3,-2,10,STONE)
Block(-10,-5,-2,STONE)
Block(-3,-3,10,STONE)
Block(-3,-4,10,STONE)
Block(-10,-2,-2,STONE)
Block(-3,-5,10,STONE)
Block(-10,-3,-2,STONE)
Block(-4,23,8,SNOW_BLOCK)
Block(-4,24,8,SNOW_BLOCK)
Block(-4,21,8,SNOW_BLOCK)
Block(-4,22,8,SNOW_BLOCK)
Block(-4,25,8,SNOW_BLOCK)
Block(-4,26,8,SNOW_BLOCK)
Block(-6,7,7,STONE)
Block(-6,6,7,STONE)
Block(-6,5,7,STONE)
Block(-6,4,7,STONE)
Block(-6,3,7,STONE)
Block(-6,2,7,STONE)
Block(-4,20,8,SNOW_BLOCK)
Block(-6,1,7,STONE)
Block(-6,0,7,STONE)
Block(-8,-1,-3,STONE)
Block(-8,-3,-3,STONE)
Block(-8,-2,-3,STONE)
Block(-8,-5,-3,STONE)
Block(-8,-4,-3,STONE)
Block(-4,18,8,STONE)
Block(-4,19,8,SNOW_BLOCK)
Block(-8,0,-6,SNOW_BLOCK)
Block(-5,-5,4,STONE)
Block(-5,-2,4,STONE)
Block(-5,-1,4,STONE)
Block(-5,-4,4,STONE)
Block(-5,-3,4,STONE)
Block(0,-2,-1,STONE)
Block(0,-1,-1,SNOW_BLOCK)
Block(0,-4,-1,STONE)
Block(-7,10,12,STONE)
Block(0,-3,-1,STONE)
Block(-7,11,12,SNOW_BLOCK)
Block(0,-5,-1,STONE)
Block(2,-2,15,SNOW)
Block(2,-3,15,SNOW_BLOCK)
Block(2,-4,15,STONE)
Block(2,-5,15,STONE)
Block(-1,-4,2,STONE)
Block(-1,-3,2,STONE)
Block(-1,-5,2,STONE)
Block(1,0,6,STONE)
Block(-1,-2,2,STONE)
Block(-1,-1,2,STONE)
Block(-3,1,0,STONE)
Block(-3,0,0,STONE)
Block(-3,10,10,STONE)
Block(-3,11,10,STONE)
Block(-3,7,0,STONE)
Block(-3,12,10,STONE)
Block(-3,6,0,STONE)
Block(-3,13,10,STONE)
Block(-3,9,0,STONE)
Block(-3,14,10,STONE)
Block(-3,8,0,STONE)
Block(-3,15,10,STONE)
Block(-3,3,0,STONE)
Block(-3,16,10,STONE)
Block(-3,2,0,STONE)
Block(-3,17,10,STONE)
Block(-3,5,0,STONE)
Block(-3,18,10,STONE)
Block(-3,4,0,STONE)
Block(-3,19,10,STONE)
Block(-2,-4,12,STONE)
Block(-1,1,4,STONE)
Block(-2,-3,12,STONE)
Block(-1,0,4,STONE)
Block(-2,-2,12,STONE)
Block(-1,3,4,STONE)
Block(-2,-1,12,STONE)
Block(-1,2,4,STONE)
Block(-7,2,-5,STONE)
Block(-1,5,4,STONE)
Block(-7,3,-5,STONE)
Block(-1,4,4,STONE)
Block(-7,4,-5,SNOW_BLOCK)
Block(-1,7,4,STONE)
Block(-2,-5,12,STONE)
Block(-1,6,4,STONE)
Block(-1,9,4,STONE)
Block(-1,8,4,STONE)
Block(-3,20,10,STONE)
Block(-3,21,10,SNOW_BLOCK)
Block(-3,22,10,SNOW_BLOCK)
Block(-3,23,10,SNOW_BLOCK)
Block(-3,24,10,SNOW_BLOCK)
Block(-4,-4,8,STONE)
Block(-7,0,-5,STONE)
Block(-4,-5,8,STONE)
Block(-7,1,-5,STONE)
Block(-1,-2,14,STONE)
Block(-4,12,8,STONE)
Block(-1,-3,14,STONE)
Block(-4,13,8,STONE)
Block(-4,10,8,STONE)
Block(-1,-1,14,STONE)
Block(-4,11,8,STONE)
Block(-4,16,8,STONE)
Block(-4,17,8,STONE)
Block(-4,14,8,STONE)
Block(-4,15,8,STONE)
Block(-6,9,-1,STONE)
Block(-6,8,-1,STONE)
Block(-6,7,-1,STONE)
Block(-1,-4,14,STONE)
Block(-6,6,-1,STONE)
Block(-1,-5,14,STONE)
Block(-6,5,-1,STONE)
Block(-6,4,-1,STONE)
Block(-6,3,-1,STONE)
Block(-6,2,-1,STONE)
Block(-6,1,-1,STONE)
Block(-6,0,-1,STONE)
Block(-7,9,9,STONE)
Block(-7,-2,12,STONE)
Block(-7,6,9,STONE)
Block(-7,-3,12,STONE)
Block(-7,5,9,STONE)
Block(-7,8,9,STONE)
Block(-4,9,10,STONE)
Block(-7,-1,12,STONE)
Block(-7,7,9,STONE)
Block(-4,8,10,STONE)
Block(-4,7,10,STONE)
Block(-4,6,10,STONE)
Block(-7,-4,12,STONE)
Block(-4,5,10,STONE)
Block(-7,-5,12,STONE)
Block(-4,4,10,STONE)
Block(-4,3,10,STONE)
Block(-4,2,10,STONE)
Block(-4,1,10,STONE)
Block(-4,0,10,STONE)
Block(0,9,10,STONE)
Block(0,1,4,STONE)
Block(0,0,4,STONE)
Block(0,3,4,STONE)
Block(0,2,4,STONE)
Block(0,4,10,STONE)
Block(0,3,10,STONE)
Block(-2,20,12,SNOW)
Block(0,2,10,STONE)
Block(0,1,10,STONE)
Block(0,8,10,STONE)
Block(0,7,10,STONE)
Block(0,6,10,STONE)
Block(0,5,10,STONE)
Block(-7,2,9,STONE)
Block(-7,1,9,STONE)
Block(-7,4,9,STONE)
Block(-7,3,9,STONE)
Block(-7,0,9,STONE)
Block(-2,18,12,STONE)
Block(-2,17,12,STONE)
Block(-2,16,12,STONE)
Block(-2,15,12,STONE)
Block(-2,19,12,SNOW_BLOCK)
Block(-2,10,12,STONE)
Block(-2,14,12,STONE)
Block(-2,13,12,STONE)
Block(-2,12,12,STONE)
Block(-2,11,12,STONE)
Block(-12,1,-2,SNOW_BLOCK)
Block(-9,-1,9,STONE)
Block(0,0,10,STONE)
Block(2,1,13,SNOW_BLOCK)
Block(2,0,13,STONE)
Block(-9,-5,9,STONE)
Block(-9,-4,9,STONE)
Block(-9,-3,9,STONE)
Block(-9,-2,9,STONE)
Block(-12,0,-2,STONE)
Block(-8,-1,10,STONE)
Block(-8,-2,10,STONE)
Block(-8,-3,10,STONE)
Block(-8,-4,10,STONE)
Block(-8,-5,10,STONE)
Block(-4,-2,8,STONE)
Block(-4,-3,8,STONE)
Block(-4,-1,8,STONE)
Block(-2,-2,9,STONE)
Block(-2,-1,9,STONE)
Block(-12,-1,18,SNOW)
Block(-12,-4,18,STONE)
Block(-12,-5,18,STONE)
Block(-12,-2,18,SNOW_BLOCK)
Block(-12,-3,18,STONE)
Block(-6,-4,-7,STONE)
Block(-6,-5,-7,STONE)
Block(-6,-2,-7,STONE)
Block(-6,0,15,STONE)
Block(-6,-3,-7,STONE)
Block(-6,2,15,STONE)
Block(-6,1,15,STONE)
Block(-6,-1,-7,SNOW)
Block(-6,4,15,STONE)
Block(-6,3,15,STONE)
Block(-2,-4,9,STONE)
Block(-3,0,-3,STONE)
Block(-6,6,15,SNOW_BLOCK)
Block(-2,-3,9,STONE)
Block(-3,1,-3,STONE)
Block(-6,5,15,STONE)
Block(-3,2,-3,STONE)
Block(-2,-5,9,STONE)
Block(-3,3,-3,STONE)
Block(-3,4,-3,STONE)
Block(-3,5,-3,STONE)
Block(0,-5,8,STONE)
Block(-3,6,-3,STONE)
Block(-3,7,-3,SNOW_BLOCK)
Block(0,-3,8,STONE)
Block(0,5,4,STONE)
Block(0,-4,8,STONE)
Block(-9,0,7,STONE)
Block(0,4,4,STONE)
Block(0,-1,8,STONE)
Block(0,-2,8,STONE)
Block(0,6,4,SNOW_BLOCK)
Block(-9,3,7,STONE)
Block(-9,4,7,STONE)
Block(-9,1,7,STONE)
Block(-9,2,7,STONE)
Block(-9,7,7,SNOW)
Block(-10,-1,14,STONE)
Block(-4,9,2,STONE)
Block(-10,-2,14,STONE)
Block(-9,5,7,STONE)
Block(-4,8,2,STONE)
Block(-10,-3,14,STONE)
Block(-9,6,7,SNOW_BLOCK)
Block(-4,7,2,STONE)
Block(-4,2,2,STONE)
Block(-4,1,2,STONE)
Block(-4,0,2,STONE)
Block(-4,6,2,STONE)
Block(-4,5,2,STONE)
Block(-4,4,2,STONE)
Block(-4,3,2,STONE)
Block(-9,-4,19,SNOW_BLOCK)
Block(-9,-5,19,SNOW_BLOCK)
Block(-4,12,-1,SNOW)
Block(-10,-4,14,STONE)
Block(-4,11,-1,SNOW_BLOCK)
Block(-10,-5,14,STONE)
Block(-4,10,-1,STONE)
Block(-2,9,6,STONE)
Block(-2,8,6,STONE)
Block(-1,13,7,STONE)
Block(-2,7,6,STONE)
Block(-1,12,7,STONE)
Block(-2,6,6,STONE)
Block(-1,11,7,STONE)
Block(-2,5,6,STONE)
Block(-1,10,7,STONE)
Block(-2,4,6,STONE)
Block(-7,14,3,SNOW_BLOCK)
Block(-2,3,6,STONE)
Block(-2,2,6,STONE)
Block(-7,12,3,STONE)
Block(-2,1,6,STONE)
Block(-7,13,3,STONE)
Block(-2,0,6,STONE)
Block(-7,10,3,STONE)
Block(-7,11,3,STONE)
Block(-3,0,-2,STONE)
Block(-3,1,-2,STONE)
Block(-3,2,-2,STONE)
Block(-3,3,-2,STONE)
Block(-3,4,-2,STONE)
Block(-3,5,-2,STONE)
Block(-3,6,-2,STONE)
Block(-3,7,-2,STONE)
Block(-3,8,-2,STONE)
Block(-3,9,-2,SNOW_BLOCK)
Block(-8,-1,15,STONE)
Block(-7,0,17,SNOW_BLOCK)
Block(-8,-4,15,STONE)
Block(-8,-5,15,STONE)
Block(-8,-2,15,STONE)
Block(-8,-3,15,STONE)
Block(-1,20,7,STONE)
Block(-1,21,7,SNOW_BLOCK)
Block(-7,-4,3,STONE)
Block(-7,-5,3,STONE)
Block(-7,-2,3,STONE)
Block(-7,-3,3,STONE)
Block(-1,17,7,STONE)
Block(-1,16,7,STONE)
Block(-1,15,7,STONE)
Block(-1,14,7,STONE)
Block(-1,19,7,STONE)
Block(-1,18,7,STONE)
Block(-11,-5,1,STONE)
Block(-11,-3,1,STONE)
Block(-11,-4,1,STONE)
Block(-4,-5,-1,STONE)
Block(-4,-4,-1,STONE)
Block(-4,-3,-1,STONE)
Block(-4,-2,-1,STONE)
Block(-4,-1,-1,STONE)
Block(-7,8,-3,SNOW_BLOCK)
Block(-7,4,-3,STONE)
Block(-7,5,-3,STONE)
Block(-7,6,-3,STONE)
Block(-7,7,-3,STONE)
Block(-1,2,13,STONE)
Block(-7,-1,3,STONE)
Block(-1,3,13,STONE)
Block(-1,4,13,STONE)
Block(-1,5,13,STONE)
Block(-1,6,13,STONE)
Block(-3,0,16,STONE)
Block(-1,7,13,STONE)
Block(-1,8,13,STONE)
Block(-1,9,13,STONE)
Block(-3,1,16,SNOW_BLOCK)
Block(-1,0,13,STONE)
Block(-1,1,13,STONE)
Block(-7,0,-3,STONE)
Block(-7,1,-3,STONE)
Block(-7,2,-3,STONE)
Block(-7,3,-3,STONE)
Block(-6,-2,3,STONE)
Block(-6,-1,3,STONE)
Block(-6,-4,3,STONE)
Block(-6,-3,3,STONE)
Block(-6,-5,3,STONE)
Block(-1,10,14,SNOW_BLOCK)
Block(-6,9,-3,SNOW_BLOCK)
Block(-6,8,-3,STONE)
Block(-6,7,-3,STONE)
Block(-6,6,-3,STONE)
Block(-6,5,-3,STONE)
Block(-6,4,-3,STONE)
Block(-6,3,-3,STONE)
Block(-6,2,-3,STONE)
Block(-6,1,-3,STONE)
Block(-5,-5,14,STONE)
Block(-6,0,-3,STONE)
Block(-5,-4,14,STONE)
Block(-5,-3,14,STONE)
Block(-8,11,5,SNOW_BLOCK)
Block(-5,-2,14,STONE)
Block(-8,12,5,SNOW)
Block(-5,-1,14,STONE)
Block(-1,-3,7,STONE)
Block(-1,-2,7,STONE)
Block(-1,-1,7,STONE)
Block(-8,10,5,STONE)
Block(-10,0,-5,STONE)
Block(-10,1,-5,STONE)
Block(-1,-5,7,STONE)
Block(-10,2,-5,SNOW_BLOCK)
Block(-1,-4,7,STONE)
Block(-3,-2,15,STONE)
Block(-3,-1,15,STONE)
Block(-11,-1,1,STONE)
Block(-3,-5,15,STONE)
Block(-11,-2,1,STONE)
Block(-3,-4,15,STONE)
Block(-3,-3,15,STONE)
Block(-5,1,14,STONE)
Block(1,6,8,STONE)
Block(-5,2,14,STONE)
Block(1,5,8,STONE)
Block(-5,3,14,STONE)
Block(1,4,8,STONE)
Block(1,3,8,STONE)
Block(-5,4,14,STONE)
Block(1,2,8,STONE)
Block(1,1,8,STONE)
Block(1,0,8,STONE)
Block(-5,0,14,STONE)
Block(-6,-4,14,STONE)
Block(-6,-3,14,STONE)
Block(-6,-5,14,STONE)
Block(-13,-5,0,STONE)
Block(-6,-2,14,STONE)
Block(1,8,8,SNOW_BLOCK)
Block(-13,-4,0,STONE)
Block(-6,-1,14,STONE)
Block(1,7,8,STONE)
Block(-3,7,8,STONE)
Block(-3,6,8,STONE)
Block(-3,9,8,STONE)
Block(-3,8,8,STONE)
Block(-3,3,8,STONE)
Block(-3,2,8,STONE)
Block(-3,5,8,STONE)
Block(-3,4,8,STONE)
Block(-5,9,14,STONE)
Block(-3,1,8,STONE)
Block(-3,0,8,STONE)
Block(-5,5,14,STONE)
Block(-5,6,14,STONE)
Block(-5,7,14,STONE)
Block(-5,8,14,STONE)
Block(-3,-5,6,STONE)
Block(-11,0,15,SNOW_BLOCK)
Block(-7,-3,18,SNOW_BLOCK)
Block(-3,-1,6,STONE)
Block(-3,-2,6,STONE)
Block(-7,-5,18,STONE)
Block(-3,-3,6,STONE)
Block(-3,-4,6,STONE)
Block(-7,-4,18,STONE)
Block(-10,-5,8,STONE)
Block(-10,-2,8,STONE)
Block(-10,-1,8,STONE)
Block(-10,-4,8,STONE)
Block(-11,1,15,SNOW)
Block(-10,-3,8,STONE)
Block(-13,-3,0,STONE)
Block(-13,-2,0,STONE)
Block(-13,-1,0,SNOW_BLOCK)
Block(1,-1,5,STONE)
Block(1,-2,5,STONE)
Block(1,-5,5,STONE)
Block(1,-3,5,STONE)
Block(1,-4,5,STONE)
Block(-5,19,4,SNOW_BLOCK)
Block(-5,16,4,STONE)
Block(-5,15,4,STONE)
Block(-5,18,4,STONE)
Block(-5,17,4,STONE)
Block(-7,3,0,STONE)
Block(-7,2,0,STONE)
Block(-5,22,4,SNOW)
Block(-7,5,0,STONE)
Block(-7,4,0,STONE)
Block(-7,1,0,STONE)
Block(-5,21,4,SNOW_BLOCK)
Block(-7,0,0,STONE)
Block(-5,20,4,SNOW_BLOCK)
Block(-5,10,14,SNOW_BLOCK)
Block(-7,7,0,STONE)
Block(-7,6,0,STONE)
Block(-7,9,0,STONE)
Block(-7,8,0,STONE)
Block(-5,5,4,STONE)
Block(-5,12,4,STONE)
Block(-5,4,4,STONE)
Block(-5,11,4,STONE)
Block(-5,7,4,STONE)
Block(-5,14,4,STONE)
Block(-5,6,4,STONE)
Block(-5,13,4,STONE)
Block(-5,9,4,STONE)
Block(-5,8,4,STONE)
Block(-5,10,4,STONE)
Block(-5,1,4,STONE)
Block(-5,0,4,STONE)
Block(-5,3,4,STONE)
Block(-5,2,4,STONE)
Block(-8,5,11,STONE)
Block(-6,10,14,SNOW)
Block(-8,6,11,STONE)
Block(-8,3,11,STONE)
Block(-8,4,11,STONE)
Block(-8,7,11,STONE)
Block(-8,8,11,SNOW_BLOCK)
Block(-2,-5,4,STONE)
Block(-2,-4,4,STONE)
Block(-2,-3,4,STONE)
Block(-2,-2,4,STONE)
Block(-2,-1,4,STONE)
Block(-8,1,11,STONE)
Block(-8,2,11,STONE)
Block(-8,0,11,STONE)
Block(-3,11,6,STONE)
Block(-3,12,6,STONE)
Block(-3,13,6,STONE)
Block(-3,14,6,STONE)
Block(-3,10,6,STONE)
Block(-3,19,6,STONE)
Block(-11,0,-1,STONE)
Block(-3,15,6,STONE)
Block(-3,16,6,STONE)
Block(-3,17,6,STONE)
Block(-3,18,6,STONE)
Block(-11,1,-1,STONE)
Block(-12,-5,13,SNOW)
Block(-11,2,-1,SNOW_BLOCK)
Block(-4,14,0,SNOW)
Block(-4,12,0,STONE)
Block(-4,13,0,SNOW_BLOCK)
Block(-4,10,0,STONE)
Block(-4,11,0,STONE)
Block(-3,22,6,SNOW_BLOCK)
Block(-3,23,6,SNOW_BLOCK)
Block(-3,24,6,SNOW_BLOCK)
Block(-3,25,6,SNOW)
Block(-3,20,6,SNOW_BLOCK)
Block(-3,21,6,SNOW_BLOCK)
Block(-5,12,-1,SNOW_BLOCK)
Block(-5,11,-1,STONE)
Block(-5,13,-1,SNOW)
Block(-5,10,-1,STONE)
Block(-9,-5,-1,STONE)
Block(0,-4,3,SNOW_BLOCK)
Block(-9,-3,-1,STONE)
Block(-9,4,-2,STONE)
Block(0,-5,3,SNOW_BLOCK)
Block(-9,-4,-1,STONE)
Block(-9,3,-2,STONE)
Block(-9,-1,-1,STONE)
Block(-9,6,-2,SNOW_BLOCK)
Block(-9,-2,-1,STONE)
Block(-9,5,-2,STONE)
Block(-9,0,-2,STONE)
Block(0,-1,3,SNOW_BLOCK)
Block(0,-2,3,SNOW_BLOCK)
Block(-9,2,-2,STONE)
Block(0,-3,3,SNOW_BLOCK)
Block(-9,1,-2,STONE)
Block(-4,5,-4,STONE)
Block(-4,4,-4,STONE)
Block(-4,6,-4,SNOW_BLOCK)
Block(-4,1,-4,STONE)
Block(-4,0,-4,STONE)
Block(-4,3,-4,STONE)
Block(-4,2,-4,STONE)
Block(-2,-4,15,STONE)
Block(-8,0,-5,STONE)
Block(-2,-5,15,STONE)
Block(-8,2,-5,STONE)
Block(-8,1,-5,STONE)
Block(-2,19,4,SNOW_BLOCK)
Block(-2,-1,15,STONE)
Block(-2,18,4,STONE)
Block(-2,-2,15,STONE)
Block(-2,17,4,STONE)
Block(-2,-3,15,STONE)
Block(-2,16,4,STONE)
Block(-2,15,4,STONE)
Block(-2,14,4,STONE)
Block(-2,13,4,STONE)
Block(-2,12,4,STONE)
Block(1,-1,8,STONE)
Block(1,-5,8,STONE)
Block(1,-4,8,STONE)
Block(1,-3,8,STONE)
Block(1,-2,8,STONE)
Block(-6,9,6,STONE)
Block(-8,4,-5,SNOW_BLOCK)
Block(-8,3,-5,STONE)
Block(-6,-5,6,STONE)
Block(-6,-4,6,STONE)
Block(-1,-5,11,STONE)
Block(-1,-1,11,STONE)
Block(-1,-2,11,STONE)
Block(-1,-3,11,STONE)
Block(-1,-4,11,STONE)
Block(-4,-2,0,STONE)
Block(-4,22,11,SNOW_BLOCK)
Block(-4,-3,0,STONE)
Block(-4,21,11,SNOW_BLOCK)
Block(-4,20,11,SNOW_BLOCK)
Block(-4,-1,0,STONE)
Block(-3,-2,9,STONE)
Block(-3,-3,9,STONE)
Block(-3,-1,9,STONE)
Block(-4,-4,0,STONE)
Block(-4,-5,0,STONE)
Block(-7,-3,15,STONE)
Block(-7,-4,15,STONE)
Block(-7,-5,15,STONE)
Block(0,0,5,STONE)
Block(-8,2,2,STONE)
Block(-8,1,2,STONE)
Block(-3,-4,9,STONE)
Block(-7,-1,15,STONE)
Block(-8,0,2,STONE)
Block(0,2,5,STONE)
Block(-3,-5,9,STONE)
Block(-7,-2,15,STONE)
Block(0,1,5,STONE)
Block(-8,6,2,STONE)
Block(-5,-5,-1,STONE)
Block(-8,5,2,STONE)
Block(-8,4,2,STONE)
Block(-8,3,2,STONE)
Block(-5,-2,-1,STONE)
Block(-5,-1,-1,STONE)
Block(-5,-4,-1,STONE)
Block(-8,8,2,SNOW_BLOCK)
Block(-5,-3,-1,STONE)
Block(-8,7,2,STONE)
Block(-9,2,16,SNOW)
Block(-9,1,16,SNOW_BLOCK)
Block(-9,0,16,STONE)
Block(-6,13,6,STONE)
Block(-6,12,6,STONE)
Block(-6,11,6,STONE)
Block(-6,10,6,STONE)
Block(-6,17,6,STONE)
Block(-6,16,6,STONE)
Block(1,0,10,STONE)
Block(-6,15,6,STONE)
Block(1,1,10,STONE)
Block(-6,14,6,STONE)
Block(-6,0,6,STONE)
Block(-6,8,6,STONE)
Block(-6,14,11,STONE)
Block(-5,16,1,SNOW_BLOCK)
Block(-6,7,6,STONE)
Block(-6,15,11,STONE)
Block(-6,6,6,STONE)
Block(-6,16,11,STONE)
Block(-6,5,6,STONE)
Block(-6,17,11,SNOW_BLOCK)
Block(-6,4,6,STONE)
Block(-6,10,11,STONE)
Block(-5,12,1,STONE)
Block(-6,3,6,STONE)
Block(-6,11,11,STONE)
Block(-5,13,1,STONE)
Block(-6,2,6,STONE)
Block(-6,12,11,STONE)
Block(-5,14,1,STONE)
Block(-6,1,6,STONE)
Block(-6,13,11,STONE)
Block(-5,15,1,STONE)
Block(-2,11,4,STONE)
Block(-2,10,4,STONE)
Block(-9,-2,6,STONE)
Block(-9,-1,6,STONE)
Block(-9,-4,6,STONE)
Block(-9,-3,6,STONE)
Block(-9,-5,6,STONE)
Block(1,2,10,STONE)
Block(1,3,10,STONE)
Block(1,4,10,STONE)
Block(-6,19,6,STONE)
Block(1,5,10,STONE)
Block(-6,18,6,STONE)
Block(1,6,10,STONE)
Block(1,7,10,STONE)
Block(1,8,10,SNOW_BLOCK)
Block(-6,20,6,SNOW_BLOCK)
Block(-3,16,9,STONE)
Block(-3,17,9,STONE)
Block(-3,14,9,STONE)
Block(-6,22,6,SNOW_BLOCK)
Block(-3,15,9,STONE)
Block(-6,21,6,SNOW_BLOCK)
Block(-3,12,9,STONE)
Block(-3,13,9,STONE)
Block(-3,10,9,STONE)
Block(-3,11,9,STONE)
Block(1,6,7,SNOW_BLOCK)
Block(-2,1,14,STONE)
Block(1,5,7,STONE)
Block(-2,0,14,STONE)
Block(1,4,7,STONE)
Block(-6,-4,-4,STONE)
Block(-5,2,-1,STONE)
Block(1,3,7,STONE)
Block(-6,-3,-4,STONE)
Block(1,2,7,STONE)
Block(-5,3,-1,STONE)
Block(-5,0,-1,STONE)
Block(1,1,7,STONE)
Block(-3,18,9,STONE)
Block(-6,-5,-4,STONE)
Block(1,0,7,STONE)
Block(-5,1,-1,STONE)
Block(-3,19,9,STONE)
Block(-6,-2,-4,STONE)
Block(-6,-1,-4,STONE)
Block(-3,20,9,STONE)
Block(-8,-4,18,STONE)
Block(-5,6,-1,STONE)
Block(-2,7,14,STONE)
Block(-8,-3,18,STONE)
Block(-2,6,14,STONE)
Block(-5,7,-1,STONE)
Block(-8,-2,18,SNOW_BLOCK)
Block(-5,4,-1,STONE)
Block(-2,9,14,STONE)
Block(-3,25,9,SNOW_BLOCK)
Block(-5,5,-1,STONE)
Block(-2,8,14,STONE)
Block(-3,26,9,SNOW)
Block(-2,3,14,STONE)
Block(-3,23,9,SNOW_BLOCK)
Block(-2,2,14,STONE)
Block(-3,24,9,SNOW_BLOCK)
Block(-2,5,14,STONE)
Block(-5,8,-1,STONE)
Block(-3,21,9,SNOW_BLOCK)
Block(-8,-5,18,STONE)
Block(-2,4,14,STONE)
Block(-5,9,-1,STONE)
Block(-3,22,9,SNOW_BLOCK)
Block(-9,-5,11,STONE)
Block(-9,-3,11,STONE)
Block(-9,-4,11,STONE)
Block(-9,-1,11,STONE)
Block(-9,-2,11,STONE)
Block(-7,10,0,STONE)
Block(-6,9,-2,STONE)
Block(-6,8,-2,STONE)
Block(-7,11,0,SNOW_BLOCK)
Block(-6,7,-2,STONE)
Block(-6,6,-2,STONE)
Block(-6,5,-2,STONE)
Block(-6,4,-2,STONE)
Block(-6,3,-2,STONE)
Block(-6,2,-2,STONE)
Block(-6,1,-2,STONE)
Block(-6,0,-2,STONE)
Block(-10,3,5,SNOW)
Block(-10,2,5,SNOW_BLOCK)
Block(-10,1,5,STONE)
Block(-10,0,5,STONE)
Block(-10,0,-4,STONE)
Block(-10,1,-4,STONE)
Block(0,-3,16,SNOW_BLOCK)
Block(-10,2,-4,STONE)
Block(0,-4,16,STONE)
Block(-10,3,-4,SNOW_BLOCK)
Block(0,-5,16,STONE)
Block(-7,7,8,STONE)
Block(-7,6,8,STONE)
Block(-7,9,8,STONE)
Block(-7,8,8,STONE)
Block(-13,-2,-3,SNOW_BLOCK)
Block(-13,-3,-3,STONE)
Block(-13,-4,-3,STONE)
Block(-13,-5,-3,STONE)
Block(2,0,12,STONE)
Block(-8,-1,5,STONE)
Block(-8,-2,5,STONE)
Block(-8,-3,5,STONE)
Block(-8,-4,5,STONE)
Block(-4,-5,11,STONE)
Block(-7,3,8,STONE)
Block(-4,-4,11,STONE)
Block(-7,2,8,STONE)
Block(-4,-3,11,STONE)
Block(-7,5,8,STONE)
Block(-4,-2,11,STONE)
Block(-7,4,8,STONE)
Block(-4,-1,11,STONE)
Block(-7,1,8,STONE)
Block(-7,0,8,STONE)
Block(-10,-4,17,STONE)
Block(-1,2,3,STONE)
Block(-10,-3,17,STONE)
Block(-1,1,3,STONE)
Block(-1,4,3,STONE)
Block(-10,-5,17,STONE)
Block(-1,3,3,STONE)
Block(-1,6,3,STONE)
Block(-1,5,3,STONE)
Block(-10,-2,17,STONE)
Block(-1,8,3,STONE)
Block(-10,-1,17,SNOW_BLOCK)
Block(-1,7,3,STONE)
Block(-1,9,3,STONE)
Block(-8,-5,5,STONE)
Block(2,1,12,SNOW_BLOCK)
Block(-1,0,3,STONE)
Block(-14,-2,17,SNOW)
Block(-5,10,1,STONE)
Block(-5,11,1,STONE)
Block(-14,-5,17,STONE)
Block(-14,-3,17,STONE)
Block(-14,-4,17,STONE)
Block(-11,-1,17,SNOW_BLOCK)
Block(-11,-5,17,STONE)
Block(-11,-4,17,STONE)
Block(-11,-3,17,STONE)
Block(-11,-2,17,STONE)
Block(-1,11,11,STONE)
Block(-1,12,11,STONE)
Block(-1,13,11,STONE)
Block(-1,14,11,STONE)
Block(-1,10,11,STONE)
Block(-1,19,11,SNOW_BLOCK)
Block(-6,1,16,STONE)
Block(-1,15,11,STONE)
Block(-5,-5,11,STONE)
Block(-6,0,16,STONE)
Block(-1,16,11,STONE)
Block(-6,3,16,SNOW_BLOCK)
Block(-1,17,11,STONE)
Block(-6,2,16,STONE)
Block(-1,18,11,SNOW_BLOCK)
Block(-7,-4,0,STONE)
Block(-5,-2,11,STONE)
Block(-7,-3,0,STONE)
Block(-5,-1,11,STONE)
Block(-6,4,16,SNOW)
Block(-5,-4,11,STONE)
Block(-7,-5,0,STONE)
Block(-5,-3,11,STONE)
Block(-2,-4,-8,STONE)
Block(-7,-2,0,STONE)
Block(-2,-5,-8,STONE)
Block(-7,-1,0,STONE)
Block(0,4,5,STONE)
Block(0,3,5,STONE)
Block(0,6,5,STONE)
Block(0,5,5,STONE)
Block(-9,2,8,STONE)
Block(0,8,5,STONE)
Block(-9,3,8,STONE)
Block(0,7,5,STONE)
Block(-9,0,8,STONE)
Block(-9,1,8,STONE)
Block(0,9,5,STONE)
Block(-9,4,8,STONE)
Block(-9,5,8,SNOW_BLOCK)
Block(-4,11,11,STONE)
Block(-4,10,11,STONE)
Block(-11,-1,-3,STONE)
Block(-11,-3,-3,STONE)
Block(-11,-2,-3,STONE)
Block(-11,-5,-3,STONE)
Block(-11,-4,-3,STONE)
Block(-4,19,11,STONE)
Block(-4,18,11,STONE)
Block(-4,17,11,STONE)
Block(-4,16,11,STONE)
Block(-6,-3,6,STONE)
Block(-4,15,11,STONE)
Block(-3,-3,-8,STONE)
Block(-6,-2,6,STONE)
Block(-4,14,11,STONE)
Block(-3,-4,-8,STONE)
Block(-6,-1,6,STONE)
Block(-4,13,11,STONE)
Block(-3,-5,-8,STONE)
Block(-4,12,11,STONE)
Block(-12,-3,3,SNOW_BLOCK)
Block(-12,-4,3,STONE)
Block(-12,-5,3,STONE)
Block(-5,-2,1,STONE)
Block(-5,-3,1,STONE)
Block(-6,-1,11,STONE)
Block(-5,-4,1,STONE)
Block(-6,-2,11,STONE)
Block(-5,-5,1,STONE)
Block(-6,-3,11,STONE)
Block(-12,-5,-3,STONE)
Block(-5,-1,1,STONE)
Block(-12,-4,-3,STONE)
Block(-12,1,-3,SNOW_BLOCK)
Block(-12,-3,-3,STONE)
Block(-12,0,-3,STONE)
Block(-12,-2,-3,STONE)
Block(-12,-1,-3,STONE)
Block(-6,-4,11,STONE)
Block(-6,-5,11,STONE)
Block(-7,-1,10,STONE)
Block(-7,-3,10,STONE)
Block(-7,-2,10,STONE)
Block(-7,-5,10,STONE)
Block(-7,-4,10,STONE)
Block(-5,4,11,STONE)
Block(-5,5,11,STONE)
Block(-5,6,11,STONE)
Block(-4,9,1,STONE)
Block(-5,7,11,STONE)
Block(-4,8,1,STONE)
Block(-5,0,11,STONE)
Block(-5,1,11,STONE)
Block(-11,3,0,SNOW)
Block(-5,2,11,STONE)
Block(-5,3,11,STONE)
Block(-11,0,0,STONE)
Block(-4,3,1,STONE)
Block(-4,2,1,STONE)
Block(-4,1,1,STONE)
Block(-11,2,0,SNOW_BLOCK)
Block(-4,0,1,STONE)
Block(-11,1,0,STONE)
Block(-4,7,1,STONE)
Block(-4,6,1,STONE)
Block(-4,5,1,STONE)
Block(-4,4,1,STONE)
Block(-11,-3,2,STONE)
Block(-11,-2,2,STONE)
Block(-11,-1,2,STONE)
Block(-5,8,11,STONE)
Block(-5,9,11,STONE)
Block(-5,-5,-6,STONE)
Block(-7,9,-2,SNOW_BLOCK)
Block(-5,-4,-6,STONE)
Block(-5,-3,-6,STONE)
Block(-5,-2,-6,STONE)
Block(-5,-1,-6,STONE)
Block(-7,5,-2,STONE)
Block(-2,9,5,STONE)
Block(-7,6,-2,STONE)
Block(-2,8,5,STONE)
Block(-11,-5,2,STONE)
Block(-7,7,-2,STONE)
Block(-2,7,5,STONE)
Block(-11,-4,2,STONE)
Block(-2,6,5,STONE)
Block(-7,8,-2,STONE)
Block(-2,5,5,STONE)
Block(-2,4,5,STONE)
Block(-2,3,5,STONE)
Block(-2,2,5,STONE)
Block(-2,1,5,STONE)
Block(-2,0,5,STONE)
Block(-8,-5,8,STONE)
Block(-5,-5,13,STONE)
Block(-8,-4,8,STONE)
Block(-5,-3,13,STONE)
Block(-5,-4,13,STONE)
Block(-8,-1,8,STONE)
Block(-5,-1,13,STONE)
Block(-5,-2,13,STONE)
Block(-8,-3,8,STONE)
Block(-8,-2,8,STONE)
Block(-7,1,-2,STONE)
Block(-7,2,-2,STONE)
Block(-7,3,-2,STONE)
Block(-7,4,-2,STONE)
Block(-7,0,-2,STONE)
Block(-4,-1,-4,STONE)
Block(-4,-2,-4,STONE)
Block(-4,-3,-4,STONE)
Block(-4,-4,-4,STONE)
Block(-4,-5,-4,STONE)
Block(-10,-1,15,STONE)
Block(-10,-2,15,STONE)
Block(-10,-3,15,STONE)
Block(-10,-4,15,STONE)
Block(-10,-5,15,STONE)
Block(-3,-4,5,STONE)
Block(-3,-5,5,STONE)
Block(-3,-1,5,STONE)
Block(-3,-2,5,STONE)
Block(-3,-3,5,STONE)
Block(-1,-5,-1,STONE)
Block(-1,-1,-1,STONE)
Block(-1,-2,-1,STONE)
Block(-1,-3,-1,STONE)
Block(-1,-4,-1,STONE)
Block(-9,-3,18,STONE)
Block(-9,-2,18,SNOW_BLOCK)
Block(-9,-5,18,STONE)
Block(-5,15,13,SNOW)
Block(-9,-4,18,STONE)
Block(-5,13,13,STONE)
Block(-5,14,13,SNOW_BLOCK)
Block(-5,11,13,STONE)
Block(-5,12,13,STONE)
Block(-5,10,13,STONE)
Block(2,-5,14,STONE)
Block(1,-1,15,SNOW_BLOCK)
Block(2,-4,14,STONE)
Block(2,-3,14,STONE)
Block(1,-3,15,STONE)
Block(2,-2,14,STONE)
Block(1,-2,15,STONE)
Block(1,-5,15,STONE)
Block(2,-1,14,SNOW_BLOCK)
Block(1,-4,15,STONE)
Block(-5,14,5,STONE)
Block(-5,15,5,STONE)
Block(-5,12,5,STONE)
Block(-5,13,5,STONE)
Block(-5,10,5,STONE)
Block(-5,11,5,STONE)
Block(-2,2,-3,STONE)
Block(-2,1,-3,STONE)
Block(-2,0,-3,STONE)
Block(-2,4,-3,SNOW_BLOCK)
Block(-2,3,-3,STONE)
Block(-2,-5,3,STONE)
Block(-2,-3,3,STONE)
Block(-2,-4,3,STONE)
Block(-2,-1,3,STONE)
Block(-2,-2,3,STONE)
Block(0,-3,2,SNOW_BLOCK)
Block(-5,6,3,STONE)
Block(0,-4,2,SNOW_BLOCK)
Block(-5,5,3,STONE)
Block(0,-5,2,SNOW_BLOCK)
Block(-5,8,3,STONE)
Block(-5,7,3,STONE)
Block(-5,9,3,STONE)
Block(0,-1,2,SNOW_BLOCK)
Block(0,-2,2,SNOW_BLOCK)
Block(-3,10,5,STONE)
Block(-3,11,5,STONE)
Block(-5,0,3,STONE)
Block(-3,12,5,STONE)
Block(-4,10,14,STONE)
Block(-3,13,5,STONE)
Block(-5,2,3,STONE)
Block(-4,11,14,STONE)
Block(-5,1,3,STONE)
Block(-4,12,14,SNOW_BLOCK)
Block(-5,4,3,STONE)
Block(-5,3,3,STONE)
Block(1,5,9,STONE)
Block(-3,18,5,STONE)
Block(1,4,9,STONE)
Block(-3,19,5,STONE)
Block(1,3,9,STONE)
Block(1,2,9,STONE)
Block(-7,-1,6,STONE)
Block(1,1,9,STONE)
Block(-3,14,5,STONE)
Block(-7,-2,6,STONE)
Block(1,0,9,STONE)
Block(-3,15,5,STONE)
Block(-7,-3,6,STONE)
Block(-3,16,5,STONE)
Block(-7,-4,6,STONE)
Block(-3,17,5,STONE)
Block(1,9,9,SNOW)
Block(1,8,9,SNOW_BLOCK)
Block(1,7,9,STONE)
Block(1,6,9,STONE)
Block(-3,8,7,STONE)
Block(-3,7,7,STONE)
Block(-8,-1,-2,STONE)
Block(-8,-2,-2,STONE)
Block(-3,9,7,STONE)
Block(-8,-3,-2,STONE)
Block(-3,-3,16,STONE)
Block(-3,4,7,STONE)
Block(-8,-4,-2,STONE)
Block(-3,-2,16,STONE)
Block(-3,3,7,STONE)
Block(-8,-5,-2,STONE)
Block(-3,-1,16,STONE)
Block(-3,6,7,STONE)
Block(-3,5,7,STONE)
Block(-7,-3,-3,STONE)
Block(-3,0,7,STONE)
Block(-3,21,5,SNOW_BLOCK)
Block(-7,-4,-3,STONE)
Block(-3,22,5,SNOW_BLOCK)
Block(-3,-5,16,STONE)
Block(-7,-1,-3,STONE)
Block(-3,2,7,STONE)
Block(-3,23,5,SNOW_BLOCK)
Block(-3,-4,16,STONE)
Block(-7,-2,-3,STONE)
Block(-3,1,7,STONE)
Block(-3,24,5,SNOW)
Block(-7,-5,-3,STONE)
Block(-3,20,5,SNOW_BLOCK)
Block(-6,-5,15,STONE)
Block(-6,-4,15,STONE)
Block(-5,-4,5,STONE)
Block(-6,-1,15,STONE)
Block(-5,-5,5,STONE)
Block(-6,-3,15,STONE)
Block(-5,-2,5,STONE)
Block(-5,-3,5,STONE)
Block(-6,-2,15,STONE)
Block(-7,-5,6,STONE)
Block(-9,-4,3,STONE)
Block(-9,-5,3,STONE)
Block(-9,6,-3,SNOW)
Block(-9,3,-3,STONE)
Block(-9,2,-3,STONE)
Block(-2,10,3,STONE)
Block(-9,5,-3,SNOW_BLOCK)
Block(-9,4,-3,STONE)
Block(-9,1,-3,STONE)
Block(-9,0,-3,STONE)
Block(1,0,14,STONE)
Block(1,1,14,STONE)
Block(1,2,14,SNOW_BLOCK)
Block(-2,15,3,STONE)
Block(-2,16,3,SNOW_BLOCK)
Block(-2,13,3,STONE)
Block(-2,14,3,STONE)
Block(-2,11,3,STONE)
Block(-2,12,3,STONE)
Block(-9,2,0,STONE)
Block(-9,3,0,STONE)
Block(-9,0,0,STONE)
Block(-9,1,0,STONE)
Block(-9,4,0,STONE)
Block(-4,9,9,STONE)
Block(-9,5,0,SNOW_BLOCK)
Block(-4,8,9,STONE)
Block(-8,6,10,STONE)
Block(-8,7,10,STONE)
Block(-8,4,10,STONE)
Block(-8,5,10,STONE)
Block(-8,8,10,STONE)
Block(-8,9,10,SNOW_BLOCK)
Block(-8,2,10,STONE)
Block(-8,3,10,STONE)
Block(-8,0,10,STONE)
Block(-8,1,10,STONE)
Block(-3,0,11,STONE)
Block(-3,1,11,STONE)
Block(-3,4,11,STONE)
Block(-5,18,5,STONE)
Block(-3,5,11,STONE)
Block(-5,19,5,STONE)
Block(-3,2,11,STONE)
Block(-5,16,5,STONE)
Block(-3,3,11,STONE)
Block(-5,17,5,STONE)
Block(-3,8,11,STONE)
Block(-3,9,11,STONE)
Block(-3,6,11,STONE)
Block(-5,23,5,SNOW_BLOCK)
Block(-3,7,11,STONE)
Block(-5,24,5,SNOW)
Block(-5,21,5,SNOW_BLOCK)
Block(-5,22,5,SNOW_BLOCK)
Block(-5,20,5,SNOW_BLOCK)
Block(-7,3,16,SNOW_BLOCK)
Block(-8,10,8,SNOW_BLOCK)
Block(-7,4,16,SNOW)
Block(-7,1,16,STONE)
Block(-7,2,16,STONE)
Block(-9,-1,3,STONE)
Block(-7,0,16,STONE)
Block(-9,-2,3,STONE)
Block(-9,-3,3,STONE)
Block(-8,3,1,STONE)
Block(-8,2,1,STONE)
Block(-8,1,1,STONE)
Block(0,1,6,STONE)
Block(-8,0,1,STONE)
Block(0,0,6,STONE)
Block(-8,7,1,STONE)
Block(-5,17,2,STONE)
Block(-8,6,1,STONE)
Block(-5,18,2,SNOW_BLOCK)
Block(-8,5,1,STONE)
Block(-5,19,2,SNOW)
Block(-8,4,1,STONE)
Block(-5,13,2,STONE)
Block(-5,14,2,STONE)
Block(-5,15,2,STONE)
Block(-8,8,1,SNOW_BLOCK)
Block(-5,16,2,STONE)
Block(-9,1,17,SNOW)
Block(-9,0,17,SNOW_BLOCK)
Block(-6,1,5,STONE)
Block(-6,0,5,STONE)
Block(1,-1,12,STONE)
Block(1,-2,12,STONE)
Block(1,-3,12,STONE)
Block(1,-4,12,STONE)
Block(1,-5,12,STONE)
Block(-3,1,10,STONE)
Block(-6,9,5,STONE)
Block(-3,2,10,STONE)
Block(-6,8,5,STONE)
Block(-6,7,5,STONE)
Block(-3,0,10,STONE)
Block(-6,6,5,STONE)
Block(-6,5,5,STONE)
Block(-3,5,10,STONE)
Block(-6,4,5,STONE)
Block(-3,6,10,STONE)
Block(-6,3,5,STONE)
Block(-3,3,10,STONE)
Block(-6,2,5,STONE)
Block(-3,4,10,STONE)
Block(-3,9,10,STONE)
Block(-5,10,2,STONE)
Block(-3,7,10,STONE)
Block(-5,11,2,STONE)
Block(-3,8,10,STONE)
Block(-5,12,2,STONE)
Block(-4,3,9,STONE)
Block(-4,2,9,STONE)
Block(-4,1,9,STONE)
Block(-6,-5,7,STONE)
Block(-4,0,9,STONE)
Block(-8,1,-4,STONE)
Block(-4,7,9,STONE)
Block(-8,0,-4,STONE)
Block(-4,6,9,STONE)
Block(-8,3,-4,STONE)
Block(-4,5,9,STONE)
Block(-8,2,-4,STONE)
Block(-4,4,9,STONE)
Block(-6,-1,12,STONE)
Block(-6,-2,12,STONE)
Block(-6,-3,12,STONE)
Block(-6,-4,12,STONE)
Block(-12,-5,-2,STONE)
Block(-12,-4,-2,STONE)
Block(-12,-3,-2,STONE)
Block(-12,-2,-2,STONE)
Block(-12,-1,-2,STONE)
Block(-6,-5,12,STONE)
Block(-8,5,-4,STONE)
Block(-3,14,8,STONE)
Block(-8,4,-4,STONE)
Block(-3,13,8,STONE)
Block(-3,16,8,STONE)
Block(-8,7,-4,SNOW)
Block(-8,6,-4,SNOW_BLOCK)
Block(-3,15,8,STONE)
Block(-3,10,8,STONE)
Block(-3,12,8,STONE)
Block(-3,11,8,STONE)
Block(-11,-5,14,STONE)
Block(-11,-3,14,STONE)
Block(-11,-4,14,STONE)
Block(-2,-3,14,STONE)
Block(-3,18,8,STONE)
Block(-2,-4,14,STONE)
Block(-3,17,8,STONE)
Block(-2,-5,14,STONE)
Block(-3,19,8,STONE)
Block(-6,0,13,STONE)
Block(-2,-1,14,STONE)
Block(-6,2,13,STONE)
Block(-2,-2,14,STONE)
Block(-6,1,13,STONE)
Block(-6,4,13,STONE)
Block(-6,3,13,STONE)
Block(-6,6,13,STONE)
Block(-6,5,13,STONE)
Block(-8,-3,-5,STONE)
Block(-6,8,13,STONE)
Block(-8,-2,-5,STONE)
Block(-6,7,13,STONE)
Block(-8,-5,-5,STONE)
Block(-8,-4,-5,STONE)
Block(-6,9,13,STONE)
Block(0,3,6,STONE)
Block(-3,25,8,SNOW_BLOCK)
Block(0,2,6,STONE)
Block(-3,24,8,SNOW_BLOCK)
Block(0,5,6,STONE)
Block(0,4,6,STONE)
Block(-3,26,8,SNOW_BLOCK)
Block(-6,-4,7,STONE)
Block(-11,-1,14,SNOW_BLOCK)
Block(0,7,6,STONE)
Block(-3,21,8,SNOW_BLOCK)
Block(-6,-3,7,STONE)
Block(-11,-2,14,STONE)
Block(0,6,6,STONE)
Block(-3,20,8,STONE)
Block(-6,-2,7,STONE)
Block(-8,-1,-5,STONE)
Block(0,9,6,STONE)
Block(-3,23,8,SNOW_BLOCK)
Block(-6,-1,7,STONE)
Block(0,8,6,STONE)
Block(-3,22,8,SNOW_BLOCK)
Block(-8,-2,0,STONE)
Block(-8,-3,0,STONE)
Block(-8,-1,0,STONE)
Block(-8,-4,0,STONE)
Block(-8,-5,0,STONE)
Block(-1,3,2,STONE)
Block(-1,2,2,STONE)
Block(-1,5,2,STONE)
Block(-1,4,2,STONE)
Block(-6,-5,-5,STONE)
Block(-6,-4,-5,STONE)
Block(-1,6,2,SNOW_BLOCK)
Block(-6,-1,-5,STONE)
Block(-6,-3,-5,STONE)
Block(-6,-2,-5,STONE)
Block(-4,-1,14,STONE)
Block(-4,-2,14,STONE)
Block(-4,-3,14,STONE)
Block(-4,-4,14,STONE)
Block(-4,-5,14,STONE)
Block(-1,1,2,STONE)
Block(-1,0,2,STONE)
Block(-7,11,6,STONE)
Block(-7,12,6,STONE)
Block(-7,13,6,STONE)
Block(-6,10,12,STONE)
Block(-7,14,6,STONE)
Block(-6,19,7,STONE)
Block(-7,15,6,STONE)
Block(-7,16,6,STONE)
Block(-7,17,6,STONE)
Block(-7,18,6,SNOW_BLOCK)
Block(-10,-4,7,STONE)
Block(-6,15,12,SNOW_BLOCK)
Block(-10,-5,7,STONE)
Block(-6,11,12,STONE)
Block(-10,-1,7,STONE)
Block(-6,12,12,STONE)
Block(-10,-2,7,STONE)
Block(-6,13,12,STONE)
Block(-10,-3,7,STONE)
Block(-7,10,6,STONE)
Block(-6,14,12,STONE)
Block(-6,21,7,SNOW_BLOCK)
Block(-6,20,7,SNOW_BLOCK)
Block(-10,1,13,SNOW_BLOCK)
Block(-10,0,13,STONE)
Block(-6,22,7,SNOW_BLOCK)
Block(-7,8,7,STONE)
Block(-7,7,7,STONE)
Block(-7,9,7,STONE)
Block(2,-1,9,STONE)
Block(2,-2,9,STONE)
Block(2,-3,9,STONE)
Block(2,-4,9,STONE)
Block(2,-5,9,STONE)
Block(-2,10,14,STONE)
Block(-2,11,14,STONE)
Block(-2,12,14,SNOW_BLOCK)
Block(-11,-4,-6,STONE)
Block(-11,-3,-6,STONE)
Block(-11,-2,-6,STONE)
Block(-6,10,7,STONE)
Block(-11,-5,-6,STONE)
Block(-6,14,7,STONE)
Block(-6,13,7,STONE)
Block(-6,12,7,STONE)
Block(-6,11,7,STONE)
Block(-6,18,7,STONE)
Block(-6,17,7,STONE)
Block(-6,16,7,STONE)
Block(-6,15,7,STONE)
Block(-8,-3,12,STONE)
Block(-8,-4,12,STONE)
Block(0,9,12,STONE)
Block(-8,-5,12,STONE)
Block(0,8,12,STONE)
Block(0,7,12,STONE)
Block(-1,10,4,STONE)
Block(0,2,12,STONE)
Block(0,1,12,STONE)
Block(0,0,12,STONE)
Block(0,6,12,STONE)
Block(0,5,12,STONE)
Block(0,4,12,STONE)
Block(0,3,12,STONE)
Block(-2,-3,-7,STONE)
Block(-2,-5,-7,STONE)
Block(-2,-4,-7,STONE)
Block(-5,1,-6,SNOW_BLOCK)
Block(-7,4,7,STONE)
Block(-7,3,7,STONE)
Block(-7,6,7,STONE)
Block(-5,0,-6,STONE)
Block(-7,5,7,STONE)
Block(-7,0,7,STONE)
Block(-8,-1,12,STONE)
Block(-7,2,7,STONE)
Block(-8,-2,12,STONE)
Block(-7,1,7,STONE)
Block(-1,13,4,STONE)
Block(-1,14,4,SNOW_BLOCK)
Block(-1,11,4,STONE)
Block(-1,12,4,STONE)
Block(-5,-5,10,STONE)
Block(-5,-4,10,STONE)
Block(-5,-1,10,STONE)
Block(-5,-3,10,STONE)
Block(-5,-2,10,STONE)
Block(-10,2,6,SNOW_BLOCK)
Block(-10,1,6,STONE)
Block(-10,0,6,STONE)
Block(-1,9,14,STONE)
Block(-1,1,14,STONE)
Block(-1,2,14,STONE)
Block(-1,3,14,STONE)
Block(-1,4,14,STONE)
Block(-1,5,14,STONE)
Block(-1,6,14,STONE)
Block(-1,7,14,STONE)
Block(-1,8,14,STONE)
Block(-3,0,-5,STONE)
Block(-3,1,-5,STONE)
Block(-3,2,-5,SNOW_BLOCK)
Block(-1,0,14,STONE)
Block(-9,1,9,STONE)
Block(-9,2,9,STONE)
Block(-9,0,9,STONE)
Block(-12,-3,4,SNOW_BLOCK)
Block(-9,5,9,SNOW_BLOCK)
Block(-12,-4,4,STONE)
Block(-12,-5,4,STONE)
Block(-10,-4,18,STONE)
Block(-9,3,9,STONE)
Block(-10,-5,18,STONE)
Block(-9,4,9,STONE)
Block(-4,9,0,STONE)
Block(-10,-2,18,SNOW_BLOCK)
Block(-10,-3,18,STONE)
Block(-5,-3,2,STONE)
Block(-4,4,0,STONE)
Block(-5,-4,2,STONE)
Block(-4,3,0,STONE)
Block(-5,-5,2,STONE)
Block(-4,2,0,STONE)
Block(-4,1,0,STONE)
Block(-4,8,0,STONE)
Block(-4,7,0,STONE)
Block(-5,-1,2,STONE)
Block(-4,6,0,STONE)
Block(-5,-2,2,STONE)
Block(-4,5,0,STONE)
Block(-4,0,0,STONE)
Block(-4,-3,-7,STONE)
Block(-7,11,10,STONE)
Block(-4,-2,-7,STONE)
Block(-7,10,10,STONE)
Block(-4,-5,-7,STONE)
Block(-7,13,10,STONE)
Block(-4,-4,-7,STONE)
Block(-2,9,4,STONE)
Block(-7,12,10,STONE)
Block(-2,8,4,STONE)
Block(-2,7,4,STONE)
Block(-7,14,10,SNOW_BLOCK)
Block(-2,6,4,STONE)
Block(-2,5,4,STONE)
Block(-2,4,4,STONE)
Block(-2,3,4,STONE)
Block(-2,2,4,STONE)
Block(-2,1,4,STONE)
Block(-2,0,4,STONE)
Block(-1,-5,4,STONE)
Block(-1,-3,4,STONE)
Block(-1,-4,4,STONE)
Block(-1,-1,4,STONE)
Block(-1,-2,4,STONE)
Block(-5,19,10,STONE)
Block(-5,18,10,STONE)
Block(-5,15,10,STONE)
Block(-5,14,10,STONE)
Block(-5,17,10,STONE)
Block(-5,16,10,STONE)
Block(-5,11,10,STONE)
Block(-5,10,10,STONE)
Block(-5,13,10,STONE)
Block(-5,12,10,STONE)
Block(-9,-4,10,STONE)
Block(-9,-5,10,STONE)
Block(-9,-2,10,STONE)
Block(-4,9,12,STONE)
Block(-9,-3,10,STONE)
Block(-4,8,12,STONE)
Block(-4,7,12,STONE)
Block(-9,-1,10,STONE)
Block(-4,6,12,STONE)
Block(-8,8,9,STONE)
Block(-8,9,9,STONE)
Block(-8,4,9,STONE)
Block(-5,22,10,SNOW_BLOCK)
Block(-8,5,9,STONE)
Block(-5,21,10,SNOW_BLOCK)
Block(-8,6,9,STONE)
Block(-5,24,10,SNOW)
Block(-8,7,9,STONE)
Block(-5,23,10,SNOW_BLOCK)
Block(-14,-5,-2,STONE)
Block(-4,5,12,STONE)
Block(-14,-4,-2,STONE)
Block(-4,4,12,STONE)
Block(-14,-3,-2,STONE)
Block(-4,3,12,STONE)
Block(-5,20,10,SNOW_BLOCK)
Block(-4,2,12,STONE)
Block(-4,1,12,STONE)
Block(-4,0,12,STONE)
Block(-1,-5,16,STONE)
Block(-1,-4,16,STONE)
Block(-1,-3,16,STONE)
Block(-6,-2,1,STONE)
Block(-1,-2,16,STONE)
Block(-6,-1,1,STONE)
Block(-6,-4,1,STONE)
Block(-1,-1,16,SNOW_BLOCK)
Block(-6,-3,1,STONE)
Block(-6,-5,1,STONE)
Block(-8,0,9,STONE)
Block(-8,1,9,STONE)
Block(-8,2,9,STONE)
Block(-8,3,9,STONE)
Block(-9,-5,-3,STONE)
Block(-9,-4,-3,STONE)
Block(-9,-3,-3,STONE)
Block(-9,-2,-3,STONE)
Block(-9,-1,-3,STONE)
Block(-14,-5,0,STONE)
Block(-7,6,-1,STONE)
Block(-7,7,-1,STONE)
Block(-7,8,-1,STONE)
Block(-7,9,-1,STONE)
Block(-3,10,13,STONE)
Block(-3,13,13,STONE)
Block(-3,14,13,STONE)
Block(-3,11,13,STONE)
Block(-3,12,13,STONE)
Block(-7,2,-1,STONE)
Block(-7,3,-1,STONE)
Block(-7,4,-1,STONE)
Block(-3,15,13,STONE)
Block(-7,5,-1,STONE)
Block(-3,16,13,SNOW_BLOCK)
Block(-7,0,-1,STONE)
Block(-7,1,-1,STONE)
Block(-2,10,9,STONE)
Block(-2,12,9,STONE)
Block(-2,11,9,STONE)
Block(-2,14,9,STONE)
Block(-2,13,9,STONE)
Block(-2,16,9,STONE)
Block(-2,15,9,STONE)
Block(0,-3,14,STONE)
Block(0,-2,14,STONE)
Block(-14,-3,0,SNOW_BLOCK)
Block(0,-1,14,STONE)
Block(-14,-4,0,STONE)
Block(0,-5,14,STONE)
Block(0,-4,14,STONE)
Block(2,-1,11,STONE)
Block(2,-2,11,STONE)
Block(0,10,8,STONE)
Block(-1,-1,9,STONE)
Block(-2,21,9,SNOW_BLOCK)
Block(-2,20,9,SNOW_BLOCK)
Block(-13,-1,-1,SNOW_BLOCK)
Block(-2,23,9,SNOW_BLOCK)
Block(-2,22,9,SNOW_BLOCK)
Block(2,-5,11,STONE)
Block(-2,25,9,SNOW)
Block(-2,24,9,SNOW_BLOCK)
Block(2,-3,11,STONE)
Block(2,-4,11,STONE)
Block(-2,18,9,STONE)
Block(-2,17,9,STONE)
Block(-12,2,-1,SNOW)
Block(-2,19,9,STONE)
Block(-13,-3,-1,STONE)
Block(-13,-2,-1,STONE)
Block(-13,-5,-1,STONE)
Block(-13,-4,-1,STONE)
Block(0,15,8,SNOW_BLOCK)
Block(0,16,8,SNOW_BLOCK)
Block(0,13,8,STONE)
Block(0,14,8,SNOW_BLOCK)
Block(-12,1,-1,SNOW_BLOCK)
Block(0,11,8,STONE)
Block(-12,0,-1,STONE)
Block(0,12,8,STONE)
Block(-6,14,1,STONE)
Block(-6,13,1,STONE)
Block(-6,15,1,SNOW_BLOCK)
Block(-11,2,1,SNOW)
Block(-11,1,1,SNOW_BLOCK)
Block(-11,0,1,STONE)
Block(-3,9,6,STONE)
Block(-3,8,6,STONE)
Block(-3,5,6,STONE)
Block(-3,4,6,STONE)
Block(-3,7,6,STONE)
Block(-3,6,6,STONE)
Block(-3,1,6,STONE)
Block(-3,0,6,STONE)
Block(-3,3,6,STONE)
Block(-9,-5,0,STONE)
Block(-3,2,6,STONE)
Block(-9,-4,0,STONE)
Block(-9,-3,0,STONE)
Block(-9,-2,0,STONE)
Block(-9,-1,0,STONE)
Block(-6,10,1,STONE)
Block(-6,12,1,STONE)
Block(-6,11,1,STONE)
Block(-7,11,1,STONE)
Block(-7,10,1,STONE)
Block(-7,13,1,SNOW_BLOCK)
Block(-7,12,1,STONE)
Block(-5,7,2,STONE)
Block(-5,6,2,STONE)
Block(-5,9,2,STONE)
Block(-5,8,2,STONE)
Block(-5,1,2,STONE)
Block(-5,0,2,STONE)
Block(-5,3,2,STONE)
Block(-5,2,2,STONE)
Block(-5,5,2,STONE)
Block(-5,4,2,STONE)
Block(-1,20,9,STONE)
Block(-1,21,9,SNOW_BLOCK)
Block(-4,11,2,STONE)
Block(-6,11,-2,SNOW)
Block(-4,10,2,STONE)
Block(-6,10,-2,SNOW_BLOCK)
Block(-10,0,12,STONE)
Block(-10,1,12,SNOW_BLOCK)
Block(-1,16,9,STONE)
Block(-1,17,9,STONE)
Block(-1,18,9,STONE)
Block(-1,19,9,STONE)
Block(-10,-1,12,STONE)
Block(-9,6,-4,SNOW)
Block(-9,5,-4,SNOW_BLOCK)
Block(-9,2,-4,STONE)
Block(-9,1,-4,STONE)
Block(-9,4,-4,STONE)
Block(-9,3,-4,STONE)
Block(-9,0,-4,STONE)
Block(-10,-5,12,STONE)
Block(-10,-4,12,STONE)
Block(-10,-3,12,STONE)
Block(-10,-2,12,STONE)
Block(-4,18,2,SNOW_BLOCK)
Block(-4,17,2,STONE)
Block(-4,16,2,STONE)
Block(-2,-4,-2,STONE)
Block(-9,1,1,STONE)
Block(-4,15,2,STONE)
Block(-2,-3,-2,STONE)
Block(-9,2,1,STONE)
Block(-4,14,2,STONE)
Block(-2,-2,-2,STONE)
Block(-4,13,2,STONE)
Block(-2,-1,-2,STONE)
Block(-9,0,1,STONE)
Block(-4,12,2,STONE)
Block(-8,-3,17,STONE)
Block(-9,5,1,SNOW_BLOCK)
Block(-8,-2,17,STONE)
Block(-8,-1,17,STONE)
Block(-9,3,1,STONE)
Block(-2,-5,-2,STONE)
Block(-9,4,1,STONE)
Block(-8,-5,17,STONE)
Block(-8,-4,17,STONE)
Block(-6,-5,-2,STONE)
Block(-5,-1,-3,STONE)
Block(-5,3,12,STONE)
Block(-4,4,8,STONE)
Block(-5,-2,-3,STONE)
Block(-4,3,8,STONE)
Block(-5,4,12,STONE)
Block(-4,2,8,STONE)
Block(-5,5,12,STONE)
Block(-4,1,8,STONE)
Block(-5,6,12,STONE)
Block(-6,-1,-2,STONE)
Block(-4,8,8,STONE)
Block(-6,-2,-2,STONE)
Block(-5,0,12,STONE)
Block(-4,7,8,STONE)
Block(-6,-3,-2,STONE)
Block(-5,1,12,STONE)
Block(-4,6,8,STONE)
Block(-6,-4,-2,STONE)
Block(-5,2,12,STONE)
Block(-4,5,8,STONE)
Block(-5,-5,-3,STONE)
Block(-4,0,8,STONE)
Block(-5,-3,-3,STONE)
Block(-5,-4,-3,STONE)
Block(-1,-2,9,STONE)
Block(-5,7,12,STONE)
Block(-1,-3,9,STONE)
Block(-5,8,12,STONE)
Block(-1,-4,9,STONE)
Block(-5,9,12,STONE)
Block(-1,-5,9,STONE)
Block(-7,6,15,SNOW_BLOCK)
Block(-5,-1,16,STONE)
Block(-5,-2,16,STONE)
Block(-5,-3,16,STONE)
Block(-5,-4,16,STONE)
Block(-5,-5,16,STONE)
Block(-7,4,15,STONE)
Block(-7,5,15,STONE)
Block(-7,2,15,STONE)
Block(-7,3,15,STONE)
Block(-7,0,15,STONE)
Block(-7,1,15,STONE)
Block(-8,0,0,STONE)
Block(-8,4,0,STONE)
Block(-8,3,0,STONE)
Block(-8,2,0,STONE)
Block(-8,1,0,STONE)
Block(-8,8,0,SNOW_BLOCK)
Block(-8,7,0,STONE)
Block(-8,6,0,STONE)
Block(-8,5,0,STONE)
Block(-2,3,-2,STONE)
Block(-2,2,-2,STONE)
Block(-3,-2,8,STONE)
Block(-2,1,-2,STONE)
Block(-3,-1,8,STONE)
Block(-2,0,-2,STONE)
Block(-2,6,-2,SNOW_BLOCK)
Block(-2,5,-2,STONE)
Block(-2,4,-2,STONE)
Block(-7,-4,16,STONE)
Block(-6,2,4,STONE)
Block(-1,12,9,STONE)
Block(-7,-5,16,STONE)
Block(1,0,13,STONE)
Block(-6,1,4,STONE)
Block(-1,13,9,STONE)
Block(-6,0,4,STONE)
Block(1,1,13,STONE)
Block(-1,14,9,STONE)
Block(1,2,13,STONE)
Block(-1,15,9,STONE)
Block(-3,-4,8,STONE)
Block(1,3,13,STONE)
Block(-3,-3,8,STONE)
Block(-7,-1,16,STONE)
Block(1,4,13,STONE)
Block(-7,-2,16,STONE)
Block(1,5,13,STONE)
Block(-1,10,9,STONE)
Block(-3,-5,8,STONE)
Block(-7,-3,16,STONE)
Block(1,6,13,SNOW_BLOCK)
Block(-1,11,9,STONE)
Block(-6,9,4,STONE)
Block(-6,8,4,STONE)
Block(-6,7,4,STONE)
Block(-6,6,4,STONE)
Block(-6,5,4,STONE)
Block(-6,4,4,STONE)
Block(-6,3,4,STONE)
Block(-4,-5,2,STONE)
Block(-3,-5,-3,STONE)
Block(-4,-4,2,STONE)
Block(-4,-3,2,STONE)
Block(-4,-2,2,STONE)
Block(1,-4,7,STONE)
Block(-4,-1,2,STONE)
Block(1,-3,7,STONE)
Block(1,-2,7,STONE)
Block(1,-1,7,STONE)
Block(1,-5,7,STONE)
Block(-4,9,8,STONE)
Block(-3,-2,-3,STONE)
Block(-3,-1,-3,STONE)
Block(-3,-4,-3,STONE)
Block(-3,-3,-3,STONE)
Block(0,-3,5,STONE)
Block(0,-2,5,STONE)
Block(0,-5,5,STONE)
Block(0,-4,5,STONE)
Block(0,-1,5,STONE)
Block(1,0,12,STONE)
Block(1,1,12,STONE)
Block(1,2,12,STONE)
Block(1,3,12,STONE)
Block(1,4,12,STONE)
Block(1,5,12,STONE)
Block(1,6,12,STONE)
Block(1,7,12,STONE)
Block(1,8,12,SNOW_BLOCK)
Block(-6,1,14,STONE)
Block(-6,0,14,STONE)
Block(-6,3,14,STONE)
Block(-6,2,14,STONE)
Block(-6,5,14,STONE)
Block(-6,4,14,STONE)
Block(-6,7,14,STONE)
Block(-6,6,14,STONE)
Block(0,9,7,STONE)
Block(-6,9,14,SNOW_BLOCK)
Block(-6,8,14,STONE)
Block(0,2,7,STONE)
Block(0,1,7,STONE)
