
#######################################################################
# +-----------------------------------------------------------------+ #
# |                            BO3 object                           | #
# +-----------------------------------------------------------------+ #
#######################################################################

# This is the config file of a custom object.
# If you add this object correctly to your BiomeConfigs, it will spawn in the world.

# This is the creator of this BO3 object
Author: LordSmellyPants

# A short description of this BO3 object
Description: No description given

# The BO3 version, don't change this! It can be used by external applications to do a version check.
Version: 3

# The settings mode, WriteAll, WriteWithoutComments or WriteDisable. See WorldConfig.
SettingsMode: WriteDisable


#######################################################################
# +-----------------------------------------------------------------+ #
# |                          Main settings                          | #
# +-----------------------------------------------------------------+ #
#######################################################################

# This needs to be set to true to spawn the object in the Tree and Sapling resources.
Tree: false

# The frequency of the BO3 from 1 to 200. Tries this many times to spawn this BO3 when using the CustomObject(...) resource.
# Ignored by Tree(..), Sapling(..) and CustomStructure(..)
Frequency: 1

# The rarity of the BO3 from 0 to 100. Each spawn attempt has rarity% chance to succeed when using the CustomObject(...) resource.
# Ignored by Tree(..), Sapling(..) and CustomStructure(..)
Rarity: 10.0

# If you set this to true, the BO3 will be placed with a random rotation.
RotateRandomly: true

# The spawn height of the BO3 - atMinY, randomY, highestBlock or highestSolidBlock.
SpawnHeight: highestSolidBlock

# The offset from the spawn height to spawn this BO3
# Ex. SpawnHeight = highestSolidBlock, SpawnHeightOffset = 3; This object will spawn 3 blocks above the highest solid block
SpawnHeightOffset: 0

# A random amount to offset the spawn location from the spawn offset height
# Ex. SpawnHeightOffset = 3, SpawnHeightVariance = 3; This object will spawn 3 to 6 blocks above the original spot it would have spawned
SpawnHeightVariance: 0

##############################
# Height Limits for the BO3. #
##############################

# When in randomY mode used as the minimum Y or in atMinY mode as the actual Y to spawn this BO3 at.
MinHeight: 0

# When in randomY mode used as the maximum Y to spawn this BO3 at.
MaxHeight: 64

######################
# Extrusion settings #
######################

# The style of extrusion you wish to use - BottomDown, TopUp, None (Default)
ExtrudeMode: None

# The blocks to extrude your BO3 through
ExtrudeThroughBlocks: AIR

# Objects can have other objects attacthed to it: branches. Branches can also
# have branches attached to it, which can also have branches, etc. This is the
# maximum branch depth for this objects.
MaxBranchDepth: 10

# When spawned with the UseWorld keyword, this BO3 should NOT spawn in the following biomes.
# If you write the BO3 name directly in the BiomeConfigs, this will be ignored.
ExcludedBiomes: All


#######################################################################
# +-----------------------------------------------------------------+ #
# |                      Source block settings                      | #
# +-----------------------------------------------------------------+ #
#######################################################################

# The B(s) the BO3 should spawn in.
SourceBlocks: STONE:1,STONE:3,STONE:5,DIRT:1,GRASS,DIRT,STONE,GRAVEL,SAND,CLAY,HARD_CLAY,159:14,159,175,175:1,175:2,175:3,175:4,175:5,31,31:1,31:2,1:1,1:5,1:3,AIR,WATER,SANDSTONE

# The maximum percentage of the BO3 that can be outside the SourceBlock.
# The BO3 won't be placed on a location with more blocks outside the SourceBlock than this percentage.
MaxPercentageOutsideSourceBlock: 20

# What to do when a block is about to be placed outside the SourceBlock? (dontPlace, placeAnyway)
OutsideSourceBlock: placeAnyway


#######################################################################
# +-----------------------------------------------------------------+ #
# |                              Blocks                             | #
# +-----------------------------------------------------------------+ #
#######################################################################

# All the blocks used in the BO3 are listed here. Possible blocks:
# B(x,y,z,id[.data][,nbtfile.nbt)
# RB(x,y,z,id[:data][,nbtfile.nbt],chance[,id[:data][,nbtfile.nbt],chance[,...]])
#  So RB(0,0,0,CHEST,chest.nbt,50,CHEST,anotherchest.nbt,100) will spawn a chest at
#  the BO3 origin, and give it a 50% chance to have the contents of chest.nbt, or, if that
#  fails, a 100% percent chance to have the contents of anotherchest.nbt.
# MinecraftObject(x,y,z,name)
#  Spawns an object in the Mojang NBT structure format. For example, 
#  MinecraftObject(0,0,0,minecraft:igloo/igloo_bottom)
#  spawns the bottom part of an igloo.
B(-8,-2,-3,STONE)
B(-8,-2,-2,STONE)
B(-8,-2,-1,STONE)
B(-8,-2,0,STONE)
B(-8,-1,-3,STONE)
B(-8,-1,-2,STONE)
B(-8,-1,-1,STONE)
B(-8,-1,0,STONE)
B(-7,-4,-3,STONE)
B(-7,-3,-3,STONE)
B(-7,-2,-4,STONE)
B(-7,-2,-3,STONE)
B(-7,-2,-2,STONE)
B(-7,-2,-1,STONE)
B(-7,-2,0,STONE)
B(-7,-2,1,STONE)
B(-7,-1,-4,STONE)
B(-7,-1,-3,STONE)
B(-7,-1,-2,STONE)
B(-7,-1,-1,STONE)
B(-7,-1,0,STONE)
B(-7,-1,1,STONE)
B(-7,0,-3,STONE)
B(-7,1,-3,STONE)
B(-7,3,-3,LEAVES:3)
B(-7,4,-4,LEAVES:3)
B(-7,4,-3,LEAVES:3)
B(-7,5,-5,LEAVES:3)
B(-7,5,-4,LEAVES:3)
B(-7,5,-3,LEAVES:3)
B(-7,5,-2,LEAVES:3)
B(-7,6,-5,LEAVES:3)
B(-7,6,-4,LEAVES:3)
B(-7,6,-3,LEAVES:3)
B(-7,6,-2,LEAVES:3)
B(-7,7,-4,LEAVES:3)
B(-7,7,-3,LEAVES:3)
B(-7,7,-2,LEAVES:3)
B(-7,8,-3,LEAVES:3)
B(-6,-7,-4,DIRT)
B(-6,-7,-3,DIRT)
B(-6,-6,-4,DIRT)
B(-6,-6,-3,DIRT)
B(-6,-5,-4,DIRT)
B(-6,-5,-3,DIRT)
B(-6,-4,-4,STONE)
B(-6,-4,-3,STONE)
B(-6,-4,-1,DIRT)
B(-6,-4,0,DIRT)
B(-6,-3,-5,STONE)
B(-6,-3,-4,STONE)
B(-6,-3,-3,STONE)
B(-6,-3,-1,STONE)
B(-6,-3,0,STONE)
B(-6,-3,1,STONE)
B(-6,-2,-5,STONE)
B(-6,-2,-4,STONE)
B(-6,-2,-3,STONE)
B(-6,-2,-2,STONE)
B(-6,-2,-1,STONE)
B(-6,-2,0,STONE)
B(-6,-2,1,STONE)
B(-6,-2,2,STONE)
B(-6,-2,3,DIRT)
B(-6,-1,-5,STONE)
B(-6,-1,-4,STONE)
B(-6,-1,-3,STONE)
B(-6,-1,-2,STONE)
B(-6,-1,-1,STONE)
B(-6,-1,0,STONE)
B(-6,-1,1,STONE)
B(-6,-1,2,STONE)
B(-6,-1,3,GRASS)
B(-6,0,-5,STONE)
B(-6,0,-4,STONE)
B(-6,0,-3,STONE)
B(-6,0,-1,STONE)
B(-6,0,0,STONE)
B(-6,0,1,STONE)
B(-6,1,-4,STONE)
B(-6,1,-3,STONE)
B(-6,1,-1,GRASS)
B(-6,1,0,GRASS)
B(-6,2,-4,DIRT)
B(-6,2,-3,DIRT)
B(-6,3,-4,DIRT)
B(-6,3,-3,DIRT)
B(-6,4,-4,GRASS)
B(-6,4,-3,DIRT)
B(-6,5,-3,LOG:3)
B(-6,6,-5,LEAVES:3)
B(-6,6,-4,LEAVES:3)
B(-6,6,-3,LOG:3)
B(-6,6,-2,LEAVES:3)
B(-6,6,-1,LEAVES:3)
B(-6,7,-4,LEAVES:3)
B(-6,7,-3,LOG:3)
B(-6,7,-2,LEAVES:3)
B(-6,8,-4,LEAVES:3)
B(-6,8,-3,LEAVES:3)
B(-6,8,-2,LEAVES:3)
B(-6,9,-3,LEAVES:3)
B(-5,-7,-4,DIRT)
B(-5,-7,-3,DIRT)
B(-5,-7,-2,STONE)
B(-5,-6,-5,DIRT)
B(-5,-6,-4,DIRT)
B(-5,-6,-3,DIRT)
B(-5,-6,-2,STONE)
B(-5,-6,-1,STONE)
B(-5,-5,-5,DIRT)
B(-5,-5,-4,STONE)
B(-5,-5,-3,STONE)
B(-5,-5,-2,DIRT)
B(-5,-5,-1,STONE)
B(-5,-5,0,DIRT)
B(-5,-5,1,DIRT)
B(-5,-4,-5,STONE)
B(-5,-4,-4,STONE)
B(-5,-4,-3,STONE)
B(-5,-4,-2,STONE)
B(-5,-4,-1,STONE)
B(-5,-4,0,STONE)
B(-5,-4,1,DIRT)
B(-5,-3,-5,STONE)
B(-5,-3,-4,STONE)
B(-5,-3,-3,STONE)
B(-5,-3,-2,STONE)
B(-5,-3,-1,STONE)
B(-5,-3,0,STONE)
B(-5,-3,1,STONE)
B(-5,-3,2,DIRT)
B(-5,-2,-6,STONE)
B(-5,-2,-5,STONE)
B(-5,-2,-4,STONE)
B(-5,-2,-3,STONE)
B(-5,-2,-2,STONE)
B(-5,-2,-1,STONE)
B(-5,-2,0,STONE)
B(-5,-2,1,STONE)
B(-5,-2,2,STONE)
B(-5,-2,3,STONE)
B(-5,-2,4,DIRT)
B(-5,-1,-6,STONE)
B(-5,-1,-5,STONE)
B(-5,-1,-4,STONE)
B(-5,-1,-3,STONE)
B(-5,-1,-2,STONE)
B(-5,-1,-1,STONE)
B(-5,-1,0,STONE)
B(-5,-1,1,STONE)
B(-5,-1,2,STONE)
B(-5,-1,3,STONE)
B(-5,-1,4,GRASS)
B(-5,0,-6,STONE)
B(-5,0,-5,STONE)
B(-5,0,-4,STONE)
B(-5,0,-3,STONE)
B(-5,0,-2,STONE)
B(-5,0,-1,STONE)
B(-5,0,0,STONE)
B(-5,0,1,STONE)
B(-5,0,2,GRASS)
B(-5,1,-6,STONE)
B(-5,1,-5,STONE)
B(-5,1,-4,STONE)
B(-5,1,-3,STONE)
B(-5,1,-2,STONE)
B(-5,1,-1,STONE)
B(-5,1,0,STONE)
B(-5,1,1,DIRT)
B(-5,1,2,LEAVES:3)
B(-5,1,4,LEAVES:3)
B(-5,2,-5,DIRT)
B(-5,2,-4,STONE)
B(-5,2,-3,STONE)
B(-5,2,-2,DIRT)
B(-5,2,-1,STONE)
B(-5,2,0,GRASS)
B(-5,2,1,GRASS)
B(-5,2,2,LEAVES:3)
B(-5,2,3,LEAVES:3)
B(-5,2,4,LEAVES:3)
B(-5,3,-5,GRASS)
B(-5,3,-4,DIRT)
B(-5,3,-3,DIRT)
B(-5,3,-2,STONE)
B(-5,3,-1,STONE)
B(-5,4,-4,GRASS)
B(-5,4,-3,GRASS)
B(-5,4,-2,STONE)
B(-5,5,-4,LEAVES:3)
B(-5,5,-2,LEAVES:3)
B(-5,5,-1,LEAVES:3)
B(-5,5,0,LEAVES:3)
B(-5,5,2,LEAVES:3)
B(-5,6,-4,LEAVES:3)
B(-5,6,-3,LEAVES:3)
B(-5,6,-2,LEAVES:3)
B(-5,6,-1,LEAVES:3)
B(-5,6,0,LEAVES:3)
B(-5,6,1,LEAVES:3)
B(-5,6,2,LEAVES:3)
B(-5,7,-4,LEAVES:3)
B(-5,7,-3,LEAVES:3)
B(-5,7,-2,LEAVES:3)
B(-5,7,1,LEAVES:3)
B(-5,8,-5,LEAVES:3)
B(-5,8,-3,LEAVES:3)
B(-5,9,-5,LEAVES:3)
B(-5,9,-4,LEAVES:3)
B(-5,9,-3,LEAVES:3)
B(-5,10,-5,LEAVES:3)
B(-5,10,-4,LEAVES:3)
B(-5,10,-3,LEAVES:3)
B(-5,11,-4,LEAVES:3)
B(-4,-12,-3,DIRT)
B(-4,-11,-5,DIRT)
B(-4,-11,-4,DIRT)
B(-4,-11,-3,DIRT)
B(-4,-11,-2,DIRT)
B(-4,-11,-1,DIRT)
B(-4,-10,-5,DIRT)
B(-4,-10,-4,STONE)
B(-4,-10,-3,STONE)
B(-4,-10,-2,DIRT)
B(-4,-10,-1,STONE)
B(-4,-9,-5,STONE)
B(-4,-9,-4,STONE)
B(-4,-9,-3,STONE)
B(-4,-9,-2,STONE)
B(-4,-9,-1,STONE)
B(-4,-8,-5,STONE)
B(-4,-8,-4,STONE)
B(-4,-8,-3,STONE)
B(-4,-8,-2,STONE)
B(-4,-8,-1,STONE)
B(-4,-7,-5,STONE)
B(-4,-7,-4,STONE)
B(-4,-7,-3,STONE)
B(-4,-7,-2,STONE)
B(-4,-7,-1,STONE)
B(-4,-7,0,STONE)
B(-4,-6,-5,STONE)
B(-4,-6,-4,STONE)
B(-4,-6,-3,STONE)
B(-4,-6,-2,STONE)
B(-4,-6,-1,STONE)
B(-4,-6,0,STONE)
B(-4,-6,1,DIRT)
B(-4,-5,-5,STONE)
B(-4,-5,-4,STONE)
B(-4,-5,-3,STONE)
B(-4,-5,-2,STONE)
B(-4,-5,-1,STONE)
B(-4,-5,0,STONE)
B(-4,-5,1,DIRT)
B(-4,-4,-5,STONE)
B(-4,-4,-4,STONE)
B(-4,-4,-3,STONE)
B(-4,-4,-2,STONE)
B(-4,-4,-1,STONE)
B(-4,-4,0,STONE)
B(-4,-4,1,STONE)
B(-4,-4,2,DIRT)
B(-4,-4,3,DIRT)
B(-4,-3,-6,STONE)
B(-4,-3,-5,STONE)
B(-4,-3,-4,STONE)
B(-4,-3,-3,STONE)
B(-4,-3,-2,STONE)
B(-4,-3,-1,STONE)
B(-4,-3,0,STONE)
B(-4,-3,1,STONE)
B(-4,-3,2,STONE)
B(-4,-3,3,STONE)
B(-4,-3,4,DIRT)
B(-4,-2,-7,STONE)
B(-4,-2,-6,STONE)
B(-4,-2,-5,STONE)
B(-4,-2,-4,STONE)
B(-4,-2,-3,STONE)
B(-4,-2,-2,STONE)
B(-4,-2,-1,STONE)
B(-4,-2,0,STONE)
B(-4,-2,1,STONE)
B(-4,-2,2,STONE)
B(-4,-2,3,STONE)
B(-4,-2,4,STONE)
B(-4,-1,-7,STONE)
B(-4,-1,-6,STONE)
B(-4,-1,-5,STONE)
B(-4,-1,-4,STONE)
B(-4,-1,-3,STONE)
B(-4,-1,-2,STONE)
B(-4,-1,-1,STONE)
B(-4,-1,0,STONE)
B(-4,-1,1,STONE)
B(-4,-1,2,STONE)
B(-4,-1,3,STONE)
B(-4,-1,4,STONE)
B(-4,0,-6,STONE)
B(-4,0,-5,STONE)
B(-4,0,-4,STONE)
B(-4,0,-3,STONE)
B(-4,0,-2,STONE)
B(-4,0,-1,STONE)
B(-4,0,0,STONE)
B(-4,0,1,STONE)
B(-4,0,2,STONE)
B(-4,0,3,STONE)
B(-4,0,4,GRASS)
B(-4,1,-6,STONE)
B(-4,1,-5,STONE)
B(-4,1,-4,STONE)
B(-4,1,-3,STONE)
B(-4,1,-2,STONE)
B(-4,1,-1,STONE)
B(-4,1,0,STONE)
B(-4,1,1,STONE)
B(-4,1,2,GRASS)
B(-4,1,3,DIRT)
B(-4,2,-6,STONE)
B(-4,2,-5,STONE)
B(-4,2,-4,STONE)
B(-4,2,-3,STONE)
B(-4,2,-2,STONE)
B(-4,2,-1,STONE)
B(-4,2,0,STONE)
B(-4,2,1,DIRT)
B(-4,2,2,LEAVES:3)
B(-4,2,3,LOG:3)
B(-4,2,4,LEAVES:3)
B(-4,3,-5,STONE)
B(-4,3,-4,STONE)
B(-4,3,-3,STONE)
B(-4,3,-2,STONE)
B(-4,3,-1,STONE)
B(-4,3,0,STONE)
B(-4,3,1,DIRT)
B(-4,3,3,LEAVES:3)
B(-4,4,-5,STONE)
B(-4,4,-4,STONE)
B(-4,4,-3,STONE)
B(-4,4,-2,STONE)
B(-4,4,-1,STONE)
B(-4,4,0,STONE)
B(-4,4,1,LOG:3)
B(-4,5,-5,STONE)
B(-4,5,-4,STONE)
B(-4,5,-3,STONE)
B(-4,5,-2,STONE)
B(-4,5,-1,STONE)
B(-4,5,1,LOG:3)
B(-4,6,-5,STONE)
B(-4,6,-4,STONE)
B(-4,6,-3,STONE)
B(-4,6,-2,STONE)
B(-4,6,-1,STONE)
B(-4,6,0,LEAVES:3)
B(-4,6,1,LOG:3)
B(-4,6,2,LEAVES:3)
B(-4,7,-5,DIRT)
B(-4,7,-4,STONE)
B(-4,7,-3,STONE)
B(-4,7,-2,DIRT)
B(-4,7,-1,STONE)
B(-4,7,0,LEAVES:3)
B(-4,7,1,LEAVES:3)
B(-4,7,2,LEAVES:3)
B(-4,8,-5,GRASS)
B(-4,8,-4,DIRT)
B(-4,8,-3,DIRT)
B(-4,8,-2,GRASS)
B(-4,8,-1,GRASS)
B(-4,8,1,LEAVES:3)
B(-4,9,-6,LEAVES:3)
B(-4,9,-5,LEAVES:3)
B(-4,9,-4,LOG:3)
B(-4,9,-3,GRASS)
B(-4,9,-2,LEAVES:3)
B(-4,9,-1,LEAVES:3)
B(-4,10,-6,LEAVES:3)
B(-4,10,-5,LEAVES:3)
B(-4,10,-4,LOG:3)
B(-4,10,-3,LEAVES:3)
B(-4,10,-2,LEAVES:3)
B(-4,10,-1,LEAVES:3)
B(-4,11,-5,LEAVES:3)
B(-4,11,-4,LOG:3)
B(-4,11,-3,LEAVES:3)
B(-4,12,-4,LEAVES:3)
B(-3,-13,-4,DIRT)
B(-3,-13,-3,DIRT)
B(-3,-12,-5,DIRT)
B(-3,-12,-4,DIRT)
B(-3,-12,-3,STONE)
B(-3,-12,-2,DIRT)
B(-3,-11,-5,STONE)
B(-3,-11,-4,STONE)
B(-3,-11,-3,STONE)
B(-3,-11,-2,STONE)
B(-3,-11,-1,DIRT)
B(-3,-11,0,DIRT)
B(-3,-10,-5,STONE)
B(-3,-10,-4,STONE)
B(-3,-10,-3,STONE)
B(-3,-10,-2,STONE)
B(-3,-10,-1,STONE)
B(-3,-10,0,DIRT)
B(-3,-9,-5,STONE)
B(-3,-9,-4,STONE)
B(-3,-9,-3,STONE)
B(-3,-9,-2,STONE)
B(-3,-9,-1,STONE)
B(-3,-9,0,STONE)
B(-3,-8,-5,STONE)
B(-3,-8,-4,STONE)
B(-3,-8,-3,STONE)
B(-3,-8,-2,STONE)
B(-3,-8,-1,STONE)
B(-3,-8,0,STONE)
B(-3,-7,-6,STONE)
B(-3,-7,-5,STONE)
B(-3,-7,-4,STONE)
B(-3,-7,-3,STONE)
B(-3,-7,-2,STONE)
B(-3,-7,-1,STONE)
B(-3,-7,0,STONE)
B(-3,-7,1,STONE)
B(-3,-6,-6,STONE)
B(-3,-6,-5,STONE)
B(-3,-6,-4,STONE)
B(-3,-6,-3,STONE)
B(-3,-6,-2,STONE)
B(-3,-6,-1,STONE)
B(-3,-6,0,STONE)
B(-3,-6,1,STONE)
B(-3,-6,2,DIRT)
B(-3,-5,-6,STONE)
B(-3,-5,-5,STONE)
B(-3,-5,-4,STONE)
B(-3,-5,-3,STONE)
B(-3,-5,-2,STONE)
B(-3,-5,-1,STONE)
B(-3,-5,0,STONE)
B(-3,-5,1,STONE)
B(-3,-5,2,DIRT)
B(-3,-4,-6,STONE)
B(-3,-4,-5,STONE)
B(-3,-4,-4,STONE)
B(-3,-4,-3,STONE)
B(-3,-4,-2,STONE)
B(-3,-4,-1,STONE)
B(-3,-4,0,STONE)
B(-3,-4,1,STONE)
B(-3,-4,2,STONE)
B(-3,-4,3,DIRT)
B(-3,-3,-6,STONE)
B(-3,-3,-5,STONE)
B(-3,-3,-4,STONE)
B(-3,-3,-3,STONE)
B(-3,-3,-2,STONE)
B(-3,-3,-1,STONE)
B(-3,-3,0,STONE)
B(-3,-3,1,STONE)
B(-3,-3,2,STONE)
B(-3,-3,3,STONE)
B(-3,-3,4,DIRT)
B(-3,-2,-8,STONE)
B(-3,-2,-7,STONE)
B(-3,-2,-6,STONE)
B(-3,-2,-5,STONE)
B(-3,-2,-4,STONE)
B(-3,-2,-3,STONE)
B(-3,-2,-2,STONE)
B(-3,-2,-1,STONE)
B(-3,-2,0,STONE)
B(-3,-2,1,STONE)
B(-3,-2,2,STONE)
B(-3,-2,3,STONE)
B(-3,-2,4,STONE)
B(-3,-2,5,STONE)
B(-3,-1,-8,STONE)
B(-3,-1,-7,STONE)
B(-3,-1,-6,STONE)
B(-3,-1,-5,STONE)
B(-3,-1,-4,STONE)
B(-3,-1,-3,STONE)
B(-3,-1,-2,STONE)
B(-3,-1,-1,STONE)
B(-3,-1,0,STONE)
B(-3,-1,1,STONE)
B(-3,-1,2,STONE)
B(-3,-1,3,STONE)
B(-3,-1,4,STONE)
B(-3,-1,5,STONE)
B(-3,0,-7,STONE)
B(-3,0,-6,STONE)
B(-3,0,-5,STONE)
B(-3,0,-4,STONE)
B(-3,0,-3,STONE)
B(-3,0,-2,STONE)
B(-3,0,-1,STONE)
B(-3,0,0,STONE)
B(-3,0,1,STONE)
B(-3,0,2,STONE)
B(-3,0,3,STONE)
B(-3,0,4,GRASS)
B(-3,1,-7,STONE)
B(-3,1,-6,STONE)
B(-3,1,-5,STONE)
B(-3,1,-4,STONE)
B(-3,1,-3,STONE)
B(-3,1,-2,STONE)
B(-3,1,-1,STONE)
B(-3,1,0,STONE)
B(-3,1,1,STONE)
B(-3,1,2,STONE)
B(-3,1,3,GRASS)
B(-3,1,4,LEAVES:3)
B(-3,2,-6,STONE)
B(-3,2,-5,STONE)
B(-3,2,-4,STONE)
B(-3,2,-3,STONE)
B(-3,2,-2,STONE)
B(-3,2,-1,STONE)
B(-3,2,0,STONE)
B(-3,2,1,STONE)
B(-3,2,2,DIRT)
B(-3,2,3,LEAVES:3)
B(-3,2,4,LEAVES:3)
B(-3,3,-6,STONE)
B(-3,3,-5,STONE)
B(-3,3,-4,STONE)
B(-3,3,-3,STONE)
B(-3,3,-2,STONE)
B(-3,3,-1,STONE)
B(-3,3,0,STONE)
B(-3,3,1,STONE)
B(-3,3,2,GRASS)
B(-3,4,-6,STONE)
B(-3,4,-5,STONE)
B(-3,4,-4,STONE)
B(-3,4,-3,STONE)
B(-3,4,-2,STONE)
B(-3,4,-1,STONE)
B(-3,4,0,STONE)
B(-3,4,1,STONE)
B(-3,5,-6,STONE)
B(-3,5,-5,STONE)
B(-3,5,-4,STONE)
B(-3,5,-3,STONE)
B(-3,5,-2,STONE)
B(-3,5,-1,STONE)
B(-3,5,0,STONE)
B(-3,5,2,LEAVES:3)
B(-3,6,-6,STONE)
B(-3,6,-5,STONE)
B(-3,6,-4,STONE)
B(-3,6,-3,STONE)
B(-3,6,-2,STONE)
B(-3,6,-1,STONE)
B(-3,6,0,STONE)
B(-3,6,1,LEAVES:3)
B(-3,6,2,LEAVES:3)
B(-3,7,-6,STONE)
B(-3,7,-5,STONE)
B(-3,7,-4,STONE)
B(-3,7,-3,STONE)
B(-3,7,-2,STONE)
B(-3,7,-1,STONE)
B(-3,7,0,DIRT)
B(-3,7,1,LEAVES:3)
B(-3,8,-6,STONE)
B(-3,8,-5,STONE)
B(-3,8,-4,STONE)
B(-3,8,-3,STONE)
B(-3,8,-2,STONE)
B(-3,8,-1,DIRT)
B(-3,8,0,GRASS)
B(-3,9,-6,GRASS)
B(-3,9,-5,GRASS)
B(-3,9,-4,DIRT)
B(-3,9,-3,STONE)
B(-3,9,-2,GRASS)
B(-3,9,-1,LOG:3)
B(-3,9,0,LEAVES:3)
B(-3,10,-6,LEAVES:3)
B(-3,10,-5,LEAVES:3)
B(-3,10,-4,GRASS)
B(-3,10,-3,GRASS)
B(-3,10,-2,LEAVES:3)
B(-3,10,-1,LOG:3)
B(-3,10,0,LEAVES:3)
B(-3,11,-5,LEAVES:3)
B(-3,11,-4,LEAVES:3)
B(-3,11,-1,LEAVES:3)
B(-2,-17,-4,STONE)
B(-2,-17,-3,STONE)
B(-2,-16,-5,STONE)
B(-2,-16,-4,STONE)
B(-2,-16,-3,STONE)
B(-2,-16,-2,STONE)
B(-2,-15,-5,STONE)
B(-2,-15,-4,STONE)
B(-2,-15,-3,STONE)
B(-2,-15,-2,STONE)
B(-2,-14,-5,STONE)
B(-2,-14,-4,STONE)
B(-2,-14,-3,DIRT)
B(-2,-14,-2,STONE)
B(-2,-13,-5,STONE)
B(-2,-13,-4,STONE)
B(-2,-13,-3,STONE)
B(-2,-13,-2,STONE)
B(-2,-13,-1,STONE)
B(-2,-12,-5,STONE)
B(-2,-12,-4,STONE)
B(-2,-12,-3,STONE)
B(-2,-12,-2,STONE)
B(-2,-12,-1,DIRT)
B(-2,-11,-6,STONE)
B(-2,-11,-5,STONE)
B(-2,-11,-4,STONE)
B(-2,-11,-3,STONE)
B(-2,-11,-2,STONE)
B(-2,-11,-1,STONE)
B(-2,-11,0,STONE)
B(-2,-11,1,STONE)
B(-2,-10,-6,STONE)
B(-2,-10,-5,STONE)
B(-2,-10,-4,STONE)
B(-2,-10,-3,STONE)
B(-2,-10,-2,STONE)
B(-2,-10,-1,STONE)
B(-2,-10,0,STONE)
B(-2,-10,1,STONE)
B(-2,-9,-6,STONE)
B(-2,-9,-5,STONE)
B(-2,-9,-4,STONE)
B(-2,-9,-3,STONE)
B(-2,-9,-2,STONE)
B(-2,-9,-1,STONE)
B(-2,-9,0,STONE)
B(-2,-9,1,STONE)
B(-2,-8,-6,STONE)
B(-2,-8,-5,STONE)
B(-2,-8,-4,STONE)
B(-2,-8,-3,STONE)
B(-2,-8,-2,STONE)
B(-2,-8,-1,STONE)
B(-2,-8,0,STONE)
B(-2,-8,1,DIRT)
B(-2,-7,-6,STONE)
B(-2,-7,-5,STONE)
B(-2,-7,-4,STONE)
B(-2,-7,-3,STONE)
B(-2,-7,-2,STONE)
B(-2,-7,-1,STONE)
B(-2,-7,0,STONE)
B(-2,-7,1,STONE)
B(-2,-7,2,STONE)
B(-2,-6,-6,STONE)
B(-2,-6,-5,STONE)
B(-2,-6,-4,STONE)
B(-2,-6,-3,STONE)
B(-2,-6,-2,STONE)
B(-2,-6,-1,STONE)
B(-2,-6,0,STONE)
B(-2,-6,1,STONE)
B(-2,-6,2,STONE)
B(-2,-6,3,STONE)
B(-2,-5,-6,STONE)
B(-2,-5,-5,STONE)
B(-2,-5,-4,STONE)
B(-2,-5,-3,STONE)
B(-2,-5,-2,STONE)
B(-2,-5,-1,STONE)
B(-2,-5,0,STONE)
B(-2,-5,1,STONE)
B(-2,-5,2,STONE)
B(-2,-5,3,DIRT)
B(-2,-4,-7,STONE)
B(-2,-4,-6,STONE)
B(-2,-4,-5,STONE)
B(-2,-4,-4,STONE)
B(-2,-4,-3,STONE)
B(-2,-4,-2,STONE)
B(-2,-4,-1,STONE)
B(-2,-4,0,STONE)
B(-2,-4,1,STONE)
B(-2,-4,2,STONE)
B(-2,-4,3,STONE)
B(-2,-3,-8,STONE)
B(-2,-3,-7,STONE)
B(-2,-3,-6,STONE)
B(-2,-3,-5,STONE)
B(-2,-3,-4,STONE)
B(-2,-3,-3,STONE)
B(-2,-3,-2,STONE)
B(-2,-3,-1,STONE)
B(-2,-3,0,STONE)
B(-2,-3,1,STONE)
B(-2,-3,2,STONE)
B(-2,-3,3,STONE)
B(-2,-3,4,DIRT)
B(-2,-2,-9,STONE)
B(-2,-2,-8,STONE)
B(-2,-2,-7,STONE)
B(-2,-2,-6,STONE)
B(-2,-2,-5,STONE)
B(-2,-2,-4,STONE)
B(-2,-2,-3,STONE)
B(-2,-2,-2,STONE)
B(-2,-2,-1,STONE)
B(-2,-2,0,STONE)
B(-2,-2,1,STONE)
B(-2,-2,2,STONE)
B(-2,-2,3,STONE)
B(-2,-2,4,STONE)
B(-2,-2,5,STONE)
B(-2,-2,6,STONE)
B(-2,-1,-9,STONE)
B(-2,-1,-8,STONE)
B(-2,-1,-7,STONE)
B(-2,-1,-6,STONE)
B(-2,-1,-5,STONE)
B(-2,-1,-4,STONE)
B(-2,-1,-3,STONE)
B(-2,-1,-2,STONE)
B(-2,-1,-1,STONE)
B(-2,-1,0,STONE)
B(-2,-1,1,STONE)
B(-2,-1,2,STONE)
B(-2,-1,3,STONE)
B(-2,-1,4,STONE)
B(-2,-1,5,STONE)
B(-2,-1,6,STONE)
B(-2,0,-8,STONE)
B(-2,0,-7,STONE)
B(-2,0,-6,STONE)
B(-2,0,-5,STONE)
B(-2,0,-4,STONE)
B(-2,0,-3,STONE)
B(-2,0,-2,STONE)
B(-2,0,-1,STONE)
B(-2,0,0,STONE)
B(-2,0,1,STONE)
B(-2,0,2,STONE)
B(-2,0,3,STONE)
B(-2,0,4,GRASS)
B(-2,1,-8,STONE)
B(-2,1,-7,STONE)
B(-2,1,-6,STONE)
B(-2,1,-5,STONE)
B(-2,1,-4,STONE)
B(-2,1,-3,STONE)
B(-2,1,-2,STONE)
B(-2,1,-1,STONE)
B(-2,1,0,STONE)
B(-2,1,1,STONE)
B(-2,1,2,STONE)
B(-2,1,3,STONE)
B(-2,2,-7,STONE)
B(-2,2,-6,STONE)
B(-2,2,-5,STONE)
B(-2,2,-4,STONE)
B(-2,2,-3,STONE)
B(-2,2,-2,STONE)
B(-2,2,-1,STONE)
B(-2,2,0,STONE)
B(-2,2,1,STONE)
B(-2,2,2,STONE)
B(-2,2,3,DIRT)
B(-2,3,-7,STONE)
B(-2,3,-6,STONE)
B(-2,3,-5,STONE)
B(-2,3,-4,STONE)
B(-2,3,-3,STONE)
B(-2,3,-2,STONE)
B(-2,3,-1,STONE)
B(-2,3,0,STONE)
B(-2,3,1,STONE)
B(-2,3,2,STONE)
B(-2,3,3,STONE)
B(-2,4,-7,STONE)
B(-2,4,-6,STONE)
B(-2,4,-5,STONE)
B(-2,4,-4,STONE)
B(-2,4,-3,STONE)
B(-2,4,-2,STONE)
B(-2,4,-1,STONE)
B(-2,4,0,STONE)
B(-2,4,1,STONE)
B(-2,4,2,STONE)
B(-2,5,-7,STONE)
B(-2,5,-6,STONE)
B(-2,5,-5,STONE)
B(-2,5,-4,STONE)
B(-2,5,-3,STONE)
B(-2,5,-2,STONE)
B(-2,5,-1,STONE)
B(-2,5,0,STONE)
B(-2,5,1,DIRT)
B(-2,6,-7,STONE)
B(-2,6,-6,STONE)
B(-2,6,-5,STONE)
B(-2,6,-4,STONE)
B(-2,6,-3,STONE)
B(-2,6,-2,STONE)
B(-2,6,-1,STONE)
B(-2,6,0,STONE)
B(-2,6,1,STONE)
B(-2,7,-7,STONE)
B(-2,7,-6,STONE)
B(-2,7,-5,STONE)
B(-2,7,-4,STONE)
B(-2,7,-3,STONE)
B(-2,7,-2,STONE)
B(-2,7,-1,STONE)
B(-2,7,0,STONE)
B(-2,7,1,STONE)
B(-2,8,-7,STONE)
B(-2,8,-6,STONE)
B(-2,8,-5,STONE)
B(-2,8,-4,STONE)
B(-2,8,-3,STONE)
B(-2,8,-2,STONE)
B(-2,8,-1,STONE)
B(-2,8,0,STONE)
B(-2,8,1,STONE)
B(-2,9,-7,GRASS)
B(-2,9,-6,STONE)
B(-2,9,-5,STONE)
B(-2,9,-4,STONE)
B(-2,9,-3,STONE)
B(-2,9,-2,STONE)
B(-2,9,-1,DIRT)
B(-2,9,0,LEAVES:3)
B(-2,10,-6,DIRT)
B(-2,10,-5,STONE)
B(-2,10,-4,STONE)
B(-2,10,-3,STONE)
B(-2,10,-2,STONE)
B(-2,10,-1,STONE)
B(-2,10,0,LEAVES:3)
B(-2,11,-6,STONE)
B(-2,11,-5,STONE)
B(-2,11,-4,STONE)
B(-2,11,-3,DIRT)
B(-2,11,-2,STONE)
B(-2,12,-5,STONE)
B(-2,12,-4,STONE)
B(-2,12,-3,STONE)
B(-2,12,-2,STONE)
B(-2,13,-5,STONE)
B(-2,13,-4,STONE)
B(-2,13,-3,STONE)
B(-2,13,-2,STONE)
B(-2,14,-4,STONE)
B(-2,14,-3,STONE)
B(-2,16,-4,STONE)
B(-2,17,-4,STONE)
B(-2,18,-4,STONE)
B(-2,18,-3,STONE)
B(-2,19,-5,LEAVES:3)
B(-2,19,-4,STONE)
B(-2,19,-3,STONE)
B(-2,19,-2,STONE)
B(-2,20,-7,LEAVES:3)
B(-2,20,-6,LEAVES:3)
B(-2,20,-5,LEAVES:3)
B(-2,20,-4,GRASS)
B(-2,20,-3,STONE)
B(-2,20,-2,STONE)
B(-2,21,-7,LEAVES:3)
B(-2,21,-6,LEAVES:3)
B(-2,21,-5,LEAVES:3)
B(-2,21,-3,GRASS)
B(-1,-18,-5,STONE)
B(-1,-18,-4,STONE)
B(-1,-18,-3,STONE)
B(-1,-18,-2,STONE)
B(-1,-17,-5,STONE)
B(-1,-17,-4,STONE)
B(-1,-17,-3,STONE)
B(-1,-17,-2,STONE)
B(-1,-16,-6,STONE)
B(-1,-16,-5,STONE)
B(-1,-16,-4,STONE)
B(-1,-16,-3,STONE)
B(-1,-16,-2,STONE)
B(-1,-16,-1,STONE)
B(-1,-15,-6,STONE)
B(-1,-15,-5,STONE)
B(-1,-15,-4,STONE)
B(-1,-15,-3,STONE)
B(-1,-15,-2,STONE)
B(-1,-15,-1,STONE)
B(-1,-14,-6,STONE)
B(-1,-14,-5,STONE)
B(-1,-14,-4,STONE)
B(-1,-14,-3,STONE)
B(-1,-14,-2,STONE)
B(-1,-14,-1,STONE)
B(-1,-13,-6,STONE)
B(-1,-13,-5,STONE)
B(-1,-13,-4,STONE)
B(-1,-13,-3,STONE)
B(-1,-13,-2,STONE)
B(-1,-13,-1,STONE)
B(-1,-13,0,DIRT)
B(-1,-12,-6,STONE)
B(-1,-12,-5,STONE)
B(-1,-12,-4,STONE)
B(-1,-12,-3,STONE)
B(-1,-12,-2,STONE)
B(-1,-12,-1,STONE)
B(-1,-12,0,DIRT)
B(-1,-11,-6,STONE)
B(-1,-11,-5,STONE)
B(-1,-11,-4,STONE)
B(-1,-11,-3,STONE)
B(-1,-11,-2,STONE)
B(-1,-11,-1,STONE)
B(-1,-11,0,STONE)
B(-1,-11,1,STONE)
B(-1,-10,-7,STONE)
B(-1,-10,-6,STONE)
B(-1,-10,-5,STONE)
B(-1,-10,-4,STONE)
B(-1,-10,-3,STONE)
B(-1,-10,-2,STONE)
B(-1,-10,-1,STONE)
B(-1,-10,0,STONE)
B(-1,-10,1,STONE)
B(-1,-10,2,STONE)
B(-1,-9,-7,STONE)
B(-1,-9,-6,STONE)
B(-1,-9,-5,STONE)
B(-1,-9,-4,STONE)
B(-1,-9,-3,STONE)
B(-1,-9,-2,STONE)
B(-1,-9,-1,STONE)
B(-1,-9,0,STONE)
B(-1,-9,1,STONE)
B(-1,-9,2,DIRT)
B(-1,-8,-7,STONE)
B(-1,-8,-6,STONE)
B(-1,-8,-5,STONE)
B(-1,-8,-4,STONE)
B(-1,-8,-3,STONE)
B(-1,-8,-2,STONE)
B(-1,-8,-1,STONE)
B(-1,-8,0,STONE)
B(-1,-8,1,STONE)
B(-1,-8,2,STONE)
B(-1,-7,-7,STONE)
B(-1,-7,-6,STONE)
B(-1,-7,-5,STONE)
B(-1,-7,-4,STONE)
B(-1,-7,-3,STONE)
B(-1,-7,-2,STONE)
B(-1,-7,-1,STONE)
B(-1,-7,0,STONE)
B(-1,-7,1,STONE)
B(-1,-7,2,STONE)
B(-1,-6,-7,STONE)
B(-1,-6,-6,STONE)
B(-1,-6,-5,STONE)
B(-1,-6,-4,STONE)
B(-1,-6,-3,STONE)
B(-1,-6,-2,STONE)
B(-1,-6,-1,STONE)
B(-1,-6,0,STONE)
B(-1,-6,1,STONE)
B(-1,-6,2,STONE)
B(-1,-5,-7,STONE)
B(-1,-5,-6,STONE)
B(-1,-5,-5,STONE)
B(-1,-5,-4,STONE)
B(-1,-5,-3,STONE)
B(-1,-5,-2,STONE)
B(-1,-5,-1,STONE)
B(-1,-5,0,STONE)
B(-1,-5,1,STONE)
B(-1,-5,2,STONE)
B(-1,-5,3,STONE)
B(-1,-4,-8,STONE)
B(-1,-4,-7,STONE)
B(-1,-4,-6,STONE)
B(-1,-4,-5,STONE)
B(-1,-4,-4,STONE)
B(-1,-4,-3,STONE)
B(-1,-4,-2,STONE)
B(-1,-4,-1,STONE)
B(-1,-4,0,STONE)
B(-1,-4,1,STONE)
B(-1,-4,2,STONE)
B(-1,-4,3,STONE)
B(-1,-4,4,DIRT)
B(-1,-3,-8,STONE)
B(-1,-3,-7,STONE)
B(-1,-3,-6,STONE)
B(-1,-3,-5,STONE)
B(-1,-3,-4,STONE)
B(-1,-3,-3,STONE)
B(-1,-3,-2,STONE)
B(-1,-3,-1,STONE)
B(-1,-3,0,STONE)
B(-1,-3,1,STONE)
B(-1,-3,2,STONE)
B(-1,-3,3,STONE)
B(-1,-3,4,STONE)
B(-1,-3,5,STONE)
B(-1,-2,-9,STONE)
B(-1,-2,-8,STONE)
B(-1,-2,-7,STONE)
B(-1,-2,-6,STONE)
B(-1,-2,-5,STONE)
B(-1,-2,-4,STONE)
B(-1,-2,-3,STONE)
B(-1,-2,-2,STONE)
B(-1,-2,-1,STONE)
B(-1,-2,0,STONE)
B(-1,-2,1,STONE)
B(-1,-2,2,STONE)
B(-1,-2,3,STONE)
B(-1,-2,4,STONE)
B(-1,-2,5,STONE)
B(-1,-2,6,STONE)
B(-1,-1,-9,STONE)
B(-1,-1,-8,STONE)
B(-1,-1,-7,STONE)
B(-1,-1,-6,STONE)
B(-1,-1,-5,STONE)
B(-1,-1,-4,STONE)
B(-1,-1,-3,STONE)
B(-1,-1,-2,STONE)
B(-1,-1,-1,STONE)
B(-1,-1,0,STONE)
B(-1,-1,1,STONE)
B(-1,-1,2,STONE)
B(-1,-1,3,STONE)
B(-1,-1,4,STONE)
B(-1,-1,5,STONE)
B(-1,-1,6,STONE)
B(-1,0,-8,STONE)
B(-1,0,-7,STONE)
B(-1,0,-6,STONE)
B(-1,0,-5,STONE)
B(-1,0,-4,STONE)
B(-1,0,-3,STONE)
B(-1,0,-2,STONE)
B(-1,0,-1,STONE)
B(-1,0,0,STONE)
B(-1,0,1,STONE)
B(-1,0,2,STONE)
B(-1,0,3,STONE)
B(-1,0,4,STONE)
B(-1,0,5,STONE)
B(-1,1,-8,STONE)
B(-1,1,-7,STONE)
B(-1,1,-6,STONE)
B(-1,1,-5,STONE)
B(-1,1,-4,STONE)
B(-1,1,-3,STONE)
B(-1,1,-2,STONE)
B(-1,1,-1,STONE)
B(-1,1,0,STONE)
B(-1,1,1,STONE)
B(-1,1,2,STONE)
B(-1,1,3,STONE)
B(-1,1,4,GRASS)
B(-1,2,-8,STONE)
B(-1,2,-7,STONE)
B(-1,2,-6,STONE)
B(-1,2,-5,STONE)
B(-1,2,-4,STONE)
B(-1,2,-3,STONE)
B(-1,2,-2,STONE)
B(-1,2,-1,STONE)
B(-1,2,0,STONE)
B(-1,2,1,STONE)
B(-1,2,2,STONE)
B(-1,2,3,STONE)
B(-1,3,-8,STONE)
B(-1,3,-7,STONE)
B(-1,3,-6,STONE)
B(-1,3,-5,STONE)
B(-1,3,-4,STONE)
B(-1,3,-3,STONE)
B(-1,3,-2,STONE)
B(-1,3,-1,STONE)
B(-1,3,0,STONE)
B(-1,3,1,STONE)
B(-1,3,2,STONE)
B(-1,3,3,LEAVES:3)
B(-1,3,5,LEAVES:3)
B(-1,4,-8,STONE)
B(-1,4,-7,STONE)
B(-1,4,-6,STONE)
B(-1,4,-5,STONE)
B(-1,4,-4,STONE)
B(-1,4,-3,STONE)
B(-1,4,-2,STONE)
B(-1,4,-1,STONE)
B(-1,4,0,STONE)
B(-1,4,1,STONE)
B(-1,4,2,STONE)
B(-1,4,3,LEAVES:3)
B(-1,4,4,LEAVES:3)
B(-1,4,5,LEAVES:3)
B(-1,5,-8,STONE)
B(-1,5,-7,STONE)
B(-1,5,-6,STONE)
B(-1,5,-5,STONE)
B(-1,5,-4,STONE)
B(-1,5,-3,STONE)
B(-1,5,-2,STONE)
B(-1,5,-1,STONE)
B(-1,5,0,STONE)
B(-1,5,1,STONE)
B(-1,5,2,STONE)
B(-1,5,4,LEAVES:3)
B(-1,6,-8,STONE)
B(-1,6,-7,STONE)
B(-1,6,-6,STONE)
B(-1,6,-5,STONE)
B(-1,6,-4,STONE)
B(-1,6,-3,STONE)
B(-1,6,-2,STONE)
B(-1,6,-1,STONE)
B(-1,6,0,STONE)
B(-1,6,1,STONE)
B(-1,6,2,DIRT)
B(-1,6,4,LEAVES:3)
B(-1,7,-8,STONE)
B(-1,7,-7,STONE)
B(-1,7,-6,STONE)
B(-1,7,-5,STONE)
B(-1,7,-4,STONE)
B(-1,7,-3,STONE)
B(-1,7,-2,STONE)
B(-1,7,-1,STONE)
B(-1,7,0,STONE)
B(-1,7,1,STONE)
B(-1,7,2,STONE)
B(-1,8,-7,STONE)
B(-1,8,-6,STONE)
B(-1,8,-5,STONE)
B(-1,8,-4,STONE)
B(-1,8,-3,STONE)
B(-1,8,-2,STONE)
B(-1,8,-1,STONE)
B(-1,8,0,STONE)
B(-1,8,1,STONE)
B(-1,9,-7,STONE)
B(-1,9,-6,STONE)
B(-1,9,-5,STONE)
B(-1,9,-4,STONE)
B(-1,9,-3,STONE)
B(-1,9,-2,STONE)
B(-1,9,-1,STONE)
B(-1,9,0,DIRT)
B(-1,10,-7,DIRT)
B(-1,10,-6,STONE)
B(-1,10,-5,STONE)
B(-1,10,-4,STONE)
B(-1,10,-3,STONE)
B(-1,10,-2,STONE)
B(-1,10,-1,STONE)
B(-1,10,0,DIRT)
B(-1,11,-7,STONE)
B(-1,11,-6,STONE)
B(-1,11,-5,STONE)
B(-1,11,-4,STONE)
B(-1,11,-3,STONE)
B(-1,11,-2,STONE)
B(-1,11,-1,STONE)
B(-1,12,-6,STONE)
B(-1,12,-5,STONE)
B(-1,12,-4,STONE)
B(-1,12,-3,STONE)
B(-1,12,-2,STONE)
B(-1,12,-1,STONE)
B(-1,13,-6,STONE)
B(-1,13,-5,STONE)
B(-1,13,-4,STONE)
B(-1,13,-3,STONE)
B(-1,13,-2,STONE)
B(-1,13,-1,STONE)
B(-1,14,-5,STONE)
B(-1,14,-4,STONE)
B(-1,14,-3,STONE)
B(-1,14,-2,STONE)
B(-1,15,-5,STONE)
B(-1,15,-4,STONE)
B(-1,15,-3,STONE)
B(-1,15,-2,STONE)
B(-1,16,-5,STONE)
B(-1,16,-4,STONE)
B(-1,16,-3,STONE)
B(-1,16,-2,STONE)
B(-1,17,-4,STONE)
B(-1,17,-3,STONE)
B(-1,17,-2,STONE)
B(-1,18,-4,STONE)
B(-1,18,-3,STONE)
B(-1,18,-2,DIRT)
B(-1,19,-7,LEAVES:3)
B(-1,19,-6,STONE)
B(-1,19,-5,STONE)
B(-1,19,-4,STONE)
B(-1,19,-3,STONE)
B(-1,19,-2,STONE)
B(-1,20,-7,LEAVES:3)
B(-1,20,-6,DIRT)
B(-1,20,-5,GRASS)
B(-1,20,-4,STONE)
B(-1,20,-3,STONE)
B(-1,20,-2,DIRT)
B(-1,21,-7,LEAVES:3)
B(-1,21,-6,LOG:3)
B(-1,21,-5,LEAVES:3)
B(-1,21,-4,STONE)
B(-1,21,-3,STONE)
B(-1,21,-2,GRASS)
B(-1,21,-1,LEAVES:3)
B(-1,22,-6,LEAVES:3)
B(-1,22,-5,LEAVES:3)
B(-1,22,-4,STONE)
B(-1,22,-3,STONE)
B(-1,22,-2,LEAVES:3)
B(-1,22,-1,LEAVES:3)
B(-1,23,-4,STONE)
B(-1,23,-3,STONE)
B(0,-18,-5,STONE)
B(0,-18,-4,STONE)
B(0,-18,-3,STONE)
B(0,-18,-2,STONE)
B(0,-18,-1,STONE)
B(0,-17,-5,STONE)
B(0,-17,-4,STONE)
B(0,-17,-3,STONE)
B(0,-17,-2,STONE)
B(0,-17,-1,STONE)
B(0,-16,-6,STONE)
B(0,-16,-5,STONE)
B(0,-16,-4,STONE)
B(0,-16,-3,STONE)
B(0,-16,-2,STONE)
B(0,-16,-1,STONE)
B(0,-15,-6,STONE)
B(0,-15,-5,STONE)
B(0,-15,-4,STONE)
B(0,-15,-3,STONE)
B(0,-15,-2,STONE)
B(0,-15,-1,STONE)
B(0,-15,0,STONE)
B(0,-14,-7,STONE)
B(0,-14,-6,STONE)
B(0,-14,-5,STONE)
B(0,-14,-4,STONE)
B(0,-14,-3,STONE)
B(0,-14,-2,STONE)
B(0,-14,-1,STONE)
B(0,-14,0,STONE)
B(0,-13,-7,STONE)
B(0,-13,-6,STONE)
B(0,-13,-5,STONE)
B(0,-13,-4,STONE)
B(0,-13,-3,STONE)
B(0,-13,-2,STONE)
B(0,-13,-1,STONE)
B(0,-13,0,STONE)
B(0,-13,1,STONE)
B(0,-12,-7,STONE)
B(0,-12,-6,STONE)
B(0,-12,-5,STONE)
B(0,-12,-4,STONE)
B(0,-12,-3,STONE)
B(0,-12,-2,STONE)
B(0,-12,-1,STONE)
B(0,-12,0,STONE)
B(0,-12,1,STONE)
B(0,-11,-7,STONE)
B(0,-11,-6,STONE)
B(0,-11,-5,STONE)
B(0,-11,-4,STONE)
B(0,-11,-3,STONE)
B(0,-11,-2,STONE)
B(0,-11,-1,STONE)
B(0,-11,0,STONE)
B(0,-11,1,STONE)
B(0,-11,2,DIRT)
B(0,-10,-7,STONE)
B(0,-10,-6,STONE)
B(0,-10,-5,STONE)
B(0,-10,-4,STONE)
B(0,-10,-3,STONE)
B(0,-10,-2,STONE)
B(0,-10,-1,STONE)
B(0,-10,0,STONE)
B(0,-10,1,STONE)
B(0,-10,2,DIRT)
B(0,-9,-8,STONE)
B(0,-9,-7,STONE)
B(0,-9,-6,STONE)
B(0,-9,-5,STONE)
B(0,-9,-4,STONE)
B(0,-9,-3,STONE)
B(0,-9,-2,STONE)
B(0,-9,-1,STONE)
B(0,-9,0,STONE)
B(0,-9,1,STONE)
B(0,-9,2,DIRT)
B(0,-8,-8,STONE)
B(0,-8,-7,STONE)
B(0,-8,-6,STONE)
B(0,-8,-5,STONE)
B(0,-8,-4,STONE)
B(0,-8,-3,STONE)
B(0,-8,-2,STONE)
B(0,-8,-1,STONE)
B(0,-8,0,STONE)
B(0,-8,1,STONE)
B(0,-8,2,DIRT)
B(0,-7,-8,STONE)
B(0,-7,-7,STONE)
B(0,-7,-6,STONE)
B(0,-7,-5,STONE)
B(0,-7,-4,STONE)
B(0,-7,-3,STONE)
B(0,-7,-2,STONE)
B(0,-7,-1,STONE)
B(0,-7,0,STONE)
B(0,-7,1,STONE)
B(0,-7,2,STONE)
B(0,-6,-8,STONE)
B(0,-6,-7,STONE)
B(0,-6,-6,STONE)
B(0,-6,-5,STONE)
B(0,-6,-4,STONE)
B(0,-6,-3,STONE)
B(0,-6,-2,STONE)
B(0,-6,-1,STONE)
B(0,-6,0,STONE)
B(0,-6,1,STONE)
B(0,-6,2,STONE)
B(0,-6,3,DIRT)
B(0,-5,-8,STONE)
B(0,-5,-7,STONE)
B(0,-5,-6,STONE)
B(0,-5,-5,STONE)
B(0,-5,-4,STONE)
B(0,-5,-3,STONE)
B(0,-5,-2,STONE)
B(0,-5,-1,STONE)
B(0,-5,0,STONE)
B(0,-5,1,STONE)
B(0,-5,2,STONE)
B(0,-5,3,DIRT)
B(0,-5,4,DIRT)
B(0,-4,-9,STONE)
B(0,-4,-8,STONE)
B(0,-4,-7,STONE)
B(0,-4,-6,STONE)
B(0,-4,-5,STONE)
B(0,-4,-4,STONE)
B(0,-4,-3,STONE)
B(0,-4,-2,STONE)
B(0,-4,-1,STONE)
B(0,-4,0,STONE)
B(0,-4,1,STONE)
B(0,-4,2,STONE)
B(0,-4,3,STONE)
B(0,-4,4,DIRT)
B(0,-3,-9,STONE)
B(0,-3,-8,STONE)
B(0,-3,-7,STONE)
B(0,-3,-6,STONE)
B(0,-3,-5,STONE)
B(0,-3,-4,STONE)
B(0,-3,-3,STONE)
B(0,-3,-2,STONE)
B(0,-3,-1,STONE)
B(0,-3,0,STONE)
B(0,-3,1,STONE)
B(0,-3,2,STONE)
B(0,-3,3,STONE)
B(0,-3,4,STONE)
B(0,-2,-9,STONE)
B(0,-2,-8,STONE)
B(0,-2,-7,STONE)
B(0,-2,-6,STONE)
B(0,-2,-5,STONE)
B(0,-2,-4,STONE)
B(0,-2,-3,STONE)
B(0,-2,-2,STONE)
B(0,-2,-1,STONE)
B(0,-2,0,STONE)
B(0,-2,1,STONE)
B(0,-2,2,STONE)
B(0,-2,3,STONE)
B(0,-2,4,STONE)
B(0,-2,5,STONE)
B(0,-1,-9,STONE)
B(0,-1,-8,STONE)
B(0,-1,-7,STONE)
B(0,-1,-6,STONE)
B(0,-1,-5,STONE)
B(0,-1,-4,STONE)
B(0,-1,-3,STONE)
B(0,-1,-2,STONE)
B(0,-1,-1,STONE)
B(0,-1,0,STONE)
B(0,-1,1,STONE)
B(0,-1,2,STONE)
B(0,-1,3,STONE)
B(0,-1,4,STONE)
B(0,-1,5,STONE)
B(0,0,-9,STONE)
B(0,0,-8,STONE)
B(0,0,-7,STONE)
B(0,0,-6,STONE)
B(0,0,-5,STONE)
B(0,0,-4,STONE)
B(0,0,-3,STONE)
B(0,0,-2,STONE)
B(0,0,-1,STONE)
B(0,0,0,STONE)
B(0,0,1,STONE)
B(0,0,2,STONE)
B(0,0,3,STONE)
B(0,0,4,STONE)
B(0,1,-9,STONE)
B(0,1,-8,STONE)
B(0,1,-7,STONE)
B(0,1,-6,STONE)
B(0,1,-5,STONE)
B(0,1,-4,STONE)
B(0,1,-3,STONE)
B(0,1,-2,STONE)
B(0,1,-1,STONE)
B(0,1,0,STONE)
B(0,1,1,STONE)
B(0,1,2,STONE)
B(0,1,3,STONE)
B(0,1,4,DIRT)
B(0,2,-9,STONE)
B(0,2,-8,STONE)
B(0,2,-7,STONE)
B(0,2,-6,STONE)
B(0,2,-5,STONE)
B(0,2,-4,STONE)
B(0,2,-3,STONE)
B(0,2,-2,STONE)
B(0,2,-1,STONE)
B(0,2,0,STONE)
B(0,2,1,STONE)
B(0,2,2,STONE)
B(0,2,3,DIRT)
B(0,2,4,DIRT)
B(0,3,-8,STONE)
B(0,3,-7,STONE)
B(0,3,-6,STONE)
B(0,3,-5,STONE)
B(0,3,-4,STONE)
B(0,3,-3,STONE)
B(0,3,-2,STONE)
B(0,3,-1,STONE)
B(0,3,0,STONE)
B(0,3,1,STONE)
B(0,3,2,STONE)
B(0,3,3,GRASS)
B(0,3,4,LOG:3)
B(0,4,-8,STONE)
B(0,4,-7,STONE)
B(0,4,-6,STONE)
B(0,4,-5,STONE)
B(0,4,-4,STONE)
B(0,4,-3,STONE)
B(0,4,-2,STONE)
B(0,4,-1,STONE)
B(0,4,0,STONE)
B(0,4,1,STONE)
B(0,4,2,STONE)
B(0,4,3,LEAVES:3)
B(0,4,4,LOG:3)
B(0,4,5,LEAVES:3)
B(0,5,-8,STONE)
B(0,5,-7,STONE)
B(0,5,-6,STONE)
B(0,5,-5,STONE)
B(0,5,-4,STONE)
B(0,5,-3,STONE)
B(0,5,-2,STONE)
B(0,5,-1,STONE)
B(0,5,0,STONE)
B(0,5,1,STONE)
B(0,5,2,DIRT)
B(0,5,3,LEAVES:3)
B(0,5,4,LOG:3)
B(0,5,5,LEAVES:3)
B(0,6,-8,STONE)
B(0,6,-7,STONE)
B(0,6,-6,STONE)
B(0,6,-5,STONE)
B(0,6,-4,STONE)
B(0,6,-3,STONE)
B(0,6,-2,STONE)
B(0,6,-1,STONE)
B(0,6,0,STONE)
B(0,6,1,STONE)
B(0,6,2,DIRT)
B(0,6,3,LEAVES:3)
B(0,6,4,LEAVES:3)
B(0,6,5,LEAVES:3)
B(0,7,-8,STONE)
B(0,7,-7,STONE)
B(0,7,-6,STONE)
B(0,7,-5,STONE)
B(0,7,-4,STONE)
B(0,7,-3,STONE)
B(0,7,-2,STONE)
B(0,7,-1,STONE)
B(0,7,0,STONE)
B(0,7,1,STONE)
B(0,7,2,DIRT)
B(0,7,4,LEAVES:3)
B(0,8,-8,STONE)
B(0,8,-7,STONE)
B(0,8,-6,STONE)
B(0,8,-5,STONE)
B(0,8,-4,STONE)
B(0,8,-3,STONE)
B(0,8,-2,STONE)
B(0,8,-1,STONE)
B(0,8,0,STONE)
B(0,8,1,STONE)
B(0,8,2,GRASS)
B(0,9,-7,STONE)
B(0,9,-6,STONE)
B(0,9,-5,STONE)
B(0,9,-4,STONE)
B(0,9,-3,STONE)
B(0,9,-2,STONE)
B(0,9,-1,STONE)
B(0,9,0,STONE)
B(0,9,1,STONE)
B(0,10,-7,STONE)
B(0,10,-6,STONE)
B(0,10,-5,STONE)
B(0,10,-4,STONE)
B(0,10,-3,STONE)
B(0,10,-2,STONE)
B(0,10,-1,STONE)
B(0,10,0,STONE)
B(0,10,1,STONE)
B(0,11,-7,STONE)
B(0,11,-6,STONE)
B(0,11,-5,STONE)
B(0,11,-4,STONE)
B(0,11,-3,STONE)
B(0,11,-2,STONE)
B(0,11,-1,STONE)
B(0,11,0,STONE)
B(0,12,-7,STONE)
B(0,12,-6,STONE)
B(0,12,-5,STONE)
B(0,12,-4,STONE)
B(0,12,-3,STONE)
B(0,12,-2,STONE)
B(0,12,-1,STONE)
B(0,12,0,STONE)
B(0,13,-6,STONE)
B(0,13,-5,STONE)
B(0,13,-4,STONE)
B(0,13,-3,STONE)
B(0,13,-2,STONE)
B(0,13,-1,STONE)
B(0,14,-6,STONE)
B(0,14,-5,STONE)
B(0,14,-4,STONE)
B(0,14,-3,STONE)
B(0,14,-2,STONE)
B(0,14,-1,STONE)
B(0,15,-6,STONE)
B(0,15,-5,STONE)
B(0,15,-4,STONE)
B(0,15,-3,STONE)
B(0,15,-2,STONE)
B(0,15,-1,STONE)
B(0,16,-6,STONE)
B(0,16,-5,STONE)
B(0,16,-4,STONE)
B(0,16,-3,STONE)
B(0,16,-2,STONE)
B(0,16,-1,STONE)
B(0,17,-7,STONE)
B(0,17,-6,DIRT)
B(0,17,-5,STONE)
B(0,17,-4,STONE)
B(0,17,-3,STONE)
B(0,17,-2,STONE)
B(0,17,-1,DIRT)
B(0,18,-7,DIRT)
B(0,18,-6,STONE)
B(0,18,-5,STONE)
B(0,18,-4,STONE)
B(0,18,-3,STONE)
B(0,18,-2,STONE)
B(0,18,-1,DIRT)
B(0,19,-7,STONE)
B(0,19,-6,STONE)
B(0,19,-5,STONE)
B(0,19,-4,STONE)
B(0,19,-3,STONE)
B(0,19,-2,STONE)
B(0,19,-1,DIRT)
B(0,20,-7,GRASS)
B(0,20,-6,GRASS)
B(0,20,-5,STONE)
B(0,20,-4,STONE)
B(0,20,-3,STONE)
B(0,20,-2,STONE)
B(0,20,-1,DIRT)
B(0,21,-7,LEAVES:3)
B(0,21,-6,LEAVES:3)
B(0,21,-5,STONE)
B(0,21,-4,STONE)
B(0,21,-3,STONE)
B(0,21,-2,STONE)
B(0,21,-1,DIRT)
B(0,21,0,LEAVES:3)
B(0,22,-6,LEAVES:3)
B(0,22,-5,STONE)
B(0,22,-4,STONE)
B(0,22,-3,STONE)
B(0,22,-2,DIRT)
B(0,22,-1,LOG:3)
B(0,22,0,LEAVES:3)
B(0,23,-5,STONE)
B(0,23,-4,STONE)
B(0,23,-3,STONE)
B(0,23,-2,STONE)
B(0,23,-1,LEAVES:3)
B(0,24,-5,STONE)
B(0,24,-4,STONE)
B(0,24,-3,STONE)
B(0,25,-5,STONE)
B(0,25,-4,STONE)
B(0,25,-3,STONE)
B(0,26,-5,STONE)
B(0,26,-4,STONE)
B(0,27,-5,STONE)
B(0,27,-4,STONE)
B(0,28,-5,STONE)
B(0,28,-4,STONE)
B(0,29,-5,STONE)
B(0,29,-4,STONE)
B(1,-18,-5,STONE)
B(1,-18,-4,STONE)
B(1,-18,-3,STONE)
B(1,-18,-2,STONE)
B(1,-18,-1,STONE)
B(1,-18,0,STONE)
B(1,-17,-6,STONE)
B(1,-17,-5,STONE)
B(1,-17,-4,STONE)
B(1,-17,-3,STONE)
B(1,-17,-2,STONE)
B(1,-17,-1,STONE)
B(1,-17,0,STONE)
B(1,-16,-6,STONE)
B(1,-16,-5,STONE)
B(1,-16,-4,STONE)
B(1,-16,-3,STONE)
B(1,-16,-2,STONE)
B(1,-16,-1,STONE)
B(1,-16,0,STONE)
B(1,-15,-7,STONE)
B(1,-15,-6,STONE)
B(1,-15,-5,STONE)
B(1,-15,-4,STONE)
B(1,-15,-3,STONE)
B(1,-15,-2,STONE)
B(1,-15,-1,STONE)
B(1,-15,0,STONE)
B(1,-14,-7,STONE)
B(1,-14,-6,STONE)
B(1,-14,-5,STONE)
B(1,-14,-4,STONE)
B(1,-14,-3,STONE)
B(1,-14,-2,STONE)
B(1,-14,-1,STONE)
B(1,-14,0,STONE)
B(1,-13,-7,STONE)
B(1,-13,-6,STONE)
B(1,-13,-5,STONE)
B(1,-13,-4,STONE)
B(1,-13,-3,STONE)
B(1,-13,-2,STONE)
B(1,-13,-1,STONE)
B(1,-13,0,STONE)
B(1,-12,-8,STONE)
B(1,-12,-7,STONE)
B(1,-12,-6,STONE)
B(1,-12,-5,STONE)
B(1,-12,-4,STONE)
B(1,-12,-3,STONE)
B(1,-12,-2,STONE)
B(1,-12,-1,STONE)
B(1,-12,0,STONE)
B(1,-12,1,STONE)
B(1,-11,-8,STONE)
B(1,-11,-7,STONE)
B(1,-11,-6,STONE)
B(1,-11,-5,STONE)
B(1,-11,-4,STONE)
B(1,-11,-3,STONE)
B(1,-11,-2,STONE)
B(1,-11,-1,STONE)
B(1,-11,0,STONE)
B(1,-11,1,STONE)
B(1,-11,2,DIRT)
B(1,-10,-8,STONE)
B(1,-10,-7,STONE)
B(1,-10,-6,STONE)
B(1,-10,-5,STONE)
B(1,-10,-4,STONE)
B(1,-10,-3,STONE)
B(1,-10,-2,STONE)
B(1,-10,-1,STONE)
B(1,-10,0,STONE)
B(1,-10,1,STONE)
B(1,-10,2,DIRT)
B(1,-9,-8,STONE)
B(1,-9,-7,STONE)
B(1,-9,-6,STONE)
B(1,-9,-5,STONE)
B(1,-9,-4,STONE)
B(1,-9,-3,STONE)
B(1,-9,-2,STONE)
B(1,-9,-1,STONE)
B(1,-9,0,STONE)
B(1,-9,1,STONE)
B(1,-9,2,DIRT)
B(1,-8,-8,STONE)
B(1,-8,-7,STONE)
B(1,-8,-6,STONE)
B(1,-8,-5,STONE)
B(1,-8,-4,STONE)
B(1,-8,-3,STONE)
B(1,-8,-2,STONE)
B(1,-8,-1,STONE)
B(1,-8,0,STONE)
B(1,-8,1,STONE)
B(1,-8,2,STONE)
B(1,-7,-9,STONE)
B(1,-7,-8,STONE)
B(1,-7,-7,STONE)
B(1,-7,-6,STONE)
B(1,-7,-5,STONE)
B(1,-7,-4,STONE)
B(1,-7,-3,STONE)
B(1,-7,-2,STONE)
B(1,-7,-1,STONE)
B(1,-7,0,STONE)
B(1,-7,1,STONE)
B(1,-7,2,STONE)
B(1,-6,-9,STONE)
B(1,-6,-8,STONE)
B(1,-6,-7,STONE)
B(1,-6,-6,STONE)
B(1,-6,-5,STONE)
B(1,-6,-4,STONE)
B(1,-6,-3,STONE)
B(1,-6,-2,STONE)
B(1,-6,-1,STONE)
B(1,-6,0,STONE)
B(1,-6,1,STONE)
B(1,-6,2,STONE)
B(1,-6,3,DIRT)
B(1,-5,-9,STONE)
B(1,-5,-8,STONE)
B(1,-5,-7,STONE)
B(1,-5,-6,STONE)
B(1,-5,-5,STONE)
B(1,-5,-4,STONE)
B(1,-5,-3,STONE)
B(1,-5,-2,STONE)
B(1,-5,-1,STONE)
B(1,-5,0,STONE)
B(1,-5,1,STONE)
B(1,-5,2,STONE)
B(1,-5,3,DIRT)
B(1,-4,-10,STONE)
B(1,-4,-9,STONE)
B(1,-4,-8,STONE)
B(1,-4,-7,STONE)
B(1,-4,-6,STONE)
B(1,-4,-5,STONE)
B(1,-4,-4,STONE)
B(1,-4,-3,STONE)
B(1,-4,-2,STONE)
B(1,-4,-1,STONE)
B(1,-4,0,STONE)
B(1,-4,1,STONE)
B(1,-4,2,STONE)
B(1,-4,3,DIRT)
B(1,-4,4,DIRT)
B(1,-3,-10,STONE)
B(1,-3,-9,STONE)
B(1,-3,-8,STONE)
B(1,-3,-7,STONE)
B(1,-3,-6,STONE)
B(1,-3,-5,STONE)
B(1,-3,-4,STONE)
B(1,-3,-3,STONE)
B(1,-3,-2,STONE)
B(1,-3,-1,STONE)
B(1,-3,0,STONE)
B(1,-3,1,STONE)
B(1,-3,2,STONE)
B(1,-3,3,STONE)
B(1,-3,4,DIRT)
B(1,-2,-10,STONE)
B(1,-2,-9,STONE)
B(1,-2,-8,STONE)
B(1,-2,-7,STONE)
B(1,-2,-6,STONE)
B(1,-2,-5,STONE)
B(1,-2,-4,STONE)
B(1,-2,-3,STONE)
B(1,-2,-2,STONE)
B(1,-2,-1,STONE)
B(1,-2,0,STONE)
B(1,-2,1,STONE)
B(1,-2,2,STONE)
B(1,-2,3,STONE)
B(1,-2,4,STONE)
B(1,-2,5,STONE)
B(1,-1,-10,STONE)
B(1,-1,-9,STONE)
B(1,-1,-8,STONE)
B(1,-1,-7,STONE)
B(1,-1,-6,STONE)
B(1,-1,-5,STONE)
B(1,-1,-4,STONE)
B(1,-1,-3,STONE)
B(1,-1,-2,STONE)
B(1,-1,-1,STONE)
B(1,-1,0,STONE)
B(1,-1,1,STONE)
B(1,-1,2,STONE)
B(1,-1,3,STONE)
B(1,-1,4,STONE)
B(1,-1,5,STONE)
B(1,0,-10,STONE)
B(1,0,-9,STONE)
B(1,0,-8,STONE)
B(1,0,-7,STONE)
B(1,0,-6,STONE)
B(1,0,-5,STONE)
B(1,0,-4,STONE)
B(1,0,-3,STONE)
B(1,0,-2,STONE)
B(1,0,-1,STONE)
B(1,0,0,STONE)
B(1,0,1,STONE)
B(1,0,2,STONE)
B(1,0,3,STONE)
B(1,0,4,DIRT)
B(1,1,-9,STONE)
B(1,1,-8,STONE)
B(1,1,-7,STONE)
B(1,1,-6,STONE)
B(1,1,-5,STONE)
B(1,1,-4,STONE)
B(1,1,-3,STONE)
B(1,1,-2,STONE)
B(1,1,-1,STONE)
B(1,1,0,STONE)
B(1,1,1,STONE)
B(1,1,2,STONE)
B(1,1,3,DIRT)
B(1,1,4,GRASS)
B(1,2,-9,STONE)
B(1,2,-8,STONE)
B(1,2,-7,STONE)
B(1,2,-6,STONE)
B(1,2,-5,STONE)
B(1,2,-4,STONE)
B(1,2,-3,STONE)
B(1,2,-2,STONE)
B(1,2,-1,STONE)
B(1,2,0,STONE)
B(1,2,1,STONE)
B(1,2,2,STONE)
B(1,2,3,DIRT)
B(1,3,-8,STONE)
B(1,3,-7,STONE)
B(1,3,-6,STONE)
B(1,3,-5,STONE)
B(1,3,-4,STONE)
B(1,3,-3,STONE)
B(1,3,-2,STONE)
B(1,3,-1,STONE)
B(1,3,0,STONE)
B(1,3,1,STONE)
B(1,3,2,STONE)
B(1,3,3,GRASS)
B(1,3,5,LEAVES:3)
B(1,4,-8,STONE)
B(1,4,-7,STONE)
B(1,4,-6,STONE)
B(1,4,-5,STONE)
B(1,4,-4,STONE)
B(1,4,-3,STONE)
B(1,4,-2,STONE)
B(1,4,-1,STONE)
B(1,4,0,STONE)
B(1,4,1,STONE)
B(1,4,2,STONE)
B(1,4,3,LEAVES:3)
B(1,4,4,LEAVES:3)
B(1,4,5,LEAVES:3)
B(1,5,-8,STONE)
B(1,5,-7,STONE)
B(1,5,-6,STONE)
B(1,5,-5,STONE)
B(1,5,-4,STONE)
B(1,5,-3,STONE)
B(1,5,-2,STONE)
B(1,5,-1,STONE)
B(1,5,0,STONE)
B(1,5,1,STONE)
B(1,5,2,STONE)
B(1,5,4,LEAVES:3)
B(1,6,-8,STONE)
B(1,6,-7,STONE)
B(1,6,-6,STONE)
B(1,6,-5,STONE)
B(1,6,-4,STONE)
B(1,6,-3,STONE)
B(1,6,-2,STONE)
B(1,6,-1,STONE)
B(1,6,0,STONE)
B(1,6,1,STONE)
B(1,6,2,DIRT)
B(1,6,4,LEAVES:3)
B(1,7,-8,STONE)
B(1,7,-7,STONE)
B(1,7,-6,STONE)
B(1,7,-5,STONE)
B(1,7,-4,STONE)
B(1,7,-3,STONE)
B(1,7,-2,STONE)
B(1,7,-1,STONE)
B(1,7,0,STONE)
B(1,7,1,STONE)
B(1,7,2,DIRT)
B(1,8,-8,STONE)
B(1,8,-7,STONE)
B(1,8,-6,STONE)
B(1,8,-5,STONE)
B(1,8,-4,STONE)
B(1,8,-3,STONE)
B(1,8,-2,STONE)
B(1,8,-1,STONE)
B(1,8,0,STONE)
B(1,8,1,STONE)
B(1,8,2,GRASS)
B(1,8,3,LEAVES:3)
B(1,9,-7,STONE)
B(1,9,-6,STONE)
B(1,9,-5,STONE)
B(1,9,-4,STONE)
B(1,9,-3,STONE)
B(1,9,-2,STONE)
B(1,9,-1,STONE)
B(1,9,0,STONE)
B(1,9,1,STONE)
B(1,9,2,LEAVES:3)
B(1,9,3,LEAVES:3)
B(1,10,-7,STONE)
B(1,10,-6,STONE)
B(1,10,-5,STONE)
B(1,10,-4,STONE)
B(1,10,-3,STONE)
B(1,10,-2,STONE)
B(1,10,-1,STONE)
B(1,10,0,STONE)
B(1,10,2,LEAVES:3)
B(1,11,-7,STONE)
B(1,11,-6,STONE)
B(1,11,-5,STONE)
B(1,11,-4,STONE)
B(1,11,-3,STONE)
B(1,11,-2,STONE)
B(1,11,-1,STONE)
B(1,11,0,STONE)
B(1,12,-7,STONE)
B(1,12,-6,STONE)
B(1,12,-5,STONE)
B(1,12,-4,STONE)
B(1,12,-3,STONE)
B(1,12,-2,STONE)
B(1,12,-1,STONE)
B(1,12,0,STONE)
B(1,13,-7,STONE)
B(1,13,-6,STONE)
B(1,13,-5,STONE)
B(1,13,-4,STONE)
B(1,13,-3,STONE)
B(1,13,-2,STONE)
B(1,13,-1,STONE)
B(1,13,0,STONE)
B(1,14,-7,STONE)
B(1,14,-6,STONE)
B(1,14,-5,STONE)
B(1,14,-4,STONE)
B(1,14,-3,STONE)
B(1,14,-2,STONE)
B(1,14,-1,STONE)
B(1,14,0,STONE)
B(1,15,-7,STONE)
B(1,15,-6,STONE)
B(1,15,-5,STONE)
B(1,15,-4,STONE)
B(1,15,-3,STONE)
B(1,15,-2,STONE)
B(1,15,-1,STONE)
B(1,15,0,STONE)
B(1,16,-7,STONE)
B(1,16,-6,STONE)
B(1,16,-5,STONE)
B(1,16,-4,STONE)
B(1,16,-3,STONE)
B(1,16,-2,STONE)
B(1,16,-1,STONE)
B(1,16,0,STONE)
B(1,17,-7,STONE)
B(1,17,-6,STONE)
B(1,17,-5,STONE)
B(1,17,-4,STONE)
B(1,17,-3,STONE)
B(1,17,-2,STONE)
B(1,17,-1,STONE)
B(1,17,0,STONE)
B(1,18,-8,STONE)
B(1,18,-7,STONE)
B(1,18,-6,STONE)
B(1,18,-5,STONE)
B(1,18,-4,STONE)
B(1,18,-3,STONE)
B(1,18,-2,STONE)
B(1,18,-1,STONE)
B(1,18,0,DIRT)
B(1,19,-8,STONE)
B(1,19,-7,STONE)
B(1,19,-6,STONE)
B(1,19,-5,STONE)
B(1,19,-4,STONE)
B(1,19,-3,STONE)
B(1,19,-2,STONE)
B(1,19,-1,STONE)
B(1,19,0,DIRT)
B(1,20,-8,STONE)
B(1,20,-7,GRASS)
B(1,20,-6,STONE)
B(1,20,-5,STONE)
B(1,20,-4,STONE)
B(1,20,-3,STONE)
B(1,20,-2,STONE)
B(1,20,-1,STONE)
B(1,20,0,GRASS)
B(1,21,-8,STONE)
B(1,21,-6,STONE)
B(1,21,-5,STONE)
B(1,21,-4,STONE)
B(1,21,-3,STONE)
B(1,21,-2,STONE)
B(1,21,-1,DIRT)
B(1,22,-6,STONE)
B(1,22,-5,STONE)
B(1,22,-4,STONE)
B(1,22,-3,STONE)
B(1,22,-2,STONE)
B(1,22,-1,STONE)
B(1,23,-6,STONE)
B(1,23,-5,STONE)
B(1,23,-4,STONE)
B(1,23,-3,STONE)
B(1,23,-2,STONE)
B(1,23,-1,STONE)
B(1,24,-6,STONE)
B(1,24,-5,STONE)
B(1,24,-4,STONE)
B(1,24,-3,STONE)
B(1,24,-2,STONE)
B(1,25,-6,STONE)
B(1,25,-5,STONE)
B(1,25,-4,STONE)
B(1,25,-3,STONE)
B(1,26,-6,STONE)
B(1,26,-5,STONE)
B(1,26,-4,STONE)
B(1,26,-3,STONE)
B(1,27,-6,STONE)
B(1,27,-5,STONE)
B(1,27,-4,STONE)
B(1,27,-3,STONE)
B(1,28,-6,STONE)
B(1,28,-5,STONE)
B(1,28,-4,STONE)
B(1,29,-5,STONE)
B(1,29,-4,STONE)
B(1,30,-5,STONE)
B(1,30,-4,STONE)
B(1,31,-5,STONE)
B(1,31,-4,STONE)
B(2,-18,-5,STONE)
B(2,-18,-4,STONE)
B(2,-18,-3,STONE)
B(2,-18,-2,STONE)
B(2,-18,-1,STONE)
B(2,-18,0,STONE)
B(2,-17,-6,STONE)
B(2,-17,-5,STONE)
B(2,-17,-4,STONE)
B(2,-17,-3,STONE)
B(2,-17,-2,STONE)
B(2,-17,-1,STONE)
B(2,-17,0,STONE)
B(2,-16,-6,STONE)
B(2,-16,-5,STONE)
B(2,-16,-4,STONE)
B(2,-16,-3,STONE)
B(2,-16,-2,STONE)
B(2,-16,-1,STONE)
B(2,-16,0,STONE)
B(2,-15,-6,STONE)
B(2,-15,-5,STONE)
B(2,-15,-4,STONE)
B(2,-15,-3,STONE)
B(2,-15,-2,STONE)
B(2,-15,-1,STONE)
B(2,-15,0,STONE)
B(2,-14,-7,STONE)
B(2,-14,-6,STONE)
B(2,-14,-5,STONE)
B(2,-14,-4,STONE)
B(2,-14,-3,STONE)
B(2,-14,-2,STONE)
B(2,-14,-1,STONE)
B(2,-14,0,STONE)
B(2,-13,-7,STONE)
B(2,-13,-6,STONE)
B(2,-13,-5,STONE)
B(2,-13,-4,STONE)
B(2,-13,-3,STONE)
B(2,-13,-2,STONE)
B(2,-13,-1,STONE)
B(2,-13,0,STONE)
B(2,-12,-7,STONE)
B(2,-12,-6,STONE)
B(2,-12,-5,STONE)
B(2,-12,-4,STONE)
B(2,-12,-3,STONE)
B(2,-12,-2,STONE)
B(2,-12,-1,STONE)
B(2,-12,0,STONE)
B(2,-11,-7,STONE)
B(2,-11,-6,STONE)
B(2,-11,-5,STONE)
B(2,-11,-4,STONE)
B(2,-11,-3,STONE)
B(2,-11,-2,STONE)
B(2,-11,-1,STONE)
B(2,-11,0,STONE)
B(2,-11,1,STONE)
B(2,-11,2,DIRT)
B(2,-10,-7,STONE)
B(2,-10,-6,STONE)
B(2,-10,-5,STONE)
B(2,-10,-4,STONE)
B(2,-10,-3,STONE)
B(2,-10,-2,STONE)
B(2,-10,-1,STONE)
B(2,-10,0,STONE)
B(2,-10,1,STONE)
B(2,-10,2,DIRT)
B(2,-9,-7,STONE)
B(2,-9,-6,STONE)
B(2,-9,-5,STONE)
B(2,-9,-4,STONE)
B(2,-9,-3,STONE)
B(2,-9,-2,STONE)
B(2,-9,-1,STONE)
B(2,-9,0,STONE)
B(2,-9,1,STONE)
B(2,-9,2,STONE)
B(2,-8,-8,STONE)
B(2,-8,-7,STONE)
B(2,-8,-6,STONE)
B(2,-8,-5,STONE)
B(2,-8,-4,STONE)
B(2,-8,-3,STONE)
B(2,-8,-2,STONE)
B(2,-8,-1,STONE)
B(2,-8,0,STONE)
B(2,-8,1,STONE)
B(2,-8,2,STONE)
B(2,-7,-8,STONE)
B(2,-7,-7,STONE)
B(2,-7,-6,STONE)
B(2,-7,-5,STONE)
B(2,-7,-4,STONE)
B(2,-7,-3,STONE)
B(2,-7,-2,STONE)
B(2,-7,-1,STONE)
B(2,-7,0,STONE)
B(2,-7,1,STONE)
B(2,-7,2,STONE)
B(2,-6,-9,STONE)
B(2,-6,-8,STONE)
B(2,-6,-7,STONE)
B(2,-6,-6,STONE)
B(2,-6,-5,STONE)
B(2,-6,-4,STONE)
B(2,-6,-3,STONE)
B(2,-6,-2,STONE)
B(2,-6,-1,STONE)
B(2,-6,0,STONE)
B(2,-6,1,STONE)
B(2,-6,2,STONE)
B(2,-6,3,DIRT)
B(2,-5,-9,STONE)
B(2,-5,-8,STONE)
B(2,-5,-7,STONE)
B(2,-5,-6,STONE)
B(2,-5,-5,STONE)
B(2,-5,-4,STONE)
B(2,-5,-3,STONE)
B(2,-5,-2,STONE)
B(2,-5,-1,STONE)
B(2,-5,0,STONE)
B(2,-5,1,STONE)
B(2,-5,2,STONE)
B(2,-5,3,DIRT)
B(2,-4,-9,STONE)
B(2,-4,-8,STONE)
B(2,-4,-7,STONE)
B(2,-4,-6,STONE)
B(2,-4,-5,STONE)
B(2,-4,-4,STONE)
B(2,-4,-3,STONE)
B(2,-4,-2,STONE)
B(2,-4,-1,STONE)
B(2,-4,0,STONE)
B(2,-4,1,STONE)
B(2,-4,2,STONE)
B(2,-4,3,STONE)
B(2,-4,4,DIRT)
B(2,-3,-10,STONE)
B(2,-3,-9,STONE)
B(2,-3,-8,STONE)
B(2,-3,-7,STONE)
B(2,-3,-6,STONE)
B(2,-3,-5,STONE)
B(2,-3,-4,STONE)
B(2,-3,-3,STONE)
B(2,-3,-2,STONE)
B(2,-3,-1,STONE)
B(2,-3,0,STONE)
B(2,-3,1,STONE)
B(2,-3,2,STONE)
B(2,-3,3,STONE)
B(2,-3,4,DIRT)
B(2,-2,-10,STONE)
B(2,-2,-9,STONE)
B(2,-2,-8,STONE)
B(2,-2,-7,STONE)
B(2,-2,-6,STONE)
B(2,-2,-5,STONE)
B(2,-2,-4,STONE)
B(2,-2,-3,STONE)
B(2,-2,-2,STONE)
B(2,-2,-1,STONE)
B(2,-2,0,STONE)
B(2,-2,1,STONE)
B(2,-2,2,STONE)
B(2,-2,3,STONE)
B(2,-2,4,STONE)
B(2,-2,5,STONE)
B(2,-1,-10,STONE)
B(2,-1,-9,STONE)
B(2,-1,-8,STONE)
B(2,-1,-7,STONE)
B(2,-1,-6,STONE)
B(2,-1,-5,STONE)
B(2,-1,-4,STONE)
B(2,-1,-3,STONE)
B(2,-1,-2,STONE)
B(2,-1,-1,STONE)
B(2,-1,0,STONE)
B(2,-1,1,STONE)
B(2,-1,2,STONE)
B(2,-1,3,STONE)
B(2,-1,4,STONE)
B(2,-1,5,STONE)
B(2,0,-10,STONE)
B(2,0,-9,STONE)
B(2,0,-8,STONE)
B(2,0,-7,STONE)
B(2,0,-6,STONE)
B(2,0,-5,STONE)
B(2,0,-4,STONE)
B(2,0,-3,STONE)
B(2,0,-2,STONE)
B(2,0,-1,STONE)
B(2,0,0,STONE)
B(2,0,1,STONE)
B(2,0,2,STONE)
B(2,0,3,STONE)
B(2,0,4,DIRT)
B(2,1,-9,STONE)
B(2,1,-8,STONE)
B(2,1,-7,STONE)
B(2,1,-6,STONE)
B(2,1,-5,STONE)
B(2,1,-4,STONE)
B(2,1,-3,STONE)
B(2,1,-2,STONE)
B(2,1,-1,STONE)
B(2,1,0,STONE)
B(2,1,1,STONE)
B(2,1,2,STONE)
B(2,1,3,STONE)
B(2,1,4,GRASS)
B(2,2,-9,STONE)
B(2,2,-8,STONE)
B(2,2,-7,STONE)
B(2,2,-6,STONE)
B(2,2,-5,STONE)
B(2,2,-4,STONE)
B(2,2,-3,STONE)
B(2,2,-2,STONE)
B(2,2,-1,STONE)
B(2,2,0,STONE)
B(2,2,1,STONE)
B(2,2,2,STONE)
B(2,2,3,DIRT)
B(2,3,-8,STONE)
B(2,3,-7,STONE)
B(2,3,-6,STONE)
B(2,3,-5,STONE)
B(2,3,-4,STONE)
B(2,3,-3,STONE)
B(2,3,-2,STONE)
B(2,3,-1,STONE)
B(2,3,0,STONE)
B(2,3,1,STONE)
B(2,3,2,STONE)
B(2,3,3,GRASS)
B(2,4,-8,STONE)
B(2,4,-7,STONE)
B(2,4,-6,STONE)
B(2,4,-5,STONE)
B(2,4,-4,STONE)
B(2,4,-3,STONE)
B(2,4,-2,STONE)
B(2,4,-1,STONE)
B(2,4,0,STONE)
B(2,4,1,STONE)
B(2,4,2,STONE)
B(2,5,-8,STONE)
B(2,5,-7,STONE)
B(2,5,-6,STONE)
B(2,5,-5,STONE)
B(2,5,-4,STONE)
B(2,5,-3,STONE)
B(2,5,-2,STONE)
B(2,5,-1,STONE)
B(2,5,0,STONE)
B(2,5,1,STONE)
B(2,5,2,STONE)
B(2,6,-8,STONE)
B(2,6,-7,STONE)
B(2,6,-6,STONE)
B(2,6,-5,STONE)
B(2,6,-4,STONE)
B(2,6,-3,STONE)
B(2,6,-2,STONE)
B(2,6,-1,STONE)
B(2,6,0,STONE)
B(2,6,1,STONE)
B(2,6,2,STONE)
B(2,7,-8,STONE)
B(2,7,-7,STONE)
B(2,7,-6,STONE)
B(2,7,-5,STONE)
B(2,7,-4,STONE)
B(2,7,-3,STONE)
B(2,7,-2,STONE)
B(2,7,-1,STONE)
B(2,7,0,STONE)
B(2,7,1,STONE)
B(2,7,2,DIRT)
B(2,8,-8,STONE)
B(2,8,-7,STONE)
B(2,8,-6,STONE)
B(2,8,-5,STONE)
B(2,8,-4,STONE)
B(2,8,-3,STONE)
B(2,8,-2,STONE)
B(2,8,-1,STONE)
B(2,8,0,STONE)
B(2,8,1,STONE)
B(2,8,2,DIRT)
B(2,9,-7,STONE)
B(2,9,-6,STONE)
B(2,9,-5,STONE)
B(2,9,-4,STONE)
B(2,9,-3,STONE)
B(2,9,-2,STONE)
B(2,9,-1,STONE)
B(2,9,0,STONE)
B(2,9,1,LEAVES:3)
B(2,9,2,LOG:3)
B(2,9,3,LEAVES:3)
B(2,10,-7,STONE)
B(2,10,-6,STONE)
B(2,10,-5,STONE)
B(2,10,-4,STONE)
B(2,10,-3,STONE)
B(2,10,-2,STONE)
B(2,10,-1,STONE)
B(2,10,0,STONE)
B(2,10,1,LEAVES:3)
B(2,10,2,LOG:3)
B(2,10,3,LEAVES:3)
B(2,11,-7,STONE)
B(2,11,-6,STONE)
B(2,11,-5,STONE)
B(2,11,-4,STONE)
B(2,11,-3,STONE)
B(2,11,-2,STONE)
B(2,11,-1,STONE)
B(2,11,0,STONE)
B(2,11,2,LEAVES:3)
B(2,12,-7,STONE)
B(2,12,-6,STONE)
B(2,12,-5,STONE)
B(2,12,-4,STONE)
B(2,12,-3,STONE)
B(2,12,-2,STONE)
B(2,12,-1,STONE)
B(2,12,0,STONE)
B(2,13,-7,STONE)
B(2,13,-6,STONE)
B(2,13,-5,STONE)
B(2,13,-4,STONE)
B(2,13,-3,STONE)
B(2,13,-2,STONE)
B(2,13,-1,STONE)
B(2,13,0,STONE)
B(2,14,-7,STONE)
B(2,14,-6,STONE)
B(2,14,-5,STONE)
B(2,14,-4,STONE)
B(2,14,-3,STONE)
B(2,14,-2,STONE)
B(2,14,-1,STONE)
B(2,14,0,STONE)
B(2,15,-6,STONE)
B(2,15,-5,STONE)
B(2,15,-4,STONE)
B(2,15,-3,STONE)
B(2,15,-2,STONE)
B(2,15,-1,STONE)
B(2,15,0,STONE)
B(2,16,-7,STONE)
B(2,16,-6,STONE)
B(2,16,-5,STONE)
B(2,16,-4,STONE)
B(2,16,-3,STONE)
B(2,16,-2,STONE)
B(2,16,-1,STONE)
B(2,16,0,STONE)
B(2,17,-7,STONE)
B(2,17,-6,STONE)
B(2,17,-5,STONE)
B(2,17,-4,STONE)
B(2,17,-3,STONE)
B(2,17,-2,STONE)
B(2,17,-1,STONE)
B(2,17,0,STONE)
B(2,18,-7,DIRT)
B(2,18,-6,STONE)
B(2,18,-5,STONE)
B(2,18,-4,STONE)
B(2,18,-3,STONE)
B(2,18,-2,STONE)
B(2,18,-1,STONE)
B(2,18,0,DIRT)
B(2,18,1,STONE)
B(2,19,-8,STONE)
B(2,19,-7,STONE)
B(2,19,-6,STONE)
B(2,19,-5,STONE)
B(2,19,-4,STONE)
B(2,19,-3,STONE)
B(2,19,-2,STONE)
B(2,19,-1,STONE)
B(2,19,0,DIRT)
B(2,19,1,DIRT)
B(2,20,-8,STONE)
B(2,20,-7,GRASS)
B(2,20,-6,STONE)
B(2,20,-5,STONE)
B(2,20,-4,STONE)
B(2,20,-3,STONE)
B(2,20,-2,STONE)
B(2,20,-1,STONE)
B(2,20,0,GRASS)
B(2,20,1,GRASS)
B(2,21,-7,LEAVES:3)
B(2,21,-6,STONE)
B(2,21,-5,STONE)
B(2,21,-4,STONE)
B(2,21,-3,STONE)
B(2,21,-2,STONE)
B(2,21,-1,DIRT)
B(2,22,-7,LEAVES:3)
B(2,22,-6,STONE)
B(2,22,-5,STONE)
B(2,22,-4,STONE)
B(2,22,-3,STONE)
B(2,22,-2,STONE)
B(2,22,-1,STONE)
B(2,22,0,LEAVES:3)
B(2,22,1,LEAVES:3)
B(2,22,2,LEAVES:3)
B(2,23,-6,STONE)
B(2,23,-5,STONE)
B(2,23,-4,STONE)
B(2,23,-3,STONE)
B(2,23,-2,STONE)
B(2,23,-1,STONE)
B(2,23,1,LEAVES:3)
B(2,24,-6,STONE)
B(2,24,-5,STONE)
B(2,24,-4,STONE)
B(2,24,-3,STONE)
B(2,24,-2,STONE)
B(2,25,-6,STONE)
B(2,25,-5,STONE)
B(2,25,-4,STONE)
B(2,25,-3,STONE)
B(2,26,-6,STONE)
B(2,26,-5,STONE)
B(2,26,-4,STONE)
B(2,26,-3,STONE)
B(2,27,-6,STONE)
B(2,27,-5,STONE)
B(2,27,-4,STONE)
B(2,27,-3,STONE)
B(2,28,-6,STONE)
B(2,28,-5,STONE)
B(2,28,-4,STONE)
B(2,29,-5,STONE)
B(2,29,-4,STONE)
B(2,30,-5,STONE)
B(2,30,-4,STONE)
B(2,31,-5,STONE)
B(2,31,-4,STONE)
B(3,-18,-5,STONE)
B(3,-18,-4,STONE)
B(3,-18,-3,STONE)
B(3,-18,-2,STONE)
B(3,-18,-1,STONE)
B(3,-18,0,STONE)
B(3,-17,-5,STONE)
B(3,-17,-4,STONE)
B(3,-17,-3,STONE)
B(3,-17,-2,STONE)
B(3,-17,-1,STONE)
B(3,-16,-6,STONE)
B(3,-16,-5,STONE)
B(3,-16,-4,STONE)
B(3,-16,-3,STONE)
B(3,-16,-2,STONE)
B(3,-16,-1,STONE)
B(3,-15,-6,STONE)
B(3,-15,-5,STONE)
B(3,-15,-4,STONE)
B(3,-15,-3,STONE)
B(3,-15,-2,STONE)
B(3,-15,-1,STONE)
B(3,-15,0,STONE)
B(3,-14,-6,STONE)
B(3,-14,-5,STONE)
B(3,-14,-4,STONE)
B(3,-14,-3,STONE)
B(3,-14,-2,STONE)
B(3,-14,-1,STONE)
B(3,-14,0,STONE)
B(3,-13,-6,STONE)
B(3,-13,-5,STONE)
B(3,-13,-4,STONE)
B(3,-13,-3,STONE)
B(3,-13,-2,STONE)
B(3,-13,-1,STONE)
B(3,-13,0,STONE)
B(3,-12,-6,STONE)
B(3,-12,-5,STONE)
B(3,-12,-4,STONE)
B(3,-12,-3,STONE)
B(3,-12,-2,STONE)
B(3,-12,-1,STONE)
B(3,-12,0,DIRT)
B(3,-11,-6,STONE)
B(3,-11,-5,STONE)
B(3,-11,-4,STONE)
B(3,-11,-3,STONE)
B(3,-11,-2,STONE)
B(3,-11,-1,STONE)
B(3,-11,0,STONE)
B(3,-11,1,DIRT)
B(3,-10,-6,STONE)
B(3,-10,-5,STONE)
B(3,-10,-4,STONE)
B(3,-10,-3,STONE)
B(3,-10,-2,STONE)
B(3,-10,-1,STONE)
B(3,-10,0,STONE)
B(3,-10,1,DIRT)
B(3,-9,-7,STONE)
B(3,-9,-6,STONE)
B(3,-9,-5,STONE)
B(3,-9,-4,STONE)
B(3,-9,-3,STONE)
B(3,-9,-2,STONE)
B(3,-9,-1,STONE)
B(3,-9,0,STONE)
B(3,-9,1,DIRT)
B(3,-8,-7,STONE)
B(3,-8,-6,STONE)
B(3,-8,-5,STONE)
B(3,-8,-4,STONE)
B(3,-8,-3,STONE)
B(3,-8,-2,STONE)
B(3,-8,-1,STONE)
B(3,-8,0,STONE)
B(3,-8,1,STONE)
B(3,-7,-7,STONE)
B(3,-7,-6,STONE)
B(3,-7,-5,STONE)
B(3,-7,-4,STONE)
B(3,-7,-3,STONE)
B(3,-7,-2,STONE)
B(3,-7,-1,STONE)
B(3,-7,0,STONE)
B(3,-7,1,STONE)
B(3,-7,2,STONE)
B(3,-6,-8,STONE)
B(3,-6,-7,STONE)
B(3,-6,-6,STONE)
B(3,-6,-5,STONE)
B(3,-6,-4,STONE)
B(3,-6,-3,STONE)
B(3,-6,-2,STONE)
B(3,-6,-1,STONE)
B(3,-6,0,STONE)
B(3,-6,1,STONE)
B(3,-6,2,STONE)
B(3,-5,-9,STONE)
B(3,-5,-8,STONE)
B(3,-5,-7,STONE)
B(3,-5,-6,STONE)
B(3,-5,-5,STONE)
B(3,-5,-4,STONE)
B(3,-5,-3,STONE)
B(3,-5,-2,STONE)
B(3,-5,-1,STONE)
B(3,-5,0,STONE)
B(3,-5,1,STONE)
B(3,-5,2,STONE)
B(3,-4,-9,STONE)
B(3,-4,-8,STONE)
B(3,-4,-7,STONE)
B(3,-4,-6,STONE)
B(3,-4,-5,STONE)
B(3,-4,-4,STONE)
B(3,-4,-3,STONE)
B(3,-4,-2,STONE)
B(3,-4,-1,STONE)
B(3,-4,0,STONE)
B(3,-4,1,STONE)
B(3,-4,2,STONE)
B(3,-4,3,DIRT)
B(3,-3,-9,STONE)
B(3,-3,-8,STONE)
B(3,-3,-7,STONE)
B(3,-3,-6,STONE)
B(3,-3,-5,STONE)
B(3,-3,-4,STONE)
B(3,-3,-3,STONE)
B(3,-3,-2,STONE)
B(3,-3,-1,STONE)
B(3,-3,0,STONE)
B(3,-3,1,STONE)
B(3,-3,2,STONE)
B(3,-3,3,STONE)
B(3,-2,-10,STONE)
B(3,-2,-9,STONE)
B(3,-2,-8,STONE)
B(3,-2,-7,STONE)
B(3,-2,-6,STONE)
B(3,-2,-5,STONE)
B(3,-2,-4,STONE)
B(3,-2,-3,STONE)
B(3,-2,-2,STONE)
B(3,-2,-1,STONE)
B(3,-2,0,STONE)
B(3,-2,1,STONE)
B(3,-2,2,STONE)
B(3,-2,3,STONE)
B(3,-2,4,STONE)
B(3,-1,-10,STONE)
B(3,-1,-9,STONE)
B(3,-1,-8,STONE)
B(3,-1,-7,STONE)
B(3,-1,-6,STONE)
B(3,-1,-5,STONE)
B(3,-1,-4,STONE)
B(3,-1,-3,STONE)
B(3,-1,-2,STONE)
B(3,-1,-1,STONE)
B(3,-1,0,STONE)
B(3,-1,1,STONE)
B(3,-1,2,STONE)
B(3,-1,3,STONE)
B(3,-1,4,STONE)
B(3,0,-10,STONE)
B(3,0,-9,STONE)
B(3,0,-8,STONE)
B(3,0,-7,STONE)
B(3,0,-6,STONE)
B(3,0,-5,STONE)
B(3,0,-4,STONE)
B(3,0,-3,STONE)
B(3,0,-2,STONE)
B(3,0,-1,STONE)
B(3,0,0,STONE)
B(3,0,1,STONE)
B(3,0,2,STONE)
B(3,0,3,STONE)
B(3,1,-9,STONE)
B(3,1,-8,STONE)
B(3,1,-7,STONE)
B(3,1,-6,STONE)
B(3,1,-5,STONE)
B(3,1,-4,STONE)
B(3,1,-3,STONE)
B(3,1,-2,STONE)
B(3,1,-1,STONE)
B(3,1,0,STONE)
B(3,1,1,STONE)
B(3,1,2,STONE)
B(3,1,3,GRASS)
B(3,2,-8,STONE)
B(3,2,-7,STONE)
B(3,2,-6,STONE)
B(3,2,-5,STONE)
B(3,2,-4,STONE)
B(3,2,-3,STONE)
B(3,2,-2,STONE)
B(3,2,-1,STONE)
B(3,2,0,STONE)
B(3,2,1,STONE)
B(3,2,2,STONE)
B(3,3,-8,STONE)
B(3,3,-7,STONE)
B(3,3,-6,STONE)
B(3,3,-5,STONE)
B(3,3,-4,STONE)
B(3,3,-3,STONE)
B(3,3,-2,STONE)
B(3,3,-1,STONE)
B(3,3,0,STONE)
B(3,3,1,STONE)
B(3,3,2,STONE)
B(3,3,6,LEAVES:3)
B(3,4,-8,STONE)
B(3,4,-7,STONE)
B(3,4,-6,STONE)
B(3,4,-5,STONE)
B(3,4,-4,STONE)
B(3,4,-3,STONE)
B(3,4,-2,STONE)
B(3,4,-1,STONE)
B(3,4,0,STONE)
B(3,4,1,STONE)
B(3,4,2,STONE)
B(3,4,3,LEAVES:3)
B(3,4,4,LEAVES:3)
B(3,4,5,LEAVES:3)
B(3,4,6,LEAVES:3)
B(3,5,-8,STONE)
B(3,5,-7,STONE)
B(3,5,-6,STONE)
B(3,5,-5,STONE)
B(3,5,-4,STONE)
B(3,5,-3,STONE)
B(3,5,-2,STONE)
B(3,5,-1,STONE)
B(3,5,0,STONE)
B(3,5,1,STONE)
B(3,6,-8,STONE)
B(3,6,-7,STONE)
B(3,6,-6,STONE)
B(3,6,-5,STONE)
B(3,6,-4,STONE)
B(3,6,-3,STONE)
B(3,6,-2,STONE)
B(3,6,-1,STONE)
B(3,6,0,STONE)
B(3,6,1,DIRT)
B(3,7,-7,STONE)
B(3,7,-6,STONE)
B(3,7,-5,STONE)
B(3,7,-4,STONE)
B(3,7,-3,STONE)
B(3,7,-2,STONE)
B(3,7,-1,STONE)
B(3,7,0,STONE)
B(3,7,1,DIRT)
B(3,8,-7,STONE)
B(3,8,-6,STONE)
B(3,8,-5,STONE)
B(3,8,-4,STONE)
B(3,8,-3,STONE)
B(3,8,-2,STONE)
B(3,8,-1,STONE)
B(3,8,0,STONE)
B(3,8,1,GRASS)
B(3,8,3,LEAVES:3)
B(3,9,-7,STONE)
B(3,9,-6,STONE)
B(3,9,-5,STONE)
B(3,9,-4,STONE)
B(3,9,-3,STONE)
B(3,9,-2,STONE)
B(3,9,-1,STONE)
B(3,9,0,DIRT)
B(3,9,2,LEAVES:3)
B(3,9,3,LEAVES:3)
B(3,10,-7,STONE)
B(3,10,-6,STONE)
B(3,10,-5,STONE)
B(3,10,-4,STONE)
B(3,10,-3,STONE)
B(3,10,-2,STONE)
B(3,10,-1,STONE)
B(3,10,0,STONE)
B(3,10,2,LEAVES:3)
B(3,11,-7,STONE)
B(3,11,-6,STONE)
B(3,11,-5,STONE)
B(3,11,-4,STONE)
B(3,11,-3,STONE)
B(3,11,-2,STONE)
B(3,11,-1,STONE)
B(3,11,0,STONE)
B(3,12,-7,STONE)
B(3,12,-6,STONE)
B(3,12,-5,STONE)
B(3,12,-4,STONE)
B(3,12,-3,STONE)
B(3,12,-2,STONE)
B(3,12,-1,STONE)
B(3,12,0,STONE)
B(3,13,-6,STONE)
B(3,13,-5,STONE)
B(3,13,-4,STONE)
B(3,13,-3,STONE)
B(3,13,-2,STONE)
B(3,13,-1,STONE)
B(3,14,-6,STONE)
B(3,14,-5,STONE)
B(3,14,-4,STONE)
B(3,14,-3,STONE)
B(3,14,-2,STONE)
B(3,14,-1,STONE)
B(3,15,-6,STONE)
B(3,15,-5,STONE)
B(3,15,-4,STONE)
B(3,15,-3,STONE)
B(3,15,-2,STONE)
B(3,15,-1,STONE)
B(3,15,0,STONE)
B(3,16,-6,STONE)
B(3,16,-5,STONE)
B(3,16,-4,STONE)
B(3,16,-3,STONE)
B(3,16,-2,STONE)
B(3,16,-1,STONE)
B(3,16,0,STONE)
B(3,16,1,STONE)
B(3,17,-6,DIRT)
B(3,17,-5,STONE)
B(3,17,-4,STONE)
B(3,17,-3,STONE)
B(3,17,-2,STONE)
B(3,17,-1,STONE)
B(3,17,0,STONE)
B(3,17,1,STONE)
B(3,18,-6,DIRT)
B(3,18,-5,STONE)
B(3,18,-4,STONE)
B(3,18,-3,STONE)
B(3,18,-2,STONE)
B(3,18,-1,STONE)
B(3,18,0,STONE)
B(3,18,1,STONE)
B(3,19,-7,STONE)
B(3,19,-6,STONE)
B(3,19,-5,STONE)
B(3,19,-4,STONE)
B(3,19,-3,STONE)
B(3,19,-2,STONE)
B(3,19,-1,STONE)
B(3,19,0,DIRT)
B(3,19,1,DIRT)
B(3,20,-7,DIRT)
B(3,20,-6,GRASS)
B(3,20,-5,STONE)
B(3,20,-4,STONE)
B(3,20,-3,STONE)
B(3,20,-2,STONE)
B(3,20,-1,STONE)
B(3,20,0,GRASS)
B(3,20,1,DIRT)
B(3,21,-8,LEAVES:3)
B(3,21,-7,LOG:3)
B(3,21,-6,LEAVES:3)
B(3,21,-5,STONE)
B(3,21,-4,STONE)
B(3,21,-3,STONE)
B(3,21,-2,STONE)
B(3,21,-1,STONE)
B(3,21,1,LOG:3)
B(3,22,-8,LEAVES:3)
B(3,22,-7,LOG:3)
B(3,22,-6,LEAVES:3)
B(3,22,-5,DIRT)
B(3,22,-4,STONE)
B(3,22,-3,STONE)
B(3,22,-2,STONE)
B(3,22,-1,DIRT)
B(3,22,0,LEAVES:3)
B(3,22,1,LOG:3)
B(3,22,2,LEAVES:3)
B(3,23,-7,LEAVES:3)
B(3,23,-5,STONE)
B(3,23,-4,STONE)
B(3,23,-3,STONE)
B(3,23,-2,STONE)
B(3,23,-1,STONE)
B(3,23,0,LEAVES:3)
B(3,23,1,LOG:3)
B(3,23,2,LEAVES:3)
B(3,24,-5,STONE)
B(3,24,-4,STONE)
B(3,24,-3,STONE)
B(3,24,1,LEAVES:3)
B(3,25,-5,STONE)
B(3,25,-4,STONE)
B(3,25,-3,STONE)
B(3,25,1,LEAVES:3)
B(3,26,-5,STONE)
B(3,26,-4,STONE)
B(3,26,-3,STONE)
B(4,-18,-5,STONE)
B(4,-18,-4,STONE)
B(4,-18,-3,STONE)
B(4,-18,-2,STONE)
B(4,-18,-1,STONE)
B(4,-17,-5,STONE)
B(4,-17,-4,STONE)
B(4,-17,-3,STONE)
B(4,-17,-2,STONE)
B(4,-17,-1,STONE)
B(4,-16,-5,STONE)
B(4,-16,-4,STONE)
B(4,-16,-3,STONE)
B(4,-16,-2,STONE)
B(4,-16,-1,STONE)
B(4,-15,-5,STONE)
B(4,-15,-4,STONE)
B(4,-15,-3,STONE)
B(4,-15,-2,STONE)
B(4,-15,-1,STONE)
B(4,-14,-5,STONE)
B(4,-14,-4,STONE)
B(4,-14,-3,STONE)
B(4,-14,-2,STONE)
B(4,-14,-1,STONE)
B(4,-14,0,STONE)
B(4,-13,-5,STONE)
B(4,-13,-4,STONE)
B(4,-13,-3,STONE)
B(4,-13,-2,STONE)
B(4,-13,-1,STONE)
B(4,-13,0,STONE)
B(4,-12,-5,STONE)
B(4,-12,-4,STONE)
B(4,-12,-3,STONE)
B(4,-12,-2,STONE)
B(4,-12,-1,STONE)
B(4,-12,0,STONE)
B(4,-11,-5,STONE)
B(4,-11,-4,STONE)
B(4,-11,-3,STONE)
B(4,-11,-2,STONE)
B(4,-11,-1,STONE)
B(4,-11,0,STONE)
B(4,-10,-6,STONE)
B(4,-10,-5,STONE)
B(4,-10,-4,STONE)
B(4,-10,-3,STONE)
B(4,-10,-2,STONE)
B(4,-10,-1,STONE)
B(4,-10,0,STONE)
B(4,-10,1,DIRT)
B(4,-9,-6,STONE)
B(4,-9,-5,STONE)
B(4,-9,-4,STONE)
B(4,-9,-3,STONE)
B(4,-9,-2,STONE)
B(4,-9,-1,STONE)
B(4,-9,0,STONE)
B(4,-9,1,DIRT)
B(4,-8,-6,STONE)
B(4,-8,-5,STONE)
B(4,-8,-4,STONE)
B(4,-8,-3,STONE)
B(4,-8,-2,STONE)
B(4,-8,-1,STONE)
B(4,-8,0,STONE)
B(4,-8,1,STONE)
B(4,-7,-7,STONE)
B(4,-7,-6,STONE)
B(4,-7,-5,STONE)
B(4,-7,-4,STONE)
B(4,-7,-3,STONE)
B(4,-7,-2,STONE)
B(4,-7,-1,STONE)
B(4,-7,0,STONE)
B(4,-7,1,STONE)
B(4,-6,-7,STONE)
B(4,-6,-6,STONE)
B(4,-6,-5,STONE)
B(4,-6,-4,STONE)
B(4,-6,-3,STONE)
B(4,-6,-2,STONE)
B(4,-6,-1,STONE)
B(4,-6,0,STONE)
B(4,-6,1,STONE)
B(4,-5,-8,STONE)
B(4,-5,-7,STONE)
B(4,-5,-6,STONE)
B(4,-5,-5,STONE)
B(4,-5,-4,STONE)
B(4,-5,-3,STONE)
B(4,-5,-2,STONE)
B(4,-5,-1,STONE)
B(4,-5,0,STONE)
B(4,-5,1,STONE)
B(4,-4,-9,STONE)
B(4,-4,-8,STONE)
B(4,-4,-7,STONE)
B(4,-4,-6,STONE)
B(4,-4,-5,STONE)
B(4,-4,-4,STONE)
B(4,-4,-3,STONE)
B(4,-4,-2,STONE)
B(4,-4,-1,STONE)
B(4,-4,0,STONE)
B(4,-4,1,STONE)
B(4,-4,2,DIRT)
B(4,-4,3,DIRT)
B(4,-3,-9,STONE)
B(4,-3,-8,STONE)
B(4,-3,-7,STONE)
B(4,-3,-6,STONE)
B(4,-3,-5,STONE)
B(4,-3,-4,STONE)
B(4,-3,-3,STONE)
B(4,-3,-2,STONE)
B(4,-3,-1,STONE)
B(4,-3,0,STONE)
B(4,-3,1,STONE)
B(4,-3,2,STONE)
B(4,-3,3,STONE)
B(4,-2,-9,STONE)
B(4,-2,-8,STONE)
B(4,-2,-7,STONE)
B(4,-2,-6,STONE)
B(4,-2,-5,STONE)
B(4,-2,-4,STONE)
B(4,-2,-3,STONE)
B(4,-2,-2,STONE)
B(4,-2,-1,STONE)
B(4,-2,0,STONE)
B(4,-2,1,STONE)
B(4,-2,2,STONE)
B(4,-2,3,STONE)
B(4,-1,-10,STONE)
B(4,-1,-9,STONE)
B(4,-1,-8,STONE)
B(4,-1,-7,STONE)
B(4,-1,-6,STONE)
B(4,-1,-5,STONE)
B(4,-1,-4,STONE)
B(4,-1,-3,STONE)
B(4,-1,-2,STONE)
B(4,-1,-1,STONE)
B(4,-1,0,STONE)
B(4,-1,1,STONE)
B(4,-1,2,STONE)
B(4,-1,3,STONE)
B(4,0,-10,STONE)
B(4,0,-9,STONE)
B(4,0,-8,STONE)
B(4,0,-7,STONE)
B(4,0,-6,STONE)
B(4,0,-5,STONE)
B(4,0,-4,STONE)
B(4,0,-3,STONE)
B(4,0,-2,STONE)
B(4,0,-1,STONE)
B(4,0,0,STONE)
B(4,0,1,STONE)
B(4,0,2,STONE)
B(4,0,3,STONE)
B(4,1,-9,STONE)
B(4,1,-8,STONE)
B(4,1,-7,STONE)
B(4,1,-6,STONE)
B(4,1,-5,STONE)
B(4,1,-4,STONE)
B(4,1,-3,STONE)
B(4,1,-2,STONE)
B(4,1,-1,STONE)
B(4,1,0,STONE)
B(4,1,1,STONE)
B(4,1,2,GRASS)
B(4,1,3,DIRT)
B(4,2,-8,STONE)
B(4,2,-7,STONE)
B(4,2,-6,STONE)
B(4,2,-5,STONE)
B(4,2,-4,STONE)
B(4,2,-3,STONE)
B(4,2,-2,STONE)
B(4,2,-1,STONE)
B(4,2,0,STONE)
B(4,2,1,STONE)
B(4,2,3,LOG:3)
B(4,3,-8,STONE)
B(4,3,-7,STONE)
B(4,3,-6,STONE)
B(4,3,-5,STONE)
B(4,3,-4,STONE)
B(4,3,-3,STONE)
B(4,3,-2,STONE)
B(4,3,-1,STONE)
B(4,3,0,STONE)
B(4,3,1,STONE)
B(4,3,3,LOG:3)
B(4,4,-7,STONE)
B(4,4,-6,STONE)
B(4,4,-5,STONE)
B(4,4,-4,STONE)
B(4,4,-3,STONE)
B(4,4,-2,STONE)
B(4,4,-1,STONE)
B(4,4,0,STONE)
B(4,4,1,STONE)
B(4,4,2,LEAVES:3)
B(4,4,3,LEAVES:3)
B(4,4,4,LEAVES:3)
B(4,4,5,LEAVES:3)
B(4,4,6,LEAVES:3)
B(4,5,-7,STONE)
B(4,5,-6,STONE)
B(4,5,-5,STONE)
B(4,5,-4,STONE)
B(4,5,-3,STONE)
B(4,5,-2,STONE)
B(4,5,-1,STONE)
B(4,5,0,STONE)
B(4,5,1,STONE)
B(4,5,3,LEAVES:3)
B(4,5,4,LEAVES:3)
B(4,5,5,LEAVES:3)
B(4,6,-7,STONE)
B(4,6,-6,STONE)
B(4,6,-5,STONE)
B(4,6,-4,STONE)
B(4,6,-3,STONE)
B(4,6,-2,STONE)
B(4,6,-1,STONE)
B(4,6,0,STONE)
B(4,6,1,DIRT)
B(4,7,-7,STONE)
B(4,7,-6,STONE)
B(4,7,-5,STONE)
B(4,7,-4,STONE)
B(4,7,-3,STONE)
B(4,7,-2,STONE)
B(4,7,-1,STONE)
B(4,7,0,STONE)
B(4,7,1,GRASS)
B(4,8,-7,STONE)
B(4,8,-6,STONE)
B(4,8,-5,STONE)
B(4,8,-4,STONE)
B(4,8,-3,STONE)
B(4,8,-2,STONE)
B(4,8,-1,STONE)
B(4,8,0,STONE)
B(4,9,-6,STONE)
B(4,9,-5,STONE)
B(4,9,-4,STONE)
B(4,9,-3,STONE)
B(4,9,-2,STONE)
B(4,9,-1,STONE)
B(4,9,0,STONE)
B(4,10,-6,STONE)
B(4,10,-5,STONE)
B(4,10,-4,STONE)
B(4,10,-3,STONE)
B(4,10,-2,STONE)
B(4,10,-1,STONE)
B(4,10,0,STONE)
B(4,11,-6,STONE)
B(4,11,-5,STONE)
B(4,11,-4,STONE)
B(4,11,-3,STONE)
B(4,11,-2,STONE)
B(4,11,-1,STONE)
B(4,11,0,STONE)
B(4,12,-6,STONE)
B(4,12,-5,STONE)
B(4,12,-4,STONE)
B(4,12,-3,STONE)
B(4,12,-2,STONE)
B(4,12,-1,STONE)
B(4,13,-5,STONE)
B(4,13,-4,STONE)
B(4,13,-3,STONE)
B(4,13,-2,STONE)
B(4,13,-1,STONE)
B(4,14,-5,STONE)
B(4,14,-4,STONE)
B(4,14,-3,STONE)
B(4,14,-2,STONE)
B(4,14,-1,STONE)
B(4,15,-5,STONE)
B(4,15,-4,STONE)
B(4,15,-3,STONE)
B(4,15,-2,STONE)
B(4,15,-1,STONE)
B(4,16,-5,STONE)
B(4,16,-4,STONE)
B(4,16,-3,STONE)
B(4,16,-2,STONE)
B(4,16,-1,STONE)
B(4,16,0,STONE)
B(4,17,-6,STONE)
B(4,17,-5,DIRT)
B(4,17,-4,STONE)
B(4,17,-3,STONE)
B(4,17,-2,STONE)
B(4,17,-1,STONE)
B(4,17,0,STONE)
B(4,17,1,STONE)
B(4,18,-6,STONE)
B(4,18,-5,STONE)
B(4,18,-4,STONE)
B(4,18,-3,STONE)
B(4,18,-2,STONE)
B(4,18,-1,STONE)
B(4,18,0,STONE)
B(4,18,1,STONE)
B(4,19,-6,DIRT)
B(4,19,-5,STONE)
B(4,19,-4,STONE)
B(4,19,-3,STONE)
B(4,19,-2,STONE)
B(4,19,-1,STONE)
B(4,19,0,STONE)
B(4,19,1,STONE)
B(4,20,-6,GRASS)
B(4,20,-5,GRASS)
B(4,20,-4,STONE)
B(4,20,-3,STONE)
B(4,20,-2,STONE)
B(4,20,-1,GRASS)
B(4,20,0,GRASS)
B(4,20,1,GRASS)
B(4,20,2,LEAVES:3)
B(4,21,-7,LEAVES:3)
B(4,21,-4,DIRT)
B(4,21,-3,DIRT)
B(4,21,-2,STONE)
B(4,22,-7,LEAVES:3)
B(4,22,-4,STONE)
B(4,22,-3,STONE)
B(4,22,-2,STONE)
B(4,22,0,LEAVES:3)
B(4,22,1,LEAVES:3)
B(4,22,2,LEAVES:3)
B(4,23,-4,STONE)
B(4,23,-3,STONE)
B(4,23,-2,STONE)
B(4,23,1,LEAVES:3)
B(5,-18,-4,STONE)
B(5,-18,-3,STONE)
B(5,-18,-2,STONE)
B(5,-18,-1,STONE)
B(5,-17,-4,STONE)
B(5,-17,-3,STONE)
B(5,-17,-2,STONE)
B(5,-16,-4,STONE)
B(5,-16,-3,STONE)
B(5,-16,-2,STONE)
B(5,-15,-5,STONE)
B(5,-15,-4,STONE)
B(5,-15,-3,STONE)
B(5,-15,-2,STONE)
B(5,-14,-5,STONE)
B(5,-14,-4,STONE)
B(5,-14,-3,STONE)
B(5,-14,-2,STONE)
B(5,-14,-1,STONE)
B(5,-13,-5,STONE)
B(5,-13,-4,STONE)
B(5,-13,-3,STONE)
B(5,-13,-2,STONE)
B(5,-13,-1,STONE)
B(5,-12,-5,STONE)
B(5,-12,-4,STONE)
B(5,-12,-3,STONE)
B(5,-12,-2,STONE)
B(5,-12,-1,STONE)
B(5,-11,-5,STONE)
B(5,-11,-4,STONE)
B(5,-11,-3,STONE)
B(5,-11,-2,STONE)
B(5,-11,-1,STONE)
B(5,-11,0,STONE)
B(5,-10,-5,STONE)
B(5,-10,-4,STONE)
B(5,-10,-3,STONE)
B(5,-10,-2,STONE)
B(5,-10,-1,STONE)
B(5,-10,0,STONE)
B(5,-9,-5,STONE)
B(5,-9,-4,STONE)
B(5,-9,-3,STONE)
B(5,-9,-2,STONE)
B(5,-9,-1,STONE)
B(5,-9,0,STONE)
B(5,-8,-5,STONE)
B(5,-8,-4,STONE)
B(5,-8,-3,STONE)
B(5,-8,-2,STONE)
B(5,-8,-1,STONE)
B(5,-8,0,STONE)
B(5,-7,-5,STONE)
B(5,-7,-4,STONE)
B(5,-7,-3,STONE)
B(5,-7,-2,STONE)
B(5,-7,-1,STONE)
B(5,-7,0,STONE)
B(5,-6,-6,STONE)
B(5,-6,-5,STONE)
B(5,-6,-4,STONE)
B(5,-6,-3,STONE)
B(5,-6,-2,STONE)
B(5,-6,-1,STONE)
B(5,-6,0,STONE)
B(5,-5,-7,STONE)
B(5,-5,-6,STONE)
B(5,-5,-5,STONE)
B(5,-5,-4,STONE)
B(5,-5,-3,STONE)
B(5,-5,-2,STONE)
B(5,-5,-1,STONE)
B(5,-5,0,STONE)
B(5,-4,-8,STONE)
B(5,-4,-7,STONE)
B(5,-4,-6,STONE)
B(5,-4,-5,STONE)
B(5,-4,-4,STONE)
B(5,-4,-3,STONE)
B(5,-4,-2,STONE)
B(5,-4,-1,STONE)
B(5,-4,0,STONE)
B(5,-4,1,DIRT)
B(5,-4,2,DIRT)
B(5,-3,-8,STONE)
B(5,-3,-7,STONE)
B(5,-3,-6,STONE)
B(5,-3,-5,STONE)
B(5,-3,-4,STONE)
B(5,-3,-3,STONE)
B(5,-3,-2,STONE)
B(5,-3,-1,STONE)
B(5,-3,0,STONE)
B(5,-3,1,STONE)
B(5,-3,2,STONE)
B(5,-2,-9,STONE)
B(5,-2,-8,STONE)
B(5,-2,-7,STONE)
B(5,-2,-6,STONE)
B(5,-2,-5,STONE)
B(5,-2,-4,STONE)
B(5,-2,-3,STONE)
B(5,-2,-2,STONE)
B(5,-2,-1,STONE)
B(5,-2,0,STONE)
B(5,-2,1,STONE)
B(5,-2,2,STONE)
B(5,-1,-10,STONE)
B(5,-1,-9,STONE)
B(5,-1,-8,STONE)
B(5,-1,-7,STONE)
B(5,-1,-6,STONE)
B(5,-1,-5,STONE)
B(5,-1,-4,STONE)
B(5,-1,-3,STONE)
B(5,-1,-2,STONE)
B(5,-1,-1,STONE)
B(5,-1,0,STONE)
B(5,-1,1,STONE)
B(5,-1,2,STONE)
B(5,0,-10,STONE)
B(5,0,-9,STONE)
B(5,0,-8,STONE)
B(5,0,-7,STONE)
B(5,0,-6,STONE)
B(5,0,-5,STONE)
B(5,0,-4,STONE)
B(5,0,-3,STONE)
B(5,0,-2,STONE)
B(5,0,-1,STONE)
B(5,0,0,STONE)
B(5,0,1,STONE)
B(5,0,2,STONE)
B(5,1,-8,STONE)
B(5,1,-7,STONE)
B(5,1,-6,STONE)
B(5,1,-5,STONE)
B(5,1,-4,STONE)
B(5,1,-3,STONE)
B(5,1,-2,STONE)
B(5,1,-1,STONE)
B(5,1,0,STONE)
B(5,1,1,GRASS)
B(5,1,2,GRASS)
B(5,2,-8,STONE)
B(5,2,-7,STONE)
B(5,2,-6,STONE)
B(5,2,-5,STONE)
B(5,2,-4,STONE)
B(5,2,-3,STONE)
B(5,2,-2,STONE)
B(5,2,-1,STONE)
B(5,2,0,STONE)
B(5,3,-7,STONE)
B(5,3,-6,STONE)
B(5,3,-5,STONE)
B(5,3,-4,STONE)
B(5,3,-3,STONE)
B(5,3,-2,STONE)
B(5,3,-1,STONE)
B(5,3,0,STONE)
B(5,4,-6,STONE)
B(5,4,-5,STONE)
B(5,4,-4,STONE)
B(5,4,-3,STONE)
B(5,4,-2,STONE)
B(5,4,-1,STONE)
B(5,4,0,STONE)
B(5,4,2,LEAVES:3)
B(5,4,3,LEAVES:3)
B(5,4,4,LOG:3)
B(5,4,5,LEAVES:3)
B(5,4,6,LEAVES:3)
B(5,5,-6,STONE)
B(5,5,-5,STONE)
B(5,5,-4,STONE)
B(5,5,-3,STONE)
B(5,5,-2,STONE)
B(5,5,-1,STONE)
B(5,5,0,STONE)
B(5,5,3,LEAVES:3)
B(5,5,4,LEAVES:3)
B(5,5,5,LEAVES:3)
B(5,6,-6,STONE)
B(5,6,-5,STONE)
B(5,6,-4,STONE)
B(5,6,-3,STONE)
B(5,6,-2,STONE)
B(5,6,-1,STONE)
B(5,6,0,STONE)
B(5,6,4,LEAVES:3)
B(5,7,-6,STONE)
B(5,7,-5,STONE)
B(5,7,-4,STONE)
B(5,7,-3,STONE)
B(5,7,-2,STONE)
B(5,7,-1,STONE)
B(5,7,0,STONE)
B(5,8,-6,STONE)
B(5,8,-5,STONE)
B(5,8,-4,STONE)
B(5,8,-3,STONE)
B(5,8,-2,STONE)
B(5,8,-1,STONE)
B(5,8,0,STONE)
B(5,9,-5,STONE)
B(5,9,-4,STONE)
B(5,9,-3,STONE)
B(5,9,-2,STONE)
B(5,9,-1,STONE)
B(5,10,-5,STONE)
B(5,10,-4,STONE)
B(5,10,-3,STONE)
B(5,10,-2,STONE)
B(5,10,-1,STONE)
B(5,11,-5,STONE)
B(5,11,-4,STONE)
B(5,11,-3,STONE)
B(5,11,-2,STONE)
B(5,11,-1,STONE)
B(5,12,-5,STONE)
B(5,12,-4,STONE)
B(5,12,-3,STONE)
B(5,12,-2,STONE)
B(5,13,-4,STONE)
B(5,13,-3,STONE)
B(5,13,-2,STONE)
B(5,14,-4,STONE)
B(5,14,-3,STONE)
B(5,14,-2,STONE)
B(5,15,-4,STONE)
B(5,15,-3,STONE)
B(5,15,-2,STONE)
B(5,15,-1,STONE)
B(5,16,-4,STONE)
B(5,16,-3,STONE)
B(5,16,-2,STONE)
B(5,16,-1,STONE)
B(5,17,-4,STONE)
B(5,17,-3,STONE)
B(5,17,-2,STONE)
B(5,17,-1,STONE)
B(5,17,0,STONE)
B(5,18,-4,STONE)
B(5,18,-3,STONE)
B(5,18,-2,STONE)
B(5,18,-1,STONE)
B(5,18,0,STONE)
B(5,18,1,STONE)
B(5,19,-5,STONE)
B(5,19,-4,STONE)
B(5,19,-3,STONE)
B(5,19,-2,STONE)
B(5,19,-1,STONE)
B(5,19,0,DIRT)
B(5,19,1,DIRT)
B(5,19,2,LEAVES:3)
B(5,20,-6,STONE)
B(5,20,-5,GRASS)
B(5,20,-4,GRASS)
B(5,20,-3,DIRT)
B(5,20,-2,GRASS)
B(5,20,-1,GRASS)
B(5,20,0,GRASS)
B(5,20,1,LOG:3)
B(5,20,2,LEAVES:3)
B(5,21,-3,LOG:3)
B(5,21,1,LEAVES:3)
B(5,22,-5,LEAVES:3)
B(5,22,-1,LEAVES:3)
B(5,23,-5,LEAVES:3)
B(5,23,-4,LEAVES:3)
B(5,23,-3,LEAVES:3)
B(5,23,-2,LEAVES:3)
B(5,23,-1,LEAVES:3)
B(5,24,-4,LEAVES:3)
B(5,24,-3,LEAVES:3)
B(5,24,-2,LEAVES:3)
B(6,-18,-3,STONE)
B(6,-17,-3,STONE)
B(6,-11,-3,STONE)
B(6,-10,-5,STONE)
B(6,-10,-4,STONE)
B(6,-10,-3,STONE)
B(6,-10,-2,STONE)
B(6,-9,-5,STONE)
B(6,-9,-4,STONE)
B(6,-9,-3,STONE)
B(6,-9,-2,STONE)
B(6,-9,-1,STONE)
B(6,-8,-5,STONE)
B(6,-8,-4,STONE)
B(6,-8,-3,STONE)
B(6,-8,-2,STONE)
B(6,-8,-1,STONE)
B(6,-7,-5,STONE)
B(6,-7,-4,STONE)
B(6,-7,-3,STONE)
B(6,-7,-2,STONE)
B(6,-7,-1,STONE)
B(6,-6,-5,STONE)
B(6,-6,-4,STONE)
B(6,-6,-3,STONE)
B(6,-6,-2,STONE)
B(6,-6,-1,STONE)
B(6,-5,-6,STONE)
B(6,-5,-5,STONE)
B(6,-5,-4,STONE)
B(6,-5,-3,STONE)
B(6,-5,-2,STONE)
B(6,-5,-1,STONE)
B(6,-4,-6,STONE)
B(6,-4,-5,STONE)
B(6,-4,-4,STONE)
B(6,-4,-3,STONE)
B(6,-4,-2,STONE)
B(6,-4,-1,STONE)
B(6,-4,0,DIRT)
B(6,-4,1,DIRT)
B(6,-3,-8,STONE)
B(6,-3,-7,STONE)
B(6,-3,-6,STONE)
B(6,-3,-5,STONE)
B(6,-3,-4,STONE)
B(6,-3,-3,STONE)
B(6,-3,-2,STONE)
B(6,-3,-1,STONE)
B(6,-3,0,STONE)
B(6,-3,1,STONE)
B(6,-2,-9,STONE)
B(6,-2,-8,STONE)
B(6,-2,-7,STONE)
B(6,-2,-6,STONE)
B(6,-2,-5,STONE)
B(6,-2,-4,STONE)
B(6,-2,-3,STONE)
B(6,-2,-2,STONE)
B(6,-2,-1,STONE)
B(6,-2,0,STONE)
B(6,-2,1,STONE)
B(6,-2,2,STONE)
B(6,-1,-9,STONE)
B(6,-1,-8,STONE)
B(6,-1,-7,STONE)
B(6,-1,-6,STONE)
B(6,-1,-5,STONE)
B(6,-1,-4,STONE)
B(6,-1,-3,STONE)
B(6,-1,-2,STONE)
B(6,-1,-1,STONE)
B(6,-1,0,STONE)
B(6,-1,1,STONE)
B(6,-1,2,STONE)
B(6,0,-9,STONE)
B(6,0,-8,STONE)
B(6,0,-7,STONE)
B(6,0,-6,STONE)
B(6,0,-5,STONE)
B(6,0,-4,STONE)
B(6,0,-3,STONE)
B(6,0,-2,STONE)
B(6,0,-1,STONE)
B(6,0,0,STONE)
B(6,0,1,STONE)
B(6,1,-8,STONE)
B(6,1,-7,STONE)
B(6,1,-6,STONE)
B(6,1,-5,STONE)
B(6,1,-4,STONE)
B(6,1,-3,STONE)
B(6,1,-2,STONE)
B(6,1,-1,STONE)
B(6,1,0,GRASS)
B(6,1,1,GRASS)
B(6,2,-7,STONE)
B(6,2,-6,STONE)
B(6,2,-5,STONE)
B(6,2,-4,STONE)
B(6,2,-3,STONE)
B(6,2,-2,STONE)
B(6,2,-1,STONE)
B(6,3,-6,STONE)
B(6,3,-5,STONE)
B(6,3,-4,STONE)
B(6,3,-3,STONE)
B(6,3,-2,STONE)
B(6,3,-1,STONE)
B(6,4,-5,STONE)
B(6,4,-4,STONE)
B(6,4,-3,STONE)
B(6,4,-2,STONE)
B(6,4,-1,STONE)
B(6,4,2,LEAVES:3)
B(6,4,3,LEAVES:3)
B(6,4,4,LEAVES:3)
B(6,4,5,LEAVES:3)
B(6,4,6,LEAVES:3)
B(6,5,-5,STONE)
B(6,5,-4,STONE)
B(6,5,-3,STONE)
B(6,5,-2,STONE)
B(6,5,-1,STONE)
B(6,5,3,LEAVES:3)
B(6,5,4,LEAVES:3)
B(6,5,5,LEAVES:3)
B(6,6,-5,STONE)
B(6,6,-4,STONE)
B(6,6,-3,STONE)
B(6,6,-2,STONE)
B(6,6,-1,STONE)
B(6,7,-5,STONE)
B(6,7,-4,STONE)
B(6,7,-3,STONE)
B(6,7,-2,STONE)
B(6,8,-3,STONE)
B(6,14,-3,STONE)
B(6,15,-3,STONE)
B(6,16,-3,STONE)
B(6,16,-2,STONE)
B(6,17,-3,STONE)
B(6,17,-2,STONE)
B(6,17,-1,STONE)
B(6,18,-4,DIRT)
B(6,18,-3,STONE)
B(6,18,-2,STONE)
B(6,18,-1,STONE)
B(6,18,0,STONE)
B(6,18,1,LEAVES:3)
B(6,19,-4,STONE)
B(6,19,-3,STONE)
B(6,19,-2,DIRT)
B(6,19,-1,DIRT)
B(6,19,0,STONE)
B(6,19,1,LEAVES:3)
B(6,20,-4,GRASS)
B(6,20,-3,GRASS)
B(6,20,-2,GRASS)
B(6,20,-1,GRASS)
B(6,20,0,LEAVES:3)
B(6,20,1,LEAVES:3)
B(6,20,2,LEAVES:3)
B(6,22,-3,LOG:3)
B(6,23,-4,LEAVES:3)
B(6,23,-3,LOG:3)
B(6,23,-2,LEAVES:3)
B(6,24,-4,LEAVES:3)
B(6,24,-3,LOG:3)
B(6,24,-2,LEAVES:3)
B(6,25,-3,LEAVES:3)
B(7,-5,-5,DIRT)
B(7,-5,-4,DIRT)
B(7,-4,-5,STONE)
B(7,-4,-4,STONE)
B(7,-4,-3,DIRT)
B(7,-4,-2,STONE)
B(7,-3,-7,STONE)
B(7,-3,-6,STONE)
B(7,-3,-5,STONE)
B(7,-3,-4,STONE)
B(7,-3,-3,STONE)
B(7,-3,-2,STONE)
B(7,-3,-1,DIRT)
B(7,-3,0,STONE)
B(7,-2,-9,STONE)
B(7,-2,-8,STONE)
B(7,-2,-7,STONE)
B(7,-2,-6,STONE)
B(7,-2,-5,STONE)
B(7,-2,-4,STONE)
B(7,-2,-3,STONE)
B(7,-2,-2,STONE)
B(7,-2,-1,STONE)
B(7,-2,0,STONE)
B(7,-2,1,STONE)
B(7,-1,-9,STONE)
B(7,-1,-8,STONE)
B(7,-1,-7,STONE)
B(7,-1,-6,STONE)
B(7,-1,-5,STONE)
B(7,-1,-4,STONE)
B(7,-1,-3,STONE)
B(7,-1,-2,STONE)
B(7,-1,-1,STONE)
B(7,-1,0,STONE)
B(7,-1,1,STONE)
B(7,0,-8,STONE)
B(7,0,-7,STONE)
B(7,0,-6,STONE)
B(7,0,-5,STONE)
B(7,0,-4,STONE)
B(7,0,-3,STONE)
B(7,0,-2,STONE)
B(7,0,-1,GRASS)
B(7,0,0,STONE)
B(7,1,-6,STONE)
B(7,1,-5,STONE)
B(7,1,-4,STONE)
B(7,1,-3,GRASS)
B(7,1,-2,STONE)
B(7,2,-6,GRASS)
B(7,2,-5,GRASS)
B(7,2,-4,GRASS)
B(7,3,2,LEAVES:3)
B(7,3,6,LEAVES:3)
B(7,4,-5,LEAVES:3)
B(7,4,-4,LEAVES:3)
B(7,4,-3,LEAVES:3)
B(7,4,2,LEAVES:3)
B(7,4,3,LEAVES:3)
B(7,4,4,LEAVES:3)
B(7,4,5,LEAVES:3)
B(7,4,6,LEAVES:3)
B(7,5,-4,LEAVES:3)
B(7,22,-5,LEAVES:3)
B(7,22,-1,LEAVES:3)
B(7,23,-5,LEAVES:3)
B(7,23,-4,LEAVES:3)
B(7,23,-3,LEAVES:3)
B(7,23,-2,LEAVES:3)
B(7,23,-1,LEAVES:3)
B(7,24,-4,LEAVES:3)
B(7,24,-3,LEAVES:3)
B(7,24,-2,LEAVES:3)
B(8,-4,-5,DIRT)
B(8,-4,-4,DIRT)
B(8,-3,-6,STONE)
B(8,-3,-5,STONE)
B(8,-3,-4,STONE)
B(8,-3,-3,STONE)
B(8,-3,-2,DIRT)
B(8,-3,-1,DIRT)
B(8,-2,-8,STONE)
B(8,-2,-7,STONE)
B(8,-2,-6,STONE)
B(8,-2,-5,STONE)
B(8,-2,-4,STONE)
B(8,-2,-3,STONE)
B(8,-2,-2,STONE)
B(8,-2,-1,STONE)
B(8,-2,0,STONE)
B(8,-1,-8,STONE)
B(8,-1,-7,STONE)
B(8,-1,-6,STONE)
B(8,-1,-5,STONE)
B(8,-1,-4,STONE)
B(8,-1,-3,STONE)
B(8,-1,-2,STONE)
B(8,-1,-1,STONE)
B(8,-1,0,STONE)
B(8,0,-7,STONE)
B(8,0,-6,STONE)
B(8,0,-5,STONE)
B(8,0,-4,STONE)
B(8,0,-3,STONE)
B(8,0,-2,GRASS)
B(8,0,-1,GRASS)
B(8,1,-6,STONE)
B(8,1,-5,GRASS)
B(8,1,-4,DIRT)
B(8,2,-4,LOG:3)
B(8,3,-5,LEAVES:3)
B(8,3,-4,LOG:3)
B(8,4,-5,LEAVES:3)
B(8,4,-4,LOG:3)
B(8,4,-3,LEAVES:3)
B(8,5,-5,LEAVES:3)
B(8,5,-4,LEAVES:3)
B(8,5,-3,LEAVES:3)
B(8,6,-4,LEAVES:3)
B(8,22,-4,LEAVES:3)
B(8,22,-2,LEAVES:3)
B(8,23,-4,LEAVES:3)
B(8,23,-2,LEAVES:3)
B(9,3,-4,LEAVES:3)
B(9,4,-5,LEAVES:3)
B(9,4,-4,LEAVES:3)
B(9,4,-3,LEAVES:3)
B(9,5,-4,LEAVES:3)

#######################################################################
# +-----------------------------------------------------------------+ #
# |                            BO3 checks                           | #
# +-----------------------------------------------------------------+ #
#######################################################################

# Require a condition at a certain location in order for the BO3 to be spawned.
# BlockCheck(x,y,z,BlockName[,BlockName[,...]]) - one of the blocks must be at the location
# BlockCheckNot(x,y,z,BlockName[,BlockName[,...]]) - all the blocks must not be at the location
# LightCheck(x,y,z,minLightLevel,maxLightLevel) - light must be between min and max (inclusive)

# You can use "Solid" as a BlockName for matching all solid blocks or "All" to match all blocks that aren't air.

# Examples:
#   BlockCheck(0,-1,0,GRASS,DIRT)  Require grass or dirt just below the object
#   BlockCheck(0,-1,0,Solid)       Require any solid block just below the object
#   BlockCheck(0,-1,0,WOOL)        Require any type of wool just below the object
#   BlockCheck(0,-1,0,WOOL:0)      Require white wool just below the object
#   BlockCheckNot(0,-1,0,WOOL:0)   Require that there is no white wool below the object
#   LightCheck(0,0,0,0,1)          Require almost complete darkness just below the object
BlockCheck(0,-1,0,GRASS)

#######################################################################
# +-----------------------------------------------------------------+ #
# |                             Branches                            | #
# +-----------------------------------------------------------------+ #
#######################################################################

# Branches are objects that will spawn when this object spawns when it is used in
# the CustomStructure resource. Branches can also have branches, making complex
# structures possible. See the wiki for more details.

# Regular Branches spawn each branch with an independent chance of spawning.
# Branch(x,y,z,branchName,rotation,chance[,anotherBranchName,rotation,chance[,...]][IndividualChance])
# branchName - name of the object to spawn.
# rotation - NORTH, SOUTH, EAST or WEST.
# IndividualChance - The chance each branch has to spawn, assumed to be 100 when left blank

# Weighted Branches spawn branches with a dependent chance of spawning.
# WBR(x,y,z,branchName,rotation,chance[,anotherBranchName,rotation,chance[,...]][MaxChanceOutOf])
# MaxChanceOutOf - The chance all branches have to spawn out of, assumed to be 100 when left blank
