
#######################################################################
# +-----------------------------------------------------------------+ #
# |                            BO3 object                           | #
# +-----------------------------------------------------------------+ #
#######################################################################

# This is the config file of a custom object.
# If you add this object correctly to your BiomeConfigs, it will spawn in the world.

# This is the creator of this BO3 object
Author: Piginabag

# A short description of this BO3 object
Description: No description given

# The BO3 version, don't change this! It can be used by external applications to do a version check.
Version: 3

# The settings mode, WriteAll, WriteWithoutComments or WriteDisable. See WorldConfig.
SettingsMode: WriteDisable


#######################################################################
# +-----------------------------------------------------------------+ #
# |                          Main settings                          | #
# +-----------------------------------------------------------------+ #
#######################################################################

# This needs to be set to true to spawn the object in the Tree and Sapling resources.
Tree: false

# The frequency of the BO3 from 1 to 200. Tries this many times to spawn this BO3 when using the CustomObject(...) resource.
# Ignored by Tree(..), Sapling(..) and CustomStructure(..)
Frequency: 1

# The rarity of the BO3 from 0 to 100. Each spawn attempt has rarity% chance to succeed when using the CustomObject(...) resource.
# Ignored by Tree(..), Sapling(..) and CustomStructure(..)
Rarity: 100.0

# If you set this to true, the BO3 will be placed with a random rotation.
RotateRandomly: false

# The spawn height of the BO3 - randomY, highestBlock or highestSolidBlock.
SpawnHeight: highestSolidBlock

# The height limits for the BO3.
MinHeight: 0

MaxHeight: 256

# Objects can have other objects attacthed to it: branches. Branches can also
# have branches attached to it, which can also have branches, etc. This is the
# maximum branch depth for this objects.
MaxBranchDepth: 10

# When spawned with the UseWorld keyword, this BO3 should NOT spawn in the following biomes.
# If you writer.write the BO3 name directly in the BiomeConfigs, this will be ignored.
ExcludedBiomes: All

#######################################################################
# +-----------------------------------------------------------------+ #
# |                      Source block settings                      | #
# +-----------------------------------------------------------------+ #
#######################################################################

# The B(s) the BO3 should spawn in.
SourceBlocks: AIR

# The maximum percentage of the BO3 that can be outside the SourceBlock.
# The BO3 won't be placed on a location with more blocks outside the SourceBlock than this percentage.
MaxPercentageOutsideSourceBlock: 100

# What to do when a block is about to be placed outside the SourceBlock? (dontPlace, placeAnyway)
OutsideSourceBlock: placeAnyway


#######################################################################
# +-----------------------------------------------------------------+ #
# |                              Blocks                             | #
# +-----------------------------------------------------------------+ #
#######################################################################

# All the blocks used in the BO3 are listed here. Possible blocks:
# B(x,y,z,id[.data][,nbtfile.nbt)
# RB(x,y,z,id[:data][,nbtfile.nbt],chance[,id[:data][,nbtfile.nbt],chance[,...]])
# So RB(0,0,0,CHEST,chest.nbt,50,CHEST,anotherchest.nbt,100) will spawn a chest at
# the BO3 origin, and give it a 50% chance to have the contents of chest.nbt, or, if that
# fails, a 100% percent chance to have the contents of anotherchest.nbt.
B(-12,-16,9,STONE)
B(-12,-15,8,STONE)
B(-12,-15,9,STONE)
B(-12,-14,1,STONE)
B(-12,-14,3,STONE)
B(-12,-14,4,STONE)
B(-12,-14,6,STONE)
B(-12,-14,7,STONE)
B(-12,-14,8,STONE)
B(-12,-14,9,STONE)
B(-12,-14,10,STONE)
B(-12,-13,0,STONE)
B(-12,-13,1,STONE)
B(-12,-13,2,STONE)
B(-12,-13,3,STONE)
B(-12,-13,4,STONE)
B(-12,-13,5,STONE)
B(-12,-13,6,STONE)
B(-12,-13,7,STONE)
B(-12,-13,8,STONE)
B(-12,-13,9,STONE)
B(-12,-13,10,STONE)
B(-12,-13,11,STONE)
B(-12,-12,1,STONE)
B(-12,-12,2,STONE)
B(-12,-12,3,STONE)
B(-12,-12,4,STONE)
B(-12,-12,5,STONE)
B(-12,-12,6,STONE)
B(-12,-12,7,STONE)
B(-12,-12,8,STONE)
B(-12,-12,9,STONE)
B(-12,-12,10,STONE)
B(-12,-12,11,STONE)
B(-12,-12,12,STONE)
B(-12,-11,1,STONE)
B(-12,-11,2,STONE)
B(-12,-11,3,STONE)
B(-12,-11,4,STONE)
B(-12,-11,5,STONE)
B(-12,-11,6,STONE)
B(-12,-11,7,STONE)
B(-12,-11,8,STONE)
B(-12,-11,9,STONE)
B(-12,-11,10,STONE)
B(-12,-11,11,STONE)
B(-12,-11,12,STONE)
B(-12,-10,0,STONE)
B(-12,-10,1,STONE)
B(-12,-10,2,STONE)
B(-12,-10,3,STONE)
B(-12,-10,4,STONE)
B(-12,-10,5,STONE)
B(-12,-10,6,STONE)
B(-12,-10,7,STONE)
B(-12,-10,8,STONE)
B(-12,-10,9,STONE)
B(-12,-10,10,STONE)
B(-12,-10,11,STONE)
B(-12,-10,12,STONE)
B(-12,-9,0,STONE)
B(-12,-9,1,STONE)
B(-12,-9,2,STONE)
B(-12,-9,3,STONE)
B(-12,-9,4,STONE)
B(-12,-9,5,STONE)
B(-12,-9,6,STONE)
B(-12,-9,7,STONE)
B(-12,-9,8,STONE)
B(-12,-9,9,STONE)
B(-12,-9,10,STONE)
B(-12,-9,11,STONE)
B(-12,-9,12,STONE)
B(-12,-9,13,STONE)
B(-12,-8,0,STONE)
B(-12,-8,1,STONE)
B(-12,-8,2,STONE)
B(-12,-8,3,STONE)
B(-12,-8,4,STONE)
B(-12,-8,5,STONE)
B(-12,-8,6,STONE)
B(-12,-8,7,STONE)
B(-12,-8,8,STONE)
B(-12,-8,9,STONE)
B(-12,-8,10,STONE)
B(-12,-8,11,STONE)
B(-12,-8,12,STONE)
B(-12,-8,13,STONE)
B(-12,-7,0,STONE)
B(-12,-7,1,STONE)
B(-12,-7,2,STONE)
B(-12,-7,3,STONE)
B(-12,-7,4,STONE)
B(-12,-7,5,STONE)
B(-12,-7,6,STONE)
B(-12,-7,7,STONE)
B(-12,-7,8,STONE)
B(-12,-7,9,STONE)
B(-12,-7,10,STONE)
B(-12,-7,11,STONE)
B(-12,-7,12,STONE)
B(-12,-7,13,STONE)
B(-12,-7,14,STONE)
B(-12,-6,1,STONE)
B(-12,-6,2,STONE)
B(-12,-6,3,STONE)
B(-12,-6,4,STONE)
B(-12,-6,5,STONE)
B(-12,-6,6,STONE)
B(-12,-6,7,STONE)
B(-12,-6,8,STONE)
B(-12,-6,9,STONE)
B(-12,-6,10,STONE)
B(-12,-6,11,STONE)
B(-12,-6,12,STONE)
B(-12,-6,13,STONE)
B(-12,-5,1,STONE)
B(-12,-5,2,STONE)
B(-12,-5,3,STONE)
B(-12,-5,4,STONE)
B(-12,-5,5,STONE)
B(-12,-5,6,STONE)
B(-12,-5,7,STONE)
B(-12,-5,8,STONE)
B(-12,-5,9,STONE)
B(-12,-5,10,STONE)
B(-12,-5,11,STONE)
B(-12,-5,12,STONE)
B(-12,-5,13,STONE)
B(-12,-4,1,STONE)
B(-12,-4,2,STONE)
B(-12,-4,3,STONE)
B(-12,-4,4,STONE)
B(-12,-4,5,STONE)
B(-12,-4,6,STONE)
B(-12,-4,7,STONE)
B(-12,-4,8,STONE)
B(-12,-4,9,STONE)
B(-12,-4,10,STONE)
B(-12,-4,11,STONE)
B(-12,-4,12,STONE)
B(-12,-4,13,STONE)
B(-12,-3,3,STONE)
B(-12,-3,4,STONE)
B(-12,-3,5,STONE)
B(-12,-3,6,STONE)
B(-12,-3,7,STONE)
B(-12,-3,8,STONE)
B(-12,-3,9,STONE)
B(-12,-3,10,STONE)
B(-12,-3,11,STONE)
B(-12,-3,12,STONE)
B(-12,-3,13,STONE)
B(-12,-2,3,STONE)
B(-12,-2,4,STONE)
B(-12,-2,5,STONE)
B(-12,-2,6,STONE)
B(-12,-2,7,STONE)
B(-12,-2,8,STONE)
B(-12,-2,9,STONE)
B(-12,-2,10,STONE)
B(-12,-2,11,STONE)
B(-12,-2,12,STONE)
B(-12,-2,13,STONE)
B(-12,-1,4,STONE)
B(-12,-1,5,STONE)
B(-12,-1,6,STONE)
B(-12,-1,7,STONE)
B(-12,-1,8,STONE)
B(-12,-1,9,STONE)
B(-12,-1,10,STONE)
B(-12,-1,11,STONE)
B(-12,-1,12,STONE)
B(-12,-1,13,STONE)
B(-12,0,9,STONE)
B(-12,0,10,STONE)
B(-12,0,11,STONE)
B(-12,1,10,STONE)
B(-12,1,11,STONE)
B(-11,-18,9,STONE)
B(-11,-17,9,STONE)
B(-11,-17,10,STONE)
B(-11,-16,8,STONE)
B(-11,-16,9,STONE)
B(-11,-16,10,STONE)
B(-11,-15,6,STONE)
B(-11,-15,7,STONE)
B(-11,-15,8,STONE)
B(-11,-15,9,STONE)
B(-11,-15,10,STONE)
B(-11,-15,11,STONE)
B(-11,-14,-1,STONE)
B(-11,-14,0,STONE)
B(-11,-14,1,STONE)
B(-11,-14,2,STONE)
B(-11,-14,3,STONE)
B(-11,-14,4,STONE)
B(-11,-14,5,STONE)
B(-11,-14,6,STONE)
B(-11,-14,7,STONE)
B(-11,-14,8,STONE)
B(-11,-14,9,STONE)
B(-11,-14,10,STONE)
B(-11,-14,11,STONE)
B(-11,-13,-1,STONE)
B(-11,-13,0,STONE)
B(-11,-13,1,STONE)
B(-11,-13,2,STONE)
B(-11,-13,3,STONE)
B(-11,-13,4,STONE)
B(-11,-13,5,STONE)
B(-11,-13,6,STONE)
B(-11,-13,7,STONE)
B(-11,-13,8,STONE)
B(-11,-13,9,STONE)
B(-11,-13,10,STONE)
B(-11,-13,11,STONE)
B(-11,-13,12,STONE)
B(-11,-12,0,STONE)
B(-11,-12,1,STONE)
B(-11,-12,2,STONE)
B(-11,-12,3,STONE)
B(-11,-12,4,STONE)
B(-11,-12,5,STONE)
B(-11,-12,6,STONE)
B(-11,-12,7,STONE)
B(-11,-12,8,STONE)
B(-11,-12,9,STONE)
B(-11,-12,10,STONE)
B(-11,-12,11,STONE)
B(-11,-12,12,STONE)
B(-11,-12,13,STONE)
B(-11,-11,0,STONE)
B(-11,-11,1,STONE)
B(-11,-11,2,STONE)
B(-11,-11,3,STONE)
B(-11,-11,4,STONE)
B(-11,-11,5,STONE)
B(-11,-11,6,STONE)
B(-11,-11,7,STONE)
B(-11,-11,8,STONE)
B(-11,-11,9,STONE)
B(-11,-11,10,STONE)
B(-11,-11,11,STONE)
B(-11,-11,12,STONE)
B(-11,-11,13,STONE)
B(-11,-10,0,STONE)
B(-11,-10,1,STONE)
B(-11,-10,2,STONE)
B(-11,-10,3,STONE)
B(-11,-10,4,STONE)
B(-11,-10,5,STONE)
B(-11,-10,6,STONE)
B(-11,-10,7,STONE)
B(-11,-10,8,STONE)
B(-11,-10,9,STONE)
B(-11,-10,10,STONE)
B(-11,-10,11,STONE)
B(-11,-10,12,STONE)
B(-11,-10,13,STONE)
B(-11,-10,14,STONE)
B(-11,-9,0,STONE)
B(-11,-9,1,STONE)
B(-11,-9,2,STONE)
B(-11,-9,3,STONE)
B(-11,-9,4,STONE)
B(-11,-9,5,STONE)
B(-11,-9,6,STONE)
B(-11,-9,7,STONE)
B(-11,-9,8,STONE)
B(-11,-9,9,STONE)
B(-11,-9,10,STONE)
B(-11,-9,11,STONE)
B(-11,-9,12,STONE)
B(-11,-9,13,STONE)
B(-11,-9,14,STONE)
B(-11,-8,0,STONE)
B(-11,-8,1,STONE)
B(-11,-8,2,STONE)
B(-11,-8,3,STONE)
B(-11,-8,4,STONE)
B(-11,-8,5,STONE)
B(-11,-8,6,STONE)
B(-11,-8,7,STONE)
B(-11,-8,8,STONE)
B(-11,-8,9,STONE)
B(-11,-8,10,STONE)
B(-11,-8,11,STONE)
B(-11,-8,12,STONE)
B(-11,-8,13,STONE)
B(-11,-8,14,STONE)
B(-11,-7,-1,STONE)
B(-11,-7,0,STONE)
B(-11,-7,1,STONE)
B(-11,-7,2,STONE)
B(-11,-7,3,STONE)
B(-11,-7,4,STONE)
B(-11,-7,5,STONE)
B(-11,-7,6,STONE)
B(-11,-7,7,STONE)
B(-11,-7,8,STONE)
B(-11,-7,9,STONE)
B(-11,-7,10,STONE)
B(-11,-7,11,STONE)
B(-11,-7,12,STONE)
B(-11,-7,13,STONE)
B(-11,-7,14,STONE)
B(-11,-6,-1,STONE)
B(-11,-6,0,STONE)
B(-11,-6,1,STONE)
B(-11,-6,2,STONE)
B(-11,-6,3,STONE)
B(-11,-6,4,STONE)
B(-11,-6,5,STONE)
B(-11,-6,6,STONE)
B(-11,-6,7,STONE)
B(-11,-6,8,STONE)
B(-11,-6,9,STONE)
B(-11,-6,10,STONE)
B(-11,-6,11,STONE)
B(-11,-6,12,STONE)
B(-11,-6,13,STONE)
B(-11,-6,14,STONE)
B(-11,-5,0,STONE)
B(-11,-5,1,STONE)
B(-11,-5,2,STONE)
B(-11,-5,3,STONE)
B(-11,-5,4,STONE)
B(-11,-5,5,STONE)
B(-11,-5,6,STONE)
B(-11,-5,7,STONE)
B(-11,-5,8,STONE)
B(-11,-5,9,STONE)
B(-11,-5,10,STONE)
B(-11,-5,11,STONE)
B(-11,-5,12,STONE)
B(-11,-5,13,STONE)
B(-11,-5,14,STONE)
B(-11,-4,0,STONE)
B(-11,-4,1,STONE)
B(-11,-4,2,STONE)
B(-11,-4,3,STONE)
B(-11,-4,4,STONE)
B(-11,-4,5,STONE)
B(-11,-4,6,STONE)
B(-11,-4,7,STONE)
B(-11,-4,8,STONE)
B(-11,-4,9,STONE)
B(-11,-4,10,STONE)
B(-11,-4,11,STONE)
B(-11,-4,12,STONE)
B(-11,-4,13,STONE)
B(-11,-4,14,STONE)
B(-11,-3,1,STONE)
B(-11,-3,2,STONE)
B(-11,-3,3,STONE)
B(-11,-3,4,STONE)
B(-11,-3,5,STONE)
B(-11,-3,6,STONE)
B(-11,-3,7,STONE)
B(-11,-3,8,STONE)
B(-11,-3,9,STONE)
B(-11,-3,10,STONE)
B(-11,-3,11,STONE)
B(-11,-3,12,STONE)
B(-11,-3,13,STONE)
B(-11,-3,14,STONE)
B(-11,-2,1,STONE)
B(-11,-2,2,STONE)
B(-11,-2,3,STONE)
B(-11,-2,4,STONE)
B(-11,-2,5,STONE)
B(-11,-2,6,STONE)
B(-11,-2,7,STONE)
B(-11,-2,8,STONE)
B(-11,-2,9,STONE)
B(-11,-2,10,STONE)
B(-11,-2,11,STONE)
B(-11,-2,12,STONE)
B(-11,-2,13,STONE)
B(-11,-2,14,STONE)
B(-11,-1,3,STONE)
B(-11,-1,4,STONE)
B(-11,-1,5,STONE)
B(-11,-1,6,STONE)
B(-11,-1,7,STONE)
B(-11,-1,8,STONE)
B(-11,-1,9,STONE)
B(-11,-1,10,STONE)
B(-11,-1,11,STONE)
B(-11,-1,12,STONE)
B(-11,-1,13,STONE)
B(-11,-1,14,STONE)
B(-11,0,3,STONE)
B(-11,0,4,STONE)
B(-11,0,5,STONE)
B(-11,0,6,STONE)
B(-11,0,7,STONE)
B(-11,0,8,STONE)
B(-11,0,9,STONE)
B(-11,0,10,STONE)
B(-11,0,11,STONE)
B(-11,0,12,STONE)
B(-11,0,13,STONE)
B(-11,1,7,MOSSY_COBBLESTONE)
B(-11,1,8,MOSSY_COBBLESTONE)
B(-11,1,9,STONE)
B(-11,1,10,STONE)
B(-11,1,11,STONE)
B(-11,1,12,STONE)
B(-10,-18,8,STONE)
B(-10,-18,9,STONE)
B(-10,-18,10,STONE)
B(-10,-17,7,STONE)
B(-10,-17,8,STONE)
B(-10,-17,9,STONE)
B(-10,-17,10,STONE)
B(-10,-16,7,STONE)
B(-10,-16,8,STONE)
B(-10,-16,9,STONE)
B(-10,-16,10,STONE)
B(-10,-16,11,STONE)
B(-10,-15,-1,STONE)
B(-10,-15,0,STONE)
B(-10,-15,2,STONE)
B(-10,-15,3,MOSSY_COBBLESTONE)
B(-10,-15,5,STONE)
B(-10,-15,6,STONE)
B(-10,-15,7,STONE)
B(-10,-15,8,STONE)
B(-10,-15,9,STONE)
B(-10,-15,10,STONE)
B(-10,-15,11,STONE)
B(-10,-14,-2,STONE)
B(-10,-14,-1,STONE)
B(-10,-14,0,STONE)
B(-10,-14,1,STONE)
B(-10,-14,2,STONE)
B(-10,-14,3,STONE)
B(-10,-14,4,STONE)
B(-10,-14,5,STONE)
B(-10,-14,6,STONE)
B(-10,-14,7,STONE)
B(-10,-14,8,STONE)
B(-10,-14,9,STONE)
B(-10,-14,10,STONE)
B(-10,-14,11,STONE)
B(-10,-14,12,STONE)
B(-10,-13,-2,STONE)
B(-10,-13,-1,STONE)
B(-10,-13,0,STONE)
B(-10,-13,1,STONE)
B(-10,-13,2,STONE)
B(-10,-13,3,AIR)
B(-10,-13,4,MOSSY_COBBLESTONE)
B(-10,-13,5,STONE)
B(-10,-13,6,STONE)
B(-10,-13,7,STONE)
B(-10,-13,8,STONE)
B(-10,-13,9,STONE)
B(-10,-13,10,STONE)
B(-10,-13,11,STONE)
B(-10,-13,12,STONE)
B(-10,-13,13,STONE)
B(-10,-12,-1,STONE)
B(-10,-12,0,STONE)
B(-10,-12,1,STONE)
B(-10,-12,2,AIR)
B(-10,-12,3,AIR)
B(-10,-12,4,AIR)
B(-10,-12,5,STONE)
B(-10,-12,6,STONE)
B(-10,-12,7,STONE)
B(-10,-12,8,STONE)
B(-10,-12,9,STONE)
B(-10,-12,10,STONE)
B(-10,-12,11,STONE)
B(-10,-12,12,STONE)
B(-10,-12,13,STONE)
B(-10,-11,0,STONE)
B(-10,-11,1,STONE)
B(-10,-11,2,AIR)
B(-10,-11,3,AIR)
B(-10,-11,4,AIR)
B(-10,-11,5,STONE)
B(-10,-11,6,STONE)
B(-10,-11,7,STONE)
B(-10,-11,8,STONE)
B(-10,-11,9,STONE)
B(-10,-11,10,STONE)
B(-10,-11,11,STONE)
B(-10,-11,12,STONE)
B(-10,-11,13,STONE)
B(-10,-11,14,STONE)
B(-10,-10,0,STONE)
B(-10,-10,1,STONE)
B(-10,-10,2,STONE)
B(-10,-10,3,STONE)
B(-10,-10,4,STONE)
B(-10,-10,5,STONE)
B(-10,-10,6,STONE)
B(-10,-10,7,STONE)
B(-10,-10,8,STONE)
B(-10,-10,9,STONE)
B(-10,-10,10,STONE)
B(-10,-10,11,STONE)
B(-10,-10,12,STONE)
B(-10,-10,13,STONE)
B(-10,-10,14,STONE)
B(-10,-9,-1,STONE)
B(-10,-9,0,STONE)
B(-10,-9,1,STONE)
B(-10,-9,2,STONE)
B(-10,-9,3,STONE)
B(-10,-9,4,STONE)
B(-10,-9,5,STONE)
B(-10,-9,6,STONE)
B(-10,-9,7,STONE)
B(-10,-9,8,STONE)
B(-10,-9,9,STONE)
B(-10,-9,10,STONE)
B(-10,-9,11,STONE)
B(-10,-9,12,STONE)
B(-10,-9,13,STONE)
B(-10,-9,14,STONE)
B(-10,-8,-1,STONE)
B(-10,-8,0,STONE)
B(-10,-8,1,STONE)
B(-10,-8,2,STONE)
B(-10,-8,3,STONE)
B(-10,-8,4,STONE)
B(-10,-8,5,STONE)
B(-10,-8,6,STONE)
B(-10,-8,7,STONE)
B(-10,-8,8,STONE)
B(-10,-8,9,STONE)
B(-10,-8,10,STONE)
B(-10,-8,11,STONE)
B(-10,-8,12,STONE)
B(-10,-8,13,STONE)
B(-10,-8,14,STONE)
B(-10,-7,-2,STONE)
B(-10,-7,-1,STONE)
B(-10,-7,0,STONE)
B(-10,-7,1,STONE)
B(-10,-7,2,STONE)
B(-10,-7,3,STONE)
B(-10,-7,4,STONE)
B(-10,-7,5,STONE)
B(-10,-7,6,STONE)
B(-10,-7,7,STONE)
B(-10,-7,8,STONE)
B(-10,-7,9,STONE)
B(-10,-7,10,STONE)
B(-10,-7,11,STONE)
B(-10,-7,12,STONE)
B(-10,-7,13,STONE)
B(-10,-7,14,STONE)
B(-10,-6,-1,STONE)
B(-10,-6,0,STONE)
B(-10,-6,1,STONE)
B(-10,-6,2,STONE)
B(-10,-6,3,STONE)
B(-10,-6,4,STONE)
B(-10,-6,5,STONE)
B(-10,-6,6,STONE)
B(-10,-6,7,STONE)
B(-10,-6,8,STONE)
B(-10,-6,9,STONE)
B(-10,-6,10,STONE)
B(-10,-6,11,STONE)
B(-10,-6,12,STONE)
B(-10,-6,13,STONE)
B(-10,-6,14,STONE)
B(-10,-5,-1,STONE)
B(-10,-5,0,STONE)
B(-10,-5,1,STONE)
B(-10,-5,2,STONE)
B(-10,-5,3,STONE)
B(-10,-5,4,STONE)
B(-10,-5,5,STONE)
B(-10,-5,6,STONE)
B(-10,-5,7,STONE)
B(-10,-5,8,STONE)
B(-10,-5,9,STONE)
B(-10,-5,10,STONE)
B(-10,-5,11,STONE)
B(-10,-5,12,STONE)
B(-10,-5,13,STONE)
B(-10,-5,14,STONE)
B(-10,-4,-1,STONE)
B(-10,-4,0,STONE)
B(-10,-4,1,STONE)
B(-10,-4,2,STONE)
B(-10,-4,3,STONE)
B(-10,-4,4,STONE)
B(-10,-4,5,STONE)
B(-10,-4,6,STONE)
B(-10,-4,7,STONE)
B(-10,-4,8,STONE)
B(-10,-4,9,STONE)
B(-10,-4,10,STONE)
B(-10,-4,11,STONE)
B(-10,-4,12,STONE)
B(-10,-4,13,STONE)
B(-10,-4,14,STONE)
B(-10,-3,0,STONE)
B(-10,-3,1,STONE)
B(-10,-3,2,STONE)
B(-10,-3,3,STONE)
B(-10,-3,4,STONE)
B(-10,-3,5,STONE)
B(-10,-3,6,STONE)
B(-10,-3,7,STONE)
B(-10,-3,8,STONE)
B(-10,-3,9,STONE)
B(-10,-3,10,STONE)
B(-10,-3,11,STONE)
B(-10,-3,12,STONE)
B(-10,-3,13,STONE)
B(-10,-3,14,STONE)
B(-10,-2,1,STONE)
B(-10,-2,2,STONE)
B(-10,-2,3,STONE)
B(-10,-2,4,STONE)
B(-10,-2,5,STONE)
B(-10,-2,6,STONE)
B(-10,-2,7,STONE)
B(-10,-2,8,STONE)
B(-10,-2,9,STONE)
B(-10,-2,10,STONE)
B(-10,-2,11,STONE)
B(-10,-2,12,STONE)
B(-10,-2,13,STONE)
B(-10,-2,14,STONE)
B(-10,-1,1,STONE)
B(-10,-1,2,STONE)
B(-10,-1,3,STONE)
B(-10,-1,4,STONE)
B(-10,-1,5,STONE)
B(-10,-1,6,STONE)
B(-10,-1,7,STONE)
B(-10,-1,8,STONE)
B(-10,-1,9,STONE)
B(-10,-1,10,STONE)
B(-10,-1,11,STONE)
B(-10,-1,12,STONE)
B(-10,-1,13,STONE)
B(-10,-1,14,STONE)
B(-10,0,2,STONE)
B(-10,0,3,STONE)
B(-10,0,4,STONE)
B(-10,0,5,MOSSY_COBBLESTONE)
B(-10,0,6,STONE)
B(-10,0,7,STONE)
B(-10,0,8,STONE)
B(-10,0,9,STONE)
B(-10,0,10,STONE)
B(-10,0,11,STONE)
B(-10,0,12,MOSSY_COBBLESTONE)
B(-10,0,13,STONE)
B(-10,0,14,STONE)
B(-10,1,4,STONE)
B(-10,1,5,STONE)
B(-10,1,6,STONE)
B(-10,1,7,STONE)
B(-10,1,8,STONE)
B(-10,1,9,STONE)
B(-10,1,10,STONE)
B(-10,1,11,STONE)
B(-10,1,12,STONE)
B(-10,1,13,MOSSY_COBBLESTONE)
B(-9,-19,7,STONE)
B(-9,-19,8,STONE)
B(-9,-18,1,STONE)
B(-9,-18,7,STONE)
B(-9,-18,8,STONE)
B(-9,-18,9,STONE)
B(-9,-18,10,STONE)
B(-9,-17,1,STONE)
B(-9,-17,6,STONE)
B(-9,-17,7,STONE)
B(-9,-17,8,STONE)
B(-9,-17,9,STONE)
B(-9,-17,10,STONE)
B(-9,-17,11,STONE)
B(-9,-16,-1,STONE)
B(-9,-16,0,STONE)
B(-9,-16,1,STONE)
B(-9,-16,2,STONE)
B(-9,-16,3,STONE)
B(-9,-16,4,STONE)
B(-9,-16,5,STONE)
B(-9,-16,6,STONE)
B(-9,-16,7,STONE)
B(-9,-16,8,STONE)
B(-9,-16,9,STONE)
B(-9,-16,10,STONE)
B(-9,-16,11,STONE)
B(-9,-15,-2,STONE)
B(-9,-15,-1,STONE)
B(-9,-15,0,STONE)
B(-9,-15,1,STONE)
B(-9,-15,2,STONE)
B(-9,-15,3,STONE)
B(-9,-15,4,STONE)
B(-9,-15,5,STONE)
B(-9,-15,6,STONE)
B(-9,-15,7,STONE)
B(-9,-15,8,STONE)
B(-9,-15,9,STONE)
B(-9,-15,10,STONE)
B(-9,-15,11,STONE)
B(-9,-15,12,STONE)
B(-9,-14,-3,STONE)
B(-9,-14,-2,STONE)
B(-9,-14,-1,STONE)
B(-9,-14,0,STONE)
B(-9,-14,1,STONE)
B(-9,-14,2,AIR)
B(-9,-14,3,AIR)
B(-9,-14,4,AIR)
B(-9,-14,5,AIR)
B(-9,-14,6,AIR)
B(-9,-14,7,STONE)
B(-9,-14,8,STONE)
B(-9,-14,9,STONE)
B(-9,-14,10,STONE)
B(-9,-14,11,STONE)
B(-9,-14,12,STONE)
B(-9,-14,13,STONE)
B(-9,-13,-3,STONE)
B(-9,-13,-2,STONE)
B(-9,-13,-1,STONE)
B(-9,-13,0,STONE)
B(-9,-13,1,AIR)
B(-9,-13,2,AIR)
B(-9,-13,3,AIR)
B(-9,-13,4,AIR)
B(-9,-13,5,AIR)
B(-9,-13,6,AIR)
B(-9,-13,7,AIR)
B(-9,-13,8,STONE)
B(-9,-13,9,STONE)
B(-9,-13,10,STONE)
B(-9,-13,11,STONE)
B(-9,-13,12,STONE)
B(-9,-13,13,STONE)
B(-9,-12,-3,STONE)
B(-9,-12,-2,STONE)
B(-9,-12,-1,STONE)
B(-9,-12,0,AIR)
B(-9,-12,1,AIR)
B(-9,-12,2,AIR)
B(-9,-12,3,AIR)
B(-9,-12,4,AIR)
B(-9,-12,5,AIR)
B(-9,-12,6,AIR)
B(-9,-12,7,AIR)
B(-9,-12,9,STONE)
B(-9,-12,10,STONE)
B(-9,-12,11,STONE)
B(-9,-12,12,STONE)
B(-9,-12,13,STONE)
B(-9,-12,14,STONE)
B(-9,-11,-2,STONE)
B(-9,-11,-1,STONE)
B(-9,-11,0,AIR)
B(-9,-11,1,AIR)
B(-9,-11,2,AIR)
B(-9,-11,3,AIR)
B(-9,-11,4,AIR)
B(-9,-11,5,AIR)
B(-9,-11,6,AIR)
B(-9,-11,7,AIR)
B(-9,-11,8,AIR)
B(-9,-11,9,MOSSY_COBBLESTONE)
B(-9,-11,10,STONE)
B(-9,-11,11,STONE)
B(-9,-11,12,STONE)
B(-9,-11,13,STONE)
B(-9,-11,14,STONE)
B(-9,-10,-1,STONE)
B(-9,-10,0,AIR)
B(-9,-10,1,AIR)
B(-9,-10,2,AIR)
B(-9,-10,3,AIR)
B(-9,-10,4,AIR)
B(-9,-10,5,AIR)
B(-9,-10,6,AIR)
B(-9,-10,7,AIR)
B(-9,-10,8,AIR)
B(-9,-10,9,AIR)
B(-9,-10,10,STONE)
B(-9,-10,11,STONE)
B(-9,-10,12,STONE)
B(-9,-10,13,STONE)
B(-9,-10,14,STONE)
B(-9,-9,-2,STONE)
B(-9,-9,-1,STONE)
B(-9,-9,0,STONE)
B(-9,-9,1,STONE)
B(-9,-9,2,STONE)
B(-9,-9,3,STONE)
B(-9,-9,4,STONE)
B(-9,-9,5,AIR)
B(-9,-9,6,AIR)
B(-9,-9,7,AIR)
B(-9,-9,8,AIR)
B(-9,-9,9,AIR)
B(-9,-9,10,AIR)
B(-9,-9,11,STONE)
B(-9,-9,12,STONE)
B(-9,-9,13,STONE)
B(-9,-9,14,STONE)
B(-9,-8,-2,STONE)
B(-9,-8,-1,STONE)
B(-9,-8,0,STONE)
B(-9,-8,1,STONE)
B(-9,-8,2,STONE)
B(-9,-8,3,STONE)
B(-9,-8,4,STONE)
B(-9,-8,5,STONE)
B(-9,-8,6,STONE)
B(-9,-8,7,STONE)
B(-9,-8,8,AIR)
B(-9,-8,9,AIR)
B(-9,-8,10,AIR)
B(-9,-8,11,STONE)
B(-9,-8,12,STONE)
B(-9,-8,13,STONE)
B(-9,-8,14,STONE)
B(-9,-7,-6,STONE)
B(-9,-7,-4,STONE)
B(-9,-7,-3,STONE)
B(-9,-7,-2,STONE)
B(-9,-7,-1,STONE)
B(-9,-7,0,STONE)
B(-9,-7,1,STONE)
B(-9,-7,2,STONE)
B(-9,-7,3,STONE)
B(-9,-7,4,STONE)
B(-9,-7,5,STONE)
B(-9,-7,6,STONE)
B(-9,-7,7,AIR)
B(-9,-7,8,AIR)
B(-9,-7,9,AIR)
B(-9,-7,10,AIR)
B(-9,-7,11,STONE)
B(-9,-7,12,STONE)
B(-9,-7,13,STONE)
B(-9,-7,14,STONE)
B(-9,-6,-2,STONE)
B(-9,-6,-1,STONE)
B(-9,-6,0,STONE)
B(-9,-6,1,STONE)
B(-9,-6,2,STONE)
B(-9,-6,3,STONE)
B(-9,-6,4,STONE)
B(-9,-6,5,STONE)
B(-9,-6,6,AIR)
B(-9,-6,7,AIR)
B(-9,-6,8,AIR)
B(-9,-6,9,AIR)
B(-9,-6,10,AIR)
B(-9,-6,11,STONE)
B(-9,-6,12,STONE)
B(-9,-6,13,STONE)
B(-9,-6,14,STONE)
B(-9,-5,-2,STONE)
B(-9,-5,-1,STONE)
B(-9,-5,0,STONE)
B(-9,-5,1,STONE)
B(-9,-5,2,STONE)
B(-9,-5,3,STONE)
B(-9,-5,4,STONE)
B(-9,-5,5,AIR)
B(-9,-5,6,AIR)
B(-9,-5,7,AIR)
B(-9,-5,8,AIR)
B(-9,-5,9,AIR)
B(-9,-5,10,AIR)
B(-9,-5,11,STONE)
B(-9,-5,12,STONE)
B(-9,-5,13,STONE)
B(-9,-5,14,STONE)
B(-9,-4,-1,STONE)
B(-9,-4,0,STONE)
B(-9,-4,1,STONE)
B(-9,-4,2,STONE)
B(-9,-4,3,AIR)
B(-9,-4,4,AIR)
B(-9,-4,5,AIR)
B(-9,-4,6,AIR)
B(-9,-4,7,AIR)
B(-9,-4,8,AIR)
B(-9,-4,9,AIR)
B(-9,-4,10,STONE)
B(-9,-4,11,STONE)
B(-9,-4,12,STONE)
B(-9,-4,13,STONE)
B(-9,-4,14,STONE)
B(-9,-3,-1,STONE)
B(-9,-3,0,STONE)
B(-9,-3,1,STONE)
B(-9,-3,2,AIR)
B(-9,-3,3,AIR)
B(-9,-3,4,AIR)
B(-9,-3,5,AIR)
B(-9,-3,6,AIR)
B(-9,-3,7,AIR)
B(-9,-3,8,AIR)
B(-9,-3,9,AIR)
B(-9,-3,10,STONE)
B(-9,-3,11,STONE)
B(-9,-3,12,STONE)
B(-9,-3,13,STONE)
B(-9,-3,14,STONE)
B(-9,-2,0,STONE)
B(-9,-2,1,STONE)
B(-9,-2,2,STONE)
B(-9,-2,3,AIR)
B(-9,-2,4,AIR)
B(-9,-2,5,AIR)
B(-9,-2,6,AIR)
B(-9,-2,7,AIR)
B(-9,-2,8,AIR)
B(-9,-2,9,AIR)
B(-9,-2,10,STONE)
B(-9,-2,11,STONE)
B(-9,-2,12,STONE)
B(-9,-2,13,STONE)
B(-9,-2,14,STONE)
B(-9,-1,1,STONE)
B(-9,-1,2,STONE)
B(-9,-1,3,STONE)
B(-9,-1,4,STONE)
B(-9,-1,5,AIR)
B(-9,-1,6,AIR)
B(-9,-1,7,AIR)
B(-9,-1,8,AIR)
B(-9,-1,9,STONE)
B(-9,-1,10,STONE)
B(-9,-1,11,STONE)
B(-9,-1,12,STONE)
B(-9,-1,13,STONE)
B(-9,-1,14,STONE)
B(-9,0,1,STONE)
B(-9,0,2,STONE)
B(-9,0,3,STONE)
B(-9,0,4,STONE)
B(-9,0,5,STONE)
B(-9,0,6,AIR)
B(-9,0,6,AIR)
B(-9,0,7,STONE)
B(-9,0,8,MOSSY_COBBLESTONE)
B(-9,0,9,STONE)
B(-9,0,10,MOSSY_COBBLESTONE)
B(-9,0,11,MOSSY_COBBLESTONE)
B(-9,0,12,STONE)
B(-9,0,13,STONE)
B(-9,0,14,STONE)
B(-9,1,2,STONE)
B(-9,1,3,STONE)
B(-9,1,4,STONE)
B(-9,1,5,STONE)
B(-9,1,6,STONE)
B(-9,1,7,MOSSY_COBBLESTONE)
B(-9,1,8,STONE)
B(-9,1,9,STONE)
B(-9,1,10,STONE)
B(-9,1,11,MOSSY_COBBLESTONE)
B(-9,1,12,MOSSY_COBBLESTONE)
B(-9,1,13,STONE)
B(-9,2,6,STONE)
B(-8,-20,-1,STONE)
B(-8,-20,0,STONE)
B(-8,-20,2,STONE)
B(-8,-20,3,STONE)
B(-8,-20,4,STONE)
B(-8,-19,-1,STONE)
B(-8,-19,0,STONE)
B(-8,-19,1,STONE)
B(-8,-19,2,STONE)
B(-8,-19,3,STONE)
B(-8,-19,5,STONE)
B(-8,-19,6,STONE)
B(-8,-19,7,STONE)
B(-8,-19,8,STONE)
B(-8,-19,9,STONE)
B(-8,-18,-1,STONE)
B(-8,-18,0,STONE)
B(-8,-18,1,STONE)
B(-8,-18,2,STONE)
B(-8,-18,3,STONE)
B(-8,-18,4,STONE)
B(-8,-18,5,STONE)
B(-8,-18,6,STONE)
B(-8,-18,7,STONE)
B(-8,-18,8,STONE)
B(-8,-18,9,STONE)
B(-8,-18,10,STONE)
B(-8,-18,11,STONE)
B(-8,-17,-2,STONE)
B(-8,-17,-1,STONE)
B(-8,-17,0,STONE)
B(-8,-17,1,STONE)
B(-8,-17,2,STONE)
B(-8,-17,3,STONE)
B(-8,-17,4,STONE)
B(-8,-17,5,STONE)
B(-8,-17,6,STONE)
B(-8,-17,7,STONE)
B(-8,-17,8,STONE)
B(-8,-17,9,STONE)
B(-8,-17,10,STONE)
B(-8,-17,11,STONE)
B(-8,-16,-3,STONE)
B(-8,-16,-2,STONE)
B(-8,-16,-1,STONE)
B(-8,-16,0,STONE)
B(-8,-16,1,STONE)
B(-8,-16,2,STONE)
B(-8,-16,3,STATIONARY_WATER)
B(-8,-16,4,STATIONARY_WATER)
B(-8,-16,5,STONE)
B(-8,-16,6,STONE)
B(-8,-16,7,STONE)
B(-8,-16,8,STONE)
B(-8,-16,9,STONE)
B(-8,-16,10,STONE)
B(-8,-16,11,STONE)
B(-8,-16,12,STONE)
B(-8,-15,-8,STONE)
B(-8,-15,-7,STONE)
B(-8,-15,-5,STONE)
B(-8,-15,-4,STONE)
B(-8,-15,-3,STONE)
B(-8,-15,-2,STONE)
B(-8,-15,-1,STONE)
B(-8,-15,0,STONE)
B(-8,-15,1,STONE)
B(-8,-15,2,STONE)
B(-8,-15,3,STATIONARY_WATER)
B(-8,-15,4,STATIONARY_WATER)
B(-8,-15,5,STATIONARY_WATER)
B(-8,-15,6,STATIONARY_WATER)
B(-8,-15,7,STATIONARY_WATER)
B(-8,-15,8,STATIONARY_WATER)
B(-8,-15,9,STONE)
B(-8,-15,10,STONE)
B(-8,-15,11,STONE)
B(-8,-15,12,STONE)
B(-8,-15,13,STONE)
B(-8,-14,-7,STONE)
B(-8,-14,-6,STONE)
B(-8,-14,-5,STONE)
B(-8,-14,-4,STONE)
B(-8,-14,-3,STONE)
B(-8,-14,-2,STONE)
B(-8,-14,-1,STONE)
B(-8,-14,0,STONE)
B(-8,-14,1,AIR)
B(-8,-14,2,AIR)
B(-8,-14,3,AIR)
B(-8,-14,4,AIR)
B(-8,-14,5,AIR)
B(-8,-14,6,AIR)
B(-8,-14,7,AIR)
B(-8,-14,8,AIR)
B(-8,-14,9,STONE)
B(-8,-14,10,STONE)
B(-8,-14,11,STONE)
B(-8,-14,12,STONE)
B(-8,-14,13,STONE)
B(-8,-13,-8,STONE)
B(-8,-13,-7,STONE)
B(-8,-13,-6,STONE)
B(-8,-13,-5,STONE)
B(-8,-13,-4,STONE)
B(-8,-13,-3,STONE)
B(-8,-13,-2,STONE)
B(-8,-13,-1,STONE)
B(-8,-13,0,AIR)
B(-8,-13,1,AIR)
B(-8,-13,2,AIR)
B(-8,-13,3,AIR)
B(-8,-13,4,AIR)
B(-8,-13,5,AIR)
B(-8,-13,6,AIR)
B(-8,-13,7,AIR)
B(-8,-13,8,AIR)
B(-8,-13,9,STONE)
B(-8,-13,10,STONE)
B(-8,-13,11,STONE)
B(-8,-13,12,STONE)
B(-8,-13,13,STONE)
B(-8,-13,14,STONE)
B(-8,-12,-7,STONE)
B(-8,-12,-6,STONE)
B(-8,-12,-5,STONE)
B(-8,-12,-4,STONE)
B(-8,-12,-3,STONE)
B(-8,-12,-2,STONE)
B(-8,-12,-1,STONE)
B(-8,-12,0,AIR)
B(-8,-12,1,AIR)
B(-8,-12,2,AIR)
B(-8,-12,3,AIR)
B(-8,-12,4,AIR)
B(-8,-12,5,AIR)
B(-8,-12,6,AIR)
B(-8,-12,7,AIR)
B(-8,-12,8,AIR)
B(-8,-12,9,AIR)
B(-8,-12,10,STONE)
B(-8,-12,11,STONE)
B(-8,-12,12,STONE)
B(-8,-12,13,STONE)
B(-8,-12,14,STONE)
B(-8,-11,-6,STONE)
B(-8,-11,-5,STONE)
B(-8,-11,-4,STONE)
B(-8,-11,-3,STONE)
B(-8,-11,-2,STONE)
B(-8,-11,-1,STONE)
B(-8,-11,0,AIR)
B(-8,-11,1,AIR)
B(-8,-11,2,AIR)
B(-8,-11,3,AIR)
B(-8,-11,4,AIR)
B(-8,-11,5,AIR)
B(-8,-11,6,AIR)
B(-8,-11,7,AIR)
B(-8,-11,8,AIR)
B(-8,-11,9,AIR)
B(-8,-11,10,STONE)
B(-8,-11,11,STONE)
B(-8,-11,12,STONE)
B(-8,-11,13,STONE)
B(-8,-11,14,STONE)
B(-8,-10,-6,STONE)
B(-8,-10,-4,STONE)
B(-8,-10,-3,STONE)
B(-8,-10,-2,STONE)
B(-8,-10,-1,STONE)
B(-8,-10,0,AIR)
B(-8,-10,1,AIR)
B(-8,-10,2,AIR)
B(-8,-10,3,AIR)
B(-8,-10,4,AIR)
B(-8,-10,5,AIR)
B(-8,-10,6,AIR)
B(-8,-10,7,AIR)
B(-8,-10,8,AIR)
B(-8,-10,9,AIR)
B(-8,-10,10,AIR)
B(-8,-10,11,STONE)
B(-8,-10,12,STONE)
B(-8,-10,13,STONE)
B(-8,-10,14,STONE)
B(-8,-9,-6,STONE)
B(-8,-9,-5,STONE)
B(-8,-9,-4,STONE)
B(-8,-9,-3,STONE)
B(-8,-9,-2,STONE)
B(-8,-9,-1,STONE)
B(-8,-9,0,STONE)
B(-8,-9,1,STONE)
B(-8,-9,2,AIR)
B(-8,-9,3,AIR)
B(-8,-9,4,AIR)
B(-8,-9,5,AIR)
B(-8,-9,6,AIR)
B(-8,-9,7,AIR)
B(-8,-9,8,AIR)
B(-8,-9,9,AIR)
B(-8,-9,10,AIR)
B(-8,-9,11,STONE)
B(-8,-9,12,STONE)
B(-8,-9,13,STONE)
B(-8,-9,14,STONE)
B(-8,-8,-6,STONE)
B(-8,-8,-5,STONE)
B(-8,-8,-4,STONE)
B(-8,-8,-3,STONE)
B(-8,-8,-2,STONE)
B(-8,-8,-1,STONE)
B(-8,-8,0,STONE)
B(-8,-8,1,STONE)
B(-8,-8,2,STONE)
B(-8,-8,3,STONE)
B(-8,-8,4,STONE)
B(-8,-8,5,AIR)
B(-8,-8,6,AIR)
B(-8,-8,7,AIR)
B(-8,-8,8,AIR)
B(-8,-8,9,AIR)
B(-8,-8,10,AIR)
B(-8,-8,11,STONE)
B(-8,-8,12,STONE)
B(-8,-8,13,STONE)
B(-8,-8,14,STONE)
B(-8,-7,-6,STONE)
B(-8,-7,-5,STONE)
B(-8,-7,-4,STONE)
B(-8,-7,-3,STONE)
B(-8,-7,-2,STONE)
B(-8,-7,-1,STONE)
B(-8,-7,0,STONE)
B(-8,-7,1,STONE)
B(-8,-7,2,STONE)
B(-8,-7,3,STONE)
B(-8,-7,4,STONE)
B(-8,-7,5,STONE)
B(-8,-7,6,AIR)
B(-8,-7,7,AIR)
B(-8,-7,8,AIR)
B(-8,-7,9,AIR)
B(-8,-7,10,AIR)
B(-8,-7,11,AIR)
B(-8,-7,12,STONE)
B(-8,-7,13,STONE)
B(-8,-7,14,STONE)
B(-8,-6,-6,STONE)
B(-8,-6,-5,STONE)
B(-8,-6,-4,STONE)
B(-8,-6,-3,STONE)
B(-8,-6,-2,STONE)
B(-8,-6,-1,STONE)
B(-8,-6,0,STONE)
B(-8,-6,1,STONE)
B(-8,-6,2,STONE)
B(-8,-6,3,STONE)
B(-8,-6,4,STONE)
B(-8,-6,5,AIR)
B(-8,-6,6,AIR)
B(-8,-6,7,AIR)
B(-8,-6,8,AIR)
B(-8,-6,9,AIR)
B(-8,-6,10,AIR)
B(-8,-6,11,AIR)
B(-8,-6,12,STONE)
B(-8,-6,13,STONE)
B(-8,-6,14,STONE)
B(-8,-5,-6,STONE)
B(-8,-5,-5,STONE)
B(-8,-5,-4,STONE)
B(-8,-5,-3,STONE)
B(-8,-5,-2,STONE)
B(-8,-5,-1,STONE)
B(-8,-5,0,STONE)
B(-8,-5,1,STONE)
B(-8,-5,2,AIR)
B(-8,-5,3,AIR)
B(-8,-5,4,AIR)
B(-8,-5,5,AIR)
B(-8,-5,6,AIR)
B(-8,-5,7,AIR)
B(-8,-5,8,AIR)
B(-8,-5,9,AIR)
B(-8,-5,10,AIR)
B(-8,-5,11,AIR)
B(-8,-5,12,STONE)
B(-8,-5,13,STONE)
B(-8,-5,14,STONE)
B(-8,-4,-5,STONE)
B(-8,-4,-3,STONE)
B(-8,-4,-2,STONE)
B(-8,-4,-1,STONE)
B(-8,-4,0,AIR)
B(-8,-4,1,AIR)
B(-8,-4,2,AIR)
B(-8,-4,3,AIR)
B(-8,-4,4,AIR)
B(-8,-4,5,AIR)
B(-8,-4,6,AIR)
B(-8,-4,7,AIR)
B(-8,-4,8,AIR)
B(-8,-4,9,AIR)
B(-8,-4,10,AIR)
B(-8,-4,11,AIR)
B(-8,-4,12,STONE)
B(-8,-4,13,STONE)
B(-8,-4,14,STONE)
B(-8,-3,-2,STONE)
B(-8,-3,-1,STONE)
B(-8,-3,0,AIR)
B(-8,-3,1,AIR)
B(-8,-3,2,AIR)
B(-8,-3,3,AIR)
B(-8,-3,4,AIR)
B(-8,-3,5,AIR)
B(-8,-3,6,AIR)
B(-8,-3,7,AIR)
B(-8,-3,8,AIR)
B(-8,-3,9,AIR)
B(-8,-3,10,AIR)
B(-8,-3,11,STONE)
B(-8,-3,12,STONE)
B(-8,-3,13,STONE)
B(-8,-3,14,STONE)
B(-8,-2,-1,STONE)
B(-8,-2,0,STONE)
B(-8,-2,1,AIR)
B(-8,-2,2,AIR)
B(-8,-2,3,AIR)
B(-8,-2,4,AIR)
B(-8,-2,5,AIR)
B(-8,-2,6,AIR)
B(-8,-2,7,AIR)
B(-8,-2,8,AIR)
B(-8,-2,9,AIR)
B(-8,-2,10,AIR)
B(-8,-2,11,STONE)
B(-8,-2,12,STONE)
B(-8,-2,13,STONE)
B(-8,-2,14,STONE)
B(-8,-1,0,STONE)
B(-8,-1,1,STONE)
B(-8,-1,2,AIR)
B(-8,-1,3,AIR)
B(-8,-1,4,AIR)
B(-8,-1,5,AIR)
B(-8,-1,6,AIR)
B(-8,-1,7,AIR)
B(-8,-1,8,AIR)
B(-8,-1,9,AIR)
B(-8,-1,10,AIR)
B(-8,-1,11,STONE)
B(-8,-1,12,STONE)
B(-8,-1,13,STONE)
B(-8,-1,14,STONE)
B(-8,0,1,STONE)
B(-8,0,2,STONE)
B(-8,0,3,STONE)
B(-8,0,4,AIR)
B(-8,0,5,AIR)
B(-8,0,6,AIR)
B(-8,0,7,AIR)
B(-8,0,8,AIR)
B(-8,0,9,AIR)
B(-8,0,10,STONE)
B(-8,0,11,STONE)
B(-8,0,12,MOSSY_COBBLESTONE)
B(-8,0,13,STONE)
B(-8,0,14,STONE)
B(-8,1,1,STONE)
B(-8,1,2,STONE)
B(-8,1,3,STONE)
B(-8,1,4,STONE)
B(-8,1,5,MOSSY_COBBLESTONE)
B(-8,1,6,MOSSY_COBBLESTONE)
B(-8,1,7,STONE)
B(-8,1,8,MOSSY_COBBLESTONE)
B(-8,1,9,STONE)
B(-8,1,10,STONE)
B(-8,1,11,STONE)
B(-8,1,12,STONE)
B(-8,1,13,STONE)
B(-8,2,5,STONE)
B(-8,2,6,MOSSY_COBBLESTONE)
B(-8,2,9,STONE)
B(-8,2,10,STONE)
B(-8,2,11,STONE)
B(-7,-21,-1,STONE)
B(-7,-21,0,STONE)
B(-7,-21,2,STONE)
B(-7,-21,3,STONE)
B(-7,-21,4,STONE)
B(-7,-21,5,STONE)
B(-7,-20,0,STONE)
B(-7,-20,1,STONE)
B(-7,-20,2,STONE)
B(-7,-20,3,STONE)
B(-7,-20,4,STONE)
B(-7,-20,5,STONE)
B(-7,-20,6,STONE)
B(-7,-19,-1,STONE)
B(-7,-19,0,STONE)
B(-7,-19,1,STONE)
B(-7,-19,2,STONE)
B(-7,-19,3,STONE)
B(-7,-19,4,STONE)
B(-7,-19,5,STONE)
B(-7,-19,6,STONE)
B(-7,-19,7,STONE)
B(-7,-19,11,STONE)
B(-7,-18,-1,STONE)
B(-7,-18,0,STONE)
B(-7,-18,1,STONE)
B(-7,-18,2,STONE)
B(-7,-18,3,STONE)
B(-7,-18,4,STONE)
B(-7,-18,5,STONE)
B(-7,-18,6,STONE)
B(-7,-18,7,STONE)
B(-7,-18,8,STONE)
B(-7,-18,9,STONE)
B(-7,-18,10,STONE)
B(-7,-18,11,STONE)
B(-7,-17,-1,STONE)
B(-7,-17,0,STONE)
B(-7,-17,1,STONE)
B(-7,-17,2,STONE)
B(-7,-17,3,STATIONARY_WATER)
B(-7,-17,4,STATIONARY_WATER)
B(-7,-17,5,STONE)
B(-7,-17,6,STONE)
B(-7,-17,7,STONE)
B(-7,-17,8,STONE)
B(-7,-17,9,STONE)
B(-7,-17,10,STONE)
B(-7,-17,11,STONE)
B(-7,-17,12,STONE)
B(-7,-16,-2,STONE)
B(-7,-16,-1,STONE)
B(-7,-16,0,STONE)
B(-7,-16,1,STONE)
B(-7,-16,2,STATIONARY_WATER)
B(-7,-16,3,STATIONARY_WATER)
B(-7,-16,4,STATIONARY_WATER)
B(-7,-16,5,STONE)
B(-7,-16,6,STONE)
B(-7,-16,7,STONE)
B(-7,-16,8,STONE)
B(-7,-16,9,STONE)
B(-7,-16,10,STONE)
B(-7,-16,11,STONE)
B(-7,-16,12,STONE)
B(-7,-16,13,STONE)
B(-7,-16,14,STONE)
B(-7,-15,-9,STONE)
B(-7,-15,-8,STONE)
B(-7,-15,-7,STONE)
B(-7,-15,-5,STONE)
B(-7,-15,-4,STONE)
B(-7,-15,-3,STONE)
B(-7,-15,-2,STONE)
B(-7,-15,-1,STONE)
B(-7,-15,0,STONE)
B(-7,-15,1,STATIONARY_WATER)
B(-7,-15,2,STATIONARY_WATER)
B(-7,-15,3,STATIONARY_WATER)
B(-7,-15,4,STATIONARY_WATER)
B(-7,-15,5,STATIONARY_WATER)
B(-7,-15,6,STATIONARY_WATER)
B(-7,-15,7,STATIONARY_WATER)
B(-7,-15,8,STATIONARY_WATER)
B(-7,-15,9,STONE)
B(-7,-15,10,STONE)
B(-7,-15,11,STONE)
B(-7,-15,12,STONE)
B(-7,-15,13,STONE)
B(-7,-15,14,STONE)
B(-7,-14,-9,STONE)
B(-7,-14,-8,STONE)
B(-7,-14,-7,STONE)
B(-7,-14,-6,STONE)
B(-7,-14,-5,STONE)
B(-7,-14,-4,STONE)
B(-7,-14,-3,STONE)
B(-7,-14,-2,STONE)
B(-7,-14,-1,STONE)
RB(-7,-14,0,CHEST,../../nbt/VanillaLoot/simple_dungeon.nbt,50,CHEST,../../nbt/VanillaLoot/stronghold_crossing.nbt,100)
B(-7,-14,1,AIR)
B(-7,-14,2,AIR)
B(-7,-14,3,AIR)
B(-7,-14,4,AIR)
B(-7,-14,5,AIR)
B(-7,-14,6,AIR)
B(-7,-14,7,AIR)
B(-7,-14,8,AIR)
B(-7,-14,9,AIR)
B(-7,-14,10,STONE)
B(-7,-14,11,STONE)
B(-7,-14,12,STONE)
B(-7,-14,13,STONE)
B(-7,-14,14,STONE)
B(-7,-13,-10,STONE)
B(-7,-13,-9,STONE)
B(-7,-13,-8,STONE)
B(-7,-13,-7,STONE)
B(-7,-13,-6,STONE)
B(-7,-13,-5,STONE)
B(-7,-13,-4,STONE)
B(-7,-13,-3,STONE)
B(-7,-13,-2,STONE)
B(-7,-13,-1,STONE)
B(-7,-13,0,AIR)
B(-7,-13,1,AIR)
B(-7,-13,2,AIR)
B(-7,-13,3,AIR)
B(-7,-13,4,AIR)
B(-7,-13,5,AIR)
B(-7,-13,6,AIR)
B(-7,-13,7,AIR)
B(-7,-13,8,AIR)
B(-7,-13,9,AIR)
B(-7,-13,10,STONE)
B(-7,-13,11,STONE)
B(-7,-13,12,STONE)
B(-7,-13,13,STONE)
B(-7,-13,14,STONE)
B(-7,-12,-8,STONE)
B(-7,-12,-7,STONE)
B(-7,-12,-6,STONE)
B(-7,-12,-5,STONE)
B(-7,-12,-4,STONE)
B(-7,-12,-3,STONE)
B(-7,-12,-2,STONE)
B(-7,-12,-1,STONE)
B(-7,-12,0,AIR)
B(-7,-12,1,AIR)
B(-7,-12,2,AIR)
B(-7,-12,3,AIR)
B(-7,-12,4,AIR)
B(-7,-12,5,AIR)
B(-7,-12,6,AIR)
B(-7,-12,7,AIR)
B(-7,-12,8,AIR)
B(-7,-12,9,AIR)
B(-7,-12,10,STONE)
B(-7,-12,11,STONE)
B(-7,-12,12,STONE)
B(-7,-12,13,STONE)
B(-7,-12,14,STONE)
B(-7,-11,-7,STONE)
B(-7,-11,-6,STONE)
B(-7,-11,-5,STONE)
B(-7,-11,-4,STONE)
B(-7,-11,-3,STONE)
B(-7,-11,-2,STONE)
B(-7,-11,-1,STONE)
B(-7,-11,0,AIR)
B(-7,-11,1,AIR)
B(-7,-11,2,AIR)
B(-7,-11,3,AIR)
B(-7,-11,4,AIR)
B(-7,-11,5,AIR)
B(-7,-11,6,AIR)
B(-7,-11,7,AIR)
B(-7,-11,8,AIR)
B(-7,-11,9,AIR)
B(-7,-11,10,AIR)
B(-7,-11,11,STONE)
B(-7,-11,12,STONE)
B(-7,-11,13,STONE)
B(-7,-11,14,STONE)
B(-7,-10,-7,STONE)
B(-7,-10,-6,STONE)
B(-7,-10,-5,STONE)
B(-7,-10,-4,STONE)
B(-7,-10,-3,STONE)
B(-7,-10,-2,STONE)
B(-7,-10,-1,STONE)
B(-7,-10,0,AIR)
B(-7,-10,1,AIR)
B(-7,-10,2,AIR)
B(-7,-10,3,AIR)
B(-7,-10,4,AIR)
B(-7,-10,5,AIR)
B(-7,-10,6,AIR)
B(-7,-10,7,AIR)
B(-7,-10,8,AIR)
B(-7,-10,9,AIR)
B(-7,-10,10,AIR)
B(-7,-10,11,STONE)
B(-7,-10,12,STONE)
B(-7,-10,13,STONE)
B(-7,-10,14,STONE)
B(-7,-9,-6,STONE)
B(-7,-9,-5,STONE)
B(-7,-9,-4,STONE)
B(-7,-9,-3,STONE)
B(-7,-9,-2,STONE)
B(-7,-9,-1,STONE)
B(-7,-9,0,STONE)
B(-7,-9,1,STONE)
B(-7,-9,2,AIR)
B(-7,-9,3,AIR)
B(-7,-9,4,AIR)
B(-7,-9,5,AIR)
B(-7,-9,6,AIR)
B(-7,-9,7,AIR)
B(-7,-9,8,AIR)
B(-7,-9,9,AIR)
B(-7,-9,10,AIR)
B(-7,-9,11,STONE)
B(-7,-9,12,STONE)
B(-7,-9,13,STONE)
B(-7,-9,14,STONE)
B(-7,-8,-7,STONE)
B(-7,-8,-6,STONE)
B(-7,-8,-5,STONE)
B(-7,-8,-4,STONE)
B(-7,-8,-3,STONE)
B(-7,-8,-2,STONE)
B(-7,-8,-1,STONE)
B(-7,-8,0,STONE)
B(-7,-8,1,STONE)
B(-7,-8,2,STONE)
B(-7,-8,3,STONE)
B(-7,-8,4,AIR)
B(-7,-8,5,AIR)
B(-7,-8,6,AIR)
B(-7,-8,7,AIR)
B(-7,-8,8,AIR)
B(-7,-8,9,AIR)
B(-7,-8,10,AIR)
B(-7,-8,11,STONE)
B(-7,-8,12,STONE)
B(-7,-8,13,STONE)
B(-7,-7,-6,STONE)
B(-7,-7,-5,STONE)
B(-7,-7,-4,STONE)
B(-7,-7,-3,STONE)
B(-7,-7,-2,STONE)
B(-7,-7,-1,STONE)
B(-7,-7,0,STONE)
B(-7,-7,1,STONE)
B(-7,-7,2,STONE)
B(-7,-7,3,STONE)
B(-7,-7,4,STONE)
B(-7,-7,5,AIR)
B(-7,-7,6,AIR)
B(-7,-7,7,AIR)
B(-7,-7,8,AIR)
B(-7,-7,9,AIR)
B(-7,-7,10,AIR)
B(-7,-7,11,AIR)
B(-7,-7,12,STONE)
B(-7,-7,13,STONE)
B(-7,-7,14,STONE)
B(-7,-6,-6,STONE)
B(-7,-6,-5,STONE)
B(-7,-6,-4,STONE)
B(-7,-6,-3,STONE)
B(-7,-6,-2,STONE)
B(-7,-6,-1,STONE)
B(-7,-6,0,STONE)
B(-7,-6,1,STONE)
B(-7,-6,2,STONE)
B(-7,-6,3,STONE)
B(-7,-6,4,AIR)
B(-7,-6,5,AIR)
B(-7,-6,6,AIR)
B(-7,-6,7,AIR)
B(-7,-6,8,AIR)
B(-7,-6,9,AIR)
B(-7,-6,10,AIR)
B(-7,-6,11,AIR)
B(-7,-6,12,STONE)
B(-7,-6,13,STONE)
B(-7,-6,14,STONE)
B(-7,-5,-6,STONE)
B(-7,-5,-5,STONE)
B(-7,-5,-4,STONE)
B(-7,-5,-3,STONE)
B(-7,-5,-2,STONE)
B(-7,-5,-1,STONE)
B(-7,-5,0,STONE)
B(-7,-5,1,AIR)
B(-7,-5,2,AIR)
B(-7,-5,3,AIR)
B(-7,-5,4,AIR)
B(-7,-5,5,AIR)
B(-7,-5,6,AIR)
B(-7,-5,7,AIR)
B(-7,-5,8,AIR)
B(-7,-5,9,AIR)
B(-7,-5,10,AIR)
B(-7,-5,11,AIR)
B(-7,-5,12,STONE)
B(-7,-5,13,STONE)
B(-7,-5,14,STONE)
B(-7,-4,-6,STONE)
B(-7,-4,-5,STONE)
B(-7,-4,-4,STONE)
B(-7,-4,-3,STONE)
B(-7,-4,-2,STONE)
B(-7,-4,-1,STONE)
B(-7,-4,0,AIR)
B(-7,-4,1,AIR)
B(-7,-4,2,AIR)
B(-7,-4,3,AIR)
B(-7,-4,4,AIR)
B(-7,-4,5,AIR)
B(-7,-4,6,AIR)
B(-7,-4,7,AIR)
B(-7,-4,8,AIR)
B(-7,-4,9,AIR)
B(-7,-4,10,AIR)
B(-7,-4,11,AIR)
B(-7,-4,12,STONE)
B(-7,-4,13,STONE)
B(-7,-4,14,STONE)
B(-7,-3,-5,STONE)
B(-7,-3,-4,STONE)
B(-7,-3,-3,STONE)
B(-7,-3,-2,STONE)
B(-7,-3,-1,STONE)
B(-7,-3,0,AIR)
B(-7,-3,1,AIR)
B(-7,-3,2,AIR)
B(-7,-3,3,AIR)
B(-7,-3,4,AIR)
B(-7,-3,5,AIR)
B(-7,-3,6,AIR)
B(-7,-3,7,AIR)
B(-7,-3,8,AIR)
B(-7,-3,9,AIR)
B(-7,-3,10,AIR)
B(-7,-3,11,AIR)
B(-7,-3,12,STONE)
B(-7,-3,13,STONE)
B(-7,-3,14,STONE)
B(-7,-2,-1,STONE)
B(-7,-2,0,AIR)
B(-7,-2,1,AIR)
B(-7,-2,2,AIR)
B(-7,-2,3,AIR)
B(-7,-2,4,AIR)
B(-7,-2,5,AIR)
B(-7,-2,6,AIR)
B(-7,-2,7,AIR)
B(-7,-2,8,AIR)
B(-7,-2,9,AIR)
B(-7,-2,10,AIR)
B(-7,-2,11,AIR)
B(-7,-2,12,STONE)
B(-7,-2,13,STONE)
B(-7,-2,14,STONE)
B(-7,-1,0,STONE)
B(-7,-1,1,STONE)
B(-7,-1,2,AIR)
B(-7,-1,3,AIR)
B(-7,-1,4,AIR)
B(-7,-1,5,AIR)
B(-7,-1,6,AIR)
B(-7,-1,7,AIR)
B(-7,-1,8,AIR)
B(-7,-1,9,AIR)
B(-7,-1,10,AIR)
B(-7,-1,11,STONE)
B(-7,-1,12,STONE)
B(-7,-1,13,STONE)
B(-7,-1,14,STONE)
B(-7,0,1,STONE)
B(-7,0,2,STONE)
B(-7,0,3,STONE)
B(-7,0,4,AIR)
B(-7,0,5,AIR)
B(-7,0,6,AIR)
B(-7,0,7,AIR)
B(-7,0,8,AIR)
B(-7,0,9,AIR)
B(-7,0,10,AIR)
B(-7,0,11,MOSSY_COBBLESTONE)
B(-7,0,12,STONE)
B(-7,0,13,STONE)
B(-7,0,14,STONE)
B(-7,1,1,STONE)
B(-7,1,2,STONE)
B(-7,1,3,STONE)
B(-7,1,4,STONE)
B(-7,1,5,STONE)
B(-7,1,6,STONE)
B(-7,1,7,AIR)
B(-7,1,8,AIR)
B(-7,1,9,STONE)
B(-7,1,10,MOSSY_COBBLESTONE)
B(-7,1,11,STONE)
B(-7,1,12,MOSSY_COBBLESTONE)
B(-7,2,4,STONE)
B(-7,2,5,STONE)
B(-7,2,6,MOSSY_COBBLESTONE)
B(-7,2,7,STONE)
B(-7,2,8,STONE)
B(-7,2,9,STONE)
B(-7,2,10,STONE)
B(-7,3,5,MOSSY_COBBLESTONE)
B(-6,-21,0,STONE)
B(-6,-21,2,STONE)
B(-6,-21,3,STONE)
B(-6,-21,4,STONE)
B(-6,-20,-1,STONE)
B(-6,-20,0,STONE)
B(-6,-20,1,STONE)
B(-6,-20,2,STONE)
B(-6,-20,3,STONE)
B(-6,-20,4,STONE)
B(-6,-20,5,STONE)
B(-6,-19,-1,STONE)
B(-6,-19,0,STONE)
B(-6,-19,1,STONE)
B(-6,-19,2,STONE)
B(-6,-19,3,STONE)
B(-6,-19,4,STONE)
B(-6,-19,5,STONE)
B(-6,-19,6,STONE)
B(-6,-18,-1,STONE)
B(-6,-18,0,STONE)
B(-6,-18,1,STONE)
B(-6,-18,2,STONE)
B(-6,-18,3,STATIONARY_WATER)
B(-6,-18,4,STATIONARY_WATER)
B(-6,-18,5,STONE)
B(-6,-18,6,STONE)
B(-6,-18,7,STONE)
B(-6,-18,8,STONE)
B(-6,-18,9,STONE)
B(-6,-18,10,STONE)
B(-6,-17,-2,MOSSY_COBBLESTONE)
B(-6,-17,-1,STONE)
B(-6,-17,0,MOSSY_COBBLESTONE)
B(-6,-17,1,MOSSY_COBBLESTONE)
B(-6,-17,2,STATIONARY_WATER)
B(-6,-17,3,STATIONARY_WATER)
B(-6,-17,4,STATIONARY_WATER)
B(-6,-17,5,STONE)
B(-6,-17,6,STONE)
B(-6,-17,7,STONE)
B(-6,-17,8,STONE)
B(-6,-17,9,STONE)
B(-6,-17,10,STONE)
B(-6,-17,11,STONE)
B(-6,-16,-3,STONE)
B(-6,-16,-2,STONE)
B(-6,-16,-1,STONE)
B(-6,-16,0,STONE)
B(-6,-16,1,STATIONARY_WATER)
B(-6,-16,2,STATIONARY_WATER)
B(-6,-16,3,STATIONARY_WATER)
B(-6,-16,4,STATIONARY_WATER)
B(-6,-16,5,STONE)
B(-6,-16,6,STONE)
B(-6,-16,7,STONE)
B(-6,-16,8,STONE)
B(-6,-16,9,STONE)
B(-6,-16,10,STONE)
B(-6,-16,11,STONE)
B(-6,-16,12,STONE)
B(-6,-15,-9,STONE)
B(-6,-15,-8,STONE)
B(-6,-15,-7,STONE)
B(-6,-15,-6,STONE)
B(-6,-15,-5,STONE)
B(-6,-15,-4,STONE)
B(-6,-15,-3,STONE)
B(-6,-15,-2,STONE)
B(-6,-15,-1,STONE)
B(-6,-15,0,STATIONARY_WATER)
B(-6,-15,1,STATIONARY_WATER)
B(-6,-15,2,STATIONARY_WATER)
B(-6,-15,3,STATIONARY_WATER)
B(-6,-15,4,STATIONARY_WATER)
B(-6,-15,5,STATIONARY_WATER)
B(-6,-15,6,STATIONARY_WATER)
B(-6,-15,7,STATIONARY_WATER)
B(-6,-15,8,STATIONARY_WATER)
B(-6,-15,9,STONE)
B(-6,-15,10,STONE)
B(-6,-15,11,STONE)
B(-6,-15,12,STONE)
B(-6,-15,13,STONE)
B(-6,-14,-9,STONE)
B(-6,-14,-8,STONE)
B(-6,-14,-7,STONE)
B(-6,-14,-6,STONE)
B(-6,-14,-5,STONE)
B(-6,-14,-4,STONE)
B(-6,-14,-3,STONE)
B(-6,-14,-2,STONE)
B(-6,-14,-1,AIR)
B(-6,-14,0,AIR)
B(-6,-14,1,AIR)
B(-6,-14,2,AIR)
B(-6,-14,3,AIR)
B(-6,-14,4,AIR)
B(-6,-14,5,AIR)
B(-6,-14,6,AIR)
B(-6,-14,7,AIR)
B(-6,-14,8,AIR)
B(-6,-14,9,AIR)
B(-6,-14,10,STONE)
B(-6,-14,11,STONE)
B(-6,-14,12,STONE)
B(-6,-14,13,STONE)
B(-6,-14,14,STONE)
B(-6,-13,-10,STONE)
B(-6,-13,-9,STONE)
B(-6,-13,-8,STONE)
B(-6,-13,-7,STONE)
B(-6,-13,-6,STONE)
B(-6,-13,-5,STONE)
B(-6,-13,-4,STONE)
B(-6,-13,-3,MOSSY_COBBLESTONE)
B(-6,-13,-2,STONE)
B(-6,-13,-1,AIR)
B(-6,-13,0,AIR)
B(-6,-13,1,AIR)
B(-6,-13,2,AIR)
B(-6,-13,3,AIR)
B(-6,-13,4,AIR)
B(-6,-13,5,AIR)
B(-6,-13,6,AIR)
B(-6,-13,7,AIR)
B(-6,-13,8,AIR)
B(-6,-13,9,AIR)
B(-6,-13,10,AIR)
B(-6,-13,11,STONE)
B(-6,-13,12,STONE)
B(-6,-13,13,STONE)
B(-6,-13,14,STONE)
B(-6,-12,-10,STONE)
B(-6,-12,-9,STONE)
B(-6,-12,-8,STONE)
B(-6,-12,-7,STONE)
B(-6,-12,-6,STONE)
B(-6,-12,-5,STONE)
B(-6,-12,-4,STONE)
B(-6,-12,-3,MOSSY_COBBLESTONE)
B(-6,-12,-2,MOSSY_COBBLESTONE)
B(-6,-12,-1,AIR)
B(-6,-12,0,AIR)
B(-6,-12,1,AIR)
B(-6,-12,2,AIR)
B(-6,-12,3,AIR)
B(-6,-12,4,AIR)
B(-6,-12,5,AIR)
B(-6,-12,6,AIR)
B(-6,-12,7,AIR)
B(-6,-12,8,AIR)
B(-6,-12,9,AIR)
B(-6,-12,10,AIR)
B(-6,-12,11,STONE)
B(-6,-12,12,STONE)
B(-6,-12,13,STONE)
B(-6,-12,14,STONE)
B(-6,-11,-8,STONE)
B(-6,-11,-7,STONE)
B(-6,-11,-6,STONE)
B(-6,-11,-5,STONE)
B(-6,-11,-4,MOSSY_COBBLESTONE)
B(-6,-11,-3,STONE)
B(-6,-11,-2,STONE)
B(-6,-11,-1,AIR)
B(-6,-11,0,AIR)
B(-6,-11,1,AIR)
B(-6,-11,2,AIR)
B(-6,-11,3,AIR)
B(-6,-11,4,AIR)
B(-6,-11,5,AIR)
B(-6,-11,6,AIR)
B(-6,-11,7,AIR)
B(-6,-11,8,AIR)
B(-6,-11,9,AIR)
B(-6,-11,10,AIR)
B(-6,-11,11,STONE)
B(-6,-11,12,STONE)
B(-6,-11,13,STONE)
B(-6,-11,14,STONE)
B(-6,-10,-8,STONE)
B(-6,-10,-7,STONE)
B(-6,-10,-6,STONE)
B(-6,-10,-5,STONE)
B(-6,-10,-4,STONE)
B(-6,-10,-3,STONE)
B(-6,-10,-2,STONE)
B(-6,-10,-1,STONE)
B(-6,-10,0,STONE)
B(-6,-10,1,AIR)
B(-6,-10,2,AIR)
B(-6,-10,3,AIR)
B(-6,-10,4,AIR)
B(-6,-10,5,AIR)
B(-6,-10,6,AIR)
B(-6,-10,7,AIR)
B(-6,-10,8,AIR)
B(-6,-10,9,AIR)
B(-6,-10,10,AIR)
B(-6,-10,11,STONE)
B(-6,-10,12,STONE)
B(-6,-9,-7,STONE)
B(-6,-9,-6,STONE)
B(-6,-9,-5,STONE)
B(-6,-9,-4,STONE)
B(-6,-9,-3,STONE)
B(-6,-9,-2,STONE)
B(-6,-9,-1,STONE)
B(-6,-9,0,STONE)
B(-6,-9,1,STONE)
B(-6,-9,2,AIR)
B(-6,-9,3,AIR)
B(-6,-9,4,AIR)
B(-6,-9,5,AIR)
B(-6,-9,6,AIR)
B(-6,-9,7,AIR)
B(-6,-9,8,AIR)
B(-6,-9,9,AIR)
B(-6,-9,10,AIR)
B(-6,-9,11,STONE)
B(-6,-8,-6,STONE)
B(-6,-8,-5,STONE)
B(-6,-8,-4,STONE)
B(-6,-8,-3,STONE)
B(-6,-8,-2,STONE)
B(-6,-8,-1,STONE)
B(-6,-8,0,STONE)
B(-6,-8,1,STONE)
B(-6,-8,2,STONE)
B(-6,-8,3,AIR)
B(-6,-8,4,AIR)
B(-6,-8,5,AIR)
B(-6,-8,6,AIR)
B(-6,-8,7,AIR)
B(-6,-8,8,AIR)
B(-6,-8,9,AIR)
B(-6,-8,10,AIR)
B(-6,-8,11,STONE)
B(-6,-7,-6,STONE)
B(-6,-7,-5,STONE)
B(-6,-7,-4,STONE)
B(-6,-7,-3,STONE)
B(-6,-7,-2,STONE)
B(-6,-7,-1,STONE)
B(-6,-7,0,STONE)
B(-6,-7,1,STONE)
B(-6,-7,2,STONE)
B(-6,-7,3,STONE)
B(-6,-7,4,STONE)
B(-6,-7,5,AIR)
B(-6,-7,6,AIR)
B(-6,-7,7,AIR)
B(-6,-7,8,AIR)
B(-6,-7,9,AIR)
B(-6,-7,10,AIR)
B(-6,-7,11,STONE)
B(-6,-6,-6,STONE)
B(-6,-6,-5,STONE)
B(-6,-6,-4,STONE)
B(-6,-6,-3,STONE)
B(-6,-6,-2,STONE)
B(-6,-6,-1,STONE)
B(-6,-6,0,STONE)
B(-6,-6,1,STONE)
B(-6,-6,2,STONE)
B(-6,-6,3,AIR)
B(-6,-6,4,AIR)
B(-6,-6,5,AIR)
B(-6,-6,6,AIR)
B(-6,-6,7,AIR)
B(-6,-6,8,AIR)
B(-6,-6,9,AIR)
B(-6,-6,10,AIR)
B(-6,-6,11,STONE)
B(-6,-6,12,STONE)
B(-6,-5,-6,STONE)
B(-6,-5,-5,STONE)
B(-6,-5,-4,STONE)
B(-6,-5,-3,STONE)
B(-6,-5,-2,STONE)
B(-6,-5,-1,STONE)
B(-6,-5,0,AIR)
B(-6,-5,1,AIR)
B(-6,-5,2,AIR)
B(-6,-5,3,AIR)
B(-6,-5,4,AIR)
B(-6,-5,5,AIR)
B(-6,-5,6,AIR)
B(-6,-5,7,AIR)
B(-6,-5,8,AIR)
B(-6,-5,9,AIR)
B(-6,-5,10,AIR)
B(-6,-5,11,AIR)
B(-6,-5,12,STONE)
B(-6,-5,13,STONE)
B(-6,-5,14,STONE)
B(-6,-4,-6,STONE)
B(-6,-4,-5,STONE)
B(-6,-4,-4,STONE)
B(-6,-4,-3,STONE)
B(-6,-4,-2,STONE)
B(-6,-4,-1,AIR)
B(-6,-4,0,AIR)
B(-6,-4,1,AIR)
B(-6,-4,2,AIR)
B(-6,-4,3,AIR)
B(-6,-4,4,AIR)
B(-6,-4,5,AIR)
B(-6,-4,6,AIR)
B(-6,-4,7,AIR)
B(-6,-4,8,AIR)
B(-6,-4,9,AIR)
B(-6,-4,10,AIR)
B(-6,-4,11,AIR)
B(-6,-4,12,STONE)
B(-6,-4,13,STONE)
B(-6,-4,14,STONE)
B(-6,-3,-5,STONE)
B(-6,-3,-4,STONE)
B(-6,-3,-3,STONE)
B(-6,-3,-2,STONE)
B(-6,-3,-1,AIR)
B(-6,-3,0,AIR)
B(-6,-3,1,AIR)
B(-6,-3,2,AIR)
B(-6,-3,3,AIR)
B(-6,-3,4,AIR)
B(-6,-3,5,AIR)
B(-6,-3,6,AIR)
B(-6,-3,7,AIR)
B(-6,-3,8,AIR)
B(-6,-3,9,AIR)
B(-6,-3,10,AIR)
B(-6,-3,11,AIR)
B(-6,-3,12,STONE)
B(-6,-3,13,STONE)
B(-6,-3,14,STONE)
B(-6,-2,-4,STONE)
B(-6,-2,-3,STONE)
B(-6,-2,-2,STONE)
B(-6,-2,-1,AIR)
B(-6,-2,0,AIR)
B(-6,-2,1,AIR)
B(-6,-2,2,AIR)
B(-6,-2,3,AIR)
B(-6,-2,4,AIR)
B(-6,-2,5,AIR)
B(-6,-2,6,AIR)
B(-6,-2,7,AIR)
B(-6,-2,8,AIR)
B(-6,-2,9,AIR)
B(-6,-2,10,AIR)
B(-6,-2,11,AIR)
B(-6,-2,12,STONE)
B(-6,-2,13,STONE)
B(-6,-2,14,STONE)
B(-6,-1,-1,STONE)
B(-6,-1,0,STONE)
B(-6,-1,1,AIR)
B(-6,-1,2,AIR)
B(-6,-1,3,AIR)
B(-6,-1,4,AIR)
B(-6,-1,5,AIR)
B(-6,-1,6,AIR)
B(-6,-1,7,AIR)
B(-6,-1,8,AIR)
B(-6,-1,9,AIR)
B(-6,-1,10,AIR)
B(-6,-1,11,AIR)
B(-6,-1,12,STONE)
B(-6,-1,13,STONE)
B(-6,-1,14,STONE)
B(-6,0,0,STONE)
B(-6,0,1,STONE)
B(-6,0,2,STONE)
B(-6,0,3,STONE)
B(-6,0,4,AIR)
B(-6,0,5,AIR)
B(-6,0,6,AIR)
B(-6,0,7,AIR)
B(-6,0,8,AIR)
B(-6,0,9,AIR)
B(-6,0,10,AIR)
B(-6,0,11,MOSSY_COBBLESTONE)
B(-6,0,12,STONE)
B(-6,0,13,STONE)
B(-6,1,0,STONE)
B(-6,1,1,STONE)
B(-6,1,2,STONE)
B(-6,1,3,STONE)
B(-6,1,4,STONE)
B(-6,1,5,STONE)
B(-6,1,6,AIR)
B(-6,1,7,AIR)
B(-6,1,8,AIR)
B(-6,1,9,AIR)
B(-6,1,10,STONE)
B(-6,1,11,STONE)
B(-6,2,3,STONE)
B(-6,2,4,STONE)
B(-6,2,5,STONE)
B(-6,2,6,STONE)
B(-6,2,7,STONE)
B(-6,2,8,STONE)
B(-6,2,9,STONE)
B(-6,2,10,STONE)
B(-6,3,5,STONE)
B(-5,-21,0,STONE)
B(-5,-21,1,STONE)
B(-5,-21,2,STONE)
B(-5,-20,-1,STONE)
B(-5,-20,0,STONE)
B(-5,-20,1,STONE)
B(-5,-20,2,STONE)
B(-5,-20,3,STONE)
B(-5,-20,4,STONE)
B(-5,-19,-1,STONE)
B(-5,-19,0,STONE)
B(-5,-19,1,STONE)
B(-5,-19,2,STONE)
B(-5,-19,3,STONE)
B(-5,-19,4,STONE)
B(-5,-19,5,STONE)
B(-5,-18,-1,STONE)
B(-5,-18,0,STONE)
B(-5,-18,1,STONE)
B(-5,-18,2,STONE)
B(-5,-18,3,STATIONARY_WATER)
B(-5,-18,4,STATIONARY_WATER)
B(-5,-18,5,STONE)
B(-5,-18,6,STONE)
B(-5,-18,7,STONE)
B(-5,-17,-2,STONE)
B(-5,-17,-1,STONE)
B(-5,-17,0,STONE)
B(-5,-17,1,STATIONARY_WATER)
B(-5,-17,2,STATIONARY_WATER)
B(-5,-17,3,STATIONARY_WATER)
B(-5,-17,4,STATIONARY_WATER)
B(-5,-17,5,STONE)
B(-5,-17,6,STONE)
B(-5,-17,7,STONE)
B(-5,-17,8,STONE)
B(-5,-17,9,STONE)
B(-5,-17,10,STONE)
B(-5,-17,11,STONE)
B(-5,-16,-8,STONE)
B(-5,-16,-3,STONE)
B(-5,-16,-2,MOSSY_COBBLESTONE)
B(-5,-16,-1,STONE)
B(-5,-16,0,STATIONARY_WATER)
B(-5,-16,1,STATIONARY_WATER)
B(-5,-16,2,STATIONARY_WATER)
B(-5,-16,3,STATIONARY_WATER)
B(-5,-16,4,STATIONARY_WATER)
B(-5,-16,5,STATIONARY_WATER)
B(-5,-16,6,STONE)
B(-5,-16,7,STONE)
B(-5,-16,8,STONE)
B(-5,-16,9,STONE)
B(-5,-16,10,STONE)
B(-5,-16,11,STONE)
B(-5,-16,12,STONE)
B(-5,-15,-9,STONE)
B(-5,-15,-8,STONE)
B(-5,-15,-7,STONE)
B(-5,-15,-6,STONE)
B(-5,-15,-5,STONE)
B(-5,-15,-4,STONE)
B(-5,-15,-3,STONE)
B(-5,-15,-2,STONE)
B(-5,-15,-1,STATIONARY_WATER)
B(-5,-15,0,STATIONARY_WATER)
B(-5,-15,1,STATIONARY_WATER)
B(-5,-15,2,STATIONARY_WATER)
B(-5,-15,3,STATIONARY_WATER)
B(-5,-15,4,STATIONARY_WATER)
B(-5,-15,5,STATIONARY_WATER)
B(-5,-15,6,STATIONARY_WATER)
B(-5,-15,7,STATIONARY_WATER)
B(-5,-15,8,STATIONARY_WATER)
B(-5,-15,9,STONE)
B(-5,-15,10,STONE)
B(-5,-15,11,STONE)
B(-5,-15,12,STONE)
B(-5,-15,13,STONE)
B(-5,-14,-10,STONE)
B(-5,-14,-9,STONE)
B(-5,-14,-8,STONE)
B(-5,-14,-7,STONE)
B(-5,-14,-6,STONE)
B(-5,-14,-5,STONE)
B(-5,-14,-4,STONE)
B(-5,-14,-3,STONE)
B(-5,-14,-2,AIR)
B(-5,-14,-1,AIR)
B(-5,-14,0,AIR)
B(-5,-14,1,AIR)
B(-5,-14,2,AIR)
B(-5,-14,3,AIR)
B(-5,-14,4,AIR)
B(-5,-14,5,AIR)
B(-5,-14,6,AIR)
B(-5,-14,7,AIR)
B(-5,-14,8,AIR)
B(-5,-14,9,AIR)
B(-5,-14,10,STONE)
B(-5,-14,11,STONE)
B(-5,-14,12,STONE)
B(-5,-14,13,STONE)
B(-5,-14,14,STONE)
B(-5,-13,-10,STONE)
B(-5,-13,-9,STONE)
B(-5,-13,-8,STONE)
B(-5,-13,-7,STONE)
B(-5,-13,-6,STONE)
B(-5,-13,-5,STONE)
B(-5,-13,-4,STONE)
B(-5,-13,-3,STONE)
B(-5,-13,-2,AIR)
B(-5,-13,-1,AIR)
B(-5,-13,0,AIR)
B(-5,-13,1,AIR)
B(-5,-13,2,AIR)
B(-5,-13,3,AIR)
B(-5,-13,4,AIR)
B(-5,-13,5,AIR)
B(-5,-13,6,AIR)
B(-5,-13,7,AIR)
B(-5,-13,8,AIR)
B(-5,-13,9,AIR)
B(-5,-13,10,AIR)
B(-5,-13,11,STONE)
B(-5,-13,12,STONE)
B(-5,-13,13,STONE)
B(-5,-13,14,STONE)
B(-5,-12,-11,STONE)
B(-5,-12,-10,STONE)
B(-5,-12,-9,STONE)
B(-5,-12,-8,STONE)
B(-5,-12,-7,STONE)
B(-5,-12,-6,STONE)
B(-5,-12,-5,STONE)
B(-5,-12,-4,STONE)
B(-5,-12,-3,STONE)
B(-5,-12,-2,AIR)
B(-5,-12,-1,AIR)
B(-5,-12,0,AIR)
B(-5,-12,1,AIR)
B(-5,-12,2,AIR)
B(-5,-12,3,AIR)
B(-5,-12,4,AIR)
B(-5,-12,5,AIR)
B(-5,-12,6,AIR)
B(-5,-12,7,AIR)
B(-5,-12,8,AIR)
B(-5,-12,9,AIR)
B(-5,-12,10,AIR)
B(-5,-12,11,STONE)
B(-5,-12,12,STONE)
B(-5,-12,13,STONE)
B(-5,-12,14,STONE)
B(-5,-11,-11,STONE)
B(-5,-11,-10,STONE)
B(-5,-11,-9,STONE)
B(-5,-11,-8,STONE)
B(-5,-11,-7,STONE)
B(-5,-11,-6,STONE)
B(-5,-11,-5,STONE)
B(-5,-11,-4,STONE)
B(-5,-11,-3,STONE)
B(-5,-11,-2,STONE)
B(-5,-11,-1,AIR)
B(-5,-11,0,AIR)
B(-5,-11,1,AIR)
B(-5,-11,2,AIR)
B(-5,-11,3,AIR)
B(-5,-11,4,AIR)
B(-5,-11,5,AIR)
B(-5,-11,6,AIR)
B(-5,-11,7,AIR)
B(-5,-11,8,AIR)
B(-5,-11,9,AIR)
B(-5,-11,10,AIR)
B(-5,-11,11,STONE)
B(-5,-11,12,STONE)
B(-5,-11,13,STONE)
B(-5,-11,14,STONE)
B(-5,-10,-10,STONE)
B(-5,-10,-9,STONE)
B(-5,-10,-8,STONE)
B(-5,-10,-7,STONE)
B(-5,-10,-6,STONE)
B(-5,-10,-5,STONE)
B(-5,-10,-4,STONE)
B(-5,-10,-3,STONE)
B(-5,-10,-2,STONE)
B(-5,-10,-1,STONE)
B(-5,-10,0,AIR)
B(-5,-10,1,AIR)
B(-5,-10,2,AIR)
B(-5,-10,3,AIR)
B(-5,-10,4,AIR)
B(-5,-10,5,AIR)
B(-5,-10,6,AIR)
B(-5,-10,7,AIR)
B(-5,-10,8,AIR)
B(-5,-10,9,AIR)
B(-5,-10,10,AIR)
B(-5,-10,11,STONE)
B(-5,-9,-8,STONE)
B(-5,-9,-7,STONE)
B(-5,-9,-6,STONE)
B(-5,-9,-5,STONE)
B(-5,-9,-4,STONE)
B(-5,-9,-3,STONE)
B(-5,-9,-2,STONE)
B(-5,-9,-1,STONE)
B(-5,-9,0,STONE)
B(-5,-9,1,STONE)
B(-5,-9,2,AIR)
B(-5,-9,3,AIR)
B(-5,-9,4,AIR)
B(-5,-9,5,AIR)
B(-5,-9,6,AIR)
B(-5,-9,7,AIR)
B(-5,-9,8,AIR)
B(-5,-9,9,AIR)
B(-5,-9,10,AIR)
B(-5,-9,11,STONE)
B(-5,-8,-7,STONE)
B(-5,-8,-6,STONE)
B(-5,-8,-5,STONE)
B(-5,-8,-4,STONE)
B(-5,-8,-3,STONE)
B(-5,-8,-2,STONE)
B(-5,-8,-1,STONE)
B(-5,-8,0,STONE)
B(-5,-8,1,STONE)
B(-5,-8,2,STONE)
B(-5,-8,3,AIR)
B(-5,-8,4,AIR)
B(-5,-8,5,AIR)
B(-5,-8,6,AIR)
B(-5,-8,7,AIR)
B(-5,-8,8,AIR)
B(-5,-8,9,AIR)
B(-5,-8,10,STONE)
B(-5,-8,11,STONE)
B(-5,-7,-6,STONE)
B(-5,-7,-5,STONE)
B(-5,-7,-4,STONE)
B(-5,-7,-3,STONE)
B(-5,-7,-2,STONE)
B(-5,-7,-1,STONE)
B(-5,-7,0,STONE)
B(-5,-7,1,STONE)
B(-5,-7,2,STONE)
B(-5,-7,3,STONE)
B(-5,-7,4,AIR)
B(-5,-7,5,AIR)
B(-5,-7,6,AIR)
B(-5,-7,7,AIR)
B(-5,-7,8,AIR)
B(-5,-7,9,AIR)
B(-5,-7,10,AIR)
B(-5,-7,11,STONE)
B(-5,-6,-6,STONE)
B(-5,-6,-5,STONE)
B(-5,-6,-4,STONE)
B(-5,-6,-3,STONE)
B(-5,-6,-2,STONE)
B(-5,-6,-1,STONE)
B(-5,-6,0,STONE)
B(-5,-6,1,AIR)
B(-5,-6,2,AIR)
B(-5,-6,3,AIR)
B(-5,-6,4,AIR)
B(-5,-6,5,AIR)
B(-5,-6,6,AIR)
B(-5,-6,7,AIR)
B(-5,-6,8,AIR)
B(-5,-6,9,AIR)
B(-5,-6,10,AIR)
B(-5,-6,11,STONE)
B(-5,-5,-6,STONE)
B(-5,-5,-5,STONE)
B(-5,-5,-4,STONE)
B(-5,-5,-3,STONE)
B(-5,-5,-2,STONE)
B(-5,-5,-1,AIR)
B(-5,-5,0,AIR)
B(-5,-5,1,AIR)
B(-5,-5,2,AIR)
B(-5,-5,3,AIR)
B(-5,-5,4,AIR)
B(-5,-5,5,AIR)
B(-5,-5,6,AIR)
B(-5,-5,7,AIR)
B(-5,-5,8,AIR)
B(-5,-5,9,AIR)
B(-5,-5,10,AIR)
B(-5,-5,11,STONE)
B(-5,-5,12,STONE)
B(-5,-5,13,STONE)
B(-5,-5,14,STONE)
B(-5,-4,-6,STONE)
B(-5,-4,-5,STONE)
B(-5,-4,-4,STONE)
B(-5,-4,-3,STONE)
B(-5,-4,-2,AIR)
B(-5,-4,-1,AIR)
B(-5,-4,0,AIR)
B(-5,-4,1,AIR)
B(-5,-4,2,AIR)
B(-5,-4,3,AIR)
B(-5,-4,4,AIR)
B(-5,-4,5,AIR)
B(-5,-4,6,AIR)
B(-5,-4,7,AIR)
B(-5,-4,8,AIR)
B(-5,-4,9,AIR)
B(-5,-4,10,AIR)
B(-5,-4,11,AIR)
B(-5,-4,12,STONE)
B(-5,-4,13,STONE)
B(-5,-4,14,STONE)
B(-5,-3,-6,STONE)
B(-5,-3,-5,STONE)
B(-5,-3,-4,STONE)
B(-5,-3,-3,STONE)
B(-5,-3,-2,AIR)
B(-5,-3,-1,AIR)
B(-5,-3,0,AIR)
B(-5,-3,1,AIR)
B(-5,-3,2,AIR)
B(-5,-3,3,AIR)
B(-5,-3,4,AIR)
B(-5,-3,5,AIR)
B(-5,-3,6,AIR)
B(-5,-3,7,AIR)
B(-5,-3,8,AIR)
B(-5,-3,9,AIR)
B(-5,-3,10,AIR)
B(-5,-3,11,AIR)
B(-5,-3,12,STONE)
B(-5,-3,13,STONE)
B(-5,-3,14,STONE)
B(-5,-2,-5,STONE)
B(-5,-2,-4,STONE)
B(-5,-2,-3,STONE)
B(-5,-2,-2,STONE)
B(-5,-2,-1,AIR)
B(-5,-2,0,AIR)
B(-5,-2,1,AIR)
B(-5,-2,2,AIR)
B(-5,-2,3,AIR)
B(-5,-2,4,AIR)
B(-5,-2,5,AIR)
B(-5,-2,6,AIR)
B(-5,-2,7,AIR)
B(-5,-2,8,AIR)
B(-5,-2,9,AIR)
B(-5,-2,10,AIR)
B(-5,-2,11,AIR)
B(-5,-2,12,STONE)
B(-5,-2,13,STONE)
B(-5,-2,14,STONE)
B(-5,-1,-4,STONE)
B(-5,-1,-3,STONE)
B(-5,-1,-2,STONE)
B(-5,-1,-1,STONE)
B(-5,-1,0,AIR)
B(-5,-1,1,AIR)
B(-5,-1,2,AIR)
B(-5,-1,3,AIR)
B(-5,-1,4,AIR)
B(-5,-1,5,AIR)
B(-5,-1,6,AIR)
B(-5,-1,7,AIR)
B(-5,-1,8,AIR)
B(-5,-1,9,AIR)
B(-5,-1,10,AIR)
B(-5,-1,11,AIR)
B(-5,-1,12,STONE)
B(-5,-1,13,STONE)
B(-5,0,-1,STONE)
B(-5,0,0,STONE)
B(-5,0,1,STONE)
B(-5,0,2,STONE)
B(-5,0,3,STONE)
B(-5,0,4,AIR)
B(-5,0,5,AIR)
B(-5,0,6,AIR)
B(-5,0,7,AIR)
B(-5,0,8,AIR)
B(-5,0,9,AIR)
B(-5,0,10,AIR)
B(-5,0,11,STONE)
B(-5,0,12,MOSSY_COBBLESTONE)
B(-5,0,13,STONE)
B(-5,1,-1,STONE)
B(-5,1,0,STONE)
B(-5,1,1,STONE)
B(-5,1,2,STONE)
B(-5,1,3,STONE)
B(-5,1,4,STONE)
B(-5,1,5,AIR)
B(-5,1,6,AIR)
B(-5,1,7,AIR)
B(-5,1,8,AIR)
B(-5,1,9,AIR)
B(-5,1,10,AIR)
B(-5,1,11,STONE)
B(-5,2,2,STONE)
B(-5,2,3,STONE)
B(-5,2,4,STONE)
B(-5,2,5,STONE)
B(-5,2,6,STONE)
B(-5,2,7,STONE)
B(-5,2,8,STONE)
B(-5,2,9,STONE)
B(-5,2,10,STONE)
B(-5,3,4,STONE)
B(-5,3,5,STONE)
B(-4,-21,1,STONE)
B(-4,-21,2,STONE)
B(-4,-20,0,STONE)
B(-4,-20,1,STONE)
B(-4,-20,2,STONE)
B(-4,-20,3,STONE)
B(-4,-20,4,STONE)
B(-4,-19,-2,STONE)
B(-4,-19,-1,STONE)
B(-4,-19,0,STONE)
B(-4,-19,1,STONE)
B(-4,-19,2,STONE)
B(-4,-19,3,STONE)
B(-4,-19,4,STONE)
B(-4,-19,5,STONE)
B(-4,-18,-2,STONE)
B(-4,-18,-1,STONE)
B(-4,-18,0,STONE)
B(-4,-18,1,STONE)
B(-4,-18,2,STATIONARY_WATER)
B(-4,-18,3,STATIONARY_WATER)
B(-4,-18,4,STATIONARY_WATER)
B(-4,-18,5,STONE)
B(-4,-18,6,STONE)
B(-4,-17,-3,STONE)
B(-4,-17,-2,MOSSY_COBBLESTONE)
B(-4,-17,-1,STONE)
B(-4,-17,0,MOSSY_COBBLESTONE)
B(-4,-17,1,STATIONARY_WATER)
B(-4,-17,2,STATIONARY_WATER)
B(-4,-17,3,STATIONARY_WATER)
B(-4,-17,4,STATIONARY_WATER)
B(-4,-17,5,STATIONARY_WATER)
B(-4,-17,6,STONE)
B(-4,-17,7,STONE)
B(-4,-17,8,STONE)
B(-4,-17,9,MOSSY_COBBLESTONE)
B(-4,-17,10,STONE)
B(-4,-16,-9,STONE)
B(-4,-16,-8,STONE)
B(-4,-16,-7,STONE)
B(-4,-16,-5,STONE)
B(-4,-16,-4,STONE)
B(-4,-16,-3,STONE)
B(-4,-16,-2,STONE)
B(-4,-16,-1,MOSSY_COBBLESTONE)
B(-4,-16,0,STATIONARY_WATER)
B(-4,-16,1,STATIONARY_WATER)
B(-4,-16,2,STATIONARY_WATER)
B(-4,-16,3,STATIONARY_WATER)
B(-4,-16,4,STATIONARY_WATER)
B(-4,-16,5,STATIONARY_WATER)
B(-4,-16,6,STATIONARY_WATER)
B(-4,-16,7,STATIONARY_WATER)
B(-4,-16,8,STONE)
B(-4,-16,9,STONE)
B(-4,-16,10,STONE)
B(-4,-16,11,STONE)
B(-4,-15,-9,STONE)
B(-4,-15,-8,STONE)
B(-4,-15,-7,STONE)
B(-4,-15,-6,STONE)
B(-4,-15,-5,STONE)
B(-4,-15,-4,MOSSY_COBBLESTONE)
B(-4,-15,-3,STONE)
B(-4,-15,-2,STONE)
B(-4,-15,-1,STATIONARY_WATER)
B(-4,-15,0,STATIONARY_WATER)
B(-4,-15,1,STATIONARY_WATER)
B(-4,-15,2,STATIONARY_WATER)
B(-4,-15,3,STATIONARY_WATER)
B(-4,-15,4,STATIONARY_WATER)
B(-4,-15,5,STATIONARY_WATER)
B(-4,-15,6,STATIONARY_WATER)
B(-4,-15,7,STATIONARY_WATER)
B(-4,-15,8,STATIONARY_WATER)
B(-4,-15,9,MOSSY_COBBLESTONE)
B(-4,-15,10,STONE)
B(-4,-15,11,STONE)
B(-4,-15,12,STONE)
B(-4,-15,13,STONE)
B(-4,-14,-9,STONE)
B(-4,-14,-8,STONE)
B(-4,-14,-7,STONE)
B(-4,-14,-6,STONE)
B(-4,-14,-5,STONE)
B(-4,-14,-4,STONE)
B(-4,-14,-3,STONE)
B(-4,-14,-2,AIR)
B(-4,-14,-1,AIR)
B(-4,-14,0,AIR)
B(-4,-14,1,AIR)
B(-4,-14,2,AIR)
B(-4,-14,3,AIR)
B(-4,-14,4,AIR)
B(-4,-14,5,AIR)
B(-4,-14,6,AIR)
B(-4,-14,7,STATIONARY_WATER:8)
B(-4,-14,8,AIR)
B(-4,-14,9,AIR)
B(-4,-14,10,MOSSY_COBBLESTONE)
B(-4,-14,11,STONE)
B(-4,-14,12,STONE)
B(-4,-14,13,STONE)
B(-4,-14,14,STONE)
B(-4,-13,-9,STONE)
B(-4,-13,-8,STONE)
B(-4,-13,-7,STONE)
B(-4,-13,-6,STONE)
B(-4,-13,-5,STONE)
B(-4,-13,-4,STONE)
B(-4,-13,-3,AIR)
B(-4,-13,-2,AIR)
B(-4,-13,-1,AIR)
B(-4,-13,0,AIR)
B(-4,-13,1,AIR)
B(-4,-13,2,AIR)
B(-4,-13,3,AIR)
B(-4,-13,4,AIR)
B(-4,-13,5,AIR)
B(-4,-13,6,AIR)
B(-4,-13,7,STATIONARY_WATER:8)
B(-4,-13,8,AIR)
B(-4,-13,9,AIR)
B(-4,-13,10,AIR)
B(-4,-13,11,STONE)
B(-4,-13,12,STONE)
B(-4,-13,13,STONE)
B(-4,-13,14,STONE)
B(-4,-12,-10,STONE)
B(-4,-12,-9,STONE)
B(-4,-12,-8,STONE)
B(-4,-12,-7,STONE)
B(-4,-12,-6,STONE)
B(-4,-12,-5,STONE)
B(-4,-12,-4,STONE)
B(-4,-12,-3,AIR)
B(-4,-12,-2,AIR)
B(-4,-12,-1,AIR)
B(-4,-12,0,AIR)
B(-4,-12,1,AIR)
B(-4,-12,2,AIR)
B(-4,-12,3,AIR)
B(-4,-12,4,AIR)
B(-4,-12,5,AIR)
B(-4,-12,6,AIR)
B(-4,-12,7,STATIONARY_WATER:8)
B(-4,-12,8,AIR)
B(-4,-12,9,AIR)
B(-4,-12,10,AIR)
B(-4,-12,11,STONE)
B(-4,-12,12,STONE)
B(-4,-12,13,STONE)
B(-4,-12,14,STONE)
B(-4,-11,-12,STONE)
B(-4,-11,-11,STONE)
B(-4,-11,-10,STONE)
B(-4,-11,-9,STONE)
B(-4,-11,-8,STONE)
B(-4,-11,-7,STONE)
B(-4,-11,-6,STONE)
B(-4,-11,-5,STONE)
B(-4,-11,-4,MOSSY_COBBLESTONE)
B(-4,-11,-3,AIR)
B(-4,-11,-2,AIR)
B(-4,-11,-1,AIR)
B(-4,-11,0,AIR)
B(-4,-11,1,AIR)
B(-4,-11,2,AIR)
B(-4,-11,3,AIR)
B(-4,-11,4,AIR)
B(-4,-11,5,AIR)
B(-4,-11,6,AIR)
B(-4,-11,7,STATIONARY_WATER:8)
B(-4,-11,8,AIR)
B(-4,-11,9,AIR)
B(-4,-11,10,AIR)
B(-4,-11,11,STONE)
B(-4,-11,12,STONE)
B(-4,-11,13,STONE)
B(-4,-10,-12,STONE)
B(-4,-10,-11,STONE)
B(-4,-10,-10,STONE)
B(-4,-10,-9,STONE)
B(-4,-10,-8,STONE)
B(-4,-10,-7,STONE)
B(-4,-10,-6,STONE)
B(-4,-10,-5,STONE)
B(-4,-10,-4,STONE)
B(-4,-10,-3,STONE)
B(-4,-10,-2,STONE)
B(-4,-10,-1,STONE)
B(-4,-10,0,AIR)
B(-4,-10,1,AIR)
B(-4,-10,2,AIR)
B(-4,-10,3,AIR)
B(-4,-10,4,AIR)
B(-4,-10,5,AIR)
B(-4,-10,6,AIR)
B(-4,-10,7,STATIONARY_WATER:8)
B(-4,-10,8,AIR)
B(-4,-10,9,AIR)
B(-4,-10,10,AIR)
B(-4,-10,11,STONE)
B(-4,-9,-8,STONE)
B(-4,-9,-7,STONE)
B(-4,-9,-6,STONE)
B(-4,-9,-5,STONE)
B(-4,-9,-4,STONE)
B(-4,-9,-3,STONE)
B(-4,-9,-2,STONE)
B(-4,-9,-1,STONE)
B(-4,-9,0,STONE)
B(-4,-9,1,AIR)
B(-4,-9,2,AIR)
B(-4,-9,3,AIR)
B(-4,-9,4,AIR)
B(-4,-9,5,AIR)
B(-4,-9,6,AIR)
B(-4,-9,7,STATIONARY_WATER:8)
B(-4,-9,8,AIR)
B(-4,-9,9,AIR)
B(-4,-9,10,STONE)
B(-4,-9,11,STONE)
B(-4,-8,-7,STONE)
B(-4,-8,-6,STONE)
B(-4,-8,-5,STONE)
B(-4,-8,-4,STONE)
B(-4,-8,-3,STONE)
B(-4,-8,-2,STONE)
B(-4,-8,-1,STONE)
B(-4,-8,0,STONE)
B(-4,-8,1,STONE)
B(-4,-8,2,STONE)
B(-4,-8,3,AIR)
B(-4,-8,4,AIR)
B(-4,-8,5,AIR)
B(-4,-8,6,AIR)
B(-4,-8,7,STATIONARY_WATER:8)
B(-4,-8,8,AIR)
B(-4,-8,9,AIR)
B(-4,-8,10,STONE)
B(-4,-7,-6,STONE)
B(-4,-7,-5,STONE)
B(-4,-7,-4,STONE)
B(-4,-7,-3,STONE)
B(-4,-7,-2,STONE)
B(-4,-7,-1,STONE)
B(-4,-7,0,STONE)
B(-4,-7,1,STONE)
B(-4,-7,2,AIR)
B(-4,-7,3,AIR)
B(-4,-7,4,AIR)
B(-4,-7,5,AIR)
B(-4,-7,6,AIR)
B(-4,-7,7,STATIONARY_WATER:8)
B(-4,-7,8,AIR)
B(-4,-7,9,STONE)
B(-4,-7,10,STONE)
B(-4,-7,11,STONE)
B(-4,-6,-6,STONE)
B(-4,-6,-5,STONE)
B(-4,-6,-4,STONE)
B(-4,-6,-3,STONE)
B(-4,-6,-2,STONE)
B(-4,-6,-1,STONE)
B(-4,-6,0,AIR)
B(-4,-6,1,AIR)
B(-4,-6,2,AIR)
B(-4,-6,3,AIR)
B(-4,-6,4,AIR)
B(-4,-6,5,AIR)
B(-4,-6,6,AIR)
B(-4,-6,7,STATIONARY_WATER:8)
B(-4,-6,8,AIR)
B(-4,-6,9,AIR)
B(-4,-6,10,STONE)
B(-4,-6,11,STONE)
B(-4,-5,-6,STONE)
B(-4,-5,-5,STONE)
B(-4,-5,-4,STONE)
B(-4,-5,-3,STONE)
B(-4,-5,-2,AIR)
B(-4,-5,-1,AIR)
B(-4,-5,0,AIR)
B(-4,-5,1,AIR)
B(-4,-5,2,AIR)
B(-4,-5,3,AIR)
B(-4,-5,4,AIR)
B(-4,-5,5,AIR)
B(-4,-5,6,AIR)
B(-4,-5,7,STATIONARY_WATER:8)
B(-4,-5,8,AIR)
B(-4,-5,9,AIR)
B(-4,-5,10,AIR)
B(-4,-5,11,STONE)
B(-4,-5,12,STONE)
B(-4,-5,13,STONE)
B(-4,-4,-6,STONE)
B(-4,-4,-5,STONE)
B(-4,-4,-4,STONE)
B(-4,-4,-3,AIR)
B(-4,-4,-2,AIR)
B(-4,-4,-1,AIR)
B(-4,-4,0,AIR)
B(-4,-4,1,AIR)
B(-4,-4,2,AIR)
B(-4,-4,3,AIR)
B(-4,-4,4,AIR)
B(-4,-4,5,AIR)
B(-4,-4,6,AIR)
B(-4,-4,7,STATIONARY_WATER:8)
B(-4,-4,8,AIR)
B(-4,-4,9,AIR)
B(-4,-4,10,AIR)
B(-4,-4,11,STONE)
B(-4,-4,12,STONE)
B(-4,-4,13,STONE)
B(-4,-4,14,STONE)
B(-4,-3,-6,STONE)
B(-4,-3,-5,STONE)
B(-4,-3,-4,STONE)
B(-4,-3,-3,AIR)
B(-4,-3,-2,AIR)
B(-4,-3,-1,AIR)
B(-4,-3,0,AIR)
B(-4,-3,1,AIR)
B(-4,-3,2,AIR)
B(-4,-3,3,AIR)
B(-4,-3,4,AIR)
B(-4,-3,5,AIR)
B(-4,-3,6,AIR)
B(-4,-3,7,STATIONARY_WATER:8)
B(-4,-3,8,AIR)
B(-4,-3,9,AIR)
B(-4,-3,10,AIR)
B(-4,-3,11,AIR)
B(-4,-3,12,STONE)
B(-4,-3,13,STONE)
B(-4,-3,14,STONE)
B(-4,-2,-6,STONE)
B(-4,-2,-5,STONE)
B(-4,-2,-4,STONE)
B(-4,-2,-3,STONE)
B(-4,-2,-2,AIR)
B(-4,-2,-1,AIR)
B(-4,-2,0,AIR)
B(-4,-2,1,AIR)
B(-4,-2,2,AIR)
B(-4,-2,3,AIR)
B(-4,-2,4,AIR)
B(-4,-2,5,AIR)
B(-4,-2,6,AIR)
B(-4,-2,7,STATIONARY_WATER:8)
B(-4,-2,8,AIR)
B(-4,-2,9,AIR)
B(-4,-2,10,AIR)
B(-4,-2,11,AIR)
B(-4,-2,12,STONE)
B(-4,-2,13,STONE)
B(-4,-1,-5,STONE)
B(-4,-1,-4,STONE)
B(-4,-1,-3,STONE)
B(-4,-1,-2,STONE)
B(-4,-1,-1,AIR)
B(-4,-1,0,AIR)
B(-4,-1,1,AIR)
B(-4,-1,2,AIR)
B(-4,-1,3,AIR)
B(-4,-1,4,AIR)
B(-4,-1,5,AIR)
B(-4,-1,6,AIR)
B(-4,-1,7,STATIONARY_WATER:8)
B(-4,-1,8,AIR)
B(-4,-1,9,AIR)
B(-4,-1,10,AIR)
B(-4,-1,11,STONE)
B(-4,-1,12,STONE)
B(-4,0,-4,STONE)
B(-4,0,-3,STONE)
B(-4,0,-2,STONE)
B(-4,0,-1,STONE)
B(-4,0,0,STONE)
B(-4,0,1,MOSSY_COBBLESTONE)
B(-4,0,2,AIR)
B(-4,0,3,AIR)
B(-4,0,4,AIR)
B(-4,0,5,AIR)
B(-4,0,6,AIR)
B(-4,0,7,STATIONARY_WATER:8)
B(-4,0,8,AIR)
B(-4,0,9,AIR)
B(-4,0,10,AIR)
B(-4,0,11,STONE)
B(-4,1,-3,STONE)
B(-4,1,-2,STONE)
B(-4,1,-1,MOSSY_COBBLESTONE)
B(-4,1,0,STONE)
B(-4,1,1,STONE)
B(-4,1,2,STONE)
B(-4,1,3,STONE)
B(-4,1,4,MOSSY_COBBLESTONE)
B(-4,1,5,AIR)
B(-4,1,6,AIR)
B(-4,1,7,STATIONARY_WATER:8)
B(-4,1,8,AIR)
B(-4,1,9,AIR)
B(-4,1,10,STONE)
B(-4,2,1,STONE)
B(-4,2,2,STONE)
B(-4,2,3,STONE)
B(-4,2,4,MOSSY_COBBLESTONE)
B(-4,2,5,STONE)
B(-4,2,6,STONE)
B(-4,2,7,STATIONARY_WATER)
B(-4,2,8,STONE)
B(-4,2,9,STONE)
B(-4,3,3,STONE)
B(-4,3,4,STONE)
B(-3,-21,0,STONE)
B(-3,-21,1,STONE)
B(-3,-20,-1,STONE)
B(-3,-20,0,STONE)
B(-3,-20,1,STONE)
B(-3,-20,2,STONE)
B(-3,-20,3,STONE)
B(-3,-20,4,STONE)
B(-3,-19,-3,STONE)
B(-3,-19,-2,STONE)
B(-3,-19,-1,STONE)
B(-3,-19,0,STONE)
B(-3,-19,1,STONE)
B(-3,-19,2,STONE)
B(-3,-19,3,STONE)
B(-3,-19,4,STONE)
B(-3,-18,-3,STONE)
B(-3,-18,-2,STONE)
B(-3,-18,-1,STONE)
B(-3,-18,0,STONE)
B(-3,-18,1,STONE)
B(-3,-18,2,STATIONARY_WATER)
B(-3,-18,3,STATIONARY_WATER)
B(-3,-18,4,STATIONARY_WATER)
B(-3,-18,5,STONE)
B(-3,-17,-8,STONE)
B(-3,-17,-7,STONE)
B(-3,-17,-6,STONE)
B(-3,-17,-5,STONE)
B(-3,-17,-4,STONE)
B(-3,-17,-3,MOSSY_COBBLESTONE)
B(-3,-17,-2,MOSSY_COBBLESTONE)
B(-3,-17,-1,STONE)
B(-3,-17,0,STONE)
B(-3,-17,1,STATIONARY_WATER)
B(-3,-17,2,STATIONARY_WATER)
B(-3,-17,3,STATIONARY_WATER)
B(-3,-17,4,STATIONARY_WATER)
B(-3,-17,5,STATIONARY_WATER)
B(-3,-17,6,STONE)
B(-3,-17,7,STONE)
B(-3,-17,8,STONE)
B(-3,-17,10,STONE)
B(-3,-17,11,STONE)
B(-3,-16,-9,STONE)
B(-3,-16,-8,STONE)
B(-3,-16,-7,STONE)
B(-3,-16,-6,STONE)
B(-3,-16,-5,STONE)
B(-3,-16,-4,STONE)
B(-3,-16,-3,STONE)
B(-3,-16,-2,STONE)
B(-3,-16,-1,STONE)
B(-3,-16,0,STATIONARY_WATER)
B(-3,-16,1,STATIONARY_WATER)
B(-3,-16,2,STATIONARY_WATER)
B(-3,-16,3,STATIONARY_WATER)
B(-3,-16,4,STATIONARY_WATER)
B(-3,-16,5,STATIONARY_WATER)
B(-3,-16,6,STATIONARY_WATER)
B(-3,-16,7,STATIONARY_WATER)
B(-3,-16,8,MOSSY_COBBLESTONE)
B(-3,-16,9,STONE)
B(-3,-16,10,MOSSY_COBBLESTONE)
B(-3,-16,11,STONE)
B(-3,-16,12,STONE)
B(-3,-15,-9,STONE)
B(-3,-15,-8,STONE)
B(-3,-15,-7,STONE)
B(-3,-15,-6,STONE)
B(-3,-15,-5,STONE)
B(-3,-15,-4,MOSSY_COBBLESTONE)
B(-3,-15,-3,MOSSY_COBBLESTONE)
B(-3,-15,-2,STATIONARY_WATER)
B(-3,-15,-1,STATIONARY_WATER)
B(-3,-15,0,STATIONARY_WATER)
B(-3,-15,1,STATIONARY_WATER)
B(-3,-15,2,STATIONARY_WATER)
B(-3,-15,3,STATIONARY_WATER)
B(-3,-15,4,STATIONARY_WATER)
B(-3,-15,5,STATIONARY_WATER)
B(-3,-15,6,STATIONARY_WATER)
B(-3,-15,7,STATIONARY_WATER)
B(-3,-15,8,STATIONARY_WATER)
B(-3,-15,9,STONE)
B(-3,-15,10,STONE)
B(-3,-15,11,STONE)
B(-3,-15,12,STONE)
B(-3,-15,13,STONE)
B(-3,-14,-9,STONE)
B(-3,-14,-8,STONE)
B(-3,-14,-7,STONE)
B(-3,-14,-6,STONE)
B(-3,-14,-5,STONE)
B(-3,-14,-4,STONE)
B(-3,-14,-3,AIR)
B(-3,-14,-2,AIR)
B(-3,-14,-1,AIR)
B(-3,-14,0,AIR)
B(-3,-14,1,AIR)
B(-3,-14,2,AIR)
B(-3,-14,3,AIR)
B(-3,-14,4,AIR)
B(-3,-14,5,STATIONARY_WATER:8)
B(-3,-14,6,STATIONARY_WATER:8)
B(-3,-14,7,AIR)
B(-3,-14,8,AIR)
B(-3,-14,9,AIR)
B(-3,-14,10,STONE)
B(-3,-14,11,STONE)
B(-3,-14,12,STONE)
B(-3,-14,13,STONE)
B(-3,-14,14,STONE)
B(-3,-13,-9,STONE)
B(-3,-13,-8,STONE)
B(-3,-13,-7,STONE)
B(-3,-13,-6,STONE)
B(-3,-13,-5,STONE)
B(-3,-13,-4,AIR)
B(-3,-13,-3,AIR)
B(-3,-13,-2,AIR)
B(-3,-13,-1,AIR)
B(-3,-13,0,AIR)
B(-3,-13,1,AIR)
B(-3,-13,2,AIR)
B(-3,-13,3,AIR)
B(-3,-13,4,AIR)
B(-3,-13,5,STATIONARY_WATER:8)
B(-3,-13,6,STATIONARY_WATER:8)
B(-3,-13,7,AIR)
B(-3,-13,8,AIR)
B(-3,-13,9,AIR)
B(-3,-13,10,AIR)
B(-3,-13,11,STONE)
B(-3,-13,12,STONE)
B(-3,-13,13,STONE)
B(-3,-13,14,STONE)
B(-3,-12,-10,STONE)
B(-3,-12,-9,STONE)
B(-3,-12,-8,STONE)
B(-3,-12,-7,STONE)
B(-3,-12,-6,STONE)
B(-3,-12,-5,STONE)
B(-3,-12,-4,STONE)
B(-3,-12,-3,AIR)
B(-3,-12,-2,AIR)
B(-3,-12,-1,AIR)
B(-3,-12,0,AIR)
B(-3,-12,1,AIR)
B(-3,-12,2,AIR)
B(-3,-12,3,AIR)
B(-3,-12,4,AIR)
B(-3,-12,5,STATIONARY_WATER:8)
B(-3,-12,6,STATIONARY_WATER:8)
B(-3,-12,7,AIR)
B(-3,-12,8,AIR)
B(-3,-12,9,AIR)
B(-3,-12,10,AIR)
B(-3,-12,11,STONE)
B(-3,-12,12,STONE)
B(-3,-12,13,STONE)
B(-3,-12,14,STONE)
B(-3,-11,-11,STONE)
B(-3,-11,-10,STONE)
B(-3,-11,-9,STONE)
B(-3,-11,-8,STONE)
B(-3,-11,-7,STONE)
B(-3,-11,-6,STONE)
B(-3,-11,-5,STONE)
B(-3,-11,-4,STONE)
B(-3,-11,-3,AIR)
B(-3,-11,-2,AIR)
B(-3,-11,-1,AIR)
B(-3,-11,0,AIR)
B(-3,-11,1,AIR)
B(-3,-11,2,AIR)
B(-3,-11,3,AIR)
B(-3,-11,4,AIR)
B(-3,-11,5,STATIONARY_WATER:8)
B(-3,-11,6,STATIONARY_WATER:8)
B(-3,-11,7,AIR)
B(-3,-11,8,AIR)
B(-3,-11,9,AIR)
B(-3,-11,10,AIR)
B(-3,-11,11,STONE)
B(-3,-11,12,STONE)
B(-3,-11,13,STONE)
B(-3,-11,14,STONE)
B(-3,-10,-12,STONE)
B(-3,-10,-11,STONE)
B(-3,-10,-10,STONE)
B(-3,-10,-9,STONE)
B(-3,-10,-8,STONE)
B(-3,-10,-7,STONE)
B(-3,-10,-6,STONE)
B(-3,-10,-5,STONE)
B(-3,-10,-4,STONE)
B(-3,-10,-3,STONE)
B(-3,-10,-2,STONE)
B(-3,-10,-1,AIR)
B(-3,-10,0,AIR)
B(-3,-10,1,AIR)
B(-3,-10,2,AIR)
B(-3,-10,3,AIR)
B(-3,-10,4,AIR)
B(-3,-10,5,STATIONARY_WATER:8)
B(-3,-10,6,STATIONARY_WATER:8)
B(-3,-10,7,AIR)
B(-3,-10,8,AIR)
B(-3,-10,9,AIR)
B(-3,-10,10,AIR)
B(-3,-10,11,STONE)
B(-3,-9,-12,STONE)
B(-3,-9,-11,STONE)
B(-3,-9,-10,STONE)
B(-3,-9,-9,STONE)
B(-3,-9,-8,STONE)
B(-3,-9,-7,STONE)
B(-3,-9,-6,STONE)
B(-3,-9,-5,STONE)
B(-3,-9,-4,STONE)
B(-3,-9,-3,STONE)
B(-3,-9,-2,STONE)
B(-3,-9,-1,STONE)
B(-3,-9,0,AIR)
B(-3,-9,1,AIR)
B(-3,-9,2,AIR)
B(-3,-9,3,AIR)
B(-3,-9,4,AIR)
B(-3,-9,5,STATIONARY_WATER:8)
B(-3,-9,6,STATIONARY_WATER:8)
B(-3,-9,7,AIR)
B(-3,-9,8,AIR)
B(-3,-9,9,STONE)
B(-3,-9,10,STONE)
B(-3,-8,-8,STONE)
B(-3,-8,-7,STONE)
B(-3,-8,-6,STONE)
B(-3,-8,-5,STONE)
B(-3,-8,-4,STONE)
B(-3,-8,-3,STONE)
B(-3,-8,-2,STONE)
B(-3,-8,-1,STONE)
B(-3,-8,0,STONE)
B(-3,-8,1,STONE)
B(-3,-8,2,AIR)
B(-3,-8,3,AIR)
B(-3,-8,4,AIR)
B(-3,-8,5,STATIONARY_WATER:8)
B(-3,-8,6,STATIONARY_WATER:8)
B(-3,-8,7,AIR)
B(-3,-8,8,AIR)
B(-3,-8,9,STONE)
B(-3,-8,10,STONE)
B(-3,-7,-7,STONE)
B(-3,-7,-6,STONE)
B(-3,-7,-5,STONE)
B(-3,-7,-4,STONE)
B(-3,-7,-3,STONE)
B(-3,-7,-2,STONE)
B(-3,-7,-1,STONE)
B(-3,-7,0,STONE)
B(-3,-7,1,AIR)
B(-3,-7,2,AIR)
B(-3,-7,3,AIR)
B(-3,-7,4,AIR)
B(-3,-7,5,STATIONARY_WATER:8)
B(-3,-7,6,STATIONARY_WATER:8)
B(-3,-7,7,AIR)
B(-3,-7,8,AIR)
B(-3,-7,9,STONE)
B(-3,-7,10,STONE)
B(-3,-6,-7,STONE)
B(-3,-6,-6,STONE)
B(-3,-6,-5,STONE)
B(-3,-6,-4,STONE)
B(-3,-6,-3,STONE)
B(-3,-6,-2,AIR)
B(-3,-6,-1,AIR)
B(-3,-6,0,AIR)
B(-3,-6,1,AIR)
B(-3,-6,2,AIR)
B(-3,-6,3,AIR)
B(-3,-6,4,AIR)
B(-3,-6,5,STATIONARY_WATER:8)
B(-3,-6,6,STATIONARY_WATER:8)
B(-3,-6,7,AIR)
B(-3,-6,8,AIR)
B(-3,-6,9,AIR)
B(-3,-6,10,STONE)
B(-3,-6,11,STONE)
B(-3,-5,-7,STONE)
B(-3,-5,-6,STONE)
B(-3,-5,-5,STONE)
B(-3,-5,-4,AIR)
B(-3,-5,-3,AIR)
B(-3,-5,-2,AIR)
B(-3,-5,-1,AIR)
B(-3,-5,0,AIR)
B(-3,-5,1,AIR)
B(-3,-5,2,AIR)
B(-3,-5,3,AIR)
B(-3,-5,4,AIR)
B(-3,-5,5,STATIONARY_WATER:8)
B(-3,-5,6,STATIONARY_WATER:8)
B(-3,-5,7,AIR)
B(-3,-5,8,AIR)
B(-3,-5,9,AIR)
B(-3,-5,10,AIR)
B(-3,-5,11,STONE)
B(-3,-5,12,STONE)
B(-3,-5,13,STONE)
B(-3,-4,-7,STONE)
B(-3,-4,-6,STONE)
B(-3,-4,-5,STONE)
B(-3,-4,-4,AIR)
B(-3,-4,-3,AIR)
B(-3,-4,-2,AIR)
B(-3,-4,-1,AIR)
B(-3,-4,0,AIR)
B(-3,-4,1,AIR)
B(-3,-4,2,AIR)
B(-3,-4,3,AIR)
B(-3,-4,4,AIR)
B(-3,-4,5,STATIONARY_WATER:8)
B(-3,-4,6,STATIONARY_WATER:8)
B(-3,-4,7,AIR)
B(-3,-4,8,AIR)
B(-3,-4,9,AIR)
B(-3,-4,10,AIR)
B(-3,-4,11,STONE)
B(-3,-4,12,STONE)
B(-3,-4,13,STONE)
B(-3,-4,14,STONE)
B(-3,-3,-7,STONE)
B(-3,-3,-6,STONE)
B(-3,-3,-5,STONE)
B(-3,-3,-4,AIR)
B(-3,-3,-3,AIR)
B(-3,-3,-2,AIR)
B(-3,-3,-1,AIR)
B(-3,-3,0,AIR)
B(-3,-3,1,AIR)
B(-3,-3,2,AIR)
B(-3,-3,3,AIR)
B(-3,-3,4,AIR)
B(-3,-3,5,STATIONARY_WATER:8)
B(-3,-3,6,STATIONARY_WATER:8)
B(-3,-3,7,AIR)
B(-3,-3,8,AIR)
B(-3,-3,9,AIR)
B(-3,-3,10,AIR)
B(-3,-3,11,AIR)
B(-3,-3,12,STONE)
B(-3,-3,13,STONE)
B(-3,-3,14,STONE)
B(-3,-2,-7,STONE)
B(-3,-2,-6,STONE)
B(-3,-2,-5,STONE)
B(-3,-2,-4,STONE)
B(-3,-2,-3,AIR)
B(-3,-2,-2,AIR)
B(-3,-2,-1,AIR)
B(-3,-2,0,AIR)
B(-3,-2,1,AIR)
B(-3,-2,2,AIR)
B(-3,-2,3,AIR)
B(-3,-2,4,AIR)
B(-3,-2,5,STATIONARY_WATER:8)
B(-3,-2,6,STATIONARY_WATER:8)
B(-3,-2,7,AIR)
B(-3,-2,8,AIR)
B(-3,-2,9,AIR)
B(-3,-2,10,AIR)
B(-3,-2,11,AIR)
B(-3,-2,12,STONE)
B(-3,-2,13,STONE)
B(-3,-1,-6,STONE)
B(-3,-1,-5,STONE)
B(-3,-1,-4,STONE)
B(-3,-1,-3,STONE)
B(-3,-1,-2,AIR)
B(-3,-1,-1,AIR)
B(-3,-1,0,AIR)
B(-3,-1,1,AIR)
B(-3,-1,2,AIR)
B(-3,-1,3,AIR)
B(-3,-1,4,AIR)
B(-3,-1,5,STATIONARY_WATER:8)
B(-3,-1,6,STATIONARY_WATER:8)
B(-3,-1,7,AIR)
B(-3,-1,8,AIR)
B(-3,-1,9,AIR)
B(-3,-1,10,AIR)
B(-3,-1,11,STONE)
B(-3,0,-5,STONE)
B(-3,0,-4,STONE)
B(-3,0,-3,STONE)
B(-3,0,-2,STONE)
B(-3,0,-1,STONE)
B(-3,0,0,STONE)
B(-3,0,1,AIR)
B(-3,0,2,AIR)
B(-3,0,3,AIR)
B(-3,0,4,AIR)
B(-3,0,5,STATIONARY_WATER:8)
B(-3,0,6,STATIONARY_WATER:8)
B(-3,0,7,AIR)
B(-3,0,8,AIR)
B(-3,0,9,AIR)
B(-3,0,10,STONE)
B(-3,1,-4,STONE)
B(-3,1,-3,STONE)
B(-3,1,-2,MOSSY_COBBLESTONE)
B(-3,1,-1,STONE)
B(-3,1,0,STONE)
B(-3,1,1,STONE)
B(-3,1,2,MOSSY_COBBLESTONE)
B(-3,1,3,STONE)
B(-3,1,4,AIR)
B(-3,1,5,STATIONARY_WATER:8)
B(-3,1,6,STATIONARY_WATER:8)
B(-3,1,7,AIR)
B(-3,1,8,AIR)
B(-3,1,9,STONE)
B(-3,1,10,STONE)
B(-3,2,0,STONE)
B(-3,2,1,STONE)
B(-3,2,2,STONE)
B(-3,2,3,STONE)
B(-3,2,4,MOSSY_COBBLESTONE)
B(-3,2,5,STATIONARY_WATER)
B(-3,2,6,STATIONARY_WATER)
B(-3,2,7,STONE)
B(-3,2,8,STONE)
B(-3,2,9,STONE)
B(-3,3,3,MOSSY_COBBLESTONE)
B(-2,-21,0,STONE)
B(-2,-21,1,STONE)
B(-2,-21,2,STONE)
B(-2,-20,-1,STONE)
B(-2,-20,0,STONE)
B(-2,-20,1,STONE)
B(-2,-20,2,STONE)
B(-2,-20,3,STONE)
B(-2,-20,4,STONE)
B(-2,-19,-4,STONE)
B(-2,-19,-3,STONE)
B(-2,-19,-2,STONE)
B(-2,-19,-1,STONE)
B(-2,-19,0,STONE)
B(-2,-19,1,STONE)
B(-2,-19,2,STONE)
B(-2,-19,3,STONE)
B(-2,-19,4,STONE)
B(-2,-19,5,STONE)
B(-2,-18,-8,STONE)
B(-2,-18,-7,STONE)
B(-2,-18,-6,STONE)
B(-2,-18,-5,STONE)
B(-2,-18,-4,STONE)
B(-2,-18,-3,STONE)
B(-2,-18,-2,STONE)
B(-2,-18,-1,STONE)
B(-2,-18,0,STONE)
B(-2,-18,1,STONE)
B(-2,-18,2,STATIONARY_WATER)
B(-2,-18,3,STATIONARY_WATER)
B(-2,-18,4,STATIONARY_WATER)
B(-2,-18,5,STONE)
B(-2,-18,6,STONE)
B(-2,-17,-8,STONE)
B(-2,-17,-7,STONE)
B(-2,-17,-6,STONE)
B(-2,-17,-5,STONE)
B(-2,-17,-4,STONE)
B(-2,-17,-3,STONE)
B(-2,-17,-2,STONE)
B(-2,-17,-1,STONE)
B(-2,-17,0,MOSSY_COBBLESTONE)
B(-2,-17,1,STATIONARY_WATER)
B(-2,-17,2,STATIONARY_WATER)
B(-2,-17,3,STATIONARY_WATER)
B(-2,-17,4,STATIONARY_WATER)
B(-2,-17,5,STATIONARY_WATER)
B(-2,-17,6,STONE)
B(-2,-17,7,STONE)
B(-2,-17,8,STONE)
B(-2,-17,9,STONE)
B(-2,-17,10,STONE)
B(-2,-17,11,STONE)
B(-2,-16,-9,STONE)
B(-2,-16,-8,STONE)
B(-2,-16,-7,STONE)
B(-2,-16,-6,STONE)
B(-2,-16,-5,STONE)
B(-2,-16,-4,STONE)
B(-2,-16,-3,STONE)
B(-2,-16,-2,STONE)
B(-2,-16,-1,STONE)
B(-2,-16,0,STATIONARY_WATER)
B(-2,-16,1,STATIONARY_WATER)
B(-2,-16,2,STATIONARY_WATER)
B(-2,-16,3,STATIONARY_WATER)
B(-2,-16,4,STATIONARY_WATER)
B(-2,-16,5,STATIONARY_WATER)
B(-2,-16,6,STATIONARY_WATER)
B(-2,-16,7,STONE)
B(-2,-16,8,STONE)
B(-2,-16,9,STONE)
B(-2,-16,10,MOSSY_COBBLESTONE)
B(-2,-16,11,STONE)
B(-2,-15,-9,STONE)
B(-2,-15,-8,STONE)
B(-2,-15,-7,STONE)
B(-2,-15,-6,STONE)
B(-2,-15,-5,STONE)
B(-2,-15,-4,MOSSY_COBBLESTONE)
B(-2,-15,-3,STATIONARY_WATER)
B(-2,-15,-2,STATIONARY_WATER)
B(-2,-15,-1,STATIONARY_WATER)
B(-2,-15,0,STATIONARY_WATER)
B(-2,-15,1,STATIONARY_WATER)
B(-2,-15,2,STATIONARY_WATER)
B(-2,-15,3,STATIONARY_WATER)
B(-2,-15,4,STATIONARY_WATER)
B(-2,-15,5,STATIONARY_WATER)
B(-2,-15,6,STATIONARY_WATER)
B(-2,-15,7,STATIONARY_WATER)
B(-2,-15,8,STATIONARY_WATER)
B(-2,-15,9,STONE)
B(-2,-15,10,STONE)
B(-2,-15,11,STONE)
B(-2,-15,12,STONE)
B(-2,-15,13,STONE)
B(-2,-14,-9,STONE)
B(-2,-14,-8,STONE)
B(-2,-14,-7,STONE)
B(-2,-14,-6,STONE)
B(-2,-14,-5,STONE)
B(-2,-14,-4,AIR)
B(-2,-14,-3,AIR)
B(-2,-14,-2,AIR)
B(-2,-14,-1,AIR)
B(-2,-14,0,AIR)
B(-2,-14,1,AIR)
B(-2,-14,2,AIR)
B(-2,-14,3,AIR)
B(-2,-14,4,AIR)
B(-2,-14,5,AIR)
B(-2,-14,6,AIR)
B(-2,-14,7,AIR)
B(-2,-14,8,AIR)
B(-2,-14,9,AIR)
B(-2,-14,10,STONE)
B(-2,-14,11,STONE)
B(-2,-14,12,STONE)
B(-2,-14,13,STONE)
B(-2,-13,-9,STONE)
B(-2,-13,-8,STONE)
B(-2,-13,-7,STONE)
B(-2,-13,-6,STONE)
B(-2,-13,-5,AIR)
B(-2,-13,-4,AIR)
B(-2,-13,-3,AIR)
B(-2,-13,-2,AIR)
B(-2,-13,-1,AIR)
B(-2,-13,0,AIR)
B(-2,-13,1,AIR)
B(-2,-13,2,AIR)
B(-2,-13,3,AIR)
B(-2,-13,4,AIR)
B(-2,-13,5,AIR)
B(-2,-13,6,AIR)
B(-2,-13,7,AIR)
B(-2,-13,8,AIR)
B(-2,-13,9,AIR)
B(-2,-13,10,AIR)
B(-2,-13,11,STONE)
B(-2,-13,12,STONE)
B(-2,-13,13,STONE)
B(-2,-13,14,STONE)
B(-2,-12,-9,STONE)
B(-2,-12,-8,STONE)
B(-2,-12,-7,STONE)
B(-2,-12,-6,STONE)
B(-2,-12,-5,AIR)
B(-2,-12,-4,AIR)
B(-2,-12,-3,AIR)
B(-2,-12,-2,AIR)
B(-2,-12,-1,AIR)
B(-2,-12,0,AIR)
B(-2,-12,1,AIR)
B(-2,-12,2,AIR)
B(-2,-12,3,AIR)
B(-2,-12,4,AIR)
B(-2,-12,5,AIR)
B(-2,-12,6,AIR)
B(-2,-12,7,AIR)
B(-2,-12,8,AIR)
B(-2,-12,9,AIR)
B(-2,-12,10,AIR)
B(-2,-12,11,STONE)
B(-2,-12,12,STONE)
B(-2,-12,13,STONE)
B(-2,-12,14,STONE)
B(-2,-11,-10,STONE)
B(-2,-11,-9,STONE)
B(-2,-11,-8,STONE)
B(-2,-11,-7,STONE)
B(-2,-11,-6,STONE)
B(-2,-11,-5,AIR)
B(-2,-11,-4,AIR)
B(-2,-11,-3,AIR)
B(-2,-11,-2,AIR)
B(-2,-11,-1,AIR)
B(-2,-11,0,AIR)
B(-2,-11,1,AIR)
B(-2,-11,2,AIR)
B(-2,-11,3,AIR)
B(-2,-11,4,AIR)
B(-2,-11,5,AIR)
B(-2,-11,6,AIR)
B(-2,-11,7,AIR)
B(-2,-11,8,AIR)
B(-2,-11,9,AIR)
B(-2,-11,10,AIR)
B(-2,-11,11,STONE)
B(-2,-11,12,STONE)
B(-2,-11,13,STONE)
B(-2,-11,14,STONE)
B(-2,-10,-12,STONE)
B(-2,-10,-11,STONE)
B(-2,-10,-10,STONE)
B(-2,-10,-9,STONE)
B(-2,-10,-8,STONE)
B(-2,-10,-7,STONE)
B(-2,-10,-6,STONE)
B(-2,-10,-5,STONE)
B(-2,-10,-4,AIR)
B(-2,-10,-3,AIR)
B(-2,-10,-2,AIR)
B(-2,-10,-1,AIR)
B(-2,-10,0,AIR)
B(-2,-10,1,AIR)
B(-2,-10,2,AIR)
B(-2,-10,3,AIR)
B(-2,-10,4,AIR)
B(-2,-10,5,AIR)
B(-2,-10,6,AIR)
B(-2,-10,7,AIR)
B(-2,-10,8,AIR)
B(-2,-10,9,AIR)
B(-2,-10,10,STONE)
B(-2,-9,-13,STONE)
B(-2,-9,-12,STONE)
B(-2,-9,-11,STONE)
B(-2,-9,-10,STONE)
B(-2,-9,-9,STONE)
B(-2,-9,-8,STONE)
B(-2,-9,-7,STONE)
B(-2,-9,-6,STONE)
B(-2,-9,-5,STONE)
B(-2,-9,-4,STONE)
B(-2,-9,-3,STONE)
B(-2,-9,-2,STONE)
B(-2,-9,-1,STONE)
B(-2,-9,0,AIR)
B(-2,-9,1,AIR)
B(-2,-9,2,AIR)
B(-2,-9,3,AIR)
B(-2,-9,4,AIR)
B(-2,-9,5,AIR)
B(-2,-9,6,AIR)
B(-2,-9,7,AIR)
B(-2,-9,8,AIR)
B(-2,-9,9,STONE)
B(-2,-9,10,STONE)
B(-2,-8,-12,STONE)
B(-2,-8,-11,STONE)
B(-2,-8,-10,STONE)
B(-2,-8,-9,STONE)
B(-2,-8,-8,STONE)
B(-2,-8,-7,STONE)
B(-2,-8,-6,STONE)
B(-2,-8,-5,STONE)
B(-2,-8,-4,STONE)
B(-2,-8,-3,STONE)
B(-2,-8,-2,STONE)
B(-2,-8,-1,STONE)
B(-2,-8,0,STONE)
B(-2,-8,1,AIR)
B(-2,-8,2,AIR)
B(-2,-8,3,AIR)
B(-2,-8,4,AIR)
B(-2,-8,5,AIR)
B(-2,-8,6,AIR)
B(-2,-8,7,AIR)
B(-2,-8,8,AIR)
B(-2,-8,9,STONE)
B(-2,-8,10,STONE)
B(-2,-7,-8,STONE)
B(-2,-7,-7,STONE)
B(-2,-7,-6,STONE)
B(-2,-7,-5,STONE)
B(-2,-7,-4,STONE)
B(-2,-7,-3,STONE)
B(-2,-7,-2,STONE)
B(-2,-7,-1,AIR)
B(-2,-7,0,AIR)
B(-2,-7,1,AIR)
B(-2,-7,2,AIR)
B(-2,-7,3,AIR)
B(-2,-7,4,AIR)
B(-2,-7,5,AIR)
B(-2,-7,6,AIR)
B(-2,-7,7,AIR)
B(-2,-7,8,AIR)
B(-2,-7,9,STONE)
B(-2,-7,10,STONE)
B(-2,-6,-8,STONE)
B(-2,-6,-7,STONE)
B(-2,-6,-6,STONE)
B(-2,-6,-5,STONE)
B(-2,-6,-4,STONE)
B(-2,-6,-3,AIR)
B(-2,-6,-2,AIR)
B(-2,-6,-1,AIR)
B(-2,-6,0,AIR)
B(-2,-6,1,AIR)
B(-2,-6,2,AIR)
B(-2,-6,3,AIR)
B(-2,-6,4,AIR)
B(-2,-6,5,AIR)
B(-2,-6,6,AIR)
B(-2,-6,7,AIR)
B(-2,-6,8,AIR)
B(-2,-6,9,STONE)
B(-2,-6,10,STONE)
B(-2,-5,-8,STONE)
B(-2,-5,-7,STONE)
B(-2,-5,-6,STONE)
B(-2,-5,-5,AIR)
B(-2,-5,-4,AIR)
B(-2,-5,-3,AIR)
B(-2,-5,-2,AIR)
B(-2,-5,-1,AIR)
B(-2,-5,0,AIR)
B(-2,-5,1,AIR)
B(-2,-5,2,AIR)
B(-2,-5,3,AIR)
B(-2,-5,4,AIR)
B(-2,-5,5,AIR)
B(-2,-5,6,AIR)
B(-2,-5,7,AIR)
B(-2,-5,8,AIR)
B(-2,-5,9,AIR)
B(-2,-5,10,STONE)
B(-2,-5,11,STONE)
B(-2,-5,12,STONE)
B(-2,-5,13,STONE)
B(-2,-4,-8,STONE)
B(-2,-4,-7,STONE)
B(-2,-4,-6,STONE)
B(-2,-4,-5,AIR)
B(-2,-4,-4,AIR)
B(-2,-4,-3,AIR)
B(-2,-4,-2,AIR)
B(-2,-4,-1,AIR)
B(-2,-4,0,AIR)
B(-2,-4,1,AIR)
B(-2,-4,2,AIR)
B(-2,-4,3,AIR)
B(-2,-4,4,AIR)
B(-2,-4,5,AIR)
B(-2,-4,6,AIR)
B(-2,-4,7,AIR)
B(-2,-4,8,AIR)
B(-2,-4,9,AIR)
B(-2,-4,10,AIR)
B(-2,-4,11,STONE)
B(-2,-4,12,STONE)
B(-2,-4,13,STONE)
B(-2,-4,14,STONE)
B(-2,-3,-8,STONE)
B(-2,-3,-7,STONE)
B(-2,-3,-6,STONE)
B(-2,-3,-5,AIR)
B(-2,-3,-4,AIR)
B(-2,-3,-3,AIR)
B(-2,-3,-2,AIR)
B(-2,-3,-1,AIR)
B(-2,-3,0,AIR)
B(-2,-3,1,AIR)
B(-2,-3,2,AIR)
B(-2,-3,3,AIR)
B(-2,-3,4,AIR)
B(-2,-3,5,AIR)
B(-2,-3,6,AIR)
B(-2,-3,7,AIR)
B(-2,-3,8,AIR)
B(-2,-3,9,AIR)
B(-2,-3,10,AIR)
B(-2,-3,11,STONE)
B(-2,-3,12,STONE)
B(-2,-3,13,STONE)
B(-2,-3,14,STONE)
B(-2,-2,-7,STONE)
B(-2,-2,-6,STONE)
B(-2,-2,-5,STONE)
B(-2,-2,-4,AIR)
B(-2,-2,-3,AIR)
B(-2,-2,-2,AIR)
B(-2,-2,-1,AIR)
B(-2,-2,0,AIR)
B(-2,-2,1,AIR)
B(-2,-2,2,AIR)
B(-2,-2,3,AIR)
B(-2,-2,4,AIR)
B(-2,-2,5,AIR)
B(-2,-2,6,AIR)
B(-2,-2,7,AIR)
B(-2,-2,8,AIR)
B(-2,-2,9,AIR)
B(-2,-2,10,AIR)
B(-2,-2,11,AIR)
B(-2,-2,12,STONE)
B(-2,-2,13,STONE)
B(-2,-1,-7,STONE)
B(-2,-1,-6,STONE)
B(-2,-1,-5,STONE)
B(-2,-1,-4,STONE)
B(-2,-1,-3,STONE)
B(-2,-1,-2,AIR)
B(-2,-1,-1,AIR)
B(-2,-1,0,AIR)
B(-2,-1,1,AIR)
B(-2,-1,2,AIR)
B(-2,-1,3,AIR)
B(-2,-1,4,AIR)
B(-2,-1,5,AIR)
B(-2,-1,6,AIR)
B(-2,-1,7,AIR)
B(-2,-1,8,AIR)
B(-2,-1,9,AIR)
B(-2,-1,10,AIR)
B(-2,-1,11,STONE)
B(-2,0,-7,STONE)
B(-2,0,-6,STONE)
B(-2,0,-5,STONE)
B(-2,0,-4,STONE)
B(-2,0,-3,STONE)
B(-2,0,-2,STONE)
B(-2,0,-1,MOSSY_COBBLESTONE)
B(-2,0,0,AIR)
B(-2,0,1,AIR)
B(-2,0,2,AIR)
B(-2,0,3,AIR)
B(-2,0,4,AIR)
B(-2,0,5,AIR)
B(-2,0,6,AIR)
B(-2,0,7,AIR)
B(-2,0,8,AIR)
B(-2,0,9,AIR)
B(-2,0,10,STONE)
B(-2,1,-5,STONE)
B(-2,1,-4,STONE)
B(-2,1,-3,STONE)
B(-2,1,-2,STONE)
B(-2,1,-1,STONE)
B(-2,1,0,STONE)
B(-2,1,1,STONE)
B(-2,1,2,AIR)
B(-2,1,3,AIR)
B(-2,1,4,AIR)
B(-2,1,5,AIR)
B(-2,1,6,AIR)
B(-2,1,7,AIR)
B(-2,1,8,AIR)
B(-2,1,9,STONE)
B(-2,2,-1,STONE)
B(-2,2,0,STONE)
B(-2,2,1,STONE)
B(-2,2,2,STONE)
B(-2,2,3,STONE)
B(-2,2,4,STONE)
B(-2,2,5,STONE)
B(-2,2,6,MOSSY_COBBLESTONE)
B(-2,2,7,STONE)
B(-2,2,8,STONE)
B(-2,2,9,STONE)
B(-1,-22,0,STONE)
B(-1,-22,1,STONE)
B(-1,-21,-1,STONE)
B(-1,-21,0,STONE)
B(-1,-21,1,STONE)
B(-1,-21,2,STONE)
B(-1,-20,-3,STONE)
B(-1,-20,-2,STONE)
B(-1,-20,-1,STONE)
B(-1,-20,0,STONE)
B(-1,-20,1,STONE)
B(-1,-20,2,STONE)
B(-1,-20,3,STONE)
B(-1,-20,4,STONE)
B(-1,-19,-8,STONE)
B(-1,-19,-7,STONE)
B(-1,-19,-6,STONE)
B(-1,-19,-5,STONE)
B(-1,-19,-4,STONE)
B(-1,-19,-3,STONE)
B(-1,-19,-2,STONE)
B(-1,-19,-1,STONE)
B(-1,-19,0,STONE)
B(-1,-19,1,STONE)
B(-1,-19,2,STONE)
B(-1,-19,3,STONE)
B(-1,-19,4,STONE)
B(-1,-19,5,STONE)
B(-1,-18,-8,STONE)
B(-1,-18,-7,STONE)
B(-1,-18,-6,STONE)
B(-1,-18,-5,STONE)
B(-1,-18,-4,STONE)
B(-1,-18,-3,STONE)
B(-1,-18,-2,STONE)
B(-1,-18,-1,STONE)
B(-1,-18,0,STONE)
B(-1,-18,1,STONE)
B(-1,-18,2,STATIONARY_WATER)
B(-1,-18,3,STATIONARY_WATER)
B(-1,-18,4,STATIONARY_WATER)
B(-1,-18,5,STONE)
B(-1,-18,6,STONE)
B(-1,-17,-9,STONE)
B(-1,-17,-8,STONE)
B(-1,-17,-7,STONE)
B(-1,-17,-6,STONE)
B(-1,-17,-5,STONE)
B(-1,-17,-4,STONE)
B(-1,-17,-3,STONE)
B(-1,-17,-2,STONE)
B(-1,-17,-1,STONE)
B(-1,-17,0,MOSSY_COBBLESTONE)
B(-1,-17,1,STATIONARY_WATER)
B(-1,-17,2,STATIONARY_WATER)
B(-1,-17,3,STATIONARY_WATER)
B(-1,-17,4,STATIONARY_WATER)
B(-1,-17,5,STATIONARY_WATER)
B(-1,-17,6,STONE)
B(-1,-17,7,MOSSY_COBBLESTONE)
B(-1,-17,8,STONE)
B(-1,-17,9,STONE)
B(-1,-17,10,STONE)
B(-1,-16,-9,STONE)
B(-1,-16,-8,STONE)
B(-1,-16,-7,STONE)
B(-1,-16,-6,STONE)
B(-1,-16,-5,STONE)
B(-1,-16,-4,MOSSY_COBBLESTONE)
B(-1,-16,-3,MOSSY_COBBLESTONE)
B(-1,-16,-2,STONE)
B(-1,-16,-1,STATIONARY_WATER)
B(-1,-16,0,STATIONARY_WATER)
B(-1,-16,1,STATIONARY_WATER)
B(-1,-16,2,STATIONARY_WATER)
B(-1,-16,3,STATIONARY_WATER)
B(-1,-16,4,STATIONARY_WATER)
B(-1,-16,5,STATIONARY_WATER)
B(-1,-16,6,STATIONARY_WATER)
B(-1,-16,7,STONE)
B(-1,-16,8,MOSSY_COBBLESTONE)
B(-1,-16,9,STONE)
B(-1,-16,10,MOSSY_COBBLESTONE)
B(-1,-15,-9,STONE)
B(-1,-15,-8,STONE)
B(-1,-15,-7,STONE)
B(-1,-15,-6,STONE)
B(-1,-15,-5,STONE)
B(-1,-15,-4,STATIONARY_WATER)
B(-1,-15,-3,STATIONARY_WATER)
B(-1,-15,-2,STATIONARY_WATER)
B(-1,-15,-1,STATIONARY_WATER)
B(-1,-15,0,STATIONARY_WATER)
B(-1,-15,1,STATIONARY_WATER)
B(-1,-15,2,STATIONARY_WATER)
B(-1,-15,3,STATIONARY_WATER)
B(-1,-15,4,STATIONARY_WATER)
B(-1,-15,5,STATIONARY_WATER)
B(-1,-15,6,STATIONARY_WATER)
B(-1,-15,7,STATIONARY_WATER)
B(-1,-15,8,MOSSY_COBBLESTONE)
B(-1,-15,9,STONE)
B(-1,-15,10,MOSSY_COBBLESTONE)
B(-1,-14,-9,STONE)
B(-1,-14,-8,STONE)
B(-1,-14,-7,AIR)
B(-1,-14,-6,AIR)
B(-1,-14,-5,AIR)
B(-1,-14,-4,AIR)
B(-1,-14,-3,AIR)
B(-1,-14,-2,AIR)
B(-1,-14,-1,AIR)
B(-1,-14,0,AIR)
B(-1,-14,1,AIR)
B(-1,-14,2,AIR)
B(-1,-14,3,STATIONARY_WATER:8)
B(-1,-14,4,STATIONARY_WATER:8)
B(-1,-14,5,AIR)
B(-1,-14,6,AIR)
B(-1,-14,7,AIR)
B(-1,-14,8,AIR)
B(-1,-14,9,AIR)
B(-1,-14,10,STONE)
B(-1,-14,11,STONE)
B(-1,-14,12,STONE)
B(-1,-14,13,STONE)
B(-1,-13,-9,STONE)
B(-1,-13,-8,AIR)
B(-1,-13,-7,AIR)
B(-1,-13,-6,AIR)
B(-1,-13,-5,AIR)
B(-1,-13,-4,AIR)
B(-1,-13,-3,AIR)
B(-1,-13,-2,AIR)
B(-1,-13,-1,AIR)
B(-1,-13,0,AIR)
B(-1,-13,1,AIR)
B(-1,-13,2,AIR)
B(-1,-13,3,STATIONARY_WATER:8)
B(-1,-13,4,STATIONARY_WATER:8)
B(-1,-13,5,AIR)
B(-1,-13,6,AIR)
B(-1,-13,7,AIR)
B(-1,-13,8,AIR)
B(-1,-13,9,AIR)
B(-1,-13,10,MOSSY_COBBLESTONE)
B(-1,-13,11,STONE)
B(-1,-13,12,STONE)
B(-1,-13,13,STONE)
B(-1,-13,14,STONE)
B(-1,-12,-10,STONE)
B(-1,-12,-9,STONE)
B(-1,-12,-8,AIR)
B(-1,-12,-7,AIR)
B(-1,-12,-6,AIR)
B(-1,-12,-5,AIR)
B(-1,-12,-4,AIR)
B(-1,-12,-3,AIR)
B(-1,-12,-2,AIR)
B(-1,-12,-1,AIR)
B(-1,-12,0,AIR)
B(-1,-12,1,AIR)
B(-1,-12,2,AIR)
B(-1,-12,3,STATIONARY_WATER:8)
B(-1,-12,4,STATIONARY_WATER:8)
B(-1,-12,5,AIR)
B(-1,-12,6,AIR)
B(-1,-12,7,AIR)
B(-1,-12,8,AIR)
B(-1,-12,9,AIR)
B(-1,-12,10,STONE)
B(-1,-12,11,STONE)
B(-1,-12,12,STONE)
B(-1,-12,13,STONE)
B(-1,-12,14,STONE)
B(-1,-11,-11,STONE)
B(-1,-11,-10,STONE)
B(-1,-11,-9,STONE)
B(-1,-11,-8,STONE)
B(-1,-11,-7,AIR)
B(-1,-11,-6,AIR)
B(-1,-11,-5,AIR)
B(-1,-11,-4,AIR)
B(-1,-11,-3,AIR)
B(-1,-11,-2,AIR)
B(-1,-11,-1,AIR)
B(-1,-11,0,AIR)
B(-1,-11,1,AIR)
B(-1,-11,2,AIR)
B(-1,-11,3,STATIONARY_WATER:8)
B(-1,-11,4,STATIONARY_WATER:8)
B(-1,-11,5,AIR)
B(-1,-11,6,AIR)
B(-1,-11,7,AIR)
B(-1,-11,8,AIR)
B(-1,-11,9,AIR)
B(-1,-11,10,MOSSY_COBBLESTONE)
B(-1,-11,11,STONE)
B(-1,-11,12,STONE)
B(-1,-10,-13,STONE)
B(-1,-10,-12,STONE)
B(-1,-10,-11,STONE)
B(-1,-10,-10,STONE)
B(-1,-10,-9,STONE)
B(-1,-10,-8,STONE)
B(-1,-10,-7,STONE)
B(-1,-10,-6,STONE)
B(-1,-10,-5,AIR)
B(-1,-10,-4,AIR)
B(-1,-10,-3,AIR)
B(-1,-10,-2,AIR)
B(-1,-10,-1,AIR)
B(-1,-10,0,AIR)
B(-1,-10,1,AIR)
B(-1,-10,2,AIR)
B(-1,-10,3,STATIONARY_WATER:8)
B(-1,-10,4,STATIONARY_WATER:8)
B(-1,-10,5,AIR)
B(-1,-10,6,AIR)
B(-1,-10,7,AIR)
B(-1,-10,8,AIR)
B(-1,-10,9,AIR)
B(-1,-10,10,STONE)
B(-1,-9,-13,STONE)
B(-1,-9,-12,STONE)
B(-1,-9,-11,STONE)
B(-1,-9,-10,STONE)
B(-1,-9,-9,STONE)
B(-1,-9,-8,STONE)
B(-1,-9,-7,STONE)
B(-1,-9,-6,STONE)
B(-1,-9,-5,STONE)
B(-1,-9,-4,STONE)
B(-1,-9,-3,STONE)
B(-1,-9,-2,STONE)
B(-1,-9,-1,AIR)
B(-1,-9,0,AIR)
B(-1,-9,1,AIR)
B(-1,-9,2,AIR)
B(-1,-9,3,STATIONARY_WATER:8)
B(-1,-9,4,STATIONARY_WATER:8)
B(-1,-9,5,AIR)
B(-1,-9,6,AIR)
B(-1,-9,7,AIR)
B(-1,-9,8,STONE)
B(-1,-9,9,STONE)
B(-1,-9,10,STONE)
B(-1,-8,-13,STONE)
B(-1,-8,-12,STONE)
B(-1,-8,-11,STONE)
B(-1,-8,-10,STONE)
B(-1,-8,-9,STONE)
B(-1,-8,-8,STONE)
B(-1,-8,-7,STONE)
B(-1,-8,-6,STONE)
B(-1,-8,-5,STONE)
B(-1,-8,-4,STONE)
B(-1,-8,-3,STONE)
B(-1,-8,-2,STONE)
B(-1,-8,-1,STONE)
B(-1,-8,0,AIR)
B(-1,-8,1,AIR)
B(-1,-8,2,AIR)
B(-1,-8,3,STATIONARY_WATER:8)
B(-1,-8,4,STATIONARY_WATER:8)
B(-1,-8,5,AIR)
B(-1,-8,6,AIR)
B(-1,-8,7,STONE)
B(-1,-8,8,STONE)
B(-1,-8,9,STONE)
B(-1,-7,-13,STONE)
B(-1,-7,-12,STONE)
B(-1,-7,-11,STONE)
B(-1,-7,-10,STONE)
B(-1,-7,-9,STONE)
B(-1,-7,-8,STONE)
B(-1,-7,-7,STONE)
B(-1,-7,-6,STONE)
B(-1,-7,-5,STONE)
B(-1,-7,-4,STONE)
B(-1,-7,-3,STONE)
B(-1,-7,-2,AIR)
B(-1,-7,-1,AIR)
B(-1,-7,0,AIR)
B(-1,-7,1,AIR)
B(-1,-7,2,AIR)
B(-1,-7,3,STATIONARY_WATER:8)
B(-1,-7,4,STATIONARY_WATER:8)
B(-1,-7,5,AIR)
B(-1,-7,6,AIR)
B(-1,-7,7,AIR)
B(-1,-7,8,STONE)
B(-1,-7,9,STONE)
B(-1,-7,10,STONE)
B(-1,-6,-11,STONE)
B(-1,-6,-10,STONE)
B(-1,-6,-9,STONE)
B(-1,-6,-8,STONE)
B(-1,-6,-7,STONE)
B(-1,-6,-6,STONE)
B(-1,-6,-5,AIR)
B(-1,-6,-4,AIR)
B(-1,-6,-3,AIR)
B(-1,-6,-2,AIR)
B(-1,-6,-1,AIR)
B(-1,-6,0,AIR)
B(-1,-6,1,AIR)
B(-1,-6,2,AIR)
B(-1,-6,3,STATIONARY_WATER:8)
B(-1,-6,4,STATIONARY_WATER:8)
B(-1,-6,5,AIR)
B(-1,-6,6,AIR)
B(-1,-6,7,AIR)
B(-1,-6,8,AIR)
B(-1,-6,9,STONE)
B(-1,-6,10,STONE)
B(-1,-5,-10,STONE)
B(-1,-5,-9,STONE)
B(-1,-5,-8,STONE)
B(-1,-5,-7,STONE)
B(-1,-5,-6,AIR)
B(-1,-5,-5,AIR)
B(-1,-5,-4,AIR)
B(-1,-5,-3,AIR)
B(-1,-5,-2,AIR)
B(-1,-5,-1,AIR)
B(-1,-5,0,AIR)
B(-1,-5,1,AIR)
B(-1,-5,2,AIR)
B(-1,-5,3,STATIONARY_WATER:8)
B(-1,-5,4,STATIONARY_WATER:8)
B(-1,-5,5,AIR)
B(-1,-5,6,AIR)
B(-1,-5,7,AIR)
B(-1,-5,8,AIR)
B(-1,-5,9,AIR)
B(-1,-5,10,STONE)
B(-1,-5,11,STONE)
B(-1,-5,12,STONE)
B(-1,-5,13,STONE)
B(-1,-4,-9,STONE)
B(-1,-4,-8,STONE)
B(-1,-4,-7,STONE)
B(-1,-4,-6,AIR)
B(-1,-4,-5,AIR)
B(-1,-4,-4,AIR)
B(-1,-4,-3,AIR)
B(-1,-4,-2,AIR)
B(-1,-4,-1,AIR)
B(-1,-4,0,AIR)
B(-1,-4,1,AIR)
B(-1,-4,2,AIR)
B(-1,-4,3,STATIONARY_WATER:8)
B(-1,-4,4,STATIONARY_WATER:8)
B(-1,-4,5,AIR)
B(-1,-4,6,AIR)
B(-1,-4,7,AIR)
B(-1,-4,8,AIR)
B(-1,-4,9,AIR)
B(-1,-4,10,AIR)
B(-1,-4,11,STONE)
B(-1,-4,12,STONE)
B(-1,-4,13,STONE)
B(-1,-4,14,STONE)
B(-1,-3,-9,STONE)
B(-1,-3,-8,STONE)
B(-1,-3,-7,STONE)
B(-1,-3,-6,AIR)
B(-1,-3,-5,AIR)
B(-1,-3,-4,AIR)
B(-1,-3,-3,AIR)
B(-1,-3,-2,AIR)
B(-1,-3,-1,AIR)
B(-1,-3,0,AIR)
B(-1,-3,1,AIR)
B(-1,-3,2,AIR)
B(-1,-3,3,STATIONARY_WATER:8)
B(-1,-3,4,STATIONARY_WATER:8)
B(-1,-3,5,AIR)
B(-1,-3,6,AIR)
B(-1,-3,7,AIR)
B(-1,-3,8,AIR)
B(-1,-3,9,AIR)
B(-1,-3,10,AIR)
B(-1,-3,11,STONE)
B(-1,-3,12,STONE)
B(-1,-3,13,STONE)
B(-1,-3,14,STONE)
B(-1,-2,-8,STONE)
B(-1,-2,-7,STONE)
B(-1,-2,-6,STONE)
B(-1,-2,-5,STONE)
B(-1,-2,-4,AIR)
B(-1,-2,-3,AIR)
B(-1,-2,-2,AIR)
B(-1,-2,-1,AIR)
B(-1,-2,0,AIR)
B(-1,-2,1,AIR)
B(-1,-2,2,AIR)
B(-1,-2,3,STATIONARY_WATER:8)
B(-1,-2,4,STATIONARY_WATER:8)
B(-1,-2,5,AIR)
B(-1,-2,6,AIR)
B(-1,-2,7,AIR)
B(-1,-2,8,AIR)
B(-1,-2,9,AIR)
B(-1,-2,10,AIR)
B(-1,-2,11,STONE)
B(-1,-2,12,STONE)
B(-1,-2,13,STONE)
B(-1,-1,-7,STONE)
B(-1,-1,-6,STONE)
B(-1,-1,-5,STONE)
B(-1,-1,-4,STONE)
B(-1,-1,-3,AIR)
B(-1,-1,-2,AIR)
B(-1,-1,-1,AIR)
B(-1,-1,0,AIR)
B(-1,-1,1,AIR)
B(-1,-1,2,AIR)
B(-1,-1,3,STATIONARY_WATER:8)
B(-1,-1,4,STATIONARY_WATER:8)
B(-1,-1,5,AIR)
B(-1,-1,6,AIR)
B(-1,-1,7,AIR)
B(-1,-1,8,AIR)
B(-1,-1,9,AIR)
B(-1,-1,10,AIR)
B(-1,-1,11,STONE)
B(-1,0,-7,STONE)
B(-1,0,-6,STONE)
B(-1,0,-5,STONE)
B(-1,0,-4,STONE)
B(-1,0,-3,STONE)
B(-1,0,-2,STONE)
B(-1,0,-1,AIR)
B(-1,0,0,AIR)
B(-1,0,1,AIR)
B(-1,0,2,AIR)
B(-1,0,3,STATIONARY_WATER:8)
B(-1,0,4,STATIONARY_WATER:8)
B(-1,0,5,AIR)
B(-1,0,6,AIR)
B(-1,0,7,AIR)
B(-1,0,8,AIR)
B(-1,0,9,AIR)
B(-1,0,10,STONE)
B(-1,1,-6,STONE)
B(-1,1,-5,STONE)
B(-1,1,-4,STONE)
B(-1,1,-3,STONE)
B(-1,1,-2,STONE)
B(-1,1,-1,STONE)
B(-1,1,0,STONE)
B(-1,1,1,AIR)
B(-1,1,2,AIR)
B(-1,1,3,STATIONARY_WATER:8)
B(-1,1,4,STATIONARY_WATER:8)
B(-1,1,5,AIR)
B(-1,1,6,AIR)
B(-1,1,7,MOSSY_COBBLESTONE)
B(-1,1,8,STONE)
B(-1,1,9,STONE)
B(-1,2,-2,STONE)
B(-1,2,-1,STONE)
B(-1,2,0,MOSSY_COBBLESTONE)
B(-1,2,1,STONE)
B(-1,2,2,STONE)
B(-1,2,3,STATIONARY_WATER)
B(-1,2,4,STATIONARY_WATER)
B(-1,2,5,STONE)
B(-1,2,6,STONE)
B(-1,2,7,STONE)
B(-1,2,8,STONE)
B(0,-22,0,STONE)
B(0,-22,1,STONE)
B(0,-21,-2,STONE)
B(0,-21,-1,STONE)
B(0,-21,0,STONE)
B(0,-21,1,STONE)
B(0,-21,2,STONE)
B(0,-21,3,STONE)
B(0,-21,4,STONE)
B(0,-20,-7,STONE)
B(0,-20,-6,STONE)
B(0,-20,-5,STONE)
B(0,-20,-4,STONE)
B(0,-20,-3,STONE)
B(0,-20,-2,STONE)
B(0,-20,-1,STONE)
B(0,-20,0,STONE)
B(0,-20,1,STONE)
B(0,-20,2,STONE)
B(0,-20,3,STONE)
B(0,-20,4,STONE)
B(0,-20,5,STONE)
B(0,-19,-8,STONE)
B(0,-19,-7,STONE)
B(0,-19,-6,STONE)
B(0,-19,-5,STONE)
B(0,-19,-4,STONE)
B(0,-19,-3,STONE)
B(0,-19,-2,STONE)
B(0,-19,-1,STONE)
B(0,-19,0,STONE)
B(0,-19,1,STONE)
B(0,-19,2,STONE)
B(0,-19,3,STONE)
B(0,-19,4,STONE)
B(0,-19,5,STONE)
B(0,-19,6,STONE)
B(0,-18,-8,STONE)
B(0,-18,-7,STONE)
B(0,-18,-6,STONE)
B(0,-18,-5,STONE)
B(0,-18,-4,STONE)
B(0,-18,-3,STONE)
B(0,-18,-2,STONE)
B(0,-18,-1,STONE)
B(0,-18,0,STONE)
B(0,-18,1,STONE)
B(0,-18,2,STATIONARY_WATER)
B(0,-18,3,STATIONARY_WATER)
B(0,-18,4,STONE)
B(0,-18,5,STONE)
B(0,-18,6,STONE)
B(0,-18,7,STONE)
B(0,-18,8,STONE)
B(0,-17,-9,STONE)
B(0,-17,-8,STONE)
B(0,-17,-7,STONE)
B(0,-17,-6,STONE)
B(0,-17,-5,STONE)
B(0,-17,-4,STONE)
B(0,-17,-3,MOSSY_COBBLESTONE)
B(0,-17,-2,MOSSY_COBBLESTONE)
B(0,-17,-1,STONE)
B(0,-17,0,STONE)
B(0,-17,1,STATIONARY_WATER)
B(0,-17,2,STATIONARY_WATER)
B(0,-17,3,STATIONARY_WATER)
B(0,-17,4,STATIONARY_WATER)
B(0,-17,5,STATIONARY_WATER)
B(0,-17,6,STONE)
B(0,-17,7,MOSSY_COBBLESTONE)
B(0,-17,8,STONE)
B(0,-17,9,STONE)
B(0,-16,-9,STONE)
B(0,-16,-8,STONE)
B(0,-16,-7,STONE)
B(0,-16,-6,STONE)
B(0,-16,-5,STONE)
B(0,-16,-4,STONE)
B(0,-16,-3,STONE)
B(0,-16,-2,STATIONARY_WATER)
B(0,-16,-1,STATIONARY_WATER)
B(0,-16,0,STATIONARY_WATER)
B(0,-16,1,STATIONARY_WATER)
B(0,-16,2,STATIONARY_WATER)
B(0,-16,3,STATIONARY_WATER)
B(0,-16,4,STATIONARY_WATER)
B(0,-16,5,STATIONARY_WATER)
B(0,-16,6,STONE)
B(0,-16,7,STONE)
B(0,-16,8,MOSSY_COBBLESTONE)
B(0,-16,9,STONE)
B(0,-15,-9,STONE)
B(0,-15,-8,STONE)
B(0,-15,-7,STONE)
B(0,-15,-6,STATIONARY_WATER)
B(0,-15,-5,STATIONARY_WATER)
B(0,-15,-4,STATIONARY_WATER)
B(0,-15,-3,STATIONARY_WATER)
B(0,-15,-2,STATIONARY_WATER)
B(0,-15,-1,STATIONARY_WATER)
B(0,-15,0,STATIONARY_WATER)
B(0,-15,1,STATIONARY_WATER)
B(0,-15,2,STATIONARY_WATER)
B(0,-15,3,STATIONARY_WATER)
B(0,-15,4,STATIONARY_WATER)
B(0,-15,5,STATIONARY_WATER)
B(0,-15,6,STATIONARY_WATER)
B(0,-15,7,STATIONARY_WATER)
B(0,-15,8,STONE)
B(0,-15,9,STONE)
B(0,-15,10,STONE)
B(0,-14,-9,STONE)
B(0,-14,-8,AIR)
B(0,-14,-7,AIR)
B(0,-14,-6,AIR)
B(0,-14,-5,AIR)
B(0,-14,-4,AIR)
B(0,-14,-3,AIR)
B(0,-14,-2,AIR)
B(0,-14,-1,AIR)
B(0,-14,0,AIR)
B(0,-14,1,STATIONARY_WATER:8)
B(0,-14,2,STATIONARY_WATER:8)
B(0,-14,3,AIR)
B(0,-14,4,AIR)
B(0,-14,5,AIR)
B(0,-14,6,AIR)
B(0,-14,7,AIR)
B(0,-14,8,AIR)
B(0,-14,9,STONE)
B(0,-14,10,STONE)
B(0,-14,11,STONE)
B(0,-13,-9,MOSSY_COBBLESTONE)
B(0,-13,-8,AIR)
B(0,-13,-7,AIR)
B(0,-13,-6,AIR)
B(0,-13,-5,AIR)
B(0,-13,-4,AIR)
B(0,-13,-3,AIR)
B(0,-13,-2,AIR)
B(0,-13,-1,AIR)
B(0,-13,0,AIR)
B(0,-13,1,STATIONARY_WATER:8)
B(0,-13,2,STATIONARY_WATER:8)
B(0,-13,3,AIR)
B(0,-13,4,AIR)
B(0,-13,5,AIR)
B(0,-13,6,AIR)
B(0,-13,7,AIR)
B(0,-13,8,AIR)
B(0,-13,9,AIR)
B(0,-13,10,STONE)
B(0,-13,11,STONE)
B(0,-13,12,STONE)
B(0,-12,-10,STONE)
B(0,-12,-9,STONE)
B(0,-12,-8,AIR)
B(0,-12,-7,AIR)
B(0,-12,-6,AIR)
B(0,-12,-5,AIR)
B(0,-12,-4,AIR)
B(0,-12,-3,AIR)
B(0,-12,-2,AIR)
B(0,-12,-1,AIR)
B(0,-12,0,AIR)
B(0,-12,1,STATIONARY_WATER:8)
B(0,-12,2,STATIONARY_WATER:8)
B(0,-12,3,AIR)
B(0,-12,4,AIR)
B(0,-12,5,AIR)
B(0,-12,6,AIR)
B(0,-12,7,AIR)
B(0,-12,8,AIR)
B(0,-12,9,AIR)
B(0,-12,10,STONE)
B(0,-12,11,STONE)
B(0,-11,-11,STONE)
B(0,-11,-10,STONE)
B(0,-11,-9,STONE)
B(0,-11,-8,AIR)
B(0,-11,-7,AIR)
B(0,-11,-6,AIR)
B(0,-11,-5,AIR)
B(0,-11,-4,AIR)
B(0,-11,-3,AIR)
B(0,-11,-2,AIR)
B(0,-11,-1,AIR)
B(0,-11,0,AIR)
B(0,-11,1,STATIONARY_WATER:8)
B(0,-11,2,STATIONARY_WATER:8)
B(0,-11,3,AIR)
B(0,-11,4,AIR)
B(0,-11,5,AIR)
B(0,-11,6,AIR)
B(0,-11,7,AIR)
B(0,-11,8,AIR)
B(0,-11,9,AIR)
B(0,-11,10,MOSSY_COBBLESTONE)
B(0,-11,11,STONE)
B(0,-10,-13,STONE)
B(0,-10,-12,STONE)
B(0,-10,-11,STONE)
B(0,-10,-10,STONE)
B(0,-10,-9,STONE)
B(0,-10,-8,STONE)
B(0,-10,-7,STONE)
B(0,-10,-6,STONE)
B(0,-10,-5,AIR)
B(0,-10,-4,AIR)
B(0,-10,-3,AIR)
B(0,-10,-2,AIR)
B(0,-10,-1,AIR)
B(0,-10,0,AIR)
B(0,-10,1,STATIONARY_WATER:8)
B(0,-10,2,STATIONARY_WATER:8)
B(0,-10,3,AIR)
B(0,-10,4,AIR)
B(0,-10,5,AIR)
B(0,-10,6,AIR)
B(0,-10,7,AIR)
B(0,-10,8,AIR)
B(0,-10,9,AIR)
B(0,-10,10,STONE)
B(0,-9,-13,STONE)
B(0,-9,-12,STONE)
B(0,-9,-11,STONE)
B(0,-9,-10,STONE)
B(0,-9,-9,STONE)
B(0,-9,-8,STONE)
B(0,-9,-7,STONE)
B(0,-9,-6,STONE)
B(0,-9,-5,STONE)
B(0,-9,-4,STONE)
B(0,-9,-3,AIR)
B(0,-9,-2,AIR)
B(0,-9,-1,AIR)
B(0,-9,0,AIR)
B(0,-9,1,STATIONARY_WATER:8)
B(0,-9,2,STATIONARY_WATER:8)
B(0,-9,3,AIR)
B(0,-9,4,AIR)
B(0,-9,5,AIR)
B(0,-9,6,AIR)
B(0,-9,7,STONE)
B(0,-9,8,STONE)
B(0,-9,9,STONE)
B(0,-9,10,STONE)
B(0,-8,-13,STONE)
B(0,-8,-12,STONE)
B(0,-8,-11,STONE)
B(0,-8,-10,STONE)
B(0,-8,-9,STONE)
B(0,-8,-8,STONE)
B(0,-8,-7,STONE)
B(0,-8,-6,STONE)
B(0,-8,-5,STONE)
B(0,-8,-4,STONE)
B(0,-8,-3,STONE)
B(0,-8,-2,STONE)
B(0,-8,-1,AIR)
B(0,-8,0,AIR)
B(0,-8,1,STATIONARY_WATER:8)
B(0,-8,2,STATIONARY_WATER:8)
B(0,-8,3,AIR)
B(0,-8,4,AIR)
B(0,-8,5,AIR)
B(0,-8,6,STONE)
B(0,-8,7,STONE)
B(0,-8,8,STONE)
B(0,-8,9,STONE)
B(0,-8,10,STONE)
B(0,-7,-13,STONE)
B(0,-7,-12,STONE)
B(0,-7,-11,STONE)
B(0,-7,-10,STONE)
B(0,-7,-9,STONE)
B(0,-7,-8,STONE)
B(0,-7,-7,STONE)
B(0,-7,-6,STONE)
B(0,-7,-5,STONE)
B(0,-7,-4,AIR)
B(0,-7,-3,AIR)
B(0,-7,-2,AIR)
B(0,-7,-1,AIR)
B(0,-7,0,AIR)
B(0,-7,1,STATIONARY_WATER:8)
B(0,-7,2,STATIONARY_WATER:8)
B(0,-7,3,AIR)
B(0,-7,4,AIR)
B(0,-7,5,AIR)
B(0,-7,6,AIR)
B(0,-7,7,AIR)
B(0,-7,8,STONE)
B(0,-7,9,STONE)
B(0,-7,10,STONE)
B(0,-6,-12,STONE)
B(0,-6,-11,STONE)
B(0,-6,-10,STONE)
B(0,-6,-9,STONE)
B(0,-6,-8,STONE)
B(0,-6,-7,STONE)
B(0,-6,-6,AIR)
B(0,-6,-5,AIR)
B(0,-6,-4,AIR)
B(0,-6,-3,AIR)
B(0,-6,-2,AIR)
B(0,-6,-1,AIR)
B(0,-6,0,AIR)
B(0,-6,1,STATIONARY_WATER:8)
B(0,-6,2,STATIONARY_WATER:8)
B(0,-6,3,AIR)
B(0,-6,4,AIR)
B(0,-6,5,AIR)
B(0,-6,6,AIR)
B(0,-6,7,AIR)
B(0,-6,8,STONE)
B(0,-6,9,STONE)
B(0,-6,10,STONE)
B(0,-5,-12,STONE)
B(0,-5,-11,STONE)
B(0,-5,-10,STONE)
B(0,-5,-9,STONE)
B(0,-5,-8,STONE)
B(0,-5,-7,AIR)
B(0,-5,-6,AIR)
B(0,-5,-5,AIR)
B(0,-5,-4,AIR)
B(0,-5,-3,AIR)
B(0,-5,-2,AIR)
B(0,-5,-1,AIR)
B(0,-5,0,AIR)
B(0,-5,1,STATIONARY_WATER:8)
B(0,-5,2,STATIONARY_WATER:8)
B(0,-5,3,AIR)
B(0,-5,4,AIR)
B(0,-5,5,AIR)
B(0,-5,6,AIR)
B(0,-5,7,AIR)
B(0,-5,8,AIR)
B(0,-5,9,STONE)
B(0,-5,10,STONE)
B(0,-5,11,STONE)
B(0,-5,12,STONE)
B(0,-5,13,STONE)
B(0,-4,-11,STONE)
B(0,-4,-10,STONE)
B(0,-4,-9,STONE)
B(0,-4,-8,STONE)
B(0,-4,-7,AIR)
B(0,-4,-6,AIR)
B(0,-4,-5,AIR)
B(0,-4,-4,AIR)
B(0,-4,-3,AIR)
B(0,-4,-2,AIR)
B(0,-4,-1,AIR)
B(0,-4,0,AIR)
B(0,-4,1,STATIONARY_WATER:8)
B(0,-4,2,STATIONARY_WATER:8)
B(0,-4,3,AIR)
B(0,-4,4,AIR)
B(0,-4,5,AIR)
B(0,-4,6,AIR)
B(0,-4,7,AIR)
B(0,-4,8,AIR)
B(0,-4,9,AIR)
B(0,-4,10,STONE)
B(0,-4,11,STONE)
B(0,-4,12,STONE)
B(0,-4,13,STONE)
B(0,-4,14,STONE)
B(0,-3,-9,STONE)
B(0,-3,-8,STONE)
B(0,-3,-7,AIR)
B(0,-3,-6,AIR)
B(0,-3,-5,AIR)
B(0,-3,-4,AIR)
B(0,-3,-3,AIR)
B(0,-3,-2,AIR)
B(0,-3,-1,AIR)
B(0,-3,0,AIR)
B(0,-3,1,STATIONARY_WATER:8)
B(0,-3,2,STATIONARY_WATER:8)
B(0,-3,3,AIR)
B(0,-3,4,AIR)
B(0,-3,5,AIR)
B(0,-3,6,AIR)
B(0,-3,7,AIR)
B(0,-3,8,AIR)
B(0,-3,9,AIR)
B(0,-3,10,AIR)
B(0,-3,11,STONE)
B(0,-3,12,STONE)
B(0,-3,13,STONE)
B(0,-3,14,STONE)
B(0,-2,-9,STONE)
B(0,-2,-8,STONE)
B(0,-2,-7,STONE)
B(0,-2,-6,STONE)
B(0,-2,-5,AIR)
B(0,-2,-4,AIR)
B(0,-2,-3,AIR)
B(0,-2,-2,AIR)
B(0,-2,-1,AIR)
B(0,-2,0,AIR)
B(0,-2,1,STATIONARY_WATER:8)
B(0,-2,2,STATIONARY_WATER:8)
B(0,-2,3,AIR)
B(0,-2,4,AIR)
B(0,-2,5,AIR)
B(0,-2,6,AIR)
B(0,-2,7,AIR)
B(0,-2,8,AIR)
B(0,-2,9,AIR)
B(0,-2,10,AIR)
B(0,-2,11,STONE)
B(0,-2,12,STONE)
B(0,-2,13,STONE)
B(0,-1,-8,STONE)
B(0,-1,-7,STONE)
B(0,-1,-6,STONE)
B(0,-1,-5,STONE)
B(0,-1,-4,STONE)
B(0,-1,-3,AIR)
B(0,-1,-2,AIR)
B(0,-1,-1,AIR)
B(0,-1,0,AIR)
B(0,-1,1,STATIONARY_WATER:8)
B(0,-1,2,STATIONARY_WATER:8)
B(0,-1,3,AIR)
B(0,-1,4,AIR)
B(0,-1,5,AIR)
B(0,-1,6,AIR)
B(0,-1,7,AIR)
B(0,-1,8,AIR)
B(0,-1,9,AIR)
B(0,-1,10,AIR)
B(0,-1,11,STONE)
B(0,0,-8,STONE)
B(0,0,-7,STONE)
B(0,0,-6,STONE)
B(0,0,-5,STONE)
B(0,0,-4,STONE)
B(0,0,-3,STONE)
B(0,0,-2,AIR)
B(0,0,-1,AIR)
B(0,0,0,AIR)
B(0,0,1,STATIONARY_WATER:8)
B(0,0,2,STATIONARY_WATER:8)
B(0,0,3,AIR)
B(0,0,4,AIR)
B(0,0,5,AIR)
B(0,0,6,AIR)
B(0,0,7,AIR)
B(0,0,8,STONE)
B(0,0,9,STONE)
B(0,0,10,STONE)
B(0,1,-7,STONE)
B(0,1,-6,STONE)
B(0,1,-5,STONE)
B(0,1,-4,STONE)
B(0,1,-3,STONE)
B(0,1,-2,STONE)
B(0,1,-1,AIR)
B(0,1,0,AIR)
B(0,1,1,STATIONARY_WATER:8)
B(0,1,2,STATIONARY_WATER:8)
B(0,1,3,AIR)
B(0,1,4,AIR)
B(0,1,5,AIR)
B(0,1,6,STONE)
B(0,1,7,STONE)
B(0,1,8,STONE)
B(0,1,9,STONE)
B(0,2,-3,STONE)
B(0,2,-2,STONE)
B(0,2,-1,STONE)
B(0,2,0,STONE)
B(0,2,1,STATIONARY_WATER)
B(0,2,2,STATIONARY_WATER)
B(0,2,3,STONE)
B(0,2,4,STONE)
B(0,2,5,MOSSY_COBBLESTONE)
B(0,2,6,STONE)
B(0,2,7,STONE)
B(1,-21,-1,STONE)
B(1,-21,0,STONE)
B(1,-21,1,STONE)
B(1,-21,2,STONE)
B(1,-21,3,STONE)
B(1,-21,4,STONE)
B(1,-21,5,STONE)
B(1,-20,-7,STONE)
B(1,-20,-6,STONE)
B(1,-20,-5,STONE)
B(1,-20,-4,STONE)
B(1,-20,-3,STONE)
B(1,-20,-2,STONE)
B(1,-20,-1,STONE)
B(1,-20,0,STONE)
B(1,-20,1,STONE)
B(1,-20,2,STONE)
B(1,-20,3,STONE)
B(1,-20,4,STONE)
B(1,-20,5,STONE)
B(1,-19,-8,STONE)
B(1,-19,-7,STONE)
B(1,-19,-6,STONE)
B(1,-19,-5,STONE)
B(1,-19,-4,STONE)
B(1,-19,-3,STONE)
B(1,-19,-2,STONE)
B(1,-19,-1,STONE)
B(1,-19,0,STONE)
B(1,-19,1,STONE)
B(1,-19,2,STONE)
B(1,-19,3,STONE)
B(1,-19,4,STONE)
B(1,-19,5,STONE)
B(1,-19,6,STONE)
B(1,-19,7,STONE)
B(1,-18,-8,STONE)
B(1,-18,-7,STONE)
B(1,-18,-6,STONE)
B(1,-18,-5,STONE)
B(1,-18,-4,STONE)
B(1,-18,-3,STONE)
B(1,-18,-2,STONE)
B(1,-18,-1,STONE)
B(1,-18,0,STONE)
B(1,-18,1,STONE)
B(1,-18,2,STONE)
B(1,-18,3,STATIONARY_WATER)
B(1,-18,4,STONE)
B(1,-18,5,STONE)
B(1,-18,6,STONE)
B(1,-18,7,STONE)
B(1,-18,8,STONE)
B(1,-18,9,STONE)
B(1,-17,-8,STONE)
B(1,-17,-7,STONE)
B(1,-17,-6,STONE)
B(1,-17,-5,STONE)
B(1,-17,-4,STONE)
B(1,-17,-3,STONE)
B(1,-17,-2,STONE)
B(1,-17,-1,STONE)
B(1,-17,0,STONE)
B(1,-17,1,STATIONARY_WATER)
B(1,-17,2,STATIONARY_WATER)
B(1,-17,3,STATIONARY_WATER)
B(1,-17,4,STATIONARY_WATER)
B(1,-17,5,STONE)
B(1,-17,6,STONE)
B(1,-17,7,STONE)
B(1,-17,8,STONE)
B(1,-17,9,STONE)
B(1,-16,-9,STONE)
B(1,-16,-8,STONE)
B(1,-16,-7,STONE)
B(1,-16,-6,STONE)
B(1,-16,-5,STONE)
B(1,-16,-4,STONE)
B(1,-16,-3,STONE)
B(1,-16,-2,STONE)
B(1,-16,-1,STATIONARY_WATER)
B(1,-16,0,STATIONARY_WATER)
B(1,-16,1,STATIONARY_WATER)
B(1,-16,2,STATIONARY_WATER)
B(1,-16,3,STATIONARY_WATER)
B(1,-16,4,STATIONARY_WATER)
B(1,-16,5,STATIONARY_WATER)
B(1,-16,6,MOSSY_COBBLESTONE)
B(1,-16,7,STONE)
B(1,-16,8,STONE)
B(1,-16,9,STONE)
B(1,-15,-9,STONE)
B(1,-15,-8,STONE)
B(1,-15,-7,STATIONARY_WATER)
B(1,-15,-6,STATIONARY_WATER)
B(1,-15,-5,STATIONARY_WATER)
B(1,-15,-4,STATIONARY_WATER)
B(1,-15,-3,STATIONARY_WATER)
B(1,-15,-2,STATIONARY_WATER)
B(1,-15,-1,STATIONARY_WATER)
B(1,-15,0,STATIONARY_WATER)
B(1,-15,1,STATIONARY_WATER)
B(1,-15,2,STATIONARY_WATER)
B(1,-15,3,STATIONARY_WATER)
B(1,-15,4,STATIONARY_WATER)
B(1,-15,5,STATIONARY_WATER)
B(1,-15,6,STATIONARY_WATER)
B(1,-15,7,MOSSY_COBBLESTONE)
B(1,-15,8,STONE)
B(1,-15,9,STONE)
B(1,-15,10,STONE)
B(1,-14,-10,STONE)
B(1,-14,-9,STONE)
B(1,-14,-8,AIR)
B(1,-14,-7,AIR)
B(1,-14,-6,AIR)
B(1,-14,-5,AIR)
B(1,-14,-4,AIR)
B(1,-14,-3,AIR)
B(1,-14,-2,AIR)
B(1,-14,-1,AIR)
B(1,-14,0,STATIONARY_WATER:8)
B(1,-14,1,AIR)
B(1,-14,2,AIR)
B(1,-14,3,AIR)
B(1,-14,4,AIR)
B(1,-14,5,AIR)
B(1,-14,6,AIR)
B(1,-14,7,AIR)
B(1,-14,8,STONE)
B(1,-14,9,STONE)
B(1,-14,10,STONE)
B(1,-14,11,STONE)
B(1,-13,-10,STONE)
B(1,-13,-9,STONE)
B(1,-13,-8,AIR)
B(1,-13,-7,AIR)
B(1,-13,-6,AIR)
B(1,-13,-5,AIR)
B(1,-13,-4,AIR)
B(1,-13,-3,AIR)
B(1,-13,-2,AIR)
B(1,-13,-1,AIR)
B(1,-13,0,STATIONARY_WATER:8)
B(1,-13,1,AIR)
B(1,-13,2,AIR)
B(1,-13,3,AIR)
B(1,-13,4,AIR)
B(1,-13,5,AIR)
B(1,-13,6,AIR)
B(1,-13,7,AIR)
B(1,-13,8,AIR)
B(1,-13,9,STONE)
B(1,-13,10,STONE)
B(1,-13,11,STONE)
B(1,-12,-11,STONE)
B(1,-12,-10,STONE)
B(1,-12,-9,STONE)
B(1,-12,-8,AIR)
B(1,-12,-7,AIR)
B(1,-12,-6,AIR)
B(1,-12,-5,AIR)
B(1,-12,-4,AIR)
B(1,-12,-3,AIR)
B(1,-12,-2,AIR)
B(1,-12,-1,AIR)
B(1,-12,0,STATIONARY_WATER:8)
B(1,-12,1,AIR)
B(1,-12,2,AIR)
B(1,-12,3,AIR)
B(1,-12,4,AIR)
B(1,-12,5,AIR)
B(1,-12,6,AIR)
B(1,-12,7,AIR)
B(1,-12,8,AIR)
B(1,-12,9,MOSSY_COBBLESTONE)
B(1,-12,10,STONE)
B(1,-12,11,STONE)
B(1,-11,-12,STONE)
B(1,-11,-11,STONE)
B(1,-11,-10,STONE)
B(1,-11,-9,STONE)
B(1,-11,-8,AIR)
B(1,-11,-7,AIR)
B(1,-11,-6,AIR)
B(1,-11,-5,AIR)
B(1,-11,-4,AIR)
B(1,-11,-3,AIR)
B(1,-11,-2,AIR)
B(1,-11,-1,AIR)
B(1,-11,0,STATIONARY_WATER:8)
B(1,-11,1,AIR)
B(1,-11,2,AIR)
B(1,-11,3,AIR)
B(1,-11,4,AIR)
B(1,-11,5,AIR)
B(1,-11,6,AIR)
B(1,-11,7,AIR)
B(1,-11,8,AIR)
B(1,-11,9,AIR)
B(1,-11,10,STONE)
B(1,-11,11,STONE)
B(1,-10,-13,STONE)
B(1,-10,-12,STONE)
B(1,-10,-11,STONE)
B(1,-10,-10,STONE)
B(1,-10,-9,STONE)
B(1,-10,-8,STONE)
B(1,-10,-7,STONE)
B(1,-10,-6,AIR)
B(1,-10,-5,AIR)
B(1,-10,-4,AIR)
B(1,-10,-3,AIR)
B(1,-10,-2,AIR)
B(1,-10,-1,AIR)
B(1,-10,0,STATIONARY_WATER:8)
B(1,-10,1,AIR)
B(1,-10,2,AIR)
B(1,-10,3,AIR)
B(1,-10,4,AIR)
B(1,-10,5,AIR)
B(1,-10,6,AIR)
B(1,-10,7,AIR)
B(1,-10,8,AIR)
B(1,-10,9,STONE)
B(1,-10,10,STONE)
B(1,-10,11,STONE)
B(1,-9,-13,STONE)
B(1,-9,-12,STONE)
B(1,-9,-11,STONE)
B(1,-9,-10,STONE)
B(1,-9,-9,STONE)
B(1,-9,-8,STONE)
B(1,-9,-7,STONE)
B(1,-9,-6,STONE)
B(1,-9,-5,STONE)
B(1,-9,-4,AIR)
B(1,-9,-3,AIR)
B(1,-9,-2,AIR)
B(1,-9,-1,AIR)
B(1,-9,0,STATIONARY_WATER:8)
B(1,-9,1,AIR)
B(1,-9,2,AIR)
B(1,-9,3,AIR)
B(1,-9,4,AIR)
B(1,-9,5,STONE)
B(1,-9,6,STONE)
B(1,-9,7,STONE)
B(1,-9,8,STONE)
B(1,-9,9,STONE)
B(1,-9,10,STONE)
B(1,-8,-13,STONE)
B(1,-8,-12,STONE)
B(1,-8,-11,STONE)
B(1,-8,-10,STONE)
B(1,-8,-9,STONE)
B(1,-8,-8,STONE)
B(1,-8,-7,STONE)
B(1,-8,-6,STONE)
B(1,-8,-5,STONE)
B(1,-8,-4,STONE)
B(1,-8,-3,STONE)
B(1,-8,-2,AIR)
B(1,-8,-1,AIR)
B(1,-8,0,STATIONARY_WATER:8)
B(1,-8,1,AIR)
B(1,-8,2,AIR)
B(1,-8,3,AIR)
B(1,-8,4,AIR)
B(1,-8,5,STONE)
B(1,-8,6,STONE)
B(1,-8,7,STONE)
B(1,-8,8,STONE)
B(1,-8,9,STONE)
B(1,-8,10,STONE)
B(1,-7,-13,STONE)
B(1,-7,-12,STONE)
B(1,-7,-11,STONE)
B(1,-7,-10,STONE)
B(1,-7,-9,STONE)
B(1,-7,-8,STONE)
B(1,-7,-7,STONE)
B(1,-7,-6,STONE)
B(1,-7,-5,STONE)
B(1,-7,-4,AIR)
B(1,-7,-3,AIR)
B(1,-7,-2,AIR)
B(1,-7,-1,AIR)
B(1,-7,0,STATIONARY_WATER:8)
B(1,-7,1,AIR)
B(1,-7,2,AIR)
B(1,-7,3,AIR)
B(1,-7,4,AIR)
B(1,-7,5,AIR)
B(1,-7,6,AIR)
B(1,-7,7,STONE)
B(1,-7,8,STONE)
B(1,-7,9,STONE)
B(1,-7,10,STONE)
B(1,-6,-13,STONE)
B(1,-6,-12,STONE)
B(1,-6,-11,STONE)
B(1,-6,-10,STONE)
B(1,-6,-9,STONE)
B(1,-6,-8,STONE)
B(1,-6,-7,AIR)
B(1,-6,-6,AIR)
B(1,-6,-5,AIR)
B(1,-6,-4,AIR)
B(1,-6,-3,AIR)
B(1,-6,-2,AIR)
B(1,-6,-1,AIR)
B(1,-6,0,STATIONARY_WATER:8)
B(1,-6,1,AIR)
B(1,-6,2,AIR)
B(1,-6,3,AIR)
B(1,-6,4,AIR)
B(1,-6,5,AIR)
B(1,-6,6,AIR)
B(1,-6,7,AIR)
B(1,-6,8,STONE)
B(1,-6,9,STONE)
B(1,-6,10,STONE)
B(1,-6,11,STONE)
B(1,-5,-12,STONE)
B(1,-5,-11,STONE)
B(1,-5,-10,STONE)
B(1,-5,-9,STONE)
B(1,-5,-8,AIR)
B(1,-5,-7,AIR)
B(1,-5,-6,AIR)
B(1,-5,-5,AIR)
B(1,-5,-4,AIR)
B(1,-5,-3,AIR)
B(1,-5,-2,AIR)
B(1,-5,-1,AIR)
B(1,-5,0,STATIONARY_WATER:8)
B(1,-5,1,AIR)
B(1,-5,2,AIR)
B(1,-5,3,AIR)
B(1,-5,4,AIR)
B(1,-5,5,AIR)
B(1,-5,6,AIR)
B(1,-5,7,AIR)
B(1,-5,8,AIR)
B(1,-5,9,STONE)
B(1,-5,10,STONE)
B(1,-5,11,STONE)
B(1,-5,12,STONE)
B(1,-5,13,STONE)
B(1,-4,-11,STONE)
B(1,-4,-10,STONE)
B(1,-4,-9,STONE)
B(1,-4,-8,AIR)
B(1,-4,-7,AIR)
B(1,-4,-6,AIR)
B(1,-4,-5,AIR)
B(1,-4,-4,AIR)
B(1,-4,-3,AIR)
B(1,-4,-2,AIR)
B(1,-4,-1,AIR)
B(1,-4,0,STATIONARY_WATER:8)
B(1,-4,1,AIR)
B(1,-4,2,AIR)
B(1,-4,3,AIR)
B(1,-4,4,AIR)
B(1,-4,5,AIR)
B(1,-4,6,AIR)
B(1,-4,7,AIR)
B(1,-4,8,AIR)
B(1,-4,9,AIR)
B(1,-4,10,STONE)
B(1,-4,11,STONE)
B(1,-4,12,STONE)
B(1,-4,13,STONE)
B(1,-4,14,STONE)
B(1,-3,-10,STONE)
B(1,-3,-9,STONE)
B(1,-3,-8,STONE)
B(1,-3,-7,AIR)
B(1,-3,-6,AIR)
B(1,-3,-5,AIR)
B(1,-3,-4,AIR)
B(1,-3,-3,AIR)
B(1,-3,-2,AIR)
B(1,-3,-1,AIR)
B(1,-3,0,STATIONARY_WATER:8)
B(1,-3,1,AIR)
B(1,-3,2,AIR)
B(1,-3,3,AIR)
B(1,-3,4,AIR)
B(1,-3,5,AIR)
B(1,-3,6,AIR)
B(1,-3,7,AIR)
B(1,-3,8,AIR)
B(1,-3,9,AIR)
B(1,-3,10,STONE)
B(1,-3,11,STONE)
B(1,-3,12,STONE)
B(1,-3,13,STONE)
B(1,-3,14,STONE)
B(1,-2,-9,STONE)
B(1,-2,-8,STONE)
B(1,-2,-7,STONE)
B(1,-2,-6,AIR)
B(1,-2,-5,AIR)
B(1,-2,-4,AIR)
B(1,-2,-3,AIR)
B(1,-2,-2,AIR)
B(1,-2,-1,AIR)
B(1,-2,0,STATIONARY_WATER:8)
B(1,-2,1,AIR)
B(1,-2,2,AIR)
B(1,-2,3,AIR)
B(1,-2,4,AIR)
