
#######################################################################
# +-----------------------------------------------------------------+ #
# |                            BO3 object                           | #
# +-----------------------------------------------------------------+ #
#######################################################################

# This is the config file of a custom object.
# If you add this object correctly to your BiomeConfigs, it will spawn in the world.

# This is the creator of this BO3 object
Author: MC_Pitman

# A short description of this BO3 object
Description: No description given

# The BO3 version, don't change this! It can be used by external applications to do a version check.
Version: 3

# The settings mode, WriteAll, WriteWithoutComments or WriteDisable. See WorldConfig.
SettingsMode: WriteDisable


#######################################################################
# +-----------------------------------------------------------------+ #
# |                          Main settings                          | #
# +-----------------------------------------------------------------+ #
#######################################################################

# This needs to be set to true to spawn the object in the Tree and Sapling resources.
Tree: false

# The frequency of the BO3 from 1 to 200. Tries this many times to spawn this BO3 when using the CustomObject(...) resource.
# Ignored by Tree(..), Sapling(..) and CustomStructure(..)
Frequency: 1

# The rarity of the BO3 from 0 to 100. Each spawn attempt has rarity% chance to succeed when using the CustomObject(...) resource.
# Ignored by Tree(..), Sapling(..) and CustomStructure(..)
Rarity: 1.0

# If you set this to true, the BO3 will be placed with a random rotation.
RotateRandomly: true

# The spawn height of the BO3 - atMinY, randomY, highestBlock or highestSolidBlock.
SpawnHeight: highestSolidBlock

# The offset from the spawn height to spawn this BO3
# Ex. SpawnHeight = highestSolidBlock, SpawnHeightOffset = 3; This object will spawn 3 blocks above the highest solid block
SpawnHeightOffset: 0

# A random amount to offset the spawn location from the spawn offset height
# Ex. SpawnHeightOffset = 3, SpawnHeightVariance = 3; This object will spawn 3 to 6 blocks above the original spot it would have spawned
SpawnHeightVariance: 0

##############################
# Height Limits for the BO3. #
##############################

# When in randomY mode used as the minimum Y or in atMinY mode as the actual Y to spawn this BO3 at.
MinHeight: 0

# When in randomY mode used as the maximum Y to spawn this BO3 at.
MaxHeight: 80

######################
# Extrusion settings #
######################

# The style of extrusion you wish to use - BottomDown, TopUp, None (Default)
ExtrudeMode: None

# The blocks to extrude your BO3 through
ExtrudeThroughBlocks: AIR

# Objects can have other objects attacthed to it: branches. Branches can also
# have branches attached to it, which can also have branches, etc. This is the
# maximum branch depth for this objects.
MaxBranchDepth: 10

# When spawned with the UseWorld keyword, this BO3 should NOT spawn in the following biomes.
# If you write the BO3 name directly in the BiomeConfigs, this will be ignored.
ExcludedBiomes: All


#######################################################################
# +-----------------------------------------------------------------+ #
# |                      Source block settings                      | #
# +-----------------------------------------------------------------+ #
#######################################################################

# The block(s) the BO3 should spawn in.
SourceBlocks: AIR,GRASS,DIRT,GRAVEL,SAND,STONE,STONE:1,STONE:3,STONE:5,DIRT:1,CLAY,HARD_CLAY,38,38:1,38:2,38:3,38:4,38:5,38:6,38:7,38:8,39,40,175,175:1,175:2,175:3,175:4,175:5,31,31:1,31:2,32

# The maximum percentage of the BO3 that can be outside the SourceBlock.
# The BO3 won't be placed on a location with more blocks outside the SourceBlock than this percentage.
MaxPercentageOutsideSourceBlock: 10

# What to do when a block is about to be placed outside the SourceBlock? (dontPlace, placeAnyway)
OutsideSourceBlock: placeAnyway


#######################################################################
# +-----------------------------------------------------------------+ #
# |                              Blocks                             | #
# +-----------------------------------------------------------------+ #
#######################################################################

# All the blocks used in the BO3 are listed here. Possible blocks:
# Block(x,y,z,id[.data][,nbtfile.nbt)
# RandomBlock(x,y,z,id[:data][,nbtfile.nbt],chance[,id[:data][,nbtfile.nbt],chance[,...]])
#  So RandomBlock(0,0,0,CHEST,chest.nbt,50,CHEST,anotherchest.nbt,100) will spawn a chest at
#  the BO3 origin, and give it a 50% chance to have the contents of chest.nbt, or, if that
#  fails, a 100% percent chance to have the contents of anotherchest.nbt.
# MinecraftObject(x,y,z,name)
#  Spawns an object in the Mojang NBT structure format. For example, 
#  MinecraftObject(0,0,0,minecraft:igloo/igloo_bottom)
#  spawns the bottom part of an igloo.
Block(-6,-5,-1,STONE)
Block(-6,-5,0,STONE)
Block(-6,-4,-1,STONE)
Block(-6,-4,0,STONE)
Block(-6,-3,-3,STONE)
Block(-6,-3,-2,STONE)
Block(-6,-3,-1,STONE)
Block(-6,-3,0,STONE)
Block(-6,-3,2,STONE)
Block(-6,-2,-4,STONE)
Block(-6,-2,-3,STONE)
Block(-6,-2,-2,STONE)
Block(-6,-2,-1,STONE)
Block(-6,-2,0,STONE)
Block(-6,-2,2,STONE)
Block(-6,-2,3,STONE)
Block(-6,-2,4,STONE)
Block(-6,-2,5,STONE)
Block(-6,-1,-3,STONE)
Block(-6,-1,-2,STONE)
Block(-6,-1,-1,STONE)
Block(-6,-1,0,STONE)
Block(-6,-1,2,STONE)
Block(-6,-1,3,STONE)
Block(-6,0,2,STONE)
Block(-6,0,3,STONE)
Block(-6,1,2,STONE)
Block(-5,-6,-1,STONE)
Block(-5,-6,0,STONE)
Block(-5,-5,-1,STONE)
Block(-5,-5,0,STONE)
Block(-5,-5,1,STONE)
Block(-5,-5,2,STONE)
Block(-5,-5,3,STONE)
Block(-5,-4,-2,STONE)
Block(-5,-4,-1,STONE)
Block(-5,-4,0,STONE)
Block(-5,-4,1,STONE)
Block(-5,-4,2,STONE)
Block(-5,-4,3,STONE)
Block(-5,-4,4,STONE)
Block(-5,-3,-6,STONE)
Block(-5,-3,-5,STONE)
Block(-5,-3,-4,STONE)
Block(-5,-3,-3,STONE)
Block(-5,-3,-2,STONE)
Block(-5,-3,-1,STONE)
Block(-5,-3,0,STONE)
Block(-5,-3,1,STONE)
Block(-5,-3,2,STONE)
Block(-5,-3,3,STONE)
Block(-5,-3,4,STONE)
Block(-5,-3,5,STONE)
Block(-5,-3,6,STONE)
Block(-5,-2,-6,STONE)
Block(-5,-2,-5,STONE)
Block(-5,-2,-4,STONE)
Block(-5,-2,-3,STONE)
Block(-5,-2,-2,STONE)
Block(-5,-2,-1,STONE)
Block(-5,-2,0,STONE)
Block(-5,-2,1,STONE)
Block(-5,-2,2,STONE)
Block(-5,-2,3,STONE)
Block(-5,-2,4,STONE)
Block(-5,-2,5,STONE)
Block(-5,-2,6,STONE)
Block(-5,-1,-5,STONE)
Block(-5,-1,-4,STONE)
Block(-5,-1,-3,STONE)
Block(-5,-1,-2,STONE)
Block(-5,-1,-1,STONE)
Block(-5,-1,0,STONE)
Block(-5,-1,1,STONE)
Block(-5,-1,2,STONE)
Block(-5,-1,3,STONE)
Block(-5,-1,4,STONE)
Block(-5,-1,5,STONE)
Block(-5,0,-4,STONE)
Block(-5,0,-3,STONE)
Block(-5,0,-2,STONE)
Block(-5,0,-1,STONE)
Block(-5,0,0,STONE)
Block(-5,0,1,STONE)
Block(-5,0,2,STONE)
Block(-5,0,3,STONE)
Block(-5,0,4,STONE)
Block(-5,1,-4,STONE)
Block(-5,1,1,STONE)
Block(-5,1,2,STONE)
Block(-5,1,3,STONE)
Block(-5,2,2,STONE)
Block(-5,2,3,STONE)
Block(-4,-7,-1,STONE)
Block(-4,-7,0,STONE)
Block(-4,-7,2,STONE)
Block(-4,-7,3,STONE)
Block(-4,-6,-4,STONE)
Block(-4,-6,-2,STONE)
Block(-4,-6,-1,STONE)
Block(-4,-6,0,STONE)
Block(-4,-6,1,STONE)
Block(-4,-6,2,STONE)
Block(-4,-6,3,STONE)
Block(-4,-5,-3,STONE)
Block(-4,-5,-2,STONE)
Block(-4,-5,-1,STONE)
Block(-4,-5,0,STONE)
Block(-4,-5,1,STONE)
Block(-4,-5,2,STONE)
Block(-4,-5,3,STONE)
Block(-4,-5,4,STONE)
Block(-4,-4,-3,STONE)
Block(-4,-4,-2,STONE)
Block(-4,-4,-1,STONE)
Block(-4,-4,0,STONE)
Block(-4,-4,1,STONE)
Block(-4,-4,2,STONE)
Block(-4,-4,3,STONE)
Block(-4,-4,4,STONE)
Block(-4,-4,5,STONE)
Block(-4,-3,-7,STONE)
Block(-4,-3,-6,STONE)
Block(-4,-3,-5,STONE)
Block(-4,-3,-4,STONE)
Block(-4,-3,-3,STONE)
Block(-4,-3,-2,STONE)
Block(-4,-3,-1,STONE)
Block(-4,-3,0,STONE)
Block(-4,-3,1,STONE)
Block(-4,-3,2,STONE)
Block(-4,-3,3,STONE)
Block(-4,-3,4,STONE)
Block(-4,-3,5,STONE)
Block(-4,-3,6,STONE)
Block(-4,-2,-7,STONE)
Block(-4,-2,-6,STONE)
Block(-4,-2,-5,STONE)
Block(-4,-2,-4,STONE)
Block(-4,-2,-3,STONE)
Block(-4,-2,-2,STONE)
Block(-4,-2,-1,STONE)
Block(-4,-2,0,STONE)
Block(-4,-2,1,STONE)
Block(-4,-2,2,STONE)
Block(-4,-2,3,STONE)
Block(-4,-2,4,STONE)
Block(-4,-2,5,STONE)
Block(-4,-2,6,STONE)
Block(-4,-1,-6,STONE)
Block(-4,-1,-5,STONE)
Block(-4,-1,-4,STONE)
Block(-4,-1,-3,STONE)
Block(-4,-1,-2,STONE)
Block(-4,-1,-1,STONE)
Block(-4,-1,0,STONE)
Block(-4,-1,1,STONE)
Block(-4,-1,2,STONE)
Block(-4,-1,3,STONE)
Block(-4,-1,4,STONE)
Block(-4,-1,5,STONE)
Block(-4,-1,6,STONE)
Block(-4,0,-5,STONE)
Block(-4,0,-4,STONE)
Block(-4,0,-3,STONE)
Block(-4,0,-2,STONE)
Block(-4,0,-1,STONE)
Block(-4,0,0,STONE)
Block(-4,0,1,STONE)
Block(-4,0,2,STONE)
Block(-4,0,3,STONE)
Block(-4,0,4,STONE)
Block(-4,0,5,STONE)
Block(-4,1,-5,STONE)
Block(-4,1,-4,STONE)
Block(-4,1,-3,STONE)
Block(-4,1,-1,STONE)
Block(-4,1,0,STONE)
Block(-4,1,1,STONE)
Block(-4,1,2,STONE)
Block(-4,1,3,STONE)
Block(-4,1,4,STONE)
Block(-4,1,5,STONE)
Block(-4,2,-4,STONE)
Block(-4,2,-3,STONE)
Block(-4,2,0,STONE)
Block(-4,2,1,STONE)
Block(-4,2,2,STONE)
Block(-4,2,3,STONE)
Block(-4,2,4,STONE)
Block(-4,3,-4,STONE)
Block(-4,3,1,STONE)
Block(-4,3,2,STONE)
Block(-4,3,3,STONE)
Block(-4,3,4,STONE)
Block(-4,4,3,GRAVEL)
Block(-3,-8,-5,STONE)
Block(-3,-8,-4,STONE)
Block(-3,-8,-3,STONE)
Block(-3,-8,-1,STONE)
Block(-3,-8,2,STONE)
Block(-3,-8,3,STONE)
Block(-3,-8,4,STONE)
Block(-3,-7,-6,STONE)
Block(-3,-7,-5,STONE)
Block(-3,-7,-4,STONE)
Block(-3,-7,-3,STONE)
Block(-3,-7,-2,STONE)
Block(-3,-7,-1,STONE)
Block(-3,-7,0,STONE)
Block(-3,-7,1,STONE)
Block(-3,-7,2,STONE)
Block(-3,-7,3,STONE)
Block(-3,-7,4,STONE)
Block(-3,-7,5,STONE)
Block(-3,-6,-6,STONE)
Block(-3,-6,-5,STONE)
Block(-3,-6,-4,STONE)
Block(-3,-6,-3,STONE)
Block(-3,-6,-2,STONE)
Block(-3,-6,-1,STONE)
Block(-3,-6,0,STONE)
Block(-3,-6,1,STONE)
Block(-3,-6,2,STONE)
Block(-3,-6,3,STONE)
Block(-3,-6,4,STONE)
Block(-3,-6,5,STONE)
Block(-3,-5,-7,STONE)
Block(-3,-5,-6,STONE)
Block(-3,-5,-5,STONE)
Block(-3,-5,-4,STONE)
Block(-3,-5,-3,STONE)
Block(-3,-5,-2,STONE)
Block(-3,-5,-1,STONE)
Block(-3,-5,0,STONE)
Block(-3,-5,1,STONE)
Block(-3,-5,2,STONE)
Block(-3,-5,3,STONE)
Block(-3,-5,4,STONE)
Block(-3,-5,5,STONE)
Block(-3,-4,-7,STONE)
Block(-3,-4,-6,STONE)
Block(-3,-4,-5,STONE)
Block(-3,-4,-4,STONE)
Block(-3,-4,-3,STONE)
Block(-3,-4,-2,STONE)
Block(-3,-4,-1,STONE)
Block(-3,-4,0,STONE)
Block(-3,-4,1,STONE)
Block(-3,-4,2,STONE)
Block(-3,-4,3,STONE)
Block(-3,-4,4,STONE)
Block(-3,-4,5,STONE)
Block(-3,-4,6,STONE)
Block(-3,-3,-8,STONE)
Block(-3,-3,-7,STONE)
Block(-3,-3,-6,STONE)
Block(-3,-3,-5,STONE)
Block(-3,-3,-4,STONE)
Block(-3,-3,-3,STONE)
Block(-3,-3,-2,STONE)
Block(-3,-3,-1,STONE)
Block(-3,-3,0,STONE)
Block(-3,-3,1,STONE)
Block(-3,-3,2,STONE)
Block(-3,-3,3,STONE)
Block(-3,-3,4,STONE)
Block(-3,-3,5,STONE)
Block(-3,-3,6,STONE)
Block(-3,-3,7,STONE)
Block(-3,-2,-8,STONE)
Block(-3,-2,-7,STONE)
Block(-3,-2,-6,STONE)
Block(-3,-2,-5,STONE)
Block(-3,-2,-4,STONE)
Block(-3,-2,-3,STONE)
Block(-3,-2,-2,STONE)
Block(-3,-2,-1,STONE)
Block(-3,-2,0,STONE)
Block(-3,-2,1,STONE)
Block(-3,-2,2,STONE)
Block(-3,-2,3,STONE)
Block(-3,-2,4,STONE)
Block(-3,-2,5,STONE)
Block(-3,-2,6,STONE)
Block(-3,-2,7,STONE)
Block(-3,-1,-7,STONE)
Block(-3,-1,-6,STONE)
Block(-3,-1,-5,STONE)
Block(-3,-1,-4,STONE)
Block(-3,-1,-3,STONE)
Block(-3,-1,-2,STONE)
Block(-3,-1,-1,STONE)
Block(-3,-1,0,STONE)
Block(-3,-1,1,STONE)
Block(-3,-1,2,STONE)
Block(-3,-1,3,STONE)
Block(-3,-1,4,STONE)
Block(-3,-1,5,STONE)
Block(-3,-1,6,STONE)
Block(-3,0,-6,STONE)
Block(-3,0,-5,STONE)
Block(-3,0,-4,STONE)
Block(-3,0,-3,STONE)
Block(-3,0,-2,STONE)
Block(-3,0,-1,STONE)
Block(-3,0,0,STONE)
Block(-3,0,1,STONE)
Block(-3,0,2,STONE)
Block(-3,0,3,STONE)
Block(-3,0,4,STONE)
Block(-3,0,5,STONE)
Block(-3,0,6,STONE)
Block(-3,1,-6,STONE)
Block(-3,1,-5,STONE)
Block(-3,1,-4,STONE)
Block(-3,1,-3,STONE)
Block(-3,1,-2,STONE)
Block(-3,1,-1,STONE)
Block(-3,1,0,STONE)
Block(-3,1,1,STONE)
Block(-3,1,2,STONE)
Block(-3,1,3,STATIONARY_LAVA)
Block(-3,1,4,STATIONARY_LAVA)
Block(-3,1,5,STONE)
Block(-3,1,6,STONE)
Block(-3,2,-5,STONE)
Block(-3,2,-4,STONE)
Block(-3,2,-3,STONE)
Block(-3,2,-2,STONE)
Block(-3,2,-1,STONE)
Block(-3,2,0,STONE)
Block(-3,2,1,STONE)
Block(-3,2,2,GRAVEL)
Block(-3,2,5,GRAVEL)
Block(-3,3,-4,STONE)
Block(-3,3,-3,STONE)
Block(-3,3,-2,STONE)
Block(-3,3,0,STONE)
Block(-3,3,1,OBSIDIAN)
Block(-3,4,-4,STONE)
Block(-3,4,-3,STONE)
Block(-2,-10,-1,STONE)
Block(-2,-10,2,STONE)
Block(-2,-9,-4,STONE)
Block(-2,-9,-1,STONE)
Block(-2,-9,0,STONE)
Block(-2,-9,1,STONE)
Block(-2,-9,2,STONE)
Block(-2,-9,3,STONE)
Block(-2,-8,-6,STONE)
Block(-2,-8,-5,STONE)
Block(-2,-8,-4,STONE)
Block(-2,-8,-3,STONE)
Block(-2,-8,-2,STONE)
Block(-2,-8,-1,STONE)
Block(-2,-8,0,STONE)
Block(-2,-8,1,STONE)
Block(-2,-8,2,STONE)
Block(-2,-8,3,STONE)
Block(-2,-8,4,STONE)
Block(-2,-7,-6,STONE)
Block(-2,-7,-5,STONE)
Block(-2,-7,-4,STONE)
Block(-2,-7,-3,STONE)
Block(-2,-7,-2,STONE)
Block(-2,-7,-1,STONE)
Block(-2,-7,0,STONE)
Block(-2,-7,1,STONE)
Block(-2,-7,2,STONE)
Block(-2,-7,3,STONE)
Block(-2,-7,4,STONE)
Block(-2,-7,5,STONE)
Block(-2,-6,-6,STONE)
Block(-2,-6,-5,STONE)
Block(-2,-6,-4,STONE)
Block(-2,-6,-3,STONE)
Block(-2,-6,-2,STONE)
Block(-2,-6,-1,STONE)
Block(-2,-6,0,STONE)
Block(-2,-6,1,STONE)
Block(-2,-6,2,STONE)
Block(-2,-6,3,STONE)
Block(-2,-6,4,STONE)
Block(-2,-6,5,STONE)
Block(-2,-5,-7,STONE)
Block(-2,-5,-6,STONE)
Block(-2,-5,-5,STONE)
Block(-2,-5,-4,STONE)
Block(-2,-5,-3,STONE)
Block(-2,-5,-2,STONE)
Block(-2,-5,-1,STONE)
Block(-2,-5,0,STONE)
Block(-2,-5,1,STONE)
Block(-2,-5,2,STONE)
Block(-2,-5,3,STONE)
Block(-2,-5,4,STONE)
Block(-2,-5,5,STONE)
Block(-2,-4,-8,STONE)
Block(-2,-4,-7,STONE)
Block(-2,-4,-6,STONE)
Block(-2,-4,-5,STONE)
Block(-2,-4,-4,STONE)
Block(-2,-4,-3,STONE)
Block(-2,-4,-2,STONE)
Block(-2,-4,-1,STONE)
Block(-2,-4,0,STONE)
Block(-2,-4,1,STONE)
Block(-2,-4,2,STONE)
Block(-2,-4,3,STONE)
Block(-2,-4,4,STONE)
Block(-2,-4,5,STONE)
Block(-2,-4,6,STONE)
Block(-2,-3,-8,STONE)
Block(-2,-3,-7,STONE)
Block(-2,-3,-6,STONE)
Block(-2,-3,-5,STONE)
Block(-2,-3,-4,STONE)
Block(-2,-3,-3,STONE)
Block(-2,-3,-2,STONE)
Block(-2,-3,-1,STONE)
Block(-2,-3,0,STONE)
Block(-2,-3,1,STONE)
Block(-2,-3,2,STONE)
Block(-2,-3,3,STONE)
Block(-2,-3,4,STONE)
Block(-2,-3,5,STONE)
Block(-2,-3,6,STONE)
Block(-2,-3,7,STONE)
Block(-2,-2,-8,STONE)
Block(-2,-2,-7,STONE)
Block(-2,-2,-6,STONE)
Block(-2,-2,-5,STONE)
Block(-2,-2,-4,STONE)
Block(-2,-2,-3,STONE)
Block(-2,-2,-2,STONE)
Block(-2,-2,-1,STONE)
Block(-2,-2,0,STONE)
Block(-2,-2,1,STONE)
Block(-2,-2,2,STONE)
Block(-2,-2,3,STONE)
Block(-2,-2,4,STONE)
Block(-2,-2,5,STONE)
Block(-2,-2,6,STONE)
Block(-2,-2,7,STONE)
Block(-2,-1,-8,STONE)
Block(-2,-1,-7,STONE)
Block(-2,-1,-6,STONE)
Block(-2,-1,-5,STONE)
Block(-2,-1,-4,STONE)
Block(-2,-1,-3,STONE)
Block(-2,-1,-2,STONE)
Block(-2,-1,-1,STONE)
Block(-2,-1,0,STONE)
Block(-2,-1,1,STONE)
Block(-2,-1,2,STONE)
Block(-2,-1,3,STONE)
Block(-2,-1,4,STONE)
Block(-2,-1,5,STONE)
Block(-2,-1,6,STONE)
Block(-2,-1,7,STONE)
Block(-2,0,-7,STONE)
Block(-2,0,-6,STONE)
Block(-2,0,-5,STONE)
Block(-2,0,-4,STONE)
Block(-2,0,-3,STONE)
Block(-2,0,-2,STONE)
Block(-2,0,-1,STONE)
Block(-2,0,0,STONE)
Block(-2,0,1,STONE)
Block(-2,0,2,STONE)
Block(-2,0,3,STATIONARY_LAVA)
Block(-2,0,4,STONE)
Block(-2,0,5,STONE)
Block(-2,0,6,STONE)
Block(-2,1,-7,STONE)
Block(-2,1,-6,STONE)
Block(-2,1,-5,STONE)
Block(-2,1,-4,STONE)
Block(-2,1,-3,STONE)
Block(-2,1,-2,STONE)
Block(-2,1,-1,STONE)
Block(-2,1,0,STONE)
Block(-2,1,1,STONE)
Block(-2,1,2,OBSIDIAN)
Block(-2,1,3,STATIONARY_LAVA)
Block(-2,1,4,STATIONARY_LAVA)
Block(-2,1,5,STONE)
Block(-2,2,-5,STONE)
Block(-2,2,-4,STONE)
Block(-2,2,-3,STONE)
Block(-2,2,-2,STONE)
Block(-2,2,-1,STONE)
Block(-2,2,0,STONE)
Block(-2,2,1,STONE)
Block(-2,2,5,STONE)
Block(-2,3,-5,STONE)
Block(-2,3,-4,STONE)
Block(-2,3,-3,STONE)
Block(-2,3,-2,STONE)
Block(-2,3,-1,STONE)
Block(-2,3,0,STONE)
Block(-2,4,-4,STONE)
Block(-2,4,-3,OBSIDIAN)
Block(-2,4,-2,STONE)
Block(-2,4,-1,STONE)
Block(-2,5,-4,STONE)
Block(-2,5,-3,OBSIDIAN)
Block(-2,5,-2,STONE)
Block(-2,6,-4,OBSIDIAN)
Block(-2,6,-3,STONE)
Block(-2,7,-4,STONE)
Block(-2,8,-4,STONE)
Block(-1,-11,2,STONE)
Block(-1,-10,2,STONE)
Block(-1,-9,-5,STONE)
Block(-1,-9,-4,STONE)
Block(-1,-9,-3,STONE)
Block(-1,-9,-1,STONE)
Block(-1,-9,0,STONE)
Block(-1,-9,1,STONE)
Block(-1,-9,2,STONE)
Block(-1,-9,3,STONE)
Block(-1,-8,-6,STONE)
Block(-1,-8,-5,STONE)
Block(-1,-8,-4,STONE)
Block(-1,-8,-3,STONE)
Block(-1,-8,-2,STONE)
Block(-1,-8,-1,STONE)
Block(-1,-8,0,STONE)
Block(-1,-8,1,STONE)
Block(-1,-8,2,STONE)
Block(-1,-8,3,STONE)
Block(-1,-8,4,STONE)
Block(-1,-7,-6,STONE)
Block(-1,-7,-5,STONE)
Block(-1,-7,-4,STONE)
Block(-1,-7,-3,STONE)
Block(-1,-7,-2,STONE)
Block(-1,-7,-1,STONE)
Block(-1,-7,0,STONE)
Block(-1,-7,1,STONE)
Block(-1,-7,2,STONE)
Block(-1,-7,3,STONE)
Block(-1,-7,4,STONE)
Block(-1,-7,5,STONE)
Block(-1,-6,-7,STONE)
Block(-1,-6,-6,STONE)
Block(-1,-6,-5,STONE)
Block(-1,-6,-4,STONE)
Block(-1,-6,-3,STONE)
Block(-1,-6,-2,STONE)
Block(-1,-6,-1,STONE)
Block(-1,-6,0,STONE)
Block(-1,-6,1,STONE)
Block(-1,-6,2,STONE)
Block(-1,-6,3,STONE)
Block(-1,-6,4,STONE)
Block(-1,-6,5,STONE)
Block(-1,-5,-8,STONE)
Block(-1,-5,-7,STONE)
Block(-1,-5,-6,STONE)
Block(-1,-5,-5,STONE)
Block(-1,-5,-4,STONE)
Block(-1,-5,-3,STONE)
Block(-1,-5,-2,STONE)
Block(-1,-5,-1,STONE)
Block(-1,-5,0,STONE)
Block(-1,-5,1,STONE)
Block(-1,-5,2,STONE)
Block(-1,-5,3,STONE)
Block(-1,-5,4,STONE)
Block(-1,-5,5,STONE)
Block(-1,-4,-8,STONE)
Block(-1,-4,-7,STONE)
Block(-1,-4,-6,STONE)
Block(-1,-4,-5,STONE)
Block(-1,-4,-4,STONE)
Block(-1,-4,-3,STONE)
Block(-1,-4,-2,STONE)
Block(-1,-4,-1,STONE)
Block(-1,-4,0,STONE)
Block(-1,-4,1,STONE)
Block(-1,-4,2,STONE)
Block(-1,-4,3,STONE)
Block(-1,-4,4,STONE)
Block(-1,-4,5,STONE)
Block(-1,-4,6,STONE)
Block(-1,-3,-8,STONE)
Block(-1,-3,-7,STONE)
Block(-1,-3,-6,STONE)
Block(-1,-3,-5,STONE)
Block(-1,-3,-4,STONE)
Block(-1,-3,-3,STONE)
Block(-1,-3,-2,STONE)
Block(-1,-3,-1,STONE)
Block(-1,-3,0,STONE)
Block(-1,-3,1,STONE)
Block(-1,-3,2,STONE)
Block(-1,-3,3,STONE)
Block(-1,-3,4,STONE)
Block(-1,-3,5,STONE)
Block(-1,-3,6,STONE)
Block(-1,-2,-8,STONE)
Block(-1,-2,-7,STONE)
Block(-1,-2,-6,STONE)
Block(-1,-2,-5,STONE)
Block(-1,-2,-4,STONE)
Block(-1,-2,-3,STONE)
Block(-1,-2,-2,STONE)
Block(-1,-2,-1,STONE)
Block(-1,-2,0,STONE)
Block(-1,-2,1,STONE)
Block(-1,-2,2,STONE)
Block(-1,-2,3,STONE)
Block(-1,-2,4,STONE)
Block(-1,-2,5,STONE)
Block(-1,-2,6,STONE)
Block(-1,-1,-8,STONE)
Block(-1,-1,-7,STONE)
Block(-1,-1,-6,STONE)
Block(-1,-1,-5,STONE)
Block(-1,-1,-4,STONE)
Block(-1,-1,-3,STONE)
Block(-1,-1,-2,STONE)
Block(-1,-1,-1,STONE)
Block(-1,-1,0,STONE)
Block(-1,-1,1,STONE)
Block(-1,-1,2,STONE)
Block(-1,-1,3,STONE)
Block(-1,-1,4,STONE)
Block(-1,-1,5,STONE)
Block(-1,-1,6,STONE)
Block(-1,0,-7,STONE)
Block(-1,0,-6,STONE)
Block(-1,0,-5,STONE)
Block(-1,0,-4,STONE)
Block(-1,0,-3,STONE)
Block(-1,0,-2,STONE)
Block(-1,0,-1,STONE)
Block(-1,0,0,STONE)
Block(-1,0,1,STONE)
Block(-1,0,2,STATIONARY_LAVA)
Block(-1,0,3,MAGMA)
Block(-1,0,4,STONE)
Block(-1,0,5,STONE)
Block(-1,1,-7,STONE)
Block(-1,1,-6,STONE)
Block(-1,1,-5,STONE)
Block(-1,1,-4,STONE)
Block(-1,1,-3,STONE)
Block(-1,1,-2,STONE)
Block(-1,1,-1,STONE)
Block(-1,1,0,STONE)
Block(-1,1,1,OBSIDIAN)
Block(-1,1,2,STATIONARY_LAVA)
Block(-1,1,3,MAGMA)
Block(-1,1,4,STATIONARY_LAVA)
Block(-1,1,5,STONE)
Block(-1,2,-6,STONE)
Block(-1,2,-5,STONE)
Block(-1,2,-4,STONE)
Block(-1,2,-3,STONE)
Block(-1,2,-2,STONE)
Block(-1,2,-1,STONE)
Block(-1,2,0,STONE)
Block(-1,2,1,MAGMA)
Block(-1,3,-6,STONE)
Block(-1,3,-5,STONE)
Block(-1,3,-4,MAGMA)
Block(-1,3,-3,STONE)
Block(-1,3,-2,STONE)
Block(-1,3,-1,STONE)
Block(-1,3,0,MAGMA)
Block(-1,4,-5,STONE)
Block(-1,4,-4,MAGMA)
Block(-1,4,-3,STATIONARY_LAVA)
Block(-1,4,-2,STONE)
Block(-1,4,-1,STONE)
Block(-1,4,0,OBSIDIAN)
Block(-1,5,-5,STONE)
Block(-1,5,-4,MAGMA)
Block(-1,5,-3,STATIONARY_LAVA)
Block(-1,5,-2,STATIONARY_LAVA)
Block(-1,5,-1,STONE)
Block(-1,6,-5,STONE)
Block(-1,7,-5,STONE)
Block(0,-10,-4,STONE)
Block(0,-10,-3,STONE)
Block(0,-9,-5,STONE)
Block(0,-9,-4,STONE)
Block(0,-9,-3,STONE)
Block(0,-9,-2,STONE)
Block(0,-9,1,STONE)
Block(0,-9,2,STONE)
Block(0,-8,-6,STONE)
Block(0,-8,-5,STONE)
Block(0,-8,-4,STONE)
Block(0,-8,-3,STONE)
Block(0,-8,-2,STONE)
Block(0,-8,-1,STONE)
Block(0,-8,0,STONE)
Block(0,-8,1,STONE)
Block(0,-8,2,STONE)
Block(0,-8,3,STONE)
Block(0,-7,-7,STONE)
Block(0,-7,-6,STONE)
Block(0,-7,-5,STONE)
Block(0,-7,-4,STONE)
Block(0,-7,-3,STONE)
Block(0,-7,-2,STONE)
Block(0,-7,-1,STONE)
Block(0,-7,0,STONE)
Block(0,-7,1,STONE)
Block(0,-7,2,STONE)
Block(0,-7,3,STONE)
Block(0,-7,4,STONE)
Block(0,-6,-7,STONE)
Block(0,-6,-6,STONE)
Block(0,-6,-5,STONE)
Block(0,-6,-4,STONE)
Block(0,-6,-3,STONE)
Block(0,-6,-2,STONE)
Block(0,-6,-1,STONE)
Block(0,-6,0,STONE)
Block(0,-6,1,STONE)
Block(0,-6,2,STONE)
Block(0,-6,3,STONE)
Block(0,-6,4,STONE)
Block(0,-6,5,STONE)
Block(0,-5,-8,STONE)
Block(0,-5,-7,STONE)
Block(0,-5,-6,STONE)
Block(0,-5,-5,STONE)
Block(0,-5,-4,STONE)
Block(0,-5,-3,STONE)
Block(0,-5,-2,STONE)
Block(0,-5,-1,STONE)
Block(0,-5,0,STONE)
Block(0,-5,1,STONE)
Block(0,-5,2,STONE)
Block(0,-5,3,STONE)
Block(0,-5,4,STONE)
Block(0,-5,5,STONE)
Block(0,-4,-8,STONE)
Block(0,-4,-7,STONE)
Block(0,-4,-6,STONE)
Block(0,-4,-5,STONE)
Block(0,-4,-4,STONE)
Block(0,-4,-3,STONE)
Block(0,-4,-2,STONE)
Block(0,-4,-1,STONE)
Block(0,-4,0,STONE)
Block(0,-4,1,STONE)
Block(0,-4,2,STONE)
Block(0,-4,3,STONE)
Block(0,-4,4,STONE)
Block(0,-4,5,STONE)
Block(0,-3,-8,STONE)
Block(0,-3,-7,STONE)
Block(0,-3,-6,STONE)
Block(0,-3,-5,STONE)
Block(0,-3,-4,STONE)
Block(0,-3,-3,STONE)
Block(0,-3,-2,STONE)
Block(0,-3,-1,STONE)
Block(0,-3,0,STONE)
Block(0,-3,1,STONE)
Block(0,-3,2,STONE)
Block(0,-3,3,STONE)
Block(0,-3,4,STONE)
Block(0,-3,5,STONE)
Block(0,-2,-8,STONE)
Block(0,-2,-7,STONE)
Block(0,-2,-6,STONE)
Block(0,-2,-5,STONE)
Block(0,-2,-4,STONE)
Block(0,-2,-3,STONE)
Block(0,-2,-2,STONE)
Block(0,-2,-1,STONE)
Block(0,-2,0,STONE)
Block(0,-2,1,STONE)
Block(0,-2,2,STONE)
Block(0,-2,3,STONE)
Block(0,-2,4,STONE)
Block(0,-2,5,STONE)
Block(0,-1,-7,STONE)
Block(0,-1,-6,STONE)
Block(0,-1,-5,STONE)
Block(0,-1,-4,STONE)
Block(0,-1,-3,STONE)
Block(0,-1,-2,STONE)
Block(0,-1,-1,STONE)
Block(0,-1,0,STONE)
Block(0,-1,1,STONE)
Block(0,-1,2,STONE)
Block(0,-1,3,STONE)
Block(0,-1,4,STONE)
Block(0,-1,5,STONE)
Block(0,0,-7,STONE)
Block(0,0,-6,STONE)
Block(0,0,-5,STONE)
Block(0,0,-4,STONE)
Block(0,0,-3,STONE)
Block(0,0,-2,STONE)
Block(0,0,-1,STONE)
Block(0,0,0,STONE)
Block(0,0,1,STONE)
Block(0,0,2,STONE)
Block(0,0,3,STONE)
Block(0,0,4,STONE)
Block(0,1,-7,STONE)
Block(0,1,-6,STONE)
Block(0,1,-5,STONE)
Block(0,1,-4,STONE)
Block(0,1,-3,STONE)
Block(0,1,-2,STONE)
Block(0,1,-1,STONE)
Block(0,1,0,STONE)
Block(0,1,1,STATIONARY_LAVA)
Block(0,1,2,STATIONARY_LAVA)
Block(0,1,3,STATIONARY_LAVA)
Block(0,1,4,STONE)
Block(0,2,-7,STONE)
Block(0,2,-6,STONE)
Block(0,2,-5,STONE)
Block(0,2,-4,STONE)
Block(0,2,-3,STONE)
Block(0,2,-2,STONE)
Block(0,2,-1,STONE)
Block(0,2,0,STONE)
Block(0,2,1,STATIONARY_LAVA:10)
Block(0,3,-6,STONE)
Block(0,3,-5,STONE)
Block(0,3,-4,STONE)
Block(0,3,-3,STONE)
Block(0,3,-2,STONE)
Block(0,3,-1,STONE)
Block(0,3,0,STONE)
Block(0,3,1,STATIONARY_LAVA:10)
Block(0,4,-6,STONE)
Block(0,4,-5,STONE)
Block(0,4,-4,STATIONARY_LAVA)
Block(0,4,-3,STATIONARY_LAVA)
Block(0,4,-2,STONE)
Block(0,4,-1,STONE)
Block(0,4,0,STATIONARY_LAVA:12)
Block(0,4,1,STATIONARY_LAVA:2)
Block(0,5,-5,STONE)
Block(0,5,-4,STATIONARY_LAVA)
Block(0,5,-3,STATIONARY_LAVA)
Block(0,5,-2,STATIONARY_LAVA)
Block(0,5,-1,STATIONARY_LAVA:2)
Block(0,5,0,STATIONARY_LAVA:4)
Block(0,6,-5,STONE)
Block(1,-9,-4,STONE)
Block(1,-9,-3,STONE)
Block(1,-8,-6,STONE)
Block(1,-8,-5,STONE)
Block(1,-8,-4,STONE)
Block(1,-8,-3,STONE)
Block(1,-8,-2,STONE)
Block(1,-8,-1,STONE)
Block(1,-8,0,STONE)
Block(1,-8,1,STONE)
Block(1,-7,-7,STONE)
Block(1,-7,-6,STONE)
Block(1,-7,-5,STONE)
Block(1,-7,-4,STONE)
Block(1,-7,-3,STONE)
Block(1,-7,-2,STONE)
Block(1,-7,-1,STONE)
Block(1,-7,0,STONE)
Block(1,-7,1,STONE)
Block(1,-7,2,STONE)
Block(1,-7,3,STONE)
Block(1,-6,-7,STONE)
Block(1,-6,-6,STONE)
Block(1,-6,-5,STONE)
Block(1,-6,-4,STONE)
Block(1,-6,-3,STONE)
Block(1,-6,-2,STONE)
Block(1,-6,-1,STONE)
Block(1,-6,0,STONE)
Block(1,-6,1,STONE)
Block(1,-6,2,STONE)
Block(1,-6,3,STONE)
Block(1,-5,-7,STONE)
Block(1,-5,-6,STONE)
Block(1,-5,-5,STONE)
Block(1,-5,-4,STONE)
Block(1,-5,-3,STONE)
Block(1,-5,-2,STONE)
Block(1,-5,-1,STONE)
Block(1,-5,0,STONE)
Block(1,-5,1,STONE)
Block(1,-5,2,STONE)
Block(1,-5,3,STONE)
Block(1,-5,4,STONE)
Block(1,-4,-8,STONE)
Block(1,-4,-7,STONE)
Block(1,-4,-6,STONE)
Block(1,-4,-5,STONE)
Block(1,-4,-4,STONE)
Block(1,-4,-3,STONE)
Block(1,-4,-2,STONE)
Block(1,-4,-1,STONE)
Block(1,-4,0,STONE)
Block(1,-4,1,STONE)
Block(1,-4,2,STONE)
Block(1,-4,3,STONE)
Block(1,-4,4,STONE)
Block(1,-3,-8,STONE)
Block(1,-3,-7,STONE)
Block(1,-3,-6,STONE)
Block(1,-3,-5,STONE)
Block(1,-3,-4,STONE)
Block(1,-3,-3,STONE)
Block(1,-3,-2,STONE)
Block(1,-3,-1,STONE)
Block(1,-3,0,STONE)
Block(1,-3,1,STONE)
Block(1,-3,2,STONE)
Block(1,-3,3,STONE)
Block(1,-3,4,STONE)
Block(1,-2,-8,STONE)
Block(1,-2,-7,STONE)
Block(1,-2,-6,STONE)
Block(1,-2,-5,STONE)
Block(1,-2,-4,STONE)
Block(1,-2,-3,STONE)
Block(1,-2,-2,STONE)
Block(1,-2,-1,STONE)
Block(1,-2,0,STONE)
Block(1,-2,1,STONE)
Block(1,-2,2,STONE)
Block(1,-2,3,STONE)
Block(1,-2,4,STONE)
Block(1,-1,-7,STONE)
Block(1,-1,-6,STONE)
Block(1,-1,-5,STONE)
Block(1,-1,-4,STONE)
Block(1,-1,-3,STONE)
Block(1,-1,-2,STONE)
Block(1,-1,-1,STONE)
Block(1,-1,0,STONE)
Block(1,-1,1,STONE)
Block(1,-1,2,STONE)
Block(1,-1,3,STONE)
Block(1,-1,4,STONE)
Block(1,0,-7,STONE)
Block(1,0,-6,STONE)
Block(1,0,-5,STONE)
Block(1,0,-4,STONE)
Block(1,0,-3,STONE)
Block(1,0,-2,STONE)
Block(1,0,-1,STONE)
Block(1,0,0,STONE)
Block(1,0,1,STONE)
Block(1,0,2,STONE)
Block(1,0,3,STONE)
Block(1,1,-6,STONE)
Block(1,1,-5,STONE)
Block(1,1,-4,STONE)
Block(1,1,-3,STONE)
Block(1,1,-2,STONE)
Block(1,1,-1,STONE)
Block(1,1,0,STONE)
Block(1,1,1,STONE)
Block(1,1,2,STONE)
Block(1,1,3,STONE)
Block(1,2,-6,STONE)
Block(1,2,-5,STONE)
Block(1,2,-4,STONE)
Block(1,2,-3,STONE)
Block(1,2,-2,STONE)
Block(1,2,-1,STONE)
Block(1,2,0,STONE)
Block(1,2,1,STONE)
Block(1,2,2,STONE)
Block(1,3,-6,STONE)
Block(1,3,-5,STONE)
Block(1,3,-4,STONE)
Block(1,3,-3,STONE)
Block(1,3,-2,STONE)
Block(1,3,-1,STONE)
Block(1,3,0,OBSIDIAN)
Block(1,3,1,GRAVEL)
Block(1,4,-6,STONE)
Block(1,4,-5,STONE)
Block(1,4,-4,STONE)
Block(1,4,-3,STONE)
Block(1,4,-2,STONE)
Block(1,4,-1,STONE)
Block(1,4,0,STONE)
Block(1,5,-5,STONE)
Block(1,5,-4,STATIONARY_LAVA)
Block(1,5,-3,MAGMA)
Block(1,5,-2,STONE)
Block(1,5,-1,GRAVEL)
Block(2,-9,-5,STONE)
Block(2,-9,-4,STONE)
Block(2,-8,-5,STONE)
Block(2,-8,-4,STONE)
Block(2,-8,-3,STONE)
Block(2,-8,-2,STONE)
Block(2,-8,-1,STONE)
Block(2,-7,-6,STONE)
Block(2,-7,-5,STONE)
Block(2,-7,-4,STONE)
Block(2,-7,-3,STONE)
Block(2,-7,-2,STONE)
Block(2,-7,-1,STONE)
Block(2,-7,0,STONE)
Block(2,-7,1,STONE)
Block(2,-6,-6,STONE)
Block(2,-6,-5,STONE)
Block(2,-6,-4,STONE)
Block(2,-6,-3,STONE)
Block(2,-6,-2,STONE)
Block(2,-6,-1,STONE)
Block(2,-6,0,STONE)
Block(2,-6,1,STONE)
Block(2,-6,2,STONE)
Block(2,-6,3,STONE)
Block(2,-5,-7,STONE)
Block(2,-5,-6,STONE)
Block(2,-5,-5,STONE)
Block(2,-5,-4,STONE)
Block(2,-5,-3,STONE)
Block(2,-5,-2,STONE)
Block(2,-5,-1,STONE)
Block(2,-5,0,STONE)
Block(2,-5,1,STONE)
Block(2,-5,2,STONE)
Block(2,-5,3,STONE)
Block(2,-4,-8,STONE)
Block(2,-4,-7,STONE)
Block(2,-4,-6,STONE)
Block(2,-4,-5,STONE)
Block(2,-4,-4,STONE)
Block(2,-4,-3,STONE)
Block(2,-4,-2,STONE)
Block(2,-4,-1,STONE)
Block(2,-4,0,STONE)
Block(2,-4,1,STONE)
Block(2,-4,2,STONE)
Block(2,-4,3,STONE)
Block(2,-3,-8,STONE)
Block(2,-3,-7,STONE)
Block(2,-3,-6,STONE)
Block(2,-3,-5,STONE)
Block(2,-3,-4,STONE)
Block(2,-3,-3,STONE)
Block(2,-3,-2,STONE)
Block(2,-3,-1,STONE)
Block(2,-3,0,STONE)
Block(2,-3,1,STONE)
Block(2,-3,2,STONE)
Block(2,-3,3,STONE)
Block(2,-2,-8,STONE)
Block(2,-2,-7,STONE)
Block(2,-2,-6,STONE)
Block(2,-2,-5,STONE)
Block(2,-2,-4,STONE)
Block(2,-2,-3,STONE)
Block(2,-2,-2,STONE)
Block(2,-2,-1,STONE)
Block(2,-2,0,STONE)
Block(2,-2,1,STONE)
Block(2,-2,2,STONE)
Block(2,-2,3,STONE)
Block(2,-1,-7,STONE)
Block(2,-1,-6,STONE)
Block(2,-1,-5,STONE)
Block(2,-1,-4,STONE)
Block(2,-1,-3,STONE)
Block(2,-1,-2,STONE)
Block(2,-1,-1,STONE)
Block(2,-1,0,STONE)
Block(2,-1,1,STONE)
Block(2,-1,2,STONE)
Block(2,0,-7,STONE)
Block(2,0,-6,STONE)
Block(2,0,-5,STONE)
Block(2,0,-4,STONE)
Block(2,0,-3,STONE)
Block(2,0,-2,STONE)
Block(2,0,-1,STONE)
Block(2,0,0,STONE)
Block(2,0,1,STONE)
Block(2,0,2,STONE)
Block(2,1,-6,STONE)
Block(2,1,-5,STONE)
Block(2,1,-4,STONE)
Block(2,1,-3,STONE)
Block(2,1,-2,STONE)
Block(2,1,-1,STONE)
Block(2,1,0,STONE)
Block(2,1,1,STONE)
Block(2,1,2,STONE)
Block(2,2,-5,STONE)
Block(2,2,-4,STONE)
Block(2,2,-3,STONE)
Block(2,2,-2,STONE)
Block(2,2,-1,STONE)
Block(2,2,0,STONE)
Block(2,2,1,STONE)
Block(2,3,-5,STONE)
Block(2,3,-4,STONE)
Block(2,3,-3,STONE)
Block(2,3,-2,STONE)
Block(2,3,-1,STONE)
Block(2,3,0,OBSIDIAN)
Block(2,4,-5,STONE)
Block(2,4,-4,STONE)
Block(2,4,-3,STONE)
Block(2,4,-2,STONE)
Block(2,5,-5,STONE)
Block(2,5,-4,GRAVEL)
Block(2,5,-3,STONE)
Block(2,5,-2,GRAVEL)
Block(2,6,-5,GRAVEL)
Block(3,-8,-4,STONE)
Block(3,-7,-5,STONE)
Block(3,-7,-4,STONE)
Block(3,-7,-3,STONE)
Block(3,-7,-2,STONE)
Block(3,-7,-1,STONE)
Block(3,-6,-6,STONE)
Block(3,-6,-5,STONE)
Block(3,-6,-4,STONE)
Block(3,-6,-3,STONE)
Block(3,-6,-2,STONE)
Block(3,-6,-1,STONE)
Block(3,-6,0,STONE)
Block(3,-5,-6,STONE)
Block(3,-5,-5,STONE)
Block(3,-5,-4,STONE)
Block(3,-5,-3,STONE)
Block(3,-5,-2,STONE)
Block(3,-5,-1,STONE)
Block(3,-5,0,STONE)
Block(3,-5,1,STONE)
Block(3,-4,-8,STONE)
Block(3,-4,-7,STONE)
Block(3,-4,-6,STONE)
Block(3,-4,-5,STONE)
Block(3,-4,-4,STONE)
Block(3,-4,-3,STONE)
Block(3,-4,-2,STONE)
Block(3,-4,-1,STONE)
Block(3,-4,0,STONE)
Block(3,-4,1,STONE)
Block(3,-3,-8,STONE)
Block(3,-3,-7,STONE)
Block(3,-3,-6,STONE)
Block(3,-3,-5,STONE)
Block(3,-3,-4,STONE)
Block(3,-3,-3,STONE)
Block(3,-3,-2,STONE)
Block(3,-3,-1,STONE)
Block(3,-3,0,STONE)
Block(3,-3,1,STONE)
Block(3,-2,-8,STONE)
Block(3,-2,-7,STONE)
Block(3,-2,-6,STONE)
Block(3,-2,-5,STONE)
Block(3,-2,-4,STONE)
Block(3,-2,-3,STONE)
Block(3,-2,-2,STONE)
Block(3,-2,-1,STONE)
Block(3,-2,0,STONE)
Block(3,-2,1,STONE)
Block(3,-1,-8,STONE)
Block(3,-1,-7,STONE)
Block(3,-1,-6,STONE)
Block(3,-1,-5,STONE)
Block(3,-1,-4,STONE)
Block(3,-1,-3,STONE)
Block(3,-1,-2,STONE)
Block(3,-1,-1,STONE)
Block(3,-1,0,STONE)
Block(3,0,-6,STONE)
Block(3,0,-5,STONE)
Block(3,0,-4,STONE)
Block(3,0,-3,STONE)
Block(3,0,-2,STONE)
Block(3,0,-1,STONE)
Block(3,0,0,STONE)
Block(3,1,-5,STONE)
Block(3,1,-4,STONE)
Block(3,1,-3,STONE)
Block(3,1,-2,STONE)
Block(3,1,-1,STONE)
Block(3,1,0,STONE)
Block(3,2,-4,STONE)
Block(3,2,-3,STONE)
Block(3,2,-2,STONE)
Block(3,2,-1,STONE)
Block(3,3,-4,STONE)
Block(3,3,-3,STONE)
Block(3,3,-2,STONE)
Block(3,4,-4,STONE)
Block(3,4,-3,STONE)
Block(3,4,-2,STONE)
Block(3,5,-4,STONE)
Block(4,-7,-5,STONE)
Block(4,-7,-4,STONE)
Block(4,-6,-6,STONE)
Block(4,-6,-5,STONE)
Block(4,-6,-4,STONE)
Block(4,-6,-3,STONE)
Block(4,-6,-2,STONE)
Block(4,-5,-7,STONE)
Block(4,-5,-6,STONE)
Block(4,-5,-5,STONE)
Block(4,-5,-4,STONE)
Block(4,-5,-3,STONE)
Block(4,-5,-2,STONE)
Block(4,-5,-1,STONE)
Block(4,-4,-7,STONE)
Block(4,-4,-6,STONE)
Block(4,-4,-5,STONE)
Block(4,-4,-4,STONE)
Block(4,-4,-3,STONE)
Block(4,-4,-2,STONE)
Block(4,-4,-1,STONE)
Block(4,-4,0,STONE)
Block(4,-3,-8,STONE)
Block(4,-3,-7,STONE)
Block(4,-3,-6,STONE)
Block(4,-3,-5,STONE)
Block(4,-3,-4,STONE)
Block(4,-3,-3,STONE)
Block(4,-3,-2,STONE)
Block(4,-3,-1,STONE)
Block(4,-3,0,STONE)
Block(4,-2,-8,STONE)
Block(4,-2,-7,STONE)
Block(4,-2,-6,STONE)
Block(4,-2,-5,STONE)
Block(4,-2,-4,STONE)
Block(4,-2,-3,STONE)
Block(4,-2,-2,STONE)
Block(4,-2,-1,STONE)
Block(4,-2,0,STONE)
Block(4,-1,-7,STONE)
Block(4,-1,-6,STONE)
Block(4,-1,-5,STONE)
Block(4,-1,-4,STONE)
Block(4,-1,-3,STONE)
Block(4,-1,-2,STONE)
Block(4,-1,-1,STONE)
Block(4,0,-5,STONE)
Block(4,0,-4,STONE)
Block(4,0,-3,STONE)
Block(4,0,-2,STONE)
Block(4,0,-1,STONE)
Block(4,1,-4,STONE)
Block(4,1,-3,STONE)
Block(4,1,-2,STONE)
Block(4,1,-1,STONE)
Block(4,2,-3,STONE)
Block(4,2,-2,STONE)
Block(4,3,-3,STONE)
Block(5,-6,-6,STONE)
Block(5,-6,-5,STONE)
Block(5,-6,-4,STONE)
Block(5,-5,-7,STONE)
Block(5,-5,-6,STONE)
Block(5,-5,-5,STONE)
Block(5,-5,-4,STONE)
Block(5,-5,-3,STONE)
Block(5,-5,-2,STONE)
Block(5,-4,-7,STONE)
Block(5,-4,-6,STONE)
Block(5,-4,-5,STONE)
Block(5,-4,-4,STONE)
Block(5,-4,-3,STONE)
Block(5,-4,-2,STONE)
Block(5,-4,-1,STONE)
Block(5,-3,-7,STONE)
Block(5,-3,-6,STONE)
Block(5,-3,-5,STONE)
Block(5,-3,-4,STONE)
Block(5,-3,-3,STONE)
Block(5,-3,-2,STONE)
Block(5,-3,-1,STONE)
Block(5,-2,-7,STONE)
Block(5,-2,-6,STONE)
Block(5,-2,-5,STONE)
Block(5,-2,-4,STONE)
Block(5,-2,-3,STONE)
Block(5,-2,-2,STONE)
Block(5,-2,-1,STONE)
Block(5,-1,-6,STONE)
Block(5,-1,-5,STONE)
Block(5,-1,-4,STONE)
Block(5,-1,-3,STONE)
Block(5,-1,-2,STONE)
Block(5,0,-4,STONE)
Block(5,0,-3,STONE)
Block(5,0,-2,STONE)
Block(5,1,-3,STONE)
Block(5,1,-2,STONE)
Block(6,-5,-5,STONE)
Block(6,-5,-4,STONE)
Block(6,-4,-6,STONE)
Block(6,-4,-5,STONE)
Block(6,-4,-4,STONE)
Block(6,-4,-3,STONE)
Block(6,-3,-6,STONE)
Block(6,-3,-5,STONE)
Block(6,-3,-4,STONE)
Block(6,-3,-3,STONE)
Block(6,-2,-6,STONE)
Block(6,-2,-5,STONE)
Block(6,-2,-4,STONE)
Block(6,-2,-3,STONE)

#######################################################################
# +-----------------------------------------------------------------+ #
# |                            BO3 checks                           | #
# +-----------------------------------------------------------------+ #
#######################################################################

# Require a condition at a certain location in order for the BO3 to be spawned.
# BlockCheck(x,y,z,BlockName[,BlockName[,...]]) - one of the blocks must be at the location
# BlockCheckNot(x,y,z,BlockName[,BlockName[,...]]) - all the blocks must not be at the location
# LightCheck(x,y,z,minLightLevel,maxLightLevel) - light must be between min and max (inclusive)

# You can use "Solid" as a BlockName for matching all solid blocks or "All" to match all blocks that aren't air.

# Examples:
#   BlockCheck(0,-1,0,GRASS,DIRT)  Require grass or dirt just below the object
#   BlockCheck(0,-1,0,Solid)       Require any solid block just below the object
#   BlockCheck(0,-1,0,WOOL)        Require any type of wool just below the object
#   BlockCheck(0,-1,0,WOOL:0)      Require white wool just below the object
#   BlockCheckNot(0,-1,0,WOOL:0)   Require that there is no white wool below the object
#   LightCheck(0,0,0,0,1)          Require almost complete darkness just below the object
BlockCheck(0,-1,0,GRASS,DIRT,12,12:1,GRAVEL,STONE,HARD_CLAY)

#######################################################################
# +-----------------------------------------------------------------+ #
# |                             Branches                            | #
# +-----------------------------------------------------------------+ #
#######################################################################

# Branches are objects that will spawn when this object spawns when it is used in
# the CustomStructure resource. Branches can also have branches, making complex
# structures possible. See the wiki for more details.

# Regular Branches spawn each branch with an independent chance of spawning.
# Branch(x,y,z,branchName,rotation,chance[,anotherBranchName,rotation,chance[,...]][IndividualChance])
# branchName - name of the object to spawn.
# rotation - NORTH, SOUTH, EAST or WEST.
# IndividualChance - The chance each branch has to spawn, assumed to be 100 when left blank

# Weighted Branches spawn branches with a dependent chance of spawning.
# WeightedBranch(x,y,z,branchName,rotation,chance[,anotherBranchName,rotation,chance[,...]][MaxChanceOutOf])
# MaxChanceOutOf - The chance all branches have to spawn out of, assumed to be 100 when left blank
