
#######################################################################
# +-----------------------------------------------------------------+ #
# |                            BO3 object                           | #
# +-----------------------------------------------------------------+ #
#######################################################################

# This is the config file of a custom object.
# If you add this object correctly to your BiomeConfigs, it will spawn in the world.

# This is the creator of this BO3 object
Author: LordSmellyPants

# A short description of this BO3 object
Description: No description given

# The BO3 version, don't change this! It can be used by external applications to do a version check.
Version: 3

# The settings mode, WriteAll, WriteWithoutComments or WriteDisable. See WorldConfig.
SettingsMode: WriteDisable


#######################################################################
# +-----------------------------------------------------------------+ #
# |                          Main settings                          | #
# +-----------------------------------------------------------------+ #
#######################################################################

# This needs to be set to true to spawn the object in the Tree and Sapling resources.
Tree: false

# The frequency of the BO3 from 1 to 200. Tries this many times to spawn this BO3 when using the CustomObject(...) resource.
# Ignored by Tree(..), Sapling(..) and CustomStructure(..)
Frequency: 1

# The rarity of the BO3 from 0 to 100. Each spawn attempt has rarity% chance to succeed when using the CustomObject(...) resource.
# Ignored by Tree(..), Sapling(..) and CustomStructure(..)
Rarity: 0.1

# If you set this to true, the BO3 will be placed with a random rotation.
RotateRandomly: true

# The spawn height of the BO3 - atMinY, randomY, highestBlock or highestSolidBlock.
SpawnHeight: highestSolidBlock

# The offset from the spawn height to spawn this BO3
# Ex. SpawnHeight = highestSolidBlock, SpawnHeightOffset = 3; This object will spawn 3 blocks above the highest solid block
SpawnHeightOffset: 0

# A random amount to offset the spawn location from the spawn offset height
# Ex. SpawnHeightOffset = 3, SpawnHeightVariance = 3; This object will spawn 3 to 6 blocks above the original spot it would have spawned
SpawnHeightVariance: 0

##############################
# Height Limits for the BO3. #
##############################

# When in randomY mode used as the minimum Y or in atMinY mode as the actual Y to spawn this BO3 at.
MinHeight: 0

# When in randomY mode used as the maximum Y to spawn this BO3 at.
MaxHeight: 80

######################
# Extrusion settings #
######################

# The style of extrusion you wish to use - BottomDown, TopUp, None (Default)
ExtrudeMode: None

# The blocks to extrude your BO3 through
ExtrudeThroughBlocks: AIR

# Objects can have other objects attacthed to it: branches. Branches can also
# have branches attached to it, which can also have branches, etc. This is the
# maximum branch depth for this objects.
MaxBranchDepth: 10

# When spawned with the UseWorld keyword, this BO3 should NOT spawn in the following biomes.
# If you write the BO3 name directly in the BiomeConfigs, this will be ignored.
ExcludedBiomes: All


#######################################################################
# +-----------------------------------------------------------------+ #
# |                      Source block settings                      | #
# +-----------------------------------------------------------------+ #
#######################################################################

# The block(s) the BO3 should spawn in.
SourceBlocks: AIR,GRASS,DIRT,GRAVEL,SAND,STONE,STONE:1,STONE:3,STONE:5,DIRT:1,CLAY,HARD_CLAY,38,38:1,38:2,38:3,38:4,38:5,38:6,38:7,38:8,39,40,175,175:1,175:2,175:3,175:4,175:5,31,31:1,31:2,32

# The maximum percentage of the BO3 that can be outside the SourceBlock.
# The BO3 won't be placed on a location with more blocks outside the SourceBlock than this percentage.
MaxPercentageOutsideSourceBlock: 100

# What to do when a block is about to be placed outside the SourceBlock? (dontPlace, placeAnyway)
OutsideSourceBlock: placeAnyway


#######################################################################
# +-----------------------------------------------------------------+ #
# |                              Blocks                             | #
# +-----------------------------------------------------------------+ #
#######################################################################

# All the blocks used in the BO3 are listed here. Possible blocks:
# Block(x,y,z,id[.data][,nbtfile.nbt)
# RandomBlock(x,y,z,id[:data][,nbtfile.nbt],chance[,id[:data][,nbtfile.nbt],chance[,...]])
#  So RandomBlock(0,0,0,CHEST,chest.nbt,50,CHEST,anotherchest.nbt,100) will spawn a chest at
#  the BO3 origin, and give it a 50% chance to have the contents of chest.nbt, or, if that
#  fails, a 100% percent chance to have the contents of anotherchest.nbt.
# MinecraftObject(x,y,z,name)
#  Spawns an object in the Mojang NBT structure format. For example, 
#  MinecraftObject(0,0,0,minecraft:igloo/igloo_bottom)
#  spawns the bottom part of an igloo.
Block(-19,-9,-8,SANDSTONE)
Block(-19,-9,-7,SANDSTONE)
Block(-19,-9,-6,SANDSTONE)
Block(-19,-9,-5,SANDSTONE)
Block(-19,-9,-4,SANDSTONE)
Block(-19,-8,-8,SANDSTONE)
Block(-19,-8,-7,SANDSTONE)
Block(-19,-8,-6,SANDSTONE)
Block(-19,-8,-5,SANDSTONE)
Block(-19,-8,-4,SANDSTONE)
Block(-19,-7,-9,SANDSTONE)
Block(-19,-7,-8,SANDSTONE)
Block(-19,-7,-7,SANDSTONE)
Block(-19,-7,-6,SANDSTONE)
Block(-19,-7,-5,SANDSTONE)
Block(-19,-7,-4,SANDSTONE)
Block(-19,-6,-10,SANDSTONE)
Block(-19,-6,-9,SANDSTONE)
Block(-19,-6,-8,SANDSTONE)
Block(-19,-6,-7,SANDSTONE)
Block(-19,-6,-6,SANDSTONE)
Block(-19,-6,-5,SANDSTONE)
Block(-19,-6,-4,SANDSTONE)
Block(-19,-6,-3,SANDSTONE)
Block(-19,-5,-13,SANDSTONE)
Block(-19,-5,-12,SANDSTONE)
Block(-19,-5,-11,SANDSTONE)
Block(-19,-5,-10,SANDSTONE)
Block(-19,-5,-9,SANDSTONE)
Block(-19,-5,-8,SANDSTONE)
Block(-19,-5,-7,SANDSTONE)
Block(-19,-5,-6,SANDSTONE)
Block(-19,-5,-5,SANDSTONE)
Block(-19,-5,-4,SANDSTONE)
Block(-19,-5,-3,SANDSTONE)
Block(-19,-4,-13,SANDSTONE)
Block(-19,-4,-12,SANDSTONE)
Block(-19,-4,-11,SANDSTONE)
Block(-19,-4,-10,SANDSTONE)
Block(-19,-4,-9,SANDSTONE)
Block(-19,-4,-8,SANDSTONE)
Block(-19,-4,-7,SANDSTONE)
Block(-19,-4,-6,SANDSTONE)
Block(-19,-4,-5,SANDSTONE)
Block(-19,-4,-4,SANDSTONE)
Block(-19,-4,-3,SANDSTONE)
Block(-19,-4,-2,SANDSTONE)
Block(-19,-3,-14,SANDSTONE)
Block(-19,-3,-13,SANDSTONE)
Block(-19,-3,-12,SANDSTONE)
Block(-19,-3,-11,SANDSTONE)
Block(-19,-3,-10,SANDSTONE)
Block(-19,-3,-9,SANDSTONE)
Block(-19,-3,-8,SANDSTONE)
Block(-19,-3,-7,SANDSTONE)
Block(-19,-3,-6,SANDSTONE)
Block(-19,-3,-5,SANDSTONE)
Block(-19,-3,-4,SANDSTONE)
Block(-19,-3,-3,SANDSTONE)
Block(-19,-3,-2,SANDSTONE)
Block(-19,-3,-1,SANDSTONE)
Block(-19,-2,-14,SANDSTONE)
Block(-19,-2,-13,SANDSTONE)
Block(-19,-2,-12,SANDSTONE)
Block(-19,-2,-11,SANDSTONE)
Block(-19,-2,-10,SANDSTONE)
Block(-19,-2,-9,SANDSTONE)
Block(-19,-2,-8,SANDSTONE)
Block(-19,-2,-7,SANDSTONE)
Block(-19,-2,-6,SANDSTONE)
Block(-19,-2,-5,SANDSTONE)
Block(-19,-2,-4,SANDSTONE)
Block(-19,-2,-3,SANDSTONE)
Block(-19,-2,-2,SANDSTONE)
Block(-19,-2,-1,SANDSTONE)
Block(-19,-1,-13,SANDSTONE)
Block(-19,-1,-12,SANDSTONE)
Block(-19,-1,-11,SANDSTONE)
Block(-19,-1,-10,SANDSTONE)
Block(-19,-1,-9,SANDSTONE)
Block(-19,-1,-8,SANDSTONE)
Block(-19,-1,-7,SANDSTONE)
Block(-19,-1,-6,SANDSTONE)
Block(-19,-1,-5,SANDSTONE)
Block(-19,-1,-4,SANDSTONE)
Block(-19,-1,-3,SANDSTONE)
Block(-19,-1,-2,SANDSTONE)
Block(-19,0,-13,SANDSTONE)
Block(-19,0,-12,SANDSTONE)
Block(-19,0,-11,SANDSTONE)
Block(-19,0,-10,SANDSTONE)
Block(-19,0,-9,SANDSTONE)
Block(-19,0,-8,SANDSTONE)
Block(-19,0,-7,SANDSTONE)
Block(-19,0,-6,SANDSTONE)
Block(-19,0,-5,SANDSTONE)
Block(-19,0,-4,SANDSTONE)
Block(-19,0,-3,SANDSTONE)
Block(-19,1,-10,SANDSTONE)
Block(-19,1,-9,SANDSTONE)
Block(-19,1,-8,SANDSTONE)
Block(-19,1,-7,SANDSTONE)
Block(-19,1,-6,SANDSTONE)
Block(-19,1,-5,SANDSTONE)
Block(-19,1,-4,SANDSTONE)
Block(-19,1,-3,SANDSTONE)
Block(-19,2,-9,SANDSTONE)
Block(-19,2,-8,SANDSTONE)
Block(-19,2,-7,SANDSTONE)
Block(-19,2,-6,SANDSTONE)
Block(-19,2,-5,SANDSTONE)
Block(-19,2,-4,SANDSTONE)
Block(-19,3,-8,SANDSTONE)
Block(-19,3,-7,SANDSTONE)
Block(-19,3,-6,SANDSTONE)
Block(-19,3,-5,SANDSTONE)
Block(-19,3,-4,SANDSTONE)
Block(-19,4,-8,SANDSTONE)
Block(-19,4,-7,SANDSTONE)
Block(-19,4,-6,SANDSTONE)
Block(-19,4,-5,SANDSTONE)
Block(-19,4,-4,SANDSTONE)
Block(-18,-10,-7,SANDSTONE)
Block(-18,-10,-6,SANDSTONE)
Block(-18,-10,-5,SANDSTONE)
Block(-18,-10,-4,SANDSTONE)
Block(-18,-9,-9,SANDSTONE)
Block(-18,-9,-8,SANDSTONE)
Block(-18,-9,-7,SANDSTONE)
Block(-18,-9,-6,SANDSTONE)
Block(-18,-9,-5,SANDSTONE)
Block(-18,-9,-4,SANDSTONE)
Block(-18,-8,-10,SANDSTONE)
Block(-18,-8,-9,SANDSTONE)
Block(-18,-8,-8,SANDSTONE)
Block(-18,-8,-7,SANDSTONE)
Block(-18,-8,-6,SANDSTONE)
Block(-18,-8,-5,SANDSTONE)
Block(-18,-8,-4,SANDSTONE)
Block(-18,-8,-3,SANDSTONE)
Block(-18,-7,-10,SANDSTONE)
Block(-18,-7,-9,SANDSTONE)
Block(-18,-7,-8,SANDSTONE)
Block(-18,-7,-7,SANDSTONE)
Block(-18,-7,-6,SANDSTONE)
Block(-18,-7,-5,SANDSTONE)
Block(-18,-7,-4,SANDSTONE)
Block(-18,-7,-3,SANDSTONE)
Block(-18,-6,-11,SANDSTONE)
Block(-18,-6,-10,SANDSTONE)
Block(-18,-6,-9,SANDSTONE)
Block(-18,-6,-8,SANDSTONE)
Block(-18,-6,-7,SANDSTONE)
Block(-18,-6,-6,SANDSTONE)
Block(-18,-6,-5,SANDSTONE)
Block(-18,-6,-4,SANDSTONE)
Block(-18,-6,-3,SANDSTONE)
Block(-18,-6,-2,SANDSTONE)
Block(-18,-5,-14,SANDSTONE)
Block(-18,-5,-13,SANDSTONE)
Block(-18,-5,-12,SANDSTONE)
Block(-18,-5,-11,SANDSTONE)
Block(-18,-5,-10,SANDSTONE)
Block(-18,-5,-9,SANDSTONE)
Block(-18,-5,-8,SANDSTONE)
Block(-18,-5,-7,SANDSTONE)
Block(-18,-5,-6,SANDSTONE)
Block(-18,-5,-5,SANDSTONE)
Block(-18,-5,-4,SANDSTONE)
Block(-18,-5,-3,SANDSTONE)
Block(-18,-5,-2,SANDSTONE)
Block(-18,-4,-14,SANDSTONE)
Block(-18,-4,-13,SANDSTONE)
Block(-18,-4,-12,SANDSTONE)
Block(-18,-4,-11,SANDSTONE)
Block(-18,-4,-10,SANDSTONE)
Block(-18,-4,-9,SANDSTONE)
Block(-18,-4,-8,SANDSTONE)
Block(-18,-4,-7,SANDSTONE)
Block(-18,-4,-6,SANDSTONE)
Block(-18,-4,-5,SANDSTONE)
Block(-18,-4,-4,SANDSTONE)
Block(-18,-4,-3,SANDSTONE)
Block(-18,-4,-2,SANDSTONE)
Block(-18,-4,-1,SANDSTONE)
Block(-18,-3,-14,SANDSTONE)
Block(-18,-3,-13,SANDSTONE)
Block(-18,-3,-12,SANDSTONE)
Block(-18,-3,-11,SANDSTONE)
Block(-18,-3,-10,SANDSTONE)
Block(-18,-3,-9,SANDSTONE)
Block(-18,-3,-8,SANDSTONE)
Block(-18,-3,-7,SANDSTONE)
Block(-18,-3,-6,SANDSTONE)
Block(-18,-3,-5,SANDSTONE)
Block(-18,-3,-4,SANDSTONE)
Block(-18,-3,-3,SANDSTONE)
Block(-18,-3,-2,SANDSTONE)
Block(-18,-3,-1,SANDSTONE)
Block(-18,-3,0,SANDSTONE)
Block(-18,-2,-14,SANDSTONE)
Block(-18,-2,-13,SANDSTONE)
Block(-18,-2,-12,SANDSTONE)
Block(-18,-2,-11,SANDSTONE)
Block(-18,-2,-10,SANDSTONE)
Block(-18,-2,-9,SANDSTONE)
Block(-18,-2,-8,SANDSTONE)
Block(-18,-2,-7,SANDSTONE)
Block(-18,-2,-6,SANDSTONE)
Block(-18,-2,-5,SANDSTONE)
Block(-18,-2,-4,SANDSTONE)
Block(-18,-2,-3,SANDSTONE)
Block(-18,-2,-2,SANDSTONE)
Block(-18,-2,-1,SANDSTONE)
Block(-18,-2,0,SANDSTONE)
Block(-18,-1,-14,SANDSTONE)
Block(-18,-1,-13,SANDSTONE)
Block(-18,-1,-12,SANDSTONE)
Block(-18,-1,-11,SANDSTONE)
Block(-18,-1,-10,SANDSTONE)
Block(-18,-1,-9,SANDSTONE)
Block(-18,-1,-8,SANDSTONE)
Block(-18,-1,-7,SANDSTONE)
Block(-18,-1,-6,SANDSTONE)
Block(-18,-1,-5,SANDSTONE)
Block(-18,-1,-4,SANDSTONE)
Block(-18,-1,-3,SANDSTONE)
Block(-18,-1,-2,SANDSTONE)
Block(-18,-1,-1,SANDSTONE)
Block(-18,0,-14,SANDSTONE)
Block(-18,0,-13,SANDSTONE)
Block(-18,0,-12,SANDSTONE)
Block(-18,0,-11,SANDSTONE)
Block(-18,0,-10,SANDSTONE)
Block(-18,0,-9,SANDSTONE)
Block(-18,0,-8,SANDSTONE)
Block(-18,0,-7,SANDSTONE)
Block(-18,0,-6,SANDSTONE)
Block(-18,0,-5,SANDSTONE)
Block(-18,0,-4,SANDSTONE)
Block(-18,0,-3,SANDSTONE)
Block(-18,0,-2,SANDSTONE)
Block(-18,1,-11,SANDSTONE)
Block(-18,1,-10,SANDSTONE)
Block(-18,1,-9,SANDSTONE)
Block(-18,1,-8,SANDSTONE)
Block(-18,1,-7,SANDSTONE)
Block(-18,1,-6,SANDSTONE)
Block(-18,1,-5,SANDSTONE)
Block(-18,1,-4,SANDSTONE)
Block(-18,1,-3,SANDSTONE)
Block(-18,1,-2,SANDSTONE)
Block(-18,2,-10,SANDSTONE)
Block(-18,2,-9,SANDSTONE)
Block(-18,2,-8,SANDSTONE)
Block(-18,2,-7,SANDSTONE)
Block(-18,2,-6,SANDSTONE)
Block(-18,2,-5,SANDSTONE)
Block(-18,2,-4,SANDSTONE)
Block(-18,2,-3,SANDSTONE)
Block(-18,3,-10,SANDSTONE)
Block(-18,3,-9,SANDSTONE)
Block(-18,3,-8,SANDSTONE)
Block(-18,3,-7,SANDSTONE)
Block(-18,3,-6,SANDSTONE)
Block(-18,3,-5,SANDSTONE)
Block(-18,3,-4,SANDSTONE)
Block(-18,3,-3,SANDSTONE)
Block(-18,4,-9,SANDSTONE)
Block(-18,4,-8,SANDSTONE)
Block(-18,4,-7,SANDSTONE)
Block(-18,4,-6,SANDSTONE)
Block(-18,4,-5,SANDSTONE)
Block(-18,4,-4,SANDSTONE)
Block(-18,5,-7,SANDSTONE)
Block(-18,5,-6,SANDSTONE)
Block(-18,5,-5,SANDSTONE)
Block(-18,5,-4,SANDSTONE)
Block(-17,-10,-8,SANDSTONE)
Block(-17,-10,-7,SANDSTONE)
Block(-17,-10,-6,SANDSTONE)
Block(-17,-10,-5,SANDSTONE)
Block(-17,-10,-4,SANDSTONE)
Block(-17,-9,-10,SANDSTONE)
Block(-17,-9,-9,SANDSTONE)
Block(-17,-9,-8,SANDSTONE)
Block(-17,-9,-7,SANDSTONE)
Block(-17,-9,-6,SANDSTONE)
Block(-17,-9,-5,SANDSTONE)
Block(-17,-9,-4,SANDSTONE)
Block(-17,-9,-3,SANDSTONE)
Block(-17,-8,-10,SANDSTONE)
Block(-17,-8,-9,SANDSTONE)
Block(-17,-8,-8,SANDSTONE)
Block(-17,-8,-7,SANDSTONE)
Block(-17,-8,-6,SANDSTONE)
Block(-17,-8,-5,SANDSTONE)
Block(-17,-8,-4,SANDSTONE)
Block(-17,-8,-3,SANDSTONE)
Block(-17,-7,-10,SANDSTONE)
Block(-17,-7,-9,SANDSTONE)
Block(-17,-7,-8,SANDSTONE)
Block(-17,-7,-7,SANDSTONE)
Block(-17,-7,-6,SANDSTONE)
Block(-17,-7,-5,SANDSTONE)
Block(-17,-7,-4,SANDSTONE)
Block(-17,-7,-3,SANDSTONE)
Block(-17,-7,-2,SANDSTONE)
Block(-17,-6,-11,SANDSTONE)
Block(-17,-6,-10,SANDSTONE)
Block(-17,-6,-9,SANDSTONE)
Block(-17,-6,-8,SANDSTONE)
Block(-17,-6,-7,SANDSTONE)
Block(-17,-6,-6,SANDSTONE)
Block(-17,-6,-5,SANDSTONE)
Block(-17,-6,-4,SANDSTONE)
Block(-17,-6,-3,SANDSTONE)
Block(-17,-6,-2,SANDSTONE)
Block(-17,-6,-1,SANDSTONE)
Block(-17,-5,-14,SANDSTONE)
Block(-17,-5,-13,SANDSTONE)
Block(-17,-5,-12,SANDSTONE)
Block(-17,-5,-11,SANDSTONE)
Block(-17,-5,-10,SANDSTONE)
Block(-17,-5,-9,SANDSTONE)
Block(-17,-5,-8,SANDSTONE)
Block(-17,-5,-7,SANDSTONE)
Block(-17,-5,-6,SANDSTONE)
Block(-17,-5,-5,SANDSTONE)
Block(-17,-5,-4,SANDSTONE)
Block(-17,-5,-3,SANDSTONE)
Block(-17,-5,-2,SANDSTONE)
Block(-17,-5,-1,SANDSTONE)
Block(-17,-4,-14,SANDSTONE)
Block(-17,-4,-13,SANDSTONE)
Block(-17,-4,-12,SANDSTONE)
Block(-17,-4,-11,SANDSTONE)
Block(-17,-4,-10,SANDSTONE)
Block(-17,-4,-9,SANDSTONE)
Block(-17,-4,-8,SANDSTONE)
Block(-17,-4,-7,SANDSTONE)
Block(-17,-4,-6,SANDSTONE)
Block(-17,-4,-5,SANDSTONE)
Block(-17,-4,-4,SANDSTONE)
Block(-17,-4,-3,SANDSTONE)
Block(-17,-4,-2,SANDSTONE)
Block(-17,-4,-1,SANDSTONE)
Block(-17,-3,-14,SANDSTONE)
Block(-17,-3,-13,SANDSTONE)
Block(-17,-3,-12,SANDSTONE)
Block(-17,-3,-11,SANDSTONE)
Block(-17,-3,-10,SANDSTONE)
Block(-17,-3,-9,SANDSTONE)
Block(-17,-3,-8,SANDSTONE)
Block(-17,-3,-7,SANDSTONE)
Block(-17,-3,-6,SANDSTONE)
Block(-17,-3,-5,SANDSTONE)
Block(-17,-3,-4,SANDSTONE)
Block(-17,-3,-3,SANDSTONE)
Block(-17,-3,-2,SANDSTONE)
Block(-17,-3,-1,SANDSTONE)
Block(-17,-3,0,SANDSTONE)
Block(-17,-3,6,SANDSTONE)
Block(-17,-3,7,SANDSTONE)
Block(-17,-3,8,SANDSTONE)
Block(-17,-3,9,SANDSTONE)
Block(-17,-2,-14,SANDSTONE)
Block(-17,-2,-13,SANDSTONE)
Block(-17,-2,-12,SANDSTONE)
Block(-17,-2,-11,SANDSTONE)
Block(-17,-2,-10,SANDSTONE)
Block(-17,-2,-9,SANDSTONE)
Block(-17,-2,-8,SANDSTONE)
Block(-17,-2,-7,SANDSTONE)
Block(-17,-2,-6,SANDSTONE)
Block(-17,-2,-5,SANDSTONE)
Block(-17,-2,-4,SANDSTONE)
Block(-17,-2,-3,SANDSTONE)
Block(-17,-2,-2,SANDSTONE)
Block(-17,-2,-1,SANDSTONE)
Block(-17,-2,0,SANDSTONE)
Block(-17,-2,6,SANDSTONE)
Block(-17,-2,7,SANDSTONE)
Block(-17,-2,8,SANDSTONE)
Block(-17,-2,9,SANDSTONE)
Block(-17,-1,-14,SANDSTONE)
Block(-17,-1,-13,SANDSTONE)
Block(-17,-1,-12,SANDSTONE)
Block(-17,-1,-11,SANDSTONE)
Block(-17,-1,-10,SANDSTONE)
Block(-17,-1,-9,SANDSTONE)
Block(-17,-1,-8,SANDSTONE)
Block(-17,-1,-7,SANDSTONE)
Block(-17,-1,-6,SANDSTONE)
Block(-17,-1,-5,SANDSTONE)
Block(-17,-1,-4,SANDSTONE)
Block(-17,-1,-3,SANDSTONE)
Block(-17,-1,-2,SANDSTONE)
Block(-17,-1,-1,SANDSTONE)
Block(-17,0,-14,SANDSTONE)
Block(-17,0,-13,SANDSTONE)
Block(-17,0,-12,SANDSTONE)
Block(-17,0,-11,SANDSTONE)
Block(-17,0,-10,SANDSTONE)
Block(-17,0,-9,SANDSTONE)
Block(-17,0,-8,SANDSTONE)
Block(-17,0,-7,SANDSTONE)
Block(-17,0,-6,SANDSTONE)
Block(-17,0,-5,SANDSTONE)
Block(-17,0,-4,SANDSTONE)
Block(-17,0,-3,SANDSTONE)
Block(-17,0,-2,SANDSTONE)
Block(-17,0,-1,SANDSTONE)
Block(-17,1,-11,SANDSTONE)
Block(-17,1,-10,SANDSTONE)
Block(-17,1,-9,SANDSTONE)
Block(-17,1,-8,SANDSTONE)
Block(-17,1,-7,SANDSTONE)
Block(-17,1,-6,SANDSTONE)
Block(-17,1,-5,SANDSTONE)
Block(-17,1,-4,SANDSTONE)
Block(-17,1,-3,SANDSTONE)
Block(-17,1,-2,SANDSTONE)
Block(-17,1,-1,SANDSTONE)
Block(-17,2,-10,SANDSTONE)
Block(-17,2,-9,SANDSTONE)
Block(-17,2,-8,SANDSTONE)
Block(-17,2,-7,SANDSTONE)
Block(-17,2,-6,SANDSTONE)
Block(-17,2,-5,SANDSTONE)
Block(-17,2,-4,SANDSTONE)
Block(-17,2,-3,SANDSTONE)
Block(-17,2,-2,SANDSTONE)
Block(-17,3,-10,SANDSTONE)
Block(-17,3,-9,SANDSTONE)
Block(-17,3,-8,SANDSTONE)
Block(-17,3,-7,SANDSTONE)
Block(-17,3,-6,SANDSTONE)
Block(-17,3,-5,SANDSTONE)
Block(-17,3,-4,SANDSTONE)
Block(-17,3,-3,SANDSTONE)
Block(-17,4,-10,SANDSTONE)
Block(-17,4,-9,SANDSTONE)
Block(-17,4,-8,SANDSTONE)
Block(-17,4,-7,SANDSTONE)
Block(-17,4,-6,SANDSTONE)
Block(-17,4,-5,SANDSTONE)
Block(-17,4,-4,SANDSTONE)
Block(-17,4,-3,SANDSTONE)
Block(-17,5,-8,SANDSTONE)
Block(-17,5,-7,SANDSTONE)
Block(-17,5,-6,SANDSTONE)
Block(-17,5,-5,SANDSTONE)
Block(-17,5,-4,SANDSTONE)
Block(-16,-11,-7,SANDSTONE)
Block(-16,-11,-6,SANDSTONE)
Block(-16,-11,-5,SANDSTONE)
Block(-16,-11,-4,SANDSTONE)
Block(-16,-11,-3,SANDSTONE)
Block(-16,-10,-8,SANDSTONE)
Block(-16,-10,-7,SANDSTONE)
Block(-16,-10,-6,SANDSTONE)
Block(-16,-10,-5,SANDSTONE)
Block(-16,-10,-4,SANDSTONE)
Block(-16,-10,-3,SANDSTONE)
Block(-16,-9,-10,SANDSTONE)
Block(-16,-9,-9,SANDSTONE)
Block(-16,-9,-8,SANDSTONE)
Block(-16,-9,-7,SANDSTONE)
Block(-16,-9,-6,SANDSTONE)
Block(-16,-9,-5,SANDSTONE)
Block(-16,-9,-4,SANDSTONE)
Block(-16,-9,-3,SANDSTONE)
Block(-16,-8,-10,SANDSTONE)
Block(-16,-8,-9,SANDSTONE)
Block(-16,-8,-8,SANDSTONE)
Block(-16,-8,-7,SANDSTONE)
Block(-16,-8,-6,SANDSTONE)
Block(-16,-8,-5,SANDSTONE)
Block(-16,-8,-4,SANDSTONE)
Block(-16,-8,-3,SANDSTONE)
Block(-16,-8,-2,SANDSTONE)
Block(-16,-7,-10,SANDSTONE)
Block(-16,-7,-9,SANDSTONE)
Block(-16,-7,-8,SANDSTONE)
Block(-16,-7,-7,SANDSTONE)
Block(-16,-7,-6,SANDSTONE)
Block(-16,-7,-5,SANDSTONE)
Block(-16,-7,-4,SANDSTONE)
Block(-16,-7,-3,SANDSTONE)
Block(-16,-7,-2,SANDSTONE)
Block(-16,-7,-1,SANDSTONE)
Block(-16,-6,-11,SANDSTONE)
Block(-16,-6,-10,SANDSTONE)
Block(-16,-6,-9,SANDSTONE)
Block(-16,-6,-8,SANDSTONE)
Block(-16,-6,-7,SANDSTONE)
Block(-16,-6,-6,SANDSTONE)
Block(-16,-6,-5,SANDSTONE)
Block(-16,-6,-4,SANDSTONE)
Block(-16,-6,-3,SANDSTONE)
Block(-16,-6,-2,SANDSTONE)
Block(-16,-6,-1,SANDSTONE)
Block(-16,-5,-14,SANDSTONE)
Block(-16,-5,-13,SANDSTONE)
Block(-16,-5,-12,SANDSTONE)
Block(-16,-5,-11,SANDSTONE)
Block(-16,-5,-10,SANDSTONE)
Block(-16,-5,-9,SANDSTONE)
Block(-16,-5,-8,SANDSTONE)
Block(-16,-5,-7,SANDSTONE)
Block(-16,-5,-6,SANDSTONE)
Block(-16,-5,-5,SANDSTONE)
Block(-16,-5,-4,SANDSTONE)
Block(-16,-5,-3,SANDSTONE)
Block(-16,-5,-2,SANDSTONE)
Block(-16,-5,-1,SANDSTONE)
Block(-16,-5,0,SANDSTONE)
Block(-16,-4,-14,SANDSTONE)
Block(-16,-4,-13,SANDSTONE)
Block(-16,-4,-12,SANDSTONE)
Block(-16,-4,-11,SANDSTONE)
Block(-16,-4,-10,SANDSTONE)
Block(-16,-4,-9,SANDSTONE)
Block(-16,-4,-8,SANDSTONE)
Block(-16,-4,-7,SANDSTONE)
Block(-16,-4,-6,SANDSTONE)
Block(-16,-4,-5,SANDSTONE)
Block(-16,-4,-4,SANDSTONE)
Block(-16,-4,-3,SANDSTONE)
Block(-16,-4,-2,SANDSTONE)
Block(-16,-4,-1,SANDSTONE)
Block(-16,-4,0,SANDSTONE)
Block(-16,-4,6,SANDSTONE)
Block(-16,-4,7,SANDSTONE)
Block(-16,-4,8,SANDSTONE)
Block(-16,-4,9,SANDSTONE)
Block(-16,-3,-14,SANDSTONE)
Block(-16,-3,-13,SANDSTONE)
Block(-16,-3,-12,SANDSTONE)
Block(-16,-3,-11,SANDSTONE)
Block(-16,-3,-10,SANDSTONE)
Block(-16,-3,-9,SANDSTONE)
Block(-16,-3,-8,SANDSTONE)
Block(-16,-3,-7,SANDSTONE)
Block(-16,-3,-6,SANDSTONE)
Block(-16,-3,-5,SANDSTONE)
Block(-16,-3,-4,SANDSTONE)
Block(-16,-3,-3,SANDSTONE)
Block(-16,-3,-2,SANDSTONE)
Block(-16,-3,-1,SANDSTONE)
Block(-16,-3,0,SANDSTONE)
Block(-16,-3,1,SANDSTONE)
Block(-16,-3,5,SANDSTONE)
Block(-16,-3,6,SANDSTONE)
Block(-16,-3,7,SANDSTONE)
Block(-16,-3,8,SANDSTONE)
Block(-16,-3,9,SANDSTONE)
Block(-16,-3,10,SANDSTONE)
Block(-16,-2,-14,SANDSTONE)
Block(-16,-2,-13,SANDSTONE)
Block(-16,-2,-12,SANDSTONE)
Block(-16,-2,-11,SANDSTONE)
Block(-16,-2,-10,SANDSTONE)
Block(-16,-2,-9,SANDSTONE)
Block(-16,-2,-8,SANDSTONE)
Block(-16,-2,-7,SANDSTONE)
Block(-16,-2,-6,SANDSTONE)
Block(-16,-2,-5,SANDSTONE)
Block(-16,-2,-4,SANDSTONE)
Block(-16,-2,-3,SANDSTONE)
Block(-16,-2,-2,SANDSTONE)
Block(-16,-2,-1,SANDSTONE)
Block(-16,-2,0,SANDSTONE)
Block(-16,-2,1,SANDSTONE)
Block(-16,-2,5,SANDSTONE)
Block(-16,-2,6,SANDSTONE)
Block(-16,-2,7,SANDSTONE)
Block(-16,-2,8,SANDSTONE)
Block(-16,-2,9,SANDSTONE)
Block(-16,-2,10,SANDSTONE)
Block(-16,-1,-14,SANDSTONE)
Block(-16,-1,-13,SANDSTONE)
Block(-16,-1,-12,SANDSTONE)
Block(-16,-1,-11,SANDSTONE)
Block(-16,-1,-10,SANDSTONE)
Block(-16,-1,-9,SANDSTONE)
Block(-16,-1,-8,SANDSTONE)
Block(-16,-1,-7,SANDSTONE)
Block(-16,-1,-6,SANDSTONE)
Block(-16,-1,-5,SANDSTONE)
Block(-16,-1,-4,SANDSTONE)
Block(-16,-1,-3,SANDSTONE)
Block(-16,-1,-2,SANDSTONE)
Block(-16,-1,-1,SANDSTONE)
Block(-16,-1,0,SANDSTONE)
Block(-16,-1,6,SANDSTONE)
Block(-16,-1,7,SANDSTONE)
Block(-16,-1,8,SANDSTONE)
Block(-16,-1,9,SANDSTONE)
Block(-16,0,-14,SANDSTONE)
Block(-16,0,-13,SANDSTONE)
Block(-16,0,-12,SANDSTONE)
Block(-16,0,-11,SANDSTONE)
Block(-16,0,-10,SANDSTONE)
Block(-16,0,-9,SANDSTONE)
Block(-16,0,-8,SANDSTONE)
Block(-16,0,-7,SANDSTONE)
Block(-16,0,-6,SANDSTONE)
Block(-16,0,-5,SANDSTONE)
Block(-16,0,-4,SANDSTONE)
Block(-16,0,-3,SANDSTONE)
Block(-16,0,-2,SANDSTONE)
Block(-16,0,-1,SANDSTONE)
Block(-16,0,0,SANDSTONE)
Block(-16,1,-11,SANDSTONE)
Block(-16,1,-10,SANDSTONE)
Block(-16,1,-9,SANDSTONE)
Block(-16,1,-8,SANDSTONE)
Block(-16,1,-7,SANDSTONE)
Block(-16,1,-6,SANDSTONE)
Block(-16,1,-5,SANDSTONE)
Block(-16,1,-4,SANDSTONE)
Block(-16,1,-3,SANDSTONE)
Block(-16,1,-2,SANDSTONE)
Block(-16,1,-1,SANDSTONE)
Block(-16,2,-10,SANDSTONE)
Block(-16,2,-9,SANDSTONE)
Block(-16,2,-8,SANDSTONE)
Block(-16,2,-7,SANDSTONE)
Block(-16,2,-6,SANDSTONE)
Block(-16,2,-5,SANDSTONE)
Block(-16,2,-4,SANDSTONE)
Block(-16,2,-3,SANDSTONE)
Block(-16,2,-2,SANDSTONE)
Block(-16,2,-1,SANDSTONE)
Block(-16,3,-10,SANDSTONE)
Block(-16,3,-9,SANDSTONE)
Block(-16,3,-8,SANDSTONE)
Block(-16,3,-7,SANDSTONE)
Block(-16,3,-6,SANDSTONE)
Block(-16,3,-5,SANDSTONE)
Block(-16,3,-4,SANDSTONE)
Block(-16,3,-3,SANDSTONE)
Block(-16,3,-2,SANDSTONE)
Block(-16,4,-10,SANDSTONE)
Block(-16,4,-9,SANDSTONE)
Block(-16,4,-8,SANDSTONE)
Block(-16,4,-7,SANDSTONE)
Block(-16,4,-6,SANDSTONE)
Block(-16,4,-5,SANDSTONE)
Block(-16,4,-4,SANDSTONE)
Block(-16,4,-3,SANDSTONE)
Block(-16,5,-8,SANDSTONE)
Block(-16,5,-7,SANDSTONE)
Block(-16,5,-6,SANDSTONE)
Block(-16,5,-5,SANDSTONE)
Block(-16,5,-4,SANDSTONE)
Block(-16,5,-3,SANDSTONE)
Block(-16,6,-7,SANDSTONE)
Block(-16,6,-6,SANDSTONE)
Block(-16,6,-5,SANDSTONE)
Block(-16,6,-4,SANDSTONE)
Block(-16,6,-3,SANDSTONE)
Block(-15,-12,-6,SANDSTONE)
Block(-15,-12,-5,SANDSTONE)
Block(-15,-12,-4,SANDSTONE)
Block(-15,-12,-3,SANDSTONE)
Block(-15,-11,-7,SANDSTONE)
Block(-15,-11,-6,SANDSTONE)
Block(-15,-11,-5,SANDSTONE)
Block(-15,-11,-4,SANDSTONE)
Block(-15,-11,-3,SANDSTONE)
Block(-15,-11,-2,SANDSTONE)
Block(-15,-11,-1,SANDSTONE)
Block(-15,-10,-8,SANDSTONE)
Block(-15,-10,-7,SANDSTONE)
Block(-15,-10,-6,SANDSTONE)
Block(-15,-10,-5,SANDSTONE)
Block(-15,-10,-4,SANDSTONE)
Block(-15,-10,-3,SANDSTONE)
Block(-15,-10,-2,SANDSTONE)
Block(-15,-10,-1,SANDSTONE)
Block(-15,-9,-9,SANDSTONE)
Block(-15,-9,-8,SANDSTONE)
Block(-15,-9,-7,SANDSTONE)
Block(-15,-9,-6,SANDSTONE)
Block(-15,-9,-5,SANDSTONE)
Block(-15,-9,-4,SANDSTONE)
Block(-15,-9,-3,SANDSTONE)
Block(-15,-9,-2,SANDSTONE)
Block(-15,-9,-1,SANDSTONE)
Block(-15,-8,-10,SANDSTONE)
Block(-15,-8,-9,SANDSTONE)
Block(-15,-8,-8,SANDSTONE)
Block(-15,-8,-7,SANDSTONE)
Block(-15,-8,-6,SANDSTONE)
Block(-15,-8,-5,SANDSTONE)
Block(-15,-8,-4,SANDSTONE)
Block(-15,-8,-3,SANDSTONE)
Block(-15,-8,-2,SANDSTONE)
Block(-15,-8,-1,SANDSTONE)
Block(-15,-7,-10,SANDSTONE)
Block(-15,-7,-9,SANDSTONE)
Block(-15,-7,-8,SANDSTONE)
Block(-15,-7,-7,SANDSTONE)
Block(-15,-7,-6,SANDSTONE)
Block(-15,-7,-5,SANDSTONE)
Block(-15,-7,-4,SANDSTONE)
Block(-15,-7,-3,SANDSTONE)
Block(-15,-7,-2,SANDSTONE)
Block(-15,-7,-1,SANDSTONE)
Block(-15,-7,0,SANDSTONE)
Block(-15,-6,-11,SANDSTONE)
Block(-15,-6,-10,SANDSTONE)
Block(-15,-6,-9,SANDSTONE)
Block(-15,-6,-8,SANDSTONE)
Block(-15,-6,-7,SANDSTONE)
Block(-15,-6,-6,SANDSTONE)
Block(-15,-6,-5,SANDSTONE)
Block(-15,-6,-4,SANDSTONE)
Block(-15,-6,-3,SANDSTONE)
Block(-15,-6,-2,SANDSTONE)
Block(-15,-6,-1,SANDSTONE)
Block(-15,-6,0,SANDSTONE)
Block(-15,-6,1,SANDSTONE)
Block(-15,-6,5,SANDSTONE)
Block(-15,-6,6,SANDSTONE)
Block(-15,-6,7,SANDSTONE)
Block(-15,-6,8,SANDSTONE)
Block(-15,-5,-14,SANDSTONE)
Block(-15,-5,-13,SANDSTONE)
Block(-15,-5,-12,SANDSTONE)
Block(-15,-5,-11,SANDSTONE)
Block(-15,-5,-10,SANDSTONE)
Block(-15,-5,-9,SANDSTONE)
Block(-15,-5,-8,SANDSTONE)
Block(-15,-5,-7,SANDSTONE)
Block(-15,-5,-6,SANDSTONE)
Block(-15,-5,-5,SANDSTONE)
Block(-15,-5,-4,SANDSTONE)
Block(-15,-5,-3,SANDSTONE)
Block(-15,-5,-2,SANDSTONE)
Block(-15,-5,-1,SANDSTONE)
Block(-15,-5,0,SANDSTONE)
Block(-15,-5,1,SANDSTONE)
Block(-15,-5,2,SANDSTONE)
Block(-15,-5,3,SANDSTONE)
Block(-15,-5,4,SANDSTONE)
Block(-15,-5,5,SANDSTONE)
Block(-15,-5,6,SANDSTONE)
Block(-15,-5,7,SANDSTONE)
Block(-15,-5,8,SANDSTONE)
Block(-15,-5,9,SANDSTONE)
Block(-15,-5,10,SANDSTONE)
Block(-15,-4,-14,SANDSTONE)
Block(-15,-4,-13,SANDSTONE)
Block(-15,-4,-12,SANDSTONE)
Block(-15,-4,-11,SANDSTONE)
Block(-15,-4,-10,SANDSTONE)
Block(-15,-4,-9,SANDSTONE)
Block(-15,-4,-8,SANDSTONE)
Block(-15,-4,-7,SANDSTONE)
Block(-15,-4,-6,SANDSTONE)
Block(-15,-4,-5,SANDSTONE)
Block(-15,-4,-4,SANDSTONE)
Block(-15,-4,-3,SANDSTONE)
Block(-15,-4,-2,SANDSTONE)
Block(-15,-4,-1,SANDSTONE)
Block(-15,-4,0,SANDSTONE)
Block(-15,-4,1,SANDSTONE)
Block(-15,-4,2,SANDSTONE)
Block(-15,-4,3,SANDSTONE)
Block(-15,-4,4,SANDSTONE)
Block(-15,-4,5,SANDSTONE)
Block(-15,-4,6,SANDSTONE)
Block(-15,-4,7,SANDSTONE)
Block(-15,-4,8,SANDSTONE)
Block(-15,-4,9,SANDSTONE)
Block(-15,-4,10,SANDSTONE)
Block(-15,-4,11,SANDSTONE)
Block(-15,-3,-14,SANDSTONE)
Block(-15,-3,-13,SANDSTONE)
Block(-15,-3,-12,SANDSTONE)
Block(-15,-3,-11,SANDSTONE)
Block(-15,-3,-10,SANDSTONE)
Block(-15,-3,-9,SANDSTONE)
Block(-15,-3,-8,SANDSTONE)
Block(-15,-3,-7,SANDSTONE)
Block(-15,-3,-6,SANDSTONE)
Block(-15,-3,-5,SANDSTONE)
Block(-15,-3,-4,SANDSTONE)
Block(-15,-3,-3,SANDSTONE)
Block(-15,-3,-2,SANDSTONE)
Block(-15,-3,-1,SANDSTONE)
Block(-15,-3,0,SANDSTONE)
Block(-15,-3,1,SANDSTONE)
Block(-15,-3,2,SANDSTONE)
Block(-15,-3,3,SANDSTONE)
Block(-15,-3,4,SANDSTONE)
Block(-15,-3,5,SANDSTONE)
Block(-15,-3,6,SANDSTONE)
Block(-15,-3,7,SANDSTONE)
Block(-15,-3,8,SANDSTONE)
Block(-15,-3,9,SANDSTONE)
Block(-15,-3,10,SANDSTONE)
Block(-15,-3,11,SANDSTONE)
Block(-15,-3,12,SANDSTONE)
Block(-15,-2,-14,SANDSTONE)
Block(-15,-2,-13,SANDSTONE)
Block(-15,-2,-12,SANDSTONE)
Block(-15,-2,-11,SANDSTONE)
Block(-15,-2,-10,SANDSTONE)
Block(-15,-2,-9,SANDSTONE)
Block(-15,-2,-8,SANDSTONE)
Block(-15,-2,-7,SANDSTONE)
Block(-15,-2,-6,SANDSTONE)
Block(-15,-2,-5,SANDSTONE)
Block(-15,-2,-4,SANDSTONE)
Block(-15,-2,-3,SANDSTONE)
Block(-15,-2,-2,SANDSTONE)
Block(-15,-2,-1,SANDSTONE)
Block(-15,-2,0,SANDSTONE)
Block(-15,-2,1,SANDSTONE)
Block(-15,-2,2,SANDSTONE)
Block(-15,-2,3,SANDSTONE)
Block(-15,-2,4,SANDSTONE)
Block(-15,-2,5,SANDSTONE)
Block(-15,-2,6,SANDSTONE)
Block(-15,-2,7,SANDSTONE)
Block(-15,-2,8,SANDSTONE)
Block(-15,-2,9,SANDSTONE)
Block(-15,-2,10,SANDSTONE)
Block(-15,-2,11,SANDSTONE)
Block(-15,-2,12,SANDSTONE)
Block(-15,-1,-14,SANDSTONE)
Block(-15,-1,-13,SANDSTONE)
Block(-15,-1,-12,SANDSTONE)
Block(-15,-1,-11,SANDSTONE)
Block(-15,-1,-10,SANDSTONE)
Block(-15,-1,-9,SANDSTONE)
Block(-15,-1,-8,SANDSTONE)
Block(-15,-1,-7,SANDSTONE)
Block(-15,-1,-6,SANDSTONE)
Block(-15,-1,-5,SANDSTONE)
Block(-15,-1,-4,SANDSTONE)
Block(-15,-1,-3,SANDSTONE)
Block(-15,-1,-2,SANDSTONE)
Block(-15,-1,-1,SANDSTONE)
Block(-15,-1,0,SANDSTONE)
Block(-15,-1,1,SANDSTONE)
Block(-15,-1,2,SANDSTONE)
Block(-15,-1,3,SANDSTONE)
Block(-15,-1,4,SANDSTONE)
Block(-15,-1,5,SANDSTONE)
Block(-15,-1,6,SANDSTONE)
Block(-15,-1,7,SANDSTONE)
Block(-15,-1,8,SANDSTONE)
Block(-15,-1,9,SANDSTONE)
Block(-15,-1,10,SANDSTONE)
Block(-15,-1,11,SANDSTONE)
Block(-15,0,-14,SANDSTONE)
Block(-15,0,-13,SANDSTONE)
Block(-15,0,-12,SANDSTONE)
Block(-15,0,-11,SANDSTONE)
Block(-15,0,-10,SANDSTONE)
Block(-15,0,-9,SANDSTONE)
Block(-15,0,-8,SANDSTONE)
Block(-15,0,-7,SANDSTONE)
Block(-15,0,-6,SANDSTONE)
Block(-15,0,-5,SANDSTONE)
Block(-15,0,-4,SANDSTONE)
Block(-15,0,-3,SANDSTONE)
Block(-15,0,-2,SANDSTONE)
Block(-15,0,-1,SANDSTONE)
Block(-15,0,0,SANDSTONE)
Block(-15,0,1,SANDSTONE)
Block(-15,0,2,SANDSTONE)
Block(-15,0,3,SANDSTONE)
Block(-15,0,4,SANDSTONE)
Block(-15,0,5,SANDSTONE)
Block(-15,0,6,SANDSTONE)
Block(-15,0,7,SANDSTONE)
Block(-15,0,8,SANDSTONE)
Block(-15,0,9,SANDSTONE)
Block(-15,0,10,SANDSTONE)
Block(-15,1,-11,SANDSTONE)
Block(-15,1,-10,SANDSTONE)
Block(-15,1,-9,SANDSTONE)
Block(-15,1,-8,SANDSTONE)
Block(-15,1,-7,SANDSTONE)
Block(-15,1,-6,SANDSTONE)
Block(-15,1,-5,SANDSTONE)
Block(-15,1,-4,SANDSTONE)
Block(-15,1,-3,SANDSTONE)
Block(-15,1,-2,SANDSTONE)
Block(-15,1,-1,SANDSTONE)
Block(-15,1,0,SANDSTONE)
Block(-15,1,1,SANDSTONE)
Block(-15,1,5,SANDSTONE)
Block(-15,1,6,SANDSTONE)
Block(-15,1,7,SANDSTONE)
Block(-15,1,8,SANDSTONE)
Block(-15,2,-10,SANDSTONE)
Block(-15,2,-9,SANDSTONE)
Block(-15,2,-8,SANDSTONE)
Block(-15,2,-7,SANDSTONE)
Block(-15,2,-6,SANDSTONE)
Block(-15,2,-5,SANDSTONE)
Block(-15,2,-4,SANDSTONE)
Block(-15,2,-3,SANDSTONE)
Block(-15,2,-2,SANDSTONE)
Block(-15,2,-1,SANDSTONE)
Block(-15,2,0,SANDSTONE)
Block(-15,3,-10,SANDSTONE)
Block(-15,3,-9,SANDSTONE)
Block(-15,3,-8,SANDSTONE)
Block(-15,3,-7,SANDSTONE)
Block(-15,3,-6,SANDSTONE)
Block(-15,3,-5,SANDSTONE)
Block(-15,3,-4,SANDSTONE)
Block(-15,3,-3,SANDSTONE)
Block(-15,3,-2,SANDSTONE)
Block(-15,3,-1,SANDSTONE)
Block(-15,4,-9,SANDSTONE)
Block(-15,4,-8,SANDSTONE)
Block(-15,4,-7,SANDSTONE)
Block(-15,4,-6,SANDSTONE)
Block(-15,4,-5,SANDSTONE)
Block(-15,4,-4,SANDSTONE)
Block(-15,4,-3,SANDSTONE)
Block(-15,4,-2,SANDSTONE)
Block(-15,4,-1,SANDSTONE)
Block(-15,5,-8,SANDSTONE)
Block(-15,5,-7,SANDSTONE)
Block(-15,5,-6,SANDSTONE)
Block(-15,5,-5,SANDSTONE)
Block(-15,5,-4,SANDSTONE)
Block(-15,5,-3,SANDSTONE)
Block(-15,5,-2,SANDSTONE)
Block(-15,5,-1,SANDSTONE)
Block(-15,6,-7,SANDSTONE)
Block(-15,6,-6,SANDSTONE)
Block(-15,6,-5,SANDSTONE)
Block(-15,6,-4,SANDSTONE)
Block(-15,6,-3,SANDSTONE)
Block(-15,6,-2,SANDSTONE)
Block(-15,6,-1,SANDSTONE)
Block(-15,7,-6,SANDSTONE)
Block(-15,7,-5,SANDSTONE)
Block(-15,7,-4,SANDSTONE)
Block(-15,7,-3,SANDSTONE)
Block(-14,-13,-6,SANDSTONE)
Block(-14,-13,-5,SANDSTONE)
Block(-14,-13,-4,SANDSTONE)
Block(-14,-13,-3,SANDSTONE)
Block(-14,-12,-7,SANDSTONE)
Block(-14,-12,-6,SANDSTONE)
Block(-14,-12,-5,SANDSTONE)
Block(-14,-12,-4,SANDSTONE)
Block(-14,-12,-3,SANDSTONE)
Block(-14,-12,-2,SANDSTONE)
Block(-14,-12,-1,SANDSTONE)
Block(-14,-12,0,SANDSTONE)
Block(-14,-11,-7,SANDSTONE)
Block(-14,-11,-6,SANDSTONE)
Block(-14,-11,-5,SANDSTONE)
Block(-14,-11,-4,SANDSTONE)
Block(-14,-11,-3,SANDSTONE)
Block(-14,-11,-2,SANDSTONE)
Block(-14,-11,-1,SANDSTONE)
Block(-14,-11,0,SANDSTONE)
Block(-14,-10,-8,SANDSTONE)
Block(-14,-10,-7,SANDSTONE)
Block(-14,-10,-6,SANDSTONE)
Block(-14,-10,-5,SANDSTONE)
Block(-14,-10,-4,SANDSTONE)
Block(-14,-10,-3,SANDSTONE)
Block(-14,-10,-2,SANDSTONE)
Block(-14,-10,-1,SANDSTONE)
Block(-14,-10,0,SANDSTONE)
Block(-14,-9,-9,SANDSTONE)
Block(-14,-9,-8,SANDSTONE)
Block(-14,-9,-7,SANDSTONE)
Block(-14,-9,-6,SANDSTONE)
Block(-14,-9,-5,SANDSTONE)
Block(-14,-9,-4,SANDSTONE)
Block(-14,-9,-3,SANDSTONE)
Block(-14,-9,-2,SANDSTONE)
Block(-14,-9,-1,SANDSTONE)
Block(-14,-9,0,SANDSTONE)
Block(-14,-8,-10,SANDSTONE)
Block(-14,-8,-9,SANDSTONE)
Block(-14,-8,-8,SANDSTONE)
Block(-14,-8,-7,SANDSTONE)
Block(-14,-8,-6,SANDSTONE)
Block(-14,-8,-5,SANDSTONE)
Block(-14,-8,-4,SANDSTONE)
Block(-14,-8,-3,SANDSTONE)
Block(-14,-8,-2,SANDSTONE)
Block(-14,-8,-1,SANDSTONE)
Block(-14,-8,0,SANDSTONE)
Block(-14,-8,5,SANDSTONE)
Block(-14,-8,6,SANDSTONE)
Block(-14,-7,-10,SANDSTONE)
Block(-14,-7,-9,SANDSTONE)
Block(-14,-7,-8,SANDSTONE)
Block(-14,-7,-7,SANDSTONE)
Block(-14,-7,-6,SANDSTONE)
Block(-14,-7,-5,SANDSTONE)
Block(-14,-7,-4,SANDSTONE)
Block(-14,-7,-3,SANDSTONE)
Block(-14,-7,-2,SANDSTONE)
Block(-14,-7,-1,SANDSTONE)
Block(-14,-7,0,SANDSTONE)
Block(-14,-7,1,SANDSTONE)
Block(-14,-7,5,SANDSTONE)
Block(-14,-7,6,SANDSTONE)
Block(-14,-7,7,SANDSTONE)
Block(-14,-6,-11,SANDSTONE)
Block(-14,-6,-10,SANDSTONE)
Block(-14,-6,-9,SANDSTONE)
Block(-14,-6,-8,SANDSTONE)
Block(-14,-6,-7,SANDSTONE)
Block(-14,-6,-6,SANDSTONE)
Block(-14,-6,-5,SANDSTONE)
Block(-14,-6,-4,SANDSTONE)
Block(-14,-6,-3,SANDSTONE)
Block(-14,-6,-2,SANDSTONE)
Block(-14,-6,-1,SANDSTONE)
Block(-14,-6,0,SANDSTONE)
Block(-14,-6,1,SANDSTONE)
Block(-14,-6,2,SANDSTONE)
Block(-14,-6,4,SANDSTONE)
Block(-14,-6,5,SANDSTONE)
Block(-14,-6,6,SANDSTONE)
Block(-14,-6,7,SANDSTONE)
Block(-14,-6,8,SANDSTONE)
Block(-14,-6,9,SANDSTONE)
Block(-14,-6,10,SANDSTONE)
Block(-14,-5,-14,SANDSTONE)
Block(-14,-5,-13,SANDSTONE)
Block(-14,-5,-12,SANDSTONE)
Block(-14,-5,-11,SANDSTONE)
Block(-14,-5,-10,SANDSTONE)
Block(-14,-5,-9,SANDSTONE)
Block(-14,-5,-8,SANDSTONE)
Block(-14,-5,-7,SANDSTONE)
Block(-14,-5,-6,SANDSTONE)
Block(-14,-5,-5,SANDSTONE)
Block(-14,-5,-4,SANDSTONE)
Block(-14,-5,-3,SANDSTONE)
Block(-14,-5,-2,SANDSTONE)
Block(-14,-5,-1,SANDSTONE)
Block(-14,-5,0,SANDSTONE)
Block(-14,-5,1,SANDSTONE)
Block(-14,-5,2,SANDSTONE)
Block(-14,-5,3,SANDSTONE)
Block(-14,-5,4,SANDSTONE)
Block(-14,-5,5,SANDSTONE)
Block(-14,-5,6,SANDSTONE)
Block(-14,-5,7,SANDSTONE)
Block(-14,-5,8,SANDSTONE)
Block(-14,-5,9,SANDSTONE)
Block(-14,-5,10,SANDSTONE)
Block(-14,-4,-14,SANDSTONE)
Block(-14,-4,-13,SANDSTONE)
Block(-14,-4,-12,SANDSTONE)
Block(-14,-4,-11,SANDSTONE)
Block(-14,-4,-10,SANDSTONE)
Block(-14,-4,-9,SANDSTONE)
Block(-14,-4,-8,SANDSTONE)
Block(-14,-4,-7,SANDSTONE)
Block(-14,-4,-6,SANDSTONE)
Block(-14,-4,-5,SANDSTONE)
Block(-14,-4,-4,SANDSTONE)
Block(-14,-4,-3,SANDSTONE)
Block(-14,-4,-2,SANDSTONE)
Block(-14,-4,-1,SANDSTONE)
Block(-14,-4,0,SANDSTONE)
Block(-14,-4,1,SANDSTONE)
Block(-14,-4,2,SANDSTONE)
Block(-14,-4,3,SANDSTONE)
Block(-14,-4,4,SANDSTONE)
Block(-14,-4,5,SANDSTONE)
Block(-14,-4,6,SANDSTONE)
Block(-14,-4,7,SANDSTONE)
Block(-14,-4,8,SANDSTONE)
Block(-14,-4,9,SANDSTONE)
Block(-14,-4,10,SANDSTONE)
Block(-14,-4,11,SANDSTONE)
Block(-14,-3,-14,SANDSTONE)
Block(-14,-3,-13,SANDSTONE)
Block(-14,-3,-12,SANDSTONE)
Block(-14,-3,-11,SANDSTONE)
Block(-14,-3,-10,SANDSTONE)
Block(-14,-3,-9,SANDSTONE)
Block(-14,-3,-8,SANDSTONE)
Block(-14,-3,-7,SANDSTONE)
Block(-14,-3,-6,SANDSTONE)
Block(-14,-3,-5,SANDSTONE)
Block(-14,-3,-4,SANDSTONE)
Block(-14,-3,-3,SANDSTONE)
Block(-14,-3,-2,SANDSTONE)
Block(-14,-3,-1,SANDSTONE)
Block(-14,-3,0,SANDSTONE)
Block(-14,-3,1,SANDSTONE)
Block(-14,-3,2,SANDSTONE)
Block(-14,-3,3,SANDSTONE)
Block(-14,-3,4,SANDSTONE)
Block(-14,-3,5,SANDSTONE)
Block(-14,-3,6,SANDSTONE)
Block(-14,-3,7,SANDSTONE)
Block(-14,-3,8,SANDSTONE)
Block(-14,-3,9,SANDSTONE)
Block(-14,-3,10,SANDSTONE)
Block(-14,-3,11,SANDSTONE)
Block(-14,-3,12,SANDSTONE)
Block(-14,-2,-14,SANDSTONE)
Block(-14,-2,-13,SANDSTONE)
Block(-14,-2,-12,SANDSTONE)
Block(-14,-2,-11,SANDSTONE)
Block(-14,-2,-10,SANDSTONE)
Block(-14,-2,-9,SANDSTONE)
Block(-14,-2,-8,SANDSTONE)
Block(-14,-2,-7,SANDSTONE)
Block(-14,-2,-6,SANDSTONE)
Block(-14,-2,-5,SANDSTONE)
Block(-14,-2,-4,SANDSTONE)
Block(-14,-2,-3,SANDSTONE)
Block(-14,-2,-2,SANDSTONE)
Block(-14,-2,-1,SANDSTONE)
Block(-14,-2,0,SANDSTONE)
Block(-14,-2,1,SANDSTONE)
Block(-14,-2,2,SANDSTONE)
Block(-14,-2,3,SANDSTONE)
Block(-14,-2,4,SANDSTONE)
Block(-14,-2,5,SANDSTONE)
Block(-14,-2,6,SANDSTONE)
Block(-14,-2,7,SANDSTONE)
Block(-14,-2,8,SANDSTONE)
Block(-14,-2,9,SANDSTONE)
Block(-14,-2,10,SANDSTONE)
Block(-14,-2,11,SANDSTONE)
Block(-14,-2,12,SANDSTONE)
Block(-14,-1,-14,SANDSTONE)
Block(-14,-1,-13,SANDSTONE)
Block(-14,-1,-12,SANDSTONE)
Block(-14,-1,-11,SANDSTONE)
Block(-14,-1,-10,SANDSTONE)
Block(-14,-1,-9,SANDSTONE)
Block(-14,-1,-8,SANDSTONE)
Block(-14,-1,-7,SANDSTONE)
Block(-14,-1,-6,SANDSTONE)
Block(-14,-1,-5,SANDSTONE)
Block(-14,-1,-4,SANDSTONE)
Block(-14,-1,-3,SANDSTONE)
Block(-14,-1,-2,SANDSTONE)
Block(-14,-1,-1,SANDSTONE)
Block(-14,-1,0,SANDSTONE)
Block(-14,-1,1,SANDSTONE)
Block(-14,-1,2,SANDSTONE)
Block(-14,-1,3,SANDSTONE)
Block(-14,-1,4,SANDSTONE)
Block(-14,-1,5,SANDSTONE)
Block(-14,-1,6,SANDSTONE)
Block(-14,-1,7,SANDSTONE)
Block(-14,-1,8,SANDSTONE)
Block(-14,-1,9,SANDSTONE)
Block(-14,-1,10,SANDSTONE)
Block(-14,-1,11,SANDSTONE)
Block(-14,0,-14,SANDSTONE)
Block(-14,0,-13,SANDSTONE)
Block(-14,0,-12,SANDSTONE)
Block(-14,0,-11,SANDSTONE)
Block(-14,0,-10,SANDSTONE)
Block(-14,0,-9,SANDSTONE)
Block(-14,0,-8,SANDSTONE)
Block(-14,0,-7,SANDSTONE)
Block(-14,0,-6,SANDSTONE)
Block(-14,0,-5,SANDSTONE)
Block(-14,0,-4,SANDSTONE)
Block(-14,0,-3,SANDSTONE)
Block(-14,0,-2,SANDSTONE)
Block(-14,0,-1,SANDSTONE)
Block(-14,0,0,SANDSTONE)
Block(-14,0,1,SANDSTONE)
Block(-14,0,2,SANDSTONE)
Block(-14,0,3,SANDSTONE)
Block(-14,0,4,SANDSTONE)
Block(-14,0,5,SANDSTONE)
Block(-14,0,6,SANDSTONE)
Block(-14,0,7,SANDSTONE)
Block(-14,0,8,SANDSTONE)
Block(-14,0,9,SANDSTONE)
Block(-14,0,10,SANDSTONE)
Block(-14,1,-11,SANDSTONE)
Block(-14,1,-10,SANDSTONE)
Block(-14,1,-9,SANDSTONE)
Block(-14,1,-8,SANDSTONE)
Block(-14,1,-7,SANDSTONE)
Block(-14,1,-6,SANDSTONE)
Block(-14,1,-5,SANDSTONE)
Block(-14,1,-4,SANDSTONE)
Block(-14,1,-3,SANDSTONE)
Block(-14,1,-2,SANDSTONE)
Block(-14,1,-1,SANDSTONE)
Block(-14,1,0,SANDSTONE)
Block(-14,1,1,SANDSTONE)
Block(-14,1,2,SANDSTONE)
Block(-14,1,4,SANDSTONE)
Block(-14,1,5,SANDSTONE)
Block(-14,1,6,SANDSTONE)
Block(-14,1,7,SANDSTONE)
Block(-14,1,8,SANDSTONE)
Block(-14,1,9,SANDSTONE)
Block(-14,1,10,SANDSTONE)
Block(-14,2,-10,SANDSTONE)
Block(-14,2,-9,SANDSTONE)
Block(-14,2,-8,SANDSTONE)
Block(-14,2,-7,SANDSTONE)
Block(-14,2,-6,SANDSTONE)
Block(-14,2,-5,SANDSTONE)
Block(-14,2,-4,SANDSTONE)
Block(-14,2,-3,SANDSTONE)
Block(-14,2,-2,SANDSTONE)
Block(-14,2,-1,SANDSTONE)
Block(-14,2,0,SANDSTONE)
Block(-14,2,1,SANDSTONE)
Block(-14,2,5,SANDSTONE)
Block(-14,2,6,SANDSTONE)
Block(-14,2,7,SANDSTONE)
Block(-14,3,-10,SANDSTONE)
Block(-14,3,-9,SANDSTONE)
Block(-14,3,-8,SANDSTONE)
Block(-14,3,-7,SANDSTONE)
Block(-14,3,-6,SANDSTONE)
Block(-14,3,-5,SANDSTONE)
Block(-14,3,-4,SANDSTONE)
Block(-14,3,-3,SANDSTONE)
Block(-14,3,-2,SANDSTONE)
Block(-14,3,-1,SANDSTONE)
Block(-14,3,0,SANDSTONE)
Block(-14,3,5,SANDSTONE)
Block(-14,3,6,SANDSTONE)
Block(-14,4,-9,SANDSTONE)
Block(-14,4,-8,SANDSTONE)
Block(-14,4,-7,SANDSTONE)
Block(-14,4,-6,SANDSTONE)
Block(-14,4,-5,SANDSTONE)
Block(-14,4,-4,SANDSTONE)
Block(-14,4,-3,SANDSTONE)
Block(-14,4,-2,SANDSTONE)
Block(-14,4,-1,SANDSTONE)
Block(-14,4,0,SANDSTONE)
Block(-14,5,-8,SANDSTONE)
Block(-14,5,-7,SANDSTONE)
Block(-14,5,-6,SANDSTONE)
Block(-14,5,-5,SANDSTONE)
Block(-14,5,-4,SANDSTONE)
Block(-14,5,-3,SANDSTONE)
Block(-14,5,-2,SANDSTONE)
Block(-14,5,-1,SANDSTONE)
Block(-14,5,0,SANDSTONE)
Block(-14,6,-7,SANDSTONE)
Block(-14,6,-6,SANDSTONE)
Block(-14,6,-5,SANDSTONE)
Block(-14,6,-4,SANDSTONE)
Block(-14,6,-3,SANDSTONE)
Block(-14,6,-2,SANDSTONE)
Block(-14,6,-1,SANDSTONE)
Block(-14,6,0,SANDSTONE)
Block(-14,7,-7,SANDSTONE)
Block(-14,7,-6,SANDSTONE)
Block(-14,7,-5,SANDSTONE)
Block(-14,7,-4,SANDSTONE)
Block(-14,7,-3,SANDSTONE)
Block(-14,7,-2,SANDSTONE)
Block(-14,7,-1,SANDSTONE)
Block(-14,7,0,SANDSTONE)
Block(-14,8,-6,SANDSTONE)
Block(-14,8,-5,SANDSTONE)
Block(-14,8,-4,SANDSTONE)
Block(-14,8,-3,SANDSTONE)
Block(-13,-15,-3,SANDSTONE)
Block(-13,-15,-2,SANDSTONE)
Block(-13,-15,-1,SANDSTONE)
Block(-13,-14,-5,SANDSTONE)
Block(-13,-14,-4,SANDSTONE)
Block(-13,-14,-3,SANDSTONE)
Block(-13,-14,-2,SANDSTONE)
Block(-13,-14,-1,SANDSTONE)
Block(-13,-14,0,SANDSTONE)
Block(-13,-13,-6,SANDSTONE)
Block(-13,-13,-5,SANDSTONE)
Block(-13,-13,-4,SANDSTONE)
Block(-13,-13,-3,SANDSTONE)
Block(-13,-13,-2,SANDSTONE)
Block(-13,-13,-1,SANDSTONE)
Block(-13,-13,0,SANDSTONE)
Block(-13,-13,1,SANDSTONE)
Block(-13,-12,-7,SANDSTONE)
Block(-13,-12,-6,SANDSTONE)
Block(-13,-12,-5,SANDSTONE)
Block(-13,-12,-4,SANDSTONE)
Block(-13,-12,-3,SANDSTONE)
Block(-13,-12,-2,SANDSTONE)
Block(-13,-12,-1,SANDSTONE)
Block(-13,-12,0,SANDSTONE)
Block(-13,-12,1,SANDSTONE)
Block(-13,-12,2,SANDSTONE)
Block(-13,-11,-7,SANDSTONE)
Block(-13,-11,-6,SANDSTONE)
Block(-13,-11,-5,SANDSTONE)
Block(-13,-11,-4,SANDSTONE)
Block(-13,-11,-3,SANDSTONE)
Block(-13,-11,-2,SANDSTONE)
Block(-13,-11,-1,SANDSTONE)
Block(-13,-11,0,SANDSTONE)
Block(-13,-11,1,SANDSTONE)
Block(-13,-11,2,SANDSTONE)
Block(-13,-11,3,SANDSTONE)
Block(-13,-10,-8,SANDSTONE)
Block(-13,-10,-7,SANDSTONE)
Block(-13,-10,-6,SANDSTONE)
Block(-13,-10,-5,SANDSTONE)
Block(-13,-10,-4,SANDSTONE)
Block(-13,-10,-3,SANDSTONE)
Block(-13,-10,-2,SANDSTONE)
Block(-13,-10,-1,SANDSTONE)
Block(-13,-10,0,SANDSTONE)
Block(-13,-10,1,SANDSTONE)
Block(-13,-10,2,SANDSTONE)
Block(-13,-10,3,SANDSTONE)
Block(-13,-10,4,SANDSTONE)
Block(-13,-10,5,SANDSTONE)
Block(-13,-9,-9,SANDSTONE)
Block(-13,-9,-8,SANDSTONE)
Block(-13,-9,-7,SANDSTONE)
Block(-13,-9,-6,SANDSTONE)
Block(-13,-9,-5,SANDSTONE)
Block(-13,-9,-4,SANDSTONE)
Block(-13,-9,-3,SANDSTONE)
Block(-13,-9,-2,SANDSTONE)
Block(-13,-9,-1,SANDSTONE)
Block(-13,-9,0,SANDSTONE)
Block(-13,-9,1,SANDSTONE)
Block(-13,-9,2,SANDSTONE)
Block(-13,-9,3,SANDSTONE)
Block(-13,-9,4,SANDSTONE)
Block(-13,-9,5,SANDSTONE)
Block(-13,-9,6,SANDSTONE)
Block(-13,-9,7,SANDSTONE)
Block(-13,-9,8,SANDSTONE)
Block(-13,-8,-10,SANDSTONE)
Block(-13,-8,-9,SANDSTONE)
Block(-13,-8,-8,SANDSTONE)
Block(-13,-8,-7,SANDSTONE)
Block(-13,-8,-6,SANDSTONE)
Block(-13,-8,-5,SANDSTONE)
Block(-13,-8,-4,SANDSTONE)
Block(-13,-8,-3,SANDSTONE)
Block(-13,-8,-2,SANDSTONE)
Block(-13,-8,-1,SANDSTONE)
Block(-13,-8,0,SANDSTONE)
Block(-13,-8,1,SANDSTONE)
Block(-13,-8,2,SANDSTONE)
Block(-13,-8,3,SANDSTONE)
Block(-13,-8,4,SANDSTONE)
Block(-13,-8,5,SANDSTONE)
Block(-13,-8,6,SANDSTONE)
Block(-13,-8,7,SANDSTONE)
Block(-13,-8,8,SANDSTONE)
Block(-13,-8,9,SANDSTONE)
Block(-13,-7,-10,SANDSTONE)
Block(-13,-7,-9,SANDSTONE)
Block(-13,-7,-8,SANDSTONE)
Block(-13,-7,-7,SANDSTONE)
Block(-13,-7,-6,SANDSTONE)
Block(-13,-7,-5,SANDSTONE)
Block(-13,-7,-4,SANDSTONE)
Block(-13,-7,-3,SANDSTONE)
Block(-13,-7,-2,SANDSTONE)
Block(-13,-7,-1,SANDSTONE)
Block(-13,-7,0,SANDSTONE)
Block(-13,-7,1,SANDSTONE)
Block(-13,-7,2,SANDSTONE)
Block(-13,-7,3,SANDSTONE)
Block(-13,-7,4,SANDSTONE)
Block(-13,-7,5,SANDSTONE)
Block(-13,-7,6,SANDSTONE)
Block(-13,-7,7,SANDSTONE)
Block(-13,-7,8,SANDSTONE)
Block(-13,-7,9,SANDSTONE)
Block(-13,-7,10,SANDSTONE)
Block(-13,-6,-11,SANDSTONE)
Block(-13,-6,-10,SANDSTONE)
Block(-13,-6,-9,SANDSTONE)
Block(-13,-6,-8,SANDSTONE)
Block(-13,-6,-7,SANDSTONE)
Block(-13,-6,-6,SANDSTONE)
Block(-13,-6,-5,SANDSTONE)
Block(-13,-6,-4,SANDSTONE)
Block(-13,-6,-3,SANDSTONE)
Block(-13,-6,-2,SANDSTONE)
Block(-13,-6,-1,SANDSTONE)
Block(-13,-6,0,SANDSTONE)
Block(-13,-6,1,SANDSTONE)
Block(-13,-6,2,SANDSTONE)
Block(-13,-6,3,SANDSTONE)
Block(-13,-6,4,SANDSTONE)
Block(-13,-6,5,SANDSTONE)
Block(-13,-6,6,SANDSTONE)
Block(-13,-6,7,SANDSTONE)
Block(-13,-6,8,SANDSTONE)
Block(-13,-6,9,SANDSTONE)
Block(-13,-6,10,SANDSTONE)
Block(-13,-6,11,SANDSTONE)
Block(-13,-5,-12,SANDSTONE)
Block(-13,-5,-11,SANDSTONE)
Block(-13,-5,-10,SANDSTONE)
Block(-13,-5,-9,SANDSTONE)
Block(-13,-5,-8,SANDSTONE)
Block(-13,-5,-7,SANDSTONE)
Block(-13,-5,-6,SANDSTONE)
Block(-13,-5,-5,SANDSTONE)
Block(-13,-5,-4,SANDSTONE)
Block(-13,-5,-3,SANDSTONE)
Block(-13,-5,-2,SANDSTONE)
Block(-13,-5,-1,SANDSTONE)
Block(-13,-5,0,SANDSTONE)
Block(-13,-5,1,SANDSTONE)
Block(-13,-5,2,SANDSTONE)
Block(-13,-5,3,SANDSTONE)
Block(-13,-5,4,SANDSTONE)
Block(-13,-5,5,SANDSTONE)
Block(-13,-5,6,SANDSTONE)
Block(-13,-5,7,SANDSTONE)
Block(-13,-5,8,SANDSTONE)
Block(-13,-5,9,SANDSTONE)
Block(-13,-5,10,SANDSTONE)
Block(-13,-5,11,SANDSTONE)
Block(-13,-4,-14,SANDSTONE)
Block(-13,-4,-13,SANDSTONE)
Block(-13,-4,-12,SANDSTONE)
Block(-13,-4,-11,SANDSTONE)
Block(-13,-4,-10,SANDSTONE)
Block(-13,-4,-9,SANDSTONE)
Block(-13,-4,-8,SANDSTONE)
Block(-13,-4,-7,SANDSTONE)
Block(-13,-4,-6,SANDSTONE)
Block(-13,-4,-5,SANDSTONE)
Block(-13,-4,-4,SANDSTONE)
Block(-13,-4,-3,SANDSTONE)
Block(-13,-4,-2,SANDSTONE)
Block(-13,-4,-1,SANDSTONE)
Block(-13,-4,0,SANDSTONE)
Block(-13,-4,1,SANDSTONE)
Block(-13,-4,2,SANDSTONE)
Block(-13,-4,3,SANDSTONE)
Block(-13,-4,4,SANDSTONE)
Block(-13,-4,5,SANDSTONE)
Block(-13,-4,6,SANDSTONE)
Block(-13,-4,7,SANDSTONE)
Block(-13,-4,8,SANDSTONE)
Block(-13,-4,9,SANDSTONE)
Block(-13,-4,10,SANDSTONE)
Block(-13,-4,11,SANDSTONE)
Block(-13,-3,-14,SANDSTONE)
Block(-13,-3,-13,SANDSTONE)
Block(-13,-3,-12,SANDSTONE)
Block(-13,-3,-11,SANDSTONE)
Block(-13,-3,-10,SANDSTONE)
Block(-13,-3,-9,SANDSTONE)
Block(-13,-3,-8,SANDSTONE)
Block(-13,-3,-7,SANDSTONE)
Block(-13,-3,-6,SANDSTONE)
Block(-13,-3,-5,SANDSTONE)
Block(-13,-3,-4,SANDSTONE)
Block(-13,-3,-3,SANDSTONE)
Block(-13,-3,-2,SANDSTONE)
Block(-13,-3,-1,SANDSTONE)
Block(-13,-3,0,SANDSTONE)
Block(-13,-3,1,SANDSTONE)
Block(-13,-3,2,SANDSTONE)
Block(-13,-3,3,SANDSTONE)
Block(-13,-3,4,SANDSTONE)
Block(-13,-3,5,SANDSTONE)
Block(-13,-3,6,SANDSTONE)
Block(-13,-3,7,SANDSTONE)
Block(-13,-3,8,SANDSTONE)
Block(-13,-3,9,SANDSTONE)
Block(-13,-3,10,SANDSTONE)
Block(-13,-3,11,SANDSTONE)
Block(-13,-3,12,SANDSTONE)
Block(-13,-2,-14,SANDSTONE)
Block(-13,-2,-13,SANDSTONE)
Block(-13,-2,-12,SANDSTONE)
Block(-13,-2,-11,SANDSTONE)
Block(-13,-2,-10,SANDSTONE)
Block(-13,-2,-9,SANDSTONE)
Block(-13,-2,-8,SANDSTONE)
Block(-13,-2,-7,SANDSTONE)
Block(-13,-2,-6,SANDSTONE)
Block(-13,-2,-5,SANDSTONE)
Block(-13,-2,-4,SANDSTONE)
Block(-13,-2,-3,SANDSTONE)
Block(-13,-2,-2,SANDSTONE)
Block(-13,-2,-1,SANDSTONE)
Block(-13,-2,0,SANDSTONE)
Block(-13,-2,1,SANDSTONE)
Block(-13,-2,2,SANDSTONE)
Block(-13,-2,3,SANDSTONE)
Block(-13,-2,4,SANDSTONE)
Block(-13,-2,5,SANDSTONE)
Block(-13,-2,6,SANDSTONE)
Block(-13,-2,7,SANDSTONE)
Block(-13,-2,8,SANDSTONE)
Block(-13,-2,9,SANDSTONE)
Block(-13,-2,10,SANDSTONE)
Block(-13,-2,11,SANDSTONE)
Block(-13,-2,12,SANDSTONE)
Block(-13,-1,-14,SANDSTONE)
Block(-13,-1,-13,SANDSTONE)
Block(-13,-1,-12,SANDSTONE)
Block(-13,-1,-11,SANDSTONE)
Block(-13,-1,-10,SANDSTONE)
Block(-13,-1,-9,SANDSTONE)
Block(-13,-1,-8,SANDSTONE)
Block(-13,-1,-7,SANDSTONE)
Block(-13,-1,-6,SANDSTONE)
Block(-13,-1,-5,SANDSTONE)
Block(-13,-1,-4,SANDSTONE)
Block(-13,-1,-3,SANDSTONE)
Block(-13,-1,-2,SANDSTONE)
Block(-13,-1,-1,SANDSTONE)
Block(-13,-1,0,SANDSTONE)
Block(-13,-1,1,SANDSTONE)
Block(-13,-1,2,SANDSTONE)
Block(-13,-1,3,SANDSTONE)
Block(-13,-1,4,SANDSTONE)
Block(-13,-1,5,SANDSTONE)
Block(-13,-1,6,SANDSTONE)
Block(-13,-1,7,SANDSTONE)
Block(-13,-1,8,SANDSTONE)
Block(-13,-1,9,SANDSTONE)
Block(-13,-1,10,SANDSTONE)
Block(-13,-1,11,SANDSTONE)
Block(-13,0,-12,SANDSTONE)
Block(-13,0,-11,SANDSTONE)
Block(-13,0,-10,SANDSTONE)
Block(-13,0,-9,SANDSTONE)
Block(-13,0,-8,SANDSTONE)
Block(-13,0,-7,SANDSTONE)
Block(-13,0,-6,SANDSTONE)
Block(-13,0,-5,SANDSTONE)
Block(-13,0,-4,SANDSTONE)
Block(-13,0,-3,SANDSTONE)
Block(-13,0,-2,SANDSTONE)
Block(-13,0,-1,SANDSTONE)
Block(-13,0,0,SANDSTONE)
Block(-13,0,1,SANDSTONE)
Block(-13,0,2,SANDSTONE)
Block(-13,0,3,SANDSTONE)
Block(-13,0,4,SANDSTONE)
Block(-13,0,5,SANDSTONE)
Block(-13,0,6,SANDSTONE)
Block(-13,0,7,SANDSTONE)
Block(-13,0,8,SANDSTONE)
Block(-13,0,9,SANDSTONE)
Block(-13,0,10,SANDSTONE)
Block(-13,0,11,SANDSTONE)
Block(-13,1,-11,SANDSTONE)
Block(-13,1,-10,SANDSTONE)
Block(-13,1,-9,SANDSTONE)
Block(-13,1,-8,SANDSTONE)
Block(-13,1,-7,SANDSTONE)
Block(-13,1,-6,SANDSTONE)
Block(-13,1,-5,SANDSTONE)
Block(-13,1,-4,SANDSTONE)
Block(-13,1,-3,SANDSTONE)
Block(-13,1,-2,SANDSTONE)
Block(-13,1,-1,SANDSTONE)
Block(-13,1,0,SANDSTONE)
Block(-13,1,1,SANDSTONE)
Block(-13,1,2,SANDSTONE)
Block(-13,1,3,SANDSTONE)
Block(-13,1,4,SANDSTONE)
Block(-13,1,5,SANDSTONE)
Block(-13,1,6,SANDSTONE)
Block(-13,1,7,SANDSTONE)
Block(-13,1,8,SANDSTONE)
Block(-13,1,9,SANDSTONE)
Block(-13,1,10,SANDSTONE)
Block(-13,1,11,SANDSTONE)
Block(-13,2,-10,SANDSTONE)
Block(-13,2,-9,SANDSTONE)
Block(-13,2,-8,SANDSTONE)
Block(-13,2,-7,SANDSTONE)
Block(-13,2,-6,SANDSTONE)
Block(-13,2,-5,SANDSTONE)
Block(-13,2,-4,SANDSTONE)
Block(-13,2,-3,SANDSTONE)
Block(-13,2,-2,SANDSTONE)
Block(-13,2,-1,SANDSTONE)
Block(-13,2,0,SANDSTONE)
Block(-13,2,1,SANDSTONE)
Block(-13,2,2,SANDSTONE)
Block(-13,2,3,SANDSTONE)
Block(-13,2,4,SANDSTONE)
Block(-13,2,5,SANDSTONE)
Block(-13,2,6,SANDSTONE)
Block(-13,2,7,SANDSTONE)
Block(-13,2,8,SANDSTONE)
Block(-13,2,9,SANDSTONE)
Block(-13,2,10,SANDSTONE)
Block(-13,3,-10,SANDSTONE)
Block(-13,3,-9,SANDSTONE)
Block(-13,3,-8,SANDSTONE)
Block(-13,3,-7,SANDSTONE)
Block(-13,3,-6,SANDSTONE)
Block(-13,3,-5,SANDSTONE)
Block(-13,3,-4,SANDSTONE)
Block(-13,3,-3,SANDSTONE)
Block(-13,3,-2,SANDSTONE)
Block(-13,3,-1,SANDSTONE)
Block(-13,3,0,SANDSTONE)
Block(-13,3,1,SANDSTONE)
Block(-13,3,2,SANDSTONE)
Block(-13,3,3,SANDSTONE)
Block(-13,3,4,SANDSTONE)
Block(-13,3,5,SANDSTONE)
Block(-13,3,6,SANDSTONE)
Block(-13,3,7,SANDSTONE)
Block(-13,3,8,SANDSTONE)
Block(-13,3,9,SANDSTONE)
Block(-13,4,-9,SANDSTONE)
Block(-13,4,-8,SANDSTONE)
Block(-13,4,-7,SANDSTONE)
Block(-13,4,-6,SANDSTONE)
Block(-13,4,-5,SANDSTONE)
Block(-13,4,-4,SANDSTONE)
Block(-13,4,-3,SANDSTONE)
Block(-13,4,-2,SANDSTONE)
Block(-13,4,-1,SANDSTONE)
Block(-13,4,0,SANDSTONE)
Block(-13,4,1,SANDSTONE)
Block(-13,4,2,SANDSTONE)
Block(-13,4,3,SANDSTONE)
Block(-13,4,4,SANDSTONE)
Block(-13,4,5,SANDSTONE)
Block(-13,4,6,SANDSTONE)
Block(-13,4,7,SANDSTONE)
Block(-13,4,8,SANDSTONE)
Block(-13,5,-8,SANDSTONE)
Block(-13,5,-7,SANDSTONE)
Block(-13,5,-6,SANDSTONE)
Block(-13,5,-5,SANDSTONE)
Block(-13,5,-4,SANDSTONE)
Block(-13,5,-3,SANDSTONE)
Block(-13,5,-2,SANDSTONE)
Block(-13,5,-1,SANDSTONE)
Block(-13,5,0,SANDSTONE)
Block(-13,5,1,SANDSTONE)
Block(-13,5,2,SANDSTONE)
Block(-13,5,3,SANDSTONE)
Block(-13,5,4,SANDSTONE)
Block(-13,5,5,SANDSTONE)
Block(-13,6,-7,SANDSTONE)
Block(-13,6,-6,SANDSTONE)
Block(-13,6,-5,SANDSTONE)
Block(-13,6,-4,SANDSTONE)
Block(-13,6,-3,SANDSTONE)
Block(-13,6,-2,SANDSTONE)
Block(-13,6,-1,SANDSTONE)
Block(-13,6,0,SANDSTONE)
Block(-13,6,1,SANDSTONE)
Block(-13,6,2,SANDSTONE)
Block(-13,6,3,SANDSTONE)
Block(-13,7,-7,SANDSTONE)
Block(-13,7,-6,SANDSTONE)
Block(-13,7,-5,SANDSTONE)
Block(-13,7,-4,SANDSTONE)
Block(-13,7,-3,SANDSTONE)
Block(-13,7,-2,SANDSTONE)
Block(-13,7,-1,SANDSTONE)
Block(-13,7,0,SANDSTONE)
Block(-13,7,1,SANDSTONE)
Block(-13,7,2,SANDSTONE)
Block(-13,8,-6,SANDSTONE)
Block(-13,8,-5,SANDSTONE)
Block(-13,8,-4,SANDSTONE)
Block(-13,8,-3,SANDSTONE)
Block(-13,8,-2,SANDSTONE)
Block(-13,8,-1,SANDSTONE)
Block(-13,8,0,SANDSTONE)
Block(-13,8,1,SANDSTONE)
Block(-13,9,-5,SANDSTONE)
Block(-13,9,-4,SANDSTONE)
Block(-13,9,-3,SANDSTONE)
Block(-13,9,-2,SANDSTONE)
Block(-13,9,-1,SANDSTONE)
Block(-13,9,0,SANDSTONE)
Block(-13,10,-3,SANDSTONE)
Block(-13,10,-2,SANDSTONE)
Block(-13,10,-1,SANDSTONE)
Block(-12,-15,-4,SANDSTONE)
Block(-12,-15,-3,SANDSTONE)
Block(-12,-15,-2,SANDSTONE)
Block(-12,-15,-1,SANDSTONE)
Block(-12,-15,0,SANDSTONE)
Block(-12,-14,-5,SANDSTONE)
Block(-12,-14,-4,SANDSTONE)
Block(-12,-14,-3,SANDSTONE)
Block(-12,-14,-2,SANDSTONE)
Block(-12,-14,-1,SANDSTONE)
Block(-12,-14,0,SANDSTONE)
Block(-12,-14,1,SANDSTONE)
Block(-12,-13,-6,SANDSTONE)
Block(-12,-13,-5,SANDSTONE)
Block(-12,-13,-4,SANDSTONE)
Block(-12,-13,-3,SANDSTONE)
Block(-12,-13,-2,SANDSTONE)
Block(-12,-13,-1,SANDSTONE)
Block(-12,-13,0,SANDSTONE)
Block(-12,-13,1,SANDSTONE)
Block(-12,-13,2,SANDSTONE)
Block(-12,-12,-7,SANDSTONE)
Block(-12,-12,-6,SANDSTONE)
Block(-12,-12,-5,SANDSTONE)
Block(-12,-12,-4,SANDSTONE)
Block(-12,-12,-3,SANDSTONE)
Block(-12,-12,-2,SANDSTONE)
Block(-12,-12,-1,SANDSTONE)
Block(-12,-12,0,SANDSTONE)
Block(-12,-12,1,SANDSTONE)
Block(-12,-12,2,SANDSTONE)
Block(-12,-12,3,SANDSTONE)
Block(-12,-11,-7,SANDSTONE)
Block(-12,-11,-6,SANDSTONE)
Block(-12,-11,-5,SANDSTONE)
Block(-12,-11,-4,SANDSTONE)
Block(-12,-11,-3,SANDSTONE)
Block(-12,-11,-2,SANDSTONE)
Block(-12,-11,-1,SANDSTONE)
Block(-12,-11,0,SANDSTONE)
Block(-12,-11,1,SANDSTONE)
Block(-12,-11,2,SANDSTONE)
Block(-12,-11,3,SANDSTONE)
Block(-12,-11,4,SANDSTONE)
Block(-12,-11,5,SANDSTONE)
Block(-12,-10,-8,SANDSTONE)
Block(-12,-10,-7,SANDSTONE)
Block(-12,-10,-6,SANDSTONE)
Block(-12,-10,-5,SANDSTONE)
Block(-12,-10,-4,SANDSTONE)
Block(-12,-10,-3,SANDSTONE)
Block(-12,-10,-2,SANDSTONE)
Block(-12,-10,-1,SANDSTONE)
Block(-12,-10,0,SANDSTONE)
Block(-12,-10,1,SANDSTONE)
Block(-12,-10,2,SANDSTONE)
Block(-12,-10,3,SANDSTONE)
Block(-12,-10,4,SANDSTONE)
Block(-12,-10,5,SANDSTONE)
Block(-12,-10,6,SANDSTONE)
Block(-12,-10,7,SANDSTONE)
Block(-12,-9,-9,SANDSTONE)
Block(-12,-9,-8,SANDSTONE)
Block(-12,-9,-7,SANDSTONE)
Block(-12,-9,-6,SANDSTONE)
Block(-12,-9,-5,SANDSTONE)
Block(-12,-9,-4,SANDSTONE)
Block(-12,-9,-3,SANDSTONE)
Block(-12,-9,-2,SANDSTONE)
Block(-12,-9,-1,SANDSTONE)
Block(-12,-9,0,SANDSTONE)
Block(-12,-9,1,SANDSTONE)
Block(-12,-9,2,SANDSTONE)
Block(-12,-9,3,SANDSTONE)
Block(-12,-9,4,SANDSTONE)
Block(-12,-9,5,SANDSTONE)
Block(-12,-9,6,SANDSTONE)
Block(-12,-9,7,SANDSTONE)
Block(-12,-9,8,SANDSTONE)
Block(-12,-8,-9,SANDSTONE)
Block(-12,-8,-8,SANDSTONE)
Block(-12,-8,-7,SANDSTONE)
Block(-12,-8,-6,SANDSTONE)
Block(-12,-8,-5,SANDSTONE)
Block(-12,-8,-4,SANDSTONE)
Block(-12,-8,-3,SANDSTONE)
Block(-12,-8,-2,SANDSTONE)
Block(-12,-8,-1,SANDSTONE)
Block(-12,-8,0,SANDSTONE)
Block(-12,-8,1,SANDSTONE)
Block(-12,-8,2,SANDSTONE)
Block(-12,-8,3,SANDSTONE)
Block(-12,-8,4,SANDSTONE)
Block(-12,-8,5,SANDSTONE)
Block(-12,-8,6,SANDSTONE)
Block(-12,-8,7,SANDSTONE)
Block(-12,-8,8,SANDSTONE)
Block(-12,-8,9,SANDSTONE)
Block(-12,-7,-10,SANDSTONE)
Block(-12,-7,-9,SANDSTONE)
Block(-12,-7,-8,SANDSTONE)
Block(-12,-7,-7,SANDSTONE)
Block(-12,-7,-6,SANDSTONE)
Block(-12,-7,-5,SANDSTONE)
Block(-12,-7,-4,SANDSTONE)
Block(-12,-7,-3,SANDSTONE)
Block(-12,-7,-2,SANDSTONE)
Block(-12,-7,-1,SANDSTONE)
Block(-12,-7,0,SANDSTONE)
Block(-12,-7,1,SANDSTONE)
Block(-12,-7,2,SANDSTONE)
Block(-12,-7,3,SANDSTONE)
Block(-12,-7,4,SANDSTONE)
Block(-12,-7,5,SANDSTONE)
Block(-12,-7,6,SANDSTONE)
Block(-12,-7,7,SANDSTONE)
Block(-12,-7,8,SANDSTONE)
Block(-12,-7,9,SANDSTONE)
Block(-12,-7,10,SANDSTONE)
Block(-12,-7,11,SANDSTONE)
Block(-12,-6,-11,SANDSTONE)
Block(-12,-6,-10,SANDSTONE)
Block(-12,-6,-9,SANDSTONE)
Block(-12,-6,-8,SANDSTONE)
Block(-12,-6,-7,SANDSTONE)
Block(-12,-6,-6,SANDSTONE)
Block(-12,-6,-5,SANDSTONE)
Block(-12,-6,-4,SANDSTONE)
Block(-12,-6,-3,SANDSTONE)
Block(-12,-6,-2,SANDSTONE)
Block(-12,-6,-1,SANDSTONE)
Block(-12,-6,0,SANDSTONE)
Block(-12,-6,1,SANDSTONE)
Block(-12,-6,2,SANDSTONE)
Block(-12,-6,3,SANDSTONE)
Block(-12,-6,4,SANDSTONE)
Block(-12,-6,5,SANDSTONE)
Block(-12,-6,6,SANDSTONE)
Block(-12,-6,7,SANDSTONE)
Block(-12,-6,8,SANDSTONE)
Block(-12,-6,9,SANDSTONE)
Block(-12,-6,10,SANDSTONE)
Block(-12,-6,11,SANDSTONE)
Block(-12,-5,-12,SANDSTONE)
Block(-12,-5,-11,SANDSTONE)
Block(-12,-5,-10,SANDSTONE)
Block(-12,-5,-9,SANDSTONE)
Block(-12,-5,-8,SANDSTONE)
Block(-12,-5,-7,SANDSTONE)
Block(-12,-5,-6,SANDSTONE)
Block(-12,-5,-5,SANDSTONE)
Block(-12,-5,-4,SANDSTONE)
Block(-12,-5,-3,SANDSTONE)
Block(-12,-5,-2,SANDSTONE)
Block(-12,-5,-1,SANDSTONE)
Block(-12,-5,0,SANDSTONE)
Block(-12,-5,1,SANDSTONE)
Block(-12,-5,2,SANDSTONE)
Block(-12,-5,3,SANDSTONE)
Block(-12,-5,4,SANDSTONE)
Block(-12,-5,5,SANDSTONE)
Block(-12,-5,6,SANDSTONE)
Block(-12,-5,7,SANDSTONE)
Block(-12,-5,8,SANDSTONE)
Block(-12,-5,9,SANDSTONE)
Block(-12,-5,10,SANDSTONE)
Block(-12,-5,11,SANDSTONE)
Block(-12,-4,-13,SANDSTONE)
Block(-12,-4,-12,SANDSTONE)
Block(-12,-4,-11,SANDSTONE)
Block(-12,-4,-10,SANDSTONE)
Block(-12,-4,-9,SANDSTONE)
Block(-12,-4,-8,SANDSTONE)
Block(-12,-4,-7,SANDSTONE)
Block(-12,-4,-6,SANDSTONE)
Block(-12,-4,-5,SANDSTONE)
Block(-12,-4,-4,SANDSTONE)
Block(-12,-4,-3,SANDSTONE)
Block(-12,-4,-2,SANDSTONE)
Block(-12,-4,-1,SANDSTONE)
Block(-12,-4,0,SANDSTONE)
Block(-12,-4,1,SANDSTONE)
Block(-12,-4,2,SANDSTONE)
Block(-12,-4,3,SANDSTONE)
Block(-12,-4,4,SANDSTONE)
Block(-12,-4,5,SANDSTONE)
Block(-12,-4,6,SANDSTONE)
Block(-12,-4,7,SANDSTONE)
Block(-12,-4,8,SANDSTONE)
Block(-12,-4,9,SANDSTONE)
Block(-12,-4,10,SANDSTONE)
Block(-12,-4,11,SANDSTONE)
Block(-12,-3,-13,SANDSTONE)
Block(-12,-3,-12,SANDSTONE)
Block(-12,-3,-11,SANDSTONE)
Block(-12,-3,-10,SANDSTONE)
Block(-12,-3,-9,SANDSTONE)
Block(-12,-3,-8,SANDSTONE)
Block(-12,-3,-7,SANDSTONE)
Block(-12,-3,-6,SANDSTONE)
Block(-12,-3,-5,SANDSTONE)
Block(-12,-3,-4,SANDSTONE)
Block(-12,-3,-3,SANDSTONE)
Block(-12,-3,-2,SANDSTONE)
Block(-12,-3,-1,SANDSTONE)
Block(-12,-3,0,SANDSTONE)
Block(-12,-3,1,SANDSTONE)
Block(-12,-3,2,SANDSTONE)
Block(-12,-3,3,SANDSTONE)
Block(-12,-3,4,SANDSTONE)
Block(-12,-3,5,SANDSTONE)
Block(-12,-3,6,SANDSTONE)
Block(-12,-3,7,SANDSTONE)
Block(-12,-3,8,SANDSTONE)
Block(-12,-3,9,SANDSTONE)
Block(-12,-3,10,SANDSTONE)
Block(-12,-3,11,SANDSTONE)
Block(-12,-3,12,SANDSTONE)
Block(-12,-2,-13,SANDSTONE)
Block(-12,-2,-12,SANDSTONE)
Block(-12,-2,-11,SANDSTONE)
Block(-12,-2,-10,SANDSTONE)
Block(-12,-2,-9,SANDSTONE)
Block(-12,-2,-8,SANDSTONE)
Block(-12,-2,-7,SANDSTONE)
Block(-12,-2,-6,SANDSTONE)
Block(-12,-2,-5,SANDSTONE)
Block(-12,-2,-4,SANDSTONE)
Block(-12,-2,-3,SANDSTONE)
Block(-12,-2,-2,SANDSTONE)
Block(-12,-2,-1,SANDSTONE)
Block(-12,-2,0,SANDSTONE)
Block(-12,-2,1,SANDSTONE)
Block(-12,-2,2,SANDSTONE)
Block(-12,-2,3,SANDSTONE)
Block(-12,-2,4,SANDSTONE)
Block(-12,-2,5,SANDSTONE)
Block(-12,-2,6,SANDSTONE)
Block(-12,-2,7,SANDSTONE)
Block(-12,-2,8,SANDSTONE)
Block(-12,-2,9,SANDSTONE)
Block(-12,-2,10,SANDSTONE)
Block(-12,-2,11,SANDSTONE)
Block(-12,-2,12,SANDSTONE)
Block(-12,-1,-13,SANDSTONE)
Block(-12,-1,-12,SANDSTONE)
Block(-12,-1,-11,SANDSTONE)
Block(-12,-1,-10,SANDSTONE)
Block(-12,-1,-9,SANDSTONE)
Block(-12,-1,-8,SANDSTONE)
Block(-12,-1,-7,SANDSTONE)
Block(-12,-1,-6,SANDSTONE)
Block(-12,-1,-5,SANDSTONE)
Block(-12,-1,-4,SANDSTONE)
Block(-12,-1,-3,SANDSTONE)
Block(-12,-1,-2,SANDSTONE)
Block(-12,-1,-1,SANDSTONE)
Block(-12,-1,0,SANDSTONE)
Block(-12,-1,1,SANDSTONE)
Block(-12,-1,2,SANDSTONE)
Block(-12,-1,3,SANDSTONE)
Block(-12,-1,4,SANDSTONE)
Block(-12,-1,5,SANDSTONE)
Block(-12,-1,6,SANDSTONE)
Block(-12,-1,7,SANDSTONE)
Block(-12,-1,8,SANDSTONE)
Block(-12,-1,9,SANDSTONE)
Block(-12,-1,10,SANDSTONE)
Block(-12,-1,11,SANDSTONE)
Block(-12,0,-12,SANDSTONE)
Block(-12,0,-11,SANDSTONE)
Block(-12,0,-10,SANDSTONE)
Block(-12,0,-9,SANDSTONE)
Block(-12,0,-8,SANDSTONE)
Block(-12,0,-7,SANDSTONE)
Block(-12,0,-6,SANDSTONE)
Block(-12,0,-5,SANDSTONE)
Block(-12,0,-4,SANDSTONE)
Block(-12,0,-3,SANDSTONE)
Block(-12,0,-2,SANDSTONE)
Block(-12,0,-1,SANDSTONE)
Block(-12,0,0,SANDSTONE)
Block(-12,0,1,SANDSTONE)
Block(-12,0,2,SANDSTONE)
Block(-12,0,3,SANDSTONE)
Block(-12,0,4,SANDSTONE)
Block(-12,0,5,SANDSTONE)
Block(-12,0,6,SANDSTONE)
Block(-12,0,7,SANDSTONE)
Block(-12,0,8,SANDSTONE)
Block(-12,0,9,SANDSTONE)
Block(-12,0,10,SANDSTONE)
Block(-12,0,11,SANDSTONE)
Block(-12,1,-11,SANDSTONE)
Block(-12,1,-10,SANDSTONE)
Block(-12,1,-9,SANDSTONE)
Block(-12,1,-8,SANDSTONE)
Block(-12,1,-7,SANDSTONE)
Block(-12,1,-6,SANDSTONE)
Block(-12,1,-5,SANDSTONE)
Block(-12,1,-4,SANDSTONE)
Block(-12,1,-3,SANDSTONE)
Block(-12,1,-2,SANDSTONE)
Block(-12,1,-1,SANDSTONE)
Block(-12,1,0,SANDSTONE)
Block(-12,1,1,SANDSTONE)
Block(-12,1,2,SANDSTONE)
Block(-12,1,3,SANDSTONE)
Block(-12,1,4,SANDSTONE)
Block(-12,1,5,SANDSTONE)
Block(-12,1,6,SANDSTONE)
Block(-12,1,7,SANDSTONE)
Block(-12,1,8,SANDSTONE)
Block(-12,1,9,SANDSTONE)
Block(-12,1,10,SANDSTONE)
Block(-12,1,11,SANDSTONE)
Block(-12,2,-10,SANDSTONE)
Block(-12,2,-9,SANDSTONE)
Block(-12,2,-8,SANDSTONE)
Block(-12,2,-7,SANDSTONE)
Block(-12,2,-6,SANDSTONE)
Block(-12,2,-5,SANDSTONE)
Block(-12,2,-4,SANDSTONE)
Block(-12,2,-3,SANDSTONE)
Block(-12,2,-2,SANDSTONE)
Block(-12,2,-1,SANDSTONE)
Block(-12,2,0,SANDSTONE)
Block(-12,2,1,SANDSTONE)
Block(-12,2,2,SANDSTONE)
Block(-12,2,3,SANDSTONE)
Block(-12,2,4,SANDSTONE)
Block(-12,2,5,SANDSTONE)
Block(-12,2,6,SANDSTONE)
Block(-12,2,7,SANDSTONE)
Block(-12,2,8,SANDSTONE)
Block(-12,2,9,SANDSTONE)
Block(-12,2,10,SANDSTONE)
Block(-12,2,11,SANDSTONE)
Block(-12,3,-9,SANDSTONE)
Block(-12,3,-8,SANDSTONE)
Block(-12,3,-7,SANDSTONE)
Block(-12,3,-6,SANDSTONE)
Block(-12,3,-5,SANDSTONE)
Block(-12,3,-4,SANDSTONE)
Block(-12,3,-3,SANDSTONE)
Block(-12,3,-2,SANDSTONE)
Block(-12,3,-1,SANDSTONE)
Block(-12,3,0,SANDSTONE)
Block(-12,3,1,SANDSTONE)
Block(-12,3,2,SANDSTONE)
Block(-12,3,3,SANDSTONE)
Block(-12,3,4,SANDSTONE)
Block(-12,3,5,SANDSTONE)
Block(-12,3,6,SANDSTONE)
Block(-12,3,7,SANDSTONE)
Block(-12,3,8,SANDSTONE)
Block(-12,3,9,SANDSTONE)
Block(-12,4,-9,SANDSTONE)
Block(-12,4,-8,SANDSTONE)
Block(-12,4,-7,SANDSTONE)
Block(-12,4,-6,SANDSTONE)
Block(-12,4,-5,SANDSTONE)
Block(-12,4,-4,SANDSTONE)
Block(-12,4,-3,SANDSTONE)
Block(-12,4,-2,SANDSTONE)
Block(-12,4,-1,SANDSTONE)
Block(-12,4,0,SANDSTONE)
Block(-12,4,1,SANDSTONE)
Block(-12,4,2,SANDSTONE)
Block(-12,4,3,SANDSTONE)
Block(-12,4,4,SANDSTONE)
Block(-12,4,5,SANDSTONE)
Block(-12,4,6,SANDSTONE)
Block(-12,4,7,SANDSTONE)
Block(-12,4,8,SANDSTONE)
Block(-12,5,-8,SANDSTONE)
Block(-12,5,-7,SANDSTONE)
Block(-12,5,-6,SANDSTONE)
Block(-12,5,-5,SANDSTONE)
Block(-12,5,-4,SANDSTONE)
Block(-12,5,-3,SANDSTONE)
Block(-12,5,-2,SANDSTONE)
Block(-12,5,-1,SANDSTONE)
Block(-12,5,0,SANDSTONE)
Block(-12,5,1,SANDSTONE)
Block(-12,5,2,SANDSTONE)
Block(-12,5,3,SANDSTONE)
Block(-12,5,4,SANDSTONE)
Block(-12,5,5,SANDSTONE)
Block(-12,5,6,SANDSTONE)
Block(-12,5,7,SANDSTONE)
Block(-12,6,-7,SANDSTONE)
Block(-12,6,-6,SANDSTONE)
Block(-12,6,-5,SANDSTONE)
Block(-12,6,-4,SANDSTONE)
Block(-12,6,-3,SANDSTONE)
Block(-12,6,-2,SANDSTONE)
Block(-12,6,-1,SANDSTONE)
Block(-12,6,0,SANDSTONE)
Block(-12,6,1,SANDSTONE)
Block(-12,6,2,SANDSTONE)
Block(-12,6,3,SANDSTONE)
Block(-12,6,4,SANDSTONE)
Block(-12,6,5,SANDSTONE)
Block(-12,7,-7,SANDSTONE)
Block(-12,7,-6,SANDSTONE)
Block(-12,7,-5,SANDSTONE)
Block(-12,7,-4,SANDSTONE)
Block(-12,7,-3,SANDSTONE)
Block(-12,7,-2,SANDSTONE)
Block(-12,7,-1,SANDSTONE)
Block(-12,7,0,SANDSTONE)
Block(-12,7,1,SANDSTONE)
Block(-12,7,2,SANDSTONE)
Block(-12,7,3,SANDSTONE)
Block(-12,8,-6,SANDSTONE)
Block(-12,8,-5,SANDSTONE)
Block(-12,8,-4,SANDSTONE)
Block(-12,8,-3,SANDSTONE)
Block(-12,8,-2,SANDSTONE)
Block(-12,8,-1,SANDSTONE)
Block(-12,8,0,SANDSTONE)
Block(-12,8,1,SANDSTONE)
Block(-12,8,2,SANDSTONE)
Block(-12,9,-5,SANDSTONE)
Block(-12,9,-4,SANDSTONE)
Block(-12,9,-3,SANDSTONE)
Block(-12,9,-2,SANDSTONE)
Block(-12,9,-1,SANDSTONE)
Block(-12,9,0,SANDSTONE)
Block(-12,9,1,SANDSTONE)
Block(-12,10,-4,SANDSTONE)
Block(-12,10,-3,SANDSTONE)
Block(-12,10,-2,SANDSTONE)
Block(-12,10,-1,SANDSTONE)
Block(-12,10,0,SANDSTONE)
Block(-11,-15,-4,SANDSTONE)
Block(-11,-15,-3,SANDSTONE)
Block(-11,-15,-2,SANDSTONE)
Block(-11,-15,-1,SANDSTONE)
Block(-11,-15,0,SANDSTONE)
Block(-11,-14,-5,SANDSTONE)
Block(-11,-14,-4,SANDSTONE)
Block(-11,-14,-3,SANDSTONE)
Block(-11,-14,-2,SANDSTONE)
Block(-11,-14,-1,SANDSTONE)
Block(-11,-14,0,SANDSTONE)
Block(-11,-14,1,SANDSTONE)
Block(-11,-14,2,SANDSTONE)
Block(-11,-13,-6,SANDSTONE)
Block(-11,-13,-5,SANDSTONE)
Block(-11,-13,-4,SANDSTONE)
Block(-11,-13,-3,SANDSTONE)
Block(-11,-13,-2,SANDSTONE)
Block(-11,-13,-1,SANDSTONE)
Block(-11,-13,0,SANDSTONE)
Block(-11,-13,1,SANDSTONE)
Block(-11,-13,2,SANDSTONE)
Block(-11,-13,3,SANDSTONE)
Block(-11,-12,-7,SANDSTONE)
Block(-11,-12,-6,SANDSTONE)
Block(-11,-12,-5,SANDSTONE)
Block(-11,-12,-4,SANDSTONE)
Block(-11,-12,-3,SANDSTONE)
Block(-11,-12,-2,SANDSTONE)
Block(-11,-12,-1,SANDSTONE)
Block(-11,-12,0,SANDSTONE)
Block(-11,-12,1,SANDSTONE)
Block(-11,-12,2,SANDSTONE)
Block(-11,-12,3,SANDSTONE)
Block(-11,-12,4,SANDSTONE)
Block(-11,-12,5,SANDSTONE)
Block(-11,-12,6,SANDSTONE)
Block(-11,-11,-7,SANDSTONE)
Block(-11,-11,-6,SANDSTONE)
Block(-11,-11,-5,SANDSTONE)
Block(-11,-11,-4,SANDSTONE)
Block(-11,-11,-3,SANDSTONE)
Block(-11,-11,-2,SANDSTONE)
Block(-11,-11,-1,SANDSTONE)
Block(-11,-11,0,SANDSTONE)
Block(-11,-11,1,SANDSTONE)
Block(-11,-11,2,SANDSTONE)
Block(-11,-11,3,SANDSTONE)
Block(-11,-11,4,SANDSTONE)
Block(-11,-11,5,SANDSTONE)
Block(-11,-11,6,SANDSTONE)
Block(-11,-11,7,SANDSTONE)
Block(-11,-10,-8,SANDSTONE)
Block(-11,-10,-7,SANDSTONE)
Block(-11,-10,-6,SANDSTONE)
Block(-11,-10,-5,SANDSTONE)
Block(-11,-10,-4,SANDSTONE)
Block(-11,-10,-3,SANDSTONE)
Block(-11,-10,-2,SANDSTONE)
Block(-11,-10,-1,SANDSTONE)
Block(-11,-10,0,SANDSTONE)
Block(-11,-10,1,SANDSTONE)
Block(-11,-10,2,SANDSTONE)
Block(-11,-10,3,SANDSTONE)
Block(-11,-10,4,SANDSTONE)
Block(-11,-10,5,SANDSTONE)
Block(-11,-10,6,SANDSTONE)
Block(-11,-10,7,SANDSTONE)
Block(-11,-10,8,SANDSTONE)
Block(-11,-9,-8,SANDSTONE)
Block(-11,-9,-7,SANDSTONE)
Block(-11,-9,-6,SANDSTONE)
Block(-11,-9,-5,SANDSTONE)
Block(-11,-9,-4,SANDSTONE)
Block(-11,-9,-3,SANDSTONE)
Block(-11,-9,-2,SANDSTONE)
Block(-11,-9,-1,SANDSTONE)
Block(-11,-9,0,SANDSTONE)
Block(-11,-9,1,SANDSTONE)
Block(-11,-9,2,SANDSTONE)
Block(-11,-9,3,SANDSTONE)
Block(-11,-9,4,SANDSTONE)
Block(-11,-9,5,SANDSTONE)
Block(-11,-9,6,SANDSTONE)
Block(-11,-9,7,SANDSTONE)
Block(-11,-9,8,SANDSTONE)
Block(-11,-9,9,SANDSTONE)
Block(-11,-8,-9,SANDSTONE)
Block(-11,-8,-8,SANDSTONE)
Block(-11,-8,-7,SANDSTONE)
Block(-11,-8,-6,SANDSTONE)
Block(-11,-8,-5,SANDSTONE)
Block(-11,-8,-4,SANDSTONE)
Block(-11,-8,-3,SANDSTONE)
Block(-11,-8,-2,SANDSTONE)
Block(-11,-8,-1,SANDSTONE)
Block(-11,-8,0,SANDSTONE)
Block(-11,-8,1,SANDSTONE)
Block(-11,-8,2,SANDSTONE)
Block(-11,-8,3,SANDSTONE)
Block(-11,-8,4,SANDSTONE)
Block(-11,-8,5,SANDSTONE)
Block(-11,-8,6,SANDSTONE)
Block(-11,-8,7,SANDSTONE)
Block(-11,-8,8,SANDSTONE)
Block(-11,-8,9,SANDSTONE)
Block(-11,-8,10,SANDSTONE)
Block(-11,-7,-10,SANDSTONE)
Block(-11,-7,-9,SANDSTONE)
Block(-11,-7,-8,SANDSTONE)
Block(-11,-7,-7,SANDSTONE)
Block(-11,-7,-6,SANDSTONE)
Block(-11,-7,-5,SANDSTONE)
Block(-11,-7,-4,SANDSTONE)
Block(-11,-7,-3,SANDSTONE)
Block(-11,-7,-2,SANDSTONE)
Block(-11,-7,-1,SANDSTONE)
Block(-11,-7,0,SANDSTONE)
Block(-11,-7,1,SANDSTONE)
Block(-11,-7,2,SANDSTONE)
Block(-11,-7,3,SANDSTONE)
Block(-11,-7,4,SANDSTONE)
Block(-11,-7,5,SANDSTONE)
Block(-11,-7,6,SANDSTONE)
Block(-11,-7,7,SANDSTONE)
Block(-11,-7,8,SANDSTONE)
Block(-11,-7,9,SANDSTONE)
Block(-11,-7,10,SANDSTONE)
Block(-11,-7,11,SANDSTONE)
Block(-11,-6,-10,SANDSTONE)
Block(-11,-6,-9,SANDSTONE)
Block(-11,-6,-8,SANDSTONE)
Block(-11,-6,-7,SANDSTONE)
Block(-11,-6,-6,SANDSTONE)
Block(-11,-6,-5,SANDSTONE)
Block(-11,-6,-4,SANDSTONE)
Block(-11,-6,-3,SANDSTONE)
Block(-11,-6,-2,SANDSTONE)
Block(-11,-6,-1,SANDSTONE)
Block(-11,-6,0,SANDSTONE)
Block(-11,-6,1,SANDSTONE)
Block(-11,-6,2,SANDSTONE)
Block(-11,-6,3,SANDSTONE)
Block(-11,-6,4,SANDSTONE)
Block(-11,-6,5,SANDSTONE)
Block(-11,-6,6,SANDSTONE)
Block(-11,-6,7,SANDSTONE)
Block(-11,-6,8,SANDSTONE)
Block(-11,-6,9,SANDSTONE)
Block(-11,-6,10,SANDSTONE)
Block(-11,-6,11,SANDSTONE)
Block(-11,-5,-11,SANDSTONE)
Block(-11,-5,-10,SANDSTONE)
Block(-11,-5,-9,SANDSTONE)
Block(-11,-5,-8,SANDSTONE)
Block(-11,-5,-7,SANDSTONE)
Block(-11,-5,-6,SANDSTONE)
Block(-11,-5,-5,SANDSTONE)
Block(-11,-5,-4,SANDSTONE)
Block(-11,-5,-3,SANDSTONE)
Block(-11,-5,-2,SANDSTONE)
Block(-11,-5,-1,SANDSTONE)
Block(-11,-5,0,SANDSTONE)
Block(-11,-5,1,SANDSTONE)
Block(-11,-5,2,SANDSTONE)
Block(-11,-5,3,SANDSTONE)
Block(-11,-5,4,SANDSTONE)
Block(-11,-5,5,SANDSTONE)
Block(-11,-5,6,SANDSTONE)
Block(-11,-5,7,SANDSTONE)
Block(-11,-5,8,SANDSTONE)
Block(-11,-5,9,SANDSTONE)
Block(-11,-5,10,SANDSTONE)
Block(-11,-5,11,SANDSTONE)
Block(-11,-4,-12,SANDSTONE)
Block(-11,-4,-11,SANDSTONE)
Block(-11,-4,-10,SANDSTONE)
Block(-11,-4,-9,SANDSTONE)
Block(-11,-4,-8,SANDSTONE)
Block(-11,-4,-7,SANDSTONE)
Block(-11,-4,-6,SANDSTONE)
Block(-11,-4,-5,SANDSTONE)
Block(-11,-4,-4,SANDSTONE)
Block(-11,-4,-3,SANDSTONE)
Block(-11,-4,-2,SANDSTONE)
Block(-11,-4,-1,SANDSTONE)
Block(-11,-4,0,SANDSTONE)
Block(-11,-4,1,SANDSTONE)
Block(-11,-4,2,SANDSTONE)
Block(-11,-4,3,SANDSTONE)
Block(-11,-4,4,SANDSTONE)
Block(-11,-4,5,SANDSTONE)
Block(-11,-4,6,SANDSTONE)
Block(-11,-4,7,SANDSTONE)
Block(-11,-4,8,SANDSTONE)
Block(-11,-4,9,SANDSTONE)
Block(-11,-4,10,SANDSTONE)
Block(-11,-4,11,SANDSTONE)
Block(-11,-4,12,SANDSTONE)
Block(-11,-3,-12,SANDSTONE)
Block(-11,-3,-11,SANDSTONE)
Block(-11,-3,-10,SANDSTONE)
Block(-11,-3,-9,SANDSTONE)
Block(-11,-3,-8,SANDSTONE)
Block(-11,-3,-7,SANDSTONE)
Block(-11,-3,-6,SANDSTONE)
Block(-11,-3,-5,SANDSTONE)
Block(-11,-3,-4,SANDSTONE)
Block(-11,-3,-3,SANDSTONE)
Block(-11,-3,-2,SANDSTONE)
Block(-11,-3,-1,SANDSTONE)
Block(-11,-3,0,SANDSTONE)
Block(-11,-3,1,SANDSTONE)
Block(-11,-3,2,SANDSTONE)
Block(-11,-3,3,SANDSTONE)
Block(-11,-3,4,SANDSTONE)
Block(-11,-3,5,SANDSTONE)
Block(-11,-3,6,SANDSTONE)
Block(-11,-3,7,SANDSTONE)
Block(-11,-3,8,SANDSTONE)
Block(-11,-3,9,SANDSTONE)
Block(-11,-3,10,SANDSTONE)
Block(-11,-3,11,SANDSTONE)
Block(-11,-3,12,SANDSTONE)
Block(-11,-2,-12,SANDSTONE)
Block(-11,-2,-11,SANDSTONE)
Block(-11,-2,-10,SANDSTONE)
Block(-11,-2,-9,SANDSTONE)
Block(-11,-2,-8,SANDSTONE)
Block(-11,-2,-7,SANDSTONE)
Block(-11,-2,-6,SANDSTONE)
Block(-11,-2,-5,SANDSTONE)
Block(-11,-2,-4,SANDSTONE)
Block(-11,-2,-3,SANDSTONE)
Block(-11,-2,-2,SANDSTONE)
Block(-11,-2,-1,SANDSTONE)
Block(-11,-2,0,SANDSTONE)
Block(-11,-2,1,SANDSTONE)
Block(-11,-2,2,SANDSTONE)
Block(-11,-2,3,SANDSTONE)
Block(-11,-2,4,SANDSTONE)
Block(-11,-2,5,SANDSTONE)
Block(-11,-2,6,SANDSTONE)
Block(-11,-2,7,SANDSTONE)
Block(-11,-2,8,SANDSTONE)
Block(-11,-2,9,SANDSTONE)
Block(-11,-2,10,SANDSTONE)
Block(-11,-2,11,SANDSTONE)
Block(-11,-2,12,SANDSTONE)
Block(-11,-1,-12,SANDSTONE)
Block(-11,-1,-11,SANDSTONE)
Block(-11,-1,-10,SANDSTONE)
Block(-11,-1,-9,SANDSTONE)
Block(-11,-1,-8,SANDSTONE)
Block(-11,-1,-7,SANDSTONE)
Block(-11,-1,-6,SANDSTONE)
Block(-11,-1,-5,SANDSTONE)
Block(-11,-1,-4,SANDSTONE)
Block(-11,-1,-3,SANDSTONE)
Block(-11,-1,-2,SANDSTONE)
Block(-11,-1,-1,SANDSTONE)
Block(-11,-1,0,SANDSTONE)
Block(-11,-1,1,SANDSTONE)
Block(-11,-1,2,SANDSTONE)
Block(-11,-1,3,SANDSTONE)
Block(-11,-1,4,SANDSTONE)
Block(-11,-1,5,SANDSTONE)
Block(-11,-1,6,SANDSTONE)
Block(-11,-1,7,SANDSTONE)
Block(-11,-1,8,SANDSTONE)
Block(-11,-1,9,SANDSTONE)
Block(-11,-1,10,SANDSTONE)
Block(-11,-1,11,SANDSTONE)
Block(-11,-1,12,SANDSTONE)
Block(-11,0,-11,SANDSTONE)
Block(-11,0,-10,SANDSTONE)
Block(-11,0,-9,SANDSTONE)
Block(-11,0,-8,SANDSTONE)
Block(-11,0,-7,SANDSTONE)
Block(-11,0,-6,SANDSTONE)
Block(-11,0,-5,SANDSTONE)
Block(-11,0,-4,SANDSTONE)
Block(-11,0,-3,SANDSTONE)
Block(-11,0,-2,SANDSTONE)
Block(-11,0,-1,SANDSTONE)
Block(-11,0,0,SANDSTONE)
Block(-11,0,1,SANDSTONE)
Block(-11,0,2,SANDSTONE)
Block(-11,0,3,SANDSTONE)
Block(-11,0,4,SANDSTONE)
Block(-11,0,5,SANDSTONE)
Block(-11,0,6,SANDSTONE)
Block(-11,0,7,SANDSTONE)
Block(-11,0,8,SANDSTONE)
Block(-11,0,9,SANDSTONE)
Block(-11,0,10,SANDSTONE)
Block(-11,0,11,SANDSTONE)
Block(-11,1,-10,SANDSTONE)
Block(-11,1,-9,SANDSTONE)
Block(-11,1,-8,SANDSTONE)
Block(-11,1,-7,SANDSTONE)
Block(-11,1,-6,SANDSTONE)
Block(-11,1,-5,SANDSTONE)
Block(-11,1,-4,SANDSTONE)
Block(-11,1,-3,SANDSTONE)
Block(-11,1,-2,SANDSTONE)
Block(-11,1,-1,SANDSTONE)
Block(-11,1,0,SANDSTONE)
Block(-11,1,1,SANDSTONE)
Block(-11,1,2,SANDSTONE)
Block(-11,1,3,SANDSTONE)
Block(-11,1,4,SANDSTONE)
Block(-11,1,5,SANDSTONE)
Block(-11,1,6,SANDSTONE)
Block(-11,1,7,SANDSTONE)
Block(-11,1,8,SANDSTONE)
Block(-11,1,9,SANDSTONE)
Block(-11,1,10,SANDSTONE)
Block(-11,1,11,SANDSTONE)
Block(-11,2,-10,SANDSTONE)
Block(-11,2,-9,SANDSTONE)
Block(-11,2,-8,SANDSTONE)
Block(-11,2,-7,SANDSTONE)
Block(-11,2,-6,SANDSTONE)
Block(-11,2,-5,SANDSTONE)
Block(-11,2,-4,SANDSTONE)
Block(-11,2,-3,SANDSTONE)
Block(-11,2,-2,SANDSTONE)
Block(-11,2,-1,SANDSTONE)
Block(-11,2,0,SANDSTONE)
Block(-11,2,1,SANDSTONE)
Block(-11,2,2,SANDSTONE)
Block(-11,2,3,SANDSTONE)
Block(-11,2,4,SANDSTONE)
Block(-11,2,5,SANDSTONE)
Block(-11,2,6,SANDSTONE)
Block(-11,2,7,SANDSTONE)
Block(-11,2,8,SANDSTONE)
Block(-11,2,9,SANDSTONE)
Block(-11,2,10,SANDSTONE)
Block(-11,2,11,SANDSTONE)
Block(-11,3,-9,SANDSTONE)
Block(-11,3,-8,SANDSTONE)
Block(-11,3,-7,SANDSTONE)
Block(-11,3,-6,SANDSTONE)
Block(-11,3,-5,SANDSTONE)
Block(-11,3,-4,SANDSTONE)
Block(-11,3,-3,SANDSTONE)
Block(-11,3,-2,SANDSTONE)
Block(-11,3,-1,SANDSTONE)
Block(-11,3,0,SANDSTONE)
Block(-11,3,1,SANDSTONE)
Block(-11,3,2,SANDSTONE)
Block(-11,3,3,SANDSTONE)
Block(-11,3,4,SANDSTONE)
Block(-11,3,5,SANDSTONE)
Block(-11,3,6,SANDSTONE)
Block(-11,3,7,SANDSTONE)
Block(-11,3,8,SANDSTONE)
Block(-11,3,9,SANDSTONE)
Block(-11,3,10,SANDSTONE)
Block(-11,4,-8,SANDSTONE)
Block(-11,4,-7,SANDSTONE)
Block(-11,4,-6,SANDSTONE)
Block(-11,4,-5,SANDSTONE)
Block(-11,4,-4,SANDSTONE)
Block(-11,4,-3,SANDSTONE)
Block(-11,4,-2,SANDSTONE)
Block(-11,4,-1,SANDSTONE)
Block(-11,4,0,SANDSTONE)
Block(-11,4,1,SANDSTONE)
Block(-11,4,2,SANDSTONE)
Block(-11,4,3,SANDSTONE)
Block(-11,4,4,SANDSTONE)
Block(-11,4,5,SANDSTONE)
Block(-11,4,6,SANDSTONE)
Block(-11,4,7,SANDSTONE)
Block(-11,4,8,SANDSTONE)
Block(-11,4,9,SANDSTONE)
Block(-11,5,-8,SANDSTONE)
Block(-11,5,-7,SANDSTONE)
Block(-11,5,-6,SANDSTONE)
Block(-11,5,-5,SANDSTONE)
Block(-11,5,-4,SANDSTONE)
Block(-11,5,-3,SANDSTONE)
Block(-11,5,-2,SANDSTONE)
Block(-11,5,-1,SANDSTONE)
Block(-11,5,0,SANDSTONE)
Block(-11,5,1,SANDSTONE)
Block(-11,5,2,SANDSTONE)
Block(-11,5,3,SANDSTONE)
Block(-11,5,4,SANDSTONE)
Block(-11,5,5,SANDSTONE)
Block(-11,5,6,SANDSTONE)
Block(-11,5,7,SANDSTONE)
Block(-11,5,8,SANDSTONE)
Block(-11,6,-7,SANDSTONE)
Block(-11,6,-6,SANDSTONE)
Block(-11,6,-5,SANDSTONE)
Block(-11,6,-4,SANDSTONE)
Block(-11,6,-3,SANDSTONE)
Block(-11,6,-2,SANDSTONE)
Block(-11,6,-1,SANDSTONE)
Block(-11,6,0,SANDSTONE)
Block(-11,6,1,SANDSTONE)
Block(-11,6,2,SANDSTONE)
Block(-11,6,3,SANDSTONE)
Block(-11,6,4,SANDSTONE)
Block(-11,6,5,SANDSTONE)
Block(-11,6,6,SANDSTONE)
Block(-11,6,7,SANDSTONE)
Block(-11,7,-7,SANDSTONE)
Block(-11,7,-6,SANDSTONE)
Block(-11,7,-5,SANDSTONE)
Block(-11,7,-4,SANDSTONE)
Block(-11,7,-3,SANDSTONE)
Block(-11,7,-2,SANDSTONE)
Block(-11,7,-1,SANDSTONE)
Block(-11,7,0,SANDSTONE)
Block(-11,7,1,SANDSTONE)
Block(-11,7,2,SANDSTONE)
Block(-11,7,3,SANDSTONE)
Block(-11,7,4,SANDSTONE)
Block(-11,7,5,SANDSTONE)
Block(-11,7,6,SANDSTONE)
Block(-11,8,-6,SANDSTONE)
Block(-11,8,-5,SANDSTONE)
Block(-11,8,-4,SANDSTONE)
Block(-11,8,-3,SANDSTONE)
Block(-11,8,-2,SANDSTONE)
Block(-11,8,-1,SANDSTONE)
Block(-11,8,0,SANDSTONE)
Block(-11,8,1,SANDSTONE)
Block(-11,8,2,SANDSTONE)
Block(-11,8,3,SANDSTONE)
Block(-11,9,-5,SANDSTONE)
Block(-11,9,-4,SANDSTONE)
Block(-11,9,-3,SANDSTONE)
Block(-11,9,-2,SANDSTONE)
Block(-11,9,-1,SANDSTONE)
Block(-11,9,0,SANDSTONE)
Block(-11,9,1,SANDSTONE)
Block(-11,9,2,SANDSTONE)
Block(-11,10,-4,SANDSTONE)
Block(-11,10,-3,SANDSTONE)
Block(-11,10,-2,SANDSTONE)
Block(-11,10,-1,SANDSTONE)
Block(-11,10,0,SANDSTONE)
Block(-10,-15,-4,SANDSTONE)
Block(-10,-15,-3,SANDSTONE)
Block(-10,-15,-2,SANDSTONE)
Block(-10,-15,-1,SANDSTONE)
Block(-10,-15,0,SANDSTONE)
Block(-10,-15,1,SANDSTONE)
Block(-10,-15,2,SANDSTONE)
Block(-10,-14,-5,SANDSTONE)
Block(-10,-14,-4,SANDSTONE)
Block(-10,-14,-3,SANDSTONE)
Block(-10,-14,-2,SANDSTONE)
Block(-10,-14,-1,SANDSTONE)
Block(-10,-14,0,SANDSTONE)
Block(-10,-14,1,SANDSTONE)
Block(-10,-14,2,SANDSTONE)
Block(-10,-14,3,SANDSTONE)
Block(-10,-14,4,SANDSTONE)
Block(-10,-13,-6,SANDSTONE)
Block(-10,-13,-5,SANDSTONE)
Block(-10,-13,-4,SANDSTONE)
Block(-10,-13,-3,SANDSTONE)
Block(-10,-13,-2,SANDSTONE)
Block(-10,-13,-1,SANDSTONE)
Block(-10,-13,0,SANDSTONE)
Block(-10,-13,1,SANDSTONE)
Block(-10,-13,2,SANDSTONE)
Block(-10,-13,3,SANDSTONE)
Block(-10,-13,4,SANDSTONE)
Block(-10,-13,5,SANDSTONE)
Block(-10,-13,6,SANDSTONE)
Block(-10,-12,-7,SANDSTONE)
Block(-10,-12,-6,SANDSTONE)
Block(-10,-12,-5,SANDSTONE)
Block(-10,-12,-4,SANDSTONE)
Block(-10,-12,-3,SANDSTONE)
Block(-10,-12,-2,SANDSTONE)
Block(-10,-12,-1,SANDSTONE)
Block(-10,-12,0,SANDSTONE)
Block(-10,-12,1,SANDSTONE)
Block(-10,-12,2,SANDSTONE)
Block(-10,-12,3,SANDSTONE)
Block(-10,-12,4,SANDSTONE)
Block(-10,-12,5,SANDSTONE)
Block(-10,-12,6,SANDSTONE)
Block(-10,-12,7,SANDSTONE)
Block(-10,-11,-7,SANDSTONE)
Block(-10,-11,-6,SANDSTONE)
Block(-10,-11,-5,SANDSTONE)
Block(-10,-11,-4,SANDSTONE)
Block(-10,-11,-3,SANDSTONE)
Block(-10,-11,-2,SANDSTONE)
Block(-10,-11,-1,SANDSTONE)
Block(-10,-11,0,SANDSTONE)
Block(-10,-11,1,SANDSTONE)
Block(-10,-11,2,SANDSTONE)
Block(-10,-11,3,SANDSTONE)
Block(-10,-11,4,SANDSTONE)
Block(-10,-11,5,SANDSTONE)
Block(-10,-11,6,SANDSTONE)
Block(-10,-11,7,SANDSTONE)
Block(-10,-11,8,SANDSTONE)
Block(-10,-10,-8,SANDSTONE)
Block(-10,-10,-7,SANDSTONE)
Block(-10,-10,-6,SANDSTONE)
Block(-10,-10,-5,SANDSTONE)
Block(-10,-10,-4,SANDSTONE)
Block(-10,-10,-3,SANDSTONE)
Block(-10,-10,-2,SANDSTONE)
Block(-10,-10,-1,SANDSTONE)
Block(-10,-10,0,SANDSTONE)
Block(-10,-10,1,SANDSTONE)
Block(-10,-10,2,SANDSTONE)
Block(-10,-10,3,SANDSTONE)
Block(-10,-10,4,SANDSTONE)
Block(-10,-10,5,SANDSTONE)
Block(-10,-10,6,SANDSTONE)
Block(-10,-10,7,SANDSTONE)
Block(-10,-10,8,SANDSTONE)
Block(-10,-9,-8,SANDSTONE)
Block(-10,-9,-7,SANDSTONE)
Block(-10,-9,-6,SANDSTONE)
Block(-10,-9,-5,SANDSTONE)
Block(-10,-9,-4,SANDSTONE)
Block(-10,-9,-3,SANDSTONE)
Block(-10,-9,-2,SANDSTONE)
Block(-10,-9,-1,SANDSTONE)
Block(-10,-9,0,SANDSTONE)
Block(-10,-9,1,SANDSTONE)
Block(-10,-9,2,SANDSTONE)
Block(-10,-9,3,SANDSTONE)
Block(-10,-9,4,SANDSTONE)
Block(-10,-9,5,SANDSTONE)
Block(-10,-9,6,SANDSTONE)
Block(-10,-9,7,SANDSTONE)
Block(-10,-9,8,SANDSTONE)
Block(-10,-9,9,SANDSTONE)
Block(-10,-8,-9,SANDSTONE)
Block(-10,-8,-8,SANDSTONE)
Block(-10,-8,-7,SANDSTONE)
Block(-10,-8,-6,SANDSTONE)
Block(-10,-8,-5,SANDSTONE)
Block(-10,-8,-4,SANDSTONE)
Block(-10,-8,-3,SANDSTONE)
Block(-10,-8,-2,SANDSTONE)
Block(-10,-8,-1,SANDSTONE)
Block(-10,-8,0,SANDSTONE)
Block(-10,-8,1,SANDSTONE)
Block(-10,-8,2,SANDSTONE)
Block(-10,-8,3,SANDSTONE)
Block(-10,-8,4,SANDSTONE)
Block(-10,-8,5,SANDSTONE)
Block(-10,-8,6,SANDSTONE)
Block(-10,-8,7,SANDSTONE)
Block(-10,-8,8,SANDSTONE)
Block(-10,-8,9,SANDSTONE)
Block(-10,-8,10,SANDSTONE)
Block(-10,-8,11,SANDSTONE)
Block(-10,-7,-9,SANDSTONE)
Block(-10,-7,-8,SANDSTONE)
Block(-10,-7,-7,SANDSTONE)
Block(-10,-7,-6,SANDSTONE)
Block(-10,-7,-5,SANDSTONE)
Block(-10,-7,-4,SANDSTONE)
Block(-10,-7,-3,SANDSTONE)
Block(-10,-7,-2,SANDSTONE)
Block(-10,-7,-1,SANDSTONE)
Block(-10,-7,0,SANDSTONE)
Block(-10,-7,1,SANDSTONE)
Block(-10,-7,2,SANDSTONE)
Block(-10,-7,3,SANDSTONE)
Block(-10,-7,4,SANDSTONE)
Block(-10,-7,5,SANDSTONE)
Block(-10,-7,6,SANDSTONE)
Block(-10,-7,7,SANDSTONE)
Block(-10,-7,8,SANDSTONE)
Block(-10,-7,9,SANDSTONE)
Block(-10,-7,10,SANDSTONE)
Block(-10,-7,11,SANDSTONE)
Block(-10,-6,-10,SANDSTONE)
Block(-10,-6,-9,SANDSTONE)
Block(-10,-6,-8,SANDSTONE)
Block(-10,-6,-7,SANDSTONE)
Block(-10,-6,-6,SANDSTONE)
Block(-10,-6,-5,SANDSTONE)
Block(-10,-6,-4,SANDSTONE)
Block(-10,-6,-3,SANDSTONE)
Block(-10,-6,-2,SANDSTONE)
Block(-10,-6,-1,SANDSTONE)
Block(-10,-6,0,SANDSTONE)
Block(-10,-6,1,SANDSTONE)
Block(-10,-6,2,SANDSTONE)
Block(-10,-6,3,SANDSTONE)
Block(-10,-6,4,SANDSTONE)
Block(-10,-6,5,SANDSTONE)
Block(-10,-6,6,SANDSTONE)
Block(-10,-6,7,SANDSTONE)
Block(-10,-6,8,SANDSTONE)
Block(-10,-6,9,SANDSTONE)
Block(-10,-6,10,SANDSTONE)
Block(-10,-6,11,SANDSTONE)
Block(-10,-5,-11,SANDSTONE)
Block(-10,-5,-10,SANDSTONE)
Block(-10,-5,-9,SANDSTONE)
Block(-10,-5,-8,SANDSTONE)
Block(-10,-5,-7,SANDSTONE)
Block(-10,-5,-6,SANDSTONE)
Block(-10,-5,-5,SANDSTONE)
Block(-10,-5,-4,SANDSTONE)
Block(-10,-5,-3,SANDSTONE)
Block(-10,-5,-2,SANDSTONE)
Block(-10,-5,-1,SANDSTONE)
Block(-10,-5,0,SANDSTONE)
Block(-10,-5,1,SANDSTONE)
Block(-10,-5,2,SANDSTONE)
Block(-10,-5,3,SANDSTONE)
Block(-10,-5,4,SANDSTONE)
Block(-10,-5,5,SANDSTONE)
Block(-10,-5,6,SANDSTONE)
Block(-10,-5,7,SANDSTONE)
Block(-10,-5,8,SANDSTONE)
Block(-10,-5,9,SANDSTONE)
Block(-10,-5,10,SANDSTONE)
Block(-10,-5,11,SANDSTONE)
Block(-10,-5,12,SANDSTONE)
Block(-10,-4,-12,SANDSTONE)
Block(-10,-4,-11,SANDSTONE)
Block(-10,-4,-10,SANDSTONE)
Block(-10,-4,-9,SANDSTONE)
Block(-10,-4,-8,SANDSTONE)
Block(-10,-4,-7,SANDSTONE)
Block(-10,-4,-6,SANDSTONE)
Block(-10,-4,-5,SANDSTONE)
Block(-10,-4,-4,SANDSTONE)
Block(-10,-4,-3,SANDSTONE)
Block(-10,-4,-2,SANDSTONE)
Block(-10,-4,-1,SANDSTONE)
Block(-10,-4,0,SANDSTONE)
Block(-10,-4,1,SANDSTONE)
Block(-10,-4,2,SANDSTONE)
Block(-10,-4,3,SANDSTONE)
Block(-10,-4,4,SANDSTONE)
Block(-10,-4,5,SANDSTONE)
Block(-10,-4,6,SANDSTONE)
Block(-10,-4,7,SANDSTONE)
Block(-10,-4,8,SANDSTONE)
Block(-10,-4,9,SANDSTONE)
Block(-10,-4,10,SANDSTONE)
Block(-10,-4,11,SANDSTONE)
Block(-10,-4,12,SANDSTONE)
Block(-10,-3,-12,SANDSTONE)
Block(-10,-3,-11,SANDSTONE)
Block(-10,-3,-10,SANDSTONE)
Block(-10,-3,-9,SANDSTONE)
Block(-10,-3,-8,SANDSTONE)
Block(-10,-3,-7,SANDSTONE)
Block(-10,-3,-6,SANDSTONE)
Block(-10,-3,-5,SANDSTONE)
Block(-10,-3,-4,SANDSTONE)
Block(-10,-3,-3,SANDSTONE)
Block(-10,-3,-2,SANDSTONE)
Block(-10,-3,-1,SANDSTONE)
Block(-10,-3,0,SANDSTONE)
Block(-10,-3,1,SANDSTONE)
Block(-10,-3,2,SANDSTONE)
Block(-10,-3,3,SANDSTONE)
Block(-10,-3,4,SANDSTONE)
Block(-10,-3,5,SANDSTONE)
Block(-10,-3,6,SANDSTONE)
Block(-10,-3,7,SANDSTONE)
Block(-10,-3,8,SANDSTONE)
Block(-10,-3,9,SANDSTONE)
Block(-10,-3,10,SANDSTONE)
Block(-10,-3,11,SANDSTONE)
Block(-10,-3,12,SANDSTONE)
Block(-10,-2,-12,SANDSTONE)
Block(-10,-2,-11,SANDSTONE)
Block(-10,-2,-10,SANDSTONE)
Block(-10,-2,-9,SANDSTONE)
Block(-10,-2,-8,SANDSTONE)
Block(-10,-2,-7,SANDSTONE)
Block(-10,-2,-6,SANDSTONE)
Block(-10,-2,-5,SANDSTONE)
Block(-10,-2,-4,SANDSTONE)
Block(-10,-2,-3,SANDSTONE)
Block(-10,-2,-2,SANDSTONE)
Block(-10,-2,-1,SANDSTONE)
Block(-10,-2,0,SANDSTONE)
Block(-10,-2,1,SANDSTONE)
Block(-10,-2,2,SANDSTONE)
Block(-10,-2,3,SANDSTONE)
Block(-10,-2,4,SANDSTONE)
Block(-10,-2,5,SANDSTONE)
Block(-10,-2,6,SANDSTONE)
Block(-10,-2,7,SANDSTONE)
Block(-10,-2,8,SANDSTONE)
Block(-10,-2,9,SANDSTONE)
Block(-10,-2,10,SANDSTONE)
Block(-10,-2,11,SANDSTONE)
Block(-10,-2,12,SANDSTONE)
Block(-10,-1,-12,SANDSTONE)
Block(-10,-1,-11,SANDSTONE)
Block(-10,-1,-10,SANDSTONE)
Block(-10,-1,-9,SANDSTONE)
Block(-10,-1,-8,SANDSTONE)
Block(-10,-1,-7,SANDSTONE)
Block(-10,-1,-6,SANDSTONE)
Block(-10,-1,-5,SANDSTONE)
Block(-10,-1,-4,SANDSTONE)
Block(-10,-1,-3,SANDSTONE)
Block(-10,-1,-2,SANDSTONE)
Block(-10,-1,-1,SANDSTONE)
Block(-10,-1,0,SANDSTONE)
Block(-10,-1,1,SANDSTONE)
Block(-10,-1,2,SANDSTONE)
Block(-10,-1,3,SANDSTONE)
Block(-10,-1,4,SANDSTONE)
Block(-10,-1,5,SANDSTONE)
Block(-10,-1,6,SANDSTONE)
Block(-10,-1,7,SANDSTONE)
Block(-10,-1,8,SANDSTONE)
Block(-10,-1,9,SANDSTONE)
Block(-10,-1,10,SANDSTONE)
Block(-10,-1,11,SANDSTONE)
Block(-10,-1,12,SANDSTONE)
Block(-10,0,-11,SANDSTONE)
Block(-10,0,-10,SANDSTONE)
Block(-10,0,-9,SANDSTONE)
Block(-10,0,-8,SANDSTONE)
Block(-10,0,-7,SANDSTONE)
Block(-10,0,-6,SANDSTONE)
Block(-10,0,-5,SANDSTONE)
Block(-10,0,-4,SANDSTONE)
Block(-10,0,-3,SANDSTONE)
Block(-10,0,-2,SANDSTONE)
Block(-10,0,-1,SANDSTONE)
Block(-10,0,0,SANDSTONE)
Block(-10,0,1,SANDSTONE)
Block(-10,0,2,SANDSTONE)
Block(-10,0,3,SANDSTONE)
Block(-10,0,4,SANDSTONE)
Block(-10,0,5,SANDSTONE)
Block(-10,0,6,SANDSTONE)
Block(-10,0,7,SANDSTONE)
Block(-10,0,8,SANDSTONE)
Block(-10,0,9,SANDSTONE)
Block(-10,0,10,SANDSTONE)
Block(-10,0,11,SANDSTONE)
Block(-10,0,12,SANDSTONE)
Block(-10,1,-10,SANDSTONE)
Block(-10,1,-9,SANDSTONE)
Block(-10,1,-8,SANDSTONE)
Block(-10,1,-7,SANDSTONE)
Block(-10,1,-6,SANDSTONE)
Block(-10,1,-5,SANDSTONE)
Block(-10,1,-4,SANDSTONE)
Block(-10,1,-3,SANDSTONE)
Block(-10,1,-2,SANDSTONE)
Block(-10,1,-1,SANDSTONE)
Block(-10,1,0,SANDSTONE)
Block(-10,1,1,SANDSTONE)
Block(-10,1,2,SANDSTONE)
Block(-10,1,3,SANDSTONE)
Block(-10,1,4,SANDSTONE)
Block(-10,1,5,SANDSTONE)
Block(-10,1,6,SANDSTONE)
Block(-10,1,7,SANDSTONE)
Block(-10,1,8,SANDSTONE)
Block(-10,1,9,SANDSTONE)
Block(-10,1,10,SANDSTONE)
Block(-10,1,11,SANDSTONE)
Block(-10,2,-9,SANDSTONE)
Block(-10,2,-8,SANDSTONE)
Block(-10,2,-7,SANDSTONE)
Block(-10,2,-6,SANDSTONE)
Block(-10,2,-5,SANDSTONE)
Block(-10,2,-4,SANDSTONE)
Block(-10,2,-3,SANDSTONE)
Block(-10,2,-2,SANDSTONE)
Block(-10,2,-1,SANDSTONE)
Block(-10,2,0,SANDSTONE)
Block(-10,2,1,SANDSTONE)
Block(-10,2,2,SANDSTONE)
Block(-10,2,3,SANDSTONE)
Block(-10,2,4,SANDSTONE)
Block(-10,2,5,SANDSTONE)
Block(-10,2,6,SANDSTONE)
Block(-10,2,7,SANDSTONE)
Block(-10,2,8,SANDSTONE)
Block(-10,2,9,SANDSTONE)
Block(-10,2,10,SANDSTONE)
Block(-10,2,11,SANDSTONE)
Block(-10,3,-9,SANDSTONE)
Block(-10,3,-8,SANDSTONE)
Block(-10,3,-7,SANDSTONE)
Block(-10,3,-6,SANDSTONE)
Block(-10,3,-5,SANDSTONE)
Block(-10,3,-4,SANDSTONE)
Block(-10,3,-3,SANDSTONE)
Block(-10,3,-2,SANDSTONE)
Block(-10,3,-1,SANDSTONE)
Block(-10,3,0,SANDSTONE)
Block(-10,3,1,SANDSTONE)
Block(-10,3,2,SANDSTONE)
Block(-10,3,3,SANDSTONE)
Block(-10,3,4,SANDSTONE)
Block(-10,3,5,SANDSTONE)
Block(-10,3,6,SANDSTONE)
Block(-10,3,7,SANDSTONE)
Block(-10,3,8,SANDSTONE)
Block(-10,3,9,SANDSTONE)
Block(-10,3,10,SANDSTONE)
Block(-10,3,11,SANDSTONE)
Block(-10,4,-8,SANDSTONE)
Block(-10,4,-7,SANDSTONE)
Block(-10,4,-6,SANDSTONE)
Block(-10,4,-5,SANDSTONE)
Block(-10,4,-4,SANDSTONE)
Block(-10,4,-3,SANDSTONE)
Block(-10,4,-2,SANDSTONE)
Block(-10,4,-1,SANDSTONE)
Block(-10,4,0,SANDSTONE)
Block(-10,4,1,SANDSTONE)
Block(-10,4,2,SANDSTONE)
Block(-10,4,3,SANDSTONE)
Block(-10,4,4,SANDSTONE)
Block(-10,4,5,SANDSTONE)
Block(-10,4,6,SANDSTONE)
Block(-10,4,7,SANDSTONE)
Block(-10,4,8,SANDSTONE)
Block(-10,4,9,SANDSTONE)
Block(-10,5,-8,SANDSTONE)
Block(-10,5,-7,SANDSTONE)
Block(-10,5,-6,SANDSTONE)
Block(-10,5,-5,SANDSTONE)
Block(-10,5,-4,SANDSTONE)
Block(-10,5,-3,SANDSTONE)
Block(-10,5,-2,SANDSTONE)
Block(-10,5,-1,SANDSTONE)
Block(-10,5,0,SANDSTONE)
Block(-10,5,1,SANDSTONE)
Block(-10,5,2,SANDSTONE)
Block(-10,5,3,SANDSTONE)
Block(-10,5,4,SANDSTONE)
Block(-10,5,5,SANDSTONE)
Block(-10,5,6,SANDSTONE)
Block(-10,5,7,SANDSTONE)
Block(-10,5,8,SANDSTONE)
Block(-10,6,-7,SANDSTONE)
Block(-10,6,-6,SANDSTONE)
Block(-10,6,-5,SANDSTONE)
Block(-10,6,-4,SANDSTONE)
Block(-10,6,-3,SANDSTONE)
Block(-10,6,-2,SANDSTONE)
Block(-10,6,-1,SANDSTONE)
Block(-10,6,0,SANDSTONE)
Block(-10,6,1,SANDSTONE)
Block(-10,6,2,SANDSTONE)
Block(-10,6,3,SANDSTONE)
Block(-10,6,4,SANDSTONE)
Block(-10,6,5,SANDSTONE)
Block(-10,6,6,SANDSTONE)
Block(-10,6,7,SANDSTONE)
Block(-10,6,8,SANDSTONE)
Block(-10,7,-7,SANDSTONE)
Block(-10,7,-6,SANDSTONE)
Block(-10,7,-5,SANDSTONE)
Block(-10,7,-4,SANDSTONE)
Block(-10,7,-3,SANDSTONE)
Block(-10,7,-2,SANDSTONE)
Block(-10,7,-1,SANDSTONE)
Block(-10,7,0,SANDSTONE)
Block(-10,7,1,SANDSTONE)
Block(-10,7,2,SANDSTONE)
Block(-10,7,3,SANDSTONE)
Block(-10,7,4,SANDSTONE)
Block(-10,7,5,SANDSTONE)
Block(-10,7,6,SANDSTONE)
Block(-10,7,7,SANDSTONE)
Block(-10,8,-6,SANDSTONE)
Block(-10,8,-5,SANDSTONE)
Block(-10,8,-4,SANDSTONE)
Block(-10,8,-3,SANDSTONE)
Block(-10,8,-2,SANDSTONE)
Block(-10,8,-1,SANDSTONE)
Block(-10,8,0,SANDSTONE)
Block(-10,8,1,SANDSTONE)
Block(-10,8,2,SANDSTONE)
Block(-10,8,3,SANDSTONE)
Block(-10,8,4,SANDSTONE)
Block(-10,8,5,SANDSTONE)
Block(-10,8,6,SANDSTONE)
Block(-10,9,-5,SANDSTONE)
Block(-10,9,-4,SANDSTONE)
Block(-10,9,-3,SANDSTONE)
Block(-10,9,-2,SANDSTONE)
Block(-10,9,-1,SANDSTONE)
Block(-10,9,0,SANDSTONE)
Block(-10,9,1,SANDSTONE)
Block(-10,9,2,SANDSTONE)
Block(-10,9,3,SANDSTONE)
Block(-10,9,4,SANDSTONE)
Block(-10,10,-4,SANDSTONE)
Block(-10,10,-3,SANDSTONE)
Block(-10,10,-2,SANDSTONE)
Block(-10,10,-1,SANDSTONE)
Block(-10,10,0,SANDSTONE)
Block(-10,10,1,SANDSTONE)
Block(-10,10,2,SANDSTONE)
Block(-9,-15,-4,SANDSTONE)
Block(-9,-15,-3,SANDSTONE)
Block(-9,-15,2,SANDSTONE)
Block(-9,-14,-5,SANDSTONE)
Block(-9,-14,-4,SANDSTONE)
Block(-9,-14,-3,SANDSTONE)
Block(-9,-14,-2,SANDSTONE)
Block(-9,-14,-1,SANDSTONE)
Block(-9,-14,0,SANDSTONE)
Block(-9,-14,1,SANDSTONE)
Block(-9,-14,2,SANDSTONE)
Block(-9,-14,3,SANDSTONE)
Block(-9,-14,4,SANDSTONE)
Block(-9,-14,5,SANDSTONE)
Block(-9,-13,-6,SANDSTONE)
Block(-9,-13,-5,SANDSTONE)
Block(-9,-13,-4,SANDSTONE)
Block(-9,-13,-3,SANDSTONE)
Block(-9,-13,-2,SANDSTONE)
Block(-9,-13,-1,SANDSTONE)
Block(-9,-13,0,SANDSTONE)
Block(-9,-13,1,SANDSTONE)
Block(-9,-13,2,SANDSTONE)
Block(-9,-13,3,SANDSTONE)
Block(-9,-13,4,SANDSTONE)
Block(-9,-13,5,SANDSTONE)
Block(-9,-13,6,SANDSTONE)
Block(-9,-12,-7,SANDSTONE)
Block(-9,-12,-6,SANDSTONE)
Block(-9,-12,-5,SANDSTONE)
Block(-9,-12,-4,SANDSTONE)
Block(-9,-12,-3,SANDSTONE)
Block(-9,-12,-2,SANDSTONE)
Block(-9,-12,-1,SANDSTONE)
Block(-9,-12,0,SANDSTONE)
Block(-9,-12,1,SANDSTONE)
Block(-9,-12,2,SANDSTONE)
Block(-9,-12,3,SANDSTONE)
Block(-9,-12,4,SANDSTONE)
Block(-9,-12,5,SANDSTONE)
Block(-9,-12,6,SANDSTONE)
Block(-9,-12,7,SANDSTONE)
Block(-9,-11,-7,SANDSTONE)
Block(-9,-11,-6,SANDSTONE)
Block(-9,-11,-5,SANDSTONE)
Block(-9,-11,-4,SANDSTONE)
Block(-9,-11,-3,SANDSTONE)
Block(-9,-11,-2,SANDSTONE)
Block(-9,-11,-1,SANDSTONE)
Block(-9,-11,0,SANDSTONE)
Block(-9,-11,1,SANDSTONE)
Block(-9,-11,2,SANDSTONE)
Block(-9,-11,3,SANDSTONE)
Block(-9,-11,4,SANDSTONE)
Block(-9,-11,5,SANDSTONE)
Block(-9,-11,6,SANDSTONE)
Block(-9,-11,7,SANDSTONE)
Block(-9,-11,8,SANDSTONE)
Block(-9,-10,-8,SANDSTONE)
Block(-9,-10,-7,SANDSTONE)
Block(-9,-10,-6,SANDSTONE)
Block(-9,-10,-5,SANDSTONE)
Block(-9,-10,-4,SANDSTONE)
Block(-9,-10,-3,SANDSTONE)
Block(-9,-10,-2,SANDSTONE)
Block(-9,-10,-1,SANDSTONE)
Block(-9,-10,0,SANDSTONE)
Block(-9,-10,1,SANDSTONE)
Block(-9,-10,2,SANDSTONE)
Block(-9,-10,3,SANDSTONE)
Block(-9,-10,4,SANDSTONE)
Block(-9,-10,5,SANDSTONE)
Block(-9,-10,6,SANDSTONE)
Block(-9,-10,7,SANDSTONE)
Block(-9,-10,8,SANDSTONE)
Block(-9,-10,9,SANDSTONE)
Block(-9,-9,-8,SANDSTONE)
Block(-9,-9,-7,SANDSTONE)
Block(-9,-9,-6,SANDSTONE)
Block(-9,-9,-5,SANDSTONE)
Block(-9,-9,-4,SANDSTONE)
Block(-9,-9,-3,SANDSTONE)
Block(-9,-9,-2,SANDSTONE)
Block(-9,-9,-1,SANDSTONE)
Block(-9,-9,0,SANDSTONE)
Block(-9,-9,1,SANDSTONE)
Block(-9,-9,2,SANDSTONE)
Block(-9,-9,3,SANDSTONE)
Block(-9,-9,4,SANDSTONE)
Block(-9,-9,5,SANDSTONE)
Block(-9,-9,6,SANDSTONE)
Block(-9,-9,7,SANDSTONE)
Block(-9,-9,8,SANDSTONE)
Block(-9,-9,9,SANDSTONE)
Block(-9,-9,10,SANDSTONE)
Block(-9,-8,-9,SANDSTONE)
Block(-9,-8,-8,SANDSTONE)
Block(-9,-8,-7,SANDSTONE)
Block(-9,-8,-6,SANDSTONE)
Block(-9,-8,-5,SANDSTONE)
Block(-9,-8,-4,SANDSTONE)
Block(-9,-8,-3,SANDSTONE)
Block(-9,-8,-2,SANDSTONE)
Block(-9,-8,-1,SANDSTONE)
Block(-9,-8,0,SANDSTONE)
Block(-9,-8,1,SANDSTONE)
Block(-9,-8,2,SANDSTONE)
Block(-9,-8,3,SANDSTONE)
Block(-9,-8,4,SANDSTONE)
Block(-9,-8,5,SANDSTONE)
Block(-9,-8,6,SANDSTONE)
Block(-9,-8,7,SANDSTONE)
Block(-9,-8,8,SANDSTONE)
Block(-9,-8,9,SANDSTONE)
Block(-9,-8,10,SANDSTONE)
Block(-9,-8,11,SANDSTONE)
Block(-9,-7,-9,SANDSTONE)
Block(-9,-7,-8,SANDSTONE)
Block(-9,-7,-7,SANDSTONE)
Block(-9,-7,-6,SANDSTONE)
Block(-9,-7,-5,SANDSTONE)
Block(-9,-7,-4,SANDSTONE)
Block(-9,-7,-3,SANDSTONE)
Block(-9,-7,-2,SANDSTONE)
Block(-9,-7,-1,SANDSTONE)
Block(-9,-7,0,SANDSTONE)
Block(-9,-7,1,SANDSTONE)
Block(-9,-7,2,SANDSTONE)
Block(-9,-7,3,SANDSTONE)
Block(-9,-7,4,SANDSTONE)
Block(-9,-7,5,SANDSTONE)
Block(-9,-7,6,SANDSTONE)
Block(-9,-7,7,SANDSTONE)
Block(-9,-7,8,SANDSTONE)
Block(-9,-7,9,SANDSTONE)
Block(-9,-7,10,SANDSTONE)
Block(-9,-7,11,SANDSTONE)
Block(-9,-6,-10,SANDSTONE)
Block(-9,-6,-9,SANDSTONE)
Block(-9,-6,-8,SANDSTONE)
Block(-9,-6,-7,SANDSTONE)
Block(-9,-6,-6,SANDSTONE)
Block(-9,-6,-5,SANDSTONE)
Block(-9,-6,-4,SANDSTONE)
Block(-9,-6,-3,SANDSTONE)
Block(-9,-6,-2,SANDSTONE)
Block(-9,-6,-1,SANDSTONE)
Block(-9,-6,0,SANDSTONE)
Block(-9,-6,1,SANDSTONE)
Block(-9,-6,2,SANDSTONE)
Block(-9,-6,3,SANDSTONE)
Block(-9,-6,4,SANDSTONE)
Block(-9,-6,5,SANDSTONE)
Block(-9,-6,6,SANDSTONE)
Block(-9,-6,7,SANDSTONE)
Block(-9,-6,8,SANDSTONE)
Block(-9,-6,9,SANDSTONE)
Block(-9,-6,10,SANDSTONE)
Block(-9,-6,11,SANDSTONE)
Block(-9,-5,-10,SANDSTONE)
Block(-9,-5,-9,SANDSTONE)
Block(-9,-5,-8,SANDSTONE)
Block(-9,-5,-7,SANDSTONE)
Block(-9,-5,-6,SANDSTONE)
Block(-9,-5,-5,SANDSTONE)
Block(-9,-5,-4,SANDSTONE)
Block(-9,-5,-3,SANDSTONE)
Block(-9,-5,-2,SANDSTONE)
Block(-9,-5,-1,SANDSTONE)
Block(-9,-5,0,SANDSTONE)
Block(-9,-5,1,SANDSTONE)
Block(-9,-5,2,SANDSTONE)
Block(-9,-5,3,SANDSTONE)
Block(-9,-5,4,SANDSTONE)
Block(-9,-5,5,SANDSTONE)
Block(-9,-5,6,SANDSTONE)
Block(-9,-5,7,SANDSTONE)
Block(-9,-5,8,SANDSTONE)
Block(-9,-5,9,SANDSTONE)
Block(-9,-5,10,SANDSTONE)
Block(-9,-5,11,SANDSTONE)
Block(-9,-5,12,SANDSTONE)
Block(-9,-4,-11,SANDSTONE)
Block(-9,-4,-10,SANDSTONE)
Block(-9,-4,-9,SANDSTONE)
Block(-9,-4,-8,SANDSTONE)
Block(-9,-4,-7,SANDSTONE)
Block(-9,-4,-6,SANDSTONE)
Block(-9,-4,-5,SANDSTONE)
Block(-9,-4,-4,SANDSTONE)
Block(-9,-4,-3,SANDSTONE)
Block(-9,-4,-2,SANDSTONE)
Block(-9,-4,-1,SANDSTONE)
Block(-9,-4,0,SANDSTONE)
Block(-9,-4,1,SANDSTONE)
Block(-9,-4,2,SANDSTONE)
Block(-9,-4,3,SANDSTONE)
Block(-9,-4,4,SANDSTONE)
Block(-9,-4,5,SANDSTONE)
Block(-9,-4,6,SANDSTONE)
Block(-9,-4,7,SANDSTONE)
Block(-9,-4,8,SANDSTONE)
Block(-9,-4,9,SANDSTONE)
Block(-9,-4,10,SANDSTONE)
Block(-9,-4,11,SANDSTONE)
Block(-9,-4,12,SANDSTONE)
Block(-9,-3,-11,SANDSTONE)
Block(-9,-3,-10,SANDSTONE)
Block(-9,-3,-9,SANDSTONE)
Block(-9,-3,-8,SANDSTONE)
Block(-9,-3,-7,SANDSTONE)
Block(-9,-3,-6,SANDSTONE)
Block(-9,-3,-5,SANDSTONE)
Block(-9,-3,-4,SANDSTONE)
Block(-9,-3,-3,SANDSTONE)
Block(-9,-3,-2,SANDSTONE)
Block(-9,-3,-1,SANDSTONE)
Block(-9,-3,0,SANDSTONE)
Block(-9,-3,1,SANDSTONE)
Block(-9,-3,2,SANDSTONE)
Block(-9,-3,3,SANDSTONE)
Block(-9,-3,4,SANDSTONE)
Block(-9,-3,5,SANDSTONE)
Block(-9,-3,6,SANDSTONE)
Block(-9,-3,7,SANDSTONE)
Block(-9,-3,8,SANDSTONE)
Block(-9,-3,9,SANDSTONE)
Block(-9,-3,10,SANDSTONE)
Block(-9,-3,11,SANDSTONE)
Block(-9,-3,12,SANDSTONE)
Block(-9,-3,13,SANDSTONE)
Block(-9,-2,-11,SANDSTONE)
Block(-9,-2,-10,SANDSTONE)
Block(-9,-2,-9,SANDSTONE)
Block(-9,-2,-8,SANDSTONE)
Block(-9,-2,-7,SANDSTONE)
Block(-9,-2,-6,SANDSTONE)
Block(-9,-2,-5,SANDSTONE)
Block(-9,-2,-4,SANDSTONE)
Block(-9,-2,-3,SANDSTONE)
Block(-9,-2,-2,SANDSTONE)
Block(-9,-2,-1,SANDSTONE)
Block(-9,-2,0,SANDSTONE)
Block(-9,-2,1,SANDSTONE)
Block(-9,-2,2,SANDSTONE)
Block(-9,-2,3,SANDSTONE)
Block(-9,-2,4,SANDSTONE)
Block(-9,-2,5,SANDSTONE)
Block(-9,-2,6,SANDSTONE)
Block(-9,-2,7,SANDSTONE)
Block(-9,-2,8,SANDSTONE)
Block(-9,-2,9,SANDSTONE)
Block(-9,-2,10,SANDSTONE)
Block(-9,-2,11,SANDSTONE)
Block(-9,-2,12,SANDSTONE)
Block(-9,-2,13,SANDSTONE)
Block(-9,-1,-11,SANDSTONE)
Block(-9,-1,-10,SANDSTONE)
Block(-9,-1,-9,SANDSTONE)
Block(-9,-1,-8,SANDSTONE)
Block(-9,-1,-7,SANDSTONE)
Block(-9,-1,-6,SANDSTONE)
Block(-9,-1,-5,SANDSTONE)
Block(-9,-1,-4,SANDSTONE)
Block(-9,-1,-3,SANDSTONE)
Block(-9,-1,-2,SANDSTONE)
Block(-9,-1,-1,SANDSTONE)
Block(-9,-1,0,SANDSTONE)
Block(-9,-1,1,SANDSTONE)
Block(-9,-1,2,SANDSTONE)
Block(-9,-1,3,SANDSTONE)
Block(-9,-1,4,SANDSTONE)
Block(-9,-1,5,SANDSTONE)
Block(-9,-1,6,SANDSTONE)
Block(-9,-1,7,SANDSTONE)
Block(-9,-1,8,SANDSTONE)
Block(-9,-1,9,SANDSTONE)
Block(-9,-1,10,SANDSTONE)
Block(-9,-1,11,SANDSTONE)
Block(-9,-1,12,SANDSTONE)
Block(-9,0,-10,SANDSTONE)
Block(-9,0,-9,SANDSTONE)
Block(-9,0,-8,SANDSTONE)
Block(-9,0,-7,SANDSTONE)
Block(-9,0,-6,SANDSTONE)
Block(-9,0,-5,SANDSTONE)
Block(-9,0,-4,SANDSTONE)
Block(-9,0,-3,SANDSTONE)
Block(-9,0,-2,SANDSTONE)
Block(-9,0,-1,SANDSTONE)
Block(-9,0,0,SANDSTONE)
Block(-9,0,1,SANDSTONE)
Block(-9,0,2,SANDSTONE)
Block(-9,0,3,SANDSTONE)
Block(-9,0,4,SANDSTONE)
Block(-9,0,5,SANDSTONE)
Block(-9,0,6,SANDSTONE)
Block(-9,0,7,SANDSTONE)
Block(-9,0,8,SANDSTONE)
Block(-9,0,9,SANDSTONE)
Block(-9,0,10,SANDSTONE)
Block(-9,0,11,SANDSTONE)
Block(-9,0,12,SANDSTONE)
Block(-9,1,-10,SANDSTONE)
Block(-9,1,-9,SANDSTONE)
Block(-9,1,-8,SANDSTONE)
Block(-9,1,-7,SANDSTONE)
Block(-9,1,-6,SANDSTONE)
Block(-9,1,-5,SANDSTONE)
Block(-9,1,-4,SANDSTONE)
Block(-9,1,-3,SANDSTONE)
Block(-9,1,-2,SANDSTONE)
Block(-9,1,-1,SANDSTONE)
Block(-9,1,0,SANDSTONE)
Block(-9,1,1,SANDSTONE)
Block(-9,1,2,SANDSTONE)
Block(-9,1,3,SANDSTONE)
Block(-9,1,4,SANDSTONE)
Block(-9,1,5,SANDSTONE)
Block(-9,1,6,SANDSTONE)
Block(-9,1,7,SANDSTONE)
Block(-9,1,8,SANDSTONE)
Block(-9,1,9,SANDSTONE)
Block(-9,1,10,SANDSTONE)
Block(-9,1,11,SANDSTONE)
Block(-9,2,-9,SANDSTONE)
Block(-9,2,-8,SANDSTONE)
Block(-9,2,-7,SANDSTONE)
Block(-9,2,-6,SANDSTONE)
Block(-9,2,-5,SANDSTONE)
Block(-9,2,-4,SANDSTONE)
Block(-9,2,-3,SANDSTONE)
Block(-9,2,-2,SANDSTONE)
Block(-9,2,-1,SANDSTONE)
Block(-9,2,0,SANDSTONE)
Block(-9,2,1,SANDSTONE)
Block(-9,2,2,SANDSTONE)
Block(-9,2,3,SANDSTONE)
Block(-9,2,4,SANDSTONE)
Block(-9,2,5,SANDSTONE)
Block(-9,2,6,SANDSTONE)
Block(-9,2,7,SANDSTONE)
Block(-9,2,8,SANDSTONE)
Block(-9,2,9,SANDSTONE)
Block(-9,2,10,SANDSTONE)
Block(-9,2,11,SANDSTONE)
Block(-9,3,-9,SANDSTONE)
Block(-9,3,-8,SANDSTONE)
Block(-9,3,-7,SANDSTONE)
Block(-9,3,-6,SANDSTONE)
Block(-9,3,-5,SANDSTONE)
Block(-9,3,-4,SANDSTONE)
Block(-9,3,-3,SANDSTONE)
Block(-9,3,-2,SANDSTONE)
Block(-9,3,-1,SANDSTONE)
Block(-9,3,0,SANDSTONE)
Block(-9,3,1,SANDSTONE)
Block(-9,3,2,SANDSTONE)
Block(-9,3,3,SANDSTONE)
Block(-9,3,4,SANDSTONE)
Block(-9,3,5,SANDSTONE)
Block(-9,3,6,SANDSTONE)
Block(-9,3,7,SANDSTONE)
Block(-9,3,8,SANDSTONE)
Block(-9,3,9,SANDSTONE)
Block(-9,3,10,SANDSTONE)
Block(-9,3,11,SANDSTONE)
Block(-9,4,-8,SANDSTONE)
Block(-9,4,-7,SANDSTONE)
Block(-9,4,-6,SANDSTONE)
Block(-9,4,-5,SANDSTONE)
Block(-9,4,-4,SANDSTONE)
Block(-9,4,-3,SANDSTONE)
Block(-9,4,-2,SANDSTONE)
Block(-9,4,-1,SANDSTONE)
Block(-9,4,0,SANDSTONE)
Block(-9,4,1,SANDSTONE)
Block(-9,4,2,SANDSTONE)
Block(-9,4,3,SANDSTONE)
Block(-9,4,4,SANDSTONE)
Block(-9,4,5,SANDSTONE)
Block(-9,4,6,SANDSTONE)
Block(-9,4,7,SANDSTONE)
Block(-9,4,8,SANDSTONE)
Block(-9,4,9,SANDSTONE)
Block(-9,4,10,SANDSTONE)
Block(-9,5,-8,SANDSTONE)
Block(-9,5,-7,SANDSTONE)
Block(-9,5,-6,SANDSTONE)
Block(-9,5,-5,SANDSTONE)
Block(-9,5,-4,SANDSTONE)
Block(-9,5,-3,SANDSTONE)
Block(-9,5,-2,SANDSTONE)
Block(-9,5,-1,SANDSTONE)
Block(-9,5,0,SANDSTONE)
Block(-9,5,1,SANDSTONE)
Block(-9,5,2,SANDSTONE)
Block(-9,5,3,SANDSTONE)
Block(-9,5,4,SANDSTONE)
Block(-9,5,5,SANDSTONE)
Block(-9,5,6,SANDSTONE)
Block(-9,5,7,SANDSTONE)
Block(-9,5,8,SANDSTONE)
Block(-9,5,9,SANDSTONE)
Block(-9,6,-7,SANDSTONE)
Block(-9,6,-6,SANDSTONE)
Block(-9,6,-5,SANDSTONE)
Block(-9,6,-4,SANDSTONE)
Block(-9,6,-3,SANDSTONE)
Block(-9,6,-2,SANDSTONE)
Block(-9,6,-1,SANDSTONE)
Block(-9,6,0,SANDSTONE)
Block(-9,6,1,SANDSTONE)
Block(-9,6,2,SANDSTONE)
Block(-9,6,3,SANDSTONE)
Block(-9,6,4,SANDSTONE)
Block(-9,6,5,SANDSTONE)
Block(-9,6,6,SANDSTONE)
Block(-9,6,7,SANDSTONE)
Block(-9,6,8,SANDSTONE)
Block(-9,7,-7,SANDSTONE)
Block(-9,7,-6,SANDSTONE)
Block(-9,7,-5,SANDSTONE)
Block(-9,7,-4,SANDSTONE)
Block(-9,7,-3,SANDSTONE)
Block(-9,7,-2,SANDSTONE)
Block(-9,7,-1,SANDSTONE)
Block(-9,7,0,SANDSTONE)
Block(-9,7,1,SANDSTONE)
Block(-9,7,2,SANDSTONE)
Block(-9,7,3,SANDSTONE)
Block(-9,7,4,SANDSTONE)
Block(-9,7,5,SANDSTONE)
Block(-9,7,6,SANDSTONE)
Block(-9,7,7,SANDSTONE)
Block(-9,8,-6,SANDSTONE)
Block(-9,8,-5,SANDSTONE)
Block(-9,8,-4,SANDSTONE)
Block(-9,8,-3,SANDSTONE)
Block(-9,8,-2,SANDSTONE)
Block(-9,8,-1,SANDSTONE)
Block(-9,8,0,SANDSTONE)
Block(-9,8,1,SANDSTONE)
Block(-9,8,2,SANDSTONE)
Block(-9,8,3,SANDSTONE)
Block(-9,8,4,SANDSTONE)
Block(-9,8,5,SANDSTONE)
Block(-9,8,6,SANDSTONE)
Block(-9,9,-5,SANDSTONE)
Block(-9,9,-4,SANDSTONE)
Block(-9,9,-3,SANDSTONE)
Block(-9,9,-2,SANDSTONE)
Block(-9,9,-1,SANDSTONE)
Block(-9,9,0,SANDSTONE)
Block(-9,9,1,SANDSTONE)
Block(-9,9,2,SANDSTONE)
Block(-9,9,3,SANDSTONE)
Block(-9,9,4,SANDSTONE)
Block(-9,9,5,SANDSTONE)
Block(-9,10,-4,SANDSTONE)
Block(-9,10,-3,SANDSTONE)
Block(-9,10,2,SANDSTONE)
Block(-8,-14,-5,SANDSTONE)
Block(-8,-14,-4,SANDSTONE)
Block(-8,-14,-3,SANDSTONE)
Block(-8,-14,-2,SANDSTONE)
Block(-8,-14,3,SANDSTONE)
Block(-8,-14,4,SANDSTONE)
Block(-8,-14,5,SANDSTONE)
Block(-8,-14,6,SANDSTONE)
Block(-8,-13,-6,SANDSTONE)
Block(-8,-13,-5,SANDSTONE)
Block(-8,-13,-4,SANDSTONE)
Block(-8,-13,-3,SANDSTONE)
Block(-8,-13,-2,SANDSTONE)
Block(-8,-13,-1,SANDSTONE)
Block(-8,-13,0,SANDSTONE)
Block(-8,-13,1,SANDSTONE)
Block(-8,-13,2,SANDSTONE)
Block(-8,-13,3,SANDSTONE)
Block(-8,-13,4,SANDSTONE)
Block(-8,-13,5,SANDSTONE)
Block(-8,-13,6,SANDSTONE)
Block(-8,-13,7,SANDSTONE)
Block(-8,-12,-7,SANDSTONE)
Block(-8,-12,-6,SANDSTONE)
Block(-8,-12,-5,SANDSTONE)
Block(-8,-12,-4,SANDSTONE)
Block(-8,-12,-3,SANDSTONE)
Block(-8,-12,-2,SANDSTONE)
Block(-8,-12,-1,SANDSTONE)
Block(-8,-12,0,SANDSTONE)
Block(-8,-12,1,SANDSTONE)
Block(-8,-12,2,SANDSTONE)
Block(-8,-12,3,SANDSTONE)
Block(-8,-12,4,SANDSTONE)
Block(-8,-12,5,SANDSTONE)
Block(-8,-12,6,SANDSTONE)
Block(-8,-12,7,SANDSTONE)
Block(-8,-12,8,SANDSTONE)
Block(-8,-11,-7,SANDSTONE)
Block(-8,-11,-6,SANDSTONE)
Block(-8,-11,-5,SANDSTONE)
Block(-8,-11,-4,SANDSTONE)
Block(-8,-11,-3,SANDSTONE)
Block(-8,-11,-2,SANDSTONE)
Block(-8,-11,-1,SANDSTONE)
Block(-8,-11,0,SANDSTONE)
Block(-8,-11,1,SANDSTONE)
Block(-8,-11,2,SANDSTONE)
Block(-8,-11,3,SANDSTONE)
Block(-8,-11,4,SANDSTONE)
Block(-8,-11,5,SANDSTONE)
Block(-8,-11,6,SANDSTONE)
Block(-8,-11,7,SANDSTONE)
Block(-8,-11,8,SANDSTONE)
Block(-8,-11,9,SANDSTONE)
Block(-8,-10,-7,SANDSTONE)
Block(-8,-10,-6,SANDSTONE)
Block(-8,-10,-5,SANDSTONE)
Block(-8,-10,-4,SANDSTONE)
Block(-8,-10,-3,SANDSTONE)
Block(-8,-10,-2,SANDSTONE)
Block(-8,-10,-1,SANDSTONE)
Block(-8,-10,0,SANDSTONE)
Block(-8,-10,1,SANDSTONE)
Block(-8,-10,2,SANDSTONE)
Block(-8,-10,3,SANDSTONE)
Block(-8,-10,4,SANDSTONE)
Block(-8,-10,5,SANDSTONE)
Block(-8,-10,6,SANDSTONE)
Block(-8,-10,7,SANDSTONE)
Block(-8,-10,8,SANDSTONE)
