
#######################################################################
# +-----------------------------------------------------------------+ #
# |                            BO3 object                           | #
# +-----------------------------------------------------------------+ #
#######################################################################

Author: LordSmellyPants

Description: No description given

Version: 3

SettingsMode: WriteWithoutComments


#######################################################################
# +-----------------------------------------------------------------+ #
# |                          Main settings                          | #
# +-----------------------------------------------------------------+ #
#######################################################################

Tree: true

Frequency: 1

Rarity: 100.0

RotateRandomly: true

SpawnHeight: highestSolidBlock

SpawnHeightOffset: 0

SpawnHeightVariance: 0

##############################
# Height Limits for the BO3. #
##############################

MinHeight: 0

MaxHeight: 256

######################
# Extrusion settings #
######################

ExtrudeMode: None

ExtrudeThroughBlocks: AIR

MaxBranchDepth: 10

ExcludedBiomes: All


#######################################################################
# +-----------------------------------------------------------------+ #
# |                      Source block settings                      | #
# +-----------------------------------------------------------------+ #
#######################################################################

SourceBlocks: AIR

MaxPercentageOutsideSourceBlock: 0

OutsideSourceBlock: placeAnyway


#######################################################################
# +-----------------------------------------------------------------+ #
# |                              Blocks                             | #
# +-----------------------------------------------------------------+ #
#######################################################################

Block(-3,7,-1,LEAVES_2:13)
Block(-3,7,0,LEAVES_2:13)
Block(-3,7,1,LEAVES_2:13)
Block(-3,8,-1,LEAVES_2:13)
Block(-3,8,0,LEAVES_2:13)
Block(-3,8,1,LEAVES_2:13)
Block(-3,8,2,LEAVES_2:13)
Block(-2,7,-1,LEAVES_2:9)
Block(-2,7,0,LEAVES_2:9)
Block(-2,7,1,LEAVES_2:9)
Block(-2,7,2,LEAVES_2:13)
Block(-2,8,-2,LEAVES_2:13)
Block(-2,8,-1,LEAVES_2:9)
Block(-2,8,0,LEAVES_2:9)
Block(-2,8,1,LEAVES_2:9)
Block(-2,8,2,LEAVES_2:9)
Block(-2,9,0,LEAVES_2:13)
Block(-2,9,1,LEAVES_2:13)
Block(-1,6,0,LOG_2:1)
Block(-1,7,-2,LEAVES_2:5)
Block(-1,7,-1,LEAVES_2:9)
Block(-1,7,0,LOG_2:1)
Block(-1,7,1,LEAVES_2:13)
Block(-1,7,2,LEAVES_2:13)
Block(-1,7,3,LEAVES_2:9)
Block(-1,8,-2,LEAVES_2:13)
Block(-1,8,-1,LEAVES_2:9)
Block(-1,8,0,LOG_2:1)
Block(-1,8,1,LEAVES_2:9)
Block(-1,8,2,LEAVES_2:9)
Block(-1,8,3,LEAVES_2:9)
Block(-1,9,-1,LEAVES_2:13)
Block(-1,9,0,LEAVES_2:9)
Block(-1,9,1,LEAVES_2:9)
Block(-1,9,2,LEAVES_2:13)
Block(-1,10,0,LEAVES_2:13)
Block(-1,10,1,LEAVES_2:13)
Block(0,0,0,LOG_2:1)
Block(0,1,0,LOG_2:1)
Block(0,2,0,LOG_2:1)
Block(0,3,0,LOG_2:1)
Block(0,4,0,LOG_2:1)
Block(0,5,0,LOG_2:1)
Block(0,5,1,LOG_2:1)
Block(0,6,0,LOG_2:1)
Block(0,6,1,LOG_2:1)
Block(0,7,-2,LEAVES_2:9)
Block(0,7,-1,LEAVES_2:9)
Block(0,7,0,LOG_2:1)
Block(0,7,1,LOG_2:1)
Block(0,7,2,LEAVES_2:9)
Block(0,7,3,LEAVES_2:9)
Block(0,8,-2,LEAVES_2:9)
Block(0,8,-1,LEAVES_2:9)
Block(0,8,0,LOG_2:1)
Block(0,8,1,LOG_2:1)
Block(0,8,2,LEAVES_2:9)
Block(0,8,3,LEAVES_2:9)
Block(0,9,-1,LEAVES_2:9)
Block(0,9,0,LEAVES_2:9)
Block(0,9,1,LEAVES_2:9)
Block(0,9,2,LEAVES_2:9)
Block(0,10,-1,LEAVES_2:13)
Block(0,10,0,LEAVES_2:13)
Block(0,10,1,LEAVES_2:9)
Block(1,7,-2,LEAVES_2:9)
Block(1,7,-1,LEAVES_2:9)
Block(1,7,0,LEAVES_2:13)
Block(1,7,1,LEAVES_2:5)
Block(1,7,2,LEAVES_2:9)
Block(1,8,-2,LEAVES_2:9)
Block(1,8,-1,LEAVES_2:9)
Block(1,8,0,LEAVES_2:13)
Block(1,8,1,LEAVES_2:5)
Block(1,8,2,LEAVES_2:9)
Block(1,8,3,LEAVES_2:9)
Block(1,9,-1,LEAVES_2:9)
Block(1,9,0,LEAVES_2:9)
Block(1,9,1,LEAVES_2:9)
Block(1,9,2,LEAVES_2:9)
Block(1,10,0,LEAVES_2:9)
Block(2,7,-1,LEAVES_2:9)
Block(2,7,0,LEAVES_2:13)
Block(2,7,1,LEAVES_2:9)
Block(2,7,2,LEAVES_2:9)
Block(2,8,-1,LEAVES_2:9)
Block(2,8,0,LEAVES_2:9)
Block(2,8,1,LEAVES_2:9)
Block(2,8,2,LEAVES_2:9)
Block(2,9,-1,LEAVES_2:9)
Block(2,9,0,LEAVES_2:9)
Block(2,9,1,LEAVES_2:9)
Block(3,7,0,LEAVES_2:13)
Block(3,7,1,LEAVES_2:13)
Block(3,8,0,LEAVES_2:13)
Block(3,8,1,LEAVES_2:13)

#######################################################################
# +-----------------------------------------------------------------+ #
# |                            BO3 checks                           | #
# +-----------------------------------------------------------------+ #
#######################################################################

BlockCheck(0,-1,0,GRASS,DIRT)

#######################################################################
# +-----------------------------------------------------------------+ #
# |                             Branches                            | #
# +-----------------------------------------------------------------+ #
#######################################################################


#######################################################################
# +-----------------------------------------------------------------+ #
# |                         EntityFunctions                         | #
# +-----------------------------------------------------------------+ #
#######################################################################

