
#######################################################################
# +-----------------------------------------------------------------+ #
# |                            BO3 object                           | #
# +-----------------------------------------------------------------+ #
#######################################################################

Author: LordSmellyPants

Description: No description given

Version: 3

SettingsMode: WriteWithoutComments


#######################################################################
# +-----------------------------------------------------------------+ #
# |                          Main settings                          | #
# +-----------------------------------------------------------------+ #
#######################################################################

Tree: true

Frequency: 1

Rarity: 100.0

RotateRandomly: true

SpawnHeight: highestSolidBlock

SpawnHeightOffset: 0

SpawnHeightVariance: 0

##############################
# Height Limits for the BO3. #
##############################

MinHeight: 0

MaxHeight: 256

######################
# Extrusion settings #
######################

ExtrudeMode: None

ExtrudeThroughBlocks: AIR

MaxBranchDepth: 10

ExcludedBiomes: All


#######################################################################
# +-----------------------------------------------------------------+ #
# |                      Source block settings                      | #
# +-----------------------------------------------------------------+ #
#######################################################################

SourceBlocks: STONE:1,STONE:3,STONE:5,DIRT:1,DIRT,SAND,GRASS,DIRT:2,HARD_CLAY,STAINED_CLAY,CLAY,SANDSTONE,SAND:1,AIR,STONE,GRAVEL,LONG_GRASS,LONG_GRASS:1,LONG_GRASS:2,DEAD_BUSH,YELLOW_FLOWER,RED_ROSE,BROWN_MUSHROOM,RED_MUSHROOM

MaxPercentageOutsideSourceBlock: 0

OutsideSourceBlock: placeAnyway

IsOTGPlus: false

InheritBO3: 

InheritBO3Rotation: NORTH

OverrideChildSettings: true

OverrideParentHeight: false

CanOverride: false

BranchFrequency: 0

BranchFrequencyGroup: 

MustBeBelowOther: false

MustBeInside: 

CannotBeInside: 

ReplacesBO3: 

CanSpawnOnWater: true

SpawnOnWaterOnly: false

SpawnUnderWater: false

SpawnAtWaterLevel: false

HeightOffset: 0

RemoveAir: true

ReplaceAbove: 

ReplaceBelow: 

ReplaceWithBiomeBlocks: true

ReplaceWithGroundBlock: DIRT

ReplaceWithSurfaceBlock: GRASS

SmoothRadius: 0

SmoothHeightOffset: 0

SmoothStartTop: false

SmoothStartWood: false

SmoothingSurfaceBlock: 

SmoothingGroundBlock: 

BO3Group: 

IsSpawnPoint: false


#######################################################################
# +-----------------------------------------------------------------+ #
# |                              Blocks                             | #
# +-----------------------------------------------------------------+ #
#######################################################################

Block(-4,2,-2,LEAVES_2:13)
Block(-4,2,-1,LEAVES_2:13)
Block(-4,2,0,LEAVES_2:13)
Block(-4,2,1,LEAVES_2:9)
Block(-4,3,-2,LEAVES_2:13)
Block(-4,3,-1,LEAVES_2:9)
Block(-4,3,0,LEAVES_2:9)
Block(-4,3,1,LEAVES_2:9)
Block(-4,3,2,LEAVES_2:13)
Block(-3,2,-3,LEAVES_2:13)
Block(-3,2,-2,LEAVES_2:13)
Block(-3,2,-1,LEAVES_2:9)
Block(-3,2,0,LEAVES_2:1)
Block(-3,2,1,LEAVES_2:9)
Block(-3,2,2,LEAVES_2:9)
Block(-3,2,3,LEAVES_2:13)
Block(-3,3,-3,LEAVES_2:13)
Block(-3,3,-2,LEAVES_2:13)
Block(-3,3,-1,LEAVES_2:9)
Block(-3,3,0,LEAVES_2:9)
Block(-3,3,1,LEAVES_2:9)
Block(-3,3,2,LEAVES_2:13)
Block(-3,3,3,LEAVES_2:9)
Block(-3,4,-1,LEAVES_2:5)
Block(-3,4,0,LEAVES_2:9)
Block(-3,4,1,LEAVES_2:9)
Block(-2,2,-3,LEAVES_2:13)
Block(-2,2,-2,LEAVES_2:9)
Block(-2,2,-1,LEAVES_2:1)
Block(-2,2,0,LEAVES_2:9)
Block(-2,2,1,LEAVES_2:9)
Block(-2,2,2,LEAVES_2:13)
Block(-2,2,3,LEAVES_2:9)
Block(-2,3,-3,LEAVES_2:9)
Block(-2,3,-2,LEAVES_2:9)
Block(-2,3,-1,LEAVES_2:9)
Block(-2,3,0,LEAVES_2:9)
Block(-2,3,1,LEAVES_2:9)
Block(-2,3,2,LEAVES_2:9)
Block(-2,3,3,LEAVES_2:13)
Block(-2,3,4,LEAVES_2:13)
Block(-2,4,-2,LEAVES_2:13)
Block(-2,4,-1,LEAVES_2:9)
Block(-2,4,0,LEAVES_2:9)
Block(-2,4,1,LEAVES_2:9)
Block(-2,4,2,LEAVES_2:9)
Block(-2,5,0,LEAVES_2:5)
Block(-1,2,-4,LEAVES_2:13)
Block(-1,2,-3,LEAVES_2:13)
Block(-1,2,-2,LEAVES_2:9)
Block(-1,2,-1,LEAVES_2:1)
Block(-1,2,0,LEAVES_2:13)
Block(-1,2,1,LEAVES_2:13)
Block(-1,2,2,LEAVES_2:9)
Block(-1,2,3,LEAVES_2:9)
Block(-1,3,-4,LEAVES_2:13)
Block(-1,3,-3,LEAVES_2:9)
Block(-1,3,-2,LEAVES_2:9)
Block(-1,3,-1,LEAVES_2:1)
Block(-1,3,0,LEAVES_2:13)
Block(-1,3,1,LEAVES_2:13)
Block(-1,3,2,LEAVES_2:9)
Block(-1,3,3,LEAVES_2:9)
Block(-1,3,4,LEAVES_2:9)
Block(-1,4,-2,LEAVES_2:9)
Block(-1,4,-1,LEAVES_2:9)
Block(-1,4,0,LEAVES_2:9)
Block(-1,4,1,LEAVES_2:9)
Block(-1,4,2,LEAVES_2:9)
Block(-1,4,3,LEAVES_2:13)
Block(-1,5,-1,LEAVES_2:5)
Block(-1,5,0,LEAVES_2:5)
Block(-1,5,1,LEAVES_2:5)
Block(0,0,0,LOG_2:1)
Block(0,1,0,LOG_2:1)
Block(0,1,1,LOG_2:1)
Block(0,2,-4,LEAVES_2:5)
Block(0,2,-3,LEAVES_2:9)
Block(0,2,-2,LEAVES_2:1)
Block(0,2,-1,LEAVES_2:1)
Block(0,2,0,LOG_2:1)
Block(0,2,1,LOG_2:1)
Block(0,2,2,LEAVES_2:9)
Block(0,2,3,LEAVES_2:9)
Block(0,2,4,LEAVES_2:13)
Block(0,3,-4,LEAVES_2:13)
Block(0,3,-3,LEAVES_2:9)
Block(0,3,-2,LEAVES_2:9)
Block(0,3,-1,LEAVES_2:1)
Block(0,3,0,LOG_2:1)
Block(0,3,1,LEAVES_2:13)
Block(0,3,2,LEAVES_2:9)
Block(0,3,3,LEAVES_2:9)
Block(0,3,4,LEAVES_2:9)
Block(0,4,-3,LEAVES_2:13)
Block(0,4,-2,LEAVES_2:9)
Block(0,4,-1,LEAVES_2:9)
Block(0,4,0,LEAVES_2:9)
Block(0,4,1,LEAVES_2:9)
Block(0,4,2,LEAVES_2:9)
Block(0,4,3,LEAVES_2:9)
Block(0,5,-1,LEAVES_2:5)
Block(0,5,0,LEAVES_2:5)
Block(0,5,1,LEAVES_2:5)
Block(1,2,-3,LEAVES_2:9)
Block(1,2,-2,LEAVES_2:9)
Block(1,2,-1,LEAVES_2:13)
Block(1,2,0,LEAVES_2:1)
Block(1,2,1,LEAVES_2:9)
Block(1,2,2,LEAVES_2:9)
Block(1,2,3,LEAVES_2:9)
Block(1,2,4,LEAVES_2:13)
Block(1,3,-4,LEAVES_2:13)
Block(1,3,-3,LEAVES_2:9)
Block(1,3,-2,LEAVES_2:9)
Block(1,3,-1,LEAVES_2:9)
Block(1,3,0,LEAVES_2:9)
Block(1,3,1,LEAVES_2:1)
Block(1,3,2,LEAVES_2:9)
Block(1,3,3,LEAVES_2:9)
Block(1,3,4,LEAVES_2:9)
Block(1,4,-2,LEAVES_2:13)
Block(1,4,-1,LEAVES_2:9)
Block(1,4,0,LEAVES_2:9)
Block(1,4,1,LEAVES_2:9)
Block(1,4,2,LEAVES_2:9)
Block(1,4,3,LEAVES_2:13)
Block(1,5,0,LEAVES_2:5)
Block(2,2,-3,LEAVES_2:13)
Block(2,2,-2,LEAVES_2:9)
Block(2,2,-1,LEAVES_2:9)
Block(2,2,0,LEAVES_2:1)
Block(2,2,1,LEAVES_2:9)
Block(2,2,2,LEAVES_2:9)
Block(2,2,3,LEAVES_2:9)
Block(2,3,-3,LEAVES_2:13)
Block(2,3,-2,LEAVES_2:9)
Block(2,3,-1,LEAVES_2:9)
Block(2,3,0,LEAVES_2:9)
Block(2,3,1,LEAVES_2:9)
Block(2,3,2,LEAVES_2:9)
Block(2,3,3,LEAVES_2:13)
Block(2,3,4,LEAVES_2:13)
Block(2,4,-2,LEAVES_2:5)
Block(2,4,-1,LEAVES_2:13)
Block(2,4,0,LEAVES_2:9)
Block(2,4,1,LEAVES_2:9)
Block(2,4,2,LEAVES_2:13)
Block(3,2,-2,LEAVES_2:5)
Block(3,2,-1,LEAVES_2:9)
Block(3,2,0,LEAVES_2:9)
Block(3,2,1,LEAVES_2:13)
Block(3,2,2,LEAVES_2:5)
Block(3,2,3,LEAVES_2:5)
Block(3,3,-3,LEAVES_2:13)
Block(3,3,-2,LEAVES_2:13)
Block(3,3,-1,LEAVES_2:9)
Block(3,3,0,LEAVES_2:9)
Block(3,3,1,LEAVES_2:9)
Block(3,3,2,LEAVES_2:13)
Block(3,3,3,LEAVES_2:13)
Block(3,4,0,LEAVES_2:13)
Block(4,2,-1,LEAVES_2:13)
Block(4,2,0,LEAVES_2:13)
Block(4,3,-1,LEAVES_2:5)
Block(4,3,0,LEAVES_2:13)
Block(4,3,1,LEAVES_2:13)

#######################################################################
# +-----------------------------------------------------------------+ #
# |                            BO3 checks                           | #
# +-----------------------------------------------------------------+ #
#######################################################################

BlockCheck(0,-1,0,GRASS,DIRT)

#######################################################################
# +-----------------------------------------------------------------+ #
# |                             Branches                            | #
# +-----------------------------------------------------------------+ #
#######################################################################


#######################################################################
# +-----------------------------------------------------------------+ #
# |                             Entities                            | #
# +-----------------------------------------------------------------+ #
#######################################################################


#######################################################################
# +-----------------------------------------------------------------+ #
# |                            Particles                            | #
# +-----------------------------------------------------------------+ #
#######################################################################


#######################################################################
# +-----------------------------------------------------------------+ #
# |                             Spawners                            | #
# +-----------------------------------------------------------------+ #
#######################################################################


#######################################################################
# +-----------------------------------------------------------------+ #
# |                             ModData                             | #
# +-----------------------------------------------------------------+ #
#######################################################################

