
#######################################################################
# +-----------------------------------------------------------------+ #
# |                            BO3 object                           | #
# +-----------------------------------------------------------------+ #
#######################################################################

Author: LordSmellyPants

Description: Converted version of the BO2 BlackSpruceL1R2

Version: 3

SettingsMode: WriteWithoutComments


#######################################################################
# +-----------------------------------------------------------------+ #
# |                          Main settings                          | #
# +-----------------------------------------------------------------+ #
#######################################################################

Tree: true

Frequency: 1

Rarity: 20.0

RotateRandomly: true

SpawnHeight: highestSolidBlock

SpawnHeightOffset: 0

SpawnHeightVariance: 0

##############################
# Height Limits for the BO3. #
##############################

MinHeight: 51

MaxHeight: 67

######################
# Extrusion settings #
######################

ExtrudeMode: None

ExtrudeThroughBlocks: AIR

MaxBranchDepth: 10

ExcludedBiomes: All


#######################################################################
# +-----------------------------------------------------------------+ #
# |                      Source block settings                      | #
# +-----------------------------------------------------------------+ #
#######################################################################

SourceBlocks: STONE:1,STONE:3,STONE:5,DIRT:1,DIRT,SAND,GRASS,DIRT:2,STATIONARY_WATER,HARD_CLAY,STAINED_CLAY,CLAY,SANDSTONE,SAND:1,AIR,STONE,GRAVEL,LONG_GRASS,LONG_GRASS:1,LONG_GRASS:2,DEAD_BUSH,YELLOW_FLOWER,RED_ROSE,BROWN_MUSHROOM,RED_MUSHROOM

MaxPercentageOutsideSourceBlock: 0

OutsideSourceBlock: placeAnyway


#######################################################################
# +-----------------------------------------------------------------+ #
# |                              Blocks                             | #
# +-----------------------------------------------------------------+ #
#######################################################################

Block(-1,10,1,LEAVES:13)
Block(-1,11,1,LEAVES:13)
Block(-1,12,1,LEAVES:13)
Block(-1,13,1,LEAVES:5)
Block(-1,14,1,LEAVES:5)
Block(-1,15,1,LEAVES:5)
Block(-1,5,0,LOG:13)
Block(-1,4,0,LOG:13)
Block(-1,7,0,LOG:13)
Block(-1,6,0,LOG:13)
Block(-1,9,0,LOG:13)
Block(-1,8,0,LOG:13)
Block(1,13,1,LEAVES:5)
Block(-1,1,0,LOG:13)
Block(-1,0,0,LOG:13)
Block(-1,3,0,LOG:13)
Block(-1,2,0,LOG:13)
Block(0,5,-1,LEAVES:13)
Block(0,4,-1,LEAVES:13)
Block(0,9,-1,LEAVES:13)
Block(0,8,-1,LEAVES:13)
Block(1,14,-1,LEAVES:5)
Block(1,13,-1,LEAVES:5)
Block(-1,5,-2,LEAVES:13)
Block(-1,4,-2,LEAVES:13)
Block(-1,9,-2,LEAVES:13)
Block(-1,8,-2,LEAVES:13)
Block(-3,5,-1,LEAVES:13)
Block(-3,9,-1,LEAVES:13)
Block(-1,12,2,LEAVES:5)
Block(0,12,-1,LEAVES:5)
Block(-1,13,2,LEAVES:5)
Block(0,13,-1,LEAVES:5)
Block(0,3,0,LEAVES:13)
Block(0,5,0,LEAVES:13)
Block(0,4,0,LEAVES:13)
Block(0,7,0,LEAVES:13)
Block(0,6,0,LEAVES:13)
Block(-2,13,0,LEAVES:5)
Block(-2,12,0,LEAVES:13)
Block(-2,15,0,LEAVES:13)
Block(-2,14,0,LEAVES:13)
Block(-2,11,0,LEAVES:13)
Block(-2,10,0,LEAVES:13)
Block(-1,5,2,LEAVES:13)
Block(-1,4,2,LEAVES:13)
Block(-1,9,2,LEAVES:13)
Block(-1,8,2,LEAVES:13)
Block(-2,9,0,LEAVES:13)
Block(-2,8,0,LEAVES:13)
Block(-2,7,0,LEAVES:13)
Block(-2,6,0,LEAVES:13)
Block(-2,5,0,LEAVES:13)
Block(-2,4,0,LEAVES:13)
Block(-2,3,0,LEAVES:13)
Block(-1,15,0,LEAVES:13)
Block(-1,16,0,LEAVES:13)
Block(-1,17,0,LEAVES:5)
Block(-1,18,0,LEAVES:5)
Block(0,8,1,LEAVES:13)
Block(0,9,1,LEAVES:13)
Block(-1,10,0,LOG:13)
Block(-1,11,0,LOG:13)
Block(-1,12,0,LOG:13)
Block(-1,13,0,LOG:13)
Block(-1,14,0,LOG:13)
Block(1,9,-1,LEAVES:13)
Block(1,5,-1,LEAVES:13)
Block(1,6,-1,LEAVES:13)
Block(-1,4,1,LEAVES:13)
Block(-1,3,1,LEAVES:13)
Block(-1,6,1,LEAVES:13)
Block(-1,5,1,LEAVES:13)
Block(-1,8,1,LEAVES:13)
Block(-1,7,1,LEAVES:13)
Block(-1,9,1,LEAVES:13)
Block(0,9,0,LEAVES:13)
Block(0,8,0,LEAVES:13)
Block(1,9,0,LEAVES:13)
Block(0,5,2,LEAVES:13)
Block(1,8,0,LEAVES:13)
Block(0,13,1,LEAVES:5)
Block(0,12,1,LEAVES:13)
Block(-3,6,0,LEAVES:13)
Block(-3,9,0,LEAVES:13)
Block(-3,8,0,LEAVES:13)
Block(-3,5,0,LEAVES:13)
Block(-3,4,0,LEAVES:13)
Block(-2,9,2,LEAVES:13)
Block(-2,6,2,LEAVES:13)
Block(-2,5,2,LEAVES:13)
Block(-1,10,-2,LEAVES:13)
Block(0,4,1,LEAVES:13)
Block(1,9,1,LEAVES:13)
Block(0,5,1,LEAVES:13)
Block(1,6,1,LEAVES:13)
Block(1,12,0,LEAVES:5)
Block(1,10,0,LEAVES:13)
Block(-1,9,-1,LEAVES:13)
Block(-1,8,-1,LEAVES:13)
Block(0,13,2,LEAVES:5)
Block(0,14,2,LEAVES:5)
Block(1,5,1,LEAVES:13)
Block(-3,10,-1,LEAVES:13)
Block(0,10,2,LEAVES:13)
Block(-3,13,-1,LEAVES:5)
Block(-3,14,-1,LEAVES:13)
Block(-3,13,1,LEAVES:5)
Block(-3,10,1,LEAVES:13)
Block(-1,12,-2,LEAVES:5)
Block(-1,13,-2,LEAVES:5)
Block(-2,13,2,LEAVES:5)
Block(-2,10,2,LEAVES:13)
Block(-1,14,-2,LEAVES:13)
Block(-2,9,-2,LEAVES:13)
Block(-3,9,1,LEAVES:13)
Block(-3,6,1,LEAVES:13)
Block(-3,5,1,LEAVES:13)
Block(0,10,-2,LEAVES:13)
Block(0,13,-2,LEAVES:5)
Block(-2,6,-2,LEAVES:13)
Block(-2,5,-2,LEAVES:13)
Block(-2,13,-2,LEAVES:5)

#######################################################################
# +-----------------------------------------------------------------+ #
# |                            BO3 checks                           | #
# +-----------------------------------------------------------------+ #
#######################################################################

BlockCheck(0,-1,0,GRASS,DIRT,DIRT:2)

#######################################################################
# +-----------------------------------------------------------------+ #
# |                             Branches                            | #
# +-----------------------------------------------------------------+ #
#######################################################################


#######################################################################
# +-----------------------------------------------------------------+ #
# |                         EntityFunctions                         | #
# +-----------------------------------------------------------------+ #
#######################################################################

