
#######################################################################
# +-----------------------------------------------------------------+ #
# |                            BO3 object                           | #
# +-----------------------------------------------------------------+ #
#######################################################################

Author: Unknown

Description: Converted version of the BO2 HugeRedwood2

Version: 3

SettingsMode: WriteWithoutComments


#######################################################################
# +-----------------------------------------------------------------+ #
# |                          Main settings                          | #
# +-----------------------------------------------------------------+ #
#######################################################################

Tree: true

Frequency: 1

Rarity: 10.0

RotateRandomly: true

SpawnHeight: highestSolidBlock

SpawnHeightOffset: 0

SpawnHeightVariance: 0

##############################
# Height Limits for the BO3. #
##############################

MinHeight: 63

MaxHeight: 210

######################
# Extrusion settings #
######################

ExtrudeMode: None

ExtrudeThroughBlocks: AIR

MaxBranchDepth: 10

ExcludedBiomes: All


#######################################################################
# +-----------------------------------------------------------------+ #
# |                      Source block settings                      | #
# +-----------------------------------------------------------------+ #
#######################################################################

SourceBlocks: STONE:1,STONE:3,STONE:5,DIRT:1,DIRT,SAND,GRASS,DIRT:2,STATIONARY_WATER,HARD_CLAY,STAINED_CLAY,CLAY,SANDSTONE,SAND:1,AIR,STONE,GRAVEL,LONG_GRASS,LONG_GRASS:1,LONG_GRASS:2,DEAD_BUSH,YELLOW_FLOWER,RED_ROSE,BROWN_MUSHROOM,RED_MUSHROOM

MaxPercentageOutsideSourceBlock: 0

OutsideSourceBlock: placeAnyway

IsOTGPlus: false

InheritBO3: 

InheritBO3Rotation: NORTH

OverrideChildSettings: true

OverrideParentHeight: false

CanOverride: false

BranchFrequency: 0

BranchFrequencyGroup: 

MustBeBelowOther: false

MustBeInside: 

CannotBeInside: 

ReplacesBO3: 

CanSpawnOnWater: true

SpawnOnWaterOnly: false

SpawnUnderWater: false

SpawnAtWaterLevel: false

HeightOffset: 0

RemoveAir: true

ReplaceAbove: 

ReplaceBelow: 

ReplaceWithBiomeBlocks: true

ReplaceWithGroundBlock: DIRT

ReplaceWithSurfaceBlock: GRASS

SmoothRadius: 0

SmoothHeightOffset: 0

SmoothStartTop: false

SmoothStartWood: false

SmoothingSurfaceBlock: 

SmoothingGroundBlock: 

BO3Group: 

IsSpawnPoint: false


#######################################################################
# +-----------------------------------------------------------------+ #
# |                              Blocks                             | #
# +-----------------------------------------------------------------+ #
#######################################################################

Block(4,40,-2,LEAVES:1)
Block(-4,30,4,LEAVES:1)
Block(-3,32,1,LEAVES:1)
Block(1,48,0,LEAVES:1)
Block(4,44,-2,LEAVES:1)
Block(1,47,0,LEAVES:1)
Block(4,41,-2,LEAVES:1)
Block(2,41,3,LEAVES:1)
Block(1,44,0,LEAVES:1)
Block(1,41,0,LOG:1)
Block(-2,20,-3,LEAVES:1)
Block(2,37,-4,LEAVES:1)
Block(-2,46,-2,LEAVES:1)
Block(2,34,-4,LOG:1)
Block(-2,44,-2,LEAVES:1)
Block(-2,17,-3,LEAVES:1)
Block(1,23,1,LOG:1)
Block(1,24,1,LEAVES:1)
Block(1,28,1,LEAVES:1)
Block(4,19,-3,LOG:1)
Block(8,28,0,LEAVES:1)
Block(1,51,0,LEAVES:1)
Block(-2,42,-2,LEAVES:1)
Block(-2,33,-2,LEAVES:1)
Block(2,44,-4,LEAVES:1)
Block(-2,38,-2,LEAVES:1)
Block(2,40,-4,LOG:1)
Block(1,18,1,LOG:1)
Block(5,34,-7,LEAVES:1)
Block(-3,24,2,LEAVES:1)
Block(1,19,-1,LOG:1)
Block(1,18,-1,LOG:1)
Block(1,17,-1,LOG:1)
Block(1,16,-1,LOG:1)
Block(1,15,-1,LOG:1)
Block(1,14,-1,LOG:1)
Block(5,28,1,LEAVES:1)
Block(-2,42,-3,LEAVES:1)
Block(0,42,-5,LEAVES:1)
Block(-2,38,-3,LEAVES:1)
Block(1,13,-1,LOG:1)
Block(1,12,-1,LOG:1)
Block(1,11,-1,LOG:1)
Block(1,48,1,LEAVES:1)
Block(1,10,-1,LOG:1)
Block(0,44,-5,LEAVES:1)
Block(1,18,2,LEAVES:1)
Block(-3,30,2,LEAVES:1)
Block(-6,32,0,LEAVES:1)
Block(4,28,-2,LOG:1)
Block(5,34,-6,LEAVES:1)
Block(5,41,0,LEAVES:1)
Block(-3,39,2,LEAVES:1)
Block(2,30,3,LOG:1)
Block(-5,32,-4,LEAVES:1)
Block(2,31,3,LEAVES:1)
Block(-2,32,-3,LEAVES:1)
Block(6,28,-1,LEAVES:1)
Block(-2,31,-3,LEAVES:1)
Block(-2,26,-3,LEAVES:1)
Block(-2,24,-3,LEAVES:1)
Block(1,30,1,LOG:1)
Block(1,31,1,LEAVES:1)
Block(2,34,-5,LEAVES:1)
Block(-2,29,-3,LEAVES:1)
Block(0,26,-6,LEAVES:1)
Block(5,40,-6,LEAVES:1)
Block(4,19,-2,LEAVES:1)
Block(6,28,-2,LEAVES:1)
Block(0,0,0,LOG:1)
Block(4,28,0,LEAVES:1)
Block(2,30,2,LOG:1)
Block(6,30,3,LEAVES:1)
Block(4,22,-4,LEAVES:1)
Block(3,30,5,LEAVES:1)
Block(2,31,2,LEAVES:1)
Block(-2,32,-4,LEAVES:1)
Block(4,22,0,LEAVES:1)
Block(-2,33,-4,LEAVES:1)
Block(2,29,-3,LEAVES:1)
Block(2,24,-3,LEAVES:1)
Block(7,34,-6,LEAVES:1)
Block(1,8,-2,LOG:1)
Block(2,22,-3,LEAVES:1)
Block(1,30,2,LEAVES:1)
Block(1,9,-2,LOG:1)
Block(1,31,2,LEAVES:1)
Block(1,6,-2,LOG:1)
Block(-2,24,-4,LEAVES:1)
Block(2,52,-2,LEAVES:1)
Block(1,7,-2,LOG:1)
Block(1,4,-2,LOG:1)
Block(-2,26,-4,LEAVES:1)
Block(1,5,-2,LOG:1)
Block(1,2,-2,LOG:1)
Block(1,3,-2,LOG:1)
Block(1,0,-2,LOG:1)
Block(1,1,-2,LOG:1)
Block(0,26,-5,LEAVES:1)
Block(5,22,0,LEAVES:1)
Block(4,40,-3,LEAVES:1)
Block(2,41,2,LEAVES:1)
Block(-2,27,0,LEAVES:1)
Block(-2,20,-4,LEAVES:1)
Block(-2,24,0,LOG:1)
Block(5,28,0,LEAVES:1)
Block(2,18,3,LEAVES:1)
Block(6,19,-2,LEAVES:1)
Block(-7,30,1,LEAVES:1)
Block(-2,46,-3,LEAVES:1)
Block(2,34,-3,LEAVES:1)
Block(1,52,1,LEAVES:1)
Block(1,23,2,LEAVES:1)
Block(0,34,-5,LEAVES:1)
Block(4,19,-4,LEAVES:1)
Block(-3,31,3,LEAVES:1)
Block(1,-3,-1,LOG:1)
Block(4,34,-3,LEAVES:1)
Block(1,-2,-1,LOG:1)
Block(1,-1,-1,LOG:1)
Block(-3,39,3,LEAVES:1)
Block(-5,32,-3,LEAVES:1)
Block(-2,24,-5,LEAVES:1)
Block(2,19,-4,LEAVES:1)
Block(-2,20,-5,LEAVES:1)
Block(2,46,-3,LEAVES:1)
Block(1,9,-1,LOG:1)
Block(2,44,-3,LEAVES:1)
Block(1,7,-1,LOG:1)
Block(1,8,-1,LOG:1)
Block(1,5,-1,LOG:1)
Block(2,40,-3,LEAVES:1)
Block(1,6,-1,LOG:1)
Block(1,3,-1,LOG:1)
Block(1,4,-1,LOG:1)
Block(8,28,-1,LEAVES:1)
Block(4,37,-3,LEAVES:1)
Block(1,1,-1,LOG:1)
Block(1,2,-1,LOG:1)
Block(0,33,-4,LEAVES:1)
Block(0,38,-4,LEAVES:1)
Block(1,0,-1,LOG:1)
Block(0,39,-4,LEAVES:1)
Block(4,-3,-5,LOG:1)
Block(2,23,2,LEAVES:1)
Block(-4,32,-3,LOG:1)
Block(4,22,-3,LEAVES:1)
Block(-4,38,-3,LEAVES:1)
Block(-1,-1,-1,LOG:1)
Block(-2,42,-4,LOG:1)
Block(1,41,2,LEAVES:1)
Block(0,42,-4,LEAVES:1)
Block(0,-1,0,LOG:1)
Block(-2,38,-4,LOG:1)
Block(0,46,-4,LEAVES:1)
Block(1,18,3,LEAVES:1)
Block(-6,30,1,LEAVES:1)
Block(4,28,-3,LEAVES:1)
Block(-4,42,-3,LEAVES:1)
Block(4,34,-5,LEAVES:1)
Block(-1,27,-1,LEAVES:1)
Block(-1,23,-1,LEAVES:1)
Block(3,34,-6,LEAVES:1)
Block(-2,52,0,LEAVES:1)
Block(-5,17,-3,LEAVES:1)
Block(-1,24,-1,LOG:1)
Block(2,28,1,LEAVES:1)
Block(-1,25,-1,LEAVES:1)
Block(-1,30,-1,LOG:1)
Block(-4,39,1,LEAVES:1)
Block(-2,30,1,LEAVES:1)
Block(-1,31,-1,LEAVES:1)
Block(-1,32,-1,LEAVES:1)
Block(0,19,1,LEAVES:1)
Block(0,18,1,LEAVES:1)
Block(3,40,-6,LEAVES:1)
Block(6,28,-3,LEAVES:1)
Block(3,30,4,LEAVES:1)
Block(-2,39,1,LOG:1)
Block(2,31,1,LEAVES:1)
Block(-5,32,-2,LEAVES:1)
Block(-4,31,1,LEAVES:1)
Block(-4,30,1,LOG:1)
Block(2,37,1,LEAVES:1)
Block(-2,31,1,LEAVES:1)
Block(1,30,3,LEAVES:1)
Block(-1,-2,0,LOG:1)
Block(-1,-3,0,LOG:1)
Block(-5,30,4,LEAVES:1)
Block(2,1,-3,LOG:1)
Block(2,0,-3,LOG:1)
Block(0,31,0,LEAVES:1)
Block(0,30,0,LOG:1)
Block(2,31,0,LEAVES:1)
Block(2,33,0,LEAVES:1)
Block(4,40,-4,LEAVES:1)
Block(-2,39,0,LEAVES:1)
Block(3,41,4,LEAVES:1)
Block(2,30,0,LEAVES:1)
Block(2,39,0,LEAVES:1)
Block(-4,32,2,LEAVES:1)
Block(0,19,0,LEAVES:1)
Block(2,-2,2,LOG:1)
Block(-2,30,0,LOG:1)
Block(-2,33,0,LEAVES:1)
Block(2,37,0,LEAVES:1)
Block(-2,32,0,LEAVES:1)
Block(0,25,0,LEAVES:1)
Block(0,24,0,LEAVES:1)
Block(1,30,4,LOG:1)
Block(0,23,0,LEAVES:1)
Block(-2,16,-1,LEAVES:1)
Block(0,29,0,LEAVES:1)
Block(-2,17,-1,LOG:1)
Block(0,28,0,LEAVES:1)
Block(4,19,-5,LEAVES:1)
Block(-2,18,-1,LEAVES:1)
Block(-1,19,-1,LEAVES:1)
Block(5,28,-4,LEAVES:1)
Block(4,34,-4,LEAVES:1)
Block(2,41,0,LOG:1)
Block(-1,16,-1,LEAVES:1)
Block(2,18,1,LEAVES:1)
Block(-1,17,-1,LOG:1)
Block(-2,48,0,LEAVES:1)
Block(-1,18,-1,LEAVES:1)
Block(-5,17,-2,LEAVES:1)
Block(2,46,0,LEAVES:1)
Block(0,18,0,LOG:1)
Block(-2,-2,-2,LOG:1)
Block(-2,-1,-2,LOG:1)
Block(6,40,-3,LEAVES:1)
Block(-4,33,-2,LEAVES:1)
Block(-4,32,-2,LEAVES:1)
Block(-4,31,-2,LEAVES:1)
Block(0,4,-2,LOG:1)
Block(0,3,-2,LOG:1)
Block(0,6,-2,LOG:1)
Block(0,5,-2,LOG:1)
Block(0,8,-2,LOG:1)
Block(0,7,-2,LOG:1)
Block(0,9,-2,LOG:1)
Block(-4,30,0,LEAVES:1)
Block(-1,38,-2,LEAVES:1)
Block(-1,39,-2,LEAVES:1)
Block(-2,39,2,LEAVES:1)
Block(4,40,-6,LEAVES:1)
Block(0,0,-2,LOG:1)
Block(0,2,-2,LOG:1)
Block(0,1,-2,LOG:1)
Block(-2,33,-1,LEAVES:1)
Block(-2,38,-1,LEAVES:1)
Block(-4,24,0,LEAVES:1)
Block(-2,-3,-3,LOG:1)
Block(-2,-2,-3,LOG:1)
Block(0,51,1,LEAVES:1)
Block(2,40,-5,LEAVES:1)
Block(3,41,2,LEAVES:1)
Block(0,23,2,LOG:1)
Block(-4,24,-2,LEAVES:1)
Block(0,53,1,LEAVES:1)
Block(0,52,1,LEAVES:1)
Block(4,34,-6,LEAVES:1)
Block(2,23,0,LEAVES:1)
Block(3,34,-5,LOG:1)
Block(-1,19,-3,LEAVES:1)
Block(7,28,1,LEAVES:1)
Block(-2,30,-1,LEAVES:1)
Block(-2,31,-1,LEAVES:1)
Block(-1,46,-2,LEAVES:1)
Block(2,27,0,LEAVES:1)
Block(-1,48,-2,LEAVES:1)
Block(-3,17,-1,LEAVES:1)
Block(1,34,-6,LEAVES:1)
Block(0,48,1,LEAVES:1)
Block(-1,52,-2,LEAVES:1)
Block(-4,17,0,LEAVES:1)
Block(0,18,2,LEAVES:1)
Block(0,46,1,LEAVES:1)
Block(-1,54,-2,LEAVES:1)
Block(-2,27,-1,LEAVES:1)
Block(0,49,1,LEAVES:1)
Block(-1,51,-2,LEAVES:1)
Block(0,44,1,LEAVES:1)
Block(0,41,1,LEAVES:1)
Block(5,28,-5,LEAVES:1)
Block(3,40,-5,LEAVES:1)
Block(3,30,3,LEAVES:1)
Block(2,40,-6,LEAVES:1)
Block(-3,30,-1,LEAVES:1)
Block(-1,16,-2,LEAVES:1)
Block(-1,48,-1,LEAVES:1)
Block(-1,17,-2,LEAVES:1)
Block(7,28,0,LEAVES:1)
Block(-2,32,-2,LOG:1)
Block(0,0,-3,LOG:1)
Block(-5,17,-1,LEAVES:1)
Block(-1,51,-1,LEAVES:1)
Block(-1,20,-2,LEAVES:1)
Block(-2,24,-2,LOG:1)
Block(-1,53,-1,LEAVES:1)
Block(5,30,2,LEAVES:1)
Block(-2,0,-2,LOG:1)
Block(-4,32,-1,LOG:1)
Block(-4,31,-1,LEAVES:1)
Block(0,31,1,LEAVES:1)
Block(-1,27,-2,LEAVES:1)
Block(-1,29,-2,LEAVES:1)
Block(2,34,-6,LEAVES:1)
Block(2,-1,1,LOG:1)
Block(-2,20,-2,LEAVES:1)
Block(-1,24,-2,LEAVES:1)
Block(-7,30,3,LEAVES:1)
Block(-2,51,-1,LEAVES:1)
Block(-3,39,-1,LEAVES:1)
Block(0,25,1,LEAVES:1)
Block(-1,31,-2,LEAVES:1)
Block(-2,46,-1,LEAVES:1)
Block(-1,32,-2,LOG:1)
Block(0,23,1,LEAVES:1)
Block(-1,33,-2,LEAVES:1)
Block(-2,44,-1,LEAVES:1)
Block(-2,49,-1,LEAVES:1)
Block(-2,17,-2,LEAVES:1)
Block(-2,16,-2,LEAVES:1)
Block(-4,32,0,LEAVES:1)
Block(0,27,1,LEAVES:1)
Block(-2,48,-1,LEAVES:1)
Block(-3,32,-1,LEAVES:1)
Block(-4,24,-1,LEAVES:1)
Block(-2,19,-2,LEAVES:1)
Block(5,34,-5,LEAVES:1)
Block(0,54,0,LEAVES:1)
Block(0,52,0,LEAVES:1)
Block(0,51,0,LEAVES:1)
Block(0,27,-1,LOG:1)
Block(0,26,-1,LOG:1)
Block(0,29,-1,LOG:1)
Block(0,28,-1,LOG:1)
Block(-1,50,0,LEAVES:1)
Block(7,28,2,LEAVES:1)
Block(1,30,6,LEAVES:1)
Block(3,40,-3,LEAVES:1)
Block(4,30,4,LEAVES:1)
Block(-1,46,-3,LEAVES:1)
Block(-1,49,-3,LEAVES:1)
Block(-1,48,0,LEAVES:1)
Block(-1,18,1,LEAVES:1)
Block(3,37,1,LEAVES:1)
Block(1,34,-5,LOG:1)
Block(-1,20,-4,LOG:1)
Block(0,39,3,LEAVES:1)
Block(0,21,-1,LOG:1)
Block(0,20,-1,LOG:1)
Block(0,23,-1,LOG:1)
Block(-1,44,0,LEAVES:1)
Block(0,22,-1,LOG:1)
Block(-3,46,-1,LEAVES:1)
Block(-3,17,-2,LOG:1)
Block(0,25,-1,LOG:1)
Block(0,30,3,LEAVES:1)
Block(0,24,-1,LOG:1)
Block(0,38,-1,LOG:1)
Block(5,22,-2,LEAVES:1)
Block(0,37,-1,LOG:1)
Block(0,39,-1,LOG:1)
Block(-3,31,-2,LEAVES:1)
Block(5,28,-2,LEAVES:1)
Block(-1,29,-4,LEAVES:1)
Block(-1,26,-4,LOG:1)
Block(4,41,4,LEAVES:1)
Block(2,0,1,LOG:1)
Block(4,41,3,LEAVES:1)
Block(1,26,-5,LEAVES:1)
Block(0,30,-1,LOG:1)
Block(-1,52,0,LEAVES:1)
Block(0,23,3,LEAVES:1)
Block(0,32,-1,LOG:1)
Block(-1,53,0,LEAVES:1)
Block(0,31,-1,LOG:1)
Block(3,41,1,LEAVES:1)
Block(0,-1,-3,LOG:1)
Block(0,34,-1,LOG:1)
Block(-1,24,1,LEAVES:1)
Block(0,33,-1,LOG:1)
Block(1,20,-5,LEAVES:1)
Block(-1,25,1,LEAVES:1)
Block(0,36,-1,LOG:1)
Block(0,35,-1,LOG:1)
Block(0,5,-1,LOG:1)
Block(0,4,-1,LOG:1)
Block(0,7,-1,LOG:1)
Block(0,6,-1,LOG:1)
Block(0,9,-1,LOG:1)
Block(0,8,-1,LOG:1)
Block(5,28,-1,LOG:1)
Block(3,34,-4,LEAVES:1)
Block(3,0,-2,LOG:1)
Block(0,1,-1,LOG:1)
Block(-1,25,-3,LEAVES:1)
Block(0,0,-1,LOG:1)
Block(-1,24,-3,LEAVES:1)
Block(0,3,-1,LOG:1)
Block(0,2,-1,LOG:1)
Block(-2,23,3,LEAVES:1)
Block(-1,26,-3,LEAVES:1)
Block(6,28,0,LOG:1)
Block(-5,30,1,LEAVES:1)
Block(-1,38,1,LEAVES:1)
Block(-1,39,1,LEAVES:1)
Block(3,37,-4,LEAVES:1)
Block(-1,30,1,LEAVES:1)
Block(-3,33,-2,LEAVES:1)
Block(-1,31,1,LEAVES:1)
Block(-3,32,-2,LOG:1)
Block(-4,32,-7,LEAVES:1)
Block(0,16,-1,LOG:1)
Block(0,15,-1,LOG:1)
Block(0,18,-1,LOG:1)
Block(0,17,-1,LOG:1)
Block(0,19,-1,LOG:1)
Block(-2,39,3,LEAVES:1)
Block(-1,36,-3,LEAVES:1)
Block(-1,38,-3,LOG:1)
Block(-1,42,-3,LOG:1)
Block(1,46,-5,LEAVES:1)
Block(0,31,2,LEAVES:1)
Block(0,10,-1,LOG:1)
Block(3,30,2,LEAVES:1)
Block(3,31,2,LEAVES:1)
Block(0,12,-1,LOG:1)
Block(0,11,-1,LOG:1)
Block(-1,46,1,LEAVES:1)
Block(0,14,-1,LOG:1)
Block(0,13,-1,LOG:1)
Block(0,30,2,LEAVES:1)
Block(5,28,-3,LOG:1)
Block(-3,32,-3,LEAVES:1)
Block(3,33,-2,LEAVES:1)
Block(-1,26,-5,LEAVES:1)
Block(1,20,-4,LEAVES:1)
Block(3,28,0,LEAVES:1)
Block(1,22,-4,LEAVES:1)
Block(3,27,0,LEAVES:1)
Block(-1,34,-5,LEAVES:1)
Block(3,-2,-4,LOG:1)
Block(6,34,-7,LEAVES:1)
Block(3,-1,-4,LOG:1)
Block(1,24,-4,LEAVES:1)
Block(3,37,-2,LEAVES:1)
Block(1,26,-4,LEAVES:1)
Block(3,22,0,LEAVES:1)
Block(-3,26,-3,LEAVES:1)
Block(5,37,-3,LEAVES:1)
Block(3,44,-2,LEAVES:1)
Block(-1,38,-5,LEAVES:1)
Block(3,19,-3,LEAVES:1)
Block(-1,16,0,LEAVES:1)
Block(1,44,-3,LEAVES:1)
Block(-1,42,-5,LEAVES:1)
Block(1,16,-4,LEAVES:1)
Block(1,48,-3,LEAVES:1)
Block(3,31,0,LEAVES:1)
Block(3,30,0,LEAVES:1)
Block(-3,38,-3,LEAVES:1)
Block(0,30,4,LEAVES:1)
Block(1,40,-3,LOG:1)
Block(5,37,-2,LEAVES:1)
Block(-3,20,-4,LEAVES:1)
Block(3,22,-3,LOG:1)
Block(3,0,-4,LOG:1)
Block(-6,32,-2,LEAVES:1)
Block(-1,44,-4,LEAVES:1)
Block(-1,29,0,LEAVES:1)
Block(0,23,4,LEAVES:1)
Block(-3,44,-3,LEAVES:1)
Block(3,41,0,LEAVES:1)
Block(-1,24,0,LEAVES:1)
Block(1,40,-4,LEAVES:1)
Block(-3,32,-4,LEAVES:1)
Block(5,19,-3,LEAVES:1)
Block(3,33,-3,LEAVES:1)
Block(-1,24,-5,LEAVES:1)
Block(-5,32,2,LEAVES:1)
Block(1,34,-4,LEAVES:1)
Block(-1,39,0,LOG:1)
Block(1,36,-4,LEAVES:1)
Block(3,37,-3,LOG:1)
Block(3,36,-3,LEAVES:1)
Block(-5,30,2,LOG:1)
Block(-3,26,-4,LEAVES:1)
Block(-1,31,0,LEAVES:1)
Block(-3,24,-4,LEAVES:1)
Block(-1,32,0,LEAVES:1)
Block(-1,33,0,LEAVES:1)
Block(3,22,1,LEAVES:1)
Block(-3,42,-4,LEAVES:1)
Block(1,48,-2,LEAVES:1)
Block(1,18,-3,LEAVES:1)
Block(2,18,-2,LEAVES:1)
Block(2,19,-2,LEAVES:1)
Block(3,22,-1,LOG:1)
Block(2,47,-1,LEAVES:1)
Block(-1,38,-6,LEAVES:1)
Block(2,49,-1,LEAVES:1)
Block(4,31,1,LEAVES:1)
Block(-2,42,-5,LEAVES:1)
Block(1,40,-2,LOG:1)
Block(3,28,-1,LEAVES:1)
Block(2,44,-1,LEAVES:1)
Block(0,40,-3,LEAVES:1)
Block(3,24,-1,LEAVES:1)
Block(-2,38,-5,LEAVES:1)
Block(2,41,-1,LEAVES:1)
Block(1,46,-2,LEAVES:1)
Block(0,44,-3,LEAVES:1)
Block(-6,30,2,LEAVES:1)
Block(0,16,-4,LEAVES:1)
Block(0,48,-3,LEAVES:1)
Block(-6,32,2,LEAVES:1)
Block(-3,38,-4,LEAVES:1)
Block(-1,39,3,LEAVES:1)
Block(6,28,2,LEAVES:1)
Block(1,-1,0,LOG:1)
Block(-3,20,-5,LEAVES:1)
Block(4,28,1,LEAVES:1)
Block(1,37,-2,LOG:1)
Block(1,38,-2,LOG:1)
Block(2,29,-2,LEAVES:1)
Block(1,39,-2,LOG:1)
Block(2,27,-2,LEAVES:1)
Block(1,30,-2,LOG:1)
Block(1,31,-2,LOG:1)
Block(2,22,-2,LOG:1)
Block(1,32,-2,LOG:1)
Block(1,33,-2,LOG:1)
Block(0,20,-4,LEAVES:1)
Block(2,20,-2,LEAVES:1)
Block(1,34,-2,LOG:1)
Block(0,52,-3,LEAVES:1)
Block(1,35,-2,LOG:1)
Block(3,36,-1,LEAVES:1)
Block(2,52,-1,LEAVES:1)
Block(1,36,-2,LOG:1)
Block(3,37,-1,LEAVES:1)
Block(0,24,-4,LOG:1)
Block(0,26,-4,LEAVES:1)
Block(-4,32,-4,LEAVES:1)
Block(-4,38,-4,LEAVES:1)
Block(-1,30,4,LEAVES:1)
Block(3,41,-1,LEAVES:1)
Block(1,39,-3,LEAVES:1)
Block(2,37,-2,LOG:1)
Block(3,-3,1,LOG:1)
Block(1,31,-3,LEAVES:1)
Block(3,19,-2,LOG:1)
Block(3,-2,1,LOG:1)
Block(1,33,-3,LEAVES:1)
Block(2,33,-2,LEAVES:1)
Block(1,34,-3,LOG:1)
Block(2,31,-2,LEAVES:1)
Block(1,36,-3,LEAVES:1)
Block(1,37,-3,LEAVES:1)
Block(0,50,-2,LEAVES:1)
Block(0,53,-2,LEAVES:1)
Block(0,52,-2,LEAVES:1)
Block(0,20,-3,LOG:1)
Block(-1,23,4,LEAVES:1)
Block(0,54,-2,LEAVES:1)
Block(0,26,-3,LOG:1)
Block(0,27,-3,LEAVES:1)
Block(0,24,-3,LEAVES:1)
Block(0,25,-3,LEAVES:1)
Block(0,39,-3,LEAVES:1)
Block(-3,42,-5,LEAVES:1)
Block(3,20,-2,LEAVES:1)
Block(1,27,-3,LEAVES:1)
Block(1,28,-3,LEAVES:1)
Block(-3,17,0,LEAVES:1)
Block(2,19,-3,LOG:1)
Block(3,22,-2,LEAVES:1)
Block(2,47,-2,LEAVES:1)
Block(-2,20,-6,LEAVES:1)
Block(3,28,-2,LOG:1)
Block(2,44,-2,LEAVES:1)
Block(1,24,-3,LOG:1)
Block(3,27,-2,LEAVES:1)
Block(0,33,-3,LEAVES:1)
Block(0,31,-3,LEAVES:1)
Block(0,32,-3,LEAVES:1)
Block(1,1,0,LOG:1)
Block(1,0,0,LOG:1)
Block(1,50,-2,LEAVES:1)
Block(0,39,-2,LOG:1)
Block(0,38,-2,LOG:1)
Block(1,38,-1,LEAVES:1)
Block(-3,24,0,LEAVES:1)
Block(-1,30,2,LEAVES:1)
Block(4,41,2,LEAVES:1)
Block(0,31,-2,LOG:1)
Block(-1,52,1,LEAVES:1)
Block(0,30,-2,LOG:1)
Block(0,33,-2,LOG:1)
Block(1,33,-1,LOG:1)
Block(0,32,-2,LOG:1)
Block(1,32,-1,LOG:1)
Block(0,-2,-4,LOG:1)
Block(1,31,-1,LOG:1)
Block(0,35,-2,LOG:1)
Block(0,-3,-4,LOG:1)
Block(1,30,-1,LOG:1)
Block(-3,30,0,LEAVES:1)
Block(0,34,-2,LOG:1)
Block(0,37,-2,LOG:1)
Block(-4,32,-5,LEAVES:1)
Block(0,36,-2,LOG:1)
Block(1,19,0,LEAVES:1)
Block(1,18,0,LEAVES:1)
Block(0,49,-2,LEAVES:1)
Block(-3,31,0,LEAVES:1)
Block(0,18,-3,LEAVES:1)
Block(1,29,-1,LOG:1)
Block(1,28,-1,LOG:1)
Block(1,27,-1,LOG:1)
Block(-1,1,-1,LOG:1)
Block(1,26,-1,LOG:1)
Block(-1,0,-1,LOG:1)
Block(1,25,-1,LOG:1)
Block(2,18,-1,LEAVES:1)
Block(-3,39,0,LEAVES:1)
Block(2,19,-1,LEAVES:1)
Block(2,16,-1,LEAVES:1)
Block(4,31,2,LEAVES:1)
Block(-2,42,-6,LEAVES:1)
Block(4,30,2,LEAVES:1)
Block(-1,39,2,LEAVES:1)
Block(-5,32,0,LOG:1)
Block(-2,38,-6,LEAVES:1)
Block(-5,30,0,LEAVES:1)
Block(0,40,-2,LOG:1)
Block(1,24,-1,LOG:1)
Block(0,42,-2,LOG:1)
Block(1,23,-1,LOG:1)
Block(0,41,-2,LOG:1)
Block(1,22,-1,LOG:1)
Block(4,22,-1,LEAVES:1)
Block(0,44,-2,LOG:1)
Block(1,21,-1,LOG:1)
Block(0,43,-2,LOG:1)
Block(1,20,-1,LOG:1)
Block(4,28,-1,LEAVES:1)
Block(-4,42,-5,LEAVES:1)
Block(0,46,-2,LOG:1)
Block(0,45,-2,LOG:1)
Block(0,48,-2,LEAVES:1)
Block(0,47,-2,LOG:1)
Block(0,17,-2,LOG:1)
Block(-3,42,-6,LEAVES:1)
Block(0,49,-1,LOG:1)
Block(0,16,-2,LOG:1)
Block(1,29,0,LEAVES:1)
Block(0,48,-1,LOG:1)
Block(0,19,-2,LOG:1)
Block(0,18,-2,LOG:1)
Block(1,24,0,LEAVES:1)
Block(2,31,4,LEAVES:1)
Block(1,23,0,LOG:1)
Block(1,22,0,LEAVES:1)
Block(1,26,-2,LOG:1)
Block(2,29,-1,LEAVES:1)
Block(1,27,-2,LOG:1)
Block(2,28,-1,LOG:1)
Block(1,20,0,LEAVES:1)
Block(1,28,-2,LOG:1)
Block(1,29,-2,LOG:1)
Block(2,25,-1,LEAVES:1)
Block(-2,42,-7,LEAVES:1)
Block(2,24,-1,LEAVES:1)
Block(4,31,3,LEAVES:1)
Block(1,20,-2,LOG:1)
Block(1,21,-2,LOG:1)
Block(2,22,-1,LEAVES:1)
Block(1,22,-2,LOG:1)
Block(1,23,-2,LOG:1)
Block(3,-1,-2,LOG:1)
Block(1,24,-2,LOG:1)
Block(1,25,-2,LOG:1)
Block(0,41,-1,LOG:1)
Block(2,30,4,LEAVES:1)
Block(-5,32,-6,LEAVES:1)
Block(0,40,-1,LOG:1)
Block(0,11,-2,LOG:1)
Block(0,43,-1,LOG:1)
Block(1,-3,2,LOG:1)
Block(0,10,-2,LOG:1)
Block(0,42,-1,LOG:1)
Block(0,13,-2,LOG:1)
Block(0,45,-1,LOG:1)
Block(0,12,-2,LOG:1)
Block(0,44,-1,LOG:1)
Block(0,15,-2,LOG:1)
Block(0,47,-1,LOG:1)
Block(1,51,-1,LEAVES:1)
Block(0,14,-2,LOG:1)
Block(0,46,-1,LOG:1)
Block(0,28,-2,LOG:1)
Block(0,27,-2,LOG:1)
Block(1,39,0,LEAVES:1)
Block(0,29,-2,LOG:1)
Block(1,38,0,LEAVES:1)
Block(1,48,-1,LEAVES:1)
Block(1,47,-1,LEAVES:1)
Block(1,15,-2,LOG:1)
Block(1,16,-2,LOG:1)
Block(2,39,-1,LEAVES:1)
Block(1,17,-2,LOG:1)
Block(1,31,0,LEAVES:1)
Block(1,18,-2,LOG:1)
Block(1,19,-2,LOG:1)
Block(-6,32,-5,LEAVES:1)
Block(2,-1,-3,LOG:1)
Block(2,-2,-3,LOG:1)
Block(2,37,-1,LEAVES:1)
Block(2,31,-1,LEAVES:1)
Block(1,10,-2,LOG:1)
Block(2,33,-1,LEAVES:1)
Block(1,11,-2,LOG:1)
Block(1,12,-2,LOG:1)
Block(1,13,-2,LOG:1)
Block(0,50,-1,LOG:1)
Block(1,14,-2,LOG:1)
Block(0,20,-2,LOG:1)
Block(1,46,-1,LEAVES:1)
Block(0,52,-1,LOG:1)
Block(0,51,-1,LOG:1)
Block(0,22,-2,LOG:1)
Block(1,44,-1,LEAVES:1)
Block(0,54,-1,LOG:1)
Block(0,21,-2,LOG:1)
Block(0,53,-1,LOG:1)
Block(0,24,-2,LOG:1)
Block(-3,30,1,LOG:1)
Block(0,23,-2,LOG:1)
Block(-3,31,1,LEAVES:1)
Block(4,-2,-2,LOG:1)
Block(0,26,-2,LOG:1)
Block(4,-3,-2,LOG:1)
Block(0,25,-2,LOG:1)
Block(6,28,1,LEAVES:1)

#######################################################################
# +-----------------------------------------------------------------+ #
# |                            BO3 checks                           | #
# +-----------------------------------------------------------------+ #
#######################################################################

BlockCheck(0,-1,0,GRASS,DIRT,DIRT:2)

#######################################################################
# +-----------------------------------------------------------------+ #
# |                             Branches                            | #
# +-----------------------------------------------------------------+ #
#######################################################################


#######################################################################
# +-----------------------------------------------------------------+ #
# |                             Entities                            | #
# +-----------------------------------------------------------------+ #
#######################################################################


#######################################################################
# +-----------------------------------------------------------------+ #
# |                            Particles                            | #
# +-----------------------------------------------------------------+ #
#######################################################################


#######################################################################
# +-----------------------------------------------------------------+ #
# |                             Spawners                            | #
# +-----------------------------------------------------------------+ #
#######################################################################


#######################################################################
# +-----------------------------------------------------------------+ #
# |                             ModData                             | #
# +-----------------------------------------------------------------+ #
#######################################################################

