
#######################################################################
# +-----------------------------------------------------------------+ #
# |                            BO3 object                           | #
# +-----------------------------------------------------------------+ #
#######################################################################

Author: LordSmellyPants

Description: No description given

Version: 3

SettingsMode: WriteWithoutComments


#######################################################################
# +-----------------------------------------------------------------+ #
# |                          Main settings                          | #
# +-----------------------------------------------------------------+ #
#######################################################################

Tree: true

Frequency: 1

Rarity: 100.0

RotateRandomly: true

SpawnHeight: highestSolidBlock

SpawnHeightOffset: 0

SpawnHeightVariance: 0

##############################
# Height Limits for the BO3. #
##############################

MinHeight: 63

MaxHeight: 70

######################
# Extrusion settings #
######################

ExtrudeMode: None

ExtrudeThroughBlocks: AIR

MaxBranchDepth: 10

ExcludedBiomes: All


#######################################################################
# +-----------------------------------------------------------------+ #
# |                      Source block settings                      | #
# +-----------------------------------------------------------------+ #
#######################################################################

SourceBlocks: STONE:1,STONE:3,STONE:5,DIRT:1,DIRT,SAND,GRASS,DIRT:2,STATIONARY_WATER,HARD_CLAY,STAINED_CLAY,CLAY,SANDSTONE,SAND:1,AIR,STONE,GRAVEL,LONG_GRASS,LONG_GRASS:1,LONG_GRASS:2,DEAD_BUSH,YELLOW_FLOWER,RED_ROSE,BROWN_MUSHROOM,RED_MUSHROOM

MaxPercentageOutsideSourceBlock: 0

OutsideSourceBlock: placeAnyway

IsOTGPlus: false

InheritBO3: 

InheritBO3Rotation: NORTH

OverrideChildSettings: true

OverrideParentHeight: false

CanOverride: false

BranchFrequency: 0

BranchFrequencyGroup: 

MustBeBelowOther: false

MustBeInside: 

CannotBeInside: 

ReplacesBO3: 

CanSpawnOnWater: true

SpawnOnWaterOnly: false

SpawnUnderWater: false

SpawnAtWaterLevel: false

HeightOffset: 0

RemoveAir: true

ReplaceAbove: 

ReplaceBelow: 

ReplaceWithBiomeBlocks: true

ReplaceWithGroundBlock: DIRT

ReplaceWithSurfaceBlock: GRASS

SmoothRadius: 0

SmoothHeightOffset: 0

SmoothStartTop: false

SmoothStartWood: false

SmoothingSurfaceBlock: 

SmoothingGroundBlock: 

BO3Group: 

IsSpawnPoint: false


#######################################################################
# +-----------------------------------------------------------------+ #
# |                              Blocks                             | #
# +-----------------------------------------------------------------+ #
#######################################################################

Block(-11,7,6,LOG:13)
Block(-10,8,6,LOG:13)
Block(-10,14,-12,LOG:13)
Block(-10,23,2,LOG:13)
Block(-9,8,5,LOG:13)
Block(-9,15,-11,LOG:13)
Block(-9,23,2,LOG:13)
Block(-8,9,5,LOG:13)
Block(-8,15,-10,LOG:13)
Block(-8,23,-3,LOG:13)
Block(-8,24,1,LOG:13)
Block(-7,9,4,LOG:13)
Block(-7,16,-9,LOG:13)
Block(-7,24,-2,LOG:13)
Block(-7,24,1,LOG:13)
Block(-6,10,3,LOG:13)
Block(-6,16,-8,LOG:13)
Block(-6,24,-1,LOG:13)
Block(-6,25,1,LOG:13)
Block(-5,10,3,LOG:13)
Block(-5,17,-7,LOG:13)
Block(-5,25,0,LOG:13)
Block(-4,-5,0,LOG:1)
Block(-4,-4,0,LOG:13)
Block(-4,-3,0,LOG:13)
Block(-4,11,2,LOG:13)
Block(-4,17,-6,LOG:13)
Block(-4,26,-1,LOG:13)
Block(-3,-5,-3,LOG:1)
Block(-3,-5,-1,LOG:1)
Block(-3,-5,0,LOG:1)
Block(-3,-5,1,LOG:1)
Block(-3,-5,2,LOG:1)
Block(-3,-4,-3,LOG:13)
Block(-3,-4,-1,LOG:13)
Block(-3,-4,1,LOG:5)
Block(-3,-4,2,LOG:13)
Block(-3,-3,-3,LOG:1)
Block(-3,-3,-1,LOG:13)
Block(-3,-3,2,LOG:13)
Block(-3,-2,-1,LOG:1)
Block(-3,11,1,LOG:13)
Block(-3,15,10,LOG:13)
Block(-3,16,-8,LOG:13)
Block(-3,17,-7,LOG:13)
Block(-3,18,-5,LOG:13)
Block(-3,26,-1,LOG:13)
Block(-3,26,1,LOG:13)
Block(-3,39,3,LOG:13)
Block(-2,-5,-2,LOG:1)
Block(-2,-5,0,LOG:1)
Block(-2,-5,2,LOG:1)
Block(-2,-4,-2,LOG:13)
Block(-2,-4,-1,LOG:13)
Block(-2,-4,0,LOG:1)
Block(-2,-4,1,LOG:13)
Block(-2,-4,2,LOG:13)
Block(-2,-3,-2,LOG:13)
Block(-2,-3,-1,LOG:13)
Block(-2,-3,0,LOG:1)
Block(-2,-3,1,LOG:13)
Block(-2,-3,2,LOG:13)
Block(-2,-2,-2,LOG:13)
Block(-2,-2,-1,LOG:13)
Block(-2,-2,1,LOG:13)
Block(-2,-2,2,LOG:13)
Block(-2,-1,-2,LOG:1)
Block(-2,-1,-1,LOG:13)
Block(-2,-1,1,LOG:13)
Block(-2,0,-1,LOG:13)
Block(-2,0,1,LOG:1)
Block(-2,1,-1,LOG:1)
Block(-2,12,0,LOG:13)
Block(-2,15,-9,LOG:13)
Block(-2,16,8,LOG:13)
Block(-2,16,9,LOG:13)
Block(-2,17,7,LOG:13)
Block(-2,18,-4,LOG:13)
Block(-2,27,-1,LOG:13)
Block(-2,27,0,LOG:13)
Block(-2,30,-6,LOG:13)
Block(-2,39,2,LOG:13)
Block(-2,43,-3,LOG:13)
Block(-1,-5,-2,LOG:1)
Block(-1,-5,1,LOG:1)
Block(-1,-4,-2,LOG:13)
Block(-1,-4,1,LOG:13)
Block(-1,-3,-2,LOG:13)
Block(-1,-3,1,LOG:13)
Block(-1,-2,-2,LOG:13)
Block(-1,-2,-1,LOG:13)
Block(-1,-2,1,LOG:1)
Block(-1,-1,-2,LOG:13)
Block(-1,-1,-1,LOG:13)
Block(-1,-1,0,LOG:13)
Block(-1,0,-1,LOG:13)
Block(-1,0,0,LOG:13)
Block(-1,1,-1,LOG:13)
Block(-1,1,0,LOG:13)
Block(-1,2,-1,LOG:13)
Block(-1,2,0,LOG:13)
Block(-1,3,-1,LOG:13)
Block(-1,3,0,LOG:13)
Block(-1,4,-1,LOG:13)
Block(-1,5,-1,LOG:13)
Block(-1,6,-1,LOG:13)
Block(-1,7,-1,LOG:13)
Block(-1,8,-1,LOG:13)
Block(-1,9,-1,LOG:13)
Block(-1,10,-1,LOG:13)
Block(-1,12,0,LOG:13)
Block(-1,15,-10,LOG:13)
Block(-1,17,6,LOG:13)
Block(-1,19,-3,LOG:13)
Block(-1,27,-1,LOG:13)
Block(-1,30,-5,LOG:13)
Block(-1,37,-6,LOG:13)
Block(-1,37,-5,LOG:13)
Block(-1,38,-4,LOG:13)
Block(-1,38,-3,LOG:13)
Block(-1,40,1,LOG:13)
Block(-1,44,-3,LOG:13)
Block(-1,50,-3,LOG:13)
Block(0,-5,-3,LOG:1)
Block(0,-5,2,LOG:1)
Block(0,-4,-3,LOG:13)
Block(0,-4,2,LOG:13)
Block(0,-3,-3,LOG:13)
Block(0,-3,-2,LOG:13)
Block(0,-3,2,LOG:1)
Block(0,-2,-3,LOG:1)
Block(0,-2,-2,LOG:13)
Block(0,-2,1,LOG:13)
Block(0,-1,-2,LOG:13)
Block(0,-1,1,LOG:13)
Block(0,0,-2,LOG:13)
Block(0,0,-1,LOG:13)
Block(0,0,0,LOG:13)
Block(0,0,1,LOG:13)
Block(0,1,-2,LOG:13)
Block(0,1,-1,LOG:13)
Block(0,1,0,LOG:13)
Block(0,1,1,LOG:13)
Block(0,2,-2,LOG:13)
Block(0,2,-1,LOG:13)
Block(0,2,0,LOG:13)
Block(0,2,1,LOG:13)
Block(0,3,-2,LOG:13)
Block(0,3,-1,LOG:13)
Block(0,3,0,LOG:13)
Block(0,3,1,LOG:13)
Block(0,4,-2,LOG:13)
Block(0,4,-1,LOG:13)
Block(0,4,0,LOG:13)
Block(0,4,1,LOG:13)
Block(0,5,-2,LOG:13)
Block(0,5,-1,LOG:13)
Block(0,5,0,LOG:13)
Block(0,5,1,LOG:13)
Block(0,6,-2,LOG:13)
Block(0,6,-1,LOG:13)
Block(0,6,0,LOG:13)
Block(0,6,1,LOG:13)
Block(0,7,-2,LOG:13)
Block(0,7,-1,LOG:13)
Block(0,7,0,LOG:13)
Block(0,8,-2,LOG:13)
Block(0,8,-1,LOG:13)
Block(0,8,0,LOG:13)
Block(0,9,-2,LOG:13)
Block(0,9,-1,LOG:13)
Block(0,9,0,LOG:13)
Block(0,10,-2,LOG:13)
Block(0,10,-1,LOG:13)
Block(0,10,0,LOG:13)
Block(0,11,-2,LOG:13)
Block(0,11,-1,LOG:13)
Block(0,11,0,LOG:13)
Block(0,12,-2,LOG:13)
Block(0,12,-1,LOG:13)
Block(0,12,0,LOG:13)
Block(0,13,-2,LOG:13)
Block(0,13,-1,LOG:13)
Block(0,13,0,LOG:13)
Block(0,14,-2,LOG:13)
Block(0,14,-1,LOG:13)
Block(0,14,0,LOG:13)
Block(0,15,-2,LOG:13)
Block(0,15,-1,LOG:13)
Block(0,15,0,LOG:13)
Block(0,16,-2,LOG:13)
Block(0,16,-1,LOG:13)
Block(0,16,0,LOG:13)
Block(0,17,-2,LOG:13)
Block(0,17,-1,LOG:13)
Block(0,17,0,LOG:13)
Block(0,18,-1,LOG:13)
Block(0,18,0,LOG:13)
Block(0,18,3,LOG:13)
Block(0,18,4,LOG:13)
Block(0,18,5,LOG:13)
Block(0,19,-2,LOG:13)
Block(0,19,-1,LOG:13)
Block(0,19,0,LOG:13)
Block(0,19,1,LOG:13)
Block(0,19,2,LOG:13)
Block(0,20,-1,LOG:13)
Block(0,20,0,LOG:13)
Block(0,21,-1,LOG:13)
Block(0,21,0,LOG:13)
Block(0,22,-1,LOG:13)
Block(0,22,0,LOG:13)
Block(0,23,-1,LOG:13)
Block(0,23,0,LOG:13)
Block(0,24,-1,LOG:13)
Block(0,24,0,LOG:13)
Block(0,25,-1,LOG:13)
Block(0,25,0,LOG:13)
Block(0,26,-1,LOG:13)
Block(0,26,0,LOG:13)
Block(0,27,-1,LOG:13)
Block(0,27,0,LOG:13)
Block(0,28,-1,LOG:13)
Block(0,28,0,LOG:13)
Block(0,29,-1,LOG:13)
Block(0,29,0,LOG:13)
Block(0,30,-1,LOG:13)
Block(0,31,-4,LOG:13)
Block(0,31,-1,LOG:13)
Block(0,31,0,LOG:13)
Block(0,31,1,LOG:13)
Block(0,31,2,LOG:13)
Block(0,32,-3,LOG:13)
Block(0,32,-2,LOG:13)
Block(0,32,-1,LOG:13)
Block(0,33,-1,LOG:13)
Block(0,34,-1,LOG:13)
Block(0,35,-1,LOG:13)
Block(0,38,-2,LOG:13)
Block(0,40,0,LOG:13)
Block(0,44,-2,LOG:13)
Block(0,48,1,LOG:13)
Block(0,51,-2,LOG:13)
Block(0,55,-1,LOG:13)
Block(1,-5,-5,LOG:1)
Block(1,-5,-4,LOG:1)
Block(1,-5,-3,LOG:1)
Block(1,-5,2,LOG:1)
Block(1,-4,-5,LOG:1)
Block(1,-4,-4,LOG:13)
Block(1,-4,-2,LOG:13)
Block(1,-4,1,LOG:13)
Block(1,-4,2,LOG:13)
Block(1,-3,-4,LOG:13)
Block(1,-3,-2,LOG:13)
Block(1,-3,1,LOG:13)
Block(1,-3,2,LOG:13)
Block(1,-2,-2,LOG:13)
Block(1,-2,1,LOG:13)
Block(1,-2,2,LOG:13)
Block(1,-1,-2,LOG:13)
Block(1,-1,0,LOG:13)
Block(1,-1,1,LOG:13)
Block(1,-1,2,LOG:13)
Block(1,0,-2,LOG:13)
Block(1,0,-1,LOG:13)
Block(1,0,0,LOG:13)
Block(1,0,1,LOG:13)
Block(1,0,2,LOG:1)
Block(1,1,-1,LOG:13)
Block(1,1,0,LOG:13)
Block(1,1,1,LOG:13)
Block(1,2,-1,LOG:13)
Block(1,2,0,LOG:13)
Block(1,2,1,LOG:13)
Block(1,3,-1,LOG:13)
Block(1,3,0,LOG:13)
Block(1,3,1,LOG:13)
Block(1,4,-1,LOG:13)
Block(1,4,0,LOG:13)
Block(1,4,1,LOG:13)
Block(1,5,-1,LOG:13)
Block(1,5,0,LOG:13)
Block(1,5,1,LOG:13)
Block(1,6,-1,LOG:13)
Block(1,6,0,LOG:13)
Block(1,6,1,LOG:13)
Block(1,7,-1,LOG:13)
Block(1,7,0,LOG:13)
Block(1,7,1,LOG:13)
Block(1,8,-1,LOG:13)
Block(1,8,0,LOG:13)
Block(1,8,1,LOG:13)
Block(1,9,-1,LOG:13)
Block(1,9,0,LOG:13)
Block(1,9,1,LOG:13)
Block(1,10,-1,LOG:13)
Block(1,10,0,LOG:13)
Block(1,10,1,LOG:13)
Block(1,11,-1,LOG:13)
Block(1,11,0,LOG:13)
Block(1,11,1,LOG:13)
Block(1,12,-1,LOG:13)
Block(1,12,0,LOG:13)
Block(1,12,1,LOG:13)
Block(1,13,-1,LOG:13)
Block(1,13,0,LOG:13)
Block(1,13,1,LOG:13)
Block(1,14,-1,LOG:13)
Block(1,14,0,LOG:13)
Block(1,15,-1,LOG:13)
Block(1,15,0,LOG:13)
Block(1,15,1,LOG:13)
Block(1,16,-1,LOG:13)
Block(1,16,0,LOG:13)
Block(1,17,-1,LOG:13)
Block(1,17,0,LOG:13)
Block(1,18,-1,LOG:13)
Block(1,18,0,LOG:13)
Block(1,18,5,LOG:13)
Block(1,19,-1,LOG:13)
Block(1,19,0,LOG:13)
Block(1,20,-1,LOG:13)
Block(1,20,0,LOG:13)
Block(1,21,-1,LOG:13)
Block(1,21,0,LOG:13)
Block(1,22,-1,LOG:13)
Block(1,22,0,LOG:13)
Block(1,23,-1,LOG:13)
Block(1,24,-1,LOG:13)
Block(1,25,-1,LOG:13)
Block(1,26,-1,LOG:13)
Block(1,27,-1,LOG:13)
Block(1,28,-1,LOG:13)
Block(1,28,7,LOG:13)
Block(1,29,-1,LOG:13)
Block(1,29,5,LOG:13)
Block(1,29,6,LOG:13)
Block(1,30,-1,LOG:13)
Block(1,30,3,LOG:13)
Block(1,30,4,LOG:13)
Block(1,31,-5,LOG:13)
Block(1,31,-1,LOG:13)
Block(1,32,-1,LOG:13)
Block(1,33,-1,LOG:13)
Block(1,34,-1,LOG:13)
Block(1,35,-1,LOG:13)
Block(1,36,-1,LOG:13)
Block(1,37,-1,LOG:13)
Block(1,38,-1,LOG:13)
Block(1,39,-1,LOG:13)
Block(1,40,-1,LOG:13)
Block(1,41,-1,LOG:13)
Block(1,42,-1,LOG:13)
Block(1,43,-1,LOG:13)
Block(1,44,-1,LOG:13)
Block(1,45,-1,LOG:13)
Block(1,45,0,LOG:13)
Block(1,46,-1,LOG:13)
Block(1,47,-1,LOG:13)
Block(1,48,-1,LOG:13)
Block(1,49,-1,LOG:13)
Block(1,49,0,LOG:13)
Block(1,50,-1,LOG:13)
Block(1,51,-1,LOG:13)
Block(1,52,-1,LOG:13)
Block(1,53,-1,LOG:13)
Block(1,54,-1,LOG:13)
Block(1,55,-1,LOG:13)
Block(1,56,-1,LOG:13)
Block(1,57,-1,LOG:13)
Block(1,58,-1,LOG:13)
Block(1,59,-1,LOG:13)
Block(2,-5,-2,LOG:1)
Block(2,-5,0,LOG:1)
Block(2,-5,1,LOG:1)
Block(2,-5,3,LOG:1)
Block(2,-4,-2,LOG:13)
Block(2,-4,-1,LOG:13)
Block(2,-4,0,LOG:13)
Block(2,-4,1,LOG:13)
Block(2,-4,2,LOG:13)
Block(2,-4,3,LOG:13)
Block(2,-3,-2,LOG:13)
Block(2,-3,-1,LOG:13)
Block(2,-3,0,LOG:13)
Block(2,-3,1,LOG:13)
Block(2,-3,2,LOG:13)
Block(2,-3,3,LOG:13)
Block(2,-2,-1,LOG:13)
Block(2,-2,0,LOG:13)
Block(2,-2,1,LOG:13)
Block(2,-2,2,LOG:13)
Block(2,-2,3,LOG:1)
Block(2,-1,-1,LOG:13)
Block(2,-1,0,LOG:13)
Block(2,-1,1,LOG:13)
Block(2,0,-1,LOG:13)
Block(2,0,0,LOG:13)
Block(2,0,1,LOG:13)
Block(2,1,-1,LOG:13)
Block(2,1,0,LOG:13)
Block(2,1,1,LOG:13)
Block(2,2,-1,LOG:13)
Block(2,2,0,LOG:13)
Block(2,3,-1,LOG:13)
Block(2,3,0,LOG:13)
Block(2,4,-1,LOG:13)
Block(2,4,0,LOG:13)
Block(2,5,-1,LOG:13)
Block(2,5,0,LOG:13)
Block(2,6,-1,LOG:13)
Block(2,6,0,LOG:13)
Block(2,7,-1,LOG:13)
Block(2,7,0,LOG:13)
Block(2,8,-1,LOG:13)
Block(2,8,0,LOG:13)
Block(2,9,-1,LOG:13)
Block(2,9,0,LOG:13)
Block(2,10,-1,LOG:13)
Block(2,10,0,LOG:13)
Block(2,11,-1,LOG:13)
Block(2,11,9,LOG:13)
Block(2,12,-1,LOG:13)
Block(2,13,-1,LOG:13)
Block(2,14,-1,LOG:13)
Block(2,15,-1,LOG:13)
Block(2,15,2,LOG:13)
Block(2,17,6,LOG:13)
Block(2,17,7,LOG:13)
Block(2,19,0,LOG:13)
Block(2,23,-1,LOG:13)
Block(2,28,-1,LOG:13)
Block(2,30,-7,LOG:13)
Block(2,30,-6,LOG:13)
Block(2,35,-2,LOG:13)
Block(2,37,0,LOG:13)
Block(2,39,-2,LOG:13)
Block(2,43,-1,LOG:13)
Block(2,44,2,LOG:13)
Block(2,45,1,LOG:13)
Block(2,48,-2,LOG:13)
Block(2,52,-1,LOG:13)
Block(3,-5,-1,LOG:1)
Block(3,-5,2,LOG:1)
Block(3,-4,-1,LOG:13)
Block(3,-4,2,LOG:13)
Block(3,-3,-1,LOG:13)
Block(3,-3,2,LOG:13)
Block(3,-2,-1,LOG:13)
Block(3,-1,-1,LOG:13)
Block(3,0,-1,LOG:1)
Block(3,11,8,LOG:13)
Block(3,14,3,LOG:13)
Block(3,16,8,LOG:13)
Block(3,19,0,LOG:13)
Block(3,22,0,LOG:13)
Block(3,28,-1,LOG:13)
Block(3,29,-9,LOG:13)
Block(3,29,-8,LOG:13)
Block(3,34,-3,LOG:13)
Block(3,37,1,LOG:13)
Block(3,39,-3,LOG:13)
Block(3,43,-1,LOG:13)
Block(3,47,-3,LOG:13)
Block(4,-5,-2,LOG:1)
Block(4,-4,-2,LOG:13)
Block(4,-3,-2,LOG:13)
Block(4,-2,-2,LOG:1)
Block(4,12,7,LOG:13)
Block(4,13,6,LOG:13)
Block(4,14,4,LOG:13)
Block(4,18,-1,LOG:13)
Block(4,22,1,LOG:13)
Block(4,27,-1,LOG:13)
Block(4,28,-10,LOG:13)
Block(4,34,-4,LOG:13)
Block(4,36,2,LOG:13)
Block(4,38,-4,LOG:13)
Block(4,42,0,LOG:13)
Block(5,13,5,LOG:13)
Block(5,17,-4,LOG:13)
Block(5,17,-3,LOG:13)
Block(5,18,-2,LOG:13)
Block(5,21,2,LOG:13)
Block(5,27,-1,LOG:13)
Block(5,32,-5,LOG:13)
Block(5,33,-4,LOG:13)
Block(5,36,3,LOG:13)
Block(5,37,-5,LOG:13)
Block(5,42,0,LOG:13)
Block(6,13,6,LOG:13)
Block(6,15,-7,LOG:13)
Block(6,16,-6,LOG:13)
Block(6,16,-5,LOG:13)
Block(6,17,-2,LOG:13)
Block(6,21,3,LOG:13)
Block(6,26,-1,LOG:13)
Block(6,33,-3,LOG:13)
Block(6,37,-6,LOG:13)
Block(7,12,7,LOG:13)
Block(7,17,-2,LOG:13)
Block(7,20,4,LOG:13)
Block(7,26,0,LOG:13)
Block(7,32,-3,LOG:13)
Block(8,12,8,LOG:13)
Block(8,17,-3,LOG:13)
Block(8,20,5,LOG:13)
Block(8,25,0,LOG:13)
Block(8,32,-3,LOG:13)
Block(9,11,9,LOG:13)
Block(9,16,-4,LOG:13)
Block(9,19,6,LOG:13)
Block(9,25,0,LOG:13)
Block(9,31,-2,LOG:13)
Block(10,11,10,LOG:13)
Block(10,16,-5,LOG:13)
Block(11,10,11,LOG:13)
Block(11,15,-5,LOG:13)
Block(12,15,-5,LOG:13)

#######################################################################
# +-----------------------------------------------------------------+ #
# |                            BO3 checks                           | #
# +-----------------------------------------------------------------+ #
#######################################################################

BlockCheck(0,-1,0,GRASS,DIRT)

#######################################################################
# +-----------------------------------------------------------------+ #
# |                             Branches                            | #
# +-----------------------------------------------------------------+ #
#######################################################################


#######################################################################
# +-----------------------------------------------------------------+ #
# |                             Entities                            | #
# +-----------------------------------------------------------------+ #
#######################################################################


#######################################################################
# +-----------------------------------------------------------------+ #
# |                            Particles                            | #
# +-----------------------------------------------------------------+ #
#######################################################################


#######################################################################
# +-----------------------------------------------------------------+ #
# |                             Spawners                            | #
# +-----------------------------------------------------------------+ #
#######################################################################


#######################################################################
# +-----------------------------------------------------------------+ #
# |                             ModData                             | #
# +-----------------------------------------------------------------+ #
#######################################################################

