
#######################################################################
# +-----------------------------------------------------------------+ #
# |                            BO3 object                           | #
# +-----------------------------------------------------------------+ #
#######################################################################

Author: Unknown

Description: Converted version of the BO2 SpruceFir10

Version: 3

SettingsMode: WriteWithoutComments


#######################################################################
# +-----------------------------------------------------------------+ #
# |                          Main settings                          | #
# +-----------------------------------------------------------------+ #
#######################################################################

Tree: true

Frequency: 1

Rarity: 5.0

RotateRandomly: true

SpawnHeight: highestSolidBlock

SpawnHeightOffset: 0

SpawnHeightVariance: 0

##############################
# Height Limits for the BO3. #
##############################

MinHeight: 63

MaxHeight: 138

######################
# Extrusion settings #
######################

ExtrudeMode: None

ExtrudeThroughBlocks: AIR

MaxBranchDepth: 10

ExcludedBiomes: All


#######################################################################
# +-----------------------------------------------------------------+ #
# |                      Source block settings                      | #
# +-----------------------------------------------------------------+ #
#######################################################################

SourceBlocks: STONE:1,STONE:3,STONE:5,DIRT:1,DIRT,SAND,GRASS,DIRT:2,STATIONARY_WATER,HARD_CLAY,STAINED_CLAY,CLAY,SANDSTONE,SAND:1,AIR,STONE,GRAVEL,LONG_GRASS,LONG_GRASS:1,LONG_GRASS:2,DEAD_BUSH,YELLOW_FLOWER,RED_ROSE,BROWN_MUSHROOM,RED_MUSHROOM

MaxPercentageOutsideSourceBlock: 2

OutsideSourceBlock: placeAnyway

IsOTGPlus: false

InheritBO3: 

InheritBO3Rotation: NORTH

OverrideChildSettings: true

OverrideParentHeight: false

CanOverride: false

BranchFrequency: 0

BranchFrequencyGroup: 

MustBeBelowOther: false

MustBeInside: 

CannotBeInside: 

ReplacesBO3: 

CanSpawnOnWater: true

SpawnOnWaterOnly: false

SpawnUnderWater: false

SpawnAtWaterLevel: false

HeightOffset: 0

RemoveAir: true

ReplaceAbove: 

ReplaceBelow: 

ReplaceWithBiomeBlocks: true

ReplaceWithGroundBlock: DIRT

ReplaceWithSurfaceBlock: GRASS

SmoothRadius: 0

SmoothHeightOffset: 0

SmoothStartTop: false

SmoothStartWood: false

SmoothingSurfaceBlock: 

SmoothingGroundBlock: 

BO3Group: 

IsSpawnPoint: false


#######################################################################
# +-----------------------------------------------------------------+ #
# |                              Blocks                             | #
# +-----------------------------------------------------------------+ #
#######################################################################

Block(-4,9,2,LEAVES:1)
Block(1,9,4,LEAVES:1)
Block(-4,30,4,LEAVES:1)
Block(-2,16,4,LEAVES:1)
Block(2,9,2,LEAVES:1)
Block(-1,16,1,LEAVES:1)
Block(1,9,-4,LEAVES:1)
Block(-1,17,1,LOG:1)
Block(-1,18,1,LOG:1)
Block(-1,19,1,LOG:1)
Block(-3,11,-2,LEAVES:1)
Block(-1,10,1,LOG:1)
Block(-4,27,4,LEAVES:1)
Block(-4,28,4,LEAVES:1)
Block(-3,10,2,LEAVES:1)
Block(-4,11,-1,LEAVES:1)
Block(-1,12,1,LEAVES:1)
Block(-4,29,4,LEAVES:1)
Block(-1,14,1,LEAVES:1)
Block(-5,8,-2,LEAVES:1)
Block(-3,13,2,LEAVES:1)
Block(-1,7,0,LEAVES:1)
Block(-3,11,2,LEAVES:1)
Block(-4,20,4,LEAVES:1)
Block(-3,16,2,LEAVES:1)
Block(-4,23,4,LEAVES:1)
Block(3,9,0,LEAVES:1)
Block(-3,19,2,LEAVES:1)
Block(-1,9,-3,LEAVES:1)
Block(2,-1,-1,LOG:1)
Block(1,11,1,LEAVES:1)
Block(1,12,1,LEAVES:1)
Block(-3,9,-2,LEAVES:1)
Block(3,10,2,LEAVES:1)
Block(1,14,1,LEAVES:1)
Block(-1,20,1,LEAVES:1)
Block(0,22,3,LEAVES:1)
Block(1,16,1,LEAVES:1)
Block(-1,22,1,LEAVES:1)
Block(-1,1,0,LOG:1)
Block(-3,21,2,LEAVES:1)
Block(-1,0,0,LOG:1)
Block(-1,3,0,LOG:1)
Block(3,12,2,LEAVES:1)
Block(1,19,1,LEAVES:1)
Block(-1,2,0,LOG:1)
Block(0,5,-1,LEAVES:1)
Block(1,9,5,LEAVES:1)
Block(-3,24,2,LEAVES:1)
Block(-4,9,1,LEAVES:1)
Block(-3,23,2,LEAVES:1)
Block(3,9,-2,LEAVES:1)
Block(1,18,-1,LEAVES:1)
Block(-3,22,2,LEAVES:1)
Block(1,16,-1,LEAVES:1)
Block(1,15,-1,LEAVES:1)
Block(-2,27,3,LEAVES:1)
Block(0,1,-1,LOG:1)
Block(-2,24,3,LEAVES:1)
Block(0,0,-1,LOG:1)
Block(-2,22,3,LEAVES:1)
Block(1,9,-3,LEAVES:1)
Block(0,19,3,LEAVES:1)
Block(2,9,3,LEAVES:1)
Block(1,10,2,LEAVES:1)
Block(0,15,3,LEAVES:1)
Block(-3,9,3,LEAVES:1)
Block(1,13,2,LEAVES:1)
Block(0,10,3,LEAVES:1)
Block(1,12,-1,LEAVES:1)
Block(0,12,3,LEAVES:1)
Block(1,10,-1,LEAVES:1)
Block(0,13,3,LEAVES:1)
Block(0,-1,-2,LOG:1)
Block(0,16,-1,LEAVES:1)
Block(-1,5,-2,LEAVES:1)
Block(0,18,-1,LEAVES:1)
Block(3,9,1,LEAVES:1)
Block(3,-2,-1,LOG:1)
Block(-1,18,2,LEAVES:1)
Block(-1,17,2,LEAVES:1)
Block(-3,9,-1,LEAVES:1)
Block(-1,10,2,LEAVES:1)
Block(0,10,-1,LEAVES:1)
Block(0,12,-1,LEAVES:1)
Block(-1,13,2,LEAVES:1)
Block(0,14,-1,LEAVES:1)
Block(-1,16,2,LEAVES:1)
Block(0,1,0,LOG:1)
Block(0,3,0,LOG:1)
Block(0,2,0,LOG:1)
Block(0,5,0,LOG:1)
Block(0,4,0,LOG:1)
Block(-3,18,3,LEAVES:1)
Block(-4,21,3,LEAVES:1)
Block(0,7,0,LOG:1)
Block(-2,19,0,LEAVES:1)
Block(0,6,0,LOG:1)
Block(-2,13,0,LEAVES:1)
Block(-2,12,0,LEAVES:1)
Block(-2,14,0,LEAVES:1)
Block(-2,10,0,LEAVES:1)
Block(2,8,4,LEAVES:1)
Block(1,9,-2,LEAVES:1)
Block(-3,21,3,LEAVES:1)
Block(-3,20,3,LEAVES:1)
Block(-3,26,3,LEAVES:1)
Block(-3,25,3,LEAVES:1)
Block(2,12,3,LEAVES:1)
Block(-3,24,3,LEAVES:1)
Block(-4,9,-1,LEAVES:1)
Block(-3,23,3,LEAVES:1)
Block(-1,7,2,LEAVES:1)
Block(-3,28,3,LEAVES:1)
Block(-3,27,3,LEAVES:1)
Block(-2,9,0,LEAVES:1)
Block(-2,6,0,LEAVES:1)
Block(-1,16,0,LEAVES:1)
Block(-5,9,1,LEAVES:1)
Block(-1,18,0,LEAVES:1)
Block(4,9,0,LEAVES:1)
Block(-1,19,0,LEAVES:1)
Block(-5,20,3,LEAVES:1)
Block(0,7,1,LEAVES:1)
Block(-1,10,0,LEAVES:1)
Block(-1,11,0,LEAVES:1)
Block(-1,12,0,LEAVES:1)
Block(-1,14,0,LEAVES:1)
Block(-4,9,3,LEAVES:1)
Block(2,12,2,LEAVES:1)
Block(2,15,2,LEAVES:1)
Block(3,15,1,LEAVES:1)
Block(1,5,-1,LEAVES:1)
Block(-1,21,0,LEAVES:1)
Block(3,13,1,LEAVES:1)
Block(2,9,5,LEAVES:1)
Block(-1,4,1,LOG:1)
Block(-3,16,4,LEAVES:1)
Block(-1,3,1,LOG:1)
Block(-1,6,1,LOG:1)
Block(-1,5,1,LOG:1)
Block(-1,8,1,LOG:1)
Block(3,9,3,LEAVES:1)
Block(-1,7,1,LOG:1)
Block(-1,9,1,LOG:1)
Block(-2,-1,1,LOG:1)
Block(-1,9,-4,LEAVES:1)
Block(-5,9,2,LEAVES:1)
Block(0,-2,0,LOG:1)
Block(1,13,3,LEAVES:1)
Block(0,9,0,LOG:1)
Block(0,11,4,LEAVES:1)
Block(-4,24,3,LEAVES:1)
Block(0,8,0,LOG:1)
Block(-4,26,3,LEAVES:1)
Block(1,17,3,LEAVES:1)
Block(-1,0,1,LOG:1)
Block(-4,28,3,LEAVES:1)
Block(-1,2,1,LOG:1)
Block(-3,21,4,LEAVES:1)
Block(-1,1,1,LOG:1)
Block(2,9,-2,LEAVES:1)
Block(-3,26,4,LEAVES:1)
Block(0,1,2,LOG:1)
Block(0,0,2,LOG:1)
Block(-3,24,4,LEAVES:1)
Block(-1,10,4,LEAVES:1)
Block(-4,11,2,LEAVES:1)
Block(-2,24,1,LEAVES:1)
Block(-2,21,1,LEAVES:1)
Block(-2,22,1,LEAVES:1)
Block(2,12,-2,LEAVES:1)
Block(-2,9,-3,LEAVES:1)
Block(0,14,1,LEAVES:1)
Block(1,13,4,LEAVES:1)
Block(0,18,1,LEAVES:1)
Block(4,8,-3,LEAVES:1)
Block(0,16,1,LEAVES:1)
Block(-3,9,0,LEAVES:1)
Block(0,11,1,LEAVES:1)
Block(0,10,1,LEAVES:1)
Block(-1,21,4,LEAVES:1)
Block(-2,6,2,LEAVES:1)
Block(-4,9,-3,LEAVES:1)
Block(-1,-2,-3,LOG:1)
Block(2,-2,3,LOG:1)
Block(-1,-1,0,LOG:1)
Block(-1,10,-2,LEAVES:1)
Block(4,9,2,LEAVES:1)
Block(4,8,2,LEAVES:1)
Block(-1,13,4,LEAVES:1)
Block(5,8,0,LEAVES:1)
Block(2,8,-3,LEAVES:1)
Block(0,0,1,LOG:1)
Block(0,2,1,LOG:1)
Block(0,1,1,LOG:1)
Block(0,3,1,LOG:1)
Block(3,12,-2,LEAVES:1)
Block(-1,-1,-2,LOG:1)
Block(-2,12,-1,LEAVES:1)
Block(-2,13,-1,LEAVES:1)
Block(-1,10,-1,LEAVES:1)
Block(-2,16,-1,LEAVES:1)
Block(-2,8,-4,LEAVES:1)
Block(-4,24,2,LEAVES:1)
Block(0,8,-5,LEAVES:1)
Block(-2,19,-1,LEAVES:1)
Block(0,20,0,LEAVES:1)
Block(2,11,1,LEAVES:1)
Block(2,10,1,LEAVES:1)
Block(-3,12,0,LEAVES:1)
Block(-4,9,-2,LEAVES:1)
Block(2,13,1,LEAVES:1)
Block(2,12,1,LEAVES:1)
Block(-2,18,1,LEAVES:1)
Block(-3,13,0,LEAVES:1)
Block(-2,19,1,LEAVES:1)
Block(-2,14,1,LEAVES:1)
Block(-1,16,-1,LEAVES:1)
Block(-2,7,1,LEAVES:1)
Block(-2,16,1,LEAVES:1)
Block(-3,17,0,LEAVES:1)
Block(-4,20,2,LEAVES:1)
Block(-2,10,1,LEAVES:1)
Block(-1,12,-1,LEAVES:1)
Block(-2,12,1,LEAVES:1)
Block(0,14,0,LOG:1)
Block(-2,0,1,LOG:1)
Block(0,13,0,LOG:1)
Block(-4,18,2,LEAVES:1)
Block(0,12,0,LOG:1)
Block(0,11,0,LOG:1)
Block(0,18,0,LEAVES:1)
Block(0,17,0,LEAVES:1)
Block(0,16,0,LOG:1)
Block(0,15,0,LOG:1)
Block(0,10,0,LOG:1)
Block(1,1,0,LOG:1)
Block(1,0,0,LOG:1)
Block(3,13,0,LEAVES:1)
Block(3,12,0,LEAVES:1)
Block(2,10,0,LEAVES:1)
Block(3,9,-1,LEAVES:1)
Block(-3,20,0,LEAVES:1)
Block(-4,9,0,LEAVES:1)
Block(1,9,2,LEAVES:1)
Block(2,12,0,LEAVES:1)
Block(-3,21,0,LEAVES:1)
Block(0,9,-2,LEAVES:1)
Block(2,18,0,LEAVES:1)
Block(2,14,0,LEAVES:1)
Block(2,15,0,LEAVES:1)
Block(-2,9,-1,LEAVES:1)
Block(-1,11,-3,LEAVES:1)
Block(4,9,-1,LEAVES:1)
Block(2,9,0,LEAVES:1)
Block(0,20,2,LEAVES:1)
Block(-1,22,2,LEAVES:1)
Block(-1,24,2,LEAVES:1)
Block(-2,6,-1,LEAVES:1)
Block(-1,6,-1,LEAVES:1)
Block(1,18,0,LEAVES:1)
Block(1,16,0,LEAVES:1)
Block(-2,9,4,LEAVES:1)
Block(1,14,0,LEAVES:1)
Block(-3,-2,2,LOG:1)
Block(1,13,0,LEAVES:1)
Block(-2,19,3,LEAVES:1)
Block(-3,-1,2,LOG:1)
Block(1,12,0,LEAVES:1)
Block(-2,17,3,LEAVES:1)
Block(1,10,0,LEAVES:1)
Block(-2,13,3,LEAVES:1)
Block(-1,13,-3,LEAVES:1)
Block(2,10,-1,LEAVES:1)
Block(-3,18,-1,LEAVES:1)
Block(0,18,2,LEAVES:1)
Block(-2,21,3,LEAVES:1)
Block(2,12,-1,LEAVES:1)
Block(5,8,-1,LEAVES:1)
Block(0,14,2,LEAVES:1)
Block(0,15,2,LEAVES:1)
Block(-3,8,-4,LEAVES:1)
Block(4,8,4,LEAVES:1)
Block(0,10,2,LEAVES:1)
Block(1,-1,1,LOG:1)
Block(0,12,2,LEAVES:1)
Block(-3,13,-1,LEAVES:1)
Block(0,13,-3,LEAVES:1)
Block(-3,15,-1,LEAVES:1)
Block(-4,18,0,LEAVES:1)
Block(-3,12,1,LEAVES:1)
Block(1,9,3,LEAVES:1)
Block(-3,10,1,LEAVES:1)
Block(-3,16,1,LEAVES:1)
Block(-3,17,1,LEAVES:1)
Block(0,9,-3,LEAVES:1)
Block(-2,18,2,LEAVES:1)
Block(-1,20,3,LEAVES:1)
Block(-2,17,2,LEAVES:1)
Block(-4,20,1,LEAVES:1)
Block(-3,18,1,LEAVES:1)
Block(-2,15,2,LEAVES:1)
Block(-3,19,1,LEAVES:1)
Block(-2,13,2,LEAVES:1)
Block(-2,10,2,LEAVES:1)
Block(2,9,1,LEAVES:1)
Block(-2,20,2,LOG:1)
Block(-2,9,-2,LEAVES:1)
Block(-4,16,1,LEAVES:1)
Block(-4,11,1,LEAVES:1)
Block(4,13,-1,LEAVES:1)
Block(1,-1,2,LOG:1)
Block(-1,10,3,LEAVES:1)
Block(-3,21,-1,LEAVES:1)
Block(0,13,-2,LEAVES:1)
Block(-1,15,3,LEAVES:1)
Block(0,12,-2,LEAVES:1)
Block(-3,20,1,LEAVES:1)
Block(0,15,-2,LEAVES:1)
Block(-1,17,3,LEAVES:1)
Block(-3,24,1,LEAVES:1)
Block(-2,9,3,LEAVES:1)
Block(-4,10,1,LEAVES:1)
Block(-2,25,2,LEAVES:1)
Block(-1,9,5,LEAVES:1)
Block(-2,26,2,LEAVES:1)
Block(-2,23,2,LEAVES:1)
Block(-2,24,2,LEAVES:1)
Block(-2,21,2,LOG:1)
Block(2,0,0,LOG:1)
Block(-2,22,2,LOG:1)
Block(-2,12,-2,LEAVES:1)
Block(1,13,-2,LEAVES:1)
Block(5,8,3,LEAVES:1)
Block(-1,21,3,LEAVES:1)
Block(-1,23,3,LEAVES:1)
Block(0,22,1,LEAVES:1)
Block(0,20,1,LEAVES:1)

#######################################################################
# +-----------------------------------------------------------------+ #
# |                            BO3 checks                           | #
# +-----------------------------------------------------------------+ #
#######################################################################

BlockCheck(0,-1,0,GRASS,DIRT,DIRT:2)

#######################################################################
# +-----------------------------------------------------------------+ #
# |                             Branches                            | #
# +-----------------------------------------------------------------+ #
#######################################################################


#######################################################################
# +-----------------------------------------------------------------+ #
# |                             Entities                            | #
# +-----------------------------------------------------------------+ #
#######################################################################


#######################################################################
# +-----------------------------------------------------------------+ #
# |                            Particles                            | #
# +-----------------------------------------------------------------+ #
#######################################################################


#######################################################################
# +-----------------------------------------------------------------+ #
# |                             Spawners                            | #
# +-----------------------------------------------------------------+ #
#######################################################################


#######################################################################
# +-----------------------------------------------------------------+ #
# |                             ModData                             | #
# +-----------------------------------------------------------------+ #
#######################################################################

