
#######################################################################
# +-----------------------------------------------------------------+ #
# |                            BO3 object                           | #
# +-----------------------------------------------------------------+ #
#######################################################################

Author: MC_Pitman

Description: No description given

Version: 3

SettingsMode: WriteWithoutComments


#######################################################################
# +-----------------------------------------------------------------+ #
# |                          Main settings                          | #
# +-----------------------------------------------------------------+ #
#######################################################################

Tree: true

Frequency: 1

Rarity: 3.0

RotateRandomly: true

SpawnHeight: highestSolidBlock

SpawnHeightOffset: 0

SpawnHeightVariance: 0

##############################
# Height Limits for the BO3. #
##############################

MinHeight: 50

MaxHeight: 60

######################
# Extrusion settings #
######################

ExtrudeMode: None

ExtrudeThroughBlocks: AIR

MaxBranchDepth: 10

ExcludedBiomes: All


#######################################################################
# +-----------------------------------------------------------------+ #
# |                      Source block settings                      | #
# +-----------------------------------------------------------------+ #
#######################################################################

SourceBlocks: STONE:1,STONE:3,STONE:5,DIRT:1,DIRT,SAND,GRASS,DIRT:2,STATIONARY_WATER,HARD_CLAY,STAINED_CLAY,CLAY,SANDSTONE,SAND:1,AIR,STONE,GRAVEL,LONG_GRASS,LONG_GRASS:1,LONG_GRASS:2,DEAD_BUSH,YELLOW_FLOWER,RED_ROSE,BROWN_MUSHROOM,RED_MUSHROOM

MaxPercentageOutsideSourceBlock: 0

OutsideSourceBlock: placeAnyway


#######################################################################
# +-----------------------------------------------------------------+ #
# |                              Blocks                             | #
# +-----------------------------------------------------------------+ #
#######################################################################

Block(-7,-3,-1,LOG:13)
Block(-7,-2,-1,LOG:13)
Block(-7,-2,0,LOG:13)
Block(-7,-2,2,LOG:13)
Block(-7,-1,-1,LOG:13)
Block(-7,-1,0,LOG:13)
Block(-7,-1,2,LOG:13)
Block(-6,-3,1,LOG:13)
Block(-6,-3,4,LOG:13)
Block(-6,-2,-2,LOG:13)
Block(-6,-2,1,LOG:13)
Block(-6,-2,3,LOG:13)
Block(-6,-2,4,LOG:13)
Block(-6,-1,-2,LOG:13)
Block(-6,-1,-1,LOG:13)
Block(-6,-1,0,LOG:13)
Block(-6,-1,1,LOG:13)
Block(-6,-1,2,LOG:13)
Block(-6,-1,3,LOG:13)
Block(-6,-1,4,LOG:13)
Block(-6,0,-1,LOG:13)
Block(-6,0,0,LOG:13)
Block(-6,0,1,LOG:13)
Block(-6,0,3,LOG:13)
Block(-6,1,0,LOG:13)
Block(-5,-3,-3,LOG:13)
Block(-5,-2,-3,LOG:13)
Block(-5,-2,4,LOG:13)
Block(-5,-1,-3,LOG:13)
Block(-5,-1,-2,LOG:13)
Block(-5,-1,-1,LOG:13)
Block(-5,-1,0,LOG:13)
Block(-5,-1,1,LOG:13)
Block(-5,-1,2,LOG:13)
Block(-5,-1,3,LOG:13)
Block(-5,-1,4,LOG:13)
Block(-5,0,-2,LOG:13)
Block(-5,0,-1,LOG:13)
Block(-5,0,0,LOG:13)
Block(-5,0,1,LOG:13)
Block(-5,0,2,LOG:13)
Block(-5,0,3,LOG:13)
Block(-5,0,4,LOG:13)
Block(-5,1,-2,LOG:13)
Block(-5,1,-1,LOG:13)
Block(-5,1,0,LOG:13)
Block(-5,1,1,LOG:13)
Block(-5,1,2,LOG:13)
Block(-5,1,3,LOG:13)
Block(-5,2,-1,LOG:13)
Block(-5,2,0,LOG:13)
Block(-5,2,1,LOG:13)
Block(-5,2,2,LOG:13)
Block(-5,3,0,LOG:13)
Block(-4,-3,4,LOG:13)
Block(-4,-2,-3,LOG:13)
Block(-4,-2,4,LOG:13)
Block(-4,-2,5,LOG:13)
Block(-4,-1,-3,LOG:13)
Block(-4,-1,-2,LOG:13)
Block(-4,-1,3,LOG:13)
Block(-4,-1,4,LOG:13)
Block(-4,-1,5,LOG:13)
Block(-4,0,-1,LOG:13)
Block(-4,0,0,LOG:13)
Block(-4,0,1,LOG:13)
Block(-4,0,2,LOG:13)
Block(-4,0,3,LOG:13)
Block(-4,0,4,LOG:13)
Block(-4,1,-1,LOG:13)
Block(-4,1,0,LOG:13)
Block(-4,1,1,LOG:13)
Block(-4,1,2,LOG:13)
Block(-4,1,3,LOG:13)
Block(-4,1,4,LOG:13)
Block(-4,2,-1,LOG:13)
Block(-4,2,0,LOG:13)
Block(-4,2,1,LOG:13)
Block(-4,2,2,LOG:13)
Block(-4,2,3,LOG:13)
Block(-4,3,-1,LOG:13)
Block(-4,3,0,LOG:13)
Block(-4,3,1,LOG:13)
Block(-4,4,-1,LOG:13)
Block(-4,4,0,LOG:13)
Block(-4,5,-1,LOG:13)
Block(-3,-3,-3,LOG:13)
Block(-3,-3,6,LOG:13)
Block(-3,-2,-3,LOG:13)
Block(-3,-2,5,LOG:13)
Block(-3,-2,6,LOG:13)
Block(-3,-1,-3,LOG:13)
Block(-3,-1,-2,LOG:13)
Block(-3,-1,4,LOG:13)
Block(-3,-1,5,LOG:13)
Block(-3,-1,6,LOG:13)
Block(-3,0,-2,LOG:13)
Block(-3,0,-1,LOG:13)
Block(-3,0,0,LOG:13)
Block(-3,0,3,LOG:13)
Block(-3,0,4,LOG:13)
Block(-3,0,5,LOG:13)
Block(-3,1,-2,LOG:13)
Block(-3,1,-1,LOG:13)
Block(-3,1,0,LOG:13)
Block(-3,1,1,LOG:13)
Block(-3,1,2,LOG:13)
Block(-3,1,3,LOG:13)
Block(-3,1,4,LOG:13)
Block(-3,2,-1,LOG:13)
Block(-3,2,0,LOG:13)
Block(-3,2,1,LOG:13)
Block(-3,2,2,LOG:13)
Block(-3,2,3,LOG:13)
Block(-3,2,4,LOG:13)
Block(-3,3,-1,LOG:13)
Block(-3,3,0,LOG:13)
Block(-3,3,1,LOG:13)
Block(-3,3,2,LOG:13)
Block(-3,3,3,LOG:13)
Block(-3,3,4,LOG:13)
Block(-3,4,-1,LOG:13)
Block(-3,4,0,LOG:13)
Block(-3,4,1,LOG:13)
Block(-3,4,2,LOG:13)
Block(-3,4,3,LOG:13)
Block(-3,5,-1,LOG:13)
Block(-3,5,0,LOG:13)
Block(-3,5,1,LOG:13)
Block(-3,6,-1,LOG:13)
Block(-3,6,0,LOG:13)
Block(-2,-3,-7,LOG:13)
Block(-2,-2,-7,LOG:13)
Block(-2,-2,-2,LOG:13)
Block(-2,-2,6,LOG:13)
Block(-2,-1,-7,LOG:13)
Block(-2,-1,-2,LOG:13)
Block(-2,-1,-1,LOG:13)
Block(-2,-1,5,LOG:13)
Block(-2,-1,6,LOG:13)
Block(-2,0,-1,LOG:13)
Block(-2,0,0,LOG:13)
Block(-2,0,4,LOG:13)
Block(-2,0,5,LOG:13)
Block(-2,1,-1,LOG:13)
Block(-2,1,0,LOG:13)
Block(-2,1,4,LOG:13)
Block(-2,1,5,LOG:13)
Block(-2,2,-1,LOG:13)
Block(-2,2,0,LOG:13)
Block(-2,2,1,LOG:13)
Block(-2,2,3,LOG:13)
Block(-2,2,4,LOG:13)
Block(-2,3,-1,LOG:13)
Block(-2,3,0,LOG:13)
Block(-2,3,1,LOG:13)
Block(-2,3,3,LOG:13)
Block(-2,3,4,LOG:13)
Block(-2,4,0,LOG:13)
Block(-2,4,1,LOG:13)
Block(-2,4,3,LOG:13)
Block(-2,4,4,LOG:13)
Block(-2,5,0,LOG:13)
Block(-2,5,1,LOG:13)
Block(-2,5,3,LOG:13)
Block(-2,6,0,LOG:13)
Block(-2,6,1,LOG:13)
Block(-2,6,3,LOG:13)
Block(-2,7,0,LOG:13)
Block(-2,7,1,LOG:13)
Block(-2,7,3,LOG:13)
Block(-2,8,0,LOG:13)
Block(-2,8,1,LOG:13)
Block(-2,9,0,LOG:13)
Block(-2,10,0,LOG:13)
Block(-1,-3,-8,LOG:13)
Block(-1,-3,-1,LOG:13)
Block(-1,-3,7,LOG:13)
Block(-1,-2,-8,LOG:13)
Block(-1,-2,-7,LOG:13)
Block(-1,-2,-6,LOG:13)
Block(-1,-2,-1,LOG:13)
Block(-1,-2,7,LOG:13)
Block(-1,-1,-8,LOG:13)
Block(-1,-1,-7,LOG:13)
Block(-1,-1,-6,LOG:13)
Block(-1,-1,-1,LOG:13)
Block(-1,-1,0,LOG:13)
Block(-1,-1,5,LOG:13)
Block(-1,-1,6,LOG:13)
Block(-1,-1,7,LOG:13)
Block(-1,0,-7,LOG:13)
Block(-1,0,-6,LOG:13)
Block(-1,0,0,LOG:13)
Block(-1,0,5,LOG:13)
Block(-1,0,6,LOG:13)
Block(-1,1,-7,LOG:13)
Block(-1,1,-6,LOG:13)
Block(-1,1,0,LOG:13)
Block(-1,1,5,LOG:13)
Block(-1,2,-7,LOG:13)
Block(-1,2,-6,LOG:13)
Block(-1,2,0,LOG:13)
Block(-1,2,1,LOG:13)
Block(-1,2,4,LOG:13)
Block(-1,2,5,LOG:13)
Block(-1,3,0,LOG:13)
Block(-1,3,1,LOG:13)
Block(-1,3,4,LOG:13)
Block(-1,4,1,LOG:13)
Block(-1,4,3,LOG:13)
Block(-1,4,4,LOG:13)
Block(-1,5,1,LOG:13)
Block(-1,5,3,LOG:13)
Block(-1,5,4,LOG:13)
Block(-1,6,1,LOG:13)
Block(-1,6,3,LOG:13)
Block(-1,6,4,LOG:13)
Block(-1,7,3,LOG:13)
Block(-1,8,3,LOG:13)
Block(-1,9,3,LOG:13)
Block(-1,10,3,LOG:13)
Block(-1,11,3,LOG:13)
Block(-1,12,3,LOG:13)
Block(0,-3,-6,LOG:13)
Block(0,-2,-8,LOG:13)
Block(0,-2,-6,LOG:13)
Block(0,-2,0,LOG:13)
Block(0,-2,7,LOG:13)
Block(0,-1,-8,LOG:13)
Block(0,-1,-7,LOG:13)
Block(0,-1,-6,LOG:13)
Block(0,-1,0,LOG:13)
Block(0,-1,6,LOG:13)
Block(0,-1,7,LOG:13)
Block(0,0,-7,LOG:13)
Block(0,0,-6,LOG:13)
Block(0,0,0,LOG:13)
Block(0,0,5,LOG:13)
Block(0,0,6,LOG:13)
Block(0,0,7,LOG:13)
Block(0,1,-7,LOG:13)
Block(0,1,-6,LOG:13)
Block(0,1,0,LOG:13)
Block(0,1,5,LOG:13)
Block(0,1,6,LOG:13)
Block(0,1,7,LOG:13)
Block(0,2,-7,LOG:13)
Block(0,2,-6,LOG:13)
Block(0,2,1,LOG:13)
Block(0,2,4,LOG:13)
Block(0,2,5,LOG:13)
Block(0,2,6,LOG:13)
Block(0,3,-7,LOG:13)
Block(0,3,-6,LOG:13)
Block(0,3,1,LOG:13)
Block(0,3,4,LOG:13)
Block(0,3,5,LOG:13)
Block(0,4,-6,LOG:13)
Block(0,4,2,LOG:13)
Block(0,4,3,LOG:13)
Block(0,4,4,LOG:13)
Block(0,4,5,LOG:13)
Block(0,5,2,LOG:13)
Block(0,5,3,LOG:13)
Block(0,5,4,LOG:13)
Block(0,6,3,LOG:13)
Block(0,6,4,LOG:13)
Block(0,7,3,LOG:13)
Block(0,7,4,LOG:13)
Block(0,8,3,LOG:13)
Block(0,8,4,LOG:13)
Block(0,9,3,LOG:13)
Block(0,9,4,LOG:13)
Block(0,10,4,LOG:13)
Block(0,11,4,LOG:13)
Block(1,-3,0,LOG:13)
Block(1,-2,-9,LOG:13)
Block(1,-2,0,LOG:13)
Block(1,-2,8,LOG:13)
Block(1,-1,-9,LOG:13)
Block(1,-1,-8,LOG:13)
Block(1,-1,-6,LOG:13)
Block(1,-1,-5,LOG:13)
Block(1,-1,0,LOG:13)
Block(1,-1,6,LOG:13)
Block(1,-1,7,LOG:13)
Block(1,-1,8,LOG:13)
Block(1,0,-8,LOG:13)
Block(1,0,-7,LOG:13)
Block(1,0,-6,LOG:13)
Block(1,0,1,LOG:13)
Block(1,0,5,LOG:13)
Block(1,0,6,LOG:13)
Block(1,0,7,LOG:13)
Block(1,1,-8,LOG:13)
Block(1,1,-7,LOG:13)
Block(1,1,-6,LOG:13)
Block(1,1,1,LOG:13)
Block(1,1,4,LOG:13)
Block(1,1,5,LOG:13)
Block(1,1,6,LOG:13)
Block(1,2,-7,LOG:13)
Block(1,2,-6,LOG:13)
Block(1,2,1,LOG:13)
Block(1,2,2,LOG:13)
Block(1,2,4,LOG:13)
Block(1,2,5,LOG:13)
Block(1,2,6,LOG:13)
Block(1,3,-7,LOG:13)
Block(1,3,-6,LOG:13)
Block(1,3,2,LOG:13)
Block(1,3,3,LOG:13)
Block(1,3,4,LOG:13)
Block(1,3,5,LOG:13)
Block(1,3,6,LOG:13)
Block(1,4,-6,LOG:13)
Block(1,4,2,LOG:13)
Block(1,4,3,LOG:13)
Block(1,4,4,LOG:13)
Block(1,4,5,LOG:13)
Block(1,5,3,LOG:13)
Block(1,5,4,LOG:13)
Block(1,5,5,LOG:13)
Block(1,6,3,LOG:13)
Block(1,6,4,LOG:13)
Block(1,6,5,LOG:13)
Block(1,7,4,LOG:13)
Block(1,7,5,LOG:13)
Block(1,8,4,LOG:13)
Block(1,9,4,LOG:13)
Block(1,10,4,LOG:13)
Block(2,-3,-10,LOG:13)
Block(2,-3,8,LOG:13)
Block(2,-2,-11,LOG:13)
Block(2,-2,-10,LOG:13)
Block(2,-2,-5,LOG:13)
Block(2,-2,1,LOG:13)
Block(2,-2,7,LOG:13)
Block(2,-2,8,LOG:13)
Block(2,-1,-11,LOG:13)
Block(2,-1,-10,LOG:13)
Block(2,-1,-9,LOG:13)
Block(2,-1,-8,LOG:13)
Block(2,-1,-5,LOG:13)
Block(2,-1,1,LOG:13)
Block(2,-1,2,LOG:13)
Block(2,-1,3,LOG:13)
Block(2,-1,4,LOG:13)
Block(2,-1,7,LOG:13)
Block(2,-1,8,LOG:13)
Block(2,0,-9,LOG:13)
Block(2,0,-8,LOG:13)
Block(2,0,-7,LOG:13)
Block(2,0,-6,LOG:13)
Block(2,0,-5,LOG:13)
Block(2,0,2,LOG:13)
Block(2,0,3,LOG:13)
Block(2,0,4,LOG:13)
Block(2,0,5,LOG:13)
Block(2,0,6,LOG:13)
Block(2,0,7,LOG:13)
Block(2,0,8,LOG:13)
Block(2,1,-8,LOG:13)
Block(2,1,-7,LOG:13)
Block(2,1,-6,LOG:13)
Block(2,1,-5,LOG:13)
Block(2,1,2,LOG:13)
Block(2,1,3,LOG:13)
Block(2,1,4,LOG:13)
Block(2,1,5,LOG:13)
Block(2,1,6,LOG:13)
Block(2,1,7,LOG:13)
Block(2,2,-8,LOG:13)
Block(2,2,-7,LOG:13)
Block(2,2,-6,LOG:13)
Block(2,2,3,LOG:13)
Block(2,2,4,LOG:13)
Block(2,2,5,LOG:13)
Block(2,2,6,LOG:13)
Block(2,3,-7,LOG:13)
Block(2,3,-6,LOG:13)
Block(2,3,3,LOG:13)
Block(2,3,4,LOG:13)
Block(2,3,5,LOG:13)
Block(2,3,6,LOG:13)
Block(2,4,-7,LOG:13)
Block(2,4,-6,LOG:13)
Block(2,4,3,LOG:13)
Block(2,4,4,LOG:13)
Block(2,4,5,LOG:13)
Block(2,4,6,LOG:13)
Block(2,5,-6,LOG:13)
Block(2,5,3,LOG:13)
Block(2,5,4,LOG:13)
Block(2,5,5,LOG:13)
Block(2,5,6,LOG:13)
Block(2,6,4,LOG:13)
Block(2,6,5,LOG:13)
Block(2,7,4,LOG:13)
Block(2,7,5,LOG:13)
Block(2,8,5,LOG:13)
Block(3,-3,4,LOG:13)
Block(3,-2,-10,LOG:13)
Block(3,-2,-9,LOG:13)
Block(3,-2,-8,LOG:13)
Block(3,-2,-4,LOG:13)
Block(3,-2,2,LOG:13)
Block(3,-2,4,LOG:13)
Block(3,-1,-10,LOG:13)
Block(3,-1,-9,LOG:13)
Block(3,-1,-8,LOG:13)
Block(3,-1,-7,LOG:13)
Block(3,-1,-5,LOG:13)
Block(3,-1,-4,LOG:13)
Block(3,-1,2,LOG:13)
Block(3,-1,3,LOG:13)
Block(3,-1,4,LOG:13)
Block(3,-1,6,LOG:13)
Block(3,-1,7,LOG:13)
Block(3,0,-8,LOG:13)
Block(3,0,-7,LOG:13)
Block(3,0,-5,LOG:13)
Block(3,0,-4,LOG:13)
Block(3,0,3,LOG:13)
Block(3,0,4,LOG:13)
Block(3,0,5,LOG:13)
Block(3,0,6,LOG:13)
Block(3,0,7,LOG:13)
Block(3,1,-8,LOG:13)
Block(3,1,-7,LOG:13)
Block(3,1,-5,LOG:13)
Block(3,1,-4,LOG:13)
Block(3,1,-3,LOG:13)
Block(3,1,3,LOG:13)
Block(3,1,4,LOG:13)
Block(3,1,5,LOG:13)
Block(3,1,6,LOG:13)
Block(3,1,7,LOG:13)
Block(3,2,-7,LOG:13)
Block(3,2,-6,LOG:13)
Block(3,2,-5,LOG:13)
Block(3,2,-3,LOG:13)
Block(3,2,3,LOG:13)
Block(3,2,4,LOG:13)
Block(3,2,5,LOG:13)
Block(3,2,6,LOG:13)
Block(3,2,7,LOG:13)
Block(3,3,-7,LOG:13)
Block(3,3,-6,LOG:13)
Block(3,3,-5,LOG:13)
Block(3,3,-3,LOG:13)
Block(3,3,4,LOG:13)
Block(3,3,6,LOG:13)
Block(3,3,7,LOG:13)
Block(3,4,-6,LOG:13)
Block(3,4,-5,LOG:13)
Block(3,4,-3,LOG:13)
Block(3,4,4,LOG:13)
Block(3,5,-6,LOG:13)
Block(3,5,-5,LOG:13)
Block(3,5,-3,LOG:13)
Block(3,5,4,LOG:13)
Block(3,6,-5,LOG:13)
Block(3,6,-3,LOG:13)
Block(3,7,-5,LOG:13)
Block(4,-3,3,LOG:13)
Block(4,-3,6,LOG:13)
Block(4,-2,-8,LOG:13)
Block(4,-2,-3,LOG:13)
Block(4,-2,-2,LOG:13)
Block(4,-2,-1,LOG:13)
Block(4,-2,3,LOG:13)
Block(4,-2,4,LOG:13)
Block(4,-2,5,LOG:13)
Block(4,-2,6,LOG:13)
Block(4,-1,-8,LOG:13)
Block(4,-1,-7,LOG:13)
Block(4,-1,-3,LOG:13)
Block(4,-1,-2,LOG:13)
Block(4,-1,-1,LOG:13)
Block(4,-1,3,LOG:13)
Block(4,-1,4,LOG:13)
Block(4,-1,5,LOG:13)
Block(4,-1,6,LOG:13)
Block(4,0,-8,LOG:13)
Block(4,0,-7,LOG:13)
Block(4,0,-3,LOG:13)
Block(4,0,-2,LOG:13)
Block(4,0,3,LOG:13)
Block(4,0,5,LOG:13)
Block(4,1,-7,LOG:13)
Block(4,1,-3,LOG:13)
Block(4,1,5,LOG:13)
Block(4,2,-7,LOG:13)
Block(4,2,-5,LOG:13)
Block(4,2,-4,LOG:13)
Block(4,2,-3,LOG:13)
Block(4,3,-6,LOG:13)
Block(4,3,-5,LOG:13)
Block(4,3,-4,LOG:13)
Block(4,3,-3,LOG:13)
Block(4,3,-2,LOG:13)
Block(4,4,-6,LOG:13)
Block(4,4,-5,LOG:13)
Block(4,4,-4,LOG:13)
Block(4,4,-3,LOG:13)
Block(4,4,-2,LOG:13)
Block(4,5,-5,LOG:13)
Block(4,5,-4,LOG:13)
Block(4,5,-3,LOG:13)
Block(4,5,-2,LOG:13)
Block(4,5,-1,LOG:13)
Block(4,6,-3,LOG:13)
Block(4,6,-2,LOG:13)
Block(4,7,-3,LOG:13)
Block(4,7,-2,LOG:13)
Block(4,8,-2,LOG:13)
Block(4,9,-2,LOG:13)
Block(4,10,-2,LOG:13)
Block(4,11,-2,LOG:13)
Block(5,-3,0,LOG:13)
Block(5,-2,-7,LOG:13)
Block(5,-2,0,LOG:13)
Block(5,-2,1,LOG:13)
Block(5,-1,-7,LOG:13)
Block(5,-1,-2,LOG:13)
Block(5,-1,-1,LOG:13)
Block(5,-1,0,LOG:13)
Block(5,-1,1,LOG:13)
Block(5,0,-7,LOG:13)
Block(5,0,-2,LOG:13)
Block(5,0,-1,LOG:13)
Block(5,0,0,LOG:13)
Block(5,1,-7,LOG:13)
Block(5,1,-2,LOG:13)
Block(5,1,-1,LOG:13)
Block(5,2,-6,LOG:13)
Block(5,2,-3,LOG:13)
Block(5,2,-2,LOG:13)
Block(5,2,-1,LOG:13)
Block(5,3,-6,LOG:13)
Block(5,3,-5,LOG:13)
Block(5,3,-3,LOG:13)
Block(5,3,-2,LOG:13)
Block(5,3,-1,LOG:13)
Block(5,4,-5,LOG:13)
Block(5,4,-4,LOG:13)
Block(5,4,-3,LOG:13)
Block(5,4,-2,LOG:13)
Block(5,4,-1,LOG:13)
Block(5,5,-4,LOG:13)
Block(5,5,-3,LOG:13)
Block(5,5,-2,LOG:13)
Block(5,5,-1,LOG:13)
Block(5,6,-4,LOG:13)
Block(5,6,-3,LOG:13)
Block(5,6,-2,LOG:13)
Block(5,6,-1,LOG:13)
Block(5,7,-2,LOG:13)
Block(5,7,-1,LOG:13)
Block(6,-3,-9,LOG:13)
Block(6,-2,-9,LOG:13)
Block(6,-2,-8,LOG:13)
Block(6,-2,1,LOG:13)
Block(6,-1,-9,LOG:13)
Block(6,-1,-8,LOG:13)
Block(6,-1,-7,LOG:13)
Block(6,-1,-6,LOG:13)
Block(6,-1,0,LOG:13)
Block(6,-1,1,LOG:13)
Block(6,0,-7,LOG:13)
Block(6,0,-6,LOG:13)
Block(6,0,-1,LOG:13)
Block(6,0,0,LOG:13)
Block(6,0,1,LOG:13)
Block(6,1,-7,LOG:13)
Block(6,1,-6,LOG:13)
Block(6,1,-1,LOG:13)
Block(6,1,0,LOG:13)
Block(6,2,-6,LOG:13)
Block(6,2,-5,LOG:13)
Block(6,2,-1,LOG:13)
Block(6,2,0,LOG:13)
Block(6,3,-5,LOG:13)
Block(6,3,-4,LOG:13)
Block(6,3,-1,LOG:13)
Block(6,3,0,LOG:13)
Block(6,4,-4,LOG:13)
Block(6,4,-1,LOG:13)
Block(6,4,0,LOG:13)
Block(6,5,-4,LOG:13)
Block(6,5,-1,LOG:13)
Block(7,-3,2,LOG:13)
Block(7,-2,-7,LOG:13)
Block(7,-2,2,LOG:13)
Block(7,-1,-7,LOG:13)
Block(7,-1,-6,LOG:13)
Block(7,-1,-5,LOG:13)
Block(7,-1,0,LOG:13)
Block(7,-1,1,LOG:13)
Block(7,-1,2,LOG:13)
Block(7,0,-6,LOG:13)
Block(7,0,-5,LOG:13)
Block(7,0,-4,LOG:13)
Block(7,0,-1,LOG:13)
Block(7,0,1,LOG:13)
Block(7,1,-5,LOG:13)
Block(7,1,-4,LOG:13)
Block(7,1,-1,LOG:13)
Block(7,1,0,LOG:13)
Block(7,1,1,LOG:13)
Block(7,2,-5,LOG:13)
Block(7,2,-4,LOG:13)
Block(7,2,-1,LOG:13)
Block(7,2,0,LOG:13)
Block(7,2,1,LOG:13)
Block(7,3,-4,LOG:13)
Block(7,3,-3,LOG:13)
Block(7,3,-2,LOG:13)
Block(7,3,-1,LOG:13)
Block(7,3,0,LOG:13)
Block(7,3,1,LOG:13)
Block(7,4,-4,LOG:13)
Block(7,4,-3,LOG:13)
Block(7,4,-1,LOG:13)
Block(7,4,0,LOG:13)
Block(7,4,1,LOG:13)
Block(7,5,-3,LOG:13)
Block(7,5,1,LOG:13)
Block(8,-3,-6,LOG:13)
Block(8,-2,-6,LOG:13)
Block(8,-2,-5,LOG:13)
Block(8,-2,2,LOG:13)
Block(8,-1,-6,LOG:13)
Block(8,-1,-5,LOG:13)
Block(8,-1,-4,LOG:13)
Block(8,-1,-3,LOG:13)
Block(8,-1,-2,LOG:13)
Block(8,-1,1,LOG:13)
Block(8,-1,2,LOG:13)
Block(8,0,-5,LOG:13)
Block(8,0,-4,LOG:13)
Block(8,0,-3,LOG:13)
Block(8,0,-2,LOG:13)
Block(8,0,-1,LOG:13)
Block(8,0,0,LOG:13)
Block(8,0,1,LOG:13)
Block(8,1,-4,LOG:13)
Block(8,1,-3,LOG:13)
Block(8,1,-2,LOG:13)
Block(8,1,-1,LOG:13)
Block(8,1,0,LOG:13)
Block(8,1,1,LOG:13)
Block(8,2,-3,LOG:13)
Block(8,2,-2,LOG:13)
Block(8,2,-1,LOG:13)
Block(8,2,0,LOG:13)
Block(8,2,1,LOG:13)
Block(8,3,-3,LOG:13)
Block(8,3,-1,LOG:13)
Block(8,3,0,LOG:13)
Block(8,3,1,LOG:13)
Block(8,4,-3,LOG:13)
Block(8,4,-1,LOG:13)
Block(8,4,0,LOG:13)
Block(8,5,-3,LOG:13)
Block(8,5,-1,LOG:13)
Block(8,6,-1,LOG:13)
Block(9,-3,0,LOG:13)
Block(9,-2,-4,LOG:13)
Block(9,-2,-3,LOG:13)
Block(9,-2,0,LOG:13)
Block(9,-2,1,LOG:13)
Block(9,-1,-4,LOG:13)
Block(9,-1,-3,LOG:13)
Block(9,-1,-2,LOG:13)
Block(9,-1,-1,LOG:13)
Block(9,-1,0,LOG:13)
Block(9,-1,1,LOG:13)
Block(9,0,-2,LOG:13)
Block(9,0,-1,LOG:13)
Block(9,0,0,LOG:13)
Block(9,0,1,LOG:13)
Block(9,1,-1,LOG:13)
Block(9,1,0,LOG:13)
Block(9,2,-1,LOG:13)
Block(9,2,0,LOG:13)
Block(9,3,-1,LOG:13)
Block(10,-3,-5,LOG:13)
Block(10,-3,-1,LOG:13)
Block(10,-2,-5,LOG:13)
Block(10,-2,-4,LOG:13)
Block(10,-2,-2,LOG:13)
Block(10,-2,-1,LOG:13)
Block(10,-2,0,LOG:13)
Block(10,-1,-5,LOG:13)
Block(10,-1,-4,LOG:13)
Block(10,-1,-2,LOG:13)
Block(10,-1,-1,LOG:13)
Block(10,-1,0,LOG:13)
Block(10,0,-1,LOG:13)
Block(10,1,-1,LOG:13)
Block(11,-3,-2,LOG:13)
Block(11,-2,-2,LOG:13)
Block(11,-1,-2,LOG:13)

#######################################################################
# +-----------------------------------------------------------------+ #
# |                            BO3 checks                           | #
# +-----------------------------------------------------------------+ #
#######################################################################


#######################################################################
# +-----------------------------------------------------------------+ #
# |                             Branches                            | #
# +-----------------------------------------------------------------+ #
#######################################################################


#######################################################################
# +-----------------------------------------------------------------+ #
# |                         EntityFunctions                         | #
# +-----------------------------------------------------------------+ #
#######################################################################

