
#######################################################################
# +-----------------------------------------------------------------+ #
# |                            BO3 object                           | #
# +-----------------------------------------------------------------+ #
#######################################################################

# This is the config file of a custom object.
# If you add this object correctly to your BiomeConfigs, it will spawn in the world.

# This is the creator of this BO3 object
Author: LordSmellyPants

# A short description of this BO3 object
Description: Converted version of the BO2 mountain5

# The BO3 version, don't change this! It can be used by external applications to do a version check.
Version: 3

# The settings mode, WriteAll, WriteWithoutComments or WriteDisable. See WorldConfig.
SettingsMode: WriteDisable


#######################################################################
# +-----------------------------------------------------------------+ #
# |                          Main settings                          | #
# +-----------------------------------------------------------------+ #
#######################################################################

# This needs to be set to true to spawn the object in the Tree and Sapling resources.
Tree: false

# The frequency of the BO3 from 1 to 200. Tries this many times to spawn this BO3 when using the CustomObject(...) resource.
# Ignored by Tree(..), Sapling(..) and CustomStructure(..)
Frequency: 1

# The rarity of the BO3 from 0 to 100. Each spawn attempt has rarity% chance to succeed when using the CustomObject(...) resource.
# Ignored by Tree(..), Sapling(..) and CustomStructure(..)
Rarity: 6.0

# If you set this to true, the BO3 will be placed with a random rotation.
RotateRandomly: true

# The spawn height of the BO3 - randomY, highestBlock or highestSolidBlock.
SpawnHeight: randomY

# The height limits for the BO3.
MinHeight: 0

MaxHeight: 70

# Objects can have other objects attacthed to it: branches. Branches can also
# have branches attached to it, which can also have branches, etc. This is the
# maximum branch depth for this objects.
MaxBranchDepth: 10

# When spawned with the UseWorld keyword, this BO3 should NOT spawn in the following biomes.
# If you writer.write the BO3 name directly in the BiomeConfigs, this will be ignored.
ExcludedBiomes: All


#######################################################################
# +-----------------------------------------------------------------+ #
# |                      Source block settings                      | #
# +-----------------------------------------------------------------+ #
#######################################################################

# The block(s) the BO3 should spawn in.
SourceBlocks: AIR

# The maximum percentage of the BO3 that can be outside the SourceBlock.
# The BO3 won't be placed on a location with more blocks outside the SourceBlock than this percentage.
MaxPercentageOutsideSourceBlock: 100

# What to do when a block is about to be placed outside the SourceBlock? (dontPlace, placeAnyway)
OutsideSourceBlock: placeAnyway


#######################################################################
# +-----------------------------------------------------------------+ #
# |                              Blocks                             | #
# +-----------------------------------------------------------------+ #
#######################################################################

# All the blocks used in the BO3 are listed here. Possible blocks:
# Block(x,y,z,id[.data][,nbtfile.nbt)
# RandomBlock(x,y,z,id[:data][,nbtfile.nbt],chance[,id[:data][,nbtfile.nbt],chance[,...]])
# So RandomBlock(0,0,0,CHEST,chest.nbt,50,CHEST,anotherchest.nbt,100) will spawn a chest at
# the BO3 origin, and give it a 50% chance to have the contents of chest.nbt, or, if that
# fails, a 100% percent chance to have the contents of anotherchest.nbt.
Block(4,40,-2,STONE)
Block(4,43,-2,STONE)
Block(4,44,-2,STONE)
Block(4,41,-2,STONE)
Block(4,42,-2,STONE)
Block(-1,-4,-10,STONE)
Block(15,-3,-7,STONE)
Block(15,-4,-7,STONE)
Block(15,-5,-7,STONE)
Block(-1,-5,-10,STONE)
Block(4,47,-2,STONE)
Block(4,45,-2,STONE)
Block(4,46,-2,STONE)
Block(4,32,-2,STONE)
Block(4,33,-2,STONE)
Block(4,30,-2,STONE)
Block(4,31,-2,STONE)
Block(5,1,-3,STONE)
Block(14,-5,-15,STONE)
Block(5,2,-3,STONE)
Block(15,-1,-7,STONE)
Block(15,-2,-7,STONE)
Block(5,0,-3,STONE)
Block(14,-2,-15,STONE)
Block(5,5,-3,STONE)
Block(14,-1,-15,STONE)
Block(5,6,-3,STONE)
Block(14,-4,-15,STONE)
Block(5,3,-3,STONE)
Block(14,-3,-15,STONE)
Block(5,4,-3,STONE)
Block(5,9,-3,STONE)
Block(4,36,-2,STONE)
Block(4,37,-2,STONE)
Block(5,7,-3,STONE)
Block(4,34,-2,STONE)
Block(5,8,-3,STONE)
Block(4,35,-2,STONE)
Block(4,38,-2,STONE)
Block(4,39,-2,STONE)
Block(6,-4,-3,STONE)
Block(5,-5,-8,STONE)
Block(6,-3,-3,STONE)
Block(5,-4,-8,STONE)
Block(6,-2,-3,STONE)
Block(5,-3,-8,STONE)
Block(6,-1,-3,STONE)
Block(4,21,-2,STONE)
Block(4,22,-2,STONE)
Block(4,20,-2,STONE)
Block(6,-5,-3,STONE)
Block(4,25,-2,STONE)
Block(4,26,-2,STONE)
Block(4,23,-2,STONE)
Block(4,24,-2,STONE)
Block(5,-2,-8,STONE)
Block(4,29,-2,STONE)
Block(5,-1,-8,STONE)
Block(4,27,-2,STONE)
Block(4,28,-2,STONE)
Block(4,10,-2,STONE)
Block(4,11,-2,STONE)
Block(4,14,-2,STONE)
Block(4,15,-2,STONE)
Block(4,12,-2,STONE)
Block(4,13,-2,STONE)
Block(4,18,-2,STONE)
Block(4,19,-2,STONE)
Block(4,16,-2,STONE)
Block(4,17,-2,STONE)
Block(5,39,-8,STONE)
Block(13,21,-6,STONE)
Block(13,20,-6,STONE)
Block(7,7,-8,STONE)
Block(15,15,-10,STONE)
Block(7,6,-8,STONE)
Block(7,5,-8,STONE)
Block(7,4,-8,STONE)
Block(15,11,-10,STONE)
Block(5,30,-8,STONE)
Block(15,12,-10,STONE)
Block(7,9,-8,STONE)
Block(15,13,-10,STONE)
Block(7,8,-8,STONE)
Block(15,14,-10,STONE)
Block(5,34,-8,STONE)
Block(5,33,-8,STONE)
Block(5,32,-8,STONE)
Block(15,10,-10,STONE)
Block(5,31,-8,STONE)
Block(7,3,-8,STONE)
Block(5,38,-8,STONE)
Block(7,2,-8,STONE)
Block(5,37,-8,STONE)
Block(7,1,-8,STONE)
Block(13,19,-6,STONE)
Block(5,36,-8,STONE)
Block(7,0,-8,STONE)
Block(13,18,-6,STONE)
Block(5,35,-8,STONE)
Block(-4,8,-1,STONE)
Block(-4,7,-1,STONE)
Block(-4,9,-1,STONE)
Block(-4,4,-1,STONE)
Block(-4,3,-1,STONE)
Block(-4,6,-1,STONE)
Block(-4,5,-1,STONE)
Block(15,13,-7,STONE)
Block(15,14,-7,STONE)
Block(15,10,-7,STONE)
Block(5,40,-8,STONE)
Block(15,11,-7,STONE)
Block(15,12,-7,STONE)
Block(-4,0,-1,STONE)
Block(-4,2,-1,STONE)
Block(-4,1,-1,STONE)
Block(6,18,-3,STONE)
Block(6,17,-3,STONE)
Block(5,19,-8,STONE)
Block(6,16,-3,STONE)
Block(5,18,-8,STONE)
Block(6,15,-3,STONE)
Block(5,17,-8,STONE)
Block(6,14,-3,STONE)
Block(6,13,-3,STONE)
Block(6,12,-3,STONE)
Block(6,11,-3,STONE)
Block(8,0,-2,STONE)
Block(8,1,-2,STONE)
Block(7,-1,-9,STONE)
Block(8,2,-2,STONE)
Block(6,19,-3,STONE)
Block(7,-2,-9,STONE)
Block(19,2,-15,STONE)
Block(7,-3,-9,STONE)
Block(19,1,-15,STONE)
Block(-3,9,5,STONE)
Block(7,-4,-9,STONE)
Block(19,0,-15,STONE)
Block(7,-5,-9,STONE)
Block(-3,6,5,STONE)
Block(-3,5,5,STONE)
Block(-3,8,5,STONE)
Block(-3,7,5,STONE)
Block(-3,2,5,STONE)
Block(6,10,-3,STONE)
Block(5,12,-8,STONE)
Block(-3,1,5,STONE)
Block(5,11,-8,STONE)
Block(-3,4,5,STONE)
Block(5,10,-8,STONE)
Block(-3,3,5,STONE)
Block(5,16,-8,STONE)
Block(5,15,-8,STONE)
Block(-3,0,5,STONE)
Block(5,14,-8,STONE)
Block(5,13,-8,STONE)
Block(5,29,-8,STONE)
Block(5,28,-8,STONE)
Block(8,3,-2,STONE)
Block(8,4,-2,STONE)
Block(8,5,-2,STONE)
Block(8,6,-2,STONE)
Block(8,7,-2,STONE)
Block(8,8,-2,STONE)
Block(8,9,-2,STONE)
Block(5,23,-8,STONE)
Block(5,22,-8,STONE)
Block(5,21,-8,STONE)
Block(5,20,-8,STONE)
Block(5,27,-8,STONE)
Block(5,26,-8,STONE)
Block(5,25,-8,STONE)
Block(5,24,-8,STONE)
Block(9,9,-12,STONE)
Block(6,39,-3,STONE)
Block(6,38,-3,STONE)
Block(6,37,-3,STONE)
Block(6,36,-3,STONE)
Block(6,35,-3,STONE)
Block(6,34,-3,STONE)
Block(6,33,-3,STONE)
Block(9,2,-12,STONE)
Block(9,1,-12,STONE)
Block(6,1,5,STONE)
Block(9,4,-12,STONE)
Block(9,3,-12,STONE)
Block(15,-5,-10,STONE)
Block(4,0,1,STONE)
Block(9,6,-12,STONE)
Block(9,5,-12,STONE)
Block(6,0,5,STONE)
Block(4,2,1,STONE)
Block(9,8,-12,STONE)
Block(4,1,1,STONE)
Block(9,7,-12,STONE)
Block(15,-1,-10,STONE)
Block(15,-2,-10,STONE)
Block(15,-3,-10,STONE)
Block(15,-4,-10,STONE)
Block(11,0,-11,STONE)
Block(11,2,-11,STONE)
Block(11,1,-11,STONE)
Block(11,4,-11,STONE)
Block(6,32,-3,STONE)
Block(11,3,-11,STONE)
Block(6,31,-3,STONE)
Block(11,6,-11,STONE)
Block(6,30,-3,STONE)
Block(11,5,-11,STONE)
Block(11,8,-11,STONE)
Block(11,7,-11,STONE)
Block(13,-5,-6,STONE)
Block(13,-4,-6,STONE)
Block(11,9,-11,STONE)
Block(10,5,-2,STONE)
Block(6,29,-3,STONE)
Block(10,4,-2,STONE)
Block(6,28,-3,STONE)
Block(10,3,-2,STONE)
Block(6,27,-3,STONE)
Block(10,2,-2,STONE)
Block(6,26,-3,STONE)
Block(10,9,-2,STONE)
Block(6,25,-3,STONE)
Block(10,8,-2,STONE)
Block(6,24,-3,STONE)
Block(10,7,-2,STONE)
Block(6,23,-3,STONE)
Block(10,6,-2,STONE)
Block(6,22,-3,STONE)
Block(-1,-4,-3,STONE)
Block(3,16,-7,STONE)
Block(-1,-3,-3,STONE)
Block(3,17,-7,STONE)
Block(3,14,-7,STONE)
Block(-1,-5,-3,STONE)
Block(3,15,-7,STONE)
Block(10,1,-2,STONE)
Block(3,12,-7,STONE)
Block(10,0,-2,STONE)
Block(3,13,-7,STONE)
Block(-1,-2,-3,STONE)
Block(3,10,-7,STONE)
Block(-1,-1,-3,STONE)
Block(3,11,-7,STONE)
Block(-9,0,2,STONE)
Block(9,0,-12,STONE)
Block(3,18,-7,STONE)
Block(3,19,-7,STONE)
Block(6,21,-3,STONE)
Block(6,20,-3,STONE)
Block(2,31,0,STONE)
Block(3,20,-7,STONE)
Block(2,32,0,STONE)
Block(2,33,0,STONE)
Block(2,34,0,STONE)
Block(2,30,0,STONE)
Block(3,27,-7,STONE)
Block(2,39,0,STONE)
Block(3,28,-7,STONE)
Block(3,25,-7,STONE)
Block(3,26,-7,STONE)
Block(3,23,-7,STONE)
Block(2,35,0,STONE)
Block(3,24,-7,STONE)
Block(2,36,0,STONE)
Block(3,21,-7,STONE)
Block(2,37,0,STONE)
Block(3,22,-7,STONE)
Block(2,38,0,STONE)
Block(8,-1,-4,STONE)
Block(8,-2,-4,STONE)
Block(8,-3,-4,STONE)
Block(3,29,-7,STONE)
Block(8,-4,-4,STONE)
Block(8,-5,-4,STONE)
Block(13,17,-6,STONE)
Block(3,30,-7,STONE)
Block(2,42,0,STONE)
Block(13,16,-6,STONE)
Block(3,31,-7,STONE)
Block(13,15,-6,STONE)
Block(13,14,-6,STONE)
Block(6,48,-3,STONE)
Block(13,13,-6,STONE)
Block(6,47,-3,STONE)
Block(13,12,-6,STONE)
Block(6,46,-3,STONE)
Block(13,11,-6,STONE)
Block(2,40,0,STONE)
Block(6,45,-3,STONE)
Block(13,10,-6,STONE)
Block(2,41,0,STONE)
Block(6,44,-3,STONE)
Block(3,38,-7,STONE)
Block(3,36,-7,STONE)
Block(3,37,-7,STONE)
Block(3,34,-7,STONE)
Block(3,35,-7,STONE)
Block(3,32,-7,STONE)
Block(3,33,-7,STONE)
Block(2,2,-4,STONE)
Block(2,1,-4,STONE)
Block(2,0,-4,STONE)
Block(2,6,-4,STONE)
Block(6,43,-3,STONE)
Block(2,5,-4,STONE)
Block(6,42,-3,STONE)
Block(2,4,-4,STONE)
Block(6,41,-3,STONE)
Block(2,3,-4,STONE)
Block(6,40,-3,STONE)
Block(2,9,-4,STONE)
Block(2,8,-4,STONE)
Block(2,7,-4,STONE)
Block(2,10,0,STONE)
Block(-10,-1,9,STONE)
Block(2,11,0,STONE)
Block(2,12,0,STONE)
Block(11,32,-5,STONE)
Block(11,31,-5,STONE)
Block(11,30,-5,STONE)
Block(2,17,0,STONE)
Block(11,36,-5,STONE)
Block(2,18,0,STONE)
Block(11,35,-5,STONE)
Block(2,19,0,STONE)
Block(11,34,-5,STONE)
Block(11,33,-5,STONE)
Block(-10,-3,9,STONE)
Block(4,9,-9,STONE)
Block(2,13,0,STONE)
Block(-10,-2,9,STONE)
Block(4,8,-9,STONE)
Block(2,14,0,STONE)
Block(11,39,-5,STONE)
Block(-10,-5,9,STONE)
Block(2,15,0,STONE)
Block(11,38,-5,STONE)
Block(-10,-4,9,STONE)
Block(2,16,0,STONE)
Block(11,37,-5,STONE)
Block(4,5,-9,STONE)
Block(-1,10,-3,STONE)
Block(4,4,-9,STONE)
Block(4,7,-9,STONE)
Block(-1,12,-3,STONE)
Block(4,6,-9,STONE)
Block(-1,11,-3,STONE)
Block(12,-5,-14,STONE)
Block(4,1,-9,STONE)
Block(4,0,-9,STONE)
Block(12,-4,-14,STONE)
Block(4,3,-9,STONE)
Block(4,2,-9,STONE)
Block(3,-1,-12,STONE)
Block(3,-4,-12,STONE)
Block(3,-5,-12,STONE)
Block(3,-2,-12,STONE)
Block(3,-3,-12,STONE)
Block(-6,3,3,STONE)
Block(2,20,0,STONE)
Block(-6,2,3,STONE)
Block(2,21,0,STONE)
Block(-6,1,3,STONE)
Block(2,22,0,STONE)
Block(-6,0,3,STONE)
Block(2,23,0,STONE)
Block(11,42,-5,STONE)
Block(11,41,-5,STONE)
Block(11,40,-5,STONE)
Block(3,-2,-7,STONE)
Block(-1,18,-3,STONE)
Block(2,28,0,STONE)
Block(3,-3,-7,STONE)
Block(-1,17,-3,STONE)
Block(2,29,0,STONE)
Block(-6,9,3,STONE)
Block(3,-1,-7,STONE)
Block(-6,8,3,STONE)
Block(-1,19,-3,STONE)
Block(-6,7,3,STONE)
Block(-1,14,-3,STONE)
Block(2,24,0,STONE)
Block(-6,6,3,STONE)
Block(-1,13,-3,STONE)
Block(2,25,0,STONE)
Block(-6,5,3,STONE)
Block(-1,16,-3,STONE)
Block(2,26,0,STONE)
Block(-6,4,3,STONE)
Block(-1,15,-3,STONE)
Block(2,27,0,STONE)
Block(-1,21,-3,STONE)
Block(-1,20,-3,STONE)
Block(-1,23,-3,STONE)
Block(-1,22,-3,STONE)
Block(3,-4,-7,STONE)
Block(3,-5,-7,STONE)
Block(11,10,-5,STONE)
Block(0,0,-10,STONE)
Block(11,14,-5,STONE)
Block(-4,21,1,STONE)
Block(11,13,-5,STONE)
Block(-4,20,1,STONE)
Block(11,12,-5,STONE)
Block(11,11,-5,STONE)
Block(11,18,-5,STONE)
Block(11,17,-5,STONE)
Block(11,16,-5,STONE)
Block(11,15,-5,STONE)
Block(8,-5,-14,STONE)
Block(8,14,-4,STONE)
Block(-4,18,1,STONE)
Block(8,15,-4,STONE)
Block(-4,17,1,STONE)
Block(8,16,-4,STONE)
Block(-4,16,1,STONE)
Block(-4,15,1,STONE)
Block(8,17,-4,STONE)
Block(8,10,-4,STONE)
Block(-4,14,1,STONE)
Block(8,11,-4,STONE)
Block(-4,13,1,STONE)
Block(8,12,-4,STONE)
Block(-4,12,1,STONE)
Block(-4,11,1,STONE)
Block(8,13,-4,STONE)
Block(8,-1,-14,STONE)
Block(8,18,-4,STONE)
Block(8,-2,-14,STONE)
Block(8,19,-4,STONE)
Block(8,-3,-14,STONE)
Block(8,-4,-14,STONE)
Block(-4,19,1,STONE)
Block(13,-3,-6,STONE)
Block(10,5,-13,STONE)
Block(13,-2,-6,STONE)
Block(10,4,-13,STONE)
Block(13,-1,-6,STONE)
Block(10,3,-13,STONE)
Block(10,2,-13,STONE)
Block(11,21,-5,STONE)
Block(10,9,-13,STONE)
Block(10,8,-13,STONE)
Block(11,20,-5,STONE)
Block(10,7,-13,STONE)
Block(10,6,-13,STONE)
Block(-4,10,1,STONE)
Block(11,25,-5,STONE)
Block(11,24,-5,STONE)
Block(11,23,-5,STONE)
Block(8,20,-4,STONE)
Block(11,22,-5,STONE)
Block(10,1,-13,STONE)
Block(11,29,-5,STONE)
Block(10,0,-13,STONE)
Block(11,28,-5,STONE)
Block(11,27,-5,STONE)
Block(11,26,-5,STONE)
Block(8,25,-4,STONE)
Block(8,26,-4,STONE)
Block(8,27,-4,STONE)
Block(11,19,-5,STONE)
Block(8,28,-4,STONE)
Block(8,21,-4,STONE)
Block(8,22,-4,STONE)
Block(8,23,-4,STONE)
Block(8,24,-4,STONE)
Block(8,29,-4,STONE)
Block(2,-3,0,STONE)
Block(2,-4,0,STONE)
Block(2,-5,0,STONE)
Block(8,30,-4,STONE)
Block(8,31,-4,STONE)
Block(2,-1,0,STONE)
Block(2,-2,0,STONE)
Block(8,36,-4,STONE)
Block(8,37,-4,STONE)
Block(8,38,-4,STONE)
Block(8,39,-4,STONE)
Block(8,32,-4,STONE)
Block(8,33,-4,STONE)
Block(8,34,-4,STONE)
Block(8,35,-4,STONE)
Block(-1,5,0,STONE)
Block(-1,4,0,STONE)
Block(-1,7,0,STONE)
Block(-1,6,0,STONE)
Block(8,0,-14,STONE)
Block(-1,9,0,STONE)
Block(-1,8,0,STONE)
Block(2,-4,-1,STONE)
Block(2,-3,-1,STONE)
Block(8,40,-4,STONE)
Block(7,-4,4,STONE)
Block(8,41,-4,STONE)
Block(2,-5,-1,STONE)
Block(7,-5,4,STONE)
Block(8,42,-4,STONE)
Block(7,-2,4,STONE)
Block(7,-3,4,STONE)
Block(2,-2,-1,STONE)
Block(2,-1,-1,STONE)
Block(7,-1,4,STONE)
Block(9,4,3,STONE)
Block(9,5,3,STONE)
Block(9,6,3,STONE)
Block(9,7,3,STONE)
Block(8,43,-4,STONE)
Block(8,44,-4,STONE)
Block(8,45,-4,STONE)
Block(8,46,-4,STONE)
Block(-6,11,5,STONE)
Block(-6,12,5,STONE)
Block(-9,-1,5,STONE)
Block(-6,10,5,STONE)
Block(-9,-3,5,STONE)
Block(9,0,3,STONE)
Block(-1,1,0,STONE)
Block(-6,15,5,STONE)
Block(-9,-2,5,STONE)
Block(-1,0,0,STONE)
Block(9,1,3,STONE)
Block(-6,16,5,STONE)
Block(-9,-5,5,STONE)
Block(9,2,3,STONE)
Block(-1,3,0,STONE)
Block(-6,13,5,STONE)
Block(-9,-4,5,STONE)
Block(-1,2,0,STONE)
Block(9,3,3,STONE)
Block(-6,14,5,STONE)
Block(12,8,-6,STONE)
Block(12,9,-6,STONE)
Block(18,-1,-11,STONE)
Block(-1,29,-3,STONE)
Block(18,-2,-11,STONE)
Block(-1,28,-3,STONE)
Block(18,-3,-11,STONE)
Block(18,-4,-11,STONE)
Block(18,-5,-11,STONE)
Block(11,-4,-5,STONE)
Block(-1,25,-3,STONE)
Block(11,-3,-5,STONE)
Block(-1,24,-3,STONE)
Block(11,-2,-5,STONE)
Block(-1,27,-3,STONE)
Block(11,-1,-5,STONE)
Block(-1,26,-3,STONE)
Block(-4,-4,1,STONE)
Block(-4,-3,1,STONE)
Block(-4,-2,1,STONE)
Block(-4,-1,1,STONE)
Block(-4,-5,1,STONE)
Block(-1,6,-2,STONE)
Block(-1,5,-2,STONE)
Block(-1,4,-2,STONE)
Block(-1,3,-2,STONE)
Block(-1,2,-2,STONE)
Block(-1,1,-2,STONE)
Block(-1,0,-2,STONE)
Block(-1,9,-2,STONE)
Block(-1,8,-2,STONE)
Block(-1,7,-2,STONE)
Block(11,-5,-5,STONE)
Block(15,2,-6,STONE)
Block(15,1,-6,STONE)
Block(15,0,-6,STONE)
Block(12,4,-6,STONE)
Block(15,6,-6,STONE)
Block(12,5,-6,STONE)
Block(15,5,-6,STONE)
Block(15,4,-6,STONE)
Block(12,6,-6,STONE)
Block(15,3,-6,STONE)
Block(12,7,-6,STONE)
Block(12,0,-6,STONE)
Block(12,1,-6,STONE)
Block(15,9,-6,STONE)
Block(12,2,-6,STONE)
Block(15,8,-6,STONE)
Block(12,3,-6,STONE)
Block(15,7,-6,STONE)
Block(4,5,0,STONE)
Block(4,4,0,STONE)
Block(4,7,0,STONE)
Block(4,6,0,STONE)
Block(4,9,0,STONE)
Block(4,8,0,STONE)
Block(4,1,0,STONE)
Block(4,0,0,STONE)
Block(4,3,0,STONE)
Block(4,2,0,STONE)
Block(12,2,-10,STONE)
Block(12,1,-10,STONE)
Block(12,0,-10,STONE)
Block(12,9,-10,STONE)
Block(12,8,-10,STONE)
Block(12,7,-10,STONE)
Block(12,6,-10,STONE)
Block(12,5,-10,STONE)
Block(12,4,-10,STONE)
Block(12,3,-10,STONE)
Block(17,-1,-8,STONE)
Block(2,47,-1,STONE)
Block(2,46,-1,STONE)
Block(-7,-5,1,STONE)
Block(2,43,-1,STONE)
Block(19,3,-14,STONE)
Block(-7,-4,1,STONE)
Block(19,2,-14,STONE)
Block(2,42,-1,STONE)
Block(19,1,-14,STONE)
Block(2,45,-1,STONE)
Block(19,0,-14,STONE)
Block(2,44,-1,STONE)
Block(-7,-1,1,STONE)
Block(-7,-3,1,STONE)
Block(2,41,-1,STONE)
Block(-7,-2,1,STONE)
Block(2,40,-1,STONE)
Block(6,-1,-13,STONE)
Block(6,-4,-13,STONE)
Block(6,-5,-13,STONE)
Block(6,-2,-13,STONE)
Block(6,-3,-13,STONE)
Block(1,-2,-11,STONE)
Block(1,-1,-11,STONE)
Block(5,-1,0,STONE)
Block(5,-5,0,STONE)
Block(5,-4,0,STONE)
Block(5,-3,0,STONE)
Block(5,-2,0,STONE)
Block(0,-5,-5,STONE)
Block(-8,6,7,STONE)
Block(-8,7,7,STONE)
Block(-8,8,7,STONE)
Block(-8,9,7,STONE)
Block(17,-3,-8,STONE)
Block(-1,-2,6,STONE)
Block(17,-2,-8,STONE)
Block(-1,-1,6,STONE)
Block(17,-5,-8,STONE)
Block(17,-4,-8,STONE)
Block(0,-4,-5,STONE)
Block(-1,-5,6,STONE)
Block(0,-3,-5,STONE)
Block(-1,-4,6,STONE)
Block(0,-2,-5,STONE)
Block(-1,-3,6,STONE)
Block(0,-1,-5,STONE)
Block(-6,-5,5,STONE)
Block(-6,-3,5,STONE)
Block(-6,-4,5,STONE)
Block(1,9,2,STONE)
Block(1,8,2,STONE)
Block(1,7,2,STONE)
Block(1,6,2,STONE)
Block(1,5,2,STONE)
Block(-8,2,7,STONE)
Block(-8,3,7,STONE)
Block(-8,4,7,STONE)
Block(-8,5,7,STONE)
Block(-8,0,7,STONE)
Block(-8,1,7,STONE)
Block(-9,0,11,STONE)
Block(2,18,-1,STONE)
Block(2,17,-1,STONE)
Block(2,19,-1,STONE)
Block(2,14,-1,STONE)
Block(2,13,-1,STONE)
Block(2,16,-1,STONE)
Block(2,15,-1,STONE)
Block(2,10,-1,STONE)
Block(2,12,-1,STONE)
Block(2,11,-1,STONE)
Block(-6,-1,5,STONE)
Block(1,-5,-11,STONE)
Block(-6,-2,5,STONE)
Block(1,-4,-11,STONE)
Block(1,-3,-11,STONE)
Block(2,29,-1,STONE)
Block(2,28,-1,STONE)
Block(2,25,-1,STONE)
Block(2,24,-1,STONE)
Block(2,27,-1,STONE)
Block(2,26,-1,STONE)
Block(-10,3,8,STONE)
Block(2,21,-1,STONE)
Block(-10,2,8,STONE)
Block(2,20,-1,STONE)
Block(-10,1,8,STONE)
Block(2,23,-1,STONE)
Block(-10,0,8,STONE)
Block(2,22,-1,STONE)
Block(4,-1,4,STONE)
Block(4,-2,4,STONE)
Block(4,-3,4,STONE)
Block(4,-4,4,STONE)
Block(4,-5,4,STONE)
Block(-11,0,10,STONE)
Block(2,39,-1,STONE)
Block(2,36,-1,STONE)
Block(2,35,-1,STONE)
Block(2,38,-1,STONE)
Block(2,37,-1,STONE)
Block(-10,4,8,STONE)
Block(2,32,-1,STONE)
Block(2,31,-1,STONE)
Block(2,34,-1,STONE)
Block(2,33,-1,STONE)
Block(2,30,-1,STONE)
Block(1,4,2,STONE)
Block(1,3,2,STONE)
Block(1,2,2,STONE)
Block(1,1,2,STONE)
Block(1,0,2,STONE)
Block(10,-5,1,STONE)
Block(16,-3,-10,STONE)
Block(10,-1,1,STONE)
Block(16,-2,-10,STONE)
Block(10,-2,1,STONE)
Block(16,-5,-10,STONE)
Block(9,-5,-5,STONE)
Block(10,-3,1,STONE)
Block(16,-4,-10,STONE)
Block(9,-4,-5,STONE)
Block(10,-4,1,STONE)
Block(-3,7,4,STONE)
Block(-3,6,4,STONE)
Block(16,-1,-10,STONE)
Block(-3,9,4,STONE)
Block(-3,8,4,STONE)
Block(-3,3,4,STONE)
Block(-3,2,4,STONE)
Block(-3,5,4,STONE)
Block(-3,4,4,STONE)
Block(9,-3,-5,STONE)
Block(9,-2,-5,STONE)
Block(9,-1,-5,STONE)
Block(-3,1,4,STONE)
Block(-3,0,4,STONE)
Block(2,-1,-6,STONE)
Block(2,-2,-6,STONE)
Block(2,-3,-6,STONE)
Block(2,-4,-6,STONE)
Block(-2,-3,-4,STONE)
Block(2,-5,-6,STONE)
Block(-2,-4,-4,STONE)
Block(-2,-5,-4,STONE)
Block(10,44,-4,STONE)
Block(-2,-1,-4,STONE)
Block(-2,-2,-4,STONE)
Block(10,40,-4,STONE)
Block(10,41,-4,STONE)
Block(10,42,-4,STONE)
Block(10,43,-4,STONE)
Block(-5,-5,8,STONE)
Block(10,37,-4,STONE)
Block(10,38,-4,STONE)
Block(10,39,-4,STONE)
Block(10,33,-4,STONE)
Block(10,34,-4,STONE)
Block(10,35,-4,STONE)
Block(10,36,-4,STONE)
Block(10,30,-4,STONE)
Block(10,31,-4,STONE)
Block(10,32,-4,STONE)
Block(10,19,-4,STONE)
Block(-5,-4,8,STONE)
Block(10,26,-4,STONE)
Block(-5,-3,8,STONE)
Block(10,27,-4,STONE)
Block(-5,-2,8,STONE)
Block(10,28,-4,STONE)
Block(-5,-1,8,STONE)
Block(10,29,-4,STONE)
Block(10,22,-4,STONE)
Block(10,23,-4,STONE)
Block(10,24,-4,STONE)
Block(10,25,-4,STONE)
Block(10,20,-4,STONE)
Block(10,21,-4,STONE)
Block(8,0,-3,STONE)
Block(8,1,-3,STONE)
Block(10,15,-4,STONE)
Block(10,16,-4,STONE)
Block(10,17,-4,STONE)
Block(10,18,-4,STONE)
Block(10,11,-4,STONE)
Block(0,21,-5,STONE)
Block(10,12,-4,STONE)
Block(0,20,-5,STONE)
Block(10,13,-4,STONE)
Block(10,14,-4,STONE)
Block(3,-3,7,STONE)
Block(3,-4,7,STONE)
Block(0,24,-5,STONE)
Block(3,-5,7,STONE)
Block(0,23,-5,STONE)
Block(10,10,-4,STONE)
Block(0,22,-5,STONE)
Block(8,2,-3,STONE)
Block(8,3,-3,STONE)
Block(8,4,-3,STONE)
Block(8,5,-3,STONE)
Block(8,6,-3,STONE)
Block(8,7,-3,STONE)
Block(8,8,-3,STONE)
Block(8,9,-3,STONE)
Block(7,6,-9,STONE)
Block(7,5,-9,STONE)
Block(7,4,-9,STONE)
Block(7,3,-9,STONE)
Block(11,1,-10,STONE)
Block(11,0,-10,STONE)
Block(7,9,-9,STONE)
Block(11,3,-10,STONE)
Block(7,8,-9,STONE)
Block(11,2,-10,STONE)
Block(7,7,-9,STONE)
Block(11,5,-10,STONE)
Block(11,4,-10,STONE)
Block(11,7,-10,STONE)
Block(11,6,-10,STONE)
Block(7,2,-9,STONE)
Block(11,9,-10,STONE)
Block(7,1,-9,STONE)
Block(11,8,-10,STONE)
Block(7,0,-9,STONE)
Block(0,19,-5,STONE)
Block(10,-5,-4,STONE)
Block(0,10,-5,STONE)
Block(-9,0,3,STONE)
Block(-9,3,3,STONE)
Block(0,14,-5,STONE)
Block(-5,10,8,STONE)
Block(-9,4,3,STONE)
Block(0,13,-5,STONE)
Block(-9,1,3,STONE)
Block(0,12,-5,STONE)
Block(-9,2,3,STONE)
Block(0,11,-5,STONE)
Block(0,18,-5,STONE)
Block(0,17,-5,STONE)
Block(-9,5,3,STONE)
Block(0,16,-5,STONE)
Block(0,15,-5,STONE)
Block(-9,6,3,STONE)
Block(5,-4,6,STONE)
Block(5,-5,6,STONE)
Block(-7,-1,7,STONE)
Block(-7,-2,7,STONE)
Block(9,42,-5,STONE)
Block(-7,-3,7,STONE)
Block(9,41,-5,STONE)
Block(-7,-4,7,STONE)
Block(9,40,-5,STONE)
Block(-7,-5,7,STONE)
Block(-1,-1,0,STONE)
Block(4,3,2,STONE)
Block(-1,-2,0,STONE)
Block(4,2,2,STONE)
Block(-1,-3,0,STONE)
Block(4,5,2,STONE)
Block(-1,-4,0,STONE)
Block(4,4,2,STONE)
Block(-1,-5,0,STONE)
Block(2,3,-3,STONE)
Block(4,7,2,STONE)
Block(2,2,-3,STONE)
Block(4,6,2,STONE)
Block(2,1,-3,STONE)
Block(4,9,2,STONE)
Block(2,0,-3,STONE)
Block(4,8,2,STONE)
Block(2,7,-3,STONE)
Block(2,6,-3,STONE)
Block(2,5,-3,STONE)
Block(9,44,-5,STONE)
Block(2,4,-3,STONE)
Block(9,43,-5,STONE)
Block(2,9,-3,STONE)
Block(2,8,-3,STONE)
Block(9,31,-5,STONE)
Block(9,30,-5,STONE)
Block(4,1,2,STONE)
Block(4,0,2,STONE)
Block(9,35,-5,STONE)
Block(9,34,-5,STONE)
Block(9,33,-5,STONE)
Block(9,32,-5,STONE)
Block(9,39,-5,STONE)
Block(9,38,-5,STONE)
Block(9,37,-5,STONE)
Block(9,36,-5,STONE)
Block(-6,4,2,STONE)
Block(-6,3,2,STONE)
Block(-6,2,2,STONE)
Block(-6,1,2,STONE)
Block(-12,-4,7,STONE)
Block(17,-2,-16,STONE)
Block(-6,0,2,STONE)
Block(9,20,-5,STONE)
Block(-12,-5,7,STONE)
Block(17,-1,-16,STONE)
Block(17,-4,-16,STONE)
Block(-12,-2,7,STONE)
Block(17,-3,-16,STONE)
Block(-12,-3,7,STONE)
Block(17,-5,-16,STONE)
Block(-12,-1,7,STONE)
Block(-6,9,2,STONE)
Block(-6,8,2,STONE)
Block(-6,7,2,STONE)
Block(-6,6,2,STONE)
Block(-6,5,2,STONE)
Block(-11,-1,5,STONE)
Block(-11,-2,5,STONE)
Block(9,29,-5,STONE)
Block(-11,-3,5,STONE)
Block(-11,-4,5,STONE)
Block(-11,-5,5,STONE)
Block(9,24,-5,STONE)
Block(9,23,-5,STONE)
Block(9,22,-5,STONE)
Block(9,21,-5,STONE)
Block(9,28,-5,STONE)
Block(9,27,-5,STONE)
Block(9,26,-5,STONE)
Block(9,25,-5,STONE)
Block(2,20,-6,STONE)
Block(2,21,-6,STONE)
Block(2,22,-6,STONE)
Block(2,23,-6,STONE)
Block(2,24,-6,STONE)
Block(2,25,-6,STONE)
Block(2,26,-6,STONE)
Block(2,27,-6,STONE)
Block(2,28,-6,STONE)
Block(2,29,-6,STONE)
Block(9,19,-5,STONE)
Block(9,18,-5,STONE)
Block(4,-2,-12,STONE)
Block(9,13,-5,STONE)
Block(4,-1,-12,STONE)
Block(9,12,-5,STONE)
Block(9,11,-5,STONE)
Block(9,10,-5,STONE)
Block(9,17,-5,STONE)
Block(4,-5,-12,STONE)
Block(9,16,-5,STONE)
Block(4,-4,-12,STONE)
Block(9,15,-5,STONE)
Block(4,-3,-12,STONE)
Block(9,14,-5,STONE)
Block(7,0,0,STONE)
Block(2,10,-6,STONE)
Block(2,11,-6,STONE)
Block(2,12,-6,STONE)
Block(2,13,-6,STONE)
Block(2,14,-6,STONE)
Block(2,15,-6,STONE)
Block(2,16,-6,STONE)
Block(2,17,-6,STONE)
Block(2,18,-6,STONE)
Block(2,19,-6,STONE)
Block(-8,-5,9,STONE)
Block(7,9,0,STONE)
Block(-8,-3,9,STONE)
Block(-8,-4,9,STONE)
Block(-8,-1,9,STONE)
Block(-8,-2,9,STONE)
Block(7,4,0,STONE)
Block(7,3,0,STONE)
Block(7,2,0,STONE)
Block(7,1,0,STONE)
Block(7,8,0,STONE)
Block(7,7,0,STONE)
Block(7,6,0,STONE)
Block(7,5,0,STONE)
Block(10,6,-1,STONE)
Block(10,5,-1,STONE)
Block(10,4,-1,STONE)
Block(10,3,-1,STONE)
Block(10,9,-1,STONE)
Block(10,8,-1,STONE)
Block(2,30,-6,STONE)
Block(10,7,-1,STONE)
Block(2,31,-6,STONE)
Block(2,32,-6,STONE)
Block(2,33,-6,STONE)
Block(2,34,-6,STONE)
Block(10,2,-1,STONE)
Block(10,1,-1,STONE)
Block(10,0,-1,STONE)
Block(5,2,-2,STONE)
Block(5,3,-2,STONE)
Block(5,0,-2,STONE)
Block(5,1,-2,STONE)
Block(5,6,-2,STONE)
Block(5,7,-2,STONE)
Block(5,4,-2,STONE)
Block(5,5,-2,STONE)
Block(5,8,-2,STONE)
Block(5,9,-2,STONE)
Block(5,12,-2,STONE)
Block(5,11,-2,STONE)
Block(5,14,-2,STONE)
Block(5,13,-2,STONE)
Block(12,9,-5,STONE)
Block(5,16,-2,STONE)
Block(5,15,-2,STONE)
Block(5,18,-2,STONE)
Block(5,17,-2,STONE)
Block(-5,9,8,STONE)
Block(-5,8,8,STONE)
Block(5,19,-2,STONE)
Block(-10,2,9,STONE)
Block(-10,1,9,STONE)
Block(-10,0,9,STONE)
Block(14,16,-7,STONE)
Block(14,17,-7,STONE)
Block(14,14,-7,STONE)
Block(14,15,-7,STONE)
Block(14,12,-7,STONE)
Block(14,13,-7,STONE)
Block(14,10,-7,STONE)
Block(5,10,-2,STONE)
Block(14,11,-7,STONE)
Block(-1,5,-3,STONE)
Block(5,23,-2,STONE)
Block(-1,4,-3,STONE)
Block(5,22,-2,STONE)
Block(-1,3,-3,STONE)
Block(5,25,-2,STONE)
Block(-1,2,-3,STONE)
Block(5,24,-2,STONE)
Block(-1,1,-3,STONE)
Block(5,27,-2,STONE)
Block(-1,0,-3,STONE)
Block(5,26,-2,STONE)
Block(5,29,-2,STONE)
Block(14,18,-7,STONE)
Block(5,28,-2,STONE)
Block(-1,9,-3,STONE)
Block(-1,8,-3,STONE)
Block(-1,7,-3,STONE)
Block(-1,6,-3,STONE)
Block(12,0,-5,STONE)
Block(1,3,3,STONE)
Block(12,5,-5,STONE)
Block(1,2,3,STONE)
Block(12,6,-5,STONE)
Block(1,1,3,STONE)
Block(12,7,-5,STONE)
Block(1,0,3,STONE)
Block(12,8,-5,STONE)
Block(12,1,-5,STONE)
Block(12,2,-5,STONE)
Block(12,3,-5,STONE)
Block(5,21,-2,STONE)
Block(12,4,-5,STONE)
Block(5,20,-2,STONE)
Block(2,-4,-11,STONE)
Block(2,-5,-11,STONE)
Block(1,23,-6,STONE)
Block(1,22,-6,STONE)
Block(1,25,-6,STONE)
Block(1,24,-6,STONE)
Block(1,27,-6,STONE)
Block(1,26,-6,STONE)
Block(1,28,-6,STONE)
Block(-3,-1,-4,STONE)
Block(-3,-4,-4,STONE)
Block(-3,-5,-4,STONE)
Block(-3,-2,-4,STONE)
Block(1,21,-6,STONE)
Block(-3,-3,-4,STONE)
Block(1,20,-6,STONE)
Block(1,19,-6,STONE)
Block(-5,1,8,STONE)
Block(1,12,-6,STONE)
Block(-5,0,8,STONE)
Block(1,11,-6,STONE)
Block(-5,3,8,STONE)
Block(1,14,-6,STONE)
Block(-5,2,8,STONE)
Block(1,13,-6,STONE)
Block(-5,5,8,STONE)
Block(1,16,-6,STONE)
Block(-5,4,8,STONE)
Block(1,15,-6,STONE)
Block(-5,7,8,STONE)
Block(1,18,-6,STONE)
Block(-5,6,8,STONE)
Block(1,17,-6,STONE)
Block(2,-1,-11,STONE)
Block(2,-2,-11,STONE)
Block(1,10,-6,STONE)
Block(2,-3,-11,STONE)
Block(6,-5,-9,STONE)
Block(3,31,-2,STONE)
Block(3,32,-2,STONE)
Block(6,-3,-9,STONE)
Block(3,33,-2,STONE)
Block(6,-4,-9,STONE)
Block(3,34,-2,STONE)
Block(3,30,-2,STONE)
Block(3,39,-2,STONE)
Block(6,-1,-9,STONE)
Block(3,35,-2,STONE)
Block(6,-2,-9,STONE)
Block(3,36,-2,STONE)
Block(3,37,-2,STONE)
Block(3,38,-2,STONE)
Block(14,-2,-7,STONE)
Block(-10,-2,10,STONE)
Block(14,-3,-7,STONE)
Block(-10,-3,10,STONE)
Block(14,-1,-7,STONE)
Block(-10,-1,10,STONE)
Block(-10,-4,10,STONE)
Block(-10,-5,10,STONE)
Block(-7,12,7,STONE)
Block(-7,13,7,STONE)
Block(-7,14,7,STONE)
Block(14,-4,-7,STONE)
Block(14,-5,-7,STONE)
Block(3,42,-2,STONE)
Block(3,43,-2,STONE)
Block(3,44,-2,STONE)
Block(13,0,-2,STONE)
Block(3,45,-2,STONE)
Block(-7,10,7,STONE)
Block(3,40,-2,STONE)
Block(-7,11,7,STONE)
Block(3,41,-2,STONE)
Block(15,3,-5,STONE)
Block(3,46,-2,STONE)
Block(15,2,-5,STONE)
Block(3,47,-2,STONE)
Block(15,1,-5,STONE)
Block(3,48,-2,STONE)
Block(15,0,-5,STONE)
Block(15,6,-5,STONE)
Block(15,5,-5,STONE)
Block(15,4,-5,STONE)
Block(5,34,-2,STONE)
Block(5,33,-2,STONE)
Block(5,36,-2,STONE)
Block(5,35,-2,STONE)
Block(5,38,-2,STONE)
Block(5,37,-2,STONE)
Block(5,39,-2,STONE)
Block(9,3,-11,STONE)
Block(9,2,-11,STONE)
Block(9,5,-11,STONE)
Block(9,4,-11,STONE)
Block(16,-1,-7,STONE)
Block(9,7,-11,STONE)
Block(1,7,-9,STONE)
Block(9,6,-11,STONE)
Block(1,8,-9,STONE)
Block(1,5,-9,STONE)
Block(9,9,-11,STONE)
Block(1,6,-9,STONE)
Block(9,8,-11,STONE)
Block(1,3,-9,STONE)
Block(1,4,-9,STONE)
Block(1,1,-9,STONE)
Block(1,2,-9,STONE)
Block(1,0,-9,STONE)
Block(9,-1,-14,STONE)
Block(9,-4,-14,STONE)
Block(5,30,-2,STONE)
Block(9,-5,-14,STONE)
Block(9,-2,-14,STONE)
Block(5,32,-2,STONE)
Block(9,-3,-14,STONE)
Block(5,31,-2,STONE)
Block(5,45,-2,STONE)
Block(5,44,-2,STONE)
Block(5,47,-2,STONE)
Block(5,46,-2,STONE)
Block(1,-5,-6,STONE)
Block(16,-5,-7,STONE)
Block(4,4,1,STONE)
Block(16,-4,-7,STONE)
Block(4,3,1,STONE)
Block(16,-3,-7,STONE)
Block(4,6,1,STONE)
Block(16,-2,-7,STONE)
Block(4,5,1,STONE)
Block(1,-2,-6,STONE)
Block(4,8,1,STONE)
Block(1,-1,-6,STONE)
Block(4,7,1,STONE)
Block(1,-4,-6,STONE)
Block(9,1,-11,STONE)
Block(1,-3,-6,STONE)
Block(9,0,-11,STONE)
Block(4,9,1,STONE)
Block(5,41,-2,STONE)
Block(5,40,-2,STONE)
Block(5,43,-2,STONE)
Block(5,42,-2,STONE)
Block(6,19,-9,STONE)
Block(6,17,-9,STONE)
Block(6,18,-9,STONE)
Block(-1,-5,-8,STONE)
Block(-1,-4,-8,STONE)
Block(10,-1,-4,STONE)
Block(6,11,-9,STONE)
Block(-2,-2,8,STONE)
Block(-2,-3,8,STONE)
Block(10,-2,-4,STONE)
Block(6,12,-9,STONE)
Block(-2,-4,8,STONE)
Block(10,-3,-4,STONE)
Block(-2,-5,8,STONE)
Block(10,-4,-4,STONE)
Block(6,10,-9,STONE)
Block(6,15,-9,STONE)
Block(6,16,-9,STONE)
Block(6,13,-9,STONE)
Block(6,14,-9,STONE)
Block(-4,11,7,STONE)
Block(-4,12,7,STONE)
Block(-4,10,7,STONE)
Block(-4,13,7,STONE)
Block(8,-5,-9,STONE)
Block(8,-3,-9,STONE)
Block(-8,7,6,STONE)
Block(8,-4,-9,STONE)
Block(-8,8,6,STONE)
Block(8,-1,-9,STONE)
Block(-8,9,6,STONE)
Block(8,-2,-9,STONE)
Block(-8,3,6,STONE)
Block(-8,4,6,STONE)
Block(3,10,-2,STONE)
Block(16,10,-7,STONE)
Block(-8,5,6,STONE)
Block(7,10,-9,STONE)
Block(3,11,-2,STONE)
Block(-8,6,6,STONE)
Block(7,11,-9,STONE)
Block(3,12,-2,STONE)
Block(19,0,-13,STONE)
Block(7,12,-9,STONE)
Block(-8,0,6,STONE)
Block(7,13,-9,STONE)
Block(-8,1,6,STONE)
Block(7,14,-9,STONE)
Block(-8,2,6,STONE)
Block(7,15,-9,STONE)
Block(7,16,-9,STONE)
Block(3,17,-2,STONE)
Block(7,17,-9,STONE)
Block(3,18,-2,STONE)
Block(19,3,-13,STONE)
Block(19,2,-13,STONE)
Block(7,18,-9,STONE)
Block(3,19,-2,STONE)
Block(6,31,-9,STONE)
Block(19,1,-13,STONE)
Block(7,19,-9,STONE)
Block(6,32,-9,STONE)
Block(3,13,-2,STONE)
Block(3,14,-2,STONE)
Block(0,-4,7,STONE)
Block(3,15,-2,STONE)
Block(0,-5,7,STONE)
Block(3,16,-2,STONE)
Block(0,-3,7,STONE)
Block(6,30,-9,STONE)
Block(3,20,-2,STONE)
Block(3,21,-2,STONE)
Block(3,22,-2,STONE)
Block(6,28,-9,STONE)
Block(3,23,-2,STONE)
Block(6,29,-9,STONE)
Block(-1,-3,-8,STONE)
Block(6,22,-9,STONE)
Block(3,28,-2,STONE)
Block(-1,-2,-8,STONE)
Block(6,23,-9,STONE)
Block(3,29,-2,STONE)
Block(-1,-1,-8,STONE)
Block(6,20,-9,STONE)
Block(6,21,-9,STONE)
Block(15,-5,-15,STONE)
Block(3,24,-2,STONE)
Block(6,26,-9,STONE)
Block(15,-4,-15,STONE)
Block(3,25,-2,STONE)
Block(6,27,-9,STONE)
Block(15,-3,-15,STONE)
Block(6,24,-9,STONE)
Block(3,26,-2,STONE)
Block(15,-2,-15,STONE)
Block(6,25,-9,STONE)
Block(3,27,-2,STONE)
Block(15,-1,-15,STONE)
Block(5,-2,-2,STONE)
Block(5,-1,-2,STONE)
Block(5,-4,-2,STONE)
Block(5,-3,-2,STONE)
Block(7,30,-9,STONE)
Block(5,-5,-2,STONE)
Block(7,31,-9,STONE)
Block(7,32,-9,STONE)
Block(7,33,-9,STONE)
Block(7,34,-9,STONE)
Block(7,35,-9,STONE)
Block(7,36,-9,STONE)
Block(7,37,-9,STONE)
Block(7,38,-9,STONE)
Block(7,39,-9,STONE)
Block(16,12,-10,STONE)
Block(-4,-5,7,STONE)
Block(-4,-3,7,STONE)
Block(16,11,-10,STONE)
Block(-4,-4,7,STONE)
Block(16,10,-10,STONE)
Block(-4,-1,7,STONE)
Block(-4,-2,7,STONE)
Block(8,13,-9,STONE)
Block(8,14,-9,STONE)
Block(7,20,-9,STONE)
Block(8,11,-9,STONE)
Block(7,21,-9,STONE)
Block(8,12,-9,STONE)
Block(7,22,-9,STONE)
Block(-10,-4,4,STONE)
Block(7,23,-9,STONE)
Block(-10,-3,4,STONE)
Block(8,10,-9,STONE)
Block(7,24,-9,STONE)
Block(-10,-2,4,STONE)
Block(7,25,-9,STONE)
Block(-10,-1,4,STONE)
Block(7,26,-9,STONE)
Block(7,27,-9,STONE)
Block(7,28,-9,STONE)
Block(8,19,-9,STONE)
Block(7,29,-9,STONE)
Block(8,17,-9,STONE)
Block(8,18,-9,STONE)
Block(8,15,-9,STONE)
Block(8,16,-9,STONE)
Block(2,-4,6,STONE)
Block(2,-3,6,STONE)
Block(1,9,3,STONE)
Block(1,8,3,STONE)
Block(1,7,3,STONE)
Block(1,6,3,STONE)
Block(1,5,3,STONE)
Block(1,4,3,STONE)
Block(8,24,-9,STONE)
Block(8,25,-9,STONE)
Block(8,22,-9,STONE)
Block(8,23,-9,STONE)
Block(8,20,-9,STONE)
Block(8,21,-9,STONE)
Block(2,-5,6,STONE)
Block(3,-3,-2,STONE)
Block(3,-4,-2,STONE)
Block(3,-5,-2,STONE)
Block(-10,-5,4,STONE)
Block(8,28,-9,STONE)
Block(8,29,-9,STONE)
Block(3,-1,-2,STONE)
Block(8,26,-9,STONE)
Block(3,-2,-2,STONE)
Block(8,27,-9,STONE)
Block(7,40,-9,STONE)
Block(10,-3,-13,STONE)
Block(8,35,-9,STONE)
Block(7,41,-9,STONE)
Block(10,-4,-13,STONE)
Block(8,36,-9,STONE)
Block(7,42,-9,STONE)
Block(10,-5,-13,STONE)
Block(8,33,-9,STONE)
Block(7,43,-9,STONE)
Block(8,34,-9,STONE)
Block(7,44,-9,STONE)
Block(8,31,-9,STONE)
Block(8,32,-9,STONE)
Block(8,30,-9,STONE)
Block(9,3,4,STONE)
Block(9,4,4,STONE)
Block(9,5,4,STONE)
Block(10,-1,-13,STONE)
Block(8,37,-9,STONE)
Block(10,-2,-13,STONE)
Block(8,38,-9,STONE)
Block(11,-2,3,STONE)
Block(11,-3,3,STONE)
Block(4,-1,-2,STONE)
Block(4,-4,-2,STONE)
Block(4,-5,-2,STONE)
Block(9,0,4,STONE)
Block(11,-4,3,STONE)
Block(4,-2,-2,STONE)
Block(9,1,4,STONE)
Block(11,-5,3,STONE)
Block(4,-3,-2,STONE)
Block(9,2,4,STONE)
Block(8,12,0,STONE)
Block(8,11,0,STONE)
Block(7,1,-13,STONE)
Block(8,14,0,STONE)
Block(7,0,-13,STONE)
Block(8,13,0,STONE)
Block(8,16,0,STONE)
Block(8,15,0,STONE)
Block(8,17,0,STONE)
Block(-5,-5,9,STONE)
Block(4,7,-7,STONE)
Block(10,27,-5,STONE)
Block(4,6,-7,STONE)
Block(10,28,-5,STONE)
Block(-5,-4,9,STONE)
Block(4,9,-7,STONE)
Block(10,29,-5,STONE)
Block(4,8,-7,STONE)
Block(-2,12,-3,STONE)
Block(4,3,-7,STONE)
Block(10,23,-5,STONE)
Block(4,2,-7,STONE)
Block(10,24,-5,STONE)
Block(4,5,-7,STONE)
Block(10,25,-5,STONE)
Block(4,4,-7,STONE)
Block(10,26,-5,STONE)
Block(0,-5,-10,STONE)
Block(10,20,-5,STONE)
Block(4,1,-7,STONE)
Block(10,21,-5,STONE)
Block(4,0,-7,STONE)
Block(10,22,-5,STONE)
Block(0,-2,-10,STONE)
Block(0,-1,-10,STONE)
Block(0,-4,-10,STONE)
Block(8,10,0,STONE)
Block(0,-3,-10,STONE)
Block(18,-1,-16,STONE)
Block(5,33,1,STONE)
Block(5,32,1,STONE)
Block(5,31,1,STONE)
Block(18,-5,-16,STONE)
Block(18,-4,-16,STONE)
Block(-6,-5,-1,STONE)
Block(18,-3,-16,STONE)
Block(18,-2,-16,STONE)
Block(-6,-4,-1,STONE)
Block(-2,11,-3,STONE)
Block(-2,10,-3,STONE)
Block(10,16,-5,STONE)
Block(10,17,-5,STONE)
Block(10,18,-5,STONE)
Block(10,19,-5,STONE)
Block(10,12,-5,STONE)
Block(10,13,-5,STONE)
Block(10,14,-5,STONE)
Block(10,15,-5,STONE)
Block(10,10,-5,STONE)
Block(10,11,-5,STONE)
Block(5,30,1,STONE)
Block(7,3,-13,STONE)
Block(7,2,-13,STONE)
Block(5,23,1,STONE)
Block(5,22,1,STONE)
Block(1,19,-1,STONE)
Block(5,21,1,STONE)
Block(1,18,-1,STONE)
Block(5,20,1,STONE)
Block(1,17,-1,STONE)
Block(5,27,1,STONE)
Block(1,16,-1,STONE)
Block(5,26,1,STONE)
Block(1,15,-1,STONE)
Block(5,25,1,STONE)
Block(1,14,-1,STONE)
Block(5,24,1,STONE)
Block(5,29,1,STONE)
Block(5,28,1,STONE)
Block(8,0,-4,STONE)
Block(-3,8,3,STONE)
Block(0,11,-6,STONE)
Block(-3,7,3,STONE)
Block(0,10,-6,STONE)
Block(-3,9,3,STONE)
Block(-3,4,3,STONE)
Block(1,13,-1,STONE)
Block(0,15,-6,STONE)
Block(-3,3,3,STONE)
Block(1,12,-1,STONE)
Block(0,14,-6,STONE)
Block(-3,6,3,STONE)
Block(1,11,-1,STONE)
Block(0,13,-6,STONE)
Block(-3,5,3,STONE)
Block(1,10,-1,STONE)
Block(0,12,-6,STONE)
Block(-3,0,3,STONE)
Block(0,19,-6,STONE)
Block(0,18,-6,STONE)
Block(-3,2,3,STONE)
Block(0,17,-6,STONE)
Block(-3,1,3,STONE)
Block(0,16,-6,STONE)
Block(5,12,1,STONE)
Block(5,11,1,STONE)
Block(5,10,1,STONE)
Block(5,16,1,STONE)
Block(5,15,1,STONE)
Block(5,14,1,STONE)
Block(5,13,1,STONE)
Block(5,19,1,STONE)
Block(5,18,1,STONE)
Block(5,17,1,STONE)
Block(10,-4,0,STONE)
Block(10,-5,0,STONE)
Block(9,-5,-4,STONE)
Block(8,1,-4,STONE)
Block(10,-1,0,STONE)
Block(8,2,-4,STONE)
Block(9,-3,-4,STONE)
Block(10,-2,0,STONE)
Block(8,3,-4,STONE)
Block(9,-4,-4,STONE)
Block(10,-3,0,STONE)
Block(8,4,-4,STONE)
Block(8,5,-4,STONE)
Block(0,22,-6,STONE)
Block(8,6,-4,STONE)
Block(0,21,-6,STONE)
Block(8,7,-4,STONE)
Block(0,20,-6,STONE)
Block(8,8,-4,STONE)
Block(8,9,-4,STONE)
Block(0,23,-6,STONE)
Block(9,-1,-4,STONE)
Block(9,-2,-4,STONE)
Block(17,-4,-17,STONE)
Block(17,-5,-17,STONE)
Block(10,9,-4,STONE)
Block(10,8,-4,STONE)
Block(10,3,-4,STONE)
Block(10,2,-4,STONE)
Block(10,1,-4,STONE)
Block(10,0,-4,STONE)
Block(10,7,-4,STONE)
Block(10,6,-4,STONE)
Block(10,5,-4,STONE)
Block(10,4,-4,STONE)
Block(10,-2,-5,STONE)
Block(10,-3,-5,STONE)
Block(10,-4,-5,STONE)
Block(10,-5,-5,STONE)
Block(10,-1,-5,STONE)
Block(-9,2,4,STONE)
Block(-9,3,4,STONE)
Block(-9,0,4,STONE)
Block(-9,1,4,STONE)
Block(-9,6,4,STONE)
Block(-9,7,4,STONE)
Block(-9,4,4,STONE)
Block(-9,5,4,STONE)
Block(1,-5,-1,STONE)
Block(-9,8,4,STONE)
Block(1,-4,-1,STONE)
Block(1,-3,-1,STONE)
Block(1,-2,-1,STONE)
Block(1,-1,-1,STONE)
Block(0,-1,-6,STONE)
Block(0,-5,-6,STONE)
Block(0,-4,-6,STONE)
Block(0,-3,-6,STONE)
Block(0,-2,-6,STONE)
Block(-11,-1,10,STONE)
Block(-11,-2,10,STONE)
Block(-11,-3,10,STONE)
Block(5,-2,1,STONE)
Block(-11,-4,10,STONE)
Block(5,-1,1,STONE)
Block(-11,-5,10,STONE)
Block(5,-5,1,STONE)
Block(5,-4,1,STONE)
Block(5,-3,1,STONE)
Block(-7,-5,2,STONE)
Block(-7,-3,2,STONE)
Block(-7,-4,2,STONE)
Block(-7,-1,2,STONE)
Block(-7,-2,2,STONE)
Block(-12,-5,8,STONE)
Block(-12,-3,8,STONE)
Block(-12,-4,8,STONE)
Block(-12,-1,8,STONE)
Block(-12,-2,8,STONE)
Block(-6,5,1,STONE)
Block(-6,4,1,STONE)
Block(-6,3,1,STONE)
Block(-6,2,1,STONE)
Block(-6,1,1,STONE)
Block(-6,0,1,STONE)
Block(-4,1,-3,STONE)
Block(-6,8,1,STONE)
Block(-6,7,1,STONE)
Block(-6,6,1,STONE)
Block(9,-5,2,STONE)
Block(9,-4,2,STONE)
Block(9,-3,2,STONE)
Block(9,-2,2,STONE)
Block(9,-1,2,STONE)
Block(-10,-3,11,STONE)
Block(-10,-4,11,STONE)
Block(-10,-1,11,STONE)
Block(-4,0,-3,STONE)
Block(-10,-2,11,STONE)
Block(-10,-5,11,STONE)
Block(14,5,-9,STONE)
Block(14,6,-9,STONE)
Block(14,3,-9,STONE)
Block(14,4,-9,STONE)
Block(14,1,-9,STONE)
Block(14,2,-9,STONE)
Block(14,0,-9,STONE)
Block(10,7,-11,STONE)
Block(10,6,-11,STONE)
Block(10,5,-11,STONE)
Block(10,4,-11,STONE)
Block(10,9,-11,STONE)
Block(10,8,-11,STONE)
Block(12,9,-12,STONE)
Block(10,3,-11,STONE)
Block(14,9,-9,STONE)
Block(10,2,-11,STONE)
Block(10,1,-11,STONE)
Block(14,7,-9,STONE)
Block(10,0,-11,STONE)
Block(14,8,-9,STONE)
Block(12,0,-12,STONE)
Block(4,2,3,STONE)
Block(4,1,3,STONE)
Block(4,4,3,STONE)
Block(4,3,3,STONE)
Block(4,6,3,STONE)
Block(4,5,3,STONE)
Block(4,8,3,STONE)
Block(4,7,3,STONE)
Block(12,8,-12,STONE)
Block(12,7,-12,STONE)
Block(4,9,3,STONE)
Block(12,6,-12,STONE)
Block(12,5,-12,STONE)
Block(12,4,-12,STONE)
Block(12,3,-12,STONE)
Block(12,2,-12,STONE)
Block(12,1,-12,STONE)
Block(0,4,-2,STONE)
Block(0,3,-2,STONE)
Block(0,6,-2,STONE)
Block(0,5,-2,STONE)
Block(0,8,-2,STONE)
Block(9,40,-4,STONE)
Block(0,7,-2,STONE)
Block(9,41,-4,STONE)
Block(0,9,-2,STONE)
Block(0,0,-2,STONE)
Block(4,0,3,STONE)
Block(0,2,-2,STONE)
Block(0,1,-2,STONE)
Block(-2,-1,-3,STONE)
Block(7,9,1,STONE)
Block(7,8,1,STONE)
Block(-2,-5,-3,STONE)
Block(-2,-4,-3,STONE)
Block(-2,-3,-3,STONE)
Block(-2,-2,-3,STONE)
Block(7,3,1,STONE)
Block(9,44,-4,STONE)
Block(7,2,1,STONE)
Block(9,45,-4,STONE)
Block(7,1,1,STONE)
Block(9,42,-4,STONE)
Block(7,0,1,STONE)
Block(9,43,-4,STONE)
Block(7,7,1,STONE)
Block(7,6,1,STONE)
Block(7,5,1,STONE)
Block(7,4,1,STONE)
Block(4,-1,-8,STONE)
Block(4,-3,-8,STONE)
Block(4,-2,-8,STONE)
Block(9,30,-4,STONE)
Block(5,3,-1,STONE)
Block(5,4,-1,STONE)
Block(5,1,-1,STONE)
Block(9,39,-4,STONE)
Block(5,2,-1,STONE)
Block(5,7,-1,STONE)
Block(5,8,-1,STONE)
Block(5,5,-1,STONE)
Block(5,6,-1,STONE)
Block(9,33,-4,STONE)
Block(9,34,-4,STONE)
Block(5,9,-1,STONE)
Block(9,31,-4,STONE)
Block(9,32,-4,STONE)
Block(4,-5,-8,STONE)
Block(9,37,-4,STONE)
Block(4,-4,-8,STONE)
Block(9,38,-4,STONE)
Block(9,35,-4,STONE)
Block(9,36,-4,STONE)
Block(-5,9,7,STONE)
Block(5,0,-1,STONE)
Block(9,28,-4,STONE)
Block(9,29,-4,STONE)
Block(9,22,-4,STONE)
Block(10,41,-5,STONE)
Block(9,23,-4,STONE)
Block(10,42,-5,STONE)
Block(9,20,-4,STONE)
Block(10,43,-5,STONE)
Block(9,21,-4,STONE)
Block(10,44,-5,STONE)
Block(9,26,-4,STONE)
Block(9,27,-4,STONE)
Block(9,24,-4,STONE)
Block(9,25,-4,STONE)
Block(10,40,-5,STONE)
Block(-6,-1,0,STONE)
Block(2,9,-6,STONE)
Block(-6,-2,0,STONE)
Block(-6,-3,0,STONE)
Block(-6,-4,0,STONE)
Block(-6,-5,0,STONE)
Block(9,19,-4,STONE)
Block(10,38,-5,STONE)
Block(10,39,-5,STONE)
Block(9,17,-4,STONE)
Block(9,18,-4,STONE)
Block(2,0,-6,STONE)
Block(10,34,-5,STONE)
Block(10,35,-5,STONE)
Block(10,36,-5,STONE)
Block(10,37,-5,STONE)
Block(2,4,-6,STONE)
Block(9,11,-4,STONE)
Block(10,30,-5,STONE)
Block(2,3,-6,STONE)
Block(9,12,-4,STONE)
Block(10,31,-5,STONE)
Block(2,2,-6,STONE)
Block(10,32,-5,STONE)
Block(2,1,-6,STONE)
Block(9,10,-4,STONE)
Block(10,33,-5,STONE)
Block(2,8,-6,STONE)
Block(9,15,-4,STONE)
Block(2,7,-6,STONE)
Block(9,16,-4,STONE)
Block(2,6,-6,STONE)
Block(9,13,-4,STONE)
Block(2,5,-6,STONE)
Block(9,14,-4,STONE)
Block(4,26,-8,STONE)
Block(1,9,4,STONE)
Block(4,25,-8,STONE)
Block(1,8,4,STONE)
Block(4,28,-8,STONE)
Block(1,7,4,STONE)
Block(4,27,-8,STONE)
Block(1,6,4,STONE)
Block(4,22,-8,STONE)
Block(1,5,4,STONE)
Block(4,21,-8,STONE)
Block(1,4,4,STONE)
Block(4,24,-8,STONE)
Block(1,3,4,STONE)
Block(4,23,-8,STONE)
Block(4,20,-8,STONE)
Block(4,29,-8,STONE)
Block(4,15,-8,STONE)
Block(4,14,-8,STONE)
Block(4,17,-8,STONE)
Block(4,16,-8,STONE)
Block(4,11,-8,STONE)
Block(4,10,-8,STONE)
Block(4,13,-8,STONE)
Block(4,12,-8,STONE)
Block(-5,2,7,STONE)
Block(-5,1,7,STONE)
Block(-5,4,7,STONE)
Block(-5,3,7,STONE)
Block(-5,6,7,STONE)
Block(-5,5,7,STONE)
Block(-5,8,7,STONE)
Block(-5,7,7,STONE)
Block(10,6,1,STONE)
Block(10,7,1,STONE)
Block(10,4,1,STONE)
Block(10,5,1,STONE)
Block(10,2,1,STONE)
Block(4,19,-8,STONE)
Block(10,3,1,STONE)
Block(4,18,-8,STONE)
Block(10,0,1,STONE)
Block(-5,0,7,STONE)
Block(10,1,1,STONE)
Block(16,-1,-15,STONE)
Block(16,-2,-15,STONE)
Block(16,-3,-15,STONE)
Block(16,-4,-15,STONE)
Block(16,-5,-15,STONE)
Block(6,-3,-8,STONE)
Block(6,-2,-8,STONE)
Block(6,-5,-8,STONE)
Block(6,-4,-8,STONE)
Block(6,-1,-8,STONE)
Block(1,2,4,STONE)
Block(1,1,4,STONE)
Block(1,0,4,STONE)
Block(16,-2,-8,STONE)
Block(16,-1,-8,STONE)
Block(-1,15,0,STONE)
Block(-2,-1,7,STONE)
Block(-2,-2,7,STONE)
Block(-1,16,0,STONE)
Block(-2,-3,7,STONE)
Block(-1,17,0,STONE)
Block(-2,-4,7,STONE)
Block(-1,18,0,STONE)
Block(-2,-5,7,STONE)
Block(0,-4,6,STONE)
Block(-1,19,0,STONE)
Block(0,-3,6,STONE)
Block(0,-5,6,STONE)
Block(0,-2,6,STONE)
Block(-1,10,0,STONE)
Block(0,-1,6,STONE)
Block(9,-5,-15,STONE)
Block(-3,-5,-5,STONE)
Block(-1,11,0,STONE)
Block(-1,12,0,STONE)
Block(-1,13,0,STONE)
Block(-1,14,0,STONE)
Block(-3,-4,-5,STONE)
Block(9,-4,-15,STONE)
Block(12,6,-8,STONE)
Block(12,7,-8,STONE)
Block(12,8,-8,STONE)
Block(12,9,-8,STONE)
Block(6,28,-8,STONE)
Block(6,27,-8,STONE)
Block(6,29,-8,STONE)
Block(6,20,-8,STONE)
Block(-1,26,0,STONE)
Block(-11,-1,6,STONE)
Block(-1,27,0,STONE)
Block(-11,-2,6,STONE)
Block(6,22,-8,STONE)
Block(-1,28,0,STONE)
Block(-11,-3,6,STONE)
Block(6,21,-8,STONE)
Block(-1,29,0,STONE)
Block(-11,-4,6,STONE)
Block(6,24,-8,STONE)
Block(15,-5,-16,STONE)
Block(-11,-5,6,STONE)
Block(6,23,-8,STONE)
Block(6,26,-8,STONE)
Block(15,-4,-16,STONE)
Block(6,25,-8,STONE)
Block(-1,20,0,STONE)
Block(-1,21,0,STONE)
Block(-1,22,0,STONE)
Block(-1,23,0,STONE)
Block(-1,24,0,STONE)
Block(-1,25,0,STONE)
Block(-1,4,-4,STONE)
Block(-1,3,-4,STONE)
Block(-1,2,-4,STONE)
Block(-1,1,-4,STONE)
Block(-1,0,-4,STONE)
Block(6,17,-8,STONE)
Block(6,16,-8,STONE)
Block(6,19,-8,STONE)
Block(-1,9,-4,STONE)
Block(6,18,-8,STONE)
Block(-1,8,-4,STONE)
Block(-1,7,-4,STONE)
Block(-1,6,-4,STONE)
Block(-1,5,-4,STONE)
Block(15,0,-4,STONE)
Block(6,11,-8,STONE)
Block(6,10,-8,STONE)
Block(-8,8,5,STONE)
Block(6,13,-8,STONE)
Block(-8,9,5,STONE)
Block(6,12,-8,STONE)
Block(6,15,-8,STONE)
Block(6,14,-8,STONE)
Block(12,2,-8,STONE)
Block(12,3,-8,STONE)
Block(-1,30,0,STONE)
Block(12,4,-8,STONE)
Block(-1,31,0,STONE)
Block(12,5,-8,STONE)
Block(-1,32,0,STONE)
Block(-1,33,0,STONE)
Block(12,0,-8,STONE)
Block(12,1,-8,STONE)
Block(-8,4,5,STONE)
Block(-8,5,5,STONE)
Block(3,20,-1,STONE)
Block(-8,6,5,STONE)
Block(3,21,-1,STONE)
Block(-8,7,5,STONE)
Block(3,22,-1,STONE)
Block(-8,-4,4,STONE)
Block(-8,0,5,STONE)
Block(-8,-5,4,STONE)
Block(-8,1,5,STONE)
Block(-8,2,5,STONE)
Block(-8,3,5,STONE)
Block(3,27,-1,STONE)
Block(6,42,-8,STONE)
Block(3,28,-1,STONE)
Block(6,41,-8,STONE)
Block(3,29,-1,STONE)
Block(6,44,-8,STONE)
Block(6,43,-8,STONE)
Block(3,23,-1,STONE)
Block(3,24,-1,STONE)
Block(6,45,-8,STONE)
Block(3,25,-1,STONE)
Block(3,26,-1,STONE)
Block(6,40,-8,STONE)
Block(3,30,-1,STONE)
Block(6,39,-8,STONE)
Block(16,12,-8,STONE)
Block(16,11,-8,STONE)
Block(3,31,-1,STONE)
Block(6,38,-8,STONE)
Block(16,10,-8,STONE)
Block(3,32,-1,STONE)
Block(3,33,-1,STONE)
Block(6,31,-8,STONE)
Block(3,38,-1,STONE)
Block(6,30,-8,STONE)
Block(3,39,-1,STONE)
Block(6,33,-8,STONE)
Block(6,32,-8,STONE)
Block(3,34,-1,STONE)
Block(6,35,-8,STONE)
Block(6,34,-8,STONE)
Block(3,35,-1,STONE)
Block(3,36,-1,STONE)
Block(6,37,-8,STONE)
Block(6,36,-8,STONE)
Block(3,37,-1,STONE)
Block(13,-4,-1,STONE)
Block(13,-3,-1,STONE)
Block(13,-5,-1,STONE)
Block(13,-2,-1,STONE)
Block(-11,0,4,STONE)
Block(6,11,3,STONE)
Block(-11,2,4,STONE)
Block(-11,1,4,STONE)
Block(6,10,3,STONE)
Block(3,41,-1,STONE)
Block(3,42,-1,STONE)
Block(3,43,-1,STONE)
Block(3,44,-1,STONE)
Block(-10,-2,3,STONE)
Block(-10,-3,3,STONE)
Block(-10,-1,3,STONE)
Block(3,40,-1,STONE)
Block(16,-5,-8,STONE)
Block(16,-4,-8,STONE)
Block(16,-3,-8,STONE)
Block(3,45,-1,STONE)
Block(3,46,-1,STONE)
Block(6,13,3,STONE)
Block(6,12,3,STONE)
Block(11,-2,2,STONE)
Block(6,15,3,STONE)
Block(6,14,3,STONE)
Block(11,-5,2,STONE)
Block(11,-3,2,STONE)
Block(11,-4,2,STONE)
Block(-8,14,4,STONE)
Block(-10,-4,3,STONE)
Block(-10,-5,3,STONE)
Block(-8,10,4,STONE)
Block(-8,11,4,STONE)
Block(-8,12,4,STONE)
Block(-8,13,4,STONE)
Block(-4,11,6,STONE)
Block(-4,10,6,STONE)
Block(8,-2,0,STONE)
Block(-4,13,6,STONE)
Block(1,39,-1,STONE)
Block(8,-1,0,STONE)
Block(-4,12,6,STONE)
Block(1,38,-1,STONE)
Block(8,-4,0,STONE)
Block(1,37,-1,STONE)
Block(-4,15,6,STONE)
Block(8,-3,0,STONE)
Block(-4,14,6,STONE)
Block(1,36,-1,STONE)
Block(8,-5,0,STONE)
Block(-3,9,2,STONE)
Block(-3,8,2,STONE)
Block(-3,5,2,STONE)
Block(1,35,-1,STONE)
Block(-3,4,2,STONE)
Block(1,34,-1,STONE)
Block(-3,7,2,STONE)
Block(1,33,-1,STONE)
Block(-3,6,2,STONE)
Block(1,32,-1,STONE)
Block(-3,1,2,STONE)
Block(1,31,-1,STONE)
Block(-3,0,2,STONE)
Block(1,30,-1,STONE)
Block(-3,3,2,STONE)
Block(-3,2,2,STONE)
Block(18,-1,-8,STONE)
Block(18,-2,-8,STONE)
Block(18,-3,-8,STONE)
Block(18,-4,-8,STONE)
Block(1,29,-1,STONE)
Block(18,-5,-8,STONE)
Block(1,28,-1,STONE)
Block(1,27,-1,STONE)
Block(1,26,-1,STONE)
Block(1,25,-1,STONE)
Block(1,24,-1,STONE)
Block(1,23,-1,STONE)
Block(1,22,-1,STONE)
Block(1,21,-1,STONE)
Block(1,20,-1,STONE)
Block(6,-1,3,STONE)
Block(6,-3,3,STONE)
Block(6,-2,3,STONE)
Block(6,-5,3,STONE)
Block(6,-4,3,STONE)
Block(3,10,-1,STONE)
Block(3,11,-1,STONE)
Block(20,-5,-15,STONE)
Block(20,-4,-15,STONE)
Block(3,16,-1,STONE)
Block(-8,-1,4,STONE)
Block(3,17,-1,STONE)
Block(-8,-2,4,STONE)
Block(3,18,-1,STONE)
Block(-8,-3,4,STONE)
Block(3,19,-1,STONE)
Block(3,12,-1,STONE)
Block(3,13,-1,STONE)
Block(3,14,-1,STONE)
Block(3,15,-1,STONE)
Block(1,46,-1,STONE)
Block(1,45,-1,STONE)
Block(1,44,-1,STONE)
Block(1,43,-1,STONE)
Block(1,42,-1,STONE)
Block(1,41,-1,STONE)
Block(1,40,-1,STONE)
Block(5,29,-7,STONE)
Block(5,28,-7,STONE)
Block(5,27,-7,STONE)
Block(4,12,-3,STONE)
Block(4,11,-3,STONE)
Block(-4,-1,6,STONE)
Block(4,10,-3,STONE)
Block(7,50,-4,STONE)
Block(15,10,-6,STONE)
Block(4,16,-3,STONE)
Block(5,22,-7,STONE)
Block(4,15,-3,STONE)
Block(5,21,-7,STONE)
Block(4,14,-3,STONE)
Block(5,20,-7,STONE)
Block(4,13,-3,STONE)
Block(5,26,-7,STONE)
Block(4,19,-3,STONE)
Block(5,25,-7,STONE)
Block(4,18,-3,STONE)
Block(5,24,-7,STONE)
Block(4,17,-3,STONE)
Block(5,23,-7,STONE)
Block(5,39,-7,STONE)
Block(5,38,-7,STONE)
Block(8,0,-5,STONE)
Block(8,1,-5,STONE)
Block(8,2,-5,STONE)
Block(8,3,-5,STONE)
Block(8,4,-5,STONE)
Block(8,5,-5,STONE)
Block(8,6,-5,STONE)
Block(8,7,-5,STONE)
Block(8,8,-5,STONE)
Block(5,33,-7,STONE)
Block(8,9,-5,STONE)
Block(5,32,-7,STONE)
Block(5,31,-7,STONE)
Block(5,30,-7,STONE)
Block(5,37,-7,STONE)
Block(5,36,-7,STONE)
Block(5,35,-7,STONE)
Block(5,34,-7,STONE)
Block(7,-3,-14,STONE)
Block(7,-2,-14,STONE)
Block(7,-1,-14,STONE)
Block(12,-5,-5,STONE)
Block(12,-4,-5,STONE)
Block(7,-5,-14,STONE)
Block(7,-4,-14,STONE)
Block(2,-3,5,STONE)
Block(-3,-2,4,STONE)
Block(5,19,-7,STONE)
Block(-12,-5,11,STONE)
Block(2,-2,5,STONE)
Block(-3,-1,4,STONE)
Block(5,18,-7,STONE)
Block(2,-1,5,STONE)
Block(5,17,-7,STONE)
Block(-12,-4,11,STONE)
Block(5,16,-7,STONE)
Block(19,-1,-12,STONE)
Block(12,-1,-5,STONE)
Block(17,3,-15,STONE)
Block(-3,-5,4,STONE)
Block(19,-2,-12,STONE)
Block(-3,-4,4,STONE)
Block(12,-3,-5,STONE)
Block(17,1,-15,STONE)
Block(-3,-3,4,STONE)
Block(12,-2,-5,STONE)
Block(17,2,-15,STONE)
Block(19,-5,-12,STONE)
Block(19,-3,-12,STONE)
Block(19,-4,-12,STONE)
Block(15,-2,-6,STONE)
Block(15,-3,-6,STONE)
Block(2,-5,5,STONE)
Block(15,-4,-6,STONE)
Block(15,-5,-6,STONE)
Block(2,-4,5,STONE)
Block(3,-2,-1,STONE)
Block(3,-3,-1,STONE)
Block(3,-4,-1,STONE)
Block(3,-5,-1,STONE)
Block(3,-1,-1,STONE)
Block(-4,-3,6,STONE)
Block(1,-2,3,STONE)
Block(-9,1,5,STONE)
Block(5,11,-7,STONE)
Block(-4,-2,6,STONE)
Block(1,-1,3,STONE)
Block(17,0,-15,STONE)
Block(-9,2,5,STONE)
Block(5,10,-7,STONE)
Block(-4,-5,6,STONE)
Block(1,-4,3,STONE)
Block(-4,-4,6,STONE)
Block(1,-3,3,STONE)
Block(-9,0,5,STONE)
Block(-9,5,5,STONE)
Block(5,15,-7,STONE)
Block(1,-5,3,STONE)
Block(-9,6,5,STONE)
Block(5,14,-7,STONE)
Block(-9,3,5,STONE)
Block(5,13,-7,STONE)
Block(-9,4,5,STONE)
Block(5,12,-7,STONE)
Block(4,51,-3,STONE)
Block(-9,7,5,STONE)
Block(4,50,-3,STONE)
Block(-9,8,5,STONE)
Block(11,-5,-14,STONE)
Block(14,-5,-14,STONE)
Block(0,-1,1,STONE)
Block(14,-4,-14,STONE)
Block(0,-5,1,STONE)
Block(14,-1,-14,STONE)
Block(0,-4,1,STONE)
Block(14,-3,-14,STONE)
Block(0,-3,1,STONE)
Block(11,-4,-14,STONE)
Block(14,-2,-14,STONE)
Block(0,-2,1,STONE)
Block(-1,14,5,STONE)
Block(-1,12,5,STONE)
Block(-1,13,5,STONE)
Block(4,41,-3,STONE)
Block(4,40,-3,STONE)
Block(4,45,-3,STONE)
Block(4,44,-3,STONE)
Block(4,43,-3,STONE)
Block(4,42,-3,STONE)
Block(4,49,-3,STONE)
Block(4,48,-3,STONE)
Block(4,47,-3,STONE)
Block(4,46,-3,STONE)
Block(14,-3,-2,STONE)
Block(4,30,-3,STONE)
Block(14,-4,-2,STONE)
Block(14,-5,-2,STONE)
Block(4,34,-3,STONE)
Block(4,33,-3,STONE)
Block(4,32,-3,STONE)
Block(4,31,-3,STONE)
Block(14,-2,-2,STONE)
Block(1,21,3,STONE)
Block(1,20,3,STONE)
Block(1,23,3,STONE)
Block(5,40,-7,STONE)
Block(1,22,3,STONE)
Block(1,25,3,STONE)
Block(1,24,3,STONE)
Block(1,27,3,STONE)
Block(4,38,-3,STONE)
Block(5,44,-7,STONE)
Block(1,26,3,STONE)
Block(4,37,-3,STONE)
Block(5,43,-7,STONE)
Block(1,29,3,STONE)
Block(4,36,-3,STONE)
Block(5,42,-7,STONE)
Block(1,28,3,STONE)
Block(4,35,-3,STONE)
Block(5,41,-7,STONE)
Block(-3,12,4,STONE)
Block(5,48,-7,STONE)
Block(-3,11,4,STONE)
Block(5,47,-7,STONE)
Block(-3,10,4,STONE)
Block(5,46,-7,STONE)
Block(4,39,-3,STONE)
Block(5,45,-7,STONE)
Block(-3,16,4,STONE)
Block(-3,15,4,STONE)
Block(-6,5,0,STONE)
Block(-6,4,0,STONE)
Block(-3,14,4,STONE)
Block(-6,3,0,STONE)
Block(-3,13,4,STONE)
Block(-6,2,0,STONE)
Block(4,23,-3,STONE)
Block(-6,1,0,STONE)
Block(-3,19,4,STONE)
Block(4,22,-3,STONE)
Block(-6,0,0,STONE)
Block(-3,18,4,STONE)
Block(4,21,-3,STONE)
Block(-3,17,4,STONE)
Block(4,20,-3,STONE)
Block(8,-1,-3,STONE)
Block(1,10,3,STONE)
Block(8,-2,-3,STONE)
Block(1,12,3,STONE)
Block(1,11,3,STONE)
Block(1,14,3,STONE)
Block(1,13,3,STONE)
Block(1,16,3,STONE)
Block(4,27,-3,STONE)
Block(1,15,3,STONE)
Block(4,26,-3,STONE)
Block(1,18,3,STONE)
Block(4,25,-3,STONE)
Block(1,17,3,STONE)
Block(4,24,-3,STONE)
Block(8,-3,-3,STONE)
Block(8,-4,-3,STONE)
Block(1,19,3,STONE)
Block(8,-5,-3,STONE)
Block(4,29,-3,STONE)
Block(-3,21,4,STONE)
Block(-3,20,4,STONE)
Block(4,28,-3,STONE)
Block(2,3,-10,STONE)
Block(2,2,-10,STONE)
Block(7,-5,-4,STONE)
Block(2,4,-10,STONE)
Block(7,-3,-4,STONE)
Block(7,-4,-4,STONE)
Block(7,-1,-4,STONE)
Block(2,1,-10,STONE)
Block(7,-2,-4,STONE)
Block(2,0,-10,STONE)
Block(0,15,1,STONE)
Block(0,14,1,STONE)
Block(0,13,1,STONE)
Block(0,12,1,STONE)
Block(0,19,1,STONE)
Block(0,18,1,STONE)
Block(0,17,1,STONE)
Block(0,16,1,STONE)
Block(0,11,1,STONE)
Block(0,10,1,STONE)
Block(8,-4,-13,STONE)
Block(1,30,3,STONE)
Block(8,-5,-13,STONE)
Block(-1,10,-2,STONE)
Block(1,32,3,STONE)
Block(-1,11,-2,STONE)
Block(1,31,3,STONE)
Block(8,-1,-13,STONE)
Block(8,-2,-13,STONE)
Block(8,-3,-13,STONE)
Block(11,22,-6,STONE)
Block(11,21,-6,STONE)
Block(-2,-4,2,STONE)
Block(11,20,-6,STONE)
Block(-2,-5,2,STONE)
Block(-1,-2,-2,STONE)
Block(-2,-2,2,STONE)
Block(9,1,-13,STONE)
Block(11,26,-6,STONE)
Block(-1,-3,-2,STONE)
Block(-2,-3,2,STONE)
Block(9,0,-13,STONE)
Block(11,25,-6,STONE)
Block(-1,-4,-2,STONE)
Block(9,3,-13,STONE)
Block(11,24,-6,STONE)
Block(-1,-5,-2,STONE)
Block(-2,-1,2,STONE)
Block(9,2,-13,STONE)
Block(11,23,-6,STONE)
Block(9,5,-13,STONE)
Block(9,4,-13,STONE)
Block(11,29,-6,STONE)
Block(11,28,-6,STONE)
Block(-1,-1,-2,STONE)
Block(11,27,-6,STONE)
Block(9,6,-13,STONE)
Block(7,9,2,STONE)
Block(7,8,2,STONE)
Block(7,7,2,STONE)
Block(7,2,2,STONE)
Block(7,1,2,STONE)
Block(7,0,2,STONE)
Block(10,9,-3,STONE)
Block(7,6,2,STONE)
Block(7,5,2,STONE)
Block(7,4,2,STONE)
Block(7,3,2,STONE)
Block(-1,2,-6,STONE)
Block(10,4,-3,STONE)
Block(-1,1,-6,STONE)
Block(10,3,-3,STONE)
Block(-1,0,-6,STONE)
Block(10,2,-3,STONE)
Block(10,1,-3,STONE)
Block(10,8,-3,STONE)
Block(11,33,-6,STONE)
Block(10,7,-3,STONE)
Block(11,32,-6,STONE)
Block(-4,2,-2,STONE)
Block(10,6,-3,STONE)
Block(11,31,-6,STONE)
Block(10,5,-3,STONE)
Block(11,30,-6,STONE)
Block(11,36,-6,STONE)
Block(-1,9,-6,STONE)
Block(12,-5,-13,STONE)
Block(-1,8,-6,STONE)
Block(11,35,-6,STONE)
Block(-1,7,-6,STONE)
Block(11,34,-6,STONE)
Block(10,0,-3,STONE)
Block(-1,6,-6,STONE)
Block(-1,5,-6,STONE)
Block(-1,4,-6,STONE)
Block(-1,3,-6,STONE)
Block(8,13,-3,STONE)
Block(8,14,-3,STONE)
Block(8,15,-3,STONE)
Block(8,16,-3,STONE)
Block(12,-3,-13,STONE)
Block(12,-4,-13,STONE)
Block(8,10,-3,STONE)
Block(12,-1,-13,STONE)
Block(8,11,-3,STONE)
Block(12,-2,-13,STONE)
Block(8,12,-3,STONE)
Block(-4,1,-2,STONE)
Block(-4,0,-2,STONE)
Block(8,17,-3,STONE)
Block(8,18,-3,STONE)
Block(8,19,-3,STONE)
Block(7,19,-4,STONE)
Block(7,17,-4,STONE)
Block(7,18,-4,STONE)
Block(7,15,-4,STONE)
Block(7,16,-4,STONE)
Block(7,13,-4,STONE)
Block(7,14,-4,STONE)
Block(7,11,-4,STONE)
Block(7,12,-4,STONE)
Block(1,14,-7,STONE)
Block(8,24,-3,STONE)
Block(7,10,-4,STONE)
Block(1,15,-7,STONE)
Block(8,25,-3,STONE)
Block(1,12,-7,STONE)
Block(8,26,-3,STONE)
Block(15,-1,-6,STONE)
Block(1,13,-7,STONE)
Block(8,27,-3,STONE)
Block(1,18,-7,STONE)
Block(8,20,-3,STONE)
Block(1,19,-7,STONE)
Block(8,21,-3,STONE)
Block(1,16,-7,STONE)
Block(8,22,-3,STONE)
Block(1,17,-7,STONE)
Block(8,23,-3,STONE)
Block(1,10,-7,STONE)
Block(8,28,-3,STONE)
Block(1,11,-7,STONE)
Block(8,29,-3,STONE)
Block(10,6,-12,STONE)
Block(10,5,-12,STONE)
Block(10,4,-12,STONE)
Block(10,3,-12,STONE)
Block(11,11,-6,STONE)
Block(10,9,-12,STONE)
Block(11,10,-6,STONE)
Block(10,8,-12,STONE)
Block(10,7,-12,STONE)
Block(11,15,-6,STONE)
Block(7,28,-4,STONE)
Block(11,14,-6,STONE)
Block(7,29,-4,STONE)
Block(11,13,-6,STONE)
Block(7,26,-4,STONE)
Block(11,12,-6,STONE)
Block(7,27,-4,STONE)
Block(8,30,-3,STONE)
Block(10,2,-12,STONE)
Block(11,19,-6,STONE)
Block(7,24,-4,STONE)
Block(10,1,-12,STONE)
Block(11,18,-6,STONE)
Block(7,25,-4,STONE)
Block(10,0,-12,STONE)
Block(11,17,-6,STONE)
Block(7,22,-4,STONE)
Block(11,16,-6,STONE)
Block(7,23,-4,STONE)
Block(4,1,4,STONE)
Block(7,20,-4,STONE)
Block(8,35,-3,STONE)
Block(4,0,4,STONE)
Block(7,21,-4,STONE)
Block(8,36,-3,STONE)
Block(4,3,4,STONE)
Block(8,37,-3,STONE)
Block(4,2,4,STONE)
Block(8,38,-3,STONE)
Block(2,1,-5,STONE)
Block(4,5,4,STONE)
Block(8,31,-3,STONE)
Block(2,0,-5,STONE)
Block(4,4,4,STONE)
Block(8,32,-3,STONE)
Block(8,33,-3,STONE)
Block(4,7,4,STONE)
Block(4,6,4,STONE)
Block(8,34,-3,STONE)
Block(2,5,-5,STONE)
Block(2,4,-5,STONE)
Block(2,3,-5,STONE)
Block(2,2,-5,STONE)
Block(2,9,-5,STONE)
Block(8,39,-3,STONE)
Block(2,8,-5,STONE)
Block(2,7,-5,STONE)
Block(2,6,-5,STONE)
Block(12,22,-5,STONE)
Block(12,21,-5,STONE)
Block(7,0,-14,STONE)
Block(12,24,-5,STONE)
Block(12,23,-5,STONE)
Block(12,25,-5,STONE)
Block(-2,18,2,STONE)
Block(-2,19,2,STONE)
Block(-1,16,-2,STONE)
Block(-2,16,2,STONE)
Block(7,39,-4,STONE)
Block(-1,17,-2,STONE)
Block(-2,17,2,STONE)
Block(-2,14,2,STONE)
Block(-1,18,-2,STONE)
Block(7,37,-4,STONE)
Block(8,40,-3,STONE)
Block(-2,15,2,STONE)
Block(-1,19,-2,STONE)
Block(7,38,-4,STONE)
Block(8,41,-3,STONE)
Block(-1,12,-2,STONE)
Block(-2,12,2,STONE)
Block(7,35,-4,STONE)
Block(4,9,-8,STONE)
Block(-1,13,-2,STONE)
Block(-2,13,2,STONE)
Block(7,36,-4,STONE)
Block(-2,10,2,STONE)
Block(-1,14,-2,STONE)
Block(12,20,-5,STONE)
Block(7,33,-4,STONE)
Block(-2,11,2,STONE)
Block(-1,15,-2,STONE)
Block(7,34,-4,STONE)
Block(4,6,-8,STONE)
Block(7,31,-4,STONE)
Block(4,5,-8,STONE)
Block(-1,20,-2,STONE)
Block(-2,20,2,STONE)
Block(7,32,-4,STONE)
Block(4,8,-8,STONE)
Block(-1,21,-2,STONE)
Block(4,7,-8,STONE)
Block(-1,22,-2,STONE)
Block(7,30,-4,STONE)
Block(0,34,1,STONE)
Block(4,2,-8,STONE)
Block(8,42,-3,STONE)
Block(4,1,-8,STONE)
Block(8,43,-3,STONE)
Block(4,4,-8,STONE)
Block(8,44,-3,STONE)
Block(4,3,-8,STONE)
Block(8,45,-3,STONE)
Block(12,19,-5,STONE)
Block(12,18,-5,STONE)
Block(4,0,-8,STONE)
Block(0,33,1,STONE)
Block(0,32,1,STONE)
Block(0,31,1,STONE)
Block(0,30,1,STONE)
Block(5,-5,-7,STONE)
Block(12,11,-5,STONE)
Block(5,-4,-7,STONE)
Block(12,10,-5,STONE)
Block(5,-3,-7,STONE)
Block(12,13,-5,STONE)
Block(5,-2,-7,STONE)
Block(12,12,-5,STONE)
Block(12,15,-5,STONE)
Block(12,14,-5,STONE)
Block(12,17,-5,STONE)
Block(12,16,-5,STONE)
Block(-1,27,-2,STONE)
Block(-1,28,-2,STONE)
Block(-2,25,2,STONE)
Block(-1,29,-2,STONE)
Block(7,48,-4,STONE)
Block(7,49,-4,STONE)
Block(-2,26,2,STONE)
Block(-1,23,-2,STONE)
Block(-2,23,2,STONE)
Block(7,46,-4,STONE)
Block(-1,24,-2,STONE)
Block(-2,24,2,STONE)
Block(7,47,-4,STONE)
Block(-2,21,2,STONE)
Block(-1,25,-2,STONE)
Block(7,44,-4,STONE)
Block(-2,22,2,STONE)
Block(-1,26,-2,STONE)
Block(7,45,-4,STONE)
Block(-5,3,6,STONE)
Block(0,26,1,STONE)
Block(7,42,-4,STONE)
Block(-1,30,-2,STONE)
Block(-5,2,6,STONE)
Block(0,25,1,STONE)
Block(7,43,-4,STONE)
Block(-5,5,6,STONE)
Block(0,24,1,STONE)
Block(7,40,-4,STONE)
Block(-5,4,6,STONE)
Block(0,23,1,STONE)
Block(7,41,-4,STONE)
Block(-5,7,6,STONE)
Block(-5,6,6,STONE)
Block(0,29,1,STONE)
Block(-5,9,6,STONE)
Block(0,28,1,STONE)
Block(-5,8,6,STONE)
Block(0,27,1,STONE)
Block(5,-1,-7,STONE)
Block(0,22,1,STONE)
Block(0,21,1,STONE)
Block(7,1,-14,STONE)
Block(-5,1,6,STONE)
Block(0,20,1,STONE)
Block(-5,0,6,STONE)
Block(1,20,-7,STONE)
Block(19,-5,-9,STONE)
Block(17,10,-9,STONE)
Block(19,-4,-9,STONE)
Block(-5,-5,3,STONE)
Block(11,-1,-6,STONE)
Block(-5,-4,3,STONE)
Block(11,-5,-6,STONE)
Block(-5,-1,3,STONE)
Block(11,-4,-6,STONE)
Block(11,-3,-6,STONE)
Block(-5,-3,3,STONE)
Block(11,-2,-6,STONE)
Block(-5,-2,3,STONE)
Block(3,18,2,STONE)
Block(3,19,2,STONE)
Block(3,16,2,STONE)
Block(3,17,2,STONE)
Block(3,10,2,STONE)
Block(3,11,2,STONE)
Block(3,14,2,STONE)
Block(3,15,2,STONE)
Block(3,12,2,STONE)
Block(3,13,2,STONE)
Block(0,5,-1,STONE)
Block(0,4,-1,STONE)
Block(0,7,-1,STONE)
Block(0,6,-1,STONE)
Block(0,9,-1,STONE)
Block(0,8,-1,STONE)
Block(1,2,5,STONE)
Block(7,-5,3,STONE)
Block(7,-3,3,STONE)
Block(7,-4,3,STONE)
Block(7,-1,3,STONE)
Block(0,1,-1,STONE)
Block(7,-2,3,STONE)
Block(0,0,-1,STONE)
Block(0,3,-1,STONE)
Block(0,2,-1,STONE)
Block(3,29,2,STONE)
Block(3,27,2,STONE)
Block(3,28,2,STONE)
Block(3,21,2,STONE)
Block(3,22,2,STONE)
Block(3,20,2,STONE)
Block(-9,-1,4,STONE)
Block(3,25,2,STONE)
Block(-9,-2,4,STONE)
Block(3,26,2,STONE)
Block(-9,-3,4,STONE)
Block(3,23,2,STONE)
Block(-9,-4,4,STONE)
Block(3,24,2,STONE)
Block(-9,-5,4,STONE)
Block(5,-5,-13,STONE)
Block(3,32,2,STONE)
Block(3,33,2,STONE)
Block(3,30,2,STONE)
Block(3,31,2,STONE)
Block(5,-1,-13,STONE)
Block(5,-2,-13,STONE)
Block(5,-3,-13,STONE)
Block(5,-4,-13,STONE)
Block(12,7,-7,STONE)
Block(12,8,-7,STONE)
Block(12,9,-7,STONE)
Block(-1,3,-5,STONE)
Block(-1,2,-5,STONE)
Block(-1,1,-5,STONE)
Block(-1,0,-5,STONE)
Block(-5,19,3,STONE)
Block(-5,18,3,STONE)
Block(-1,9,-5,STONE)
Block(-1,8,-5,STONE)
Block(-1,7,-5,STONE)
Block(-5,15,3,STONE)
Block(-1,6,-5,STONE)
Block(-5,14,3,STONE)
Block(-1,5,-5,STONE)
Block(-5,17,3,STONE)
Block(-1,4,-5,STONE)
Block(-5,16,3,STONE)
Block(3,-4,2,STONE)
Block(12,1,-11,STONE)
Block(3,-5,2,STONE)
Block(12,0,-11,STONE)
Block(3,-2,2,STONE)
Block(3,-3,2,STONE)
Block(-8,9,4,STONE)
Block(-5,20,3,STONE)
Block(1,1,5,STONE)
Block(12,3,-7,STONE)
Block(12,9,-11,STONE)
Block(1,0,5,STONE)
Block(12,4,-7,STONE)
Block(12,8,-11,STONE)
Block(12,5,-7,STONE)
Block(12,7,-11,STONE)
Block(12,6,-11,STONE)
Block(12,6,-7,STONE)
Block(12,5,-11,STONE)
Block(3,-1,2,STONE)
Block(12,0,-7,STONE)
Block(12,4,-11,STONE)
Block(12,1,-7,STONE)
Block(12,3,-11,STONE)
Block(12,2,-11,STONE)
Block(12,2,-7,STONE)
Block(-8,0,4,STONE)
Block(-8,5,4,STONE)
Block(-8,6,4,STONE)
Block(-8,7,4,STONE)
Block(-8,8,4,STONE)
Block(-8,1,4,STONE)
Block(-8,2,4,STONE)
Block(-8,3,4,STONE)
Block(7,13,3,STONE)
Block(-8,4,4,STONE)
Block(-5,11,3,STONE)
Block(7,11,3,STONE)
Block(-5,10,3,STONE)
Block(7,12,3,STONE)
Block(-5,13,3,STONE)
Block(7,10,3,STONE)
Block(-5,12,3,STONE)
Block(18,-1,-10,STONE)
Block(18,-2,-10,STONE)
Block(18,-3,-10,STONE)
Block(18,-4,-10,STONE)
Block(18,-5,-10,STONE)
Block(13,-4,-15,STONE)
Block(13,-5,-15,STONE)
Block(10,0,0,STONE)
Block(13,-1,-15,STONE)
Block(13,-2,-15,STONE)
Block(13,-3,-15,STONE)
Block(10,7,0,STONE)
Block(10,8,0,STONE)
Block(10,5,0,STONE)
Block(10,6,0,STONE)
Block(17,10,-11,STONE)
Block(10,3,0,STONE)
Block(10,4,0,STONE)
Block(10,1,0,STONE)
Block(10,2,0,STONE)
Block(-1,-1,5,STONE)
Block(-1,-4,5,STONE)
Block(-1,-5,5,STONE)
Block(-1,-2,5,STONE)
Block(-1,-3,5,STONE)
Block(-1,10,5,STONE)
Block(-1,11,5,STONE)
Block(17,-5,-11,STONE)
Block(17,-4,-11,STONE)
Block(17,-3,-11,STONE)
Block(17,-2,-11,STONE)
Block(17,-1,-11,STONE)
Block(-11,2,5,STONE)
Block(-11,1,5,STONE)
Block(-11,0,5,STONE)
Block(17,-5,-9,STONE)
Block(6,-5,-12,STONE)
Block(17,-3,-9,STONE)
Block(17,-4,-9,STONE)
Block(6,-2,-12,STONE)
Block(6,-1,-12,STONE)
Block(6,-4,-12,STONE)
Block(6,-3,-12,STONE)
Block(17,-1,-9,STONE)
Block(17,-2,-9,STONE)
Block(-3,0,1,STONE)
Block(-3,9,1,STONE)
Block(-3,6,1,STONE)
Block(-3,5,1,STONE)
Block(-3,8,1,STONE)
Block(-3,7,1,STONE)
Block(-3,2,1,STONE)
Block(-3,1,1,STONE)
Block(-3,4,1,STONE)
Block(-3,3,1,STONE)
Block(-3,-1,3,STONE)
Block(-3,-5,3,STONE)
Block(-3,-4,3,STONE)
Block(-3,-3,3,STONE)
Block(-3,-2,3,STONE)
Block(12,-3,-10,STONE)
Block(12,-2,-10,STONE)
Block(12,-5,-10,STONE)
Block(12,-4,-10,STONE)
Block(12,-1,-10,STONE)
Block(11,-4,4,STONE)
Block(11,-5,4,STONE)
Block(2,19,-5,STONE)
Block(2,18,-5,STONE)
Block(2,17,-5,STONE)
Block(2,16,-5,STONE)
Block(2,15,-5,STONE)
Block(2,14,-5,STONE)
Block(2,13,-5,STONE)
Block(2,12,-5,STONE)
Block(2,11,-5,STONE)
Block(2,10,-5,STONE)
Block(12,-3,-4,STONE)
Block(12,-4,-4,STONE)
Block(12,-5,-4,STONE)
Block(11,11,-9,STONE)
Block(12,10,-4,STONE)
Block(11,12,-9,STONE)
Block(12,11,-4,STONE)
Block(11,13,-9,STONE)
Block(12,12,-4,STONE)
Block(11,14,-9,STONE)
Block(12,13,-4,STONE)
Block(12,14,-4,STONE)
Block(12,15,-4,STONE)
Block(11,10,-9,STONE)
Block(12,16,-4,STONE)
Block(11,19,-9,STONE)
Block(11,15,-9,STONE)
Block(11,16,-9,STONE)
Block(11,17,-9,STONE)
Block(2,29,-5,STONE)
Block(11,18,-9,STONE)
Block(2,28,-5,STONE)
Block(2,27,-5,STONE)
Block(2,26,-5,STONE)
Block(2,25,-5,STONE)
Block(-5,14,7,STONE)
Block(2,24,-5,STONE)
Block(-5,12,7,STONE)
Block(2,23,-5,STONE)
Block(-5,13,7,STONE)
Block(2,22,-5,STONE)
Block(-5,10,7,STONE)
Block(2,21,-5,STONE)
Block(-5,11,7,STONE)
Block(2,20,-5,STONE)
Block(-4,16,5,STONE)
Block(-4,15,5,STONE)
Block(-4,18,5,STONE)
Block(-4,17,5,STONE)
Block(11,22,-9,STONE)
Block(11,23,-9,STONE)
Block(-4,10,5,STONE)
Block(11,24,-9,STONE)
Block(11,25,-9,STONE)
Block(-4,12,5,STONE)
Block(-4,11,5,STONE)
Block(-4,14,5,STONE)
Block(11,20,-9,STONE)
Block(-4,13,5,STONE)
Block(11,21,-9,STONE)
Block(11,26,-9,STONE)
Block(11,27,-9,STONE)
Block(11,28,-9,STONE)
Block(2,39,-5,STONE)
Block(2,38,-5,STONE)
Block(2,37,-5,STONE)
Block(2,36,-5,STONE)
Block(2,35,-5,STONE)
Block(2,34,-5,STONE)
Block(2,33,-5,STONE)
Block(2,32,-5,STONE)
Block(2,31,-5,STONE)
Block(2,30,-5,STONE)
Block(-3,11,3,STONE)
Block(-3,10,3,STONE)
Block(-3,15,3,STONE)
Block(-3,14,3,STONE)
Block(-3,13,3,STONE)
Block(-3,12,3,STONE)
Block(-3,19,3,STONE)
Block(-3,18,3,STONE)
Block(-3,17,3,STONE)
Block(-3,16,3,STONE)
Block(12,17,-10,STONE)
Block(12,16,-10,STONE)
Block(12,19,-10,STONE)
Block(12,18,-10,STONE)
Block(4,9,-5,STONE)
Block(4,8,-5,STONE)
Block(12,11,-10,STONE)
Block(12,10,-10,STONE)
Block(4,5,-5,STONE)
Block(12,13,-10,STONE)
Block(4,4,-5,STONE)
Block(12,12,-10,STONE)
Block(4,7,-5,STONE)
Block(12,15,-10,STONE)
Block(4,6,-5,STONE)
Block(12,14,-10,STONE)
Block(4,1,-5,STONE)
Block(4,0,-5,STONE)
Block(4,3,-5,STONE)
Block(4,2,-5,STONE)
Block(-3,22,3,STONE)
Block(-3,21,3,STONE)
Block(-3,20,3,STONE)
Block(-3,23,3,STONE)
Block(2,-5,-5,STONE)
Block(2,-4,-5,STONE)
Block(2,-3,-5,STONE)
Block(10,-3,2,STONE)
Block(2,-2,-5,STONE)
Block(10,-2,2,STONE)
Block(2,-1,-5,STONE)
Block(10,-5,2,STONE)
Block(10,-4,2,STONE)
Block(10,-1,2,STONE)
Block(-4,9,3,STONE)
Block(-4,8,3,STONE)
Block(-4,7,3,STONE)
Block(-4,6,3,STONE)
Block(12,-1,-4,STONE)
Block(12,-2,-4,STONE)
Block(11,-5,-9,STONE)
Block(-4,1,3,STONE)
Block(-4,0,3,STONE)
Block(11,-1,-9,STONE)
Block(-4,5,3,STONE)
Block(11,-2,-9,STONE)
Block(-4,4,3,STONE)
Block(11,-3,-9,STONE)
Block(-4,3,3,STONE)
Block(11,-4,-9,STONE)
Block(-4,2,3,STONE)
Block(-4,-2,5,STONE)
Block(-4,-1,5,STONE)
Block(-4,-4,5,STONE)
Block(-4,-3,5,STONE)
Block(-4,-5,5,STONE)
Block(-2,-4,1,STONE)
Block(-2,-3,1,STONE)
Block(-2,-5,1,STONE)
Block(-2,-2,1,STONE)
Block(-2,-1,1,STONE)
Block(12,20,-10,STONE)
Block(12,22,-10,STONE)
Block(12,21,-10,STONE)
Block(12,24,-10,STONE)
Block(12,23,-10,STONE)
Block(9,21,-6,STONE)
Block(9,20,-6,STONE)
Block(-2,25,1,STONE)
Block(-2,24,1,STONE)
Block(-2,27,1,STONE)
Block(-2,26,1,STONE)
Block(-2,21,1,STONE)
Block(-2,20,1,STONE)
Block(-2,23,1,STONE)
Block(-2,22,1,STONE)
Block(7,9,3,STONE)
Block(7,8,3,STONE)
Block(7,7,3,STONE)
Block(7,6,3,STONE)
Block(7,1,3,STONE)
Block(9,25,-6,STONE)
Block(7,0,3,STONE)
Block(9,24,-6,STONE)
Block(9,23,-6,STONE)
Block(9,22,-6,STONE)
Block(7,5,3,STONE)
Block(9,29,-6,STONE)
Block(7,4,3,STONE)
Block(9,28,-6,STONE)
Block(7,3,3,STONE)
Block(9,27,-6,STONE)
Block(7,2,3,STONE)
Block(9,26,-6,STONE)
Block(-1,1,-7,STONE)
Block(-1,0,-7,STONE)
Block(9,10,-6,STONE)
Block(-1,5,-7,STONE)
Block(-1,4,-7,STONE)
Block(-1,3,-7,STONE)
Block(-5,-4,-4,STONE)
Block(-5,-5,-4,STONE)
Block(-1,2,-7,STONE)
Block(9,19,-6,STONE)
Block(-6,-3,9,STONE)
Block(9,14,-6,STONE)
Block(-6,-4,9,STONE)
Block(9,13,-6,STONE)
Block(-6,-5,9,STONE)
Block(9,12,-6,STONE)
Block(9,11,-6,STONE)
Block(-9,-5,1,STONE)
Block(9,18,-6,STONE)
Block(9,17,-6,STONE)
Block(-9,-4,1,STONE)
Block(9,16,-6,STONE)
Block(-6,-1,9,STONE)
Block(2,-5,-13,STONE)
Block(-6,-2,9,STONE)
Block(9,15,-6,STONE)
Block(-10,0,11,STONE)
Block(14,12,-5,STONE)
Block(14,11,-5,STONE)
Block(14,10,-5,STONE)
Block(4,-1,-6,STONE)
Block(-2,18,1,STONE)
Block(-2,17,1,STONE)
Block(-2,19,1,STONE)
Block(-2,14,1,STONE)
Block(-2,13,1,STONE)
Block(-2,16,1,STONE)
Block(-2,15,1,STONE)
Block(-2,10,1,STONE)
Block(-2,12,1,STONE)
Block(-2,11,1,STONE)
Block(12,0,-2,STONE)
Block(12,1,-2,STONE)
Block(12,2,-2,STONE)
Block(12,3,-2,STONE)
Block(4,10,-11,STONE)
Block(4,-2,-6,STONE)
Block(12,4,-2,STONE)
Block(4,-3,-6,STONE)
Block(4,-4,-6,STONE)
Block(4,-5,-6,STONE)
Block(4,45,-6,STONE)
Block(4,46,-6,STONE)
Block(4,47,-6,STONE)
Block(4,48,-6,STONE)
Block(-2,0,-1,STONE)
Block(4,41,-6,STONE)
Block(4,42,-6,STONE)
Block(4,43,-6,STONE)
Block(4,44,-6,STONE)
Block(4,40,-6,STONE)
Block(-7,2,1,STONE)
Block(-7,1,1,STONE)
Block(-2,9,-1,STONE)
Block(-7,0,1,STONE)
Block(-2,4,-1,STONE)
Block(2,41,-5,STONE)
Block(-2,3,-1,STONE)
Block(2,40,-5,STONE)
Block(-2,2,-1,STONE)
Block(-2,1,-1,STONE)
Block(-2,8,-1,STONE)
Block(4,49,-6,STONE)
Block(-2,7,-1,STONE)
Block(-2,6,-1,STONE)
Block(-2,5,-1,STONE)
Block(4,34,-6,STONE)
Block(4,35,-6,STONE)
Block(4,36,-6,STONE)
Block(4,37,-6,STONE)
Block(4,30,-6,STONE)
Block(4,31,-6,STONE)
Block(4,32,-6,STONE)
Block(4,33,-6,STONE)
Block(-5,-4,7,STONE)
Block(-5,-5,7,STONE)
Block(7,-5,-15,STONE)
Block(9,-5,-6,STONE)
Block(12,17,-4,STONE)
Block(9,-4,-6,STONE)
Block(4,38,-6,STONE)
Block(9,-3,-6,STONE)
Block(4,39,-6,STONE)
Block(9,-2,-6,STONE)
Block(7,-3,-15,STONE)
Block(7,-4,-15,STONE)
Block(9,-1,-6,STONE)
Block(4,23,-6,STONE)
Block(4,24,-6,STONE)
Block(4,25,-6,STONE)
Block(4,26,-6,STONE)
Block(2,2,-11,STONE)
Block(2,1,-11,STONE)
Block(4,20,-6,STONE)
Block(4,21,-6,STONE)
Block(4,22,-6,STONE)
Block(2,0,-11,STONE)
Block(-5,-2,7,STONE)
Block(14,7,-7,STONE)
Block(-5,-3,7,STONE)
Block(14,8,-7,STONE)
Block(14,5,-7,STONE)
Block(-5,-1,7,STONE)
Block(14,6,-7,STONE)
Block(14,3,-7,STONE)
Block(14,4,-7,STONE)
Block(14,1,-7,STONE)
Block(6,3,-13,STONE)
Block(14,2,-7,STONE)
Block(14,0,-7,STONE)
Block(14,-1,-5,STONE)
Block(4,27,-6,STONE)
Block(4,28,-6,STONE)
Block(4,29,-6,STONE)
Block(4,12,-6,STONE)
Block(4,13,-6,STONE)
Block(4,14,-6,STONE)
Block(4,15,-6,STONE)
Block(14,-3,-5,STONE)
Block(14,-2,-5,STONE)
Block(14,-5,-5,STONE)
Block(4,10,-6,STONE)
Block(14,-4,-5,STONE)
Block(4,11,-6,STONE)
Block(6,1,-13,STONE)
Block(6,2,-13,STONE)
Block(6,0,-13,STONE)
Block(14,9,-7,STONE)
Block(4,-1,-11,STONE)
Block(4,-4,-11,STONE)
Block(4,16,-6,STONE)
Block(4,-5,-11,STONE)
Block(4,17,-6,STONE)
Block(4,-2,-11,STONE)
Block(4,18,-6,STONE)
Block(4,-3,-11,STONE)
Block(4,19,-6,STONE)
Block(0,27,-1,STONE)
Block(5,43,-1,STONE)
Block(0,26,-1,STONE)
Block(0,29,-1,STONE)
Block(0,28,-1,STONE)
Block(-10,-1,5,STONE)
Block(3,44,-3,STONE)
Block(3,43,-3,STONE)
Block(3,46,-3,STONE)
Block(3,45,-3,STONE)
Block(-10,-5,5,STONE)
Block(3,40,-3,STONE)
Block(-10,-4,5,STONE)
Block(-10,-3,5,STONE)
Block(3,42,-3,STONE)
Block(-10,-2,5,STONE)
Block(3,41,-3,STONE)
Block(3,-5,3,STONE)
Block(3,-4,3,STONE)
Block(3,-3,3,STONE)
Block(3,48,-3,STONE)
Block(3,47,-3,STONE)
Block(6,4,-12,STONE)
Block(3,49,-3,STONE)
Block(6,5,-12,STONE)
Block(0,21,-1,STONE)
Block(0,20,-1,STONE)
Block(3,-2,3,STONE)
Block(0,23,-1,STONE)
Block(3,-1,3,STONE)
Block(0,22,-1,STONE)
Block(5,40,-1,STONE)
Block(0,25,-1,STONE)
Block(5,41,-1,STONE)
Block(0,24,-1,STONE)
Block(5,42,-1,STONE)
Block(0,38,-1,STONE)
Block(0,37,-1,STONE)
Block(0,39,-1,STONE)
Block(6,2,-12,STONE)
Block(6,3,-12,STONE)
Block(6,0,-12,STONE)
Block(6,1,-12,STONE)
Block(3,50,-3,STONE)
Block(-8,-1,2,STONE)
Block(0,30,-1,STONE)
Block(0,32,-1,STONE)
Block(0,31,-1,STONE)
Block(0,34,-1,STONE)
Block(0,33,-1,STONE)
Block(0,36,-1,STONE)
Block(0,35,-1,STONE)
Block(5,21,-1,STONE)
Block(5,22,-1,STONE)
Block(5,23,-1,STONE)
Block(5,24,-1,STONE)
Block(14,0,-10,STONE)
Block(5,25,-1,STONE)
Block(5,26,-1,STONE)
Block(5,27,-1,STONE)
Block(5,28,-1,STONE)
Block(-8,-5,2,STONE)
Block(14,4,-10,STONE)
Block(5,29,-1,STONE)
Block(-8,-4,2,STONE)
Block(14,3,-10,STONE)
Block(-8,-3,2,STONE)
Block(14,2,-10,STONE)
Block(-8,-2,2,STONE)
Block(11,0,-8,STONE)
Block(14,1,-10,STONE)
Block(11,1,-8,STONE)
Block(14,8,-10,STONE)
Block(11,2,-8,STONE)
Block(14,7,-10,STONE)
Block(11,3,-8,STONE)
Block(14,6,-10,STONE)
Block(11,4,-8,STONE)
Block(14,5,-10,STONE)
Block(14,9,-10,STONE)
Block(-6,9,7,STONE)
Block(-6,8,7,STONE)
Block(5,20,-1,STONE)
Block(0,16,-1,STONE)
Block(5,32,-1,STONE)
Block(0,15,-1,STONE)
Block(5,33,-1,STONE)
Block(0,18,-1,STONE)
Block(5,34,-1,STONE)
Block(0,17,-1,STONE)
Block(5,35,-1,STONE)
Block(5,36,-1,STONE)
Block(0,19,-1,STONE)
Block(5,37,-1,STONE)
Block(5,38,-1,STONE)
Block(5,39,-1,STONE)
Block(4,50,-6,STONE)
Block(4,51,-6,STONE)
Block(9,-5,-13,STONE)
Block(0,10,-1,STONE)
Block(9,-2,-13,STONE)
Block(0,12,-1,STONE)
Block(9,-1,-13,STONE)
Block(0,11,-1,STONE)
Block(9,-4,-13,STONE)
Block(0,14,-1,STONE)
Block(5,30,-1,STONE)
Block(9,-3,-13,STONE)
Block(0,13,-1,STONE)
Block(5,31,-1,STONE)
Block(-6,7,7,STONE)
Block(3,11,-3,STONE)
Block(-6,6,7,STONE)
Block(3,10,-3,STONE)
Block(-6,5,7,STONE)
Block(3,13,-3,STONE)
Block(-6,4,7,STONE)
Block(3,12,-3,STONE)
Block(-6,3,7,STONE)
Block(-6,2,7,STONE)
Block(-6,1,7,STONE)
Block(-6,0,7,STONE)
Block(11,5,-8,STONE)
Block(3,19,-3,STONE)
Block(11,6,-8,STONE)
Block(3,18,-3,STONE)
Block(11,7,-8,STONE)
Block(11,8,-8,STONE)
Block(11,9,-8,STONE)
Block(3,15,-3,STONE)
Block(3,14,-3,STONE)
Block(3,17,-3,STONE)
Block(3,16,-3,STONE)
Block(9,43,-6,STONE)
Block(9,42,-6,STONE)
Block(9,41,-6,STONE)
Block(9,40,-6,STONE)
Block(3,22,-3,STONE)
Block(3,21,-3,STONE)
Block(3,24,-3,STONE)
Block(3,23,-3,STONE)
Block(3,20,-3,STONE)
Block(3,29,-3,STONE)
Block(8,-4,-8,STONE)
Block(8,-5,-8,STONE)
Block(8,-2,-8,STONE)
Block(3,26,-3,STONE)
Block(8,-3,-8,STONE)
Block(3,25,-3,STONE)
Block(3,28,-3,STONE)
Block(8,-1,-8,STONE)
Block(3,27,-3,STONE)
Block(9,45,-6,STONE)
Block(9,44,-6,STONE)
Block(0,-2,-1,STONE)
Block(0,-1,-1,STONE)
Block(0,-4,-1,STONE)
Block(0,-3,-1,STONE)
Block(9,32,-6,STONE)
Block(0,-5,-1,STONE)
Block(9,31,-6,STONE)
Block(9,30,-6,STONE)
Block(17,-1,-12,STONE)
Block(3,33,-3,STONE)
Block(17,-2,-12,STONE)
Block(3,32,-3,STONE)
Block(17,-3,-12,STONE)
Block(3,35,-3,STONE)
Block(17,-4,-12,STONE)
Block(3,34,-3,STONE)
Block(17,-5,-12,STONE)
Block(3,31,-3,STONE)
Block(3,30,-3,STONE)
Block(3,37,-3,STONE)
Block(3,36,-3,STONE)
Block(3,39,-3,STONE)
Block(18,0,-8,STONE)
Block(3,38,-3,STONE)
Block(9,36,-6,STONE)
Block(9,35,-6,STONE)
Block(9,34,-6,STONE)
Block(9,33,-6,STONE)
Block(9,39,-6,STONE)
Block(9,38,-6,STONE)
Block(9,37,-6,STONE)
Block(7,20,-8,STONE)
Block(7,21,-8,STONE)
Block(7,22,-8,STONE)
Block(7,23,-8,STONE)
Block(7,24,-8,STONE)
Block(7,25,-8,STONE)
Block(7,26,-8,STONE)
Block(7,27,-8,STONE)
Block(7,28,-8,STONE)
Block(7,29,-8,STONE)
Block(-1,1,4,STONE)
Block(-1,0,4,STONE)
Block(-1,3,4,STONE)
Block(-1,2,4,STONE)
Block(-1,5,4,STONE)
Block(5,-1,-1,STONE)
Block(-1,4,4,STONE)
Block(5,-2,-1,STONE)
Block(-1,7,4,STONE)
Block(5,-3,-1,STONE)
Block(-1,6,4,STONE)
Block(5,-4,-1,STONE)
Block(-1,9,4,STONE)
Block(5,-5,-1,STONE)
Block(-1,8,4,STONE)
Block(7,10,-8,STONE)
Block(7,11,-8,STONE)
Block(7,12,-8,STONE)
Block(7,13,-8,STONE)
Block(7,14,-8,STONE)
Block(3,-5,-3,STONE)
Block(7,15,-8,STONE)
Block(3,-4,-3,STONE)
Block(7,16,-8,STONE)
Block(7,17,-8,STONE)
Block(7,18,-8,STONE)
Block(3,-1,-3,STONE)
Block(7,19,-8,STONE)
Block(3,-3,-3,STONE)
Block(3,-2,-3,STONE)
Block(10,-5,-12,STONE)
Block(10,-4,-12,STONE)
Block(10,-3,-12,STONE)
Block(10,-2,-12,STONE)
Block(8,12,-8,STONE)
Block(7,40,-8,STONE)
Block(8,13,-8,STONE)
Block(7,41,-8,STONE)
Block(8,10,-8,STONE)
Block(7,42,-8,STONE)
Block(8,11,-8,STONE)
Block(7,43,-8,STONE)
Block(7,44,-8,STONE)
Block(8,18,-8,STONE)
Block(8,19,-8,STONE)
Block(8,16,-8,STONE)
Block(8,17,-8,STONE)
Block(8,14,-8,STONE)
Block(8,15,-8,STONE)
Block(10,-1,-12,STONE)
Block(8,23,-8,STONE)
Block(8,24,-8,STONE)
Block(7,30,-8,STONE)
Block(8,21,-8,STONE)
Block(7,31,-8,STONE)
Block(8,22,-8,STONE)
Block(7,32,-8,STONE)
Block(7,33,-8,STONE)
Block(8,20,-8,STONE)
Block(7,34,-8,STONE)
Block(7,35,-8,STONE)
Block(7,36,-8,STONE)
Block(7,37,-8,STONE)
Block(7,38,-8,STONE)
Block(8,29,-8,STONE)
Block(7,39,-8,STONE)
Block(8,27,-8,STONE)
Block(8,28,-8,STONE)
Block(8,25,-8,STONE)
Block(8,26,-8,STONE)
Block(8,34,-8,STONE)
Block(8,35,-8,STONE)
Block(8,32,-8,STONE)
Block(8,33,-8,STONE)
Block(8,30,-8,STONE)
Block(8,31,-8,STONE)
Block(1,8,-6,STONE)
Block(1,9,-6,STONE)
Block(1,6,-6,STONE)
Block(1,7,-6,STONE)
Block(15,-5,-14,STONE)
Block(1,4,-6,STONE)
Block(1,5,-6,STONE)
Block(15,-3,-14,STONE)
Block(1,2,-6,STONE)
Block(2,7,0,STONE)
Block(8,38,-8,STONE)
Block(15,-4,-14,STONE)
Block(1,3,-6,STONE)
Block(2,6,0,STONE)
Block(8,39,-8,STONE)
Block(15,-1,-14,STONE)
Block(1,0,-6,STONE)
Block(2,9,0,STONE)
Block(8,36,-8,STONE)
Block(15,-2,-14,STONE)
Block(1,1,-6,STONE)
Block(2,8,0,STONE)
Block(8,37,-8,STONE)
Block(5,10,-1,STONE)
Block(5,11,-1,STONE)
Block(5,12,-1,STONE)
Block(5,13,-1,STONE)
Block(5,14,-1,STONE)
Block(5,15,-1,STONE)
Block(5,16,-1,STONE)
Block(5,17,-1,STONE)
Block(5,18,-1,STONE)
Block(5,19,-1,STONE)
Block(8,43,-8,STONE)
Block(8,44,-8,STONE)
Block(8,41,-8,STONE)
Block(8,42,-8,STONE)
Block(2,-3,7,STONE)
Block(2,-4,7,STONE)
Block(2,-5,7,STONE)
Block(8,40,-8,STONE)
Block(-11,2,6,STONE)
Block(-11,1,6,STONE)
Block(-11,0,6,STONE)
Block(10,16,-12,STONE)
Block(10,15,-12,STONE)
Block(10,14,-12,STONE)
Block(10,13,-12,STONE)
Block(10,12,-12,STONE)
Block(10,11,-12,STONE)
Block(10,10,-12,STONE)
Block(2,3,0,STONE)
Block(2,2,0,STONE)
Block(2,5,0,STONE)
Block(2,4,0,STONE)
Block(2,1,0,STONE)
Block(2,0,0,STONE)
Block(8,0,-6,STONE)
Block(8,1,-6,STONE)
Block(8,2,-6,STONE)
Block(8,3,-6,STONE)
Block(8,4,-6,STONE)
Block(8,5,-6,STONE)
Block(8,6,-6,STONE)
Block(8,7,-6,STONE)
Block(8,8,-6,STONE)
Block(8,9,-6,STONE)
Block(5,14,2,STONE)
Block(9,9,-1,STONE)
Block(-4,9,2,STONE)
Block(5,15,2,STONE)
Block(-4,8,2,STONE)
Block(5,16,2,STONE)
Block(-4,7,2,STONE)
Block(5,17,2,STONE)
Block(9,6,-1,STONE)
Block(5,10,2,STONE)
Block(9,5,-1,STONE)
Block(5,11,2,STONE)
Block(9,8,-1,STONE)
Block(5,12,2,STONE)
Block(9,7,-1,STONE)
Block(5,13,2,STONE)
Block(-4,2,2,STONE)
Block(-4,1,2,STONE)
Block(-4,0,2,STONE)
Block(-4,6,2,STONE)
Block(5,18,2,STONE)
Block(-4,5,2,STONE)
Block(5,19,2,STONE)
Block(-4,4,2,STONE)
Block(-4,3,2,STONE)
Block(11,-3,-12,STONE)
Block(11,-4,-12,STONE)
Block(11,-5,-12,STONE)
Block(4,8,-6,STONE)
Block(4,7,-6,STONE)
Block(4,9,-6,STONE)
Block(4,4,-6,STONE)
Block(4,3,-6,STONE)
Block(11,-1,-12,STONE)
Block(4,6,-6,STONE)
Block(11,-2,-12,STONE)
Block(4,5,-6,STONE)
Block(4,0,-6,STONE)
Block(4,2,-6,STONE)
Block(4,1,-6,STONE)
Block(4,42,-1,STONE)
Block(4,43,-1,STONE)
Block(4,40,-1,STONE)
Block(4,41,-1,STONE)
Block(9,2,-1,STONE)
Block(9,1,-1,STONE)
Block(9,4,-1,STONE)
Block(4,44,-1,STONE)
Block(9,3,-1,STONE)
Block(4,45,-1,STONE)
Block(9,0,-1,STONE)
Block(5,-1,2,STONE)
Block(5,-2,2,STONE)
Block(5,-3,2,STONE)
Block(5,-4,2,STONE)
Block(5,-5,2,STONE)
Block(-6,-2,3,STONE)
Block(13,19,-7,STONE)
Block(-6,-1,3,STONE)
Block(-6,-4,3,STONE)
Block(-6,-3,3,STONE)
Block(18,-3,-15,STONE)
Block(-6,-5,3,STONE)
Block(18,-4,-15,STONE)
Block(18,-1,-15,STONE)
Block(18,-2,-15,STONE)
Block(18,-5,-15,STONE)
Block(11,10,-12,STONE)
Block(11,11,-12,STONE)
Block(11,12,-12,STONE)
Block(11,13,-12,STONE)
Block(11,14,-12,STONE)
Block(11,15,-12,STONE)
Block(13,20,-7,STONE)
Block(13,21,-7,STONE)
Block(11,16,-12,STONE)
Block(17,-2,-7,STONE)
Block(13,22,-7,STONE)
Block(17,-1,-7,STONE)
Block(17,-4,-7,STONE)
Block(17,-3,-7,STONE)
Block(17,-5,-7,STONE)
Block(13,10,-7,STONE)
Block(13,11,-7,STONE)
Block(13,12,-7,STONE)
Block(13,13,-7,STONE)
Block(13,14,-7,STONE)
Block(13,15,-7,STONE)
Block(13,16,-7,STONE)
Block(13,17,-7,STONE)
Block(13,18,-7,STONE)
Block(7,39,-2,STONE)
Block(13,-5,-10,STONE)
Block(7,36,-2,STONE)
Block(7,35,-2,STONE)
Block(13,-3,-10,STONE)
Block(7,38,-2,STONE)
Block(13,-4,-10,STONE)
Block(7,37,-2,STONE)
Block(7,32,-2,STONE)
Block(7,31,-2,STONE)
Block(7,34,-2,STONE)
Block(7,33,-2,STONE)
Block(14,6,-8,STONE)
Block(14,7,-8,STONE)
Block(14,4,-8,STONE)
Block(7,30,-2,STONE)
Block(14,5,-8,STONE)
Block(13,-1,-10,STONE)
Block(14,2,-8,STONE)
Block(13,-2,-10,STONE)
Block(14,3,-8,STONE)
Block(14,0,-8,STONE)
Block(14,1,-8,STONE)
Block(10,8,-10,STONE)
Block(10,7,-10,STONE)
Block(10,6,-10,STONE)
Block(10,5,-10,STONE)
Block(12,9,-13,STONE)
Block(12,8,-13,STONE)
Block(10,9,-10,STONE)
Block(10,0,-10,STONE)
Block(19,-2,-10,STONE)
Block(19,-4,-10,STONE)
Block(19,-3,-10,STONE)
Block(10,4,-10,STONE)
Block(7,43,-2,STONE)
Block(19,-5,-10,STONE)
Block(10,3,-10,STONE)
Block(7,42,-2,STONE)
Block(10,2,-10,STONE)
Block(14,8,-8,STONE)
Block(10,1,-10,STONE)
Block(14,9,-8,STONE)
Block(7,44,-2,STONE)
Block(12,1,-1,STONE)
Block(7,41,-2,STONE)
Block(7,40,-2,STONE)
Block(1,-1,5,STONE)
Block(1,-2,5,STONE)
Block(12,0,-1,STONE)
Block(1,-5,5,STONE)
Block(5,-2,-11,STONE)
Block(12,7,-13,STONE)
Block(5,-1,-11,STONE)
Block(12,6,-13,STONE)
Block(5,9,0,STONE)
Block(1,-3,5,STONE)
Block(12,5,-13,STONE)
Block(5,8,0,STONE)
Block(1,-4,5,STONE)
Block(12,4,-13,STONE)
Block(5,7,0,STONE)
Block(12,3,-13,STONE)
Block(5,6,0,STONE)
Block(5,-5,-11,STONE)
Block(12,2,-13,STONE)
Block(5,5,0,STONE)
Block(5,-4,-11,STONE)
Block(12,1,-13,STONE)
Block(5,4,0,STONE)
Block(5,-3,-11,STONE)
Block(12,0,-13,STONE)
Block(5,3,0,STONE)
Block(13,-5,-7,STONE)
Block(6,1,-9,STONE)
Block(5,2,0,STONE)
Block(6,0,-9,STONE)
Block(5,1,0,STONE)
Block(5,0,0,STONE)
Block(6,9,-9,STONE)
Block(6,8,-9,STONE)
Block(6,7,-9,STONE)
Block(6,6,-9,STONE)
Block(6,5,-9,STONE)
Block(6,4,-9,STONE)
Block(6,3,-9,STONE)
Block(6,2,-9,STONE)
Block(9,-5,1,STONE)
Block(9,-4,1,STONE)
Block(9,-3,1,STONE)
Block(9,-2,1,STONE)
Block(9,-1,1,STONE)
Block(13,-1,-7,STONE)
Block(13,-2,-7,STONE)
Block(13,-3,-7,STONE)
Block(13,-4,-7,STONE)
Block(16,-4,-17,STONE)
Block(-1,-5,-4,STONE)
Block(13,19,-10,STONE)
Block(16,-5,-17,STONE)
Block(-1,-4,-4,STONE)
Block(13,17,-10,STONE)
Block(13,18,-10,STONE)
Block(-1,-1,-4,STONE)
Block(-1,-3,-4,STONE)
Block(-1,-2,-4,STONE)
Block(13,11,-10,STONE)
Block(13,12,-10,STONE)
Block(3,19,3,STONE)
Block(3,18,3,STONE)
Block(-10,0,10,STONE)
Block(13,10,-10,STONE)
Block(3,17,3,STONE)
Block(13,15,-10,STONE)
Block(13,16,-10,STONE)
Block(13,13,-10,STONE)
Block(-4,21,0,STONE)
Block(13,14,-10,STONE)
Block(3,12,3,STONE)
Block(3,11,3,STONE)
Block(3,10,3,STONE)
Block(3,16,3,STONE)
Block(3,15,3,STONE)
Block(3,14,3,STONE)
Block(3,13,3,STONE)
Block(1,0,-11,STONE)
Block(-4,20,0,STONE)
Block(-4,16,0,STONE)
Block(13,22,-10,STONE)
Block(-4,17,0,STONE)
Block(-4,14,0,STONE)
Block(13,20,-10,STONE)
Block(-4,15,0,STONE)
Block(13,21,-10,STONE)
Block(-4,12,0,STONE)
Block(-4,13,0,STONE)
Block(-4,10,0,STONE)
Block(-4,11,0,STONE)
Block(-4,18,0,STONE)
Block(-4,19,0,STONE)
Block(0,-4,3,STONE)
Block(0,-5,3,STONE)
Block(0,-1,3,STONE)
Block(0,-2,3,STONE)
Block(0,-3,3,STONE)
Block(-1,0,-8,STONE)
Block(3,-5,-13,STONE)
Block(3,-3,-13,STONE)
Block(3,-4,-13,STONE)
Block(-11,1,7,STONE)
Block(-11,0,7,STONE)
Block(-11,2,7,STONE)
Block(11,20,-4,STONE)
Block(11,23,-4,STONE)
Block(-1,19,-4,STONE)
Block(-1,18,-4,STONE)
Block(11,24,-4,STONE)
Block(11,21,-4,STONE)
Block(11,22,-4,STONE)
Block(-1,15,-4,STONE)
Block(11,27,-4,STONE)
Block(-1,14,-4,STONE)
Block(11,28,-4,STONE)
Block(-1,17,-4,STONE)
Block(11,25,-4,STONE)
Block(-1,16,-4,STONE)
Block(11,26,-4,STONE)
Block(6,50,-5,STONE)
Block(11,18,-4,STONE)
Block(6,51,-5,STONE)
Block(11,19,-4,STONE)
Block(6,52,-5,STONE)
Block(6,53,-5,STONE)
Block(6,54,-5,STONE)
Block(6,55,-5,STONE)
Block(-6,9,6,STONE)
Block(11,30,-4,STONE)
Block(11,31,-4,STONE)
Block(2,2,1,STONE)
Block(11,34,-4,STONE)
Block(6,46,-5,STONE)
Block(2,1,1,STONE)
Block(11,35,-4,STONE)
Block(6,47,-5,STONE)
Block(2,4,1,STONE)
Block(11,32,-4,STONE)
Block(6,48,-5,STONE)
Block(2,3,1,STONE)
Block(11,33,-4,STONE)
Block(6,49,-5,STONE)
Block(2,0,1,STONE)
Block(11,36,-4,STONE)
Block(-4,-2,0,STONE)
Block(0,29,3,STONE)
Block(-4,-3,0,STONE)
Block(11,29,-4,STONE)
Block(6,40,-5,STONE)
Block(-4,-1,0,STONE)
Block(6,41,-5,STONE)
Block(0,25,3,STONE)
Block(6,42,-5,STONE)
Block(0,26,3,STONE)
Block(6,43,-5,STONE)
Block(0,27,3,STONE)
Block(6,44,-5,STONE)
Block(0,28,3,STONE)
Block(6,45,-5,STONE)
Block(0,21,3,STONE)
Block(0,22,3,STONE)
Block(0,23,3,STONE)
Block(0,24,3,STONE)
Block(-4,-4,0,STONE)
Block(-4,-5,0,STONE)
Block(0,20,3,STONE)
Block(7,-4,-2,STONE)
Block(7,-3,-2,STONE)
Block(7,-5,-2,STONE)
Block(7,-2,-2,STONE)
Block(7,-1,-2,STONE)
Block(0,18,3,STONE)
Block(0,19,3,STONE)
Block(6,9,-11,STONE)
Block(6,7,-11,STONE)
Block(0,14,3,STONE)
Block(6,8,-11,STONE)
Block(0,15,3,STONE)
Block(6,5,-11,STONE)
Block(0,16,3,STONE)
Block(6,6,-11,STONE)
Block(0,17,3,STONE)
Block(0,10,3,STONE)
Block(0,11,3,STONE)
Block(0,12,3,STONE)
Block(0,13,3,STONE)
Block(-6,0,6,STONE)
Block(6,3,-11,STONE)
Block(-6,8,6,STONE)
Block(11,12,-4,STONE)
Block(-5,16,1,STONE)
Block(6,4,-11,STONE)
Block(-6,7,6,STONE)
Block(11,13,-4,STONE)
Block(-5,17,1,STONE)
Block(6,1,-11,STONE)
Block(-6,6,6,STONE)
Block(11,10,-4,STONE)
Block(-5,18,1,STONE)
Block(6,2,-11,STONE)
Block(-6,5,6,STONE)
Block(11,11,-4,STONE)
Block(-5,19,1,STONE)
Block(-6,4,6,STONE)
Block(-5,12,1,STONE)
Block(11,16,-4,STONE)
Block(6,0,-11,STONE)
Block(-6,3,6,STONE)
Block(-5,13,1,STONE)
Block(11,17,-4,STONE)
Block(-6,2,6,STONE)
Block(11,14,-4,STONE)
Block(-5,14,1,STONE)
Block(-6,1,6,STONE)
Block(11,15,-4,STONE)
Block(-5,15,1,STONE)
Block(-1,11,-4,STONE)
Block(-1,10,-4,STONE)
Block(-5,20,1,STONE)
Block(-1,13,-4,STONE)
Block(-1,12,-4,STONE)
Block(6,2,-8,STONE)
Block(6,1,-8,STONE)
Block(6,0,-8,STONE)
Block(6,9,-8,STONE)
Block(11,0,-7,STONE)
Block(6,8,-8,STONE)
Block(11,1,-7,STONE)
Block(6,7,-8,STONE)
Block(11,2,-7,STONE)
Block(6,6,-8,STONE)
Block(11,3,-7,STONE)
Block(6,5,-8,STONE)
Block(6,4,-8,STONE)
Block(11,4,-7,STONE)
Block(6,3,-8,STONE)
Block(11,5,-7,STONE)
Block(11,-4,-4,STONE)
Block(11,-5,-4,STONE)
Block(-9,-2,6,STONE)
Block(-9,-1,6,STONE)
Block(-9,-4,6,STONE)
Block(-9,-3,6,STONE)
Block(-9,-5,6,STONE)
Block(-13,-5,10,STONE)
Block(-13,-4,10,STONE)
Block(-13,-3,10,STONE)
Block(18,1,-9,STONE)
Block(5,10,-11,STONE)
Block(18,0,-9,STONE)
Block(7,18,-2,STONE)
Block(-5,2,-1,STONE)
Block(7,17,-2,STONE)
Block(-5,0,-1,STONE)
Block(-5,1,-1,STONE)
Block(7,19,-2,STONE)
Block(7,14,-2,STONE)
Block(7,13,-2,STONE)
Block(7,16,-2,STONE)
Block(7,15,-2,STONE)
Block(7,10,-2,STONE)
Block(7,12,-2,STONE)
Block(7,11,-2,STONE)
Block(7,7,4,STONE)
Block(7,6,4,STONE)
Block(7,5,4,STONE)
Block(7,0,4,STONE)
Block(7,4,4,STONE)
Block(7,3,4,STONE)
Block(7,2,4,STONE)
Block(7,1,4,STONE)
Block(7,29,-2,STONE)
Block(7,28,-2,STONE)
Block(7,25,-2,STONE)
Block(7,24,-2,STONE)
Block(7,27,-2,STONE)
Block(7,26,-2,STONE)
Block(11,-2,-4,STONE)
Block(7,21,-2,STONE)
Block(11,-3,-4,STONE)
Block(7,20,-2,STONE)
Block(7,23,-2,STONE)
Block(11,-1,-4,STONE)
Block(7,22,-2,STONE)
Block(11,6,-7,STONE)
Block(11,7,-7,STONE)
Block(11,8,-7,STONE)
Block(11,9,-7,STONE)
Block(-9,-5,11,STONE)
Block(-9,-3,11,STONE)
Block(-9,-4,11,STONE)
Block(-9,-1,11,STONE)
Block(-9,-2,11,STONE)
Block(18,-5,-7,STONE)
Block(18,-4,-7,STONE)
Block(6,-1,-14,STONE)
Block(6,-2,-14,STONE)
Block(6,-5,-14,STONE)
Block(6,-3,-14,STONE)
Block(6,-4,-14,STONE)
Block(-1,2,3,STONE)
Block(-1,1,3,STONE)
Block(-1,4,3,STONE)
Block(-1,3,3,STONE)
Block(-1,6,3,STONE)
Block(-1,5,3,STONE)
Block(-1,8,3,STONE)
Block(-1,7,3,STONE)
Block(-1,9,3,STONE)
Block(6,-1,4,STONE)
Block(6,-2,4,STONE)
Block(6,-5,4,STONE)
Block(6,-3,4,STONE)
Block(-1,0,3,STONE)
Block(6,-4,4,STONE)
Block(-5,10,1,STONE)
Block(-5,11,1,STONE)
Block(8,0,-7,STONE)
Block(8,1,-7,STONE)
Block(-7,-5,0,STONE)
Block(8,2,-7,STONE)
Block(4,-2,5,STONE)
Block(4,-3,5,STONE)
Block(8,3,-7,STONE)
Block(4,-4,5,STONE)
Block(8,4,-7,STONE)
Block(4,-5,5,STONE)
Block(8,5,-7,STONE)
Block(8,6,-7,STONE)
Block(8,7,-7,STONE)
Block(8,8,-7,STONE)
Block(8,9,-7,STONE)
Block(1,9,-5,STONE)
Block(1,7,-5,STONE)
Block(1,8,-5,STONE)
Block(2,9,1,STONE)
Block(1,5,-5,STONE)
Block(1,6,-5,STONE)
Block(1,3,-5,STONE)
Block(2,6,1,STONE)
Block(1,4,-5,STONE)
Block(2,5,1,STONE)
Block(1,1,-5,STONE)
Block(2,8,1,STONE)
Block(1,2,-5,STONE)
Block(2,7,1,STONE)
Block(1,0,-5,STONE)
Block(-5,-2,1,STONE)
Block(-5,-3,1,STONE)
Block(-5,-4,1,STONE)
Block(-5,-5,1,STONE)
Block(-5,-1,1,STONE)
Block(5,50,-6,STONE)
Block(13,10,-8,STONE)
Block(13,11,-8,STONE)
Block(13,12,-8,STONE)
Block(5,53,-6,STONE)
Block(13,13,-8,STONE)
Block(5,54,-6,STONE)
Block(13,14,-8,STONE)
Block(5,51,-6,STONE)
Block(13,15,-8,STONE)
Block(5,52,-6,STONE)
Block(13,16,-8,STONE)
Block(13,17,-8,STONE)
Block(13,18,-8,STONE)
Block(5,55,-6,STONE)
Block(13,19,-8,STONE)
Block(11,-5,-13,STONE)
Block(11,-4,-13,STONE)
Block(11,-1,-13,STONE)
Block(11,-3,-13,STONE)
Block(11,-2,-13,STONE)
Block(9,9,-2,STONE)
Block(5,39,-6,STONE)
Block(9,8,-2,STONE)
Block(-4,9,1,STONE)
Block(5,37,-6,STONE)
Block(-4,8,1,STONE)
Block(5,38,-6,STONE)
Block(9,5,-2,STONE)
Block(9,4,-2,STONE)
Block(9,7,-2,STONE)
Block(9,6,-2,STONE)
Block(-4,3,1,STONE)
Block(-4,2,1,STONE)
Block(-4,1,1,STONE)
Block(-4,0,1,STONE)
Block(-4,7,1,STONE)
Block(-4,6,1,STONE)
Block(-4,5,1,STONE)
Block(-4,4,1,STONE)
Block(14,9,-5,STONE)
Block(14,7,-5,STONE)
Block(14,8,-5,STONE)
Block(14,5,-5,STONE)
Block(14,6,-5,STONE)
Block(14,3,-5,STONE)
Block(14,4,-5,STONE)
Block(14,1,-5,STONE)
Block(5,31,-6,STONE)
Block(14,2,-5,STONE)
Block(5,32,-6,STONE)
Block(14,0,-5,STONE)
Block(5,30,-6,STONE)
Block(5,35,-6,STONE)
Block(5,36,-6,STONE)
Block(5,33,-6,STONE)
Block(5,34,-6,STONE)
Block(5,48,-6,STONE)
Block(5,49,-6,STONE)
Block(-8,-5,8,STONE)
Block(-8,-4,8,STONE)
Block(-8,-1,8,STONE)
Block(13,20,-8,STONE)
Block(-8,-3,8,STONE)
Block(13,21,-8,STONE)
Block(-8,-2,8,STONE)
Block(13,22,-8,STONE)
Block(5,42,-6,STONE)
Block(5,43,-6,STONE)
Block(5,40,-6,STONE)
Block(5,41,-6,STONE)
Block(5,46,-6,STONE)
Block(5,47,-6,STONE)
Block(5,44,-6,STONE)
Block(5,45,-6,STONE)
Block(-4,-1,-4,STONE)
Block(-4,-2,-4,STONE)
Block(-4,-3,-4,STONE)
Block(-4,-4,-4,STONE)
Block(-4,-5,-4,STONE)
Block(8,-2,-12,STONE)
Block(8,-1,-12,STONE)
Block(8,-1,-2,STONE)
Block(1,-1,4,STONE)
Block(8,-5,-2,STONE)
Block(1,-3,4,STONE)
Block(8,-4,-2,STONE)
Block(1,-2,4,STONE)
Block(1,-5,4,STONE)
Block(8,-3,-2,STONE)
Block(1,-4,4,STONE)
Block(8,-2,-2,STONE)
Block(13,-1,-8,STONE)
Block(13,-2,-8,STONE)
Block(8,-5,-12,STONE)
Block(13,-3,-8,STONE)
Block(8,-4,-12,STONE)
Block(13,-4,-8,STONE)
Block(13,-5,-8,STONE)
Block(8,-3,-12,STONE)
Block(15,1,-11,STONE)
Block(15,2,-11,STONE)
Block(15,0,-11,STONE)
Block(15,5,-11,STONE)
Block(15,6,-11,STONE)
Block(15,3,-11,STONE)
Block(15,4,-11,STONE)
Block(9,1,-2,STONE)
Block(15,9,-11,STONE)
Block(9,0,-2,STONE)
Block(9,3,-2,STONE)
Block(15,7,-11,STONE)
Block(9,2,-2,STONE)
Block(15,8,-11,STONE)
Block(14,-3,-13,STONE)
Block(2,0,-2,STONE)
Block(14,-4,-13,STONE)
Block(14,-5,-13,STONE)
Block(2,4,-2,STONE)
Block(2,3,-2,STONE)
Block(14,-1,-13,STONE)
Block(2,2,-2,STONE)
Block(14,-2,-13,STONE)
Block(2,1,-2,STONE)
Block(2,8,-2,STONE)
Block(2,7,-2,STONE)
Block(2,6,-2,STONE)
Block(2,5,-2,STONE)
Block(2,9,-2,STONE)
Block(8,-4,4,STONE)
Block(5,-3,-6,STONE)
Block(5,-4,-6,STONE)
Block(8,-3,4,STONE)
Block(8,-2,4,STONE)
Block(5,-1,-6,STONE)
Block(5,-2,-6,STONE)
Block(8,-1,4,STONE)
Block(5,-5,-6,STONE)
Block(8,-5,4,STONE)
Block(8,11,-2,STONE)
Block(-2,9,-3,STONE)
Block(8,10,-2,STONE)
Block(-2,8,-3,STONE)
Block(1,11,4,STONE)
Block(-2,7,-3,STONE)
Block(1,10,4,STONE)
Block(1,13,4,STONE)
Block(8,15,-2,STONE)
Block(1,12,4,STONE)
Block(8,14,-2,STONE)
Block(8,13,-2,STONE)
Block(1,15,4,STONE)
Block(8,10,-12,STONE)
Block(8,12,-2,STONE)
Block(1,14,4,STONE)
Block(-2,2,-3,STONE)
Block(8,19,-2,STONE)
Block(-2,1,-3,STONE)
Block(8,18,-2,STONE)
Block(-2,0,-3,STONE)
Block(8,17,-2,STONE)
Block(8,16,-2,STONE)
Block(-2,6,-3,STONE)
Block(-2,5,-3,STONE)
Block(-2,4,-3,STONE)
Block(-2,3,-3,STONE)
Block(7,19,-3,STONE)
Block(7,18,-3,STONE)
Block(7,15,-3,STONE)
Block(7,14,-3,STONE)
Block(7,17,-3,STONE)
Block(7,16,-3,STONE)
Block(7,11,-3,STONE)
Block(7,10,-3,STONE)
Block(7,13,-3,STONE)
Block(7,12,-3,STONE)
Block(0,-3,2,STONE)
Block(8,22,-2,STONE)
Block(0,-4,2,STONE)
Block(8,21,-2,STONE)
Block(0,-5,2,STONE)
Block(8,20,-2,STONE)
Block(8,26,-2,STONE)
Block(8,25,-2,STONE)
Block(0,-1,2,STONE)
Block(8,24,-2,STONE)
Block(0,-2,2,STONE)
Block(8,23,-2,STONE)
Block(8,29,-2,STONE)
Block(8,28,-2,STONE)
Block(8,27,-2,STONE)
Block(-7,-1,6,STONE)
Block(-7,-2,6,STONE)
Block(7,29,-3,STONE)
Block(-7,-3,6,STONE)
Block(-7,-4,6,STONE)
Block(7,26,-3,STONE)
Block(7,25,-3,STONE)
Block(7,28,-3,STONE)
Block(7,27,-3,STONE)
Block(7,22,-3,STONE)
Block(7,21,-3,STONE)
Block(7,24,-3,STONE)
Block(7,23,-3,STONE)
Block(8,33,-2,STONE)
Block(8,32,-2,STONE)
Block(-3,7,7,STONE)
Block(7,20,-3,STONE)
Block(8,31,-2,STONE)
Block(8,30,-2,STONE)
Block(-3,4,7,STONE)
Block(8,37,-2,STONE)
Block(-3,3,7,STONE)
Block(8,36,-2,STONE)
Block(-3,6,7,STONE)
Block(8,35,-2,STONE)
Block(-3,5,7,STONE)
Block(8,34,-2,STONE)
Block(-3,0,7,STONE)
Block(-3,2,7,STONE)
Block(-3,1,7,STONE)
Block(8,38,-2,STONE)
Block(7,37,-3,STONE)
Block(7,36,-3,STONE)
Block(13,-4,-11,STONE)
Block(7,39,-3,STONE)
Block(13,-5,-11,STONE)
Block(7,38,-3,STONE)
Block(7,33,-3,STONE)
Block(7,32,-3,STONE)
Block(7,35,-3,STONE)
Block(7,34,-3,STONE)
Block(7,31,-3,STONE)
Block(7,30,-3,STONE)
Block(13,-2,-11,STONE)
Block(13,-3,-11,STONE)
Block(13,-1,-11,STONE)
Block(-7,-5,6,STONE)
Block(5,9,1,STONE)
Block(5,8,1,STONE)
Block(5,7,1,STONE)
Block(5,6,1,STONE)
Block(5,5,1,STONE)
Block(5,4,1,STONE)
Block(5,3,1,STONE)
Block(5,2,1,STONE)
Block(5,1,1,STONE)
Block(5,17,-6,STONE)
Block(5,0,1,STONE)
Block(5,18,-6,STONE)
Block(11,9,-13,STONE)
Block(5,15,-6,STONE)
Block(5,16,-6,STONE)
Block(5,19,-6,STONE)
Block(7,44,-3,STONE)
Block(7,43,-3,STONE)
Block(7,46,-3,STONE)
Block(7,45,-3,STONE)
Block(0,28,2,STONE)
Block(7,40,-3,STONE)
Block(0,29,2,STONE)
Block(7,42,-3,STONE)
Block(7,41,-3,STONE)
Block(0,24,2,STONE)
Block(0,25,2,STONE)
Block(11,0,-13,STONE)
Block(0,26,2,STONE)
Block(0,27,2,STONE)
Block(11,2,-13,STONE)
Block(0,20,2,STONE)
Block(11,1,-13,STONE)
Block(5,10,-6,STONE)
Block(0,21,2,STONE)
Block(11,4,-13,STONE)
Block(0,22,2,STONE)
Block(11,3,-13,STONE)
Block(0,23,2,STONE)
Block(11,6,-13,STONE)
Block(5,13,-6,STONE)
Block(11,5,-13,STONE)
Block(5,14,-6,STONE)
Block(11,8,-13,STONE)
Block(5,11,-6,STONE)
Block(11,7,-13,STONE)
Block(5,12,-6,STONE)
Block(5,28,-6,STONE)
Block(5,29,-6,STONE)
Block(5,26,-6,STONE)
Block(5,27,-6,STONE)
Block(0,17,2,STONE)
Block(0,18,2,STONE)
Block(0,19,2,STONE)
Block(0,13,2,STONE)
Block(0,14,2,STONE)
Block(0,15,2,STONE)
Block(0,16,2,STONE)
Block(5,20,-6,STONE)
Block(0,10,2,STONE)
Block(5,21,-6,STONE)
Block(0,11,2,STONE)
Block(0,12,2,STONE)
Block(5,24,-6,STONE)
Block(5,25,-6,STONE)
Block(5,22,-6,STONE)
Block(5,23,-6,STONE)
Block(19,-1,-11,STONE)
Block(15,-4,-5,STONE)
Block(19,-3,-11,STONE)
Block(15,-3,-5,STONE)
Block(19,-2,-11,STONE)
Block(19,-5,-11,STONE)
Block(15,-2,-5,STONE)
Block(19,-4,-11,STONE)
Block(15,-1,-5,STONE)
Block(15,-5,-5,STONE)
Block(16,-2,-4,STONE)
Block(16,-4,-4,STONE)
Block(16,-3,-4,STONE)
Block(16,-5,-4,STONE)
Block(1,2,-10,STONE)
Block(1,1,-10,STONE)
Block(1,0,-10,STONE)
Block(7,-3,2,STONE)
Block(7,-2,2,STONE)
Block(7,-5,2,STONE)
Block(13,18,-11,STONE)
Block(7,-4,2,STONE)
Block(13,19,-11,STONE)
Block(7,-1,2,STONE)
Block(1,3,-10,STONE)
Block(13,12,-11,STONE)
Block(13,13,-11,STONE)
Block(12,0,-4,STONE)
Block(13,10,-11,STONE)
Block(12,1,-4,STONE)
Block(13,11,-11,STONE)
Block(13,16,-11,STONE)
Block(13,17,-11,STONE)
Block(13,14,-11,STONE)
Block(13,15,-11,STONE)
Block(12,6,-4,STONE)
Block(12,7,-4,STONE)
Block(12,8,-4,STONE)
Block(12,9,-4,STONE)
Block(12,2,-4,STONE)
Block(12,3,-4,STONE)
Block(12,4,-4,STONE)
Block(12,5,-4,STONE)
Block(16,3,-14,STONE)
Block(16,4,-14,STONE)
Block(16,5,-14,STONE)
Block(10,-5,-1,STONE)
Block(-5,17,2,STONE)
Block(10,-4,-1,STONE)
Block(-5,18,2,STONE)
Block(10,-3,-1,STONE)
Block(-5,19,2,STONE)
Block(10,-2,-1,STONE)
Block(-5,13,2,STONE)
Block(-5,14,2,STONE)
Block(-5,15,2,STONE)
Block(-5,16,2,STONE)
Block(2,9,2,STONE)
Block(1,33,-5,STONE)
Block(-5,20,2,STONE)
Block(2,8,2,STONE)
Block(1,32,-5,STONE)
Block(1,35,-5,STONE)
Block(1,34,-5,STONE)
Block(4,-4,6,STONE)
Block(2,5,2,STONE)
Block(2,4,2,STONE)
Block(4,-3,6,STONE)
Block(2,7,2,STONE)
Block(4,-5,6,STONE)
Block(2,6,2,STONE)
Block(16,0,-14,STONE)
Block(16,1,-14,STONE)
Block(1,31,-5,STONE)
Block(16,2,-14,STONE)
Block(1,30,-5,STONE)
Block(-6,1,5,STONE)
Block(-6,0,5,STONE)
Block(-6,9,5,STONE)
Block(-6,8,5,STONE)
Block(1,29,-5,STONE)
Block(-6,7,5,STONE)
Block(-6,6,5,STONE)
Block(-6,5,5,STONE)
Block(-6,4,5,STONE)
Block(-6,3,5,STONE)
Block(-6,2,5,STONE)
Block(1,22,-5,STONE)
Block(-5,10,2,STONE)
Block(1,21,-5,STONE)
Block(-5,11,2,STONE)
Block(1,24,-5,STONE)
Block(-5,12,2,STONE)
Block(1,23,-5,STONE)
Block(10,-1,-1,STONE)
Block(1,26,-5,STONE)
Block(1,25,-5,STONE)
Block(1,28,-5,STONE)
Block(1,27,-5,STONE)
Block(1,20,-5,STONE)
Block(-11,0,8,STONE)
Block(-11,2,8,STONE)
Block(-11,1,8,STONE)
Block(2,1,2,STONE)
Block(2,0,2,STONE)
Block(7,16,2,STONE)
Block(2,3,2,STONE)
Block(2,2,2,STONE)
Block(7,13,2,STONE)
Block(7,12,2,STONE)
Block(7,15,2,STONE)
Block(7,14,2,STONE)
Block(7,11,2,STONE)
Block(7,10,2,STONE)
Block(0,31,2,STONE)
Block(0,32,2,STONE)
Block(0,33,2,STONE)
Block(0,30,2,STONE)
Block(9,4,-10,STONE)
Block(9,3,-10,STONE)
Block(9,6,-10,STONE)
Block(9,5,-10,STONE)
Block(9,8,-10,STONE)
Block(9,7,-10,STONE)
Block(9,9,-10,STONE)
Block(5,-4,-12,STONE)
Block(5,-5,-12,STONE)
Block(5,-1,-12,STONE)
Block(2,-2,-12,STONE)
Block(2,-3,-12,STONE)
Block(5,-2,-12,STONE)
Block(7,1,5,STONE)
Block(2,-4,-12,STONE)
Block(5,-3,-12,STONE)
Block(7,0,5,STONE)
Block(-1,3,2,STONE)
Block(-1,2,2,STONE)
Block(-1,5,2,STONE)
Block(-1,4,2,STONE)
Block(7,-5,-3,STONE)
Block(-1,7,2,STONE)
Block(7,-4,-3,STONE)
Block(-1,6,2,STONE)
Block(-1,9,2,STONE)
Block(-1,8,2,STONE)
Block(12,-4,0,STONE)
Block(7,-1,-3,STONE)
Block(12,-5,0,STONE)
Block(7,-3,-3,STONE)
Block(7,-2,-3,STONE)
Block(12,-3,0,STONE)
Block(9,0,-10,STONE)
Block(9,2,-10,STONE)
Block(9,1,-10,STONE)
Block(14,15,-6,STONE)
Block(14,16,-6,STONE)
Block(14,13,-6,STONE)
Block(14,14,-6,STONE)
Block(14,11,-6,STONE)
Block(14,12,-6,STONE)
Block(-1,1,2,STONE)
Block(-1,0,2,STONE)
Block(14,10,-6,STONE)
Block(6,3,-7,STONE)
Block(-7,11,6,STONE)
Block(6,2,-7,STONE)
Block(-7,12,6,STONE)
Block(6,1,-7,STONE)
Block(-7,13,6,STONE)
Block(6,0,-7,STONE)
Block(-7,14,6,STONE)
Block(-7,15,6,STONE)
Block(14,17,-6,STONE)
Block(1,19,-5,STONE)
Block(1,18,-5,STONE)
Block(6,9,-7,STONE)
Block(6,8,-7,STONE)
Block(6,7,-7,STONE)
Block(6,6,-7,STONE)
Block(6,5,-7,STONE)
Block(6,4,-7,STONE)
Block(-7,10,6,STONE)
Block(1,11,-5,STONE)
Block(1,10,-5,STONE)
Block(1,13,-5,STONE)
Block(1,12,-5,STONE)
Block(1,15,-5,STONE)
Block(1,14,-5,STONE)
Block(1,17,-5,STONE)
Block(1,16,-5,STONE)
Block(2,-5,-12,STONE)
Block(-1,10,4,STONE)
Block(1,8,-8,STONE)
Block(1,9,-8,STONE)
Block(1,6,-8,STONE)
Block(1,7,-8,STONE)
Block(1,4,-8,STONE)
Block(1,5,-8,STONE)
Block(1,2,-8,STONE)
Block(1,3,-8,STONE)
Block(1,0,-8,STONE)
Block(1,1,-8,STONE)
Block(-1,20,4,STONE)
Block(-1,21,4,STONE)
Block(-1,19,4,STONE)
Block(16,11,-11,STONE)
Block(-1,13,4,STONE)
Block(-1,14,4,STONE)
Block(16,12,-11,STONE)
Block(-1,11,4,STONE)
Block(16,10,-11,STONE)
Block(-1,12,4,STONE)
Block(-1,17,4,STONE)
Block(-1,18,4,STONE)
Block(-1,15,4,STONE)
Block(-1,16,4,STONE)
Block(1,-5,-5,STONE)
Block(1,-4,-5,STONE)
Block(7,11,-10,STONE)
Block(7,10,-10,STONE)
Block(4,-5,-1,STONE)
Block(7,13,-10,STONE)
Block(7,12,-10,STONE)
Block(1,-1,-5,STONE)
Block(4,8,-2,STONE)
Block(4,7,-2,STONE)
Block(1,-3,-5,STONE)
Block(1,-2,-5,STONE)
Block(4,9,-2,STONE)
Block(4,4,-2,STONE)
Block(4,3,-2,STONE)
Block(7,18,-10,STONE)
Block(4,6,-2,STONE)
Block(4,5,-2,STONE)
Block(4,-3,-1,STONE)
Block(4,0,-2,STONE)
Block(7,15,-10,STONE)
Block(4,-4,-1,STONE)
Block(7,14,-10,STONE)
Block(4,-1,-1,STONE)
Block(4,2,-2,STONE)
Block(7,17,-10,STONE)
Block(4,-2,-1,STONE)
Block(4,1,-2,STONE)
Block(7,16,-10,STONE)
Block(15,2,-10,STONE)
Block(15,3,-10,STONE)
Block(15,0,-10,STONE)
Block(15,1,-10,STONE)
Block(15,6,-10,STONE)
Block(15,7,-10,STONE)
Block(15,4,-10,STONE)
Block(15,5,-10,STONE)
Block(8,0,-8,STONE)
Block(8,1,-8,STONE)
Block(8,2,-8,STONE)
Block(8,3,-8,STONE)
Block(8,4,-8,STONE)
Block(8,5,-8,STONE)
Block(8,6,-8,STONE)
Block(8,7,-8,STONE)
Block(15,8,-10,STONE)
Block(8,8,-8,STONE)
Block(15,9,-10,STONE)
Block(8,9,-8,STONE)
Block(3,0,-9,STONE)
Block(-12,-4,4,STONE)
Block(-12,-5,4,STONE)
Block(3,1,-9,STONE)
Block(3,2,-9,STONE)
Block(-4,9,0,STONE)
Block(3,3,-9,STONE)
Block(4,31,-1,STONE)
Block(3,4,-9,STONE)
Block(4,32,-1,STONE)
Block(3,5,-9,STONE)
Block(3,6,-9,STONE)
Block(4,30,-1,STONE)
Block(-5,-3,2,STONE)
Block(-4,4,0,STONE)
Block(-5,-4,2,STONE)
Block(-4,3,0,STONE)
Block(-5,-5,2,STONE)
Block(-4,2,0,STONE)
Block(-4,1,0,STONE)
Block(19,1,-12,STONE)
Block(-4,8,0,STONE)
Block(19,0,-12,STONE)
Block(-4,7,0,STONE)
Block(-5,-1,2,STONE)
Block(-4,6,0,STONE)
Block(-5,-2,2,STONE)
Block(-4,5,0,STONE)
Block(19,3,-12,STONE)
Block(19,2,-12,STONE)
Block(-4,0,0,STONE)
Block(3,7,-9,STONE)
Block(4,35,-1,STONE)
Block(3,8,-9,STONE)
Block(4,36,-1,STONE)
Block(3,9,-9,STONE)
Block(4,33,-1,STONE)
Block(4,34,-1,STONE)
Block(4,39,-1,STONE)
Block(4,37,-1,STONE)
Block(4,38,-1,STONE)
Block(4,20,-1,STONE)
Block(4,21,-1,STONE)
Block(16,-5,-11,STONE)
Block(10,11,-1,STONE)
Block(10,10,-1,STONE)
