
#######################################################################
# +-----------------------------------------------------------------+ #
# |                            BO3 object                           | #
# +-----------------------------------------------------------------+ #
#######################################################################

# This is the config file of a custom object.
# If you add this object correctly to your BiomeConfigs, it will spawn in the world.

# This is the creator of this BO3 object
Author: LordSmellyPants

# A short description of this BO3 object
Description: No description given

# The BO3 version, don't change this! It can be used by external applications to do a version check.
Version: 3

# The settings mode, WriteAll, WriteWithoutComments or WriteDisable. See WorldConfig.
SettingsMode: WriteDisable


#######################################################################
# +-----------------------------------------------------------------+ #
# |                          Main settings                          | #
# +-----------------------------------------------------------------+ #
#######################################################################

# This needs to be set to true to spawn the object in the Tree and Sapling resources.
Tree: false

# The frequency of the BO3 from 1 to 200. Tries this many times to spawn this BO3 when using the CustomObject(...) resource.
# Ignored by Tree(..), Sapling(..) and CustomStructure(..)
Frequency: 1

# The rarity of the BO3 from 0 to 100. Each spawn attempt has rarity% chance to succeed when using the CustomObject(...) resource.
# Ignored by Tree(..), Sapling(..) and CustomStructure(..)
Rarity: 100.0

# If you set this to true, the BO3 will be placed with a random rotation.
RotateRandomly: false

# The spawn height of the BO3 - randomY, highestBlock or highestSolidBlock.
SpawnHeight: highestSolidBlock

# The height limits for the BO3.
MinHeight: 52

MaxHeight: 70

# Objects can have other objects attacthed to it: branches. Branches can also
# have branches attached to it, which can also have branches, etc. This is the
# maximum branch depth for this objects.
MaxBranchDepth: 10

# When spawned with the UseWorld keyword, this BO3 should NOT spawn in the following biomes.
# If you writer.write the BO3 name directly in the BiomeConfigs, this will be ignored.
ExcludedBiomes: All


#######################################################################
# +-----------------------------------------------------------------+ #
# |                      Source block settings                      | #
# +-----------------------------------------------------------------+ #
#######################################################################

# The block(s) the BO3 should spawn in.
SourceBlocks: GRASS

# The maximum percentage of the BO3 that can be outside the SourceBlock.
# The BO3 won't be placed on a location with more blocks outside the SourceBlock than this percentage.
MaxPercentageOutsideSourceBlock: 100

# What to do when a block is about to be placed outside the SourceBlock? (dontPlace, placeAnyway)
OutsideSourceBlock: dontPlace


#######################################################################
# +-----------------------------------------------------------------+ #
# |                              Blocks                             | #
# +-----------------------------------------------------------------+ #
#######################################################################

# All the blocks used in the BO3 are listed here. Possible blocks:
# Block(x,y,z,id[.data][,nbtfile.nbt)
# RandomBlock(x,y,z,id[:data][,nbtfile.nbt],chance[,id[:data][,nbtfile.nbt],chance[,...]])
# So RandomBlock(0,0,0,CHEST,chest.nbt,50,CHEST,anotherchest.nbt,100) will spawn a chest at
# the BO3 origin, and give it a 50% chance to have the contents of chest.nbt, or, if that
# fails, a 100% percent chance to have the contents of anotherchest.nbt.
RandomBlock(-7,-5,-2,COBBLESTONE,30,STONE,20,GRAVEL,15,48,10,GRASS,100)
RandomBlock(-7,-5,-1,COBBLESTONE,30,STONE,20,GRAVEL,15,48,10,GRASS,100)
RandomBlock(-7,-5,0,COBBLESTONE,30,STONE,20,GRAVEL,15,48,10,GRASS,100)
RandomBlock(-7,-5,1,COBBLESTONE,30,STONE,20,GRAVEL,15,48,10,GRASS,100)
RandomBlock(-7,-5,2,COBBLESTONE,30,STONE,20,GRAVEL,15,48,10,GRASS,100)
RandomBlock(-7,-4,-2,COBBLESTONE,30,STONE,20,GRAVEL,15,48,10,GRASS,100)
RandomBlock(-7,-4,-1,COBBLESTONE,30,STONE,20,GRAVEL,15,48,10,GRASS,100)
RandomBlock(-7,-4,0,COBBLESTONE,30,STONE,20,GRAVEL,15,48,10,GRASS,100)
RandomBlock(-7,-4,1,COBBLESTONE,30,STONE,20,GRAVEL,15,48,10,GRASS,100)
RandomBlock(-7,-4,2,COBBLESTONE,30,STONE,20,GRAVEL,15,48,10,GRASS,100)
RandomBlock(-7,-3,-2,COBBLESTONE,30,STONE,20,GRAVEL,15,48,10,GRASS,100)
RandomBlock(-7,-3,-1,COBBLESTONE,30,STONE,20,GRAVEL,15,48,10,GRASS,100)
RandomBlock(-7,-3,0,COBBLESTONE,30,STONE,20,GRAVEL,15,48,10,GRASS,100)
RandomBlock(-7,-3,1,COBBLESTONE,30,STONE,20,GRAVEL,15,48,10,GRASS,100)
RandomBlock(-7,-3,2,COBBLESTONE,30,STONE,20,GRAVEL,15,48,10,GRASS,100)
RandomBlock(-7,-2,-2,COBBLESTONE,30,STONE,20,GRAVEL,15,48,10,GRASS,100)
RandomBlock(-7,-2,-1,COBBLESTONE,30,STONE,20,GRAVEL,15,48,10,GRASS,100)
RandomBlock(-7,-2,0,COBBLESTONE,30,STONE,20,GRAVEL,15,48,10,GRASS,100)
RandomBlock(-7,-2,1,COBBLESTONE,30,STONE,20,GRAVEL,15,48,10,GRASS,100)
RandomBlock(-7,-2,2,COBBLESTONE,30,STONE,20,GRAVEL,15,48,10,GRASS,100)
RandomBlock(-7,-1,-2,COBBLESTONE,30,STONE,20,GRAVEL,15,48,10,GRASS,100)
RandomBlock(-7,-1,-1,COBBLESTONE,30,STONE,20,GRAVEL,15,48,10,GRASS,100)
RandomBlock(-7,-1,0,COBBLESTONE,30,STONE,20,GRAVEL,15,48,10,GRASS,100)
RandomBlock(-7,-1,1,COBBLESTONE,30,STONE,20,GRAVEL,15,48,10,GRASS,100)
RandomBlock(-7,-1,2,COBBLESTONE,30,STONE,20,GRAVEL,15,48,10,GRASS,100)
RandomBlock(-7,0,-2,COBBLESTONE,30,STONE,20,GRAVEL,15,48,10,GRASS,100)
RandomBlock(-7,0,-1,COBBLESTONE,30,STONE,20,GRAVEL,15,48,10,GRASS,100)
RandomBlock(-7,0,0,COBBLESTONE,30,STONE,20,GRAVEL,15,48,10,GRASS,100)
RandomBlock(-7,0,1,COBBLESTONE,30,STONE,20,GRAVEL,15,48,10,GRASS,100)
RandomBlock(-7,0,2,COBBLESTONE,30,STONE,20,GRAVEL,15,48,10,GRASS,100)
RandomBlock(-7,1,-2,COBBLESTONE,30,STONE,20,GRAVEL,15,48,10,GRASS,100)
RandomBlock(-7,1,-1,COBBLESTONE,30,STONE,20,GRAVEL,15,48,10,GRASS,100)
RandomBlock(-7,1,0,COBBLESTONE,30,STONE,20,GRAVEL,15,48,10,GRASS,100)
RandomBlock(-7,1,1,COBBLESTONE,30,STONE,20,GRAVEL,15,48,10,GRASS,100)
RandomBlock(-7,1,2,COBBLESTONE,30,STONE,20,GRAVEL,15,48,10,GRASS,100)
RandomBlock(-7,2,-2,COBBLESTONE,30,STONE,20,GRAVEL,15,48,10,GRASS,100)
RandomBlock(-7,2,-1,COBBLESTONE,30,STONE,20,GRAVEL,15,48,10,GRASS,100)
RandomBlock(-7,2,0,COBBLESTONE,30,STONE,20,GRAVEL,15,48,10,GRASS,100)
RandomBlock(-7,2,1,COBBLESTONE,30,STONE,20,GRAVEL,15,48,10,GRASS,100)
RandomBlock(-7,2,2,COBBLESTONE,30,STONE,20,GRAVEL,15,48,10,GRASS,100)
RandomBlock(-7,3,-2,COBBLESTONE,30,STONE,20,GRAVEL,15,48,10,GRASS,100)
RandomBlock(-7,3,-1,COBBLESTONE,30,STONE,20,GRAVEL,15,48,10,GRASS,100)
RandomBlock(-7,3,0,COBBLESTONE,30,STONE,20,GRAVEL,15,48,10,GRASS,100)
RandomBlock(-7,3,1,COBBLESTONE,30,STONE,20,GRAVEL,15,48,10,GRASS,100)
RandomBlock(-7,3,2,COBBLESTONE,30,STONE,20,GRAVEL,15,48,10,GRASS,100)
RandomBlock(-7,4,-2,COBBLESTONE,30,STONE,20,GRAVEL,15,48,10,GRASS,100)
RandomBlock(-7,4,-1,COBBLESTONE,30,STONE,20,GRAVEL,15,48,10,GRASS,100)
RandomBlock(-7,4,0,COBBLESTONE,30,STONE,20,GRAVEL,15,48,10,GRASS,100)
RandomBlock(-7,4,1,COBBLESTONE,30,STONE,20,GRAVEL,15,48,10,GRASS,100)
RandomBlock(-7,4,2,COBBLESTONE,30,STONE,20,GRAVEL,15,48,10,GRASS,100)
RandomBlock(-7,5,-2,COBBLESTONE,30,STONE,20,GRAVEL,15,48,10,GRASS,100)
RandomBlock(-7,5,-1,COBBLESTONE,30,STONE,20,GRAVEL,15,48,10,GRASS,100)
RandomBlock(-7,5,0,COBBLESTONE,30,STONE,20,GRAVEL,15,48,10,GRASS,100)
RandomBlock(-7,5,1,COBBLESTONE,30,STONE,20,GRAVEL,15,48,10,GRASS,100)
RandomBlock(-7,5,2,COBBLESTONE,30,STONE,20,GRAVEL,15,48,10,GRASS,100)
RandomBlock(-6,-5,-2,COBBLESTONE,30,STONE,20,GRAVEL,15,48,10,GRASS,100)
RandomBlock(-6,-5,-1,COBBLESTONE,30,STONE,20,GRAVEL,15,48,10,GRASS,100)
RandomBlock(-6,-5,0,COBBLESTONE,30,STONE,20,GRAVEL,15,48,10,GRASS,100)
RandomBlock(-6,-5,1,COBBLESTONE,30,STONE,20,GRAVEL,15,48,10,GRASS,100)
RandomBlock(-6,-5,2,COBBLESTONE,30,STONE,20,GRAVEL,15,48,10,GRASS,100)
RandomBlock(-6,-4,-2,COBBLESTONE,30,STONE,20,GRAVEL,15,48,10,GRASS,100)
RandomBlock(-6,-4,-1,COBBLESTONE,30,STONE,20,GRAVEL,15,48,10,GRASS,100)
RandomBlock(-6,-4,0,COBBLESTONE,30,STONE,20,GRAVEL,15,48,10,GRASS,100)
RandomBlock(-6,-4,1,COBBLESTONE,30,STONE,20,GRAVEL,15,48,10,GRASS,100)
RandomBlock(-6,-4,2,COBBLESTONE,30,STONE,20,GRAVEL,15,48,10,GRASS,100)
RandomBlock(-6,-3,-2,COBBLESTONE,30,STONE,20,GRAVEL,15,48,10,GRASS,100)
RandomBlock(-6,-3,-1,COBBLESTONE,30,STONE,20,GRAVEL,15,48,10,GRASS,100)
RandomBlock(-6,-3,0,COBBLESTONE,30,STONE,20,GRAVEL,15,48,10,GRASS,100)
RandomBlock(-6,-3,1,COBBLESTONE,30,STONE,20,GRAVEL,15,48,10,GRASS,100)
RandomBlock(-6,-3,2,COBBLESTONE,30,STONE,20,GRAVEL,15,48,10,GRASS,100)
RandomBlock(-6,-2,-2,COBBLESTONE,30,STONE,20,GRAVEL,15,48,10,GRASS,100)
RandomBlock(-6,-2,-1,COBBLESTONE,30,STONE,20,GRAVEL,15,48,10,GRASS,100)
RandomBlock(-6,-2,0,COBBLESTONE,30,STONE,20,GRAVEL,15,48,10,GRASS,100)
RandomBlock(-6,-2,1,COBBLESTONE,30,STONE,20,GRAVEL,15,48,10,GRASS,100)
RandomBlock(-6,-2,2,COBBLESTONE,30,STONE,20,GRAVEL,15,48,10,GRASS,100)
RandomBlock(-6,-1,-2,COBBLESTONE,30,STONE,20,GRAVEL,15,48,10,GRASS,100)
RandomBlock(-6,-1,-1,COBBLESTONE,30,STONE,20,GRAVEL,15,48,10,GRASS,100)
RandomBlock(-6,-1,0,COBBLESTONE,30,STONE,20,GRAVEL,15,48,10,GRASS,100)
RandomBlock(-6,-1,1,COBBLESTONE,30,STONE,20,GRAVEL,15,48,10,GRASS,100)
RandomBlock(-6,-1,2,COBBLESTONE,30,STONE,20,GRAVEL,15,48,10,GRASS,100)
RandomBlock(-6,0,-2,COBBLESTONE,30,STONE,20,GRAVEL,15,48,10,GRASS,100)
RandomBlock(-6,0,-1,COBBLESTONE,30,STONE,20,GRAVEL,15,48,10,GRASS,100)
RandomBlock(-6,0,0,COBBLESTONE,30,STONE,20,GRAVEL,15,48,10,GRASS,100)
RandomBlock(-6,0,1,COBBLESTONE,30,STONE,20,GRAVEL,15,48,10,GRASS,100)
RandomBlock(-6,0,2,COBBLESTONE,30,STONE,20,GRAVEL,15,48,10,GRASS,100)
RandomBlock(-6,1,-2,COBBLESTONE,30,STONE,20,GRAVEL,15,48,10,GRASS,100)
RandomBlock(-6,1,-1,COBBLESTONE,30,STONE,20,GRAVEL,15,48,10,GRASS,100)
RandomBlock(-6,1,0,COBBLESTONE,30,STONE,20,GRAVEL,15,48,10,GRASS,100)
RandomBlock(-6,1,1,COBBLESTONE,30,STONE,20,GRAVEL,15,48,10,GRASS,100)
RandomBlock(-6,1,2,COBBLESTONE,30,STONE,20,GRAVEL,15,48,10,GRASS,100)
RandomBlock(-6,2,-2,COBBLESTONE,30,STONE,20,GRAVEL,15,48,10,GRASS,100)
RandomBlock(-6,2,-1,COBBLESTONE,30,STONE,20,GRAVEL,15,48,10,GRASS,100)
RandomBlock(-6,2,0,COBBLESTONE,30,STONE,20,GRAVEL,15,48,10,GRASS,100)
RandomBlock(-6,2,1,COBBLESTONE,30,STONE,20,GRAVEL,15,48,10,GRASS,100)
RandomBlock(-6,2,2,COBBLESTONE,30,STONE,20,GRAVEL,15,48,10,GRASS,100)
RandomBlock(-6,3,-2,COBBLESTONE,30,STONE,20,GRAVEL,15,48,10,GRASS,100)
RandomBlock(-6,3,-1,COBBLESTONE,30,STONE,20,GRAVEL,15,48,10,GRASS,100)
RandomBlock(-6,3,0,COBBLESTONE,30,STONE,20,GRAVEL,15,48,10,GRASS,100)
RandomBlock(-6,3,1,COBBLESTONE,30,STONE,20,GRAVEL,15,48,10,GRASS,100)
RandomBlock(-6,3,2,COBBLESTONE,30,STONE,20,GRAVEL,15,48,10,GRASS,100)
RandomBlock(-6,4,-2,COBBLESTONE,30,STONE,20,GRAVEL,15,48,10,GRASS,100)
RandomBlock(-6,4,-1,COBBLESTONE,30,STONE,20,GRAVEL,15,48,10,GRASS,100)
RandomBlock(-6,4,0,COBBLESTONE,30,STONE,20,GRAVEL,15,48,10,GRASS,100)
RandomBlock(-6,4,1,COBBLESTONE,30,STONE,20,GRAVEL,15,48,10,GRASS,100)
RandomBlock(-6,4,2,COBBLESTONE,30,STONE,20,GRAVEL,15,48,10,GRASS,100)
RandomBlock(-6,5,-2,COBBLESTONE,30,STONE,20,GRAVEL,15,48,10,GRASS,100)
RandomBlock(-6,5,-1,COBBLESTONE,30,STONE,20,GRAVEL,15,48,10,GRASS,100)
RandomBlock(-6,5,0,COBBLESTONE,30,STONE,20,GRAVEL,15,48,10,GRASS,100)
RandomBlock(-6,5,1,COBBLESTONE,30,STONE,20,GRAVEL,15,48,10,GRASS,100)
RandomBlock(-6,5,2,COBBLESTONE,30,STONE,20,GRAVEL,15,48,10,GRASS,100)
RandomBlock(-5,-5,-2,COBBLESTONE,30,STONE,20,GRAVEL,15,48,10,GRASS,100)
RandomBlock(-5,-5,-1,COBBLESTONE,30,STONE,20,GRAVEL,15,48,10,GRASS,100)
RandomBlock(-5,-5,0,COBBLESTONE,30,STONE,20,GRAVEL,15,48,10,GRASS,100)
RandomBlock(-5,-5,1,COBBLESTONE,30,STONE,20,GRAVEL,15,48,10,GRASS,100)
RandomBlock(-5,-5,2,COBBLESTONE,30,STONE,20,GRAVEL,15,48,10,GRASS,100)
RandomBlock(-5,-4,-2,COBBLESTONE,30,STONE,20,GRAVEL,15,48,10,GRASS,100)
RandomBlock(-5,-4,-1,COBBLESTONE,30,STONE,20,GRAVEL,15,48,10,GRASS,100)
RandomBlock(-5,-4,0,COBBLESTONE,30,STONE,20,GRAVEL,15,48,10,GRASS,100)
RandomBlock(-5,-4,1,COBBLESTONE,30,STONE,20,GRAVEL,15,48,10,GRASS,100)
RandomBlock(-5,-4,2,COBBLESTONE,30,STONE,20,GRAVEL,15,48,10,GRASS,100)
RandomBlock(-5,-3,-2,COBBLESTONE,30,STONE,20,GRAVEL,15,48,10,GRASS,100)
RandomBlock(-5,-3,-1,COBBLESTONE,30,STONE,20,GRAVEL,15,48,10,GRASS,100)
RandomBlock(-5,-3,0,COBBLESTONE,30,STONE,20,GRAVEL,15,48,10,GRASS,100)
RandomBlock(-5,-3,1,COBBLESTONE,30,STONE,20,GRAVEL,15,48,10,GRASS,100)
RandomBlock(-5,-3,2,COBBLESTONE,30,STONE,20,GRAVEL,15,48,10,GRASS,100)
RandomBlock(-5,-2,-2,COBBLESTONE,30,STONE,20,GRAVEL,15,48,10,GRASS,100)
RandomBlock(-5,-2,-1,COBBLESTONE,30,STONE,20,GRAVEL,15,48,10,GRASS,100)
RandomBlock(-5,-2,0,COBBLESTONE,30,STONE,20,GRAVEL,15,48,10,GRASS,100)
RandomBlock(-5,-2,1,COBBLESTONE,30,STONE,20,GRAVEL,15,48,10,GRASS,100)
RandomBlock(-5,-2,2,COBBLESTONE,30,STONE,20,GRAVEL,15,48,10,GRASS,100)
RandomBlock(-5,-1,-2,COBBLESTONE,30,STONE,20,GRAVEL,15,48,10,GRASS,100)
RandomBlock(-5,-1,-1,COBBLESTONE,30,STONE,20,GRAVEL,15,48,10,GRASS,100)
RandomBlock(-5,-1,0,COBBLESTONE,30,STONE,20,GRAVEL,15,48,10,GRASS,100)
RandomBlock(-5,-1,1,COBBLESTONE,30,STONE,20,GRAVEL,15,48,10,GRASS,100)
RandomBlock(-5,-1,2,COBBLESTONE,30,STONE,20,GRAVEL,15,48,10,GRASS,100)
RandomBlock(-5,0,-2,COBBLESTONE,30,STONE,20,GRAVEL,15,48,10,GRASS,100)
RandomBlock(-5,0,-1,COBBLESTONE,30,STONE,20,GRAVEL,15,48,10,GRASS,100)
RandomBlock(-5,0,0,COBBLESTONE,30,STONE,20,GRAVEL,15,48,10,GRASS,100)
RandomBlock(-5,0,1,COBBLESTONE,30,STONE,20,GRAVEL,15,48,10,GRASS,100)
RandomBlock(-5,0,2,COBBLESTONE,30,STONE,20,GRAVEL,15,48,10,GRASS,100)
RandomBlock(-5,1,-2,COBBLESTONE,30,STONE,20,GRAVEL,15,48,10,GRASS,100)
RandomBlock(-5,1,-1,COBBLESTONE,30,STONE,20,GRAVEL,15,48,10,GRASS,100)
RandomBlock(-5,1,0,COBBLESTONE,30,STONE,20,GRAVEL,15,48,10,GRASS,100)
RandomBlock(-5,1,1,COBBLESTONE,30,STONE,20,GRAVEL,15,48,10,GRASS,100)
RandomBlock(-5,1,2,COBBLESTONE,30,STONE,20,GRAVEL,15,48,10,GRASS,100)
RandomBlock(-5,2,-2,COBBLESTONE,30,STONE,20,GRAVEL,15,48,10,GRASS,100)
RandomBlock(-5,2,-1,COBBLESTONE,30,STONE,20,GRAVEL,15,48,10,GRASS,100)
RandomBlock(-5,2,0,COBBLESTONE,30,STONE,20,GRAVEL,15,48,10,GRASS,100)
RandomBlock(-5,2,1,COBBLESTONE,30,STONE,20,GRAVEL,15,48,10,GRASS,100)
RandomBlock(-5,2,2,COBBLESTONE,30,STONE,20,GRAVEL,15,48,10,GRASS,100)
RandomBlock(-5,3,-2,COBBLESTONE,30,STONE,20,GRAVEL,15,48,10,GRASS,100)
RandomBlock(-5,3,-1,COBBLESTONE,30,STONE,20,GRAVEL,15,48,10,GRASS,100)
RandomBlock(-5,3,0,COBBLESTONE,30,STONE,20,GRAVEL,15,48,10,GRASS,100)
RandomBlock(-5,3,1,COBBLESTONE,30,STONE,20,GRAVEL,15,48,10,GRASS,100)
RandomBlock(-5,3,2,COBBLESTONE,30,STONE,20,GRAVEL,15,48,10,GRASS,100)
RandomBlock(-5,4,-2,COBBLESTONE,30,STONE,20,GRAVEL,15,48,10,GRASS,100)
RandomBlock(-5,4,-1,COBBLESTONE,30,STONE,20,GRAVEL,15,48,10,GRASS,100)
RandomBlock(-5,4,0,COBBLESTONE,30,STONE,20,GRAVEL,15,48,10,GRASS,100)
RandomBlock(-5,4,1,COBBLESTONE,30,STONE,20,GRAVEL,15,48,10,GRASS,100)
RandomBlock(-5,4,2,COBBLESTONE,30,STONE,20,GRAVEL,15,48,10,GRASS,100)
RandomBlock(-5,5,-2,COBBLESTONE,30,STONE,20,GRAVEL,15,48,10,GRASS,100)
RandomBlock(-5,5,-1,COBBLESTONE,30,STONE,20,GRAVEL,15,48,10,GRASS,100)
RandomBlock(-5,5,0,COBBLESTONE,30,STONE,20,GRAVEL,15,48,10,GRASS,100)
RandomBlock(-5,5,1,COBBLESTONE,30,STONE,20,GRAVEL,15,48,10,GRASS,100)
RandomBlock(-5,5,2,COBBLESTONE,30,STONE,20,GRAVEL,15,48,10,GRASS,100)
RandomBlock(-4,-5,-2,COBBLESTONE,30,STONE,20,GRAVEL,15,48,10,GRASS,100)
RandomBlock(-4,-5,-1,COBBLESTONE,30,STONE,20,GRAVEL,15,48,10,GRASS,100)
RandomBlock(-4,-5,0,COBBLESTONE,30,STONE,20,GRAVEL,15,48,10,GRASS,100)
RandomBlock(-4,-5,1,COBBLESTONE,30,STONE,20,GRAVEL,15,48,10,GRASS,100)
RandomBlock(-4,-5,2,COBBLESTONE,30,STONE,20,GRAVEL,15,48,10,GRASS,100)
RandomBlock(-4,-4,-2,COBBLESTONE,30,STONE,20,GRAVEL,15,48,10,GRASS,100)
RandomBlock(-4,-4,-1,COBBLESTONE,30,STONE,20,GRAVEL,15,48,10,GRASS,100)
RandomBlock(-4,-4,0,COBBLESTONE,30,STONE,20,GRAVEL,15,48,10,GRASS,100)
RandomBlock(-4,-4,1,COBBLESTONE,30,STONE,20,GRAVEL,15,48,10,GRASS,100)
RandomBlock(-4,-4,2,COBBLESTONE,30,STONE,20,GRAVEL,15,48,10,GRASS,100)
RandomBlock(-4,-3,-2,COBBLESTONE,30,STONE,20,GRAVEL,15,48,10,GRASS,100)
RandomBlock(-4,-3,-1,COBBLESTONE,30,STONE,20,GRAVEL,15,48,10,GRASS,100)
RandomBlock(-4,-3,0,COBBLESTONE,30,STONE,20,GRAVEL,15,48,10,GRASS,100)
RandomBlock(-4,-3,1,COBBLESTONE,30,STONE,20,GRAVEL,15,48,10,GRASS,100)
RandomBlock(-4,-3,2,COBBLESTONE,30,STONE,20,GRAVEL,15,48,10,GRASS,100)
RandomBlock(-4,-2,-2,COBBLESTONE,30,STONE,20,GRAVEL,15,48,10,GRASS,100)
RandomBlock(-4,-2,-1,COBBLESTONE,30,STONE,20,GRAVEL,15,48,10,GRASS,100)
RandomBlock(-4,-2,0,COBBLESTONE,30,STONE,20,GRAVEL,15,48,10,GRASS,100)
RandomBlock(-4,-2,1,COBBLESTONE,30,STONE,20,GRAVEL,15,48,10,GRASS,100)
RandomBlock(-4,-2,2,COBBLESTONE,30,STONE,20,GRAVEL,15,48,10,GRASS,100)
RandomBlock(-4,-1,-2,COBBLESTONE,30,STONE,20,GRAVEL,15,48,10,GRASS,100)
RandomBlock(-4,-1,-1,COBBLESTONE,30,STONE,20,GRAVEL,15,48,10,GRASS,100)
RandomBlock(-4,-1,0,COBBLESTONE,30,STONE,20,GRAVEL,15,48,10,GRASS,100)
RandomBlock(-4,-1,1,COBBLESTONE,30,STONE,20,GRAVEL,15,48,10,GRASS,100)
RandomBlock(-4,-1,2,COBBLESTONE,30,STONE,20,GRAVEL,15,48,10,GRASS,100)
RandomBlock(-4,0,-2,COBBLESTONE,30,STONE,20,GRAVEL,15,48,10,GRASS,100)
RandomBlock(-4,0,-1,COBBLESTONE,30,STONE,20,GRAVEL,15,48,10,GRASS,100)
RandomBlock(-4,0,0,COBBLESTONE,30,STONE,20,GRAVEL,15,48,10,GRASS,100)
RandomBlock(-4,0,1,COBBLESTONE,30,STONE,20,GRAVEL,15,48,10,GRASS,100)
RandomBlock(-4,0,2,COBBLESTONE,30,STONE,20,GRAVEL,15,48,10,GRASS,100)
RandomBlock(-4,1,-2,COBBLESTONE,30,STONE,20,GRAVEL,15,48,10,GRASS,100)
RandomBlock(-4,1,-1,COBBLESTONE,30,STONE,20,GRAVEL,15,48,10,GRASS,100)
RandomBlock(-4,1,0,COBBLESTONE,30,STONE,20,GRAVEL,15,48,10,GRASS,100)
RandomBlock(-4,1,1,COBBLESTONE,30,STONE,20,GRAVEL,15,48,10,GRASS,100)
RandomBlock(-4,1,2,COBBLESTONE,30,STONE,20,GRAVEL,15,48,10,GRASS,100)
RandomBlock(-4,2,-2,COBBLESTONE,30,STONE,20,GRAVEL,15,48,10,GRASS,100)
RandomBlock(-4,2,-1,COBBLESTONE,30,STONE,20,GRAVEL,15,48,10,GRASS,100)
RandomBlock(-4,2,0,COBBLESTONE,30,STONE,20,GRAVEL,15,48,10,GRASS,100)
RandomBlock(-4,2,1,COBBLESTONE,30,STONE,20,GRAVEL,15,48,10,GRASS,100)
RandomBlock(-4,2,2,COBBLESTONE,30,STONE,20,GRAVEL,15,48,10,GRASS,100)
RandomBlock(-4,3,-2,COBBLESTONE,30,STONE,20,GRAVEL,15,48,10,GRASS,100)
RandomBlock(-4,3,-1,COBBLESTONE,30,STONE,20,GRAVEL,15,48,10,GRASS,100)
RandomBlock(-4,3,0,COBBLESTONE,30,STONE,20,GRAVEL,15,48,10,GRASS,100)
RandomBlock(-4,3,1,COBBLESTONE,30,STONE,20,GRAVEL,15,48,10,GRASS,100)
RandomBlock(-4,3,2,COBBLESTONE,30,STONE,20,GRAVEL,15,48,10,GRASS,100)
RandomBlock(-4,4,-2,COBBLESTONE,30,STONE,20,GRAVEL,15,48,10,GRASS,100)
RandomBlock(-4,4,-1,COBBLESTONE,30,STONE,20,GRAVEL,15,48,10,GRASS,100)
RandomBlock(-4,4,0,COBBLESTONE,30,STONE,20,GRAVEL,15,48,10,GRASS,100)
RandomBlock(-4,4,1,COBBLESTONE,30,STONE,20,GRAVEL,15,48,10,GRASS,100)
RandomBlock(-4,4,2,COBBLESTONE,30,STONE,20,GRAVEL,15,48,10,GRASS,100)
RandomBlock(-4,5,-2,COBBLESTONE,30,STONE,20,GRAVEL,15,48,10,GRASS,100)
RandomBlock(-4,5,-1,COBBLESTONE,30,STONE,20,GRAVEL,15,48,10,GRASS,100)
RandomBlock(-4,5,0,COBBLESTONE,30,STONE,20,GRAVEL,15,48,10,GRASS,100)
RandomBlock(-4,5,1,COBBLESTONE,30,STONE,20,GRAVEL,15,48,10,GRASS,100)
RandomBlock(-4,5,2,COBBLESTONE,30,STONE,20,GRAVEL,15,48,10,GRASS,100)
RandomBlock(-3,-5,-2,COBBLESTONE,30,STONE,20,GRAVEL,15,48,10,GRASS,100)
RandomBlock(-3,-5,-1,COBBLESTONE,30,STONE,20,GRAVEL,15,48,10,GRASS,100)
RandomBlock(-3,-5,0,COBBLESTONE,30,STONE,20,GRAVEL,15,48,10,GRASS,100)
RandomBlock(-3,-5,1,COBBLESTONE,30,STONE,20,GRAVEL,15,48,10,GRASS,100)
RandomBlock(-3,-5,2,COBBLESTONE,30,STONE,20,GRAVEL,15,48,10,GRASS,100)
RandomBlock(-3,-4,-2,COBBLESTONE,30,STONE,20,GRAVEL,15,48,10,GRASS,100)
RandomBlock(-3,-4,-1,COBBLESTONE,30,STONE,20,GRAVEL,15,48,10,GRASS,100)
RandomBlock(-3,-4,0,COBBLESTONE,30,STONE,20,GRAVEL,15,48,10,GRASS,100)
RandomBlock(-3,-4,1,COBBLESTONE,30,STONE,20,GRAVEL,15,48,10,GRASS,100)
RandomBlock(-3,-4,2,COBBLESTONE,30,STONE,20,GRAVEL,15,48,10,GRASS,100)
RandomBlock(-3,-3,-2,COBBLESTONE,30,STONE,20,GRAVEL,15,48,10,GRASS,100)
RandomBlock(-3,-3,-1,COBBLESTONE,30,STONE,20,GRAVEL,15,48,10,GRASS,100)
RandomBlock(-3,-3,0,COBBLESTONE,30,STONE,20,GRAVEL,15,48,10,GRASS,100)
RandomBlock(-3,-3,1,COBBLESTONE,30,STONE,20,GRAVEL,15,48,10,GRASS,100)
RandomBlock(-3,-3,2,COBBLESTONE,30,STONE,20,GRAVEL,15,48,10,GRASS,100)
RandomBlock(-3,-2,-2,COBBLESTONE,30,STONE,20,GRAVEL,15,48,10,GRASS,100)
RandomBlock(-3,-2,-1,COBBLESTONE,30,STONE,20,GRAVEL,15,48,10,GRASS,100)
RandomBlock(-3,-2,0,COBBLESTONE,30,STONE,20,GRAVEL,15,48,10,GRASS,100)
RandomBlock(-3,-2,1,COBBLESTONE,30,STONE,20,GRAVEL,15,48,10,GRASS,100)
RandomBlock(-3,-2,2,COBBLESTONE,30,STONE,20,GRAVEL,15,48,10,GRASS,100)
RandomBlock(-3,-1,-2,COBBLESTONE,30,STONE,20,GRAVEL,15,48,10,GRASS,100)
RandomBlock(-3,-1,-1,COBBLESTONE,30,STONE,20,GRAVEL,15,48,10,GRASS,100)
RandomBlock(-3,-1,0,COBBLESTONE,30,STONE,20,GRAVEL,15,48,10,GRASS,100)
RandomBlock(-3,-1,1,COBBLESTONE,30,STONE,20,GRAVEL,15,48,10,GRASS,100)
RandomBlock(-3,-1,2,COBBLESTONE,30,STONE,20,GRAVEL,15,48,10,GRASS,100)
RandomBlock(-3,0,-2,COBBLESTONE,30,STONE,20,GRAVEL,15,48,10,GRASS,100)
RandomBlock(-3,0,-1,COBBLESTONE,30,STONE,20,GRAVEL,15,48,10,GRASS,100)
RandomBlock(-3,0,0,COBBLESTONE,30,STONE,20,GRAVEL,15,48,10,GRASS,100)
RandomBlock(-3,0,1,COBBLESTONE,30,STONE,20,GRAVEL,15,48,10,GRASS,100)
RandomBlock(-3,0,2,COBBLESTONE,30,STONE,20,GRAVEL,15,48,10,GRASS,100)
RandomBlock(-3,1,-2,COBBLESTONE,30,STONE,20,GRAVEL,15,48,10,GRASS,100)
RandomBlock(-3,1,-1,COBBLESTONE,30,STONE,20,GRAVEL,15,48,10,GRASS,100)
RandomBlock(-3,1,0,COBBLESTONE,30,STONE,20,GRAVEL,15,48,10,GRASS,100)
RandomBlock(-3,1,1,COBBLESTONE,30,STONE,20,GRAVEL,15,48,10,GRASS,100)
RandomBlock(-3,1,2,COBBLESTONE,30,STONE,20,GRAVEL,15,48,10,GRASS,100)
RandomBlock(-3,2,-2,COBBLESTONE,30,STONE,20,GRAVEL,15,48,10,GRASS,100)
RandomBlock(-3,2,-1,COBBLESTONE,30,STONE,20,GRAVEL,15,48,10,GRASS,100)
RandomBlock(-3,2,0,COBBLESTONE,30,STONE,20,GRAVEL,15,48,10,GRASS,100)
RandomBlock(-3,2,1,COBBLESTONE,30,STONE,20,GRAVEL,15,48,10,GRASS,100)
RandomBlock(-3,2,2,COBBLESTONE,30,STONE,20,GRAVEL,15,48,10,GRASS,100)
RandomBlock(-3,3,-2,COBBLESTONE,30,STONE,20,GRAVEL,15,48,10,GRASS,100)
RandomBlock(-3,3,-1,COBBLESTONE,30,STONE,20,GRAVEL,15,48,10,GRASS,100)
RandomBlock(-3,3,0,COBBLESTONE,30,STONE,20,GRAVEL,15,48,10,GRASS,100)
RandomBlock(-3,3,1,COBBLESTONE,30,STONE,20,GRAVEL,15,48,10,GRASS,100)
RandomBlock(-3,3,2,COBBLESTONE,30,STONE,20,GRAVEL,15,48,10,GRASS,100)
RandomBlock(-3,4,-2,COBBLESTONE,30,STONE,20,GRAVEL,15,48,10,GRASS,100)
RandomBlock(-3,4,-1,COBBLESTONE,30,STONE,20,GRAVEL,15,48,10,GRASS,100)
RandomBlock(-3,4,0,COBBLESTONE,30,STONE,20,GRAVEL,15,48,10,GRASS,100)
RandomBlock(-3,4,1,COBBLESTONE,30,STONE,20,GRAVEL,15,48,10,GRASS,100)
RandomBlock(-3,4,2,COBBLESTONE,30,STONE,20,GRAVEL,15,48,10,GRASS,100)
RandomBlock(-3,5,-2,COBBLESTONE,30,STONE,20,GRAVEL,15,48,10,GRASS,100)
RandomBlock(-3,5,-1,COBBLESTONE,30,STONE,20,GRAVEL,15,48,10,GRASS,100)
RandomBlock(-3,5,0,COBBLESTONE,30,STONE,20,GRAVEL,15,48,10,GRASS,100)
RandomBlock(-3,5,1,COBBLESTONE,30,STONE,20,GRAVEL,15,48,10,GRASS,100)
RandomBlock(-3,5,2,COBBLESTONE,30,STONE,20,GRAVEL,15,48,10,GRASS,100)
RandomBlock(-2,-5,-7,COBBLESTONE,30,STONE,20,GRAVEL,15,48,10,GRASS,100)
RandomBlock(-2,-5,-6,COBBLESTONE,30,STONE,20,GRAVEL,15,48,10,GRASS,100)
RandomBlock(-2,-5,-5,COBBLESTONE,30,STONE,20,GRAVEL,15,48,10,GRASS,100)
RandomBlock(-2,-5,-4,COBBLESTONE,30,STONE,20,GRAVEL,15,48,10,GRASS,100)
RandomBlock(-2,-5,-3,COBBLESTONE,30,STONE,20,GRAVEL,15,48,10,GRASS,100)
RandomBlock(-2,-5,-2,COBBLESTONE,30,STONE,20,GRAVEL,15,48,10,GRASS,100)
RandomBlock(-2,-5,-1,COBBLESTONE,30,STONE,20,GRAVEL,15,48,10,GRASS,100)
RandomBlock(-2,-5,0,COBBLESTONE,30,STONE,20,GRAVEL,15,48,10,GRASS,100)
RandomBlock(-2,-5,1,COBBLESTONE,30,STONE,20,GRAVEL,15,48,10,GRASS,100)
RandomBlock(-2,-5,2,COBBLESTONE,30,STONE,20,GRAVEL,15,48,10,GRASS,100)
RandomBlock(-2,-5,3,COBBLESTONE,30,STONE,20,GRAVEL,15,48,10,GRASS,100)
RandomBlock(-2,-5,4,COBBLESTONE,30,STONE,20,GRAVEL,15,48,10,GRASS,100)
RandomBlock(-2,-5,5,COBBLESTONE,30,STONE,20,GRAVEL,15,48,10,GRASS,100)
RandomBlock(-2,-5,6,COBBLESTONE,30,STONE,20,GRAVEL,15,48,10,GRASS,100)
RandomBlock(-2,-5,7,COBBLESTONE,30,STONE,20,GRAVEL,15,48,10,GRASS,100)
RandomBlock(-2,-4,-7,COBBLESTONE,30,STONE,20,GRAVEL,15,48,10,GRASS,100)
RandomBlock(-2,-4,-6,COBBLESTONE,30,STONE,20,GRAVEL,15,48,10,GRASS,100)
RandomBlock(-2,-4,-5,COBBLESTONE,30,STONE,20,GRAVEL,15,48,10,GRASS,100)
RandomBlock(-2,-4,-4,COBBLESTONE,30,STONE,20,GRAVEL,15,48,10,GRASS,100)
RandomBlock(-2,-4,-3,COBBLESTONE,30,STONE,20,GRAVEL,15,48,10,GRASS,100)
RandomBlock(-2,-4,-2,COBBLESTONE,30,STONE,20,GRAVEL,15,48,10,GRASS,100)
RandomBlock(-2,-4,-1,COBBLESTONE,30,STONE,20,GRAVEL,15,48,10,GRASS,100)
RandomBlock(-2,-4,0,COBBLESTONE,30,STONE,20,GRAVEL,15,48,10,GRASS,100)
RandomBlock(-2,-4,1,COBBLESTONE,30,STONE,20,GRAVEL,15,48,10,GRASS,100)
RandomBlock(-2,-4,2,COBBLESTONE,30,STONE,20,GRAVEL,15,48,10,GRASS,100)
RandomBlock(-2,-4,3,COBBLESTONE,30,STONE,20,GRAVEL,15,48,10,GRASS,100)
RandomBlock(-2,-4,4,COBBLESTONE,30,STONE,20,GRAVEL,15,48,10,GRASS,100)
RandomBlock(-2,-4,5,COBBLESTONE,30,STONE,20,GRAVEL,15,48,10,GRASS,100)
RandomBlock(-2,-4,6,COBBLESTONE,30,STONE,20,GRAVEL,15,48,10,GRASS,100)
RandomBlock(-2,-4,7,COBBLESTONE,30,STONE,20,GRAVEL,15,48,10,GRASS,100)
RandomBlock(-2,-3,-7,COBBLESTONE,30,STONE,20,GRAVEL,15,48,10,GRASS,100)
RandomBlock(-2,-3,-6,COBBLESTONE,30,STONE,20,GRAVEL,15,48,10,GRASS,100)
RandomBlock(-2,-3,-5,COBBLESTONE,30,STONE,20,GRAVEL,15,48,10,GRASS,100)
RandomBlock(-2,-3,-4,COBBLESTONE,30,STONE,20,GRAVEL,15,48,10,GRASS,100)
RandomBlock(-2,-3,-3,COBBLESTONE,30,STONE,20,GRAVEL,15,48,10,GRASS,100)
RandomBlock(-2,-3,-2,COBBLESTONE,30,STONE,20,GRAVEL,15,48,10,GRASS,100)
RandomBlock(-2,-3,-1,COBBLESTONE,30,STONE,20,GRAVEL,15,48,10,GRASS,100)
RandomBlock(-2,-3,0,COBBLESTONE,30,STONE,20,GRAVEL,15,48,10,GRASS,100)
RandomBlock(-2,-3,1,COBBLESTONE,30,STONE,20,GRAVEL,15,48,10,GRASS,100)
RandomBlock(-2,-3,2,COBBLESTONE,30,STONE,20,GRAVEL,15,48,10,GRASS,100)
RandomBlock(-2,-3,3,COBBLESTONE,30,STONE,20,GRAVEL,15,48,10,GRASS,100)
RandomBlock(-2,-3,4,COBBLESTONE,30,STONE,20,GRAVEL,15,48,10,GRASS,100)
RandomBlock(-2,-3,5,COBBLESTONE,30,STONE,20,GRAVEL,15,48,10,GRASS,100)
RandomBlock(-2,-3,6,COBBLESTONE,30,STONE,20,GRAVEL,15,48,10,GRASS,100)
RandomBlock(-2,-3,7,COBBLESTONE,30,STONE,20,GRAVEL,15,48,10,GRASS,100)
RandomBlock(-2,-2,-7,COBBLESTONE,30,STONE,20,GRAVEL,15,48,10,GRASS,100)
RandomBlock(-2,-2,-6,COBBLESTONE,30,STONE,20,GRAVEL,15,48,10,GRASS,100)
RandomBlock(-2,-2,-5,COBBLESTONE,30,STONE,20,GRAVEL,15,48,10,GRASS,100)
RandomBlock(-2,-2,-4,COBBLESTONE,30,STONE,20,GRAVEL,15,48,10,GRASS,100)
RandomBlock(-2,-2,-3,COBBLESTONE,30,STONE,20,GRAVEL,15,48,10,GRASS,100)
RandomBlock(-2,-2,-2,COBBLESTONE,30,STONE,20,GRAVEL,15,48,10,GRASS,100)
RandomBlock(-2,-2,-1,COBBLESTONE,30,STONE,20,GRAVEL,15,48,10,GRASS,100)
RandomBlock(-2,-2,0,COBBLESTONE,30,STONE,20,GRAVEL,15,48,10,GRASS,100)
RandomBlock(-2,-2,1,COBBLESTONE,30,STONE,20,GRAVEL,15,48,10,GRASS,100)
RandomBlock(-2,-2,2,COBBLESTONE,30,STONE,20,GRAVEL,15,48,10,GRASS,100)
RandomBlock(-2,-2,3,COBBLESTONE,30,STONE,20,GRAVEL,15,48,10,GRASS,100)
RandomBlock(-2,-2,4,COBBLESTONE,30,STONE,20,GRAVEL,15,48,10,GRASS,100)
RandomBlock(-2,-2,5,COBBLESTONE,30,STONE,20,GRAVEL,15,48,10,GRASS,100)
RandomBlock(-2,-2,6,COBBLESTONE,30,STONE,20,GRAVEL,15,48,10,GRASS,100)
RandomBlock(-2,-2,7,COBBLESTONE,30,STONE,20,GRAVEL,15,48,10,GRASS,100)
RandomBlock(-2,-1,-7,COBBLESTONE,30,STONE,20,GRAVEL,15,48,10,GRASS,100)
RandomBlock(-2,-1,-6,COBBLESTONE,30,STONE,20,GRAVEL,15,48,10,GRASS,100)
RandomBlock(-2,-1,-5,COBBLESTONE,30,STONE,20,GRAVEL,15,48,10,GRASS,100)
RandomBlock(-2,-1,-4,COBBLESTONE,30,STONE,20,GRAVEL,15,48,10,GRASS,100)
RandomBlock(-2,-1,-3,COBBLESTONE,30,STONE,20,GRAVEL,15,48,10,GRASS,100)
RandomBlock(-2,-1,-2,COBBLESTONE,30,STONE,20,GRAVEL,15,48,10,GRASS,100)
RandomBlock(-2,-1,-1,COBBLESTONE,30,STONE,20,GRAVEL,15,48,10,GRASS,100)
RandomBlock(-2,-1,0,COBBLESTONE,30,STONE,20,GRAVEL,15,48,10,GRASS,100)
RandomBlock(-2,-1,1,COBBLESTONE,30,STONE,20,GRAVEL,15,48,10,GRASS,100)
RandomBlock(-2,-1,2,COBBLESTONE,30,STONE,20,GRAVEL,15,48,10,GRASS,100)
RandomBlock(-2,-1,3,COBBLESTONE,30,STONE,20,GRAVEL,15,48,10,GRASS,100)
RandomBlock(-2,-1,4,COBBLESTONE,30,STONE,20,GRAVEL,15,48,10,GRASS,100)
RandomBlock(-2,-1,5,COBBLESTONE,30,STONE,20,GRAVEL,15,48,10,GRASS,100)
RandomBlock(-2,-1,6,COBBLESTONE,30,STONE,20,GRAVEL,15,48,10,GRASS,100)
RandomBlock(-2,-1,7,COBBLESTONE,30,STONE,20,GRAVEL,15,48,10,GRASS,100)
RandomBlock(-2,0,-7,COBBLESTONE,30,STONE,20,GRAVEL,15,48,10,GRASS,100)
RandomBlock(-2,0,-6,COBBLESTONE,30,STONE,20,GRAVEL,15,48,10,GRASS,100)
RandomBlock(-2,0,-5,COBBLESTONE,30,STONE,20,GRAVEL,15,48,10,GRASS,100)
RandomBlock(-2,0,-4,COBBLESTONE,30,STONE,20,GRAVEL,15,48,10,GRASS,100)
RandomBlock(-2,0,-3,COBBLESTONE,30,STONE,20,GRAVEL,15,48,10,GRASS,100)
RandomBlock(-2,0,-2,COBBLESTONE,30,STONE,20,GRAVEL,15,48,10,GRASS,100)
RandomBlock(-2,0,-1,COBBLESTONE,30,STONE,20,GRAVEL,15,48,10,GRASS,100)
RandomBlock(-2,0,0,COBBLESTONE,30,STONE,20,GRAVEL,15,48,10,GRASS,100)
RandomBlock(-2,0,1,COBBLESTONE,30,STONE,20,GRAVEL,15,48,10,GRASS,100)
RandomBlock(-2,0,2,COBBLESTONE,30,STONE,20,GRAVEL,15,48,10,GRASS,100)
RandomBlock(-2,0,3,COBBLESTONE,30,STONE,20,GRAVEL,15,48,10,GRASS,100)
RandomBlock(-2,0,4,COBBLESTONE,30,STONE,20,GRAVEL,15,48,10,GRASS,100)
RandomBlock(-2,0,5,COBBLESTONE,30,STONE,20,GRAVEL,15,48,10,GRASS,100)
RandomBlock(-2,0,6,COBBLESTONE,30,STONE,20,GRAVEL,15,48,10,GRASS,100)
RandomBlock(-2,0,7,COBBLESTONE,30,STONE,20,GRAVEL,15,48,10,GRASS,100)
RandomBlock(-2,1,-7,COBBLESTONE,30,STONE,20,GRAVEL,15,48,10,GRASS,100)
RandomBlock(-2,1,-6,COBBLESTONE,30,STONE,20,GRAVEL,15,48,10,GRASS,100)
RandomBlock(-2,1,-5,COBBLESTONE,30,STONE,20,GRAVEL,15,48,10,GRASS,100)
RandomBlock(-2,1,-4,COBBLESTONE,30,STONE,20,GRAVEL,15,48,10,GRASS,100)
RandomBlock(-2,1,-3,COBBLESTONE,30,STONE,20,GRAVEL,15,48,10,GRASS,100)
RandomBlock(-2,1,-2,COBBLESTONE,30,STONE,20,GRAVEL,15,48,10,GRASS,100)
RandomBlock(-2,1,-1,COBBLESTONE,30,STONE,20,GRAVEL,15,48,10,GRASS,100)
RandomBlock(-2,1,0,COBBLESTONE,30,STONE,20,GRAVEL,15,48,10,GRASS,100)
RandomBlock(-2,1,1,COBBLESTONE,30,STONE,20,GRAVEL,15,48,10,GRASS,100)
RandomBlock(-2,1,2,COBBLESTONE,30,STONE,20,GRAVEL,15,48,10,GRASS,100)
RandomBlock(-2,1,3,COBBLESTONE,30,STONE,20,GRAVEL,15,48,10,GRASS,100)
RandomBlock(-2,1,4,COBBLESTONE,30,STONE,20,GRAVEL,15,48,10,GRASS,100)
RandomBlock(-2,1,5,COBBLESTONE,30,STONE,20,GRAVEL,15,48,10,GRASS,100)
RandomBlock(-2,1,6,COBBLESTONE,30,STONE,20,GRAVEL,15,48,10,GRASS,100)
RandomBlock(-2,1,7,COBBLESTONE,30,STONE,20,GRAVEL,15,48,10,GRASS,100)
RandomBlock(-2,2,-7,COBBLESTONE,30,STONE,20,GRAVEL,15,48,10,GRASS,100)
RandomBlock(-2,2,-6,COBBLESTONE,30,STONE,20,GRAVEL,15,48,10,GRASS,100)
RandomBlock(-2,2,-5,COBBLESTONE,30,STONE,20,GRAVEL,15,48,10,GRASS,100)
RandomBlock(-2,2,-4,COBBLESTONE,30,STONE,20,GRAVEL,15,48,10,GRASS,100)
RandomBlock(-2,2,-3,COBBLESTONE,30,STONE,20,GRAVEL,15,48,10,GRASS,100)
RandomBlock(-2,2,-2,COBBLESTONE,30,STONE,20,GRAVEL,15,48,10,GRASS,100)
RandomBlock(-2,2,-1,COBBLESTONE,30,STONE,20,GRAVEL,15,48,10,GRASS,100)
RandomBlock(-2,2,0,COBBLESTONE,30,STONE,20,GRAVEL,15,48,10,GRASS,100)
RandomBlock(-2,2,1,COBBLESTONE,30,STONE,20,GRAVEL,15,48,10,GRASS,100)
RandomBlock(-2,2,2,COBBLESTONE,30,STONE,20,GRAVEL,15,48,10,GRASS,100)
RandomBlock(-2,2,3,COBBLESTONE,30,STONE,20,GRAVEL,15,48,10,GRASS,100)
RandomBlock(-2,2,4,COBBLESTONE,30,STONE,20,GRAVEL,15,48,10,GRASS,100)
RandomBlock(-2,2,5,COBBLESTONE,30,STONE,20,GRAVEL,15,48,10,GRASS,100)
RandomBlock(-2,2,6,COBBLESTONE,30,STONE,20,GRAVEL,15,48,10,GRASS,100)
RandomBlock(-2,2,7,COBBLESTONE,30,STONE,20,GRAVEL,15,48,10,GRASS,100)
RandomBlock(-2,3,-7,COBBLESTONE,30,STONE,20,GRAVEL,15,48,10,GRASS,100)
RandomBlock(-2,3,-6,COBBLESTONE,30,STONE,20,GRAVEL,15,48,10,GRASS,100)
RandomBlock(-2,3,-5,COBBLESTONE,30,STONE,20,GRAVEL,15,48,10,GRASS,100)
RandomBlock(-2,3,-4,COBBLESTONE,30,STONE,20,GRAVEL,15,48,10,GRASS,100)
RandomBlock(-2,3,-3,COBBLESTONE,30,STONE,20,GRAVEL,15,48,10,GRASS,100)
RandomBlock(-2,3,-2,COBBLESTONE,30,STONE,20,GRAVEL,15,48,10,GRASS,100)
RandomBlock(-2,3,-1,COBBLESTONE,30,STONE,20,GRAVEL,15,48,10,GRASS,100)
RandomBlock(-2,3,0,COBBLESTONE,30,STONE,20,GRAVEL,15,48,10,GRASS,100)
RandomBlock(-2,3,1,COBBLESTONE,30,STONE,20,GRAVEL,15,48,10,GRASS,100)
RandomBlock(-2,3,2,COBBLESTONE,30,STONE,20,GRAVEL,15,48,10,GRASS,100)
RandomBlock(-2,3,3,COBBLESTONE,30,STONE,20,GRAVEL,15,48,10,GRASS,100)
RandomBlock(-2,3,4,COBBLESTONE,30,STONE,20,GRAVEL,15,48,10,GRASS,100)
RandomBlock(-2,3,5,COBBLESTONE,30,STONE,20,GRAVEL,15,48,10,GRASS,100)
RandomBlock(-2,3,6,COBBLESTONE,30,STONE,20,GRAVEL,15,48,10,GRASS,100)
RandomBlock(-2,3,7,COBBLESTONE,30,STONE,20,GRAVEL,15,48,10,GRASS,100)
RandomBlock(-2,4,-7,COBBLESTONE,30,STONE,20,GRAVEL,15,48,10,GRASS,100)
RandomBlock(-2,4,-6,COBBLESTONE,30,STONE,20,GRAVEL,15,48,10,GRASS,100)
RandomBlock(-2,4,-5,COBBLESTONE,30,STONE,20,GRAVEL,15,48,10,GRASS,100)
RandomBlock(-2,4,-4,COBBLESTONE,30,STONE,20,GRAVEL,15,48,10,GRASS,100)
RandomBlock(-2,4,-3,COBBLESTONE,30,STONE,20,GRAVEL,15,48,10,GRASS,100)
RandomBlock(-2,4,-2,COBBLESTONE,30,STONE,20,GRAVEL,15,48,10,GRASS,100)
RandomBlock(-2,4,-1,COBBLESTONE,30,STONE,20,GRAVEL,15,48,10,GRASS,100)
RandomBlock(-2,4,0,COBBLESTONE,30,STONE,20,GRAVEL,15,48,10,GRASS,100)
RandomBlock(-2,4,1,COBBLESTONE,30,STONE,20,GRAVEL,15,48,10,GRASS,100)
RandomBlock(-2,4,2,COBBLESTONE,30,STONE,20,GRAVEL,15,48,10,GRASS,100)
RandomBlock(-2,4,3,COBBLESTONE,30,STONE,20,GRAVEL,15,48,10,GRASS,100)
RandomBlock(-2,4,4,COBBLESTONE,30,STONE,20,GRAVEL,15,48,10,GRASS,100)
RandomBlock(-2,4,5,COBBLESTONE,30,STONE,20,GRAVEL,15,48,10,GRASS,100)
RandomBlock(-2,4,6,COBBLESTONE,30,STONE,20,GRAVEL,15,48,10,GRASS,100)
RandomBlock(-2,4,7,COBBLESTONE,30,STONE,20,GRAVEL,15,48,10,GRASS,100)
RandomBlock(-2,5,-7,COBBLESTONE,30,STONE,20,GRAVEL,15,48,10,GRASS,100)
RandomBlock(-2,5,-6,COBBLESTONE,30,STONE,20,GRAVEL,15,48,10,GRASS,100)
RandomBlock(-2,5,-5,COBBLESTONE,30,STONE,20,GRAVEL,15,48,10,GRASS,100)
RandomBlock(-2,5,-4,COBBLESTONE,30,STONE,20,GRAVEL,15,48,10,GRASS,100)
RandomBlock(-2,5,-3,COBBLESTONE,30,STONE,20,GRAVEL,15,48,10,GRASS,100)
RandomBlock(-2,5,-2,COBBLESTONE,30,STONE,20,GRAVEL,15,48,10,GRASS,100)
RandomBlock(-2,5,-1,COBBLESTONE,30,STONE,20,GRAVEL,15,48,10,GRASS,100)
RandomBlock(-2,5,0,COBBLESTONE,30,STONE,20,GRAVEL,15,48,10,GRASS,100)
RandomBlock(-2,5,1,COBBLESTONE,30,STONE,20,GRAVEL,15,48,10,GRASS,100)
RandomBlock(-2,5,2,COBBLESTONE,30,STONE,20,GRAVEL,15,48,10,GRASS,100)
RandomBlock(-2,5,3,COBBLESTONE,30,STONE,20,GRAVEL,15,48,10,GRASS,100)
RandomBlock(-2,5,4,COBBLESTONE,30,STONE,20,GRAVEL,15,48,10,GRASS,100)
RandomBlock(-2,5,5,COBBLESTONE,30,STONE,20,GRAVEL,15,48,10,GRASS,100)
RandomBlock(-2,5,6,COBBLESTONE,30,STONE,20,GRAVEL,15,48,10,GRASS,100)
RandomBlock(-2,5,7,COBBLESTONE,30,STONE,20,GRAVEL,15,48,10,GRASS,100)
RandomBlock(-1,-5,-7,COBBLESTONE,30,STONE,20,GRAVEL,15,48,10,GRASS,100)
RandomBlock(-1,-5,-6,COBBLESTONE,30,STONE,20,GRAVEL,15,48,10,GRASS,100)
RandomBlock(-1,-5,-5,COBBLESTONE,30,STONE,20,GRAVEL,15,48,10,GRASS,100)
RandomBlock(-1,-5,-4,COBBLESTONE,30,STONE,20,GRAVEL,15,48,10,GRASS,100)
RandomBlock(-1,-5,-3,COBBLESTONE,30,STONE,20,GRAVEL,15,48,10,GRASS,100)
RandomBlock(-1,-5,-2,COBBLESTONE,30,STONE,20,GRAVEL,15,48,10,GRASS,100)
RandomBlock(-1,-5,-1,COBBLESTONE,30,STONE,20,GRAVEL,15,48,10,GRASS,100)
RandomBlock(-1,-5,0,COBBLESTONE,30,STONE,20,GRAVEL,15,48,10,GRASS,100)
RandomBlock(-1,-5,1,COBBLESTONE,30,STONE,20,GRAVEL,15,48,10,GRASS,100)
RandomBlock(-1,-5,2,COBBLESTONE,30,STONE,20,GRAVEL,15,48,10,GRASS,100)
RandomBlock(-1,-5,3,COBBLESTONE,30,STONE,20,GRAVEL,15,48,10,GRASS,100)
RandomBlock(-1,-5,4,COBBLESTONE,30,STONE,20,GRAVEL,15,48,10,GRASS,100)
RandomBlock(-1,-5,5,COBBLESTONE,30,STONE,20,GRAVEL,15,48,10,GRASS,100)
RandomBlock(-1,-5,6,COBBLESTONE,30,STONE,20,GRAVEL,15,48,10,GRASS,100)
RandomBlock(-1,-5,7,COBBLESTONE,30,STONE,20,GRAVEL,15,48,10,GRASS,100)
RandomBlock(-1,-4,-7,COBBLESTONE,30,STONE,20,GRAVEL,15,48,10,GRASS,100)
RandomBlock(-1,-4,-6,COBBLESTONE,30,STONE,20,GRAVEL,15,48,10,GRASS,100)
RandomBlock(-1,-4,-5,COBBLESTONE,30,STONE,20,GRAVEL,15,48,10,GRASS,100)
RandomBlock(-1,-4,-4,COBBLESTONE,30,STONE,20,GRAVEL,15,48,10,GRASS,100)
RandomBlock(-1,-4,-3,COBBLESTONE,30,STONE,20,GRAVEL,15,48,10,GRASS,100)
RandomBlock(-1,-4,-2,COBBLESTONE,30,STONE,20,GRAVEL,15,48,10,GRASS,100)
RandomBlock(-1,-4,-1,COBBLESTONE,30,STONE,20,GRAVEL,15,48,10,GRASS,100)
RandomBlock(-1,-4,0,COBBLESTONE,30,STONE,20,GRAVEL,15,48,10,GRASS,100)
RandomBlock(-1,-4,1,COBBLESTONE,30,STONE,20,GRAVEL,15,48,10,GRASS,100)
RandomBlock(-1,-4,2,COBBLESTONE,30,STONE,20,GRAVEL,15,48,10,GRASS,100)
RandomBlock(-1,-4,3,COBBLESTONE,30,STONE,20,GRAVEL,15,48,10,GRASS,100)
RandomBlock(-1,-4,4,COBBLESTONE,30,STONE,20,GRAVEL,15,48,10,GRASS,100)
RandomBlock(-1,-4,5,COBBLESTONE,30,STONE,20,GRAVEL,15,48,10,GRASS,100)
RandomBlock(-1,-4,6,COBBLESTONE,30,STONE,20,GRAVEL,15,48,10,GRASS,100)
RandomBlock(-1,-4,7,COBBLESTONE,30,STONE,20,GRAVEL,15,48,10,GRASS,100)
RandomBlock(-1,-3,-7,COBBLESTONE,30,STONE,20,GRAVEL,15,48,10,GRASS,100)
RandomBlock(-1,-3,-6,COBBLESTONE,30,STONE,20,GRAVEL,15,48,10,GRASS,100)
RandomBlock(-1,-3,-5,COBBLESTONE,30,STONE,20,GRAVEL,15,48,10,GRASS,100)
RandomBlock(-1,-3,-4,COBBLESTONE,30,STONE,20,GRAVEL,15,48,10,GRASS,100)
RandomBlock(-1,-3,-3,COBBLESTONE,30,STONE,20,GRAVEL,15,48,10,GRASS,100)
RandomBlock(-1,-3,-2,COBBLESTONE,30,STONE,20,GRAVEL,15,48,10,GRASS,100)
RandomBlock(-1,-3,-1,COBBLESTONE,30,STONE,20,GRAVEL,15,48,10,GRASS,100)
RandomBlock(-1,-3,0,COBBLESTONE,30,STONE,20,GRAVEL,15,48,10,GRASS,100)
RandomBlock(-1,-3,1,COBBLESTONE,30,STONE,20,GRAVEL,15,48,10,GRASS,100)
RandomBlock(-1,-3,2,COBBLESTONE,30,STONE,20,GRAVEL,15,48,10,GRASS,100)
RandomBlock(-1,-3,3,COBBLESTONE,30,STONE,20,GRAVEL,15,48,10,GRASS,100)
RandomBlock(-1,-3,4,COBBLESTONE,30,STONE,20,GRAVEL,15,48,10,GRASS,100)
RandomBlock(-1,-3,5,COBBLESTONE,30,STONE,20,GRAVEL,15,48,10,GRASS,100)
RandomBlock(-1,-3,6,COBBLESTONE,30,STONE,20,GRAVEL,15,48,10,GRASS,100)
RandomBlock(-1,-3,7,COBBLESTONE,30,STONE,20,GRAVEL,15,48,10,GRASS,100)
RandomBlock(-1,-2,-7,COBBLESTONE,30,STONE,20,GRAVEL,15,48,10,GRASS,100)
RandomBlock(-1,-2,-6,COBBLESTONE,30,STONE,20,GRAVEL,15,48,10,GRASS,100)
RandomBlock(-1,-2,-5,COBBLESTONE,30,STONE,20,GRAVEL,15,48,10,GRASS,100)
RandomBlock(-1,-2,-4,COBBLESTONE,30,STONE,20,GRAVEL,15,48,10,GRASS,100)
RandomBlock(-1,-2,-3,COBBLESTONE,30,STONE,20,GRAVEL,15,48,10,GRASS,100)
RandomBlock(-1,-2,-2,COBBLESTONE,30,STONE,20,GRAVEL,15,48,10,GRASS,100)
RandomBlock(-1,-2,-1,COBBLESTONE,30,STONE,20,GRAVEL,15,48,10,GRASS,100)
RandomBlock(-1,-2,0,COBBLESTONE,30,STONE,20,GRAVEL,15,48,10,GRASS,100)
RandomBlock(-1,-2,1,COBBLESTONE,30,STONE,20,GRAVEL,15,48,10,GRASS,100)
RandomBlock(-1,-2,2,COBBLESTONE,30,STONE,20,GRAVEL,15,48,10,GRASS,100)
RandomBlock(-1,-2,3,COBBLESTONE,30,STONE,20,GRAVEL,15,48,10,GRASS,100)
RandomBlock(-1,-2,4,COBBLESTONE,30,STONE,20,GRAVEL,15,48,10,GRASS,100)
RandomBlock(-1,-2,5,COBBLESTONE,30,STONE,20,GRAVEL,15,48,10,GRASS,100)
RandomBlock(-1,-2,6,COBBLESTONE,30,STONE,20,GRAVEL,15,48,10,GRASS,100)
RandomBlock(-1,-2,7,COBBLESTONE,30,STONE,20,GRAVEL,15,48,10,GRASS,100)
RandomBlock(-1,-1,-7,COBBLESTONE,30,STONE,20,GRAVEL,15,48,10,GRASS,100)
RandomBlock(-1,-1,-6,COBBLESTONE,30,STONE,20,GRAVEL,15,48,10,GRASS,100)
RandomBlock(-1,-1,-5,COBBLESTONE,30,STONE,20,GRAVEL,15,48,10,GRASS,100)
RandomBlock(-1,-1,-4,COBBLESTONE,30,STONE,20,GRAVEL,15,48,10,GRASS,100)
RandomBlock(-1,-1,-3,COBBLESTONE,30,STONE,20,GRAVEL,15,48,10,GRASS,100)
RandomBlock(-1,-1,-2,COBBLESTONE,30,STONE,20,GRAVEL,15,48,10,GRASS,100)
RandomBlock(-1,-1,-1,COBBLESTONE,30,STONE,20,GRAVEL,15,48,10,GRASS,100)
RandomBlock(-1,-1,0,COBBLESTONE,30,STONE,20,GRAVEL,15,48,10,GRASS,100)
RandomBlock(-1,-1,1,COBBLESTONE,30,STONE,20,GRAVEL,15,48,10,GRASS,100)
RandomBlock(-1,-1,2,COBBLESTONE,30,STONE,20,GRAVEL,15,48,10,GRASS,100)
RandomBlock(-1,-1,3,COBBLESTONE,30,STONE,20,GRAVEL,15,48,10,GRASS,100)
RandomBlock(-1,-1,4,COBBLESTONE,30,STONE,20,GRAVEL,15,48,10,GRASS,100)
RandomBlock(-1,-1,5,COBBLESTONE,30,STONE,20,GRAVEL,15,48,10,GRASS,100)
RandomBlock(-1,-1,6,COBBLESTONE,30,STONE,20,GRAVEL,15,48,10,GRASS,100)
RandomBlock(-1,-1,7,COBBLESTONE,30,STONE,20,GRAVEL,15,48,10,GRASS,100)
RandomBlock(-1,0,-7,COBBLESTONE,30,STONE,20,GRAVEL,15,48,10,GRASS,100)
RandomBlock(-1,0,-6,COBBLESTONE,30,STONE,20,GRAVEL,15,48,10,GRASS,100)
RandomBlock(-1,0,-5,COBBLESTONE,30,STONE,20,GRAVEL,15,48,10,GRASS,100)
RandomBlock(-1,0,-4,COBBLESTONE,30,STONE,20,GRAVEL,15,48,10,GRASS,100)
RandomBlock(-1,0,-3,COBBLESTONE,30,STONE,20,GRAVEL,15,48,10,GRASS,100)
RandomBlock(-1,0,-2,COBBLESTONE,30,STONE,20,GRAVEL,15,48,10,GRASS,100)
RandomBlock(-1,0,-1,COBBLESTONE,30,STONE,20,GRAVEL,15,48,10,GRASS,100)
RandomBlock(-1,0,0,COBBLESTONE,30,STONE,20,GRAVEL,15,48,10,GRASS,100)
RandomBlock(-1,0,1,COBBLESTONE,30,STONE,20,GRAVEL,15,48,10,GRASS,100)
RandomBlock(-1,0,2,COBBLESTONE,30,STONE,20,GRAVEL,15,48,10,GRASS,100)
RandomBlock(-1,0,3,COBBLESTONE,30,STONE,20,GRAVEL,15,48,10,GRASS,100)
RandomBlock(-1,0,4,COBBLESTONE,30,STONE,20,GRAVEL,15,48,10,GRASS,100)
RandomBlock(-1,0,5,COBBLESTONE,30,STONE,20,GRAVEL,15,48,10,GRASS,100)
RandomBlock(-1,0,6,COBBLESTONE,30,STONE,20,GRAVEL,15,48,10,GRASS,100)
RandomBlock(-1,0,7,COBBLESTONE,30,STONE,20,GRAVEL,15,48,10,GRASS,100)
RandomBlock(-1,1,-7,COBBLESTONE,30,STONE,20,GRAVEL,15,48,10,GRASS,100)
RandomBlock(-1,1,-6,COBBLESTONE,30,STONE,20,GRAVEL,15,48,10,GRASS,100)
RandomBlock(-1,1,-5,COBBLESTONE,30,STONE,20,GRAVEL,15,48,10,GRASS,100)
RandomBlock(-1,1,-4,COBBLESTONE,30,STONE,20,GRAVEL,15,48,10,GRASS,100)
RandomBlock(-1,1,-3,COBBLESTONE,30,STONE,20,GRAVEL,15,48,10,GRASS,100)
RandomBlock(-1,1,-2,COBBLESTONE,30,STONE,20,GRAVEL,15,48,10,GRASS,100)
RandomBlock(-1,1,-1,COBBLESTONE,30,STONE,20,GRAVEL,15,48,10,GRASS,100)
RandomBlock(-1,1,0,COBBLESTONE,30,STONE,20,GRAVEL,15,48,10,GRASS,100)
RandomBlock(-1,1,1,COBBLESTONE,30,STONE,20,GRAVEL,15,48,10,GRASS,100)
RandomBlock(-1,1,2,COBBLESTONE,30,STONE,20,GRAVEL,15,48,10,GRASS,100)
RandomBlock(-1,1,3,COBBLESTONE,30,STONE,20,GRAVEL,15,48,10,GRASS,100)
RandomBlock(-1,1,4,COBBLESTONE,30,STONE,20,GRAVEL,15,48,10,GRASS,100)
RandomBlock(-1,1,5,COBBLESTONE,30,STONE,20,GRAVEL,15,48,10,GRASS,100)
RandomBlock(-1,1,6,COBBLESTONE,30,STONE,20,GRAVEL,15,48,10,GRASS,100)
RandomBlock(-1,1,7,COBBLESTONE,30,STONE,20,GRAVEL,15,48,10,GRASS,100)
RandomBlock(-1,2,-7,COBBLESTONE,30,STONE,20,GRAVEL,15,48,10,GRASS,100)
RandomBlock(-1,2,-6,COBBLESTONE,30,STONE,20,GRAVEL,15,48,10,GRASS,100)
RandomBlock(-1,2,-5,COBBLESTONE,30,STONE,20,GRAVEL,15,48,10,GRASS,100)
RandomBlock(-1,2,-4,COBBLESTONE,30,STONE,20,GRAVEL,15,48,10,GRASS,100)
RandomBlock(-1,2,-3,COBBLESTONE,30,STONE,20,GRAVEL,15,48,10,GRASS,100)
RandomBlock(-1,2,-2,COBBLESTONE,30,STONE,20,GRAVEL,15,48,10,GRASS,100)
RandomBlock(-1,2,-1,COBBLESTONE,30,STONE,20,GRAVEL,15,48,10,GRASS,100)
RandomBlock(-1,2,0,COBBLESTONE,30,STONE,20,GRAVEL,15,48,10,GRASS,100)
RandomBlock(-1,2,1,COBBLESTONE,30,STONE,20,GRAVEL,15,48,10,GRASS,100)
RandomBlock(-1,2,2,COBBLESTONE,30,STONE,20,GRAVEL,15,48,10,GRASS,100)
RandomBlock(-1,2,3,COBBLESTONE,30,STONE,20,GRAVEL,15,48,10,GRASS,100)
RandomBlock(-1,2,4,COBBLESTONE,30,STONE,20,GRAVEL,15,48,10,GRASS,100)
RandomBlock(-1,2,5,COBBLESTONE,30,STONE,20,GRAVEL,15,48,10,GRASS,100)
RandomBlock(-1,2,6,COBBLESTONE,30,STONE,20,GRAVEL,15,48,10,GRASS,100)
RandomBlock(-1,2,7,COBBLESTONE,30,STONE,20,GRAVEL,15,48,10,GRASS,100)
RandomBlock(-1,3,-7,COBBLESTONE,30,STONE,20,GRAVEL,15,48,10,GRASS,100)
RandomBlock(-1,3,-6,COBBLESTONE,30,STONE,20,GRAVEL,15,48,10,GRASS,100)
RandomBlock(-1,3,-5,COBBLESTONE,30,STONE,20,GRAVEL,15,48,10,GRASS,100)
RandomBlock(-1,3,-4,COBBLESTONE,30,STONE,20,GRAVEL,15,48,10,GRASS,100)
RandomBlock(-1,3,-3,COBBLESTONE,30,STONE,20,GRAVEL,15,48,10,GRASS,100)
RandomBlock(-1,3,-2,COBBLESTONE,30,STONE,20,GRAVEL,15,48,10,GRASS,100)
RandomBlock(-1,3,-1,COBBLESTONE,30,STONE,20,GRAVEL,15,48,10,GRASS,100)
RandomBlock(-1,3,0,COBBLESTONE,30,STONE,20,GRAVEL,15,48,10,GRASS,100)
RandomBlock(-1,3,1,COBBLESTONE,30,STONE,20,GRAVEL,15,48,10,GRASS,100)
RandomBlock(-1,3,2,COBBLESTONE,30,STONE,20,GRAVEL,15,48,10,GRASS,100)
RandomBlock(-1,3,3,COBBLESTONE,30,STONE,20,GRAVEL,15,48,10,GRASS,100)
RandomBlock(-1,3,4,COBBLESTONE,30,STONE,20,GRAVEL,15,48,10,GRASS,100)
RandomBlock(-1,3,5,COBBLESTONE,30,STONE,20,GRAVEL,15,48,10,GRASS,100)
RandomBlock(-1,3,6,COBBLESTONE,30,STONE,20,GRAVEL,15,48,10,GRASS,100)
RandomBlock(-1,3,7,COBBLESTONE,30,STONE,20,GRAVEL,15,48,10,GRASS,100)
RandomBlock(-1,4,-7,COBBLESTONE,30,STONE,20,GRAVEL,15,48,10,GRASS,100)
RandomBlock(-1,4,-6,COBBLESTONE,30,STONE,20,GRAVEL,15,48,10,GRASS,100)
RandomBlock(-1,4,-5,COBBLESTONE,30,STONE,20,GRAVEL,15,48,10,GRASS,100)
RandomBlock(-1,4,-4,COBBLESTONE,30,STONE,20,GRAVEL,15,48,10,GRASS,100)
RandomBlock(-1,4,-3,COBBLESTONE,30,STONE,20,GRAVEL,15,48,10,GRASS,100)
RandomBlock(-1,4,-2,COBBLESTONE,30,STONE,20,GRAVEL,15,48,10,GRASS,100)
RandomBlock(-1,4,-1,COBBLESTONE,30,STONE,20,GRAVEL,15,48,10,GRASS,100)
RandomBlock(-1,4,0,COBBLESTONE,30,STONE,20,GRAVEL,15,48,10,GRASS,100)
RandomBlock(-1,4,1,COBBLESTONE,30,STONE,20,GRAVEL,15,48,10,GRASS,100)
RandomBlock(-1,4,2,COBBLESTONE,30,STONE,20,GRAVEL,15,48,10,GRASS,100)
RandomBlock(-1,4,3,COBBLESTONE,30,STONE,20,GRAVEL,15,48,10,GRASS,100)
RandomBlock(-1,4,4,COBBLESTONE,30,STONE,20,GRAVEL,15,48,10,GRASS,100)
RandomBlock(-1,4,5,COBBLESTONE,30,STONE,20,GRAVEL,15,48,10,GRASS,100)
RandomBlock(-1,4,6,COBBLESTONE,30,STONE,20,GRAVEL,15,48,10,GRASS,100)
RandomBlock(-1,4,7,COBBLESTONE,30,STONE,20,GRAVEL,15,48,10,GRASS,100)
RandomBlock(-1,5,-7,COBBLESTONE,30,STONE,20,GRAVEL,15,48,10,GRASS,100)
RandomBlock(-1,5,-6,COBBLESTONE,30,STONE,20,GRAVEL,15,48,10,GRASS,100)
RandomBlock(-1,5,-5,COBBLESTONE,30,STONE,20,GRAVEL,15,48,10,GRASS,100)
RandomBlock(-1,5,-4,COBBLESTONE,30,STONE,20,GRAVEL,15,48,10,GRASS,100)
RandomBlock(-1,5,-3,COBBLESTONE,30,STONE,20,GRAVEL,15,48,10,GRASS,100)
RandomBlock(-1,5,-2,COBBLESTONE,30,STONE,20,GRAVEL,15,48,10,GRASS,100)
RandomBlock(-1,5,-1,COBBLESTONE,30,STONE,20,GRAVEL,15,48,10,GRASS,100)
RandomBlock(-1,5,0,COBBLESTONE,30,STONE,20,GRAVEL,15,48,10,GRASS,100)
RandomBlock(-1,5,1,COBBLESTONE,30,STONE,20,GRAVEL,15,48,10,GRASS,100)
RandomBlock(-1,5,2,COBBLESTONE,30,STONE,20,GRAVEL,15,48,10,GRASS,100)
RandomBlock(-1,5,3,COBBLESTONE,30,STONE,20,GRAVEL,15,48,10,GRASS,100)
RandomBlock(-1,5,4,COBBLESTONE,30,STONE,20,GRAVEL,15,48,10,GRASS,100)
RandomBlock(-1,5,5,COBBLESTONE,30,STONE,20,GRAVEL,15,48,10,GRASS,100)
RandomBlock(-1,5,6,COBBLESTONE,30,STONE,20,GRAVEL,15,48,10,GRASS,100)
RandomBlock(-1,5,7,COBBLESTONE,30,STONE,20,GRAVEL,15,48,10,GRASS,100)
RandomBlock(0,-5,-7,COBBLESTONE,30,STONE,20,GRAVEL,15,48,10,GRASS,100)
RandomBlock(0,-5,-6,COBBLESTONE,30,STONE,20,GRAVEL,15,48,10,GRASS,100)
RandomBlock(0,-5,-5,COBBLESTONE,30,STONE,20,GRAVEL,15,48,10,GRASS,100)
RandomBlock(0,-5,-4,COBBLESTONE,30,STONE,20,GRAVEL,15,48,10,GRASS,100)
RandomBlock(0,-5,-3,COBBLESTONE,30,STONE,20,GRAVEL,15,48,10,GRASS,100)
RandomBlock(0,-5,-2,COBBLESTONE,30,STONE,20,GRAVEL,15,48,10,GRASS,100)
RandomBlock(0,-5,-1,COBBLESTONE,30,STONE,20,GRAVEL,15,48,10,GRASS,100)
RandomBlock(0,-5,0,COBBLESTONE,30,STONE,20,GRAVEL,15,48,10,GRASS,100)
RandomBlock(0,-5,1,COBBLESTONE,30,STONE,20,GRAVEL,15,48,10,GRASS,100)
RandomBlock(0,-5,2,COBBLESTONE,30,STONE,20,GRAVEL,15,48,10,GRASS,100)
RandomBlock(0,-5,3,COBBLESTONE,30,STONE,20,GRAVEL,15,48,10,GRASS,100)
RandomBlock(0,-5,4,COBBLESTONE,30,STONE,20,GRAVEL,15,48,10,GRASS,100)
RandomBlock(0,-5,5,COBBLESTONE,30,STONE,20,GRAVEL,15,48,10,GRASS,100)
RandomBlock(0,-5,6,COBBLESTONE,30,STONE,20,GRAVEL,15,48,10,GRASS,100)
RandomBlock(0,-5,7,COBBLESTONE,30,STONE,20,GRAVEL,15,48,10,GRASS,100)
RandomBlock(0,-4,-7,COBBLESTONE,30,STONE,20,GRAVEL,15,48,10,GRASS,100)
RandomBlock(0,-4,-6,COBBLESTONE,30,STONE,20,GRAVEL,15,48,10,GRASS,100)
RandomBlock(0,-4,-5,COBBLESTONE,30,STONE,20,GRAVEL,15,48,10,GRASS,100)
RandomBlock(0,-4,-4,COBBLESTONE,30,STONE,20,GRAVEL,15,48,10,GRASS,100)
RandomBlock(0,-4,-3,COBBLESTONE,30,STONE,20,GRAVEL,15,48,10,GRASS,100)
RandomBlock(0,-4,-2,COBBLESTONE,30,STONE,20,GRAVEL,15,48,10,GRASS,100)
RandomBlock(0,-4,-1,COBBLESTONE,30,STONE,20,GRAVEL,15,48,10,GRASS,100)
RandomBlock(0,-4,0,COBBLESTONE,30,STONE,20,GRAVEL,15,48,10,GRASS,100)
RandomBlock(0,-4,1,COBBLESTONE,30,STONE,20,GRAVEL,15,48,10,GRASS,100)
RandomBlock(0,-4,2,COBBLESTONE,30,STONE,20,GRAVEL,15,48,10,GRASS,100)
RandomBlock(0,-4,3,COBBLESTONE,30,STONE,20,GRAVEL,15,48,10,GRASS,100)
RandomBlock(0,-4,4,COBBLESTONE,30,STONE,20,GRAVEL,15,48,10,GRASS,100)
RandomBlock(0,-4,5,COBBLESTONE,30,STONE,20,GRAVEL,15,48,10,GRASS,100)
RandomBlock(0,-4,6,COBBLESTONE,30,STONE,20,GRAVEL,15,48,10,GRASS,100)
RandomBlock(0,-4,7,COBBLESTONE,30,STONE,20,GRAVEL,15,48,10,GRASS,100)
RandomBlock(0,-3,-7,COBBLESTONE,30,STONE,20,GRAVEL,15,48,10,GRASS,100)
RandomBlock(0,-3,-6,COBBLESTONE,30,STONE,20,GRAVEL,15,48,10,GRASS,100)
RandomBlock(0,-3,-5,COBBLESTONE,30,STONE,20,GRAVEL,15,48,10,GRASS,100)
RandomBlock(0,-3,-4,COBBLESTONE,30,STONE,20,GRAVEL,15,48,10,GRASS,100)
RandomBlock(0,-3,-3,COBBLESTONE,30,STONE,20,GRAVEL,15,48,10,GRASS,100)
RandomBlock(0,-3,-2,COBBLESTONE,30,STONE,20,GRAVEL,15,48,10,GRASS,100)
RandomBlock(0,-3,-1,COBBLESTONE,30,STONE,20,GRAVEL,15,48,10,GRASS,100)
RandomBlock(0,-3,0,COBBLESTONE,30,STONE,20,GRAVEL,15,48,10,GRASS,100)
RandomBlock(0,-3,1,COBBLESTONE,30,STONE,20,GRAVEL,15,48,10,GRASS,100)
RandomBlock(0,-3,2,COBBLESTONE,30,STONE,20,GRAVEL,15,48,10,GRASS,100)
RandomBlock(0,-3,3,COBBLESTONE,30,STONE,20,GRAVEL,15,48,10,GRASS,100)
RandomBlock(0,-3,4,COBBLESTONE,30,STONE,20,GRAVEL,15,48,10,GRASS,100)
RandomBlock(0,-3,5,COBBLESTONE,30,STONE,20,GRAVEL,15,48,10,GRASS,100)
RandomBlock(0,-3,6,COBBLESTONE,30,STONE,20,GRAVEL,15,48,10,GRASS,100)
RandomBlock(0,-3,7,COBBLESTONE,30,STONE,20,GRAVEL,15,48,10,GRASS,100)
RandomBlock(0,-2,-7,COBBLESTONE,30,STONE,20,GRAVEL,15,48,10,GRASS,100)
RandomBlock(0,-2,-6,COBBLESTONE,30,STONE,20,GRAVEL,15,48,10,GRASS,100)
RandomBlock(0,-2,-5,COBBLESTONE,30,STONE,20,GRAVEL,15,48,10,GRASS,100)
RandomBlock(0,-2,-4,COBBLESTONE,30,STONE,20,GRAVEL,15,48,10,GRASS,100)
RandomBlock(0,-2,-3,COBBLESTONE,30,STONE,20,GRAVEL,15,48,10,GRASS,100)
RandomBlock(0,-2,-2,COBBLESTONE,30,STONE,20,GRAVEL,15,48,10,GRASS,100)
RandomBlock(0,-2,-1,COBBLESTONE,30,STONE,20,GRAVEL,15,48,10,GRASS,100)
RandomBlock(0,-2,0,COBBLESTONE,30,STONE,20,GRAVEL,15,48,10,GRASS,100)
RandomBlock(0,-2,1,COBBLESTONE,30,STONE,20,GRAVEL,15,48,10,GRASS,100)
RandomBlock(0,-2,2,COBBLESTONE,30,STONE,20,GRAVEL,15,48,10,GRASS,100)
RandomBlock(0,-2,3,COBBLESTONE,30,STONE,20,GRAVEL,15,48,10,GRASS,100)
RandomBlock(0,-2,4,COBBLESTONE,30,STONE,20,GRAVEL,15,48,10,GRASS,100)
RandomBlock(0,-2,5,COBBLESTONE,30,STONE,20,GRAVEL,15,48,10,GRASS,100)
RandomBlock(0,-2,6,COBBLESTONE,30,STONE,20,GRAVEL,15,48,10,GRASS,100)
RandomBlock(0,-2,7,COBBLESTONE,30,STONE,20,GRAVEL,15,48,10,GRASS,100)
RandomBlock(0,-1,-7,COBBLESTONE,30,STONE,20,GRAVEL,15,48,10,GRASS,100)
RandomBlock(0,-1,-6,COBBLESTONE,30,STONE,20,GRAVEL,15,48,10,GRASS,100)
RandomBlock(0,-1,-5,COBBLESTONE,30,STONE,20,GRAVEL,15,48,10,GRASS,100)
RandomBlock(0,-1,-4,COBBLESTONE,30,STONE,20,GRAVEL,15,48,10,GRASS,100)
RandomBlock(0,-1,-3,COBBLESTONE,30,STONE,20,GRAVEL,15,48,10,GRASS,100)
RandomBlock(0,-1,-2,COBBLESTONE,30,STONE,20,GRAVEL,15,48,10,GRASS,100)
RandomBlock(0,-1,-1,COBBLESTONE,30,STONE,20,GRAVEL,15,48,10,GRASS,100)
RandomBlock(0,-1,0,COBBLESTONE,30,STONE,20,GRAVEL,15,48,10,GRASS,100)
RandomBlock(0,-1,1,COBBLESTONE,30,STONE,20,GRAVEL,15,48,10,GRASS,100)
RandomBlock(0,-1,2,COBBLESTONE,30,STONE,20,GRAVEL,15,48,10,GRASS,100)
RandomBlock(0,-1,3,COBBLESTONE,30,STONE,20,GRAVEL,15,48,10,GRASS,100)
RandomBlock(0,-1,4,COBBLESTONE,30,STONE,20,GRAVEL,15,48,10,GRASS,100)
RandomBlock(0,-1,5,COBBLESTONE,30,STONE,20,GRAVEL,15,48,10,GRASS,100)
RandomBlock(0,-1,6,COBBLESTONE,30,STONE,20,GRAVEL,15,48,10,GRASS,100)
RandomBlock(0,-1,7,COBBLESTONE,30,STONE,20,GRAVEL,15,48,10,GRASS,100)
RandomBlock(0,0,-7,COBBLESTONE,30,STONE,20,GRAVEL,15,48,10,GRASS,100)
RandomBlock(0,0,-6,COBBLESTONE,30,STONE,20,GRAVEL,15,48,10,GRASS,100)
RandomBlock(0,0,-5,COBBLESTONE,30,STONE,20,GRAVEL,15,48,10,GRASS,100)
RandomBlock(0,0,-4,COBBLESTONE,30,STONE,20,GRAVEL,15,48,10,GRASS,100)
RandomBlock(0,0,-3,COBBLESTONE,30,STONE,20,GRAVEL,15,48,10,GRASS,100)
RandomBlock(0,0,-2,COBBLESTONE,30,STONE,20,GRAVEL,15,48,10,GRASS,100)
RandomBlock(0,0,-1,COBBLESTONE,30,STONE,20,GRAVEL,15,48,10,GRASS,100)
RandomBlock(0,0,0,COBBLESTONE,30,STONE,20,GRAVEL,15,48,10,GRASS,100)
RandomBlock(0,0,1,COBBLESTONE,30,STONE,20,GRAVEL,15,48,10,GRASS,100)
RandomBlock(0,0,2,COBBLESTONE,30,STONE,20,GRAVEL,15,48,10,GRASS,100)
RandomBlock(0,0,3,COBBLESTONE,30,STONE,20,GRAVEL,15,48,10,GRASS,100)
RandomBlock(0,0,4,COBBLESTONE,30,STONE,20,GRAVEL,15,48,10,GRASS,100)
RandomBlock(0,0,6,COBBLESTONE,30,STONE,20,GRAVEL,15,48,10,GRASS,100)
RandomBlock(0,0,7,COBBLESTONE,30,STONE,20,GRAVEL,15,48,10,GRASS,100)
RandomBlock(0,1,-7,COBBLESTONE,30,STONE,20,GRAVEL,15,48,10,GRASS,100)
RandomBlock(0,1,-6,COBBLESTONE,30,STONE,20,GRAVEL,15,48,10,GRASS,100)
RandomBlock(0,1,-5,COBBLESTONE,30,STONE,20,GRAVEL,15,48,10,GRASS,100)
RandomBlock(0,1,-4,COBBLESTONE,30,STONE,20,GRAVEL,15,48,10,GRASS,100)
RandomBlock(0,1,-3,COBBLESTONE,30,STONE,20,GRAVEL,15,48,10,GRASS,100)
RandomBlock(0,1,-2,COBBLESTONE,30,STONE,20,GRAVEL,15,48,10,GRASS,100)
RandomBlock(0,1,-1,COBBLESTONE,30,STONE,20,GRAVEL,15,48,10,GRASS,100)
RandomBlock(0,1,0,COBBLESTONE,30,STONE,20,GRAVEL,15,48,10,GRASS,100)
RandomBlock(0,1,1,COBBLESTONE,30,STONE,20,GRAVEL,15,48,10,GRASS,100)
RandomBlock(0,1,2,COBBLESTONE,30,STONE,20,GRAVEL,15,48,10,GRASS,100)
RandomBlock(0,1,3,COBBLESTONE,30,STONE,20,GRAVEL,15,48,10,GRASS,100)
RandomBlock(0,1,4,COBBLESTONE,30,STONE,20,GRAVEL,15,48,10,GRASS,100)
RandomBlock(0,1,5,COBBLESTONE,30,STONE,20,GRAVEL,15,48,10,GRASS,100)
RandomBlock(0,1,6,COBBLESTONE,30,STONE,20,GRAVEL,15,48,10,GRASS,100)
RandomBlock(0,1,7,COBBLESTONE,30,STONE,20,GRAVEL,15,48,10,GRASS,100)
RandomBlock(0,2,-7,COBBLESTONE,30,STONE,20,GRAVEL,15,48,10,GRASS,100)
RandomBlock(0,2,-6,COBBLESTONE,30,STONE,20,GRAVEL,15,48,10,GRASS,100)
RandomBlock(0,2,-5,COBBLESTONE,30,STONE,20,GRAVEL,15,48,10,GRASS,100)
RandomBlock(0,2,-4,COBBLESTONE,30,STONE,20,GRAVEL,15,48,10,GRASS,100)
RandomBlock(0,2,-3,COBBLESTONE,30,STONE,20,GRAVEL,15,48,10,GRASS,100)
RandomBlock(0,2,-2,COBBLESTONE,30,STONE,20,GRAVEL,15,48,10,GRASS,100)
RandomBlock(0,2,-1,COBBLESTONE,30,STONE,20,GRAVEL,15,48,10,GRASS,100)
RandomBlock(0,2,0,COBBLESTONE,30,STONE,20,GRAVEL,15,48,10,GRASS,100)
RandomBlock(0,2,1,COBBLESTONE,30,STONE,20,GRAVEL,15,48,10,GRASS,100)
RandomBlock(0,2,2,COBBLESTONE,30,STONE,20,GRAVEL,15,48,10,GRASS,100)
RandomBlock(0,2,3,COBBLESTONE,30,STONE,20,GRAVEL,15,48,10,GRASS,100)
RandomBlock(0,2,4,COBBLESTONE,30,STONE,20,GRAVEL,15,48,10,GRASS,100)
RandomBlock(0,2,5,COBBLESTONE,30,STONE,20,GRAVEL,15,48,10,GRASS,100)
RandomBlock(0,2,6,COBBLESTONE,30,STONE,20,GRAVEL,15,48,10,GRASS,100)
RandomBlock(0,2,7,COBBLESTONE,30,STONE,20,GRAVEL,15,48,10,GRASS,100)
RandomBlock(0,3,-7,COBBLESTONE,30,STONE,20,GRAVEL,15,48,10,GRASS,100)
RandomBlock(0,3,-6,COBBLESTONE,30,STONE,20,GRAVEL,15,48,10,GRASS,100)
RandomBlock(0,3,-5,COBBLESTONE,30,STONE,20,GRAVEL,15,48,10,GRASS,100)
RandomBlock(0,3,-4,COBBLESTONE,30,STONE,20,GRAVEL,15,48,10,GRASS,100)
RandomBlock(0,3,-3,COBBLESTONE,30,STONE,20,GRAVEL,15,48,10,GRASS,100)
RandomBlock(0,3,-2,COBBLESTONE,30,STONE,20,GRAVEL,15,48,10,GRASS,100)
RandomBlock(0,3,-1,COBBLESTONE,30,STONE,20,GRAVEL,15,48,10,GRASS,100)
RandomBlock(0,3,0,COBBLESTONE,30,STONE,20,GRAVEL,15,48,10,GRASS,100)
RandomBlock(0,3,1,COBBLESTONE,30,STONE,20,GRAVEL,15,48,10,GRASS,100)
RandomBlock(0,3,2,COBBLESTONE,30,STONE,20,GRAVEL,15,48,10,GRASS,100)
RandomBlock(0,3,3,COBBLESTONE,30,STONE,20,GRAVEL,15,48,10,GRASS,100)
RandomBlock(0,3,4,COBBLESTONE,30,STONE,20,GRAVEL,15,48,10,GRASS,100)
RandomBlock(0,3,5,COBBLESTONE,30,STONE,20,GRAVEL,15,48,10,GRASS,100)
RandomBlock(0,3,6,COBBLESTONE,30,STONE,20,GRAVEL,15,48,10,GRASS,100)
RandomBlock(0,3,7,COBBLESTONE,30,STONE,20,GRAVEL,15,48,10,GRASS,100)
RandomBlock(0,4,-7,COBBLESTONE,30,STONE,20,GRAVEL,15,48,10,GRASS,100)
RandomBlock(0,4,-6,COBBLESTONE,30,STONE,20,GRAVEL,15,48,10,GRASS,100)
RandomBlock(0,4,-5,COBBLESTONE,30,STONE,20,GRAVEL,15,48,10,GRASS,100)
RandomBlock(0,4,-4,COBBLESTONE,30,STONE,20,GRAVEL,15,48,10,GRASS,100)
RandomBlock(0,4,-3,COBBLESTONE,30,STONE,20,GRAVEL,15,48,10,GRASS,100)
RandomBlock(0,4,-2,COBBLESTONE,30,STONE,20,GRAVEL,15,48,10,GRASS,100)
RandomBlock(0,4,-1,COBBLESTONE,30,STONE,20,GRAVEL,15,48,10,GRASS,100)
RandomBlock(0,4,0,COBBLESTONE,30,STONE,20,GRAVEL,15,48,10,GRASS,100)
RandomBlock(0,4,1,COBBLESTONE,30,STONE,20,GRAVEL,15,48,10,GRASS,100)
RandomBlock(0,4,2,COBBLESTONE,30,STONE,20,GRAVEL,15,48,10,GRASS,100)
RandomBlock(0,4,3,COBBLESTONE,30,STONE,20,GRAVEL,15,48,10,GRASS,100)
RandomBlock(0,4,4,COBBLESTONE,30,STONE,20,GRAVEL,15,48,10,GRASS,100)
RandomBlock(0,4,5,COBBLESTONE,30,STONE,20,GRAVEL,15,48,10,GRASS,100)
RandomBlock(0,4,6,COBBLESTONE,30,STONE,20,GRAVEL,15,48,10,GRASS,100)
RandomBlock(0,4,7,COBBLESTONE,30,STONE,20,GRAVEL,15,48,10,GRASS,100)
RandomBlock(0,5,-7,COBBLESTONE,30,STONE,20,GRAVEL,15,48,10,GRASS,100)
RandomBlock(0,5,-6,COBBLESTONE,30,STONE,20,GRAVEL,15,48,10,GRASS,100)
RandomBlock(0,5,-5,COBBLESTONE,30,STONE,20,GRAVEL,15,48,10,GRASS,100)
RandomBlock(0,5,-4,COBBLESTONE,30,STONE,20,GRAVEL,15,48,10,GRASS,100)
RandomBlock(0,5,-3,COBBLESTONE,30,STONE,20,GRAVEL,15,48,10,GRASS,100)
RandomBlock(0,5,-2,COBBLESTONE,30,STONE,20,GRAVEL,15,48,10,GRASS,100)
RandomBlock(0,5,-1,COBBLESTONE,30,STONE,20,GRAVEL,15,48,10,GRASS,100)
RandomBlock(0,5,0,COBBLESTONE,30,STONE,20,GRAVEL,15,48,10,GRASS,100)
RandomBlock(0,5,1,COBBLESTONE,30,STONE,20,GRAVEL,15,48,10,GRASS,100)
RandomBlock(0,5,2,COBBLESTONE,30,STONE,20,GRAVEL,15,48,10,GRASS,100)
RandomBlock(0,5,3,COBBLESTONE,30,STONE,20,GRAVEL,15,48,10,GRASS,100)
RandomBlock(0,5,4,COBBLESTONE,30,STONE,20,GRAVEL,15,48,10,GRASS,100)
RandomBlock(0,5,5,COBBLESTONE,30,STONE,20,GRAVEL,15,48,10,GRASS,100)
RandomBlock(0,5,6,COBBLESTONE,30,STONE,20,GRAVEL,15,48,10,GRASS,100)
RandomBlock(0,5,7,COBBLESTONE,30,STONE,20,GRAVEL,15,48,10,GRASS,100)
RandomBlock(1,-5,-7,COBBLESTONE,30,STONE,20,GRAVEL,15,48,10,GRASS,100)
RandomBlock(1,-5,-6,COBBLESTONE,30,STONE,20,GRAVEL,15,48,10,GRASS,100)
RandomBlock(1,-5,-5,COBBLESTONE,30,STONE,20,GRAVEL,15,48,10,GRASS,100)
RandomBlock(1,-5,-4,COBBLESTONE,30,STONE,20,GRAVEL,15,48,10,GRASS,100)
RandomBlock(1,-5,-3,COBBLESTONE,30,STONE,20,GRAVEL,15,48,10,GRASS,100)
RandomBlock(1,-5,-2,COBBLESTONE,30,STONE,20,GRAVEL,15,48,10,GRASS,100)
RandomBlock(1,-5,-1,COBBLESTONE,30,STONE,20,GRAVEL,15,48,10,GRASS,100)
RandomBlock(1,-5,0,COBBLESTONE,30,STONE,20,GRAVEL,15,48,10,GRASS,100)
RandomBlock(1,-5,1,COBBLESTONE,30,STONE,20,GRAVEL,15,48,10,GRASS,100)
RandomBlock(1,-5,2,COBBLESTONE,30,STONE,20,GRAVEL,15,48,10,GRASS,100)
RandomBlock(1,-5,3,COBBLESTONE,30,STONE,20,GRAVEL,15,48,10,GRASS,100)
RandomBlock(1,-5,4,COBBLESTONE,30,STONE,20,GRAVEL,15,48,10,GRASS,100)
RandomBlock(1,-5,5,COBBLESTONE,30,STONE,20,GRAVEL,15,48,10,GRASS,100)
RandomBlock(1,-5,6,COBBLESTONE,30,STONE,20,GRAVEL,15,48,10,GRASS,100)
RandomBlock(1,-5,7,COBBLESTONE,30,STONE,20,GRAVEL,15,48,10,GRASS,100)
RandomBlock(1,-4,-7,COBBLESTONE,30,STONE,20,GRAVEL,15,48,10,GRASS,100)
RandomBlock(1,-4,-6,COBBLESTONE,30,STONE,20,GRAVEL,15,48,10,GRASS,100)
RandomBlock(1,-4,-5,COBBLESTONE,30,STONE,20,GRAVEL,15,48,10,GRASS,100)
RandomBlock(1,-4,-4,COBBLESTONE,30,STONE,20,GRAVEL,15,48,10,GRASS,100)
RandomBlock(1,-4,-3,COBBLESTONE,30,STONE,20,GRAVEL,15,48,10,GRASS,100)
RandomBlock(1,-4,-2,COBBLESTONE,30,STONE,20,GRAVEL,15,48,10,GRASS,100)
RandomBlock(1,-4,-1,COBBLESTONE,30,STONE,20,GRAVEL,15,48,10,GRASS,100)
RandomBlock(1,-4,0,COBBLESTONE,30,STONE,20,GRAVEL,15,48,10,GRASS,100)
RandomBlock(1,-4,1,COBBLESTONE,30,STONE,20,GRAVEL,15,48,10,GRASS,100)
RandomBlock(1,-4,2,COBBLESTONE,30,STONE,20,GRAVEL,15,48,10,GRASS,100)
RandomBlock(1,-4,3,COBBLESTONE,30,STONE,20,GRAVEL,15,48,10,GRASS,100)
RandomBlock(1,-4,4,COBBLESTONE,30,STONE,20,GRAVEL,15,48,10,GRASS,100)
RandomBlock(1,-4,5,COBBLESTONE,30,STONE,20,GRAVEL,15,48,10,GRASS,100)
RandomBlock(1,-4,6,COBBLESTONE,30,STONE,20,GRAVEL,15,48,10,GRASS,100)
RandomBlock(1,-4,7,COBBLESTONE,30,STONE,20,GRAVEL,15,48,10,GRASS,100)
RandomBlock(1,-3,-7,COBBLESTONE,30,STONE,20,GRAVEL,15,48,10,GRASS,100)
RandomBlock(1,-3,-6,COBBLESTONE,30,STONE,20,GRAVEL,15,48,10,GRASS,100)
RandomBlock(1,-3,-5,COBBLESTONE,30,STONE,20,GRAVEL,15,48,10,GRASS,100)
RandomBlock(1,-3,-4,COBBLESTONE,30,STONE,20,GRAVEL,15,48,10,GRASS,100)
RandomBlock(1,-3,-3,COBBLESTONE,30,STONE,20,GRAVEL,15,48,10,GRASS,100)
RandomBlock(1,-3,-2,COBBLESTONE,30,STONE,20,GRAVEL,15,48,10,GRASS,100)
RandomBlock(1,-3,-1,COBBLESTONE,30,STONE,20,GRAVEL,15,48,10,GRASS,100)
RandomBlock(1,-3,0,COBBLESTONE,30,STONE,20,GRAVEL,15,48,10,GRASS,100)
RandomBlock(1,-3,1,COBBLESTONE,30,STONE,20,GRAVEL,15,48,10,GRASS,100)
RandomBlock(1,-3,2,COBBLESTONE,30,STONE,20,GRAVEL,15,48,10,GRASS,100)
RandomBlock(1,-3,3,COBBLESTONE,30,STONE,20,GRAVEL,15,48,10,GRASS,100)
RandomBlock(1,-3,4,COBBLESTONE,30,STONE,20,GRAVEL,15,48,10,GRASS,100)
RandomBlock(1,-3,5,COBBLESTONE,30,STONE,20,GRAVEL,15,48,10,GRASS,100)
RandomBlock(1,-3,6,COBBLESTONE,30,STONE,20,GRAVEL,15,48,10,GRASS,100)
RandomBlock(1,-3,7,COBBLESTONE,30,STONE,20,GRAVEL,15,48,10,GRASS,100)
RandomBlock(1,-2,-7,COBBLESTONE,30,STONE,20,GRAVEL,15,48,10,GRASS,100)
RandomBlock(1,-2,-6,COBBLESTONE,30,STONE,20,GRAVEL,15,48,10,GRASS,100)
RandomBlock(1,-2,-5,COBBLESTONE,30,STONE,20,GRAVEL,15,48,10,GRASS,100)
RandomBlock(1,-2,-4,COBBLESTONE,30,STONE,20,GRAVEL,15,48,10,GRASS,100)
RandomBlock(1,-2,-3,COBBLESTONE,30,STONE,20,GRAVEL,15,48,10,GRASS,100)
RandomBlock(1,-2,-2,COBBLESTONE,30,STONE,20,GRAVEL,15,48,10,GRASS,100)
RandomBlock(1,-2,-1,COBBLESTONE,30,STONE,20,GRAVEL,15,48,10,GRASS,100)
RandomBlock(1,-2,0,COBBLESTONE,30,STONE,20,GRAVEL,15,48,10,GRASS,100)
RandomBlock(1,-2,1,COBBLESTONE,30,STONE,20,GRAVEL,15,48,10,GRASS,100)
RandomBlock(1,-2,2,COBBLESTONE,30,STONE,20,GRAVEL,15,48,10,GRASS,100)
RandomBlock(1,-2,3,COBBLESTONE,30,STONE,20,GRAVEL,15,48,10,GRASS,100)
RandomBlock(1,-2,4,COBBLESTONE,30,STONE,20,GRAVEL,15,48,10,GRASS,100)
RandomBlock(1,-2,5,COBBLESTONE,30,STONE,20,GRAVEL,15,48,10,GRASS,100)
RandomBlock(1,-2,6,COBBLESTONE,30,STONE,20,GRAVEL,15,48,10,GRASS,100)
RandomBlock(1,-2,7,COBBLESTONE,30,STONE,20,GRAVEL,15,48,10,GRASS,100)
RandomBlock(1,-1,-7,COBBLESTONE,30,STONE,20,GRAVEL,15,48,10,GRASS,100)
RandomBlock(1,-1,-6,COBBLESTONE,30,STONE,20,GRAVEL,15,48,10,GRASS,100)
RandomBlock(1,-1,-5,COBBLESTONE,30,STONE,20,GRAVEL,15,48,10,GRASS,100)
RandomBlock(1,-1,-4,COBBLESTONE,30,STONE,20,GRAVEL,15,48,10,GRASS,100)
RandomBlock(1,-1,-3,COBBLESTONE,30,STONE,20,GRAVEL,15,48,10,GRASS,100)
RandomBlock(1,-1,-2,COBBLESTONE,30,STONE,20,GRAVEL,15,48,10,GRASS,100)
RandomBlock(1,-1,-1,COBBLESTONE,30,STONE,20,GRAVEL,15,48,10,GRASS,100)
RandomBlock(1,-1,0,COBBLESTONE,30,STONE,20,GRAVEL,15,48,10,GRASS,100)
RandomBlock(1,-1,1,COBBLESTONE,30,STONE,20,GRAVEL,15,48,10,GRASS,100)
RandomBlock(1,-1,2,COBBLESTONE,30,STONE,20,GRAVEL,15,48,10,GRASS,100)
RandomBlock(1,-1,3,COBBLESTONE,30,STONE,20,GRAVEL,15,48,10,GRASS,100)
RandomBlock(1,-1,4,COBBLESTONE,30,STONE,20,GRAVEL,15,48,10,GRASS,100)
RandomBlock(1,-1,5,COBBLESTONE,30,STONE,20,GRAVEL,15,48,10,GRASS,100)
RandomBlock(1,-1,6,COBBLESTONE,30,STONE,20,GRAVEL,15,48,10,GRASS,100)
RandomBlock(1,-1,7,COBBLESTONE,30,STONE,20,GRAVEL,15,48,10,GRASS,100)
RandomBlock(1,0,-7,COBBLESTONE,30,STONE,20,GRAVEL,15,48,10,GRASS,100)
RandomBlock(1,0,-6,COBBLESTONE,30,STONE,20,GRAVEL,15,48,10,GRASS,100)
RandomBlock(1,0,-5,COBBLESTONE,30,STONE,20,GRAVEL,15,48,10,GRASS,100)
RandomBlock(1,0,-4,COBBLESTONE,30,STONE,20,GRAVEL,15,48,10,GRASS,100)
RandomBlock(1,0,-3,COBBLESTONE,30,STONE,20,GRAVEL,15,48,10,GRASS,100)
RandomBlock(1,0,-2,COBBLESTONE,30,STONE,20,GRAVEL,15,48,10,GRASS,100)
RandomBlock(1,0,-1,COBBLESTONE,30,STONE,20,GRAVEL,15,48,10,GRASS,100)
RandomBlock(1,0,0,COBBLESTONE,30,STONE,20,GRAVEL,15,48,10,GRASS,100)
RandomBlock(1,0,1,COBBLESTONE,30,STONE,20,GRAVEL,15,48,10,GRASS,100)
RandomBlock(1,0,2,COBBLESTONE,30,STONE,20,GRAVEL,15,48,10,GRASS,100)
RandomBlock(1,0,3,COBBLESTONE,30,STONE,20,GRAVEL,15,48,10,GRASS,100)
RandomBlock(1,0,4,COBBLESTONE,30,STONE,20,GRAVEL,15,48,10,GRASS,100)
RandomBlock(1,0,5,COBBLESTONE,30,STONE,20,GRAVEL,15,48,10,GRASS,100)
RandomBlock(1,0,6,COBBLESTONE,30,STONE,20,GRAVEL,15,48,10,GRASS,100)
RandomBlock(1,0,7,COBBLESTONE,30,STONE,20,GRAVEL,15,48,10,GRASS,100)
RandomBlock(1,1,-7,COBBLESTONE,30,STONE,20,GRAVEL,15,48,10,GRASS,100)
RandomBlock(1,1,-6,COBBLESTONE,30,STONE,20,GRAVEL,15,48,10,GRASS,100)
RandomBlock(1,1,-5,COBBLESTONE,30,STONE,20,GRAVEL,15,48,10,GRASS,100)
RandomBlock(1,1,-4,COBBLESTONE,30,STONE,20,GRAVEL,15,48,10,GRASS,100)
RandomBlock(1,1,-3,COBBLESTONE,30,STONE,20,GRAVEL,15,48,10,GRASS,100)
RandomBlock(1,1,-2,COBBLESTONE,30,STONE,20,GRAVEL,15,48,10,GRASS,100)
RandomBlock(1,1,-1,COBBLESTONE,30,STONE,20,GRAVEL,15,48,10,GRASS,100)
RandomBlock(1,1,0,COBBLESTONE,30,STONE,20,GRAVEL,15,48,10,GRASS,100)
RandomBlock(1,1,1,COBBLESTONE,30,STONE,20,GRAVEL,15,48,10,GRASS,100)
RandomBlock(1,1,2,COBBLESTONE,30,STONE,20,GRAVEL,15,48,10,GRASS,100)
RandomBlock(1,1,3,COBBLESTONE,30,STONE,20,GRAVEL,15,48,10,GRASS,100)
RandomBlock(1,1,4,COBBLESTONE,30,STONE,20,GRAVEL,15,48,10,GRASS,100)
RandomBlock(1,1,5,COBBLESTONE,30,STONE,20,GRAVEL,15,48,10,GRASS,100)
RandomBlock(1,1,6,COBBLESTONE,30,STONE,20,GRAVEL,15,48,10,GRASS,100)
RandomBlock(1,1,7,COBBLESTONE,30,STONE,20,GRAVEL,15,48,10,GRASS,100)
RandomBlock(1,2,-7,COBBLESTONE,30,STONE,20,GRAVEL,15,48,10,GRASS,100)
RandomBlock(1,2,-6,COBBLESTONE,30,STONE,20,GRAVEL,15,48,10,GRASS,100)
RandomBlock(1,2,-5,COBBLESTONE,30,STONE,20,GRAVEL,15,48,10,GRASS,100)
RandomBlock(1,2,-4,COBBLESTONE,30,STONE,20,GRAVEL,15,48,10,GRASS,100)
RandomBlock(1,2,-3,COBBLESTONE,30,STONE,20,GRAVEL,15,48,10,GRASS,100)
RandomBlock(1,2,-2,COBBLESTONE,30,STONE,20,GRAVEL,15,48,10,GRASS,100)
RandomBlock(1,2,-1,COBBLESTONE,30,STONE,20,GRAVEL,15,48,10,GRASS,100)
RandomBlock(1,2,0,COBBLESTONE,30,STONE,20,GRAVEL,15,48,10,GRASS,100)
RandomBlock(1,2,1,COBBLESTONE,30,STONE,20,GRAVEL,15,48,10,GRASS,100)
RandomBlock(1,2,2,COBBLESTONE,30,STONE,20,GRAVEL,15,48,10,GRASS,100)
RandomBlock(1,2,3,COBBLESTONE,30,STONE,20,GRAVEL,15,48,10,GRASS,100)
RandomBlock(1,2,4,COBBLESTONE,30,STONE,20,GRAVEL,15,48,10,GRASS,100)
RandomBlock(1,2,5,COBBLESTONE,30,STONE,20,GRAVEL,15,48,10,GRASS,100)
RandomBlock(1,2,6,COBBLESTONE,30,STONE,20,GRAVEL,15,48,10,GRASS,100)
RandomBlock(1,2,7,COBBLESTONE,30,STONE,20,GRAVEL,15,48,10,GRASS,100)
RandomBlock(1,3,-7,COBBLESTONE,30,STONE,20,GRAVEL,15,48,10,GRASS,100)
RandomBlock(1,3,-6,COBBLESTONE,30,STONE,20,GRAVEL,15,48,10,GRASS,100)
RandomBlock(1,3,-5,COBBLESTONE,30,STONE,20,GRAVEL,15,48,10,GRASS,100)
RandomBlock(1,3,-4,COBBLESTONE,30,STONE,20,GRAVEL,15,48,10,GRASS,100)
RandomBlock(1,3,-3,COBBLESTONE,30,STONE,20,GRAVEL,15,48,10,GRASS,100)
RandomBlock(1,3,-2,COBBLESTONE,30,STONE,20,GRAVEL,15,48,10,GRASS,100)
RandomBlock(1,3,-1,COBBLESTONE,30,STONE,20,GRAVEL,15,48,10,GRASS,100)
RandomBlock(1,3,0,COBBLESTONE,30,STONE,20,GRAVEL,15,48,10,GRASS,100)
RandomBlock(1,3,1,COBBLESTONE,30,STONE,20,GRAVEL,15,48,10,GRASS,100)
RandomBlock(1,3,2,COBBLESTONE,30,STONE,20,GRAVEL,15,48,10,GRASS,100)
RandomBlock(1,3,3,COBBLESTONE,30,STONE,20,GRAVEL,15,48,10,GRASS,100)
RandomBlock(1,3,4,COBBLESTONE,30,STONE,20,GRAVEL,15,48,10,GRASS,100)
RandomBlock(1,3,5,COBBLESTONE,30,STONE,20,GRAVEL,15,48,10,GRASS,100)
RandomBlock(1,3,6,COBBLESTONE,30,STONE,20,GRAVEL,15,48,10,GRASS,100)
RandomBlock(1,3,7,COBBLESTONE,30,STONE,20,GRAVEL,15,48,10,GRASS,100)
RandomBlock(1,4,-7,COBBLESTONE,30,STONE,20,GRAVEL,15,48,10,GRASS,100)
RandomBlock(1,4,-6,COBBLESTONE,30,STONE,20,GRAVEL,15,48,10,GRASS,100)
RandomBlock(1,4,-5,COBBLESTONE,30,STONE,20,GRAVEL,15,48,10,GRASS,100)
RandomBlock(1,4,-4,COBBLESTONE,30,STONE,20,GRAVEL,15,48,10,GRASS,100)
RandomBlock(1,4,-3,COBBLESTONE,30,STONE,20,GRAVEL,15,48,10,GRASS,100)
RandomBlock(1,4,-2,COBBLESTONE,30,STONE,20,GRAVEL,15,48,10,GRASS,100)
RandomBlock(1,4,-1,COBBLESTONE,30,STONE,20,GRAVEL,15,48,10,GRASS,100)
RandomBlock(1,4,0,COBBLESTONE,30,STONE,20,GRAVEL,15,48,10,GRASS,100)
RandomBlock(1,4,1,COBBLESTONE,30,STONE,20,GRAVEL,15,48,10,GRASS,100)
RandomBlock(1,4,2,COBBLESTONE,30,STONE,20,GRAVEL,15,48,10,GRASS,100)
RandomBlock(1,4,3,COBBLESTONE,30,STONE,20,GRAVEL,15,48,10,GRASS,100)
RandomBlock(1,4,4,COBBLESTONE,30,STONE,20,GRAVEL,15,48,10,GRASS,100)
RandomBlock(1,4,5,COBBLESTONE,30,STONE,20,GRAVEL,15,48,10,GRASS,100)
RandomBlock(1,4,6,COBBLESTONE,30,STONE,20,GRAVEL,15,48,10,GRASS,100)
RandomBlock(1,4,7,COBBLESTONE,30,STONE,20,GRAVEL,15,48,10,GRASS,100)
RandomBlock(1,5,-7,COBBLESTONE,30,STONE,20,GRAVEL,15,48,10,GRASS,100)
RandomBlock(1,5,-6,COBBLESTONE,30,STONE,20,GRAVEL,15,48,10,GRASS,100)
RandomBlock(1,5,-5,COBBLESTONE,30,STONE,20,GRAVEL,15,48,10,GRASS,100)
RandomBlock(1,5,-4,COBBLESTONE,30,STONE,20,GRAVEL,15,48,10,GRASS,100)
RandomBlock(1,5,-3,COBBLESTONE,30,STONE,20,GRAVEL,15,48,10,GRASS,100)
RandomBlock(1,5,-2,COBBLESTONE,30,STONE,20,GRAVEL,15,48,10,GRASS,100)
RandomBlock(1,5,-1,COBBLESTONE,30,STONE,20,GRAVEL,15,48,10,GRASS,100)
RandomBlock(1,5,0,COBBLESTONE,30,STONE,20,GRAVEL,15,48,10,GRASS,100)
RandomBlock(1,5,1,COBBLESTONE,30,STONE,20,GRAVEL,15,48,10,GRASS,100)
RandomBlock(1,5,2,COBBLESTONE,30,STONE,20,GRAVEL,15,48,10,GRASS,100)
RandomBlock(1,5,3,COBBLESTONE,30,STONE,20,GRAVEL,15,48,10,GRASS,100)
RandomBlock(1,5,4,COBBLESTONE,30,STONE,20,GRAVEL,15,48,10,GRASS,100)
RandomBlock(1,5,5,COBBLESTONE,30,STONE,20,GRAVEL,15,48,10,GRASS,100)
RandomBlock(1,5,6,COBBLESTONE,30,STONE,20,GRAVEL,15,48,10,GRASS,100)
RandomBlock(1,5,7,COBBLESTONE,30,STONE,20,GRAVEL,15,48,10,GRASS,100)
RandomBlock(2,-5,-7,COBBLESTONE,30,STONE,20,GRAVEL,15,48,10,GRASS,100)
RandomBlock(2,-5,-6,COBBLESTONE,30,STONE,20,GRAVEL,15,48,10,GRASS,100)
RandomBlock(2,-5,-5,COBBLESTONE,30,STONE,20,GRAVEL,15,48,10,GRASS,100)
RandomBlock(2,-5,-4,COBBLESTONE,30,STONE,20,GRAVEL,15,48,10,GRASS,100)
RandomBlock(2,-5,-3,COBBLESTONE,30,STONE,20,GRAVEL,15,48,10,GRASS,100)
RandomBlock(2,-5,-2,COBBLESTONE,30,STONE,20,GRAVEL,15,48,10,GRASS,100)
RandomBlock(2,-5,-1,COBBLESTONE,30,STONE,20,GRAVEL,15,48,10,GRASS,100)
RandomBlock(2,-5,0,COBBLESTONE,30,STONE,20,GRAVEL,15,48,10,GRASS,100)
RandomBlock(2,-5,1,COBBLESTONE,30,STONE,20,GRAVEL,15,48,10,GRASS,100)
RandomBlock(2,-5,2,COBBLESTONE,30,STONE,20,GRAVEL,15,48,10,GRASS,100)
RandomBlock(2,-5,3,COBBLESTONE,30,STONE,20,GRAVEL,15,48,10,GRASS,100)
RandomBlock(2,-5,4,COBBLESTONE,30,STONE,20,GRAVEL,15,48,10,GRASS,100)
RandomBlock(2,-5,5,COBBLESTONE,30,STONE,20,GRAVEL,15,48,10,GRASS,100)
RandomBlock(2,-5,6,COBBLESTONE,30,STONE,20,GRAVEL,15,48,10,GRASS,100)
RandomBlock(2,-5,7,COBBLESTONE,30,STONE,20,GRAVEL,15,48,10,GRASS,100)
RandomBlock(2,-4,-7,COBBLESTONE,30,STONE,20,GRAVEL,15,48,10,GRASS,100)
RandomBlock(2,-4,-6,COBBLESTONE,30,STONE,20,GRAVEL,15,48,10,GRASS,100)
RandomBlock(2,-4,-5,COBBLESTONE,30,STONE,20,GRAVEL,15,48,10,GRASS,100)
RandomBlock(2,-4,-4,COBBLESTONE,30,STONE,20,GRAVEL,15,48,10,GRASS,100)
RandomBlock(2,-4,-3,COBBLESTONE,30,STONE,20,GRAVEL,15,48,10,GRASS,100)
RandomBlock(2,-4,-2,COBBLESTONE,30,STONE,20,GRAVEL,15,48,10,GRASS,100)
RandomBlock(2,-4,-1,COBBLESTONE,30,STONE,20,GRAVEL,15,48,10,GRASS,100)
RandomBlock(2,-4,0,COBBLESTONE,30,STONE,20,GRAVEL,15,48,10,GRASS,100)
RandomBlock(2,-4,1,COBBLESTONE,30,STONE,20,GRAVEL,15,48,10,GRASS,100)
RandomBlock(2,-4,2,COBBLESTONE,30,STONE,20,GRAVEL,15,48,10,GRASS,100)
RandomBlock(2,-4,3,COBBLESTONE,30,STONE,20,GRAVEL,15,48,10,GRASS,100)
RandomBlock(2,-4,4,COBBLESTONE,30,STONE,20,GRAVEL,15,48,10,GRASS,100)
RandomBlock(2,-4,5,COBBLESTONE,30,STONE,20,GRAVEL,15,48,10,GRASS,100)
RandomBlock(2,-4,6,COBBLESTONE,30,STONE,20,GRAVEL,15,48,10,GRASS,100)
RandomBlock(2,-4,7,COBBLESTONE,30,STONE,20,GRAVEL,15,48,10,GRASS,100)
RandomBlock(2,-3,-7,COBBLESTONE,30,STONE,20,GRAVEL,15,48,10,GRASS,100)
RandomBlock(2,-3,-6,COBBLESTONE,30,STONE,20,GRAVEL,15,48,10,GRASS,100)
RandomBlock(2,-3,-5,COBBLESTONE,30,STONE,20,GRAVEL,15,48,10,GRASS,100)
RandomBlock(2,-3,-4,COBBLESTONE,30,STONE,20,GRAVEL,15,48,10,GRASS,100)
RandomBlock(2,-3,-3,COBBLESTONE,30,STONE,20,GRAVEL,15,48,10,GRASS,100)
RandomBlock(2,-3,-2,COBBLESTONE,30,STONE,20,GRAVEL,15,48,10,GRASS,100)
RandomBlock(2,-3,-1,COBBLESTONE,30,STONE,20,GRAVEL,15,48,10,GRASS,100)
RandomBlock(2,-3,0,COBBLESTONE,30,STONE,20,GRAVEL,15,48,10,GRASS,100)
RandomBlock(2,-3,1,COBBLESTONE,30,STONE,20,GRAVEL,15,48,10,GRASS,100)
RandomBlock(2,-3,2,COBBLESTONE,30,STONE,20,GRAVEL,15,48,10,GRASS,100)
RandomBlock(2,-3,3,COBBLESTONE,30,STONE,20,GRAVEL,15,48,10,GRASS,100)
RandomBlock(2,-3,4,COBBLESTONE,30,STONE,20,GRAVEL,15,48,10,GRASS,100)
RandomBlock(2,-3,5,COBBLESTONE,30,STONE,20,GRAVEL,15,48,10,GRASS,100)
RandomBlock(2,-3,6,COBBLESTONE,30,STONE,20,GRAVEL,15,48,10,GRASS,100)
RandomBlock(2,-3,7,COBBLESTONE,30,STONE,20,GRAVEL,15,48,10,GRASS,100)
RandomBlock(2,-2,-7,COBBLESTONE,30,STONE,20,GRAVEL,15,48,10,GRASS,100)
RandomBlock(2,-2,-6,COBBLESTONE,30,STONE,20,GRAVEL,15,48,10,GRASS,100)
RandomBlock(2,-2,-5,COBBLESTONE,30,STONE,20,GRAVEL,15,48,10,GRASS,100)
RandomBlock(2,-2,-4,COBBLESTONE,30,STONE,20,GRAVEL,15,48,10,GRASS,100)
RandomBlock(2,-2,-3,COBBLESTONE,30,STONE,20,GRAVEL,15,48,10,GRASS,100)
RandomBlock(2,-2,-2,COBBLESTONE,30,STONE,20,GRAVEL,15,48,10,GRASS,100)
RandomBlock(2,-2,-1,COBBLESTONE,30,STONE,20,GRAVEL,15,48,10,GRASS,100)
RandomBlock(2,-2,0,COBBLESTONE,30,STONE,20,GRAVEL,15,48,10,GRASS,100)
RandomBlock(2,-2,1,COBBLESTONE,30,STONE,20,GRAVEL,15,48,10,GRASS,100)
RandomBlock(2,-2,2,COBBLESTONE,30,STONE,20,GRAVEL,15,48,10,GRASS,100)
RandomBlock(2,-2,3,COBBLESTONE,30,STONE,20,GRAVEL,15,48,10,GRASS,100)
RandomBlock(2,-2,4,COBBLESTONE,30,STONE,20,GRAVEL,15,48,10,GRASS,100)
RandomBlock(2,-2,5,COBBLESTONE,30,STONE,20,GRAVEL,15,48,10,GRASS,100)
RandomBlock(2,-2,6,COBBLESTONE,30,STONE,20,GRAVEL,15,48,10,GRASS,100)
RandomBlock(2,-2,7,COBBLESTONE,30,STONE,20,GRAVEL,15,48,10,GRASS,100)
RandomBlock(2,-1,-7,COBBLESTONE,30,STONE,20,GRAVEL,15,48,10,GRASS,100)
RandomBlock(2,-1,-6,COBBLESTONE,30,STONE,20,GRAVEL,15,48,10,GRASS,100)
RandomBlock(2,-1,-5,COBBLESTONE,30,STONE,20,GRAVEL,15,48,10,GRASS,100)
RandomBlock(2,-1,-4,COBBLESTONE,30,STONE,20,GRAVEL,15,48,10,GRASS,100)
RandomBlock(2,-1,-3,COBBLESTONE,30,STONE,20,GRAVEL,15,48,10,GRASS,100)
RandomBlock(2,-1,-2,COBBLESTONE,30,STONE,20,GRAVEL,15,48,10,GRASS,100)
RandomBlock(2,-1,-1,COBBLESTONE,30,STONE,20,GRAVEL,15,48,10,GRASS,100)
RandomBlock(2,-1,0,COBBLESTONE,30,STONE,20,GRAVEL,15,48,10,GRASS,100)
RandomBlock(2,-1,1,COBBLESTONE,30,STONE,20,GRAVEL,15,48,10,GRASS,100)
RandomBlock(2,-1,2,COBBLESTONE,30,STONE,20,GRAVEL,15,48,10,GRASS,100)
RandomBlock(2,-1,3,COBBLESTONE,30,STONE,20,GRAVEL,15,48,10,GRASS,100)
RandomBlock(2,-1,4,COBBLESTONE,30,STONE,20,GRAVEL,15,48,10,GRASS,100)
RandomBlock(2,-1,5,COBBLESTONE,30,STONE,20,GRAVEL,15,48,10,GRASS,100)
RandomBlock(2,-1,6,COBBLESTONE,30,STONE,20,GRAVEL,15,48,10,GRASS,100)
RandomBlock(2,-1,7,COBBLESTONE,30,STONE,20,GRAVEL,15,48,10,GRASS,100)
RandomBlock(2,0,-7,COBBLESTONE,30,STONE,20,GRAVEL,15,48,10,GRASS,100)
RandomBlock(2,0,-6,COBBLESTONE,30,STONE,20,GRAVEL,15,48,10,GRASS,100)
RandomBlock(2,0,-5,COBBLESTONE,30,STONE,20,GRAVEL,15,48,10,GRASS,100)
RandomBlock(2,0,-4,COBBLESTONE,30,STONE,20,GRAVEL,15,48,10,GRASS,100)
RandomBlock(2,0,-3,COBBLESTONE,30,STONE,20,GRAVEL,15,48,10,GRASS,100)
RandomBlock(2,0,-2,COBBLESTONE,30,STONE,20,GRAVEL,15,48,10,GRASS,100)
RandomBlock(2,0,-1,COBBLESTONE,30,STONE,20,GRAVEL,15,48,10,GRASS,100)
RandomBlock(2,0,0,COBBLESTONE,30,STONE,20,GRAVEL,15,48,10,GRASS,100)
RandomBlock(2,0,1,COBBLESTONE,30,STONE,20,GRAVEL,15,48,10,GRASS,100)
RandomBlock(2,0,2,COBBLESTONE,30,STONE,20,GRAVEL,15,48,10,GRASS,100)
RandomBlock(2,0,3,COBBLESTONE,30,STONE,20,GRAVEL,15,48,10,GRASS,100)
RandomBlock(2,0,4,COBBLESTONE,30,STONE,20,GRAVEL,15,48,10,GRASS,100)
RandomBlock(2,0,5,COBBLESTONE,30,STONE,20,GRAVEL,15,48,10,GRASS,100)
RandomBlock(2,0,6,COBBLESTONE,30,STONE,20,GRAVEL,15,48,10,GRASS,100)
RandomBlock(2,0,7,COBBLESTONE,30,STONE,20,GRAVEL,15,48,10,GRASS,100)
RandomBlock(2,1,-7,COBBLESTONE,30,STONE,20,GRAVEL,15,48,10,GRASS,100)
RandomBlock(2,1,-6,COBBLESTONE,30,STONE,20,GRAVEL,15,48,10,GRASS,100)
RandomBlock(2,1,-5,COBBLESTONE,30,STONE,20,GRAVEL,15,48,10,GRASS,100)
RandomBlock(2,1,-4,COBBLESTONE,30,STONE,20,GRAVEL,15,48,10,GRASS,100)
RandomBlock(2,1,-3,COBBLESTONE,30,STONE,20,GRAVEL,15,48,10,GRASS,100)
RandomBlock(2,1,-2,COBBLESTONE,30,STONE,20,GRAVEL,15,48,10,GRASS,100)
RandomBlock(2,1,-1,COBBLESTONE,30,STONE,20,GRAVEL,15,48,10,GRASS,100)
RandomBlock(2,1,0,COBBLESTONE,30,STONE,20,GRAVEL,15,48,10,GRASS,100)
RandomBlock(2,1,1,COBBLESTONE,30,STONE,20,GRAVEL,15,48,10,GRASS,100)
RandomBlock(2,1,2,COBBLESTONE,30,STONE,20,GRAVEL,15,48,10,GRASS,100)
RandomBlock(2,1,3,COBBLESTONE,30,STONE,20,GRAVEL,15,48,10,GRASS,100)
RandomBlock(2,1,4,COBBLESTONE,30,STONE,20,GRAVEL,15,48,10,GRASS,100)
RandomBlock(2,1,5,COBBLESTONE,30,STONE,20,GRAVEL,15,48,10,GRASS,100)
RandomBlock(2,1,6,COBBLESTONE,30,STONE,20,GRAVEL,15,48,10,GRASS,100)
RandomBlock(2,1,7,COBBLESTONE,30,STONE,20,GRAVEL,15,48,10,GRASS,100)
RandomBlock(2,2,-7,COBBLESTONE,30,STONE,20,GRAVEL,15,48,10,GRASS,100)
RandomBlock(2,2,-6,COBBLESTONE,30,STONE,20,GRAVEL,15,48,10,GRASS,100)
RandomBlock(2,2,-5,COBBLESTONE,30,STONE,20,GRAVEL,15,48,10,GRASS,100)
RandomBlock(2,2,-4,COBBLESTONE,30,STONE,20,GRAVEL,15,48,10,GRASS,100)
RandomBlock(2,2,-3,COBBLESTONE,30,STONE,20,GRAVEL,15,48,10,GRASS,100)
RandomBlock(2,2,-2,COBBLESTONE,30,STONE,20,GRAVEL,15,48,10,GRASS,100)
RandomBlock(2,2,-1,COBBLESTONE,30,STONE,20,GRAVEL,15,48,10,GRASS,100)
RandomBlock(2,2,0,COBBLESTONE,30,STONE,20,GRAVEL,15,48,10,GRASS,100)
RandomBlock(2,2,1,COBBLESTONE,30,STONE,20,GRAVEL,15,48,10,GRASS,100)
RandomBlock(2,2,2,COBBLESTONE,30,STONE,20,GRAVEL,15,48,10,GRASS,100)
RandomBlock(2,2,3,COBBLESTONE,30,STONE,20,GRAVEL,15,48,10,GRASS,100)
RandomBlock(2,2,4,COBBLESTONE,30,STONE,20,GRAVEL,15,48,10,GRASS,100)
RandomBlock(2,2,5,COBBLESTONE,30,STONE,20,GRAVEL,15,48,10,GRASS,100)
RandomBlock(2,2,6,COBBLESTONE,30,STONE,20,GRAVEL,15,48,10,GRASS,100)
RandomBlock(2,2,7,COBBLESTONE,30,STONE,20,GRAVEL,15,48,10,GRASS,100)
RandomBlock(2,3,-7,COBBLESTONE,30,STONE,20,GRAVEL,15,48,10,GRASS,100)
RandomBlock(2,3,-6,COBBLESTONE,30,STONE,20,GRAVEL,15,48,10,GRASS,100)
RandomBlock(2,3,-5,COBBLESTONE,30,STONE,20,GRAVEL,15,48,10,GRASS,100)
RandomBlock(2,3,-4,COBBLESTONE,30,STONE,20,GRAVEL,15,48,10,GRASS,100)
RandomBlock(2,3,-3,COBBLESTONE,30,STONE,20,GRAVEL,15,48,10,GRASS,100)
RandomBlock(2,3,-2,COBBLESTONE,30,STONE,20,GRAVEL,15,48,10,GRASS,100)
RandomBlock(2,3,-1,COBBLESTONE,30,STONE,20,GRAVEL,15,48,10,GRASS,100)
RandomBlock(2,3,0,COBBLESTONE,30,STONE,20,GRAVEL,15,48,10,GRASS,100)
RandomBlock(2,3,1,COBBLESTONE,30,STONE,20,GRAVEL,15,48,10,GRASS,100)
RandomBlock(2,3,2,COBBLESTONE,30,STONE,20,GRAVEL,15,48,10,GRASS,100)
RandomBlock(2,3,3,COBBLESTONE,30,STONE,20,GRAVEL,15,48,10,GRASS,100)
RandomBlock(2,3,4,COBBLESTONE,30,STONE,20,GRAVEL,15,48,10,GRASS,100)
RandomBlock(2,3,5,COBBLESTONE,30,STONE,20,GRAVEL,15,48,10,GRASS,100)
RandomBlock(2,3,6,COBBLESTONE,30,STONE,20,GRAVEL,15,48,10,GRASS,100)
RandomBlock(2,3,7,COBBLESTONE,30,STONE,20,GRAVEL,15,48,10,GRASS,100)
RandomBlock(2,4,-7,COBBLESTONE,30,STONE,20,GRAVEL,15,48,10,GRASS,100)
RandomBlock(2,4,-6,COBBLESTONE,30,STONE,20,GRAVEL,15,48,10,GRASS,100)
RandomBlock(2,4,-5,COBBLESTONE,30,STONE,20,GRAVEL,15,48,10,GRASS,100)
RandomBlock(2,4,-4,COBBLESTONE,30,STONE,20,GRAVEL,15,48,10,GRASS,100)
RandomBlock(2,4,-3,COBBLESTONE,30,STONE,20,GRAVEL,15,48,10,GRASS,100)
RandomBlock(2,4,-2,COBBLESTONE,30,STONE,20,GRAVEL,15,48,10,GRASS,100)
RandomBlock(2,4,-1,COBBLESTONE,30,STONE,20,GRAVEL,15,48,10,GRASS,100)
RandomBlock(2,4,0,COBBLESTONE,30,STONE,20,GRAVEL,15,48,10,GRASS,100)
RandomBlock(2,4,1,COBBLESTONE,30,STONE,20,GRAVEL,15,48,10,GRASS,100)
RandomBlock(2,4,2,COBBLESTONE,30,STONE,20,GRAVEL,15,48,10,GRASS,100)
RandomBlock(2,4,3,COBBLESTONE,30,STONE,20,GRAVEL,15,48,10,GRASS,100)
RandomBlock(2,4,4,COBBLESTONE,30,STONE,20,GRAVEL,15,48,10,GRASS,100)
RandomBlock(2,4,5,COBBLESTONE,30,STONE,20,GRAVEL,15,48,10,GRASS,100)
RandomBlock(2,4,6,COBBLESTONE,30,STONE,20,GRAVEL,15,48,10,GRASS,100)
RandomBlock(2,4,7,COBBLESTONE,30,STONE,20,GRAVEL,15,48,10,GRASS,100)
RandomBlock(2,5,-7,COBBLESTONE,30,STONE,20,GRAVEL,15,48,10,GRASS,100)
RandomBlock(2,5,-6,COBBLESTONE,30,STONE,20,GRAVEL,15,48,10,GRASS,100)
RandomBlock(2,5,-5,COBBLESTONE,30,STONE,20,GRAVEL,15,48,10,GRASS,100)
RandomBlock(2,5,-4,COBBLESTONE,30,STONE,20,GRAVEL,15,48,10,GRASS,100)
RandomBlock(2,5,-3,COBBLESTONE,30,STONE,20,GRAVEL,15,48,10,GRASS,100)
RandomBlock(2,5,-2,COBBLESTONE,30,STONE,20,GRAVEL,15,48,10,GRASS,100)
RandomBlock(2,5,-1,COBBLESTONE,30,STONE,20,GRAVEL,15,48,10,GRASS,100)
RandomBlock(2,5,0,COBBLESTONE,30,STONE,20,GRAVEL,15,48,10,GRASS,100)
RandomBlock(2,5,1,COBBLESTONE,30,STONE,20,GRAVEL,15,48,10,GRASS,100)
RandomBlock(2,5,2,COBBLESTONE,30,STONE,20,GRAVEL,15,48,10,GRASS,100)
RandomBlock(2,5,3,COBBLESTONE,30,STONE,20,GRAVEL,15,48,10,GRASS,100)
RandomBlock(2,5,4,COBBLESTONE,30,STONE,20,GRAVEL,15,48,10,GRASS,100)
RandomBlock(2,5,5,COBBLESTONE,30,STONE,20,GRAVEL,15,48,10,GRASS,100)
RandomBlock(2,5,6,COBBLESTONE,30,STONE,20,GRAVEL,15,48,10,GRASS,100)
RandomBlock(2,5,7,COBBLESTONE,30,STONE,20,GRAVEL,15,48,10,GRASS,100)
RandomBlock(3,-5,-2,COBBLESTONE,30,STONE,20,GRAVEL,15,48,10,GRASS,100)
RandomBlock(3,-5,-1,COBBLESTONE,30,STONE,20,GRAVEL,15,48,10,GRASS,100)
RandomBlock(3,-5,0,COBBLESTONE,30,STONE,20,GRAVEL,15,48,10,GRASS,100)
RandomBlock(3,-5,1,COBBLESTONE,30,STONE,20,GRAVEL,15,48,10,GRASS,100)
RandomBlock(3,-5,2,COBBLESTONE,30,STONE,20,GRAVEL,15,48,10,GRASS,100)
RandomBlock(3,-4,-2,COBBLESTONE,30,STONE,20,GRAVEL,15,48,10,GRASS,100)
RandomBlock(3,-4,-1,COBBLESTONE,30,STONE,20,GRAVEL,15,48,10,GRASS,100)
RandomBlock(3,-4,0,COBBLESTONE,30,STONE,20,GRAVEL,15,48,10,GRASS,100)
RandomBlock(3,-4,1,COBBLESTONE,30,STONE,20,GRAVEL,15,48,10,GRASS,100)
RandomBlock(3,-4,2,COBBLESTONE,30,STONE,20,GRAVEL,15,48,10,GRASS,100)
RandomBlock(3,-3,-2,COBBLESTONE,30,STONE,20,GRAVEL,15,48,10,GRASS,100)
RandomBlock(3,-3,-1,COBBLESTONE,30,STONE,20,GRAVEL,15,48,10,GRASS,100)
RandomBlock(3,-3,0,COBBLESTONE,30,STONE,20,GRAVEL,15,48,10,GRASS,100)
RandomBlock(3,-3,1,COBBLESTONE,30,STONE,20,GRAVEL,15,48,10,GRASS,100)
RandomBlock(3,-3,2,COBBLESTONE,30,STONE,20,GRAVEL,15,48,10,GRASS,100)
RandomBlock(3,-2,-2,COBBLESTONE,30,STONE,20,GRAVEL,15,48,10,GRASS,100)
RandomBlock(3,-2,-1,COBBLESTONE,30,STONE,20,GRAVEL,15,48,10,GRASS,100)
RandomBlock(3,-2,0,COBBLESTONE,30,STONE,20,GRAVEL,15,48,10,GRASS,100)
RandomBlock(3,-2,1,COBBLESTONE,30,STONE,20,GRAVEL,15,48,10,GRASS,100)
RandomBlock(3,-2,2,COBBLESTONE,30,STONE,20,GRAVEL,15,48,10,GRASS,100)
RandomBlock(3,-1,-2,COBBLESTONE,30,STONE,20,GRAVEL,15,48,10,GRASS,100)
RandomBlock(3,-1,-1,COBBLESTONE,30,STONE,20,GRAVEL,15,48,10,GRASS,100)
RandomBlock(3,-1,0,COBBLESTONE,30,STONE,20,GRAVEL,15,48,10,GRASS,100)
RandomBlock(3,-1,1,COBBLESTONE,30,STONE,20,GRAVEL,15,48,10,GRASS,100)
RandomBlock(3,-1,2,COBBLESTONE,30,STONE,20,GRAVEL,15,48,10,GRASS,100)
RandomBlock(3,0,-2,COBBLESTONE,30,STONE,20,GRAVEL,15,48,10,GRASS,100)
RandomBlock(3,0,-1,COBBLESTONE,30,STONE,20,GRAVEL,15,48,10,GRASS,100)
RandomBlock(3,0,0,COBBLESTONE,30,STONE,20,GRAVEL,15,48,10,GRASS,100)
RandomBlock(3,0,1,COBBLESTONE,30,STONE,20,GRAVEL,15,48,10,GRASS,100)
RandomBlock(3,0,2,COBBLESTONE,30,STONE,20,GRAVEL,15,48,10,GRASS,100)
RandomBlock(3,1,-2,COBBLESTONE,30,STONE,20,GRAVEL,15,48,10,GRASS,100)
RandomBlock(3,1,-1,COBBLESTONE,30,STONE,20,GRAVEL,15,48,10,GRASS,100)
RandomBlock(3,1,0,COBBLESTONE,30,STONE,20,GRAVEL,15,48,10,GRASS,100)
RandomBlock(3,1,1,COBBLESTONE,30,STONE,20,GRAVEL,15,48,10,GRASS,100)
RandomBlock(3,1,2,COBBLESTONE,30,STONE,20,GRAVEL,15,48,10,GRASS,100)
RandomBlock(3,2,-2,COBBLESTONE,30,STONE,20,GRAVEL,15,48,10,GRASS,100)
RandomBlock(3,2,-1,COBBLESTONE,30,STONE,20,GRAVEL,15,48,10,GRASS,100)
RandomBlock(3,2,0,COBBLESTONE,30,STONE,20,GRAVEL,15,48,10,GRASS,100)
RandomBlock(3,2,1,COBBLESTONE,30,STONE,20,GRAVEL,15,48,10,GRASS,100)
RandomBlock(3,2,2,COBBLESTONE,30,STONE,20,GRAVEL,15,48,10,GRASS,100)
RandomBlock(3,3,-2,COBBLESTONE,30,STONE,20,GRAVEL,15,48,10,GRASS,100)
RandomBlock(3,3,-1,COBBLESTONE,30,STONE,20,GRAVEL,15,48,10,GRASS,100)
RandomBlock(3,3,0,COBBLESTONE,30,STONE,20,GRAVEL,15,48,10,GRASS,100)
RandomBlock(3,3,1,COBBLESTONE,30,STONE,20,GRAVEL,15,48,10,GRASS,100)
RandomBlock(3,3,2,COBBLESTONE,30,STONE,20,GRAVEL,15,48,10,GRASS,100)
RandomBlock(3,4,-2,COBBLESTONE,30,STONE,20,GRAVEL,15,48,10,GRASS,100)
RandomBlock(3,4,-1,COBBLESTONE,30,STONE,20,GRAVEL,15,48,10,GRASS,100)
RandomBlock(3,4,0,COBBLESTONE,30,STONE,20,GRAVEL,15,48,10,GRASS,100)
RandomBlock(3,4,1,COBBLESTONE,30,STONE,20,GRAVEL,15,48,10,GRASS,100)
RandomBlock(3,4,2,COBBLESTONE,30,STONE,20,GRAVEL,15,48,10,GRASS,100)
RandomBlock(3,5,-2,COBBLESTONE,30,STONE,20,GRAVEL,15,48,10,GRASS,100)
RandomBlock(3,5,-1,COBBLESTONE,30,STONE,20,GRAVEL,15,48,10,GRASS,100)
RandomBlock(3,5,0,COBBLESTONE,30,STONE,20,GRAVEL,15,48,10,GRASS,100)
RandomBlock(3,5,1,COBBLESTONE,30,STONE,20,GRAVEL,15,48,10,GRASS,100)
RandomBlock(3,5,2,COBBLESTONE,30,STONE,20,GRAVEL,15,48,10,GRASS,100)
RandomBlock(4,-5,-2,COBBLESTONE,30,STONE,20,GRAVEL,15,48,10,GRASS,100)
RandomBlock(4,-5,-1,COBBLESTONE,30,STONE,20,GRAVEL,15,48,10,GRASS,100)
RandomBlock(4,-5,0,COBBLESTONE,30,STONE,20,GRAVEL,15,48,10,GRASS,100)
RandomBlock(4,-5,1,COBBLESTONE,30,STONE,20,GRAVEL,15,48,10,GRASS,100)
RandomBlock(4,-5,2,COBBLESTONE,30,STONE,20,GRAVEL,15,48,10,GRASS,100)
RandomBlock(4,-4,-2,COBBLESTONE,30,STONE,20,GRAVEL,15,48,10,GRASS,100)
RandomBlock(4,-4,-1,COBBLESTONE,30,STONE,20,GRAVEL,15,48,10,GRASS,100)
RandomBlock(4,-4,0,COBBLESTONE,30,STONE,20,GRAVEL,15,48,10,GRASS,100)
RandomBlock(4,-4,1,COBBLESTONE,30,STONE,20,GRAVEL,15,48,10,GRASS,100)
RandomBlock(4,-4,2,COBBLESTONE,30,STONE,20,GRAVEL,15,48,10,GRASS,100)
RandomBlock(4,-3,-2,COBBLESTONE,30,STONE,20,GRAVEL,15,48,10,GRASS,100)
RandomBlock(4,-3,-1,COBBLESTONE,30,STONE,20,GRAVEL,15,48,10,GRASS,100)
RandomBlock(4,-3,0,COBBLESTONE,30,STONE,20,GRAVEL,15,48,10,GRASS,100)
RandomBlock(4,-3,1,COBBLESTONE,30,STONE,20,GRAVEL,15,48,10,GRASS,100)
RandomBlock(4,-3,2,COBBLESTONE,30,STONE,20,GRAVEL,15,48,10,GRASS,100)
RandomBlock(4,-2,-2,COBBLESTONE,30,STONE,20,GRAVEL,15,48,10,GRASS,100)
RandomBlock(4,-2,-1,COBBLESTONE,30,STONE,20,GRAVEL,15,48,10,GRASS,100)
RandomBlock(4,-2,0,COBBLESTONE,30,STONE,20,GRAVEL,15,48,10,GRASS,100)
RandomBlock(4,-2,1,COBBLESTONE,30,STONE,20,GRAVEL,15,48,10,GRASS,100)
RandomBlock(4,-2,2,COBBLESTONE,30,STONE,20,GRAVEL,15,48,10,GRASS,100)
RandomBlock(4,-1,-2,COBBLESTONE,30,STONE,20,GRAVEL,15,48,10,GRASS,100)
RandomBlock(4,-1,-1,COBBLESTONE,30,STONE,20,GRAVEL,15,48,10,GRASS,100)
RandomBlock(4,-1,0,COBBLESTONE,30,STONE,20,GRAVEL,15,48,10,GRASS,100)
RandomBlock(4,-1,1,COBBLESTONE,30,STONE,20,GRAVEL,15,48,10,GRASS,100)
RandomBlock(4,-1,2,COBBLESTONE,30,STONE,20,GRAVEL,15,48,10,GRASS,100)
RandomBlock(4,0,-2,COBBLESTONE,30,STONE,20,GRAVEL,15,48,10,GRASS,100)
RandomBlock(4,0,-1,COBBLESTONE,30,STONE,20,GRAVEL,15,48,10,GRASS,100)
RandomBlock(4,0,0,COBBLESTONE,30,STONE,20,GRAVEL,15,48,10,GRASS,100)
RandomBlock(4,0,1,COBBLESTONE,30,STONE,20,GRAVEL,15,48,10,GRASS,100)
RandomBlock(4,0,2,COBBLESTONE,30,STONE,20,GRAVEL,15,48,10,GRASS,100)
RandomBlock(4,1,-2,COBBLESTONE,30,STONE,20,GRAVEL,15,48,10,GRASS,100)
RandomBlock(4,1,-1,COBBLESTONE,30,STONE,20,GRAVEL,15,48,10,GRASS,100)
RandomBlock(4,1,0,COBBLESTONE,30,STONE,20,GRAVEL,15,48,10,GRASS,100)
RandomBlock(4,1,1,COBBLESTONE,30,STONE,20,GRAVEL,15,48,10,GRASS,100)
RandomBlock(4,1,2,COBBLESTONE,30,STONE,20,GRAVEL,15,48,10,GRASS,100)
RandomBlock(4,2,-2,COBBLESTONE,30,STONE,20,GRAVEL,15,48,10,GRASS,100)
RandomBlock(4,2,-1,COBBLESTONE,30,STONE,20,GRAVEL,15,48,10,GRASS,100)
RandomBlock(4,2,0,COBBLESTONE,30,STONE,20,GRAVEL,15,48,10,GRASS,100)
RandomBlock(4,2,1,COBBLESTONE,30,STONE,20,GRAVEL,15,48,10,GRASS,100)
RandomBlock(4,2,2,COBBLESTONE,30,STONE,20,GRAVEL,15,48,10,GRASS,100)
RandomBlock(4,3,-2,COBBLESTONE,30,STONE,20,GRAVEL,15,48,10,GRASS,100)
RandomBlock(4,3,-1,COBBLESTONE,30,STONE,20,GRAVEL,15,48,10,GRASS,100)
RandomBlock(4,3,0,COBBLESTONE,30,STONE,20,GRAVEL,15,48,10,GRASS,100)
RandomBlock(4,3,1,COBBLESTONE,30,STONE,20,GRAVEL,15,48,10,GRASS,100)
RandomBlock(4,3,2,COBBLESTONE,30,STONE,20,GRAVEL,15,48,10,GRASS,100)
RandomBlock(4,4,-2,COBBLESTONE,30,STONE,20,GRAVEL,15,48,10,GRASS,100)
RandomBlock(4,4,-1,COBBLESTONE,30,STONE,20,GRAVEL,15,48,10,GRASS,100)
RandomBlock(4,4,0,COBBLESTONE,30,STONE,20,GRAVEL,15,48,10,GRASS,100)
RandomBlock(4,4,1,COBBLESTONE,30,STONE,20,GRAVEL,15,48,10,GRASS,100)
RandomBlock(4,4,2,COBBLESTONE,30,STONE,20,GRAVEL,15,48,10,GRASS,100)
RandomBlock(4,5,-2,COBBLESTONE,30,STONE,20,GRAVEL,15,48,10,GRASS,100)
RandomBlock(4,5,-1,COBBLESTONE,30,STONE,20,GRAVEL,15,48,10,GRASS,100)
RandomBlock(4,5,0,COBBLESTONE,30,STONE,20,GRAVEL,15,48,10,GRASS,100)
RandomBlock(4,5,1,COBBLESTONE,30,STONE,20,GRAVEL,15,48,10,GRASS,100)
RandomBlock(4,5,2,COBBLESTONE,30,STONE,20,GRAVEL,15,48,10,GRASS,100)
RandomBlock(5,-5,-2,COBBLESTONE,30,STONE,20,GRAVEL,15,48,10,GRASS,100)
RandomBlock(5,-5,-1,COBBLESTONE,30,STONE,20,GRAVEL,15,48,10,GRASS,100)
RandomBlock(5,-5,0,COBBLESTONE,30,STONE,20,GRAVEL,15,48,10,GRASS,100)
RandomBlock(5,-5,1,COBBLESTONE,30,STONE,20,GRAVEL,15,48,10,GRASS,100)
RandomBlock(5,-5,2,COBBLESTONE,30,STONE,20,GRAVEL,15,48,10,GRASS,100)
RandomBlock(5,-4,-2,COBBLESTONE,30,STONE,20,GRAVEL,15,48,10,GRASS,100)
RandomBlock(5,-4,-1,COBBLESTONE,30,STONE,20,GRAVEL,15,48,10,GRASS,100)
RandomBlock(5,-4,0,COBBLESTONE,30,STONE,20,GRAVEL,15,48,10,GRASS,100)
RandomBlock(5,-4,1,COBBLESTONE,30,STONE,20,GRAVEL,15,48,10,GRASS,100)
RandomBlock(5,-4,2,COBBLESTONE,30,STONE,20,GRAVEL,15,48,10,GRASS,100)
RandomBlock(5,-3,-2,COBBLESTONE,30,STONE,20,GRAVEL,15,48,10,GRASS,100)
RandomBlock(5,-3,-1,COBBLESTONE,30,STONE,20,GRAVEL,15,48,10,GRASS,100)
RandomBlock(5,-3,0,COBBLESTONE,30,STONE,20,GRAVEL,15,48,10,GRASS,100)
RandomBlock(5,-3,1,COBBLESTONE,30,STONE,20,GRAVEL,15,48,10,GRASS,100)
RandomBlock(5,-3,2,COBBLESTONE,30,STONE,20,GRAVEL,15,48,10,GRASS,100)
RandomBlock(5,-2,-2,COBBLESTONE,30,STONE,20,GRAVEL,15,48,10,GRASS,100)
RandomBlock(5,-2,-1,COBBLESTONE,30,STONE,20,GRAVEL,15,48,10,GRASS,100)
RandomBlock(5,-2,0,COBBLESTONE,30,STONE,20,GRAVEL,15,48,10,GRASS,100)
RandomBlock(5,-2,1,COBBLESTONE,30,STONE,20,GRAVEL,15,48,10,GRASS,100)
RandomBlock(5,-2,2,COBBLESTONE,30,STONE,20,GRAVEL,15,48,10,GRASS,100)
RandomBlock(5,-1,-2,COBBLESTONE,30,STONE,20,GRAVEL,15,48,10,GRASS,100)
RandomBlock(5,-1,-1,COBBLESTONE,30,STONE,20,GRAVEL,15,48,10,GRASS,100)
RandomBlock(5,-1,0,COBBLESTONE,30,STONE,20,GRAVEL,15,48,10,GRASS,100)
RandomBlock(5,-1,1,COBBLESTONE,30,STONE,20,GRAVEL,15,48,10,GRASS,100)
RandomBlock(5,-1,2,COBBLESTONE,30,STONE,20,GRAVEL,15,48,10,GRASS,100)
RandomBlock(5,0,-2,COBBLESTONE,30,STONE,20,GRAVEL,15,48,10,GRASS,100)
RandomBlock(5,0,-1,COBBLESTONE,30,STONE,20,GRAVEL,15,48,10,GRASS,100)
RandomBlock(5,0,0,COBBLESTONE,30,STONE,20,GRAVEL,15,48,10,GRASS,100)
RandomBlock(5,0,1,COBBLESTONE,30,STONE,20,GRAVEL,15,48,10,GRASS,100)
RandomBlock(5,0,2,COBBLESTONE,30,STONE,20,GRAVEL,15,48,10,GRASS,100)
RandomBlock(5,1,-2,COBBLESTONE,30,STONE,20,GRAVEL,15,48,10,GRASS,100)
RandomBlock(5,1,-1,COBBLESTONE,30,STONE,20,GRAVEL,15,48,10,GRASS,100)
RandomBlock(5,1,0,COBBLESTONE,30,STONE,20,GRAVEL,15,48,10,GRASS,100)
RandomBlock(5,1,1,COBBLESTONE,30,STONE,20,GRAVEL,15,48,10,GRASS,100)
RandomBlock(5,1,2,COBBLESTONE,30,STONE,20,GRAVEL,15,48,10,GRASS,100)
RandomBlock(5,2,-2,COBBLESTONE,30,STONE,20,GRAVEL,15,48,10,GRASS,100)
RandomBlock(5,2,-1,COBBLESTONE,30,STONE,20,GRAVEL,15,48,10,GRASS,100)
RandomBlock(5,2,0,COBBLESTONE,30,STONE,20,GRAVEL,15,48,10,GRASS,100)
RandomBlock(5,2,1,COBBLESTONE,30,STONE,20,GRAVEL,15,48,10,GRASS,100)
RandomBlock(5,2,2,COBBLESTONE,30,STONE,20,GRAVEL,15,48,10,GRASS,100)
RandomBlock(5,3,-2,COBBLESTONE,30,STONE,20,GRAVEL,15,48,10,GRASS,100)
RandomBlock(5,3,-1,COBBLESTONE,30,STONE,20,GRAVEL,15,48,10,GRASS,100)
RandomBlock(5,3,0,COBBLESTONE,30,STONE,20,GRAVEL,15,48,10,GRASS,100)
RandomBlock(5,3,1,COBBLESTONE,30,STONE,20,GRAVEL,15,48,10,GRASS,100)
RandomBlock(5,3,2,COBBLESTONE,30,STONE,20,GRAVEL,15,48,10,GRASS,100)
RandomBlock(5,4,-2,COBBLESTONE,30,STONE,20,GRAVEL,15,48,10,GRASS,100)
RandomBlock(5,4,-1,COBBLESTONE,30,STONE,20,GRAVEL,15,48,10,GRASS,100)
RandomBlock(5,4,0,COBBLESTONE,30,STONE,20,GRAVEL,15,48,10,GRASS,100)
RandomBlock(5,4,1,COBBLESTONE,30,STONE,20,GRAVEL,15,48,10,GRASS,100)
RandomBlock(5,4,2,COBBLESTONE,30,STONE,20,GRAVEL,15,48,10,GRASS,100)
RandomBlock(5,5,-2,COBBLESTONE,30,STONE,20,GRAVEL,15,48,10,GRASS,100)
RandomBlock(5,5,-1,COBBLESTONE,30,STONE,20,GRAVEL,15,48,10,GRASS,100)
RandomBlock(5,5,0,COBBLESTONE,30,STONE,20,GRAVEL,15,48,10,GRASS,100)
RandomBlock(5,5,1,COBBLESTONE,30,STONE,20,GRAVEL,15,48,10,GRASS,100)
RandomBlock(5,5,2,COBBLESTONE,30,STONE,20,GRAVEL,15,48,10,GRASS,100)
RandomBlock(6,-5,-2,COBBLESTONE,30,STONE,20,GRAVEL,15,48,10,GRASS,100)
RandomBlock(6,-5,-1,COBBLESTONE,30,STONE,20,GRAVEL,15,48,10,GRASS,100)
RandomBlock(6,-5,0,COBBLESTONE,30,STONE,20,GRAVEL,15,48,10,GRASS,100)
RandomBlock(6,-5,1,COBBLESTONE,30,STONE,20,GRAVEL,15,48,10,GRASS,100)
RandomBlock(6,-5,2,COBBLESTONE,30,STONE,20,GRAVEL,15,48,10,GRASS,100)
RandomBlock(6,-4,-2,COBBLESTONE,30,STONE,20,GRAVEL,15,48,10,GRASS,100)
RandomBlock(6,-4,-1,COBBLESTONE,30,STONE,20,GRAVEL,15,48,10,GRASS,100)
RandomBlock(6,-4,0,COBBLESTONE,30,STONE,20,GRAVEL,15,48,10,GRASS,100)
RandomBlock(6,-4,1,COBBLESTONE,30,STONE,20,GRAVEL,15,48,10,GRASS,100)
RandomBlock(6,-4,2,COBBLESTONE,30,STONE,20,GRAVEL,15,48,10,GRASS,100)
RandomBlock(6,-3,-2,COBBLESTONE,30,STONE,20,GRAVEL,15,48,10,GRASS,100)
RandomBlock(6,-3,-1,COBBLESTONE,30,STONE,20,GRAVEL,15,48,10,GRASS,100)
RandomBlock(6,-3,0,COBBLESTONE,30,STONE,20,GRAVEL,15,48,10,GRASS,100)
RandomBlock(6,-3,1,COBBLESTONE,30,STONE,20,GRAVEL,15,48,10,GRASS,100)
RandomBlock(6,-3,2,COBBLESTONE,30,STONE,20,GRAVEL,15,48,10,GRASS,100)
RandomBlock(6,-2,-2,COBBLESTONE,30,STONE,20,GRAVEL,15,48,10,GRASS,100)
RandomBlock(6,-2,-1,COBBLESTONE,30,STONE,20,GRAVEL,15,48,10,GRASS,100)
RandomBlock(6,-2,0,COBBLESTONE,30,STONE,20,GRAVEL,15,48,10,GRASS,100)
RandomBlock(6,-2,1,COBBLESTONE,30,STONE,20,GRAVEL,15,48,10,GRASS,100)
RandomBlock(6,-2,2,COBBLESTONE,30,STONE,20,GRAVEL,15,48,10,GRASS,100)
RandomBlock(6,-1,-2,COBBLESTONE,30,STONE,20,GRAVEL,15,48,10,GRASS,100)
RandomBlock(6,-1,-1,COBBLESTONE,30,STONE,20,GRAVEL,15,48,10,GRASS,100)
RandomBlock(6,-1,0,COBBLESTONE,30,STONE,20,GRAVEL,15,48,10,GRASS,100)
RandomBlock(6,-1,1,COBBLESTONE,30,STONE,20,GRAVEL,15,48,10,GRASS,100)
RandomBlock(6,-1,2,COBBLESTONE,30,STONE,20,GRAVEL,15,48,10,GRASS,100)
RandomBlock(6,0,-2,COBBLESTONE,30,STONE,20,GRAVEL,15,48,10,GRASS,100)
RandomBlock(6,0,-1,COBBLESTONE,30,STONE,20,GRAVEL,15,48,10,GRASS,100)
RandomBlock(6,0,0,COBBLESTONE,30,STONE,20,GRAVEL,15,48,10,GRASS,100)
RandomBlock(6,0,1,COBBLESTONE,30,STONE,20,GRAVEL,15,48,10,GRASS,100)
RandomBlock(6,0,2,COBBLESTONE,30,STONE,20,GRAVEL,15,48,10,GRASS,100)
RandomBlock(6,1,-2,COBBLESTONE,30,STONE,20,GRAVEL,15,48,10,GRASS,100)
RandomBlock(6,1,-1,COBBLESTONE,30,STONE,20,GRAVEL,15,48,10,GRASS,100)
RandomBlock(6,1,0,COBBLESTONE,30,STONE,20,GRAVEL,15,48,10,GRASS,100)
RandomBlock(6,1,1,COBBLESTONE,30,STONE,20,GRAVEL,15,48,10,GRASS,100)
RandomBlock(6,1,2,COBBLESTONE,30,STONE,20,GRAVEL,15,48,10,GRASS,100)
RandomBlock(6,2,-2,COBBLESTONE,30,STONE,20,GRAVEL,15,48,10,GRASS,100)
RandomBlock(6,2,-1,COBBLESTONE,30,STONE,20,GRAVEL,15,48,10,GRASS,100)
RandomBlock(6,2,0,COBBLESTONE,30,STONE,20,GRAVEL,15,48,10,GRASS,100)
RandomBlock(6,2,1,COBBLESTONE,30,STONE,20,GRAVEL,15,48,10,GRASS,100)
RandomBlock(6,2,2,COBBLESTONE,30,STONE,20,GRAVEL,15,48,10,GRASS,100)
RandomBlock(6,3,-2,COBBLESTONE,30,STONE,20,GRAVEL,15,48,10,GRASS,100)
RandomBlock(6,3,-1,COBBLESTONE,30,STONE,20,GRAVEL,15,48,10,GRASS,100)
RandomBlock(6,3,0,COBBLESTONE,30,STONE,20,GRAVEL,15,48,10,GRASS,100)
RandomBlock(6,3,1,COBBLESTONE,30,STONE,20,GRAVEL,15,48,10,GRASS,100)
RandomBlock(6,3,2,COBBLESTONE,30,STONE,20,GRAVEL,15,48,10,GRASS,100)
RandomBlock(6,4,-2,COBBLESTONE,30,STONE,20,GRAVEL,15,48,10,GRASS,100)
RandomBlock(6,4,-1,COBBLESTONE,30,STONE,20,GRAVEL,15,48,10,GRASS,100)
RandomBlock(6,4,0,COBBLESTONE,30,STONE,20,GRAVEL,15,48,10,GRASS,100)
RandomBlock(6,4,1,COBBLESTONE,30,STONE,20,GRAVEL,15,48,10,GRASS,100)
RandomBlock(6,4,2,COBBLESTONE,30,STONE,20,GRAVEL,15,48,10,GRASS,100)
RandomBlock(6,5,-2,COBBLESTONE,30,STONE,20,GRAVEL,15,48,10,GRASS,100)
RandomBlock(6,5,-1,COBBLESTONE,30,STONE,20,GRAVEL,15,48,10,GRASS,100)
RandomBlock(6,5,0,COBBLESTONE,30,STONE,20,GRAVEL,15,48,10,GRASS,100)
RandomBlock(6,5,1,COBBLESTONE,30,STONE,20,GRAVEL,15,48,10,GRASS,100)
RandomBlock(6,5,2,COBBLESTONE,30,STONE,20,GRAVEL,15,48,10,GRASS,100)
RandomBlock(7,-5,-2,COBBLESTONE,30,STONE,20,GRAVEL,15,48,10,GRASS,100)
RandomBlock(7,-5,-1,COBBLESTONE,30,STONE,20,GRAVEL,15,48,10,GRASS,100)
RandomBlock(7,-5,0,COBBLESTONE,30,STONE,20,GRAVEL,15,48,10,GRASS,100)
RandomBlock(7,-5,1,COBBLESTONE,30,STONE,20,GRAVEL,15,48,10,GRASS,100)
RandomBlock(7,-5,2,COBBLESTONE,30,STONE,20,GRAVEL,15,48,10,GRASS,100)
RandomBlock(7,-4,-2,COBBLESTONE,30,STONE,20,GRAVEL,15,48,10,GRASS,100)
RandomBlock(7,-4,-1,COBBLESTONE,30,STONE,20,GRAVEL,15,48,10,GRASS,100)
RandomBlock(7,-4,0,COBBLESTONE,30,STONE,20,GRAVEL,15,48,10,GRASS,100)
RandomBlock(7,-4,1,COBBLESTONE,30,STONE,20,GRAVEL,15,48,10,GRASS,100)
RandomBlock(7,-4,2,COBBLESTONE,30,STONE,20,GRAVEL,15,48,10,GRASS,100)
RandomBlock(7,-3,-2,COBBLESTONE,30,STONE,20,GRAVEL,15,48,10,GRASS,100)
RandomBlock(7,-3,-1,COBBLESTONE,30,STONE,20,GRAVEL,15,48,10,GRASS,100)
RandomBlock(7,-3,0,COBBLESTONE,30,STONE,20,GRAVEL,15,48,10,GRASS,100)
RandomBlock(7,-3,1,COBBLESTONE,30,STONE,20,GRAVEL,15,48,10,GRASS,100)
RandomBlock(7,-3,2,COBBLESTONE,30,STONE,20,GRAVEL,15,48,10,GRASS,100)
RandomBlock(7,-2,-2,COBBLESTONE,30,STONE,20,GRAVEL,15,48,10,GRASS,100)
RandomBlock(7,-2,-1,COBBLESTONE,30,STONE,20,GRAVEL,15,48,10,GRASS,100)
RandomBlock(7,-2,0,COBBLESTONE,30,STONE,20,GRAVEL,15,48,10,GRASS,100)
RandomBlock(7,-2,1,COBBLESTONE,30,STONE,20,GRAVEL,15,48,10,GRASS,100)
RandomBlock(7,-2,2,COBBLESTONE,30,STONE,20,GRAVEL,15,48,10,GRASS,100)
RandomBlock(7,-1,-2,COBBLESTONE,30,STONE,20,GRAVEL,15,48,10,GRASS,100)
RandomBlock(7,-1,-1,COBBLESTONE,30,STONE,20,GRAVEL,15,48,10,GRASS,100)
RandomBlock(7,-1,0,COBBLESTONE,30,STONE,20,GRAVEL,15,48,10,GRASS,100)
RandomBlock(7,-1,1,COBBLESTONE,30,STONE,20,GRAVEL,15,48,10,GRASS,100)
RandomBlock(7,-1,2,COBBLESTONE,30,STONE,20,GRAVEL,15,48,10,GRASS,100)
RandomBlock(7,0,-2,COBBLESTONE,30,STONE,20,GRAVEL,15,48,10,GRASS,100)
RandomBlock(7,0,-1,COBBLESTONE,30,STONE,20,GRAVEL,15,48,10,GRASS,100)
RandomBlock(7,0,0,COBBLESTONE,30,STONE,20,GRAVEL,15,48,10,GRASS,100)
RandomBlock(7,0,1,COBBLESTONE,30,STONE,20,GRAVEL,15,48,10,GRASS,100)
RandomBlock(7,0,2,COBBLESTONE,30,STONE,20,GRAVEL,15,48,10,GRASS,100)
RandomBlock(7,1,-2,COBBLESTONE,30,STONE,20,GRAVEL,15,48,10,GRASS,100)
RandomBlock(7,1,-1,COBBLESTONE,30,STONE,20,GRAVEL,15,48,10,GRASS,100)
RandomBlock(7,1,0,COBBLESTONE,30,STONE,20,GRAVEL,15,48,10,GRASS,100)
RandomBlock(7,1,1,COBBLESTONE,30,STONE,20,GRAVEL,15,48,10,GRASS,100)
RandomBlock(7,1,2,COBBLESTONE,30,STONE,20,GRAVEL,15,48,10,GRASS,100)
RandomBlock(7,2,-2,COBBLESTONE,30,STONE,20,GRAVEL,15,48,10,GRASS,100)
RandomBlock(7,2,-1,COBBLESTONE,30,STONE,20,GRAVEL,15,48,10,GRASS,100)
RandomBlock(7,2,0,COBBLESTONE,30,STONE,20,GRAVEL,15,48,10,GRASS,100)
RandomBlock(7,2,1,COBBLESTONE,30,STONE,20,GRAVEL,15,48,10,GRASS,100)
RandomBlock(7,2,2,COBBLESTONE,30,STONE,20,GRAVEL,15,48,10,GRASS,100)
RandomBlock(7,3,-2,COBBLESTONE,30,STONE,20,GRAVEL,15,48,10,GRASS,100)
RandomBlock(7,3,-1,COBBLESTONE,30,STONE,20,GRAVEL,15,48,10,GRASS,100)
RandomBlock(7,3,0,COBBLESTONE,30,STONE,20,GRAVEL,15,48,10,GRASS,100)
RandomBlock(7,3,1,COBBLESTONE,30,STONE,20,GRAVEL,15,48,10,GRASS,100)
RandomBlock(7,3,2,COBBLESTONE,30,STONE,20,GRAVEL,15,48,10,GRASS,100)
