#######################################################################
# +-----------------------------------------------------------------+ #
# |                            BO3 object                           | #
# +-----------------------------------------------------------------+ #
#######################################################################

# The descriptions in this file are true only for TerrainControl. They are not true for the Minecraft Worlds mod!
# Minecraft Worlds completely reimplemented BO3s, check the MCW documentation on the mc/mctcp forums for how to use BO3s with MCW
# or watch the video's on my YT channel at https://www.youtube.com/user/PeeGee85. You can check out the "Editing and importing schematics & BO3s" 
# series of video's, in part 2 I explain BO3s. 

# This is the config file of a custom object.
# If you add this object correctly to your BiomeConfigs, it will spawn in the world.

# This is the creator of this BO3 object
Author: Unknown

# A short description of this BO3 object
Description: This BO3 was converted from a schematic using the MineCraft Worlds Editor. Unfortunately the author and description information for the schematic could not be found. If you know who the author of the schematic is then please tell the author of this BO3!

# The BO3 version, don't change this! It can be used by external applications to do a version check.
Version: 3

# The settings mode, WriteAll, WriteWithoutComments or WriteDisable. See WorldConfig.
SettingsMode: WriteDisable

#######################################################################
# +-----------------------------------------------------------------+ #
# |                          Main settings                          | #
# +-----------------------------------------------------------------+ #
#######################################################################

# This needs to be set to true to spawn the object in the Tree and Sapling resources.
Tree: false

# The frequency of the BO3 from 1 to 200. Tries this many times to spawn this BO3 when using the CustomObject(...) resource.
# Ignored by Tree(..), Sapling(..) and CustomStructure(..)
Frequency: 40

# The rarity of the BO3 from 0 to 100. Each spawn attempt has rarity% chance to succeed when using the CustomObject(...) resource.
# Ignored by Tree(..), Sapling(..) and CustomStructure(..)
Rarity: 100.0

# If you set this to true, the BO3 will be placed with a random rotation.
RotateRandomly: false

# The spawn height of the BO3 - randomY, highestBlock or highestSolidBlock.
SpawnHeight: randomY

# The height limits for the BO3.
MinHeight: 20

MaxHeight: 22

# Objects can have other objects attached to it: branches. Branches can also
# have branches attached to it, which can also have branches, etc. This is the
# maximum branch depth for this objects.
MaxBranchDepth: 10

# When spawned with the UseWorld keyword, this BO3 should NOT spawn in the following biomes.
# If you writer.write the BO3 name directly in the BiomeConfigs, this will be ignored.
ExcludedBiomes: All

#######################################################################
# +-----------------------------------------------------------------+ #
# |                      Source block settings                      | #
# +-----------------------------------------------------------------+ #
#######################################################################

# The block(s) the BO3 should spawn in.
SourceBlocks: AIR

# The maximum percentage of the BO3 that can be outside the SourceBlock.
# The BO3 won't be placed on a location with more blocks outside the SourceBlock than this percentage.
MaxPercentageOutsideSourceBlock: 100

# What to do when a block is about to be placed outside the SourceBlock? (dontPlace, placeAnyway)
OutsideSourceBlock: placeAnyway

#######################################################################
# +-----------------------------------------------------------------+ #
# |                              Blocks                             | #
# +-----------------------------------------------------------------+ #
#######################################################################

# All the blocks used in the BO3 are listed here. Possible blocks:
# Block(x,y,z,id[.data][,nbtfile.nbt)
# RandomBlock(x,y,z,id[:data][,nbtfile.nbt],chance[,id[:data][,nbtfile.nbt],chance[,...]])
# So RandomBlock(0,0,0,CHEST,chest.nbt,50,CHEST,anotherchest.nbt,100) will spawn a chest at
# the BO3 origin, and give it a 50% chance to have the contents of chest.nbt, or, if that
# fails, a 100% percent chance to have the contents of anotherchest.nbt.

Block(-8,13,-5,1:5)
Block(-8,13,-4,1:5)
Block(-8,14,-6,1)
Block(-8,14,-5,1:5)
Block(-8,14,-4,1:5)
Block(-8,15,-7,1)
Block(-8,15,-6,1)
Block(-8,15,-5,1:5)
Block(-8,15,-4,1:5)
Block(-8,16,-7,1)
Block(-8,16,-6,1)
Block(-8,16,-5,1:5)
Block(-8,16,-4,1:5)
Block(-8,17,-7,1)
Block(-8,17,-6,1)
Block(-8,17,-5,1:5)
Block(-8,17,-4,1:5)
Block(-8,17,-3,1)
Block(-8,18,-7,1)
Block(-8,18,-6,1)
Block(-8,18,-5,1)
Block(-8,18,-4,1)
Block(-8,18,-3,1)
Block(-8,18,-2,1)
Block(-8,19,-7,1)
Block(-8,19,-6,1)
Block(-8,19,-5,1)
Block(-8,19,-4,1)
Block(-8,19,-3,1)
Block(-8,19,-2,1)
Block(-8,19,-1,1)
Block(-8,20,-7,1)
Block(-8,20,-6,1)
Block(-8,20,-5,1)
Block(-8,20,-4,1)
Block(-8,20,-3,1)
Block(-8,20,-2,1)
Block(-8,20,-1,1)
Block(-8,20,0,1)
Block(-8,20,1,1)
Block(-8,20,3,1)
Block(-8,21,-7,1)
Block(-8,21,-6,1)
Block(-8,21,-5,1)
Block(-8,21,-4,1)
Block(-8,21,-3,1)
Block(-8,21,-2,1)
Block(-8,21,-1,1)
Block(-8,21,0,1)
Block(-8,21,1,1)
Block(-8,21,2,1)
Block(-8,21,3,1)
Block(-8,21,4,1)
Block(-8,21,5,1)
Block(-8,22,-7,1)
Block(-8,22,-6,1)
Block(-8,22,-5,1)
Block(-8,22,-4,1)
Block(-8,22,-3,1)
Block(-8,22,-2,1)
Block(-8,22,-1,1)
Block(-8,22,0,1)
Block(-8,22,1,1)
Block(-8,22,2,1)
Block(-8,22,3,1)
Block(-8,22,4,1)
Block(-8,22,5,1)
Block(-8,23,-7,1)
Block(-8,23,-6,1)
Block(-8,23,-5,1)
Block(-8,23,-4,1)
Block(-8,23,-3,1)
Block(-8,23,-2,1)
Block(-8,23,-1,1)
Block(-8,23,0,1)
Block(-8,23,1,1)
Block(-8,23,2,1)
Block(-8,23,3,1)
Block(-8,23,4,1)
Block(-8,24,-7,1)
Block(-8,24,-6,1)
Block(-8,24,-5,1)
Block(-8,24,-4,1)
Block(-8,24,-3,1)
Block(-8,24,-2,1)
Block(-8,24,-1,1)
Block(-8,24,0,1)
Block(-8,24,1,1)
Block(-8,24,2,1)
Block(-8,24,3,1)
Block(-8,24,4,1)
Block(-8,25,-7,1)
Block(-8,25,-6,1)
Block(-8,25,-5,1)
Block(-8,25,-4,1)
Block(-8,25,-3,1)
Block(-8,25,-2,1)
Block(-8,25,-1,1)
Block(-8,25,0,1)
Block(-8,25,1,1:5)
Block(-8,25,2,1)
Block(-8,25,3,1)
Block(-8,26,-7,1)
Block(-8,26,-6,1)
Block(-8,26,-5,1)
Block(-8,26,-4,1)
Block(-8,26,-3,1)
Block(-8,26,-2,1)
Block(-8,26,-1,1:5)
Block(-8,26,0,1:5)
Block(-8,26,1,1)
Block(-8,26,2,1)
Block(-8,27,-7,1)
Block(-8,27,-6,1)
Block(-8,27,-5,1:5)
Block(-8,27,-4,1)
Block(-8,27,-3,1)
Block(-8,27,-2,1:5)
Block(-8,27,-1,1:5)
Block(-8,27,0,1:5)
Block(-8,27,1,1:5)
Block(-8,28,-7,1)
Block(-8,28,-6,1)
Block(-8,28,-5,1:5)
Block(-8,28,-4,1:5)
Block(-8,28,-3,1)
Block(-8,28,-2,1:5)
Block(-8,28,-1,1:5)
Block(-8,28,0,1:5)
Block(-8,28,1,1:5)
Block(-8,29,-7,1)
Block(-8,29,-6,1)
Block(-8,29,-5,1:5)
Block(-8,29,-4,1:5)
Block(-8,29,-3,1:5)
Block(-8,29,-2,1:5)
Block(-8,29,-1,1:5)
Block(-8,29,0,1:5)
Block(-8,30,-7,1)
Block(-8,30,-4,1:5)
Block(-8,30,-3,1:5)
Block(-8,30,-2,1:5)
Block(-8,30,-1,1:5)
Block(-8,30,0,1:5)
Block(-8,31,-3,1:5)
Block(-8,31,-2,1:5)
Block(-8,31,-1,1:5)
Block(-8,32,-2,1:5)
Block(-7,15,-6,1)
Block(-7,16,-7,1)
Block(-7,16,-6,1)
Block(-7,17,-7,1:5)
Block(-7,17,-6,1:5)
Block(-7,17,-5,1)
Block(-7,18,-7,1)
Block(-7,18,-6,1:5)
Block(-7,18,-5,1)
Block(-7,18,-4,1)
Block(-7,19,-7,1)
Block(-7,19,-6,1:5)
Block(-7,19,-5,1:5)
Block(-7,19,-4,1)
Block(-7,19,-3,1)
Block(-7,20,-7,1)
Block(-7,20,-6,1)
Block(-7,20,-5,1:5)
Block(-7,20,-4,1:5)
Block(-7,20,-3,1:5)
Block(-7,20,-2,1:5)
Block(-7,20,-1,1:5)
Block(-7,21,-7,1)
Block(-7,21,-6,1)
Block(-7,21,-5,1:5)
Block(-7,21,-4,1:5)
Block(-7,21,-3,1:5)
Block(-7,21,-2,1:5)
Block(-7,21,-1,1:5)
Block(-7,21,0,1:5)
Block(-7,21,1,1:5)
Block(-7,22,-7,1)
Block(-7,22,-6,1)
Block(-7,22,-5,1:5)
Block(-7,22,-4,1:5)
Block(-7,22,-3,1)
Block(-7,22,-2,1:5)
Block(-7,22,-1,1:5)
Block(-7,22,0,1:5)
Block(-7,22,1,1:5)
Block(-7,22,2,1)
Block(-7,23,-7,1)
Block(-7,23,-6,1)
Block(-7,23,-5,1:5)
Block(-7,23,-4,1:5)
Block(-7,23,-3,1)
Block(-7,23,-2,1:5)
Block(-7,23,-1,1:5)
Block(-7,23,0,1:5)
Block(-7,23,1,1)
Block(-7,23,2,1)
Block(-7,23,3,1)
Block(-7,24,-7,1)
Block(-7,24,-6,1)
Block(-7,24,-5,1:5)
Block(-7,24,-4,1:5)
Block(-7,24,-3,1)
Block(-7,24,-2,1:5)
Block(-7,24,-1,1:5)
Block(-7,24,0,1:5)
Block(-7,24,1,1)
Block(-7,24,2,1)
Block(-7,25,-7,1)
Block(-7,25,-6,1)
Block(-7,25,-5,1:5)
Block(-7,25,-4,1:5)
Block(-7,25,-3,1:5)
Block(-7,25,-2,1:5)
Block(-7,25,-1,1:5)
Block(-7,25,0,1:5)
Block(-7,25,1,1)
Block(-7,26,-7,1)
Block(-7,26,-6,1:5)
Block(-7,26,-5,1:5)
Block(-7,26,-4,1:5)
Block(-7,26,-3,1:5)
Block(-7,26,-2,1:5)
Block(-7,26,-1,1:5)
Block(-7,26,0,1:5)
Block(-7,27,-7,1:5)
Block(-7,27,-6,1)
Block(-7,27,-5,1:5)
Block(-7,27,-4,1:5)
Block(-7,27,-3,1:5)
Block(-7,27,-2,1:5)
Block(-7,27,-1,1:5)
Block(-7,27,0,1)
Block(-7,28,-6,1)
Block(-7,28,-5,1:5)
Block(-7,28,-4,1:5)
Block(-7,28,-3,1)
Block(-6,17,-6,1)
Block(-6,18,-7,1)
Block(-6,18,-6,1)
Block(-6,19,-7,1)
Block(-6,19,-6,1)
Block(-6,19,-5,1)
Block(-6,20,-7,1:5)
Block(-6,20,-6,1)
Block(-6,20,-5,1)
Block(-6,21,-7,1:5)
Block(-6,21,-6,1:5)
Block(-6,21,-5,1)
Block(-6,21,-4,1:3)
Block(-6,22,-7,1:5)
Block(-6,22,-6,1:5)
Block(-6,22,-5,1)
Block(-6,22,-4,1:3)
Block(-6,22,-3,1)
Block(-6,22,-2,1)
Block(-6,22,-1,1)
Block(-6,22,0,1)
Block(-6,23,-7,1:5)
Block(-6,23,-6,1:5)
Block(-6,23,-5,1)
Block(-6,23,-4,1:3)
Block(-6,23,-3,1)
Block(-6,23,-2,1)
Block(-6,23,-1,1)
Block(-6,23,0,1)
Block(-6,24,-7,1:5)
Block(-6,24,-6,1:5)
Block(-6,24,-5,1)
Block(-6,24,-4,1:3)
Block(-6,24,-3,1)
Block(-6,24,-2,1)
Block(-6,24,-1,1)
Block(-6,24,0,1)
Block(-6,25,-7,1:5)
Block(-6,25,-6,1:5)
Block(-6,25,-5,1)
Block(-6,25,-4,1:3)
Block(-6,25,-3,1)
Block(-6,25,-2,1)
Block(-6,25,-1,1)
Block(-6,26,-6,1:5)
Block(-6,26,-5,1)
Block(-6,26,-4,1)
Block(-6,26,-3,1)
Block(-6,26,-2,1)
Block(-6,27,-5,1)
Block(-6,27,-4,1)
Block(-5,19,-7,1)
Block(-5,20,-7,1)
Block(-5,20,-6,1)
Block(-5,21,-7,1)
Block(-5,21,-6,1)
Block(-5,22,-7,1)
Block(-5,22,-6,1)
Block(-5,22,-5,1)
Block(-5,23,-7,1)
Block(-5,23,-6,1)
Block(-5,23,-5,1)
Block(-5,23,-4,1)
Block(-5,23,-3,1)
Block(-5,24,-7,1)
Block(-5,24,-6,1)
Block(-5,24,-5,1)
Block(-5,24,-4,1)
Block(-5,24,-3,1)
Block(-5,25,-6,1)
Block(-5,25,-5,1)
Block(-5,25,-4,1)
Block(-5,26,-5,1)


#######################################################################
# +-----------------------------------------------------------------+ #
# |                            BO3 checks                           | #
# +-----------------------------------------------------------------+ #
#######################################################################

# Require a condition at a certain location in order for the BO3 to be spawned.
# BlockCheck(x,y,z,BlockName[,BlockName[,...]]) - one of the blocks must be at the location
# BlockCheckNot(x,y,z,BlockName[,BlockName[,...]]) - all the blocks must not be at the location
# LightCheck(x,y,z,minLightLevel,maxLightLevel) - light must be between min and max (inclusive)

# You can use "Solid" as a BlockName for matching all solid blocks or "All" to match all blocks that aren't air.

# Examples:
#   BlockCheck(0,-1,0,GRASS,DIRT)  Require grass or dirt just below the object
#   BlockCheck(0,-1,0,Solid)       Require any solid block just below the object
#   BlockCheck(0,-1,0,WOOL)        Require any type of wool just below the object
#   BlockCheck(0,-1,0,WOOL:0)      Require white wool just below the object
#   BlockCheckNot(0,0,0,WOOL:0)   Require that there is no white wool below the object
#   LightCheck(0,0,0,0,1)          Require almost complete darkness just below the object

#######################################################################
# +-----------------------------------------------------------------+ #
# |                             Branches                            | #
# +-----------------------------------------------------------------+ #
#######################################################################

# Branches are objects that will spawn when this object spawns when it is used in
# the CustomStructure resource. Branches can also have branches, making complex
# structures possible. See the wiki for more details.

# Regular Branches spawn each branch with an independent chance of spawning.
# Branch(x,y,z,branchName,rotation,chance[,anotherBranchName,rotation,chance[,...]][IndividualChance])
# branchName - name of the object to spawn.
# rotation - NORTH, SOUTH, EAST or WEST.
# IndividualChance - The chance each branch has to spawn, assumed to be 100 when left blank

# WeightedBranch(x,y,z,branchName,rotation,chance[,anotherBranchName,rotation,chance[,...]][MaxChanceOutOf])
# MaxChanceOutOf - The chance all branches have to spawn out of, assumed to be 100 when left blank
