
#######################################################################
# +-----------------------------------------------------------------+ #
# |                            BO3 object                           | #
# +-----------------------------------------------------------------+ #
#######################################################################

# This is the config file of a custom object.
# If you add this object correctly to your BiomeConfigs, it will spawn in the world.

# This is the creator of this BO3 object
Author: LordSmellyPants

# A short description of this BO3 object
Description: No description given

# The BO3 version, don't change this! It can be used by external applications to do a version check.
Version: 3

# The settings mode, WriteAll, WriteWithoutComments or WriteDisable. See WorldConfig.
SettingsMode: WriteDisable


#######################################################################
# +-----------------------------------------------------------------+ #
# |                          Main settings                          | #
# +-----------------------------------------------------------------+ #
#######################################################################

# This needs to be set to true to spawn the object in the Tree and Sapling resources.
Tree: false

# The frequency of the BO3 from 1 to 200. Tries this many times to spawn this BO3 when using the CustomObject(...) resource.
# Ignored by Tree(..), Sapling(..) and CustomStructure(..)
Frequency: 1

# The rarity of the BO3 from 0 to 100. Each spawn attempt has rarity% chance to succeed when using the CustomObject(...) resource.
# Ignored by Tree(..), Sapling(..) and CustomStructure(..)
Rarity: 25.0

# If you set this to true, the BO3 will be placed with a random rotation.
RotateRandomly: true

# The spawn height of the BO3 - randomY, highestBlock or highestSolidBlock.
SpawnHeight: randomY

# The height limits for the BO3.
MinHeight: 147

MaxHeight: 148

# Objects can have other objects attacthed to it: branches. Branches can also
# have branches attached to it, which can also have branches, etc. This is the
# maximum branch depth for this objects.
MaxBranchDepth: 10

# When spawned with the UseWorld keyword, this BO3 should NOT spawn in the following biomes.
# If you writer.write the BO3 name directly in the BiomeConfigs, this will be ignored.
ExcludedBiomes: All


#######################################################################
# +-----------------------------------------------------------------+ #
# |                      Source block settings                      | #
# +-----------------------------------------------------------------+ #
#######################################################################

# The B(s) the BO3 should spawn in.
SourceBlocks: STONE:1,STONE:3,STONE:5,DIRT:1,STONE

# The maximum percentage of the BO3 that can be outside the SourceBlock.
# The BO3 won't be placed on a location with more blocks outside the SourceBlock than this percentage.
MaxPercentageOutsideSourceBlock: 50

# What to do when a block is about to be placed outside the SourceBlock? (dontPlace, placeAnyway)
OutsideSourceBlock: placeAnyway


#######################################################################
# +-----------------------------------------------------------------+ #
# |                              Blocks                             | #
# +-----------------------------------------------------------------+ #
#######################################################################

# All the blocks used in the BO3 are listed here. Possible blocks:
# B(x,y,z,id[.data][,nbtfile.nbt)
# RB(x,y,z,id[:data][,nbtfile.nbt],chance[,id[:data][,nbtfile.nbt],chance[,...]])
# So RB(0,0,0,CHEST,chest.nbt,50,CHEST,anotherchest.nbt,100) will spawn a chest at
# the BO3 origin, and give it a 50% chance to have the contents of chest.nbt, or, if that
# fails, a 100% percent chance to have the contents of anotherchest.nbt.
B(-8,14,-4,STONE)
B(-8,14,-3,STONE)
B(-8,14,-2,STONE)
B(-8,14,-1,STONE)
B(-8,14,0,STONE)
B(-8,14,1,STONE)
B(-8,14,2,STONE)
B(-8,14,3,STONE)
B(-8,14,4,STONE)
B(-8,14,5,STONE)
B(-8,15,-6,STONE)
B(-8,15,-5,STONE)
B(-8,15,-4,STONE)
B(-8,15,-3,STONE)
B(-8,15,-2,STONE)
B(-8,15,-1,STONE)
B(-8,15,0,STONE)
B(-8,15,1,STONE)
B(-8,15,2,STONE)
B(-8,15,3,STONE)
B(-8,15,4,STONE)
B(-8,15,5,STONE)
B(-8,15,6,STONE)
B(-8,15,7,STONE)
B(-8,16,-7,STONE)
B(-8,16,-6,STONE)
B(-8,16,-5,STONE)
B(-8,16,-4,STONE)
B(-8,16,-3,STONE)
B(-8,16,-2,STONE)
B(-8,16,-1,STONE)
B(-8,16,0,STONE)
B(-8,16,1,STONE)
B(-8,16,2,STONE)
B(-8,16,3,STONE)
B(-8,16,4,STONE)
B(-8,16,5,STONE)
B(-8,16,6,STONE)
B(-8,16,7,STONE)
B(-8,16,8,STONE)
B(-8,17,-6,STONE)
B(-8,17,-5,STONE)
B(-8,17,-4,STONE)
B(-8,17,-3,STONE)
B(-8,17,-2,STONE)
B(-8,17,-1,STONE)
B(-8,17,0,STONE)
B(-8,17,1,STONE)
B(-8,17,2,STONE)
B(-8,17,3,STONE)
B(-8,17,4,STONE)
B(-8,17,5,STONE)
B(-8,17,6,STONE)
B(-8,17,7,STONE)
B(-8,18,-4,STONE)
B(-8,18,-3,STONE)
B(-8,18,-2,STONE)
B(-8,18,-1,STONE)
B(-8,18,0,STONE)
B(-8,18,1,STONE)
B(-8,18,2,STONE)
B(-8,18,3,STONE)
B(-8,18,4,STONE)
B(-8,18,5,STONE)
B(-7,12,-3,STONE)
B(-7,12,-2,STONE)
B(-7,12,-1,STONE)
B(-7,12,0,STONE)
B(-7,12,1,STONE)
B(-7,12,2,STONE)
B(-7,12,3,STONE)
B(-7,12,4,STONE)
B(-7,13,-4,STONE)
B(-7,13,-3,STONE)
B(-7,13,-2,STONE)
B(-7,13,-1,STONE)
B(-7,13,0,STONE)
B(-7,13,1,STONE)
B(-7,13,2,STONE)
B(-7,13,3,STONE)
B(-7,13,4,STONE)
B(-7,13,5,STONE)
B(-7,14,-5,STONE)
B(-7,14,-4,STONE)
B(-7,14,-3,STONE)
B(-7,14,-2,STONE)
B(-7,14,-1,STONE)
B(-7,14,0,STONE)
B(-7,14,1,STONE)
B(-7,14,2,STONE)
B(-7,14,3,STONE)
B(-7,14,4,STONE)
B(-7,14,5,STONE)
B(-7,14,6,STONE)
B(-7,14,7,STONE)
B(-7,15,-7,STONE)
B(-7,15,-6,STONE)
B(-7,15,-5,STONE)
B(-7,15,-4,STONE)
B(-7,15,-3,STONE)
B(-7,15,-2,STONE)
B(-7,15,-1,STONE)
B(-7,15,0,STONE)
B(-7,15,1,STONE)
B(-7,15,2,STONE)
B(-7,15,3,STONE)
B(-7,15,4,STONE)
B(-7,15,5,STONE)
B(-7,15,6,STONE)
B(-7,15,7,STONE)
B(-7,15,8,STONE)
B(-7,16,-7,STONE)
B(-7,16,-6,STONE)
B(-7,16,-5,STONE)
B(-7,16,-4,STONE)
B(-7,16,-3,STONE)
B(-7,16,-2,STONE)
B(-7,16,-1,STONE)
B(-7,16,0,STONE)
B(-7,16,1,STONE)
B(-7,16,2,STONE)
B(-7,16,3,STONE)
B(-7,16,4,STONE)
B(-7,16,5,STONE)
B(-7,16,6,STONE)
B(-7,16,7,STONE)
B(-7,16,8,STONE)
B(-7,17,-7,STONE)
B(-7,17,-6,STONE)
B(-7,17,-5,STONE)
B(-7,17,-4,STONE)
B(-7,17,-3,STONE)
B(-7,17,-2,STONE)
B(-7,17,-1,STONE)
B(-7,17,0,STONE)
B(-7,17,1,STONE)
B(-7,17,2,STONE)
B(-7,17,3,STONE)
B(-7,17,4,STONE)
B(-7,17,5,STONE)
B(-7,17,6,STONE)
B(-7,17,7,STONE)
B(-7,17,8,STONE)
B(-7,18,-5,STONE)
B(-7,18,-4,STONE)
B(-7,18,-3,STONE)
B(-7,18,-2,STONE)
B(-7,18,-1,STONE)
B(-7,18,0,STONE)
B(-7,18,1,STONE)
B(-7,18,2,STONE)
B(-7,18,3,STONE)
B(-7,18,4,STONE)
B(-7,18,5,STONE)
B(-7,18,6,STONE)
B(-7,19,-1,STONE)
B(-7,19,0,STONE)
B(-7,19,1,STONE)
B(-7,19,2,STONE)
B(-6,11,-2,STONE)
B(-6,11,-1,STONE)
B(-6,11,0,STONE)
B(-6,11,1,STONE)
B(-6,11,2,STONE)
B(-6,11,3,STONE)
B(-6,12,-4,STONE)
B(-6,12,-3,STONE)
B(-6,12,-2,STONE)
B(-6,12,-1,STONE)
B(-6,12,0,STONE)
B(-6,12,1,STONE)
B(-6,12,2,STONE)
B(-6,12,3,STONE)
B(-6,12,4,STONE)
B(-6,12,5,STONE)
B(-6,13,-5,STONE)
B(-6,13,-4,STONE)
B(-6,13,-3,STONE)
B(-6,13,-2,STONE)
B(-6,13,-1,STONE)
B(-6,13,0,STONE)
B(-6,13,1,STONE)
B(-6,13,2,STONE)
B(-6,13,3,STONE)
B(-6,13,4,STONE)
B(-6,13,5,STONE)
B(-6,13,6,STONE)
B(-6,14,-6,STONE)
B(-6,14,-5,STONE)
B(-6,14,-4,STONE)
B(-6,14,-3,STONE)
B(-6,14,-2,STONE)
B(-6,14,-1,STONE)
B(-6,14,0,STONE)
B(-6,14,1,STONE)
B(-6,14,2,STONE)
B(-6,14,3,STONE)
B(-6,14,4,STONE)
B(-6,14,5,STONE)
B(-6,14,6,STONE)
B(-6,14,7,STONE)
B(-6,15,-7,STONE)
B(-6,15,-6,STONE)
B(-6,15,-5,STONE)
B(-6,15,-4,STONE)
B(-6,15,-3,STONE)
B(-6,15,-2,STONE)
B(-6,15,-1,STONE)
B(-6,15,0,STONE)
B(-6,15,1,STONE)
B(-6,15,2,STONE)
B(-6,15,3,STONE)
B(-6,15,4,STONE)
B(-6,15,5,STONE)
B(-6,15,6,STONE)
B(-6,15,7,STONE)
B(-6,15,8,STONE)
B(-6,16,-7,STONE)
B(-6,16,-6,STONE)
B(-6,16,-5,STONE)
B(-6,16,-4,STONE)
B(-6,16,-3,STONE)
B(-6,16,-2,STONE)
B(-6,16,-1,STONE)
B(-6,16,0,STONE)
B(-6,16,1,STONE)
B(-6,16,2,STONE)
B(-6,16,3,STONE)
B(-6,16,4,STONE)
B(-6,16,5,STONE)
B(-6,16,6,STONE)
B(-6,16,7,STONE)
B(-6,16,8,STONE)
B(-6,17,-7,STONE)
B(-6,17,-6,STONE)
B(-6,17,-5,STONE)
B(-6,17,-4,STONE)
B(-6,17,-3,STONE)
B(-6,17,-2,STONE)
B(-6,17,-1,STONE)
B(-6,17,0,STONE)
B(-6,17,1,STONE)
B(-6,17,2,STONE)
B(-6,17,3,STONE)
B(-6,17,4,STONE)
B(-6,17,5,STONE)
B(-6,17,6,STONE)
B(-6,17,7,STONE)
B(-6,17,8,STONE)
B(-6,18,-6,STONE)
B(-6,18,-5,STONE)
B(-6,18,-4,STONE)
B(-6,18,-3,STONE)
B(-6,18,-2,STONE)
B(-6,18,-1,STONE)
B(-6,18,0,STONE)
B(-6,18,1,STONE)
B(-6,18,2,STONE)
B(-6,18,3,STONE)
B(-6,18,4,STONE)
B(-6,18,5,STONE)
B(-6,18,6,STONE)
B(-6,18,7,STONE)
B(-6,19,-5,STONE)
B(-6,19,-4,STONE)
B(-6,19,-3,STONE)
B(-6,19,-2,STONE)
B(-6,19,-1,STONE)
B(-6,19,0,STONE)
B(-6,19,1,STONE)
B(-6,19,2,STONE)
B(-6,19,3,STONE)
B(-6,19,4,STONE)
B(-6,19,5,STONE)
B(-6,19,6,STONE)
B(-6,20,-4,STONE)
B(-6,20,-3,STONE)
B(-6,20,-2,STONE)
B(-6,20,-1,STONE)
B(-6,20,0,STONE)
B(-6,20,1,STONE)
B(-6,20,2,STONE)
B(-6,20,3,STONE)
B(-6,20,4,STONE)
B(-6,20,5,STONE)
B(-6,21,-2,STONE)
B(-6,21,-1,STONE)
B(-6,21,0,STONE)
B(-6,21,1,STONE)
B(-6,21,2,STONE)
B(-6,21,3,STONE)
B(-6,22,0,STONE)
B(-5,10,-2,STONE)
B(-5,10,-1,STONE)
B(-5,10,0,STONE)
B(-5,10,1,STONE)
B(-5,10,2,STONE)
B(-5,10,3,STONE)
B(-5,11,-3,STONE)
B(-5,11,-2,STONE)
B(-5,11,-1,STONE)
B(-5,11,0,STONE)
B(-5,11,1,STONE)
B(-5,11,2,STONE)
B(-5,11,3,STONE)
B(-5,11,4,STONE)
B(-5,12,-5,STONE)
B(-5,12,-4,STONE)
B(-5,12,-3,STONE)
B(-5,12,-2,STONE)
B(-5,12,-1,STONE)
B(-5,12,0,STONE)
B(-5,12,1,STONE)
B(-5,12,2,STONE)
B(-5,12,3,STONE)
B(-5,12,4,STONE)
B(-5,12,5,STONE)
B(-5,12,6,STONE)
B(-5,13,-6,STONE)
B(-5,13,-5,STONE)
B(-5,13,-4,STONE)
B(-5,13,-3,STONE)
B(-5,13,-2,STONE)
B(-5,13,-1,STONE)
B(-5,13,0,STONE)
B(-5,13,1,STONE)
B(-5,13,2,STONE)
B(-5,13,3,STONE)
B(-5,13,4,STONE)
B(-5,13,5,STONE)
B(-5,13,6,STONE)
B(-5,13,7,STONE)
B(-5,14,-6,STONE)
B(-5,14,-5,STONE)
B(-5,14,-4,STONE)
B(-5,14,-3,STONE)
B(-5,14,-2,STONE)
B(-5,14,-1,STONE)
B(-5,14,0,STONE)
B(-5,14,1,STONE)
B(-5,14,2,STONE)
B(-5,14,3,STONE)
B(-5,14,4,STONE)
B(-5,14,5,STONE)
B(-5,14,6,STONE)
B(-5,14,7,STONE)
B(-5,15,-7,STONE)
B(-5,15,-6,STONE)
B(-5,15,-5,STONE)
B(-5,15,-4,STONE)
B(-5,15,-3,STONE)
B(-5,15,-2,STONE)
B(-5,15,-1,STONE)
B(-5,15,0,STONE)
B(-5,15,1,STONE)
B(-5,15,2,STONE)
B(-5,15,3,STONE)
B(-5,15,4,STONE)
B(-5,15,5,STONE)
B(-5,15,6,STONE)
B(-5,15,7,STONE)
B(-5,15,8,STONE)
B(-5,16,-7,STONE)
B(-5,16,-6,STONE)
B(-5,16,-5,STONE)
B(-5,16,-4,STONE)
B(-5,16,-3,STONE)
B(-5,16,-2,STONE)
B(-5,16,-1,STONE)
B(-5,16,0,STONE)
B(-5,16,1,STONE)
B(-5,16,2,STONE)
B(-5,16,3,STONE)
B(-5,16,4,STONE)
B(-5,16,5,STONE)
B(-5,16,6,STONE)
B(-5,16,7,STONE)
B(-5,16,8,STONE)
B(-5,17,-7,STONE)
B(-5,17,-6,STONE)
B(-5,17,-5,STONE)
B(-5,17,-4,STONE)
B(-5,17,-3,STONE)
B(-5,17,-2,STONE)
B(-5,17,-1,STONE)
B(-5,17,0,STONE)
B(-5,17,1,STONE)
B(-5,17,2,STONE)
B(-5,17,3,STONE)
B(-5,17,4,STONE)
B(-5,17,5,STONE)
B(-5,17,6,STONE)
B(-5,17,7,STONE)
B(-5,17,8,STONE)
B(-5,18,-7,STONE)
B(-5,18,-6,STONE)
B(-5,18,-5,STONE)
B(-5,18,-4,STONE)
B(-5,18,-3,STONE)
B(-5,18,-2,STONE)
B(-5,18,-1,STONE)
B(-5,18,0,STONE)
B(-5,18,1,STONE)
B(-5,18,2,STONE)
B(-5,18,3,STONE)
B(-5,18,4,STONE)
B(-5,18,5,STONE)
B(-5,18,6,STONE)
B(-5,18,7,STONE)
B(-5,18,8,STONE)
B(-5,19,-5,STONE)
B(-5,19,-4,STONE)
B(-5,19,-3,STONE)
B(-5,19,-2,STONE)
B(-5,19,-1,STONE)
B(-5,19,0,STONE)
B(-5,19,1,STONE)
B(-5,19,2,STONE)
B(-5,19,3,STONE)
B(-5,19,4,STONE)
B(-5,19,5,STONE)
B(-5,19,6,STONE)
B(-5,20,-5,STONE)
B(-5,20,-4,STONE)
B(-5,20,-3,STONE)
B(-5,20,-2,STONE)
B(-5,20,-1,STONE)
B(-5,20,0,STONE)
B(-5,20,1,STONE)
B(-5,20,2,STONE)
B(-5,20,3,STONE)
B(-5,20,4,STONE)
B(-5,20,5,STONE)
B(-5,20,6,STONE)
B(-5,21,-3,STONE)
B(-5,21,-2,STONE)
B(-5,21,-1,STONE)
B(-5,21,0,STONE)
B(-5,21,1,STONE)
B(-5,21,2,STONE)
B(-5,21,3,STONE)
B(-5,21,4,STONE)
B(-5,22,0,STONE)
B(-5,22,1,STONE)
B(-4,7,0,STONE)
B(-4,8,-1,STONE)
B(-4,8,0,STONE)
B(-4,8,1,STONE)
B(-4,9,-2,STONE)
B(-4,9,-1,STONE)
B(-4,9,0,STONE)
B(-4,9,1,STONE)
B(-4,9,2,STONE)
B(-4,10,-3,STONE)
B(-4,10,-2,STONE)
B(-4,10,-1,STONE)
B(-4,10,0,STONE)
B(-4,10,1,STONE)
B(-4,10,2,STONE)
B(-4,10,3,STONE)
B(-4,10,4,STONE)
B(-4,11,-4,STONE)
B(-4,11,-3,STONE)
B(-4,11,-2,STONE)
B(-4,11,-1,STONE)
B(-4,11,0,STONE)
B(-4,11,1,STONE)
B(-4,11,2,STONE)
B(-4,11,3,STONE)
B(-4,11,4,STONE)
B(-4,11,5,STONE)
B(-4,12,-6,STONE)
B(-4,12,-5,STONE)
B(-4,12,-4,STONE)
B(-4,12,-3,STONE)
B(-4,12,-2,STONE)
B(-4,12,-1,STONE)
B(-4,12,0,STONE)
B(-4,12,1,STONE)
B(-4,12,2,STONE)
B(-4,12,3,STONE)
B(-4,12,4,STONE)
B(-4,12,5,STONE)
B(-4,12,6,STONE)
B(-4,12,7,STONE)
B(-4,13,-6,STONE)
B(-4,13,-5,STONE)
B(-4,13,-4,STONE)
B(-4,13,-3,STONE)
B(-4,13,-2,STONE)
B(-4,13,-1,STONE)
B(-4,13,0,STONE)
B(-4,13,1,STONE)
B(-4,13,2,STONE)
B(-4,13,3,STONE)
B(-4,13,4,STONE)
B(-4,13,5,STONE)
B(-4,13,6,STONE)
B(-4,13,7,STONE)
B(-4,14,-6,STONE)
B(-4,14,-5,STONE)
B(-4,14,-4,STONE)
B(-4,14,-3,STONE)
B(-4,14,-2,STONE)
B(-4,14,-1,STONE)
B(-4,14,0,STONE)
B(-4,14,1,STONE)
B(-4,14,2,STONE)
B(-4,14,3,STONE)
B(-4,14,4,STONE)
B(-4,14,5,STONE)
B(-4,14,6,STONE)
B(-4,14,7,STONE)
B(-4,14,8,STONE)
B(-4,15,-7,STONE)
B(-4,15,-6,STONE)
B(-4,15,-5,STONE)
B(-4,15,-4,STONE)
B(-4,15,-3,STONE)
B(-4,15,-2,STONE)
B(-4,15,-1,STONE)
B(-4,15,0,STONE)
B(-4,15,1,STONE)
B(-4,15,2,STONE)
B(-4,15,3,STONE)
B(-4,15,4,STONE)
B(-4,15,5,STONE)
B(-4,15,6,STONE)
B(-4,15,7,STONE)
B(-4,15,8,STONE)
B(-4,16,-7,STONE)
B(-4,16,-6,STONE)
B(-4,16,-5,STONE)
B(-4,16,-4,STONE)
B(-4,16,-3,STONE)
B(-4,16,-2,STONE)
B(-4,16,-1,STONE)
B(-4,16,0,STONE)
B(-4,16,1,STONE)
B(-4,16,2,STONE)
B(-4,16,3,STONE)
B(-4,16,4,STONE)
B(-4,16,5,STONE)
B(-4,16,6,STONE)
B(-4,16,7,STONE)
B(-4,16,8,STONE)
B(-4,17,-7,STONE)
B(-4,17,-6,STONE)
B(-4,17,-5,STONE)
B(-4,17,-4,STONE)
B(-4,17,-3,STONE)
B(-4,17,-2,STONE)
B(-4,17,-1,STONE)
B(-4,17,0,STONE)
B(-4,17,1,STONE)
B(-4,17,2,STONE)
B(-4,17,3,STONE)
B(-4,17,4,STONE)
B(-4,17,5,STONE)
B(-4,17,6,STONE)
B(-4,17,7,STONE)
B(-4,17,8,STONE)
B(-4,18,-7,STONE)
B(-4,18,-6,STONE)
B(-4,18,-5,STONE)
B(-4,18,-4,STONE)
B(-4,18,-3,STONE)
B(-4,18,-2,STONE)
B(-4,18,-1,STONE)
B(-4,18,0,STONE)
B(-4,18,1,STONE)
B(-4,18,2,STONE)
B(-4,18,3,STONE)
B(-4,18,4,STONE)
B(-4,18,5,STONE)
B(-4,18,6,STONE)
B(-4,18,7,STONE)
B(-4,18,8,STONE)
B(-4,19,-6,STONE)
B(-4,19,-5,STONE)
B(-4,19,-4,STONE)
B(-4,19,-3,STONE)
B(-4,19,-2,STONE)
B(-4,19,-1,STONE)
B(-4,19,0,STONE)
B(-4,19,1,STONE)
B(-4,19,2,STONE)
B(-4,19,3,STONE)
B(-4,19,4,STONE)
B(-4,19,5,STONE)
B(-4,19,6,STONE)
B(-4,20,-5,STONE)
B(-4,20,-4,STONE)
B(-4,20,-3,STONE)
B(-4,20,-2,STONE)
B(-4,20,-1,STONE)
B(-4,20,0,STONE)
B(-4,20,1,STONE)
B(-4,20,2,STONE)
B(-4,20,3,STONE)
B(-4,20,4,STONE)
B(-4,20,5,STONE)
B(-4,20,6,STONE)
B(-4,21,-4,STONE)
B(-4,21,-3,STONE)
B(-4,21,-2,STONE)
B(-4,21,-1,STONE)
B(-4,21,0,STONE)
B(-4,21,1,STONE)
B(-4,21,2,STONE)
B(-4,21,3,STONE)
B(-4,21,4,STONE)
B(-4,21,5,STONE)
B(-4,22,-1,STONE)
B(-4,22,0,STONE)
B(-4,22,1,STONE)
B(-4,22,2,STONE)
B(-4,23,0,STONE)
B(-4,23,1,STONE)
B(-4,24,1,STONE)
B(-3,5,0,STONE)
B(-3,6,-1,STONE)
B(-3,6,0,STONE)
B(-3,6,1,STONE)
B(-3,7,-2,STONE)
B(-3,7,-1,STONE)
B(-3,7,0,STONE)
B(-3,7,1,STONE)
B(-3,7,2,STONE)
B(-3,8,-3,STONE)
B(-3,8,-2,STONE)
B(-3,8,-1,STONE)
B(-3,8,0,STONE)
B(-3,8,1,STONE)
B(-3,8,2,STONE)
B(-3,8,3,STONE)
B(-3,9,-3,STONE)
B(-3,9,-2,STONE)
B(-3,9,-1,STONE)
B(-3,9,0,STONE)
B(-3,9,1,STONE)
B(-3,9,2,STONE)
B(-3,9,3,STONE)
B(-3,10,-4,STONE)
B(-3,10,-3,STONE)
B(-3,10,-2,STONE)
B(-3,10,-1,STONE)
B(-3,10,0,STONE)
B(-3,10,1,STONE)
B(-3,10,2,STONE)
B(-3,10,3,STONE)
B(-3,10,4,STONE)
B(-3,10,5,STONE)
B(-3,11,-5,STONE)
B(-3,11,-4,STONE)
B(-3,11,-3,STONE)
B(-3,11,-2,STONE)
B(-3,11,-1,STONE)
B(-3,11,0,STONE)
B(-3,11,1,STONE)
B(-3,11,2,STONE)
B(-3,11,3,STONE)
B(-3,11,4,STONE)
B(-3,11,5,STONE)
B(-3,11,6,STONE)
B(-3,12,-6,STONE)
B(-3,12,-5,STONE)
B(-3,12,-4,STONE)
B(-3,12,-3,STONE)
B(-3,12,-2,STONE)
B(-3,12,-1,STONE)
B(-3,12,0,STONE)
B(-3,12,1,STONE)
B(-3,12,2,STONE)
B(-3,12,3,STONE)
B(-3,12,4,STONE)
B(-3,12,5,STONE)
B(-3,12,6,STONE)
B(-3,12,7,STONE)
B(-3,13,-6,STONE)
B(-3,13,-5,STONE)
B(-3,13,-4,STONE)
B(-3,13,-3,STONE)
B(-3,13,-2,STONE)
B(-3,13,-1,STONE)
B(-3,13,0,STONE)
B(-3,13,1,STONE)
B(-3,13,2,STONE)
B(-3,13,3,STONE)
B(-3,13,4,STONE)
B(-3,13,5,STONE)
B(-3,13,6,STONE)
B(-3,13,7,STONE)
B(-3,14,-7,STONE)
B(-3,14,-6,STONE)
B(-3,14,-5,STONE)
B(-3,14,-4,STONE)
B(-3,14,-3,STONE)
B(-3,14,-2,STONE)
B(-3,14,-1,STONE)
B(-3,14,0,STONE)
B(-3,14,1,STONE)
B(-3,14,2,STONE)
B(-3,14,3,STONE)
B(-3,14,4,STONE)
B(-3,14,5,STONE)
B(-3,14,6,STONE)
B(-3,14,7,STONE)
B(-3,14,8,STONE)
B(-3,15,-7,STONE)
B(-3,15,-6,STONE)
B(-3,15,-5,STONE)
B(-3,15,-4,STONE)
B(-3,15,-3,STONE)
B(-3,15,-2,STONE)
B(-3,15,-1,STONE)
B(-3,15,0,STONE)
B(-3,15,1,STONE)
B(-3,15,2,STONE)
B(-3,15,3,STONE)
B(-3,15,4,STONE)
B(-3,15,5,STONE)
B(-3,15,6,STONE)
B(-3,15,7,STONE)
B(-3,15,8,STONE)
B(-3,16,-7,STONE)
B(-3,16,-6,STONE)
B(-3,16,-5,STONE)
B(-3,16,-4,STONE)
B(-3,16,-3,STONE)
B(-3,16,-2,STONE)
B(-3,16,-1,STONE)
B(-3,16,0,STONE)
B(-3,16,1,STONE)
B(-3,16,2,STONE)
B(-3,16,3,STONE)
B(-3,16,4,STONE)
B(-3,16,5,STONE)
B(-3,16,6,STONE)
B(-3,16,7,STONE)
B(-3,16,8,STONE)
B(-3,17,-7,STONE)
B(-3,17,-6,STONE)
B(-3,17,-5,STONE)
B(-3,17,-4,STONE)
B(-3,17,-3,STONE)
B(-3,17,-2,STONE)
B(-3,17,-1,STONE)
B(-3,17,0,STONE)
B(-3,17,1,STONE)
B(-3,17,2,STONE)
B(-3,17,3,STONE)
B(-3,17,4,STONE)
B(-3,17,5,STONE)
B(-3,17,6,STONE)
B(-3,17,7,STONE)
B(-3,17,8,STONE)
B(-3,18,-7,STONE)
B(-3,18,-6,STONE)
B(-3,18,-5,STONE)
B(-3,18,-4,STONE)
B(-3,18,-3,STONE)
B(-3,18,-2,STONE)
B(-3,18,-1,STONE)
B(-3,18,0,STONE)
B(-3,18,1,STONE)
B(-3,18,2,STONE)
B(-3,18,3,STONE)
B(-3,18,4,STONE)
B(-3,18,5,STONE)
B(-3,18,6,STONE)
B(-3,18,7,STONE)
B(-3,18,8,STONE)
B(-3,19,-6,STONE)
B(-3,19,-5,STONE)
B(-3,19,-4,STONE)
B(-3,19,-3,STONE)
B(-3,19,-2,STONE)
B(-3,19,-1,STONE)
B(-3,19,0,STONE)
B(-3,19,1,STONE)
B(-3,19,2,STONE)
B(-3,19,3,STONE)
B(-3,19,4,STONE)
B(-3,19,5,STONE)
B(-3,19,6,STONE)
B(-3,20,-5,STONE)
B(-3,20,-4,STONE)
B(-3,20,-3,STONE)
B(-3,20,-2,STONE)
B(-3,20,-1,STONE)
B(-3,20,0,STONE)
B(-3,20,1,STONE)
B(-3,20,2,STONE)
B(-3,20,3,STONE)
B(-3,20,4,STONE)
B(-3,20,5,STONE)
B(-3,20,6,STONE)
B(-3,21,-5,STONE)
B(-3,21,-4,STONE)
B(-3,21,-3,STONE)
B(-3,21,-2,STONE)
B(-3,21,-1,STONE)
B(-3,21,0,STONE)
B(-3,21,1,STONE)
B(-3,21,2,STONE)
B(-3,21,3,STONE)
B(-3,21,4,STONE)
B(-3,21,5,STONE)
B(-3,21,6,STONE)
B(-3,22,-2,STONE)
B(-3,22,-1,STONE)
B(-3,22,0,STONE)
B(-3,22,1,STONE)
B(-3,22,2,STONE)
B(-3,22,3,STONE)
B(-3,23,-2,STONE)
B(-3,23,-1,STONE)
B(-3,23,0,STONE)
B(-3,23,1,STONE)
B(-3,23,2,STONE)
B(-3,23,3,STONE)
B(-3,24,0,STONE)
B(-3,24,1,STONE)
B(-3,24,2,STONE)
B(-3,25,0,STONE)
B(-2,3,0,STONE)
B(-2,4,-1,STONE)
B(-2,4,0,STONE)
B(-2,4,1,STONE)
B(-2,5,-2,STONE)
B(-2,5,-1,STONE)
B(-2,5,0,STONE)
B(-2,5,1,STONE)
B(-2,5,2,STONE)
B(-2,6,-2,STONE)
B(-2,6,-1,STONE)
B(-2,6,0,STONE)
B(-2,6,1,STONE)
B(-2,6,2,STONE)
B(-2,7,-3,STONE)
B(-2,7,-2,STONE)
B(-2,7,-1,STONE)
B(-2,7,0,STONE)
B(-2,7,1,STONE)
B(-2,7,2,STONE)
B(-2,7,3,STONE)
B(-2,8,-3,STONE)
B(-2,8,-2,STONE)
B(-2,8,-1,STONE)
B(-2,8,0,STONE)
B(-2,8,1,STONE)
B(-2,8,2,STONE)
B(-2,8,3,STONE)
B(-2,9,-4,STONE)
B(-2,9,-3,STONE)
B(-2,9,-2,STONE)
B(-2,9,-1,STONE)
B(-2,9,0,STONE)
B(-2,9,1,STONE)
B(-2,9,2,STONE)
B(-2,9,3,STONE)
B(-2,9,4,STONE)
B(-2,10,-4,STONE)
B(-2,10,-3,STONE)
B(-2,10,-2,STONE)
B(-2,10,-1,STONE)
B(-2,10,0,STONE)
B(-2,10,1,STONE)
B(-2,10,2,STONE)
B(-2,10,3,STONE)
B(-2,10,4,STONE)
B(-2,10,5,STONE)
B(-2,10,6,STONE)
B(-2,11,-5,STONE)
B(-2,11,-4,STONE)
B(-2,11,-3,STONE)
B(-2,11,-2,STONE)
B(-2,11,-1,STONE)
B(-2,11,0,STONE)
B(-2,11,1,STONE)
B(-2,11,2,STONE)
B(-2,11,3,STONE)
B(-2,11,4,STONE)
B(-2,11,5,STONE)
B(-2,11,6,STONE)
B(-2,12,-6,STONE)
B(-2,12,-5,STONE)
B(-2,12,-4,STONE)
B(-2,12,-3,STONE)
B(-2,12,-2,STONE)
B(-2,12,-1,STONE)
B(-2,12,0,STONE)
B(-2,12,1,STONE)
B(-2,12,2,STONE)
B(-2,12,3,STONE)
B(-2,12,4,STONE)
B(-2,12,5,STONE)
B(-2,12,6,STONE)
B(-2,12,7,STONE)
B(-2,13,-6,STONE)
B(-2,13,-5,STONE)
B(-2,13,-4,STONE)
B(-2,13,-3,STONE)
B(-2,13,-2,STONE)
B(-2,13,-1,STONE)
B(-2,13,0,STONE)
B(-2,13,1,STONE)
B(-2,13,2,STONE)
B(-2,13,3,STONE)
B(-2,13,4,STONE)
B(-2,13,5,STONE)
B(-2,13,6,STONE)
B(-2,13,7,STONE)
B(-2,14,-7,STONE)
B(-2,14,-6,STONE)
B(-2,14,-5,STONE)
B(-2,14,-4,STONE)
B(-2,14,-3,STONE)
B(-2,14,-2,STONE)
B(-2,14,-1,STONE)
B(-2,14,0,STONE)
B(-2,14,1,STONE)
B(-2,14,2,STONE)
B(-2,14,3,STONE)
B(-2,14,4,STONE)
B(-2,14,5,STONE)
B(-2,14,6,STONE)
B(-2,14,7,STONE)
B(-2,14,8,STONE)
B(-2,15,-7,STONE)
B(-2,15,-6,STONE)
B(-2,15,-5,STONE)
B(-2,15,-4,STONE)
B(-2,15,-3,STONE)
B(-2,15,-2,STONE)
B(-2,15,-1,STONE)
B(-2,15,0,STONE)
B(-2,15,1,STONE)
B(-2,15,2,STONE)
B(-2,15,3,STONE)
B(-2,15,4,STONE)
B(-2,15,5,STONE)
B(-2,15,6,STONE)
B(-2,15,7,STONE)
B(-2,15,8,STONE)
B(-2,16,-7,STONE)
B(-2,16,-6,STONE)
B(-2,16,-5,STONE)
B(-2,16,-4,STONE)
B(-2,16,-3,STONE)
B(-2,16,-2,STONE)
B(-2,16,-1,STONE)
B(-2,16,0,STONE)
B(-2,16,1,STONE)
B(-2,16,2,STONE)
B(-2,16,3,STONE)
B(-2,16,4,STONE)
B(-2,16,5,STONE)
B(-2,16,6,STONE)
B(-2,16,7,STONE)
B(-2,16,8,STONE)
B(-2,17,-7,STONE)
B(-2,17,-6,STONE)
B(-2,17,-5,STONE)
B(-2,17,-4,STONE)
B(-2,17,-3,STONE)
B(-2,17,-2,STONE)
B(-2,17,-1,STONE)
B(-2,17,0,STONE)
B(-2,17,1,STONE)
B(-2,17,2,STONE)
B(-2,17,3,STONE)
B(-2,17,4,STONE)
B(-2,17,5,STONE)
B(-2,17,6,STONE)
B(-2,17,7,STONE)
B(-2,17,8,STONE)
B(-2,18,-7,STONE)
B(-2,18,-6,STONE)
B(-2,18,-5,STONE)
B(-2,18,-4,STONE)
B(-2,18,-3,STONE)
B(-2,18,-2,STONE)
B(-2,18,-1,STONE)
B(-2,18,0,STONE)
B(-2,18,1,STONE)
B(-2,18,2,STONE)
B(-2,18,3,STONE)
B(-2,18,4,STONE)
B(-2,18,5,STONE)
B(-2,18,6,STONE)
B(-2,18,7,STONE)
B(-2,18,8,STONE)
B(-2,19,-6,STONE)
B(-2,19,-5,STONE)
B(-2,19,-4,STONE)
B(-2,19,-3,STONE)
B(-2,19,-2,STONE)
B(-2,19,-1,STONE)
B(-2,19,0,STONE)
B(-2,19,1,STONE)
B(-2,19,2,STONE)
B(-2,19,3,STONE)
B(-2,19,4,STONE)
B(-2,19,5,STONE)
B(-2,19,6,STONE)
B(-2,19,7,STONE)
B(-2,20,-6,STONE)
B(-2,20,-5,STONE)
B(-2,20,-4,STONE)
B(-2,20,-3,STONE)
B(-2,20,-2,STONE)
B(-2,20,-1,STONE)
B(-2,20,0,STONE)
B(-2,20,1,STONE)
B(-2,20,2,STONE)
B(-2,20,3,STONE)
B(-2,20,4,STONE)
B(-2,20,5,STONE)
B(-2,20,6,STONE)
B(-2,21,-5,STONE)
B(-2,21,-4,STONE)
B(-2,21,-3,STONE)
B(-2,21,-2,STONE)
B(-2,21,-1,STONE)
B(-2,21,0,STONE)
B(-2,21,1,STONE)
B(-2,21,2,STONE)
B(-2,21,3,STONE)
B(-2,21,4,STONE)
B(-2,21,5,STONE)
B(-2,21,6,STONE)
B(-2,22,-3,STONE)
B(-2,22,-2,STONE)
B(-2,22,-1,STONE)
B(-2,22,0,STONE)
B(-2,22,1,STONE)
B(-2,22,2,STONE)
B(-2,22,3,STONE)
B(-2,22,4,STONE)
B(-2,22,5,STONE)
B(-2,22,6,STONE)
B(-2,23,-2,STONE)
B(-2,23,-1,STONE)
B(-2,23,0,STONE)
B(-2,23,1,STONE)
B(-2,23,2,STONE)
B(-2,23,3,STONE)
B(-2,23,4,STONE)
B(-2,24,-1,STONE)
B(-2,24,0,STONE)
B(-2,24,1,STONE)
B(-2,24,2,STONE)
B(-2,25,-1,STONE)
B(-2,25,0,STONE)
B(-2,25,1,STONE)
B(-2,26,0,STONE)
B(-2,26,1,STONE)
B(-1,1,0,STONE)
B(-1,2,-1,STONE)
B(-1,2,0,STONE)
B(-1,2,1,STONE)
B(-1,3,-1,STONE)
B(-1,3,0,STONE)
B(-1,3,1,STONE)
B(-1,4,-2,STONE)
B(-1,4,-1,STONE)
B(-1,4,0,STONE)
B(-1,4,1,STONE)
B(-1,4,2,STONE)
B(-1,5,-2,STONE)
B(-1,5,-1,STONE)
B(-1,5,0,STONE)
B(-1,5,1,STONE)
B(-1,5,2,STONE)
B(-1,6,-3,STONE)
B(-1,6,-2,STONE)
B(-1,6,-1,STONE)
B(-1,6,0,STONE)
B(-1,6,1,STONE)
B(-1,6,2,STONE)
B(-1,6,3,STONE)
B(-1,7,-3,STONE)
B(-1,7,-2,STONE)
B(-1,7,-1,STONE)
B(-1,7,0,STONE)
B(-1,7,1,STONE)
B(-1,7,2,STONE)
B(-1,7,3,STONE)
B(-1,8,-4,STONE)
B(-1,8,-3,STONE)
B(-1,8,-2,STONE)
B(-1,8,-1,STONE)
B(-1,8,0,STONE)
B(-1,8,1,STONE)
B(-1,8,2,STONE)
B(-1,8,3,STONE)
B(-1,8,4,STONE)
B(-1,9,-4,STONE)
B(-1,9,-3,STONE)
B(-1,9,-2,STONE)
B(-1,9,-1,STONE)
B(-1,9,0,STONE)
B(-1,9,1,STONE)
B(-1,9,2,STONE)
B(-1,9,3,STONE)
B(-1,9,4,STONE)
B(-1,9,5,STONE)
B(-1,10,-5,STONE)
B(-1,10,-4,STONE)
B(-1,10,-3,STONE)
B(-1,10,-2,STONE)
B(-1,10,-1,STONE)
B(-1,10,0,STONE)
B(-1,10,1,STONE)
B(-1,10,2,STONE)
B(-1,10,3,STONE)
B(-1,10,4,STONE)
B(-1,10,5,STONE)
B(-1,10,6,STONE)
B(-1,11,-5,STONE)
B(-1,11,-4,STONE)
B(-1,11,-3,STONE)
B(-1,11,-2,STONE)
B(-1,11,-1,STONE)
B(-1,11,0,STONE)
B(-1,11,1,STONE)
B(-1,11,2,STONE)
B(-1,11,3,STONE)
B(-1,11,4,STONE)
B(-1,11,5,STONE)
B(-1,11,6,STONE)
B(-1,12,-6,STONE)
B(-1,12,-5,STONE)
B(-1,12,-4,STONE)
B(-1,12,-3,STONE)
B(-1,12,-2,STONE)
B(-1,12,-1,STONE)
B(-1,12,0,STONE)
B(-1,12,1,STONE)
B(-1,12,2,STONE)
B(-1,12,3,STONE)
B(-1,12,4,STONE)
B(-1,12,5,STONE)
B(-1,12,6,STONE)
B(-1,12,7,STONE)
B(-1,13,-6,STONE)
B(-1,13,-5,STONE)
B(-1,13,-4,STONE)
B(-1,13,-3,STONE)
B(-1,13,-2,STONE)
B(-1,13,-1,STONE)
B(-1,13,0,STONE)
B(-1,13,1,STONE)
B(-1,13,2,STONE)
B(-1,13,3,STONE)
B(-1,13,4,STONE)
B(-1,13,5,STONE)
B(-1,13,6,STONE)
B(-1,13,7,STONE)
B(-1,14,-7,STONE)
B(-1,14,-6,STONE)
B(-1,14,-5,STONE)
B(-1,14,-4,STONE)
B(-1,14,-3,STONE)
B(-1,14,-2,STONE)
B(-1,14,-1,STONE)
B(-1,14,0,STONE)
B(-1,14,1,STONE)
B(-1,14,2,STONE)
B(-1,14,3,STONE)
B(-1,14,4,STONE)
B(-1,14,5,STONE)
B(-1,14,6,STONE)
B(-1,14,7,STONE)
B(-1,14,8,STONE)
B(-1,15,-7,STONE)
B(-1,15,-6,STONE)
B(-1,15,-5,STONE)
B(-1,15,-4,STONE)
B(-1,15,-3,STONE)
B(-1,15,-2,STONE)
B(-1,15,-1,STONE)
B(-1,15,0,STONE)
B(-1,15,1,STONE)
B(-1,15,2,STONE)
B(-1,15,3,STONE)
B(-1,15,4,STONE)
B(-1,15,5,STONE)
B(-1,15,6,STONE)
B(-1,15,7,STONE)
B(-1,15,8,STONE)
B(-1,16,-7,STONE)
B(-1,16,-6,STONE)
B(-1,16,-5,STONE)
B(-1,16,-4,STONE)
B(-1,16,-3,STONE)
B(-1,16,-2,STONE)
B(-1,16,-1,STONE)
B(-1,16,0,STONE)
B(-1,16,1,STONE)
B(-1,16,2,STONE)
B(-1,16,3,STONE)
B(-1,16,4,STONE)
B(-1,16,5,STONE)
B(-1,16,6,STONE)
B(-1,16,7,STONE)
B(-1,16,8,STONE)
B(-1,17,-7,STONE)
B(-1,17,-6,STONE)
B(-1,17,-5,STONE)
B(-1,17,-4,STONE)
B(-1,17,-3,STONE)
B(-1,17,-2,STONE)
B(-1,17,-1,STONE)
B(-1,17,0,STONE)
B(-1,17,1,STONE)
B(-1,17,2,STONE)
B(-1,17,3,STONE)
B(-1,17,4,STONE)
B(-1,17,5,STONE)
B(-1,17,6,STONE)
B(-1,17,7,STONE)
B(-1,17,8,STONE)
B(-1,18,-7,STONE)
B(-1,18,-6,STONE)
B(-1,18,-5,STONE)
B(-1,18,-4,STONE)
B(-1,18,-3,STONE)
B(-1,18,-2,STONE)
B(-1,18,-1,STONE)
B(-1,18,0,STONE)
B(-1,18,1,STONE)
B(-1,18,2,STONE)
B(-1,18,3,STONE)
B(-1,18,4,STONE)
B(-1,18,5,STONE)
B(-1,18,6,STONE)
B(-1,18,7,STONE)
B(-1,18,8,STONE)
B(-1,19,-6,STONE)
B(-1,19,-5,STONE)
B(-1,19,-4,STONE)
B(-1,19,-3,STONE)
B(-1,19,-2,STONE)
B(-1,19,-1,STONE)
B(-1,19,0,STONE)
B(-1,19,1,STONE)
B(-1,19,2,STONE)
B(-1,19,3,STONE)
B(-1,19,4,STONE)
B(-1,19,5,STONE)
B(-1,19,6,STONE)
B(-1,19,7,STONE)
B(-1,20,-6,STONE)
B(-1,20,-5,STONE)
B(-1,20,-4,STONE)
B(-1,20,-3,STONE)
B(-1,20,-2,STONE)
B(-1,20,-1,STONE)
B(-1,20,0,STONE)
B(-1,20,1,STONE)
B(-1,20,2,STONE)
B(-1,20,3,STONE)
B(-1,20,4,STONE)
B(-1,20,5,STONE)
B(-1,20,6,STONE)
B(-1,21,-5,STONE)
B(-1,21,-4,STONE)
B(-1,21,-3,STONE)
B(-1,21,-2,STONE)
B(-1,21,-1,STONE)
B(-1,21,0,STONE)
B(-1,21,1,STONE)
B(-1,21,2,STONE)
B(-1,21,3,STONE)
B(-1,21,4,STONE)
B(-1,21,5,STONE)
B(-1,21,6,STONE)
B(-1,22,-4,STONE)
B(-1,22,-3,STONE)
B(-1,22,-2,STONE)
B(-1,22,-1,STONE)
B(-1,22,0,STONE)
B(-1,22,1,STONE)
B(-1,22,2,STONE)
B(-1,22,3,STONE)
B(-1,22,4,STONE)
B(-1,22,5,STONE)
B(-1,23,-3,STONE)
B(-1,23,-2,STONE)
B(-1,23,-1,STONE)
B(-1,23,0,STONE)
B(-1,23,1,STONE)
B(-1,23,2,STONE)
B(-1,23,3,STONE)
B(-1,24,-2,STONE)
B(-1,24,-1,STONE)
B(-1,24,0,STONE)
B(-1,24,1,STONE)
B(-1,24,2,STONE)
B(-1,24,3,STONE)
B(-1,25,-1,STONE)
B(-1,25,0,STONE)
B(-1,25,1,STONE)
B(-1,25,2,STONE)
B(-1,26,-1,STONE)
B(-1,26,0,STONE)
B(-1,26,1,STONE)
B(-1,26,2,STONE)
B(-1,27,0,STONE)
B(-1,27,1,STONE)
B(-1,28,0,STONE)
B(-1,28,1,STONE)
B(0,0,0,STONE)
B(0,1,-1,STONE)
B(0,1,0,STONE)
B(0,1,1,STONE)
B(0,2,-1,STONE)
B(0,2,0,STONE)
B(0,2,1,STONE)
B(0,3,-2,STONE)
B(0,3,-1,STONE)
B(0,3,0,STONE)
B(0,3,1,STONE)
B(0,3,2,STONE)
B(0,4,-2,STONE)
B(0,4,-1,STONE)
B(0,4,0,STONE)
B(0,4,1,STONE)
B(0,4,2,STONE)
B(0,5,-3,STONE)
B(0,5,-2,STONE)
B(0,5,-1,STONE)
B(0,5,0,STONE)
B(0,5,1,STONE)
B(0,5,2,STONE)
B(0,5,3,STONE)
B(0,6,-3,STONE)
B(0,6,-2,STONE)
B(0,6,-1,STONE)
B(0,6,0,STONE)
B(0,6,1,STONE)
B(0,6,2,STONE)
B(0,6,3,STONE)
B(0,7,-4,STONE)
B(0,7,-3,STONE)
B(0,7,-2,STONE)
B(0,7,-1,STONE)
B(0,7,0,STONE)
B(0,7,1,STONE)
B(0,7,2,STONE)
B(0,7,3,STONE)
B(0,7,4,STONE)
B(0,8,-4,STONE)
B(0,8,-3,STONE)
B(0,8,-2,STONE)
B(0,8,-1,STONE)
B(0,8,0,STONE)
B(0,8,1,STONE)
B(0,8,2,STONE)
B(0,8,3,STONE)
B(0,8,4,STONE)
B(0,9,-5,STONE)
B(0,9,-4,STONE)
B(0,9,-3,STONE)
B(0,9,-2,STONE)
B(0,9,-1,STONE)
B(0,9,0,STONE)
B(0,9,1,STONE)
B(0,9,2,STONE)
B(0,9,3,STONE)
B(0,9,4,STONE)
B(0,9,5,STONE)
B(0,9,6,STONE)
B(0,10,-5,STONE)
B(0,10,-4,STONE)
B(0,10,-3,STONE)
B(0,10,-2,STONE)
B(0,10,-1,STONE)
B(0,10,0,STONE)
B(0,10,1,STONE)
B(0,10,2,STONE)
B(0,10,3,STONE)
B(0,10,4,STONE)
B(0,10,5,STONE)
B(0,10,6,STONE)
B(0,11,-5,STONE)
B(0,11,-4,STONE)
B(0,11,-3,STONE)
B(0,11,-2,STONE)
B(0,11,-1,STONE)
B(0,11,0,STONE)
B(0,11,1,STONE)
B(0,11,2,STONE)
B(0,11,3,STONE)
B(0,11,4,STONE)
B(0,11,5,STONE)
B(0,11,6,STONE)
B(0,12,-6,STONE)
B(0,12,-5,STONE)
B(0,12,-4,STONE)
B(0,12,-3,STONE)
B(0,12,-2,STONE)
B(0,12,-1,STONE)
B(0,12,0,STONE)
B(0,12,1,STONE)
B(0,12,2,STONE)
B(0,12,3,STONE)
B(0,12,4,STONE)
B(0,12,5,STONE)
B(0,12,6,STONE)
B(0,12,7,STONE)
B(0,13,-6,STONE)
B(0,13,-5,STONE)
B(0,13,-4,STONE)
B(0,13,-3,STONE)
B(0,13,-2,STONE)
B(0,13,-1,STONE)
B(0,13,0,STONE)
B(0,13,1,STONE)
B(0,13,2,STONE)
B(0,13,3,STONE)
B(0,13,4,STONE)
B(0,13,5,STONE)
B(0,13,6,STONE)
B(0,13,7,STONE)
B(0,14,-7,STONE)
B(0,14,-6,STONE)
B(0,14,-5,STONE)
B(0,14,-4,STONE)
B(0,14,-3,STONE)
B(0,14,-2,STONE)
B(0,14,-1,STONE)
B(0,14,0,STONE)
B(0,14,1,STONE)
B(0,14,2,STONE)
B(0,14,3,STONE)
B(0,14,4,STONE)
B(0,14,5,STONE)
B(0,14,6,STONE)
B(0,14,7,STONE)
B(0,14,8,STONE)
B(0,15,-7,STONE)
B(0,15,-6,STONE)
B(0,15,-5,STONE)
B(0,15,-4,STONE)
B(0,15,-3,STONE)
B(0,15,-2,STONE)
B(0,15,-1,STONE)
B(0,15,0,STONE)
B(0,15,1,STONE)
B(0,15,2,STONE)
B(0,15,3,STONE)
B(0,15,4,STONE)
B(0,15,5,STONE)
B(0,15,6,STONE)
B(0,15,7,STONE)
B(0,15,8,STONE)
B(0,16,-7,STONE)
B(0,16,-6,STONE)
B(0,16,-5,STONE)
B(0,16,-4,STONE)
B(0,16,-3,STONE)
B(0,16,-2,STONE)
B(0,16,-1,STONE)
B(0,16,0,STONE)
B(0,16,1,STONE)
B(0,16,2,STONE)
B(0,16,3,STONE)
B(0,16,4,STONE)
B(0,16,5,STONE)
B(0,16,6,STONE)
B(0,16,7,STONE)
B(0,16,8,STONE)
B(0,17,-7,STONE)
B(0,17,-6,STONE)
B(0,17,-5,STONE)
B(0,17,-4,STONE)
B(0,17,-3,STONE)
B(0,17,-2,STONE)
B(0,17,-1,STONE)
B(0,17,0,STONE)
B(0,17,1,STONE)
B(0,17,2,STONE)
B(0,17,3,STONE)
B(0,17,4,STONE)
B(0,17,5,STONE)
B(0,17,6,STONE)
B(0,17,7,STONE)
B(0,17,8,STONE)
B(0,18,-7,STONE)
B(0,18,-6,STONE)
B(0,18,-5,STONE)
B(0,18,-4,STONE)
B(0,18,-3,STONE)
B(0,18,-2,STONE)
B(0,18,-1,STONE)
B(0,18,0,STONE)
B(0,18,1,STONE)
B(0,18,2,STONE)
B(0,18,3,STONE)
B(0,18,4,STONE)
B(0,18,5,STONE)
B(0,18,6,STONE)
B(0,18,7,STONE)
B(0,18,8,STONE)
B(0,19,-6,STONE)
B(0,19,-5,STONE)
B(0,19,-4,STONE)
B(0,19,-3,STONE)
B(0,19,-2,STONE)
B(0,19,-1,STONE)
B(0,19,0,STONE)
B(0,19,1,STONE)
B(0,19,2,STONE)
B(0,19,3,STONE)
B(0,19,4,STONE)
B(0,19,5,STONE)
B(0,19,6,STONE)
B(0,19,7,STONE)
B(0,20,-6,STONE)
B(0,20,-5,STONE)
B(0,20,-4,STONE)
B(0,20,-3,STONE)
B(0,20,-2,STONE)
B(0,20,-1,STONE)
B(0,20,0,STONE)
B(0,20,1,STONE)
B(0,20,2,STONE)
B(0,20,3,STONE)
B(0,20,4,STONE)
B(0,20,5,STONE)
B(0,20,6,STONE)
B(0,21,-5,STONE)
B(0,21,-4,STONE)
B(0,21,-3,STONE)
B(0,21,-2,STONE)
B(0,21,-1,STONE)
B(0,21,0,STONE)
B(0,21,1,STONE)
B(0,21,2,STONE)
B(0,21,3,STONE)
B(0,21,4,STONE)
B(0,21,5,STONE)
B(0,21,6,STONE)
B(0,22,-4,STONE)
B(0,22,-3,STONE)
B(0,22,-2,STONE)
B(0,22,-1,STONE)
B(0,22,0,STONE)
B(0,22,1,STONE)
B(0,22,2,STONE)
B(0,22,3,STONE)
B(0,22,4,STONE)
B(0,22,5,STONE)
B(0,23,-3,STONE)
B(0,23,-2,STONE)
B(0,23,-1,STONE)
B(0,23,0,STONE)
B(0,23,1,STONE)
B(0,23,2,STONE)
B(0,23,3,STONE)
B(0,23,4,STONE)
B(0,24,-2,STONE)
B(0,24,-1,STONE)
B(0,24,0,STONE)
B(0,24,1,STONE)
B(0,24,2,STONE)
B(0,24,3,STONE)
B(0,25,-2,STONE)
B(0,25,-1,STONE)
B(0,25,0,STONE)
B(0,25,1,STONE)
B(0,25,2,STONE)
B(0,26,-1,STONE)
B(0,26,0,STONE)
B(0,26,1,STONE)
B(0,26,2,STONE)
B(0,27,0,STONE)
B(0,27,1,STONE)
B(0,27,2,STONE)
B(0,28,0,STONE)
B(0,28,1,STONE)
B(1,1,0,STONE)
B(1,2,-1,STONE)
B(1,2,0,STONE)
B(1,2,1,STONE)
B(1,3,-1,STONE)
B(1,3,0,STONE)
B(1,3,1,STONE)
B(1,4,-2,STONE)
B(1,4,-1,STONE)
B(1,4,0,STONE)
B(1,4,1,STONE)
B(1,4,2,STONE)
B(1,5,-2,STONE)
B(1,5,-1,STONE)
B(1,5,0,STONE)
B(1,5,1,STONE)
B(1,5,2,STONE)
B(1,6,-3,STONE)
B(1,6,-2,STONE)
B(1,6,-1,STONE)
B(1,6,0,STONE)
B(1,6,1,STONE)
B(1,6,2,STONE)
B(1,6,3,STONE)
B(1,7,-3,STONE)
B(1,7,-2,STONE)
B(1,7,-1,STONE)
B(1,7,0,STONE)
B(1,7,1,STONE)
B(1,7,2,STONE)
B(1,7,3,STONE)
B(1,8,-4,STONE)
B(1,8,-3,STONE)
B(1,8,-2,STONE)
B(1,8,-1,STONE)
B(1,8,0,STONE)
B(1,8,1,STONE)
B(1,8,2,STONE)
B(1,8,3,STONE)
B(1,8,4,STONE)
B(1,9,-4,STONE)
B(1,9,-3,STONE)
B(1,9,-2,STONE)
B(1,9,-1,STONE)
B(1,9,0,STONE)
B(1,9,1,STONE)
B(1,9,2,STONE)
B(1,9,3,STONE)
B(1,9,4,STONE)
B(1,9,5,STONE)
B(1,10,-5,STONE)
B(1,10,-4,STONE)
B(1,10,-3,STONE)
B(1,10,-2,STONE)
B(1,10,-1,STONE)
B(1,10,0,STONE)
B(1,10,1,STONE)
B(1,10,2,STONE)
B(1,10,3,STONE)
B(1,10,4,STONE)
B(1,10,5,STONE)
B(1,10,6,STONE)
B(1,11,-5,STONE)
B(1,11,-4,STONE)
B(1,11,-3,STONE)
B(1,11,-2,STONE)
B(1,11,-1,STONE)
B(1,11,0,STONE)
B(1,11,1,STONE)
B(1,11,2,STONE)
B(1,11,3,STONE)
B(1,11,4,STONE)
B(1,11,5,STONE)
B(1,11,6,STONE)
B(1,12,-6,STONE)
B(1,12,-5,STONE)
B(1,12,-4,STONE)
B(1,12,-3,STONE)
B(1,12,-2,STONE)
B(1,12,-1,STONE)
B(1,12,0,STONE)
B(1,12,1,STONE)
B(1,12,2,STONE)
B(1,12,3,STONE)
B(1,12,4,STONE)
B(1,12,5,STONE)
B(1,12,6,STONE)
B(1,12,7,STONE)
B(1,13,-6,STONE)
B(1,13,-5,STONE)
B(1,13,-4,STONE)
B(1,13,-3,STONE)
B(1,13,-2,STONE)
B(1,13,-1,STONE)
B(1,13,0,STONE)
B(1,13,1,STONE)
B(1,13,2,STONE)
B(1,13,3,STONE)
B(1,13,4,STONE)
B(1,13,5,STONE)
B(1,13,6,STONE)
B(1,13,7,STONE)
B(1,14,-7,STONE)
B(1,14,-6,STONE)
B(1,14,-5,STONE)
B(1,14,-4,STONE)
B(1,14,-3,STONE)
B(1,14,-2,STONE)
B(1,14,-1,STONE)
B(1,14,0,STONE)
B(1,14,1,STONE)
B(1,14,2,STONE)
B(1,14,3,STONE)
B(1,14,4,STONE)
B(1,14,5,STONE)
B(1,14,6,STONE)
B(1,14,7,STONE)
B(1,14,8,STONE)
B(1,15,-7,STONE)
B(1,15,-6,STONE)
B(1,15,-5,STONE)
B(1,15,-4,STONE)
B(1,15,-3,STONE)
B(1,15,-2,STONE)
B(1,15,-1,STONE)
B(1,15,0,STONE)
B(1,15,1,STONE)
B(1,15,2,STONE)
B(1,15,3,STONE)
B(1,15,4,STONE)
B(1,15,5,STONE)
B(1,15,6,STONE)
B(1,15,7,STONE)
B(1,15,8,STONE)
B(1,16,-7,STONE)
B(1,16,-6,STONE)
B(1,16,-5,STONE)
B(1,16,-4,STONE)
B(1,16,-3,STONE)
B(1,16,-2,STONE)
B(1,16,-1,STONE)
B(1,16,0,STONE)
B(1,16,1,STONE)
B(1,16,2,STONE)
B(1,16,3,STONE)
B(1,16,4,STONE)
B(1,16,5,STONE)
B(1,16,6,STONE)
B(1,16,7,STONE)
B(1,16,8,STONE)
B(1,17,-7,STONE)
B(1,17,-6,STONE)
B(1,17,-5,STONE)
B(1,17,-4,STONE)
B(1,17,-3,STONE)
B(1,17,-2,STONE)
B(1,17,-1,STONE)
B(1,17,0,STONE)
B(1,17,1,STONE)
B(1,17,2,STONE)
B(1,17,3,STONE)
B(1,17,4,STONE)
B(1,17,5,STONE)
B(1,17,6,STONE)
B(1,17,7,STONE)
B(1,17,8,STONE)
B(1,18,-7,STONE)
B(1,18,-6,STONE)
B(1,18,-5,STONE)
B(1,18,-4,STONE)
B(1,18,-3,STONE)
B(1,18,-2,STONE)
B(1,18,-1,STONE)
B(1,18,0,STONE)
B(1,18,1,STONE)
B(1,18,2,STONE)
B(1,18,3,STONE)
B(1,18,4,STONE)
B(1,18,5,STONE)
B(1,18,6,STONE)
B(1,18,7,STONE)
B(1,18,8,STONE)
B(1,19,-6,STONE)
B(1,19,-5,STONE)
B(1,19,-4,STONE)
B(1,19,-3,STONE)
B(1,19,-2,STONE)
B(1,19,-1,STONE)
B(1,19,0,STONE)
B(1,19,1,STONE)
B(1,19,2,STONE)
B(1,19,3,STONE)
B(1,19,4,STONE)
B(1,19,5,STONE)
B(1,19,6,STONE)
B(1,19,7,STONE)
B(1,20,-6,STONE)
B(1,20,-5,STONE)
B(1,20,-4,STONE)
B(1,20,-3,STONE)
B(1,20,-2,STONE)
B(1,20,-1,STONE)
B(1,20,0,STONE)
B(1,20,1,STONE)
B(1,20,2,STONE)
B(1,20,3,STONE)
B(1,20,4,STONE)
B(1,20,5,STONE)
B(1,20,6,STONE)
B(1,21,-5,STONE)
B(1,21,-4,STONE)
B(1,21,-3,STONE)
B(1,21,-2,STONE)
B(1,21,-1,STONE)
B(1,21,0,STONE)
B(1,21,1,STONE)
B(1,21,2,STONE)
B(1,21,3,STONE)
B(1,21,4,STONE)
B(1,21,5,STONE)
B(1,21,6,STONE)
B(1,22,-3,STONE)
B(1,22,-2,STONE)
B(1,22,-1,STONE)
B(1,22,0,STONE)
B(1,22,1,STONE)
B(1,22,2,STONE)
B(1,22,3,STONE)
B(1,22,4,STONE)
B(1,22,5,STONE)
B(1,22,6,STONE)
B(1,23,-2,STONE)
B(1,23,-1,STONE)
B(1,23,0,STONE)
B(1,23,1,STONE)
B(1,23,2,STONE)
B(1,23,3,STONE)
B(1,23,4,STONE)
B(1,24,-1,STONE)
B(1,24,0,STONE)
B(1,24,1,STONE)
B(1,24,2,STONE)
B(1,25,-1,STONE)
B(1,25,0,STONE)
B(1,25,1,STONE)
B(1,26,0,STONE)
B(1,26,1,STONE)
B(1,27,1,STONE)
B(2,3,0,STONE)
B(2,4,-1,STONE)
B(2,4,0,STONE)
B(2,4,1,STONE)
B(2,5,-2,STONE)
B(2,5,-1,STONE)
B(2,5,0,STONE)
B(2,5,1,STONE)
B(2,5,2,STONE)
B(2,6,-2,STONE)
B(2,6,-1,STONE)
B(2,6,0,STONE)
B(2,6,1,STONE)
B(2,6,2,STONE)
B(2,7,-3,STONE)
B(2,7,-2,STONE)
B(2,7,-1,STONE)
B(2,7,0,STONE)
B(2,7,1,STONE)
B(2,7,2,STONE)
B(2,7,3,STONE)
B(2,8,-3,STONE)
B(2,8,-2,STONE)
B(2,8,-1,STONE)
B(2,8,0,STONE)
B(2,8,1,STONE)
B(2,8,2,STONE)
B(2,8,3,STONE)
B(2,9,-4,STONE)
B(2,9,-3,STONE)
B(2,9,-2,STONE)
B(2,9,-1,STONE)
B(2,9,0,STONE)
B(2,9,1,STONE)
B(2,9,2,STONE)
B(2,9,3,STONE)
B(2,9,4,STONE)
B(2,10,-4,STONE)
B(2,10,-3,STONE)
B(2,10,-2,STONE)
B(2,10,-1,STONE)
B(2,10,0,STONE)
B(2,10,1,STONE)
B(2,10,2,STONE)
B(2,10,3,STONE)
B(2,10,4,STONE)
B(2,10,5,STONE)
B(2,10,6,STONE)
B(2,11,-5,STONE)
B(2,11,-4,STONE)
B(2,11,-3,STONE)
B(2,11,-2,STONE)
B(2,11,-1,STONE)
B(2,11,0,STONE)
B(2,11,1,STONE)
B(2,11,2,STONE)
B(2,11,3,STONE)
B(2,11,4,STONE)
B(2,11,5,STONE)
B(2,11,6,STONE)
B(2,12,-6,STONE)
B(2,12,-5,STONE)
B(2,12,-4,STONE)
B(2,12,-3,STONE)
B(2,12,-2,STONE)
B(2,12,-1,STONE)
B(2,12,0,STONE)
B(2,12,1,STONE)
B(2,12,2,STONE)
B(2,12,3,STONE)
B(2,12,4,STONE)
B(2,12,5,STONE)
B(2,12,6,STONE)
B(2,12,7,STONE)
B(2,13,-6,STONE)
B(2,13,-5,STONE)
B(2,13,-4,STONE)
B(2,13,-3,STONE)
B(2,13,-2,STONE)
B(2,13,-1,STONE)
B(2,13,0,STONE)
B(2,13,1,STONE)
B(2,13,2,STONE)
B(2,13,3,STONE)
B(2,13,4,STONE)
B(2,13,5,STONE)
B(2,13,6,STONE)
B(2,13,7,STONE)
B(2,14,-7,STONE)
B(2,14,-6,STONE)
B(2,14,-5,STONE)
B(2,14,-4,STONE)
B(2,14,-3,STONE)
B(2,14,-2,STONE)
B(2,14,-1,STONE)
B(2,14,0,STONE)
B(2,14,1,STONE)
B(2,14,2,STONE)
B(2,14,3,STONE)
B(2,14,4,STONE)
B(2,14,5,STONE)
B(2,14,6,STONE)
B(2,14,7,STONE)
B(2,14,8,STONE)
B(2,15,-7,STONE)
B(2,15,-6,STONE)
B(2,15,-5,STONE)
B(2,15,-4,STONE)
B(2,15,-3,STONE)
B(2,15,-2,STONE)
B(2,15,-1,STONE)
B(2,15,0,STONE)
B(2,15,1,STONE)
B(2,15,2,STONE)
B(2,15,3,STONE)
B(2,15,4,STONE)
B(2,15,5,STONE)
B(2,15,6,STONE)
B(2,15,7,STONE)
B(2,15,8,STONE)
B(2,16,-7,STONE)
B(2,16,-6,STONE)
B(2,16,-5,STONE)
B(2,16,-4,STONE)
B(2,16,-3,STONE)
B(2,16,-2,STONE)
B(2,16,-1,STONE)
B(2,16,0,STONE)
B(2,16,1,STONE)
B(2,16,2,STONE)
B(2,16,3,STONE)
B(2,16,4,STONE)
B(2,16,5,STONE)
B(2,16,6,STONE)
B(2,16,7,STONE)
B(2,16,8,STONE)
B(2,17,-7,STONE)
B(2,17,-6,STONE)
B(2,17,-5,STONE)
B(2,17,-4,STONE)
B(2,17,-3,STONE)
B(2,17,-2,STONE)
B(2,17,-1,STONE)
B(2,17,0,STONE)
B(2,17,1,STONE)
B(2,17,2,STONE)
B(2,17,3,STONE)
B(2,17,4,STONE)
B(2,17,5,STONE)
B(2,17,6,STONE)
B(2,17,7,STONE)
B(2,17,8,STONE)
B(2,18,-7,STONE)
B(2,18,-6,STONE)
B(2,18,-5,STONE)
B(2,18,-4,STONE)
B(2,18,-3,STONE)
B(2,18,-2,STONE)
B(2,18,-1,STONE)
B(2,18,0,STONE)
B(2,18,1,STONE)
B(2,18,2,STONE)
B(2,18,3,STONE)
B(2,18,4,STONE)
B(2,18,5,STONE)
B(2,18,6,STONE)
B(2,18,7,STONE)
B(2,18,8,STONE)
B(2,19,-6,STONE)
B(2,19,-5,STONE)
B(2,19,-4,STONE)
B(2,19,-3,STONE)
B(2,19,-2,STONE)
B(2,19,-1,STONE)
B(2,19,0,STONE)
B(2,19,1,STONE)
B(2,19,2,STONE)
B(2,19,3,STONE)
B(2,19,4,STONE)
B(2,19,5,STONE)
B(2,19,6,STONE)
B(2,20,-5,STONE)
B(2,20,-4,STONE)
B(2,20,-3,STONE)
B(2,20,-2,STONE)
B(2,20,-1,STONE)
B(2,20,0,STONE)
B(2,20,1,STONE)
B(2,20,2,STONE)
B(2,20,3,STONE)
B(2,20,4,STONE)
B(2,20,5,STONE)
B(2,20,6,STONE)
B(2,21,-5,STONE)
B(2,21,-4,STONE)
B(2,21,-3,STONE)
B(2,21,-2,STONE)
B(2,21,-1,STONE)
B(2,21,0,STONE)
B(2,21,1,STONE)
B(2,21,2,STONE)
B(2,21,3,STONE)
B(2,21,4,STONE)
B(2,21,5,STONE)
B(2,21,6,STONE)
B(2,22,-2,STONE)
B(2,22,-1,STONE)
B(2,22,0,STONE)
B(2,22,1,STONE)
B(2,22,2,STONE)
B(2,22,3,STONE)
B(2,22,4,STONE)
B(2,23,-2,STONE)
B(2,23,-1,STONE)
B(2,23,0,STONE)
B(2,23,1,STONE)
B(2,23,2,STONE)
B(2,23,3,STONE)
B(2,24,0,STONE)
B(2,24,1,STONE)
B(3,5,0,STONE)
B(3,6,-1,STONE)
B(3,6,0,STONE)
B(3,6,1,STONE)
B(3,7,-2,STONE)
B(3,7,-1,STONE)
B(3,7,0,STONE)
B(3,7,1,STONE)
B(3,7,2,STONE)
B(3,8,-3,STONE)
B(3,8,-2,STONE)
B(3,8,-1,STONE)
B(3,8,0,STONE)
B(3,8,1,STONE)
B(3,8,2,STONE)
B(3,8,3,STONE)
B(3,9,-3,STONE)
B(3,9,-2,STONE)
B(3,9,-1,STONE)
B(3,9,0,STONE)
B(3,9,1,STONE)
B(3,9,2,STONE)
B(3,9,3,STONE)
B(3,10,-4,STONE)
B(3,10,-3,STONE)
B(3,10,-2,STONE)
B(3,10,-1,STONE)
B(3,10,0,STONE)
B(3,10,1,STONE)
B(3,10,2,STONE)
B(3,10,3,STONE)
B(3,10,4,STONE)
B(3,10,5,STONE)
B(3,11,-5,STONE)
B(3,11,-4,STONE)
B(3,11,-3,STONE)
B(3,11,-2,STONE)
B(3,11,-1,STONE)
B(3,11,0,STONE)
B(3,11,1,STONE)
B(3,11,2,STONE)
B(3,11,3,STONE)
B(3,11,4,STONE)
B(3,11,5,STONE)
B(3,11,6,STONE)
B(3,12,-6,STONE)
B(3,12,-5,STONE)
B(3,12,-4,STONE)
B(3,12,-3,STONE)
B(3,12,-2,STONE)
B(3,12,-1,STONE)
B(3,12,0,STONE)
B(3,12,1,STONE)
B(3,12,2,STONE)
B(3,12,3,STONE)
B(3,12,4,STONE)
B(3,12,5,STONE)
B(3,12,6,STONE)
B(3,12,7,STONE)
B(3,13,-6,STONE)
B(3,13,-5,STONE)
B(3,13,-4,STONE)
B(3,13,-3,STONE)
B(3,13,-2,STONE)
B(3,13,-1,STONE)
B(3,13,0,STONE)
B(3,13,1,STONE)
B(3,13,2,STONE)
B(3,13,3,STONE)
B(3,13,4,STONE)
B(3,13,5,STONE)
B(3,13,6,STONE)
B(3,13,7,STONE)
B(3,14,-6,STONE)
B(3,14,-5,STONE)
B(3,14,-4,STONE)
B(3,14,-3,STONE)
B(3,14,-2,STONE)
B(3,14,-1,STONE)
B(3,14,0,STONE)
B(3,14,1,STONE)
B(3,14,2,STONE)
B(3,14,3,STONE)
B(3,14,4,STONE)
B(3,14,5,STONE)
B(3,14,6,STONE)
B(3,14,7,STONE)
B(3,14,8,STONE)
B(3,15,-7,STONE)
B(3,15,-6,STONE)
B(3,15,-5,STONE)
B(3,15,-4,STONE)
B(3,15,-3,STONE)
B(3,15,-2,STONE)
B(3,15,-1,STONE)
B(3,15,0,STONE)
B(3,15,1,STONE)
B(3,15,2,STONE)
B(3,15,3,STONE)
B(3,15,4,STONE)
B(3,15,5,STONE)
B(3,15,6,STONE)
B(3,15,7,STONE)
B(3,15,8,STONE)
B(3,16,-7,STONE)
B(3,16,-6,STONE)
B(3,16,-5,STONE)
B(3,16,-4,STONE)
B(3,16,-3,STONE)
B(3,16,-2,STONE)
B(3,16,-1,STONE)
B(3,16,0,STONE)
B(3,16,1,STONE)
B(3,16,2,STONE)
B(3,16,3,STONE)
B(3,16,4,STONE)
B(3,16,5,STONE)
B(3,16,6,STONE)
B(3,16,7,STONE)
B(3,16,8,STONE)
B(3,17,-7,STONE)
B(3,17,-6,STONE)
B(3,17,-5,STONE)
B(3,17,-4,STONE)
B(3,17,-3,STONE)
B(3,17,-2,STONE)
B(3,17,-1,STONE)
B(3,17,0,STONE)
B(3,17,1,STONE)
B(3,17,2,STONE)
B(3,17,3,STONE)
B(3,17,4,STONE)
B(3,17,5,STONE)
B(3,17,6,STONE)
B(3,17,7,STONE)
B(3,17,8,STONE)
B(3,18,-7,STONE)
B(3,18,-6,STONE)
B(3,18,-5,STONE)
B(3,18,-4,STONE)
B(3,18,-3,STONE)
B(3,18,-2,STONE)
B(3,18,-1,STONE)
B(3,18,0,STONE)
B(3,18,1,STONE)
B(3,18,2,STONE)
B(3,18,3,STONE)
B(3,18,4,STONE)
B(3,18,5,STONE)
B(3,18,6,STONE)
B(3,18,7,STONE)
B(3,18,8,STONE)
B(3,19,-6,STONE)
B(3,19,-5,STONE)
B(3,19,-4,STONE)
B(3,19,-3,STONE)
B(3,19,-2,STONE)
B(3,19,-1,STONE)
B(3,19,0,STONE)
B(3,19,1,STONE)
B(3,19,2,STONE)
B(3,19,3,STONE)
B(3,19,4,STONE)
B(3,19,5,STONE)
B(3,19,6,STONE)
B(3,20,-5,STONE)
B(3,20,-4,STONE)
B(3,20,-3,STONE)
B(3,20,-2,STONE)
B(3,20,-1,STONE)
B(3,20,0,STONE)
B(3,20,1,STONE)
B(3,20,2,STONE)
B(3,20,3,STONE)
B(3,20,4,STONE)
B(3,20,5,STONE)
B(3,20,6,STONE)
B(3,21,-4,STONE)
B(3,21,-3,STONE)
B(3,21,-2,STONE)
B(3,21,-1,STONE)
B(3,21,0,STONE)
B(3,21,1,STONE)
B(3,21,2,STONE)
B(3,21,3,STONE)
B(3,21,4,STONE)
B(3,21,5,STONE)
B(3,22,-1,STONE)
B(3,22,0,STONE)
B(3,22,1,STONE)
B(3,23,0,STONE)
B(3,23,1,STONE)
B(4,7,0,STONE)
B(4,8,-1,STONE)
B(4,8,0,STONE)
B(4,8,1,STONE)
B(4,9,-2,STONE)
B(4,9,-1,STONE)
B(4,9,0,STONE)
B(4,9,1,STONE)
B(4,9,2,STONE)
B(4,10,-3,STONE)
B(4,10,-2,STONE)
B(4,10,-1,STONE)
B(4,10,0,STONE)
B(4,10,1,STONE)
B(4,10,2,STONE)
B(4,10,3,STONE)
B(4,11,-4,STONE)
B(4,11,-3,STONE)
B(4,11,-2,STONE)
B(4,11,-1,STONE)
B(4,11,0,STONE)
B(4,11,1,STONE)
B(4,11,2,STONE)
B(4,11,3,STONE)
B(4,11,4,STONE)
B(4,11,5,STONE)
B(4,12,-5,STONE)
B(4,12,-4,STONE)
B(4,12,-3,STONE)
B(4,12,-2,STONE)
B(4,12,-1,STONE)
B(4,12,0,STONE)
B(4,12,1,STONE)
B(4,12,2,STONE)
B(4,12,3,STONE)
B(4,12,4,STONE)
B(4,12,5,STONE)
B(4,12,6,STONE)
B(4,13,-6,STONE)
B(4,13,-5,STONE)
B(4,13,-4,STONE)
B(4,13,-3,STONE)
B(4,13,-2,STONE)
B(4,13,-1,STONE)
B(4,13,0,STONE)
B(4,13,1,STONE)
B(4,13,2,STONE)
B(4,13,3,STONE)
B(4,13,4,STONE)
B(4,13,5,STONE)
B(4,13,6,STONE)
B(4,13,7,STONE)
B(4,14,-6,STONE)
B(4,14,-5,STONE)
B(4,14,-4,STONE)
B(4,14,-3,STONE)
B(4,14,-2,STONE)
B(4,14,-1,STONE)
B(4,14,0,STONE)
B(4,14,1,STONE)
B(4,14,2,STONE)
B(4,14,3,STONE)
B(4,14,4,STONE)
B(4,14,5,STONE)
B(4,14,6,STONE)
B(4,14,7,STONE)
B(4,14,8,STONE)
B(4,15,-7,STONE)
B(4,15,-6,STONE)
B(4,15,-5,STONE)
B(4,15,-4,STONE)
B(4,15,-3,STONE)
B(4,15,-2,STONE)
B(4,15,-1,STONE)
B(4,15,0,STONE)
B(4,15,1,STONE)
B(4,15,2,STONE)
B(4,15,3,STONE)
B(4,15,4,STONE)
B(4,15,5,STONE)
B(4,15,6,STONE)
B(4,15,7,STONE)
B(4,15,8,STONE)
B(4,16,-7,STONE)
B(4,16,-6,STONE)
B(4,16,-5,STONE)
B(4,16,-4,STONE)
B(4,16,-3,STONE)
B(4,16,-2,STONE)
B(4,16,-1,STONE)
B(4,16,0,STONE)
B(4,16,1,STONE)
B(4,16,2,STONE)
B(4,16,3,STONE)
B(4,16,4,STONE)
B(4,16,5,STONE)
B(4,16,6,STONE)
B(4,16,7,STONE)
B(4,16,8,STONE)
B(4,17,-7,STONE)
B(4,17,-6,STONE)
B(4,17,-5,STONE)
B(4,17,-4,STONE)
B(4,17,-3,STONE)
B(4,17,-2,STONE)
B(4,17,-1,STONE)
B(4,17,0,STONE)
B(4,17,1,STONE)
B(4,17,2,STONE)
B(4,17,3,STONE)
B(4,17,4,STONE)
B(4,17,5,STONE)
B(4,17,6,STONE)
B(4,17,7,STONE)
B(4,17,8,STONE)
B(4,18,-7,STONE)
B(4,18,-6,STONE)
B(4,18,-5,STONE)
B(4,18,-4,STONE)
B(4,18,-3,STONE)
B(4,18,-2,STONE)
B(4,18,-1,STONE)
B(4,18,0,STONE)
B(4,18,1,STONE)
B(4,18,2,STONE)
B(4,18,3,STONE)
B(4,18,4,STONE)
B(4,18,5,STONE)
B(4,18,6,STONE)
B(4,18,7,STONE)
B(4,18,8,STONE)
B(4,19,-5,STONE)
B(4,19,-4,STONE)
B(4,19,-3,STONE)
B(4,19,-2,STONE)
B(4,19,-1,STONE)
B(4,19,0,STONE)
B(4,19,1,STONE)
B(4,19,2,STONE)
B(4,19,3,STONE)
B(4,19,4,STONE)
B(4,19,5,STONE)
B(4,19,6,STONE)
B(4,20,-5,STONE)
B(4,20,-4,STONE)
B(4,20,-3,STONE)
B(4,20,-2,STONE)
B(4,20,-1,STONE)
B(4,20,0,STONE)
B(4,20,1,STONE)
B(4,20,2,STONE)
B(4,20,3,STONE)
B(4,20,4,STONE)
B(4,20,5,STONE)
B(4,20,6,STONE)
B(4,21,-3,STONE)
B(4,21,-2,STONE)
B(4,21,-1,STONE)
B(4,21,0,STONE)
B(4,21,1,STONE)
B(4,21,2,STONE)
B(4,21,3,STONE)
B(4,21,4,STONE)
B(4,22,0,STONE)
B(5,9,0,STONE)
B(5,10,-1,STONE)
B(5,10,0,STONE)
B(5,10,1,STONE)
B(5,11,-3,STONE)
B(5,11,-2,STONE)
B(5,11,-1,STONE)
B(5,11,0,STONE)
B(5,11,1,STONE)
B(5,11,2,STONE)
B(5,11,3,STONE)
B(5,12,-4,STONE)
B(5,12,-3,STONE)
B(5,12,-2,STONE)
B(5,12,-1,STONE)
B(5,12,0,STONE)
B(5,12,1,STONE)
B(5,12,2,STONE)
B(5,12,3,STONE)
B(5,12,4,STONE)
B(5,12,5,STONE)
B(5,13,-5,STONE)
B(5,13,-4,STONE)
B(5,13,-3,STONE)
B(5,13,-2,STONE)
B(5,13,-1,STONE)
B(5,13,0,STONE)
B(5,13,1,STONE)
B(5,13,2,STONE)
B(5,13,3,STONE)
B(5,13,4,STONE)
B(5,13,5,STONE)
B(5,13,6,STONE)
B(5,14,-6,STONE)
B(5,14,-5,STONE)
B(5,14,-4,STONE)
B(5,14,-3,STONE)
B(5,14,-2,STONE)
B(5,14,-1,STONE)
B(5,14,0,STONE)
B(5,14,1,STONE)
B(5,14,2,STONE)
B(5,14,3,STONE)
B(5,14,4,STONE)
B(5,14,5,STONE)
B(5,14,6,STONE)
B(5,14,7,STONE)
B(5,15,-7,STONE)
B(5,15,-6,STONE)
B(5,15,-5,STONE)
B(5,15,-4,STONE)
B(5,15,-3,STONE)
B(5,15,-2,STONE)
B(5,15,-1,STONE)
B(5,15,0,STONE)
B(5,15,1,STONE)
B(5,15,2,STONE)
B(5,15,3,STONE)
B(5,15,4,STONE)
B(5,15,5,STONE)
B(5,15,6,STONE)
B(5,15,7,STONE)
B(5,15,8,STONE)
B(5,16,-7,STONE)
B(5,16,-6,STONE)
B(5,16,-5,STONE)
B(5,16,-4,STONE)
B(5,16,-3,STONE)
B(5,16,-2,STONE)
B(5,16,-1,STONE)
B(5,16,0,STONE)
B(5,16,1,STONE)
B(5,16,2,STONE)
B(5,16,3,STONE)
B(5,16,4,STONE)
B(5,16,5,STONE)
B(5,16,6,STONE)
B(5,16,7,STONE)
B(5,16,8,STONE)
B(5,17,-7,STONE)
B(5,17,-6,STONE)
B(5,17,-5,STONE)
B(5,17,-4,STONE)
B(5,17,-3,STONE)
B(5,17,-2,STONE)
B(5,17,-1,STONE)
B(5,17,0,STONE)
B(5,17,1,STONE)
B(5,17,2,STONE)
B(5,17,3,STONE)
B(5,17,4,STONE)
B(5,17,5,STONE)
B(5,17,6,STONE)
B(5,17,7,STONE)
B(5,17,8,STONE)
B(5,18,-6,STONE)
B(5,18,-5,STONE)
B(5,18,-4,STONE)
B(5,18,-3,STONE)
B(5,18,-2,STONE)
B(5,18,-1,STONE)
B(5,18,0,STONE)
B(5,18,1,STONE)
B(5,18,2,STONE)
B(5,18,3,STONE)
B(5,18,4,STONE)
B(5,18,5,STONE)
B(5,18,6,STONE)
B(5,18,7,STONE)
B(5,19,-5,STONE)
B(5,19,-4,STONE)
B(5,19,-3,STONE)
B(5,19,-2,STONE)
B(5,19,-1,STONE)
B(5,19,0,STONE)
B(5,19,1,STONE)
B(5,19,2,STONE)
B(5,19,3,STONE)
B(5,19,4,STONE)
B(5,19,5,STONE)
B(5,19,6,STONE)
B(5,20,-4,STONE)
B(5,20,-3,STONE)
B(5,20,-2,STONE)
B(5,20,-1,STONE)
B(5,20,0,STONE)
B(5,20,1,STONE)
B(5,20,2,STONE)
B(5,20,3,STONE)
B(5,20,4,STONE)
B(5,20,5,STONE)
B(5,21,-2,STONE)
B(5,21,-1,STONE)
B(5,21,0,STONE)
B(5,21,1,STONE)
B(5,21,2,STONE)
B(5,21,3,STONE)
B(6,12,-3,STONE)
B(6,12,-2,STONE)
B(6,12,-1,STONE)
B(6,12,0,STONE)
B(6,12,1,STONE)
B(6,12,2,STONE)
B(6,12,3,STONE)
B(6,13,-4,STONE)
B(6,13,-3,STONE)
B(6,13,-2,STONE)
B(6,13,-1,STONE)
B(6,13,0,STONE)
B(6,13,1,STONE)
B(6,13,2,STONE)
B(6,13,3,STONE)
B(6,13,4,STONE)
B(6,13,5,STONE)
B(6,14,-5,STONE)
B(6,14,-4,STONE)
B(6,14,-3,STONE)
B(6,14,-2,STONE)
B(6,14,-1,STONE)
B(6,14,0,STONE)
B(6,14,1,STONE)
B(6,14,2,STONE)
B(6,14,3,STONE)
B(6,14,4,STONE)
B(6,14,5,STONE)
B(6,14,6,STONE)
B(6,15,-7,STONE)
B(6,15,-6,STONE)
B(6,15,-5,STONE)
B(6,15,-4,STONE)
B(6,15,-3,STONE)
B(6,15,-2,STONE)
B(6,15,-1,STONE)
B(6,15,0,STONE)
B(6,15,1,STONE)
B(6,15,2,STONE)
B(6,15,3,STONE)
B(6,15,4,STONE)
B(6,15,5,STONE)
B(6,15,6,STONE)
B(6,15,7,STONE)
B(6,15,8,STONE)
B(6,16,-7,STONE)
B(6,16,-6,STONE)
B(6,16,-5,STONE)
B(6,16,-4,STONE)
B(6,16,-3,STONE)
B(6,16,-2,STONE)
B(6,16,-1,STONE)
B(6,16,0,STONE)
B(6,16,1,STONE)
B(6,16,2,STONE)
B(6,16,3,STONE)
B(6,16,4,STONE)
B(6,16,5,STONE)
B(6,16,6,STONE)
B(6,16,7,STONE)
B(6,16,8,STONE)
B(6,17,-7,STONE)
B(6,17,-6,STONE)
B(6,17,-5,STONE)
B(6,17,-4,STONE)
B(6,17,-3,STONE)
B(6,17,-2,STONE)
B(6,17,-1,STONE)
B(6,17,0,STONE)
B(6,17,1,STONE)
B(6,17,2,STONE)
B(6,17,3,STONE)
B(6,17,4,STONE)
B(6,17,5,STONE)
B(6,17,6,STONE)
B(6,17,7,STONE)
B(6,17,8,STONE)
B(6,18,-5,STONE)
B(6,18,-4,STONE)
B(6,18,-3,STONE)
B(6,18,-2,STONE)
B(6,18,-1,STONE)
B(6,18,0,STONE)
B(6,18,1,STONE)
B(6,18,2,STONE)
B(6,18,3,STONE)
B(6,18,4,STONE)
B(6,18,5,STONE)
B(6,18,6,STONE)
B(7,14,-3,STONE)
B(7,14,-2,STONE)
B(7,14,-1,STONE)
B(7,14,0,STONE)
B(7,14,1,STONE)
B(7,14,2,STONE)
B(7,14,3,STONE)
B(7,14,4,STONE)
B(7,15,-6,STONE)
B(7,15,-5,STONE)
B(7,15,-4,STONE)
B(7,15,-3,STONE)
B(7,15,-2,STONE)
B(7,15,-1,STONE)
B(7,15,0,STONE)
B(7,15,1,STONE)
B(7,15,2,STONE)
B(7,15,3,STONE)
B(7,15,4,STONE)
B(7,15,5,STONE)
B(7,15,6,STONE)
B(7,15,7,STONE)
B(7,16,-7,STONE)
B(7,16,-6,STONE)
B(7,16,-5,STONE)
B(7,16,-4,STONE)
B(7,16,-3,STONE)
B(7,16,-2,STONE)
B(7,16,-1,STONE)
B(7,16,0,STONE)
B(7,16,1,STONE)
B(7,16,2,STONE)
B(7,16,3,STONE)
B(7,16,4,STONE)
B(7,16,5,STONE)
B(7,16,6,STONE)
B(7,16,7,STONE)
B(7,16,8,STONE)
B(7,17,-6,STONE)
B(7,17,-5,STONE)
B(7,17,-4,STONE)
B(7,17,-3,STONE)
B(7,17,-2,STONE)
B(7,17,-1,STONE)
B(7,17,0,STONE)
B(7,17,1,STONE)
B(7,17,2,STONE)
B(7,17,3,STONE)
B(7,17,4,STONE)
B(7,17,5,STONE)
B(7,17,6,STONE)
B(7,17,7,STONE)
B(7,18,-4,STONE)
B(7,18,-3,STONE)
B(7,18,-2,STONE)
B(7,18,-1,STONE)
B(7,18,0,STONE)
B(7,18,1,STONE)
B(7,18,2,STONE)
B(7,18,3,STONE)
B(7,18,4,STONE)
B(7,18,5,STONE)

#######################################################################
# +-----------------------------------------------------------------+ #
# |                            BO3 checks                           | #
# +-----------------------------------------------------------------+ #
#######################################################################

# Require a condition at a certain location in order for the BO3 to be spawned.
# BlockCheck(x,y,z,BlockName[,BlockName[,...]]) - one of the blocks must be at the location
# BlockCheckNot(x,y,z,BlockName[,BlockName[,...]]) - all the blocks must not be at the location
# LightCheck(x,y,z,minLightLevel,maxLightLevel) - light must be between min and max (inclusive)

# You can use "Solid" as a BlockName for matching all solid blocks or "All" to match all blocks that aren't air.

# Examples:
#   BlockCheck(0,-1,0,GRASS,DIRT)  Require grass or dirt just below the object
#   BlockCheck(0,-1,0,Solid)       Require any solid block just below the object
#   BlockCheck(0,-1,0,WOOL)        Require any type of wool just below the object
#   BlockCheck(0,-1,0,WOOL:0)      Require white wool just below the object
#   BlockCheckNot(0,0,0,WOOL:0)   Require that there is no white wool below the object
#   LightCheck(0,0,0,0,1)          Require almost complete darkness just below the object
BlockCheck(0,1,0,STONE)
LightCheck(0,0,0,0,14)
#######################################################################
# +-----------------------------------------------------------------+ #
# |                             Branches                            | #
# +-----------------------------------------------------------------+ #
#######################################################################

# Branches are objects that will spawn when this object spawns when it is used in
# the CustomStructure resource. Branches can also have branches, making complex
# structures possible. See the wiki for more details.

# Regular Branches spawn each branch with an independent chance of spawning.
# Branch(x,y,z,branchName,rotation,chance[,anotherBranchName,rotation,chance[,...]][IndividualChance])
# branchName - name of the object to spawn.
# rotation - NORTH, SOUTH, EAST or WEST.
# IndividualChance - The chance each branch has to spawn, assumed to be 100 when left blank

# Weighted Branches spawn branches with a dependent chance of spawning.
# WBR(x,y,z,branchName,rotation,chance[,anotherBranchName,rotation,chance[,...]][MaxChanceOutOf])
# MaxChanceOutOf - The chance all branches have to spawn out of, assumed to be 100 when left blank
