[META]
version=2.0
spawnOnBlockType=2,3
spawnSunlight=True
spawnDarkness=True
spawnUnderground=True
spawnWater=False
spawnLava=False
underFill=False
randomRotation=True
dig=True
tree=False
branch=False
needsFoundation=True
rarity=100
collisionPercentage=100
spawnElevationMin=126
spawnElevationMax=127
spawnInBiome=Custom
spawnInBiome=Custom
[DATA]
16,-17,-5:1.0
17,-17,-5:1.0
18,-17,-5:1.0
15,-16,-5:1.0
16,-16,-5:1.0
17,-16,-5:1.0
18,-16,-5:1.0
19,-16,-5:1.0
6,-15,-5:1.0
7,-15,-5:1.0
8,-15,-5:1.0
9,-15,-5:80.0
13,-15,-5:1.0
14,-15,-5:1.0
15,-15,-5:1.0
16,-15,-5:1.0
17,-15,-5:1.0
18,-15,-5:1.0
19,-15,-5:1.0
20,-15,-5:1.0
4,-14,-5:1.0
5,-14,-5:1.0
6,-14,-5:1.0
7,-14,-5:1.0
8,-14,-5:1.0
9,-14,-5:1.0
10,-14,-5:1.0
11,-14,-5:80.0
12,-14,-5:80.0
13,-14,-5:1.0
14,-14,-5:1.0
15,-14,-5:1.0
16,-14,-5:1.0
17,-14,-5:1.0
18,-14,-5:1.0
19,-14,-5:1.0
20,-14,-5:1.0
3,-13,-5:1.0
4,-13,-5:1.0
5,-13,-5:1.0
6,-13,-5:1.0
7,-13,-5:1.0
8,-13,-5:1.0
9,-13,-5:1.0
10,-13,-5:1.0
11,-13,-5:1.0
12,-13,-5:1.0
13,-13,-5:1.0
14,-13,-5:1.0
15,-13,-5:1.0
16,-13,-5:1.0
17,-13,-5:1.0
18,-13,-5:1.0
19,-13,-5:1.0
2,-12,-5:1.0
3,-12,-5:1.0
4,-12,-5:1.0
5,-12,-5:1.0
6,-12,-5:1.0
7,-12,-5:1.0
8,-12,-5:1.0
9,-12,-5:1.0
10,-12,-5:1.0
11,-12,-5:1.0
12,-12,-5:1.0
13,-12,-5:1.0
14,-12,-5:1.0
15,-12,-5:1.0
16,-12,-5:1.0
17,-12,-5:1.0
18,-12,-5:1.0
19,-12,-5:1.0
0,-11,-5:1.0
1,-11,-5:1.0
2,-11,-5:1.0
3,-11,-5:1.0
4,-11,-5:1.0
5,-11,-5:1.0
6,-11,-5:1.0
7,-11,-5:1.0
8,-11,-5:1.0
9,-11,-5:1.0
10,-11,-5:1.0
11,-11,-5:1.0
12,-11,-5:1.0
13,-11,-5:1.0
14,-11,-5:1.0
15,-11,-5:1.0
16,-11,-5:1.0
17,-11,-5:1.0
18,-11,-5:1.0
19,-11,-5:1.0
-1,-10,-5:1.0
0,-10,-5:1.0
1,-10,-5:1.0
2,-10,-5:1.0
3,-10,-5:1.0
4,-10,-5:1.0
5,-10,-5:1.0
6,-10,-5:1.0
7,-10,-5:1.0
8,-10,-5:1.0
9,-10,-5:1.0
10,-10,-5:1.0
11,-10,-5:1.0
12,-10,-5:1.0
13,-10,-5:1.0
14,-10,-5:1.0
15,-10,-5:1.0
16,-10,-5:1.0
17,-10,-5:1.0
18,-10,-5:1.0
19,-10,-5:1.0
-1,-9,-5:1.0
0,-9,-5:1.0
1,-9,-5:1.0
2,-9,-5:1.0
3,-9,-5:1.0
4,-9,-5:1.0
5,-9,-5:1.0
6,-9,-5:1.0
7,-9,-5:1.0
8,-9,-5:1.0
9,-9,-5:1.0
10,-9,-5:1.0
11,-9,-5:1.0
12,-9,-5:1.0
13,-9,-5:1.0
14,-9,-5:1.0
15,-9,-5:1.0
16,-9,-5:1.0
17,-9,-5:1.0
18,-9,-5:1.0
19,-9,-5:1.0
-1,-8,-5:1.0
0,-8,-5:1.0
1,-8,-5:1.0
2,-8,-5:1.0
3,-8,-5:1.0
4,-8,-5:1.0
5,-8,-5:1.0
6,-8,-5:1.0
7,-8,-5:1.0
8,-8,-5:1.0
9,-8,-5:1.0
10,-8,-5:1.0
11,-8,-5:1.0
12,-8,-5:1.0
13,-8,-5:1.0
14,-8,-5:1.0
15,-8,-5:1.0
16,-8,-5:1.0
17,-8,-5:1.0
18,-8,-5:1.0
-1,-7,-5:1.0
0,-7,-5:1.0
1,-7,-5:1.0
2,-7,-5:1.0
3,-7,-5:1.0
4,-7,-5:1.0
5,-7,-5:1.0
6,-7,-5:1.0
7,-7,-5:1.0
8,-7,-5:1.0
9,-7,-5:1.0
10,-7,-5:1.0
11,-7,-5:1.0
12,-7,-5:1.0
13,-7,-5:1.0
14,-7,-5:1.0
15,-7,-5:1.0
16,-7,-5:1.0
17,-7,-5:1.0
18,-7,-5:1.0
-2,-6,-5:1.0
-1,-6,-5:1.0
0,-6,-5:1.0
1,-6,-5:1.0
2,-6,-5:1.0
3,-6,-5:1.0
4,-6,-5:1.0
5,-6,-5:1.0
6,-6,-5:1.0
7,-6,-5:1.0
8,-6,-5:1.0
9,-6,-5:1.0
10,-6,-5:1.0
11,-6,-5:1.0
12,-6,-5:1.0
13,-6,-5:1.0
14,-6,-5:1.0
15,-6,-5:1.0
16,-6,-5:1.0
17,-6,-5:1.0
-3,-5,-5:1.0
-2,-5,-5:1.0
-1,-5,-5:1.0
0,-5,-5:1.0
1,-5,-5:1.0
2,-5,-5:1.0
3,-5,-5:1.0
4,-5,-5:1.0
5,-5,-5:1.0
6,-5,-5:1.0
7,-5,-5:1.0
8,-5,-5:1.0
9,-5,-5:1.0
10,-5,-5:1.0
11,-5,-5:1.0
12,-5,-5:1.0
13,-5,-5:1.0
14,-5,-5:1.0
15,-5,-5:1.0
16,-5,-5:1.0
17,-5,-5:1.0
-5,-4,-5:1.0
-4,-4,-5:1.0
-3,-4,-5:1.0
-2,-4,-5:1.0
-1,-4,-5:1.0
0,-4,-5:1.0
1,-4,-5:1.0
2,-4,-5:1.0
3,-4,-5:1.0
4,-4,-5:1.0
5,-4,-5:1.0
6,-4,-5:1.0
7,-4,-5:1.0
8,-4,-5:1.0
9,-4,-5:1.0
10,-4,-5:1.0
11,-4,-5:1.0
12,-4,-5:1.0
13,-4,-5:1.0
14,-4,-5:1.0
15,-4,-5:1.0
16,-4,-5:1.0
-5,-3,-5:1.0
-4,-3,-5:1.0
-3,-3,-5:1.0
-2,-3,-5:1.0
-1,-3,-5:1.0
0,-3,-5:1.0
1,-3,-5:1.0
2,-3,-5:1.0
3,-3,-5:1.0
4,-3,-5:1.0
5,-3,-5:1.0
6,-3,-5:1.0
7,-3,-5:1.0
8,-3,-5:1.0
9,-3,-5:1.0
10,-3,-5:1.0
11,-3,-5:1.0
12,-3,-5:1.0
13,-3,-5:1.0
14,-3,-5:1.0
15,-3,-5:1.0
-5,-2,-5:1.0
-4,-2,-5:1.0
-3,-2,-5:1.0
-2,-2,-5:1.0
-1,-2,-5:1.0
0,-2,-5:1.0
1,-2,-5:1.0
2,-2,-5:1.0
3,-2,-5:1.0
4,-2,-5:1.0
5,-2,-5:1.0
6,-2,-5:1.0
7,-2,-5:1.0
8,-2,-5:1.0
9,-2,-5:1.0
10,-2,-5:1.0
11,-2,-5:1.0
12,-2,-5:1.0
13,-2,-5:1.0
14,-2,-5:1.0
-6,-1,-5:1.0
-5,-1,-5:1.0
-4,-1,-5:1.0
-3,-1,-5:1.0
-2,-1,-5:1.0
-1,-1,-5:1.0
0,-1,-5:1.0
1,-1,-5:1.0
2,-1,-5:1.0
3,-1,-5:1.0
4,-1,-5:1.0
5,-1,-5:1.0
6,-1,-5:1.0
7,-1,-5:1.0
8,-1,-5:1.0
9,-1,-5:1.0
10,-1,-5:1.0
11,-1,-5:1.0
12,-1,-5:1.0
13,-1,-5:1.0
-6,0,-5:1.0
-5,0,-5:1.0
-4,0,-5:1.0
-3,0,-5:1.0
-2,0,-5:1.0
-1,0,-5:1.0
0,0,-5:1.0
1,0,-5:1.0
2,0,-5:1.0
3,0,-5:1.0
4,0,-5:1.0
5,0,-5:1.0
6,0,-5:1.0
7,0,-5:1.0
8,0,-5:1.0
9,0,-5:1.0
10,0,-5:1.0
11,0,-5:1.0
12,0,-5:1.0
-9,1,-5:1.0
-8,1,-5:1.0
-7,1,-5:1.0
-6,1,-5:1.0
-5,1,-5:1.0
-4,1,-5:1.0
-3,1,-5:1.0
-2,1,-5:1.0
-1,1,-5:1.0
0,1,-5:1.0
1,1,-5:1.0
2,1,-5:1.0
3,1,-5:1.0
4,1,-5:1.0
5,1,-5:1.0
6,1,-5:1.0
7,1,-5:1.0
8,1,-5:1.0
9,1,-5:1.0
10,1,-5:1.0
11,1,-5:1.0
-10,2,-5:1.0
-9,2,-5:1.0
-8,2,-5:1.0
-7,2,-5:1.0
-6,2,-5:1.0
-5,2,-5:1.0
-4,2,-5:1.0
-3,2,-5:1.0
-2,2,-5:1.0
-1,2,-5:1.0
0,2,-5:1.0
1,2,-5:1.0
2,2,-5:1.0
3,2,-5:1.0
4,2,-5:1.0
5,2,-5:1.0
6,2,-5:1.0
7,2,-5:1.0
8,2,-5:1.0
9,2,-5:1.0
10,2,-5:1.0
11,2,-5:1.0
-11,3,-5:1.0
-10,3,-5:1.0
-9,3,-5:1.0
-8,3,-5:1.0
-7,3,-5:1.0
-6,3,-5:1.0
-5,3,-5:1.0
-4,3,-5:1.0
-3,3,-5:1.0
-2,3,-5:1.0
-1,3,-5:1.0
0,3,-5:1.0
1,3,-5:1.0
2,3,-5:1.0
3,3,-5:1.0
4,3,-5:1.0
5,3,-5:1.0
6,3,-5:1.0
7,3,-5:1.0
8,3,-5:1.0
9,3,-5:1.0
10,3,-5:1.0
11,3,-5:1.0
-12,4,-5:1.0
-11,4,-5:1.0
-10,4,-5:1.0
-9,4,-5:1.0
-8,4,-5:1.0
-7,4,-5:1.0
-6,4,-5:1.0
-5,4,-5:1.0
-4,4,-5:1.0
-3,4,-5:1.0
-2,4,-5:1.0
-1,4,-5:1.0
0,4,-5:1.0
1,4,-5:1.0
2,4,-5:1.0
3,4,-5:1.0
4,4,-5:1.0
5,4,-5:1.0
6,4,-5:1.0
7,4,-5:1.0
8,4,-5:1.0
9,4,-5:1.0
10,4,-5:1.0
11,4,-5:80.0
-12,5,-5:1.0
-11,5,-5:1.0
-10,5,-5:1.0
-9,5,-5:1.0
-8,5,-5:1.0
-7,5,-5:1.0
-6,5,-5:1.0
-5,5,-5:1.0
-4,5,-5:1.0
-3,5,-5:1.0
-2,5,-5:1.0
-1,5,-5:1.0
0,5,-5:1.0
1,5,-5:1.0
2,5,-5:1.0
3,5,-5:1.0
4,5,-5:1.0
5,5,-5:1.0
6,5,-5:1.0
7,5,-5:1.0
-12,6,-5:1.0
-11,6,-5:1.0
-10,6,-5:1.0
-9,6,-5:1.0
-8,6,-5:1.0
-7,6,-5:1.0
-6,6,-5:1.0
-5,6,-5:1.0
-4,6,-5:1.0
-3,6,-5:1.0
-2,6,-5:1.0
-1,6,-5:1.0
0,6,-5:1.0
1,6,-5:1.0
2,6,-5:1.0
3,6,-5:1.0
4,6,-5:1.0
5,6,-5:1.0
-13,7,-5:1.0
-12,7,-5:1.0
-11,7,-5:1.0
-10,7,-5:1.0
-9,7,-5:1.0
-8,7,-5:1.0
-7,7,-5:1.0
-6,7,-5:1.0
-5,7,-5:1.0
-4,7,-5:1.0
-3,7,-5:1.0
-2,7,-5:1.0
-1,7,-5:1.0
0,7,-5:1.0
1,7,-5:1.0
2,7,-5:1.0
3,7,-5:1.0
4,7,-5:80.0
-13,8,-5:1.0
-12,8,-5:1.0
-11,8,-5:1.0
-10,8,-5:1.0
-9,8,-5:1.0
-8,8,-5:1.0
-7,8,-5:1.0
-6,8,-5:1.0
-5,8,-5:1.0
-4,8,-5:1.0
-3,8,-5:1.0
-2,8,-5:1.0
-1,8,-5:80.0
-13,9,-5:1.0
-12,9,-5:1.0
-11,9,-5:1.0
-10,9,-5:1.0
-9,9,-5:1.0
-8,9,-5:1.0
-7,9,-5:1.0
-6,9,-5:1.0
-5,9,-5:80.0
-13,10,-5:1.0
-12,10,-5:1.0
-11,10,-5:1.0
-10,10,-5:1.0
-9,10,-5:1.0
-8,10,-5:1.0
-7,10,-5:1.0
-12,11,-5:1.0
-11,11,-5:1.0
-10,11,-5:1.0
-9,11,-5:1.0
-8,11,-5:1.0
16,-17,-4:1.0
17,-17,-4:1.0
18,-17,-4:1.0
15,-16,-4:1.0
16,-16,-4:1.0
17,-16,-4:1.0
18,-16,-4:1.0
19,-16,-4:1.0
6,-15,-4:1.0
7,-15,-4:1.0
8,-15,-4:1.0
9,-15,-4:80.0
13,-15,-4:1.0
14,-15,-4:1.0
15,-15,-4:1.0
16,-15,-4:1.0
17,-15,-4:1.0
18,-15,-4:1.0
19,-15,-4:1.0
20,-15,-4:1.0
4,-14,-4:1.0
5,-14,-4:1.0
6,-14,-4:1.0
7,-14,-4:1.0
8,-14,-4:1.0
9,-14,-4:1.0
10,-14,-4:1.0
11,-14,-4:80.0
12,-14,-4:80.0
13,-14,-4:1.0
14,-14,-4:1.0
15,-14,-4:1.0
16,-14,-4:1.0
17,-14,-4:1.0
18,-14,-4:1.0
19,-14,-4:1.0
20,-14,-4:1.0
3,-13,-4:1.0
4,-13,-4:1.0
5,-13,-4:1.0
6,-13,-4:1.0
7,-13,-4:1.0
8,-13,-4:1.0
9,-13,-4:1.0
10,-13,-4:1.0
11,-13,-4:1.0
12,-13,-4:1.0
13,-13,-4:1.0
14,-13,-4:1.0
15,-13,-4:1.0
16,-13,-4:1.0
17,-13,-4:1.0
18,-13,-4:1.0
19,-13,-4:1.0
2,-12,-4:1.0
3,-12,-4:1.0
4,-12,-4:1.0
5,-12,-4:1.0
6,-12,-4:1.0
7,-12,-4:1.0
8,-12,-4:1.0
9,-12,-4:1.0
10,-12,-4:1.0
11,-12,-4:1.0
12,-12,-4:1.0
13,-12,-4:1.0
14,-12,-4:1.0
15,-12,-4:1.0
16,-12,-4:1.0
17,-12,-4:1.0
18,-12,-4:1.0
19,-12,-4:1.0
0,-11,-4:1.0
1,-11,-4:1.0
2,-11,-4:1.0
3,-11,-4:1.0
4,-11,-4:1.0
5,-11,-4:1.0
6,-11,-4:1.0
7,-11,-4:1.0
8,-11,-4:1.0
9,-11,-4:1.0
10,-11,-4:1.0
11,-11,-4:1.0
12,-11,-4:1.0
13,-11,-4:1.0
14,-11,-4:1.0
15,-11,-4:1.0
16,-11,-4:1.0
17,-11,-4:1.0
18,-11,-4:1.0
19,-11,-4:1.0
-1,-10,-4:1.0
0,-10,-4:1.0
1,-10,-4:1.0
2,-10,-4:1.0
3,-10,-4:1.0
4,-10,-4:1.0
5,-10,-4:1.0
6,-10,-4:1.0
7,-10,-4:1.0
8,-10,-4:1.0
9,-10,-4:1.0
10,-10,-4:1.0
11,-10,-4:1.0
12,-10,-4:1.0
13,-10,-4:1.0
14,-10,-4:1.0
15,-10,-4:1.0
16,-10,-4:1.0
17,-10,-4:1.0
18,-10,-4:1.0
19,-10,-4:1.0
-1,-9,-4:1.0
0,-9,-4:1.0
1,-9,-4:1.0
2,-9,-4:1.0
3,-9,-4:1.0
4,-9,-4:1.0
5,-9,-4:1.0
6,-9,-4:1.0
7,-9,-4:1.0
8,-9,-4:1.0
9,-9,-4:1.0
10,-9,-4:1.0
11,-9,-4:1.0
12,-9,-4:1.0
13,-9,-4:1.0
14,-9,-4:1.0
15,-9,-4:1.0
16,-9,-4:1.0
17,-9,-4:1.0
18,-9,-4:1.0
19,-9,-4:1.0
-1,-8,-4:1.0
0,-8,-4:1.0
1,-8,-4:1.0
2,-8,-4:1.0
3,-8,-4:1.0
4,-8,-4:1.0
5,-8,-4:1.0
6,-8,-4:1.0
7,-8,-4:1.0
8,-8,-4:1.0
9,-8,-4:1.0
10,-8,-4:1.0
11,-8,-4:1.0
12,-8,-4:1.0
13,-8,-4:1.0
14,-8,-4:1.0
15,-8,-4:1.0
16,-8,-4:1.0
17,-8,-4:1.0
18,-8,-4:1.0
-1,-7,-4:1.0
0,-7,-4:1.0
1,-7,-4:1.0
2,-7,-4:1.0
3,-7,-4:1.0
4,-7,-4:1.0
5,-7,-4:1.0
6,-7,-4:1.0
7,-7,-4:1.0
8,-7,-4:1.0
9,-7,-4:1.0
10,-7,-4:1.0
11,-7,-4:1.0
12,-7,-4:1.0
13,-7,-4:1.0
14,-7,-4:1.0
15,-7,-4:1.0
16,-7,-4:1.0
17,-7,-4:1.0
18,-7,-4:1.0
-2,-6,-4:1.0
-1,-6,-4:1.0
0,-6,-4:1.0
1,-6,-4:1.0
2,-6,-4:1.0
3,-6,-4:1.0
4,-6,-4:1.0
5,-6,-4:1.0
6,-6,-4:1.0
7,-6,-4:1.0
8,-6,-4:1.0
9,-6,-4:1.0
10,-6,-4:1.0
11,-6,-4:1.0
12,-6,-4:1.0
13,-6,-4:1.0
14,-6,-4:1.0
15,-6,-4:1.0
16,-6,-4:1.0
17,-6,-4:1.0
-3,-5,-4:1.0
-2,-5,-4:1.0
-1,-5,-4:1.0
0,-5,-4:1.0
1,-5,-4:1.0
2,-5,-4:1.0
3,-5,-4:1.0
4,-5,-4:1.0
5,-5,-4:1.0
6,-5,-4:1.0
7,-5,-4:1.0
8,-5,-4:1.0
9,-5,-4:1.0
10,-5,-4:1.0
11,-5,-4:1.0
12,-5,-4:1.0
13,-5,-4:1.0
14,-5,-4:1.0
15,-5,-4:1.0
16,-5,-4:1.0
17,-5,-4:1.0
-5,-4,-4:1.0
-4,-4,-4:1.0
-3,-4,-4:1.0
-2,-4,-4:1.0
-1,-4,-4:1.0
0,-4,-4:1.0
1,-4,-4:1.0
2,-4,-4:1.0
3,-4,-4:1.0
4,-4,-4:1.0
5,-4,-4:1.0
6,-4,-4:1.0
7,-4,-4:1.0
8,-4,-4:1.0
9,-4,-4:1.0
10,-4,-4:1.0
11,-4,-4:1.0
12,-4,-4:1.0
13,-4,-4:1.0
14,-4,-4:1.0
15,-4,-4:1.0
16,-4,-4:1.0
-5,-3,-4:1.0
-4,-3,-4:1.0
-3,-3,-4:1.0
-2,-3,-4:1.0
-1,-3,-4:1.0
0,-3,-4:1.0
1,-3,-4:1.0
2,-3,-4:1.0
3,-3,-4:1.0
4,-3,-4:1.0
5,-3,-4:1.0
6,-3,-4:1.0
7,-3,-4:1.0
8,-3,-4:1.0
9,-3,-4:1.0
10,-3,-4:1.0
11,-3,-4:1.0
12,-3,-4:1.0
13,-3,-4:1.0
14,-3,-4:1.0
15,-3,-4:1.0
-5,-2,-4:1.0
-4,-2,-4:1.0
-3,-2,-4:1.0
-2,-2,-4:1.0
-1,-2,-4:1.0
0,-2,-4:1.0
1,-2,-4:1.0
2,-2,-4:1.0
3,-2,-4:1.0
4,-2,-4:1.0
5,-2,-4:1.0
6,-2,-4:1.0
7,-2,-4:1.0
8,-2,-4:1.0
9,-2,-4:1.0
10,-2,-4:1.0
11,-2,-4:1.0
12,-2,-4:1.0
13,-2,-4:1.0
14,-2,-4:1.0
-6,-1,-4:1.0
-5,-1,-4:1.0
-4,-1,-4:1.0
-3,-1,-4:1.0
-2,-1,-4:1.0
-1,-1,-4:1.0
0,-1,-4:1.0
1,-1,-4:1.0
2,-1,-4:1.0
3,-1,-4:1.0
4,-1,-4:1.0
5,-1,-4:1.0
6,-1,-4:1.0
7,-1,-4:1.0
8,-1,-4:1.0
9,-1,-4:1.0
10,-1,-4:1.0
11,-1,-4:1.0
12,-1,-4:1.0
13,-1,-4:1.0
-6,0,-4:1.0
-5,0,-4:1.0
-4,0,-4:1.0
-3,0,-4:1.0
-2,0,-4:1.0
-1,0,-4:1.0
0,0,-4:1.0
1,0,-4:1.0
2,0,-4:1.0
3,0,-4:1.0
4,0,-4:1.0
5,0,-4:1.0
6,0,-4:1.0
7,0,-4:1.0
8,0,-4:1.0
9,0,-4:1.0
10,0,-4:1.0
11,0,-4:1.0
12,0,-4:1.0
-9,1,-4:1.0
-8,1,-4:1.0
-7,1,-4:1.0
-6,1,-4:1.0
-5,1,-4:1.0
-4,1,-4:1.0
-3,1,-4:1.0
-2,1,-4:1.0
-1,1,-4:1.0
0,1,-4:1.0
1,1,-4:1.0
2,1,-4:1.0
3,1,-4:1.0
4,1,-4:1.0
5,1,-4:1.0
6,1,-4:1.0
7,1,-4:1.0
8,1,-4:1.0
9,1,-4:1.0
10,1,-4:1.0
11,1,-4:1.0
-10,2,-4:1.0
-9,2,-4:1.0
-8,2,-4:1.0
-7,2,-4:1.0
-6,2,-4:1.0
-5,2,-4:1.0
-4,2,-4:1.0
-3,2,-4:1.0
-2,2,-4:1.0
-1,2,-4:1.0
0,2,-4:1.0
1,2,-4:1.0
2,2,-4:1.0
3,2,-4:1.0
4,2,-4:1.0
5,2,-4:1.0
6,2,-4:1.0
7,2,-4:1.0
8,2,-4:1.0
9,2,-4:1.0
10,2,-4:1.0
11,2,-4:1.0
-11,3,-4:1.0
-10,3,-4:1.0
-9,3,-4:1.0
-8,3,-4:1.0
-7,3,-4:1.0
-6,3,-4:1.0
-5,3,-4:1.0
-4,3,-4:1.0
-3,3,-4:1.0
-2,3,-4:1.0
-1,3,-4:1.0
0,3,-4:1.0
1,3,-4:1.0
2,3,-4:1.0
3,3,-4:1.0
4,3,-4:1.0
5,3,-4:1.0
6,3,-4:1.0
7,3,-4:1.0
8,3,-4:1.0
9,3,-4:1.0
10,3,-4:1.0
11,3,-4:1.0
-12,4,-4:1.0
-11,4,-4:1.0
-10,4,-4:1.0
-9,4,-4:1.0
-8,4,-4:1.0
-7,4,-4:1.0
-6,4,-4:1.0
-5,4,-4:1.0
-4,4,-4:1.0
-3,4,-4:1.0
-2,4,-4:1.0
-1,4,-4:1.0
0,4,-4:1.0
1,4,-4:1.0
2,4,-4:1.0
3,4,-4:1.0
4,4,-4:1.0
5,4,-4:1.0
6,4,-4:1.0
7,4,-4:1.0
8,4,-4:1.0
9,4,-4:1.0
10,4,-4:1.0
11,4,-4:80.0
-12,5,-4:1.0
-11,5,-4:1.0
-10,5,-4:1.0
-9,5,-4:1.0
-8,5,-4:1.0
-7,5,-4:1.0
-6,5,-4:1.0
-5,5,-4:1.0
-4,5,-4:1.0
-3,5,-4:1.0
-2,5,-4:1.0
-1,5,-4:1.0
0,5,-4:1.0
1,5,-4:1.0
2,5,-4:1.0
3,5,-4:1.0
4,5,-4:1.0
5,5,-4:1.0
6,5,-4:1.0
7,5,-4:1.0
-12,6,-4:1.0
-11,6,-4:1.0
-10,6,-4:1.0
-9,6,-4:1.0
-8,6,-4:1.0
-7,6,-4:1.0
-6,6,-4:1.0
-5,6,-4:1.0
-4,6,-4:1.0
-3,6,-4:1.0
-2,6,-4:1.0
-1,6,-4:1.0
0,6,-4:1.0
1,6,-4:1.0
2,6,-4:1.0
3,6,-4:1.0
4,6,-4:1.0
5,6,-4:1.0
-13,7,-4:1.0
-12,7,-4:1.0
-11,7,-4:1.0
-10,7,-4:1.0
-9,7,-4:1.0
-8,7,-4:1.0
-7,7,-4:1.0
-6,7,-4:1.0
-5,7,-4:1.0
-4,7,-4:1.0
-3,7,-4:1.0
-2,7,-4:1.0
-1,7,-4:1.0
0,7,-4:1.0
1,7,-4:1.0
2,7,-4:1.0
3,7,-4:80.0
4,7,-4:80.0
-13,8,-4:1.0
-12,8,-4:1.0
-11,8,-4:1.0
-10,8,-4:1.0
-9,8,-4:1.0
-8,8,-4:1.0
-7,8,-4:1.0
-6,8,-4:1.0
-5,8,-4:1.0
-4,8,-4:1.0
-3,8,-4:1.0
-2,8,-4:1.0
-1,8,-4:80.0
-13,9,-4:1.0
-12,9,-4:1.0
-11,9,-4:1.0
-10,9,-4:1.0
-9,9,-4:1.0
-8,9,-4:1.0
-7,9,-4:1.0
-6,9,-4:1.0
-5,9,-4:80.0
-13,10,-4:1.0
-12,10,-4:1.0
-11,10,-4:1.0
-10,10,-4:1.0
-9,10,-4:1.0
-8,10,-4:1.0
-7,10,-4:1.0
-12,11,-4:1.0
-11,11,-4:1.0
-10,11,-4:1.0
-9,11,-4:1.0
-8,11,-4:1.0
16,-17,-3:1.0
17,-17,-3:1.0
15,-16,-3:1.0
16,-16,-3:1.0
17,-16,-3:1.0
18,-16,-3:1.0
19,-16,-3:1.0
6,-15,-3:1.0
7,-15,-3:80.0
8,-15,-3:1.0
9,-15,-3:80.0
13,-15,-3:1.0
14,-15,-3:1.0
15,-15,-3:1.0
16,-15,-3:1.0
17,-15,-3:1.0
18,-15,-3:1.0
19,-15,-3:1.0
20,-15,-3:1.0
4,-14,-3:1.0
5,-14,-3:1.0
6,-14,-3:1.0
7,-14,-3:1.0
8,-14,-3:1.0
9,-14,-3:1.0
10,-14,-3:1.0
11,-14,-3:80.0
12,-14,-3:80.0
13,-14,-3:1.0
14,-14,-3:1.0
15,-14,-3:1.0
16,-14,-3:1.0
17,-14,-3:1.0
18,-14,-3:1.0
19,-14,-3:1.0
20,-14,-3:1.0
3,-13,-3:1.0
4,-13,-3:1.0
5,-13,-3:1.0
6,-13,-3:1.0
7,-13,-3:1.0
8,-13,-3:1.0
9,-13,-3:1.0
10,-13,-3:1.0
11,-13,-3:1.0
12,-13,-3:1.0
13,-13,-3:1.0
14,-13,-3:1.0
15,-13,-3:1.0
16,-13,-3:1.0
17,-13,-3:1.0
18,-13,-3:1.0
19,-13,-3:1.0
2,-12,-3:1.0
3,-12,-3:1.0
4,-12,-3:1.0
5,-12,-3:1.0
6,-12,-3:1.0
7,-12,-3:1.0
8,-12,-3:1.0
9,-12,-3:1.0
10,-12,-3:1.0
11,-12,-3:1.0
12,-12,-3:1.0
13,-12,-3:1.0
14,-12,-3:1.0
15,-12,-3:1.0
16,-12,-3:1.0
17,-12,-3:1.0
18,-12,-3:1.0
19,-12,-3:1.0
0,-11,-3:1.0
1,-11,-3:1.0
2,-11,-3:1.0
3,-11,-3:1.0
4,-11,-3:1.0
5,-11,-3:1.0
6,-11,-3:1.0
7,-11,-3:1.0
8,-11,-3:1.0
9,-11,-3:1.0
10,-11,-3:1.0
11,-11,-3:1.0
12,-11,-3:1.0
13,-11,-3:1.0
14,-11,-3:1.0
15,-11,-3:1.0
16,-11,-3:1.0
17,-11,-3:1.0
18,-11,-3:1.0
19,-11,-3:1.0
-1,-10,-3:1.0
0,-10,-3:1.0
1,-10,-3:1.0
2,-10,-3:1.0
3,-10,-3:1.0
4,-10,-3:1.0
5,-10,-3:1.0
6,-10,-3:1.0
7,-10,-3:1.0
8,-10,-3:1.0
9,-10,-3:1.0
10,-10,-3:1.0
11,-10,-3:1.0
12,-10,-3:1.0
13,-10,-3:1.0
14,-10,-3:1.0
15,-10,-3:1.0
16,-10,-3:1.0
17,-10,-3:1.0
18,-10,-3:1.0
19,-10,-3:1.0
-1,-9,-3:1.0
0,-9,-3:1.0
1,-9,-3:1.0
2,-9,-3:1.0
3,-9,-3:1.0
4,-9,-3:1.0
5,-9,-3:1.0
6,-9,-3:1.0
7,-9,-3:1.0
8,-9,-3:1.0
9,-9,-3:1.0
10,-9,-3:1.0
11,-9,-3:1.0
12,-9,-3:1.0
13,-9,-3:1.0
14,-9,-3:1.0
15,-9,-3:1.0
16,-9,-3:1.0
17,-9,-3:1.0
18,-9,-3:1.0
19,-9,-3:1.0
-1,-8,-3:1.0
0,-8,-3:1.0
1,-8,-3:1.0
2,-8,-3:1.0
3,-8,-3:1.0
4,-8,-3:1.0
5,-8,-3:1.0
6,-8,-3:1.0
7,-8,-3:1.0
8,-8,-3:1.0
9,-8,-3:1.0
10,-8,-3:1.0
11,-8,-3:1.0
12,-8,-3:1.0
13,-8,-3:1.0
14,-8,-3:1.0
15,-8,-3:1.0
16,-8,-3:1.0
17,-8,-3:1.0
18,-8,-3:1.0
-1,-7,-3:1.0
0,-7,-3:1.0
1,-7,-3:1.0
2,-7,-3:1.0
3,-7,-3:1.0
4,-7,-3:1.0
5,-7,-3:1.0
6,-7,-3:1.0
7,-7,-3:1.0
8,-7,-3:1.0
9,-7,-3:1.0
10,-7,-3:1.0
11,-7,-3:1.0
12,-7,-3:1.0
13,-7,-3:1.0
14,-7,-3:1.0
15,-7,-3:1.0
16,-7,-3:1.0
17,-7,-3:1.0
18,-7,-3:1.0
-2,-6,-3:1.0
-1,-6,-3:1.0
0,-6,-3:1.0
1,-6,-3:1.0
2,-6,-3:1.0
3,-6,-3:1.0
4,-6,-3:1.0
5,-6,-3:1.0
6,-6,-3:1.0
7,-6,-3:1.0
8,-6,-3:1.0
9,-6,-3:1.0
10,-6,-3:1.0
11,-6,-3:1.0
12,-6,-3:1.0
13,-6,-3:1.0
14,-6,-3:1.0
15,-6,-3:1.0
16,-6,-3:1.0
17,-6,-3:1.0
-3,-5,-3:1.0
-2,-5,-3:1.0
-1,-5,-3:1.0
0,-5,-3:1.0
1,-5,-3:1.0
2,-5,-3:1.0
3,-5,-3:1.0
4,-5,-3:1.0
5,-5,-3:1.0
6,-5,-3:1.0
7,-5,-3:1.0
8,-5,-3:1.0
9,-5,-3:1.0
10,-5,-3:1.0
11,-5,-3:1.0
12,-5,-3:1.0
13,-5,-3:1.0
14,-5,-3:1.0
15,-5,-3:1.0
16,-5,-3:1.0
17,-5,-3:1.0
-5,-4,-3:1.0
-4,-4,-3:1.0
-3,-4,-3:1.0
-2,-4,-3:1.0
-1,-4,-3:1.0
0,-4,-3:1.0
1,-4,-3:1.0
2,-4,-3:1.0
3,-4,-3:1.0
4,-4,-3:1.0
5,-4,-3:1.0
6,-4,-3:1.0
7,-4,-3:1.0
8,-4,-3:1.0
9,-4,-3:1.0
10,-4,-3:1.0
11,-4,-3:1.0
12,-4,-3:1.0
13,-4,-3:1.0
14,-4,-3:1.0
15,-4,-3:1.0
16,-4,-3:1.0
-5,-3,-3:1.0
-4,-3,-3:1.0
-3,-3,-3:1.0
-2,-3,-3:1.0
-1,-3,-3:1.0
0,-3,-3:1.0
1,-3,-3:1.0
2,-3,-3:1.0
3,-3,-3:1.0
4,-3,-3:1.0
5,-3,-3:1.0
6,-3,-3:1.0
7,-3,-3:1.0
8,-3,-3:1.0
9,-3,-3:1.0
10,-3,-3:1.0
11,-3,-3:1.0
12,-3,-3:1.0
13,-3,-3:1.0
14,-3,-3:1.0
15,-3,-3:1.0
-5,-2,-3:1.0
-4,-2,-3:1.0
-3,-2,-3:1.0
-2,-2,-3:1.0
-1,-2,-3:1.0
0,-2,-3:1.0
1,-2,-3:1.0
2,-2,-3:1.0
3,-2,-3:1.0
4,-2,-3:1.0
5,-2,-3:1.0
6,-2,-3:1.0
7,-2,-3:1.0
8,-2,-3:1.0
9,-2,-3:1.0
10,-2,-3:1.0
11,-2,-3:1.0
12,-2,-3:1.0
13,-2,-3:1.0
14,-2,-3:1.0
-6,-1,-3:1.0
-5,-1,-3:1.0
-4,-1,-3:1.0
-3,-1,-3:1.0
-2,-1,-3:1.0
-1,-1,-3:1.0
0,-1,-3:1.0
1,-1,-3:1.0
2,-1,-3:1.0
3,-1,-3:1.0
4,-1,-3:1.0
5,-1,-3:1.0
6,-1,-3:1.0
7,-1,-3:1.0
8,-1,-3:1.0
9,-1,-3:1.0
10,-1,-3:1.0
11,-1,-3:1.0
12,-1,-3:1.0
13,-1,-3:1.0
-6,0,-3:1.0
-5,0,-3:1.0
-4,0,-3:1.0
-3,0,-3:1.0
-2,0,-3:1.0
-1,0,-3:1.0
0,0,-3:1.0
1,0,-3:1.0
2,0,-3:1.0
3,0,-3:1.0
4,0,-3:1.0
5,0,-3:1.0
6,0,-3:1.0
7,0,-3:1.0
8,0,-3:1.0
9,0,-3:1.0
10,0,-3:1.0
11,0,-3:1.0
12,0,-3:1.0
-9,1,-3:1.0
-8,1,-3:1.0
-7,1,-3:1.0
-6,1,-3:1.0
-5,1,-3:1.0
-4,1,-3:1.0
-3,1,-3:1.0
-2,1,-3:1.0
-1,1,-3:1.0
0,1,-3:1.0
1,1,-3:1.0
2,1,-3:1.0
3,1,-3:1.0
4,1,-3:1.0
5,1,-3:1.0
6,1,-3:1.0
7,1,-3:1.0
8,1,-3:1.0
9,1,-3:1.0
10,1,-3:1.0
11,1,-3:1.0
-10,2,-3:1.0
-9,2,-3:1.0
-8,2,-3:1.0
-7,2,-3:1.0
-6,2,-3:1.0
-5,2,-3:1.0
-4,2,-3:1.0
-3,2,-3:1.0
-2,2,-3:1.0
-1,2,-3:1.0
0,2,-3:1.0
1,2,-3:1.0
2,2,-3:1.0
3,2,-3:1.0
4,2,-3:1.0
5,2,-3:1.0
6,2,-3:1.0
7,2,-3:1.0
8,2,-3:1.0
9,2,-3:1.0
10,2,-3:1.0
11,2,-3:1.0
-11,3,-3:1.0
-10,3,-3:1.0
-9,3,-3:1.0
-8,3,-3:1.0
-7,3,-3:1.0
-6,3,-3:1.0
-5,3,-3:1.0
-4,3,-3:1.0
-3,3,-3:1.0
-2,3,-3:1.0
-1,3,-3:1.0
0,3,-3:1.0
1,3,-3:1.0
2,3,-3:1.0
3,3,-3:1.0
4,3,-3:1.0
5,3,-3:1.0
6,3,-3:1.0
7,3,-3:1.0
8,3,-3:1.0
9,3,-3:1.0
10,3,-3:1.0
11,3,-3:1.0
-12,4,-3:1.0
-11,4,-3:1.0
-10,4,-3:1.0
-9,4,-3:1.0
-8,4,-3:1.0
-7,4,-3:1.0
-6,4,-3:1.0
-5,4,-3:1.0
-4,4,-3:1.0
-3,4,-3:1.0
-2,4,-3:1.0
-1,4,-3:1.0
0,4,-3:1.0
1,4,-3:1.0
2,4,-3:1.0
3,4,-3:1.0
4,4,-3:1.0
5,4,-3:1.0
6,4,-3:1.0
7,4,-3:1.0
8,4,-3:1.0
9,4,-3:1.0
10,4,-3:1.0
11,4,-3:80.0
-12,5,-3:1.0
-11,5,-3:1.0
-10,5,-3:1.0
-9,5,-3:1.0
-8,5,-3:1.0
-7,5,-3:1.0
-6,5,-3:1.0
-5,5,-3:1.0
-4,5,-3:1.0
-3,5,-3:1.0
-2,5,-3:1.0
-1,5,-3:1.0
0,5,-3:1.0
1,5,-3:1.0
2,5,-3:1.0
3,5,-3:1.0
4,5,-3:1.0
5,5,-3:1.0
6,5,-3:1.0
7,5,-3:1.0
-12,6,-3:1.0
-11,6,-3:1.0
-10,6,-3:1.0
-9,6,-3:1.0
-8,6,-3:1.0
-7,6,-3:1.0
-6,6,-3:1.0
-5,6,-3:1.0
-4,6,-3:1.0
-3,6,-3:1.0
-2,6,-3:1.0
-1,6,-3:1.0
0,6,-3:1.0
1,6,-3:1.0
2,6,-3:1.0
3,6,-3:1.0
4,6,-3:1.0
5,6,-3:1.0
-13,7,-3:1.0
-12,7,-3:1.0
-11,7,-3:1.0
-10,7,-3:1.0
-9,7,-3:1.0
-8,7,-3:1.0
-7,7,-3:1.0
-6,7,-3:1.0
-5,7,-3:1.0
-4,7,-3:1.0
-3,7,-3:1.0
-2,7,-3:1.0
-1,7,-3:1.0
0,7,-3:1.0
1,7,-3:80.0
2,7,-3:80.0
-13,8,-3:1.0
-12,8,-3:1.0
-11,8,-3:1.0
-10,8,-3:1.0
-9,8,-3:1.0
-8,8,-3:1.0
-7,8,-3:1.0
-6,8,-3:1.0
-5,8,-3:1.0
-4,8,-3:1.0
-3,8,-3:1.0
-2,8,-3:1.0
-1,8,-3:80.0
-13,9,-3:1.0
-12,9,-3:1.0
-11,9,-3:1.0
-10,9,-3:1.0
-9,9,-3:1.0
-8,9,-3:1.0
-7,9,-3:1.0
-6,9,-3:1.0
-5,9,-3:80.0
-12,10,-3:1.0
-11,10,-3:1.0
-10,10,-3:1.0
-9,10,-3:1.0
-8,10,-3:1.0
-7,10,-3:1.0
-12,11,-3:1.0
-11,11,-3:1.0
-10,11,-3:1.0
-9,11,-3:1.0
-8,11,-3:1.0
15,-16,-2:1.0
16,-16,-2:80.0
17,-16,-2:1.0
18,-16,-2:1.0
8,-15,-2:80.0
13,-15,-2:80.0
14,-15,-2:1.0
15,-15,-2:1.0
16,-15,-2:1.0
17,-15,-2:1.0
18,-15,-2:1.0
19,-15,-2:80.0
5,-14,-2:80.0
6,-14,-2:1.0
7,-14,-2:1.0
8,-14,-2:1.0
9,-14,-2:1.0
10,-14,-2:1.0
11,-14,-2:80.0
12,-14,-2:80.0
13,-14,-2:1.0
14,-14,-2:1.0
15,-14,-2:1.0
16,-14,-2:1.0
17,-14,-2:1.0
18,-14,-2:1.0
19,-14,-2:1.0
3,-13,-2:1.0
4,-13,-2:1.0
5,-13,-2:1.0
6,-13,-2:1.0
7,-13,-2:1.0
8,-13,-2:1.0
9,-13,-2:1.0
10,-13,-2:1.0
11,-13,-2:1.0
12,-13,-2:1.0
13,-13,-2:1.0
14,-13,-2:1.0
15,-13,-2:1.0
16,-13,-2:1.0
17,-13,-2:1.0
18,-13,-2:1.0
19,-13,-2:1.0
2,-12,-2:1.0
3,-12,-2:1.0
4,-12,-2:1.0
5,-12,-2:1.0
6,-12,-2:1.0
7,-12,-2:1.0
8,-12,-2:1.0
9,-12,-2:1.0
10,-12,-2:1.0
11,-12,-2:1.0
12,-12,-2:1.0
13,-12,-2:1.0
14,-12,-2:1.0
15,-12,-2:1.0
16,-12,-2:1.0
17,-12,-2:1.0
18,-12,-2:1.0
19,-12,-2:1.0
0,-11,-2:1.0
1,-11,-2:1.0
2,-11,-2:1.0
3,-11,-2:1.0
4,-11,-2:1.0
5,-11,-2:1.0
6,-11,-2:1.0
7,-11,-2:1.0
8,-11,-2:1.0
9,-11,-2:1.0
10,-11,-2:1.0
11,-11,-2:1.0
12,-11,-2:1.0
13,-11,-2:1.0
14,-11,-2:1.0
15,-11,-2:1.0
16,-11,-2:1.0
17,-11,-2:1.0
18,-11,-2:1.0
19,-11,-2:1.0
-1,-10,-2:1.0
0,-10,-2:1.0
1,-10,-2:1.0
2,-10,-2:1.0
3,-10,-2:1.0
4,-10,-2:1.0
5,-10,-2:1.0
6,-10,-2:1.0
7,-10,-2:1.0
8,-10,-2:1.0
9,-10,-2:1.0
10,-10,-2:1.0
11,-10,-2:1.0
12,-10,-2:1.0
13,-10,-2:1.0
14,-10,-2:1.0
15,-10,-2:1.0
16,-10,-2:1.0
17,-10,-2:1.0
18,-10,-2:1.0
19,-10,-2:1.0
-1,-9,-2:1.0
0,-9,-2:1.0
1,-9,-2:1.0
2,-9,-2:1.0
3,-9,-2:1.0
4,-9,-2:1.0
5,-9,-2:1.0
6,-9,-2:1.0
7,-9,-2:1.0
8,-9,-2:1.0
9,-9,-2:1.0
10,-9,-2:1.0
11,-9,-2:1.0
12,-9,-2:1.0
13,-9,-2:1.0
14,-9,-2:1.0
15,-9,-2:1.0
16,-9,-2:1.0
17,-9,-2:1.0
18,-9,-2:1.0
19,-9,-2:1.0
-1,-8,-2:1.0
0,-8,-2:1.0
1,-8,-2:1.0
2,-8,-2:1.0
3,-8,-2:1.0
4,-8,-2:1.0
5,-8,-2:1.0
6,-8,-2:1.0
7,-8,-2:1.0
8,-8,-2:1.0
9,-8,-2:1.0
10,-8,-2:1.0
11,-8,-2:1.0
12,-8,-2:1.0
13,-8,-2:1.0
14,-8,-2:1.0
15,-8,-2:1.0
16,-8,-2:1.0
17,-8,-2:1.0
18,-8,-2:1.0
-1,-7,-2:1.0
0,-7,-2:1.0
1,-7,-2:1.0
2,-7,-2:1.0
3,-7,-2:1.0
4,-7,-2:1.0
5,-7,-2:1.0
6,-7,-2:1.0
7,-7,-2:1.0
8,-7,-2:1.0
9,-7,-2:1.0
10,-7,-2:1.0
11,-7,-2:1.0
12,-7,-2:1.0
13,-7,-2:1.0
14,-7,-2:1.0
15,-7,-2:1.0
16,-7,-2:1.0
17,-7,-2:1.0
18,-7,-2:1.0
-2,-6,-2:1.0
-1,-6,-2:1.0
0,-6,-2:1.0
1,-6,-2:1.0
2,-6,-2:1.0
3,-6,-2:1.0
4,-6,-2:1.0
5,-6,-2:1.0
6,-6,-2:1.0
7,-6,-2:1.0
8,-6,-2:1.0
9,-6,-2:1.0
10,-6,-2:1.0
11,-6,-2:1.0
12,-6,-2:1.0
13,-6,-2:1.0
14,-6,-2:1.0
15,-6,-2:1.0
16,-6,-2:1.0
17,-6,-2:1.0
-3,-5,-2:1.0
-2,-5,-2:1.0
-1,-5,-2:1.0
0,-5,-2:1.0
1,-5,-2:1.0
2,-5,-2:1.0
3,-5,-2:1.0
4,-5,-2:1.0
5,-5,-2:1.0
6,-5,-2:1.0
7,-5,-2:1.0
8,-5,-2:1.0
9,-5,-2:1.0
10,-5,-2:1.0
11,-5,-2:1.0
12,-5,-2:1.0
13,-5,-2:1.0
14,-5,-2:1.0
15,-5,-2:1.0
16,-5,-2:1.0
17,-5,-2:1.0
-4,-4,-2:1.0
-3,-4,-2:1.0
-2,-4,-2:1.0
-1,-4,-2:1.0
0,-4,-2:1.0
1,-4,-2:1.0
2,-4,-2:1.0
3,-4,-2:1.0
4,-4,-2:1.0
5,-4,-2:1.0
6,-4,-2:1.0
7,-4,-2:1.0
8,-4,-2:1.0
9,-4,-2:1.0
10,-4,-2:1.0
11,-4,-2:1.0
12,-4,-2:1.0
13,-4,-2:1.0
14,-4,-2:1.0
15,-4,-2:1.0
16,-4,-2:1.0
-5,-3,-2:1.0
-4,-3,-2:1.0
-3,-3,-2:1.0
-2,-3,-2:1.0
-1,-3,-2:1.0
0,-3,-2:1.0
1,-3,-2:1.0
2,-3,-2:1.0
3,-3,-2:1.0
4,-3,-2:1.0
5,-3,-2:1.0
6,-3,-2:1.0
7,-3,-2:1.0
8,-3,-2:1.0
9,-3,-2:1.0
10,-3,-2:1.0
11,-3,-2:1.0
12,-3,-2:1.0
13,-3,-2:1.0
14,-3,-2:1.0
15,-3,-2:1.0
-5,-2,-2:1.0
-4,-2,-2:1.0
-3,-2,-2:1.0
-2,-2,-2:1.0
-1,-2,-2:1.0
0,-2,-2:1.0
1,-2,-2:1.0
2,-2,-2:1.0
3,-2,-2:1.0
4,-2,-2:1.0
5,-2,-2:1.0
6,-2,-2:1.0
7,-2,-2:1.0
8,-2,-2:1.0
9,-2,-2:1.0
10,-2,-2:1.0
11,-2,-2:1.0
12,-2,-2:1.0
13,-2,-2:1.0
14,-2,-2:1.0
-6,-1,-2:1.0
-5,-1,-2:1.0
-4,-1,-2:1.0
-3,-1,-2:1.0
-2,-1,-2:1.0
-1,-1,-2:1.0
0,-1,-2:1.0
1,-1,-2:1.0
2,-1,-2:1.0
3,-1,-2:1.0
4,-1,-2:1.0
5,-1,-2:1.0
6,-1,-2:1.0
7,-1,-2:1.0
8,-1,-2:1.0
9,-1,-2:1.0
10,-1,-2:1.0
11,-1,-2:1.0
12,-1,-2:1.0
13,-1,-2:1.0
-6,0,-2:1.0
-5,0,-2:1.0
-4,0,-2:1.0
-3,0,-2:1.0
-2,0,-2:1.0
-1,0,-2:1.0
0,0,-2:1.0
1,0,-2:1.0
2,0,-2:1.0
3,0,-2:1.0
4,0,-2:1.0
5,0,-2:1.0
6,0,-2:1.0
7,0,-2:1.0
8,0,-2:1.0
9,0,-2:1.0
10,0,-2:1.0
11,0,-2:1.0
12,0,-2:1.0
-9,1,-2:1.0
-8,1,-2:1.0
-7,1,-2:1.0
-6,1,-2:1.0
-5,1,-2:1.0
-4,1,-2:1.0
-3,1,-2:1.0
-2,1,-2:1.0
-1,1,-2:1.0
0,1,-2:1.0
1,1,-2:1.0
2,1,-2:1.0
3,1,-2:1.0
4,1,-2:1.0
5,1,-2:1.0
6,1,-2:1.0
7,1,-2:1.0
8,1,-2:1.0
9,1,-2:1.0
10,1,-2:1.0
11,1,-2:1.0
-10,2,-2:1.0
-9,2,-2:1.0
-8,2,-2:1.0
-7,2,-2:1.0
-6,2,-2:1.0
-5,2,-2:1.0
-4,2,-2:1.0
-3,2,-2:1.0
-2,2,-2:1.0
-1,2,-2:1.0
0,2,-2:1.0
1,2,-2:1.0
2,2,-2:1.0
3,2,-2:1.0
4,2,-2:1.0
5,2,-2:1.0
6,2,-2:1.0
7,2,-2:1.0
8,2,-2:1.0
9,2,-2:1.0
10,2,-2:1.0
11,2,-2:1.0
-11,3,-2:1.0
-10,3,-2:1.0
-9,3,-2:1.0
-8,3,-2:1.0
-7,3,-2:1.0
-6,3,-2:1.0
-5,3,-2:1.0
-4,3,-2:1.0
-3,3,-2:1.0
-2,3,-2:1.0
-1,3,-2:1.0
0,3,-2:1.0
1,3,-2:1.0
2,3,-2:1.0
3,3,-2:1.0
4,3,-2:1.0
5,3,-2:1.0
6,3,-2:1.0
7,3,-2:1.0
8,3,-2:1.0
9,3,-2:1.0
10,3,-2:1.0
11,3,-2:80.0
-11,4,-2:1.0
-10,4,-2:1.0
-9,4,-2:1.0
-8,4,-2:1.0
-7,4,-2:1.0
-6,4,-2:1.0
-5,4,-2:1.0
-4,4,-2:1.0
-3,4,-2:1.0
-2,4,-2:1.0
-1,4,-2:1.0
0,4,-2:1.0
1,4,-2:1.0
2,4,-2:1.0
3,4,-2:1.0
4,4,-2:1.0
5,4,-2:1.0
6,4,-2:1.0
7,4,-2:1.0
8,4,-2:1.0
9,4,-2:1.0
10,4,-2:1.0
-12,5,-2:1.0
-11,5,-2:1.0
-10,5,-2:1.0
-9,5,-2:1.0
-8,5,-2:1.0
-7,5,-2:1.0
-6,5,-2:1.0
-5,5,-2:1.0
-4,5,-2:1.0
-3,5,-2:1.0
-2,5,-2:1.0
-1,5,-2:1.0
0,5,-2:1.0
1,5,-2:1.0
2,5,-2:1.0
3,5,-2:1.0
4,5,-2:1.0
5,5,-2:1.0
6,5,-2:1.0
7,5,-2:1.0
-12,6,-2:1.0
-11,6,-2:1.0
-10,6,-2:1.0
-9,6,-2:1.0
-8,6,-2:1.0
-7,6,-2:1.0
-6,6,-2:1.0
-5,6,-2:1.0
-4,6,-2:1.0
-3,6,-2:1.0
-2,6,-2:1.0
-1,6,-2:1.0
0,6,-2:1.0
1,6,-2:1.0
2,6,-2:1.0
3,6,-2:80.0
4,6,-2:80.0
5,6,-2:1.0
-12,7,-2:1.0
-11,7,-2:1.0
-10,7,-2:1.0
-9,7,-2:1.0
-8,7,-2:1.0
-7,7,-2:1.0
-6,7,-2:1.0
-5,7,-2:1.0
-4,7,-2:1.0
-3,7,-2:1.0
-2,7,-2:1.0
-1,7,-2:1.0
0,7,-2:80.0
-12,8,-2:1.0
-11,8,-2:1.0
-10,8,-2:1.0
-9,8,-2:1.0
-8,8,-2:1.0
-7,8,-2:1.0
-6,8,-2:1.0
-5,8,-2:1.0
-4,8,-2:1.0
-3,8,-2:1.0
-2,8,-2:1.0
-12,9,-2:80.0
-11,9,-2:1.0
-10,9,-2:1.0
-9,9,-2:1.0
-8,9,-2:1.0
-7,9,-2:1.0
-6,9,-2:1.0
-5,9,-2:80.0
-12,10,-2:80.0
-11,10,-2:1.0
-10,10,-2:1.0
-9,10,-2:1.0
-8,10,-2:1.0
-7,10,-2:80.0
-11,11,-2:80.0
-10,11,-2:1.0
-9,11,-2:1.0
-8,11,-2:80.0
14,-15,-1:80.0
15,-15,-1:1.0
16,-15,-1:1.0
17,-15,-1:1.0
18,-15,-1:1.0
6,-14,-1:80.0
7,-14,-1:1.0
8,-14,-1:1.0
9,-14,-1:1.0
10,-14,-1:1.0
11,-14,-1:80.0
12,-14,-1:80.0
13,-14,-1:1.0
14,-14,-1:1.0
15,-14,-1:1.0
16,-14,-1:1.0
17,-14,-1:1.0
18,-14,-1:1.0
19,-14,-1:80.0
4,-13,-1:1.0
5,-13,-1:1.0
6,-13,-1:1.0
7,-13,-1:1.0
8,-13,-1:1.0
9,-13,-1:1.0
10,-13,-1:1.0
11,-13,-1:1.0
12,-13,-1:1.0
13,-13,-1:1.0
14,-13,-1:1.0
15,-13,-1:1.0
16,-13,-1:1.0
17,-13,-1:1.0
18,-13,-1:1.0
19,-13,-1:1.0
2,-12,-1:80.0
3,-12,-1:1.0
4,-12,-1:1.0
5,-12,-1:1.0
6,-12,-1:1.0
7,-12,-1:1.0
8,-12,-1:1.0
9,-12,-1:1.0
10,-12,-1:1.0
11,-12,-1:1.0
12,-12,-1:1.0
13,-12,-1:1.0
14,-12,-1:1.0
15,-12,-1:1.0
16,-12,-1:1.0
17,-12,-1:1.0
18,-12,-1:1.0
19,-12,-1:1.0
1,-11,-1:1.0
2,-11,-1:1.0
3,-11,-1:1.0
4,-11,-1:1.0
5,-11,-1:1.0
6,-11,-1:1.0
7,-11,-1:1.0
8,-11,-1:1.0
9,-11,-1:1.0
10,-11,-1:1.0
11,-11,-1:1.0
12,-11,-1:1.0
13,-11,-1:1.0
14,-11,-1:1.0
15,-11,-1:1.0
16,-11,-1:1.0
17,-11,-1:1.0
18,-11,-1:1.0
19,-11,-1:1.0
0,-10,-1:1.0
1,-10,-1:1.0
2,-10,-1:1.0
3,-10,-1:1.0
4,-10,-1:1.0
5,-10,-1:1.0
6,-10,-1:1.0
7,-10,-1:1.0
8,-10,-1:1.0
9,-10,-1:1.0
10,-10,-1:1.0
11,-10,-1:1.0
12,-10,-1:1.0
13,-10,-1:1.0
14,-10,-1:1.0
15,-10,-1:1.0
16,-10,-1:1.0
17,-10,-1:1.0
18,-10,-1:1.0
19,-10,-1:80.0
-1,-9,-1:1.0
0,-9,-1:1.0
1,-9,-1:1.0
2,-9,-1:1.0
3,-9,-1:1.0
4,-9,-1:1.0
5,-9,-1:1.0
6,-9,-1:1.0
7,-9,-1:1.0
8,-9,-1:1.0
9,-9,-1:1.0
10,-9,-1:1.0
11,-9,-1:1.0
12,-9,-1:1.0
13,-9,-1:1.0
14,-9,-1:1.0
15,-9,-1:1.0
16,-9,-1:1.0
17,-9,-1:1.0
18,-9,-1:1.0
-1,-8,-1:1.0
0,-8,-1:1.0
1,-8,-1:1.0
2,-8,-1:1.0
3,-8,-1:1.0
4,-8,-1:1.0
5,-8,-1:1.0
6,-8,-1:1.0
7,-8,-1:1.0
8,-8,-1:1.0
9,-8,-1:1.0
10,-8,-1:1.0
11,-8,-1:1.0
12,-8,-1:1.0
13,-8,-1:1.0
14,-8,-1:1.0
15,-8,-1:1.0
16,-8,-1:1.0
17,-8,-1:1.0
18,-8,-1:1.0
-1,-7,-1:1.0
0,-7,-1:1.0
1,-7,-1:1.0
2,-7,-1:1.0
3,-7,-1:1.0
4,-7,-1:1.0
5,-7,-1:1.0
6,-7,-1:1.0
7,-7,-1:1.0
8,-7,-1:1.0
9,-7,-1:1.0
10,-7,-1:1.0
11,-7,-1:1.0
12,-7,-1:1.0
13,-7,-1:1.0
14,-7,-1:1.0
15,-7,-1:1.0
16,-7,-1:1.0
17,-7,-1:1.0
18,-7,-1:1.0
-2,-6,-1:1.0
-1,-6,-1:1.0
0,-6,-1:1.0
1,-6,-1:1.0
2,-6,-1:1.0
3,-6,-1:1.0
4,-6,-1:1.0
5,-6,-1:1.0
6,-6,-1:1.0
7,-6,-1:1.0
8,-6,-1:1.0
9,-6,-1:1.0
10,-6,-1:1.0
11,-6,-1:1.0
12,-6,-1:1.0
13,-6,-1:1.0
14,-6,-1:1.0
15,-6,-1:1.0
16,-6,-1:1.0
17,-6,-1:1.0
-3,-5,-1:1.0
-2,-5,-1:1.0
-1,-5,-1:1.0
0,-5,-1:1.0
1,-5,-1:1.0
2,-5,-1:1.0
3,-5,-1:1.0
4,-5,-1:1.0
5,-5,-1:1.0
6,-5,-1:1.0
7,-5,-1:1.0
8,-5,-1:1.0
9,-5,-1:1.0
10,-5,-1:1.0
11,-5,-1:1.0
12,-5,-1:1.0
13,-5,-1:1.0
14,-5,-1:1.0
15,-5,-1:1.0
16,-5,-1:1.0
-4,-4,-1:1.0
-3,-4,-1:1.0
-2,-4,-1:1.0
-1,-4,-1:1.0
0,-4,-1:1.0
1,-4,-1:1.0
2,-4,-1:1.0
3,-4,-1:1.0
4,-4,-1:1.0
5,-4,-1:1.0
6,-4,-1:1.0
7,-4,-1:1.0
8,-4,-1:1.0
9,-4,-1:1.0
10,-4,-1:1.0
11,-4,-1:1.0
12,-4,-1:1.0
13,-4,-1:1.0
14,-4,-1:1.0
15,-4,-1:1.0
16,-4,-1:80.0
-5,-3,-1:1.0
-4,-3,-1:1.0
-3,-3,-1:1.0
-2,-3,-1:1.0
-1,-3,-1:1.0
0,-3,-1:1.0
1,-3,-1:1.0
2,-3,-1:1.0
3,-3,-1:1.0
4,-3,-1:1.0
5,-3,-1:1.0
6,-3,-1:1.0
7,-3,-1:1.0
8,-3,-1:1.0
9,-3,-1:1.0
10,-3,-1:1.0
11,-3,-1:1.0
12,-3,-1:1.0
13,-3,-1:1.0
14,-3,-1:1.0
15,-3,-1:1.0
-5,-2,-1:1.0
-4,-2,-1:1.0
-3,-2,-1:1.0
-2,-2,-1:1.0
-1,-2,-1:1.0
0,-2,-1:1.0
1,-2,-1:1.0
2,-2,-1:1.0
3,-2,-1:1.0
4,-2,-1:1.0
5,-2,-1:1.0
6,-2,-1:1.0
7,-2,-1:1.0
8,-2,-1:1.0
9,-2,-1:1.0
10,-2,-1:1.0
11,-2,-1:1.0
12,-2,-1:1.0
13,-2,-1:1.0
14,-2,-1:1.0
-6,-1,-1:1.0
-5,-1,-1:1.0
-4,-1,-1:1.0
-3,-1,-1:1.0
-2,-1,-1:1.0
-1,-1,-1:1.0
0,-1,-1:1.0
1,-1,-1:1.0
2,-1,-1:1.0
3,-1,-1:1.0
4,-1,-1:1.0
5,-1,-1:1.0
6,-1,-1:1.0
7,-1,-1:1.0
8,-1,-1:1.0
9,-1,-1:1.0
10,-1,-1:1.0
11,-1,-1:1.0
12,-1,-1:1.0
13,-1,-1:1.0
-6,0,-1:1.0
-5,0,-1:1.0
-4,0,-1:1.0
-3,0,-1:1.0
-2,0,-1:1.0
-1,0,-1:1.0
0,0,-1:1.0
1,0,-1:1.0
2,0,-1:1.0
3,0,-1:1.0
4,0,-1:1.0
5,0,-1:1.0
6,0,-1:1.0
7,0,-1:1.0
8,0,-1:1.0
9,0,-1:1.0
10,0,-1:1.0
11,0,-1:1.0
12,0,-1:1.0
-8,1,-1:1.0
-7,1,-1:1.0
-6,1,-1:1.0
-5,1,-1:1.0
-4,1,-1:1.0
-3,1,-1:1.0
-2,1,-1:1.0
-1,1,-1:1.0
0,1,-1:1.0
1,1,-1:1.0
2,1,-1:1.0
3,1,-1:1.0
4,1,-1:1.0
5,1,-1:1.0
6,1,-1:1.0
7,1,-1:1.0
8,1,-1:1.0
9,1,-1:1.0
10,1,-1:1.0
11,1,-1:1.0
-9,2,-1:1.0
-8,2,-1:1.0
-7,2,-1:1.0
-6,2,-1:1.0
-5,2,-1:1.0
-4,2,-1:1.0
-3,2,-1:1.0
-2,2,-1:1.0
-1,2,-1:1.0
0,2,-1:1.0
1,2,-1:1.0
2,2,-1:1.0
3,2,-1:1.0
4,2,-1:1.0
5,2,-1:1.0
6,2,-1:1.0
7,2,-1:1.0
8,2,-1:1.0
9,2,-1:1.0
10,2,-1:1.0
11,2,-1:80.0
-10,3,-1:1.0
-9,3,-1:1.0
-8,3,-1:1.0
-7,3,-1:1.0
-6,3,-1:1.0
-5,3,-1:1.0
-4,3,-1:1.0
-3,3,-1:1.0
-2,3,-1:1.0
-1,3,-1:1.0
0,3,-1:1.0
1,3,-1:1.0
2,3,-1:1.0
3,3,-1:1.0
4,3,-1:1.0
5,3,-1:1.0
6,3,-1:1.0
7,3,-1:1.0
8,3,-1:1.0
9,3,-1:1.0
10,3,-1:1.0
-11,4,-1:80.0
-10,4,-1:1.0
-9,4,-1:1.0
-8,4,-1:1.0
-7,4,-1:1.0
-6,4,-1:1.0
-5,4,-1:1.0
-4,4,-1:1.0
-3,4,-1:1.0
-2,4,-1:1.0
-1,4,-1:1.0
0,4,-1:1.0
1,4,-1:1.0
2,4,-1:1.0
3,4,-1:1.0
4,4,-1:1.0
5,4,-1:1.0
6,4,-1:1.0
7,4,-1:1.0
8,4,-1:1.0
9,4,-1:1.0
10,4,-1:80.0
-11,5,-1:1.0
-10,5,-1:1.0
-9,5,-1:1.0
-8,5,-1:1.0
-7,5,-1:1.0
-6,5,-1:1.0
-5,5,-1:1.0
-4,5,-1:1.0
-3,5,-1:1.0
-2,5,-1:1.0
-1,5,-1:1.0
0,5,-1:1.0
1,5,-1:1.0
2,5,-1:1.0
3,5,-1:1.0
4,5,-1:1.0
5,5,-1:1.0
6,5,-1:1.0
7,5,-1:1.0
-12,6,-1:80.0
-11,6,-1:1.0
-10,6,-1:1.0
-9,6,-1:1.0
-8,6,-1:1.0
-7,6,-1:1.0
-6,6,-1:1.0
-5,6,-1:1.0
-4,6,-1:1.0
-3,6,-1:1.0
-2,6,-1:1.0
-1,6,-1:1.0
0,6,-1:1.0
1,6,-1:1.0
2,6,-1:80.0
-12,7,-1:80.0
-11,7,-1:1.0
-10,7,-1:1.0
-9,7,-1:1.0
-8,7,-1:1.0
-7,7,-1:1.0
-6,7,-1:1.0
-5,7,-1:1.0
-4,7,-1:1.0
-3,7,-1:1.0
-2,7,-1:1.0
-1,7,-1:1.0
-12,8,-1:80.0
-11,8,-1:1.0
-10,8,-1:1.0
-9,8,-1:1.0
-8,8,-1:1.0
-7,8,-1:1.0
-6,8,-1:1.0
-5,8,-1:1.0
-4,8,-1:1.0
-3,8,-1:1.0
-2,8,-1:80.0
-11,9,-1:1.0
-10,9,-1:1.0
-9,9,-1:1.0
-8,9,-1:1.0
-7,9,-1:1.0
-6,9,-1:1.0
-5,9,-1:80.0
-11,10,-1:80.0
-10,10,-1:1.0
-9,10,-1:1.0
-8,10,-1:80.0
-10,11,-1:80.0
-9,11,-1:80.0
15,-15,0:80.0
16,-15,0:1.0
17,-15,0:80.0
18,-15,0:80.0
7,-14,0:80.0
8,-14,0:80.0
9,-14,0:1.0
10,-14,0:1.0
11,-14,0:80.0
12,-14,0:80.0
13,-14,0:1.0
14,-14,0:1.0
15,-14,0:1.0
16,-14,0:1.0
17,-14,0:1.0
18,-14,0:1.0
4,-13,0:80.0
5,-13,0:1.0
6,-13,0:1.0
7,-13,0:1.0
8,-13,0:1.0
9,-13,0:1.0
10,-13,0:1.0
11,-13,0:1.0
12,-13,0:1.0
13,-13,0:1.0
14,-13,0:1.0
15,-13,0:1.0
16,-13,0:1.0
17,-13,0:1.0
18,-13,0:1.0
19,-13,0:80.0
3,-12,0:1.0
4,-12,0:1.0
5,-12,0:1.0
6,-12,0:1.0
7,-12,0:1.0
8,-12,0:1.0
9,-12,0:1.0
10,-12,0:1.0
11,-12,0:1.0
12,-12,0:1.0
13,-12,0:1.0
14,-12,0:1.0
15,-12,0:1.0
16,-12,0:1.0
17,-12,0:1.0
18,-12,0:1.0
19,-12,0:80.0
1,-11,0:80.0
2,-11,0:1.0
3,-11,0:1.0
4,-11,0:1.0
5,-11,0:1.0
6,-11,0:1.0
7,-11,0:1.0
8,-11,0:1.0
9,-11,0:1.0
10,-11,0:1.0
11,-11,0:1.0
12,-11,0:1.0
13,-11,0:1.0
14,-11,0:1.0
15,-11,0:1.0
16,-11,0:1.0
17,-11,0:1.0
18,-11,0:1.0
19,-11,0:80.0
0,-10,0:1.0
1,-10,0:1.0
2,-10,0:1.0
3,-10,0:1.0
4,-10,0:1.0
5,-10,0:1.0
6,-10,0:1.0
7,-10,0:1.0
8,-10,0:1.0
9,-10,0:1.0
10,-10,0:1.0
11,-10,0:1.0
12,-10,0:1.0
13,-10,0:1.0
14,-10,0:1.0
15,-10,0:1.0
16,-10,0:1.0
17,-10,0:1.0
18,-10,0:1.0
-1,-9,0:1.0
0,-9,0:1.0
1,-9,0:1.0
2,-9,0:1.0
3,-9,0:1.0
4,-9,0:1.0
5,-9,0:1.0
6,-9,0:1.0
7,-9,0:1.0
8,-9,0:1.0
9,-9,0:1.0
10,-9,0:1.0
11,-9,0:1.0
12,-9,0:1.0
13,-9,0:1.0
14,-9,0:1.0
15,-9,0:1.0
16,-9,0:1.0
17,-9,0:1.0
18,-9,0:1.0
-1,-8,0:1.0
0,-8,0:1.0
1,-8,0:1.0
2,-8,0:1.0
3,-8,0:1.0
4,-8,0:1.0
5,-8,0:1.0
6,-8,0:1.0
7,-8,0:1.0
8,-8,0:1.0
9,-8,0:1.0
10,-8,0:1.0
11,-8,0:1.0
12,-8,0:1.0
13,-8,0:1.0
14,-8,0:1.0
15,-8,0:1.0
16,-8,0:1.0
17,-8,0:1.0
18,-8,0:80.0
-1,-7,0:1.0
0,-7,0:1.0
1,-7,0:1.0
2,-7,0:1.0
3,-7,0:1.0
4,-7,0:1.0
5,-7,0:1.0
6,-7,0:1.0
7,-7,0:1.0
8,-7,0:1.0
9,-7,0:1.0
10,-7,0:1.0
11,-7,0:1.0
12,-7,0:1.0
13,-7,0:1.0
14,-7,0:1.0
15,-7,0:1.0
16,-7,0:1.0
17,-7,0:1.0
-2,-6,0:1.0
-1,-6,0:1.0
0,-6,0:1.0
1,-6,0:1.0
2,-6,0:1.0
3,-6,0:1.0
4,-6,0:1.0
5,-6,0:1.0
6,-6,0:1.0
7,-6,0:1.0
8,-6,0:1.0
9,-6,0:1.0
10,-6,0:1.0
11,-6,0:1.0
12,-6,0:1.0
13,-6,0:1.0
14,-6,0:1.0
15,-6,0:1.0
16,-6,0:1.0
17,-6,0:80.0
-3,-5,0:1.0
-2,-5,0:1.0
-1,-5,0:1.0
0,-5,0:1.0
1,-5,0:1.0
2,-5,0:1.0
3,-5,0:1.0
4,-5,0:1.0
5,-5,0:1.0
6,-5,0:1.0
7,-5,0:1.0
8,-5,0:1.0
9,-5,0:1.0
10,-5,0:1.0
11,-5,0:1.0
12,-5,0:1.0
13,-5,0:1.0
14,-5,0:1.0
15,-5,0:1.0
16,-5,0:1.0
-3,-4,0:1.0
-2,-4,0:1.0
-1,-4,0:1.0
0,-4,0:1.0
1,-4,0:1.0
2,-4,0:1.0
3,-4,0:1.0
4,-4,0:1.0
5,-4,0:1.0
6,-4,0:1.0
7,-4,0:1.0
8,-4,0:1.0
9,-4,0:1.0
10,-4,0:1.0
11,-4,0:1.0
12,-4,0:1.0
13,-4,0:1.0
14,-4,0:1.0
15,-4,0:1.0
-4,-3,0:1.0
-3,-3,0:1.0
-2,-3,0:1.0
-1,-3,0:1.0
0,-3,0:1.0
1,-3,0:1.0
2,-3,0:1.0
3,-3,0:1.0
4,-3,0:1.0
5,-3,0:1.0
6,-3,0:1.0
7,-3,0:1.0
8,-3,0:1.0
9,-3,0:1.0
10,-3,0:1.0
11,-3,0:1.0
12,-3,0:1.0
13,-3,0:1.0
14,-3,0:1.0
-5,-2,0:1.0
-4,-2,0:1.0
-3,-2,0:1.0
-2,-2,0:1.0
-1,-2,0:1.0
0,-2,0:1.0
1,-2,0:1.0
2,-2,0:1.0
3,-2,0:1.0
4,-2,0:1.0
5,-2,0:1.0
6,-2,0:1.0
7,-2,0:1.0
8,-2,0:1.0
9,-2,0:1.0
10,-2,0:1.0
11,-2,0:1.0
12,-2,0:1.0
13,-2,0:1.0
-6,-1,0:1.0
-5,-1,0:1.0
-4,-1,0:1.0
-3,-1,0:1.0
-2,-1,0:1.0
-1,-1,0:1.0
0,-1,0:1.0
1,-1,0:1.0
2,-1,0:1.0
3,-1,0:1.0
4,-1,0:1.0
5,-1,0:1.0
6,-1,0:1.0
7,-1,0:1.0
8,-1,0:1.0
9,-1,0:1.0
10,-1,0:1.0
11,-1,0:1.0
12,-1,0:1.0
-6,0,0:1.0
-5,0,0:1.0
-4,0,0:1.0
-3,0,0:1.0
-2,0,0:1.0
-1,0,0:1.0
0,0,0:1.0
1,0,0:1.0
2,0,0:1.0
3,0,0:1.0
4,0,0:1.0
5,0,0:1.0
6,0,0:1.0
7,0,0:1.0
8,0,0:1.0
9,0,0:1.0
10,0,0:1.0
11,0,0:1.0
-8,1,0:1.0
-7,1,0:1.0
-6,1,0:1.0
-5,1,0:1.0
-4,1,0:1.0
-3,1,0:1.0
-2,1,0:1.0
-1,1,0:1.0
0,1,0:1.0
1,1,0:1.0
2,1,0:1.0
3,1,0:1.0
4,1,0:1.0
5,1,0:1.0
6,1,0:1.0
7,1,0:1.0
8,1,0:1.0
9,1,0:1.0
10,1,0:1.0
11,1,0:1.0
-9,2,0:1.0
-8,2,0:1.0
-7,2,0:1.0
-6,2,0:1.0
-5,2,0:1.0
-4,2,0:1.0
-3,2,0:1.0
-2,2,0:1.0
-1,2,0:1.0
0,2,0:1.0
1,2,0:1.0
2,2,0:1.0
3,2,0:1.0
4,2,0:1.0
5,2,0:1.0
6,2,0:1.0
7,2,0:1.0
8,2,0:1.0
9,2,0:1.0
10,2,0:1.0
-10,3,0:80.0
-9,3,0:1.0
-8,3,0:1.0
-7,3,0:1.0
-6,3,0:1.0
-5,3,0:1.0
-4,3,0:1.0
-3,3,0:1.0
-2,3,0:1.0
-1,3,0:1.0
0,3,0:1.0
1,3,0:1.0
2,3,0:1.0
3,3,0:1.0
4,3,0:1.0
5,3,0:1.0
6,3,0:1.0
7,3,0:1.0
8,3,0:1.0
9,3,0:1.0
10,3,0:1.0
-10,4,0:1.0
-9,4,0:1.0
-8,4,0:1.0
-7,4,0:1.0
-6,4,0:1.0
-5,4,0:1.0
-4,4,0:1.0
-3,4,0:1.0
-2,4,0:1.0
-1,4,0:1.0
0,4,0:1.0
1,4,0:1.0
2,4,0:1.0
3,4,0:1.0
4,4,0:1.0
5,4,0:1.0
6,4,0:1.0
7,4,0:1.0
8,4,0:1.0
9,4,0:1.0
-11,5,0:80.0
-10,5,0:1.0
-9,5,0:1.0
-8,5,0:1.0
-7,5,0:1.0
-6,5,0:1.0
-5,5,0:1.0
-4,5,0:1.0
-3,5,0:1.0
-2,5,0:1.0
-1,5,0:1.0
0,5,0:1.0
1,5,0:1.0
2,5,0:1.0
3,5,0:1.0
4,5,0:1.0
5,5,0:1.0
6,5,0:1.0
7,5,0:80.0
-11,6,0:1.0
-10,6,0:1.0
-9,6,0:1.0
-8,6,0:1.0
-7,6,0:1.0
-6,6,0:1.0
-5,6,0:1.0
-4,6,0:1.0
-3,6,0:1.0
-2,6,0:1.0
-1,6,0:1.0
0,6,0:1.0
1,6,0:1.0
-11,7,0:1.0
-10,7,0:1.0
-9,7,0:1.0
-8,7,0:1.0
-7,7,0:1.0
-6,7,0:1.0
-5,7,0:1.0
-4,7,0:1.0
-3,7,0:1.0
-2,7,0:1.0
-1,7,0:80.0
-11,8,0:80.0
-10,8,0:1.0
-9,8,0:1.0
-8,8,0:1.0
-7,8,0:1.0
-6,8,0:1.0
-5,8,0:1.0
-4,8,0:1.0
-3,8,0:1.0
-11,9,0:80.0
-10,9,0:1.0
-9,9,0:1.0
-8,9,0:1.0
-7,9,0:1.0
-6,9,0:1.0
-5,9,0:80.0
-10,10,0:80.0
-9,10,0:80.0
16,-15,1:80.0
9,-14,1:80.0
10,-14,1:80.0
11,-14,1:80.0
12,-14,1:80.0
13,-14,1:1.0
14,-14,1:1.0
15,-14,1:1.0
16,-14,1:1.0
17,-14,1:1.0
18,-14,1:80.0
5,-13,1:80.0
6,-13,1:1.0
7,-13,1:1.0
8,-13,1:1.0
9,-13,1:1.0
10,-13,1:1.0
11,-13,1:1.0
12,-13,1:1.0
13,-13,1:1.0
14,-13,1:1.0
15,-13,1:1.0
16,-13,1:1.0
17,-13,1:1.0
18,-13,1:1.0
3,-12,1:1.0
4,-12,1:1.0
5,-12,1:1.0
6,-12,1:1.0
7,-12,1:1.0
8,-12,1:1.0
9,-12,1:1.0
10,-12,1:1.0
11,-12,1:1.0
12,-12,1:1.0
13,-12,1:1.0
14,-12,1:1.0
15,-12,1:1.0
16,-12,1:1.0
17,-12,1:1.0
18,-12,1:1.0
2,-11,1:1.0
3,-11,1:1.0
4,-11,1:1.0
5,-11,1:1.0
6,-11,1:1.0
7,-11,1:1.0
8,-11,1:1.0
9,-11,1:1.0
10,-11,1:1.0
11,-11,1:1.0
12,-11,1:1.0
13,-11,1:1.0
14,-11,1:1.0
15,-11,1:1.0
16,-11,1:1.0
17,-11,1:1.0
18,-11,1:1.0
1,-10,1:1.0
2,-10,1:1.0
3,-10,1:1.0
4,-10,1:1.0
5,-10,1:1.0
6,-10,1:1.0
7,-10,1:1.0
8,-10,1:1.0
9,-10,1:1.0
10,-10,1:1.0
11,-10,1:1.0
12,-10,1:1.0
13,-10,1:1.0
14,-10,1:1.0
15,-10,1:1.0
16,-10,1:1.0
17,-10,1:1.0
18,-10,1:1.0
0,-9,1:1.0
1,-9,1:1.0
2,-9,1:1.0
3,-9,1:1.0
4,-9,1:1.0
5,-9,1:1.0
6,-9,1:1.0
7,-9,1:1.0
8,-9,1:1.0
9,-9,1:1.0
10,-9,1:1.0
11,-9,1:1.0
12,-9,1:1.0
13,-9,1:1.0
14,-9,1:1.0
15,-9,1:1.0
16,-9,1:1.0
17,-9,1:1.0
18,-9,1:80.0
-1,-8,1:1.0
0,-8,1:1.0
1,-8,1:1.0
2,-8,1:1.0
3,-8,1:1.0
4,-8,1:1.0
5,-8,1:1.0
6,-8,1:1.0
7,-8,1:1.0
8,-8,1:1.0
9,-8,1:1.0
10,-8,1:1.0
11,-8,1:1.0
12,-8,1:1.0
13,-8,1:1.0
14,-8,1:1.0
15,-8,1:1.0
16,-8,1:1.0
17,-8,1:1.0
-1,-7,1:1.0
0,-7,1:1.0
1,-7,1:1.0
2,-7,1:1.0
3,-7,1:1.0
4,-7,1:1.0
5,-7,1:1.0
6,-7,1:1.0
7,-7,1:1.0
8,-7,1:1.0
9,-7,1:1.0
10,-7,1:1.0
11,-7,1:1.0
12,-7,1:1.0
13,-7,1:1.0
14,-7,1:1.0
15,-7,1:1.0
16,-7,1:1.0
17,-7,1:1.0
-2,-6,1:1.0
-1,-6,1:1.0
0,-6,1:1.0
1,-6,1:1.0
2,-6,1:1.0
3,-6,1:1.0
4,-6,1:1.0
5,-6,1:1.0
6,-6,1:1.0
7,-6,1:1.0
8,-6,1:1.0
9,-6,1:1.0
10,-6,1:1.0
11,-6,1:1.0
12,-6,1:1.0
13,-6,1:1.0
14,-6,1:1.0
15,-6,1:1.0
16,-6,1:1.0
-2,-5,1:1.0
-1,-5,1:1.0
0,-5,1:1.0
1,-5,1:1.0
2,-5,1:1.0
3,-5,1:1.0
4,-5,1:1.0
5,-5,1:1.0
6,-5,1:1.0
7,-5,1:1.0
8,-5,1:1.0
9,-5,1:1.0
10,-5,1:1.0
11,-5,1:1.0
12,-5,1:1.0
13,-5,1:1.0
14,-5,1:1.0
15,-5,1:1.0
16,-5,1:1.0
-3,-4,1:1.0
-2,-4,1:1.0
-1,-4,1:1.0
0,-4,1:1.0
1,-4,1:1.0
2,-4,1:1.0
3,-4,1:1.0
4,-4,1:1.0
5,-4,1:1.0
6,-4,1:1.0
7,-4,1:1.0
8,-4,1:1.0
9,-4,1:1.0
10,-4,1:1.0
11,-4,1:1.0
12,-4,1:1.0
13,-4,1:1.0
14,-4,1:1.0
15,-4,1:1.0
-4,-3,1:1.0
-3,-3,1:1.0
-2,-3,1:1.0
-1,-3,1:1.0
0,-3,1:1.0
1,-3,1:1.0
2,-3,1:1.0
3,-3,1:1.0
4,-3,1:1.0
5,-3,1:1.0
6,-3,1:1.0
7,-3,1:1.0
8,-3,1:1.0
9,-3,1:1.0
10,-3,1:1.0
11,-3,1:1.0
12,-3,1:1.0
13,-3,1:1.0
14,-3,1:1.0
-5,-2,1:1.0
-4,-2,1:1.0
-3,-2,1:1.0
-2,-2,1:1.0
-1,-2,1:1.0
0,-2,1:1.0
1,-2,1:1.0
2,-2,1:1.0
3,-2,1:1.0
4,-2,1:1.0
5,-2,1:1.0
6,-2,1:1.0
7,-2,1:1.0
8,-2,1:1.0
9,-2,1:1.0
10,-2,1:1.0
11,-2,1:1.0
12,-2,1:1.0
13,-2,1:1.0
-6,-1,1:1.0
-5,-1,1:1.0
-4,-1,1:1.0
-3,-1,1:1.0
-2,-1,1:1.0
-1,-1,1:1.0
0,-1,1:1.0
1,-1,1:1.0
2,-1,1:1.0
3,-1,1:1.0
4,-1,1:1.0
5,-1,1:1.0
6,-1,1:1.0
7,-1,1:1.0
8,-1,1:1.0
9,-1,1:1.0
10,-1,1:1.0
11,-1,1:1.0
12,-1,1:1.0
-6,0,1:1.0
-5,0,1:1.0
-4,0,1:1.0
-3,0,1:1.0
-2,0,1:1.0
-1,0,1:1.0
0,0,1:1.0
1,0,1:1.0
2,0,1:1.0
3,0,1:1.0
4,0,1:1.0
5,0,1:1.0
6,0,1:1.0
7,0,1:1.0
8,0,1:1.0
9,0,1:1.0
10,0,1:1.0
11,0,1:1.0
-7,1,1:1.0
-6,1,1:1.0
-5,1,1:1.0
-4,1,1:1.0
-3,1,1:1.0
-2,1,1:1.0
-1,1,1:1.0
0,1,1:1.0
1,1,1:1.0
2,1,1:1.0
3,1,1:1.0
4,1,1:1.0
5,1,1:1.0
6,1,1:1.0
7,1,1:1.0
8,1,1:1.0
9,1,1:1.0
10,1,1:1.0
11,1,1:80.0
-8,2,1:1.0
-7,2,1:1.0
-6,2,1:1.0
-5,2,1:1.0
-4,2,1:1.0
-3,2,1:1.0
-2,2,1:1.0
-1,2,1:1.0
0,2,1:1.0
1,2,1:1.0
2,2,1:1.0
3,2,1:1.0
4,2,1:1.0
5,2,1:1.0
6,2,1:1.0
7,2,1:1.0
8,2,1:1.0
9,2,1:1.0
10,2,1:1.0
-9,3,1:1.0
-8,3,1:1.0
-7,3,1:1.0
-6,3,1:1.0
-5,3,1:1.0
-4,3,1:1.0
-3,3,1:1.0
-2,3,1:1.0
-1,3,1:1.0
0,3,1:1.0
1,3,1:1.0
2,3,1:1.0
3,3,1:1.0
4,3,1:1.0
5,3,1:1.0
6,3,1:1.0
7,3,1:1.0
8,3,1:1.0
9,3,1:1.0
10,3,1:80.0
-10,4,1:1.0
-9,4,1:1.0
-8,4,1:1.0
-7,4,1:1.0
-6,4,1:1.0
-5,4,1:1.0
-4,4,1:1.0
-3,4,1:1.0
-2,4,1:1.0
-1,4,1:1.0
0,4,1:1.0
1,4,1:1.0
2,4,1:1.0
3,4,1:1.0
4,4,1:1.0
5,4,1:1.0
6,4,1:1.0
7,4,1:1.0
8,4,1:1.0
9,4,1:80.0
-10,5,1:1.0
-9,5,1:1.0
-8,5,1:1.0
-7,5,1:1.0
-6,5,1:1.0
-5,5,1:1.0
-4,5,1:1.0
-3,5,1:1.0
-2,5,1:1.0
-1,5,1:1.0
0,5,1:1.0
1,5,1:1.0
2,5,1:1.0
3,5,1:1.0
4,5,1:1.0
5,5,1:80.0
6,5,1:80.0
-11,6,1:80.0
-10,6,1:1.0
-9,6,1:1.0
-8,6,1:1.0
-7,6,1:1.0
-6,6,1:1.0
-5,6,1:1.0
-4,6,1:1.0
-3,6,1:1.0
-2,6,1:1.0
-1,6,1:1.0
0,6,1:1.0
1,6,1:80.0
-11,7,1:80.0
-10,7,1:1.0
-9,7,1:1.0
-8,7,1:1.0
-7,7,1:1.0
-6,7,1:1.0
-5,7,1:1.0
-4,7,1:1.0
-3,7,1:1.0
-2,7,1:1.0
-10,8,1:1.0
-9,8,1:1.0
-8,8,1:1.0
-7,8,1:1.0
-6,8,1:1.0
-5,8,1:1.0
-4,8,1:1.0
-3,8,1:80.0
-10,9,1:80.0
-9,9,1:80.0
-8,9,1:1.0
-7,9,1:1.0
-6,9,1:80.0
13,-14,2:80.0
14,-14,2:1.0
15,-14,2:1.0
16,-14,2:1.0
17,-14,2:80.0
6,-13,2:80.0
7,-13,2:1.0
8,-13,2:1.0
9,-13,2:1.0
10,-13,2:1.0
11,-13,2:1.0
12,-13,2:1.0
13,-13,2:1.0
14,-13,2:1.0
15,-13,2:1.0
16,-13,2:1.0
17,-13,2:1.0
18,-13,2:80.0
3,-12,2:80.0
4,-12,2:1.0
5,-12,2:1.0
6,-12,2:1.0
7,-12,2:1.0
8,-12,2:1.0
9,-12,2:1.0
10,-12,2:1.0
11,-12,2:1.0
12,-12,2:1.0
13,-12,2:1.0
14,-12,2:1.0
15,-12,2:1.0
16,-12,2:1.0
17,-12,2:1.0
18,-12,2:1.0
2,-11,2:1.0
3,-11,2:1.0
4,-11,2:1.0
5,-11,2:1.0
6,-11,2:1.0
7,-11,2:1.0
8,-11,2:1.0
9,-11,2:1.0
10,-11,2:1.0
11,-11,2:1.0
12,-11,2:1.0
13,-11,2:1.0
14,-11,2:1.0
15,-11,2:1.0
16,-11,2:1.0
17,-11,2:1.0
18,-11,2:1.0
1,-10,2:1.0
2,-10,2:1.0
3,-10,2:1.0
4,-10,2:1.0
5,-10,2:1.0
6,-10,2:1.0
7,-10,2:1.0
8,-10,2:1.0
9,-10,2:1.0
10,-10,2:1.0
11,-10,2:1.0
12,-10,2:1.0
13,-10,2:1.0
14,-10,2:1.0
15,-10,2:1.0
16,-10,2:1.0
17,-10,2:1.0
18,-10,2:80.0
0,-9,2:1.0
1,-9,2:1.0
2,-9,2:1.0
3,-9,2:1.0
4,-9,2:1.0
5,-9,2:1.0
6,-9,2:1.0
7,-9,2:1.0
8,-9,2:1.0
9,-9,2:1.0
10,-9,2:1.0
11,-9,2:1.0
12,-9,2:1.0
13,-9,2:1.0
14,-9,2:1.0
15,-9,2:1.0
16,-9,2:1.0
17,-9,2:1.0
-1,-8,2:1.0
0,-8,2:1.0
1,-8,2:1.0
2,-8,2:1.0
3,-8,2:1.0
4,-8,2:1.0
5,-8,2:1.0
6,-8,2:1.0
7,-8,2:1.0
8,-8,2:1.0
9,-8,2:1.0
10,-8,2:1.0
11,-8,2:1.0
12,-8,2:1.0
13,-8,2:1.0
14,-8,2:1.0
15,-8,2:1.0
16,-8,2:1.0
17,-8,2:1.0
-1,-7,2:1.0
0,-7,2:1.0
1,-7,2:1.0
2,-7,2:1.0
3,-7,2:1.0
4,-7,2:1.0
5,-7,2:1.0
6,-7,2:1.0
7,-7,2:1.0
8,-7,2:1.0
9,-7,2:1.0
10,-7,2:1.0
11,-7,2:1.0
12,-7,2:1.0
13,-7,2:1.0
14,-7,2:1.0
15,-7,2:1.0
16,-7,2:1.0
17,-7,2:1.0
-2,-6,2:1.0
-1,-6,2:1.0
0,-6,2:1.0
1,-6,2:1.0
2,-6,2:1.0
3,-6,2:1.0
4,-6,2:1.0
5,-6,2:1.0
6,-6,2:1.0
7,-6,2:1.0
8,-6,2:1.0
9,-6,2:1.0
10,-6,2:1.0
11,-6,2:1.0
12,-6,2:1.0
13,-6,2:1.0
14,-6,2:1.0
15,-6,2:1.0
16,-6,2:1.0
-2,-5,2:1.0
-1,-5,2:1.0
0,-5,2:1.0
1,-5,2:1.0
2,-5,2:1.0
3,-5,2:1.0
4,-5,2:1.0
5,-5,2:1.0
6,-5,2:1.0
7,-5,2:1.0
8,-5,2:1.0
9,-5,2:1.0
10,-5,2:1.0
11,-5,2:1.0
12,-5,2:1.0
13,-5,2:1.0
14,-5,2:1.0
15,-5,2:1.0
16,-5,2:80.0
-3,-4,2:1.0
-2,-4,2:1.0
-1,-4,2:1.0
0,-4,2:1.0
1,-4,2:1.0
2,-4,2:1.0
3,-4,2:1.0
4,-4,2:1.0
5,-4,2:1.0
6,-4,2:1.0
7,-4,2:1.0
8,-4,2:1.0
9,-4,2:1.0
10,-4,2:1.0
11,-4,2:1.0
12,-4,2:1.0
13,-4,2:1.0
14,-4,2:1.0
15,-4,2:80.0
-4,-3,2:1.0
-3,-3,2:1.0
-2,-3,2:1.0
-1,-3,2:1.0
0,-3,2:1.0
1,-3,2:1.0
2,-3,2:1.0
3,-3,2:1.0
4,-3,2:1.0
5,-3,2:1.0
6,-3,2:1.0
7,-3,2:1.0
8,-3,2:1.0
9,-3,2:1.0
10,-3,2:1.0
11,-3,2:1.0
12,-3,2:1.0
13,-3,2:1.0
14,-3,2:80.0
-5,-2,2:1.0
-4,-2,2:1.0
-3,-2,2:1.0
-2,-2,2:1.0
-1,-2,2:1.0
0,-2,2:1.0
1,-2,2:1.0
2,-2,2:1.0
3,-2,2:1.0
4,-2,2:1.0
5,-2,2:1.0
6,-2,2:1.0
7,-2,2:1.0
8,-2,2:1.0
9,-2,2:1.0
10,-2,2:1.0
11,-2,2:1.0
12,-2,2:1.0
13,-2,2:1.0
-5,-1,2:1.0
-4,-1,2:1.0
-3,-1,2:1.0
-2,-1,2:1.0
-1,-1,2:1.0
0,-1,2:1.0
1,-1,2:1.0
2,-1,2:1.0
3,-1,2:1.0
4,-1,2:1.0
5,-1,2:1.0
6,-1,2:1.0
7,-1,2:1.0
8,-1,2:1.0
9,-1,2:1.0
10,-1,2:1.0
11,-1,2:1.0
12,-1,2:1.0
-6,0,2:1.0
-5,0,2:1.0
-4,0,2:1.0
-3,0,2:1.0
-2,0,2:1.0
-1,0,2:1.0
0,0,2:1.0
1,0,2:1.0
2,0,2:1.0
3,0,2:1.0
4,0,2:1.0
5,0,2:1.0
6,0,2:1.0
7,0,2:1.0
8,0,2:1.0
9,0,2:1.0
10,0,2:1.0
11,0,2:1.0
-7,1,2:1.0
-6,1,2:1.0
-5,1,2:1.0
-4,1,2:1.0
-3,1,2:1.0
-2,1,2:1.0
-1,1,2:1.0
0,1,2:1.0
1,1,2:1.0
2,1,2:1.0
3,1,2:1.0
4,1,2:1.0
5,1,2:1.0
6,1,2:1.0
7,1,2:1.0
8,1,2:1.0
9,1,2:1.0
10,1,2:1.0
-8,2,2:1.0
-7,2,2:1.0
-6,2,2:1.0
-5,2,2:1.0
-4,2,2:1.0
-3,2,2:1.0
-2,2,2:1.0
-1,2,2:1.0
0,2,2:1.0
1,2,2:1.0
2,2,2:1.0
3,2,2:1.0
4,2,2:1.0
5,2,2:1.0
6,2,2:1.0
7,2,2:1.0
8,2,2:1.0
9,2,2:1.0
10,2,2:1.0
-9,3,2:1.0
-8,3,2:1.0
-7,3,2:1.0
-6,3,2:1.0
-5,3,2:1.0
-4,3,2:1.0
-3,3,2:1.0
-2,3,2:1.0
-1,3,2:1.0
0,3,2:1.0
1,3,2:1.0
2,3,2:1.0
3,3,2:1.0
4,3,2:1.0
5,3,2:1.0
6,3,2:1.0
7,3,2:1.0
8,3,2:1.0
9,3,2:1.0
-10,4,2:80.0
-9,4,2:1.0
-8,4,2:1.0
-7,4,2:1.0
-6,4,2:1.0
-5,4,2:1.0
-4,4,2:1.0
-3,4,2:1.0
-2,4,2:1.0
-1,4,2:1.0
0,4,2:1.0
1,4,2:1.0
2,4,2:1.0
3,4,2:1.0
4,4,2:1.0
5,4,2:1.0
6,4,2:1.0
7,4,2:1.0
8,4,2:1.0
-10,5,2:1.0
-9,5,2:1.0
-8,5,2:1.0
-7,5,2:1.0
-6,5,2:1.0
-5,5,2:1.0
-4,5,2:1.0
-3,5,2:1.0
-2,5,2:1.0
-1,5,2:1.0
0,5,2:1.0
1,5,2:1.0
2,5,2:1.0
3,5,2:1.0
4,5,2:80.0
-10,6,2:1.0
-9,6,2:1.0
-8,6,2:1.0
-7,6,2:1.0
-6,6,2:1.0
-5,6,2:1.0
-4,6,2:1.0
-3,6,2:1.0
-2,6,2:1.0
-1,6,2:1.0
0,6,2:1.0
-10,7,2:1.0
-9,7,2:1.0
-8,7,2:1.0
-7,7,2:1.0
-6,7,2:1.0
-5,7,2:1.0
-4,7,2:1.0
-3,7,2:1.0
-2,7,2:1.0
-10,8,2:80.0
-9,8,2:1.0
-8,8,2:1.0
-7,8,2:1.0
-6,8,2:1.0
-5,8,2:1.0
-4,8,2:1.0
-8,9,2:80.0
-7,9,2:80.0
14,-14,3:80.0
15,-14,3:80.0
16,-14,3:80.0
7,-13,3:80.0
8,-13,3:1.0
9,-13,3:1.0
10,-13,3:1.0
11,-13,3:1.0
12,-13,3:1.0
13,-13,3:1.0
14,-13,3:1.0
15,-13,3:1.0
16,-13,3:1.0
17,-13,3:1.0
4,-12,3:1.0
5,-12,3:1.0
6,-12,3:1.0
7,-12,3:1.0
8,-12,3:1.0
9,-12,3:1.0
10,-12,3:1.0
11,-12,3:1.0
12,-12,3:1.0
13,-12,3:1.0
14,-12,3:1.0
15,-12,3:1.0
16,-12,3:1.0
17,-12,3:1.0
18,-12,3:80.0
2,-11,3:80.0
3,-11,3:1.0
4,-11,3:1.0
5,-11,3:1.0
6,-11,3:1.0
7,-11,3:1.0
8,-11,3:1.0
9,-11,3:1.0
10,-11,3:1.0
11,-11,3:1.0
12,-11,3:1.0
13,-11,3:1.0
14,-11,3:1.0
15,-11,3:1.0
16,-11,3:1.0
17,-11,3:1.0
18,-11,3:80.0
1,-10,3:80.0
2,-10,3:1.0
3,-10,3:1.0
4,-10,3:1.0
5,-10,3:1.0
6,-10,3:1.0
7,-10,3:1.0
8,-10,3:1.0
9,-10,3:1.0
10,-10,3:1.0
11,-10,3:1.0
12,-10,3:1.0
13,-10,3:1.0
14,-10,3:1.0
15,-10,3:1.0
16,-10,3:1.0
17,-10,3:1.0
0,-9,3:1.0
1,-9,3:1.0
2,-9,3:1.0
3,-9,3:1.0
4,-9,3:1.0
5,-9,3:1.0
6,-9,3:1.0
7,-9,3:1.0
8,-9,3:1.0
9,-9,3:1.0
10,-9,3:1.0
11,-9,3:1.0
12,-9,3:1.0
13,-9,3:1.0
14,-9,3:1.0
15,-9,3:1.0
16,-9,3:1.0
17,-9,3:1.0
0,-8,3:1.0
1,-8,3:1.0
2,-8,3:1.0
3,-8,3:1.0
4,-8,3:1.0
5,-8,3:1.0
6,-8,3:1.0
7,-8,3:1.0
8,-8,3:1.0
9,-8,3:1.0
10,-8,3:1.0
11,-8,3:1.0
12,-8,3:1.0
13,-8,3:1.0
14,-8,3:1.0
15,-8,3:1.0
16,-8,3:1.0
17,-8,3:1.0
-1,-7,3:1.0
0,-7,3:1.0
1,-7,3:1.0
2,-7,3:1.0
3,-7,3:1.0
4,-7,3:1.0
5,-7,3:1.0
6,-7,3:1.0
7,-7,3:1.0
8,-7,3:1.0
9,-7,3:1.0
10,-7,3:1.0
11,-7,3:1.0
12,-7,3:1.0
13,-7,3:1.0
14,-7,3:1.0
15,-7,3:1.0
16,-7,3:1.0
17,-7,3:80.0
-1,-6,3:1.0
0,-6,3:1.0
1,-6,3:1.0
2,-6,3:1.0
3,-6,3:1.0
4,-6,3:1.0
5,-6,3:1.0
6,-6,3:1.0
7,-6,3:1.0
8,-6,3:1.0
9,-6,3:1.0
10,-6,3:1.0
11,-6,3:1.0
12,-6,3:1.0
13,-6,3:1.0
14,-6,3:1.0
15,-6,3:1.0
16,-6,3:1.0
-2,-5,3:1.0
-1,-5,3:1.0
0,-5,3:1.0
1,-5,3:1.0
2,-5,3:1.0
3,-5,3:1.0
4,-5,3:1.0
5,-5,3:1.0
6,-5,3:1.0
7,-5,3:1.0
8,-5,3:1.0
9,-5,3:1.0
10,-5,3:1.0
11,-5,3:1.0
12,-5,3:1.0
13,-5,3:1.0
14,-5,3:1.0
15,-5,3:1.0
-3,-4,3:1.0
-2,-4,3:1.0
-1,-4,3:1.0
0,-4,3:1.0
1,-4,3:1.0
2,-4,3:1.0
3,-4,3:1.0
4,-4,3:1.0
5,-4,3:1.0
6,-4,3:1.0
7,-4,3:1.0
8,-4,3:1.0
9,-4,3:1.0
10,-4,3:1.0
11,-4,3:1.0
12,-4,3:1.0
13,-4,3:1.0
14,-4,3:1.0
-4,-3,3:1.0
-3,-3,3:1.0
-2,-3,3:1.0
-1,-3,3:1.0
0,-3,3:1.0
1,-3,3:1.0
2,-3,3:1.0
3,-3,3:1.0
4,-3,3:1.0
5,-3,3:1.0
6,-3,3:1.0
7,-3,3:1.0
8,-3,3:1.0
9,-3,3:1.0
10,-3,3:1.0
11,-3,3:1.0
12,-3,3:1.0
13,-3,3:1.0
-4,-2,3:1.0
-3,-2,3:1.0
-2,-2,3:1.0
-1,-2,3:1.0
0,-2,3:1.0
1,-2,3:1.0
2,-2,3:1.0
3,-2,3:1.0
4,-2,3:1.0
5,-2,3:1.0
6,-2,3:1.0
7,-2,3:1.0
8,-2,3:1.0
9,-2,3:1.0
10,-2,3:1.0
11,-2,3:1.0
12,-2,3:1.0
13,-2,3:80.0
-5,-1,3:1.0
-4,-1,3:1.0
-3,-1,3:1.0
-2,-1,3:1.0
-1,-1,3:1.0
0,-1,3:1.0
1,-1,3:1.0
2,-1,3:1.0
3,-1,3:1.0
4,-1,3:1.0
5,-1,3:1.0
6,-1,3:1.0
7,-1,3:1.0
8,-1,3:1.0
9,-1,3:1.0
10,-1,3:1.0
11,-1,3:1.0
12,-1,3:80.0
-6,0,3:1.0
-5,0,3:1.0
-4,0,3:1.0
-3,0,3:1.0
-2,0,3:1.0
-1,0,3:1.0
0,0,3:1.0
1,0,3:1.0
2,0,3:1.0
3,0,3:1.0
4,0,3:1.0
5,0,3:1.0
6,0,3:1.0
7,0,3:1.0
8,0,3:1.0
9,0,3:1.0
10,0,3:1.0
11,0,3:1.0
-7,1,3:1.0
-6,1,3:1.0
-5,1,3:1.0
-4,1,3:1.0
-3,1,3:1.0
-2,1,3:1.0
-1,1,3:1.0
0,1,3:1.0
1,1,3:1.0
2,1,3:1.0
3,1,3:1.0
4,1,3:1.0
5,1,3:1.0
6,1,3:1.0
7,1,3:1.0
8,1,3:1.0
9,1,3:1.0
10,1,3:1.0
-8,2,3:80.0
-7,2,3:1.0
-6,2,3:1.0
-5,2,3:1.0
-4,2,3:1.0
-3,2,3:1.0
-2,2,3:1.0
-1,2,3:1.0
0,2,3:1.0
1,2,3:1.0
2,2,3:1.0
3,2,3:1.0
4,2,3:1.0
5,2,3:1.0
6,2,3:1.0
7,2,3:1.0
8,2,3:1.0
9,2,3:1.0
10,2,3:80.0
-9,3,3:80.0
-8,3,3:1.0
-7,3,3:1.0
-6,3,3:1.0
-5,3,3:1.0
-4,3,3:1.0
-3,3,3:1.0
-2,3,3:1.0
-1,3,3:1.0
0,3,3:1.0
1,3,3:1.0
2,3,3:1.0
3,3,3:1.0
4,3,3:1.0
5,3,3:1.0
6,3,3:1.0
7,3,3:1.0
8,3,3:1.0
9,3,3:1.0
-9,4,3:1.0
-8,4,3:1.0
-7,4,3:1.0
-6,4,3:1.0
-5,4,3:1.0
-4,4,3:1.0
-3,4,3:1.0
-2,4,3:1.0
-1,4,3:1.0
0,4,3:1.0
1,4,3:1.0
2,4,3:1.0
3,4,3:1.0
4,4,3:1.0
5,4,3:1.0
6,4,3:1.0
7,4,3:1.0
8,4,3:80.0
-10,5,3:80.0
-9,5,3:1.0
-8,5,3:1.0
-7,5,3:1.0
-6,5,3:1.0
-5,5,3:1.0
-4,5,3:1.0
-3,5,3:1.0
-2,5,3:1.0
-1,5,3:1.0
0,5,3:1.0
1,5,3:1.0
2,5,3:1.0
3,5,3:80.0
-10,6,3:80.0
-9,6,3:1.0
-8,6,3:1.0
-7,6,3:1.0
-6,6,3:1.0
-5,6,3:1.0
-4,6,3:1.0
-3,6,3:1.0
-2,6,3:1.0
-1,6,3:1.0
0,6,3:80.0
-10,7,3:80.0
-9,7,3:1.0
-8,7,3:1.0
-7,7,3:1.0
-6,7,3:1.0
-5,7,3:1.0
-4,7,3:1.0
-3,7,3:1.0
-2,7,3:80.0
-9,8,3:80.0
-8,8,3:1.0
-7,8,3:1.0
-6,8,3:1.0
-5,8,3:1.0
-4,8,3:80.0
8,-13,4:80.0
9,-13,4:1.0
10,-13,4:1.0
11,-13,4:1.0
12,-13,4:1.0
13,-13,4:1.0
14,-13,4:1.0
15,-13,4:1.0
16,-13,4:1.0
17,-13,4:80.0
4,-12,4:80.0
5,-12,4:1.0
6,-12,4:1.0
7,-12,4:1.0
8,-12,4:1.0
9,-12,4:1.0
10,-12,4:1.0
11,-12,4:1.0
12,-12,4:1.0
13,-12,4:1.0
14,-12,4:1.0
15,-12,4:1.0
16,-12,4:1.0
17,-12,4:1.0
3,-11,4:1.0
4,-11,4:1.0
5,-11,4:1.0
6,-11,4:1.0
7,-11,4:1.0
8,-11,4:1.0
9,-11,4:1.0
10,-11,4:1.0
11,-11,4:1.0
12,-11,4:1.0
13,-11,4:1.0
14,-11,4:1.0
15,-11,4:1.0
16,-11,4:1.0
17,-11,4:1.0
2,-10,4:1.0
3,-10,4:1.0
4,-10,4:1.0
5,-10,4:1.0
6,-10,4:1.0
7,-10,4:1.0
8,-10,4:1.0
9,-10,4:1.0
10,-10,4:1.0
11,-10,4:1.0
12,-10,4:1.0
13,-10,4:1.0
14,-10,4:1.0
15,-10,4:1.0
16,-10,4:1.0
17,-10,4:1.0
0,-9,4:80.0
1,-9,4:1.0
2,-9,4:1.0
3,-9,4:1.0
4,-9,4:1.0
5,-9,4:1.0
6,-9,4:1.0
7,-9,4:1.0
8,-9,4:1.0
9,-9,4:1.0
10,-9,4:1.0
11,-9,4:1.0
12,-9,4:1.0
13,-9,4:1.0
14,-9,4:1.0
15,-9,4:1.0
16,-9,4:1.0
17,-9,4:1.0
0,-8,4:1.0
1,-8,4:1.0
2,-8,4:1.0
3,-8,4:1.0
4,-8,4:1.0
5,-8,4:1.0
6,-8,4:1.0
7,-8,4:1.0
8,-8,4:1.0
9,-8,4:1.0
10,-8,4:1.0
11,-8,4:1.0
12,-8,4:1.0
13,-8,4:1.0
14,-8,4:1.0
15,-8,4:1.0
16,-8,4:1.0
17,-8,4:1.0
-1,-7,4:1.0
0,-7,4:1.0
1,-7,4:1.0
2,-7,4:1.0
3,-7,4:1.0
4,-7,4:1.0
5,-7,4:1.0
6,-7,4:1.0
7,-7,4:1.0
8,-7,4:1.0
9,-7,4:1.0
10,-7,4:1.0
11,-7,4:1.0
12,-7,4:1.0
13,-7,4:1.0
14,-7,4:1.0
15,-7,4:1.0
16,-7,4:1.0
-1,-6,4:1.0
0,-6,4:1.0
1,-6,4:1.0
2,-6,4:1.0
3,-6,4:1.0
4,-6,4:1.0
5,-6,4:1.0
6,-6,4:1.0
7,-6,4:1.0
8,-6,4:1.0
9,-6,4:1.0
10,-6,4:1.0
11,-6,4:1.0
12,-6,4:1.0
13,-6,4:1.0
14,-6,4:1.0
15,-6,4:1.0
16,-6,4:1.0
-2,-5,4:1.0
-1,-5,4:1.0
0,-5,4:1.0
1,-5,4:1.0
2,-5,4:1.0
3,-5,4:1.0
4,-5,4:1.0
5,-5,4:1.0
6,-5,4:1.0
7,-5,4:1.0
8,-5,4:1.0
9,-5,4:1.0
10,-5,4:1.0
11,-5,4:1.0
12,-5,4:1.0
13,-5,4:1.0
14,-5,4:1.0
15,-5,4:1.0
-3,-4,4:1.0
-2,-4,4:1.0
-1,-4,4:1.0
0,-4,4:1.0
1,-4,4:1.0
2,-4,4:1.0
3,-4,4:1.0
4,-4,4:1.0
5,-4,4:1.0
6,-4,4:1.0
7,-4,4:1.0
8,-4,4:1.0
9,-4,4:1.0
10,-4,4:1.0
11,-4,4:1.0
12,-4,4:1.0
13,-4,4:1.0
14,-4,4:1.0
-3,-3,4:1.0
-2,-3,4:1.0
-1,-3,4:1.0
0,-3,4:1.0
1,-3,4:1.0
2,-3,4:1.0
3,-3,4:1.0
4,-3,4:1.0
5,-3,4:1.0
6,-3,4:1.0
7,-3,4:1.0
8,-3,4:1.0
9,-3,4:1.0
10,-3,4:1.0
11,-3,4:1.0
12,-3,4:1.0
13,-3,4:1.0
-4,-2,4:1.0
-3,-2,4:1.0
-2,-2,4:1.0
-1,-2,4:1.0
0,-2,4:1.0
1,-2,4:1.0
2,-2,4:1.0
3,-2,4:1.0
4,-2,4:1.0
5,-2,4:1.0
6,-2,4:1.0
7,-2,4:1.0
8,-2,4:1.0
9,-2,4:1.0
10,-2,4:1.0
11,-2,4:1.0
12,-2,4:1.0
-5,-1,4:1.0
-4,-1,4:1.0
-3,-1,4:1.0
-2,-1,4:1.0
-1,-1,4:1.0
0,-1,4:1.0
1,-1,4:1.0
2,-1,4:1.0
3,-1,4:1.0
4,-1,4:1.0
5,-1,4:1.0
6,-1,4:1.0
7,-1,4:1.0
8,-1,4:1.0
9,-1,4:1.0
10,-1,4:1.0
11,-1,4:1.0
-6,0,4:80.0
-5,0,4:1.0
-4,0,4:1.0
-3,0,4:1.0
-2,0,4:1.0
-1,0,4:1.0
0,0,4:1.0
1,0,4:1.0
2,0,4:1.0
3,0,4:1.0
4,0,4:1.0
5,0,4:1.0
6,0,4:1.0
7,0,4:1.0
8,0,4:1.0
9,0,4:1.0
10,0,4:1.0
11,0,4:80.0
-6,1,4:1.0
-5,1,4:1.0
-4,1,4:1.0
-3,1,4:1.0
-2,1,4:1.0
-1,1,4:1.0
0,1,4:1.0
1,1,4:1.0
2,1,4:1.0
3,1,4:1.0
4,1,4:1.0
5,1,4:1.0
6,1,4:1.0
7,1,4:1.0
8,1,4:1.0
9,1,4:1.0
10,1,4:1.0
-7,2,4:1.0
-6,2,4:1.0
-5,2,4:1.0
-4,2,4:1.0
-3,2,4:1.0
-2,2,4:1.0
-1,2,4:1.0
0,2,4:1.0
1,2,4:1.0
2,2,4:1.0
3,2,4:1.0
4,2,4:1.0
5,2,4:1.0
6,2,4:1.0
7,2,4:1.0
8,2,4:1.0
9,2,4:1.0
-8,3,4:1.0
-7,3,4:1.0
-6,3,4:1.0
-5,3,4:1.0
-4,3,4:1.0
-3,3,4:1.0
-2,3,4:1.0
-1,3,4:1.0
0,3,4:1.0
1,3,4:1.0
2,3,4:1.0
3,3,4:1.0
4,3,4:1.0
5,3,4:1.0
6,3,4:1.0
7,3,4:1.0
8,3,4:1.0
9,3,4:80.0
-9,4,4:1.0
-8,4,4:1.0
-7,4,4:1.0
-6,4,4:1.0
-5,4,4:1.0
-4,4,4:1.0
-3,4,4:1.0
-2,4,4:1.0
-1,4,4:1.0
0,4,4:1.0
1,4,4:1.0
2,4,4:1.0
3,4,4:1.0
4,4,4:1.0
5,4,4:1.0
6,4,4:1.0
7,4,4:80.0
-9,5,4:1.0
-8,5,4:1.0
-7,5,4:1.0
-6,5,4:1.0
-5,5,4:1.0
-4,5,4:1.0
-3,5,4:1.0
-2,5,4:1.0
-1,5,4:1.0
0,5,4:1.0
1,5,4:1.0
2,5,4:80.0
-9,6,4:1.0
-8,6,4:1.0
-7,6,4:1.0
-6,6,4:1.0
-5,6,4:1.0
-4,6,4:1.0
-3,6,4:1.0
-2,6,4:1.0
-1,6,4:1.0
-9,7,4:1.0
-8,7,4:1.0
-7,7,4:1.0
-6,7,4:1.0
-5,7,4:1.0
-4,7,4:1.0
-3,7,4:1.0
-8,8,4:1.0
-7,8,4:1.0
-6,8,4:1.0
-5,8,4:1.0
9,-13,5:80.0
10,-13,5:1.0
11,-13,5:1.0
12,-13,5:1.0
13,-13,5:1.0
14,-13,5:1.0
15,-13,5:1.0
16,-13,5:1.0
5,-12,5:80.0
6,-12,5:1.0
7,-12,5:1.0
8,-12,5:1.0
9,-12,5:1.0
10,-12,5:1.0
11,-12,5:1.0
12,-12,5:1.0
13,-12,5:1.0
14,-12,5:1.0
15,-12,5:1.0
16,-12,5:1.0
17,-12,5:80.0
3,-11,5:80.0
4,-11,5:1.0
5,-11,5:1.0
6,-11,5:1.0
7,-11,5:1.0
8,-11,5:1.0
9,-11,5:1.0
10,-11,5:1.0
11,-11,5:1.0
12,-11,5:1.0
13,-11,5:1.0
14,-11,5:1.0
15,-11,5:1.0
16,-11,5:1.0
17,-11,5:1.0
2,-10,5:1.0
3,-10,5:1.0
4,-10,5:1.0
5,-10,5:1.0
6,-10,5:1.0
7,-10,5:1.0
8,-10,5:1.0
9,-10,5:1.0
10,-10,5:1.0
11,-10,5:1.0
12,-10,5:1.0
13,-10,5:1.0
14,-10,5:1.0
15,-10,5:1.0
16,-10,5:1.0
17,-10,5:1.0
1,-9,5:1.0
2,-9,5:1.0
3,-9,5:1.0
4,-9,5:1.0
5,-9,5:1.0
6,-9,5:1.0
7,-9,5:1.0
8,-9,5:1.0
9,-9,5:1.0
10,-9,5:1.0
11,-9,5:1.0
12,-9,5:1.0
13,-9,5:1.0
14,-9,5:1.0
15,-9,5:1.0
16,-9,5:1.0
17,-9,5:1.0
0,-8,5:1.0
1,-8,5:1.0
2,-8,5:1.0
3,-8,5:1.0
4,-8,5:1.0
5,-8,5:1.0
6,-8,5:1.0
7,-8,5:1.0
8,-8,5:1.0
9,-8,5:1.0
10,-8,5:1.0
11,-8,5:1.0
12,-8,5:1.0
13,-8,5:1.0
14,-8,5:1.0
15,-8,5:1.0
16,-8,5:1.0
17,-8,5:80.0
-1,-7,5:1.0
0,-7,5:1.0
1,-7,5:1.0
2,-7,5:1.0
3,-7,5:1.0
4,-7,5:1.0
5,-7,5:1.0
6,-7,5:1.0
7,-7,5:1.0
8,-7,5:1.0
9,-7,5:1.0
10,-7,5:1.0
11,-7,5:1.0
12,-7,5:1.0
13,-7,5:1.0
14,-7,5:1.0
15,-7,5:1.0
16,-7,5:1.0
-1,-6,5:1.0
0,-6,5:1.0
1,-6,5:1.0
2,-6,5:1.0
3,-6,5:1.0
4,-6,5:1.0
5,-6,5:1.0
6,-6,5:1.0
7,-6,5:1.0
8,-6,5:1.0
9,-6,5:1.0
10,-6,5:1.0
11,-6,5:1.0
12,-6,5:1.0
13,-6,5:1.0
14,-6,5:1.0
15,-6,5:1.0
16,-6,5:80.0
-2,-5,5:1.0
-1,-5,5:1.0
0,-5,5:1.0
1,-5,5:1.0
2,-5,5:1.0
3,-5,5:1.0
4,-5,5:1.0
5,-5,5:1.0
6,-5,5:1.0
7,-5,5:1.0
8,-5,5:1.0
9,-5,5:1.0
10,-5,5:1.0
11,-5,5:1.0
12,-5,5:1.0
13,-5,5:1.0
14,-5,5:1.0
15,-5,5:80.0
-2,-4,5:1.0
-1,-4,5:1.0
0,-4,5:1.0
1,-4,5:1.0
2,-4,5:1.0
3,-4,5:1.0
4,-4,5:1.0
5,-4,5:1.0
6,-4,5:1.0
7,-4,5:1.0
8,-4,5:1.0
9,-4,5:1.0
10,-4,5:1.0
11,-4,5:1.0
12,-4,5:1.0
13,-4,5:1.0
14,-4,5:1.0
-3,-3,5:1.0
-2,-3,5:1.0
-1,-3,5:1.0
0,-3,5:1.0
1,-3,5:1.0
2,-3,5:1.0
3,-3,5:1.0
4,-3,5:1.0
5,-3,5:1.0
6,-3,5:1.0
7,-3,5:1.0
8,-3,5:1.0
9,-3,5:1.0
10,-3,5:1.0
11,-3,5:1.0
12,-3,5:1.0
13,-3,5:1.0
-4,-2,5:1.0
-3,-2,5:1.0
-2,-2,5:1.0
-1,-2,5:1.0
0,-2,5:1.0
1,-2,5:1.0
2,-2,5:1.0
3,-2,5:1.0
4,-2,5:1.0
5,-2,5:1.0
6,-2,5:1.0
7,-2,5:1.0
8,-2,5:1.0
9,-2,5:1.0
10,-2,5:1.0
11,-2,5:1.0
12,-2,5:1.0
-5,-1,5:1.0
-4,-1,5:1.0
-3,-1,5:1.0
-2,-1,5:1.0
-1,-1,5:1.0
0,-1,5:1.0
1,-1,5:1.0
2,-1,5:1.0
3,-1,5:1.0
4,-1,5:1.0
5,-1,5:1.0
6,-1,5:1.0
7,-1,5:1.0
8,-1,5:1.0
9,-1,5:1.0
10,-1,5:1.0
11,-1,5:1.0
-5,0,5:1.0
-4,0,5:1.0
-3,0,5:1.0
-2,0,5:1.0
-1,0,5:1.0
0,0,5:1.0
1,0,5:1.0
2,0,5:1.0
3,0,5:1.0
4,0,5:1.0
5,0,5:1.0
6,0,5:1.0
7,0,5:1.0
8,0,5:1.0
9,0,5:1.0
10,0,5:1.0
-6,1,5:1.0
-5,1,5:1.0
-4,1,5:1.0
-3,1,5:1.0
-2,1,5:1.0
-1,1,5:1.0
0,1,5:1.0
1,1,5:1.0
2,1,5:1.0
3,1,5:1.0
4,1,5:1.0
5,1,5:1.0
6,1,5:1.0
7,1,5:1.0
8,1,5:1.0
9,1,5:1.0
10,1,5:80.0
-7,2,5:1.0
-6,2,5:1.0
-5,2,5:1.0
-4,2,5:1.0
-3,2,5:1.0
-2,2,5:1.0
-1,2,5:1.0
0,2,5:1.0
1,2,5:1.0
2,2,5:1.0
3,2,5:1.0
4,2,5:1.0
5,2,5:1.0
6,2,5:1.0
7,2,5:1.0
8,2,5:1.0
9,2,5:1.0
-8,3,5:1.0
-7,3,5:1.0
-6,3,5:1.0
-5,3,5:1.0
-4,3,5:1.0
-3,3,5:1.0
-2,3,5:1.0
-1,3,5:1.0
0,3,5:1.0
1,3,5:1.0
2,3,5:1.0
3,3,5:1.0
4,3,5:1.0
5,3,5:1.0
6,3,5:1.0
7,3,5:1.0
8,3,5:1.0
-9,4,5:80.0
-8,4,5:1.0
-7,4,5:1.0
-6,4,5:1.0
-5,4,5:1.0
-4,4,5:1.0
-3,4,5:1.0
-2,4,5:1.0
-1,4,5:1.0
0,4,5:1.0
1,4,5:1.0
2,4,5:1.0
3,4,5:1.0
4,4,5:1.0
5,4,5:1.0
6,4,5:1.0
-9,5,5:1.0
-8,5,5:1.0
-7,5,5:1.0
-6,5,5:1.0
-5,5,5:1.0
-4,5,5:1.0
-3,5,5:1.0
-2,5,5:1.0
-1,5,5:1.0
0,5,5:1.0
1,5,5:1.0
-9,6,5:1.0
-8,6,5:1.0
-7,6,5:1.0
-6,6,5:1.0
-5,6,5:1.0
-4,6,5:1.0
-3,6,5:1.0
-2,6,5:1.0
-1,6,5:80.0
-9,7,5:80.0
-8,7,5:1.0
-7,7,5:1.0
-6,7,5:1.0
-5,7,5:1.0
-4,7,5:1.0
-3,7,5:1.0
-8,8,5:80.0
-7,8,5:80.0
-6,8,5:1.0
-5,8,5:80.0
10,-13,6:80.0
11,-13,6:1.0
12,-13,6:1.0
13,-13,6:1.0
14,-13,6:1.0
15,-13,6:1.0
16,-13,6:80.0
6,-12,6:80.0
7,-12,6:1.0
8,-12,6:1.0
9,-12,6:1.0
10,-12,6:1.0
11,-12,6:1.0
12,-12,6:1.0
13,-12,6:1.0
14,-12,6:1.0
15,-12,6:1.0
16,-12,6:1.0
4,-11,6:1.0
5,-11,6:1.0
6,-11,6:1.0
7,-11,6:1.0
8,-11,6:1.0
9,-11,6:1.0
10,-11,6:1.0
11,-11,6:1.0
12,-11,6:1.0
13,-11,6:1.0
14,-11,6:1.0
15,-11,6:1.0
16,-11,6:1.0
17,-11,6:80.0
2,-10,6:1.0
3,-10,6:1.0
4,-10,6:1.0
5,-10,6:1.0
6,-10,6:1.0
7,-10,6:1.0
8,-10,6:1.0
9,-10,6:1.0
10,-10,6:1.0
11,-10,6:1.0
12,-10,6:1.0
13,-10,6:1.0
14,-10,6:1.0
15,-10,6:1.0
16,-10,6:1.0
17,-10,6:80.0
1,-9,6:1.0
2,-9,6:1.0
3,-9,6:1.0
4,-9,6:1.0
5,-9,6:1.0
6,-9,6:1.0
7,-9,6:1.0
8,-9,6:1.0
9,-9,6:1.0
10,-9,6:1.0
11,-9,6:1.0
12,-9,6:1.0
13,-9,6:1.0
14,-9,6:1.0
15,-9,6:1.0
16,-9,6:1.0
17,-9,6:80.0
0,-8,6:1.0
1,-8,6:1.0
2,-8,6:1.0
3,-8,6:1.0
4,-8,6:1.0
5,-8,6:1.0
6,-8,6:1.0
7,-8,6:1.0
8,-8,6:1.0
9,-8,6:1.0
10,-8,6:1.0
11,-8,6:1.0
12,-8,6:1.0
13,-8,6:1.0
14,-8,6:1.0
15,-8,6:1.0
16,-8,6:1.0
-1,-7,6:80.0
0,-7,6:1.0
1,-7,6:1.0
2,-7,6:1.0
3,-7,6:1.0
4,-7,6:1.0
5,-7,6:1.0
6,-7,6:1.0
7,-7,6:1.0
8,-7,6:1.0
9,-7,6:1.0
10,-7,6:1.0
11,-7,6:1.0
12,-7,6:1.0
13,-7,6:1.0
14,-7,6:1.0
15,-7,6:1.0
16,-7,6:1.0
-1,-6,6:1.0
0,-6,6:1.0
1,-6,6:1.0
2,-6,6:1.0
3,-6,6:1.0
4,-6,6:1.0
5,-6,6:1.0
6,-6,6:1.0
7,-6,6:1.0
8,-6,6:1.0
9,-6,6:1.0
10,-6,6:1.0
11,-6,6:1.0
12,-6,6:1.0
13,-6,6:1.0
14,-6,6:1.0
15,-6,6:1.0
-2,-5,6:1.0
-1,-5,6:1.0
0,-5,6:1.0
1,-5,6:1.0
2,-5,6:1.0
3,-5,6:1.0
4,-5,6:1.0
5,-5,6:1.0
6,-5,6:1.0
7,-5,6:1.0
8,-5,6:1.0
9,-5,6:1.0
10,-5,6:1.0
11,-5,6:1.0
12,-5,6:1.0
13,-5,6:1.0
14,-5,6:1.0
-2,-4,6:1.0
-1,-4,6:1.0
0,-4,6:1.0
1,-4,6:1.0
2,-4,6:1.0
3,-4,6:1.0
4,-4,6:1.0
5,-4,6:1.0
6,-4,6:1.0
7,-4,6:1.0
8,-4,6:1.0
9,-4,6:1.0
10,-4,6:1.0
11,-4,6:1.0
12,-4,6:1.0
13,-4,6:1.0
14,-4,6:80.0
-3,-3,6:1.0
-2,-3,6:1.0
-1,-3,6:1.0
0,-3,6:1.0
1,-3,6:1.0
2,-3,6:1.0
3,-3,6:1.0
4,-3,6:1.0
5,-3,6:1.0
6,-3,6:1.0
7,-3,6:1.0
8,-3,6:1.0
9,-3,6:1.0
10,-3,6:1.0
11,-3,6:1.0
12,-3,6:1.0
13,-3,6:1.0
-4,-2,6:1.0
-3,-2,6:1.0
-2,-2,6:1.0
-1,-2,6:1.0
0,-2,6:1.0
1,-2,6:1.0
2,-2,6:1.0
3,-2,6:1.0
4,-2,6:1.0
5,-2,6:1.0
6,-2,6:1.0
7,-2,6:1.0
8,-2,6:1.0
9,-2,6:1.0
10,-2,6:1.0
11,-2,6:1.0
12,-2,6:1.0
-5,-1,6:1.0
-4,-1,6:1.0
-3,-1,6:1.0
-2,-1,6:1.0
-1,-1,6:1.0
0,-1,6:1.0
1,-1,6:1.0
2,-1,6:1.0
3,-1,6:1.0
4,-1,6:1.0
5,-1,6:1.0
6,-1,6:1.0
7,-1,6:1.0
8,-1,6:1.0
9,-1,6:1.0
10,-1,6:1.0
11,-1,6:1.0
-5,0,6:1.0
-4,0,6:1.0
-3,0,6:1.0
-2,0,6:1.0
-1,0,6:1.0
0,0,6:1.0
1,0,6:1.0
2,0,6:1.0
3,0,6:1.0
4,0,6:1.0
5,0,6:1.0
6,0,6:1.0
7,0,6:1.0
8,0,6:1.0
9,0,6:1.0
10,0,6:1.0
-6,1,6:1.0
-5,1,6:1.0
-4,1,6:1.0
-3,1,6:1.0
-2,1,6:1.0
-1,1,6:1.0
0,1,6:1.0
1,1,6:1.0
2,1,6:1.0
3,1,6:1.0
4,1,6:1.0
5,1,6:1.0
6,1,6:1.0
7,1,6:1.0
8,1,6:1.0
9,1,6:1.0
-7,2,6:1.0
-6,2,6:1.0
-5,2,6:1.0
-4,2,6:1.0
-3,2,6:1.0
-2,2,6:1.0
-1,2,6:1.0
0,2,6:1.0
1,2,6:1.0
2,2,6:1.0
3,2,6:1.0
4,2,6:1.0
5,2,6:1.0
6,2,6:1.0
7,2,6:1.0
8,2,6:1.0
9,2,6:1.0
-8,3,6:80.0
-7,3,6:1.0
-6,3,6:1.0
-5,3,6:1.0
-4,3,6:1.0
-3,3,6:1.0
-2,3,6:1.0
-1,3,6:1.0
0,3,6:1.0
1,3,6:1.0
2,3,6:1.0
3,3,6:1.0
4,3,6:1.0
5,3,6:1.0
6,3,6:1.0
7,3,6:1.0
8,3,6:1.0
-8,4,6:1.0
-7,4,6:1.0
-6,4,6:1.0
-5,4,6:1.0
-4,4,6:1.0
-3,4,6:1.0
-2,4,6:1.0
-1,4,6:1.0
0,4,6:1.0
1,4,6:1.0
2,4,6:1.0
3,4,6:1.0
4,4,6:1.0
5,4,6:1.0
6,4,6:80.0
-9,5,6:80.0
-8,5,6:1.0
-7,5,6:1.0
-6,5,6:1.0
-5,5,6:1.0
-4,5,6:1.0
-3,5,6:1.0
-2,5,6:1.0
-1,5,6:1.0
0,5,6:1.0
1,5,6:80.0
-9,6,6:80.0
-8,6,6:1.0
-7,6,6:1.0
-6,6,6:1.0
-5,6,6:1.0
-4,6,6:1.0
-3,6,6:1.0
-2,6,6:1.0
-8,7,6:1.0
-7,7,6:1.0
-6,7,6:1.0
-5,7,6:1.0
-4,7,6:1.0
-3,7,6:80.0
-6,8,6:80.0
11,-13,7:80.0
12,-13,7:80.0
13,-13,7:80.0
14,-13,7:80.0
15,-13,7:80.0
7,-12,7:1.0
8,-12,7:1.0
9,-12,7:1.0
10,-12,7:1.0
11,-12,7:1.0
12,-12,7:1.0
13,-12,7:1.0
14,-12,7:1.0
15,-12,7:1.0
16,-12,7:1.0
4,-11,7:1.0
5,-11,7:1.0
6,-11,7:1.0
7,-11,7:1.0
8,-11,7:1.0
9,-11,7:1.0
10,-11,7:1.0
11,-11,7:1.0
12,-11,7:1.0
13,-11,7:1.0
14,-11,7:1.0
15,-11,7:1.0
16,-11,7:1.0
2,-10,7:80.0
3,-10,7:1.0
4,-10,7:1.0
5,-10,7:1.0
6,-10,7:1.0
7,-10,7:1.0
8,-10,7:1.0
9,-10,7:1.0
10,-10,7:1.0
11,-10,7:1.0
12,-10,7:1.0
13,-10,7:1.0
14,-10,7:1.0
15,-10,7:1.0
16,-10,7:1.0
1,-9,7:1.0
2,-9,7:1.0
3,-9,7:1.0
4,-9,7:1.0
5,-9,7:1.0
6,-9,7:1.0
7,-9,7:1.0
8,-9,7:1.0
9,-9,7:1.0
10,-9,7:1.0
11,-9,7:1.0
12,-9,7:1.0
13,-9,7:1.0
14,-9,7:1.0
15,-9,7:1.0
16,-9,7:1.0
0,-8,7:1.0
1,-8,7:1.0
2,-8,7:1.0
3,-8,7:1.0
4,-8,7:1.0
5,-8,7:1.0
6,-8,7:1.0
7,-8,7:1.0
8,-8,7:1.0
9,-8,7:1.0
10,-8,7:1.0
11,-8,7:1.0
12,-8,7:1.0
13,-8,7:1.0
14,-8,7:1.0
15,-8,7:1.0
16,-8,7:1.0
0,-7,7:1.0
1,-7,7:1.0
2,-7,7:1.0
3,-7,7:1.0
4,-7,7:1.0
5,-7,7:1.0
6,-7,7:1.0
7,-7,7:1.0
8,-7,7:1.0
9,-7,7:1.0
10,-7,7:1.0
11,-7,7:1.0
12,-7,7:1.0
13,-7,7:1.0
14,-7,7:1.0
15,-7,7:1.0
16,-7,7:80.0
-1,-6,7:1.0
0,-6,7:1.0
1,-6,7:1.0
2,-6,7:1.0
3,-6,7:1.0
4,-6,7:1.0
5,-6,7:1.0
6,-6,7:1.0
7,-6,7:1.0
8,-6,7:1.0
9,-6,7:1.0
10,-6,7:1.0
11,-6,7:1.0
12,-6,7:1.0
13,-6,7:1.0
14,-6,7:1.0
15,-6,7:1.0
-1,-5,7:1.0
0,-5,7:1.0
1,-5,7:1.0
2,-5,7:1.0
3,-5,7:1.0
4,-5,7:1.0
5,-5,7:1.0
6,-5,7:1.0
7,-5,7:1.0
8,-5,7:1.0
9,-5,7:1.0
10,-5,7:1.0
11,-5,7:1.0
12,-5,7:1.0
13,-5,7:1.0
14,-5,7:1.0
-2,-4,7:1.0
-1,-4,7:1.0
0,-4,7:1.0
1,-4,7:1.0
2,-4,7:1.0
3,-4,7:1.0
4,-4,7:1.0
5,-4,7:1.0
6,-4,7:1.0
7,-4,7:1.0
8,-4,7:1.0
9,-4,7:1.0
10,-4,7:1.0
11,-4,7:1.0
12,-4,7:1.0
13,-4,7:1.0
-3,-3,7:1.0
-2,-3,7:1.0
-1,-3,7:1.0
0,-3,7:1.0
1,-3,7:1.0
2,-3,7:1.0
3,-3,7:1.0
4,-3,7:1.0
5,-3,7:1.0
6,-3,7:1.0
7,-3,7:1.0
8,-3,7:1.0
9,-3,7:1.0
10,-3,7:1.0
11,-3,7:1.0
12,-3,7:1.0
13,-3,7:80.0
-4,-2,7:1.0
-3,-2,7:1.0
-2,-2,7:1.0
-1,-2,7:1.0
0,-2,7:1.0
1,-2,7:1.0
2,-2,7:1.0
3,-2,7:1.0
4,-2,7:1.0
5,-2,7:1.0
6,-2,7:1.0
7,-2,7:1.0
8,-2,7:1.0
9,-2,7:1.0
10,-2,7:1.0
11,-2,7:1.0
12,-2,7:1.0
-4,-1,7:1.0
-3,-1,7:1.0
-2,-1,7:1.0
-1,-1,7:1.0
0,-1,7:1.0
1,-1,7:1.0
2,-1,7:1.0
3,-1,7:1.0
4,-1,7:1.0
5,-1,7:1.0
6,-1,7:1.0
7,-1,7:1.0
8,-1,7:1.0
9,-1,7:1.0
10,-1,7:1.0
11,-1,7:1.0
-5,0,7:1.0
-4,0,7:1.0
-3,0,7:1.0
-2,0,7:1.0
-1,0,7:1.0
0,0,7:1.0
1,0,7:1.0
2,0,7:1.0
3,0,7:1.0
4,0,7:1.0
5,0,7:1.0
6,0,7:1.0
7,0,7:1.0
8,0,7:1.0
9,0,7:1.0
10,0,7:1.0
-6,1,7:1.0
-5,1,7:1.0
-4,1,7:1.0
-3,1,7:1.0
-2,1,7:1.0
-1,1,7:1.0
0,1,7:1.0
1,1,7:1.0
2,1,7:1.0
3,1,7:1.0
4,1,7:1.0
5,1,7:1.0
6,1,7:1.0
7,1,7:1.0
8,1,7:1.0
9,1,7:1.0
-7,2,7:80.0
-6,2,7:1.0
-5,2,7:1.0
-4,2,7:1.0
-3,2,7:1.0
-2,2,7:1.0
-1,2,7:1.0
0,2,7:1.0
1,2,7:1.0
2,2,7:1.0
3,2,7:1.0
4,2,7:1.0
5,2,7:1.0
6,2,7:1.0
7,2,7:1.0
8,2,7:1.0
9,2,7:80.0
-7,3,7:1.0
-6,3,7:1.0
-5,3,7:1.0
-4,3,7:1.0
-3,3,7:1.0
-2,3,7:1.0
-1,3,7:1.0
0,3,7:1.0
1,3,7:1.0
2,3,7:1.0
3,3,7:1.0
4,3,7:1.0
5,3,7:1.0
6,3,7:1.0
7,3,7:1.0
8,3,7:80.0
-8,4,7:1.0
-7,4,7:1.0
-6,4,7:1.0
-5,4,7:1.0
-4,4,7:1.0
-3,4,7:1.0
-2,4,7:1.0
-1,4,7:1.0
0,4,7:1.0
1,4,7:1.0
2,4,7:1.0
3,4,7:1.0
4,4,7:1.0
5,4,7:80.0
-8,5,7:1.0
-7,5,7:1.0
-6,5,7:1.0
-5,5,7:1.0
-4,5,7:1.0
-3,5,7:1.0
-2,5,7:1.0
-1,5,7:1.0
0,5,7:1.0
-8,6,7:1.0
-7,6,7:1.0
-6,6,7:1.0
-5,6,7:1.0
-4,6,7:1.0
-3,6,7:1.0
-2,6,7:1.0
-8,7,7:80.0
-7,7,7:1.0
-6,7,7:1.0
-5,7,7:1.0
-4,7,7:1.0
7,-12,8:80.0
8,-12,8:1.0
9,-12,8:1.0
10,-12,8:1.0
11,-12,8:1.0
12,-12,8:1.0
13,-12,8:1.0
14,-12,8:1.0
15,-12,8:1.0
16,-12,8:80.0
4,-11,8:80.0
5,-11,8:1.0
6,-11,8:1.0
7,-11,8:1.0
8,-11,8:1.0
9,-11,8:1.0
10,-11,8:1.0
11,-11,8:1.0
12,-11,8:1.0
13,-11,8:1.0
14,-11,8:1.0
15,-11,8:1.0
16,-11,8:1.0
3,-10,8:1.0
4,-10,8:1.0
5,-10,8:1.0
6,-10,8:1.0
7,-10,8:1.0
8,-10,8:1.0
9,-10,8:1.0
10,-10,8:1.0
11,-10,8:1.0
12,-10,8:1.0
13,-10,8:1.0
14,-10,8:1.0
15,-10,8:1.0
16,-10,8:1.0
1,-9,8:80.0
2,-9,8:1.0
3,-9,8:1.0
4,-9,8:1.0
5,-9,8:1.0
6,-9,8:1.0
7,-9,8:1.0
8,-9,8:1.0
9,-9,8:1.0
10,-9,8:1.0
11,-9,8:1.0
12,-9,8:1.0
13,-9,8:1.0
14,-9,8:1.0
15,-9,8:1.0
16,-9,8:1.0
0,-8,8:80.0
1,-8,8:1.0
2,-8,8:1.0
3,-8,8:1.0
4,-8,8:1.0
5,-8,8:1.0
6,-8,8:1.0
7,-8,8:1.0
8,-8,8:1.0
9,-8,8:1.0
10,-8,8:1.0
11,-8,8:1.0
12,-8,8:1.0
13,-8,8:1.0
14,-8,8:1.0
15,-8,8:1.0
16,-8,8:1.0
0,-7,8:1.0
1,-7,8:1.0
2,-7,8:1.0
3,-7,8:1.0
4,-7,8:1.0
5,-7,8:1.0
6,-7,8:1.0
7,-7,8:1.0
8,-7,8:1.0
9,-7,8:1.0
10,-7,8:1.0
11,-7,8:1.0
12,-7,8:1.0
13,-7,8:1.0
14,-7,8:1.0
15,-7,8:1.0
-1,-6,8:1.0
0,-6,8:1.0
1,-6,8:1.0
2,-6,8:1.0
3,-6,8:1.0
4,-6,8:1.0
5,-6,8:1.0
6,-6,8:1.0
7,-6,8:1.0
8,-6,8:1.0
9,-6,8:1.0
10,-6,8:1.0
11,-6,8:1.0
12,-6,8:1.0
13,-6,8:1.0
14,-6,8:1.0
15,-6,8:1.0
-1,-5,8:1.0
0,-5,8:1.0
1,-5,8:1.0
2,-5,8:1.0
3,-5,8:1.0
4,-5,8:1.0
5,-5,8:1.0
6,-5,8:1.0
7,-5,8:1.0
8,-5,8:1.0
9,-5,8:1.0
10,-5,8:1.0
11,-5,8:1.0
12,-5,8:1.0
13,-5,8:1.0
14,-5,8:1.0
-2,-4,8:1.0
-1,-4,8:1.0
0,-4,8:1.0
1,-4,8:1.0
2,-4,8:1.0
3,-4,8:1.0
4,-4,8:1.0
5,-4,8:1.0
6,-4,8:1.0
7,-4,8:1.0
8,-4,8:1.0
9,-4,8:1.0
10,-4,8:1.0
11,-4,8:1.0
12,-4,8:1.0
13,-4,8:1.0
-3,-3,8:80.0
-2,-3,8:1.0
-1,-3,8:1.0
0,-3,8:1.0
1,-3,8:1.0
2,-3,8:1.0
3,-3,8:1.0
4,-3,8:1.0
5,-3,8:1.0
6,-3,8:1.0
7,-3,8:1.0
8,-3,8:1.0
9,-3,8:1.0
10,-3,8:1.0
11,-3,8:1.0
12,-3,8:1.0
-3,-2,8:1.0
-2,-2,8:1.0
-1,-2,8:1.0
0,-2,8:1.0
1,-2,8:1.0
2,-2,8:1.0
3,-2,8:1.0
4,-2,8:1.0
5,-2,8:1.0
6,-2,8:1.0
7,-2,8:1.0
8,-2,8:1.0
9,-2,8:1.0
10,-2,8:1.0
11,-2,8:1.0
12,-2,8:80.0
-4,-1,8:1.0
-3,-1,8:1.0
-2,-1,8:1.0
-1,-1,8:1.0
0,-1,8:1.0
1,-1,8:1.0
2,-1,8:1.0
3,-1,8:1.0
4,-1,8:1.0
5,-1,8:1.0
6,-1,8:1.0
7,-1,8:1.0
8,-1,8:1.0
9,-1,8:1.0
10,-1,8:1.0
11,-1,8:80.0
-5,0,8:1.0
-4,0,8:1.0
-3,0,8:1.0
-2,0,8:1.0
-1,0,8:1.0
0,0,8:1.0
1,0,8:1.0
2,0,8:1.0
3,0,8:1.0
4,0,8:1.0
5,0,8:1.0
6,0,8:1.0
7,0,8:1.0
8,0,8:1.0
9,0,8:1.0
10,0,8:1.0
-6,1,8:80.0
-5,1,8:1.0
-4,1,8:1.0
-3,1,8:1.0
-2,1,8:1.0
-1,1,8:1.0
0,1,8:1.0
1,1,8:1.0
2,1,8:1.0
3,1,8:1.0
4,1,8:1.0
5,1,8:1.0
6,1,8:1.0
7,1,8:1.0
8,1,8:1.0
9,1,8:1.0
-6,2,8:1.0
-5,2,8:1.0
-4,2,8:1.0
-3,2,8:1.0
-2,2,8:1.0
-1,2,8:1.0
0,2,8:1.0
1,2,8:1.0
2,2,8:1.0
3,2,8:1.0
4,2,8:1.0
5,2,8:1.0
6,2,8:1.0
7,2,8:1.0
8,2,8:1.0
-7,3,8:1.0
-6,3,8:1.0
-5,3,8:1.0
-4,3,8:1.0
-3,3,8:1.0
-2,3,8:1.0
-1,3,8:1.0
0,3,8:1.0
1,3,8:1.0
2,3,8:1.0
3,3,8:1.0
4,3,8:1.0
5,3,8:1.0
6,3,8:1.0
7,3,8:1.0
-8,4,8:1.0
-7,4,8:1.0
-6,4,8:1.0
-5,4,8:1.0
-4,4,8:1.0
-3,4,8:1.0
-2,4,8:1.0
-1,4,8:1.0
0,4,8:1.0
1,4,8:1.0
2,4,8:1.0
3,4,8:1.0
4,4,8:80.0
-8,5,8:1.0
-7,5,8:1.0
-6,5,8:1.0
-5,5,8:1.0
-4,5,8:1.0
-3,5,8:1.0
-2,5,8:1.0
-1,5,8:1.0
0,5,8:1.0
-8,6,8:1.0
-7,6,8:1.0
-6,6,8:1.0
-5,6,8:1.0
-4,6,8:1.0
-3,6,8:1.0
-2,6,8:80.0
-7,7,8:1.0
-6,7,8:1.0
-5,7,8:1.0
-4,7,8:80.0
8,-12,9:80.0
9,-12,9:1.0
10,-12,9:1.0
11,-12,9:1.0
12,-12,9:1.0
13,-12,9:1.0
14,-12,9:1.0
15,-12,9:80.0
5,-11,9:80.0
6,-11,9:1.0
7,-11,9:1.0
8,-11,9:1.0
9,-11,9:1.0
10,-11,9:1.0
11,-11,9:1.0
12,-11,9:1.0
13,-11,9:1.0
14,-11,9:1.0
15,-11,9:1.0
16,-11,9:80.0
3,-10,9:1.0
4,-10,9:1.0
5,-10,9:1.0
6,-10,9:1.0
7,-10,9:1.0
8,-10,9:1.0
9,-10,9:1.0
10,-10,9:1.0
11,-10,9:1.0
12,-10,9:1.0
13,-10,9:1.0
14,-10,9:1.0
15,-10,9:1.0
16,-10,9:1.0
2,-9,9:1.0
3,-9,9:1.0
4,-9,9:1.0
5,-9,9:1.0
6,-9,9:1.0
7,-9,9:1.0
8,-9,9:1.0
9,-9,9:1.0
10,-9,9:1.0
11,-9,9:1.0
12,-9,9:1.0
13,-9,9:1.0
14,-9,9:1.0
15,-9,9:1.0
16,-9,9:1.0
1,-8,9:1.0
2,-8,9:1.0
3,-8,9:1.0
4,-8,9:1.0
5,-8,9:1.0
6,-8,9:1.0
7,-8,9:1.0
8,-8,9:1.0
9,-8,9:1.0
10,-8,9:1.0
11,-8,9:1.0
12,-8,9:1.0
13,-8,9:1.0
14,-8,9:1.0
15,-8,9:1.0
16,-8,9:80.0
0,-7,9:1.0
1,-7,9:1.0
2,-7,9:1.0
3,-7,9:1.0
4,-7,9:1.0
5,-7,9:1.0
6,-7,9:1.0
7,-7,9:1.0
8,-7,9:1.0
9,-7,9:1.0
10,-7,9:1.0
11,-7,9:1.0
12,-7,9:1.0
13,-7,9:1.0
14,-7,9:1.0
15,-7,9:1.0
-1,-6,9:1.0
0,-6,9:1.0
1,-6,9:1.0
2,-6,9:1.0
3,-6,9:1.0
4,-6,9:1.0
5,-6,9:1.0
6,-6,9:1.0
7,-6,9:1.0
8,-6,9:1.0
9,-6,9:1.0
10,-6,9:1.0
11,-6,9:1.0
12,-6,9:1.0
13,-6,9:1.0
14,-6,9:1.0
15,-6,9:80.0
-1,-5,9:1.0
0,-5,9:1.0
1,-5,9:1.0
2,-5,9:1.0
3,-5,9:1.0
4,-5,9:1.0
5,-5,9:1.0
6,-5,9:1.0
7,-5,9:1.0
8,-5,9:1.0
9,-5,9:1.0
10,-5,9:1.0
11,-5,9:1.0
12,-5,9:1.0
13,-5,9:1.0
14,-5,9:1.0
-2,-4,9:1.0
-1,-4,9:1.0
0,-4,9:1.0
1,-4,9:1.0
2,-4,9:1.0
3,-4,9:1.0
4,-4,9:1.0
5,-4,9:1.0
6,-4,9:1.0
7,-4,9:1.0
8,-4,9:1.0
9,-4,9:1.0
10,-4,9:1.0
11,-4,9:1.0
12,-4,9:1.0
13,-4,9:1.0
-2,-3,9:1.0
-1,-3,9:1.0
0,-3,9:1.0
1,-3,9:1.0
2,-3,9:1.0
3,-3,9:1.0
4,-3,9:1.0
5,-3,9:1.0
6,-3,9:1.0
7,-3,9:1.0
8,-3,9:1.0
9,-3,9:1.0
10,-3,9:1.0
11,-3,9:1.0
12,-3,9:1.0
-3,-2,9:1.0
-2,-2,9:1.0
-1,-2,9:1.0
0,-2,9:1.0
1,-2,9:1.0
2,-2,9:1.0
3,-2,9:1.0
4,-2,9:1.0
5,-2,9:1.0
6,-2,9:1.0
7,-2,9:1.0
8,-2,9:1.0
9,-2,9:1.0
10,-2,9:1.0
11,-2,9:1.0
-4,-1,9:1.0
-3,-1,9:1.0
-2,-1,9:1.0
-1,-1,9:1.0
0,-1,9:1.0
1,-1,9:1.0
2,-1,9:1.0
3,-1,9:1.0
4,-1,9:1.0
5,-1,9:1.0
6,-1,9:1.0
7,-1,9:1.0
8,-1,9:1.0
9,-1,9:1.0
10,-1,9:1.0
-5,0,9:1.0
-4,0,9:1.0
-3,0,9:1.0
-2,0,9:1.0
-1,0,9:1.0
0,0,9:1.0
1,0,9:1.0
2,0,9:1.0
3,0,9:1.0
4,0,9:1.0
5,0,9:1.0
6,0,9:1.0
7,0,9:1.0
8,0,9:1.0
9,0,9:1.0
10,0,9:80.0
-5,1,9:1.0
-4,1,9:1.0
-3,1,9:1.0
-2,1,9:1.0
-1,1,9:1.0
0,1,9:1.0
1,1,9:1.0
2,1,9:1.0
3,1,9:1.0
4,1,9:1.0
5,1,9:1.0
6,1,9:1.0
7,1,9:1.0
8,1,9:1.0
9,1,9:1.0
-6,2,9:1.0
-5,2,9:1.0
-4,2,9:1.0
-3,2,9:1.0
-2,2,9:1.0
-1,2,9:1.0
0,2,9:1.0
1,2,9:1.0
2,2,9:1.0
3,2,9:1.0
4,2,9:1.0
5,2,9:1.0
6,2,9:1.0
7,2,9:1.0
8,2,9:1.0
-7,3,9:1.0
-6,3,9:1.0
-5,3,9:1.0
-4,3,9:1.0
-3,3,9:1.0
-2,3,9:1.0
-1,3,9:1.0
0,3,9:1.0
1,3,9:1.0
2,3,9:1.0
3,3,9:1.0
4,3,9:1.0
5,3,9:1.0
6,3,9:1.0
7,3,9:1.0
-8,4,9:80.0
-7,4,9:1.0
-6,4,9:1.0
-5,4,9:1.0
-4,4,9:1.0
-3,4,9:1.0
-2,4,9:1.0
-1,4,9:1.0
0,4,9:1.0
1,4,9:1.0
2,4,9:1.0
3,4,9:1.0
-8,5,9:1.0
-7,5,9:1.0
-6,5,9:1.0
-5,5,9:1.0
-4,5,9:1.0
-3,5,9:1.0
-2,5,9:1.0
-1,5,9:1.0
0,5,9:80.0
-8,6,9:80.0
-7,6,9:1.0
-6,6,9:1.0
-5,6,9:1.0
-4,6,9:1.0
-3,6,9:1.0
-7,7,9:80.0
-6,7,9:1.0
-5,7,9:80.0
9,-12,10:1.0
10,-12,10:1.0
11,-12,10:1.0
12,-12,10:1.0
13,-12,10:1.0
14,-12,10:1.0
6,-11,10:1.0
7,-11,10:1.0
8,-11,10:1.0
9,-11,10:1.0
10,-11,10:1.0
11,-11,10:1.0
12,-11,10:1.0
13,-11,10:1.0
14,-11,10:1.0
15,-11,10:1.0
3,-10,10:80.0
4,-10,10:1.0
5,-10,10:1.0
6,-10,10:1.0
7,-10,10:1.0
8,-10,10:1.0
9,-10,10:1.0
10,-10,10:1.0
11,-10,10:1.0
12,-10,10:1.0
13,-10,10:1.0
14,-10,10:1.0
15,-10,10:1.0
16,-10,10:80.0
2,-9,10:1.0
3,-9,10:1.0
4,-9,10:1.0
5,-9,10:1.0
6,-9,10:1.0
7,-9,10:1.0
8,-9,10:1.0
9,-9,10:1.0
10,-9,10:1.0
11,-9,10:1.0
12,-9,10:1.0
13,-9,10:1.0
14,-9,10:1.0
15,-9,10:1.0
16,-9,10:80.0
1,-8,10:1.0
2,-8,10:1.0
3,-8,10:1.0
4,-8,10:1.0
5,-8,10:1.0
6,-8,10:1.0
7,-8,10:1.0
8,-8,10:1.0
9,-8,10:1.0
10,-8,10:1.0
11,-8,10:1.0
12,-8,10:1.0
13,-8,10:1.0
14,-8,10:1.0
15,-8,10:1.0
0,-7,10:1.0
1,-7,10:1.0
2,-7,10:1.0
3,-7,10:1.0
4,-7,10:1.0
5,-7,10:1.0
6,-7,10:1.0
7,-7,10:1.0
8,-7,10:1.0
9,-7,10:1.0
10,-7,10:1.0
11,-7,10:1.0
12,-7,10:1.0
13,-7,10:1.0
14,-7,10:1.0
15,-7,10:1.0
-1,-6,10:80.0
0,-6,10:1.0
1,-6,10:1.0
2,-6,10:1.0
3,-6,10:1.0
4,-6,10:1.0
5,-6,10:1.0
6,-6,10:1.0
7,-6,10:1.0
8,-6,10:1.0
9,-6,10:1.0
10,-6,10:1.0
11,-6,10:1.0
12,-6,10:1.0
13,-6,10:1.0
14,-6,10:1.0
-1,-5,10:1.0
0,-5,10:1.0
1,-5,10:1.0
2,-5,10:1.0
3,-5,10:1.0
4,-5,10:1.0
5,-5,10:1.0
6,-5,10:1.0
7,-5,10:1.0
8,-5,10:1.0
9,-5,10:1.0
10,-5,10:1.0
11,-5,10:1.0
12,-5,10:1.0
13,-5,10:1.0
14,-5,10:80.0
-2,-4,10:1.0
-1,-4,10:1.0
0,-4,10:1.0
1,-4,10:1.0
2,-4,10:1.0
3,-4,10:1.0
4,-4,10:1.0
5,-4,10:1.0
6,-4,10:1.0
7,-4,10:1.0
8,-4,10:1.0
9,-4,10:1.0
10,-4,10:1.0
11,-4,10:1.0
12,-4,10:1.0
13,-4,10:1.0
-2,-3,10:1.0
-1,-3,10:1.0
0,-3,10:1.0
1,-3,10:1.0
2,-3,10:1.0
3,-3,10:1.0
4,-3,10:1.0
5,-3,10:1.0
6,-3,10:1.0
7,-3,10:1.0
8,-3,10:1.0
9,-3,10:1.0
10,-3,10:1.0
11,-3,10:1.0
12,-3,10:1.0
-3,-2,10:1.0
-2,-2,10:1.0
-1,-2,10:1.0
0,-2,10:1.0
1,-2,10:1.0
2,-2,10:1.0
3,-2,10:1.0
4,-2,10:1.0
5,-2,10:1.0
6,-2,10:1.0
7,-2,10:1.0
8,-2,10:1.0
9,-2,10:1.0
10,-2,10:1.0
11,-2,10:1.0
-4,-1,10:1.0
-3,-1,10:1.0
-2,-1,10:1.0
-1,-1,10:1.0
0,-1,10:1.0
1,-1,10:1.0
2,-1,10:1.0
3,-1,10:1.0
4,-1,10:1.0
5,-1,10:1.0
6,-1,10:1.0
7,-1,10:1.0
8,-1,10:1.0
9,-1,10:1.0
10,-1,10:1.0
-5,0,10:80.0
-4,0,10:1.0
-3,0,10:1.0
-2,0,10:1.0
-1,0,10:1.0
0,0,10:1.0
1,0,10:1.0
2,0,10:1.0
3,0,10:1.0
4,0,10:1.0
5,0,10:1.0
6,0,10:1.0
7,0,10:1.0
8,0,10:1.0
9,0,10:1.0
-5,1,10:1.0
-4,1,10:1.0
-3,1,10:1.0
-2,1,10:1.0
-1,1,10:1.0
0,1,10:1.0
1,1,10:1.0
2,1,10:1.0
3,1,10:1.0
4,1,10:1.0
5,1,10:1.0
6,1,10:1.0
7,1,10:1.0
8,1,10:1.0
9,1,10:80.0
-6,2,10:1.0
-5,2,10:1.0
-4,2,10:1.0
-3,2,10:1.0
-2,2,10:1.0
-1,2,10:1.0
0,2,10:1.0
1,2,10:1.0
2,2,10:1.0
3,2,10:1.0
4,2,10:1.0
5,2,10:1.0
6,2,10:1.0
7,2,10:1.0
8,2,10:1.0
-7,3,10:80.0
-6,3,10:1.0
-5,3,10:1.0
-4,3,10:1.0
-3,3,10:1.0
-2,3,10:1.0
-1,3,10:1.0
0,3,10:1.0
1,3,10:1.0
2,3,10:1.0
3,3,10:1.0
4,3,10:1.0
5,3,10:1.0
6,3,10:1.0
7,3,10:80.0
-7,4,10:1.0
-6,4,10:1.0
-5,4,10:1.0
-4,4,10:1.0
-3,4,10:1.0
-2,4,10:1.0
-1,4,10:1.0
0,4,10:1.0
1,4,10:1.0
2,4,10:1.0
3,4,10:80.0
-8,5,10:80.0
-7,5,10:1.0
-6,5,10:1.0
-5,5,10:1.0
-4,5,10:1.0
-3,5,10:1.0
-2,5,10:1.0
-1,5,10:1.0
-7,6,10:1.0
-6,6,10:1.0
-5,6,10:1.0
-4,6,10:1.0
-3,6,10:1.0
-6,7,10:80.0
9,-12,11:80.0
10,-12,11:1.0
11,-12,11:1.0
12,-12,11:1.0
13,-12,11:1.0
14,-12,11:80.0
6,-11,11:80.0
7,-11,11:1.0
8,-11,11:1.0
9,-11,11:1.0
10,-11,11:1.0
11,-11,11:1.0
12,-11,11:1.0
13,-11,11:1.0
14,-11,11:1.0
15,-11,11:1.0
4,-10,11:1.0
5,-10,11:1.0
6,-10,11:1.0
7,-10,11:1.0
8,-10,11:1.0
9,-10,11:1.0
10,-10,11:1.0
11,-10,11:1.0
12,-10,11:1.0
13,-10,11:1.0
14,-10,11:1.0
15,-10,11:1.0
2,-9,11:1.0
3,-9,11:1.0
4,-9,11:1.0
5,-9,11:1.0
6,-9,11:1.0
7,-9,11:1.0
8,-9,11:1.0
9,-9,11:1.0
10,-9,11:1.0
11,-9,11:1.0
12,-9,11:1.0
13,-9,11:1.0
14,-9,11:1.0
15,-9,11:1.0
1,-8,11:1.0
2,-8,11:1.0
3,-8,11:1.0
4,-8,11:1.0
5,-8,11:1.0
6,-8,11:1.0
7,-8,11:1.0
8,-8,11:1.0
9,-8,11:1.0
10,-8,11:1.0
11,-8,11:1.0
12,-8,11:1.0
13,-8,11:1.0
14,-8,11:1.0
15,-8,11:1.0
0,-7,11:1.0
1,-7,11:1.0
2,-7,11:1.0
3,-7,11:1.0
4,-7,11:1.0
5,-7,11:1.0
6,-7,11:1.0
7,-7,11:1.0
8,-7,11:1.0
9,-7,11:1.0
10,-7,11:1.0
11,-7,11:1.0
12,-7,11:1.0
13,-7,11:1.0
14,-7,11:1.0
15,-7,11:1.0
0,-6,11:1.0
1,-6,11:1.0
2,-6,11:1.0
3,-6,11:1.0
4,-6,11:1.0
5,-6,11:1.0
6,-6,11:1.0
7,-6,11:1.0
8,-6,11:1.0
9,-6,11:1.0
10,-6,11:1.0
11,-6,11:1.0
12,-6,11:1.0
13,-6,11:1.0
14,-6,11:1.0
-1,-5,11:1.0
0,-5,11:1.0
1,-5,11:1.0
2,-5,11:1.0
3,-5,11:1.0
4,-5,11:1.0
5,-5,11:1.0
6,-5,11:1.0
7,-5,11:1.0
8,-5,11:1.0
9,-5,11:1.0
10,-5,11:1.0
11,-5,11:1.0
12,-5,11:1.0
13,-5,11:1.0
-2,-4,11:80.0
-1,-4,11:1.0
0,-4,11:1.0
1,-4,11:1.0
2,-4,11:1.0
3,-4,11:1.0
4,-4,11:1.0
5,-4,11:1.0
6,-4,11:1.0
7,-4,11:1.0
8,-4,11:1.0
9,-4,11:1.0
10,-4,11:1.0
11,-4,11:1.0
12,-4,11:1.0
13,-4,11:1.0
-2,-3,11:1.0
-1,-3,11:1.0
0,-3,11:1.0
1,-3,11:1.0
2,-3,11:1.0
3,-3,11:1.0
4,-3,11:1.0
5,-3,11:1.0
6,-3,11:1.0
7,-3,11:1.0
8,-3,11:1.0
9,-3,11:1.0
10,-3,11:1.0
11,-3,11:1.0
12,-3,11:1.0
-3,-2,11:1.0
-2,-2,11:1.0
-1,-2,11:1.0
0,-2,11:1.0
1,-2,11:1.0
2,-2,11:1.0
3,-2,11:1.0
4,-2,11:1.0
5,-2,11:1.0
6,-2,11:1.0
7,-2,11:1.0
8,-2,11:1.0
9,-2,11:1.0
10,-2,11:1.0
11,-2,11:1.0
-4,-1,11:80.0
-3,-1,11:1.0
-2,-1,11:1.0
-1,-1,11:1.0
0,-1,11:1.0
1,-1,11:1.0
2,-1,11:1.0
3,-1,11:1.0
4,-1,11:1.0
5,-1,11:1.0
6,-1,11:1.0
7,-1,11:1.0
8,-1,11:1.0
9,-1,11:1.0
10,-1,11:1.0
-4,0,11:1.0
-3,0,11:1.0
-2,0,11:1.0
-1,0,11:1.0
0,0,11:1.0
1,0,11:1.0
2,0,11:1.0
3,0,11:1.0
4,0,11:1.0
5,0,11:1.0
6,0,11:1.0
7,0,11:1.0
8,0,11:1.0
9,0,11:1.0
-5,1,11:1.0
-4,1,11:1.0
-3,1,11:1.0
-2,1,11:1.0
-1,1,11:1.0
0,1,11:1.0
1,1,11:1.0
2,1,11:1.0
3,1,11:1.0
4,1,11:1.0
5,1,11:1.0
6,1,11:1.0
7,1,11:1.0
8,1,11:1.0
-6,2,11:80.0
-5,2,11:1.0
-4,2,11:1.0
-3,2,11:1.0
-2,2,11:1.0
-1,2,11:1.0
0,2,11:1.0
1,2,11:1.0
2,2,11:1.0
3,2,11:1.0
4,2,11:1.0
5,2,11:1.0
6,2,11:1.0
7,2,11:1.0
8,2,11:80.0
-6,3,11:1.0
-5,3,11:1.0
-4,3,11:1.0
-3,3,11:1.0
-2,3,11:1.0
-1,3,11:1.0
0,3,11:1.0
1,3,11:1.0
2,3,11:1.0
3,3,11:1.0
4,3,11:1.0
5,3,11:1.0
6,3,11:1.0
-7,4,11:1.0
-6,4,11:1.0
-5,4,11:1.0
-4,4,11:1.0
-3,4,11:1.0
-2,4,11:1.0
-1,4,11:1.0
0,4,11:1.0
1,4,11:1.0
2,4,11:1.0
-7,5,11:1.0
-6,5,11:1.0
-5,5,11:1.0
-4,5,11:1.0
-3,5,11:1.0
-2,5,11:1.0
-1,5,11:80.0
-7,6,11:80.0
-6,6,11:1.0
-5,6,11:1.0
-4,6,11:1.0
-3,6,11:80.0
10,-12,12:80.0
11,-12,12:1.0
12,-12,12:1.0
13,-12,12:80.0
7,-11,12:1.0
8,-11,12:1.0
9,-11,12:1.0
10,-11,12:1.0
11,-11,12:1.0
12,-11,12:1.0
13,-11,12:1.0
14,-11,12:1.0
15,-11,12:80.0
4,-10,12:1.0
5,-10,12:1.0
6,-10,12:1.0
7,-10,12:1.0
8,-10,12:1.0
9,-10,12:1.0
10,-10,12:1.0
11,-10,12:1.0
12,-10,12:1.0
13,-10,12:1.0
14,-10,12:1.0
15,-10,12:1.0
2,-9,12:80.0
3,-9,12:1.0
4,-9,12:1.0
5,-9,12:1.0
6,-9,12:1.0
7,-9,12:1.0
8,-9,12:1.0
9,-9,12:1.0
10,-9,12:1.0
11,-9,12:1.0
12,-9,12:1.0
13,-9,12:1.0
14,-9,12:1.0
15,-9,12:1.0
1,-8,12:1.0
2,-8,12:1.0
3,-8,12:1.0
4,-8,12:1.0
5,-8,12:1.0
6,-8,12:1.0
7,-8,12:1.0
8,-8,12:1.0
9,-8,12:1.0
10,-8,12:1.0
11,-8,12:1.0
12,-8,12:1.0
13,-8,12:1.0
14,-8,12:1.0
15,-8,12:1.0
0,-7,12:1.0
1,-7,12:1.0
2,-7,12:1.0
3,-7,12:1.0
4,-7,12:1.0
5,-7,12:1.0
6,-7,12:1.0
7,-7,12:1.0
8,-7,12:1.0
9,-7,12:1.0
10,-7,12:1.0
11,-7,12:1.0
12,-7,12:1.0
13,-7,12:1.0
14,-7,12:1.0
15,-7,12:80.0
0,-6,12:1.0
1,-6,12:1.0
2,-6,12:1.0
3,-6,12:1.0
4,-6,12:1.0
5,-6,12:1.0
6,-6,12:1.0
7,-6,12:1.0
8,-6,12:1.0
9,-6,12:1.0
10,-6,12:1.0
11,-6,12:1.0
12,-6,12:1.0
13,-6,12:1.0
14,-6,12:1.0
-1,-5,12:1.0
0,-5,12:1.0
1,-5,12:1.0
2,-5,12:1.0
3,-5,12:1.0
4,-5,12:1.0
5,-5,12:1.0
6,-5,12:1.0
7,-5,12:1.0
8,-5,12:1.0
9,-5,12:1.0
10,-5,12:1.0
11,-5,12:1.0
12,-5,12:1.0
13,-5,12:1.0
-1,-4,12:1.0
0,-4,12:1.0
1,-4,12:1.0
2,-4,12:1.0
3,-4,12:1.0
4,-4,12:1.0
5,-4,12:1.0
6,-4,12:1.0
7,-4,12:1.0
8,-4,12:1.0
9,-4,12:1.0
10,-4,12:1.0
11,-4,12:1.0
12,-4,12:1.0
13,-4,12:80.0
-2,-3,12:1.0
-1,-3,12:1.0
0,-3,12:1.0
1,-3,12:1.0
2,-3,12:1.0
3,-3,12:1.0
4,-3,12:1.0
5,-3,12:1.0
6,-3,12:1.0
7,-3,12:1.0
8,-3,12:1.0
9,-3,12:1.0
10,-3,12:1.0
11,-3,12:1.0
12,-3,12:1.0
-3,-2,12:1.0
-2,-2,12:1.0
-1,-2,12:1.0
0,-2,12:1.0
1,-2,12:1.0
2,-2,12:1.0
3,-2,12:1.0
4,-2,12:1.0
5,-2,12:1.0
6,-2,12:1.0
7,-2,12:1.0
8,-2,12:1.0
9,-2,12:1.0
10,-2,12:1.0
11,-2,12:1.0
-3,-1,12:1.0
-2,-1,12:1.0
-1,-1,12:1.0
0,-1,12:1.0
1,-1,12:1.0
2,-1,12:1.0
3,-1,12:1.0
4,-1,12:1.0
5,-1,12:1.0
6,-1,12:1.0
7,-1,12:1.0
8,-1,12:1.0
9,-1,12:1.0
10,-1,12:1.0
-4,0,12:1.0
-3,0,12:1.0
-2,0,12:1.0
-1,0,12:1.0
0,0,12:1.0
1,0,12:1.0
2,0,12:1.0
3,0,12:1.0
4,0,12:1.0
5,0,12:1.0
6,0,12:1.0
7,0,12:1.0
8,0,12:1.0
9,0,12:1.0
-5,1,12:1.0
-4,1,12:1.0
-3,1,12:1.0
-2,1,12:1.0
-1,1,12:1.0
0,1,12:1.0
1,1,12:1.0
2,1,12:1.0
3,1,12:1.0
4,1,12:1.0
5,1,12:1.0
6,1,12:1.0
7,1,12:1.0
8,1,12:1.0
-5,2,12:1.0
-4,2,12:1.0
-3,2,12:1.0
-2,2,12:1.0
-1,2,12:1.0
0,2,12:1.0
1,2,12:1.0
2,2,12:1.0
3,2,12:1.0
4,2,12:1.0
5,2,12:1.0
6,2,12:1.0
7,2,12:1.0
-6,3,12:1.0
-5,3,12:1.0
-4,3,12:1.0
-3,3,12:1.0
-2,3,12:1.0
-1,3,12:1.0
0,3,12:1.0
1,3,12:1.0
2,3,12:1.0
3,3,12:1.0
4,3,12:1.0
5,3,12:1.0
6,3,12:80.0
-7,4,12:80.0
-6,4,12:1.0
-5,4,12:1.0
-4,4,12:1.0
-3,4,12:1.0
-2,4,12:1.0
-1,4,12:1.0
0,4,12:1.0
1,4,12:1.0
2,4,12:80.0
-7,5,12:80.0
-6,5,12:1.0
-5,5,12:1.0
-4,5,12:1.0
-3,5,12:1.0
-2,5,12:1.0
-6,6,12:1.0
-5,6,12:1.0
-4,6,12:80.0
11,-12,13:80.0
12,-12,13:80.0
7,-11,13:1.0
8,-11,13:1.0
9,-11,13:1.0
10,-11,13:1.0
11,-11,13:1.0
12,-11,13:1.0
13,-11,13:1.0
14,-11,13:1.0
4,-10,13:80.0
5,-10,13:1.0
6,-10,13:1.0
7,-10,13:1.0
8,-10,13:1.0
9,-10,13:1.0
10,-10,13:1.0
11,-10,13:1.0
12,-10,13:1.0
13,-10,13:1.0
14,-10,13:1.0
15,-10,13:80.0
3,-9,13:1.0
4,-9,13:1.0
5,-9,13:1.0
6,-9,13:1.0
7,-9,13:1.0
8,-9,13:1.0
9,-9,13:1.0
10,-9,13:1.0
11,-9,13:1.0
12,-9,13:1.0
13,-9,13:1.0
14,-9,13:1.0
15,-9,13:1.0
1,-8,13:1.0
2,-8,13:1.0
3,-8,13:1.0
4,-8,13:1.0
5,-8,13:1.0
6,-8,13:1.0
7,-8,13:1.0
8,-8,13:1.0
9,-8,13:1.0
10,-8,13:1.0
11,-8,13:1.0
12,-8,13:1.0
13,-8,13:1.0
14,-8,13:1.0
15,-8,13:80.0
0,-7,13:80.0
1,-7,13:1.0
2,-7,13:1.0
3,-7,13:1.0
4,-7,13:1.0
5,-7,13:1.0
6,-7,13:1.0
7,-7,13:1.0
8,-7,13:1.0
9,-7,13:1.0
10,-7,13:1.0
11,-7,13:1.0
12,-7,13:1.0
13,-7,13:1.0
14,-7,13:1.0
0,-6,13:1.0
1,-6,13:1.0
2,-6,13:1.0
3,-6,13:1.0
4,-6,13:1.0
5,-6,13:1.0
6,-6,13:1.0
7,-6,13:1.0
8,-6,13:1.0
9,-6,13:1.0
10,-6,13:1.0
11,-6,13:1.0
12,-6,13:1.0
13,-6,13:1.0
14,-6,13:1.0
-1,-5,13:1.0
0,-5,13:1.0
1,-5,13:1.0
2,-5,13:1.0
3,-5,13:1.0
4,-5,13:1.0
5,-5,13:1.0
6,-5,13:1.0
7,-5,13:1.0
8,-5,13:1.0
9,-5,13:1.0
10,-5,13:1.0
11,-5,13:1.0
12,-5,13:1.0
13,-5,13:1.0
-1,-4,13:1.0
0,-4,13:1.0
1,-4,13:1.0
2,-4,13:1.0
3,-4,13:1.0
4,-4,13:1.0
5,-4,13:1.0
6,-4,13:1.0
7,-4,13:1.0
8,-4,13:1.0
9,-4,13:1.0
10,-4,13:1.0
11,-4,13:1.0
12,-4,13:1.0
-2,-3,13:1.0
-1,-3,13:1.0
0,-3,13:1.0
1,-3,13:1.0
2,-3,13:1.0
3,-3,13:1.0
4,-3,13:1.0
5,-3,13:1.0
6,-3,13:1.0
7,-3,13:1.0
8,-3,13:1.0
9,-3,13:1.0
10,-3,13:1.0
11,-3,13:1.0
12,-3,13:1.0
-3,-2,13:80.0
-2,-2,13:1.0
-1,-2,13:1.0
0,-2,13:1.0
1,-2,13:1.0
2,-2,13:1.0
3,-2,13:1.0
4,-2,13:1.0
5,-2,13:1.0
6,-2,13:1.0
7,-2,13:1.0
8,-2,13:1.0
9,-2,13:1.0
10,-2,13:1.0
11,-2,13:1.0
-3,-1,13:1.0
-2,-1,13:1.0
-1,-1,13:1.0
0,-1,13:1.0
1,-1,13:1.0
2,-1,13:1.0
3,-1,13:1.0
4,-1,13:1.0
5,-1,13:1.0
6,-1,13:1.0
7,-1,13:1.0
8,-1,13:1.0
9,-1,13:1.0
10,-1,13:1.0
-4,0,13:1.0
-3,0,13:1.0
-2,0,13:1.0
-1,0,13:1.0
0,0,13:1.0
1,0,13:1.0
2,0,13:1.0
3,0,13:1.0
4,0,13:1.0
5,0,13:1.0
6,0,13:1.0
7,0,13:1.0
8,0,13:1.0
9,0,13:1.0
-5,1,13:80.0
-4,1,13:1.0
-3,1,13:1.0
-2,1,13:1.0
-1,1,13:1.0
0,1,13:1.0
1,1,13:1.0
2,1,13:1.0
3,1,13:1.0
4,1,13:1.0
5,1,13:1.0
6,1,13:1.0
7,1,13:1.0
8,1,13:1.0
-5,2,13:1.0
-4,2,13:1.0
-3,2,13:1.0
-2,2,13:1.0
-1,2,13:1.0
0,2,13:1.0
1,2,13:1.0
2,2,13:1.0
3,2,13:1.0
4,2,13:1.0
5,2,13:1.0
6,2,13:1.0
7,2,13:1.0
-6,3,13:80.0
-5,3,13:1.0
-4,3,13:1.0
-3,3,13:1.0
-2,3,13:1.0
-1,3,13:1.0
0,3,13:1.0
1,3,13:1.0
2,3,13:1.0
3,3,13:1.0
4,3,13:1.0
5,3,13:1.0
-6,4,13:1.0
-5,4,13:1.0
-4,4,13:1.0
-3,4,13:1.0
-2,4,13:1.0
-1,4,13:1.0
0,4,13:1.0
1,4,13:1.0
-6,5,13:1.0
-5,5,13:1.0
-4,5,13:1.0
-3,5,13:1.0
-2,5,13:1.0
-6,6,13:80.0
-5,6,13:80.0
7,-11,14:80.0
8,-11,14:1.0
9,-11,14:1.0
10,-11,14:1.0
11,-11,14:1.0
12,-11,14:1.0
13,-11,14:1.0
14,-11,14:80.0
5,-10,14:1.0
6,-10,14:1.0
7,-10,14:1.0
8,-10,14:1.0
9,-10,14:1.0
10,-10,14:1.0
11,-10,14:1.0
12,-10,14:1.0
13,-10,14:1.0
14,-10,14:1.0
3,-9,14:1.0
4,-9,14:1.0
5,-9,14:1.0
6,-9,14:1.0
7,-9,14:1.0
8,-9,14:1.0
9,-9,14:1.0
10,-9,14:1.0
11,-9,14:1.0
12,-9,14:1.0
13,-9,14:1.0
14,-9,14:1.0
15,-9,14:80.0
1,-8,14:80.0
2,-8,14:1.0
3,-8,14:1.0
4,-8,14:1.0
5,-8,14:1.0
6,-8,14:1.0
7,-8,14:1.0
8,-8,14:1.0
9,-8,14:1.0
10,-8,14:1.0
11,-8,14:1.0
12,-8,14:1.0
13,-8,14:1.0
14,-8,14:1.0
1,-7,14:1.0
2,-7,14:1.0
3,-7,14:1.0
4,-7,14:1.0
5,-7,14:1.0
6,-7,14:1.0
7,-7,14:1.0
8,-7,14:1.0
9,-7,14:1.0
10,-7,14:1.0
11,-7,14:1.0
12,-7,14:1.0
13,-7,14:1.0
14,-7,14:1.0
0,-6,14:1.0
1,-6,14:1.0
2,-6,14:1.0
3,-6,14:1.0
4,-6,14:1.0
5,-6,14:1.0
6,-6,14:1.0
7,-6,14:1.0
8,-6,14:1.0
9,-6,14:1.0
10,-6,14:1.0
11,-6,14:1.0
12,-6,14:1.0
13,-6,14:1.0
14,-6,14:80.0
-1,-5,14:1.0
0,-5,14:1.0
1,-5,14:1.0
2,-5,14:1.0
3,-5,14:1.0
4,-5,14:1.0
5,-5,14:1.0
6,-5,14:1.0
7,-5,14:1.0
8,-5,14:1.0
9,-5,14:1.0
10,-5,14:1.0
11,-5,14:1.0
12,-5,14:1.0
13,-5,14:1.0
-1,-4,14:1.0
0,-4,14:1.0
1,-4,14:1.0
2,-4,14:1.0
3,-4,14:1.0
4,-4,14:1.0
5,-4,14:1.0
6,-4,14:1.0
7,-4,14:1.0
8,-4,14:1.0
9,-4,14:1.0
10,-4,14:1.0
11,-4,14:1.0
12,-4,14:1.0
-2,-3,14:1.0
-1,-3,14:1.0
0,-3,14:1.0
1,-3,14:1.0
2,-3,14:1.0
3,-3,14:1.0
4,-3,14:1.0
5,-3,14:1.0
6,-3,14:1.0
7,-3,14:1.0
8,-3,14:1.0
9,-3,14:1.0
10,-3,14:1.0
11,-3,14:1.0
12,-3,14:80.0
-2,-2,14:1.0
-1,-2,14:1.0
0,-2,14:1.0
1,-2,14:1.0
2,-2,14:1.0
3,-2,14:1.0
4,-2,14:1.0
5,-2,14:1.0
6,-2,14:1.0
7,-2,14:1.0
8,-2,14:1.0
9,-2,14:1.0
10,-2,14:1.0
11,-2,14:1.0
-3,-1,14:1.0
-2,-1,14:1.0
-1,-1,14:1.0
0,-1,14:1.0
1,-1,14:1.0
2,-1,14:1.0
3,-1,14:1.0
4,-1,14:1.0
5,-1,14:1.0
6,-1,14:1.0
7,-1,14:1.0
8,-1,14:1.0
9,-1,14:1.0
10,-1,14:80.0
-4,0,14:1.0
-3,0,14:1.0
-2,0,14:1.0
-1,0,14:1.0
0,0,14:1.0
1,0,14:1.0
2,0,14:1.0
3,0,14:1.0
4,0,14:1.0
5,0,14:1.0
6,0,14:1.0
7,0,14:1.0
8,0,14:1.0
9,0,14:80.0
-4,1,14:1.0
-3,1,14:1.0
-2,1,14:1.0
-1,1,14:1.0
0,1,14:1.0
1,1,14:1.0
2,1,14:1.0
3,1,14:1.0
4,1,14:1.0
5,1,14:1.0
6,1,14:1.0
7,1,14:1.0
8,1,14:1.0
-5,2,14:1.0
-4,2,14:1.0
-3,2,14:1.0
-2,2,14:1.0
-1,2,14:1.0
0,2,14:1.0
1,2,14:1.0
2,2,14:1.0
3,2,14:1.0
4,2,14:1.0
5,2,14:1.0
6,2,14:1.0
7,2,14:80.0
-5,3,14:1.0
-4,3,14:1.0
-3,3,14:1.0
-2,3,14:1.0
-1,3,14:1.0
0,3,14:1.0
1,3,14:1.0
2,3,14:1.0
3,3,14:1.0
4,3,14:1.0
5,3,14:80.0
-6,4,14:80.0
-5,4,14:1.0
-4,4,14:1.0
-3,4,14:1.0
-2,4,14:1.0
-1,4,14:1.0
0,4,14:1.0
1,4,14:80.0
-6,5,14:80.0
-5,5,14:1.0
-4,5,14:1.0
-3,5,14:1.0
-2,5,14:80.0
8,-11,15:1.0
9,-11,15:1.0
10,-11,15:1.0
11,-11,15:1.0
12,-11,15:1.0
13,-11,15:1.0
5,-10,15:1.0
6,-10,15:1.0
7,-10,15:1.0
8,-10,15:1.0
9,-10,15:1.0
10,-10,15:1.0
11,-10,15:1.0
12,-10,15:1.0
13,-10,15:1.0
14,-10,15:1.0
3,-9,15:1.0
4,-9,15:1.0
5,-9,15:1.0
6,-9,15:1.0
7,-9,15:1.0
8,-9,15:1.0
9,-9,15:1.0
10,-9,15:1.0
11,-9,15:1.0
12,-9,15:1.0
13,-9,15:1.0
14,-9,15:1.0
2,-8,15:1.0
3,-8,15:1.0
4,-8,15:1.0
5,-8,15:1.0
6,-8,15:1.0
7,-8,15:1.0
8,-8,15:1.0
9,-8,15:1.0
10,-8,15:1.0
11,-8,15:1.0
12,-8,15:1.0
13,-8,15:1.0
14,-8,15:1.0
1,-7,15:1.0
2,-7,15:1.0
3,-7,15:1.0
4,-7,15:1.0
5,-7,15:1.0
6,-7,15:1.0
7,-7,15:1.0
8,-7,15:1.0
9,-7,15:1.0
10,-7,15:1.0
11,-7,15:1.0
12,-7,15:1.0
13,-7,15:1.0
14,-7,15:1.0
0,-6,15:1.0
1,-6,15:1.0
2,-6,15:1.0
3,-6,15:1.0
4,-6,15:1.0
5,-6,15:1.0
6,-6,15:1.0
7,-6,15:1.0
8,-6,15:1.0
9,-6,15:1.0
10,-6,15:1.0
11,-6,15:1.0
12,-6,15:1.0
13,-6,15:1.0
-1,-5,15:80.0
0,-5,15:1.0
1,-5,15:1.0
2,-5,15:1.0
3,-5,15:1.0
4,-5,15:1.0
5,-5,15:1.0
6,-5,15:1.0
7,-5,15:1.0
8,-5,15:1.0
9,-5,15:1.0
10,-5,15:1.0
11,-5,15:1.0
12,-5,15:1.0
13,-5,15:1.0
-1,-4,15:1.0
0,-4,15:1.0
1,-4,15:1.0
2,-4,15:1.0
3,-4,15:1.0
4,-4,15:1.0
5,-4,15:1.0
6,-4,15:1.0
7,-4,15:1.0
8,-4,15:1.0
9,-4,15:1.0
10,-4,15:1.0
11,-4,15:1.0
12,-4,15:1.0
-2,-3,15:1.0
-1,-3,15:1.0
0,-3,15:1.0
1,-3,15:1.0
2,-3,15:1.0
3,-3,15:1.0
4,-3,15:1.0
5,-3,15:1.0
6,-3,15:1.0
7,-3,15:1.0
8,-3,15:1.0
9,-3,15:1.0
10,-3,15:1.0
11,-3,15:1.0
-2,-2,15:1.0
-1,-2,15:1.0
0,-2,15:1.0
1,-2,15:1.0
2,-2,15:1.0
3,-2,15:1.0
4,-2,15:1.0
5,-2,15:1.0
6,-2,15:1.0
7,-2,15:1.0
8,-2,15:1.0
9,-2,15:1.0
10,-2,15:1.0
11,-2,15:80.0
-3,-1,15:1.0
-2,-1,15:1.0
-1,-1,15:1.0
0,-1,15:1.0
1,-1,15:1.0
2,-1,15:1.0
3,-1,15:1.0
4,-1,15:1.0
5,-1,15:1.0
6,-1,15:1.0
7,-1,15:1.0
8,-1,15:1.0
9,-1,15:1.0
-4,0,15:80.0
-3,0,15:1.0
-2,0,15:1.0
-1,0,15:1.0
0,0,15:1.0
1,0,15:1.0
2,0,15:1.0
3,0,15:1.0
4,0,15:1.0
5,0,15:1.0
6,0,15:1.0
7,0,15:1.0
8,0,15:1.0
-4,1,15:1.0
-3,1,15:1.0
-2,1,15:1.0
-1,1,15:1.0
0,1,15:1.0
1,1,15:1.0
2,1,15:1.0
3,1,15:1.0
4,1,15:1.0
5,1,15:1.0
6,1,15:1.0
7,1,15:1.0
8,1,15:80.0
-5,2,15:1.0
-4,2,15:1.0
-3,2,15:1.0
-2,2,15:1.0
-1,2,15:1.0
0,2,15:1.0
1,2,15:1.0
2,2,15:1.0
3,2,15:1.0
4,2,15:1.0
5,2,15:1.0
6,2,15:1.0
-5,3,15:1.0
-4,3,15:1.0
-3,3,15:1.0
-2,3,15:1.0
-1,3,15:1.0
0,3,15:1.0
1,3,15:1.0
2,3,15:1.0
3,3,15:1.0
4,3,15:1.0
-5,4,15:1.0
-4,4,15:1.0
-3,4,15:1.0
-2,4,15:1.0
-1,4,15:1.0
0,4,15:1.0
-5,5,15:80.0
-4,5,15:1.0
-3,5,15:80.0
8,-11,16:80.0
9,-11,16:1.0
10,-11,16:1.0
11,-11,16:1.0
12,-11,16:1.0
13,-11,16:80.0
5,-10,16:80.0
6,-10,16:1.0
7,-10,16:1.0
8,-10,16:1.0
9,-10,16:1.0
10,-10,16:1.0
11,-10,16:1.0
12,-10,16:1.0
13,-10,16:1.0
14,-10,16:80.0
3,-9,16:80.0
4,-9,16:1.0
5,-9,16:1.0
6,-9,16:1.0
7,-9,16:1.0
8,-9,16:1.0
9,-9,16:1.0
10,-9,16:1.0
11,-9,16:1.0
12,-9,16:1.0
13,-9,16:1.0
14,-9,16:1.0
2,-8,16:1.0
3,-8,16:1.0
4,-8,16:1.0
5,-8,16:1.0
6,-8,16:1.0
7,-8,16:1.0
8,-8,16:1.0
9,-8,16:1.0
10,-8,16:1.0
11,-8,16:1.0
12,-8,16:1.0
13,-8,16:1.0
14,-8,16:1.0
1,-7,16:1.0
2,-7,16:1.0
3,-7,16:1.0
4,-7,16:1.0
5,-7,16:1.0
6,-7,16:1.0
7,-7,16:1.0
8,-7,16:1.0
9,-7,16:1.0
10,-7,16:1.0
11,-7,16:1.0
12,-7,16:1.0
13,-7,16:1.0
14,-7,16:80.0
0,-6,16:1.0
1,-6,16:1.0
2,-6,16:1.0
3,-6,16:1.0
4,-6,16:1.0
5,-6,16:1.0
6,-6,16:1.0
7,-6,16:1.0
8,-6,16:1.0
9,-6,16:1.0
10,-6,16:1.0
11,-6,16:1.0
12,-6,16:1.0
13,-6,16:1.0
0,-5,16:1.0
1,-5,16:1.0
2,-5,16:1.0
3,-5,16:1.0
4,-5,16:1.0
5,-5,16:1.0
6,-5,16:1.0
7,-5,16:1.0
8,-5,16:1.0
9,-5,16:1.0
10,-5,16:1.0
11,-5,16:1.0
12,-5,16:1.0
13,-5,16:80.0
-1,-4,16:1.0
0,-4,16:1.0
1,-4,16:1.0
2,-4,16:1.0
3,-4,16:1.0
4,-4,16:1.0
5,-4,16:1.0
6,-4,16:1.0
7,-4,16:1.0
8,-4,16:1.0
9,-4,16:1.0
10,-4,16:1.0
11,-4,16:1.0
12,-4,16:1.0
-2,-3,16:80.0
-1,-3,16:1.0
0,-3,16:1.0
1,-3,16:1.0
2,-3,16:1.0
3,-3,16:1.0
4,-3,16:1.0
5,-3,16:1.0
6,-3,16:1.0
7,-3,16:1.0
8,-3,16:1.0
9,-3,16:1.0
10,-3,16:1.0
11,-3,16:1.0
-2,-2,16:1.0
-1,-2,16:1.0
0,-2,16:1.0
1,-2,16:1.0
2,-2,16:1.0
3,-2,16:1.0
4,-2,16:1.0
5,-2,16:1.0
6,-2,16:1.0
7,-2,16:1.0
8,-2,16:1.0
9,-2,16:1.0
10,-2,16:1.0
-3,-1,16:1.0
-2,-1,16:1.0
-1,-1,16:1.0
0,-1,16:1.0
1,-1,16:1.0
2,-1,16:1.0
3,-1,16:1.0
4,-1,16:1.0
5,-1,16:1.0
6,-1,16:1.0
7,-1,16:1.0
8,-1,16:1.0
9,-1,16:1.0
-3,0,16:1.0
-2,0,16:1.0
-1,0,16:1.0
0,0,16:1.0
1,0,16:1.0
2,0,16:1.0
3,0,16:1.0
4,0,16:1.0
5,0,16:1.0
6,0,16:1.0
7,0,16:1.0
8,0,16:1.0
-4,1,16:1.0
-3,1,16:1.0
-2,1,16:1.0
-1,1,16:1.0
0,1,16:1.0
1,1,16:1.0
2,1,16:1.0
3,1,16:1.0
4,1,16:1.0
5,1,16:1.0
6,1,16:1.0
7,1,16:1.0
-5,2,16:80.0
-4,2,16:1.0
-3,2,16:1.0
-2,2,16:1.0
-1,2,16:1.0
0,2,16:1.0
1,2,16:1.0
2,2,16:1.0
3,2,16:1.0
4,2,16:1.0
5,2,16:1.0
6,2,16:1.0
-5,3,16:80.0
-4,3,16:1.0
-3,3,16:1.0
-2,3,16:1.0
-1,3,16:1.0
0,3,16:1.0
1,3,16:1.0
2,3,16:1.0
3,3,16:1.0
4,3,16:80.0
-5,4,16:80.0
-4,4,16:1.0
-3,4,16:1.0
-2,4,16:1.0
-1,4,16:1.0
0,4,16:80.0
-4,5,16:80.0
9,-11,17:80.0
10,-11,17:1.0
11,-11,17:1.0
12,-11,17:80.0
6,-10,17:1.0
7,-10,17:1.0
8,-10,17:1.0
9,-10,17:1.0
10,-10,17:1.0
11,-10,17:1.0
12,-10,17:1.0
13,-10,17:1.0
4,-9,17:1.0
5,-9,17:1.0
6,-9,17:1.0
7,-9,17:1.0
8,-9,17:1.0
9,-9,17:1.0
10,-9,17:1.0
11,-9,17:1.0
12,-9,17:1.0
13,-9,17:1.0
14,-9,17:80.0
2,-8,17:1.0
3,-8,17:1.0
4,-8,17:1.0
5,-8,17:1.0
6,-8,17:1.0
7,-8,17:1.0
8,-8,17:1.0
9,-8,17:1.0
10,-8,17:1.0
11,-8,17:1.0
12,-8,17:1.0
13,-8,17:1.0
14,-8,17:80.0
1,-7,17:1.0
2,-7,17:1.0
3,-7,17:1.0
4,-7,17:1.0
5,-7,17:1.0
6,-7,17:1.0
7,-7,17:1.0
8,-7,17:1.0
9,-7,17:1.0
10,-7,17:1.0
11,-7,17:1.0
12,-7,17:1.0
13,-7,17:1.0
0,-6,17:1.0
1,-6,17:1.0
2,-6,17:1.0
3,-6,17:1.0
4,-6,17:1.0
5,-6,17:1.0
6,-6,17:1.0
7,-6,17:1.0
8,-6,17:1.0
9,-6,17:1.0
10,-6,17:1.0
11,-6,17:1.0
12,-6,17:1.0
13,-6,17:1.0
0,-5,17:1.0
1,-5,17:1.0
2,-5,17:1.0
3,-5,17:1.0
4,-5,17:1.0
5,-5,17:1.0
6,-5,17:1.0
7,-5,17:1.0
8,-5,17:1.0
9,-5,17:1.0
10,-5,17:1.0
11,-5,17:1.0
12,-5,17:1.0
-1,-4,17:1.0
0,-4,17:1.0
1,-4,17:1.0
2,-4,17:1.0
3,-4,17:1.0
4,-4,17:1.0
5,-4,17:1.0
6,-4,17:1.0
7,-4,17:1.0
8,-4,17:1.0
9,-4,17:1.0
10,-4,17:1.0
11,-4,17:1.0
12,-4,17:1.0
-1,-3,17:1.0
0,-3,17:1.0
1,-3,17:1.0
2,-3,17:1.0
3,-3,17:1.0
4,-3,17:1.0
5,-3,17:1.0
6,-3,17:1.0
7,-3,17:1.0
8,-3,17:1.0
9,-3,17:1.0
10,-3,17:1.0
11,-3,17:1.0
-2,-2,17:1.0
-1,-2,17:1.0
0,-2,17:1.0
1,-2,17:1.0
2,-2,17:1.0
3,-2,17:1.0
4,-2,17:1.0
5,-2,17:1.0
6,-2,17:1.0
7,-2,17:1.0
8,-2,17:1.0
9,-2,17:1.0
10,-2,17:1.0
-3,-1,17:80.0
-2,-1,17:1.0
-1,-1,17:1.0
0,-1,17:1.0
1,-1,17:1.0
2,-1,17:1.0
3,-1,17:1.0
4,-1,17:1.0
5,-1,17:1.0
6,-1,17:1.0
7,-1,17:1.0
8,-1,17:1.0
9,-1,17:1.0
-3,0,17:1.0
-2,0,17:1.0
-1,0,17:1.0
0,0,17:1.0
1,0,17:1.0
2,0,17:1.0
3,0,17:1.0
4,0,17:1.0
5,0,17:1.0
6,0,17:1.0
7,0,17:1.0
8,0,17:1.0
-4,1,17:1.0
-3,1,17:1.0
-2,1,17:1.0
-1,1,17:1.0
0,1,17:1.0
1,1,17:1.0
2,1,17:1.0
3,1,17:1.0
4,1,17:1.0
5,1,17:1.0
6,1,17:1.0
7,1,17:1.0
-4,2,17:1.0
-3,2,17:1.0
-2,2,17:1.0
-1,2,17:1.0
0,2,17:1.0
1,2,17:1.0
2,2,17:1.0
3,2,17:1.0
4,2,17:1.0
5,2,17:1.0
6,2,17:1.0
-4,3,17:1.0
-3,3,17:1.0
-2,3,17:1.0
-1,3,17:1.0
0,3,17:1.0
1,3,17:1.0
2,3,17:1.0
3,3,17:1.0
-4,4,17:1.0
-3,4,17:1.0
-2,4,17:1.0
-1,4,17:80.0
10,-11,18:80.0
11,-11,18:80.0
6,-10,18:1.0
7,-10,18:1.0
8,-10,18:1.0
9,-10,18:1.0
10,-10,18:1.0
11,-10,18:1.0
12,-10,18:1.0
13,-10,18:1.0
4,-9,18:1.0
5,-9,18:1.0
6,-9,18:1.0
7,-9,18:1.0
8,-9,18:1.0
9,-9,18:1.0
10,-9,18:1.0
11,-9,18:1.0
12,-9,18:1.0
13,-9,18:1.0
2,-8,18:1.0
3,-8,18:1.0
4,-8,18:1.0
5,-8,18:1.0
6,-8,18:1.0
7,-8,18:1.0
8,-8,18:1.0
9,-8,18:1.0
10,-8,18:1.0
11,-8,18:1.0
12,-8,18:1.0
13,-8,18:1.0
1,-7,18:1.0
2,-7,18:1.0
3,-7,18:1.0
4,-7,18:1.0
5,-7,18:1.0
6,-7,18:1.0
7,-7,18:1.0
8,-7,18:1.0
9,-7,18:1.0
10,-7,18:1.0
11,-7,18:1.0
12,-7,18:1.0
13,-7,18:1.0
0,-6,18:80.0
1,-6,18:1.0
2,-6,18:1.0
3,-6,18:1.0
4,-6,18:1.0
5,-6,18:1.0
6,-6,18:1.0
7,-6,18:1.0
8,-6,18:1.0
9,-6,18:1.0
10,-6,18:1.0
11,-6,18:1.0
12,-6,18:1.0
13,-6,18:1.0
0,-5,18:1.0
1,-5,18:1.0
2,-5,18:1.0
3,-5,18:1.0
4,-5,18:1.0
5,-5,18:1.0
6,-5,18:1.0
7,-5,18:1.0
8,-5,18:1.0
9,-5,18:1.0
10,-5,18:1.0
11,-5,18:1.0
12,-5,18:1.0
-1,-4,18:1.0
0,-4,18:1.0
1,-4,18:1.0
2,-4,18:1.0
3,-4,18:1.0
4,-4,18:1.0
5,-4,18:1.0
6,-4,18:1.0
7,-4,18:1.0
8,-4,18:1.0
9,-4,18:1.0
10,-4,18:1.0
11,-4,18:1.0
12,-4,18:1.0
-1,-3,18:1.0
0,-3,18:1.0
1,-3,18:1.0
2,-3,18:1.0
3,-3,18:1.0
4,-3,18:1.0
5,-3,18:1.0
6,-3,18:1.0
7,-3,18:1.0
8,-3,18:1.0
9,-3,18:1.0
10,-3,18:1.0
11,-3,18:1.0
-2,-2,18:1.0
-1,-2,18:1.0
0,-2,18:1.0
1,-2,18:1.0
2,-2,18:1.0
3,-2,18:1.0
4,-2,18:1.0
5,-2,18:1.0
6,-2,18:1.0
7,-2,18:1.0
8,-2,18:1.0
9,-2,18:1.0
10,-2,18:1.0
-2,-1,18:1.0
-1,-1,18:1.0
0,-1,18:1.0
1,-1,18:1.0
2,-1,18:1.0
3,-1,18:1.0
4,-1,18:1.0
5,-1,18:1.0
6,-1,18:1.0
7,-1,18:1.0
8,-1,18:1.0
9,-1,18:1.0
-3,0,18:1.0
-2,0,18:1.0
-1,0,18:1.0
0,0,18:1.0
1,0,18:1.0
2,0,18:1.0
3,0,18:1.0
4,0,18:1.0
5,0,18:1.0
6,0,18:1.0
7,0,18:1.0
8,0,18:1.0
-4,1,18:80.0
-3,1,18:1.0
-2,1,18:1.0
-1,1,18:1.0
0,1,18:1.0
1,1,18:1.0
2,1,18:1.0
3,1,18:1.0
4,1,18:1.0
5,1,18:1.0
6,1,18:1.0
7,1,18:1.0
-4,2,18:1.0
-3,2,18:1.0
-2,2,18:1.0
-1,2,18:1.0
0,2,18:1.0
1,2,18:1.0
2,2,18:1.0
3,2,18:1.0
4,2,18:1.0
5,2,18:1.0
6,2,18:80.0
-4,3,18:1.0
-3,3,18:1.0
-2,3,18:1.0
-1,3,18:1.0
0,3,18:1.0
1,3,18:1.0
2,3,18:1.0
3,3,18:1.0
-4,4,18:80.0
-3,4,18:80.0
-2,4,18:80.0
6,-10,19:80.0
7,-10,19:1.0
8,-10,19:1.0
9,-10,19:1.0
10,-10,19:1.0
11,-10,19:1.0
12,-10,19:1.0
13,-10,19:80.0
4,-9,19:1.0
5,-9,19:1.0
6,-9,19:1.0
7,-9,19:1.0
8,-9,19:1.0
9,-9,19:1.0
10,-9,19:1.0
11,-9,19:1.0
12,-9,19:1.0
13,-9,19:1.0
2,-8,19:80.0
3,-8,19:1.0
4,-8,19:1.0
5,-8,19:1.0
6,-8,19:1.0
7,-8,19:1.0
8,-8,19:1.0
9,-8,19:1.0
10,-8,19:1.0
11,-8,19:1.0
12,-8,19:1.0
13,-8,19:1.0
1,-7,19:1.0
2,-7,19:1.0
3,-7,19:1.0
4,-7,19:1.0
5,-7,19:1.0
6,-7,19:1.0
7,-7,19:1.0
8,-7,19:1.0
9,-7,19:1.0
10,-7,19:1.0
11,-7,19:1.0
12,-7,19:1.0
13,-7,19:1.0
1,-6,19:1.0
2,-6,19:1.0
3,-6,19:1.0
4,-6,19:1.0
5,-6,19:1.0
6,-6,19:1.0
7,-6,19:1.0
8,-6,19:1.0
9,-6,19:1.0
10,-6,19:1.0
11,-6,19:1.0
12,-6,19:1.0
13,-6,19:80.0
0,-5,19:1.0
1,-5,19:1.0
2,-5,19:1.0
3,-5,19:1.0
4,-5,19:1.0
5,-5,19:1.0
6,-5,19:1.0
7,-5,19:1.0
8,-5,19:1.0
9,-5,19:1.0
10,-5,19:1.0
11,-5,19:1.0
12,-5,19:1.0
-1,-4,19:1.0
0,-4,19:1.0
1,-4,19:1.0
2,-4,19:1.0
3,-4,19:1.0
4,-4,19:1.0
5,-4,19:1.0
6,-4,19:1.0
7,-4,19:1.0
8,-4,19:1.0
9,-4,19:1.0
10,-4,19:1.0
11,-4,19:1.0
12,-4,19:80.0
-1,-3,19:1.0
0,-3,19:1.0
1,-3,19:1.0
2,-3,19:1.0
3,-3,19:1.0
4,-3,19:1.0
5,-3,19:1.0
6,-3,19:1.0
7,-3,19:1.0
8,-3,19:1.0
9,-3,19:1.0
10,-3,19:1.0
11,-3,19:1.0
-2,-2,19:1.0
-1,-2,19:1.0
0,-2,19:1.0
1,-2,19:1.0
2,-2,19:1.0
3,-2,19:1.0
4,-2,19:1.0
5,-2,19:1.0
6,-2,19:1.0
7,-2,19:1.0
8,-2,19:1.0
9,-2,19:1.0
10,-2,19:1.0
-2,-1,19:1.0
-1,-1,19:1.0
0,-1,19:1.0
1,-1,19:1.0
2,-1,19:1.0
3,-1,19:1.0
4,-1,19:1.0
5,-1,19:1.0
6,-1,19:1.0
7,-1,19:1.0
8,-1,19:1.0
9,-1,19:1.0
-3,0,19:1.0
-2,0,19:1.0
-1,0,19:1.0
0,0,19:1.0
1,0,19:1.0
2,0,19:1.0
3,0,19:1.0
4,0,19:1.0
5,0,19:1.0
6,0,19:1.0
7,0,19:1.0
8,0,19:80.0
-3,1,19:1.0
-2,1,19:1.0
-1,1,19:1.0
0,1,19:1.0
1,1,19:1.0
2,1,19:1.0
3,1,19:1.0
4,1,19:1.0
5,1,19:1.0
6,1,19:1.0
7,1,19:80.0
-4,2,19:80.0
-3,2,19:1.0
-2,2,19:1.0
-1,2,19:1.0
0,2,19:1.0
1,2,19:1.0
2,2,19:1.0
3,2,19:1.0
4,2,19:1.0
5,2,19:1.0
-4,3,19:80.0
-3,3,19:1.0
-2,3,19:1.0
-1,3,19:1.0
0,3,19:1.0
1,3,19:1.0
2,3,19:1.0
3,3,19:80.0
7,-10,20:1.0
8,-10,20:1.0
9,-10,20:1.0
10,-10,20:1.0
11,-10,20:1.0
12,-10,20:1.0
4,-9,20:80.0
5,-9,20:1.0
6,-9,20:1.0
7,-9,20:1.0
8,-9,20:1.0
9,-9,20:1.0
10,-9,20:1.0
11,-9,20:1.0
12,-9,20:1.0
13,-9,20:1.0
3,-8,20:1.0
4,-8,20:1.0
5,-8,20:1.0
6,-8,20:1.0
7,-8,20:1.0
8,-8,20:1.0
9,-8,20:1.0
10,-8,20:1.0
11,-8,20:1.0
12,-8,20:1.0
13,-8,20:1.0
1,-7,20:80.0
2,-7,20:1.0
3,-7,20:1.0
4,-7,20:1.0
5,-7,20:1.0
6,-7,20:1.0
7,-7,20:1.0
8,-7,20:1.0
9,-7,20:1.0
10,-7,20:1.0
11,-7,20:1.0
12,-7,20:1.0
13,-7,20:1.0
1,-6,20:1.0
2,-6,20:1.0
3,-6,20:1.0
4,-6,20:1.0
5,-6,20:1.0
6,-6,20:1.0
7,-6,20:1.0
8,-6,20:1.0
9,-6,20:1.0
10,-6,20:1.0
11,-6,20:1.0
12,-6,20:1.0
0,-5,20:1.0
1,-5,20:1.0
2,-5,20:1.0
3,-5,20:1.0
4,-5,20:1.0
5,-5,20:1.0
6,-5,20:1.0
7,-5,20:1.0
8,-5,20:1.0
9,-5,20:1.0
10,-5,20:1.0
11,-5,20:1.0
12,-5,20:1.0
-1,-4,20:80.0
0,-4,20:1.0
1,-4,20:1.0
2,-4,20:1.0
3,-4,20:1.0
4,-4,20:1.0
5,-4,20:1.0
6,-4,20:1.0
7,-4,20:1.0
8,-4,20:1.0
9,-4,20:1.0
10,-4,20:1.0
11,-4,20:1.0
-1,-3,20:1.0
0,-3,20:1.0
1,-3,20:1.0
2,-3,20:1.0
3,-3,20:1.0
4,-3,20:1.0
5,-3,20:1.0
6,-3,20:1.0
7,-3,20:1.0
8,-3,20:1.0
9,-3,20:1.0
10,-3,20:1.0
11,-3,20:1.0
-2,-2,20:80.0
-1,-2,20:1.0
0,-2,20:1.0
1,-2,20:1.0
2,-2,20:1.0
3,-2,20:1.0
4,-2,20:1.0
5,-2,20:1.0
6,-2,20:1.0
7,-2,20:1.0
8,-2,20:1.0
9,-2,20:1.0
10,-2,20:1.0
-2,-1,20:1.0
-1,-1,20:1.0
0,-1,20:1.0
1,-1,20:1.0
2,-1,20:1.0
3,-1,20:1.0
4,-1,20:1.0
5,-1,20:1.0
6,-1,20:1.0
7,-1,20:1.0
8,-1,20:1.0
9,-1,20:80.0
-3,0,20:80.0
-2,0,20:1.0
-1,0,20:1.0
0,0,20:1.0
1,0,20:1.0
2,0,20:1.0
3,0,20:1.0
4,0,20:1.0
5,0,20:1.0
6,0,20:1.0
7,0,20:1.0
-3,1,20:1.0
-2,1,20:1.0
-1,1,20:1.0
0,1,20:1.0
1,1,20:1.0
2,1,20:1.0
3,1,20:1.0
4,1,20:1.0
5,1,20:1.0
6,1,20:1.0
-3,2,20:1.0
-2,2,20:1.0
-1,2,20:1.0
0,2,20:1.0
1,2,20:1.0
2,2,20:1.0
3,2,20:1.0
4,2,20:1.0
5,2,20:1.0
-3,3,20:1.0
-2,3,20:1.0
-1,3,20:1.0
0,3,20:1.0
1,3,20:1.0
2,3,20:1.0
7,-10,21:80.0
8,-10,21:1.0
9,-10,21:1.0
10,-10,21:1.0
11,-10,21:1.0
12,-10,21:80.0
5,-9,21:1.0
6,-9,21:1.0
7,-9,21:1.0
8,-9,21:1.0
9,-9,21:1.0
10,-9,21:1.0
11,-9,21:1.0
12,-9,21:1.0
13,-9,21:80.0
3,-8,21:1.0
4,-8,21:1.0
5,-8,21:1.0
6,-8,21:1.0
7,-8,21:1.0
8,-8,21:1.0
9,-8,21:1.0
10,-8,21:1.0
11,-8,21:1.0
12,-8,21:1.0
13,-8,21:80.0
2,-7,21:1.0
3,-7,21:1.0
4,-7,21:1.0
5,-7,21:1.0
6,-7,21:1.0
7,-7,21:1.0
8,-7,21:1.0
9,-7,21:1.0
10,-7,21:1.0
11,-7,21:1.0
12,-7,21:1.0
13,-7,21:80.0
1,-6,21:1.0
2,-6,21:1.0
3,-6,21:1.0
4,-6,21:1.0
5,-6,21:1.0
6,-6,21:1.0
7,-6,21:1.0
8,-6,21:1.0
9,-6,21:1.0
10,-6,21:1.0
11,-6,21:1.0
12,-6,21:1.0
0,-5,21:1.0
1,-5,21:1.0
2,-5,21:1.0
3,-5,21:1.0
4,-5,21:1.0
5,-5,21:1.0
6,-5,21:1.0
7,-5,21:1.0
8,-5,21:1.0
9,-5,21:1.0
10,-5,21:1.0
11,-5,21:1.0
12,-5,21:1.0
0,-4,21:1.0
1,-4,21:1.0
2,-4,21:1.0
3,-4,21:1.0
4,-4,21:1.0
5,-4,21:1.0
6,-4,21:1.0
7,-4,21:1.0
8,-4,21:1.0
9,-4,21:1.0
10,-4,21:1.0
11,-4,21:1.0
-1,-3,21:1.0
0,-3,21:1.0
1,-3,21:1.0
2,-3,21:1.0
3,-3,21:1.0
4,-3,21:1.0
5,-3,21:1.0
6,-3,21:1.0
7,-3,21:1.0
8,-3,21:1.0
9,-3,21:1.0
10,-3,21:1.0
11,-3,21:1.0
-1,-2,21:1.0
0,-2,21:1.0
1,-2,21:1.0
2,-2,21:1.0
3,-2,21:1.0
4,-2,21:1.0
5,-2,21:1.0
6,-2,21:1.0
7,-2,21:1.0
8,-2,21:1.0
9,-2,21:1.0
10,-2,21:1.0
-2,-1,21:1.0
-1,-1,21:1.0
0,-1,21:1.0
1,-1,21:1.0
2,-1,21:1.0
3,-1,21:1.0
4,-1,21:1.0
5,-1,21:1.0
6,-1,21:1.0
7,-1,21:1.0
8,-1,21:1.0
-2,0,21:1.0
-1,0,21:1.0
0,0,21:1.0
1,0,21:1.0
2,0,21:1.0
3,0,21:1.0
4,0,21:1.0
5,0,21:1.0
6,0,21:1.0
7,0,21:1.0
-3,1,21:1.0
-2,1,21:1.0
-1,1,21:1.0
0,1,21:1.0
1,1,21:1.0
2,1,21:1.0
3,1,21:1.0
4,1,21:1.0
5,1,21:1.0
6,1,21:1.0
-3,2,21:1.0
-2,2,21:1.0
-1,2,21:1.0
0,2,21:1.0
1,2,21:1.0
2,2,21:1.0
3,2,21:1.0
4,2,21:1.0
5,2,21:80.0
-3,3,21:80.0
-2,3,21:1.0
-1,3,21:1.0
0,3,21:1.0
1,3,21:1.0
2,3,21:80.0
8,-10,22:1.0
9,-10,22:1.0
10,-10,22:1.0
11,-10,22:1.0
5,-9,22:1.0
6,-9,22:1.0
7,-9,22:1.0
8,-9,22:1.0
9,-9,22:1.0
10,-9,22:1.0
11,-9,22:1.0
12,-9,22:1.0
3,-8,22:1.0
4,-8,22:1.0
5,-8,22:1.0
6,-8,22:1.0
7,-8,22:1.0
8,-8,22:1.0
9,-8,22:1.0
10,-8,22:1.0
11,-8,22:1.0
12,-8,22:1.0
2,-7,22:1.0
3,-7,22:1.0
4,-7,22:1.0
5,-7,22:1.0
6,-7,22:1.0
7,-7,22:1.0
8,-7,22:1.0
9,-7,22:1.0
10,-7,22:1.0
11,-7,22:1.0
12,-7,22:1.0
1,-6,22:1.0
2,-6,22:1.0
3,-6,22:1.0
4,-6,22:1.0
5,-6,22:1.0
6,-6,22:1.0
7,-6,22:1.0
8,-6,22:1.0
9,-6,22:1.0
10,-6,22:1.0
11,-6,22:1.0
12,-6,22:1.0
0,-5,22:1.0
1,-5,22:1.0
2,-5,22:1.0
3,-5,22:1.0
4,-5,22:1.0
5,-5,22:1.0
6,-5,22:1.0
7,-5,22:1.0
8,-5,22:1.0
9,-5,22:1.0
10,-5,22:1.0
11,-5,22:1.0
12,-5,22:1.0
0,-4,22:1.0
1,-4,22:1.0
2,-4,22:1.0
3,-4,22:1.0
4,-4,22:1.0
5,-4,22:1.0
6,-4,22:1.0
7,-4,22:1.0
8,-4,22:1.0
9,-4,22:1.0
10,-4,22:1.0
11,-4,22:1.0
-1,-3,22:1.0
0,-3,22:1.0
1,-3,22:1.0
2,-3,22:1.0
3,-3,22:1.0
4,-3,22:1.0
5,-3,22:1.0
6,-3,22:1.0
7,-3,22:1.0
8,-3,22:1.0
9,-3,22:1.0
10,-3,22:1.0
11,-3,22:80.0
-1,-2,22:1.0
0,-2,22:1.0
1,-2,22:1.0
2,-2,22:1.0
3,-2,22:1.0
4,-2,22:1.0
5,-2,22:1.0
6,-2,22:1.0
7,-2,22:1.0
8,-2,22:1.0
9,-2,22:1.0
10,-2,22:80.0
-2,-1,22:1.0
-1,-1,22:1.0
0,-1,22:1.0
1,-1,22:1.0
2,-1,22:1.0
3,-1,22:1.0
4,-1,22:1.0
5,-1,22:1.0
6,-1,22:1.0
7,-1,22:1.0
8,-1,22:1.0
-2,0,22:1.0
-1,0,22:1.0
0,0,22:1.0
1,0,22:1.0
2,0,22:1.0
3,0,22:1.0
4,0,22:1.0
5,0,22:1.0
6,0,22:1.0
7,0,22:1.0
-3,1,22:80.0
-2,1,22:1.0
-1,1,22:1.0
0,1,22:1.0
1,1,22:1.0
2,1,22:1.0
3,1,22:1.0
4,1,22:1.0
5,1,22:1.0
6,1,22:1.0
-3,2,22:80.0
-2,2,22:1.0
-1,2,22:1.0
0,2,22:1.0
1,2,22:1.0
2,2,22:1.0
3,2,22:1.0
4,2,22:1.0
-2,3,22:80.0
-1,3,22:1.0
0,3,22:1.0
1,3,22:80.0
8,-10,23:80.0
9,-10,23:1.0
10,-10,23:1.0
11,-10,23:80.0
5,-9,23:1.0
6,-9,23:1.0
7,-9,23:1.0
8,-9,23:1.0
9,-9,23:1.0
10,-9,23:1.0
11,-9,23:1.0
12,-9,23:80.0
3,-8,23:1.0
4,-8,23:1.0
5,-8,23:1.0
6,-8,23:1.0
7,-8,23:1.0
8,-8,23:1.0
9,-8,23:1.0
10,-8,23:1.0
11,-8,23:1.0
12,-8,23:1.0
2,-7,23:1.0
3,-7,23:1.0
4,-7,23:1.0
5,-7,23:1.0
6,-7,23:1.0
7,-7,23:1.0
8,-7,23:1.0
9,-7,23:1.0
10,-7,23:1.0
11,-7,23:1.0
12,-7,23:1.0
1,-6,23:1.0
2,-6,23:1.0
3,-6,23:1.0
4,-6,23:1.0
5,-6,23:1.0
6,-6,23:1.0
7,-6,23:1.0
8,-6,23:1.0
9,-6,23:1.0
10,-6,23:1.0
11,-6,23:1.0
12,-6,23:1.0
0,-5,23:1.0
1,-5,23:1.0
2,-5,23:1.0
3,-5,23:1.0
4,-5,23:1.0
5,-5,23:1.0
6,-5,23:1.0
7,-5,23:1.0
8,-5,23:1.0
9,-5,23:1.0
10,-5,23:1.0
11,-5,23:1.0
12,-5,23:80.0
0,-4,23:1.0
1,-4,23:1.0
2,-4,23:1.0
3,-4,23:1.0
4,-4,23:1.0
5,-4,23:1.0
6,-4,23:1.0
7,-4,23:1.0
8,-4,23:1.0
9,-4,23:1.0
10,-4,23:1.0
11,-4,23:1.0
-1,-3,23:1.0
0,-3,23:1.0
1,-3,23:1.0
2,-3,23:1.0
3,-3,23:1.0
4,-3,23:1.0
5,-3,23:1.0
6,-3,23:1.0
