
#######################################################################
# +-----------------------------------------------------------------+ #
# |                            BO3 object                           | #
# +-----------------------------------------------------------------+ #
#######################################################################

Author: LordSmellyPants

Description: No description given

Version: 3

SettingsMode: WriteWithoutComments


#######################################################################
# +-----------------------------------------------------------------+ #
# |                          Main settings                          | #
# +-----------------------------------------------------------------+ #
#######################################################################

Tree: true

Frequency: 1

Rarity: 25.0

RotateRandomly: true

SpawnHeight: highestSolidBlock

SpawnHeightOffset: 0

SpawnHeightVariance: 0

##############################
# Height Limits for the BO3. #
##############################

MinHeight: 61

MaxHeight: 111

######################
# Extrusion settings #
######################

ExtrudeMode: None

ExtrudeThroughBlocks: AIR

MaxBranchDepth: 10

ExcludedBiomes: All


#######################################################################
# +-----------------------------------------------------------------+ #
# |                      Source block settings                      | #
# +-----------------------------------------------------------------+ #
#######################################################################

SourceBlocks: STONE:1,STONE:3,STONE:5,DIRT:1,DIRT,SAND,GRASS,DIRT:2,STATIONARY_WATER,HARD_CLAY,STAINED_CLAY,CLAY,SANDSTONE,SAND:1,AIR,STONE,GRAVEL,LONG_GRASS,LONG_GRASS:1,LONG_GRASS:2,DEAD_BUSH,YELLOW_FLOWER,RED_ROSE,BROWN_MUSHROOM,RED_MUSHROOM

MaxPercentageOutsideSourceBlock: 0

OutsideSourceBlock: placeAnyway

IsOTGPlus: false

InheritBO3: 

InheritBO3Rotation: NORTH

OverrideChildSettings: true

OverrideParentHeight: false

CanOverride: false

BranchFrequency: 0

BranchFrequencyGroup: 

MustBeBelowOther: false

MustBeInside: 

CannotBeInside: 

ReplacesBO3: 

CanSpawnOnWater: true

SpawnOnWaterOnly: false

SpawnUnderWater: false

SpawnAtWaterLevel: false

HeightOffset: 0

RemoveAir: true

ReplaceAbove: 

ReplaceBelow: 

ReplaceWithBiomeBlocks: true

ReplaceWithGroundBlock: DIRT

ReplaceWithSurfaceBlock: GRASS

SmoothRadius: 0

SmoothHeightOffset: 0

SmoothStartTop: false

SmoothStartWood: false

SmoothingSurfaceBlock: 

SmoothingGroundBlock: 

BO3Group: 

IsSpawnPoint: false


#######################################################################
# +-----------------------------------------------------------------+ #
# |                              Blocks                             | #
# +-----------------------------------------------------------------+ #
#######################################################################

Block(-24,17,4,LEAVES:0)
Block(-24,17,5,LEAVES:0)
Block(-24,18,3,LEAVES:0)
Block(-24,18,4,LEAVES:0)
Block(-24,19,4,LEAVES:0)
Block(-24,19,5,LEAVES:0)
Block(-23,16,6,LEAVES:0)
Block(-23,16,7,LEAVES:0)
Block(-23,16,8,LEAVES:0)
Block(-23,17,4,LEAVES:0)
Block(-23,17,5,LEAVES:0)
Block(-23,17,6,LEAVES:0)
Block(-23,17,8,LEAVES:0)
Block(-23,17,9,LEAVES:0)
Block(-23,18,3,LEAVES:0)
Block(-23,18,4,LEAVES:0)
Block(-23,18,5,LEAVES:0)
Block(-23,18,6,LEAVES:0)
Block(-23,19,2,LEAVES:0)
Block(-23,19,5,LEAVES:0)
Block(-23,19,6,LEAVES:0)
Block(-23,20,3,LEAVES:0)
Block(-23,20,4,LEAVES:0)
Block(-23,20,5,LEAVES:0)
Block(-23,21,1,LEAVES:0)
Block(-23,21,2,LEAVES:0)
Block(-23,21,3,LEAVES:0)
Block(-22,12,2,LEAVES:0)
Block(-22,12,3,LEAVES:0)
Block(-22,13,1,LEAVES:0)
Block(-22,13,2,LEAVES:0)
Block(-22,14,1,LEAVES:0)
Block(-22,14,3,LEAVES:0)
Block(-22,14,8,LEAVES:0)
Block(-22,15,2,LEAVES:0)
Block(-22,15,3,LEAVES:0)
Block(-22,15,6,LEAVES:0)
Block(-22,15,7,LEAVES:0)
Block(-22,15,8,LEAVES:0)
Block(-22,15,9,LEAVES:0)
Block(-22,16,3,LEAVES:0)
Block(-22,16,6,LEAVES:0)
Block(-22,16,7,LEAVES:0)
Block(-22,16,8,LEAVES:0)
Block(-22,16,9,LEAVES:0)
Block(-22,16,10,LEAVES:0)
Block(-22,17,2,LEAVES:0)
Block(-22,17,4,LEAVES:0)
Block(-22,17,5,LEAVES:0)
Block(-22,17,6,LEAVES:0)
Block(-22,17,7,LEAVES:0)
Block(-22,17,8,LEAVES:0)
Block(-22,17,9,LEAVES:0)
Block(-22,17,10,LEAVES:0)
Block(-22,18,2,LEAVES:0)
Block(-22,18,5,LEAVES:0)
Block(-22,18,6,LEAVES:0)
Block(-22,18,7,LEAVES:0)
Block(-22,18,9,LEAVES:0)
Block(-22,19,1,LEAVES:0)
Block(-22,19,2,LEAVES:0)
Block(-22,19,3,LEAVES:0)
Block(-22,19,4,LEAVES:0)
Block(-22,19,5,LEAVES:0)
Block(-22,19,6,LEAVES:0)
Block(-22,19,7,LEAVES:0)
Block(-22,19,8,LEAVES:0)
Block(-22,20,2,LEAVES:0)
Block(-22,20,3,LEAVES:0)
Block(-22,20,5,LEAVES:0)
Block(-22,20,6,LEAVES:0)
Block(-22,20,7,LEAVES:0)
Block(-22,21,1,LEAVES:0)
Block(-22,21,2,LEAVES:0)
Block(-22,21,3,LEAVES:0)
Block(-22,21,4,LEAVES:0)
Block(-22,21,5,LEAVES:0)
Block(-22,22,2,LEAVES:0)
Block(-22,22,5,LEAVES:0)
Block(-21,12,1,LEAVES:0)
Block(-21,12,2,LEAVES:0)
Block(-21,12,3,LEAVES:0)
Block(-21,13,0,LEAVES:0)
Block(-21,13,1,LEAVES:0)
Block(-21,13,2,LEAVES:0)
Block(-21,13,8,LEAVES:0)
Block(-21,14,0,LEAVES:0)
Block(-21,14,1,LOG)
Block(-21,14,2,LOG)
Block(-21,14,8,LEAVES:0)
Block(-21,15,1,LEAVES:0)
Block(-21,15,2,LEAVES:0)
Block(-21,15,7,LEAVES:0)
Block(-21,15,8,LEAVES:0)
Block(-21,16,1,LEAVES:0)
Block(-21,16,2,LEAVES:0)
Block(-21,16,3,LEAVES:0)
Block(-21,16,6,LEAVES:0)
Block(-21,16,7,LEAVES:0)
Block(-21,16,8,LEAVES:0)
Block(-21,16,9,LEAVES:0)
Block(-21,17,1,LEAVES:0)
Block(-21,17,2,LEAVES:0)
Block(-21,17,3,LEAVES:0)
Block(-21,17,4,LEAVES:0)
Block(-21,17,5,LEAVES:0)
Block(-21,17,6,LEAVES:0)
Block(-21,17,7,LEAVES:0)
Block(-21,17,8,LEAVES:0)
Block(-21,17,9,LEAVES:0)
Block(-21,17,10,LEAVES:0)
Block(-21,17,11,LEAVES:0)
Block(-21,17,12,LEAVES:0)
Block(-21,18,0,LEAVES:0)
Block(-21,18,2,LEAVES:0)
Block(-21,18,3,LEAVES:0)
Block(-21,18,4,LEAVES:0)
Block(-21,18,6,LEAVES:0)
Block(-21,18,7,LEAVES:0)
Block(-21,18,8,LEAVES:0)
Block(-21,18,10,LEAVES:0)
Block(-21,18,11,LEAVES:0)
Block(-21,18,12,LEAVES:0)
Block(-21,19,1,LEAVES:0)
Block(-21,19,2,LEAVES:0)
Block(-21,19,3,LEAVES:0)
Block(-21,19,5,LEAVES:0)
Block(-21,19,6,LEAVES:0)
Block(-21,19,8,LEAVES:0)
Block(-21,19,9,LEAVES:0)
Block(-21,19,10,LEAVES:0)
Block(-21,20,1,LEAVES:0)
Block(-21,20,5,LEAVES:0)
Block(-21,20,6,LEAVES:0)
Block(-21,20,7,LEAVES:0)
Block(-21,20,8,LEAVES:0)
Block(-21,21,1,LEAVES:0)
Block(-21,21,2,LEAVES:0)
Block(-21,21,5,LEAVES:0)
Block(-21,21,6,LEAVES:0)
Block(-21,21,11,LEAVES:0)
Block(-21,21,12,LEAVES:0)
Block(-21,22,1,LEAVES:0)
Block(-21,22,2,LEAVES:0)
Block(-21,22,3,LEAVES:0)
Block(-21,22,4,LEAVES:0)
Block(-20,12,0,LEAVES:0)
Block(-20,12,1,LEAVES:0)
Block(-20,12,2,LEAVES:0)
Block(-20,13,-1,LEAVES:0)
Block(-20,13,0,LEAVES:0)
Block(-20,13,1,LEAVES:0)
Block(-20,13,2,LEAVES:0)
Block(-20,13,3,LEAVES:0)
Block(-20,14,0,LEAVES:0)
Block(-20,14,1,LEAVES:0)
Block(-20,14,2,LOG)
Block(-20,14,3,LOG)
Block(-20,14,4,LEAVES:0)
Block(-20,14,8,LEAVES:0)
Block(-20,15,1,LEAVES:0)
Block(-20,15,2,LEAVES:0)
Block(-20,15,5,LOG)
Block(-20,15,6,LEAVES:0)
Block(-20,15,7,LEAVES:0)
Block(-20,15,8,LEAVES:0)
Block(-20,15,9,LEAVES:0)
Block(-20,16,2,LEAVES:0)
Block(-20,16,4,LEAVES:0)
Block(-20,16,6,LOG)
Block(-20,16,7,LEAVES:0)
Block(-20,16,8,LEAVES:0)
Block(-20,16,9,LEAVES:0)
Block(-20,16,10,LEAVES:0)
Block(-20,16,11,LEAVES:0)
Block(-20,16,12,LEAVES:0)
Block(-20,16,14,LEAVES:0)
Block(-20,16,15,LEAVES:0)
Block(-20,17,0,LEAVES:0)
Block(-20,17,2,LEAVES:0)
Block(-20,17,4,LEAVES:0)
Block(-20,17,7,LOG)
Block(-20,17,9,LEAVES:0)
Block(-20,17,10,LEAVES:0)
Block(-20,17,11,LEAVES:0)
Block(-20,17,12,LEAVES:0)
Block(-20,17,13,LEAVES:0)
Block(-20,17,14,LEAVES:0)
Block(-20,17,15,LEAVES:0)
Block(-20,18,0,LEAVES:0)
Block(-20,18,1,LEAVES:0)
Block(-20,18,2,LEAVES:0)
Block(-20,18,3,LEAVES:0)
Block(-20,18,4,LEAVES:0)
Block(-20,18,5,LEAVES:0)
Block(-20,18,6,LEAVES:0)
Block(-20,18,7,LEAVES:0)
Block(-20,18,8,LEAVES:0)
Block(-20,18,9,LEAVES:0)
Block(-20,18,10,LEAVES:0)
Block(-20,18,11,LEAVES:0)
Block(-20,18,12,LEAVES:0)
Block(-20,18,13,LEAVES:0)
Block(-20,18,15,LEAVES:0)
Block(-20,19,0,LEAVES:0)
Block(-20,19,1,LEAVES:0)
Block(-20,19,2,LEAVES:0)
Block(-20,19,4,LEAVES:0)
Block(-20,19,5,LEAVES:0)
Block(-20,19,7,LEAVES:0)
Block(-20,19,8,LEAVES:0)
Block(-20,19,10,LEAVES:0)
Block(-20,19,11,LEAVES:0)
Block(-20,19,12,LEAVES:0)
Block(-20,20,1,LEAVES:0)
Block(-20,20,2,LEAVES:0)
Block(-20,20,4,LEAVES:0)
Block(-20,20,5,LEAVES:0)
Block(-20,20,7,LEAVES:0)
Block(-20,20,8,LEAVES:0)
Block(-20,20,9,LEAVES:0)
Block(-20,20,10,LEAVES:0)
Block(-20,20,12,LEAVES:0)
Block(-20,21,0,LEAVES:0)
Block(-20,21,1,LEAVES:0)
Block(-20,21,2,LEAVES:0)
Block(-20,21,6,LEAVES:0)
Block(-20,21,8,LEAVES:0)
Block(-20,21,9,LEAVES:0)
Block(-20,21,10,LEAVES:0)
Block(-20,21,11,LEAVES:0)
Block(-20,21,12,LEAVES:0)
Block(-20,21,13,LEAVES:0)
Block(-20,22,2,LEAVES:0)
Block(-20,22,9,LEAVES:0)
Block(-20,22,11,LEAVES:0)
Block(-20,23,2,LEAVES:0)
Block(-20,24,3,LEAVES:0)
Block(-20,24,4,LEAVES:0)
Block(-20,25,4,LEAVES:0)
Block(-19,11,11,LEAVES:0)
Block(-19,11,12,LEAVES:0)
Block(-19,12,1,LEAVES:0)
Block(-19,12,3,LEAVES:0)
Block(-19,12,11,LEAVES:0)
Block(-19,13,1,LEAVES:0)
Block(-19,13,2,LEAVES:0)
Block(-19,13,3,LEAVES:0)
Block(-19,13,4,LEAVES:0)
Block(-19,13,6,LEAVES:0)
Block(-19,14,1,LEAVES:0)
Block(-19,14,3,LOG)
Block(-19,14,4,LEAVES:0)
Block(-19,14,5,LEAVES:0)
Block(-19,14,6,LEAVES:0)
Block(-19,14,7,LEAVES:0)
Block(-19,14,8,LEAVES:0)
Block(-19,15,1,LEAVES:0)
Block(-19,15,2,LEAVES:0)
Block(-19,15,3,LOG)
Block(-19,15,4,LOG)
Block(-19,15,5,LOG)
Block(-19,15,6,LEAVES:0)
Block(-19,15,7,LEAVES:0)
Block(-19,15,8,LEAVES:0)
Block(-19,15,9,LEAVES:0)
Block(-19,15,13,LEAVES:0)
Block(-19,15,14,LEAVES:0)
Block(-19,15,15,LEAVES:0)
Block(-19,15,16,LEAVES:0)
Block(-19,16,0,LEAVES:0)
Block(-19,16,1,LEAVES:0)
Block(-19,16,2,LEAVES:0)
Block(-19,16,3,LEAVES:0)
Block(-19,16,7,LEAVES:0)
Block(-19,16,8,LEAVES:0)
Block(-19,16,13,LEAVES:0)
Block(-19,16,14,LEAVES:0)
Block(-19,16,15,LEAVES:0)
Block(-19,16,16,LEAVES:0)
Block(-19,17,1,LEAVES:0)
Block(-19,17,2,LEAVES:0)
Block(-19,17,3,LEAVES:0)
Block(-19,17,8,LEAVES:0)
Block(-19,17,9,LEAVES:0)
Block(-19,17,11,LEAVES:0)
Block(-19,17,12,LEAVES:0)
Block(-19,17,13,LEAVES:0)
Block(-19,17,15,LEAVES:0)
Block(-19,17,16,LEAVES:0)
Block(-19,18,0,LEAVES:0)
Block(-19,18,1,LEAVES:0)
Block(-19,18,2,LEAVES:0)
Block(-19,18,3,LEAVES:0)
Block(-19,18,4,LEAVES:0)
Block(-19,18,7,LEAVES:0)
Block(-19,18,9,LEAVES:0)
Block(-19,18,10,LEAVES:0)
Block(-19,18,11,LEAVES:0)
Block(-19,18,13,LEAVES:0)
Block(-19,18,15,LEAVES:0)
Block(-19,19,0,LEAVES:0)
Block(-19,19,1,LEAVES:0)
Block(-19,19,2,LEAVES:0)
Block(-19,19,3,LEAVES:0)
Block(-19,19,7,LEAVES:0)
Block(-19,19,9,LEAVES:0)
Block(-19,19,10,LEAVES:0)
Block(-19,20,1,LEAVES:0)
Block(-19,20,2,LEAVES:0)
Block(-19,20,8,LEAVES:0)
Block(-19,20,10,LEAVES:0)
Block(-19,20,13,LEAVES:0)
Block(-19,21,0,LEAVES:0)
Block(-19,21,1,LEAVES:0)
Block(-19,21,6,LEAVES:0)
Block(-19,21,7,LEAVES:0)
Block(-19,21,8,LEAVES:0)
Block(-19,21,10,LEAVES:0)
Block(-19,21,12,LEAVES:0)
Block(-19,21,13,LEAVES:0)
Block(-19,22,1,LEAVES:0)
Block(-19,22,2,LEAVES:0)
Block(-19,22,9,LEAVES:0)
Block(-19,22,11,LEAVES:0)
Block(-19,22,12,LEAVES:0)
Block(-19,22,13,LEAVES:0)
Block(-19,23,0,LEAVES:0)
Block(-19,23,2,LEAVES:0)
Block(-19,23,3,LEAVES:0)
Block(-19,23,10,LEAVES:0)
Block(-19,23,11,LEAVES:0)
Block(-19,23,13,LEAVES:0)
Block(-19,24,-1,LEAVES:0)
Block(-19,24,0,LEAVES:0)
Block(-19,24,3,LEAVES:0)
Block(-19,24,4,LEAVES:0)
Block(-19,24,5,LEAVES:0)
Block(-19,25,0,LEAVES:0)
Block(-19,25,1,LEAVES:0)
Block(-19,25,2,LEAVES:0)
Block(-19,25,3,LEAVES:0)
Block(-19,25,4,LEAVES:0)
Block(-19,26,0,LEAVES:0)
Block(-18,11,10,LEAVES:0)
Block(-18,11,12,LEAVES:0)
Block(-18,12,9,LEAVES:0)
Block(-18,12,10,LEAVES:0)
Block(-18,12,11,LEAVES:0)
Block(-18,12,12,LEAVES:0)
Block(-18,13,3,LEAVES:0)
Block(-18,13,13,LEAVES:0)
Block(-18,14,2,LEAVES:0)
Block(-18,14,4,LEAVES:0)
Block(-18,15,1,LEAVES:0)
Block(-18,15,2,LEAVES:0)
Block(-18,15,3,LEAVES:0)
Block(-18,15,4,LOG)
Block(-18,15,5,LEAVES:0)
Block(-18,15,6,LEAVES:0)
Block(-18,15,7,LEAVES:0)
Block(-18,15,8,LEAVES:0)
Block(-18,15,13,LEAVES:0)
Block(-18,15,14,LEAVES:0)
Block(-18,16,1,LEAVES:0)
Block(-18,16,2,LEAVES:0)
Block(-18,16,3,LEAVES:0)
Block(-18,16,4,LOG)
Block(-18,16,5,LEAVES:0)
Block(-18,16,6,LEAVES:0)
Block(-18,16,11,LEAVES:0)
Block(-18,16,13,LEAVES:0)
Block(-18,16,14,LEAVES:0)
Block(-18,16,16,LEAVES:0)
Block(-18,16,17,LEAVES:0)
Block(-18,17,-7,LEAVES:0)
Block(-18,17,1,LEAVES:0)
Block(-18,17,2,LEAVES:0)
Block(-18,17,3,LEAVES:0)
Block(-18,17,4,LEAVES:0)
Block(-18,17,5,LEAVES:0)
Block(-18,17,7,LEAVES:0)
Block(-18,17,10,LEAVES:0)
Block(-18,17,12,LEAVES:0)
Block(-18,17,15,LEAVES:0)
Block(-18,17,16,LEAVES:0)
Block(-18,18,-8,LEAVES:0)
Block(-18,18,-7,LEAVES:0)
Block(-18,18,1,LEAVES:0)
Block(-18,18,2,LEAVES:0)
Block(-18,18,3,LEAVES:0)
Block(-18,18,4,LEAVES:0)
Block(-18,18,5,LEAVES:0)
Block(-18,18,7,LEAVES:0)
Block(-18,18,10,LEAVES:0)
Block(-18,18,11,LEAVES:0)
Block(-18,18,12,LEAVES:0)
Block(-18,18,13,LOG)
Block(-18,18,14,LEAVES:0)
Block(-18,18,15,LEAVES:0)
Block(-18,19,-7,LEAVES:0)
Block(-18,19,-5,LEAVES:0)
Block(-18,19,-4,LEAVES:0)
Block(-18,19,0,LEAVES:0)
Block(-18,19,1,LEAVES:0)
Block(-18,19,2,LEAVES:0)
Block(-18,19,4,LEAVES:0)
Block(-18,19,7,LEAVES:0)
Block(-18,19,9,LEAVES:0)
Block(-18,19,10,LEAVES:0)
Block(-18,19,15,LEAVES:0)
Block(-18,20,-4,LEAVES:0)
Block(-18,20,5,LEAVES:0)
Block(-18,20,7,LEAVES:0)
Block(-18,20,8,LEAVES:0)
Block(-18,20,9,LEAVES:0)
Block(-18,20,11,LEAVES:0)
Block(-18,20,12,LEAVES:0)
Block(-18,20,13,LEAVES:0)
Block(-18,20,14,LEAVES:0)
Block(-18,20,15,LEAVES:0)
Block(-18,21,0,LEAVES:0)
Block(-18,21,1,LEAVES:0)
Block(-18,21,2,LEAVES:0)
Block(-18,21,4,LEAVES:0)
Block(-18,21,7,LEAVES:0)
Block(-18,21,9,LEAVES:0)
Block(-18,21,10,LEAVES:0)
Block(-18,21,11,LEAVES:0)
Block(-18,21,12,LEAVES:0)
Block(-18,21,13,LEAVES:0)
Block(-18,22,-1,LEAVES:0)
Block(-18,22,0,LEAVES:0)
Block(-18,22,1,LEAVES:0)
Block(-18,22,2,LOG)
Block(-18,22,4,LEAVES:0)
Block(-18,22,5,LEAVES:0)
Block(-18,22,9,LEAVES:0)
Block(-18,22,10,LEAVES:0)
Block(-18,22,11,LEAVES:0)
Block(-18,22,12,LEAVES:0)
Block(-18,22,14,LEAVES:0)
Block(-18,23,1,LEAVES:0)
Block(-18,23,2,LOG)
Block(-18,23,3,LEAVES:0)
Block(-18,23,4,LEAVES:0)
Block(-18,23,5,LEAVES:0)
Block(-18,23,9,LEAVES:0)
Block(-18,23,10,LEAVES:0)
Block(-18,23,11,LEAVES:0)
Block(-18,23,12,LEAVES:0)
Block(-18,23,13,LEAVES:0)
Block(-18,23,14,LEAVES:0)
Block(-18,24,1,LOG)
Block(-18,24,2,LEAVES:0)
Block(-18,24,3,LEAVES:0)
Block(-18,24,4,LEAVES:0)
Block(-18,24,5,LEAVES:0)
Block(-18,24,6,LEAVES:0)
Block(-18,24,8,LEAVES:0)
Block(-18,24,11,LEAVES:0)
Block(-18,25,-2,LEAVES:0)
Block(-18,25,-1,LEAVES:0)
Block(-18,25,0,LEAVES:0)
Block(-18,25,1,LEAVES:0)
Block(-18,25,2,LEAVES:0)
Block(-18,25,3,LEAVES:0)
Block(-18,25,4,LEAVES:0)
Block(-18,25,11,LEAVES:0)
Block(-18,26,-4,LEAVES:0)
Block(-18,26,-2,LEAVES:0)
Block(-18,26,0,LEAVES:0)
Block(-18,26,1,LEAVES:0)
Block(-18,26,3,LEAVES:0)
Block(-18,27,0,LEAVES:0)
Block(-17,9,11,LEAVES:0)
Block(-17,10,10,LEAVES:0)
Block(-17,10,11,LEAVES:0)
Block(-17,10,12,LEAVES:0)
Block(-17,11,9,LEAVES:0)
Block(-17,11,10,LOG)
Block(-17,11,11,LEAVES:0)
Block(-17,11,12,LEAVES:0)
Block(-17,11,13,LEAVES:0)
Block(-17,11,14,LEAVES:0)
Block(-17,12,7,LEAVES:0)
Block(-17,12,8,LEAVES:0)
Block(-17,12,11,LEAVES:0)
Block(-17,12,12,LEAVES:0)
Block(-17,13,8,LEAVES:0)
Block(-17,13,9,LEAVES:0)
Block(-17,13,12,LEAVES:0)
Block(-17,13,14,LEAVES:0)
Block(-17,14,6,LEAVES:0)
Block(-17,15,5,LEAVES:0)
Block(-17,15,6,LEAVES:0)
Block(-17,15,7,LEAVES:0)
Block(-17,15,17,LEAVES:0)
Block(-17,16,-7,LEAVES:0)
Block(-17,16,-6,LEAVES:0)
Block(-17,16,-5,LEAVES:0)
Block(-17,16,2,LEAVES:0)
Block(-17,16,3,LEAVES:0)
Block(-17,16,4,LOG)
Block(-17,16,6,LEAVES:0)
Block(-17,16,7,LEAVES:0)
Block(-17,16,12,LEAVES:0)
Block(-17,16,13,LEAVES:0)
Block(-17,16,14,LEAVES:0)
Block(-17,16,15,LEAVES:0)
Block(-17,16,16,LEAVES:0)
Block(-17,17,-8,LEAVES:0)
Block(-17,17,-6,LEAVES:0)
Block(-17,17,-5,LEAVES:0)
Block(-17,17,-4,LEAVES:0)
Block(-17,17,3,LEAVES:0)
Block(-17,17,4,LOG)
Block(-17,17,5,LEAVES:0)
Block(-17,17,6,LEAVES:0)
Block(-17,17,10,LEAVES:0)
Block(-17,17,14,LOG)
Block(-17,17,15,LEAVES:0)
Block(-17,17,16,LEAVES:0)
Block(-17,18,-9,LEAVES:0)
Block(-17,18,-8,LEAVES:0)
Block(-17,18,-7,LEAVES:0)
Block(-17,18,-5,LEAVES:0)
Block(-17,18,3,LEAVES:0)
Block(-17,18,4,LEAVES:0)
Block(-17,18,5,LEAVES:0)
Block(-17,18,7,LEAVES:0)
Block(-17,18,16,LEAVES:0)
Block(-17,19,-8,LEAVES:0)
Block(-17,19,-7,LEAVES:0)
Block(-17,19,-6,LEAVES:0)
Block(-17,19,-5,LEAVES:0)
Block(-17,19,-4,LEAVES:0)
Block(-17,19,-3,LEAVES:0)
Block(-17,19,6,LEAVES:0)
Block(-17,19,12,LEAVES:0)
Block(-17,19,13,LEAVES:0)
Block(-17,20,-6,LEAVES:0)
Block(-17,20,-5,LEAVES:0)
Block(-17,20,-3,LEAVES:0)
Block(-17,20,-2,LEAVES:0)
Block(-17,20,1,LEAVES:0)
Block(-17,20,2,LEAVES:0)
Block(-17,20,3,LOG)
Block(-17,20,4,LOG)
Block(-17,20,5,LEAVES:0)
Block(-17,20,7,LEAVES:0)
Block(-17,20,8,LEAVES:0)
Block(-17,20,11,LEAVES:0)
Block(-17,20,12,LEAVES:0)
Block(-17,20,13,LEAVES:0)
Block(-17,20,15,LEAVES:0)
Block(-17,21,-5,LEAVES:0)
Block(-17,21,-4,LEAVES:0)
Block(-17,21,-3,LEAVES:0)
Block(-17,21,0,LEAVES:0)
Block(-17,21,1,LEAVES:0)
Block(-17,21,2,LOG)
Block(-17,21,3,LOG)
Block(-17,21,4,LOG)
Block(-17,21,6,LEAVES:0)
Block(-17,21,12,LEAVES:0)
Block(-17,21,13,LEAVES:0)
Block(-17,21,14,LEAVES:0)
Block(-17,21,15,LEAVES:0)
Block(-17,22,-4,LEAVES:0)
Block(-17,22,-1,LEAVES:0)
Block(-17,22,0,LEAVES:0)
Block(-17,22,1,LEAVES:0)
Block(-17,22,2,LOG)
Block(-17,22,3,LOG)
Block(-17,22,6,LEAVES:0)
Block(-17,22,7,LEAVES:0)
Block(-17,22,8,LEAVES:0)
Block(-17,22,10,LEAVES:0)
Block(-17,22,11,LEAVES:0)
Block(-17,22,12,LEAVES:0)
Block(-17,22,13,LEAVES:0)
Block(-17,22,14,LEAVES:0)
Block(-17,23,0,LEAVES:0)
Block(-17,23,1,LEAVES:0)
Block(-17,23,2,LEAVES:0)
Block(-17,23,3,LEAVES:0)
Block(-17,23,4,LEAVES:0)
Block(-17,23,5,LEAVES:0)
Block(-17,23,10,LEAVES:0)
Block(-17,23,11,LEAVES:0)
Block(-17,23,12,LEAVES:0)
Block(-17,23,13,LEAVES:0)
Block(-17,23,14,LEAVES:0)
Block(-17,23,15,LEAVES:0)
Block(-17,24,-1,LEAVES:0)
Block(-17,24,0,LOG)
Block(-17,24,3,LEAVES:0)
Block(-17,24,4,LEAVES:0)
Block(-17,24,5,LEAVES:0)
Block(-17,24,6,LEAVES:0)
Block(-17,24,7,LEAVES:0)
Block(-17,24,8,LEAVES:0)
Block(-17,24,10,LEAVES:0)
Block(-17,24,11,LEAVES:0)
Block(-17,24,12,LEAVES:0)
Block(-17,24,13,LEAVES:0)
Block(-17,25,-5,LEAVES:0)
Block(-17,25,-4,LEAVES:0)
Block(-17,25,-3,LEAVES:0)
Block(-17,25,1,LEAVES:0)
Block(-17,25,2,LEAVES:0)
Block(-17,25,5,LEAVES:0)
Block(-17,25,6,LEAVES:0)
Block(-17,25,8,LEAVES:0)
Block(-17,25,11,LEAVES:0)
Block(-17,25,12,LEAVES:0)
Block(-17,26,-4,LEAVES:0)
Block(-17,26,-3,LEAVES:0)
Block(-17,26,-2,LEAVES:0)
Block(-17,26,-1,LEAVES:0)
Block(-17,26,1,LEAVES:0)
Block(-17,26,2,LEAVES:0)
Block(-17,27,-6,LEAVES:0)
Block(-17,27,-4,LEAVES:0)
Block(-17,27,-2,LEAVES:0)
Block(-17,27,-1,LEAVES:0)
Block(-17,27,0,LEAVES:0)
Block(-17,28,0,LEAVES:0)
Block(-16,10,13,LEAVES:0)
Block(-16,11,9,LEAVES:0)
Block(-16,11,10,LEAVES:0)
Block(-16,11,11,LEAVES:0)
Block(-16,12,8,LEAVES:0)
Block(-16,12,9,LEAVES:0)
Block(-16,12,10,LEAVES:0)
Block(-16,12,11,LOG)
Block(-16,12,12,LOG)
Block(-16,12,13,LEAVES:0)
Block(-16,12,14,LEAVES:0)
Block(-16,13,8,LEAVES:0)
Block(-16,13,9,LEAVES:0)
Block(-16,13,10,LEAVES:0)
Block(-16,13,11,LEAVES:0)
Block(-16,13,12,LEAVES:0)
Block(-16,13,13,LEAVES:0)
Block(-16,13,14,LEAVES:0)
Block(-16,13,15,LEAVES:0)
Block(-16,14,9,LEAVES:0)
Block(-16,14,10,LEAVES:0)
Block(-16,14,11,LEAVES:0)
Block(-16,14,13,LEAVES:0)
Block(-16,14,15,LEAVES:0)
Block(-16,14,16,LEAVES:0)
Block(-16,15,5,LEAVES:0)
Block(-16,15,6,LEAVES:0)
Block(-16,15,13,LOG)
Block(-16,15,14,LOG)
Block(-16,15,16,LEAVES:0)
Block(-16,16,-6,LEAVES:0)
Block(-16,16,-4,LEAVES:0)
Block(-16,16,-3,LEAVES:0)
Block(-16,16,3,LEAVES:0)
Block(-16,16,6,LEAVES:0)
Block(-16,16,12,LEAVES:0)
Block(-16,16,14,LOG)
Block(-16,16,15,LOG)
Block(-16,16,16,LEAVES:0)
Block(-16,17,-10,LEAVES:0)
Block(-16,17,-8,LEAVES:0)
Block(-16,17,-6,LEAVES:0)
Block(-16,17,-5,LEAVES:0)
Block(-16,17,-4,LEAVES:0)
Block(-16,17,-3,LEAVES:0)
Block(-16,17,-2,LEAVES:0)
Block(-16,17,4,LOG)
Block(-16,17,5,LEAVES:0)
Block(-16,17,13,LEAVES:0)
Block(-16,17,14,LEAVES:0)
Block(-16,17,15,LEAVES:0)
Block(-16,17,16,LEAVES:0)
Block(-16,17,17,LEAVES:0)
Block(-16,18,-9,LEAVES:0)
Block(-16,18,-8,LEAVES:0)
Block(-16,18,-7,LEAVES:0)
Block(-16,18,-6,LEAVES:0)
Block(-16,18,-4,LEAVES:0)
Block(-16,18,5,LEAVES:0)
Block(-16,18,13,LEAVES:0)
Block(-16,19,-10,LEAVES:0)
Block(-16,19,-9,LEAVES:0)
Block(-16,19,-8,LEAVES:0)
Block(-16,19,-6,LEAVES:0)
Block(-16,19,-5,LEAVES:0)
Block(-16,19,-4,LEAVES:0)
Block(-16,19,-3,LEAVES:0)
Block(-16,19,2,LEAVES:0)
Block(-16,19,3,LEAVES:0)
Block(-16,19,4,LOG)
Block(-16,19,6,LEAVES:0)
Block(-16,19,10,LEAVES:0)
Block(-16,19,11,LEAVES:0)
Block(-16,19,12,LEAVES:0)
Block(-16,19,14,LEAVES:0)
Block(-16,19,15,LEAVES:0)
Block(-16,19,16,LEAVES:0)
Block(-16,20,-9,LEAVES:0)
Block(-16,20,-8,LEAVES:0)
Block(-16,20,-7,LEAVES:0)
Block(-16,20,-6,LEAVES:0)
Block(-16,20,-5,LEAVES:0)
Block(-16,20,-4,LEAVES:0)
Block(-16,20,-3,LEAVES:0)
Block(-16,20,-2,LEAVES:0)
Block(-16,20,-1,LEAVES:0)
Block(-16,20,1,LEAVES:0)
Block(-16,20,2,LEAVES:0)
Block(-16,20,3,LEAVES:0)
Block(-16,20,4,LOG)
Block(-16,20,5,LEAVES:0)
Block(-16,20,7,LEAVES:0)
Block(-16,20,9,LEAVES:0)
Block(-16,20,10,LEAVES:0)
Block(-16,20,11,LEAVES:0)
Block(-16,20,12,LEAVES:0)
Block(-16,20,13,LEAVES:0)
Block(-16,20,14,LEAVES:0)
Block(-16,21,-7,LEAVES:0)
Block(-16,21,-5,LEAVES:0)
Block(-16,21,-4,LEAVES:0)
Block(-16,21,-3,LEAVES:0)
Block(-16,21,3,LEAVES:0)
Block(-16,21,4,LEAVES:0)
Block(-16,21,5,LEAVES:0)
Block(-16,21,7,LEAVES:0)
Block(-16,21,10,LEAVES:0)
Block(-16,21,12,LEAVES:0)
Block(-16,21,13,LEAVES:0)
Block(-16,21,14,LEAVES:0)
Block(-16,21,15,LEAVES:0)
Block(-16,22,-4,LEAVES:0)
Block(-16,22,0,LEAVES:0)
Block(-16,22,1,LEAVES:0)
Block(-16,22,2,LEAVES:0)
Block(-16,22,3,LEAVES:0)
Block(-16,22,8,LEAVES:0)
Block(-16,22,10,LEAVES:0)
Block(-16,22,11,LEAVES:0)
Block(-16,22,12,LEAVES:0)
Block(-16,22,14,LEAVES:0)
Block(-16,23,-4,LEAVES:0)
Block(-16,23,2,LEAVES:0)
Block(-16,23,3,LEAVES:0)
Block(-16,23,8,LEAVES:0)
Block(-16,23,9,LEAVES:0)
Block(-16,23,10,LEAVES:0)
Block(-16,23,12,LEAVES:0)
Block(-16,24,-4,LEAVES:0)
Block(-16,24,-3,LEAVES:0)
Block(-16,24,3,LEAVES:0)
Block(-16,24,4,LEAVES:0)
Block(-16,24,5,LEAVES:0)
Block(-16,24,6,LEAVES:0)
Block(-16,24,7,LEAVES:0)
Block(-16,24,8,LEAVES:0)
Block(-16,24,9,LEAVES:0)
Block(-16,24,10,LEAVES:0)
Block(-16,24,11,LEAVES:0)
Block(-16,24,12,LEAVES:0)
Block(-16,24,13,LEAVES:0)
Block(-16,24,14,LEAVES:0)
Block(-16,24,15,LEAVES:0)
Block(-16,25,-5,LEAVES:0)
Block(-16,25,-4,LEAVES:0)
Block(-16,25,-3,LEAVES:0)
Block(-16,25,-2,LEAVES:0)
Block(-16,25,-1,LOG)
Block(-16,25,3,LEAVES:0)
Block(-16,25,4,LEAVES:0)
Block(-16,25,5,LEAVES:0)
Block(-16,25,6,LEAVES:0)
Block(-16,25,7,LEAVES:0)
Block(-16,25,8,LEAVES:0)
Block(-16,25,10,LEAVES:0)
Block(-16,25,12,LEAVES:0)
Block(-16,26,-7,LEAVES:0)
Block(-16,26,-6,LEAVES:0)
Block(-16,26,-5,LEAVES:0)
Block(-16,26,-4,LEAVES:0)
Block(-16,26,-3,LEAVES:0)
Block(-16,26,-2,LEAVES:0)
Block(-16,26,5,LEAVES:0)
Block(-16,26,11,LEAVES:0)
Block(-16,26,13,LEAVES:0)
Block(-16,27,-6,LEAVES:0)
Block(-16,27,-5,LEAVES:0)
Block(-16,27,-4,LEAVES:0)
Block(-16,27,-3,LEAVES:0)
Block(-16,27,-2,LEAVES:0)
Block(-16,27,1,LEAVES:0)
Block(-16,28,-6,LEAVES:0)
Block(-16,28,-1,LEAVES:0)
Block(-16,28,0,LEAVES:0)
Block(-15,9,12,LEAVES:0)
Block(-15,10,13,LEAVES:0)
Block(-15,10,14,LEAVES:0)
Block(-15,11,12,LEAVES:0)
Block(-15,12,8,LEAVES:0)
Block(-15,12,9,LEAVES:0)
Block(-15,12,10,LEAVES:0)
Block(-15,12,11,LEAVES:0)
Block(-15,12,12,LOG)
Block(-15,12,13,LEAVES:0)
Block(-15,12,14,LEAVES:0)
Block(-15,12,15,LEAVES:0)
Block(-15,13,9,LEAVES:0)
Block(-15,13,10,LEAVES:0)
Block(-15,13,11,LEAVES:0)
Block(-15,13,12,LOG)
Block(-15,13,15,LEAVES:0)
Block(-15,14,10,LEAVES:0)
Block(-15,14,11,LEAVES:0)
Block(-15,14,12,LOG)
Block(-15,14,13,LOG)
Block(-15,14,14,LEAVES:0)
Block(-15,14,15,LEAVES:0)
Block(-15,14,17,LEAVES:0)
Block(-15,15,11,LEAVES:0)
Block(-15,15,12,LEAVES:0)
Block(-15,15,13,LOG)
Block(-15,15,15,LEAVES:0)
Block(-15,15,17,LEAVES:0)
Block(-15,16,-7,LEAVES:0)
Block(-15,16,-6,LEAVES:0)
Block(-15,16,-4,LEAVES:0)
Block(-15,16,14,LEAVES:0)
Block(-15,16,15,LEAVES:0)
Block(-15,17,-9,LEAVES:0)
Block(-15,17,-6,LEAVES:0)
Block(-15,17,-5,LEAVES:0)
Block(-15,17,-4,LEAVES:0)
Block(-15,17,-2,LEAVES:0)
Block(-15,17,-1,LEAVES:0)
Block(-15,17,4,LOG)
Block(-15,17,13,LEAVES:0)
Block(-15,17,14,LEAVES:0)
Block(-15,17,15,LEAVES:0)
Block(-15,17,16,LEAVES:0)
Block(-15,17,17,LEAVES:0)
Block(-15,18,-11,LEAVES:0)
Block(-15,18,-10,LEAVES:0)
Block(-15,18,-9,LEAVES:0)
Block(-15,18,-8,LEAVES:0)
Block(-15,18,-7,LEAVES:0)
Block(-15,18,-4,LOG)
Block(-15,18,2,LOG)
Block(-15,18,3,LOG)
Block(-15,18,4,LOG)
Block(-15,18,5,LEAVES:0)
Block(-15,18,13,LEAVES:0)
Block(-15,18,15,LEAVES:0)
Block(-15,19,-10,LEAVES:0)
Block(-15,19,-9,LEAVES:0)
Block(-15,19,-8,LEAVES:0)
Block(-15,19,-5,LEAVES:0)
Block(-15,19,-4,LOG)
Block(-15,19,-3,LEAVES:0)
Block(-15,19,2,LEAVES:0)
Block(-15,19,3,LEAVES:0)
Block(-15,19,4,LOG)
Block(-15,19,13,LEAVES:0)
Block(-15,19,14,LEAVES:0)
Block(-15,19,15,LEAVES:0)
Block(-15,20,-11,LEAVES:0)
Block(-15,20,-10,LEAVES:0)
Block(-15,20,-9,LEAVES:0)
Block(-15,20,-8,LEAVES:0)
Block(-15,20,-7,LEAVES:0)
Block(-15,20,-6,LEAVES:0)
Block(-15,20,-5,LEAVES:0)
Block(-15,20,-4,LEAVES:0)
Block(-15,20,-3,LEAVES:0)
Block(-15,20,-2,LEAVES:0)
Block(-15,20,3,LEAVES:0)
Block(-15,20,4,LEAVES:0)
Block(-15,20,5,LEAVES:0)
Block(-15,20,6,LEAVES:0)
Block(-15,20,8,LEAVES:0)
Block(-15,20,9,LEAVES:0)
Block(-15,20,12,LEAVES:0)
Block(-15,20,13,LEAVES:0)
Block(-15,20,14,LEAVES:0)
Block(-15,20,15,LEAVES:0)
Block(-15,21,-8,LEAVES:0)
Block(-15,21,-7,LEAVES:0)
Block(-15,21,-6,LEAVES:0)
Block(-15,21,-4,LEAVES:0)
Block(-15,21,-3,LEAVES:0)
Block(-15,21,-2,LEAVES:0)
Block(-15,21,3,LEAVES:0)
Block(-15,21,5,LEAVES:0)
Block(-15,21,7,LEAVES:0)
Block(-15,21,8,LEAVES:0)
Block(-15,21,9,LEAVES:0)
Block(-15,21,10,LEAVES:0)
Block(-15,21,11,LEAVES:0)
Block(-15,21,13,LEAVES:0)
Block(-15,22,-6,LEAVES:0)
Block(-15,22,-3,LEAVES:0)
Block(-15,22,4,LEAVES:0)
Block(-15,22,5,LEAVES:0)
Block(-15,22,6,LEAVES:0)
Block(-15,22,8,LOG)
Block(-15,22,9,LOG)
Block(-15,22,12,LEAVES:0)
Block(-15,23,-4,LEAVES:0)
Block(-15,23,-3,LEAVES:0)
Block(-15,23,-2,LEAVES:0)
Block(-15,23,2,LEAVES:0)
Block(-15,23,4,LEAVES:0)
Block(-15,23,5,LEAVES:0)
Block(-15,23,6,LEAVES:0)
Block(-15,23,8,LEAVES:0)
Block(-15,23,13,LEAVES:0)
Block(-15,23,14,LEAVES:0)
Block(-15,23,15,LEAVES:0)
Block(-15,24,-2,LEAVES:0)
Block(-15,24,-1,LEAVES:0)
Block(-15,24,3,LEAVES:0)
Block(-15,24,4,LEAVES:0)
Block(-15,24,5,LEAVES:0)
Block(-15,24,7,LEAVES:0)
Block(-15,24,10,LEAVES:0)
Block(-15,24,11,LEAVES:0)
Block(-15,24,12,LEAVES:0)
Block(-15,24,14,LEAVES:0)
Block(-15,25,-7,LEAVES:0)
Block(-15,25,-6,LEAVES:0)
Block(-15,25,-5,LEAVES:0)
Block(-15,25,-4,LEAVES:0)
Block(-15,25,-3,LEAVES:0)
Block(-15,25,-1,LEAVES:0)
Block(-15,25,0,LEAVES:0)
Block(-15,25,3,LEAVES:0)
Block(-15,25,4,LEAVES:0)
Block(-15,25,5,LEAVES:0)
Block(-15,25,7,LEAVES:0)
Block(-15,25,8,LEAVES:0)
Block(-15,25,9,LEAVES:0)
Block(-15,25,10,LEAVES:0)
Block(-15,25,11,LEAVES:0)
Block(-15,25,12,LEAVES:0)
Block(-15,25,14,LEAVES:0)
Block(-15,26,-5,LEAVES:0)
Block(-15,26,-4,LEAVES:0)
Block(-15,26,-3,LEAVES:0)
Block(-15,26,-2,LEAVES:0)
Block(-15,26,-1,LEAVES:0)
Block(-15,26,0,LEAVES:0)
Block(-15,26,4,LEAVES:0)
Block(-15,26,5,LEAVES:0)
Block(-15,26,6,LEAVES:0)
Block(-15,26,8,LEAVES:0)
Block(-15,26,10,LEAVES:0)
Block(-15,26,11,LEAVES:0)
Block(-15,26,13,LEAVES:0)
Block(-15,26,14,LEAVES:0)
Block(-15,27,-5,LEAVES:0)
Block(-15,27,-4,LEAVES:0)
Block(-15,27,-2,LEAVES:0)
Block(-15,27,-1,LEAVES:0)
Block(-15,27,11,LEAVES:0)
Block(-15,28,-5,LEAVES:0)
Block(-15,28,0,LEAVES:0)
Block(-14,9,13,LEAVES:0)
Block(-14,10,11,LEAVES:0)
Block(-14,10,12,LEAVES:0)
Block(-14,10,13,LEAVES:0)
Block(-14,10,14,LEAVES:0)
Block(-14,10,15,LEAVES:0)
Block(-14,11,10,LEAVES:0)
Block(-14,11,12,LEAVES:0)
Block(-14,11,13,LEAVES:0)
Block(-14,11,14,LEAVES:0)
Block(-14,11,15,LEAVES:0)
Block(-14,12,11,LEAVES:0)
Block(-14,12,12,LEAVES:0)
Block(-14,12,14,LEAVES:0)
Block(-14,12,15,LEAVES:0)
Block(-14,13,10,LEAVES:0)
Block(-14,13,11,LEAVES:0)
Block(-14,13,12,LEAVES:0)
Block(-14,13,14,LEAVES:0)
Block(-14,13,15,LEAVES:0)
Block(-14,13,16,LEAVES:0)
Block(-14,14,11,LEAVES:0)
Block(-14,14,12,LEAVES:0)
Block(-14,14,13,LOG)
Block(-14,14,14,LEAVES:0)
Block(-14,14,15,LEAVES:0)
Block(-14,14,16,LEAVES:0)
Block(-14,15,-9,LEAVES:0)
Block(-14,15,-8,LEAVES:0)
Block(-14,15,-7,LEAVES:0)
Block(-14,15,-5,LEAVES:0)
Block(-14,15,12,LEAVES:0)
Block(-14,15,13,LEAVES:0)
Block(-14,15,15,LEAVES:0)
Block(-14,16,-10,LEAVES:0)
Block(-14,16,-8,LEAVES:0)
Block(-14,16,-7,LEAVES:0)
Block(-14,16,-6,LEAVES:0)
Block(-14,16,-5,LEAVES:0)
Block(-14,16,15,LEAVES:0)
Block(-14,16,16,LEAVES:0)
Block(-14,16,17,LEAVES:0)
Block(-14,17,-11,LEAVES:0)
Block(-14,17,-10,LEAVES:0)
Block(-14,17,-5,LEAVES:0)
Block(-14,17,-4,LOG)
Block(-14,17,-2,LEAVES:0)
Block(-14,17,0,LOG)
Block(-14,17,1,LOG)
Block(-14,17,15,LEAVES:0)
Block(-14,18,-10,LEAVES:0)
Block(-14,18,-9,LEAVES:0)
Block(-14,18,-8,LEAVES:0)
Block(-14,18,-5,LOG)
Block(-14,18,-4,LOG)
Block(-14,18,-3,LEAVES:0)
Block(-14,18,-2,LEAVES:0)
Block(-14,18,-1,LEAVES:0)
Block(-14,18,1,LOG)
Block(-14,18,2,LOG)
Block(-14,18,3,LOG)
Block(-14,18,4,LOG)
Block(-14,19,-11,LEAVES:0)
Block(-14,19,-9,LEAVES:0)
Block(-14,19,-3,LEAVES:0)
Block(-14,19,3,LOG)
Block(-14,19,4,LOG)
Block(-14,19,5,LEAVES:0)
Block(-14,20,-10,LEAVES:0)
Block(-14,20,-9,LEAVES:0)
Block(-14,20,-8,LEAVES:0)
Block(-14,20,-5,LEAVES:0)
Block(-14,20,-4,LEAVES:0)
Block(-14,20,-3,LEAVES:0)
Block(-14,20,3,LEAVES:0)
Block(-14,20,4,LEAVES:0)
Block(-14,20,5,LEAVES:0)
Block(-14,20,6,LEAVES:0)
Block(-14,20,8,LEAVES:0)
Block(-14,20,10,LEAVES:0)
Block(-14,20,12,LEAVES:0)
Block(-14,20,13,LEAVES:0)
Block(-14,21,-9,LEAVES:0)
Block(-14,21,-8,LEAVES:0)
Block(-14,21,-6,LEAVES:0)
Block(-14,21,-3,LEAVES:0)
Block(-14,21,-2,LEAVES:0)
Block(-14,21,3,LEAVES:0)
Block(-14,21,4,LEAVES:0)
Block(-14,21,5,LEAVES:0)
Block(-14,21,6,LEAVES:0)
Block(-14,21,7,LEAVES:0)
Block(-14,21,9,LOG)
Block(-14,21,10,LOG)
Block(-14,21,11,LEAVES:0)
Block(-14,21,12,LEAVES:0)
Block(-14,22,-8,LEAVES:0)
Block(-14,22,-7,LEAVES:0)
Block(-14,22,-6,LEAVES:0)
Block(-14,22,-5,LEAVES:0)
Block(-14,22,5,LEAVES:0)
Block(-14,22,9,LOG)
Block(-14,22,10,LEAVES:0)
Block(-14,22,11,LEAVES:0)
Block(-14,22,12,LEAVES:0)
Block(-14,23,-7,LEAVES:0)
Block(-14,23,-6,LEAVES:0)
Block(-14,23,-4,LEAVES:0)
Block(-14,23,-3,LEAVES:0)
Block(-14,23,-2,LEAVES:0)
Block(-14,23,6,LEAVES:0)
Block(-14,23,8,LEAVES:0)
Block(-14,23,9,LEAVES:0)
Block(-14,23,10,LEAVES:0)
Block(-14,23,13,LEAVES:0)
Block(-14,23,14,LEAVES:0)
Block(-14,23,15,LEAVES:0)
Block(-14,24,-8,LEAVES:0)
Block(-14,24,-7,LEAVES:0)
Block(-14,24,-5,LEAVES:0)
Block(-14,24,-3,LEAVES:0)
Block(-14,24,-1,LEAVES:0)
Block(-14,24,8,LEAVES:0)
Block(-14,24,10,LEAVES:0)
Block(-14,24,14,LEAVES:0)
Block(-14,24,15,LEAVES:0)
Block(-14,24,16,LEAVES:0)
Block(-14,25,-7,LEAVES:0)
Block(-14,25,-6,LEAVES:0)
Block(-14,25,-5,LEAVES:0)
Block(-14,25,-1,LEAVES:0)
Block(-14,25,7,LEAVES:0)
Block(-14,25,8,LEAVES:0)
Block(-14,25,10,LEAVES:0)
Block(-14,25,13,LEAVES:0)
Block(-14,25,14,LEAVES:0)
Block(-14,26,-7,LEAVES:0)
Block(-14,26,-6,LEAVES:0)
Block(-14,26,-5,LEAVES:0)
Block(-14,26,-3,LEAVES:0)
Block(-14,26,-2,LEAVES:0)
Block(-14,26,-1,LEAVES:0)
Block(-14,26,3,LEAVES:0)
Block(-14,26,4,LEAVES:0)
Block(-14,26,5,LEAVES:0)
Block(-14,26,6,LEAVES:0)
Block(-14,26,7,LEAVES:0)
Block(-14,26,8,LEAVES:0)
Block(-14,26,9,LEAVES:0)
Block(-14,26,11,LEAVES:0)
Block(-14,26,12,LEAVES:0)
Block(-14,26,13,LEAVES:0)
Block(-14,26,15,LEAVES:0)
Block(-14,26,16,LEAVES:0)
Block(-14,27,-6,LEAVES:0)
Block(-14,27,-4,LEAVES:0)
Block(-14,27,-3,LEAVES:0)
Block(-14,27,-1,LEAVES:0)
Block(-14,27,6,LEAVES:0)
Block(-14,27,7,LEAVES:0)
Block(-14,27,8,LEAVES:0)
Block(-14,27,11,LEAVES:0)
Block(-14,27,13,LEAVES:0)
Block(-14,27,14,LEAVES:0)
Block(-14,27,15,LEAVES:0)
Block(-14,27,16,LEAVES:0)
Block(-14,27,17,LEAVES:0)
Block(-14,28,-6,LEAVES:0)
Block(-14,28,-5,LEAVES:0)
Block(-14,28,-4,LEAVES:0)
Block(-14,28,15,LEAVES:0)
Block(-14,28,16,LEAVES:0)
Block(-13,10,10,LEAVES:0)
Block(-13,10,11,LEAVES:0)
Block(-13,10,12,LEAVES:0)
Block(-13,10,14,LEAVES:0)
Block(-13,10,16,LEAVES:0)
Block(-13,11,11,LEAVES:0)
Block(-13,11,12,LEAVES:0)
Block(-13,11,13,LEAVES:0)
Block(-13,11,14,LEAVES:0)
Block(-13,11,16,LEAVES:0)
Block(-13,11,17,LEAVES:0)
Block(-13,12,10,LEAVES:0)
Block(-13,12,11,LEAVES:0)
Block(-13,12,12,LEAVES:0)
Block(-13,12,15,LEAVES:0)
Block(-13,12,16,LEAVES:0)
Block(-13,13,10,LEAVES:0)
Block(-13,13,11,LEAVES:0)
Block(-13,13,12,LEAVES:0)
Block(-13,13,13,LEAVES:0)
Block(-13,14,-10,LEAVES:0)
Block(-13,14,-9,LEAVES:0)
Block(-13,14,-6,LEAVES:0)
Block(-13,14,10,LEAVES:0)
Block(-13,14,11,LEAVES:0)
Block(-13,14,12,LOG)
Block(-13,14,13,LOG)
Block(-13,14,14,LEAVES:0)
Block(-13,14,16,LEAVES:0)
Block(-13,14,17,LEAVES:0)
Block(-13,15,-9,LEAVES:0)
Block(-13,15,-5,LEAVES:0)
Block(-13,15,16,LEAVES:0)
Block(-13,16,-11,LEAVES:0)
Block(-13,16,-10,LEAVES:0)
Block(-13,16,-9,LEAVES:0)
Block(-13,16,-8,LEAVES:0)
Block(-13,16,-7,LEAVES:0)
Block(-13,16,-4,LOG)
Block(-13,16,-3,LOG)
Block(-13,16,-2,LOG)
Block(-13,16,0,LOG)
Block(-13,16,16,LEAVES:0)
Block(-13,16,17,LEAVES:0)
Block(-13,17,-11,LEAVES:0)
Block(-13,17,-8,LEAVES:0)
Block(-13,17,-7,LEAVES:0)
Block(-13,17,-4,LOG)
Block(-13,17,0,LOG)
Block(-13,17,1,LOG)
Block(-13,18,-13,LEAVES:0)
Block(-13,18,-12,LEAVES:0)
Block(-13,18,-11,LEAVES:0)
Block(-13,18,-10,LEAVES:0)
Block(-13,18,-9,LEAVES:0)
Block(-13,18,-8,LEAVES:0)
Block(-13,18,-7,LEAVES:0)
Block(-13,18,-6,LEAVES:0)
Block(-13,18,-4,LOG)
Block(-13,19,-12,LEAVES:0)
Block(-13,19,-11,LEAVES:0)
Block(-13,19,-10,LEAVES:0)
Block(-13,19,-9,LEAVES:0)
Block(-13,19,-8,LEAVES:0)
Block(-13,19,-7,LEAVES:0)
Block(-13,19,-4,LEAVES:0)
Block(-13,19,4,LOG)
Block(-13,20,-11,LEAVES:0)
Block(-13,20,-10,LEAVES:0)
Block(-13,20,-8,LEAVES:0)
Block(-13,20,-6,LEAVES:0)
Block(-13,20,-3,LEAVES:0)
Block(-13,20,3,LOG)
Block(-13,20,4,LOG)
Block(-13,20,7,LEAVES:0)
Block(-13,20,8,LEAVES:0)
Block(-13,20,10,LEAVES:0)
Block(-13,20,11,LEAVES:0)
Block(-13,21,-10,LEAVES:0)
Block(-13,21,-9,LEAVES:0)
Block(-13,21,-6,LEAVES:0)
Block(-13,21,-4,LEAVES:0)
Block(-13,21,3,LOG)
Block(-13,21,5,LEAVES:0)
Block(-13,21,6,LEAVES:0)
Block(-13,21,9,LOG)
Block(-13,21,10,LOG)
Block(-13,21,11,LOG)
Block(-13,21,12,LEAVES:0)
Block(-13,22,-8,LEAVES:0)
Block(-13,22,-7,LEAVES:0)
Block(-13,22,-6,LEAVES:0)
Block(-13,22,6,LEAVES:0)
Block(-13,22,8,LEAVES:0)
Block(-13,22,9,LEAVES:0)
Block(-13,22,10,LEAVES:0)
Block(-13,22,11,LEAVES:0)
Block(-13,23,-6,LEAVES:0)
Block(-13,23,-4,LEAVES:0)
Block(-13,23,12,LEAVES:0)
Block(-13,23,13,LEAVES:0)
Block(-13,23,14,LEAVES:0)
Block(-13,23,15,LEAVES:0)
Block(-13,24,-6,LEAVES:0)
Block(-13,24,-5,LEAVES:0)
Block(-13,24,-4,LEAVES:0)
Block(-13,24,-3,LEAVES:0)
Block(-13,24,13,LEAVES:0)
Block(-13,24,15,LEAVES:0)
Block(-13,25,-7,LEAVES:0)
Block(-13,25,-5,LEAVES:0)
Block(-13,25,4,LEAVES:0)
Block(-13,25,5,LEAVES:0)
Block(-13,25,6,LEAVES:0)
Block(-13,25,7,LEAVES:0)
Block(-13,25,8,LEAVES:0)
Block(-13,25,11,LEAVES:0)
Block(-13,25,13,LEAVES:0)
Block(-13,25,15,LEAVES:0)
Block(-13,25,16,LEAVES:0)
Block(-13,25,17,LEAVES:0)
Block(-13,26,-7,LEAVES:0)
Block(-13,26,-5,LEAVES:0)
Block(-13,26,-4,LEAVES:0)
Block(-13,26,-2,LEAVES:0)
Block(-13,26,3,LEAVES:0)
Block(-13,26,4,LEAVES:0)
Block(-13,26,7,LEAVES:0)
Block(-13,26,8,LEAVES:0)
Block(-13,26,9,LEAVES:0)
Block(-13,26,14,LOG)
Block(-13,26,17,LEAVES:0)
Block(-13,27,-6,LEAVES:0)
Block(-13,27,-5,LEAVES:0)
Block(-13,27,-3,LEAVES:0)
Block(-13,27,-2,LEAVES:0)
Block(-13,27,3,LEAVES:0)
Block(-13,27,4,LEAVES:0)
Block(-13,27,12,LEAVES:0)
Block(-13,27,13,LEAVES:0)
Block(-13,27,14,LEAVES:0)
Block(-13,27,15,LEAVES:0)
Block(-13,27,16,LEAVES:0)
Block(-13,27,17,LEAVES:0)
Block(-13,28,-5,LEAVES:0)
Block(-13,28,13,LEAVES:0)
Block(-13,28,14,LEAVES:0)
Block(-13,28,15,LEAVES:0)
Block(-13,28,17,LEAVES:0)
Block(-13,29,15,LEAVES:0)
Block(-13,29,16,LEAVES:0)
Block(-12,10,12,LEAVES:0)
Block(-12,10,14,LEAVES:0)
Block(-12,11,11,LEAVES:0)
Block(-12,11,12,LEAVES:0)
Block(-12,12,11,LEAVES:0)
Block(-12,12,12,LEAVES:0)
Block(-12,12,14,LEAVES:0)
Block(-12,12,15,LEAVES:0)
Block(-12,12,16,LEAVES:0)
Block(-12,12,17,LEAVES:0)
Block(-12,13,-6,LOG)
Block(-12,13,-5,LOG)
Block(-12,13,10,LEAVES:0)
Block(-12,13,11,LEAVES:0)
Block(-12,13,12,LEAVES:0)
Block(-12,13,15,LEAVES:0)
Block(-12,13,16,LEAVES:0)
Block(-12,13,17,LEAVES:0)
Block(-12,14,-10,LEAVES:0)
Block(-12,14,-9,LEAVES:0)
Block(-12,14,-8,LEAVES:0)
Block(-12,14,-7,LEAVES:0)
Block(-12,14,-6,LEAVES:0)
Block(-12,14,-5,LOG)
Block(-12,14,-4,LOG)
Block(-12,14,11,LEAVES:0)
Block(-12,14,12,LOG)
Block(-12,14,13,LEAVES:0)
Block(-12,14,14,LOG)
Block(-12,14,15,LEAVES:0)
Block(-12,15,-11,LEAVES:0)
Block(-12,15,-10,LEAVES:0)
Block(-12,15,-9,LEAVES:0)
Block(-12,15,-7,LEAVES:0)
Block(-12,15,-6,LEAVES:0)
Block(-12,15,-5,LEAVES:0)
Block(-12,15,-4,LOG)
Block(-12,15,-3,LOG)
Block(-12,15,-2,LOG)
Block(-12,15,-1,LOG)
Block(-12,15,16,LEAVES:0)
Block(-12,16,-11,LEAVES:0)
Block(-12,16,-10,LEAVES:0)
Block(-12,16,-9,LEAVES:0)
Block(-12,16,-8,LEAVES:0)
Block(-12,16,-7,LEAVES:0)
Block(-12,16,-3,LOG)
Block(-12,16,-2,LOG)
Block(-12,16,-1,LOG)
Block(-12,16,0,LOG)
Block(-12,17,-13,LEAVES:0)
Block(-12,17,-8,LEAVES:0)
Block(-12,17,0,LOG)
Block(-12,18,-13,LEAVES:0)
Block(-12,18,-12,LEAVES:0)
Block(-12,18,-9,LEAVES:0)
Block(-12,18,-7,LEAVES:0)
Block(-12,18,-6,LEAVES:0)
Block(-12,19,-11,LEAVES:0)
Block(-12,19,-10,LEAVES:0)
Block(-12,19,-9,LEAVES:0)
Block(-12,19,-4,LEAVES:0)
Block(-12,20,-12,LEAVES:0)
Block(-12,20,-11,LEAVES:0)
Block(-12,20,-10,LEAVES:0)
Block(-12,20,-8,LEAVES:0)
Block(-12,20,-7,LEAVES:0)
Block(-12,20,-5,LEAVES:0)
Block(-12,20,3,LOG)
Block(-12,20,10,LOG)
Block(-12,20,11,LOG)
Block(-12,21,-10,LEAVES:0)
Block(-12,21,2,LOG)
Block(-12,21,3,LOG)
Block(-12,21,10,LOG)
Block(-12,21,11,LOG)
Block(-12,21,12,LEAVES:0)
Block(-12,21,13,LEAVES:0)
Block(-12,22,-10,LEAVES:0)
Block(-12,22,14,LEAVES:0)
Block(-12,23,14,LEAVES:0)
Block(-12,23,15,LEAVES:0)
Block(-12,23,16,LEAVES:0)
Block(-12,24,-4,LEAVES:0)
Block(-12,24,13,LOG)
Block(-12,24,14,LOG)
Block(-12,24,15,LEAVES:0)
Block(-12,24,16,LEAVES:0)
Block(-12,25,-8,LEAVES:0)
Block(-12,25,-7,LEAVES:0)
Block(-12,25,-6,LEAVES:0)
Block(-12,25,3,LEAVES:0)
Block(-12,25,4,LOG)
Block(-12,25,11,LEAVES:0)
Block(-12,25,12,LEAVES:0)
Block(-12,25,13,LEAVES:0)
Block(-12,25,14,LOG)
Block(-12,25,15,LEAVES:0)
Block(-12,25,16,LEAVES:0)
Block(-12,25,17,LEAVES:0)
Block(-12,25,18,LEAVES:0)
Block(-12,26,-8,LEAVES:0)
Block(-12,26,-5,LEAVES:0)
Block(-12,26,-4,LEAVES:0)
Block(-12,26,-3,LEAVES:0)
Block(-12,26,2,LEAVES:0)
Block(-12,26,3,LEAVES:0)
Block(-12,26,4,LEAVES:0)
Block(-12,26,5,LOG)
Block(-12,26,8,LEAVES:0)
Block(-12,26,11,LEAVES:0)
Block(-12,26,12,LEAVES:0)
Block(-12,26,13,LEAVES:0)
Block(-12,26,14,LEAVES:0)
Block(-12,26,15,LEAVES:0)
Block(-12,26,16,LEAVES:0)
Block(-12,26,17,LEAVES:0)
Block(-12,26,18,LEAVES:0)
Block(-12,27,-7,LEAVES:0)
Block(-12,27,-6,LEAVES:0)
Block(-12,27,-5,LEAVES:0)
Block(-12,27,2,LEAVES:0)
Block(-12,27,3,LEAVES:0)
Block(-12,27,4,LEAVES:0)
Block(-12,27,5,LEAVES:0)
Block(-12,27,12,LEAVES:0)
Block(-12,27,14,LEAVES:0)
Block(-12,27,15,LOG)
Block(-12,27,16,LEAVES:0)
Block(-12,27,17,LEAVES:0)
Block(-12,27,18,LEAVES:0)
Block(-12,28,-6,LEAVES:0)
Block(-12,28,-5,LEAVES:0)
Block(-12,28,-4,LEAVES:0)
Block(-12,28,5,LEAVES:0)
Block(-12,28,7,LEAVES:0)
Block(-12,28,13,LEAVES:0)
Block(-12,28,14,LEAVES:0)
Block(-12,28,15,LEAVES:0)
Block(-12,28,18,LEAVES:0)
Block(-12,29,15,LEAVES:0)
Block(-12,29,17,LEAVES:0)
Block(-11,10,14,LEAVES:0)
Block(-11,10,15,LEAVES:0)
Block(-11,11,12,LEAVES:0)
Block(-11,11,14,LEAVES:0)
Block(-11,11,15,LEAVES:0)
Block(-11,11,16,LEAVES:0)
Block(-11,12,12,LEAVES:0)
Block(-11,12,13,LEAVES:0)
Block(-11,12,14,LOG)
Block(-11,12,16,LEAVES:0)
Block(-11,13,-7,LOG)
Block(-11,13,-6,LOG)
Block(-11,13,12,LEAVES:0)
Block(-11,13,13,LEAVES:0)
Block(-11,13,14,LOG)
Block(-11,13,15,LEAVES:0)
Block(-11,14,-11,LEAVES:0)
Block(-11,14,-10,LEAVES:0)
Block(-11,14,-9,LEAVES:0)
Block(-11,14,-8,LEAVES:0)
Block(-11,14,-7,LOG)
Block(-11,14,-2,LOG)
Block(-11,14,-1,LOG)
Block(-11,14,0,LOG)
Block(-11,14,1,LOG)
Block(-11,14,11,LOG)
Block(-11,14,12,LOG)
Block(-11,14,14,LEAVES:0)
Block(-11,14,15,LEAVES:0)
Block(-11,14,16,LEAVES:0)
Block(-11,15,-12,LEAVES:0)
Block(-11,15,-11,LEAVES:0)
Block(-11,15,-10,LEAVES:0)
Block(-11,15,-8,LEAVES:0)
Block(-11,15,-7,LEAVES:0)
Block(-11,15,-2,LOG)
Block(-11,15,-1,LOG)
Block(-11,15,0,LOG)
Block(-11,15,13,LEAVES:0)
Block(-11,15,14,LEAVES:0)
Block(-11,15,15,LEAVES:0)
Block(-11,15,16,LEAVES:0)
Block(-11,16,-13,LEAVES:0)
Block(-11,16,-12,LEAVES:0)
Block(-11,16,-11,LOG)
Block(-11,16,-10,LOG)
Block(-11,16,-8,LEAVES:0)
Block(-11,16,-7,LEAVES:0)
Block(-11,16,-1,LOG)
Block(-11,17,-13,LEAVES:0)
Block(-11,17,-12,LEAVES:0)
Block(-11,17,-11,LEAVES:0)
Block(-11,17,-10,LEAVES:0)
Block(-11,17,9,LOG)
Block(-11,18,-13,LEAVES:0)
Block(-11,18,-9,LEAVES:0)
Block(-11,18,9,LOG)
Block(-11,18,10,LOG)
Block(-11,19,-13,LEAVES:0)
Block(-11,19,-12,LEAVES:0)
Block(-11,19,-11,LEAVES:0)
Block(-11,19,-10,LEAVES:0)
Block(-11,19,10,LOG)
Block(-11,20,-11,LEAVES:0)
Block(-11,20,-10,LEAVES:0)
Block(-11,20,10,LOG)
Block(-11,20,14,LEAVES:0)
Block(-11,21,-11,LEAVES:0)
Block(-11,21,-10,LEAVES:0)
Block(-11,21,-9,LEAVES:0)
Block(-11,21,1,LOG)
Block(-11,21,2,LOG)
Block(-11,21,11,LOG)
Block(-11,21,12,LEAVES:0)
Block(-11,21,14,LEAVES:0)
Block(-11,21,15,LEAVES:0)
Block(-11,22,-11,LEAVES:0)
Block(-11,22,-10,LEAVES:0)
Block(-11,22,-9,LEAVES:0)
Block(-11,22,1,LOG)
Block(-11,22,11,LOG)
Block(-11,22,12,LOG)
Block(-11,22,13,LOG)
Block(-11,22,14,LEAVES:0)
Block(-11,22,15,LEAVES:0)
Block(-11,22,16,LEAVES:0)
Block(-11,23,13,LOG)
Block(-11,23,14,LEAVES:0)
Block(-11,24,3,LOG)
Block(-11,24,11,LEAVES:0)
Block(-11,24,12,LEAVES:0)
Block(-11,24,13,LOG)
Block(-11,24,15,LEAVES:0)
Block(-11,24,16,LEAVES:0)
Block(-11,24,17,LEAVES:0)
Block(-11,24,18,LEAVES:0)
Block(-11,25,-5,LEAVES:0)
Block(-11,25,-4,LEAVES:0)
Block(-11,25,-2,LEAVES:0)
Block(-11,25,2,LEAVES:0)
Block(-11,25,3,LOG)
Block(-11,25,4,LOG)
Block(-11,25,7,LEAVES:0)
Block(-11,25,12,LEAVES:0)
Block(-11,25,13,LEAVES:0)
Block(-11,25,14,LEAVES:0)
Block(-11,25,15,LEAVES:0)
Block(-11,25,16,LEAVES:0)
Block(-11,25,18,LEAVES:0)
Block(-11,25,19,LEAVES:0)
Block(-11,26,-7,LEAVES:0)
Block(-11,26,-6,LEAVES:0)
Block(-11,26,-4,LEAVES:0)
Block(-11,26,-2,LEAVES:0)
Block(-11,26,2,LEAVES:0)
Block(-11,26,3,LEAVES:0)
Block(-11,26,8,LEAVES:0)
Block(-11,26,9,LEAVES:0)
Block(-11,26,12,LEAVES:0)
Block(-11,26,13,LEAVES:0)
Block(-11,26,15,LEAVES:0)
Block(-11,26,16,LEAVES:0)
Block(-11,26,17,LEAVES:0)
Block(-11,26,18,LEAVES:0)
Block(-11,26,19,LEAVES:0)
Block(-11,27,-6,LEAVES:0)
Block(-11,27,-5,LEAVES:0)
Block(-11,27,-4,LEAVES:0)
Block(-11,27,3,LEAVES:0)
Block(-11,27,4,LEAVES:0)
Block(-11,27,5,LEAVES:0)
Block(-11,27,6,LOG)
Block(-11,27,8,LEAVES:0)
Block(-11,27,13,LEAVES:0)
Block(-11,27,16,LEAVES:0)
Block(-11,27,18,LEAVES:0)
Block(-11,28,-5,LEAVES:0)
Block(-11,28,4,LEAVES:0)
Block(-11,28,5,LEAVES:0)
Block(-11,28,8,LEAVES:0)
Block(-11,28,16,LEAVES:0)
Block(-11,28,18,LEAVES:0)
Block(-11,29,6,LEAVES:0)
Block(-11,29,8,LEAVES:0)
Block(-11,29,16,LEAVES:0)
Block(-10,10,14,LEAVES:0)
Block(-10,11,12,LEAVES:0)
Block(-10,11,13,LEAVES:0)
Block(-10,11,14,LEAVES:0)
Block(-10,12,11,LEAVES:0)
Block(-10,12,12,LEAVES:0)
Block(-10,12,13,LEAVES:0)
Block(-10,12,14,LEAVES:0)
Block(-10,12,15,LEAVES:0)
Block(-10,13,2,LOG)
Block(-10,13,11,LEAVES:0)
Block(-10,13,13,LEAVES:0)
Block(-10,13,14,LEAVES:0)
Block(-10,13,15,LEAVES:0)
Block(-10,13,16,LEAVES:0)
Block(-10,14,-12,LEAVES:0)
Block(-10,14,-11,LEAVES:0)
Block(-10,14,-10,LEAVES:0)
Block(-10,14,-9,LEAVES:0)
Block(-10,14,-7,LOG)
Block(-10,14,-1,LOG)
Block(-10,14,0,LOG)
Block(-10,14,1,LOG)
Block(-10,14,11,LOG)
Block(-10,14,16,LEAVES:0)
Block(-10,15,-13,LEAVES:0)
Block(-10,15,-12,LEAVES:0)
Block(-10,15,-11,LEAVES:0)
Block(-10,15,-9,LOG)
Block(-10,15,0,LOG)
Block(-10,15,1,LOG)
Block(-10,15,8,LOG)
Block(-10,15,11,LOG)
Block(-10,15,14,LEAVES:0)
Block(-10,15,15,LEAVES:0)
Block(-10,16,-12,LEAVES:0)
Block(-10,16,-11,LEAVES:0)
Block(-10,16,-10,LOG)
Block(-10,16,-9,LOG)
Block(-10,16,-7,LEAVES:0)
Block(-10,16,8,LOG)
Block(-10,16,9,LOG)
Block(-10,16,14,LEAVES:0)
Block(-10,17,-13,LEAVES:0)
Block(-10,17,-12,LEAVES:0)
Block(-10,17,-11,LEAVES:0)
Block(-10,17,-9,LEAVES:0)
Block(-10,17,-5,LEAVES:0)
Block(-10,17,8,LOG)
Block(-10,17,9,LOG)
Block(-10,18,-11,LEAVES:0)
Block(-10,18,-10,LEAVES:0)
Block(-10,18,-9,LEAVES:0)
Block(-10,18,-6,LEAVES:0)
Block(-10,18,9,LOG)
Block(-10,19,-12,LEAVES:0)
Block(-10,19,-11,LEAVES:0)
Block(-10,19,-10,LEAVES:0)
Block(-10,19,-9,LEAVES:0)
Block(-10,20,-11,LEAVES:0)
Block(-10,20,-10,LEAVES:0)
Block(-10,20,-9,LEAVES:0)
Block(-10,20,-7,LEAVES:0)
Block(-10,20,13,LEAVES:0)
Block(-10,21,-11,LEAVES:0)
Block(-10,21,-10,LEAVES:0)
Block(-10,21,-9,LEAVES:0)
Block(-10,21,13,LEAVES:0)
Block(-10,21,14,LEAVES:0)
Block(-10,21,15,LEAVES:0)
Block(-10,21,16,LEAVES:0)
Block(-10,22,-10,LEAVES:0)
Block(-10,22,-9,LEAVES:0)
Block(-10,22,-8,LEAVES:0)
Block(-10,22,0,LOG)
Block(-10,22,1,LOG)
Block(-10,22,2,LEAVES:0)
Block(-10,22,15,LEAVES:0)
Block(-10,23,-10,LEAVES:0)
Block(-10,23,-9,LEAVES:0)
Block(-10,23,-8,LEAVES:0)
Block(-10,23,-7,LEAVES:0)
Block(-10,23,-6,LEAVES:0)
Block(-10,23,0,LOG)
Block(-10,23,1,LOG)
Block(-10,23,2,LOG)
Block(-10,23,11,LOG)
Block(-10,23,15,LEAVES:0)
Block(-10,23,16,LEAVES:0)
Block(-10,24,-3,LEAVES:0)
Block(-10,24,2,LOG)
Block(-10,24,3,LOG)
Block(-10,24,8,LEAVES:0)
Block(-10,24,11,LEAVES:0)
Block(-10,24,12,LEAVES:0)
Block(-10,24,15,LEAVES:0)
Block(-10,24,18,LEAVES:0)
Block(-10,25,-4,LEAVES:0)
Block(-10,25,-3,LEAVES:0)
Block(-10,25,-1,LEAVES:0)
Block(-10,25,2,LEAVES:0)
Block(-10,25,3,LEAVES:0)
Block(-10,25,4,LEAVES:0)
Block(-10,25,7,LEAVES:0)
Block(-10,25,8,LEAVES:0)
Block(-10,25,15,LEAVES:0)
Block(-10,25,16,LEAVES:0)
Block(-10,25,17,LEAVES:0)
Block(-10,25,18,LEAVES:0)
Block(-10,25,19,LEAVES:0)
Block(-10,26,-4,LEAVES:0)
Block(-10,26,-3,LEAVES:0)
Block(-10,26,2,LEAVES:0)
Block(-10,26,3,LEAVES:0)
Block(-10,26,7,LEAVES:0)
Block(-10,26,16,LEAVES:0)
Block(-10,26,17,LEAVES:0)
Block(-10,26,18,LEAVES:0)
Block(-10,26,19,LEAVES:0)
Block(-10,27,-7,LEAVES:0)
Block(-10,27,-6,LEAVES:0)
Block(-10,27,-5,LEAVES:0)
Block(-10,27,-4,LEAVES:0)
Block(-10,27,-3,LEAVES:0)
Block(-10,27,-2,LEAVES:0)
Block(-10,27,0,LEAVES:0)
Block(-10,27,2,LEAVES:0)
Block(-10,27,3,LEAVES:0)
Block(-10,27,7,LEAVES:0)
Block(-10,27,8,LEAVES:0)
Block(-10,27,9,LEAVES:0)
Block(-10,27,13,LEAVES:0)
Block(-10,27,14,LEAVES:0)
Block(-10,27,15,LEAVES:0)
Block(-10,27,17,LEAVES:0)
Block(-10,27,18,LEAVES:0)
Block(-10,28,-5,LEAVES:0)
Block(-10,28,-4,LEAVES:0)
Block(-10,28,3,LEAVES:0)
Block(-10,28,4,LEAVES:0)
Block(-10,28,5,LEAVES:0)
Block(-10,28,6,LEAVES:0)
Block(-10,28,7,LEAVES:0)
Block(-10,29,4,LEAVES:0)
Block(-10,29,5,LEAVES:0)
Block(-10,29,6,LEAVES:0)
Block(-9,10,14,LEAVES:0)
Block(-9,11,14,LEAVES:0)
Block(-9,12,2,LOG)
Block(-9,12,3,LOG)
Block(-9,12,12,LEAVES:0)
Block(-9,12,13,LEAVES:0)
Block(-9,12,14,LEAVES:0)
Block(-9,12,15,LEAVES:0)
Block(-9,13,0,LOG)
Block(-9,13,1,LOG)
Block(-9,13,2,LOG)
Block(-9,13,13,LEAVES:0)
Block(-9,13,14,LEAVES:0)
Block(-9,13,15,LEAVES:0)
Block(-9,14,-13,LEAVES:0)
Block(-9,14,-12,LEAVES:0)
Block(-9,14,-11,LEAVES:0)
Block(-9,14,-10,LEAVES:0)
Block(-9,14,-9,LEAVES:0)
Block(-9,14,-7,LOG)
Block(-9,14,-6,LEAVES:0)
Block(-9,14,0,LOG)
Block(-9,14,1,LOG)
Block(-9,14,2,LOG)
Block(-9,14,7,LOG)
Block(-9,14,10,LOG)
Block(-9,14,16,LEAVES:0)
Block(-9,15,-12,LEAVES:0)
Block(-9,15,-9,LOG)
Block(-9,15,-8,LOG)
Block(-9,15,-7,LOG)
Block(-9,15,-6,LEAVES:0)
Block(-9,15,-5,LEAVES:0)
Block(-9,15,7,LOG)
Block(-9,15,8,LOG)
Block(-9,15,9,LOG)
Block(-9,15,10,LOG)
Block(-9,15,11,LOG)
Block(-9,15,14,LEAVES:0)
Block(-9,15,16,LEAVES:0)
Block(-9,15,17,LEAVES:0)
Block(-9,16,-13,LEAVES:0)
Block(-9,16,-12,LEAVES:0)
Block(-9,16,-11,LEAVES:0)
Block(-9,16,-10,LEAVES:0)
Block(-9,16,-6,LEAVES:0)
Block(-9,16,-5,LEAVES:0)
Block(-9,16,9,LOG)
Block(-9,16,14,LEAVES:0)
Block(-9,16,15,LEAVES:0)
Block(-9,16,17,LEAVES:0)
Block(-9,17,-12,LEAVES:0)
Block(-9,17,-11,LEAVES:0)
Block(-9,17,-10,LEAVES:0)
Block(-9,17,-9,LEAVES:0)
Block(-9,17,-8,LEAVES:0)
Block(-9,17,-5,LEAVES:0)
Block(-9,17,-4,LEAVES:0)
Block(-9,18,-12,LEAVES:0)
Block(-9,18,-11,LEAVES:0)
Block(-9,18,-8,LEAVES:0)
Block(-9,18,-6,LEAVES:0)
Block(-9,18,-5,LEAVES:0)
Block(-9,19,-12,LEAVES:0)
Block(-9,19,-11,LEAVES:0)
Block(-9,19,-9,LEAVES:0)
Block(-9,19,-5,LEAVES:0)
Block(-9,20,-11,LEAVES:0)
Block(-9,20,-10,LEAVES:0)
Block(-9,20,-9,LEAVES:0)
Block(-9,20,-8,LEAVES:0)
Block(-9,20,-7,LEAVES:0)
Block(-9,20,15,LEAVES:0)
Block(-9,20,16,LEAVES:0)
Block(-9,20,17,LEAVES:0)
Block(-9,21,-11,LEAVES:0)
Block(-9,21,-10,LEAVES:0)
Block(-9,21,-9,LEAVES:0)
Block(-9,21,-8,LEAVES:0)
Block(-9,21,-7,LEAVES:0)
Block(-9,21,-6,LEAVES:0)
Block(-9,21,15,LEAVES:0)
Block(-9,22,-10,LEAVES:0)
Block(-9,22,-9,LEAVES:0)
Block(-9,22,-8,LEAVES:0)
Block(-9,22,-5,LEAVES:0)
Block(-9,22,-4,LEAVES:0)
Block(-9,22,2,LEAVES:0)
Block(-9,22,3,LEAVES:0)
Block(-9,22,15,LEAVES:0)
Block(-9,22,16,LEAVES:0)
Block(-9,22,18,LEAVES:0)
Block(-9,23,-9,LEAVES:0)
Block(-9,23,-8,LEAVES:0)
Block(-9,23,-1,LOG)
Block(-9,23,0,LOG)
Block(-9,23,2,LEAVES:0)
Block(-9,23,6,LEAVES:0)
Block(-9,23,7,LEAVES:0)
Block(-9,23,8,LEAVES:0)
Block(-9,23,11,LOG)
Block(-9,23,16,LEAVES:0)
Block(-9,23,17,LEAVES:0)
Block(-9,23,18,LEAVES:0)
Block(-9,24,-9,LEAVES:0)
Block(-9,24,-8,LEAVES:0)
Block(-9,24,-2,LOG)
Block(-9,24,-1,LOG)
Block(-9,24,7,LEAVES:0)
Block(-9,24,8,LEAVES:0)
Block(-9,24,9,LEAVES:0)
Block(-9,24,11,LEAVES:0)
Block(-9,24,15,LEAVES:0)
Block(-9,24,17,LEAVES:0)
Block(-9,24,18,LEAVES:0)
Block(-9,25,-7,LEAVES:0)
Block(-9,25,-5,LEAVES:0)
Block(-9,25,-4,LEAVES:0)
Block(-9,25,-3,LOG)
Block(-9,25,-2,LOG)
Block(-9,25,6,LEAVES:0)
Block(-9,25,7,LEAVES:0)
Block(-9,25,8,LEAVES:0)
Block(-9,25,9,LEAVES:0)
Block(-9,25,14,LEAVES:0)
Block(-9,26,-6,LEAVES:0)
Block(-9,26,-5,LEAVES:0)
Block(-9,26,-4,LEAVES:0)
Block(-9,26,-3,LEAVES:0)
Block(-9,26,-2,LEAVES:0)
Block(-9,26,3,LEAVES:0)
Block(-9,26,6,LEAVES:0)
Block(-9,26,9,LEAVES:0)
Block(-9,26,14,LEAVES:0)
Block(-9,26,17,LEAVES:0)
Block(-9,26,18,LEAVES:0)
Block(-9,26,19,LEAVES:0)
Block(-9,27,-6,LEAVES:0)
Block(-9,27,-5,LEAVES:0)
Block(-9,27,-4,LEAVES:0)
Block(-9,27,-3,LEAVES:0)
Block(-9,27,-2,LEAVES:0)
Block(-9,27,-1,LEAVES:0)
Block(-9,27,0,LEAVES:0)
Block(-9,27,1,LEAVES:0)
Block(-9,27,2,LEAVES:0)
Block(-9,27,3,LEAVES:0)
Block(-9,27,8,LEAVES:0)
Block(-9,27,15,LEAVES:0)
Block(-9,27,17,LEAVES:0)
Block(-9,28,-5,LEAVES:0)
Block(-9,28,2,LEAVES:0)
Block(-9,28,3,LEAVES:0)
Block(-9,28,4,LEAVES:0)
Block(-9,28,5,LEAVES:0)
Block(-9,28,6,LEAVES:0)
Block(-9,28,7,LEAVES:0)
Block(-9,28,8,LEAVES:0)
Block(-9,28,15,LEAVES:0)
Block(-9,29,7,LEAVES:0)
Block(-8,11,2,LOG)
Block(-8,11,3,LOG)
Block(-8,11,4,LOG)
Block(-8,11,5,LOG)
Block(-8,11,14,LEAVES:0)
Block(-8,12,2,LOG)
Block(-8,12,3,LOG)
Block(-8,12,5,LOG)
Block(-8,12,6,LOG)
Block(-8,12,14,LEAVES:0)
Block(-8,12,15,LEAVES:0)
Block(-8,13,1,LOG)
Block(-8,13,2,LOG)
Block(-8,13,3,LOG)
Block(-8,13,6,LOG)
Block(-8,13,14,LEAVES:0)
Block(-8,14,-9,LEAVES:0)
Block(-8,14,-6,LEAVES:0)
Block(-8,14,7,LOG)
Block(-8,14,13,LEAVES:0)
Block(-8,14,15,LEAVES:0)
Block(-8,14,16,LEAVES:0)
Block(-8,14,17,LEAVES:0)
Block(-8,15,-12,LEAVES:0)
Block(-8,15,-11,LEAVES:0)
Block(-8,15,-10,LEAVES:0)
Block(-8,15,-9,LEAVES:0)
Block(-8,15,-7,LOG)
Block(-8,15,-6,LEAVES:0)
Block(-8,15,-5,LEAVES:0)
Block(-8,15,14,LEAVES:0)
Block(-8,15,15,LEAVES:0)
Block(-8,15,16,LEAVES:0)
Block(-8,15,17,LEAVES:0)
Block(-8,16,-12,LEAVES:0)
Block(-8,16,-11,LEAVES:0)
Block(-8,16,-10,LEAVES:0)
Block(-8,16,-9,LEAVES:0)
Block(-8,16,-7,LOG)
Block(-8,16,-6,LOG)
Block(-8,16,-5,LEAVES:0)
Block(-8,16,-4,LEAVES:0)
Block(-8,16,15,LEAVES:0)
Block(-8,16,16,LEAVES:0)
Block(-8,16,17,LEAVES:0)
Block(-8,17,-12,LEAVES:0)
Block(-8,17,-11,LEAVES:0)
Block(-8,17,-10,LEAVES:0)
Block(-8,17,-6,LEAVES:0)
Block(-8,17,-4,LEAVES:0)
Block(-8,17,13,LEAVES:0)
Block(-8,17,15,LEAVES:0)
Block(-8,17,16,LEAVES:0)
Block(-8,17,17,LEAVES:0)
Block(-8,18,-12,LEAVES:0)
Block(-8,18,-11,LEAVES:0)
Block(-8,18,-10,LEAVES:0)
Block(-8,18,-9,LEAVES:0)
Block(-8,18,-8,LEAVES:0)
Block(-8,18,-5,LEAVES:0)
Block(-8,19,-11,LEAVES:0)
Block(-8,19,-8,LEAVES:0)
Block(-8,19,-7,LEAVES:0)
Block(-8,19,15,LEAVES:0)
Block(-8,19,16,LEAVES:0)
Block(-8,19,17,LEAVES:0)
Block(-8,20,-11,LEAVES:0)
Block(-8,20,-10,LEAVES:0)
Block(-8,20,-9,LEAVES:0)
Block(-8,20,-8,LEAVES:0)
Block(-8,20,-6,LEAVES:0)
Block(-8,20,17,LEAVES:0)
Block(-8,20,18,LEAVES:0)
Block(-8,21,-10,LEAVES:0)
Block(-8,21,-9,LEAVES:0)
Block(-8,21,-4,LEAVES:0)
Block(-8,21,2,LEAVES:0)
Block(-8,21,14,LEAVES:0)
Block(-8,21,15,LEAVES:0)
Block(-8,21,17,LEAVES:0)
Block(-8,22,-10,LEAVES:0)
Block(-8,22,-9,LEAVES:0)
Block(-8,22,-8,LEAVES:0)
Block(-8,22,-5,LEAVES:0)
Block(-8,22,-4,LEAVES:0)
Block(-8,22,0,LEAVES:0)
Block(-8,22,2,LEAVES:0)
Block(-8,22,6,LEAVES:0)
Block(-8,22,7,LEAVES:0)
Block(-8,22,9,LEAVES:0)
Block(-8,22,10,LEAVES:0)
Block(-8,22,11,LOG)
Block(-8,22,13,LEAVES:0)
Block(-8,22,14,LEAVES:0)
Block(-8,22,15,LEAVES:0)
Block(-8,22,16,LEAVES:0)
Block(-8,22,18,LEAVES:0)
Block(-8,23,-10,LEAVES:0)
Block(-8,23,-9,LEAVES:0)
Block(-8,23,-5,LEAVES:0)
Block(-8,23,2,LEAVES:0)
Block(-8,23,3,LEAVES:0)
Block(-8,23,6,LEAVES:0)
Block(-8,23,7,LEAVES:0)
Block(-8,23,8,LEAVES:0)
Block(-8,23,9,LEAVES:0)
Block(-8,23,10,LEAVES:0)
Block(-8,23,11,LEAVES:0)
Block(-8,23,12,LEAVES:0)
Block(-8,23,14,LEAVES:0)
Block(-8,23,15,LEAVES:0)
Block(-8,23,16,LEAVES:0)
Block(-8,23,17,LEAVES:0)
Block(-8,24,-9,LEAVES:0)
Block(-8,24,-8,LEAVES:0)
Block(-8,24,-7,LEAVES:0)
Block(-8,24,-2,LEAVES:0)
Block(-8,24,-1,LEAVES:0)
Block(-8,24,2,LEAVES:0)
Block(-8,24,3,LEAVES:0)
Block(-8,24,7,LEAVES:0)
Block(-8,24,8,LEAVES:0)
Block(-8,24,9,LEAVES:0)
Block(-8,24,11,LEAVES:0)
Block(-8,24,15,LEAVES:0)
Block(-8,24,16,LEAVES:0)
Block(-8,24,17,LEAVES:0)
Block(-8,24,18,LEAVES:0)
Block(-8,25,-8,LEAVES:0)
Block(-8,25,-7,LEAVES:0)
Block(-8,25,-5,LOG)
Block(-8,25,-4,LOG)
Block(-8,25,-3,LOG)
Block(-8,25,-2,LEAVES:0)
Block(-8,25,3,LEAVES:0)
Block(-8,25,7,LEAVES:0)
Block(-8,25,8,LEAVES:0)
Block(-8,25,11,LEAVES:0)
Block(-8,25,14,LEAVES:0)
Block(-8,25,15,LEAVES:0)
Block(-8,25,17,LEAVES:0)
Block(-8,25,18,LEAVES:0)
Block(-8,26,-4,LEAVES:0)
Block(-8,26,-3,LEAVES:0)
Block(-8,26,-2,LEAVES:0)
Block(-8,26,7,LEAVES:0)
Block(-8,26,8,LEAVES:0)
Block(-8,26,13,LEAVES:0)
Block(-8,26,14,LEAVES:0)
Block(-8,26,15,LEAVES:0)
Block(-8,26,16,LEAVES:0)
Block(-8,27,-2,LEAVES:0)
Block(-8,27,-1,LEAVES:0)
Block(-8,27,0,LEAVES:0)
Block(-8,27,1,LEAVES:0)
Block(-8,27,6,LEAVES:0)
Block(-8,27,7,LEAVES:0)
Block(-8,27,8,LEAVES:0)
Block(-8,27,9,LEAVES:0)
Block(-8,27,15,LEAVES:0)
Block(-8,27,16,LEAVES:0)
Block(-8,28,-6,LEAVES:0)
Block(-8,28,-5,LEAVES:0)
Block(-8,28,-2,LEAVES:0)
Block(-8,28,0,LEAVES:0)
Block(-8,28,4,LEAVES:0)
Block(-8,28,5,LEAVES:0)
Block(-8,28,6,LEAVES:0)
Block(-8,28,7,LEAVES:0)
Block(-8,28,16,LEAVES:0)
Block(-8,29,-1,LEAVES:0)
Block(-8,29,4,LEAVES:0)
Block(-8,29,5,LEAVES:0)
Block(-7,9,3,LOG)
Block(-7,10,2,LOG)
Block(-7,10,3,LOG)
Block(-7,10,4,LOG)
Block(-7,10,5,LOG)
Block(-7,11,1,LOG)
Block(-7,11,2,LOG)
Block(-7,11,4,LOG)
Block(-7,11,5,LOG)
Block(-7,11,6,LOG)
Block(-7,12,2,LOG)
Block(-7,12,3,LOG)
Block(-7,12,4,LOG)
Block(-7,12,5,LOG)
Block(-7,12,6,LOG)
Block(-7,12,7,LOG)
Block(-7,12,13,LEAVES:0)
Block(-7,12,14,LEAVES:0)
Block(-7,12,16,LEAVES:0)
Block(-7,13,3,LOG)
Block(-7,13,6,LOG)
Block(-7,13,7,LOG)
Block(-7,13,14,LEAVES:0)
Block(-7,13,15,LEAVES:0)
Block(-7,13,16,LEAVES:0)
Block(-7,14,-5,LEAVES:0)
Block(-7,14,7,LOG)
Block(-7,14,16,LEAVES:0)
Block(-7,14,17,LEAVES:0)
Block(-7,15,-12,LEAVES:0)
Block(-7,15,-9,LEAVES:0)
Block(-7,15,-6,LEAVES:0)
Block(-7,15,-5,LEAVES:0)
Block(-7,15,13,LEAVES:0)
Block(-7,15,15,LEAVES:0)
Block(-7,15,17,LEAVES:0)
Block(-7,16,-11,LEAVES:0)
Block(-7,16,-10,LEAVES:0)
Block(-7,16,-8,LEAVES:0)
Block(-7,16,-6,LOG)
Block(-7,16,-5,LOG)
Block(-7,16,-4,LEAVES:0)
Block(-7,16,-3,LEAVES:0)
Block(-7,16,14,LEAVES:0)
Block(-7,16,15,LEAVES:0)
Block(-7,16,17,LEAVES:0)
Block(-7,16,18,LEAVES:0)
Block(-7,17,-11,LEAVES:0)
Block(-7,17,-10,LEAVES:0)
Block(-7,17,-9,LEAVES:0)
Block(-7,17,-8,LEAVES:0)
Block(-7,17,-7,LEAVES:0)
Block(-7,17,-5,LEAVES:0)
Block(-7,17,-4,LEAVES:0)
Block(-7,17,13,LEAVES:0)
Block(-7,17,14,LEAVES:0)
Block(-7,17,16,LEAVES:0)
Block(-7,18,-11,LEAVES:0)
Block(-7,18,-10,LEAVES:0)
Block(-7,18,-9,LEAVES:0)
Block(-7,18,-8,LEAVES:0)
Block(-7,18,-7,LEAVES:0)
Block(-7,18,-6,LEAVES:0)
Block(-7,18,15,LEAVES:0)
Block(-7,18,16,LEAVES:0)
Block(-7,19,-10,LEAVES:0)
Block(-7,19,-9,LEAVES:0)
Block(-7,19,-8,LEAVES:0)
Block(-7,19,-7,LEAVES:0)
Block(-7,19,-6,LEAVES:0)
Block(-7,19,13,LEAVES:0)
Block(-7,19,16,LEAVES:0)
Block(-7,19,17,LEAVES:0)
Block(-7,19,18,LEAVES:0)
Block(-7,20,-10,LEAVES:0)
Block(-7,20,-8,LEAVES:0)
Block(-7,20,-7,LEAVES:0)
Block(-7,20,-6,LEAVES:0)
Block(-7,20,17,LEAVES:0)
Block(-7,20,18,LEAVES:0)
Block(-7,21,-11,LEAVES:0)
Block(-7,21,-10,LEAVES:0)
Block(-7,21,-9,LEAVES:0)
Block(-7,21,-8,LEAVES:0)
Block(-7,21,-7,LEAVES:0)
Block(-7,21,-6,LEAVES:0)
Block(-7,21,-4,LEAVES:0)
Block(-7,21,1,LEAVES:0)
Block(-7,21,2,LEAVES:0)
Block(-7,21,10,LEAVES:0)
Block(-7,21,11,LEAVES:0)
Block(-7,21,12,LOG)
Block(-7,21,13,LEAVES:0)
Block(-7,21,14,LEAVES:0)
Block(-7,21,15,LEAVES:0)
Block(-7,21,16,LEAVES:0)
Block(-7,21,17,LEAVES:0)
Block(-7,21,18,LEAVES:0)
Block(-7,22,-10,LEAVES:0)
Block(-7,22,-9,LEAVES:0)
Block(-7,22,-8,LEAVES:0)
Block(-7,22,-7,LEAVES:0)
Block(-7,22,0,LEAVES:0)
Block(-7,22,1,LEAVES:0)
Block(-7,22,2,LEAVES:0)
Block(-7,22,3,LEAVES:0)
Block(-7,22,7,LEAVES:0)
Block(-7,22,8,LEAVES:0)
Block(-7,22,10,LEAVES:0)
Block(-7,22,11,LEAVES:0)
Block(-7,22,13,LEAVES:0)
Block(-7,22,15,LEAVES:0)
Block(-7,22,16,LEAVES:0)
Block(-7,22,17,LEAVES:0)
Block(-7,23,-9,LEAVES:0)
Block(-7,23,-8,LEAVES:0)
Block(-7,23,-5,LEAVES:0)
Block(-7,23,-4,LEAVES:0)
Block(-7,23,-3,LEAVES:0)
Block(-7,23,-2,LEAVES:0)
Block(-7,23,-1,LEAVES:0)
Block(-7,23,0,LEAVES:0)
Block(-7,23,1,LEAVES:0)
Block(-7,23,2,LEAVES:0)
Block(-7,23,3,LEAVES:0)
Block(-7,23,6,LEAVES:0)
Block(-7,23,9,LEAVES:0)
Block(-7,23,10,LEAVES:0)
Block(-7,23,11,LEAVES:0)
Block(-7,23,12,LEAVES:0)
Block(-7,23,15,LEAVES:0)
Block(-7,23,16,LEAVES:0)
Block(-7,23,17,LEAVES:0)
Block(-7,24,-9,LEAVES:0)
Block(-7,24,-8,LEAVES:0)
Block(-7,24,-6,LEAVES:0)
Block(-7,24,-5,LEAVES:0)
Block(-7,24,-2,LEAVES:0)
Block(-7,24,1,LEAVES:0)
Block(-7,24,8,LEAVES:0)
Block(-7,24,9,LEAVES:0)
Block(-7,24,11,LEAVES:0)
Block(-7,24,12,LEAVES:0)
Block(-7,24,16,LEAVES:0)
Block(-7,25,-8,LEAVES:0)
Block(-7,25,-7,LEAVES:0)
Block(-7,25,-6,LEAVES:0)
Block(-7,25,-5,LOG)
Block(-7,25,-4,LEAVES:0)
Block(-7,25,7,LEAVES:0)
Block(-7,25,8,LOG)
Block(-7,25,12,LEAVES:0)
Block(-7,25,14,LEAVES:0)
Block(-7,25,17,LEAVES:0)
Block(-7,26,-6,LEAVES:0)
Block(-7,26,-5,LEAVES:0)
Block(-7,26,-4,LEAVES:0)
Block(-7,26,-3,LOG)
Block(-7,26,-2,LOG)
Block(-7,26,7,LEAVES:0)
Block(-7,26,13,LEAVES:0)
Block(-7,26,14,LEAVES:0)
Block(-7,26,15,LEAVES:0)
Block(-7,27,-5,LEAVES:0)
Block(-7,27,-4,LEAVES:0)
Block(-7,27,-3,LEAVES:0)
Block(-7,27,-1,LEAVES:0)
Block(-7,27,0,LEAVES:0)
Block(-7,27,1,LEAVES:0)
Block(-7,27,2,LEAVES:0)
Block(-7,27,5,LEAVES:0)
Block(-7,27,6,LEAVES:0)
Block(-7,27,7,LEAVES:0)
Block(-7,28,-4,LEAVES:0)
Block(-7,28,-3,LEAVES:0)
Block(-7,28,-2,LEAVES:0)
Block(-7,28,-1,LEAVES:0)
Block(-7,28,0,LEAVES:0)
Block(-7,28,1,LEAVES:0)
Block(-7,28,3,LEAVES:0)
Block(-7,28,4,LEAVES:0)
Block(-7,28,5,LEAVES:0)
Block(-7,28,6,LEAVES:0)
Block(-7,28,7,LEAVES:0)
Block(-7,28,8,LEAVES:0)
Block(-7,29,-2,LEAVES:0)
Block(-7,29,-1,LEAVES:0)
Block(-7,29,0,LEAVES:0)
Block(-6,-4,-5,LOG)
Block(-6,-4,-4,LOG)
Block(-6,-2,3,LOG)
Block(-6,6,3,LOG)
Block(-6,7,4,LOG)
Block(-6,8,3,LOG)
Block(-6,8,4,LOG)
Block(-6,9,3,LOG)
Block(-6,9,4,LOG)
Block(-6,9,5,LOG)
Block(-6,10,3,LOG)
Block(-6,10,4,LOG)
Block(-6,10,5,LOG)
Block(-6,11,3,LOG)
Block(-6,11,4,LOG)
Block(-6,11,5,LOG)
Block(-6,12,3,LOG)
Block(-6,12,4,LOG)
Block(-6,12,5,LOG)
Block(-6,12,6,LOG)
Block(-6,12,7,LOG)
Block(-6,12,14,LEAVES:0)
Block(-6,12,15,LEAVES:0)
Block(-6,13,6,LOG)
Block(-6,13,7,LOG)
Block(-6,13,14,LEAVES:0)
Block(-6,13,15,LEAVES:0)
Block(-6,13,16,LEAVES:0)
Block(-6,14,-5,LEAVES:0)
Block(-6,14,7,LOG)
Block(-6,14,8,LOG)
Block(-6,14,13,LEAVES:0)
Block(-6,14,16,LEAVES:0)
Block(-6,15,-5,LEAVES:0)
Block(-6,15,-4,LEAVES:0)
Block(-6,15,15,LEAVES:0)
Block(-6,15,16,LEAVES:0)
Block(-6,15,17,LEAVES:0)
Block(-6,15,18,LEAVES:0)
Block(-6,16,-10,LEAVES:0)
Block(-6,16,-8,LEAVES:0)
Block(-6,16,-7,LEAVES:0)
Block(-6,16,-5,LEAVES:0)
Block(-6,16,-4,LEAVES:0)
Block(-6,16,13,LEAVES:0)
Block(-6,16,14,LEAVES:0)
Block(-6,16,15,LOG)
Block(-6,16,16,LOG)
Block(-6,16,17,LEAVES:0)
Block(-6,16,18,LEAVES:0)
Block(-6,17,-10,LEAVES:0)
Block(-6,17,-9,LEAVES:0)
Block(-6,17,-8,LEAVES:0)
Block(-6,17,-7,LEAVES:0)
Block(-6,17,-6,LEAVES:0)
Block(-6,17,-5,LEAVES:0)
Block(-6,17,-4,LEAVES:0)
Block(-6,17,13,LEAVES:0)
Block(-6,17,16,LEAVES:0)
Block(-6,17,17,LEAVES:0)
Block(-6,17,18,LEAVES:0)
Block(-6,18,-9,LEAVES:0)
Block(-6,18,-7,LEAVES:0)
Block(-6,18,-6,LEAVES:0)
Block(-6,18,-5,LEAVES:0)
Block(-6,18,12,LEAVES:0)
Block(-6,18,16,LEAVES:0)
Block(-6,18,17,LEAVES:0)
Block(-6,18,18,LEAVES:0)
Block(-6,19,-9,LEAVES:0)
Block(-6,19,-8,LEAVES:0)
Block(-6,19,-5,LEAVES:0)
Block(-6,19,11,LEAVES:0)
Block(-6,19,14,LEAVES:0)
Block(-6,19,16,LEAVES:0)
Block(-6,20,-10,LEAVES:0)
Block(-6,20,-9,LEAVES:0)
Block(-6,20,-8,LEAVES:0)
Block(-6,20,-7,LEAVES:0)
Block(-6,20,-6,LEAVES:0)
Block(-6,20,-5,LEAVES:0)
Block(-6,20,7,LOG)
Block(-6,20,8,LOG)
Block(-6,20,17,LEAVES:0)
Block(-6,20,18,LEAVES:0)
Block(-6,21,-9,LEAVES:0)
Block(-6,21,-8,LEAVES:0)
Block(-6,21,-6,LEAVES:0)
Block(-6,21,-5,LEAVES:0)
Block(-6,21,6,LOG)
Block(-6,21,7,LOG)
Block(-6,21,10,LEAVES:0)
Block(-6,21,12,LOG)
Block(-6,21,13,LEAVES:0)
Block(-6,21,15,LEAVES:0)
Block(-6,21,16,LEAVES:0)
Block(-6,21,17,LEAVES:0)
Block(-6,22,-9,LEAVES:0)
Block(-6,22,-8,LEAVES:0)
Block(-6,22,-7,LEAVES:0)
Block(-6,22,-5,LEAVES:0)
Block(-6,22,-4,LEAVES:0)
Block(-6,22,-3,LEAVES:0)
Block(-6,22,0,LEAVES:0)
Block(-6,22,1,LEAVES:0)
Block(-6,22,2,LEAVES:0)
Block(-6,22,4,LOG)
Block(-6,22,5,LOG)
Block(-6,22,6,LOG)
Block(-6,22,11,LEAVES:0)
Block(-6,22,12,LEAVES:0)
Block(-6,22,13,LEAVES:0)
Block(-6,22,16,LEAVES:0)
Block(-6,22,17,LEAVES:0)
Block(-6,22,18,LEAVES:0)
Block(-6,23,-8,LEAVES:0)
Block(-6,23,-7,LEAVES:0)
Block(-6,23,-4,LEAVES:0)
Block(-6,23,0,LEAVES:0)
Block(-6,23,1,LEAVES:0)
Block(-6,23,2,LEAVES:0)
Block(-6,23,3,LEAVES:0)
Block(-6,23,4,LOG)
Block(-6,23,5,LEAVES:0)
Block(-6,23,6,LOG)
Block(-6,23,8,LEAVES:0)
Block(-6,23,9,LEAVES:0)
Block(-6,23,10,LEAVES:0)
Block(-6,23,11,LEAVES:0)
Block(-6,23,12,LEAVES:0)
Block(-6,23,13,LEAVES:0)
Block(-6,23,14,LEAVES:0)
Block(-6,23,16,LEAVES:0)
Block(-6,24,-8,LEAVES:0)
Block(-6,24,-5,LEAVES:0)
Block(-6,24,0,LEAVES:0)
Block(-6,24,2,LEAVES:0)
Block(-6,24,7,LOG)
Block(-6,24,8,LOG)
Block(-6,24,9,LEAVES:0)
Block(-6,24,12,LEAVES:0)
Block(-6,24,14,LEAVES:0)
Block(-6,24,16,LEAVES:0)
Block(-6,24,17,LEAVES:0)
Block(-6,25,-8,LEAVES:0)
Block(-6,25,-7,LEAVES:0)
Block(-6,25,-5,LEAVES:0)
Block(-6,25,-4,LEAVES:0)
Block(-6,25,-1,LEAVES:0)
Block(-6,25,0,LEAVES:0)
Block(-6,25,1,LEAVES:0)
Block(-6,25,7,LEAVES:0)
Block(-6,25,8,LEAVES:0)
Block(-6,25,12,LEAVES:0)
Block(-6,25,13,LEAVES:0)
Block(-6,25,14,LEAVES:0)
Block(-6,25,16,LEAVES:0)
Block(-6,25,17,LEAVES:0)
Block(-6,26,-5,LEAVES:0)
Block(-6,26,-4,LEAVES:0)
Block(-6,26,3,LEAVES:0)
Block(-6,26,5,LEAVES:0)
Block(-6,26,6,LEAVES:0)
Block(-6,26,8,LEAVES:0)
Block(-6,26,13,LEAVES:0)
Block(-6,27,-7,LEAVES:0)
Block(-6,27,-6,LEAVES:0)
Block(-6,27,-5,LEAVES:0)
Block(-6,27,-4,LEAVES:0)
Block(-6,27,-3,LEAVES:0)
Block(-6,27,-2,LOG)
Block(-6,27,1,LEAVES:0)
Block(-6,27,2,LEAVES:0)
Block(-6,28,-4,LEAVES:0)
Block(-6,28,-2,LEAVES:0)
Block(-6,28,-1,LOG)
Block(-6,28,0,LEAVES:0)
Block(-6,28,8,LEAVES:0)
Block(-6,29,-1,LEAVES:0)
Block(-5,-4,-4,LOG)
Block(-5,-4,-3,LOG)
Block(-5,-4,-2,LOG)
Block(-5,-3,-2,LOG)
Block(-5,-3,3,LOG)
Block(-5,-2,3,LOG)
Block(-5,5,4,LOG)
Block(-5,6,2,LOG)
Block(-5,6,3,LOG)
Block(-5,6,4,LOG)
Block(-5,7,2,LOG)
Block(-5,7,3,LOG)
Block(-5,7,4,LOG)
Block(-5,8,2,LOG)
Block(-5,8,3,LOG)
Block(-5,8,4,LOG)
Block(-5,8,5,LOG)
Block(-5,9,2,LOG)
Block(-5,9,3,LOG)
Block(-5,9,4,LOG)
Block(-5,9,5,LOG)
Block(-5,10,3,LOG)
Block(-5,10,4,LOG)
Block(-5,10,5,LOG)
Block(-5,11,3,LOG)
Block(-5,11,4,LOG)
Block(-5,13,7,LOG)
Block(-5,13,8,LOG)
Block(-5,13,14,LEAVES:0)
Block(-5,14,7,LOG)
Block(-5,14,8,LOG)
Block(-5,14,14,LEAVES:0)
Block(-5,14,15,LEAVES:0)
Block(-5,14,17,LEAVES:0)
Block(-5,15,-5,LEAVES:0)
Block(-5,15,-4,LEAVES:0)
Block(-5,15,7,LOG)
Block(-5,15,8,LOG)
Block(-5,15,12,LEAVES:0)
Block(-5,15,13,LEAVES:0)
Block(-5,15,14,LEAVES:0)
Block(-5,15,15,LEAVES:0)
Block(-5,15,16,LEAVES:0)
Block(-5,15,17,LEAVES:0)
Block(-5,15,18,LEAVES:0)
Block(-5,16,-8,LEAVES:0)
Block(-5,16,-7,LEAVES:0)
Block(-5,16,-5,LEAVES:0)
Block(-5,16,-4,LEAVES:0)
Block(-5,16,13,LEAVES:0)
Block(-5,16,14,LOG)
Block(-5,16,15,LOG)
Block(-5,16,16,LEAVES:0)
Block(-5,16,17,LEAVES:0)
Block(-5,17,-7,LEAVES:0)
Block(-5,17,-6,LEAVES:0)
Block(-5,17,-5,LEAVES:0)
Block(-5,17,15,LEAVES:0)
Block(-5,17,16,LEAVES:0)
Block(-5,17,18,LEAVES:0)
Block(-5,18,-9,LEAVES:0)
Block(-5,18,-8,LEAVES:0)
Block(-5,18,-7,LEAVES:0)
Block(-5,18,-6,LEAVES:0)
Block(-5,18,8,LOG)
Block(-5,18,11,LEAVES:0)
Block(-5,18,14,LEAVES:0)
Block(-5,18,16,LEAVES:0)
Block(-5,19,-8,LEAVES:0)
Block(-5,19,-7,LEAVES:0)
Block(-5,19,8,LOG)
Block(-5,19,14,LEAVES:0)
Block(-5,19,16,LEAVES:0)
Block(-5,19,17,LEAVES:0)
Block(-5,20,-9,LEAVES:0)
Block(-5,20,-7,LEAVES:0)
Block(-5,20,7,LOG)
Block(-5,20,8,LOG)
Block(-5,20,15,LEAVES:0)
Block(-5,20,16,LEAVES:0)
Block(-5,21,-9,LEAVES:0)
Block(-5,21,-6,LEAVES:0)
Block(-5,21,1,LEAVES:0)
Block(-5,21,11,LEAVES:0)
Block(-5,21,14,LEAVES:0)
Block(-5,21,15,LEAVES:0)
Block(-5,21,16,LEAVES:0)
Block(-5,22,-9,LEAVES:0)
Block(-5,22,-6,LEAVES:0)
Block(-5,22,-5,LEAVES:0)
Block(-5,22,-2,LEAVES:0)
Block(-5,22,0,LEAVES:0)
Block(-5,22,1,LEAVES:0)
Block(-5,22,2,LEAVES:0)
Block(-5,22,5,LEAVES:0)
Block(-5,22,11,LEAVES:0)
Block(-5,22,12,LEAVES:0)
Block(-5,22,13,LEAVES:0)
Block(-5,22,14,LEAVES:0)
Block(-5,22,15,LEAVES:0)
Block(-5,22,16,LEAVES:0)
Block(-5,22,17,LEAVES:0)
Block(-5,23,-8,LEAVES:0)
Block(-5,23,-7,LEAVES:0)
Block(-5,23,-6,LEAVES:0)
Block(-5,23,-5,LEAVES:0)
Block(-5,23,-4,LEAVES:0)
Block(-5,23,-3,LEAVES:0)
Block(-5,23,-1,LEAVES:0)
Block(-5,23,1,LEAVES:0)
Block(-5,23,3,LOG)
Block(-5,23,4,LOG)
Block(-5,23,5,LEAVES:0)
Block(-5,23,6,LEAVES:0)
Block(-5,23,12,LEAVES:0)
Block(-5,23,13,LEAVES:0)
Block(-5,23,15,LEAVES:0)
Block(-5,23,16,LEAVES:0)
Block(-5,23,17,LEAVES:0)
Block(-5,24,-7,LEAVES:0)
Block(-5,24,-5,LEAVES:0)
Block(-5,24,1,LEAVES:0)
Block(-5,24,2,LOG)
Block(-5,24,4,LEAVES:0)
Block(-5,24,6,LEAVES:0)
Block(-5,24,7,LEAVES:0)
Block(-5,24,8,LEAVES:0)
Block(-5,24,13,LEAVES:0)
Block(-5,24,14,LEAVES:0)
Block(-5,24,15,LEAVES:0)
Block(-5,25,-6,LEAVES:0)
Block(-5,25,-5,LEAVES:0)
Block(-5,25,-3,LEAVES:0)
Block(-5,25,-2,LEAVES:0)
Block(-5,25,-1,LEAVES:0)
Block(-5,25,0,LEAVES:0)
Block(-5,25,3,LEAVES:0)
Block(-5,25,6,LEAVES:0)
Block(-5,25,7,LEAVES:0)
Block(-5,25,8,LEAVES:0)
Block(-5,25,12,LEAVES:0)
Block(-5,25,13,LEAVES:0)
Block(-5,25,14,LEAVES:0)
Block(-5,26,-7,LEAVES:0)
Block(-5,26,-6,LEAVES:0)
Block(-5,26,-4,LEAVES:0)
Block(-5,26,-3,LEAVES:0)
Block(-5,26,-2,LEAVES:0)
Block(-5,26,2,LEAVES:0)
Block(-5,26,3,LEAVES:0)
Block(-5,26,4,LEAVES:0)
Block(-5,26,5,LEAVES:0)
Block(-5,26,8,LEAVES:0)
Block(-5,26,13,LEAVES:0)
Block(-5,27,-5,LEAVES:0)
Block(-5,27,-4,LEAVES:0)
Block(-5,27,-2,LEAVES:0)
Block(-5,27,2,LEAVES:0)
Block(-5,27,3,LEAVES:0)
Block(-5,28,-1,LEAVES:0)
Block(-5,29,0,LEAVES:0)
Block(-4,-4,-3,LOG)
Block(-4,-4,-2,LOG)
Block(-4,-3,-2,LOG)
Block(-4,-3,-1,LOG)
Block(-4,-2,-1,LOG)
Block(-4,-2,0,LOG)
Block(-4,-2,1,LOG)
Block(-4,-2,2,LOG)
Block(-4,-2,3,LOG)
Block(-4,-1,0,LOG)
Block(-4,-1,1,LOG)
Block(-4,3,3,LOG)
Block(-4,4,2,LOG)
Block(-4,4,3,LOG)
Block(-4,4,4,LOG)
Block(-4,5,1,LOG)
Block(-4,5,2,LOG)
Block(-4,5,4,LOG)
Block(-4,6,1,LOG)
Block(-4,6,2,LOG)
Block(-4,6,3,LOG)
Block(-4,6,4,LOG)
Block(-4,7,2,LOG)
Block(-4,7,3,LOG)
Block(-4,7,4,LOG)
Block(-4,7,5,LOG)
Block(-4,8,3,LOG)
Block(-4,8,4,LOG)
Block(-4,8,5,LOG)
Block(-4,9,3,LOG)
Block(-4,9,4,LOG)
Block(-4,9,5,LOG)
Block(-4,10,4,LOG)
Block(-4,10,5,LOG)
Block(-4,14,8,LOG)
Block(-4,15,7,LOG)
Block(-4,15,8,LOG)
Block(-4,15,14,LEAVES:0)
Block(-4,16,-6,LEAVES:0)
Block(-4,16,-5,LEAVES:0)
Block(-4,16,6,LOG)
Block(-4,16,7,LOG)
Block(-4,16,8,LOG)
Block(-4,16,13,LEAVES:0)
Block(-4,16,14,LOG)
Block(-4,16,15,LEAVES:0)
Block(-4,16,16,LEAVES:0)
Block(-4,16,17,LEAVES:0)
Block(-4,17,-7,LEAVES:0)
Block(-4,17,-6,LEAVES:0)
Block(-4,17,6,LOG)
Block(-4,17,7,LOG)
Block(-4,17,8,LOG)
Block(-4,17,11,LEAVES:0)
Block(-4,17,12,LEAVES:0)
Block(-4,17,13,LEAVES:0)
Block(-4,17,14,LOG)
Block(-4,17,15,LEAVES:0)
Block(-4,18,8,LOG)
Block(-4,18,9,LOG)
Block(-4,18,10,LOG)
Block(-4,18,11,LOG)
Block(-4,18,14,LEAVES:0)
Block(-4,18,17,LEAVES:0)
Block(-4,19,9,LOG)
Block(-4,19,10,LOG)
Block(-4,19,11,LEAVES:0)
Block(-4,19,14,LEAVES:0)
Block(-4,19,15,LEAVES:0)
Block(-4,19,16,LEAVES:0)
Block(-4,19,17,LEAVES:0)
Block(-4,20,16,LEAVES:0)
Block(-4,22,-2,LEAVES:0)
Block(-4,22,0,LEAVES:0)
Block(-4,22,1,LEAVES:0)
Block(-4,22,2,LEAVES:0)
Block(-4,22,4,LEAVES:0)
Block(-4,22,11,LEAVES:0)
Block(-4,22,13,LEAVES:0)
Block(-4,22,14,LEAVES:0)
Block(-4,22,15,LEAVES:0)
Block(-4,22,16,LEAVES:0)
Block(-4,23,-7,LEAVES:0)
Block(-4,23,-6,LEAVES:0)
Block(-4,23,-2,LEAVES:0)
Block(-4,23,-1,LEAVES:0)
Block(-4,23,0,LEAVES:0)
Block(-4,23,1,LEAVES:0)
Block(-4,23,2,LEAVES:0)
Block(-4,23,3,LEAVES:0)
Block(-4,23,12,LEAVES:0)
Block(-4,23,13,LEAVES:0)
Block(-4,23,15,LEAVES:0)
Block(-4,23,16,LEAVES:0)
Block(-4,23,17,LEAVES:0)
Block(-4,24,-2,LEAVES:0)
Block(-4,24,0,LEAVES:0)
Block(-4,24,2,LEAVES:0)
Block(-4,24,3,LEAVES:0)
Block(-4,24,6,LEAVES:0)
Block(-4,24,7,LEAVES:0)
Block(-4,24,12,LEAVES:0)
Block(-4,24,13,LEAVES:0)
Block(-4,24,16,LEAVES:0)
Block(-4,24,17,LEAVES:0)
Block(-4,25,-2,LEAVES:0)
Block(-4,25,-1,LEAVES:0)
Block(-4,25,2,LEAVES:0)
Block(-4,25,3,LEAVES:0)
Block(-4,25,4,LEAVES:0)
Block(-4,25,5,LEAVES:0)
Block(-4,25,8,LEAVES:0)
Block(-4,25,11,LEAVES:0)
Block(-4,25,12,LEAVES:0)
Block(-4,25,13,LEAVES:0)
Block(-4,25,14,LEAVES:0)
Block(-4,25,15,LEAVES:0)
Block(-4,26,-6,LEAVES:0)
Block(-4,26,-2,LEAVES:0)
Block(-4,26,-1,LEAVES:0)
Block(-4,26,0,LEAVES:0)
Block(-4,26,4,LEAVES:0)
Block(-4,26,5,LEAVES:0)
Block(-4,26,7,LEAVES:0)
Block(-4,27,-1,LEAVES:0)
Block(-4,27,0,LEAVES:0)
Block(-3,-4,6,LOG)
Block(-3,-2,1,LOG)
Block(-3,-2,2,LOG)
Block(-3,-1,-8,LOG)
Block(-3,-1,0,LOG)
Block(-3,-1,1,LOG)
Block(-3,-1,2,LOG)
Block(-3,0,-8,LOG)
Block(-3,0,0,LOG)
Block(-3,0,1,LOG)
Block(-3,3,1,LOG)
Block(-3,3,2,LOG)
Block(-3,3,3,LOG)
Block(-3,4,1,LOG)
Block(-3,4,2,LOG)
Block(-3,4,3,LOG)
Block(-3,5,1,LOG)
Block(-3,5,2,LOG)
Block(-3,5,3,LOG)
Block(-3,5,4,LOG)
Block(-3,6,1,LOG)
Block(-3,6,2,LOG)
Block(-3,6,3,LOG)
Block(-3,6,4,LOG)
Block(-3,7,2,LOG)
Block(-3,7,3,LOG)
Block(-3,7,4,LOG)
Block(-3,8,3,LOG)
Block(-3,8,4,LOG)
Block(-3,9,4,LOG)
Block(-3,15,8,LOG)
Block(-3,16,7,LOG)
Block(-3,16,8,LOG)
Block(-3,16,17,LEAVES:0)
Block(-3,17,5,LOG)
Block(-3,17,6,LOG)
Block(-3,17,7,LOG)
Block(-3,17,12,LOG)
Block(-3,17,13,LOG)
Block(-3,17,14,LOG)
Block(-3,17,15,LEAVES:0)
Block(-3,17,16,LEAVES:0)
Block(-3,18,6,LOG)
Block(-3,18,11,LOG)
Block(-3,18,12,LOG)
Block(-3,18,13,LEAVES:0)
Block(-3,18,14,LEAVES:0)
Block(-3,18,15,LEAVES:0)
Block(-3,18,16,LEAVES:0)
Block(-3,18,17,LEAVES:0)
Block(-3,19,11,LEAVES:0)
Block(-3,19,12,LEAVES:0)
Block(-3,19,15,LEAVES:0)
Block(-3,19,16,LEAVES:0)
Block(-3,20,11,LEAVES:0)
Block(-3,20,12,LEAVES:0)
Block(-3,21,11,LEAVES:0)
Block(-3,21,12,LEAVES:0)
Block(-3,22,-2,LEAVES:0)
Block(-3,22,1,LEAVES:0)
Block(-3,22,10,LEAVES:0)
Block(-3,22,11,LEAVES:0)
Block(-3,22,12,LEAVES:0)
Block(-3,22,13,LEAVES:0)
Block(-3,22,16,LEAVES:0)
Block(-3,22,17,LEAVES:0)
Block(-3,23,-3,LEAVES:0)
Block(-3,23,-2,LEAVES:0)
Block(-3,23,-1,LEAVES:0)
Block(-3,23,0,LEAVES:0)
Block(-3,23,1,LEAVES:0)
Block(-3,23,2,LEAVES:0)
Block(-3,23,10,LEAVES:0)
Block(-3,23,11,LEAVES:0)
Block(-3,23,12,LEAVES:0)
Block(-3,23,13,LEAVES:0)
Block(-3,23,15,LEAVES:0)
Block(-3,23,16,LEAVES:0)
Block(-3,23,17,LEAVES:0)
Block(-3,24,-2,LEAVES:0)
Block(-3,24,0,LEAVES:0)
Block(-3,24,1,LEAVES:0)
Block(-3,24,2,LEAVES:0)
Block(-3,24,3,LEAVES:0)
Block(-3,24,10,LEAVES:0)
Block(-3,24,11,LEAVES:0)
Block(-3,24,12,LEAVES:0)
Block(-3,24,13,LEAVES:0)
Block(-3,24,15,LEAVES:0)
Block(-3,24,16,LEAVES:0)
Block(-3,25,-3,LEAVES:0)
Block(-3,25,-2,LEAVES:0)
Block(-3,25,-1,LEAVES:0)
Block(-3,25,0,LEAVES:0)
Block(-3,25,2,LEAVES:0)
Block(-3,25,3,LEAVES:0)
Block(-3,25,4,LEAVES:0)
Block(-3,25,8,LEAVES:0)
Block(-3,25,9,LEAVES:0)
Block(-3,25,11,LEAVES:0)
Block(-3,25,13,LEAVES:0)
Block(-3,25,14,LEAVES:0)
Block(-3,25,15,LEAVES:0)
Block(-3,25,16,LEAVES:0)
Block(-3,26,-2,LEAVES:0)
Block(-3,26,-1,LEAVES:0)
Block(-3,26,0,LEAVES:0)
Block(-3,26,1,LEAVES:0)
Block(-3,26,15,LEAVES:0)
Block(-3,27,-2,LEAVES:0)
Block(-3,27,-1,LEAVES:0)
Block(-3,27,0,LEAVES:0)
Block(-2,-4,5,LOG)
Block(-2,-4,6,LOG)
Block(-2,-3,4,LOG)
Block(-2,-3,5,LOG)
Block(-2,-2,3,LOG)
Block(-2,-2,4,LOG)
Block(-2,-1,-8,LOG)
Block(-2,-1,-7,LOG)
Block(-2,-1,2,LOG)
Block(-2,-1,3,LOG)
Block(-2,0,-5,LOG)
Block(-2,0,1,LOG)
Block(-2,1,1,LOG)
Block(-2,2,1,LOG)
Block(-2,2,2,LOG)
Block(-2,3,0,LOG)
Block(-2,3,1,LOG)
Block(-2,3,2,LOG)
Block(-2,3,3,LOG)
Block(-2,4,0,LOG)
Block(-2,4,1,LOG)
Block(-2,4,2,LOG)
Block(-2,4,3,LOG)
Block(-2,5,1,LOG)
Block(-2,5,2,LOG)
Block(-2,5,3,LOG)
Block(-2,5,4,LOG)
Block(-2,6,1,LOG)
Block(-2,6,2,LOG)
Block(-2,6,3,LOG)
Block(-2,7,3,LOG)
Block(-2,11,15,LEAVES:0)
Block(-2,11,16,LEAVES:0)
Block(-2,12,14,LEAVES:0)
Block(-2,12,15,LEAVES:0)
Block(-2,17,5,LOG)
Block(-2,17,6,LOG)
Block(-2,17,10,LEAVES:0)
Block(-2,17,15,LEAVES:0)
Block(-2,18,5,LOG)
Block(-2,18,17,LEAVES:0)
Block(-2,19,10,LEAVES:0)
Block(-2,19,11,LEAVES:0)
Block(-2,19,12,LEAVES:0)
Block(-2,19,13,LEAVES:0)
Block(-2,19,15,LEAVES:0)
Block(-2,19,16,LEAVES:0)
Block(-2,20,9,LEAVES:0)
Block(-2,20,10,LEAVES:0)
Block(-2,20,11,LEAVES:0)
Block(-2,20,13,LEAVES:0)
Block(-2,20,14,LEAVES:0)
Block(-2,21,10,LEAVES:0)
Block(-2,22,0,LEAVES:0)
Block(-2,22,11,LEAVES:0)
Block(-2,22,12,LEAVES:0)
Block(-2,22,14,LOG)
Block(-2,22,15,LOG)
Block(-2,23,12,LEAVES:0)
Block(-2,23,15,LOG)
Block(-2,24,0,LEAVES:0)
Block(-2,24,1,LEAVES:0)
Block(-2,24,2,LEAVES:0)
Block(-2,24,3,LOG)
Block(-2,24,4,LEAVES:0)
Block(-2,24,5,LEAVES:0)
Block(-2,24,11,LEAVES:0)
Block(-2,24,12,LEAVES:0)
Block(-2,24,13,LEAVES:0)
Block(-2,24,14,LEAVES:0)
Block(-2,24,15,LEAVES:0)
Block(-2,24,16,LEAVES:0)
Block(-2,24,17,LEAVES:0)
Block(-2,25,-3,LEAVES:0)
Block(-2,25,-2,LEAVES:0)
Block(-2,25,3,LEAVES:0)
Block(-2,25,4,LEAVES:0)
Block(-2,25,7,LEAVES:0)
Block(-2,25,8,LEAVES:0)
Block(-2,25,9,LEAVES:0)
Block(-2,25,10,LEAVES:0)
Block(-2,25,11,LEAVES:0)
Block(-2,25,13,LEAVES:0)
Block(-2,25,14,LEAVES:0)
Block(-2,25,15,LEAVES:0)
Block(-2,25,16,LEAVES:0)
Block(-2,25,17,LEAVES:0)
Block(-2,26,-1,LEAVES:0)
Block(-2,26,0,LEAVES:0)
Block(-2,26,13,LEAVES:0)
Block(-2,26,16,LEAVES:0)
Block(-1,-3,-5,LOG)
Block(-1,-2,-5,LOG)
Block(-1,-1,-7,LOG)
Block(-1,-1,-6,LOG)
Block(-1,-1,-5,LOG)
Block(-1,-1,2,LOG)
Block(-1,-1,3,LOG)
Block(-1,0,-5,LOG)
Block(-1,0,-4,LOG)
Block(-1,0,-3,LOG)
Block(-1,0,-2,LOG)
Block(-1,0,0,LOG)
Block(-1,0,1,LOG)
Block(-1,1,-5,LOG)
Block(-1,1,-4,LOG)
Block(-1,1,-3,LOG)
Block(-1,1,-2,LOG)
Block(-1,1,1,LOG)
Block(-1,1,2,LOG)
Block(-1,2,-3,LOG)
Block(-1,2,-2,LOG)
Block(-1,2,-1,LOG)
Block(-1,2,0,LOG)
Block(-1,2,2,LOG)
Block(-1,3,-2,LOG)
Block(-1,3,-1,LOG)
Block(-1,3,0,LOG)
Block(-1,3,1,LOG)
Block(-1,3,2,LOG)
Block(-1,4,0,LOG)
Block(-1,4,1,LOG)
Block(-1,4,2,LOG)
Block(-1,5,0,LOG)
Block(-1,5,1,LOG)
Block(-1,5,2,LOG)
Block(-1,6,1,LOG)
Block(-1,6,2,LOG)
Block(-1,6,3,LOG)
Block(-1,7,2,LOG)
Block(-1,10,13,LEAVES:0)
Block(-1,10,14,LEAVES:0)
Block(-1,11,13,LEAVES:0)
Block(-1,11,14,LEAVES:0)
Block(-1,11,15,LEAVES:0)
Block(-1,11,16,LEAVES:0)
Block(-1,12,13,LEAVES:0)
Block(-1,12,14,LEAVES:0)
Block(-1,12,16,LEAVES:0)
Block(-1,13,11,LEAVES:0)
Block(-1,13,13,LEAVES:0)
Block(-1,13,14,LEAVES:0)
Block(-1,13,15,LEAVES:0)
Block(-1,17,6,LOG)
Block(-1,17,10,LEAVES:0)
Block(-1,17,11,LEAVES:0)
Block(-1,18,5,LOG)
Block(-1,18,6,LOG)
Block(-1,18,11,LEAVES:0)
Block(-1,19,7,LEAVES:0)
Block(-1,19,8,LEAVES:0)
Block(-1,19,9,LEAVES:0)
Block(-1,19,10,LEAVES:0)
Block(-1,19,11,LEAVES:0)
Block(-1,19,12,LEAVES:0)
Block(-1,19,13,LEAVES:0)
Block(-1,19,15,LEAVES:0)
Block(-1,20,8,LEAVES:0)
Block(-1,20,10,LEAVES:0)
Block(-1,20,11,LEAVES:0)
Block(-1,20,12,LEAVES:0)
Block(-1,20,13,LEAVES:0)
Block(-1,20,14,LEAVES:0)
Block(-1,21,12,LEAVES:0)
Block(-1,21,13,LEAVES:0)
Block(-1,22,1,LEAVES:0)
Block(-1,22,11,LEAVES:0)
Block(-1,22,13,LEAVES:0)
Block(-1,22,14,LOG)
Block(-1,23,-1,LEAVES:0)
Block(-1,23,4,LOG)
Block(-1,23,5,LOG)
Block(-1,23,7,LEAVES:0)
Block(-1,23,14,LEAVES:0)
Block(-1,24,-2,LEAVES:0)
Block(-1,24,-1,LEAVES:0)
Block(-1,24,3,LOG)
Block(-1,24,4,LOG)
Block(-1,24,5,LEAVES:0)
Block(-1,24,6,LEAVES:0)
Block(-1,24,7,LEAVES:0)
Block(-1,24,11,LEAVES:0)
Block(-1,24,14,LEAVES:0)
Block(-1,24,15,LEAVES:0)
Block(-1,24,16,LEAVES:0)
Block(-1,25,-2,LEAVES:0)
Block(-1,25,0,LEAVES:0)
Block(-1,25,1,LEAVES:0)
Block(-1,25,2,LEAVES:0)
Block(-1,25,3,LEAVES:0)
Block(-1,25,4,LEAVES:0)
Block(-1,25,5,LEAVES:0)
Block(-1,25,7,LEAVES:0)
Block(-1,25,8,LEAVES:0)
Block(-1,25,11,LEAVES:0)
Block(-1,25,12,LEAVES:0)
Block(-1,25,14,LEAVES:0)
Block(-1,25,16,LEAVES:0)
Block(-1,26,-2,LEAVES:0)
Block(-1,26,-1,LEAVES:0)
Block(-1,26,0,LEAVES:0)
Block(-1,26,2,LEAVES:0)
Block(-1,26,3,LEAVES:0)
Block(-1,26,4,LEAVES:0)
Block(-1,26,7,LEAVES:0)
Block(-1,26,8,LEAVES:0)
Block(-1,26,9,LEAVES:0)
Block(-1,26,10,LEAVES:0)
Block(-1,26,11,LEAVES:0)
Block(-1,26,12,LEAVES:0)
Block(-1,26,15,LEAVES:0)
Block(0,-3,-6,LOG)
Block(0,-3,-5,LOG)
Block(0,-1,1,LOG)
Block(0,-1,2,LOG)
Block(0,0,-1,LOG)
Block(0,0,0,LOG)
Block(0,0,1,LOG)
Block(0,0,2,LOG)
Block(0,1,-5,LOG)
Block(0,1,-4,LOG)
Block(0,1,-3,LOG)
Block(0,1,-1,LOG)
Block(0,1,0,LOG)
Block(0,1,1,LOG)
Block(0,2,-4,LOG)
Block(0,2,-3,LOG)
Block(0,2,-2,LOG)
Block(0,2,-1,LOG)
Block(0,2,0,LOG)
Block(0,2,1,LOG)
Block(0,2,2,LOG)
Block(0,3,-2,LOG)
Block(0,3,-1,LOG)
Block(0,3,0,LOG)
Block(0,3,1,LOG)
Block(0,4,-1,LOG)
Block(0,4,0,LOG)
Block(0,4,1,LOG)
Block(0,5,0,LOG)
Block(0,5,1,LOG)
Block(0,5,2,LOG)
Block(0,9,14,LEAVES:0)
Block(0,10,13,LEAVES:0)
Block(0,10,14,LEAVES:0)
Block(0,10,15,LEAVES:0)
Block(0,11,12,LEAVES:0)
Block(0,11,13,LEAVES:0)
Block(0,11,14,LEAVES:0)
Block(0,11,15,LEAVES:0)
Block(0,11,16,LEAVES:0)
Block(0,12,11,LEAVES:0)
Block(0,12,12,LEAVES:0)
Block(0,12,13,LEAVES:0)
Block(0,12,14,LOG)
Block(0,12,15,LEAVES:0)
Block(0,12,16,LEAVES:0)
Block(0,12,17,LEAVES:0)
Block(0,13,11,LEAVES:0)
Block(0,13,13,LEAVES:0)
Block(0,13,14,LEAVES:0)
Block(0,13,15,LEAVES:0)
Block(0,13,16,LEAVES:0)
Block(0,14,11,LEAVES:0)
Block(0,14,12,LEAVES:0)
Block(0,14,14,LEAVES:0)
Block(0,14,16,LEAVES:0)
Block(0,15,10,LEAVES:0)
Block(0,15,13,LEAVES:0)
Block(0,16,9,LOG)
Block(0,16,10,LOG)
Block(0,16,11,LEAVES:0)
Block(0,16,12,LEAVES:0)
Block(0,17,6,LOG)
Block(0,17,7,LOG)
Block(0,17,8,LOG)
Block(0,17,9,LOG)
Block(0,17,11,LEAVES:0)
Block(0,17,12,LEAVES:0)
Block(0,18,4,LOG)
Block(0,18,5,LOG)
Block(0,18,6,LOG)
Block(0,18,7,LOG)
Block(0,18,8,LOG)
Block(0,18,9,LOG)
Block(0,18,10,LOG)
Block(0,18,12,LEAVES:0)
Block(0,18,13,LEAVES:0)
Block(0,19,4,LOG)
Block(0,19,6,LEAVES:0)
Block(0,19,7,LEAVES:0)
Block(0,19,8,LEAVES:0)
Block(0,19,9,LOG)
Block(0,19,10,LOG)
Block(0,19,11,LEAVES:0)
Block(0,19,12,LEAVES:0)
Block(0,20,7,LEAVES:0)
Block(0,20,8,LEAVES:0)
Block(0,20,9,LEAVES:0)
Block(0,20,10,LEAVES:0)
Block(0,20,12,LEAVES:0)
Block(0,20,14,LEAVES:0)
Block(0,20,15,LEAVES:0)
Block(0,20,16,LEAVES:0)
Block(0,21,10,LEAVES:0)
Block(0,21,12,LEAVES:0)
Block(0,21,14,LOG)
Block(0,21,15,LEAVES:0)
Block(0,22,5,LOG)
Block(0,22,7,LEAVES:0)
Block(0,22,11,LEAVES:0)
Block(0,22,14,LOG)
Block(0,23,1,LEAVES:0)
Block(0,23,2,LEAVES:0)
Block(0,23,4,LEAVES:0)
Block(0,23,5,LOG)
Block(0,23,6,LEAVES:0)
Block(0,23,7,LEAVES:0)
Block(0,23,8,LEAVES:0)
Block(0,23,13,LOG)
Block(0,23,14,LEAVES:0)
Block(0,24,0,LEAVES:0)
Block(0,24,1,LEAVES:0)
Block(0,24,2,LEAVES:0)
Block(0,24,3,LEAVES:0)
Block(0,24,4,LEAVES:0)
Block(0,24,5,LEAVES:0)
Block(0,24,6,LEAVES:0)
Block(0,24,13,LOG)
Block(0,24,14,LEAVES:0)
Block(0,24,15,LEAVES:0)
Block(0,24,16,LEAVES:0)
Block(0,25,-1,LEAVES:0)
Block(0,25,1,LEAVES:0)
Block(0,25,2,LOG)
Block(0,25,3,LEAVES:0)
Block(0,25,6,LEAVES:0)
Block(0,25,7,LEAVES:0)
Block(0,25,8,LEAVES:0)
Block(0,25,9,LEAVES:0)
Block(0,25,13,LEAVES:0)
Block(0,25,14,LEAVES:0)
Block(0,25,15,LEAVES:0)
Block(0,26,-1,LEAVES:0)
Block(0,26,1,LEAVES:0)
Block(0,26,2,LEAVES:0)
Block(0,26,3,LEAVES:0)
Block(0,26,4,LEAVES:0)
Block(0,26,5,LEAVES:0)
Block(0,26,6,LEAVES:0)
Block(0,26,7,LEAVES:0)
Block(0,26,9,LEAVES:0)
Block(0,26,10,LEAVES:0)
Block(0,26,11,LEAVES:0)
Block(0,26,12,LEAVES:0)
Block(0,26,13,LEAVES:0)
Block(0,27,1,LEAVES:0)
Block(0,27,2,LEAVES:0)
Block(0,27,3,LEAVES:0)
Block(0,27,7,LEAVES:0)
Block(0,27,10,LEAVES:0)
Block(0,27,11,LEAVES:0)
Block(0,27,12,LEAVES:0)
Block(0,27,13,LEAVES:0)
Block(0,28,2,LEAVES:0)
Block(1,-4,-6,LOG)
Block(1,-3,-6,LOG)
Block(1,0,-1,LOG)
Block(1,0,0,LOG)
Block(1,0,1,LOG)
Block(1,1,-4,LOG)
Block(1,1,-3,LOG)
Block(1,1,-1,LOG)
Block(1,1,0,LOG)
Block(1,1,1,LOG)
Block(1,2,-3,LOG)
Block(1,2,-2,LOG)
Block(1,2,-1,LOG)
Block(1,2,0,LOG)
Block(1,2,1,LOG)
Block(1,3,-3,LOG)
Block(1,3,-2,LOG)
Block(1,3,-1,LOG)
Block(1,3,0,LOG)
Block(1,4,-2,LOG)
Block(1,4,0,LOG)
Block(1,9,13,LEAVES:0)
Block(1,9,14,LEAVES:0)
Block(1,10,14,LEAVES:0)
Block(1,11,11,LEAVES:0)
Block(1,11,12,LEAVES:0)
Block(1,11,13,LEAVES:0)
Block(1,11,14,LEAVES:0)
Block(1,11,15,LEAVES:0)
Block(1,11,16,LEAVES:0)
Block(1,11,17,LEAVES:0)
Block(1,12,11,LEAVES:0)
Block(1,12,12,LEAVES:0)
Block(1,12,13,LOG)
Block(1,12,14,LOG)
Block(1,12,15,LEAVES:0)
Block(1,12,16,LEAVES:0)
Block(1,13,11,LEAVES:0)
Block(1,13,12,LEAVES:0)
Block(1,13,15,LEAVES:0)
Block(1,13,16,LEAVES:0)
Block(1,13,17,LEAVES:0)
Block(1,14,11,LEAVES:0)
Block(1,14,12,LEAVES:0)
Block(1,14,14,LEAVES:0)
Block(1,14,15,LEAVES:0)
Block(1,14,16,LEAVES:0)
Block(1,15,10,LOG)
Block(1,15,11,LEAVES:0)
Block(1,15,12,LEAVES:0)
Block(1,15,14,LEAVES:0)
Block(1,16,10,LOG)
Block(1,16,11,LEAVES:0)
Block(1,16,12,LEAVES:0)
Block(1,16,13,LEAVES:0)
Block(1,17,6,LOG)
Block(1,17,7,LOG)
Block(1,17,10,LEAVES:0)
Block(1,17,13,LEAVES:0)
Block(1,18,4,LOG)
Block(1,18,7,LEAVES:0)
Block(1,18,8,LOG)
Block(1,18,9,LOG)
Block(1,18,10,LOG)
Block(1,18,13,LEAVES:0)
Block(1,18,14,LEAVES:0)
Block(1,19,4,LOG)
Block(1,19,10,LOG)
Block(1,19,11,LOG)
Block(1,19,13,LEAVES:0)
Block(1,19,14,LEAVES:0)
Block(1,19,15,LEAVES:0)
Block(1,20,4,LOG)
Block(1,20,10,LOG)
Block(1,20,12,LEAVES:0)
Block(1,20,13,LEAVES:0)
Block(1,20,14,LEAVES:0)
Block(1,20,15,LEAVES:0)
Block(1,21,6,LEAVES:0)
Block(1,21,7,LEAVES:0)
Block(1,21,11,LEAVES:0)
Block(1,21,12,LEAVES:0)
Block(1,21,13,LOG)
Block(1,21,14,LOG)
Block(1,21,15,LEAVES:0)
Block(1,21,16,LEAVES:0)
Block(1,22,5,LOG)
Block(1,22,6,LEAVES:0)
Block(1,22,12,LEAVES:0)
Block(1,22,14,LEAVES:0)
Block(1,22,15,LEAVES:0)
Block(1,23,1,LEAVES:0)
Block(1,23,4,LEAVES:0)
Block(1,23,5,LEAVES:0)
Block(1,23,6,LEAVES:0)
Block(1,23,7,LEAVES:0)
Block(1,23,8,LEAVES:0)
Block(1,23,14,LEAVES:0)
Block(1,24,0,LEAVES:0)
Block(1,24,1,LEAVES:0)
Block(1,24,2,LEAVES:0)
Block(1,24,3,LEAVES:0)
Block(1,24,5,LEAVES:0)
Block(1,24,6,LEAVES:0)
Block(1,24,7,LEAVES:0)
Block(1,24,8,LEAVES:0)
Block(1,24,9,LEAVES:0)
Block(1,24,10,LEAVES:0)
Block(1,24,12,LOG)
Block(1,24,13,LEAVES:0)
Block(1,24,14,LEAVES:0)
Block(1,24,15,LEAVES:0)
Block(1,24,16,LEAVES:0)
Block(1,25,0,LEAVES:0)
Block(1,25,1,LEAVES:0)
Block(1,25,2,LEAVES:0)
Block(1,25,3,LEAVES:0)
Block(1,25,4,LEAVES:0)
Block(1,25,5,LEAVES:0)
Block(1,25,6,LEAVES:0)
Block(1,25,7,LEAVES:0)
Block(1,25,8,LEAVES:0)
Block(1,25,9,LEAVES:0)
Block(1,25,10,LEAVES:0)
Block(1,25,11,LOG)
Block(1,25,12,LEAVES:0)
Block(1,25,13,LEAVES:0)
Block(1,25,14,LEAVES:0)
Block(1,25,15,LEAVES:0)
Block(1,26,2,LEAVES:0)
Block(1,26,3,LEAVES:0)
Block(1,26,4,LEAVES:0)
Block(1,26,7,LEAVES:0)
Block(1,26,8,LEAVES:0)
Block(1,26,9,LEAVES:0)
Block(1,26,10,LEAVES:0)
Block(1,26,11,LEAVES:0)
Block(1,26,12,LEAVES:0)
Block(1,26,14,LEAVES:0)
Block(1,27,2,LEAVES:0)
Block(1,27,3,LEAVES:0)
Block(1,27,7,LEAVES:0)
Block(1,27,9,LEAVES:0)
Block(1,27,10,LEAVES:0)
Block(1,27,11,LEAVES:0)
Block(1,27,12,LEAVES:0)
Block(1,27,13,LEAVES:0)
Block(2,-4,3,LOG)
Block(2,-3,3,LOG)
Block(2,0,0,LOG)
Block(2,0,1,LOG)
Block(2,0,2,LOG)
Block(2,1,-4,LOG)
Block(2,1,-1,LOG)
Block(2,1,0,LOG)
Block(2,1,1,LOG)
Block(2,1,2,LOG)
Block(2,2,-4,LOG)
Block(2,2,-3,LOG)
Block(2,2,-2,LOG)
Block(2,2,0,LOG)
Block(2,2,1,LOG)
Block(2,3,-4,LOG)
Block(2,3,-3,LOG)
Block(2,3,-2,LOG)
Block(2,10,13,LEAVES:0)
Block(2,10,15,LEAVES:0)
Block(2,10,16,LEAVES:0)
Block(2,11,12,LEAVES:0)
Block(2,11,13,LEAVES:0)
Block(2,11,14,LEAVES:0)
Block(2,11,15,LEAVES:0)
Block(2,11,16,LEAVES:0)
Block(2,12,11,LEAVES:0)
Block(2,12,12,LEAVES:0)
Block(2,12,13,LOG)
Block(2,12,14,LEAVES:0)
Block(2,12,15,LEAVES:0)
Block(2,12,16,LEAVES:0)
Block(2,12,17,LEAVES:0)
Block(2,13,11,LEAVES:0)
Block(2,13,12,LOG)
Block(2,13,13,LOG)
Block(2,13,14,LEAVES:0)
Block(2,13,15,LEAVES:0)
Block(2,13,16,LEAVES:0)
Block(2,14,10,LEAVES:0)
Block(2,14,11,LOG)
Block(2,14,12,LOG)
Block(2,14,13,LEAVES:0)
Block(2,14,15,LEAVES:0)
Block(2,14,16,LEAVES:0)
Block(2,15,8,LEAVES:0)
Block(2,15,9,LEAVES:0)
Block(2,15,10,LOG)
Block(2,15,11,LOG)
Block(2,15,12,LEAVES:0)
Block(2,15,13,LEAVES:0)
Block(2,15,14,LEAVES:0)
Block(2,15,15,LEAVES:0)
Block(2,16,10,LEAVES:0)
Block(2,16,11,LEAVES:0)
Block(2,16,12,LEAVES:0)
Block(2,16,14,LEAVES:0)
Block(2,17,9,LEAVES:0)
Block(2,17,14,LEAVES:0)
Block(2,18,7,LEAVES:0)
Block(2,18,8,LEAVES:0)
Block(2,18,9,LEAVES:0)
Block(2,18,13,LEAVES:0)
Block(2,19,10,LEAVES:0)
Block(2,19,11,LOG)
Block(2,19,12,LOG)
Block(2,19,13,LOG)
Block(2,19,14,LEAVES:0)
Block(2,20,4,LOG)
Block(2,20,5,LEAVES:0)
Block(2,20,6,LEAVES:0)
Block(2,20,7,LEAVES:0)
Block(2,20,10,LOG)
Block(2,20,11,LOG)
Block(2,20,12,LEAVES:0)
Block(2,20,13,LOG)
Block(2,20,14,LEAVES:0)
Block(2,20,15,LEAVES:0)
Block(2,21,4,LOG)
Block(2,21,5,LOG)
Block(2,21,6,LEAVES:0)
Block(2,21,10,LEAVES:0)
Block(2,21,11,LEAVES:0)
Block(2,21,12,LEAVES:0)
Block(2,21,13,LOG)
Block(2,21,15,LEAVES:0)
Block(2,22,5,LOG)
Block(2,22,6,LOG)
Block(2,22,7,LEAVES:0)
Block(2,22,9,LEAVES:0)
Block(2,22,12,LEAVES:0)
Block(2,23,1,LEAVES:0)
Block(2,23,3,LEAVES:0)
Block(2,23,4,LEAVES:0)
Block(2,23,5,LEAVES:0)
Block(2,23,6,LOG)
Block(2,23,7,LEAVES:0)
Block(2,23,8,LEAVES:0)
Block(2,23,11,LEAVES:0)
Block(2,24,0,LEAVES:0)
Block(2,24,1,LEAVES:0)
Block(2,24,5,LEAVES:0)
Block(2,24,6,LOG)
Block(2,24,7,LEAVES:0)
Block(2,24,9,LEAVES:0)
Block(2,24,15,LEAVES:0)
Block(2,25,1,LEAVES:0)
Block(2,25,4,LEAVES:0)
Block(2,25,5,LEAVES:0)
Block(2,25,6,LEAVES:0)
Block(2,25,7,LEAVES:0)
Block(2,25,8,LEAVES:0)
Block(2,25,9,LEAVES:0)
Block(2,25,11,LEAVES:0)
Block(2,25,12,LEAVES:0)
Block(2,25,13,LEAVES:0)
Block(2,25,14,LEAVES:0)
Block(2,26,1,LEAVES:0)
Block(2,26,2,LEAVES:0)
Block(2,26,3,LEAVES:0)
Block(2,26,4,LEAVES:0)
Block(2,26,5,LEAVES:0)
Block(2,26,6,LEAVES:0)
Block(2,26,7,LEAVES:0)
Block(2,26,8,LEAVES:0)
Block(2,26,9,LEAVES:0)
Block(2,26,10,LEAVES:0)
Block(2,26,11,LEAVES:0)
Block(2,26,12,LEAVES:0)
Block(2,26,13,LEAVES:0)
Block(2,27,4,LEAVES:0)
Block(2,27,7,LEAVES:0)
Block(2,27,8,LEAVES:0)
Block(2,27,9,LEAVES:0)
Block(2,27,10,LEAVES:0)
Block(2,28,7,LEAVES:0)
Block(3,-3,3,LOG)
Block(3,-2,2,LOG)
Block(3,-2,3,LOG)
Block(3,-1,1,LOG)
Block(3,-1,2,LOG)
Block(3,0,1,LOG)
Block(3,0,2,LOG)
Block(3,1,2,LOG)
Block(3,2,-3,LOG)
Block(3,2,2,LOG)
Block(3,2,3,LOG)
Block(3,3,-4,LOG)
Block(3,3,-3,LOG)
Block(3,4,-4,LOG)
Block(3,10,13,LEAVES:0)
Block(3,10,15,LEAVES:0)
Block(3,11,13,LEAVES:0)
Block(3,11,14,LEAVES:0)
Block(3,11,15,LEAVES:0)
Block(3,12,11,LEAVES:0)
Block(3,12,12,LEAVES:0)
Block(3,12,13,LEAVES:0)
Block(3,12,15,LEAVES:0)
Block(3,12,16,LEAVES:0)
Block(3,13,9,LEAVES:0)
Block(3,13,10,LEAVES:0)
Block(3,13,11,LEAVES:0)
Block(3,13,12,LEAVES:0)
Block(3,13,15,LEAVES:0)
Block(3,13,16,LEAVES:0)
Block(3,14,9,LEAVES:0)
Block(3,14,10,LEAVES:0)
Block(3,14,11,LEAVES:0)
Block(3,14,12,LEAVES:0)
Block(3,14,13,LEAVES:0)
Block(3,14,14,LEAVES:0)
Block(3,14,15,LEAVES:0)
Block(3,15,8,LEAVES:0)
Block(3,15,9,LEAVES:0)
Block(3,15,10,LEAVES:0)
Block(3,15,11,LEAVES:0)
Block(3,15,12,LEAVES:0)
Block(3,15,15,LEAVES:0)
Block(3,16,9,LEAVES:0)
Block(3,16,10,LEAVES:0)
Block(3,16,11,LEAVES:0)
Block(3,16,14,LEAVES:0)
Block(3,17,8,LEAVES:0)
Block(3,17,9,LEAVES:0)
Block(3,17,10,LEAVES:0)
Block(3,17,11,LEAVES:0)
Block(3,17,12,LEAVES:0)
Block(3,17,13,LEAVES:0)
Block(3,18,7,LEAVES:0)
Block(3,18,8,LEAVES:0)
Block(3,18,9,LEAVES:0)
Block(3,18,10,LEAVES:0)
Block(3,18,11,LEAVES:0)
Block(3,18,12,LEAVES:0)
Block(3,18,13,LEAVES:0)
Block(3,18,14,LEAVES:0)
Block(3,19,9,LEAVES:0)
Block(3,19,11,LEAVES:0)
Block(3,19,13,LEAVES:0)
Block(3,19,14,LEAVES:0)
Block(3,20,5,LEAVES:0)
Block(3,20,7,LEAVES:0)
Block(3,20,11,LEAVES:0)
Block(3,20,12,LEAVES:0)
Block(3,20,13,LEAVES:0)
Block(3,20,14,LEAVES:0)
Block(3,20,15,LEAVES:0)
Block(3,20,16,LEAVES:0)
Block(3,21,13,LEAVES:0)
Block(3,21,15,LEAVES:0)
Block(3,22,4,LEAVES:0)
Block(3,22,5,LEAVES:0)
Block(3,22,6,LEAVES:0)
Block(3,22,12,LEAVES:0)
Block(3,22,14,LEAVES:0)
Block(3,23,4,LEAVES:0)
Block(3,23,6,LEAVES:0)
Block(3,23,9,LEAVES:0)
Block(3,23,13,LEAVES:0)
Block(3,23,14,LEAVES:0)
Block(3,24,2,LEAVES:0)
Block(3,24,3,LEAVES:0)
Block(3,24,5,LEAVES:0)
Block(3,24,7,LOG)
Block(3,24,9,LEAVES:0)
Block(3,24,10,LEAVES:0)
Block(3,24,12,LEAVES:0)
Block(3,24,14,LEAVES:0)
Block(3,25,1,LEAVES:0)
Block(3,25,2,LEAVES:0)
Block(3,25,5,LEAVES:0)
Block(3,25,6,LEAVES:0)
Block(3,25,7,LEAVES:0)
Block(3,25,8,LOG)
Block(3,25,9,LEAVES:0)
Block(3,25,10,LEAVES:0)
Block(3,25,12,LEAVES:0)
Block(3,25,13,LEAVES:0)
Block(3,25,14,LEAVES:0)
Block(3,26,2,LEAVES:0)
Block(3,26,3,LEAVES:0)
Block(3,26,4,LEAVES:0)
Block(3,26,5,LEAVES:0)
Block(3,26,6,LEAVES:0)
Block(3,26,7,LEAVES:0)
Block(3,26,8,LEAVES:0)
Block(3,26,9,LEAVES:0)
Block(3,26,10,LEAVES:0)
Block(3,26,11,LEAVES:0)
Block(3,26,12,LEAVES:0)
Block(3,27,3,LEAVES:0)
Block(3,27,4,LEAVES:0)
Block(3,27,5,LEAVES:0)
Block(3,27,6,LEAVES:0)
Block(3,27,7,LEAVES:0)
Block(3,27,8,LEAVES:0)
Block(3,27,9,LEAVES:0)
Block(3,27,10,LEAVES:0)
Block(3,28,7,LEAVES:0)
Block(4,-1,7,LOG)
Block(4,0,2,LOG)
Block(4,1,2,LOG)
Block(4,2,-5,LOG)
Block(4,2,2,LOG)
Block(4,2,3,LOG)
Block(4,2,4,LOG)
Block(4,3,-5,LOG)
Block(4,3,-4,LOG)
Block(4,3,-3,LOG)
Block(4,4,-4,LOG)
Block(4,11,11,LEAVES:0)
Block(4,11,12,LEAVES:0)
Block(4,11,13,LEAVES:0)
Block(4,11,14,LEAVES:0)
Block(4,12,11,LEAVES:0)
Block(4,12,12,LEAVES:0)
Block(4,12,13,LEAVES:0)
Block(4,12,14,LEAVES:0)
Block(4,13,10,LEAVES:0)
Block(4,13,11,LEAVES:0)
Block(4,13,12,LEAVES:0)
Block(4,13,13,LEAVES:0)
Block(4,13,14,LEAVES:0)
Block(4,13,16,LEAVES:0)
Block(4,14,12,LEAVES:0)
Block(4,14,13,LEAVES:0)
Block(4,14,15,LEAVES:0)
Block(4,15,10,LEAVES:0)
Block(4,15,11,LEAVES:0)
Block(4,15,12,LEAVES:0)
Block(4,15,13,LEAVES:0)
Block(4,16,9,LEAVES:0)
Block(4,16,10,LEAVES:0)
Block(4,17,8,LEAVES:0)
Block(4,17,9,LEAVES:0)
Block(4,17,10,LEAVES:0)
Block(4,17,11,LEAVES:0)
Block(4,18,11,LEAVES:0)
Block(4,18,12,LEAVES:0)
Block(4,18,14,LEAVES:0)
Block(4,18,15,LEAVES:0)
Block(4,20,14,LEAVES:0)
Block(4,21,12,LEAVES:0)
Block(4,21,13,LEAVES:0)
Block(4,21,14,LEAVES:0)
Block(4,21,15,LEAVES:0)
Block(4,22,6,LEAVES:0)
Block(4,22,7,LEAVES:0)
Block(4,22,12,LEAVES:0)
Block(4,22,13,LEAVES:0)
Block(4,22,14,LEAVES:0)
Block(4,23,3,LEAVES:0)
Block(4,23,4,LEAVES:0)
Block(4,23,5,LEAVES:0)
Block(4,23,6,LEAVES:0)
Block(4,23,8,LEAVES:0)
Block(4,23,9,LEAVES:0)
Block(4,23,10,LEAVES:0)
Block(4,23,12,LEAVES:0)
Block(4,24,4,LEAVES:0)
Block(4,24,9,LEAVES:0)
Block(4,24,10,LEAVES:0)
Block(4,24,11,LEAVES:0)
Block(4,24,12,LEAVES:0)
Block(4,25,3,LEAVES:0)
Block(4,25,4,LEAVES:0)
Block(4,25,5,LEAVES:0)
Block(4,25,6,LEAVES:0)
Block(4,25,7,LEAVES:0)
Block(4,25,8,LEAVES:0)
Block(4,25,10,LEAVES:0)
Block(4,25,11,LEAVES:0)
Block(4,25,12,LEAVES:0)
Block(4,25,13,LEAVES:0)
Block(4,26,3,LEAVES:0)
Block(4,26,4,LEAVES:0)
Block(4,26,5,LEAVES:0)
Block(4,26,6,LEAVES:0)
Block(4,26,7,LEAVES:0)
Block(4,26,8,LEAVES:0)
Block(4,26,9,LEAVES:0)
Block(4,26,10,LEAVES:0)
Block(4,26,11,LEAVES:0)
Block(4,27,6,LEAVES:0)
Block(4,27,7,LEAVES:0)
Block(4,27,8,LEAVES:0)
Block(4,28,8,LEAVES:0)
Block(5,-3,10,LOG)
Block(5,-3,11,LOG)
Block(5,-2,6,LOG)
Block(5,-2,7,LOG)
Block(5,-1,6,LOG)
Block(5,-1,7,LOG)
Block(5,0,6,LOG)
Block(5,1,-6,LOG)
Block(5,1,-5,LOG)
Block(5,2,-5,LOG)
Block(5,2,-4,LOG)
Block(5,2,3,LOG)
Block(5,2,4,LOG)
Block(5,2,5,LOG)
Block(5,3,4,LOG)
Block(5,11,13,LEAVES:0)
Block(5,12,10,LEAVES:0)
Block(5,12,11,LEAVES:0)
Block(5,12,12,LEAVES:0)
Block(5,13,11,LEAVES:0)
Block(5,13,12,LEAVES:0)
Block(5,13,13,LEAVES:0)
Block(5,14,11,LEAVES:0)
Block(5,14,12,LEAVES:0)
Block(5,15,10,LEAVES:0)
Block(5,15,11,LEAVES:0)
Block(5,15,12,LEAVES:0)
Block(5,15,13,LEAVES:0)
Block(5,15,14,LEAVES:0)
Block(5,16,10,LEAVES:0)
Block(5,17,9,LEAVES:0)
Block(5,17,10,LEAVES:0)
Block(5,17,11,LEAVES:0)
Block(5,17,12,LEAVES:0)
Block(5,17,13,LEAVES:0)
Block(5,18,9,LEAVES:0)
Block(5,18,10,LEAVES:0)
Block(5,18,11,LEAVES:0)
Block(5,18,12,LEAVES:0)
Block(5,18,13,LEAVES:0)
Block(5,18,14,LEAVES:0)
Block(5,19,9,LEAVES:0)
Block(5,19,12,LEAVES:0)
Block(5,19,13,LEAVES:0)
Block(5,20,10,LEAVES:0)
Block(5,20,12,LEAVES:0)
Block(5,20,14,LEAVES:0)
Block(5,21,9,LEAVES:0)
Block(5,21,10,LEAVES:0)
Block(5,21,11,LEAVES:0)
Block(5,21,12,LEAVES:0)
Block(5,21,14,LEAVES:0)
Block(5,22,10,LEAVES:0)
Block(5,22,12,LEAVES:0)
Block(5,22,13,LEAVES:0)
Block(5,23,8,LEAVES:0)
Block(5,23,10,LEAVES:0)
Block(5,23,11,LEAVES:0)
Block(5,23,12,LEAVES:0)
Block(5,24,4,LEAVES:0)
Block(5,24,5,LEAVES:0)
Block(5,24,6,LEAVES:0)
Block(5,24,7,LEAVES:0)
Block(5,24,8,LEAVES:0)
Block(5,24,9,LEAVES:0)
Block(5,24,10,LEAVES:0)
Block(5,24,11,LEAVES:0)
Block(5,24,12,LEAVES:0)
Block(5,24,13,LEAVES:0)
Block(5,25,6,LEAVES:0)
Block(5,25,7,LEAVES:0)
Block(5,25,8,LEAVES:0)
Block(5,25,10,LEAVES:0)
Block(5,25,11,LEAVES:0)
Block(5,25,12,LEAVES:0)
Block(5,26,6,LEAVES:0)
Block(5,26,7,LEAVES:0)
Block(5,26,8,LEAVES:0)
Block(5,26,9,LEAVES:0)
Block(5,26,10,LEAVES:0)
Block(5,26,12,LEAVES:0)
Block(5,27,7,LEAVES:0)
Block(6,-3,9,LOG)
Block(6,-3,10,LOG)
Block(6,-2,4,LOG)
Block(6,-2,7,LOG)
Block(6,-2,8,LOG)
Block(6,-2,9,LOG)
Block(6,-1,-6,LOG)
Block(6,-1,4,LOG)
Block(6,-1,5,LOG)
Block(6,-1,6,LOG)
Block(6,0,-6,LOG)
Block(6,0,-5,LOG)
Block(6,0,6,LOG)
Block(6,0,7,LOG)
Block(6,1,-6,LOG)
Block(6,1,-5,LOG)
Block(6,1,5,LOG)
Block(6,1,6,LOG)
Block(6,2,4,LOG)
Block(6,2,5,LOG)
Block(6,13,12,LEAVES:0)
Block(6,15,11,LEAVES:0)
Block(6,15,13,LEAVES:0)
Block(6,16,11,LEAVES:0)
Block(6,17,9,LEAVES:0)
Block(6,17,10,LEAVES:0)
Block(6,17,12,LEAVES:0)
Block(6,18,9,LEAVES:0)
Block(6,18,10,LEAVES:0)
Block(6,18,13,LEAVES:0)
Block(6,18,14,LEAVES:0)
Block(6,19,12,LEAVES:0)
Block(6,19,13,LEAVES:0)
Block(6,20,12,LEAVES:0)
Block(6,20,13,LEAVES:0)
Block(6,21,13,LEAVES:0)
Block(6,22,9,LEAVES:0)
Block(6,22,10,LEAVES:0)
Block(6,22,11,LEAVES:0)
Block(6,22,12,LEAVES:0)
Block(6,22,13,LEAVES:0)
Block(6,23,9,LEAVES:0)
Block(6,23,10,LEAVES:0)
Block(6,23,11,LEAVES:0)
Block(6,23,12,LEAVES:0)
Block(6,23,13,LEAVES:0)
Block(6,23,14,LEAVES:0)
Block(6,24,7,LEAVES:0)
Block(6,24,9,LEAVES:0)
Block(6,24,11,LEAVES:0)
Block(6,24,12,LEAVES:0)
Block(6,24,13,LEAVES:0)
Block(6,25,7,LEAVES:0)
Block(6,25,8,LEAVES:0)
Block(6,25,9,LEAVES:0)
Block(6,25,10,LEAVES:0)
Block(6,25,11,LEAVES:0)
Block(6,25,12,LEAVES:0)
Block(6,26,10,LEAVES:0)
Block(6,26,11,LEAVES:0)
Block(7,-3,3,LOG)
Block(7,-2,3,LOG)
Block(7,-2,4,LOG)
Block(7,-2,7,LOG)
Block(7,-1,-6,LOG)
Block(7,-1,-5,LOG)
Block(7,0,5,LOG)
Block(7,0,6,LOG)
Block(7,1,5,LOG)
Block(7,18,10,LEAVES:0)
Block(7,18,14,LEAVES:0)
Block(7,19,12,LEAVES:0)
Block(7,19,14,LEAVES:0)
Block(7,20,11,LEAVES:0)
Block(7,20,12,LEAVES:0)
Block(7,20,13,LEAVES:0)
Block(7,20,14,LEAVES:0)
Block(7,21,10,LEAVES:0)
Block(7,21,11,LEAVES:0)
Block(7,21,12,LEAVES:0)
Block(7,21,13,LEAVES:0)
Block(7,22,11,LEAVES:0)
Block(7,22,12,LEAVES:0)
Block(7,22,13,LEAVES:0)
Block(7,23,10,LEAVES:0)
Block(7,23,12,LEAVES:0)
Block(7,24,12,LEAVES:0)
Block(7,25,10,LEAVES:0)
Block(7,25,11,LEAVES:0)
Block(8,-3,3,LOG)
Block(8,-3,7,LOG)
Block(8,-2,7,LOG)
Block(8,20,13,LEAVES:0)
Block(8,20,14,LEAVES:0)
Block(8,21,11,LEAVES:0)
Block(8,21,13,LEAVES:0)
Block(8,22,12,LEAVES:0)

#######################################################################
# +-----------------------------------------------------------------+ #
# |                            BO3 checks                           | #
# +-----------------------------------------------------------------+ #
#######################################################################

BlockCheck(0,-1,0,GRASS)

#######################################################################
# +-----------------------------------------------------------------+ #
# |                             Branches                            | #
# +-----------------------------------------------------------------+ #
#######################################################################


#######################################################################
# +-----------------------------------------------------------------+ #
# |                             Entities                            | #
# +-----------------------------------------------------------------+ #
#######################################################################


#######################################################################
# +-----------------------------------------------------------------+ #
# |                            Particles                            | #
# +-----------------------------------------------------------------+ #
#######################################################################


#######################################################################
# +-----------------------------------------------------------------+ #
# |                             Spawners                            | #
# +-----------------------------------------------------------------+ #
#######################################################################


#######################################################################
# +-----------------------------------------------------------------+ #
# |                             ModData                             | #
# +-----------------------------------------------------------------+ #
#######################################################################

