
#######################################################################
# +-----------------------------------------------------------------+ #
# |                            BO3 object                           | #
# +-----------------------------------------------------------------+ #
#######################################################################

Author: Unknown

Description: Converted version of the BO2 OakForestLarge1

Version: 3

SettingsMode: WriteWithoutComments


#######################################################################
# +-----------------------------------------------------------------+ #
# |                          Main settings                          | #
# +-----------------------------------------------------------------+ #
#######################################################################

Tree: true

Frequency: 1

Rarity: 10.0

RotateRandomly: true

SpawnHeight: highestSolidBlock

SpawnHeightOffset: 0

SpawnHeightVariance: 0

##############################
# Height Limits for the BO3. #
##############################

MinHeight: 62

MaxHeight: 210

######################
# Extrusion settings #
######################

ExtrudeMode: None

ExtrudeThroughBlocks: AIR

MaxBranchDepth: 10

ExcludedBiomes: All


#######################################################################
# +-----------------------------------------------------------------+ #
# |                      Source block settings                      | #
# +-----------------------------------------------------------------+ #
#######################################################################

SourceBlocks: STONE:1,STONE:3,STONE:5,DIRT:1,DIRT,SAND,GRASS,DIRT:2,STATIONARY_WATER,HARD_CLAY,STAINED_CLAY,CLAY,SANDSTONE,SAND:1,AIR,STONE,GRAVEL,LONG_GRASS,LONG_GRASS:1,LONG_GRASS:2,DEAD_BUSH,YELLOW_FLOWER,RED_ROSE,BROWN_MUSHROOM,RED_MUSHROOM

MaxPercentageOutsideSourceBlock: 0

OutsideSourceBlock: placeAnyway

IsOTGPlus: false

InheritBO3: 

InheritBO3Rotation: NORTH

OverrideChildSettings: true

OverrideParentHeight: false

CanOverride: false

BranchFrequency: 0

BranchFrequencyGroup: 

MustBeBelowOther: false

MustBeInside: 

CannotBeInside: 

ReplacesBO3: 

CanSpawnOnWater: true

SpawnOnWaterOnly: false

SpawnUnderWater: false

SpawnAtWaterLevel: false

HeightOffset: 0

RemoveAir: true

ReplaceAbove: 

ReplaceBelow: 

ReplaceWithBiomeBlocks: true

ReplaceWithGroundBlock: DIRT

ReplaceWithSurfaceBlock: GRASS

SmoothRadius: 0

SmoothHeightOffset: 0

SmoothStartTop: false

SmoothStartWood: false

SmoothingSurfaceBlock: 

SmoothingGroundBlock: 

BO3Group: 

IsSpawnPoint: false


#######################################################################
# +-----------------------------------------------------------------+ #
# |                              Blocks                             | #
# +-----------------------------------------------------------------+ #
#######################################################################

Block(-4,9,2,LEAVES:0)
Block(-4,8,2,LOG)
Block(-4,7,2,LEAVES:0)
Block(5,10,2,LEAVES:0)
Block(6,9,1,LEAVES:0)
Block(2,10,4,LEAVES:0)
Block(6,8,1,LEAVES:0)
Block(6,7,1,LEAVES:0)
Block(1,8,-4,LEAVES:0)
Block(1,6,-4,LEAVES:0)
Block(1,7,-4,LEAVES:0)
Block(-3,10,2,LEAVES:0)
Block(-4,10,-1,LEAVES:0)
Block(-3,13,2,LEAVES:0)
Block(-1,10,7,LEAVES:0)
Block(-2,11,-3,LEAVES:0)
Block(-2,10,-3,LEAVES:0)
Block(1,10,1,LEAVES:0)
Block(-3,7,-2,LEAVES:0)
Block(1,11,1,LEAVES:0)
Block(-3,8,-2,LEAVES:0)
Block(1,12,1,LEAVES:0)
Block(-3,9,-2,LOG)
Block(1,13,1,LEAVES:0)
Block(1,14,1,LEAVES:0)
Block(1,15,1,LEAVES:0)
Block(1,16,1,LEAVES:0)
Block(-4,9,1,LEAVES:0)
Block(-4,8,1,LEAVES:0)
Block(1,15,-1,LEAVES:0)
Block(6,7,0,LEAVES:0)
Block(-2,10,-4,LEAVES:0)
Block(6,9,0,LEAVES:0)
Block(-4,7,1,LEAVES:0)
Block(4,7,-6,LEAVES:0)
Block(1,7,-3,LEAVES:0)
Block(1,5,-3,LEAVES:0)
Block(-3,8,3,LEAVES:0)
Block(1,10,2,LEAVES:0)
Block(1,6,-3,LOG)
Block(-3,9,3,LEAVES:0)
Block(1,13,2,LEAVES:0)
Block(1,13,-1,LEAVES:0)
Block(1,14,2,LOG)
Block(1,12,-1,LEAVES:0)
Block(1,15,2,LEAVES:0)
Block(1,11,-1,LEAVES:0)
Block(1,10,-1,LEAVES:0)
Block(5,11,1,LEAVES:0)
Block(5,10,1,LEAVES:0)
Block(-2,9,5,LEAVES:0)
Block(-5,9,0,LEAVES:0)
Block(-5,8,0,LEAVES:0)
Block(-3,7,-1,LEAVES:0)
Block(-3,8,-1,LEAVES:0)
Block(-3,9,-1,LEAVES:0)
Block(0,5,0,LEAVES:0)
Block(0,4,0,LOG:8)
Block(0,7,0,LEAVES:0)
Block(0,6,0,LOG)
Block(-4,9,4,LEAVES:0)
Block(-2,13,0,LEAVES:0)
Block(-2,12,0,LEAVES:0)
Block(-2,15,0,LEAVES:0)
Block(-2,14,0,LEAVES:0)
Block(1,6,-2,LEAVES:0)
Block(1,7,-2,LEAVES:0)
Block(4,7,-5,LEAVES:0)
Block(1,5,-2,LEAVES:0)
Block(0,7,-6,LEAVES:0)
Block(-4,8,-1,LEAVES:0)
Block(-4,10,-3,LEAVES:0)
Block(2,14,3,LEAVES:0)
Block(-4,9,-1,LEAVES:0)
Block(-4,10,3,LEAVES:0)
Block(4,10,0,LEAVES:0)
Block(-5,8,1,LEAVES:0)
Block(-5,9,1,LEAVES:0)
Block(0,8,1,LOG)
Block(0,7,1,LOG)
Block(2,7,-1,LEAVES:0)
Block(0,9,1,LOG)
Block(-6,10,1,LEAVES:0)
Block(-4,9,3,LEAVES:0)
Block(-4,8,3,LEAVES:0)
Block(5,10,0,LEAVES:0)
Block(2,14,2,LEAVES:0)
Block(-1,11,6,LEAVES:0)
Block(-1,10,6,LEAVES:0)
Block(4,10,1,LEAVES:0)
Block(4,11,1,LEAVES:0)
Block(2,15,2,LEAVES:0)
Block(1,7,-1,LEAVES:0)
Block(1,5,-1,LEAVES:0)
Block(1,6,-1,LEAVES:0)
Block(4,7,-4,LEAVES:0)
Block(1,4,-1,LEAVES:0)
Block(-6,10,2,LEAVES:0)
Block(-6,9,0,LEAVES:0)
Block(-5,9,2,LOG)
Block(1,10,3,LEAVES:0)
Block(-5,8,2,LEAVES:0)
Block(1,14,3,LEAVES:0)
Block(0,9,0,LEAVES:0)
Block(0,8,0,LEAVES:0)
Block(1,15,3,LEAVES:0)
Block(2,6,-2,LEAVES:0)
Block(0,6,-4,LEAVES:0)
Block(0,7,-4,LEAVES:0)
Block(-4,11,2,LEAVES:0)
Block(-4,10,2,LEAVES:0)
Block(0,15,1,LOG)
Block(-2,9,-3,LOG)
Block(0,14,1,LOG)
Block(-2,8,-3,LEAVES:0)
Block(1,11,4,LEAVES:0)
Block(0,13,1,LOG)
Block(-2,7,-3,LEAVES:0)
Block(1,10,4,LEAVES:0)
Block(0,12,1,LOG)
Block(0,17,1,LEAVES:0)
Block(0,16,1,LEAVES:0)
Block(0,11,1,LOG)
Block(0,10,1,LOG)
Block(-6,9,1,LEAVES:0)
Block(-4,9,-3,LEAVES:0)
Block(-5,8,3,LEAVES:0)
Block(-1,10,-2,LEAVES:0)
Block(4,7,2,LEAVES:0)
Block(-5,9,3,LEAVES:0)
Block(4,9,2,LEAVES:0)
Block(4,8,2,LEAVES:0)
Block(2,7,-3,LEAVES:0)
Block(2,6,-3,LEAVES:0)
Block(5,9,0,LEAVES:0)
Block(5,8,0,LEAVES:0)
Block(5,7,0,LEAVES:0)
Block(2,8,-3,LEAVES:0)
Block(0,7,-5,LEAVES:0)
Block(7,9,2,LEAVES:0)
Block(-2,10,-1,LEAVES:0)
Block(-2,8,-4,LEAVES:0)
Block(-2,9,-4,LEAVES:0)
Block(2,10,1,LEAVES:0)
Block(-4,9,-2,LEAVES:0)
Block(-4,8,-2,LEAVES:0)
Block(-2,14,1,LEAVES:0)
Block(-1,15,-1,LEAVES:0)
Block(-2,13,1,LOG)
Block(-6,9,2,LEAVES:0)
Block(-2,15,1,LEAVES:0)
Block(2,15,1,LEAVES:0)
Block(-1,12,-1,LEAVES:0)
Block(2,14,1,LEAVES:0)
Block(-2,12,1,LEAVES:0)
Block(-2,11,1,LEAVES:0)
Block(0,14,0,LEAVES:0)
Block(0,13,0,LEAVES:0)
Block(0,12,0,LEAVES:0)
Block(0,11,0,LEAVES:0)
Block(-5,9,4,LEAVES:0)
Block(4,8,3,LEAVES:0)
Block(0,16,0,LEAVES:0)
Block(4,7,3,LEAVES:0)
Block(0,15,0,LEAVES:0)
Block(2,6,-4,LEAVES:0)
Block(5,9,1,LOG)
Block(5,8,1,LEAVES:0)
Block(4,9,3,LEAVES:0)
Block(5,7,1,LEAVES:0)
Block(0,10,0,LEAVES:0)
Block(2,9,-4,LEAVES:0)
Block(2,8,-4,LEAVES:0)
Block(2,7,-4,LOG)
Block(3,7,-1,LEAVES:0)
Block(2,10,0,LEAVES:0)
Block(0,6,-2,LEAVES:0)
Block(2,11,0,LEAVES:0)
Block(0,5,-2,LOG)
Block(2,12,0,LEAVES:0)
Block(0,7,-2,LEAVES:0)
Block(0,9,-2,LEAVES:0)
Block(6,9,3,LEAVES:0)
Block(-2,10,-2,LEAVES:0)
Block(2,15,0,LEAVES:0)
Block(-1,10,-3,LEAVES:0)
Block(7,9,1,LEAVES:0)
Block(7,8,1,LEAVES:0)
Block(-2,9,-1,LEAVES:0)
Block(-7,9,1,LEAVES:0)
Block(-2,8,-1,LEAVES:0)
Block(-2,7,-1,LEAVES:0)
Block(-2,6,-1,LEAVES:0)
Block(-6,9,3,LEAVES:0)
Block(1,11,5,LEAVES:0)
Block(1,10,5,LEAVES:0)
Block(5,7,-1,LEAVES:0)
Block(0,13,2,LEAVES:0)
Block(0,14,2,LEAVES:0)
Block(0,15,2,LEAVES:0)
Block(5,9,2,LEAVES:0)
Block(0,16,2,LEAVES:0)
Block(5,8,2,LEAVES:0)
Block(5,7,2,LEAVES:0)
Block(-3,10,-1,LEAVES:0)
Block(0,10,2,LEAVES:0)
Block(5,9,-1,LEAVES:0)
Block(0,11,2,LEAVES:0)
Block(0,12,2,LEAVES:0)
Block(2,9,-5,LEAVES:0)
Block(2,8,-5,LEAVES:0)
Block(2,7,-5,LOG)
Block(-4,10,-2,LEAVES:0)
Block(2,6,-5,LEAVES:0)
Block(0,5,-3,LEAVES:0)
Block(0,7,-3,LEAVES:0)
Block(6,9,2,LEAVES:0)
Block(0,6,-3,LEAVES:0)
Block(6,8,2,LEAVES:0)
Block(0,9,-3,LEAVES:0)
Block(6,7,2,LEAVES:0)
Block(-2,14,2,LEAVES:0)
Block(-2,15,2,LEAVES:0)
Block(-2,12,2,LEAVES:0)
Block(-2,13,2,LEAVES:0)
Block(-2,9,-2,LEAVES:0)
Block(1,10,6,LEAVES:0)
Block(-2,8,-2,LOG)
Block(7,9,0,LEAVES:0)
Block(1,11,6,LEAVES:0)
Block(-4,13,1,LEAVES:0)
Block(-7,9,2,LEAVES:0)
Block(-2,7,-2,LEAVES:0)
Block(-4,10,1,LEAVES:0)
Block(-6,9,4,LEAVES:0)
Block(5,9,3,LEAVES:0)
Block(5,8,3,LEAVES:0)
Block(5,7,3,LEAVES:0)
Block(2,8,-6,LEAVES:0)
Block(2,7,-6,LEAVES:0)
Block(2,6,-6,LEAVES:0)
Block(1,9,4,LEAVES:0)
Block(3,7,-3,LEAVES:0)
Block(2,9,2,LEAVES:0)
Block(-1,16,1,LEAVES:0)
Block(2,8,2,LEAVES:0)
Block(2,7,2,LEAVES:0)
Block(2,6,2,LEAVES:0)
Block(-3,11,-2,LEAVES:0)
Block(-3,10,-2,LEAVES:0)
Block(-1,10,1,LEAVES:0)
Block(-7,9,3,LEAVES:0)
Block(-1,11,1,LEAVES:0)
Block(-5,9,-2,LEAVES:0)
Block(-1,12,1,LOG)
Block(-1,13,1,LEAVES:0)
Block(-1,14,1,LEAVES:0)
Block(-1,15,1,LEAVES:0)
Block(-1,5,0,LEAVES:0)
Block(3,7,0,LEAVES:0)
Block(3,6,0,LEAVES:0)
Block(-1,7,0,LEAVES:0)
Block(-1,6,0,LEAVES:0)
Block(-1,9,0,LEAVES:0)
Block(-1,8,0,LEAVES:0)
Block(3,9,0,LEAVES:0)
Block(-1,9,-3,LEAVES:0)
Block(-1,8,-3,LEAVES:0)
Block(-1,7,-3,LEAVES:0)
Block(-1,6,-3,LEAVES:0)
Block(-5,10,2,LEAVES:0)
Block(-5,11,2,LEAVES:0)
Block(2,7,-7,LEAVES:0)
Block(0,5,-1,LEAVES:0)
Block(1,9,5,LEAVES:0)
Block(0,4,-1,LOG:8)
Block(0,7,-1,LEAVES:0)
Block(0,6,-1,LEAVES:0)
Block(-3,10,-3,LEAVES:0)
Block(2,8,3,LEAVES:0)
Block(2,7,3,LEAVES:0)
Block(0,14,3,LEAVES:0)
Block(0,15,3,LEAVES:0)
Block(0,10,3,LEAVES:0)
Block(0,11,3,LEAVES:0)
Block(-1,6,-2,LEAVES:0)
Block(3,7,1,LOG)
Block(-1,5,-2,LEAVES:0)
Block(3,6,1,LEAVES:0)
Block(0,15,-1,LEAVES:0)
Block(3,9,1,LEAVES:0)
Block(3,8,1,LEAVES:0)
Block(-1,9,-2,LEAVES:0)
Block(-1,8,-2,LEAVES:0)
Block(-1,7,-2,LEAVES:0)
Block(-1,10,-4,LEAVES:0)
Block(-2,10,4,LEAVES:0)
Block(6,10,0,LEAVES:0)
Block(-1,12,2,LEAVES:0)
Block(0,12,-1,LEAVES:0)
Block(-1,14,2,LEAVES:0)
Block(0,11,-1,LEAVES:0)
Block(-1,13,2,LEAVES:0)
Block(0,9,6,LEAVES:0)
Block(-1,16,2,LEAVES:0)
Block(0,13,-1,LEAVES:0)
Block(-1,15,2,LEAVES:0)
Block(3,6,-5,LEAVES:0)
Block(3,7,-5,LEAVES:0)
Block(3,8,-5,LEAVES:0)
Block(0,12,5,LEAVES:0)
Block(0,11,5,LEAVES:0)
Block(0,10,5,LOG)
Block(3,6,2,LEAVES:0)
Block(-1,7,2,LEAVES:0)
Block(-3,10,-4,LEAVES:0)
Block(3,9,2,LEAVES:0)
Block(3,8,2,LEAVES:0)
Block(-1,9,2,LEAVES:0)
Block(3,7,2,LEAVES:0)
Block(-1,8,2,LEAVES:0)
Block(-2,9,0,LEAVES:0)
Block(-2,8,0,LEAVES:0)
Block(-2,7,0,LEAVES:0)
Block(-2,6,0,LEAVES:0)
Block(-1,15,0,LEAVES:0)
Block(4,7,0,LEAVES:0)
Block(-2,10,6,LEAVES:0)
Block(4,9,0,LEAVES:0)
Block(4,8,0,LEAVES:0)
Block(-1,11,0,LEAVES:0)
Block(-1,12,0,LEAVES:0)
Block(-1,13,0,LEAVES:0)
Block(3,6,-4,LEAVES:0)
Block(3,7,-4,LEAVES:0)
Block(3,8,-4,LEAVES:0)
Block(-5,10,3,LEAVES:0)
Block(-2,10,5,LEAVES:0)
Block(3,10,1,LEAVES:0)
Block(-5,8,-1,LEAVES:0)
Block(-5,9,-1,LEAVES:0)
Block(-1,5,1,LOG:4)
Block(-1,8,1,LEAVES:0)
Block(-1,7,1,LEAVES:0)
Block(3,8,3,LEAVES:0)
Block(3,7,3,LEAVES:0)
Block(-1,9,1,LEAVES:0)
Block(-1,9,-4,LEAVES:0)
Block(4,6,1,LEAVES:0)
Block(4,8,1,LOG)
Block(4,7,1,LEAVES:0)
Block(4,9,1,LEAVES:0)
Block(0,11,4,LEAVES:0)
Block(0,12,4,LEAVES:0)
Block(0,10,4,LOG)
Block(1,9,0,LEAVES:0)
Block(-1,10,4,LEAVES:0)
Block(3,7,-7,LEAVES:0)
Block(1,7,0,LEAVES:0)
Block(2,10,-2,LEAVES:0)
Block(2,11,-2,LEAVES:0)
Block(-3,7,0,LEAVES:0)
Block(-3,9,0,LEAVES:0)
Block(-3,8,0,LEAVES:0)
Block(6,10,2,LEAVES:0)
Block(-2,9,2,LEAVES:0)
Block(-2,8,2,LEAVES:0)
Block(-1,9,4,LEAVES:0)
Block(-2,7,2,LEAVES:0)
Block(-1,8,4,LEAVES:0)
Block(0,8,3,LEAVES:0)
Block(-1,11,4,LEAVES:0)
Block(0,10,6,LEAVES:0)
Block(0,9,3,LOG)
Block(0,11,6,LEAVES:0)
Block(0,0,1,LOG)
Block(6,9,-1,LEAVES:0)
Block(0,2,1,LOG)
Block(0,1,1,LOG)
Block(0,4,1,LOG)
Block(3,6,-6,LEAVES:0)
Block(1,9,1,LEAVES:0)
Block(0,3,1,LOG)
Block(3,7,-6,LEAVES:0)
Block(1,8,1,LEAVES:0)
Block(0,6,1,LOG)
Block(1,7,1,LEAVES:0)
Block(3,8,-6,LEAVES:0)
Block(0,5,1,LOG)
Block(1,6,1,LOG:4)
Block(1,7,-7,LEAVES:0)
Block(-1,10,5,LEAVES:0)
Block(-1,11,5,LEAVES:0)
Block(-1,8,3,LEAVES:0)
Block(-3,13,0,LEAVES:0)
Block(-3,14,0,LEAVES:0)
Block(-2,9,1,LEAVES:0)
Block(-2,8,1,LEAVES:0)
Block(-1,9,3,LEAVES:0)
Block(-2,7,1,LEAVES:0)
Block(-2,6,1,LOG)
Block(4,10,2,LEAVES:0)
Block(1,6,0,LEAVES:0)
Block(0,7,2,LEAVES:0)
Block(-6,10,3,LEAVES:0)
Block(0,9,2,LEAVES:0)
Block(0,8,2,LOG:8)
Block(3,10,0,LEAVES:0)
Block(-4,9,0,LEAVES:0)
Block(1,9,2,LEAVES:0)
Block(1,8,2,LEAVES:0)
Block(1,7,2,LEAVES:0)
Block(1,6,2,LEAVES:0)
Block(-4,8,0,LEAVES:0)
Block(-4,7,0,LEAVES:0)
Block(1,8,-6,LEAVES:0)
Block(1,6,-6,LEAVES:0)
Block(1,7,-6,LEAVES:0)
Block(-5,10,1,LEAVES:0)
Block(2,7,0,LEAVES:0)
Block(4,9,-1,LEAVES:0)
Block(-3,9,2,LEAVES:0)
Block(2,6,0,LEAVES:0)
Block(-3,8,2,LEAVES:0)
Block(2,9,0,LEAVES:0)
Block(2,8,0,LEAVES:0)
Block(6,10,1,LEAVES:0)
Block(4,7,-1,LEAVES:0)
Block(-3,7,2,LEAVES:0)
Block(-1,7,-1,LOG)
Block(-1,6,-1,LEAVES:0)
Block(-1,5,-1,LEAVES:0)
Block(1,16,0,LEAVES:0)
Block(1,15,0,LEAVES:0)
Block(1,13,0,LEAVES:0)
Block(1,12,0,LEAVES:0)
Block(1,11,0,LEAVES:0)
Block(1,10,0,LOG)
Block(-1,9,6,LEAVES:0)
Block(-1,8,-1,LEAVES:0)
Block(2,10,-1,LEAVES:0)
Block(2,12,-1,LEAVES:0)
Block(2,11,-1,LOG)
Block(-3,9,-4,LEAVES:0)
Block(0,10,-3,LEAVES:0)
Block(0,8,5,LEAVES:0)
Block(0,9,5,LEAVES:0)
Block(-3,12,1,LEAVES:0)
Block(-3,13,1,LEAVES:0)
Block(1,9,3,LEAVES:0)
Block(1,8,3,LEAVES:0)
Block(1,7,3,LEAVES:0)
Block(-3,14,1,LEAVES:0)
Block(1,7,-5,LEAVES:0)
Block(1,8,-5,LEAVES:0)
Block(2,9,1,LEAVES:0)
Block(1,6,-5,LEAVES:0)
Block(2,6,1,LOG:4)
Block(-3,9,1,LEAVES:0)
Block(2,8,1,LEAVES:0)
Block(2,7,1,LEAVES:0)
Block(-1,10,3,LEAVES:0)
Block(-3,8,1,LEAVES:0)
Block(-1,13,3,LEAVES:0)
Block(-3,7,1,LOG)
Block(-1,12,3,LEAVES:0)
Block(-1,14,3,LEAVES:0)
Block(0,10,7,LEAVES:0)
Block(2,10,5,LEAVES:0)
Block(3,10,-1,LEAVES:0)
Block(-1,9,5,LEAVES:0)
Block(3,11,-1,LEAVES:0)
Block(1,11,-2,LEAVES:0)
Block(-3,8,-3,LEAVES:0)
Block(-3,9,-3,LEAVES:0)
Block(0,9,4,LEAVES:0)
Block(0,8,4,LEAVES:0)

#######################################################################
# +-----------------------------------------------------------------+ #
# |                            BO3 checks                           | #
# +-----------------------------------------------------------------+ #
#######################################################################

BlockCheck(0,-1,1,GRASS,DIRT,DIRT:2)

#######################################################################
# +-----------------------------------------------------------------+ #
# |                             Branches                            | #
# +-----------------------------------------------------------------+ #
#######################################################################


#######################################################################
# +-----------------------------------------------------------------+ #
# |                             Entities                            | #
# +-----------------------------------------------------------------+ #
#######################################################################


#######################################################################
# +-----------------------------------------------------------------+ #
# |                            Particles                            | #
# +-----------------------------------------------------------------+ #
#######################################################################


#######################################################################
# +-----------------------------------------------------------------+ #
# |                             Spawners                            | #
# +-----------------------------------------------------------------+ #
#######################################################################


#######################################################################
# +-----------------------------------------------------------------+ #
# |                             ModData                             | #
# +-----------------------------------------------------------------+ #
#######################################################################

