
#######################################################################
# +-----------------------------------------------------------------+ #
# |                            BO3 object                           | #
# +-----------------------------------------------------------------+ #
#######################################################################

Author: LordSmellyPants

Description: No description given

Version: 3

SettingsMode: WriteWithoutComments


#######################################################################
# +-----------------------------------------------------------------+ #
# |                          Main settings                          | #
# +-----------------------------------------------------------------+ #
#######################################################################

Tree: true

Frequency: 1

Rarity: 25.0

RotateRandomly: true

SpawnHeight: highestSolidBlock

SpawnHeightOffset: 0

SpawnHeightVariance: 0

##############################
# Height Limits for the BO3. #
##############################

MinHeight: 61

MaxHeight: 111

######################
# Extrusion settings #
######################

ExtrudeMode: None

ExtrudeThroughBlocks: AIR

MaxBranchDepth: 10

ExcludedBiomes: All


#######################################################################
# +-----------------------------------------------------------------+ #
# |                      Source block settings                      | #
# +-----------------------------------------------------------------+ #
#######################################################################

SourceBlocks: STONE:1,STONE:3,STONE:5,DIRT:1,DIRT,SAND,GRASS,DIRT:2,STATIONARY_WATER,HARD_CLAY,STAINED_CLAY,CLAY,SANDSTONE,SAND:1,AIR,STONE,GRAVEL,LONG_GRASS,LONG_GRASS:1,LONG_GRASS:2,DEAD_BUSH,YELLOW_FLOWER,RED_ROSE,BROWN_MUSHROOM,RED_MUSHROOM

MaxPercentageOutsideSourceBlock: 0

OutsideSourceBlock: placeAnyway

IsOTGPlus: false

InheritBO3: 

InheritBO3Rotation: NORTH

OverrideChildSettings: true

OverrideParentHeight: false

CanOverride: false

BranchFrequency: 0

BranchFrequencyGroup: 

MustBeBelowOther: false

MustBeInside: 

CannotBeInside: 

ReplacesBO3: 

CanSpawnOnWater: true

SpawnOnWaterOnly: false

SpawnUnderWater: false

SpawnAtWaterLevel: false

HeightOffset: 0

RemoveAir: true

ReplaceAbove: 

ReplaceBelow: 

ReplaceWithBiomeBlocks: true

ReplaceWithGroundBlock: DIRT

ReplaceWithSurfaceBlock: GRASS

SmoothRadius: 0

SmoothHeightOffset: 0

SmoothStartTop: false

SmoothStartWood: false

SmoothingSurfaceBlock: 

SmoothingGroundBlock: 

BO3Group: 

IsSpawnPoint: false


#######################################################################
# +-----------------------------------------------------------------+ #
# |                              Blocks                             | #
# +-----------------------------------------------------------------+ #
#######################################################################

Block(-12,7,-2,LEAVES:0)
Block(-12,8,0,LEAVES:0)
Block(-12,8,2,LEAVES:0)
Block(-12,9,-4,LEAVES:0)
Block(-12,9,-1,LEAVES:0)
Block(-12,10,-3,LEAVES:0)
Block(-11,6,1,LEAVES:0)
Block(-11,7,-3,LEAVES:0)
Block(-11,7,-2,LEAVES:0)
Block(-11,7,-1,LEAVES:0)
Block(-11,7,3,LEAVES:0)
Block(-11,8,-3,LEAVES:0)
Block(-11,8,0,LEAVES:0)
Block(-11,8,1,LEAVES:0)
Block(-11,8,2,LEAVES:0)
Block(-11,8,3,LEAVES:0)
Block(-11,9,-5,LEAVES:0)
Block(-11,9,-4,LEAVES:0)
Block(-11,9,-3,LEAVES:0)
Block(-11,9,-2,LOG)
Block(-11,9,-1,LEAVES:0)
Block(-11,9,0,LEAVES:0)
Block(-11,9,1,LEAVES:0)
Block(-11,9,2,LEAVES:0)
Block(-11,10,-4,LEAVES:0)
Block(-11,10,-3,LEAVES:0)
Block(-11,10,-2,LEAVES:0)
Block(-11,10,-1,LEAVES:0)
Block(-11,11,-3,LEAVES:0)
Block(-11,11,2,LEAVES:0)
Block(-11,13,0,LEAVES:0)
Block(-11,14,-1,LEAVES:0)
Block(-10,5,3,LEAVES:0)
Block(-10,6,-2,LEAVES:0)
Block(-10,6,-1,LEAVES:0)
Block(-10,6,0,LEAVES:0)
Block(-10,6,1,LEAVES:0)
Block(-10,6,2,LEAVES:0)
Block(-10,7,-3,LEAVES:0)
Block(-10,7,-2,LEAVES:0)
Block(-10,7,-1,LEAVES:0)
Block(-10,7,0,LEAVES:0)
Block(-10,7,2,LEAVES:0)
Block(-10,8,-3,LEAVES:0)
Block(-10,8,-2,LEAVES:0)
Block(-10,8,-1,LOG)
Block(-10,8,0,LEAVES:0)
Block(-10,8,1,LEAVES:0)
Block(-10,8,2,LEAVES:0)
Block(-10,9,-4,LEAVES:0)
Block(-10,9,-3,LEAVES:0)
Block(-10,9,-2,LEAVES:0)
Block(-10,9,-1,LEAVES:0)
Block(-10,9,1,LEAVES:0)
Block(-10,9,2,LEAVES:0)
Block(-10,9,4,LEAVES:0)
Block(-10,10,-3,LEAVES:0)
Block(-10,10,-1,LEAVES:0)
Block(-10,10,1,LEAVES:0)
Block(-10,10,2,LEAVES:0)
Block(-10,11,0,LEAVES:0)
Block(-10,11,1,LEAVES:0)
Block(-10,12,-4,LEAVES:0)
Block(-10,12,-1,LEAVES:0)
Block(-10,13,-1,LEAVES:0)
Block(-10,13,0,LEAVES:0)
Block(-10,13,1,LEAVES:0)
Block(-10,14,-2,LEAVES:0)
Block(-9,4,0,LEAVES:0)
Block(-9,4,2,LEAVES:0)
Block(-9,4,4,LEAVES:0)
Block(-9,5,0,LEAVES:0)
Block(-9,5,3,LEAVES:0)
Block(-9,6,1,LEAVES:0)
Block(-9,6,2,LEAVES:0)
Block(-9,6,3,LEAVES:0)
Block(-9,6,4,LEAVES:0)
Block(-9,7,-1,LEAVES:0)
Block(-9,7,0,LEAVES:0)
Block(-9,7,2,LEAVES:0)
Block(-9,8,-2,LEAVES:0)
Block(-9,8,0,LOG)
Block(-9,8,1,LEAVES:0)
Block(-9,8,2,LEAVES:0)
Block(-9,9,-5,LEAVES:0)
Block(-9,9,-4,LEAVES:0)
Block(-9,9,-2,LEAVES:0)
Block(-9,9,-1,LEAVES:0)
Block(-9,9,0,LEAVES:0)
Block(-9,9,1,LEAVES:0)
Block(-9,9,3,LEAVES:0)
Block(-9,10,-4,LEAVES:0)
Block(-9,10,0,LEAVES:0)
Block(-9,10,1,LEAVES:0)
Block(-9,10,2,LEAVES:0)
Block(-9,11,-4,LEAVES:0)
Block(-9,11,3,LEAVES:0)
Block(-9,12,-3,LEAVES:0)
Block(-9,12,-2,LEAVES:0)
Block(-9,12,-1,LEAVES:0)
Block(-9,12,0,LEAVES:0)
Block(-9,12,1,LOG)
Block(-9,12,2,LEAVES:0)
Block(-9,13,-3,LEAVES:0)
Block(-9,13,-2,LEAVES:0)
Block(-9,13,0,LOG)
Block(-9,13,1,LEAVES:0)
Block(-9,13,2,LEAVES:0)
Block(-9,13,3,LEAVES:0)
Block(-9,14,-3,LEAVES:0)
Block(-9,14,-2,LEAVES:0)
Block(-9,14,0,LEAVES:0)
Block(-9,14,1,LEAVES:0)
Block(-9,14,2,LEAVES:0)
Block(-9,15,-3,LEAVES:0)
Block(-9,15,-2,LEAVES:0)
Block(-9,15,1,LEAVES:0)
Block(-9,16,-3,LEAVES:0)
Block(-8,4,-1,LEAVES:0)
Block(-8,4,0,LEAVES:0)
Block(-8,4,1,LEAVES:0)
Block(-8,4,2,LEAVES:0)
Block(-8,4,4,LEAVES:0)
Block(-8,5,0,LEAVES:0)
Block(-8,5,1,LEAVES:0)
Block(-8,5,2,LOG)
Block(-8,5,4,LEAVES:0)
Block(-8,6,3,LEAVES:0)
Block(-8,8,-6,LEAVES:0)
Block(-8,8,-4,LEAVES:0)
Block(-8,8,-3,LEAVES:0)
Block(-8,8,-2,LEAVES:0)
Block(-8,8,0,LOG)
Block(-8,8,2,LEAVES:0)
Block(-8,8,3,LEAVES:0)
Block(-8,8,4,LEAVES:0)
Block(-8,9,-5,LEAVES:0)
Block(-8,9,0,LOG)
Block(-8,10,-3,LEAVES:0)
Block(-8,10,0,LEAVES:0)
Block(-8,10,1,LEAVES:0)
Block(-8,10,3,LEAVES:0)
Block(-8,11,-4,LEAVES:0)
Block(-8,11,-1,LEAVES:0)
Block(-8,11,1,LEAVES:0)
Block(-8,11,2,LOG)
Block(-8,11,3,LEAVES:0)
Block(-8,11,4,LEAVES:0)
Block(-8,12,-6,LEAVES:0)
Block(-8,12,-5,LEAVES:0)
Block(-8,12,-3,LEAVES:0)
Block(-8,12,-1,LEAVES:0)
Block(-8,12,0,LEAVES:0)
Block(-8,12,1,LEAVES:0)
Block(-8,13,-7,LEAVES:0)
Block(-8,13,-4,LEAVES:0)
Block(-8,13,0,LEAVES:0)
Block(-8,13,2,LEAVES:0)
Block(-8,13,3,LEAVES:0)
Block(-8,13,4,LEAVES:0)
Block(-8,14,-6,LEAVES:0)
Block(-8,14,-4,LEAVES:0)
Block(-8,14,-2,LEAVES:0)
Block(-8,14,-1,LEAVES:0)
Block(-8,14,0,LEAVES:0)
Block(-8,14,2,LEAVES:0)
Block(-8,15,-8,LEAVES:0)
Block(-8,15,-5,LEAVES:0)
Block(-8,15,-4,LEAVES:0)
Block(-8,15,-1,LEAVES:0)
Block(-8,15,1,LEAVES:0)
Block(-8,16,-6,LEAVES:0)
Block(-7,3,1,LEAVES:0)
Block(-7,4,0,LEAVES:0)
Block(-7,4,1,LEAVES:0)
Block(-7,4,2,LEAVES:0)
Block(-7,4,3,LEAVES:0)
Block(-7,4,4,LEAVES:0)
Block(-7,5,1,LEAVES:0)
Block(-7,5,2,LEAVES:0)
Block(-7,6,1,LEAVES:0)
Block(-7,6,2,LEAVES:0)
Block(-7,6,3,LOG)
Block(-7,6,4,LEAVES:0)
Block(-7,6,5,LEAVES:0)
Block(-7,7,-6,LEAVES:0)
Block(-7,7,-4,LEAVES:0)
Block(-7,7,0,LEAVES:0)
Block(-7,7,3,LEAVES:0)
Block(-7,8,-7,LEAVES:0)
Block(-7,8,-6,LEAVES:0)
Block(-7,8,-5,LEAVES:0)
Block(-7,8,0,LEAVES:0)
Block(-7,8,2,LEAVES:0)
Block(-7,8,3,LEAVES:0)
Block(-7,9,-5,LOG)
Block(-7,9,-4,LEAVES:0)
Block(-7,9,-3,LEAVES:0)
Block(-7,9,0,LOG)
Block(-7,9,1,LOG)
Block(-7,9,2,LEAVES:0)
Block(-7,10,-6,LEAVES:0)
Block(-7,10,-4,LEAVES:0)
Block(-7,10,1,LOG)
Block(-7,10,2,LOG)
Block(-7,10,3,LOG)
Block(-7,10,4,LEAVES:0)
Block(-7,11,-6,LEAVES:0)
Block(-7,11,-4,LEAVES:0)
Block(-7,11,-1,LEAVES:0)
Block(-7,11,1,LEAVES:0)
Block(-7,11,2,LEAVES:0)
Block(-7,11,5,LEAVES:0)
Block(-7,12,-5,LEAVES:0)
Block(-7,12,-4,LEAVES:0)
Block(-7,12,-3,LEAVES:0)
Block(-7,12,-2,LEAVES:0)
Block(-7,12,-1,LEAVES:0)
Block(-7,12,1,LEAVES:0)
Block(-7,13,-8,LEAVES:0)
Block(-7,13,-6,LEAVES:0)
Block(-7,13,-5,LEAVES:0)
Block(-7,13,-4,LEAVES:0)
Block(-7,13,-2,LEAVES:0)
Block(-7,13,1,LEAVES:0)
Block(-7,13,2,LEAVES:0)
Block(-7,13,3,LEAVES:0)
Block(-7,14,-9,LEAVES:0)
Block(-7,14,-8,LEAVES:0)
Block(-7,14,-7,LEAVES:0)
Block(-7,14,-6,LEAVES:0)
Block(-7,14,-5,LEAVES:0)
Block(-7,14,3,LEAVES:0)
Block(-7,15,-8,LEAVES:0)
Block(-7,15,-7,LEAVES:0)
Block(-7,15,-4,LEAVES:0)
Block(-7,15,-3,LEAVES:0)
Block(-7,16,-7,LEAVES:0)
Block(-7,16,-6,LEAVES:0)
Block(-7,16,-3,LEAVES:0)
Block(-6,4,1,LEAVES:0)
Block(-6,6,1,LEAVES:0)
Block(-6,6,2,LOG)
Block(-6,6,3,LEAVES:0)
Block(-6,6,4,LEAVES:0)
Block(-6,7,-5,LEAVES:0)
Block(-6,7,2,LOG)
Block(-6,8,-6,LEAVES:0)
Block(-6,8,0,LOG)
Block(-6,9,-6,LEAVES:0)
Block(-6,9,-4,LOG)
Block(-6,9,0,LOG)
Block(-6,9,3,LEAVES:0)
Block(-6,10,-6,LEAVES:0)
Block(-6,10,4,LEAVES:0)
Block(-6,10,5,LEAVES:0)
Block(-6,11,-3,LEAVES:0)
Block(-6,11,3,LEAVES:0)
Block(-6,11,4,LEAVES:0)
Block(-6,12,-7,LEAVES:0)
Block(-6,12,-3,LEAVES:0)
Block(-6,12,-2,LEAVES:0)
Block(-6,12,-1,LEAVES:0)
Block(-6,12,1,LEAVES:0)
Block(-6,12,2,LEAVES:0)
Block(-6,12,3,LEAVES:0)
Block(-6,12,4,LEAVES:0)
Block(-6,13,-7,LEAVES:0)
Block(-6,13,-5,LEAVES:0)
Block(-6,13,-4,LEAVES:0)
Block(-6,13,2,LEAVES:0)
Block(-6,13,4,LEAVES:0)
Block(-6,13,5,LEAVES:0)
Block(-6,14,-7,LEAVES:0)
Block(-6,14,-6,LEAVES:0)
Block(-6,14,-3,LEAVES:0)
Block(-6,14,1,LEAVES:0)
Block(-6,14,2,LEAVES:0)
Block(-6,15,-9,LEAVES:0)
Block(-6,15,-8,LEAVES:0)
Block(-6,15,-7,LEAVES:0)
Block(-6,15,-5,LEAVES:0)
Block(-6,15,-4,LEAVES:0)
Block(-6,15,-3,LEAVES:0)
Block(-6,15,-2,LEAVES:0)
Block(-6,15,2,LEAVES:0)
Block(-6,15,3,LEAVES:0)
Block(-6,16,-8,LEAVES:0)
Block(-6,16,-6,LEAVES:0)
Block(-6,16,-5,LEAVES:0)
Block(-6,17,-7,LEAVES:0)
Block(-5,6,3,LEAVES:0)
Block(-5,7,1,LOG)
Block(-5,7,2,LOG)
Block(-5,8,-4,LOG)
Block(-5,8,-3,LOG)
Block(-5,8,-1,LOG)
Block(-5,8,0,LOG)
Block(-5,8,1,LOG)
Block(-5,9,-5,LEAVES:0)
Block(-5,9,-1,LOG)
Block(-5,9,5,LEAVES:0)
Block(-5,10,-5,LEAVES:0)
Block(-5,10,3,LEAVES:0)
Block(-5,10,4,LEAVES:0)
Block(-5,10,5,LEAVES:0)
Block(-5,10,6,LEAVES:0)
Block(-5,11,3,LEAVES:0)
Block(-5,11,4,LEAVES:0)
Block(-5,11,5,LEAVES:0)
Block(-5,11,6,LEAVES:0)
Block(-5,12,4,LOG)
Block(-5,13,-11,LEAVES:0)
Block(-5,13,-7,LEAVES:0)
Block(-5,13,-6,LEAVES:0)
Block(-5,13,-5,LOG)
Block(-5,13,2,LEAVES:0)
Block(-5,13,3,LOG)
Block(-5,13,4,LEAVES:0)
Block(-5,13,5,LEAVES:0)
Block(-5,14,-10,LEAVES:0)
Block(-5,14,-9,LEAVES:0)
Block(-5,14,-7,LEAVES:0)
Block(-5,14,-6,LOG)
Block(-5,14,-5,LEAVES:0)
Block(-5,14,-4,LEAVES:0)
Block(-5,14,0,LEAVES:0)
Block(-5,14,1,LEAVES:0)
Block(-5,14,3,LEAVES:0)
Block(-5,15,-9,LEAVES:0)
Block(-5,15,-7,LOG)
Block(-5,15,-6,LEAVES:0)
Block(-5,15,-5,LEAVES:0)
Block(-5,15,-4,LEAVES:0)
Block(-5,15,-3,LEAVES:0)
Block(-5,15,0,LEAVES:0)
Block(-5,15,1,LEAVES:0)
Block(-5,15,3,LEAVES:0)
Block(-5,15,4,LEAVES:0)
Block(-5,16,-10,LEAVES:0)
Block(-5,16,-9,LEAVES:0)
Block(-5,16,-7,LEAVES:0)
Block(-5,16,-6,LEAVES:0)
Block(-5,16,-5,LEAVES:0)
Block(-5,16,-4,LEAVES:0)
Block(-5,17,-7,LEAVES:0)
Block(-5,17,-6,LEAVES:0)
Block(-4,6,2,LOG)
Block(-4,7,1,LOG)
Block(-4,7,2,LOG)
Block(-4,8,-3,LOG)
Block(-4,8,-2,LOG)
Block(-4,8,2,LOG)
Block(-4,9,-2,LOG)
Block(-4,9,-1,LOG)
Block(-4,9,2,LOG)
Block(-4,9,3,LOG)
Block(-4,9,4,LEAVES:0)
Block(-4,10,-2,LOG)
Block(-4,10,2,LEAVES:0)
Block(-4,10,3,LOG)
Block(-4,10,4,LOG)
Block(-4,10,5,LEAVES:0)
Block(-4,11,2,LEAVES:0)
Block(-4,11,3,LEAVES:0)
Block(-4,11,4,LOG)
Block(-4,11,5,LEAVES:0)
Block(-4,11,6,LEAVES:0)
Block(-4,12,3,LEAVES:0)
Block(-4,12,4,LEAVES:0)
Block(-4,12,5,LEAVES:0)
Block(-4,12,6,LEAVES:0)
Block(-4,13,-12,LEAVES:0)
Block(-4,13,-11,LEAVES:0)
Block(-4,13,-10,LEAVES:0)
Block(-4,13,-5,LOG)
Block(-4,13,-4,LEAVES:0)
Block(-4,13,-1,LEAVES:0)
Block(-4,13,0,LEAVES:0)
Block(-4,13,4,LEAVES:0)
Block(-4,13,5,LEAVES:0)
Block(-4,13,6,LEAVES:0)
Block(-4,14,-10,LEAVES:0)
Block(-4,14,-4,LEAVES:0)
Block(-4,14,0,LEAVES:0)
Block(-4,14,1,LEAVES:0)
Block(-4,14,2,LEAVES:0)
Block(-4,14,3,LEAVES:0)
Block(-4,15,-10,LEAVES:0)
Block(-4,15,-9,LEAVES:0)
Block(-4,15,-7,LEAVES:0)
Block(-4,15,-6,LEAVES:0)
Block(-4,15,-5,LEAVES:0)
Block(-4,15,-4,LEAVES:0)
Block(-4,15,2,LEAVES:0)
Block(-4,16,-6,LEAVES:0)
Block(-4,16,-5,LEAVES:0)
Block(-4,17,-9,LEAVES:0)
Block(-4,17,-8,LEAVES:0)
Block(-4,17,-7,LEAVES:0)
Block(-4,17,-6,LEAVES:0)
Block(-4,17,-5,LEAVES:0)
Block(-4,18,-8,LEAVES:0)
Block(-4,18,-6,LEAVES:0)
Block(-3,5,0,LOG)
Block(-3,5,1,LOG)
Block(-3,6,0,LOG)
Block(-3,6,1,LOG)
Block(-3,6,2,LOG)
Block(-3,9,2,LEAVES:0)
Block(-3,9,5,LEAVES:0)
Block(-3,10,-2,LOG)
Block(-3,10,3,LEAVES:0)
Block(-3,10,5,LEAVES:0)
Block(-3,10,6,LEAVES:0)
Block(-3,11,-2,LOG)
Block(-3,11,1,LEAVES:0)
Block(-3,11,5,LEAVES:0)
Block(-3,12,-11,LEAVES:0)
Block(-3,12,-9,LEAVES:0)
Block(-3,12,-5,LOG)
Block(-3,12,-1,LOG)
Block(-3,12,2,LEAVES:0)
Block(-3,12,4,LEAVES:0)
Block(-3,13,-10,LEAVES:0)
Block(-3,13,-5,LOG)
Block(-3,13,-1,LEAVES:0)
Block(-3,13,0,LEAVES:0)
Block(-3,13,2,LEAVES:0)
Block(-3,13,3,LEAVES:0)
Block(-3,13,4,LEAVES:0)
Block(-3,13,5,LEAVES:0)
Block(-3,14,-11,LEAVES:0)
Block(-3,14,-10,LEAVES:0)
Block(-3,14,-7,LEAVES:0)
Block(-3,14,-1,LEAVES:0)
Block(-3,14,0,LEAVES:0)
Block(-3,14,1,LEAVES:0)
Block(-3,14,3,LEAVES:0)
Block(-3,14,4,LEAVES:0)
Block(-3,14,5,LEAVES:0)
Block(-3,15,-9,LEAVES:0)
Block(-3,15,-6,LEAVES:0)
Block(-3,15,-5,LEAVES:0)
Block(-3,15,0,LEAVES:0)
Block(-3,15,4,LEAVES:0)
Block(-3,16,-11,LEAVES:0)
Block(-3,16,-7,LEAVES:0)
Block(-3,16,-5,LEAVES:0)
Block(-3,17,-8,LEAVES:0)
Block(-3,17,-7,LEAVES:0)
Block(-3,17,-5,LEAVES:0)
Block(-3,17,-4,LEAVES:0)
Block(-3,18,-7,LEAVES:0)
Block(-3,18,-6,LEAVES:0)
Block(-3,18,-5,LEAVES:0)
Block(-2,2,1,LOG)
Block(-2,3,1,LOG)
Block(-2,4,1,LOG)
Block(-2,5,0,LOG)
Block(-2,5,1,LOG)
Block(-2,6,1,LOG)
Block(-2,10,1,LEAVES:0)
Block(-2,10,2,LEAVES:0)
Block(-2,10,4,LEAVES:0)
Block(-2,11,-6,LOG)
Block(-2,11,2,LEAVES:0)
Block(-2,11,3,LEAVES:0)
Block(-2,11,4,LEAVES:0)
Block(-2,11,5,LEAVES:0)
Block(-2,12,-12,LEAVES:0)
Block(-2,12,-11,LEAVES:0)
Block(-2,12,-10,LEAVES:0)
Block(-2,12,-6,LOG)
Block(-2,12,-5,LOG)
Block(-2,12,0,LEAVES:0)
Block(-2,12,4,LEAVES:0)
Block(-2,12,5,LEAVES:0)
Block(-2,13,-9,LEAVES:0)
Block(-2,13,-7,LEAVES:0)
Block(-2,13,0,LOG)
Block(-2,13,1,LEAVES:0)
Block(-2,13,3,LEAVES:0)
Block(-2,13,4,LEAVES:0)
Block(-2,14,-12,LEAVES:0)
Block(-2,14,-10,LEAVES:0)
Block(-2,14,-7,LEAVES:0)
Block(-2,14,-5,LOG)
Block(-2,14,-4,LEAVES:0)
Block(-2,14,-2,LEAVES:0)
Block(-2,14,-1,LEAVES:0)
Block(-2,14,1,LEAVES:0)
Block(-2,14,2,LEAVES:0)
Block(-2,14,3,LEAVES:0)
Block(-2,14,5,LEAVES:0)
Block(-2,14,6,LEAVES:0)
Block(-2,15,-12,LEAVES:0)
Block(-2,15,-8,LEAVES:0)
Block(-2,15,-6,LEAVES:0)
Block(-2,15,-5,LEAVES:0)
Block(-2,15,-4,LEAVES:0)
Block(-2,15,-3,LEAVES:0)
Block(-2,15,0,LEAVES:0)
Block(-2,15,1,LEAVES:0)
Block(-2,15,5,LEAVES:0)
Block(-2,16,-10,LEAVES:0)
Block(-2,16,-9,LEAVES:0)
Block(-2,16,-8,LEAVES:0)
Block(-2,16,-7,LEAVES:0)
Block(-2,16,-4,LEAVES:0)
Block(-2,17,-9,LEAVES:0)
Block(-2,17,-7,LEAVES:0)
Block(-2,17,-6,LEAVES:0)
Block(-2,17,-5,LEAVES:0)
Block(-2,18,-8,LEAVES:0)
Block(-2,18,-7,LEAVES:0)
Block(-1,2,0,LOG)
Block(-1,2,1,LOG)
Block(-1,3,0,LOG)
Block(-1,3,1,LOG)
Block(-1,4,-1,LOG)
Block(-1,4,0,LOG)
Block(-1,10,4,LEAVES:0)
Block(-1,11,-11,LEAVES:0)
Block(-1,11,-10,LEAVES:0)
Block(-1,11,-6,LOG)
Block(-1,11,1,LEAVES:0)
Block(-1,11,3,LEAVES:0)
Block(-1,11,4,LEAVES:0)
Block(-1,11,5,LEAVES:0)
Block(-1,12,-11,LEAVES:0)
Block(-1,12,-10,LEAVES:0)
Block(-1,12,-9,LEAVES:0)
Block(-1,12,-1,LEAVES:0)
Block(-1,12,5,LEAVES:0)
Block(-1,13,-12,LEAVES:0)
Block(-1,13,-11,LEAVES:0)
Block(-1,13,-10,LOG)
Block(-1,13,-6,LEAVES:0)
Block(-1,13,-1,LEAVES:0)
Block(-1,13,0,LEAVES:0)
Block(-1,13,4,LEAVES:0)
Block(-1,14,-10,LEAVES:0)
Block(-1,14,-5,LOG)
Block(-1,14,-1,LEAVES:0)
Block(-1,14,0,LEAVES:0)
Block(-1,14,1,LEAVES:0)
Block(-1,14,2,LEAVES:0)
Block(-1,14,3,LEAVES:0)
Block(-1,14,5,LEAVES:0)
Block(-1,15,-10,LEAVES:0)
Block(-1,15,-7,LEAVES:0)
Block(-1,15,-6,LOG)
Block(-1,15,-5,LEAVES:0)
Block(-1,15,-4,LEAVES:0)
Block(-1,15,-3,LEAVES:0)
Block(-1,15,-2,LEAVES:0)
Block(-1,15,2,LEAVES:0)
Block(-1,16,-6,LEAVES:0)
Block(-1,16,-3,LEAVES:0)
Block(-1,17,-6,LEAVES:0)
Block(-1,18,-6,LEAVES:0)
Block(0,-1,3,LOG)
Block(0,-1,4,LOG)
Block(0,-1,5,LOG)
Block(0,-1,6,LOG)
Block(0,0,0,LOG)
Block(0,0,1,LOG)
Block(0,0,2,LOG)
Block(0,1,0,LOG)
Block(0,1,1,LOG)
Block(0,1,2,LOG)
Block(0,2,0,LOG)
Block(0,2,1,LOG)
Block(0,2,2,LOG)
Block(0,3,0,LOG)
Block(0,3,1,LOG)
Block(0,4,-1,LOG)
Block(0,4,0,LOG)
Block(0,5,-2,LOG)
Block(0,5,-1,LOG)
Block(0,6,-2,LOG)
Block(0,9,-6,LOG)
Block(0,9,-5,LOG)
Block(0,10,-7,LOG)
Block(0,10,-6,LOG)
Block(0,10,3,LOG)
Block(0,10,4,LEAVES:0)
Block(0,11,-12,LEAVES:0)
Block(0,11,-11,LEAVES:0)
Block(0,11,-9,LEAVES:0)
Block(0,11,-8,LOG)
Block(0,11,-6,LOG)
Block(0,11,3,LOG)
Block(0,11,4,LEAVES:0)
Block(0,12,-11,LEAVES:0)
Block(0,12,-10,LEAVES:0)
Block(0,12,-9,LOG)
Block(0,12,1,LEAVES:0)
Block(0,12,2,LEAVES:0)
Block(0,12,3,LEAVES:0)
Block(0,13,-10,LEAVES:0)
Block(0,13,-9,LEAVES:0)
Block(0,13,-8,LEAVES:0)
Block(0,14,-10,LEAVES:0)
Block(0,14,0,LEAVES:0)
Block(0,14,1,LEAVES:0)
Block(0,14,2,LEAVES:0)
Block(0,14,3,LEAVES:0)
Block(0,14,4,LEAVES:0)
Block(0,15,-6,LEAVES:0)
Block(0,15,-5,LEAVES:0)
Block(0,15,-4,LEAVES:0)
Block(0,15,-3,LEAVES:0)
Block(0,15,0,LEAVES:0)
Block(0,15,2,LEAVES:0)
Block(0,16,-6,LEAVES:0)
Block(0,16,-5,LEAVES:0)
Block(0,16,-3,LEAVES:0)
Block(0,17,-6,LEAVES:0)
Block(1,-1,0,LOG)
Block(1,-1,1,LOG)
Block(1,-1,2,LOG)
Block(1,-1,3,LOG)
Block(1,-1,4,LOG)
Block(1,-1,7,LOG)
Block(1,0,0,LOG)
Block(1,0,1,LOG)
Block(1,0,2,LOG)
Block(1,0,3,LOG)
Block(1,1,0,LOG)
Block(1,1,1,LOG)
Block(1,1,2,LOG)
Block(1,2,0,LOG)
Block(1,2,1,LOG)
Block(1,5,-2,LOG)
Block(1,6,-2,LOG)
Block(1,8,-4,LOG)
Block(1,9,-6,LOG)
Block(1,9,-5,LOG)
Block(1,9,-4,LOG)
Block(1,10,2,LOG)
Block(1,10,3,LOG)
Block(1,10,5,LEAVES:0)
Block(1,11,-8,LEAVES:0)
Block(1,11,1,LEAVES:0)
Block(1,11,5,LEAVES:0)
Block(1,12,-9,LEAVES:0)
Block(1,12,2,LEAVES:0)
Block(1,12,3,LEAVES:0)
Block(1,12,4,LEAVES:0)
Block(1,12,5,LEAVES:0)
Block(1,13,-9,LEAVES:0)
Block(1,13,1,LEAVES:0)
Block(1,13,4,LEAVES:0)
Block(1,13,5,LEAVES:0)
Block(1,14,-11,LEAVES:0)
Block(1,14,-10,LEAVES:0)
Block(1,14,-9,LEAVES:0)
Block(1,14,-8,LEAVES:0)
Block(1,14,-7,LEAVES:0)
Block(1,14,-6,LEAVES:0)
Block(1,14,0,LEAVES:0)
Block(1,14,1,LEAVES:0)
Block(1,14,2,LEAVES:0)
Block(1,14,3,LEAVES:0)
Block(1,15,-8,LEAVES:0)
Block(1,15,-7,LEAVES:0)
Block(1,15,-5,LEAVES:0)
Block(1,15,-3,LEAVES:0)
Block(1,15,3,LEAVES:0)
Block(2,-1,1,LOG)
Block(2,-1,2,LOG)
Block(2,-1,3,LOG)
Block(2,0,2,LOG)
Block(2,6,-3,LOG)
Block(2,6,-2,LOG)
Block(2,6,-1,LOG)
Block(2,7,-4,LOG)
Block(2,7,-3,LOG)
Block(2,7,-2,LOG)
Block(2,7,-1,LOG)
Block(2,8,-4,LOG)
Block(2,8,-3,LOG)
Block(2,9,2,LOG)
Block(2,10,-8,LEAVES:0)
Block(2,10,-5,LEAVES:0)
Block(2,10,-4,LEAVES:0)
Block(2,10,2,LOG)
Block(2,11,-9,LEAVES:0)
Block(2,11,-8,LEAVES:0)
Block(2,11,2,LEAVES:0)
Block(2,11,3,LEAVES:0)
Block(2,12,-10,LEAVES:0)
Block(2,12,-9,LEAVES:0)
Block(2,12,-8,LEAVES:0)
Block(2,12,-7,LEAVES:0)
Block(2,12,-6,LEAVES:0)
Block(2,12,1,LEAVES:0)
Block(2,12,2,LEAVES:0)
Block(2,12,3,LEAVES:0)
Block(2,13,-10,LEAVES:0)
Block(2,13,-9,LEAVES:0)
Block(2,13,-8,LEAVES:0)
Block(2,13,-7,LEAVES:0)
Block(2,13,-6,LEAVES:0)
Block(2,13,1,LEAVES:0)
Block(2,13,2,LEAVES:0)
Block(2,13,4,LEAVES:0)
Block(2,14,-9,LEAVES:0)
Block(2,14,-7,LEAVES:0)
Block(2,14,1,LEAVES:0)
Block(2,14,2,LEAVES:0)
Block(2,14,4,LEAVES:0)
Block(2,15,-7,LEAVES:0)
Block(2,15,-6,LEAVES:0)
Block(2,15,2,LEAVES:0)
Block(2,16,1,LEAVES:0)
Block(3,-1,2,LOG)
Block(3,-1,3,LOG)
Block(3,5,-4,LEAVES:0)
Block(3,5,-2,LEAVES:0)
Block(3,6,-3,LEAVES:0)
Block(3,6,-2,LEAVES:0)
Block(3,6,-1,LEAVES:0)
Block(3,7,-1,LOG)
Block(3,7,0,LOG)
Block(3,8,-4,LOG)
Block(3,8,0,LOG)
Block(3,8,1,LOG)
Block(3,9,-6,LEAVES:0)
Block(3,9,-4,LOG)
Block(3,9,1,LOG)
Block(3,9,2,LOG)
Block(3,10,-7,LEAVES:0)
Block(3,10,-6,LEAVES:0)
Block(3,10,-5,LEAVES:0)
Block(3,10,-4,LEAVES:0)
Block(3,11,-8,LEAVES:0)
Block(3,11,-7,LEAVES:0)
Block(3,11,-6,LEAVES:0)
Block(3,11,0,LEAVES:0)
Block(3,11,1,LEAVES:0)
Block(3,12,-9,LEAVES:0)
Block(3,12,-8,LEAVES:0)
Block(3,12,-7,LEAVES:0)
Block(3,12,-6,LEAVES:0)
Block(3,12,-5,LEAVES:0)
Block(3,12,0,LEAVES:0)
Block(3,12,1,LEAVES:0)
Block(3,12,3,LEAVES:0)
Block(3,13,-10,LEAVES:0)
Block(3,13,-6,LEAVES:0)
Block(3,13,-3,LEAVES:0)
Block(3,13,-2,LEAVES:0)
Block(3,13,2,LEAVES:0)
Block(3,13,3,LEAVES:0)
Block(3,14,1,LEAVES:0)
Block(3,14,2,LEAVES:0)
Block(3,14,3,LEAVES:0)
Block(3,15,-7,LEAVES:0)
Block(3,15,2,LEAVES:0)
Block(4,-1,3,LOG)
Block(4,-1,4,LOG)
Block(4,4,-4,LEAVES:0)
Block(4,4,-3,LEAVES:0)
Block(4,5,-3,LEAVES:0)
Block(4,5,-2,LEAVES:0)
Block(4,6,-5,LEAVES:0)
Block(4,6,-3,LEAVES:0)
Block(4,6,-2,LEAVES:0)
Block(4,6,-1,LEAVES:0)
Block(4,6,0,LEAVES:0)
Block(4,7,-1,LEAVES:0)
Block(4,8,-4,LEAVES:0)
Block(4,8,-3,LEAVES:0)
Block(4,9,-7,LEAVES:0)
Block(4,9,-6,LEAVES:0)
Block(4,9,-5,LOG)
Block(4,9,-4,LOG)
Block(4,9,-2,LEAVES:0)
Block(4,10,-7,LEAVES:0)
Block(4,10,-6,LEAVES:0)
Block(4,10,-5,LOG)
Block(4,10,-4,LEAVES:0)
Block(4,10,-3,LEAVES:0)
Block(4,10,1,LOG)
Block(4,11,-9,LEAVES:0)
Block(4,11,-8,LEAVES:0)
Block(4,11,-3,LEAVES:0)
Block(4,11,-2,LEAVES:0)
Block(4,11,0,LEAVES:0)
Block(4,11,2,LEAVES:0)
Block(4,12,-10,LEAVES:0)
Block(4,12,-9,LEAVES:0)
Block(4,12,-8,LEAVES:0)
Block(4,12,-7,LEAVES:0)
Block(4,12,-5,LEAVES:0)
Block(4,12,-4,LEAVES:0)
Block(4,12,-1,LEAVES:0)
Block(4,12,0,LEAVES:0)
Block(4,12,2,LEAVES:0)
Block(4,13,-8,LEAVES:0)
Block(4,13,-6,LEAVES:0)
Block(4,13,-5,LEAVES:0)
Block(4,13,-3,LEAVES:0)
Block(4,13,-1,LEAVES:0)
Block(4,13,0,LEAVES:0)
Block(4,13,1,LEAVES:0)
Block(4,13,2,LEAVES:0)
Block(4,13,3,LEAVES:0)
Block(4,14,-3,LEAVES:0)
Block(4,14,-2,LEAVES:0)
Block(4,14,-1,LEAVES:0)
Block(4,14,0,LEAVES:0)
Block(4,15,-1,LEAVES:0)
Block(4,15,0,LEAVES:0)
Block(4,15,1,LEAVES:0)
Block(5,-1,4,LOG)
Block(5,3,-2,LEAVES:0)
Block(5,4,-3,LEAVES:0)
Block(5,4,-2,LEAVES:0)
Block(5,5,-4,LEAVES:0)
Block(5,5,-3,LEAVES:0)
Block(5,5,-2,LOG)
Block(5,5,-1,LEAVES:0)
Block(5,5,0,LEAVES:0)
Block(5,6,-6,LEAVES:0)
Block(5,6,-5,LEAVES:0)
Block(5,6,-3,LOG)
Block(5,6,-2,LEAVES:0)
Block(5,6,-1,LEAVES:0)
Block(5,7,-5,LOG)
Block(5,7,-4,LOG)
Block(5,8,-5,LOG)
Block(5,8,-4,LEAVES:0)
Block(5,8,-3,LEAVES:0)
Block(5,9,-7,LEAVES:0)
Block(5,9,-6,LEAVES:0)
Block(5,9,-5,LEAVES:0)
Block(5,9,-3,LEAVES:0)
Block(5,9,-2,LEAVES:0)
Block(5,9,-1,LEAVES:0)
Block(5,10,-6,LOG)
Block(5,10,-5,LOG)
Block(5,10,-4,LEAVES:0)
Block(5,10,-3,LEAVES:0)
Block(5,10,0,LEAVES:0)
Block(5,10,1,LEAVES:0)
Block(5,11,-8,LEAVES:0)
Block(5,11,-7,LEAVES:0)
Block(5,11,-6,LEAVES:0)
Block(5,11,1,LEAVES:0)
Block(5,11,2,LOG)
Block(5,12,-6,LEAVES:0)
Block(5,12,-2,LEAVES:0)
Block(5,12,-1,LEAVES:0)
Block(5,12,1,LEAVES:0)
Block(5,12,2,LEAVES:0)
Block(5,12,3,LEAVES:0)
Block(5,13,-5,LEAVES:0)
Block(5,13,-2,LEAVES:0)
Block(5,13,-1,LEAVES:0)
Block(5,13,0,LEAVES:0)
Block(5,13,1,LEAVES:0)
Block(5,13,2,LEAVES:0)
Block(5,14,-5,LEAVES:0)
Block(5,14,-4,LEAVES:0)
Block(5,14,-1,LEAVES:0)
Block(5,14,1,LEAVES:0)
Block(5,14,2,LEAVES:0)
Block(5,14,3,LEAVES:0)
Block(5,15,-2,LEAVES:0)
Block(5,15,-1,LEAVES:0)
Block(6,-1,5,LOG)
Block(6,5,-3,LEAVES:0)
Block(6,5,-2,LEAVES:0)
Block(6,5,-1,LEAVES:0)
Block(6,6,-5,LEAVES:0)
Block(6,6,-4,LEAVES:0)
Block(6,6,-3,LEAVES:0)
Block(6,6,0,LEAVES:0)
Block(6,7,-6,LEAVES:0)
Block(6,7,-5,LEAVES:0)
Block(6,7,-4,LEAVES:0)
Block(6,7,-3,LEAVES:0)
Block(6,7,-2,LEAVES:0)
Block(6,7,-1,LEAVES:0)
Block(6,8,-7,LEAVES:0)
Block(6,8,-6,LEAVES:0)
Block(6,8,-5,LEAVES:0)
Block(6,8,-4,LEAVES:0)
Block(6,8,-3,LEAVES:0)
Block(6,8,-2,LEAVES:0)
Block(6,9,-6,LEAVES:0)
Block(6,9,-5,LEAVES:0)
Block(6,9,-3,LEAVES:0)
Block(6,9,-2,LEAVES:0)
Block(6,9,-1,LEAVES:0)
Block(6,9,0,LEAVES:0)
Block(6,10,-6,LEAVES:0)
Block(6,10,-5,LEAVES:0)
Block(6,10,-2,LEAVES:0)
Block(6,10,0,LEAVES:0)
Block(6,10,1,LEAVES:0)
Block(6,10,3,LEAVES:0)
Block(6,11,-6,LEAVES:0)
Block(6,11,-5,LEAVES:0)
Block(6,11,-4,LEAVES:0)
Block(6,11,-2,LEAVES:0)
Block(6,11,-1,LEAVES:0)
Block(6,11,0,LEAVES:0)
Block(6,11,2,LEAVES:0)
Block(6,11,3,LEAVES:0)
Block(6,12,-7,LEAVES:0)
Block(6,12,0,LEAVES:0)
Block(6,12,1,LEAVES:0)
Block(6,12,2,LOG)
Block(6,12,3,LEAVES:0)
Block(6,12,4,LEAVES:0)
Block(6,13,-2,LEAVES:0)
Block(6,13,0,LEAVES:0)
Block(6,13,1,LEAVES:0)
Block(6,13,2,LEAVES:0)
Block(6,13,3,LEAVES:0)
Block(6,13,4,LEAVES:0)
Block(6,14,-1,LEAVES:0)
Block(6,14,0,LEAVES:0)
Block(6,14,1,LEAVES:0)
Block(6,14,2,LEAVES:0)
Block(6,14,3,LEAVES:0)
Block(7,6,-4,LEAVES:0)
Block(7,7,-5,LEAVES:0)
Block(7,7,-4,LEAVES:0)
Block(7,7,-3,LEAVES:0)
Block(7,8,-4,LEAVES:0)
Block(7,8,-3,LEAVES:0)
Block(7,9,-2,LEAVES:0)
Block(7,9,-1,LEAVES:0)
Block(7,9,0,LEAVES:0)
Block(7,10,1,LEAVES:0)
Block(7,10,2,LEAVES:0)
Block(7,11,1,LEAVES:0)
Block(7,11,2,LEAVES:0)
Block(7,11,3,LEAVES:0)
Block(7,11,4,LEAVES:0)
Block(7,12,-3,LEAVES:0)
Block(7,12,-2,LEAVES:0)
Block(7,12,0,LEAVES:0)
Block(7,12,2,LEAVES:0)
Block(7,12,3,LEAVES:0)
Block(7,12,4,LEAVES:0)
Block(7,13,-3,LEAVES:0)
Block(7,13,-1,LEAVES:0)
Block(7,13,1,LEAVES:0)
Block(7,14,3,LEAVES:0)
Block(8,7,-4,LEAVES:0)
Block(8,8,-3,LEAVES:0)
Block(8,8,-1,LEAVES:0)
Block(8,9,-1,LEAVES:0)
Block(8,10,-1,LEAVES:0)
Block(8,10,0,LEAVES:0)
Block(8,11,0,LEAVES:0)
Block(8,11,2,LEAVES:0)
Block(8,11,3,LEAVES:0)
Block(8,12,0,LEAVES:0)
Block(8,13,0,LEAVES:0)

#######################################################################
# +-----------------------------------------------------------------+ #
# |                            BO3 checks                           | #
# +-----------------------------------------------------------------+ #
#######################################################################

BlockCheck(0,-1,0,GRASS)

#######################################################################
# +-----------------------------------------------------------------+ #
# |                             Branches                            | #
# +-----------------------------------------------------------------+ #
#######################################################################


#######################################################################
# +-----------------------------------------------------------------+ #
# |                             Entities                            | #
# +-----------------------------------------------------------------+ #
#######################################################################


#######################################################################
# +-----------------------------------------------------------------+ #
# |                            Particles                            | #
# +-----------------------------------------------------------------+ #
#######################################################################


#######################################################################
# +-----------------------------------------------------------------+ #
# |                             Spawners                            | #
# +-----------------------------------------------------------------+ #
#######################################################################


#######################################################################
# +-----------------------------------------------------------------+ #
# |                             ModData                             | #
# +-----------------------------------------------------------------+ #
#######################################################################

