
#######################################################################
# +-----------------------------------------------------------------+ #
# |                            BO3 object                           | #
# +-----------------------------------------------------------------+ #
#######################################################################

Author: LordSmellyPants

Description: No description given

Version: 3

SettingsMode: WriteWithoutComments


#######################################################################
# +-----------------------------------------------------------------+ #
# |                          Main settings                          | #
# +-----------------------------------------------------------------+ #
#######################################################################

Tree: true

Frequency: 1

Rarity: 10.0

RotateRandomly: true

SpawnHeight: highestSolidBlock

SpawnHeightOffset: 0

SpawnHeightVariance: 0

##############################
# Height Limits for the BO3. #
##############################

MinHeight: 51

MaxHeight: 256

######################
# Extrusion settings #
######################

ExtrudeMode: None

ExtrudeThroughBlocks: AIR

MaxBranchDepth: 10

ExcludedBiomes: All


#######################################################################
# +-----------------------------------------------------------------+ #
# |                      Source block settings                      | #
# +-----------------------------------------------------------------+ #
#######################################################################

SourceBlocks: STONE:1,STONE:3,STONE:5,DIRT:1,DIRT,SAND,GRASS,DIRT:2,STATIONARY_WATER,HARD_CLAY,STAINED_CLAY,CLAY,SANDSTONE,SAND:1,AIR,STONE,GRAVEL,LONG_GRASS,LONG_GRASS:1,LONG_GRASS:2,DEAD_BUSH,YELLOW_FLOWER,RED_ROSE,BROWN_MUSHROOM,RED_MUSHROOM

MaxPercentageOutsideSourceBlock: 0

OutsideSourceBlock: placeAnyway


#######################################################################
# +-----------------------------------------------------------------+ #
# |                              Blocks                             | #
# +-----------------------------------------------------------------+ #
#######################################################################

Block(-5,7,1,LEAVES)
Block(-5,7,2,LEAVES)
Block(-5,7,3,LEAVES)
Block(-4,7,0,LEAVES)
Block(-4,7,1,LEAVES)
Block(-4,7,2,LOG:4)
Block(-4,7,4,LEAVES)
Block(-4,8,-4,LEAVES)
Block(-4,8,1,LEAVES)
Block(-4,8,2,LEAVES)
Block(-4,8,3,LEAVES)
Block(-4,9,-5,LEAVES)
Block(-4,9,-4,LEAVES)
Block(-4,9,-3,LEAVES)
Block(-4,10,-4,LEAVES)
Block(-3,7,1,LOG:4)
Block(-3,7,2,LEAVES)
Block(-3,7,3,LEAVES)
Block(-3,8,-5,LEAVES)
Block(-3,8,-4,LOG:8)
Block(-3,8,-3,LEAVES)
Block(-3,8,0,LEAVES)
Block(-3,8,1,LEAVES)
Block(-3,8,2,LEAVES)
Block(-3,9,-5,LEAVES)
Block(-3,9,-4,LEAVES)
Block(-3,9,-3,LEAVES)
Block(-3,10,-5,LEAVES)
Block(-3,10,-4,LEAVES)
Block(-3,10,-3,LEAVES)
Block(-3,10,3,LEAVES)
Block(-3,10,4,LEAVES)
Block(-3,11,3,LEAVES)
Block(-2,7,1,LOG:4)
Block(-2,8,-4,LEAVES)
Block(-2,8,-3,LOG:8)
Block(-2,8,-2,LOG:8)
Block(-2,9,-5,LEAVES)
Block(-2,9,-4,LEAVES)
Block(-2,9,-3,LEAVES)
Block(-2,10,-4,LEAVES)
Block(-2,10,2,LOG:8)
Block(-2,10,3,LOG:8)
Block(-2,10,4,LEAVES)
Block(-2,11,-1,LEAVES)
Block(-2,11,2,LEAVES)
Block(-2,11,3,LEAVES)
Block(-2,11,4,LEAVES)
Block(-1,7,0,LOG:4)
Block(-1,8,-1,LOG:8)
Block(-1,10,1,LOG:8)
Block(-1,10,3,LEAVES)
Block(-1,11,-2,LEAVES)
Block(-1,11,-1,LOG:8)
Block(-1,11,0,LEAVES)
Block(-1,11,3,LEAVES)
Block(-1,12,-1,LEAVES)
Block(0,-1,0,LOG)
Block(0,0,0,LOG)
Block(0,1,0,LOG)
Block(0,2,0,LOG)
Block(0,3,0,LOG)
Block(0,4,0,LOG)
Block(0,5,0,LOG)
Block(0,6,0,LOG)
Block(0,7,0,LOG)
Block(0,8,0,LOG)
Block(0,8,1,LOG:8)
Block(0,8,2,LOG:8)
Block(0,8,3,LOG:8)
Block(0,8,4,LEAVES)
Block(0,9,0,LOG)
Block(0,9,4,LEAVES)
Block(0,9,5,LEAVES)
Block(0,10,-3,LEAVES)
Block(0,10,0,LOG)
Block(0,10,4,LEAVES)
Block(0,11,-1,LEAVES)
Block(0,11,0,LOG)
Block(0,12,0,LEAVES)
Block(0,12,1,LEAVES)
Block(0,12,2,LEAVES)
Block(0,13,1,LEAVES)
Block(1,7,0,LOG:4)
Block(1,8,4,LEAVES)
Block(1,9,-4,LEAVES)
Block(1,9,-3,LEAVES)
Block(1,9,-1,LOG:8)
Block(1,9,3,LEAVES)
Block(1,9,4,LOG)
Block(1,9,5,LEAVES)
Block(1,10,-3,LEAVES)
Block(1,10,-2,LEAVES)
Block(1,10,3,LEAVES)
Block(1,10,4,LEAVES)
Block(1,10,5,LEAVES)
Block(1,11,1,LEAVES)
Block(1,12,0,LEAVES)
Block(1,12,1,LOG)
Block(1,12,2,LEAVES)
Block(1,13,0,LEAVES)
Block(1,13,1,LEAVES)
Block(1,13,2,LEAVES)
Block(2,7,1,LOG:4)
Block(2,9,-4,LEAVES)
Block(2,9,-3,LOG:8)
Block(2,9,-2,LOG:8)
Block(2,9,4,LEAVES)
Block(2,9,5,LEAVES)
Block(2,10,-4,LEAVES)
Block(2,10,-3,LEAVES)
Block(2,10,-2,LEAVES)
Block(2,10,4,LEAVES)
Block(2,11,-3,LEAVES)
Block(2,11,-2,LEAVES)
Block(2,12,0,LEAVES)
Block(2,12,1,LEAVES)
Block(2,12,2,LEAVES)
Block(2,13,1,LEAVES)
Block(3,7,1,LOG:4)
Block(3,9,-4,LEAVES)
Block(3,9,-3,LEAVES)
Block(3,9,1,LEAVES)
Block(3,10,-3,LEAVES)
Block(3,10,-2,LEAVES)
Block(4,8,0,LEAVES)
Block(4,8,1,LOG:4)
Block(4,8,2,LEAVES)
Block(4,9,0,LEAVES)
Block(4,9,1,LEAVES)
Block(4,9,2,LEAVES)
Block(4,10,-3,LEAVES)
Block(4,10,1,LEAVES)
Block(5,8,1,LEAVES)
Block(5,9,0,LEAVES)
Block(5,9,1,LEAVES)
Block(5,9,2,LEAVES)

#######################################################################
# +-----------------------------------------------------------------+ #
# |                            BO3 checks                           | #
# +-----------------------------------------------------------------+ #
#######################################################################

BlockCheck(0,-1,0,GRASS,DIRT)

#######################################################################
# +-----------------------------------------------------------------+ #
# |                             Branches                            | #
# +-----------------------------------------------------------------+ #
#######################################################################


#######################################################################
# +-----------------------------------------------------------------+ #
# |                         EntityFunctions                         | #
# +-----------------------------------------------------------------+ #
#######################################################################

