
#######################################################################
# +-----------------------------------------------------------------+ #
# |                            BO3 object                           | #
# +-----------------------------------------------------------------+ #
#######################################################################

Author: Unknown

Description: This BO3 was converted from a schematic using the MineCraft Worlds Editor. Unfortunately the author and description information for the schematic could not be found. If you know who the author of the schematic is then please tell the author of this BO3!

Version: 3

SettingsMode: WriteWithoutComments


#######################################################################
# +-----------------------------------------------------------------+ #
# |                          Main settings                          | #
# +-----------------------------------------------------------------+ #
#######################################################################

Tree: true

Frequency: 40

Rarity: 30.0

RotateRandomly: true

SpawnHeight: highestSolidBlock

SpawnHeightOffset: 0

SpawnHeightVariance: 0

##############################
# Height Limits for the BO3. #
##############################

MinHeight: 62

MaxHeight: 256

######################
# Extrusion settings #
######################

ExtrudeMode: None

ExtrudeThroughBlocks: AIR

MaxBranchDepth: 10

ExcludedBiomes: All


#######################################################################
# +-----------------------------------------------------------------+ #
# |                      Source block settings                      | #
# +-----------------------------------------------------------------+ #
#######################################################################

SourceBlocks: STONE:1,STONE:3,STONE:5,DIRT:1,DIRT,SAND,GRASS,DIRT:2,STATIONARY_WATER,HARD_CLAY,STAINED_CLAY,CLAY,SANDSTONE,SAND:1,AIR,STONE,GRAVEL,LONG_GRASS,LONG_GRASS:1,LONG_GRASS:2,DEAD_BUSH,YELLOW_FLOWER,RED_ROSE,BROWN_MUSHROOM,RED_MUSHROOM

MaxPercentageOutsideSourceBlock: 0

OutsideSourceBlock: placeAnyway


#######################################################################
# +-----------------------------------------------------------------+ #
# |                              Blocks                             | #
# +-----------------------------------------------------------------+ #
#######################################################################

B(-7,17,0,LEAVES:0)
B(-7,17,1,LEAVES:0)
B(-7,17,2,LEAVES:0)
B(-6,17,-1,LEAVES:0)
B(-6,17,0,LEAVES:0)
B(-6,17,1,LEAVES:0)
B(-6,17,2,LEAVES:0)
B(-6,17,3,LEAVES:0)
B(-6,20,0,LEAVES:0)
B(-6,20,1,LEAVES:0)
B(-6,20,2,LEAVES:0)
B(-5,13,-1,LEAVES:0)
B(-5,14,0,LEAVES:3)
B(-5,17,-1,LEAVES:0)
B(-5,17,0,LEAVES:0)
B(-5,17,1,LEAVES:0)
B(-5,20,1,LOG)
B(-5,20,2,LEAVES:0)
B(-5,21,1,LEAVES:0)
B(-5,21,2,LEAVES:0)
B(-5,21,3,LEAVES:0)
B(-5,21,4,LEAVES:0)
B(-5,25,0,LEAVES:0)
B(-4,2,1,LOG)
B(-4,3,1,LOG)
B(-4,13,-3,LEAVES:0)
B(-4,13,-1,LEAVES:0)
B(-4,13,0,LOG)
B(-4,13,1,LEAVES:0)
B(-4,13,2,LEAVES:0)
B(-4,13,3,LEAVES:0)
B(-4,14,0,LEAVES:3)
B(-4,16,0,LEAVES:0)
B(-4,17,-2,LEAVES:0)
B(-4,17,-1,LEAVES:0)
B(-4,17,0,LEAVES:0)
B(-4,17,1,LOG)
B(-4,17,3,LEAVES:0)
B(-4,17,4,LEAVES:0)
B(-4,18,-1,LEAVES:0)
B(-4,18,1,LEAVES:0)
B(-4,19,1,LEAVES:0)
B(-4,19,2,LEAVES:0)
B(-4,20,0,LEAVES:0)
B(-4,20,1,LOG)
B(-4,20,3,LEAVES:0)
B(-4,21,0,LEAVES:0)
B(-4,21,4,LOG)
B(-4,21,5,LEAVES:0)
B(-4,22,3,LEAVES:0)
B(-4,23,-2,LEAVES:0)
B(-4,23,-1,LEAVES:0)
B(-4,24,-1,LEAVES:0)
B(-4,25,0,LEAVES:0)
B(-4,25,2,LEAVES:0)
B(-4,25,3,LEAVES:0)
B(-3,2,-1,LOG)
B(-3,3,-1,LOG)
B(-3,4,0,LOG)
B(-3,4,1,LOG)
B(-3,5,0,LOG)
B(-3,6,0,LOG)
B(-3,13,-3,LEAVES:0)
B(-3,13,-2,LEAVES:0)
B(-3,13,-1,LEAVES:0)
B(-3,13,0,LOG)
B(-3,13,1,LEAVES:0)
B(-3,13,2,LEAVES:0)
B(-3,14,-1,LEAVES:0)
B(-3,14,0,LEAVES:0)
B(-3,14,3,LEAVES:0)
B(-3,14,4,LEAVES:0)
B(-3,15,1,LEAVES:0)
B(-3,15,2,LEAVES:0)
B(-3,16,-4,LEAVES:0)
B(-3,16,-3,LEAVES:0)
B(-3,17,-2,LEAVES:0)
B(-3,17,-1,LEAVES:0)
B(-3,17,0,LEAVES:0)
B(-3,17,1,LOG)
B(-3,17,2,LEAVES:0)
B(-3,17,3,LEAVES:0)
B(-3,18,-2,LEAVES:0)
B(-3,18,-1,LEAVES:0)
B(-3,18,0,LEAVES:0)
B(-3,19,0,LEAVES:0)
B(-3,19,1,LOG)
B(-3,19,2,LEAVES:0)
B(-3,20,-4,LEAVES:0)
B(-3,20,-2,LEAVES:0)
B(-3,20,-1,LEAVES:0)
B(-3,20,0,LEAVES:0)
B(-3,20,2,LEAVES:0)
B(-3,20,3,LEAVES:0)
B(-3,20,4,LEAVES:0)
B(-3,21,0,LEAVES:0)
B(-3,21,2,LEAVES:0)
B(-3,21,3,LOG)
B(-3,21,4,LEAVES:0)
B(-3,21,5,LEAVES:0)
B(-3,22,-2,LEAVES:0)
B(-3,22,2,LEAVES:0)
B(-3,22,3,LEAVES:0)
B(-3,22,4,LEAVES:0)
B(-3,23,-2,LEAVES:0)
B(-3,23,-1,LEAVES:0)
B(-3,23,0,LEAVES:0)
B(-3,24,-2,LEAVES:0)
B(-3,24,-1,LEAVES:0)
B(-3,24,2,LEAVES:0)
B(-3,25,-2,LEAVES:0)
B(-3,25,-1,LEAVES:0)
B(-3,25,0,LEAVES:0)
B(-3,25,1,LEAVES:0)
B(-3,25,2,LEAVES:0)
B(-3,25,3,LEAVES:0)
B(-3,26,-1,LEAVES:0)
B(-3,26,1,LEAVES:3)
B(-3,26,2,LEAVES:3)
B(-3,27,1,LEAVES:3)
B(-2,2,3,LOG)
B(-2,3,3,LOG)
B(-2,4,-1,LOG)
B(-2,4,1,LOG)
B(-2,4,2,LOG)
B(-2,5,-1,LOG)
B(-2,5,0,LOG)
B(-2,5,1,LOG)
B(-2,5,2,LOG)
B(-2,6,0,LOG)
B(-2,6,1,LOG)
B(-2,7,0,LOG)
B(-2,7,1,LOG)
B(-2,8,0,LOG)
B(-2,8,1,LOG)
B(-2,9,0,LOG)
B(-2,9,1,LOG)
B(-2,10,1,LOG)
B(-2,12,0,LOG)
B(-2,13,-3,LEAVES:0)
B(-2,13,-2,LEAVES:0)
B(-2,13,-1,LEAVES:0)
B(-2,13,0,LOG)
B(-2,13,1,LEAVES:0)
B(-2,13,2,LEAVES:0)
B(-2,14,-1,LEAVES:0)
B(-2,14,1,LEAVES:0)
B(-2,14,2,LEAVES:0)
B(-2,14,3,LEAVES:0)
B(-2,14,4,LEAVES:0)
B(-2,15,-1,LEAVES:0)
B(-2,15,0,LEAVES:0)
B(-2,15,2,LEAVES:0)
B(-2,15,3,LEAVES:0)
B(-2,16,-5,LEAVES:0)
B(-2,16,-4,LEAVES:0)
B(-2,16,-3,LEAVES:0)
B(-2,16,-2,LEAVES:0)
B(-2,16,-1,LEAVES:0)
B(-2,16,0,LEAVES:0)
B(-2,16,1,LOG)
B(-2,16,2,LEAVES:0)
B(-2,17,-2,LEAVES:0)
B(-2,17,1,LOG)
B(-2,17,2,LEAVES:0)
B(-2,17,3,LEAVES:0)
B(-2,17,4,LEAVES:0)
B(-2,18,-2,LEAVES:0)
B(-2,18,-1,LEAVES:0)
B(-2,18,1,LEAVES:0)
B(-2,18,2,LEAVES:0)
B(-2,18,3,LEAVES:0)
B(-2,18,4,LEAVES:0)
B(-2,19,-4,LEAVES:0)
B(-2,19,-2,LEAVES:0)
B(-2,19,0,LEAVES:0)
B(-2,19,1,LOG)
B(-2,19,2,LEAVES:0)
B(-2,20,-5,LEAVES:0)
B(-2,20,-4,LEAVES:0)
B(-2,20,-3,LEAVES:0)
B(-2,20,-2,LEAVES:0)
B(-2,20,0,LEAVES:0)
B(-2,20,1,LEAVES:0)
B(-2,20,2,LEAVES:0)
B(-2,20,4,LEAVES:0)
B(-2,21,-3,LEAVES:0)
B(-2,21,-2,LEAVES:0)
B(-2,21,0,LEAVES:0)
B(-2,21,1,LEAVES:0)
B(-2,21,2,LOG)
B(-2,21,3,LEAVES:0)
B(-2,22,-4,LEAVES:0)
B(-2,22,-2,LEAVES:0)
B(-2,22,-1,LEAVES:0)
B(-2,22,0,LEAVES:0)
B(-2,22,1,LEAVES:0)
B(-2,22,2,LEAVES:0)
B(-2,23,-5,LEAVES:0)
B(-2,23,-4,LEAVES:0)
B(-2,23,-3,LEAVES:0)
B(-2,23,-2,LEAVES:0)
B(-2,23,-1,LEAVES:0)
B(-2,23,0,LEAVES:0)
B(-2,23,1,LEAVES:0)
B(-2,24,-3,LEAVES:0)
B(-2,24,-2,LEAVES:0)
B(-2,24,-1,LEAVES:0)
B(-2,24,0,LEAVES:0)
B(-2,24,1,LEAVES:0)
B(-2,25,-2,LEAVES:0)
B(-2,25,-1,LEAVES:0)
B(-2,25,1,LOG)
B(-2,25,2,LEAVES:0)
B(-2,25,3,LEAVES:0)
B(-2,25,4,LEAVES:0)
B(-2,26,-2,LEAVES:0)
B(-2,26,-1,LEAVES:0)
B(-2,26,0,LEAVES:0)
B(-2,26,1,LEAVES:0)
B(-2,26,2,LEAVES:0)
B(-2,27,-1,LEAVES:0)
B(-2,27,0,LEAVES:0)
B(-2,27,3,LEAVES:0)
B(-2,28,0,LEAVES:0)
B(-2,28,1,LEAVES:0)
B(-2,29,1,LEAVES_2:5)
B(-1,1,0,LOG)
B(-1,2,0,LOG)
B(-1,3,0,LOG)
B(-1,4,0,LOG)
B(-1,4,3,LOG)
B(-1,5,-2,LOG)
B(-1,5,-1,LOG)
B(-1,5,0,LOG)
B(-1,5,2,LOG)
B(-1,5,3,LOG)
B(-1,6,-1,LOG)
B(-1,6,0,LOG)
B(-1,6,1,LOG)
B(-1,6,2,LOG)
B(-1,6,3,LOG)
B(-1,7,-1,LOG)
B(-1,7,0,LOG)
B(-1,7,1,LOG)
B(-1,7,2,LOG)
B(-1,8,0,LOG)
B(-1,8,1,LOG)
B(-1,8,2,LOG)
B(-1,9,0,LOG)
B(-1,9,1,LOG)
B(-1,9,2,LOG)
B(-1,10,0,LOG)
B(-1,10,1,LOG)
B(-1,11,0,LOG)
B(-1,11,1,LOG)
B(-1,12,0,LOG)
B(-1,12,1,LOG)
B(-1,13,0,LOG)
B(-1,13,1,LOG)
B(-1,13,2,LOG)
B(-1,14,-3,LEAVES:0)
B(-1,14,-2,LEAVES:0)
B(-1,14,0,LOG)
B(-1,14,1,LOG)
B(-1,14,2,LOG)
B(-1,14,3,LOG)
B(-1,14,4,LOG)
B(-1,14,5,LEAVES:0)
B(-1,15,-2,LEAVES:0)
B(-1,15,0,LOG)
B(-1,15,1,LOG)
B(-1,15,4,LEAVES:0)
B(-1,16,-3,LEAVES:0)
B(-1,16,-2,LEAVES:0)
B(-1,16,-1,LEAVES:0)
B(-1,16,0,LOG)
B(-1,16,1,LOG)
B(-1,16,2,LEAVES:0)
B(-1,17,-3,LEAVES:0)
B(-1,17,-2,LEAVES:0)
B(-1,17,0,LOG)
B(-1,17,1,LOG)
B(-1,18,-5,LEAVES:0)
B(-1,18,-4,LEAVES:0)
B(-1,18,-3,LEAVES:0)
B(-1,18,-2,LEAVES:0)
B(-1,18,-1,LEAVES:0)
B(-1,18,0,LOG)
B(-1,18,1,LOG)
B(-1,18,2,LOG)
B(-1,18,3,LOG)
B(-1,18,4,LOG)
B(-1,18,5,LEAVES:0)
B(-1,19,-4,LEAVES:0)
B(-1,19,-3,LEAVES:0)
B(-1,19,-2,LEAVES:0)
B(-1,19,-1,LOG)
B(-1,19,0,LOG)
B(-1,19,1,LOG)
B(-1,19,2,LOG)
B(-1,19,3,LEAVES:0)
B(-1,20,-5,LEAVES:0)
B(-1,20,-4,LEAVES:0)
B(-1,20,-3,LOG)
B(-1,20,-2,LOG)
B(-1,20,-1,LOG)
B(-1,20,0,LOG)
B(-1,20,1,LOG)
B(-1,20,2,LOG)
B(-1,20,3,LOG)
B(-1,20,4,LOG)
B(-1,20,5,LEAVES:0)
B(-1,21,-3,LEAVES:0)
B(-1,21,-2,LEAVES:0)
B(-1,21,0,LOG)
B(-1,21,1,LOG)
B(-1,21,2,LEAVES:0)
B(-1,21,4,LEAVES:0)
B(-1,22,-4,LEAVES:0)
B(-1,22,-3,LEAVES:0)
B(-1,22,-2,LOG)
B(-1,22,-1,LOG)
B(-1,22,0,LOG)
B(-1,22,1,LOG)
B(-1,22,2,LEAVES:0)
B(-1,22,3,LEAVES:0)
B(-1,22,4,LEAVES:0)
B(-1,23,-5,LEAVES:3)
B(-1,23,-3,LOG)
B(-1,23,-2,LEAVES:0)
B(-1,23,-1,LEAVES:0)
B(-1,23,0,LOG)
B(-1,23,1,LOG)
B(-1,23,2,LEAVES:0)
B(-1,24,-4,LEAVES:0)
B(-1,24,-1,LEAVES:0)
B(-1,24,0,LOG)
B(-1,24,1,LOG)
B(-1,24,2,LEAVES:0)
B(-1,24,3,LEAVES:0)
B(-1,25,-2,LEAVES:0)
B(-1,25,-1,LEAVES:0)
B(-1,25,0,LOG)
B(-1,25,1,LOG)
B(-1,25,4,LEAVES:0)
B(-1,26,-2,LEAVES:0)
B(-1,26,0,LOG)
B(-1,26,1,LOG)
B(-1,26,2,LEAVES:0)
B(-1,26,4,LEAVES_2:5)
B(-1,27,1,LOG)
B(-1,27,2,LEAVES:0)
B(-1,27,3,LEAVES:0)
B(-1,28,0,LEAVES:0)
B(-1,28,1,LOG)
B(-1,28,2,LEAVES:0)
B(-1,28,3,LEAVES_2:5)
B(-1,29,0,LEAVES_2:5)
B(-1,29,1,LEAVES:3)
B(-1,29,2,LEAVES_2:5)
B(-1,30,1,LEAVES:3)
B(-1,31,1,LEAVES_2:5)
B(-1,32,1,LEAVES_2:5)
B(-1,33,1,LEAVES_2:5)
B(0,2,-3,LOG)
B(0,3,-3,LOG)
B(0,3,1,LOG)
B(0,4,-2,LOG)
B(0,4,1,LOG)
B(0,4,2,LOG)
B(0,4,3,LOG)
B(0,5,-2,LOG)
B(0,5,-1,LOG)
B(0,5,1,LOG)
B(0,5,2,LOG)
B(0,6,-2,LOG)
B(0,6,-1,LOG)
B(0,6,0,LOG)
B(0,6,1,LOG)
B(0,6,2,LOG)
B(0,7,-1,LOG)
B(0,7,0,LOG)
B(0,7,1,LOG)
B(0,7,2,LOG)
B(0,8,-1,LOG)
B(0,8,0,LOG)
B(0,8,1,LOG)
B(0,9,-1,LOG)
B(0,9,0,LOG)
B(0,9,1,LOG)
B(0,10,-1,LOG)
B(0,10,0,LOG)
B(0,10,1,LOG)
B(0,11,-1,LEAVES:3)
B(0,11,0,LOG)
B(0,11,1,LOG)
B(0,12,0,LOG)
B(0,12,1,LOG)
B(0,12,2,LEAVES:3)
B(0,13,-1,LEAVES:0)
B(0,13,0,LOG)
B(0,13,1,LOG)
B(0,14,-2,LEAVES:0)
B(0,14,-1,LEAVES:0)
B(0,14,0,LOG)
B(0,14,1,LOG)
B(0,14,4,LEAVES:0)
B(0,14,5,LEAVES:0)
B(0,15,-2,LEAVES:0)
B(0,15,-1,LOG)
B(0,15,0,LOG)
B(0,15,1,LOG)
B(0,16,-6,LEAVES:0)
B(0,16,-5,LEAVES:0)
B(0,16,-4,LEAVES:0)
B(0,16,-3,LOG)
B(0,16,-2,LOG)
B(0,16,-1,LOG)
B(0,16,0,LOG)
B(0,16,1,LOG)
B(0,17,-2,LOG)
B(0,17,-1,LOG)
B(0,17,0,LOG)
B(0,17,1,LOG)
B(0,18,-5,LEAVES:0)
B(0,18,-4,LOG)
B(0,18,-3,LOG)
B(0,18,-1,LEAVES:0)
B(0,18,0,LOG)
B(0,18,1,LOG)
B(0,18,4,LEAVES:0)
B(0,18,5,LEAVES:0)
B(0,19,-4,LEAVES:0)
B(0,19,-3,LEAVES:0)
B(0,19,-2,LEAVES:0)
B(0,19,0,LOG)
B(0,19,1,LOG)
B(0,19,3,LEAVES:0)
B(0,20,-5,LEAVES:0)
B(0,20,-4,LEAVES:0)
B(0,20,-3,LEAVES:0)
B(0,20,-2,LEAVES:0)
B(0,20,0,LOG)
B(0,20,1,LOG)
B(0,20,3,LEAVES:0)
B(0,20,4,LEAVES:0)
B(0,21,-3,LEAVES:0)
B(0,21,-2,LEAVES:0)
B(0,21,-1,LEAVES:0)
B(0,21,0,LOG)
B(0,21,1,LOG)
B(0,21,2,LEAVES:0)
B(0,21,3,LEAVES:0)
B(0,21,4,LEAVES:0)
B(0,22,-3,LEAVES:0)
B(0,22,-2,LEAVES:0)
B(0,22,0,LOG)
B(0,22,1,LOG)
B(0,22,2,LEAVES:0)
B(0,22,3,LEAVES:0)
B(0,23,-4,LEAVES:0)
B(0,23,-3,LEAVES:0)
B(0,23,0,LOG)
B(0,23,1,LOG)
B(0,23,2,LEAVES:0)
B(0,24,-4,LEAVES:0)
B(0,24,-1,LEAVES:0)
B(0,24,0,LEAVES:0)
B(0,24,1,LOG)
B(0,24,3,LEAVES:0)
B(0,25,-1,LEAVES:0)
B(0,25,1,LEAVES:0)
B(0,25,3,LEAVES:0)
B(0,26,-1,LEAVES:0)
B(0,26,1,LEAVES:0)
B(0,26,2,LEAVES:0)
B(0,27,0,LEAVES:0)
B(0,27,1,LEAVES:0)
B(0,27,2,LEAVES:0)
B(0,27,3,LEAVES:0)
B(0,28,1,LEAVES:0)
B(0,28,2,LEAVES:0)
B(0,29,1,LEAVES_2:5)
B(0,30,1,LEAVES_2:5)
B(1,1,1,LOG)
B(1,2,1,LOG)
B(1,2,3,LOG)
B(1,3,3,LOG)
B(1,4,-1,LOG)
B(1,4,0,LOG)
B(1,4,1,LOG)
B(1,4,2,LOG)
B(1,5,-1,LOG)
B(1,5,0,LOG)
B(1,5,1,LOG)
B(1,6,0,LOG)
B(1,6,1,LOG)
B(1,7,1,LOG)
B(1,8,1,LOG)
B(1,10,1,LOG)
B(1,11,0,LEAVES:0)
B(1,11,1,LOG)
B(1,11,2,LEAVES:0)
B(1,12,0,LEAVES:0)
B(1,12,1,LEAVES:0)
B(1,12,2,LEAVES:0)
B(1,14,-1,LEAVES:0)
B(1,14,1,LEAVES:0)
B(1,14,2,LEAVES:0)
B(1,14,3,LEAVES:0)
B(1,14,4,LEAVES:0)
B(1,15,-2,LEAVES:0)
B(1,15,-1,LEAVES:0)
B(1,15,0,LEAVES:0)
B(1,15,1,LEAVES:0)
B(1,15,2,LEAVES:0)
B(1,16,-6,LEAVES:0)
B(1,16,-5,LEAVES:0)
B(1,16,-4,LEAVES:0)
B(1,16,-3,LEAVES:0)
B(1,16,-1,LEAVES:0)
B(1,16,0,LEAVES:0)
B(1,16,1,LEAVES:0)
B(1,16,2,LEAVES:0)
B(1,17,-3,LEAVES:0)
B(1,17,-2,LEAVES:0)
B(1,17,0,LEAVES:0)
B(1,17,1,LOG)
B(1,18,-5,LEAVES:0)
B(1,18,-4,LEAVES:0)
B(1,18,-3,LEAVES:0)
B(1,18,-2,LEAVES:0)
B(1,18,-1,LEAVES:0)
B(1,18,0,LEAVES:0)
B(1,18,1,LOG)
B(1,18,2,LEAVES:0)
B(1,19,-3,LEAVES:0)
B(1,19,-2,LEAVES:0)
B(1,19,-1,LEAVES:0)
B(1,19,0,LEAVES:0)
B(1,19,1,LEAVES:0)
B(1,19,2,LEAVES:0)
B(1,20,-4,LEAVES:0)
B(1,20,-2,LEAVES:0)
B(1,20,-1,LEAVES:0)
B(1,20,0,LOG)
B(1,20,1,LEAVES:0)
B(1,20,2,LEAVES:0)
B(1,20,4,LEAVES:0)
B(1,21,-1,LEAVES:0)
B(1,21,4,LEAVES:0)
B(1,22,-1,LEAVES:0)
B(1,22,0,LEAVES:0)
B(1,22,1,LOG)
B(1,23,-2,LEAVES:0)
B(1,23,-1,LEAVES:0)
B(1,23,0,LEAVES:0)
B(1,23,1,LOG)
B(1,23,2,LEAVES:0)
B(1,23,3,LEAVES:0)
B(1,23,4,LEAVES:0)
B(1,24,1,LEAVES:0)
B(1,24,2,LEAVES:0)
B(1,25,0,LEAVES:0)
B(1,25,1,LEAVES:0)
B(1,25,3,LEAVES:3)
B(1,27,0,LEAVES:0)
B(1,27,2,LEAVES:0)
B(2,2,0,LOG)
B(2,3,0,LOG)
B(2,4,1,LOG)
B(2,5,1,LOG)
B(2,11,0,LEAVES:0)
B(2,11,1,LOG)
B(2,11,2,LEAVES:0)
B(2,12,1,LEAVES:3)
B(2,14,1,LEAVES:0)
B(2,14,2,LEAVES:0)
B(2,15,0,LEAVES:0)
B(2,15,2,LEAVES:0)
B(2,16,-5,LEAVES:0)
B(2,16,-4,LEAVES:0)
B(2,16,-3,LEAVES:0)
B(2,16,-2,LEAVES:0)
B(2,16,-1,LEAVES:0)
B(2,16,2,LEAVES:0)
B(2,16,3,LEAVES:0)
B(2,17,-2,LEAVES:0)
B(2,17,-1,LEAVES:0)
B(2,17,0,LEAVES:0)
B(2,18,-1,LEAVES:0)
B(2,18,0,LEAVES:0)
B(2,18,1,LOG)
B(2,18,3,LEAVES:0)
B(2,19,-1,LEAVES:0)
B(2,19,0,LEAVES:0)
B(2,19,1,LEAVES:0)
B(2,19,2,LEAVES:0)
B(2,20,0,LOG)
B(2,20,1,LEAVES:0)
B(2,20,2,LEAVES:0)
B(2,20,3,LEAVES:0)
B(2,21,-1,LEAVES:0)
B(2,21,0,LEAVES:0)
B(2,21,1,LEAVES:0)
B(2,21,2,LEAVES:0)
B(2,21,3,LEAVES:0)
B(2,22,-1,LEAVES:0)
B(2,22,0,LEAVES:0)
B(2,23,-2,LEAVES:0)
B(2,23,-1,LEAVES:0)
B(2,23,1,LOG)
B(2,23,2,LEAVES:0)
B(2,23,3,LEAVES:0)
B(2,24,0,LEAVES:0)
B(2,25,2,LEAVES:3)
B(3,11,0,LEAVES:0)
B(3,11,1,LEAVES:3)
B(3,14,0,LEAVES:0)
B(3,14,1,LEAVES:0)
B(3,15,1,LEAVES:0)
B(3,15,2,LEAVES:3)
B(3,16,-4,LEAVES:0)
B(3,16,-2,LEAVES:0)
B(3,17,-2,LEAVES:0)
B(3,17,0,LEAVES:0)
B(3,18,-2,LEAVES:0)
B(3,18,-1,LEAVES:0)
B(3,18,0,LEAVES:0)
B(3,18,1,LOG)
B(3,18,2,LEAVES:0)
B(3,18,3,LEAVES:0)
B(3,19,-1,LEAVES:0)
B(3,19,0,LEAVES:0)
B(3,20,-1,LEAVES:0)
B(3,20,0,LOG)
B(3,20,1,LEAVES:0)
B(3,21,0,LEAVES:0)
B(3,21,1,LEAVES:0)
B(3,21,2,LEAVES:0)
B(3,22,-1,LEAVES:0)
B(3,22,1,LEAVES:0)
B(3,22,2,LEAVES:0)
B(3,23,-1,LEAVES:0)
B(3,23,1,LEAVES:0)
B(3,23,3,LEAVES:0)
B(3,24,-1,LEAVES:0)
B(3,24,0,LEAVES:0)
B(3,24,1,LEAVES:0)
B(4,17,-2,LEAVES:0)
B(4,18,-2,LEAVES:0)
B(4,18,-1,LEAVES:0)
B(4,18,1,LEAVES:0)
B(4,18,2,LEAVES:0)
B(4,20,-1,LEAVES:0)
B(4,20,0,LEAVES:0)
B(4,20,1,LEAVES:0)
B(4,21,-1,LEAVES:0)
B(4,21,0,LOG)
B(4,21,1,LEAVES:0)
B(4,22,0,LEAVES:0)
B(4,22,1,LEAVES:0)
B(4,23,1,LEAVES:0)
B(5,18,1,LEAVES:0)
B(5,20,-1,LEAVES:0)
B(5,20,0,LEAVES:0)
B(5,20,1,LEAVES:0)
B(5,21,0,LEAVES:3)

#######################################################################
# +-----------------------------------------------------------------+ #
# |                            BO3 checks                           | #
# +-----------------------------------------------------------------+ #
#######################################################################

BlockCheck(0,-1,0,GRASS,DIRT,DIRT:2)

#######################################################################
# +-----------------------------------------------------------------+ #
# |                             Branches                            | #
# +-----------------------------------------------------------------+ #
#######################################################################


#######################################################################
# +-----------------------------------------------------------------+ #
# |                         EntityFunctions                         | #
# +-----------------------------------------------------------------+ #
#######################################################################

