
#######################################################################
# +-----------------------------------------------------------------+ #
# |                            BO3 object                           | #
# +-----------------------------------------------------------------+ #
#######################################################################

Author: MC_Pitman

Description: No description given

Version: 3

SettingsMode: WriteWithoutComments


#######################################################################
# +-----------------------------------------------------------------+ #
# |                          Main settings                          | #
# +-----------------------------------------------------------------+ #
#######################################################################

Tree: true

Frequency: 1

Rarity: 3.0

RotateRandomly: true

SpawnHeight: highestSolidBlock

SpawnHeightOffset: -3

SpawnHeightVariance: 0

##############################
# Height Limits for the BO3. #
##############################

MinHeight: 61

MaxHeight: 71

######################
# Extrusion settings #
######################

ExtrudeMode: None

ExtrudeThroughBlocks: AIR

MaxBranchDepth: 10

ExcludedBiomes: All


#######################################################################
# +-----------------------------------------------------------------+ #
# |                      Source block settings                      | #
# +-----------------------------------------------------------------+ #
#######################################################################

SourceBlocks: STONE:1,STONE:3,STONE:5,DIRT:1,DIRT,SAND,GRASS,DIRT:2,STATIONARY_WATER,HARD_CLAY,STAINED_CLAY,CLAY,SANDSTONE,SAND:1,AIR,STONE,GRAVEL,LONG_GRASS,LONG_GRASS:1,LONG_GRASS:2,DEAD_BUSH,YELLOW_FLOWER,RED_ROSE,BROWN_MUSHROOM,RED_MUSHROOM

MaxPercentageOutsideSourceBlock: 0

OutsideSourceBlock: placeAnyway

IsOTGPlus: false

InheritBO3: 

InheritBO3Rotation: NORTH

OverrideChildSettings: true

OverrideParentHeight: false

CanOverride: false

BranchFrequency: 0

BranchFrequencyGroup: 

MustBeBelowOther: false

MustBeInside: 

CannotBeInside: 

ReplacesBO3: 

CanSpawnOnWater: true

SpawnOnWaterOnly: false

SpawnUnderWater: false

SpawnAtWaterLevel: false

HeightOffset: 0

RemoveAir: true

ReplaceAbove: 

ReplaceBelow: 

ReplaceWithBiomeBlocks: true

ReplaceWithGroundBlock: DIRT

ReplaceWithSurfaceBlock: GRASS

SmoothRadius: 0

SmoothHeightOffset: 0

SmoothStartTop: false

SmoothStartWood: false

SmoothingSurfaceBlock: 

SmoothingGroundBlock: 

BO3Group: 

IsSpawnPoint: false


#######################################################################
# +-----------------------------------------------------------------+ #
# |                              Blocks                             | #
# +-----------------------------------------------------------------+ #
#######################################################################

Block(-6,0,-3,LOG)
Block(-6,0,-1,LOG)
Block(-6,1,-3,LOG)
Block(-6,1,-1,LOG:12)
Block(-6,1,0,DIRT:1)
Block(-5,0,-2,DIRT:1)
Block(-5,0,-1,DIRT:1)
Block(-5,0,0,LOG)
Block(-5,1,-2,LOG)
Block(-5,1,-1,LOG:12)
Block(-5,1,0,LOG:12)
Block(-5,1,1,DIRT)
Block(-5,1,2,DIRT:1)
Block(-5,2,-1,BROWN_MUSHROOM)
Block(-5,2,0,LOG:12)
Block(-5,2,1,GRASS)
Block(-4,0,-5,LOG)
Block(-4,0,-3,DIRT:1)
Block(-4,0,-2,DIRT:1)
Block(-4,0,1,LOG)
Block(-4,0,2,LOG)
Block(-4,1,-5,LOG)
Block(-4,1,-3,DIRT:1)
Block(-4,1,-2,GRASS)
Block(-4,1,-1,DIRT)
Block(-4,1,0,LOG:12)
Block(-4,1,1,LOG:12)
Block(-4,1,2,LOG)
Block(-4,1,3,GRASS)
Block(-4,2,-1,DIRT:1)
Block(-4,2,0,LOG:12)
Block(-4,2,1,LOG:12)
Block(-4,2,2,DIRT:1)
Block(-4,2,3,LONG_GRASS:1)
Block(-4,3,0,LOG:12)
Block(-4,3,1,GRASS)
Block(-3,0,-4,DIRT:1)
Block(-3,0,3,LOG)
Block(-3,1,-4,LOG:12)
Block(-3,1,-3,GRASS)
Block(-3,1,-2,LOG:12)
Block(-3,1,1,LOG:12)
Block(-3,1,2,LOG)
Block(-3,1,3,LOG)
Block(-3,2,-1,LOG:12)
Block(-3,2,0,LOG:12)
Block(-3,2,1,LOG:12)
Block(-3,2,2,LOG:12)
Block(-3,3,-1,LOG:12)
Block(-3,3,0,LOG:12)
Block(-3,3,1,LOG:12)
Block(-3,3,2,HUGE_MUSHROOM_1:0)
Block(-3,4,-1,WEB)
Block(-3,4,0,LOG:12)
Block(-3,4,1,LOG:12)
Block(-3,5,0,LOG:12)
Block(-3,5,1,LOG:12)
Block(-3,6,0,LOG:12)
Block(-3,7,0,LOG)
Block(-2,0,-5,DIRT:1)
Block(-2,0,-4,DIRT:1)
Block(-2,0,5,LOG)
Block(-2,0,6,LOG)
Block(-2,1,-6,LOG:12)
Block(-2,1,-5,DIRT:1)
Block(-2,1,-4,LOG:12)
Block(-2,1,-3,LOG:12)
Block(-2,1,2,LOG:12)
Block(-2,1,3,LOG:12)
Block(-2,1,5,LOG:12)
Block(-2,1,6,LOG)
Block(-2,2,-3,GRASS)
Block(-2,2,-2,GRASS)
Block(-2,2,-1,LOG:12)
Block(-2,2,1,LOG:12)
Block(-2,2,2,LOG:12)
Block(-2,2,3,LOG)
Block(-2,3,-1,LOG)
Block(-2,3,0,LOG:12)
Block(-2,3,1,LOG:12)
Block(-2,3,2,LOG:12)
Block(-2,4,0,BROWN_MUSHROOM)
Block(-2,4,1,LOG:12)
Block(-2,4,2,LOG)
Block(-2,5,0,LOG:12)
Block(-2,5,1,LOG:12)
Block(-2,5,2,LOG)
Block(-2,6,0,LOG:12)
Block(-2,6,1,LOG:12)
Block(-2,6,2,LOG)
Block(-2,7,0,LOG)
Block(-2,7,1,LOG:12)
Block(-2,8,0,LOG)
Block(-2,8,1,LOG:12)
Block(-2,9,1,LOG)
Block(-1,0,-5,DIRT:1)
Block(-1,0,-4,DIRT:1)
Block(-1,0,4,LOG)
Block(-1,1,-5,LOG)
Block(-1,1,-4,LOG:12)
Block(-1,1,4,LOG:12)
Block(-1,1,5,LOG:12)
Block(-1,2,-5,DIRT:1)
Block(-1,2,-4,LOG:12)
Block(-1,2,-3,LOG:12)
Block(-1,2,-2,GRASS)
Block(-1,2,-1,DIRT:1)
Block(-1,2,0,DIRT:1)
Block(-1,2,1,LOG)
Block(-1,2,2,LOG:12)
Block(-1,2,3,LOG:12)
Block(-1,2,4,BROWN_MUSHROOM)
Block(-1,3,0,GRASS)
Block(-1,3,1,DIRT)
Block(-1,3,2,LOG:12)
Block(-1,3,3,LOG:12)
Block(-1,4,0,LONG_GRASS:1)
Block(-1,4,1,LOG:12)
Block(-1,4,2,LOG:12)
Block(-1,4,3,LOG:12)
Block(-1,5,1,LOG:12)
Block(-1,5,2,LOG:12)
Block(-1,5,3,LOG:12)
Block(-1,6,0,LOG:12)
Block(-1,6,1,LOG:12)
Block(-1,6,2,LOG:12)
Block(-1,6,3,LOG:12)
Block(-1,7,0,LOG:12)
Block(-1,7,1,LOG:12)
Block(-1,7,2,LOG:12)
Block(-1,7,3,LOG)
Block(-1,8,0,BROWN_MUSHROOM)
Block(-1,8,1,LOG:12)
Block(-1,8,2,LOG:12)
Block(-1,9,2,LOG:12)
Block(-1,10,2,LOG)
Block(0,0,-5,DIRT:1)
Block(0,0,6,LOG)
Block(0,1,-6,DIRT:1)
Block(0,1,-5,LOG:12)
Block(0,1,-4,LOG:12)
Block(0,1,4,LOG:12)
Block(0,1,5,LOG:12)
Block(0,1,6,LOG:12)
Block(0,2,-5,HUGE_MUSHROOM_1)
Block(0,2,-4,LOG:12)
Block(0,2,-3,LOG:12)
Block(0,2,-2,LOG)
Block(0,2,-1,LOG)
Block(0,2,0,LOG)
Block(0,2,3,LOG:12)
Block(0,2,4,LOG:12)
Block(0,2,5,LOG:12)
Block(0,3,-4,LOG:12)
Block(0,3,-3,LOG:12)
Block(0,3,-1,DIRT:1)
Block(0,3,0,GRASS)
Block(0,3,1,LOG:12)
Block(0,3,2,LOG:12)
Block(0,3,3,LOG:12)
Block(0,3,4,LOG:12)
Block(0,4,-4,LOG:12)
Block(0,4,-3,LOG:12)
Block(0,4,0,LONG_GRASS:1)
Block(0,4,1,LOG:12)
Block(0,4,2,LOG:12)
Block(0,4,3,LOG:12)
Block(0,4,4,LOG:12)
Block(0,5,-3,LOG:12)
Block(0,5,2,LOG:12)
Block(0,5,3,LOG:12)
Block(0,6,-3,LOG:12)
Block(0,6,1,LOG:12)
Block(0,6,2,LOG:12)
Block(0,6,3,LOG:12)
Block(0,7,-3,LOG)
Block(0,7,1,LOG:12)
Block(0,7,2,LOG:12)
Block(0,7,3,LOG:12)
Block(0,8,1,LOG:12)
Block(0,8,2,LOG:12)
Block(0,8,3,LOG:12)
Block(0,9,1,LOG:12)
Block(0,9,2,LOG:12)
Block(1,1,-6,LOG:12)
Block(1,1,-4,LOG:12)
Block(1,1,-3,LOG)
Block(1,1,-2,LOG:12)
Block(1,1,4,LOG:12)
Block(1,1,5,LOG:12)
Block(1,2,-5,LOG:12)
Block(1,2,-4,LOG:12)
Block(1,2,-3,LOG)
Block(1,2,-2,LOG)
Block(1,2,-1,LOG)
Block(1,2,0,LOG)
Block(1,2,1,DIRT:1)
Block(1,2,2,DIRT:1)
Block(1,2,3,LOG:12)
Block(1,2,4,LOG:12)
Block(1,3,-4,LOG:12)
Block(1,3,-3,LOG)
Block(1,3,-2,GRASS)
Block(1,3,-1,LOG)
Block(1,3,0,LOG)
Block(1,3,1,DIRT)
Block(1,3,2,LOG:12)
Block(1,3,3,LOG:12)
Block(1,4,-4,LOG:12)
Block(1,4,-3,GRASS)
Block(1,4,-2,LONG_GRASS:1)
Block(1,4,0,GRASS)
Block(1,4,1,GRASS)
Block(1,4,2,LOG:12)
Block(1,4,3,LOG:12)
Block(1,4,4,HUGE_MUSHROOM_1:0)
Block(1,5,-4,LOG:12)
Block(1,5,1,LONG_GRASS:1)
Block(1,5,2,LOG:12)
Block(1,5,3,LOG:12)
Block(1,6,-4,LOG:12)
Block(1,6,-3,LOG)
Block(1,6,2,LOG:12)
Block(1,6,3,LOG:12)
Block(1,7,-4,LOG:12)
Block(1,7,-3,LOG:12)
Block(1,7,2,LOG:12)
Block(1,7,3,LOG:12)
Block(1,8,-4,LOG)
Block(1,8,-3,LOG:12)
Block(1,8,2,LOG:12)
Block(1,8,3,LOG:12)
Block(1,9,2,LOG:12)
Block(1,9,3,LOG:12)
Block(1,10,2,LOG:12)
Block(1,11,2,LOG)
Block(2,0,4,LOG)
Block(2,1,-5,LOG:12)
Block(2,1,-4,LOG:12)
Block(2,1,-3,LOG:12)
Block(2,1,-2,LOG)
Block(2,1,-1,LOG:12)
Block(2,1,0,LOG)
Block(2,1,1,LOG:12)
Block(2,1,4,LOG)
Block(2,2,-5,WEB)
Block(2,2,-4,LOG:12)
Block(2,2,-3,LOG:12)
Block(2,2,-2,LOG)
Block(2,2,-1,LOG)
Block(2,2,0,LOG)
Block(2,2,1,LOG:12)
Block(2,2,2,LOG:12)
Block(2,2,3,LOG:12)
Block(2,3,-4,LOG:12)
Block(2,3,-3,LOG:12)
Block(2,3,-2,LOG:12)
Block(2,3,-1,HUGE_MUSHROOM_1)
Block(2,3,0,LOG)
Block(2,3,2,LOG:12)
Block(2,4,-3,LOG:12)
Block(2,4,-2,LOG)
Block(2,4,0,LOG)
Block(2,4,1,LOG:12)
Block(2,4,2,LOG:12)
Block(2,4,3,HUGE_MUSHROOM_1:0)
Block(2,4,4,HUGE_MUSHROOM_1:0)
Block(2,5,-3,LOG:12)
Block(2,5,-2,LOG)
Block(2,5,0,LOG)
Block(2,5,1,LOG:12)
Block(2,5,2,LOG:12)
Block(2,5,3,HUGE_MUSHROOM_1:0)
Block(2,6,-4,HUGE_MUSHROOM_1:0)
Block(2,6,-3,LOG:12)
Block(2,6,-2,HUGE_MUSHROOM_1:0)
Block(2,6,0,LOG)
Block(2,6,1,LOG:12)
Block(2,6,2,LOG:12)
Block(2,7,-3,LOG:12)
Block(2,7,1,LOG:12)
Block(2,7,2,LOG:12)
Block(2,8,-3,LOG:12)
Block(2,8,0,WEB)
Block(2,8,1,LOG:12)
Block(2,8,2,LOG:12)
Block(2,9,-3,LOG:12)
Block(2,9,1,LOG)
Block(2,9,2,LOG:12)
Block(2,10,-3,LOG:12)
Block(2,10,2,LOG:12)
Block(2,11,-3,LOG)
Block(3,0,2,LOG)
Block(3,0,3,LOG)
Block(3,1,-6,LOG)
Block(3,1,-5,LOG)
Block(3,1,-4,LOG:12)
Block(3,1,-3,LOG:12)
Block(3,1,-2,LOG:12)
Block(3,1,-1,LOG:12)
Block(3,1,0,LOG:12)
Block(3,1,1,LOG:12)
Block(3,1,2,LOG:12)
Block(3,1,3,LOG:12)
Block(3,2,-4,LOG:12)
Block(3,2,-3,LOG:12)
Block(3,2,-2,LOG:12)
Block(3,2,-1,LOG)
Block(3,2,0,LOG)
Block(3,2,1,LOG:12)
Block(3,2,2,LOG:12)
Block(3,3,-3,LOG:12)
Block(3,3,-2,LOG:12)
Block(3,3,-1,LOG)
Block(3,3,0,LOG)
Block(3,3,1,LOG:12)
Block(3,3,2,LOG:12)
Block(3,4,-3,LOG:12)
Block(3,4,-2,LOG:12)
Block(3,4,-1,LOG)
Block(3,4,0,LOG)
Block(3,4,1,LOG:12)
Block(3,4,2,HUGE_MUSHROOM_1:0)
Block(3,4,3,HUGE_MUSHROOM_1:0)
Block(3,5,-2,LOG:12)
Block(3,5,-1,LOG)
Block(3,5,0,LOG)
Block(3,5,1,LOG:12)
Block(3,6,-4,HUGE_MUSHROOM_1:0)
Block(3,6,-3,HUGE_MUSHROOM_1:0)
Block(3,6,-2,LOG:12)
Block(3,6,-1,LOG:12)
Block(3,6,0,LOG:12)
Block(3,6,1,LOG:12)
Block(3,7,-3,HUGE_MUSHROOM_1:0)
Block(3,7,-2,LOG:12)
Block(3,7,-1,LOG:12)
Block(3,7,0,LOG:12)
Block(3,8,-2,LOG)
Block(3,8,-1,LOG:12)
Block(3,8,0,LOG:12)
Block(3,9,-1,LOG)
Block(3,9,0,LOG:12)
Block(3,10,0,LOG:12)
Block(3,11,0,LOG)
Block(4,1,-4,LOG:12)
Block(4,1,-3,LOG:12)
Block(4,1,-2,LOG:12)
Block(4,1,-1,LOG:12)
Block(4,1,0,LOG:12)
Block(4,1,1,LOG)
Block(4,2,-3,LOG:12)
Block(4,2,-2,LOG:12)
Block(4,2,-1,LOG:12)
Block(4,2,0,LOG:12)
Block(4,2,1,LOG:12)
Block(4,3,-3,BROWN_MUSHROOM)
Block(4,3,-2,LOG:12)
Block(4,3,-1,LOG:12)
Block(4,3,0,LOG:12)
Block(4,4,-1,LOG:12)
Block(4,4,0,LOG:12)
Block(4,5,-1,LOG:12)
Block(4,5,0,LOG:12)
Block(4,6,-3,HUGE_MUSHROOM_1:0)
Block(4,6,-2,HUGE_MUSHROOM_1:0)
Block(4,6,-1,LOG)
Block(4,7,-1,LOG)
Block(5,0,-1,LOG)
Block(5,0,1,LOG)
Block(5,1,-2,LOG:12)
Block(5,1,-1,LOG:12)
Block(5,1,1,LOG:12)
Block(5,2,-2,LOG:12)
Block(6,0,-3,LOG)
Block(6,0,-2,LOG)
Block(6,1,-3,LOG)
Block(6,1,-2,LOG:12)

#######################################################################
# +-----------------------------------------------------------------+ #
# |                            BO3 checks                           | #
# +-----------------------------------------------------------------+ #
#######################################################################


#######################################################################
# +-----------------------------------------------------------------+ #
# |                             Branches                            | #
# +-----------------------------------------------------------------+ #
#######################################################################


#######################################################################
# +-----------------------------------------------------------------+ #
# |                             Entities                            | #
# +-----------------------------------------------------------------+ #
#######################################################################


#######################################################################
# +-----------------------------------------------------------------+ #
# |                            Particles                            | #
# +-----------------------------------------------------------------+ #
#######################################################################


#######################################################################
# +-----------------------------------------------------------------+ #
# |                             Spawners                            | #
# +-----------------------------------------------------------------+ #
#######################################################################


#######################################################################
# +-----------------------------------------------------------------+ #
# |                             ModData                             | #
# +-----------------------------------------------------------------+ #
#######################################################################

